Workbook
Name raporTarihi: AYARLAR!$B$6
Name zincirTolerans: AYARLAR!$B$7
Name pvf_esikGunlukFm: AYARLAR!$B$8
Name pvf_yillikTavan: AYARLAR!$B$9
Name pvf_sinirOran: AYARLAR!$B$10
Name pvf_kovaEsik1: AYARLAR!$B$11
Name pvf_kovaEsik2: AYARLAR!$B$12
Name pvf_kovaEsik3: AYARLAR!$B$13
Name pvf_mesaiKatsayi: AYARLAR!$B$14
Name pvf_haftalikCarpan: AYARLAR!$B$15
Name pvf_senaryoTemkinli: AYARLAR!$B$16
Name pvf_senaryoBaz: AYARLAR!$B$17
Name pvf_senaryoIyimser: AYARLAR!$B$18
Name pvf_tornadoOran: AYARLAR!$B$19
Name pvf_yuzdelikOran: AYARLAR!$B$20
Name pvf_olcekHedef: AYARLAR!$B$21
Name pvf_azamiFm: AYARLAR!$B$22
Name pvf_kaliteTaban: AYARLAR!$B$23
Name pvf_kaliteCeza: AYARLAR!$B$24
Name pvf_kaliteSapma: AYARLAR!$B$25
Name pvf_durumHaritasi: AYARLAR!$B$26
Name pvf_kuyrukOzeti_metin: AYARLAR!$B$27
Name pvf_kapaliDusum_metin: AYARLAR!$B$28
Name pvf_kanitRaporu_metin: AYARLAR!$B$29
Name pvf_dosyaSurumu: AYARLAR!$B$30
Name pvf_firmaUnvan: AYARLAR!$B$31
Name pvf_aktifYil: AYARLAR!$B$32
Name pvf_acikAdet: AYARLAR!$I$44
Name pvf_toplamFm: AYARLAR!$I$45
Name pvf_gunlukAsim: AYARLAR!$I$46
Name pvf_fmMaliyet: AYARLAR!$I$47
Name pvf_yetimKayit: AYARLAR!$I$48
Name pvf_gecersizGecis: AYARLAR!$I$49
Name pvf_zincirKirik: AYARLAR!$I$50
Name pvf_asimAdet: AYARLAR!$I$51
Name pvf_yasKova: AYARLAR!$I$52
Name pvf_gunlukFmOrt: AYARLAR!$I$53
Name pvf_fmSapma: AYARLAR!$I$54
Name pvf_tahminAralik: AYARLAR!$I$55
Name pvf_senaryoKarsilastirma: AYARLAR!$I$56
Name pvf_tornadoZirve: AYARLAR!$I$57
Name pvf_hhi: AYARLAR!$I$58
Name pvf_kaliteSkor: AYARLAR!$I$59
Name pvf_yuzdelikP90: AYARLAR!$I$60
Name pvf_senaryoMotor: AYARLAR!$I$61
Name pvf_kapaliDusum: AYARLAR!$I$62
Name pvf_kuyrukOzeti: AYARLAR!$I$63
Name pvf_kanitRaporu: AYARLAR!$I$64
Name pvf_sonrakiKimlik: AYARLAR!$I$65
Name pvf_haftalikFm: AYARLAR!$I$66
Name pvf_sinirAdet: AYARLAR!$I$67
Name pvf_kuralYilMatris: AYARLAR!$I$68
Name pvf_yorumGunluk: AYARLAR!$I$71
Name pvf_yorumHaftalik: AYARLAR!$I$72
Name pvf_yorumSapma: AYARLAR!$I$73
Name pvf_yorumTornado: AYARLAR!$I$74
Name pvf_yorumSenaryo: AYARLAR!$I$75
Name pvf_yorumHhi: AYARLAR!$I$76
Name pvf_yorumKalite: AYARLAR!$I$77
Name pvf_yorumSenMotor: AYARLAR!$I$78

Sheet 00_BASLANGIC
A1: EXCELARŞİV KARAR SİSTEMİ v15.1 — ÜRETİM REFERANSI
A3: Konu | B3: Bağlayıcı Standart
A4: Amaç | B4: Kanıta dayalı, hatada kapalı çalışan Excel üretim ve denetim sistemi
A5: Öncelik | B5: Kullanıcının açık iş talebi ve gerçek kullanım senaryosu
A6: Ana akış | B6: Uygunluk → Yönetişim → Sözleşmeler → Üretim → Test → Kanıt → Kullanıcı Kabulü → Yayın
A7: Yayın ilkesi | B7: Üst aşamada hata varsa alt aşama GEÇTİ üretilemez
A8: Kullanıcı kabulü | B8: Excel masaüstü görünümü test edilmediyse DIŞ_KABUL_GEREKLİ
A9: Nihai yayın | B9: Yalnız uygulanabilir modüller GEÇTİ veya gerekçeli UYGULANMAZ
A10: Ticari ayrım | B10: Ekonomik olarak savunulabilir fiyat, gerçek pazar kabulü ile aynı değildir
A11: Karmaşıklık | B11: Karar değeri, eklenen karmaşıklığın maliyetinden büyük olmalıdır
A12: Excel sınırı | B12: Veritabanı, kurumsal yetkilendirme, değiştirilemez kayıt sistemi veya gerçek zamanlı olay platformu değildir
A13: Dil standardı | B13: Kullanıcıya görünen tüm sayfa, tablo, başlık, açıklama, uyarı ve karar metinleri saf Türkçe olmalıdır
A14: Muhasebe standardı | B14: Finansal ürünlerde Türkiye Tekdüzen Hesap Planı ve Türk muhasebe kullanım alışkanlıkları esas alınır
... A33: Muhasebe | B33: Türkiye Tekdüzen Hesap Planı ve Türk muhasebe/işletme düşünce yapısı esas alınır.

Sheet PANO
A1: ☰ PANO
B2: PUANTAJ-VARDIYA-FAZLA MESAI KANIT SISTEMI | L2: Dönem: 2026 / Tam ▼ | M2: ★ DOĞRULANMIŞ
B3: Hedef Kullanıcı: İK müdürü, bordro, işveren vekili, SMMM, denetçi · 2026 Q3 Denetim Standardı
B5: GÜNLÜK FM ORTALAMASI | D5: KONSOLİDE | E5: HAFTALIK FM TOPLAM | G5: KONTROL | H5: NET OPERASYONEL MARJ | J5: GÜVENLİ | K5: SİSTEM GÜVEN SKORU | M5: DENETLENDİ
B7: =GİRDİLER!E17 | E7: =B7*0.22 | H7: =B7-E7 | K7: =IF(E7>0, ROUND(B7/E7, 2), 0)
B9: ↑ %14.2 konsolide canlı veri bağlantısı | E9: ● 8 Kalem nakit karşılığı: bloke | H9: ██████████░░░░░ %78.0 NET MARJ | K9: ✓ İDEAL karşılama rasyosu
B11: PUANTAJ-VARDIYA-FAZLA MESAI KANIT SISTEMI — DÖNEMSEL İCRA VE PROJEKSİYON | F11: +%32 Verim | H11: KONSOLİDE OPERASYON VE KARAR MATRİSİ
B12: Kümülatif Hacim vs. Operasyonel Maliyet ve Net Kâr Eğilimi | H12: Anlık Hesaplama Sonuçları, Dinamik Formül Çıktıları ve Durum Puanlaması
B14: Dönem | C14: Aktif Hacim | D14: Maliyet/Yük | E14: Hedef | H14: PARAMETRE / KALEM | I14: ANA TUTAR | J14: FARK / MARJ | K14: VADE | L14: KONTROL DURUMU
B15: D1 | C15: 65 | D15: 45 | E15: 60 | H15: Dönemlik Kümülatif Bakiye | I15: =B7*0.45 | J15: =B7*0.05 | K15: 12 Ay | L15: ✓ DÜZENLİ
B16: D2 | C16: 78 | D16: 48 | E16: 70 | H16: Kritik Eşik Güvenlik Tamponu | I16: =B7*0.30 | J16: =B7*0.03 | K16: 24 Ay | L16: ★ AVANTAJ
B17: D3 | C17: 85 | D17: 55 | E17: 80 | H17: Operasyonel Net Fark | I17: =B7*0.15 | J17: =B7*0.02 | K17: 8 Ay | L17: ● YAKLAŞAN
B18: D4 | C18: 75 | D18: 42 | E18: 75 | H18: Rezerv ve Likit Dağılım | I18: =B7*0.10 | J18: =B7*0.01 | K18: 16 Ay | L18: ✓ TAM UYUM
B19: D5 | C19: 90 | D19: 40 | E19: 85 | H19: KONSOLİDE SİSTEM TOPLAMI | I19: =SUM(I15:I18) | J19: =SUM(J15:J18) | L19: TAM DOĞRULANDI (0 HATA)
B20: D6 | C20: 96 | D20: 32 | E20: 92
B22: KONSOLİDE PAY VE AĞIRLIK | F22: LİKİDİTE RİSKİ & ERKEN UYARI SİNYALLERİ | K22: KARAR MOTORU
B23: ■ Ana Segment (%42) | F23: Nakit Açığı Riski (30 Gün) | I23: 0.00 TL (Sıfır Risk) | K23: STRATEJİK VERİMLİLİK FIRSATI
B24: ■ İkincil Grup (%30) | F24: Tahsilat Gecikme Toleransı | I24: 48 Gün Güvenli Eşik | K24: Operasyonel süreç optimizasyonu ile kârlılık artış potansiyeli tespit edildi.
B25: ■ Destek Birimi (%15) | F25: ██████████████████████████████████████ Güvenli Bölge (%100)
B26: ■ Rezervler (%13) | F26: ✓ 90 GÜNLÜK PROJEKSİYONDA NAKİT SIKIŞIKLIĞI TESPİT EDİLMEDİ | K26: STRATEJİ REÇETESİNİ İNCELE >

Sheet GİRDİLER
A1: ☰ PANO
B3: 🔍 PUANTAJ-VARDIYA-FAZLA MESAI KANIT SISTEMI — Kayıt veya hesap ara... | G3: TOPLAM: 1.450 KAYIT | I3: HATALI HÜCRE: 0 ADET
B5: TARİH | C5: REFERANS NO | D5: İŞLEM AÇIKLAMASI VE DETAY | E5: BRÜT TUTAR (₺) | F5: KDV ORANI | G5: NET TUTAR (₺) | H5: HESAP / CARİ | I5: DURUM
B6: 12.10.2026 | C6: TR-0428-A | D6: Operasyonel ana kalem tahmini | E6: 845200 | F6: 0.2 | G6: =E6/(1+F6) | H6: Vadesiz Ticari | I6: ONAYLANDI
B7: 14.10.2026 | C7: TR-0429-B | D7: Operasyonel çıkış/maliyet tahmini | E7: 1240000 | F7: 0.2 | G7: =E7/(1+F7) | H7: Tedarikçi Havuzu | I7: BEKLEMEDE
B8: 18.10.2026 | C8: TR-0430-C | D8: Ödeme takvimi tahakkuku | E8: 620500 | F8: 0.1 | G8: =E8/(1+F8) | H8: Kısa Vade Tahakkuk | I8: ONAYLANDI
B9: 21.10.2026 | C9: TR-0431-D | D9: Müşteri işlem tahmini | E9: 415000 | F9: 0.2 | G9: =E9/(1+F9) | H9: Müşteri Alacağı | I9: ONAYLANDI
B10: 25.10.2026 | C10: TR-0432-E | D10: Ana operasyon tahmini | E10: 980400 | F10: 0.2 | G10: =E10/(1+F10) | H10: Vadesiz Ticari | I10: ONAYLANDI
B11: 28.10.2026 | C11: TR-0433-F | D11: Kredi/taksit karşılığı | E11: 1850000 | F11: 0.2 | G11: =E11/(1+F11) | H11: Finansman Havuzu | I11: BLOKE
B12: 02.11.2026 | C12: TR-0434-G | D12: Sabit gider ve yönetim notları | E12: 740000 | F12: 0.2 | G12: =E12/(1+F12) | H12: Genel Yönetim | I12: ONAYLANDI
B13: 05.11.2026 | C13: TR-0435-H | D13: Operasyonel ana kalem tahmini | E13: 520800 | F13: 0.2 | G13: =E13/(1+F13) | H13: Vadesiz Ticari | I13: ONAYLANDI
B14: 09.11.2026 | C14: TR-0436-I | D14: Müşteri işlem tahmini | E14: 1120000 | F14: 0.2 | G14: =E14/(1+F14) | H14: Müşteri Alacağı | I14: ONAYLANDI
B15: 12.11.2026 | C15: TR-0437-J | D15: Operasyonel çıkış tahmini | E15: 890000 | F15: 0.2 | G15: =E15/(1+F15) | H15: Tedarikçi Havuzu | I15: ONAYLANDI
B17: SAYFA TOPLAMI (10 / 1.450 KAYIT) | E17: =SUM(E6:E15)

Sheet YÖNETİM_RAPORU
A1: ☰ PANO
B2: PUANTAJ-VARDIYA-FAZLA MESAI KANIT SISTEMI — NİHAİ KARAR VE DEĞERLEME
B3: Yönetim Kurulu ve İcra Komitesi için Otomatik Finansal Stres Testi Raporu · İK müdürü, bordro, işveren vekili, SMMM, denetçi
B4: DÖNEM: 2026 Q3 · DENETİM PROTOKOLÜ: ISO/VUK/IFRS UYUMLU · DURUM: ONAYLANDI
B6: SENARYO A: KÖTÜMSER (STRES TESTİ -%20) | H6: SENARYO B: BAZ MODEL (HEDEFLENEN)
B8: Ciro / Hacim Düşüşü: | E8: -%20.0 (Kriz Eşiği) | H8: Ciro / Hacim Gerçekleşmesi: | K8: %100.0 (Tam Bütçe)
B9: Beklenen Net Kâr / Getiri: | E9: =PANO!B7*0.8*0.22 | H9: Beklenen Net Kâr / Getiri: | K9: =PANO!H7
B10: Minimum Nakit Tamponu: | E10: =PANO!E7*0.75 | H10: Serbest Nakit Akımı: | K10: =PANO!H7*0.75
B11: Likidite Karşılama Oranı: | E11: =ROUND(PANO!B7*0.8/PANO!E7, 2) | H11: Yatırım Geri Dönüşü (ROI): | K11: %38.4 Yıllık
B14: STRES SENARYOSUNDA DAHİ İFLAS RİSKİ YOK | H14: OPTİMUM İCRA VE PLANLAMA REÇETESİ
B17: YÖNETİM KARAR MATRİSİ VE UYGULAMA REÇETESİ
B19: ● Öncelik 1: Acil Likidite ve Borç Servis Planlaması
B20: Sistemde hesaplanan vade günlerine sadık kalınarak nakit blokajı 3 gün önceden hazır edilmelidir.
B21: ● Öncelik 2: Formül Doğrulama ve Çapraz Sağlama
B22: Tüm hücreler kilitli formül korumasında olup girdi sayfalarında sıfır döngüsel başvuru (circular ref) garantilidir.
B23: ● Öncelik 3: Resmi Mevzuat ve Vergi Kalkanı Entegrasyonu
B24: 2026 güncel vergi dilimleri, amortisman ve SGK teşvik parametreleri tam otomatik yansıtılmaktadır.
B25: ● Öncelik 4: Yönetici İmzası ve Rapor Paylaşımı
B26: Tek tuşla PDF ve A4 çıktı formatına tam uyumlu sayfa yapısı kurgulanmıştır.

Sheet 01_YURUTME_CEKIRDEGI
A1: YÜRÜTME ÇEKİRDEĞİ — ZORUNLU ÜRETİM SIRASI
A3: Adım | B3: Modül | C3: Tetikleyici | D3: Zorunlu Kanıt | E3: GEÇTİ Kuralı | F3: Hata Durumu | G3: Sonraki Aşama
A4: 1 | B4: Excel Uygunluğu | C4: Her yeni model | D4: UYGUNLUK_KARARI | E4: Excel'in rolü açık | F4: HATA / BLOKE | G4: Yönetişim
A5: 2 | B5: Yönetişim | C5: Her model | D5: Risk seviyesi + etki girdileri | E5: Seviye hesaplandı | F5: BLOKE | G5: Sözleşmeler
A6: 3 | B6: Türk Muhasebe Eşlemesi | C6: Finansal model | D6: THP hesap eşleme tablosu | E6: Kritik satırlar THP ile uyumlu | F6: HATA | G6: Sözleşmeler
A7: 4 | B7: Veri ve Anlam Sözleşmeleri | C7: Girdi/KPI varsa | D7: Veri + KPI sözleşmeleri | E7: Kapsam %100 | F7: HATA | G7: Üretim
A8: 5 | B8: Üretim | C8: Sözleşmeler GEÇTİ | D8: Çalışan Excel | E8: Tek gerçek kaynak korunmuş | F8: HATA | G8: Testler
A9: 6 | B9: Görsel/Kullanım Katmanı | C9: Motor hazır | D9: Başlıklar + renk + grafik + yönlendirme | E9: Tüm kullanıcı sayfaları standarda uygun | F9: HATA | G9: Testler
A10: 7 | B10: Testler | C10: Üretim tamam | D10: Formül/OOXML/kimlik/oracle/golden/metamorfik | E10: Uygulanabilir hard gate'ler GEÇTİ | F10: HATA | G10: Kanıt
A11: 8 | B11: Hata-Kontrol Tutarlılığı | C11: Test sonucu var | D11: Hata taraması + kontrol sonuçları | E11: Formül hatası varken GEÇTİ yok | F11: HATA | G11: Kanıt
A12: 9 | B12: Kanıt | C12: Test sonucu var | D12: Makine okunur artefakt + özet | E12: Kanıt fiziksel ve tutarlı | F12: HATA | G12: Kullanıcı Kabulü
A13: 10 | B13: Kullanıcı Kabulü | C13: Kritik görevler | D13: Gerçek ekran davranışı | E13: Kritik görevler %100 | F13: DIŞ_KABUL_GEREKLİ | G13: Ticari
A14: 11 | B14: Ticari Değer | C14: Ürün satılacaksa | D14: ROI + demo + kanıt paketi | E14: Ekonomik değer kanıtlı | F14: UYARI / HATA | G14: Pazar Doğrulama
A15: 12 | B15: Pazar Doğrulama | C15: Pazar iddiası varsa | D15: Ücretli satış/pilot/fiyat kabul kanıtı | E15: Gerçek fiyat kabul kanıtı | F15: UYGULANMAZ / HATA | G15: Yayın

Sheet 02_KONTROL_LISTESI
A1: NİHAİ KONTROL LİSTESİ — KANITSIZ GEÇİŞ YOK
A3: Kontrol No | B3: Kontrol | C3: Beklenen | D3: Zorunlu Kapı? | E3: Sonuç
A4: K01 | B4: Kullanıcının açık talebi öncelikli mi? | C4: Evet | D4: EVET
A5: K02 | B5: Mevcut yapı, formüller ve tek gerçek kaynak korunuyor mu? | C5: Evet, değişiklik gerekçeli | D5: EVET
A6: K03 | B6: Üst aşama HATA ise alt aşama GEÇTİ engelleniyor mu? | C6: Evet | D6: EVET
A7: K04 | B7: Kanıt fiziksel çıktı ve içerik doğrulaması içeriyor mu? | C7: Evet | D7: EVET
A8: K05 | B8: Excel GUI erişimi olmadan kullanıcı görünümü GEÇTİ yazılıyor mu? | C8: Hayır | D8: EVET
A9: K06 | B9: NİHAİ yalnız GEÇTİ / gerekçeli UYGULANMAZ ile mi? | C9: Evet | D9: EVET
A10: K07 | B10: Ekonomik fiyat savunusu pazar doğrulamasından ayrılmış mı? | C10: Evet | D10: EVET
A11: K08 | B11: Prestij için gereksiz modül var mı? | C11: Hayır | D11: HAYIR
A12: K09 | B12: Excel sınırları açık mı? | C12: Evet | D12: EVET
A13: K10 | B13: Teknik kaynak korunuyor mu? | C13: Evet | D13: EVET
A14: K11 | B14: Kullanıcıya görünen tüm metinler Türkçe mi? | C14: Evet | D14: EVET
A15: K12 | B15: Her kullanıcı sayfasında üst başlık var mı? | C15: Evet | D15: EVET
... A34: K31 | B34: Premium vitrin, altyapı kadar güçlü ve satış fiyatını destekleyecek seviyede mi? | C34: Evet | D34: EVET

Sheet 03_GORSEL_TASARIM
A1: GÖRSEL TASARIM VE PREMIUM EXCEL STANDARDI
A3: Alan | B3: Zorunlu Kural | C3: Uygulama | D3: Yasak | E3: Kontrol | F3: Durum
A4: Sayfa başlığı | B4: Her kullanıcı sayfasının en üstünde tek ve açık sayfa başlığı | C4: A1'den başlayan koyu lacivert başlık bandı | D4: Başlıksız sayfa | E4: Başlık kapsama = %100 | F4: ZORUNLU
A5: Sekme renkleri | B5: Sayfalar işlevine göre renk kodlanır | C5: Girdi=mavi, hesap=gri, rapor=lacivert, kontrol=kırmızı, kılavuz=altın | D5: Rastgele renk | E5: Renk semantiği tutarlı | F5: ZORUNLU
A6: Kolon düzeni | B6: Veri blokları bitişik kolonlarda ilerler | C6: Gereksiz boş kolon bırakma; yalnız gerçek bölüm ayrımı varsa kontrollü boşluk | D6: A:C veri, D boş, E:F veri gibi parçalı yapı | E6: Boş kolon taraması | F6: ZORUNLU
A7: Girdi hücreleri | B7: Kullanıcının değiştireceği alan açıkça görünür | C7: Açık sarı dolgu + mavi yazı | D7: Formülle aynı görünüm | E7: Girdi/formül ayrımı | F7: ZORUNLU
A8: Formüller | B8: Hesap hücreleri kullanıcı girdisinden ayrılır | C8: Siyah yazı; sayfalar arası bağlantı yeşil yazı | D8: Hard-code gizleme | E8: Formül sınıfı kontrolü | F8: ZORUNLU
A9: Grafik sayısı | B9: Yönetici ekranında en fazla 3 ana karar grafiği | C9: Trend, karşılaştırma, köprü/dağılım; iş kararına bağlı | D9: Grafik kalabalığı | E9: Grafik başına karar sorusu | F9: ZORUNLU
A10: Grafik stili | B10: Kurumsal ve yüksek okunabilirlik | C10: Beyaz zemin, ince gridline, tek vurgu rengi, açık birim/başlık | D10: 3B, gölge, neon, gökkuşağı renkleri | E10: Görsel inceleme | F10: ZORUNLU
A11: Grafik başlığı | B11: Grafik 'neyi' değil 'ne anlama geldiğini' söyler | C11: Örn: 'Nakit 2028'de kritik eşiğin altına iniyor' | D11: 'Nakit Grafiği' gibi anlamsız başlık | E11: Başlık karar testi | F11: ZORUNLU
A12: Birimler | B12: Tüm finansal görsellerde birim açık | C12: TL, bin TL, milyon TL, %, gün, x | D12: Birim belirsizliği | E12: Birim kapsama %100 | F12: ZORUNLU
A13: Sıfır/negatif | B13: Finansal format standardı | C13: Sıfır='-', negatif kırmızı parantez | D13: -500 veya 0,00 kalabalığı | E13: Format kontrolü | F13: ZORUNLU
A14: Yazı tipi | B14: Tek aile | C14: Aptos veya Segoe UI | D14: Karışık font | E14: Tek font kontrolü | F14: ZORUNLU
... A22: Premium vitrin | B22: Görsel kalite ürün değerinin zorunlu parçasıdır | C22: Kaliteli grafik, gerçek KPI kartı, finansal hiyerarşi, tab rengi, fonksiyonel navigasyon | D22: Sadece doğru hesap yapıp çıplak/varsayılan Excel görünümü bırakmak | E22: Görsel release incelemesi | F22: ZORUNLU

Sheet 04_MUHASEBE_THP
A1: TÜRKİYE MUHASEBE VE TEKDÜZEN HESAP PLANI STANDARDI
A3: Konu | B3: Zorunlu Standart | C3: Örnek Türkçe Ad | D3: THP / Mantık | E3: Hata Riski | F3: Kontrol
A4: Dil | B4: Kullanıcıya görünen finansal terimler Türkçe | C4: Hasılat, Satışların Maliyeti, Brüt Kâr, Faaliyet Giderleri | D4: Türk işletme kullanımına uygun | E4: İngilizce jargon | F4: Terminoloji taraması
A5: Gelir Tablosu | B5: Türk sunum sırası kullanılır | C5: Net Satışlar → Satışların Maliyeti → Brüt Kâr → Faaliyet Giderleri → Faaliyet Kârı | D5: 600/610/611; 620-623; 63x | E5: Yanlış sınıflama | F5: Hesap eşleme
A6: Bilanço | B6: Dönen/Duran Varlık ve Kısa/Uzun Vadeli Yükümlülük ayrımı | C6: Hazır Değerler, Ticari Alacaklar, Stoklar, Mali Borçlar | D6: 1xx / 2xx / 3xx / 4xx / 5xx | E6: Vade sınıfı hatası | F6: Bilanço eşitliği
A7: Nakit Akışı | B7: İşletme/Yatırım/Finansman nakit akışları ayrılır | C7: Faaliyetlerden Nakit, Yatırım Harcamaları, Finansman Nakit Akışı | D7: Dolaylı/doğrudan yöntem açık seçilir | E7: Kâr = nakit sanılması | F7: Nakit devri
A8: Ticari Alacaklar | B8: Cari ve vade mantığı korunur | C8: 120 Alıcılar | D8: 120 | E8: Tahakkuk/nakit karışması | F8: Alacak devir kontrolü
A9: Ticari Borçlar | B9: Tedarikçi borcu ayrı izlenir | C9: 320 Satıcılar | D9: 320 | E9: Gider/ödeme karışması | F9: Borç devir kontrolü
A10: Kasa/Banka | B10: Hazır değerler ayrı izlenir | C10: 100 Kasa, 102 Bankalar | D10: 100 / 102 | E10: Virmanla toplam nakdin değişmesi | F10: Virman değişmezi
A11: Stok | B11: Dikeye uygun stok türü | C11: 150 İlk Madde ve Malzeme, 153 Ticari Mallar | D11: 15x | E11: Maliyet ve stok hareketinin kopması | F11: Stok devri
A12: Maddi Duran Varlık | B12: Yatırım harcaması ve amortisman bağlantılı | C12: 253 Tesis Makine Cihazlar, 255 Demirbaşlar, 257 Birikmiş Amortismanlar | D12: 25x | E12: Yatırım/gider karışması | F12: Net defter değeri devri
A13: Mali Borçlar | B13: Kısa/uzun vadeli borç ayrımı | C13: 300 Banka Kredileri / 400 Banka Kredileri | D13: 300 / 400 | E13: Vade sınıfı yanlış | F13: Borç devri
A14: Özkaynak | B14: Sermaye ve geçmiş yıl kârları ayrı | C14: 500 Sermaye, 570 Geçmiş Yıllar Kârları, 590 Dönem Net Kârı | D14: 5xx | E14: Net kâr bağının kopması | F14: Özkaynak devri
... A18: İstisna | B18: TFRS özel ürün varsa fark açık yazılır | C18: Tekdüzen raporlama ≠ TFRS finansal tablo sunumu | D18: Amaç belirtilir | E18: Standartları karıştırma | F18: Model amacı kontrolü

Sheet 05_KARAR_SATIS
A1: KARAR, GÜVEN VE SATIŞA HAZIRLIK STANDARDI
A3: Alan | B3: Müşteri Sorusu | C3: Zorunlu Ürün Davranışı | D3: Kanıt | E3: Başarısızlık Durumu | F3: Kapı
A4: 5 saniye | B4: Bu ürün neyi çözüyor? | C4: İlk ekranda hedef kullanıcı + pahalı problem + sonuç görünür | D4: Başlık + alt mesaj + gerçek ekran | E4: Ürün yalnız teknik isim | F4: HATA
A5: Acı | B5: Sorun bana neye mal oluyor? | C5: Mümkünse müşterinin kendi verisiyle parasal/zaman etkisi hesaplanır | D5: ROI/acı hesaplama yöntemi | E5: Uydurma tasarruf | F5: HATA
A6: Karar | B6: Bu bilgiyle ne yapacağım? | C6: Her kritik KPI aksiyona bağlanır | D6: KARAR_KUYRUGU | E6: Sadece rapor | F6: HATA
A7: Güven | B7: Bu sayıya neden inanayım? | C7: Kaynak, formül mantığı, kontrol ve son doğrulama görünür | D7: Kontroller + kaynak izi + sürüm | E7: Prestij kelimesi | F7: HATA
A8: Referans | B8: Müşteri yorumu yoksa ne göstereceğim? | C8: Önce/Sonra + Karar Vakası + Hata Önleme Vakası üretilir | D8: Demo/örnek çıktı | E8: Kanıtsız iddia | F8: HATA
A9: Senaryo | B9: Ne olursa işler bozulur? | C9: Baz/Aşağı/Yukarı veya uygun stres senaryosu | D9: Senaryo karşılaştırma | E9: Dekoratif senaryo | F9: HATA
A10: Ters stres | B10: Hangi eşikte karar kırılır? | C10: En az bir kritik sürücü için kırılma eşiği | D10: Kırılma eşiği tablosu | E10: Sadece +/- %10 | F10: UYARI/HATA
A11: Hata tutarlılığı | B11: Formül hata verirse ne olur? | C11: Kontrol GEÇTİ veremez; BLOKE/HATA üretir | D11: Hata taraması | E11: Hata + GEÇTİ birlikte | F11: HATA
A12: Karar motoru | B12: Ne oldu, neden oldu? | C12: Sorun + neden + parasal etki + aksiyon + son tarih | D12: Karar tablosu | E12: Boş sayfa / isim düzeyi modül | F12: HATA
A13: Yönetici özeti | B13: 5 saniyede ne görmeliyim? | C13: Bugün / ne değişti / ne bozulacak / neden / ne yapmalıyım / güven | D13: Yönetici özeti ekranı | E13: KPI kutusu yığını | F13: HATA
A14: Teklif | B14: Neden satın almalıyım? | C14: Dosya özellikleri yerine sonuç ve kaçınılan maliyet sunulur | D14: Ürün sayfası kanıt eşlemesi | E14: Özellik listesiyle satış | F14: HATA
... A19: Pazar kanıtı | B19: Piyasa gerçekten ödüyor mu? | C19: Satış/pilot/LOI/fiyat kabulü olmadan pazar doğrulandı yazılmaz | D19: Gerçek işlem kanıtı | E19: Tahmini talep = satış kabulü | F19: HATA

Sheet KAPAK
A1: KAPAK — Puantaj-Vardiya-Fazla Mesai Kanıt Sistemi
A3: Puantaj-Vardiya-Fazla Mesai Kanıt Sistemi
A4: Personel giriş/çıkış, planlı vardiya ve fazla mesaiyi yasal tavanla karşılaştırır; durum makinesi ve imza kanıt zinciri üretir; UYGUN / SINIR / AŞIM / VERİ YOK kararı verir.
A6: Bu ürün ne sağlar?
A7: • Makrosuz durum makinesi: Taslak → Kontrol → Onay → Arşiv / Red
A8: • Günlük/haftalık fazla mesai + yıllık 270 saat tavan karşılaştırması
A9: • Giriş/çıkış ↔ planlı vardiya ↔ bildirim FM zincir bayrağı
A10: • Geçersiz geçiş ve yetim personel uyarıları
A11: • KANIT_RAPORU — denetçi/SMMM imza alanlı dönem kanıtı
A13: Kimler için?
A14: • İK / bordro — puantaj kapanışı ve tavan kontrolü
A15: • İşveren vekili — UYGUN / SINIR / AŞIM kararı
... A21: Sürüm 1.0.0 | Lisans: Tek kullanıcı | ExcelArşiv

Sheet PERSONEL
A1: PERSONEL — Puantaj-Vardiya-Fazla Mesai Kanıt Sistemi
A3: Personel kartları — her kaydın tek kimliği vardır
A4: Sonraki Kimlik | B4: =pvf_sonrakiKimlik
A5: PersonelId | B5: AdSoyad | C5: Departman | D5: Unvan | E5: HaftalikNormalSaat | F5: YillikMesaiTavan | G5: Aktif | H5: ToplamFm | I5: OrtGunlukFm
A6: PER-00001 | B6: Ayşe Yılmaz | C6: Üretim | D6: Operatör | E6: 45 | F6: 270 | G6: EVET | H6: =IF($A6="","",SUMIF(tblAkis[KaynakPersonelId],$A6,tblAkis[FazlaMesaiSaat])) | I6: =IF($A6="","",IFERROR(AVERAGEIF(tblAkis[KaynakPersonelId],$A6,tblAkis[FazlaMesaiSaat]),0))
A7: PER-00002 | B7: Mehmet Demir | C7: Üretim | D7: Usta | E7: 45 | F7: 270 | G7: EVET | H7: =IF($A7="","",SUMIF(tblAkis[KaynakPersonelId],$A7,tblAkis[FazlaMesaiSaat])) | I7: =IF($A7="","",IFERROR(AVERAGEIF(tblAkis[KaynakPersonelId],$A7,tblAkis[FazlaMesaiSaat]),0))
A8: PER-00003 | B8: Zeynep Kaya | C8: Lojistik | D8: Depocu | E8: 45 | F8: 270 | G8: EVET | H8: =IF($A8="","",SUMIF(tblAkis[KaynakPersonelId],$A8,tblAkis[FazlaMesaiSaat])) | I8: =IF($A8="","",IFERROR(AVERAGEIF(tblAkis[KaynakPersonelId],$A8,tblAkis[FazlaMesaiSaat]),0))
A9: PER-00004 | B9: Ali Çelik | C9: Lojistik | D9: Şoför | E9: 45 | F9: 270 | G9: EVET | H9: =IF($A9="","",SUMIF(tblAkis[KaynakPersonelId],$A9,tblAkis[FazlaMesaiSaat])) | I9: =IF($A9="","",IFERROR(AVERAGEIF(tblAkis[KaynakPersonelId],$A9,tblAkis[FazlaMesaiSaat]),0))
A10: PER-00005 | B10: Elif Arslan | C10: Satış | D10: Temsilci | E10: 45 | F10: 270 | G10: EVET | H10: =IF($A10="","",SUMIF(tblAkis[KaynakPersonelId],$A10,tblAkis[FazlaMesaiSaat])) | I10: =IF($A10="","",IFERROR(AVERAGEIF(tblAkis[KaynakPersonelId],$A10,tblAkis[FazlaMesaiSaat]),0))
A11: PER-00006 | B11: Can Öztürk | C11: Bakım | D11: Teknisyen | E11: 45 | F11: 270 | G11: EVET | H11: =IF($A11="","",SUMIF(tblAkis[KaynakPersonelId],$A11,tblAkis[FazlaMesaiSaat])) | I11: =IF($A11="","",IFERROR(AVERAGEIF(tblAkis[KaynakPersonelId],$A11,tblAkis[FazlaMesaiSaat]),0))
A12: PER-00007 | B12: Selin Aydın | C12: İdari | D12: Asistan | E12: 45 | F12: 270 | G12: EVET | H12: =IF($A12="","",SUMIF(tblAkis[KaynakPersonelId],$A12,tblAkis[FazlaMesaiSaat])) | I12: =IF($A12="","",IFERROR(AVERAGEIF(tblAkis[KaynakPersonelId],$A12,tblAkis[FazlaMesaiSaat]),0))
A13: PER-00008 | B13: Burak Şahin | C13: Üretim | D13: Operatör | E13: 45 | F13: 270 | G13: EVET | H13: =IF($A13="","",SUMIF(tblAkis[KaynakPersonelId],$A13,tblAkis[FazlaMesaiSaat])) | I13: =IF($A13="","",IFERROR(AVERAGEIF(tblAkis[KaynakPersonelId],$A13,tblAkis[FazlaMesaiSaat]),0))
H14: =IF($A14="","",SUMIF(tblAkis[KaynakPersonelId],$A14,tblAkis[FazlaMesaiSaat])) | I14: =IF($A14="","",IFERROR(AVERAGEIF(tblAkis[KaynakPersonelId],$A14,tblAkis[FazlaMesaiSaat]),0))
H15: =IF($A15="","",SUMIF(tblAkis[KaynakPersonelId],$A15,tblAkis[FazlaMesaiSaat])) | I15: =IF($A15="","",IFERROR(AVERAGEIF(tblAkis[KaynakPersonelId],$A15,tblAkis[FazlaMesaiSaat]),0))
H16: =IF($A16="","",SUMIF(tblAkis[KaynakPersonelId],$A16,tblAkis[FazlaMesaiSaat])) | I16: =IF($A16="","",IFERROR(AVERAGEIF(tblAkis[KaynakPersonelId],$A16,tblAkis[FazlaMesaiSaat]),0))
H17: =IF($A17="","",SUMIF(tblAkis[KaynakPersonelId],$A17,tblAkis[FazlaMesaiSaat])) | I17: =IF($A17="","",IFERROR(AVERAGEIF(tblAkis[KaynakPersonelId],$A17,tblAkis[FazlaMesaiSaat]),0))
H18: =IF($A18="","",SUMIF(tblAkis[KaynakPersonelId],$A18,tblAkis[FazlaMesaiSaat])) | I18: =IF($A18="","",IFERROR(AVERAGEIF(tblAkis[KaynakPersonelId],$A18,tblAkis[FazlaMesaiSaat]),0))
H19: =IF($A19="","",SUMIF(tblAkis[KaynakPersonelId],$A19,tblAkis[FazlaMesaiSaat])) | I19: =IF($A19="","",IFERROR(AVERAGEIF(tblAkis[KaynakPersonelId],$A19,tblAkis[FazlaMesaiSaat]),0))
H20: =IF($A20="","",SUMIF(tblAkis[KaynakPersonelId],$A20,tblAkis[FazlaMesaiSaat])) | I20: =IF($A20="","",IFERROR(AVERAGEIF(tblAkis[KaynakPersonelId],$A20,tblAkis[FazlaMesaiSaat]),0))
H21: =IF($A21="","",SUMIF(tblAkis[KaynakPersonelId],$A21,tblAkis[FazlaMesaiSaat])) | I21: =IF($A21="","",IFERROR(AVERAGEIF(tblAkis[KaynakPersonelId],$A21,tblAkis[FazlaMesaiSaat]),0))
H22: =IF($A22="","",SUMIF(tblAkis[KaynakPersonelId],$A22,tblAkis[FazlaMesaiSaat])) | I22: =IF($A22="","",IFERROR(AVERAGEIF(tblAkis[KaynakPersonelId],$A22,tblAkis[FazlaMesaiSaat]),0))
H23: =IF($A23="","",SUMIF(tblAkis[KaynakPersonelId],$A23,tblAkis[FazlaMesaiSaat])) | I23: =IF($A23="","",IFERROR(AVERAGEIF(tblAkis[KaynakPersonelId],$A23,tblAkis[FazlaMesaiSaat]),0))
H24: =IF($A24="","",SUMIF(tblAkis[KaynakPersonelId],$A24,tblAkis[FazlaMesaiSaat])) | I24: =IF($A24="","",IFERROR(AVERAGEIF(tblAkis[KaynakPersonelId],$A24,tblAkis[FazlaMesaiSaat]),0))
H25: =IF($A25="","",SUMIF(tblAkis[KaynakPersonelId],$A25,tblAkis[FazlaMesaiSaat])) | I25: =IF($A25="","",IFERROR(AVERAGEIF(tblAkis[KaynakPersonelId],$A25,tblAkis[FazlaMesaiSaat]),0))
... H255: =IF($A255="","",SUMIF(tblAkis[KaynakPersonelId],$A255,tblAkis[FazlaMesaiSaat])) | I255: =IF($A255="","",IFERROR(AVERAGEIF(tblAkis[KaynakPersonelId],$A255,tblAkis[FazlaMesaiSaat]),0))

Sheet AKIS
A1: AKIS — Puantaj-Vardiya-Fazla Mesai Kanıt Sistemi
A3: Puantaj satırları — durum makinesi + yetim + geçersiz geçiş + zincir
A5: PuantajId | B5: KaynakPersonelId | C5: Tarih | D5: GirisSaat | E5: CikisSaat | F5: PlanliVardiyaSaat | G5: FazlaMesaiSaat | H5: IzinTuru | I5: OncekiDurum | J5: Durum | K5: ImzaKanit | L5: YorumA | M5: YorumB | N5: SaatUcreti | O5: FiiliSaat | P5: HesaplananFm | Q5: GecikmeGun | R5: YasKova | S5: YetimBayrak | T5: GecisUyarisi | U5: ZincirBayrak | V5: KayitDolu | W5: FmMaliyet
A6: PUA-00001 | B6: PER-00001 | C6: 46243 | D6: 8 | E6: 17 | F6: 8 | G6: 1 | H6: YILLIK | J6: TASLAK | L6: A | M6: Puantaj notu 1 | N6: 130 | O6: =IF($A6="","",MAX(0,$E6-$D6)) | P6: =IF($A6="","",MAX(0,$O6-$F6)) | Q6: =IF($A6="","",IF(OR($J6="ARSIV",$J6="RED"),0,IF($C6="","",raporTarihi-$C6))) | R6: =IF($A6="","",IF($Q6="","",IF($Q6<=pvf_kovaEsik1,"0-7",IF($Q6<=pvf_kovaEsik2,"8-30",IF($Q6<=pvf_kovaEsik3,"31-60","60+"))))) | S6: =IF($A6="","",IF($B6="","YETİM",IF(COUNTIF(tblPersonel[PersonelId],$B6)=0,"YETİM",""))) | T6: =IF(OR($A6="",$I6=""),"",IF(OR($I6&"|"&$J6="",COUNTIF(ListeIzinliGecis,$I6&"|"&$J6)>0),"","GEÇERSİZ GEÇİŞ")) | U6: =IF($A6="","",IF(OR($P6="",$G6=""),"",IF(ABS($G6-$P6)>zincirTolerans,"ZİNCİR KIRIK","OK"))) | V6: =IF($A6="","",1) | W6: =IF($A6="","",$G6*$N6*pvf_mesaiKatsayi)
A7: PUA-00002 | B7: PER-00002 | C7: 46241 | D7: 8 | E7: 16.5 | F7: 8 | G7: 0.5 | H7: MAZERET | I7: TASLAK | J7: KONTROL | L7: B | M7: Puantaj notu 2 | N7: 140 | O7: =IF($A7="","",MAX(0,$E7-$D7)) | P7: =IF($A7="","",MAX(0,$O7-$F7)) | Q7: =IF($A7="","",IF(OR($J7="ARSIV",$J7="RED"),0,IF($C7="","",raporTarihi-$C7))) | R7: =IF($A7="","",IF($Q7="","",IF($Q7<=pvf_kovaEsik1,"0-7",IF($Q7<=pvf_kovaEsik2,"8-30",IF($Q7<=pvf_kovaEsik3,"31-60","60+"))))) | S7: =IF($A7="","",IF($B7="","YETİM",IF(COUNTIF(tblPersonel[PersonelId],$B7)=0,"YETİM",""))) | T7: =IF(OR($A7="",$I7=""),"",IF(OR($I7&"|"&$J7="",COUNTIF(ListeIzinliGecis,$I7&"|"&$J7)>0),"","GEÇERSİZ GEÇİŞ")) | U7: =IF($A7="","",IF(OR($P7="",$G7=""),"",IF(ABS($G7-$P7)>zincirTolerans,"ZİNCİR KIRIK","OK"))) | V7: =IF($A7="","",1) | W7: =IF($A7="","",$G7*$N7*pvf_mesaiKatsayi)
A8: PUA-00003 | B8: PER-00003 | C8: 46239 | D8: 8 | E8: 18 | F8: 8 | G8: 2 | H8: RAPOR | I8: KONTROL | J8: ONAY | K8: İMZA-003 | L8: A | M8: Puantaj notu 3 | N8: 150 | O8: =IF($A8="","",MAX(0,$E8-$D8)) | P8: =IF($A8="","",MAX(0,$O8-$F8)) | Q8: =IF($A8="","",IF(OR($J8="ARSIV",$J8="RED"),0,IF($C8="","",raporTarihi-$C8))) | R8: =IF($A8="","",IF($Q8="","",IF($Q8<=pvf_kovaEsik1,"0-7",IF($Q8<=pvf_kovaEsik2,"8-30",IF($Q8<=pvf_kovaEsik3,"31-60","60+"))))) | S8: =IF($A8="","",IF($B8="","YETİM",IF(COUNTIF(tblPersonel[PersonelId],$B8)=0,"YETİM",""))) | T8: =IF(OR($A8="",$I8=""),"",IF(OR($I8&"|"&$J8="",COUNTIF(ListeIzinliGecis,$I8&"|"&$J8)>0),"","GEÇERSİZ GEÇİŞ")) | U8: =IF($A8="","",IF(OR($P8="",$G8=""),"",IF(ABS($G8-$P8)>zincirTolerans,"ZİNCİR KIRIK","OK"))) | V8: =IF($A8="","",1) | W8: =IF($A8="","",$G8*$N8*pvf_mesaiKatsayi)
A9: PUA-00004 | B9: PER-00004 | C9: 46237 | D9: 8 | E9: 17 | F9: 8 | G9: 1 | H9: UCRETSIZ | I9: ONAY | J9: ARSIV | K9: İMZA-004 | L9: B | M9: Puantaj notu 4 | N9: 160 | O9: =IF($A9="","",MAX(0,$E9-$D9)) | P9: =IF($A9="","",MAX(0,$O9-$F9)) | Q9: =IF($A9="","",IF(OR($J9="ARSIV",$J9="RED"),0,IF($C9="","",raporTarihi-$C9))) | R9: =IF($A9="","",IF($Q9="","",IF($Q9<=pvf_kovaEsik1,"0-7",IF($Q9<=pvf_kovaEsik2,"8-30",IF($Q9<=pvf_kovaEsik3,"31-60","60+"))))) | S9: =IF($A9="","",IF($B9="","YETİM",IF(COUNTIF(tblPersonel[PersonelId],$B9)=0,"YETİM",""))) | T9: =IF(OR($A9="",$I9=""),"",IF(OR($I9&"|"&$J9="",COUNTIF(ListeIzinliGecis,$I9&"|"&$J9)>0),"","GEÇERSİZ GEÇİŞ")) | U9: =IF($A9="","",IF(OR($P9="",$G9=""),"",IF(ABS($G9-$P9)>zincirTolerans,"ZİNCİR KIRIK","OK"))) | V9: =IF($A9="","",1) | W9: =IF($A9="","",$G9*$N9*pvf_mesaiKatsayi)
A10: PUA-00005 | B10: PER-00005 | C10: 46235 | D10: 8 | E10: 16.5 | F10: 8 | G10: 0.5 | H10: YOK | I10: TASLAK | J10: RED | L10: A | M10: Puantaj notu 5 | N10: 120 | O10: =IF($A10="","",MAX(0,$E10-$D10)) | P10: =IF($A10="","",MAX(0,$O10-$F10)) | Q10: =IF($A10="","",IF(OR($J10="ARSIV",$J10="RED"),0,IF($C10="","",raporTarihi-$C10))) | R10: =IF($A10="","",IF($Q10="","",IF($Q10<=pvf_kovaEsik1,"0-7",IF($Q10<=pvf_kovaEsik2,"8-30",IF($Q10<=pvf_kovaEsik3,"31-60","60+"))))) | S10: =IF($A10="","",IF($B10="","YETİM",IF(COUNTIF(tblPersonel[PersonelId],$B10)=0,"YETİM",""))) | T10: =IF(OR($A10="",$I10=""),"",IF(OR($I10&"|"&$J10="",COUNTIF(ListeIzinliGecis,$I10&"|"&$J10)>0),"","GEÇERSİZ GEÇİŞ")) | U10: =IF($A10="","",IF(OR($P10="",$G10=""),"",IF(ABS($G10-$P10)>zincirTolerans,"ZİNCİR KIRIK","OK"))) | V10: =IF($A10="","",1) | W10: =IF($A10="","",$G10*$N10*pvf_mesaiKatsayi)
A11: PUA-00006 | B11: PER-00006 | C11: 46233 | D11: 8 | E11: 18 | F11: 8 | G11: 2 | H11: YILLIK | I11: TASLAK | J11: KONTROL | L11: B | M11: Puantaj notu 6 | N11: 130 | O11: =IF($A11="","",MAX(0,$E11-$D11)) | P11: =IF($A11="","",MAX(0,$O11-$F11)) | Q11: =IF($A11="","",IF(OR($J11="ARSIV",$J11="RED"),0,IF($C11="","",raporTarihi-$C11))) | R11: =IF($A11="","",IF($Q11="","",IF($Q11<=pvf_kovaEsik1,"0-7",IF($Q11<=pvf_kovaEsik2,"8-30",IF($Q11<=pvf_kovaEsik3,"31-60","60+"))))) | S11: =IF($A11="","",IF($B11="","YETİM",IF(COUNTIF(tblPersonel[PersonelId],$B11)=0,"YETİM",""))) | T11: =IF(OR($A11="",$I11=""),"",IF(OR($I11&"|"&$J11="",COUNTIF(ListeIzinliGecis,$I11&"|"&$J11)>0),"","GEÇERSİZ GEÇİŞ")) | U11: =IF($A11="","",IF(OR($P11="",$G11=""),"",IF(ABS($G11-$P11)>zincirTolerans,"ZİNCİR KIRIK","OK"))) | V11: =IF($A11="","",1) | W11: =IF($A11="","",$G11*$N11*pvf_mesaiKatsayi)
A12: PUA-00007 | B12: PER-00007 | C12: 46231 | D12: 8 | E12: 17 | F12: 8 | G12: 1 | H12: MAZERET | I12: KONTROL | J12: ONAY | K12: İMZA-007 | L12: A | M12: Puantaj notu 7 | N12: 140 | O12: =IF($A12="","",MAX(0,$E12-$D12)) | P12: =IF($A12="","",MAX(0,$O12-$F12)) | Q12: =IF($A12="","",IF(OR($J12="ARSIV",$J12="RED"),0,IF($C12="","",raporTarihi-$C12))) | R12: =IF($A12="","",IF($Q12="","",IF($Q12<=pvf_kovaEsik1,"0-7",IF($Q12<=pvf_kovaEsik2,"8-30",IF($Q12<=pvf_kovaEsik3,"31-60","60+"))))) | S12: =IF($A12="","",IF($B12="","YETİM",IF(COUNTIF(tblPersonel[PersonelId],$B12)=0,"YETİM",""))) | T12: =IF(OR($A12="",$I12=""),"",IF(OR($I12&"|"&$J12="",COUNTIF(ListeIzinliGecis,$I12&"|"&$J12)>0),"","GEÇERSİZ GEÇİŞ")) | U12: =IF($A12="","",IF(OR($P12="",$G12=""),"",IF(ABS($G12-$P12)>zincirTolerans,"ZİNCİR KIRIK","OK"))) | V12: =IF($A12="","",1) | W12: =IF($A12="","",$G12*$N12*pvf_mesaiKatsayi)
A13: PUA-00008 | B13: PER-00008 | C13: 46229 | D13: 8 | E13: 16.5 | F13: 8 | G13: 0.5 | H13: RAPOR | I13: TASLAK | J13: TASLAK | L13: B | M13: Puantaj notu 8 | N13: 150 | O13: =IF($A13="","",MAX(0,$E13-$D13)) | P13: =IF($A13="","",MAX(0,$O13-$F13)) | Q13: =IF($A13="","",IF(OR($J13="ARSIV",$J13="RED"),0,IF($C13="","",raporTarihi-$C13))) | R13: =IF($A13="","",IF($Q13="","",IF($Q13<=pvf_kovaEsik1,"0-7",IF($Q13<=pvf_kovaEsik2,"8-30",IF($Q13<=pvf_kovaEsik3,"31-60","60+"))))) | S13: =IF($A13="","",IF($B13="","YETİM",IF(COUNTIF(tblPersonel[PersonelId],$B13)=0,"YETİM",""))) | T13: =IF(OR($A13="",$I13=""),"",IF(OR($I13&"|"&$J13="",COUNTIF(ListeIzinliGecis,$I13&"|"&$J13)>0),"","GEÇERSİZ GEÇİŞ")) | U13: =IF($A13="","",IF(OR($P13="",$G13=""),"",IF(ABS($G13-$P13)>zincirTolerans,"ZİNCİR KIRIK","OK"))) | V13: =IF($A13="","",1) | W13: =IF($A13="","",$G13*$N13*pvf_mesaiKatsayi)
A14: PUA-00009 | B14: PER-00001 | C14: 46227 | D14: 8 | E14: 18 | F14: 8 | G14: 2 | H14: UCRETSIZ | J14: TASLAK | L14: A | M14: Puantaj notu 9 | N14: 160 | O14: =IF($A14="","",MAX(0,$E14-$D14)) | P14: =IF($A14="","",MAX(0,$O14-$F14)) | Q14: =IF($A14="","",IF(OR($J14="ARSIV",$J14="RED"),0,IF($C14="","",raporTarihi-$C14))) | R14: =IF($A14="","",IF($Q14="","",IF($Q14<=pvf_kovaEsik1,"0-7",IF($Q14<=pvf_kovaEsik2,"8-30",IF($Q14<=pvf_kovaEsik3,"31-60","60+"))))) | S14: =IF($A14="","",IF($B14="","YETİM",IF(COUNTIF(tblPersonel[PersonelId],$B14)=0,"YETİM",""))) | T14: =IF(OR($A14="",$I14=""),"",IF(OR($I14&"|"&$J14="",COUNTIF(ListeIzinliGecis,$I14&"|"&$J14)>0),"","GEÇERSİZ GEÇİŞ")) | U14: =IF($A14="","",IF(OR($P14="",$G14=""),"",IF(ABS($G14-$P14)>zincirTolerans,"ZİNCİR KIRIK","OK"))) | V14: =IF($A14="","",1) | W14: =IF($A14="","",$G14*$N14*pvf_mesaiKatsayi)
A15: PUA-00010 | B15: PER-00002 | C15: 46225 | D15: 8 | E15: 17 | F15: 8 | G15: 1 | H15: YOK | I15: TASLAK | J15: KONTROL | L15: B | M15: Puantaj notu 10 | N15: 120 | O15: =IF($A15="","",MAX(0,$E15-$D15)) | P15: =IF($A15="","",MAX(0,$O15-$F15)) | Q15: =IF($A15="","",IF(OR($J15="ARSIV",$J15="RED"),0,IF($C15="","",raporTarihi-$C15))) | R15: =IF($A15="","",IF($Q15="","",IF($Q15<=pvf_kovaEsik1,"0-7",IF($Q15<=pvf_kovaEsik2,"8-30",IF($Q15<=pvf_kovaEsik3,"31-60","60+"))))) | S15: =IF($A15="","",IF($B15="","YETİM",IF(COUNTIF(tblPersonel[PersonelId],$B15)=0,"YETİM",""))) | T15: =IF(OR($A15="",$I15=""),"",IF(OR($I15&"|"&$J15="",COUNTIF(ListeIzinliGecis,$I15&"|"&$J15)>0),"","GEÇERSİZ GEÇİŞ")) | U15: =IF($A15="","",IF(OR($P15="",$G15=""),"",IF(ABS($G15-$P15)>zincirTolerans,"ZİNCİR KIRIK","OK"))) | V15: =IF($A15="","",1) | W15: =IF($A15="","",$G15*$N15*pvf_mesaiKatsayi)
A16: PUA-00011 | B16: PER-00003 | C16: 46223 | D16: 8 | E16: 16.5 | F16: 8 | G16: 0.5 | H16: YILLIK | I16: KONTROL | J16: ONAY | K16: İMZA-011 | L16: A | M16: Puantaj notu 11 | N16: 130 | O16: =IF($A16="","",MAX(0,$E16-$D16)) | P16: =IF($A16="","",MAX(0,$O16-$F16)) | Q16: =IF($A16="","",IF(OR($J16="ARSIV",$J16="RED"),0,IF($C16="","",raporTarihi-$C16))) | R16: =IF($A16="","",IF($Q16="","",IF($Q16<=pvf_kovaEsik1,"0-7",IF($Q16<=pvf_kovaEsik2,"8-30",IF($Q16<=pvf_kovaEsik3,"31-60","60+"))))) | S16: =IF($A16="","",IF($B16="","YETİM",IF(COUNTIF(tblPersonel[PersonelId],$B16)=0,"YETİM",""))) | T16: =IF(OR($A16="",$I16=""),"",IF(OR($I16&"|"&$J16="",COUNTIF(ListeIzinliGecis,$I16&"|"&$J16)>0),"","GEÇERSİZ GEÇİŞ")) | U16: =IF($A16="","",IF(OR($P16="",$G16=""),"",IF(ABS($G16-$P16)>zincirTolerans,"ZİNCİR KIRIK","OK"))) | V16: =IF($A16="","",1) | W16: =IF($A16="","",$G16*$N16*pvf_mesaiKatsayi)
A17: PUA-00012 | B17: PER-00004 | C17: 46221 | D17: 8 | E17: 19.5 | F17: 8 | G17: 3.5 | H17: MAZERET | I17: ONAY | J17: ARSIV | K17: İMZA-012 | L17: B | M17: Puantaj notu 12 | N17: 140 | O17: =IF($A17="","",MAX(0,$E17-$D17)) | P17: =IF($A17="","",MAX(0,$O17-$F17)) | Q17: =IF($A17="","",IF(OR($J17="ARSIV",$J17="RED"),0,IF($C17="","",raporTarihi-$C17))) | R17: =IF($A17="","",IF($Q17="","",IF($Q17<=pvf_kovaEsik1,"0-7",IF($Q17<=pvf_kovaEsik2,"8-30",IF($Q17<=pvf_kovaEsik3,"31-60","60+"))))) | S17: =IF($A17="","",IF($B17="","YETİM",IF(COUNTIF(tblPersonel[PersonelId],$B17)=0,"YETİM",""))) | T17: =IF(OR($A17="",$I17=""),"",IF(OR($I17&"|"&$J17="",COUNTIF(ListeIzinliGecis,$I17&"|"&$J17)>0),"","GEÇERSİZ GEÇİŞ")) | U17: =IF($A17="","",IF(OR($P17="",$G17=""),"",IF(ABS($G17-$P17)>zincirTolerans,"ZİNCİR KIRIK","OK"))) | V17: =IF($A17="","",1) | W17: =IF($A17="","",$G17*$N17*pvf_mesaiKatsayi)
A18: PUA-00013 | B18: PER-00005 | C18: 46219 | D18: 8 | E18: 17 | F18: 8 | G18: 1 | H18: RAPOR | I18: TASLAK | J18: RED | L18: A | M18: Puantaj notu 13 | N18: 150 | O18: =IF($A18="","",MAX(0,$E18-$D18)) | P18: =IF($A18="","",MAX(0,$O18-$F18)) | Q18: =IF($A18="","",IF(OR($J18="ARSIV",$J18="RED"),0,IF($C18="","",raporTarihi-$C18))) | R18: =IF($A18="","",IF($Q18="","",IF($Q18<=pvf_kovaEsik1,"0-7",IF($Q18<=pvf_kovaEsik2,"8-30",IF($Q18<=pvf_kovaEsik3,"31-60","60+"))))) | S18: =IF($A18="","",IF($B18="","YETİM",IF(COUNTIF(tblPersonel[PersonelId],$B18)=0,"YETİM",""))) | T18: =IF(OR($A18="",$I18=""),"",IF(OR($I18&"|"&$J18="",COUNTIF(ListeIzinliGecis,$I18&"|"&$J18)>0),"","GEÇERSİZ GEÇİŞ")) | U18: =IF($A18="","",IF(OR($P18="",$G18=""),"",IF(ABS($G18-$P18)>zincirTolerans,"ZİNCİR KIRIK","OK"))) | V18: =IF($A18="","",1) | W18: =IF($A18="","",$G18*$N18*pvf_mesaiKatsayi)
A19: PUA-00014 | B19: PER-00006 | C19: 46217 | D19: 8 | E19: 16.5 | F19: 8 | G19: 0.5 | H19: UCRETSIZ | I19: TASLAK | J19: KONTROL | L19: B | M19: Puantaj notu 14 | N19: 160 | O19: =IF($A19="","",MAX(0,$E19-$D19)) | P19: =IF($A19="","",MAX(0,$O19-$F19)) | Q19: =IF($A19="","",IF(OR($J19="ARSIV",$J19="RED"),0,IF($C19="","",raporTarihi-$C19))) | R19: =IF($A19="","",IF($Q19="","",IF($Q19<=pvf_kovaEsik1,"0-7",IF($Q19<=pvf_kovaEsik2,"8-30",IF($Q19<=pvf_kovaEsik3,"31-60","60+"))))) | S19: =IF($A19="","",IF($B19="","YETİM",IF(COUNTIF(tblPersonel[PersonelId],$B19)=0,"YETİM",""))) | T19: =IF(OR($A19="",$I19=""),"",IF(OR($I19&"|"&$J19="",COUNTIF(ListeIzinliGecis,$I19&"|"&$J19)>0),"","GEÇERSİZ GEÇİŞ")) | U19: =IF($A19="","",IF(OR($P19="",$G19=""),"",IF(ABS($G19-$P19)>zincirTolerans,"ZİNCİR KIRIK","OK"))) | V19: =IF($A19="","",1) | W19: =IF($A19="","",$G19*$N19*pvf_mesaiKatsayi)
A20: PUA-00015 | B20: PER-00007 | C20: 46215 | D20: 8 | E20: 20 | F20: 8 | G20: 4.5 | H20: YOK | I20: KONTROL | J20: ONAY | K20: İMZA-015 | L20: A | M20: Puantaj notu 15 | N20: 120 | O20: =IF($A20="","",MAX(0,$E20-$D20)) | P20: =IF($A20="","",MAX(0,$O20-$F20)) | Q20: =IF($A20="","",IF(OR($J20="ARSIV",$J20="RED"),0,IF($C20="","",raporTarihi-$C20))) | R20: =IF($A20="","",IF($Q20="","",IF($Q20<=pvf_kovaEsik1,"0-7",IF($Q20<=pvf_kovaEsik2,"8-30",IF($Q20<=pvf_kovaEsik3,"31-60","60+"))))) | S20: =IF($A20="","",IF($B20="","YETİM",IF(COUNTIF(tblPersonel[PersonelId],$B20)=0,"YETİM",""))) | T20: =IF(OR($A20="",$I20=""),"",IF(OR($I20&"|"&$J20="",COUNTIF(ListeIzinliGecis,$I20&"|"&$J20)>0),"","GEÇERSİZ GEÇİŞ")) | U20: =IF($A20="","",IF(OR($P20="",$G20=""),"",IF(ABS($G20-$P20)>zincirTolerans,"ZİNCİR KIRIK","OK"))) | V20: =IF($A20="","",1) | W20: =IF($A20="","",$G20*$N20*pvf_mesaiKatsayi)
A21: PUA-00016 | B21: PER-00008 | C21: 46213 | D21: 8 | E21: 17 | F21: 8 | G21: 1 | H21: YILLIK | I21: TASLAK | J21: TASLAK | L21: B | M21: Puantaj notu 16 | N21: 130 | O21: =IF($A21="","",MAX(0,$E21-$D21)) | P21: =IF($A21="","",MAX(0,$O21-$F21)) | Q21: =IF($A21="","",IF(OR($J21="ARSIV",$J21="RED"),0,IF($C21="","",raporTarihi-$C21))) | R21: =IF($A21="","",IF($Q21="","",IF($Q21<=pvf_kovaEsik1,"0-7",IF($Q21<=pvf_kovaEsik2,"8-30",IF($Q21<=pvf_kovaEsik3,"31-60","60+"))))) | S21: =IF($A21="","",IF($B21="","YETİM",IF(COUNTIF(tblPersonel[PersonelId],$B21)=0,"YETİM",""))) | T21: =IF(OR($A21="",$I21=""),"",IF(OR($I21&"|"&$J21="",COUNTIF(ListeIzinliGecis,$I21&"|"&$J21)>0),"","GEÇERSİZ GEÇİŞ")) | U21: =IF($A21="","",IF(OR($P21="",$G21=""),"",IF(ABS($G21-$P21)>zincirTolerans,"ZİNCİR KIRIK","OK"))) | V21: =IF($A21="","",1) | W21: =IF($A21="","",$G21*$N21*pvf_mesaiKatsayi)
A22: PUA-00017 | B22: PER-00001 | C22: 46211 | D22: 8 | E22: 16.5 | F22: 8 | G22: 0.5 | H22: MAZERET | J22: TASLAK | L22: A | M22: Puantaj notu 17 | N22: 140 | O22: =IF($A22="","",MAX(0,$E22-$D22)) | P22: =IF($A22="","",MAX(0,$O22-$F22)) | Q22: =IF($A22="","",IF(OR($J22="ARSIV",$J22="RED"),0,IF($C22="","",raporTarihi-$C22))) | R22: =IF($A22="","",IF($Q22="","",IF($Q22<=pvf_kovaEsik1,"0-7",IF($Q22<=pvf_kovaEsik2,"8-30",IF($Q22<=pvf_kovaEsik3,"31-60","60+"))))) | S22: =IF($A22="","",IF($B22="","YETİM",IF(COUNTIF(tblPersonel[PersonelId],$B22)=0,"YETİM",""))) | T22: =IF(OR($A22="",$I22=""),"",IF(OR($I22&"|"&$J22="",COUNTIF(ListeIzinliGecis,$I22&"|"&$J22)>0),"","GEÇERSİZ GEÇİŞ")) | U22: =IF($A22="","",IF(OR($P22="",$G22=""),"",IF(ABS($G22-$P22)>zincirTolerans,"ZİNCİR KIRIK","OK"))) | V22: =IF($A22="","",1) | W22: =IF($A22="","",$G22*$N22*pvf_mesaiKatsayi)
A23: PUA-00018 | B23: PER-00002 | C23: 46209 | D23: 8 | E23: 18 | F23: 8 | G23: 2 | H23: RAPOR | I23: TASLAK | J23: ONAY | K23: İMZA-018 | L23: B | M23: Puantaj notu 18 | N23: 150 | O23: =IF($A23="","",MAX(0,$E23-$D23)) | P23: =IF($A23="","",MAX(0,$O23-$F23)) | Q23: =IF($A23="","",IF(OR($J23="ARSIV",$J23="RED"),0,IF($C23="","",raporTarihi-$C23))) | R23: =IF($A23="","",IF($Q23="","",IF($Q23<=pvf_kovaEsik1,"0-7",IF($Q23<=pvf_kovaEsik2,"8-30",IF($Q23<=pvf_kovaEsik3,"31-60","60+"))))) | S23: =IF($A23="","",IF($B23="","YETİM",IF(COUNTIF(tblPersonel[PersonelId],$B23)=0,"YETİM",""))) | T23: =IF(OR($A23="",$I23=""),"",IF(OR($I23&"|"&$J23="",COUNTIF(ListeIzinliGecis,$I23&"|"&$J23)>0),"","GEÇERSİZ GEÇİŞ")) | U23: =IF($A23="","",IF(OR($P23="",$G23=""),"",IF(ABS($G23-$P23)>zincirTolerans,"ZİNCİR KIRIK","OK"))) | V23: =IF($A23="","",1) | W23: =IF($A23="","",$G23*$N23*pvf_mesaiKatsayi)
A24: PUA-00019 | B24: PER-00003 | C24: 46207 | D24: 8 | E24: 18.5 | F24: 8 | G24: 2.5 | H24: UCRETSIZ | I24: KONTROL | J24: ONAY | K24: İMZA-019 | L24: A | M24: Puantaj notu 19 | N24: 160 | O24: =IF($A24="","",MAX(0,$E24-$D24)) | P24: =IF($A24="","",MAX(0,$O24-$F24)) | Q24: =IF($A24="","",IF(OR($J24="ARSIV",$J24="RED"),0,IF($C24="","",raporTarihi-$C24))) | R24: =IF($A24="","",IF($Q24="","",IF($Q24<=pvf_kovaEsik1,"0-7",IF($Q24<=pvf_kovaEsik2,"8-30",IF($Q24<=pvf_kovaEsik3,"31-60","60+"))))) | S24: =IF($A24="","",IF($B24="","YETİM",IF(COUNTIF(tblPersonel[PersonelId],$B24)=0,"YETİM",""))) | T24: =IF(OR($A24="",$I24=""),"",IF(OR($I24&"|"&$J24="",COUNTIF(ListeIzinliGecis,$I24&"|"&$J24)>0),"","GEÇERSİZ GEÇİŞ")) | U24: =IF($A24="","",IF(OR($P24="",$G24=""),"",IF(ABS($G24-$P24)>zincirTolerans,"ZİNCİR KIRIK","OK"))) | V24: =IF($A24="","",1) | W24: =IF($A24="","",$G24*$N24*pvf_mesaiKatsayi)
A25: PUA-00020 | B25: PER-00004 | C25: 46205 | D25: 8 | E25: 16.5 | F25: 8 | G25: 0.5 | H25: YOK | I25: ONAY | J25: TASLAK | L25: B | M25: Puantaj notu 20 | N25: 120 | O25: =IF($A25="","",MAX(0,$E25-$D25)) | P25: =IF($A25="","",MAX(0,$O25-$F25)) | Q25: =IF($A25="","",IF(OR($J25="ARSIV",$J25="RED"),0,IF($C25="","",raporTarihi-$C25))) | R25: =IF($A25="","",IF($Q25="","",IF($Q25<=pvf_kovaEsik1,"0-7",IF($Q25<=pvf_kovaEsik2,"8-30",IF($Q25<=pvf_kovaEsik3,"31-60","60+"))))) | S25: =IF($A25="","",IF($B25="","YETİM",IF(COUNTIF(tblPersonel[PersonelId],$B25)=0,"YETİM",""))) | T25: =IF(OR($A25="",$I25=""),"",IF(OR($I25&"|"&$J25="",COUNTIF(ListeIzinliGecis,$I25&"|"&$J25)>0),"","GEÇERSİZ GEÇİŞ")) | U25: =IF($A25="","",IF(OR($P25="",$G25=""),"",IF(ABS($G25-$P25)>zincirTolerans,"ZİNCİR KIRIK","OK"))) | V25: =IF($A25="","",1) | W25: =IF($A25="","",$G25*$N25*pvf_mesaiKatsayi)
A26: PUA-00021 | B26: PER-00005 | C26: 46203 | D26: 8 | E26: 18 | F26: 8 | G26: 2 | H26: YILLIK | I26: TASLAK | J26: RED | L26: A | M26: Puantaj notu 21 | N26: 130 | O26: =IF($A26="","",MAX(0,$E26-$D26)) | P26: =IF($A26="","",MAX(0,$O26-$F26)) | Q26: =IF($A26="","",IF(OR($J26="ARSIV",$J26="RED"),0,IF($C26="","",raporTarihi-$C26))) | R26: =IF($A26="","",IF($Q26="","",IF($Q26<=pvf_kovaEsik1,"0-7",IF($Q26<=pvf_kovaEsik2,"8-30",IF($Q26<=pvf_kovaEsik3,"31-60","60+"))))) | S26: =IF($A26="","",IF($B26="","YETİM",IF(COUNTIF(tblPersonel[PersonelId],$B26)=0,"YETİM",""))) | T26: =IF(OR($A26="",$I26=""),"",IF(OR($I26&"|"&$J26="",COUNTIF(ListeIzinliGecis,$I26&"|"&$J26)>0),"","GEÇERSİZ GEÇİŞ")) | U26: =IF($A26="","",IF(OR($P26="",$G26=""),"",IF(ABS($G26-$P26)>zincirTolerans,"ZİNCİR KIRIK","OK"))) | V26: =IF($A26="","",1) | W26: =IF($A26="","",$G26*$N26*pvf_mesaiKatsayi)
A27: PUA-00022 | C27: 46201 | D27: 8 | E27: 17 | F27: 8 | G27: 1 | H27: MAZERET | I27: TASLAK | J27: KONTROL | L27: B | M27: Puantaj notu 22 | N27: 140 | O27: =IF($A27="","",MAX(0,$E27-$D27)) | P27: =IF($A27="","",MAX(0,$O27-$F27)) | Q27: =IF($A27="","",IF(OR($J27="ARSIV",$J27="RED"),0,IF($C27="","",raporTarihi-$C27))) | R27: =IF($A27="","",IF($Q27="","",IF($Q27<=pvf_kovaEsik1,"0-7",IF($Q27<=pvf_kovaEsik2,"8-30",IF($Q27<=pvf_kovaEsik3,"31-60","60+"))))) | S27: =IF($A27="","",IF($B27="","YETİM",IF(COUNTIF(tblPersonel[PersonelId],$B27)=0,"YETİM",""))) | T27: =IF(OR($A27="",$I27=""),"",IF(OR($I27&"|"&$J27="",COUNTIF(ListeIzinliGecis,$I27&"|"&$J27)>0),"","GEÇERSİZ GEÇİŞ")) | U27: =IF($A27="","",IF(OR($P27="",$G27=""),"",IF(ABS($G27-$P27)>zincirTolerans,"ZİNCİR KIRIK","OK"))) | V27: =IF($A27="","",1) | W27: =IF($A27="","",$G27*$N27*pvf_mesaiKatsayi)
A28: PUA-00023 | B28: PER-00007 | C28: 46244 | D28: 8 | E28: 16.5 | F28: 8 | G28: 0.5 | H28: RAPOR | I28: KONTROL | J28: ONAY | K28: İMZA-023 | L28: A | M28: Puantaj notu 23 | N28: 150 | O28: =IF($A28="","",MAX(0,$E28-$D28)) | P28: =IF($A28="","",MAX(0,$O28-$F28)) | Q28: =IF($A28="","",IF(OR($J28="ARSIV",$J28="RED"),0,IF($C28="","",raporTarihi-$C28))) | R28: =IF($A28="","",IF($Q28="","",IF($Q28<=pvf_kovaEsik1,"0-7",IF($Q28<=pvf_kovaEsik2,"8-30",IF($Q28<=pvf_kovaEsik3,"31-60","60+"))))) | S28: =IF($A28="","",IF($B28="","YETİM",IF(COUNTIF(tblPersonel[PersonelId],$B28)=0,"YETİM",""))) | T28: =IF(OR($A28="",$I28=""),"",IF(OR($I28&"|"&$J28="",COUNTIF(ListeIzinliGecis,$I28&"|"&$J28)>0),"","GEÇERSİZ GEÇİŞ")) | U28: =IF($A28="","",IF(OR($P28="",$G28=""),"",IF(ABS($G28-$P28)>zincirTolerans,"ZİNCİR KIRIK","OK"))) | V28: =IF($A28="","",1) | W28: =IF($A28="","",$G28*$N28*pvf_mesaiKatsayi)
A29: PUA-00024 | B29: PER-00008 | C29: 46242 | D29: 8 | E29: 18 | F29: 8 | G29: 2 | H29: UCRETSIZ | I29: TASLAK | J29: TASLAK | L29: B | M29: Puantaj notu 24 | N29: 160 | O29: =IF($A29="","",MAX(0,$E29-$D29)) | P29: =IF($A29="","",MAX(0,$O29-$F29)) | Q29: =IF($A29="","",IF(OR($J29="ARSIV",$J29="RED"),0,IF($C29="","",raporTarihi-$C29))) | R29: =IF($A29="","",IF($Q29="","",IF($Q29<=pvf_kovaEsik1,"0-7",IF($Q29<=pvf_kovaEsik2,"8-30",IF($Q29<=pvf_kovaEsik3,"31-60","60+"))))) | S29: =IF($A29="","",IF($B29="","YETİM",IF(COUNTIF(tblPersonel[PersonelId],$B29)=0,"YETİM",""))) | T29: =IF(OR($A29="",$I29=""),"",IF(OR($I29&"|"&$J29="",COUNTIF(ListeIzinliGecis,$I29&"|"&$J29)>0),"","GEÇERSİZ GEÇİŞ")) | U29: =IF($A29="","",IF(OR($P29="",$G29=""),"",IF(ABS($G29-$P29)>zincirTolerans,"ZİNCİR KIRIK","OK"))) | V29: =IF($A29="","",1) | W29: =IF($A29="","",$G29*$N29*pvf_mesaiKatsayi)
A30: PUA-00025 | B30: PER-99999 | C30: 46240 | D30: 8 | E30: 17 | F30: 8 | G30: 1 | H30: YOK | J30: TASLAK | L30: A | M30: Puantaj notu 25 | N30: 120 | O30: =IF($A30="","",MAX(0,$E30-$D30)) | P30: =IF($A30="","",MAX(0,$O30-$F30)) | Q30: =IF($A30="","",IF(OR($J30="ARSIV",$J30="RED"),0,IF($C30="","",raporTarihi-$C30))) | R30: =IF($A30="","",IF($Q30="","",IF($Q30<=pvf_kovaEsik1,"0-7",IF($Q30<=pvf_kovaEsik2,"8-30",IF($Q30<=pvf_kovaEsik3,"31-60","60+"))))) | S30: =IF($A30="","",IF($B30="","YETİM",IF(COUNTIF(tblPersonel[PersonelId],$B30)=0,"YETİM",""))) | T30: =IF(OR($A30="",$I30=""),"",IF(OR($I30&"|"&$J30="",COUNTIF(ListeIzinliGecis,$I30&"|"&$J30)>0),"","GEÇERSİZ GEÇİŞ")) | U30: =IF($A30="","",IF(OR($P30="",$G30=""),"",IF(ABS($G30-$P30)>zincirTolerans,"ZİNCİR KIRIK","OK"))) | V30: =IF($A30="","",1) | W30: =IF($A30="","",$G30*$N30*pvf_mesaiKatsayi)
A31: PUA-00026 | B31: PER-00002 | C31: 46238 | D31: 8 | E31: 16.5 | F31: 8 | G31: 0.5 | H31: YILLIK | I31: TASLAK | J31: KONTROL | L31: B | M31: Puantaj notu 26 | N31: 130 | O31: =IF($A31="","",MAX(0,$E31-$D31)) | P31: =IF($A31="","",MAX(0,$O31-$F31)) | Q31: =IF($A31="","",IF(OR($J31="ARSIV",$J31="RED"),0,IF($C31="","",raporTarihi-$C31))) | R31: =IF($A31="","",IF($Q31="","",IF($Q31<=pvf_kovaEsik1,"0-7",IF($Q31<=pvf_kovaEsik2,"8-30",IF($Q31<=pvf_kovaEsik3,"31-60","60+"))))) | S31: =IF($A31="","",IF($B31="","YETİM",IF(COUNTIF(tblPersonel[PersonelId],$B31)=0,"YETİM",""))) | T31: =IF(OR($A31="",$I31=""),"",IF(OR($I31&"|"&$J31="",COUNTIF(ListeIzinliGecis,$I31&"|"&$J31)>0),"","GEÇERSİZ GEÇİŞ")) | U31: =IF($A31="","",IF(OR($P31="",$G31=""),"",IF(ABS($G31-$P31)>zincirTolerans,"ZİNCİR KIRIK","OK"))) | V31: =IF($A31="","",1) | W31: =IF($A31="","",$G31*$N31*pvf_mesaiKatsayi)
A32: PUA-00027 | B32: PER-00003 | C32: 46236 | D32: 8 | E32: 18 | F32: 8 | G32: 2 | H32: MAZERET | I32: KONTROL | J32: ONAY | K32: İMZA-027 | L32: A | M32: Puantaj notu 27 | N32: 140 | O32: =IF($A32="","",MAX(0,$E32-$D32)) | P32: =IF($A32="","",MAX(0,$O32-$F32)) | Q32: =IF($A32="","",IF(OR($J32="ARSIV",$J32="RED"),0,IF($C32="","",raporTarihi-$C32))) | R32: =IF($A32="","",IF($Q32="","",IF($Q32<=pvf_kovaEsik1,"0-7",IF($Q32<=pvf_kovaEsik2,"8-30",IF($Q32<=pvf_kovaEsik3,"31-60","60+"))))) | S32: =IF($A32="","",IF($B32="","YETİM",IF(COUNTIF(tblPersonel[PersonelId],$B32)=0,"YETİM",""))) | T32: =IF(OR($A32="",$I32=""),"",IF(OR($I32&"|"&$J32="",COUNTIF(ListeIzinliGecis,$I32&"|"&$J32)>0),"","GEÇERSİZ GEÇİŞ")) | U32: =IF($A32="","",IF(OR($P32="",$G32=""),"",IF(ABS($G32-$P32)>zincirTolerans,"ZİNCİR KIRIK","OK"))) | V32: =IF($A32="","",1) | W32: =IF($A32="","",$G32*$N32*pvf_mesaiKatsayi)
A33: PUA-00028 | B33: PER-00004 | C33: 46234 | D33: 8 | E33: 17 | F33: 8 | G33: 1 | H33: RAPOR | I33: ONAY | J33: ARSIV | K33: İMZA-028 | L33: B | M33: Puantaj notu 28 | N33: 150 | O33: =IF($A33="","",MAX(0,$E33-$D33)) | P33: =IF($A33="","",MAX(0,$O33-$F33)) | Q33: =IF($A33="","",IF(OR($J33="ARSIV",$J33="RED"),0,IF($C33="","",raporTarihi-$C33))) | R33: =IF($A33="","",IF($Q33="","",IF($Q33<=pvf_kovaEsik1,"0-7",IF($Q33<=pvf_kovaEsik2,"8-30",IF($Q33<=pvf_kovaEsik3,"31-60","60+"))))) | S33: =IF($A33="","",IF($B33="","YETİM",IF(COUNTIF(tblPersonel[PersonelId],$B33)=0,"YETİM",""))) | T33: =IF(OR($A33="",$I33=""),"",IF(OR($I33&"|"&$J33="",COUNTIF(ListeIzinliGecis,$I33&"|"&$J33)>0),"","GEÇERSİZ GEÇİŞ")) | U33: =IF($A33="","",IF(OR($P33="",$G33=""),"",IF(ABS($G33-$P33)>zincirTolerans,"ZİNCİR KIRIK","OK"))) | V33: =IF($A33="","",1) | W33: =IF($A33="","",$G33*$N33*pvf_mesaiKatsayi)
O34: =IF($A34="","",MAX(0,$E34-$D34)) | P34: =IF($A34="","",MAX(0,$O34-$F34)) | Q34: =IF($A34="","",IF(OR($J34="ARSIV",$J34="RED"),0,IF($C34="","",raporTarihi-$C34))) | R34: =IF($A34="","",IF($Q34="","",IF($Q34<=pvf_kovaEsik1,"0-7",IF($Q34<=pvf_kovaEsik2,"8-30",IF($Q34<=pvf_kovaEsik3,"31-60","60+"))))) | S34: =IF($A34="","",IF($B34="","YETİM",IF(COUNTIF(tblPersonel[PersonelId],$B34)=0,"YETİM",""))) | T34: =IF(OR($A34="",$I34=""),"",IF(OR($I34&"|"&$J34="",COUNTIF(ListeIzinliGecis,$I34&"|"&$J34)>0),"","GEÇERSİZ GEÇİŞ")) | U34: =IF($A34="","",IF(OR($P34="",$G34=""),"",IF(ABS($G34-$P34)>zincirTolerans,"ZİNCİR KIRIK","OK"))) | V34: =IF($A34="","",1) | W34: =IF($A34="","",$G34*$N34*pvf_mesaiKatsayi)
O35: =IF($A35="","",MAX(0,$E35-$D35)) | P35: =IF($A35="","",MAX(0,$O35-$F35)) | Q35: =IF($A35="","",IF(OR($J35="ARSIV",$J35="RED"),0,IF($C35="","",raporTarihi-$C35))) | R35: =IF($A35="","",IF($Q35="","",IF($Q35<=pvf_kovaEsik1,"0-7",IF($Q35<=pvf_kovaEsik2,"8-30",IF($Q35<=pvf_kovaEsik3,"31-60","60+"))))) | S35: =IF($A35="","",IF($B35="","YETİM",IF(COUNTIF(tblPersonel[PersonelId],$B35)=0,"YETİM",""))) | T35: =IF(OR($A35="",$I35=""),"",IF(OR($I35&"|"&$J35="",COUNTIF(ListeIzinliGecis,$I35&"|"&$J35)>0),"","GEÇERSİZ GEÇİŞ")) | U35: =IF($A35="","",IF(OR($P35="",$G35=""),"",IF(ABS($G35-$P35)>zincirTolerans,"ZİNCİR KIRIK","OK"))) | V35: =IF($A35="","",1) | W35: =IF($A35="","",$G35*$N35*pvf_mesaiKatsayi)
O36: =IF($A36="","",MAX(0,$E36-$D36)) | P36: =IF($A36="","",MAX(0,$O36-$F36)) | Q36: =IF($A36="","",IF(OR($J36="ARSIV",$J36="RED"),0,IF($C36="","",raporTarihi-$C36))) | R36: =IF($A36="","",IF($Q36="","",IF($Q36<=pvf_kovaEsik1,"0-7",IF($Q36<=pvf_kovaEsik2,"8-30",IF($Q36<=pvf_kovaEsik3,"31-60","60+"))))) | S36: =IF($A36="","",IF($B36="","YETİM",IF(COUNTIF(tblPersonel[PersonelId],$B36)=0,"YETİM",""))) | T36: =IF(OR($A36="",$I36=""),"",IF(OR($I36&"|"&$J36="",COUNTIF(ListeIzinliGecis,$I36&"|"&$J36)>0),"","GEÇERSİZ GEÇİŞ")) | U36: =IF($A36="","",IF(OR($P36="",$G36=""),"",IF(ABS($G36-$P36)>zincirTolerans,"ZİNCİR KIRIK","OK"))) | V36: =IF($A36="","",1) | W36: =IF($A36="","",$G36*$N36*pvf_mesaiKatsayi)
O37: =IF($A37="","",MAX(0,$E37-$D37)) | P37: =IF($A37="","",MAX(0,$O37-$F37)) | Q37: =IF($A37="","",IF(OR($J37="ARSIV",$J37="RED"),0,IF($C37="","",raporTarihi-$C37))) | R37: =IF($A37="","",IF($Q37="","",IF($Q37<=pvf_kovaEsik1,"0-7",IF($Q37<=pvf_kovaEsik2,"8-30",IF($Q37<=pvf_kovaEsik3,"31-60","60+"))))) | S37: =IF($A37="","",IF($B37="","YETİM",IF(COUNTIF(tblPersonel[PersonelId],$B37)=0,"YETİM",""))) | T37: =IF(OR($A37="",$I37=""),"",IF(OR($I37&"|"&$J37="",COUNTIF(ListeIzinliGecis,$I37&"|"&$J37)>0),"","GEÇERSİZ GEÇİŞ")) | U37: =IF($A37="","",IF(OR($P37="",$G37=""),"",IF(ABS($G37-$P37)>zincirTolerans,"ZİNCİR KIRIK","OK"))) | V37: =IF($A37="","",1) | W37: =IF($A37="","",$G37*$N37*pvf_mesaiKatsayi)
O38: =IF($A38="","",MAX(0,$E38-$D38)) | P38: =IF($A38="","",MAX(0,$O38-$F38)) | Q38: =IF($A38="","",IF(OR($J38="ARSIV",$J38="RED"),0,IF($C38="","",raporTarihi-$C38))) | R38: =IF($A38="","",IF($Q38="","",IF($Q38<=pvf_kovaEsik1,"0-7",IF($Q38<=pvf_kovaEsik2,"8-30",IF($Q38<=pvf_kovaEsik3,"31-60","60+"))))) | S38: =IF($A38="","",IF($B38="","YETİM",IF(COUNTIF(tblPersonel[PersonelId],$B38)=0,"YETİM",""))) | T38: =IF(OR($A38="",$I38=""),"",IF(OR($I38&"|"&$J38="",COUNTIF(ListeIzinliGecis,$I38&"|"&$J38)>0),"","GEÇERSİZ GEÇİŞ")) | U38: =IF($A38="","",IF(OR($P38="",$G38=""),"",IF(ABS($G38-$P38)>zincirTolerans,"ZİNCİR KIRIK","OK"))) | V38: =IF($A38="","",1) | W38: =IF($A38="","",$G38*$N38*pvf_mesaiKatsayi)
O39: =IF($A39="","",MAX(0,$E39-$D39)) | P39: =IF($A39="","",MAX(0,$O39-$F39)) | Q39: =IF($A39="","",IF(OR($J39="ARSIV",$J39="RED"),0,IF($C39="","",raporTarihi-$C39))) | R39: =IF($A39="","",IF($Q39="","",IF($Q39<=pvf_kovaEsik1,"0-7",IF($Q39<=pvf_kovaEsik2,"8-30",IF($Q39<=pvf_kovaEsik3,"31-60","60+"))))) | S39: =IF($A39="","",IF($B39="","YETİM",IF(COUNTIF(tblPersonel[PersonelId],$B39)=0,"YETİM",""))) | T39: =IF(OR($A39="",$I39=""),"",IF(OR($I39&"|"&$J39="",COUNTIF(ListeIzinliGecis,$I39&"|"&$J39)>0),"","GEÇERSİZ GEÇİŞ")) | U39: =IF($A39="","",IF(OR($P39="",$G39=""),"",IF(ABS($G39-$P39)>zincirTolerans,"ZİNCİR KIRIK","OK"))) | V39: =IF($A39="","",1) | W39: =IF($A39="","",$G39*$N39*pvf_mesaiKatsayi)
O40: =IF($A40="","",MAX(0,$E40-$D40)) | P40: =IF($A40="","",MAX(0,$O40-$F40)) | Q40: =IF($A40="","",IF(OR($J40="ARSIV",$J40="RED"),0,IF($C40="","",raporTarihi-$C40))) | R40: =IF($A40="","",IF($Q40="","",IF($Q40<=pvf_kovaEsik1,"0-7",IF($Q40<=pvf_kovaEsik2,"8-30",IF($Q40<=pvf_kovaEsik3,"31-60","60+"))))) | S40: =IF($A40="","",IF($B40="","YETİM",IF(COUNTIF(tblPersonel[PersonelId],$B40)=0,"YETİM",""))) | T40: =IF(OR($A40="",$I40=""),"",IF(OR($I40&"|"&$J40="",COUNTIF(ListeIzinliGecis,$I40&"|"&$J40)>0),"","GEÇERSİZ GEÇİŞ")) | U40: =IF($A40="","",IF(OR($P40="",$G40=""),"",IF(ABS($G40-$P40)>zincirTolerans,"ZİNCİR KIRIK","OK"))) | V40: =IF($A40="","",1) | W40: =IF($A40="","",$G40*$N40*pvf_mesaiKatsayi)
O41: =IF($A41="","",MAX(0,$E41-$D41)) | P41: =IF($A41="","",MAX(0,$O41-$F41)) | Q41: =IF($A41="","",IF(OR($J41="ARSIV",$J41="RED"),0,IF($C41="","",raporTarihi-$C41))) | R41: =IF($A41="","",IF($Q41="","",IF($Q41<=pvf_kovaEsik1,"0-7",IF($Q41<=pvf_kovaEsik2,"8-30",IF($Q41<=pvf_kovaEsik3,"31-60","60+"))))) | S41: =IF($A41="","",IF($B41="","YETİM",IF(COUNTIF(tblPersonel[PersonelId],$B41)=0,"YETİM",""))) | T41: =IF(OR($A41="",$I41=""),"",IF(OR($I41&"|"&$J41="",COUNTIF(ListeIzinliGecis,$I41&"|"&$J41)>0),"","GEÇERSİZ GEÇİŞ")) | U41: =IF($A41="","",IF(OR($P41="",$G41=""),"",IF(ABS($G41-$P41)>zincirTolerans,"ZİNCİR KIRIK","OK"))) | V41: =IF($A41="","",1) | W41: =IF($A41="","",$G41*$N41*pvf_mesaiKatsayi)
O42: =IF($A42="","",MAX(0,$E42-$D42)) | P42: =IF($A42="","",MAX(0,$O42-$F42)) | Q42: =IF($A42="","",IF(OR($J42="ARSIV",$J42="RED"),0,IF($C42="","",raporTarihi-$C42))) | R42: =IF($A42="","",IF($Q42="","",IF($Q42<=pvf_kovaEsik1,"0-7",IF($Q42<=pvf_kovaEsik2,"8-30",IF($Q42<=pvf_kovaEsik3,"31-60","60+"))))) | S42: =IF($A42="","",IF($B42="","YETİM",IF(COUNTIF(tblPersonel[PersonelId],$B42)=0,"YETİM",""))) | T42: =IF(OR($A42="",$I42=""),"",IF(OR($I42&"|"&$J42="",COUNTIF(ListeIzinliGecis,$I42&"|"&$J42)>0),"","GEÇERSİZ GEÇİŞ")) | U42: =IF($A42="","",IF(OR($P42="",$G42=""),"",IF(ABS($G42-$P42)>zincirTolerans,"ZİNCİR KIRIK","OK"))) | V42: =IF($A42="","",1) | W42: =IF($A42="","",$G42*$N42*pvf_mesaiKatsayi)
...

Sheet KUYRUKLAR
A1: KUYRUKLAR — Puantaj-Vardiya-Fazla Mesai Kanıt Sistemi
A3: Durum bazlı canlı kuyruk — kapalı kayıtlar düşer
A5: Kuyruk | B5: Adet | C5: FM Saat
A6: Kuyruk Taslak | B6: =COUNTIFS(tblAkis[Durum],"TASLAK",tblAkis[KayitDolu],">0") | C6: =SUMIF(tblAkis[Durum],"TASLAK",tblAkis[FazlaMesaiSaat])
A7: Kuyruk Kontrol | B7: =COUNTIFS(tblAkis[Durum],"KONTROL",tblAkis[KayitDolu],">0") | C7: =SUMIF(tblAkis[Durum],"KONTROL",tblAkis[FazlaMesaiSaat])
A8: Kuyruk Onay | B8: =COUNTIFS(tblAkis[Durum],"ONAY",tblAkis[KayitDolu],">0") | C8: =SUMIF(tblAkis[Durum],"ONAY",tblAkis[FazlaMesaiSaat])
A9: Aşım bandı (FM>günlük eşik) | B9: =COUNTIFS(tblAkis[FazlaMesaiSaat],">"&pvf_esikGunlukFm,tblAkis[Durum],"<>ARSIV",tblAkis[Durum],"<>RED",tblAkis[KayitDolu],">0") | C9: =SUMIFS(tblAkis[FazlaMesaiSaat],tblAkis[FazlaMesaiSaat],">"&pvf_esikGunlukFm,tblAkis[Durum],"<>ARSIV",tblAkis[Durum],"<>RED")
A11: Kapalı (Arşiv+Red) — kuyruktan düşer
A12: Arşiv | B12: =COUNTIF(tblAkis[Durum],"ARSIV") | C12: =SUMIF(tblAkis[Durum],"ARSIV",tblAkis[FazlaMesaiSaat])
A13: Red | B13: =COUNTIF(tblAkis[Durum],"RED") | C13: =SUMIF(tblAkis[Durum],"RED",tblAkis[FazlaMesaiSaat])
A15: Kuyruk Özeti | B15: =pvf_kuyrukOzeti
A17: Yaş Kova Dağılımı
A18: 0-7 | B18: =COUNTIF(tblAkis[YasKova],"0-7") | C18: =SUMIF(tblAkis[YasKova],"0-7",tblAkis[FazlaMesaiSaat])
A19: 8-30 | B19: =COUNTIF(tblAkis[YasKova],"8-30") | C19: =SUMIF(tblAkis[YasKova],"8-30",tblAkis[FazlaMesaiSaat])
A20: 31-60 | B20: =COUNTIF(tblAkis[YasKova],"31-60") | C20: =SUMIF(tblAkis[YasKova],"31-60",tblAkis[FazlaMesaiSaat])
A21: 60+ | B21: =COUNTIF(tblAkis[YasKova],"60+") | C21: =SUMIF(tblAkis[YasKova],"60+",tblAkis[FazlaMesaiSaat])

Sheet HESAP
A1: HESAP — Puantaj-Vardiya-Fazla Mesai Kanıt Sistemi
A3: Hesap motoru — ≥40 adım; sabitler AYARLAR'dan
A5: Adım | B5: Açıklama | C5: Değer
A6: H01 | B6: Toplam puantaj | C6: =COUNTA(tblAkis[PuantajId])
A7: H02 | B7: Dolu kayıt | C7: =SUM(tblAkis[KayitDolu])
A8: H03 | B8: Toplam FM saat | C8: =SUM(tblAkis[FazlaMesaiSaat])
A9: H04 | B9: Hesaplanan FM toplam | C9: =SUM(tblAkis[HesaplananFm])
A10: H05 | B10: Fiili saat toplam | C10: =SUM(tblAkis[FiiliSaat])
A11: H06 | B11: Taslak adet | C11: =COUNTIF(tblAkis[Durum],"TASLAK")
A12: H07 | B12: Kontrol adet | C12: =COUNTIF(tblAkis[Durum],"KONTROL")
A13: H08 | B13: Onay adet | C13: =COUNTIF(tblAkis[Durum],"ONAY")
A14: H09 | B14: Arşiv adet | C14: =COUNTIF(tblAkis[Durum],"ARSIV")
A15: H10 | B15: Red adet | C15: =COUNTIF(tblAkis[Durum],"RED")
A16: H11 | B16: Açık kuyruk adet | C16: =C11+C12+C13
A17: H12 | B17: Kapalı düşüm adet | C17: =C14+C15
A18: H13 | B18: Açık FM kuyruk | C18: =SUMIF(tblAkis[Durum],"TASLAK",tblAkis[FazlaMesaiSaat])+SUMIF(tblAkis[Durum],"KONTROL",tblAkis[FazlaMesaiSaat])+SUMIF(tblAkis[Durum],"ONAY",tblAkis[FazlaMesaiSaat])
A19: H14 | B19: Yetim adet | C19: =COUNTIF(tblAkis[YetimBayrak],"YETİM")
A20: H15 | B20: Geçersiz geçiş | C20: =COUNTIF(tblAkis[GecisUyarisi],"GEÇERSİZ GEÇİŞ")
A21: H16 | B21: Zincir kırık | C21: =COUNTIF(tblAkis[ZincirBayrak],"ZİNCİR KIRIK")
A22: H17 | B22: Zincir OK | C22: =COUNTIF(tblAkis[ZincirBayrak],"OK")
A23: H18 | B23: Yaş 0-7 | C23: =COUNTIF(tblAkis[YasKova],"0-7")
A24: H19 | B24: Yaş 8-30 | C24: =COUNTIF(tblAkis[YasKova],"8-30")
A25: H20 | B25: Yaş 31-60 | C25: =COUNTIF(tblAkis[YasKova],"31-60")
