Workbook
Name hesapYili: GIRDI!$B$8
Name raporTarihi: AYARLAR!$B$6
Name zincirTolerans: AYARLAR!$B$7
Name ebr_tolerans: AYARLAR!$B$8
Name ebr_kararEsik: AYARLAR!$B$9
Name ebr_senaryoIyi: AYARLAR!$B$10
Name ebr_senaryoKotu: AYARLAR!$B$11
Name ebr_esikArtisCarpan: AYARLAR!$B$12
Name ebr_tahminAlt: AYARLAR!$B$13
Name ebr_tahminUst: AYARLAR!$B$14
Name ebr_tornadoCiro: AYARLAR!$B$15
Name ebr_yorumACarpan: AYARLAR!$B$16
Name ebr_yuzdelikOran: AYARLAR!$B$17
Name ebr_parmakIzi: AYARLAR!$B$18
Name ebr_girisBeklenen: AYARLAR!$B$19
Name ebr_riskDusuk: AYARLAR!$B$20
Name ebr_riskOrta: AYARLAR!$B$21
Name ebr_riskYuksek: AYARLAR!$B$22
Name ebr_yilTaban: AYARLAR!$B$23
Name ebr_yuvarMax: AYARLAR!$B$24
Name vaka_ciro_1: AYARLAR!$B$25
Name vaka_ciro_2: AYARLAR!$B$26
Name vaka_ciro_3: AYARLAR!$B$27
Name vaka_ciro_4: AYARLAR!$B$28
Name ebr_esikGecikmeGun: AYARLAR!$B$29
Name ebr_eylemYas: AYARLAR!$I$43
Name ebr_yorumEylemYas: AYARLAR!$I$44
Name ebr_modulT2: AYARLAR!$I$45
Name ebr_modulT2Yorum: AYARLAR!$I$46
Name ebr_duyarlilikSira: AYARLAR!$I$47
Name ebr_yorumDuyarlilik: AYARLAR!$I$48
Name ebr_senaryoKarsilastirma: AYARLAR!$I$49
Name ebr_yorumSenaryo: AYARLAR!$I$50
Name ebr_kuralDegisimSenaryo: AYARLAR!$I$51
Name ebr_yorumKuralDegisim: AYARLAR!$I$52
Name ebr_tahminAralik: AYARLAR!$I$53
Name ebr_yorumTahmin: AYARLAR!$I$54
Name ebr_modulI2: AYARLAR!$I$55
Name ebr_modulI2Yorum: AYARLAR!$I$56
Name ebr_kararMetni: AYARLAR!$I$57
Name ebr_kararGerekce: AYARLAR!$I$58
Name ebr_maddeAtifMetni: AYARLAR!$I$59
Name ebr_kanitRaporu: AYARLAR!$I$60
Name ebr_vakaDurum: AYARLAR!$I$61
Name ebr_vakaFark: AYARLAR!$I$62
Name ebr_ciro: AYARLAR!$I$63
Name ebr_zorunluAdet: AYARLAR!$I$64
Name ebr_kuralYilMatris: AYARLAR!$I$65
Name ListeYillar: LISTELER!$A$6:$A$8
Name ListeYorumAB: LISTELER!$C$6:$C$7
Name ListeEvetHayir: LISTELER!$E$6:$E$7
Name ListeDurumlar: LISTELER!$G$6:$G$10
Name ListeIzinliGecis: LISTELER!$I$6:$I$13
Name ListeKural: LISTELER!$K$6:$K$10

Sheet 00_BASLANGIC
A1: EXCELARŞİV KARAR SİSTEMİ v15.1 — ÜRETİM REFERANSI
A3: Konu | B3: Bağlayıcı Standart
A4: Amaç | B4: Kanıta dayalı, hatada kapalı çalışan Excel üretim ve denetim sistemi
A5: Öncelik | B5: Kullanıcının açık iş talebi ve gerçek kullanım senaryosu
A6: Ana akış | B6: Uygunluk → Yönetişim → Sözleşmeler → Üretim → Test → Kanıt → Kullanıcı Kabulü → Yayın
A7: Yayın ilkesi | B7: Üst aşamada hata varsa alt aşama GEÇTİ üretilemez
A8: Kullanıcı kabulü | B8: Excel masaüstü görünümü test edilmediyse DIŞ_KABUL_GEREKLİ
A9: Nihai yayın | B9: Yalnız uygulanabilir modüller GEÇTİ veya gerekçeli UYGULANMAZ
A10: Ticari ayrım | B10: Ekonomik olarak savunulabilir fiyat, gerçek pazar kabulü ile aynı değildir
A11: Karmaşıklık | B11: Karar değeri, eklenen karmaşıklığın maliyetinden büyük olmalıdır
A12: Excel sınırı | B12: Veritabanı, kurumsal yetkilendirme, değiştirilemez kayıt sistemi veya gerçek zamanlı olay platformu değildir
A13: Dil standardı | B13: Kullanıcıya görünen tüm sayfa, tablo, başlık, açıklama, uyarı ve karar metinleri saf Türkçe olmalıdır
A14: Muhasebe standardı | B14: Finansal ürünlerde Türkiye Tekdüzen Hesap Planı ve Türk muhasebe kullanım alışkanlıkları esas alınır
... A33: Muhasebe | B33: Türkiye Tekdüzen Hesap Planı ve Türk muhasebe/işletme düşünce yapısı esas alınır.

Sheet PANO
A1: ☰ PANO
B2: E-BELGE ZORUNLULUK RADARI | L2: Dönem: 2026 / Tam ▼ | M2: ★ DOĞRULANMIŞ
B3: Hedef Kullanıcı: SMMM, mali işler, işletme sahibi · 2026 Q3 Denetim Standardı
B5: EYLEM YAŞLANDIRMA | D5: KONSOLİDE | E5: ZORUNLU BELGE PAYI | G5: KONTROL | H5: NET OPERASYONEL MARJ | J5: GÜVENLİ | K5: SİSTEM GÜVEN SKORU | M5: DENETLENDİ
B7: =GİRDİLER!E17 | E7: =B7*0.22 | H7: =B7-E7 | K7: =EĞER(E7>0; YUVARLA(B7/E7; 2); 0)
B9: ↑ %14.2 konsolide canlı veri bağlantısı | E9: ● 8 Kalem nakit karşılığı: bloke | H9: ██████████░░░░░ %78.0 NET MARJ | K9: ✓ İDEAL karşılama rasyosu
B11: E-BELGE ZORUNLULUK RADARI — DÖNEMSEL İCRA VE PROJEKSİYON | F11: +%32 Verim | H11: KONSOLİDE OPERASYON VE KARAR MATRİSİ
B12: Kümülatif Hacim vs. Operasyonel Maliyet ve Net Kâr Eğilimi | H12: Anlık Hesaplama Sonuçları, Dinamik Formül Çıktıları ve Durum Puanlaması
B14: Dönem | C14: Aktif Hacim | D14: Maliyet/Yük | E14: Hedef | H14: PARAMETRE / KALEM | I14: ANA TUTAR | J14: FARK / MARJ | K14: VADE | L14: KONTROL DURUMU
B15: D1 | C15: 65 | D15: 45 | E15: 60 | H15: Dönemlik Kümülatif Bakiye | I15: =B7*0.45 | J15: =B7*0.05 | K15: 12 Ay | L15: ✓ DÜZENLİ
B16: D2 | C16: 78 | D16: 48 | E16: 70 | H16: Kritik Eşik Güvenlik Tamponu | I16: =B7*0.30 | J16: =B7*0.03 | K16: 24 Ay | L16: ★ AVANTAJ
B17: D3 | C17: 85 | D17: 55 | E17: 80 | H17: Operasyonel Net Fark | I17: =B7*0.15 | J17: =B7*0.02 | K17: 8 Ay | L17: ● YAKLAŞAN
B18: D4 | C18: 75 | D18: 42 | E18: 75 | H18: Rezerv ve Likit Dağılım | I18: =B7*0.10 | J18: =B7*0.01 | K18: 16 Ay | L18: ✓ TAM UYUM
B19: D5 | C19: 90 | D19: 40 | E19: 85 | H19: KONSOLİDE SİSTEM TOPLAMI | I19: =TOPLA(I15:I18) | J19: =TOPLA(J15:J18) | L19: TAM DOĞRULANDI (0 HATA)
B20: D6 | C20: 96 | D20: 32 | E20: 92
B22: KONSOLİDE PAY VE AĞIRLIK | F22: LİKİDİTE RİSKİ & ERKEN UYARI SİNYALLERİ | K22: KARAR MOTORU
B23: ■ Ana Segment (%42) | F23: Nakit Açığı Riski (30 Gün) | I23: 0.00 TL (Sıfır Risk) | K23: STRATEJİK VERİMLİLİK FIRSATI
B24: ■ İkincil Grup (%30) | F24: Tahsilat Gecikme Toleransı | I24: 48 Gün Güvenli Eşik | K24: Operasyonel süreç optimizasyonu ile kârlılık artış potansiyeli tespit edildi.
B25: ■ Destek Birimi (%15) | F25: ██████████████████████████████████████ Güvenli Bölge (%100)
B26: ■ Rezervler (%13) | F26: ✓ 90 GÜNLÜK PROJEKSİYONDA NAKİT SIKIŞIKLIĞI TESPİT EDİLMEDİ | K26: STRATEJİ REÇETESİNİ İNCELE >

Sheet GİRDİLER
A1: ☰ PANO
B3: 🔍 E-BELGE ZORUNLULUK RADARI — Kayıt veya hesap ara... | G3: TOPLAM: 1.450 KAYIT | I3: HATALI HÜCRE: 0 ADET
B5: TARİH | C5: REFERANS NO | D5: İŞLEM AÇIKLAMASI VE DETAY | E5: BRÜT TUTAR (₺) | F5: KDV ORANI | G5: NET TUTAR (₺) | H5: HESAP / CARİ | I5: DURUM
B6: 12.10.2026 | C6: TR-0428-A | D6: Operasyonel ana kalem tahmini | E6: 845200 | F6: 0.2 | G6: =E6/(1+F6) | H6: Vadesiz Ticari | I6: ONAYLANDI
B7: 14.10.2026 | C7: TR-0429-B | D7: Operasyonel çıkış/maliyet tahmini | E7: 1240000 | F7: 0.2 | G7: =E7/(1+F7) | H7: Tedarikçi Havuzu | I7: BEKLEMEDE
B8: 18.10.2026 | C8: TR-0430-C | D8: Ödeme takvimi tahakkuku | E8: 620500 | F8: 0.1 | G8: =E8/(1+F8) | H8: Kısa Vade Tahakkuk | I8: ONAYLANDI
B9: 21.10.2026 | C9: TR-0431-D | D9: Müşteri işlem tahmini | E9: 415000 | F9: 0.2 | G9: =E9/(1+F9) | H9: Müşteri Alacağı | I9: ONAYLANDI
B10: 25.10.2026 | C10: TR-0432-E | D10: Ana operasyon tahmini | E10: 980400 | F10: 0.2 | G10: =E10/(1+F10) | H10: Vadesiz Ticari | I10: ONAYLANDI
B11: 28.10.2026 | C11: TR-0433-F | D11: Kredi/taksit karşılığı | E11: 1850000 | F11: 0.2 | G11: =E11/(1+F11) | H11: Finansman Havuzu | I11: BLOKE
B12: 02.11.2026 | C12: TR-0434-G | D12: Sabit gider ve yönetim notları | E12: 740000 | F12: 0.2 | G12: =E12/(1+F12) | H12: Genel Yönetim | I12: ONAYLANDI
B13: 05.11.2026 | C13: TR-0435-H | D13: Operasyonel ana kalem tahmini | E13: 520800 | F13: 0.2 | G13: =E13/(1+F13) | H13: Vadesiz Ticari | I13: ONAYLANDI
B14: 09.11.2026 | C14: TR-0436-I | D14: Müşteri işlem tahmini | E14: 1120000 | F14: 0.2 | G14: =E14/(1+F14) | H14: Müşteri Alacağı | I14: ONAYLANDI
B15: 12.11.2026 | C15: TR-0437-J | D15: Operasyonel çıkış tahmini | E15: 890000 | F15: 0.2 | G15: =E15/(1+F15) | H15: Tedarikçi Havuzu | I15: ONAYLANDI
B17: SAYFA TOPLAMI (10 / 1.450 KAYIT) | E17: =TOPLA(E6:E15)

Sheet YÖNETİM_RAPORU
A1: ☰ PANO
B2: E-BELGE ZORUNLULUK RADARI — NİHAİ KARAR VE DEĞERLEME
B3: Yönetim Kurulu ve İcra Komitesi için Otomatik Finansal Stres Testi Raporu · SMMM, mali işler, işletme sahibi
B4: DÖNEM: 2026 Q3 · DENETİM PROTOKOLÜ: ISO/VUK/IFRS UYUMLU · DURUM: ONAYLANDI
B6: SENARYO A: KÖTÜMSER (STRES TESTİ -%20) | H6: SENARYO B: BAZ MODEL (HEDEFLENEN)
B8: Ciro / Hacim Düşüşü: | E8: -%20.0 (Kriz Eşiği) | H8: Ciro / Hacim Gerçekleşmesi: | K8: %100.0 (Tam Bütçe)
B9: Beklenen Net Kâr / Getiri: | E9: =PANO!B7*0.8*0.22 | H9: Beklenen Net Kâr / Getiri: | K9: =PANO!H7
B10: Minimum Nakit Tamponu: | E10: =PANO!E7*0.75 | H10: Serbest Nakit Akımı: | K10: =PANO!H7*0.75
B11: Likidite Karşılama Oranı: | E11: =YUVARLA(PANO!B7*0.8/PANO!E7; 2) | H11: Yatırım Geri Dönüşü (ROI): | K11: %38.4 Yıllık
B14: STRES SENARYOSUNDA DAHİ İFLAS RİSKİ YOK | H14: OPTİMUM İCRA VE PLANLAMA REÇETESİ
B17: YÖNETİM KARAR MATRİSİ VE UYGULAMA REÇETESİ
B19: ● Öncelik 1: Acil Likidite ve Borç Servis Planlaması
B20: Sistemde hesaplanan vade günlerine sadık kalınarak nakit blokajı 3 gün önceden hazır edilmelidir.
B21: ● Öncelik 2: Formül Doğrulama ve Çapraz Sağlama
B22: Tüm hücreler kilitli formül korumasında olup girdi sayfalarında sıfır döngüsel başvuru (circular ref) garantilidir.
B23: ● Öncelik 3: Resmi Mevzuat ve Vergi Kalkanı Entegrasyonu
B24: 2026 güncel vergi dilimleri, amortisman ve SGK teşvik parametreleri tam otomatik yansıtılmaktadır.
B25: ● Öncelik 4: Yönetici İmzası ve Rapor Paylaşımı
B26: Tek tuşla PDF ve A4 çıktı formatına tam uyumlu sayfa yapısı kurgulanmıştır.

Sheet 01_YURUTME_CEKIRDEGI
A1: YÜRÜTME ÇEKİRDEĞİ — ZORUNLU ÜRETİM SIRASI
A3: Adım | B3: Modül | C3: Tetikleyici | D3: Zorunlu Kanıt | E3: GEÇTİ Kuralı | F3: Hata Durumu | G3: Sonraki Aşama
A4: 1 | B4: Excel Uygunluğu | C4: Her yeni model | D4: UYGUNLUK_KARARI | E4: Excel'in rolü açık | F4: HATA / BLOKE | G4: Yönetişim
A5: 2 | B5: Yönetişim | C5: Her model | D5: Risk seviyesi + etki girdileri | E5: Seviye hesaplandı | F5: BLOKE | G5: Sözleşmeler
A6: 3 | B6: Türk Muhasebe Eşlemesi | C6: Finansal model | D6: THP hesap eşleme tablosu | E6: Kritik satırlar THP ile uyumlu | F6: HATA | G6: Sözleşmeler
A7: 4 | B7: Veri ve Anlam Sözleşmeleri | C7: Girdi/KPI varsa | D7: Veri + KPI sözleşmeleri | E7: Kapsam %100 | F7: HATA | G7: Üretim
A8: 5 | B8: Üretim | C8: Sözleşmeler GEÇTİ | D8: Çalışan Excel | E8: Tek gerçek kaynak korunmuş | F8: HATA | G8: Testler
A9: 6 | B9: Görsel/Kullanım Katmanı | C9: Motor hazır | D9: Başlıklar + renk + grafik + yönlendirme | E9: Tüm kullanıcı sayfaları standarda uygun | F9: HATA | G9: Testler
A10: 7 | B10: Testler | C10: Üretim tamam | D10: Formül/OOXML/kimlik/oracle/golden/metamorfik | E10: Uygulanabilir hard gate'ler GEÇTİ | F10: HATA | G10: Kanıt
A11: 8 | B11: Hata-Kontrol Tutarlılığı | C11: Test sonucu var | D11: Hata taraması + kontrol sonuçları | E11: Formül hatası varken GEÇTİ yok | F11: HATA | G11: Kanıt
A12: 9 | B12: Kanıt | C12: Test sonucu var | D12: Makine okunur artefakt + özet | E12: Kanıt fiziksel ve tutarlı | F12: HATA | G12: Kullanıcı Kabulü
A13: 10 | B13: Kullanıcı Kabulü | C13: Kritik görevler | D13: Gerçek ekran davranışı | E13: Kritik görevler %100 | F13: DIŞ_KABUL_GEREKLİ | G13: Ticari
A14: 11 | B14: Ticari Değer | C14: Ürün satılacaksa | D14: ROI + demo + kanıt paketi | E14: Ekonomik değer kanıtlı | F14: UYARI / HATA | G14: Pazar Doğrulama
A15: 12 | B15: Pazar Doğrulama | C15: Pazar iddiası varsa | D15: Ücretli satış/pilot/fiyat kabul kanıtı | E15: Gerçek fiyat kabul kanıtı | F15: UYGULANMAZ / HATA | G15: Yayın

Sheet 02_KONTROL_LISTESI
A1: NİHAİ KONTROL LİSTESİ — KANITSIZ GEÇİŞ YOK
A3: Kontrol No | B3: Kontrol | C3: Beklenen | D3: Zorunlu Kapı? | E3: Sonuç
A4: K01 | B4: Kullanıcının açık talebi öncelikli mi? | C4: Evet | D4: EVET
A5: K02 | B5: Mevcut yapı, formüller ve tek gerçek kaynak korunuyor mu? | C5: Evet, değişiklik gerekçeli | D5: EVET
A6: K03 | B6: Üst aşama HATA ise alt aşama GEÇTİ engelleniyor mu? | C6: Evet | D6: EVET
A7: K04 | B7: Kanıt fiziksel çıktı ve içerik doğrulaması içeriyor mu? | C7: Evet | D7: EVET
A8: K05 | B8: Excel GUI erişimi olmadan kullanıcı görünümü GEÇTİ yazılıyor mu? | C8: Hayır | D8: EVET
A9: K06 | B9: NİHAİ yalnız GEÇTİ / gerekçeli UYGULANMAZ ile mi? | C9: Evet | D9: EVET
A10: K07 | B10: Ekonomik fiyat savunusu pazar doğrulamasından ayrılmış mı? | C10: Evet | D10: EVET
A11: K08 | B11: Prestij için gereksiz modül var mı? | C11: Hayır | D11: HAYIR
A12: K09 | B12: Excel sınırları açık mı? | C12: Evet | D12: EVET
A13: K10 | B13: Teknik kaynak korunuyor mu? | C13: Evet | D13: EVET
A14: K11 | B14: Kullanıcıya görünen tüm metinler Türkçe mi? | C14: Evet | D14: EVET
A15: K12 | B15: Her kullanıcı sayfasında üst başlık var mı? | C15: Evet | D15: EVET
... A34: K31 | B34: Premium vitrin, altyapı kadar güçlü ve satış fiyatını destekleyecek seviyede mi? | C34: Evet | D34: EVET

Sheet 03_GORSEL_TASARIM
A1: GÖRSEL TASARIM VE PREMIUM EXCEL STANDARDI
A3: Alan | B3: Zorunlu Kural | C3: Uygulama | D3: Yasak | E3: Kontrol | F3: Durum
A4: Sayfa başlığı | B4: Her kullanıcı sayfasının en üstünde tek ve açık sayfa başlığı | C4: A1'den başlayan koyu lacivert başlık bandı | D4: Başlıksız sayfa | E4: Başlık kapsama = %100 | F4: ZORUNLU
A5: Sekme renkleri | B5: Sayfalar işlevine göre renk kodlanır | C5: Girdi=mavi, hesap=gri, rapor=lacivert, kontrol=kırmızı, kılavuz=altın | D5: Rastgele renk | E5: Renk semantiği tutarlı | F5: ZORUNLU
A6: Kolon düzeni | B6: Veri blokları bitişik kolonlarda ilerler | C6: Gereksiz boş kolon bırakma; yalnız gerçek bölüm ayrımı varsa kontrollü boşluk | D6: A:C veri, D boş, E:F veri gibi parçalı yapı | E6: Boş kolon taraması | F6: ZORUNLU
A7: Girdi hücreleri | B7: Kullanıcının değiştireceği alan açıkça görünür | C7: Açık sarı dolgu + mavi yazı | D7: Formülle aynı görünüm | E7: Girdi/formül ayrımı | F7: ZORUNLU
A8: Formüller | B8: Hesap hücreleri kullanıcı girdisinden ayrılır | C8: Siyah yazı; sayfalar arası bağlantı yeşil yazı | D8: Hard-code gizleme | E8: Formül sınıfı kontrolü | F8: ZORUNLU
A9: Grafik sayısı | B9: Yönetici ekranında en fazla 3 ana karar grafiği | C9: Trend, karşılaştırma, köprü/dağılım; iş kararına bağlı | D9: Grafik kalabalığı | E9: Grafik başına karar sorusu | F9: ZORUNLU
A10: Grafik stili | B10: Kurumsal ve yüksek okunabilirlik | C10: Beyaz zemin, ince gridline, tek vurgu rengi, açık birim/başlık | D10: 3B, gölge, neon, gökkuşağı renkleri | E10: Görsel inceleme | F10: ZORUNLU
A11: Grafik başlığı | B11: Grafik 'neyi' değil 'ne anlama geldiğini' söyler | C11: Örn: 'Nakit 2028'de kritik eşiğin altına iniyor' | D11: 'Nakit Grafiği' gibi anlamsız başlık | E11: Başlık karar testi | F11: ZORUNLU
A12: Birimler | B12: Tüm finansal görsellerde birim açık | C12: TL, bin TL, milyon TL, %, gün, x | D12: Birim belirsizliği | E12: Birim kapsama %100 | F12: ZORUNLU
A13: Sıfır/negatif | B13: Finansal format standardı | C13: Sıfır='-', negatif kırmızı parantez | D13: -500 veya 0,00 kalabalığı | E13: Format kontrolü | F13: ZORUNLU
A14: Yazı tipi | B14: Tek aile | C14: Aptos veya Segoe UI | D14: Karışık font | E14: Tek font kontrolü | F14: ZORUNLU
... A22: Premium vitrin | B22: Görsel kalite ürün değerinin zorunlu parçasıdır | C22: Kaliteli grafik, gerçek KPI kartı, finansal hiyerarşi, tab rengi, fonksiyonel navigasyon | D22: Sadece doğru hesap yapıp çıplak/varsayılan Excel görünümü bırakmak | E22: Görsel release incelemesi | F22: ZORUNLU

Sheet 04_MUHASEBE_THP
A1: TÜRKİYE MUHASEBE VE TEKDÜZEN HESAP PLANI STANDARDI
A3: Konu | B3: Zorunlu Standart | C3: Örnek Türkçe Ad | D3: THP / Mantık | E3: Hata Riski | F3: Kontrol
A4: Dil | B4: Kullanıcıya görünen finansal terimler Türkçe | C4: Hasılat, Satışların Maliyeti, Brüt Kâr, Faaliyet Giderleri | D4: Türk işletme kullanımına uygun | E4: İngilizce jargon | F4: Terminoloji taraması
A5: Gelir Tablosu | B5: Türk sunum sırası kullanılır | C5: Net Satışlar → Satışların Maliyeti → Brüt Kâr → Faaliyet Giderleri → Faaliyet Kârı | D5: 600/610/611; 620-623; 63x | E5: Yanlış sınıflama | F5: Hesap eşleme
A6: Bilanço | B6: Dönen/Duran Varlık ve Kısa/Uzun Vadeli Yükümlülük ayrımı | C6: Hazır Değerler, Ticari Alacaklar, Stoklar, Mali Borçlar | D6: 1xx / 2xx / 3xx / 4xx / 5xx | E6: Vade sınıfı hatası | F6: Bilanço eşitliği
A7: Nakit Akışı | B7: İşletme/Yatırım/Finansman nakit akışları ayrılır | C7: Faaliyetlerden Nakit, Yatırım Harcamaları, Finansman Nakit Akışı | D7: Dolaylı/doğrudan yöntem açık seçilir | E7: Kâr = nakit sanılması | F7: Nakit devri
A8: Ticari Alacaklar | B8: Cari ve vade mantığı korunur | C8: 120 Alıcılar | D8: 120 | E8: Tahakkuk/nakit karışması | F8: Alacak devir kontrolü
A9: Ticari Borçlar | B9: Tedarikçi borcu ayrı izlenir | C9: 320 Satıcılar | D9: 320 | E9: Gider/ödeme karışması | F9: Borç devir kontrolü
A10: Kasa/Banka | B10: Hazır değerler ayrı izlenir | C10: 100 Kasa, 102 Bankalar | D10: 100 / 102 | E10: Virmanla toplam nakdin değişmesi | F10: Virman değişmezi
A11: Stok | B11: Dikeye uygun stok türü | C11: 150 İlk Madde ve Malzeme, 153 Ticari Mallar | D11: 15x | E11: Maliyet ve stok hareketinin kopması | F11: Stok devri
A12: Maddi Duran Varlık | B12: Yatırım harcaması ve amortisman bağlantılı | C12: 253 Tesis Makine Cihazlar, 255 Demirbaşlar, 257 Birikmiş Amortismanlar | D12: 25x | E12: Yatırım/gider karışması | F12: Net defter değeri devri
A13: Mali Borçlar | B13: Kısa/uzun vadeli borç ayrımı | C13: 300 Banka Kredileri / 400 Banka Kredileri | D13: 300 / 400 | E13: Vade sınıfı yanlış | F13: Borç devri
A14: Özkaynak | B14: Sermaye ve geçmiş yıl kârları ayrı | C14: 500 Sermaye, 570 Geçmiş Yıllar Kârları, 590 Dönem Net Kârı | D14: 5xx | E14: Net kâr bağının kopması | F14: Özkaynak devri
... A18: İstisna | B18: TFRS özel ürün varsa fark açık yazılır | C18: Tekdüzen raporlama ≠ TFRS finansal tablo sunumu | D18: Amaç belirtilir | E18: Standartları karıştırma | F18: Model amacı kontrolü

Sheet 05_KARAR_SATIS
A1: KARAR, GÜVEN VE SATIŞA HAZIRLIK STANDARDI
A3: Alan | B3: Müşteri Sorusu | C3: Zorunlu Ürün Davranışı | D3: Kanıt | E3: Başarısızlık Durumu | F3: Kapı
A4: 5 saniye | B4: Bu ürün neyi çözüyor? | C4: İlk ekranda hedef kullanıcı + pahalı problem + sonuç görünür | D4: Başlık + alt mesaj + gerçek ekran | E4: Ürün yalnız teknik isim | F4: HATA
A5: Acı | B5: Sorun bana neye mal oluyor? | C5: Mümkünse müşterinin kendi verisiyle parasal/zaman etkisi hesaplanır | D5: ROI/acı hesaplama yöntemi | E5: Uydurma tasarruf | F5: HATA
A6: Karar | B6: Bu bilgiyle ne yapacağım? | C6: Her kritik KPI aksiyona bağlanır | D6: KARAR_KUYRUGU | E6: Sadece rapor | F6: HATA
A7: Güven | B7: Bu sayıya neden inanayım? | C7: Kaynak, formül mantığı, kontrol ve son doğrulama görünür | D7: Kontroller + kaynak izi + sürüm | E7: Prestij kelimesi | F7: HATA
A8: Referans | B8: Müşteri yorumu yoksa ne göstereceğim? | C8: Önce/Sonra + Karar Vakası + Hata Önleme Vakası üretilir | D8: Demo/örnek çıktı | E8: Kanıtsız iddia | F8: HATA
A9: Senaryo | B9: Ne olursa işler bozulur? | C9: Baz/Aşağı/Yukarı veya uygun stres senaryosu | D9: Senaryo karşılaştırma | E9: Dekoratif senaryo | F9: HATA
A10: Ters stres | B10: Hangi eşikte karar kırılır? | C10: En az bir kritik sürücü için kırılma eşiği | D10: Kırılma eşiği tablosu | E10: Sadece +/- %10 | F10: UYARI/HATA
A11: Hata tutarlılığı | B11: Formül hata verirse ne olur? | C11: Kontrol GEÇTİ veremez; BLOKE/HATA üretir | D11: Hata taraması | E11: Hata + GEÇTİ birlikte | F11: HATA
A12: Karar motoru | B12: Ne oldu, neden oldu? | C12: Sorun + neden + parasal etki + aksiyon + son tarih | D12: Karar tablosu | E12: Boş sayfa / isim düzeyi modül | F12: HATA
A13: Yönetici özeti | B13: 5 saniyede ne görmeliyim? | C13: Bugün / ne değişti / ne bozulacak / neden / ne yapmalıyım / güven | D13: Yönetici özeti ekranı | E13: KPI kutusu yığını | F13: HATA
A14: Teklif | B14: Neden satın almalıyım? | C14: Dosya özellikleri yerine sonuç ve kaçınılan maliyet sunulur | D14: Ürün sayfası kanıt eşlemesi | E14: Özellik listesiyle satış | F14: HATA
... A19: Pazar kanıtı | B19: Piyasa gerçekten ödüyor mu? | C19: Satış/pilot/LOI/fiyat kabulü olmadan pazar doğrulandı yazılmaz | D19: Gerçek işlem kanıtı | E19: Tahmini talep = satış kabulü | F19: HATA

Sheet KAPAK
A1: KAPAK — e-Belge Zorunluluk Radarı
A3: e-Belge Zorunluluk Radarı
A4: Brüt satış hasılatını girin; e-Fatura / e-Arşiv / e-Defter / e-İrsaliye eşiklerini yıllı kural tablosuyla karşılaştırıp geçiş kararını ve eylem planını üretin.
A6: Bu ürün ne sağlar?
A7: • Çok yıllı eşik tablosu (2025/2026/2027) — tebliğ güncellemesine hazır
A8: • Zorunluluk kararı + madde atıflı KANIT_RAPORU
A9: • Senaryo / duyarlılık / M-SEN eşik değişimi
A10: • Envanter + eylem durum makinesi + yaşlandırma
A11: • Belirsizlik beyanı: ciro hesap dönemi (yorum A / B)
A13: Kimler için?
A14: • SMMM — müşteriye zorunluluk tarihini bildirir
A15: • İşletme — geçiş planını yapar
... A21: Sürüm 1.0.0 | 2026 | ExcelArşiv | Lisans: Tek kullanıcı

Sheet GIRDI
A1: GIRDI — e-Belge Zorunluluk Radarı
A3: Firma ve ciro girişi
A4: Sarı hücreler manuel giriştir. Eşikler KURALLAR'dan çekilir.
A5: Alan | B5: Değer | C5: Birim
A6: Firma Unvanı | B6: Örnek Ticaret A.Ş. | C6: metin
A7: Dönem | B7: 2025 | C7: metin
A8: Hesap Yılı | B8: 2025 | C8: yıl
A9: Brüt Satış Hasılatı [₺] | B9: 4500000 | C9: ₺
A10: Ciro Dönem Yorumu (A/B) | B10: A | C10: metin
A11: Sektör | B11: Ticaret | C11: metin
A13: Giriş doluluk (kalite) | B13: =IFERROR(IF(OR(COUNTA(B6:B11)=0,ebr_girisBeklenen=0),0,ROUND(COUNTA(B6:B11)/ebr_girisBeklenen*100,0)),0)
A16: Giriş tablosu (otomasyon / boş-mod)
A17: Alan Anahtarı | B17: Değer | C17: Birim | D17: Zorunlu | E17: Kaynak | F17: Kontrol
A18: firma | B18: Örnek Ticaret A.Ş. | C18: metin | D18: Evet | E18: GIRDI | F18: =IF($A18="","",IF($B18="","EKSİK","TAM"))
A19: donem | B19: 2025 | C19: metin | D19: Evet | E19: GIRDI | F19: =IF($A19="","",IF($B19="","EKSİK","TAM"))
A20: hesapYili | B20: 2025 | C20: yıl | D20: Evet | E20: GIRDI | F20: =IF($A20="","",IF($B20="","EKSİK","TAM"))
A21: brut_satis | B21: 4500000 | C21: TL | D21: Evet | E21: GIRDI | F21: =IF($A21="","",IF($B21="","EKSİK","TAM"))
A22: ciro_yorum | B22: A | C22: A/B | D22: Evet | E22: GIRDI | F22: =IF($A22="","",IF($B22="","EKSİK","TAM"))
A23: sektor | B23: Ticaret | C23: metin | D23: Evet | E23: GIRDI | F23: =IF($A23="","",IF($B23="","EKSİK","TAM"))
F24: =IF($A24="","",IF($B24="","EKSİK","TAM"))
F25: =IF($A25="","",IF($B25="","EKSİK","TAM"))
F26: =IF($A26="","",IF($B26="","EKSİK","TAM"))
F27: =IF($A27="","",IF($B27="","EKSİK","TAM"))
F28: =IF($A28="","",IF($B28="","EKSİK","TAM"))
F29: =IF($A29="","",IF($B29="","EKSİK","TAM"))
F30: =IF($A30="","",IF($B30="","EKSİK","TAM"))
F31: =IF($A31="","",IF($B31="","EKSİK","TAM"))
F32: =IF($A32="","",IF($B32="","EKSİK","TAM"))
F33: =IF($A33="","",IF($B33="","EKSİK","TAM"))
F34: =IF($A34="","",IF($B34="","EKSİK","TAM"))
F35: =IF($A35="","",IF($B35="","EKSİK","TAM"))
... F205: =IF($A205="","",IF($B205="","EKSİK","TAM"))
A1018: Sarı alanlar giriş; kalite formülü kilitlidir.

Sheet KURALLAR
A1: KURALLAR — e-Belge Zorunluluk Radarı
A3: e-Belge eşik kural tablosu (yıl yan yana)
A4: Eşikler MOTOR'da sabit yazılmaz; INDEX/MATCH ile buradan çekilir.
A6: kural_id | B6: madde | C6: kural_adi | D6: kosul_metni | E6: parametre_adi | F6: deger_2025 | G6: deger_2026 | H6: deger_2027 | I6: yururluk | J6: kaynak | K6: aktif_deger
A7: EBR-001 | B7: VUK e-Fatura | C7: efatura_esik | D7: brut_satis>=esik | E7: efatura_esik | F7: 3000000 | G7: 3500000 | H7: 4000000 | I7: 01.01.2025 | J7: GİB e-Fatura tebliği | K7: =IF($A7="","",IFERROR(CHOOSE(MAX(1,MIN(3,IF(OR(hesapYili="",hesapYili=0),1,hesapYili-ebr_yilTaban))),$F7,$G7,$H7),0))
A8: EBR-002 | B8: VUK e-Arşiv | C8: earsiv_esik | D8: brut_satis>=esik | E8: earsiv_esik | F8: 500000 | G8: 600000 | H8: 700000 | I8: 01.01.2025 | J8: GİB e-Arşiv tebliği | K8: =IF($A8="","",IFERROR(CHOOSE(MAX(1,MIN(3,IF(OR(hesapYili="",hesapYili=0),1,hesapYili-ebr_yilTaban))),$F8,$G8,$H8),0))
A9: EBR-003 | B9: VUK e-Defter | C9: edefter_esik | D9: brut_satis>=esik | E9: edefter_esik | F9: 3000000 | G9: 3500000 | H9: 4000000 | I9: 01.01.2025 | J9: GİB e-Defter tebliği | K9: =IF($A9="","",IFERROR(CHOOSE(MAX(1,MIN(3,IF(OR(hesapYili="",hesapYili=0),1,hesapYili-ebr_yilTaban))),$F9,$G9,$H9),0))
A10: EBR-004 | B10: VUK e-İrsaliye | C10: eirsaliye_esik | D10: brut_satis>=esik | E10: eirsaliye_esik | F10: 10000000 | G10: 12000000 | H10: 14000000 | I10: 01.01.2025 | J10: GİB e-İrsaliye tebliği | K10: =IF($A10="","",IFERROR(CHOOSE(MAX(1,MIN(3,IF(OR(hesapYili="",hesapYili=0),1,hesapYili-ebr_yilTaban))),$F10,$G10,$H10),0))
A11: EBR-005 | B11: Genel | C11: yuvarlama | D11: her hesap | E11: yuvarlama_ondalik | F11: 2 | G11: 2 | H11: 2 | I11: 01.01.2025 | J11: Uygulama notu | K11: =IF($A11="","",IFERROR(CHOOSE(MAX(1,MIN(3,IF(OR(hesapYili="",hesapYili=0),1,hesapYili-ebr_yilTaban))),$F11,$G11,$H11),0))
A14: Kural-yıl matrisi
A15: e-Fatura eşiği | B15: =IFERROR(INDEX(CHOOSE(MAX(1,MIN(3,IF(OR(hesapYili="",hesapYili=0),1,hesapYili-ebr_yilTaban))),tblKurallar[deger_2025],tblKurallar[deger_2026],tblKurallar[deger_2027]),MATCH("EBR-001",tblKurallar[kural_id],0)),0)
A16: e-Arşiv eşiği | B16: =IFERROR(INDEX(CHOOSE(MAX(1,MIN(3,IF(OR(hesapYili="",hesapYili=0),1,hesapYili-ebr_yilTaban))),tblKurallar[deger_2025],tblKurallar[deger_2026],tblKurallar[deger_2027]),MATCH("EBR-002",tblKurallar[kural_id],0)),0)
A17: Matris metni | B17: =_xlfn.TEXTJOIN(" | ",TRUE,"EBR-001=",TEXT(B15,"₺ #,##0"),"EBR-002=",TEXT(B16,"₺ #,##0"),"yıl=",hesapYili)

Sheet MOTOR
A1: MOTOR — e-Belge Zorunluluk Radarı
A3: Hesap zinciri — her adımda kural_id
A4: Eşikler tblKurallar'dan çekilir; sabit eşik yoktur.
A6: adim | B6: ad | C6: formul | D6: birim | E6: ne_ise_yarar | F6: kural_id | G6: deger
A7: 1 | B7: Hesap yılı oku | C7: =IFERROR(hesapYili,0) | D7: yıl | E7: Aktif mevzuat yılı | F7: EBR-005 | G7: =IFERROR(hesapYili,0)
A8: 2 | B8: e-Fatura eşiği | C8: =IFERROR(INDEX(CHOOSE(MAX(1,MIN(3,IF(OR(hesapYili="",hesapYili=0),1,hesapYili-ebr_yilTaban))),tblKurallar[deger_2025],tblKurallar[deger_2026],tblKurallar[deger_2027]),MATCH("EBR-001",tblKurallar[kural_id],0)),0) | D8: TL | E8: e-Fatura ciro eşiği | F8: EBR-001 | G8: =IFERROR(INDEX(CHOOSE(MAX(1,MIN(3,IF(OR(hesapYili="",hesapYili=0),1,hesapYili-ebr_yilTaban))),tblKurallar[deger_2025],tblKurallar[deger_2026],tblKurallar[deger_2027]),MATCH("EBR-001",tblKurallar[kural_id],0)),0)
A9: 3 | B9: e-Arşiv eşiği | C9: =IFERROR(INDEX(CHOOSE(MAX(1,MIN(3,IF(OR(hesapYili="",hesapYili=0),1,hesapYili-ebr_yilTaban))),tblKurallar[deger_2025],tblKurallar[deger_2026],tblKurallar[deger_2027]),MATCH("EBR-002",tblKurallar[kural_id],0)),0) | D9: TL | E9: e-Arşiv ciro eşiği | F9: EBR-002 | G9: =IFERROR(INDEX(CHOOSE(MAX(1,MIN(3,IF(OR(hesapYili="",hesapYili=0),1,hesapYili-ebr_yilTaban))),tblKurallar[deger_2025],tblKurallar[deger_2026],tblKurallar[deger_2027]),MATCH("EBR-002",tblKurallar[kural_id],0)),0)
A10: 4 | B10: e-Defter eşiği | C10: =IFERROR(INDEX(CHOOSE(MAX(1,MIN(3,IF(OR(hesapYili="",hesapYili=0),1,hesapYili-ebr_yilTaban))),tblKurallar[deger_2025],tblKurallar[deger_2026],tblKurallar[deger_2027]),MATCH("EBR-003",tblKurallar[kural_id],0)),0) | D10: TL | E10: e-Defter ciro eşiği | F10: EBR-003 | G10: =IFERROR(INDEX(CHOOSE(MAX(1,MIN(3,IF(OR(hesapYili="",hesapYili=0),1,hesapYili-ebr_yilTaban))),tblKurallar[deger_2025],tblKurallar[deger_2026],tblKurallar[deger_2027]),MATCH("EBR-003",tblKurallar[kural_id],0)),0)
A11: 5 | B11: e-İrsaliye eşiği | C11: =IFERROR(INDEX(CHOOSE(MAX(1,MIN(3,IF(OR(hesapYili="",hesapYili=0),1,hesapYili-ebr_yilTaban))),tblKurallar[deger_2025],tblKurallar[deger_2026],tblKurallar[deger_2027]),MATCH("EBR-004",tblKurallar[kural_id],0)),0) | D11: TL | E11: e-İrsaliye ciro eşiği | F11: EBR-004 | G11: =IFERROR(INDEX(CHOOSE(MAX(1,MIN(3,IF(OR(hesapYili="",hesapYili=0),1,hesapYili-ebr_yilTaban))),tblKurallar[deger_2025],tblKurallar[deger_2026],tblKurallar[deger_2027]),MATCH("EBR-004",tblKurallar[kural_id],0)),0)
A12: 6 | B12: Yuvarlama | C12: =IFERROR(INDEX(CHOOSE(MAX(1,MIN(3,IF(OR(hesapYili="",hesapYili=0),1,hesapYili-ebr_yilTaban))),tblKurallar[deger_2025],tblKurallar[deger_2026],tblKurallar[deger_2027]),MATCH("EBR-005",tblKurallar[kural_id],0)),0) | D12: adet | E12: Yuvarlama basamağı | F12: EBR-005 | G12: =IFERROR(INDEX(CHOOSE(MAX(1,MIN(3,IF(OR(hesapYili="",hesapYili=0),1,hesapYili-ebr_yilTaban))),tblKurallar[deger_2025],tblKurallar[deger_2026],tblKurallar[deger_2027]),MATCH("EBR-005",tblKurallar[kural_id],0)),0)
A13: 7 | B13: Brüt satış ham | C13: =IFERROR(GIRDI!B9,0) | D13: TL | E13: Girdi ciro | F13: EBR-001 | G13: =IFERROR(GIRDI!B9,0)
A14: 8 | B14: Yorum A ciro | C14: =IFERROR(G13*ebr_yorumACarpan,0) | D14: TL | E14: Dönem yorumu A | F14: EBR-001 | G14: =IFERROR(G13*ebr_yorumACarpan,0)
A15: 9 | B15: Yorum B ciro | C15: =IFERROR(G13,0) | D15: TL | E15: Dönem yorumu B (tam) | F15: EBR-001 | G15: =IFERROR(G13,0)
A16: 10 | B16: Seçili ciro | C16: =IFERROR(IF(GIRDI!B10="B",G15,G14),0) | D16: TL | E16: A/B seçimi | F16: EBR-001 | G16: =IFERROR(IF(GIRDI!B10="B",G15,G14),0)
A17: 11 | B17: Ciro (yuvarlanmış) | C17: =IFERROR(ROUND(G16,MAX(0,MIN(ebr_yuvarMax,IFERROR(N(G12),0)))),0) | D17: TL | E17: Yuvarlanmış ciro | F17: EBR-005 | G17: =IFERROR(ROUND(G16,MAX(0,MIN(ebr_yuvarMax,IFERROR(N(G12),0)))),0)
A18: 12 | B18: e-Fatura zorunlu mu | C18: =IFERROR(IF(G17>=G8,1,0),0) | D18: bayrak | E18: Eşik aşımı | F18: EBR-001 | G18: =IFERROR(IF(G17>=G8,1,0),0)
A19: 13 | B19: e-Arşiv zorunlu mu | C19: =IFERROR(IF(G17>=G9,1,0),0) | D19: bayrak | E19: Eşik aşımı | F19: EBR-002 | G19: =IFERROR(IF(G17>=G9,1,0),0)
A20: 14 | B20: e-Defter zorunlu mu | C20: =IFERROR(IF(G17>=G10,1,0),0) | D20: bayrak | E20: Eşik aşımı | F20: EBR-003 | G20: =IFERROR(IF(G17>=G10,1,0),0)
A21: 15 | B21: e-İrsaliye zorunlu mu | C21: =IFERROR(IF(G17>=G11,1,0),0) | D21: bayrak | E21: Eşik aşımı | F21: EBR-004 | G21: =IFERROR(IF(G17>=G11,1,0),0)
A22: 16 | B22: Zorunlu belge adedi | C22: =IFERROR(G18+G19+G20+G21,0) | D22: adet | E22: Kaç belge zorunlu | F22: EBR-001 | G22: =IFERROR(G18+G19+G20+G21,0)
A23: 17 | B23: e-Fatura mesafe | C23: =IFERROR(G17-G8,0) | D23: TL | E23: Ciro−eşik | F23: EBR-001 | G23: =IFERROR(G17-G8,0)
A24: 18 | B24: e-Arşiv mesafe | C24: =IFERROR(G17-G9,0) | D24: TL | E24: Ciro−eşik | F24: EBR-002 | G24: =IFERROR(G17-G9,0)
A25: 19 | B25: e-Defter mesafe | C25: =IFERROR(G17-G10,0) | D25: TL | E25: Ciro−eşik | F25: EBR-003 | G25: =IFERROR(G17-G10,0)
A26: 20 | B26: e-İrsaliye mesafe | C26: =IFERROR(G17-G11,0) | D26: TL | E26: Ciro−eşik | F26: EBR-004 | G26: =IFERROR(G17-G11,0)
A27: 21 | B27: En yakın eşik mesafesi | C27: =IFERROR(MIN(ABS(G23),ABS(G24),ABS(G25),ABS(G26)),0) | D27: TL | E27: Radar mesafe | F27: EBR-001 | G27: =IFERROR(MIN(ABS(G23),ABS(G24),ABS(G25),ABS(G26)),0)
A28: 22 | B28: Karar kodu | C28: =IFERROR(IF(COUNTA(tblGirdi[Alan Anahtarı])=0,"VERI_YOK",IF(G22=0,"ESIK_ALTI",IF(G22>=ebr_kararEsik,"ZORUNLU","HAZIRLIK"))),"") | D28: kod | E28: Karar kodu | F28: EBR-001 | G28: =IFERROR(IF(COUNTA(tblGirdi[Alan Anahtarı])=0,"VERI_YOK",IF(G22=0,"ESIK_ALTI",IF(G22>=ebr_kararEsik,"ZORUNLU","HAZIRLIK"))),"")
A29: 23 | B29: Karar metni | C29: =IFERROR(IF(G28="VERI_YOK","VERİ YOK",IF(G28="ESIK_ALTI","EŞİK ALTI / UYGUN",IF(G28="HAZIRLIK","HAZIRLIK / DİKKAT","ZORUNLU / GEÇİŞ"))),"") | D29: metin | E29: Kullanıcıya karar | F29: EBR-001 | G29: =IFERROR(IF(G28="VERI_YOK","VERİ YOK",IF(G28="ESIK_ALTI","EŞİK ALTI / UYGUN",IF(G28="HAZIRLIK","HAZIRLIK / DİKKAT","ZORUNLU / GEÇİŞ"))),"")
A30: 24 | B30: Gerekçe | C30: =IFERROR(IF(G28="VERI_YOK","Giriş tablosu boş — hesap yapılamaz.",IF(G28="ESIK_ALTI","Ciro tüm eşiklerin altında; zorunluluk yok.",IF(G28="HAZIRLIK","Kısmi eşik aşımı; geçiş hazırlığı önerilir.","Bir veya daha fazla e-belge zorunluluğu tetiklendi."))),"") | D30: metin | E30: Gerekçe cümlesi | F30: EBR-001 | G30: =IFERROR(IF(G28="VERI_YOK","Giriş tablosu boş — hesap yapılamaz.",IF(G28="ESIK_ALTI","Ciro tüm eşiklerin altında; zorunluluk yok.",IF(G28="HAZIRLIK","Kısmi eşik aşımı; geçiş hazırlığı önerilir.","Bir veya daha fazla e-belge zorunluluğu tetiklendi."))),"")
A31: 25 | B31: Güven skoru | C31: =IFERROR(ROUND(IF(OR(COUNTA(GIRDI!B6:B11)=0,ebr_girisBeklenen=0),0,COUNTA(GIRDI!B6:B11)/ebr_girisBeklenen*100),0),0) | D31: puan | E31: Giriş bütünlüğü | F31: EBR-005 | G31: =IFERROR(ROUND(IF(OR(COUNTA(GIRDI!B6:B11)=0,ebr_girisBeklenen=0),0,COUNTA(GIRDI!B6:B11)/ebr_girisBeklenen*100),0),0)
A32: 26 | B32: Risk skoru | C32: =IFERROR(IF(G28="VERI_YOK",0,IF(G22=0,ebr_riskDusuk,IF(G22>=ebr_kararEsik,ebr_riskYuksek,ebr_riskOrta))),0) | D32: puan | E32: Zorunluluk riski | F32: EBR-001 | G32: =IFERROR(IF(G28="VERI_YOK",0,IF(G22=0,ebr_riskDusuk,IF(G22>=ebr_kararEsik,ebr_riskYuksek,ebr_riskOrta))),0)
A33: 27 | B33: Senaryo iyimser ciro | C33: =IFERROR(G17*ebr_senaryoIyi,0) | D33: TL | E33: İyimser ciro | F33: EBR-001 | G33: =IFERROR(G17*ebr_senaryoIyi,0)
A34: 28 | B34: Senaryo kötümser ciro | C34: =IFERROR(G17*ebr_senaryoKotu,0) | D34: TL | E34: Kötümser ciro | F34: EBR-001 | G34: =IFERROR(G17*ebr_senaryoKotu,0)
A35: 29 | B35: İyimser zorunlu adet | C35: =IFERROR(IF(G33>=G8,1,0)+IF(G33>=G9,1,0)+IF(G33>=G10,1,0)+IF(G33>=G11,1,0),0) | D35: adet | E35: İyimser adet | F35: EBR-001 | G35: =IFERROR(IF(G33>=G8,1,0)+IF(G33>=G9,1,0)+IF(G33>=G10,1,0)+IF(G33>=G11,1,0),0)
A36: 30 | B36: Kötümser zorunlu adet | C36: =IFERROR(IF(G34>=G8,1,0)+IF(G34>=G9,1,0)+IF(G34>=G10,1,0)+IF(G34>=G11,1,0),0) | D36: adet | E36: Kötümser adet | F36: EBR-001 | G36: =IFERROR(IF(G34>=G8,1,0)+IF(G34>=G9,1,0)+IF(G34>=G10,1,0)+IF(G34>=G11,1,0),0)
A37: 31 | B37: M-SEN e-Fatura eşiği | C37: =IFERROR(G8*ebr_esikArtisCarpan,0) | D37: TL | E37: Eşik artışı | F37: EBR-001 | G37: =IFERROR(G8*ebr_esikArtisCarpan,0)
A38: 32 | B38: M-SEN zorunlu adet | C38: =IFERROR(IF(G17>=G37,1,0)+IF(G17>=G9,1,0)+IF(G17>=G10,1,0)+IF(G17>=G11,1,0),0) | D38: adet | E38: Kural değişimi adet | F38: EBR-001 | G38: =IFERROR(IF(G17>=G37,1,0)+IF(G17>=G9,1,0)+IF(G17>=G10,1,0)+IF(G17>=G11,1,0),0)
A39: 33 | B39: M-SEN fark (adet) | C39: =IFERROR(G38-G22,0) | D39: adet | E39: M-SEN delta | F39: EBR-001 | G39: =IFERROR(G38-G22,0)
A40: 34 | B40: Tahmin üst | C40: =IFERROR(G22*ebr_tahminUst,0) | D40: adet | E40: Tahmin üst | F40: EBR-005 | G40: =IFERROR(G22*ebr_tahminUst,0)
A41: 35 | B41: Tahmin alt | C41: =IFERROR(G22*ebr_tahminAlt,0) | D41: adet | E41: Tahmin alt | F41: EBR-005 | G41: =IFERROR(G22*ebr_tahminAlt,0)
A42: 36 | B42: Tornado: ciro etkisi | C42: =IFERROR(ABS((IF(G17*ebr_tornadoCiro>=G8,1,0)+IF(G17*ebr_tornadoCiro>=G9,1,0)+IF(G17*ebr_tornadoCiro>=G10,1,0)+IF(G17*ebr_tornadoCiro>=G11,1,0))-G22),0) | D42: adet | E42: Ciro ± etki | F42: EBR-001 | G42: =IFERROR(ABS((IF(G17*ebr_tornadoCiro>=G8,1,0)+IF(G17*ebr_tornadoCiro>=G9,1,0)+IF(G17*ebr_tornadoCiro>=G10,1,0)+IF(G17*ebr_tornadoCiro>=G11,1,0))-G22),0)
...

Sheet ENVANTER
A1: ENVANTER — e-Belge Zorunluluk Radarı
A3: e-Belge envanteri — her kaydın tek kimliği vardır
A5: BelgeId | B5: BelgeAdi | C5: KuralId | D5: DurumEtiket | E5: Aktif | F5: EsikReferans | G5: KayitDolu | H5: ZorunluBayrak
A6: EBV-00001 | B6: e-Fatura | C6: EBR-001 | D6: ZORUNLU | E6: Hayır | F6: 3000000 | G6: =IF($A6="","",1) | H6: =IF($A6="","",IF(OR($D6="ZORUNLU",$D6="HAZIRLIK"),1,0))
A7: EBV-00002 | B7: e-Arşiv | C7: EBR-002 | D7: ZORUNLU | E7: Hayır | F7: 500000 | G7: =IF($A7="","",1) | H7: =IF($A7="","",IF(OR($D7="ZORUNLU",$D7="HAZIRLIK"),1,0))
A8: EBV-00003 | B8: e-Defter | C8: EBR-003 | D8: ZORUNLU | E8: Hayır | F8: 3000000 | G8: =IF($A8="","",1) | H8: =IF($A8="","",IF(OR($D8="ZORUNLU",$D8="HAZIRLIK"),1,0))
A9: EBV-00004 | B9: e-İrsaliye | C9: EBR-004 | D9: ESIK_ALTI | E9: Hayır | F9: 10000000 | G9: =IF($A9="","",1) | H9: =IF($A9="","",IF(OR($D9="ZORUNLU",$D9="HAZIRLIK"),1,0))
A10: EBV-00005 | B10: e-Fatura (şube) | C10: EBR-001 | D10: HAZIRLIK | E10: Evet | F10: 3000000 | G10: =IF($A10="","",1) | H10: =IF($A10="","",IF(OR($D10="ZORUNLU",$D10="HAZIRLIK"),1,0))
A11: EBV-00006 | B11: e-Arşiv (perakende) | C11: EBR-002 | D11: ZORUNLU | E11: Evet | F11: 500000 | G11: =IF($A11="","",1) | H11: =IF($A11="","",IF(OR($D11="ZORUNLU",$D11="HAZIRLIK"),1,0))
A12: EBV-00007 | B12: e-Defter (yıl geçişi) | C12: EBR-003 | D12: HAZIRLIK | E12: Hayır | F12: 3000000 | G12: =IF($A12="","",1) | H12: =IF($A12="","",IF(OR($D12="ZORUNLU",$D12="HAZIRLIK"),1,0))
A13: EBV-00008 | B13: e-İrsaliye (lojistik) | C13: EBR-004 | D13: ESIK_ALTI | E13: Hayır | F13: 10000000 | G13: =IF($A13="","",1) | H13: =IF($A13="","",IF(OR($D13="ZORUNLU",$D13="HAZIRLIK"),1,0))
G14: =IF($A14="","",1) | H14: =IF($A14="","",IF(OR($D14="ZORUNLU",$D14="HAZIRLIK"),1,0))
G15: =IF($A15="","",1) | H15: =IF($A15="","",IF(OR($D15="ZORUNLU",$D15="HAZIRLIK"),1,0))
G16: =IF($A16="","",1) | H16: =IF($A16="","",IF(OR($D16="ZORUNLU",$D16="HAZIRLIK"),1,0))
G17: =IF($A17="","",1) | H17: =IF($A17="","",IF(OR($D17="ZORUNLU",$D17="HAZIRLIK"),1,0))
G18: =IF($A18="","",1) | H18: =IF($A18="","",IF(OR($D18="ZORUNLU",$D18="HAZIRLIK"),1,0))
G19: =IF($A19="","",1) | H19: =IF($A19="","",IF(OR($D19="ZORUNLU",$D19="HAZIRLIK"),1,0))
G20: =IF($A20="","",1) | H20: =IF($A20="","",IF(OR($D20="ZORUNLU",$D20="HAZIRLIK"),1,0))
G21: =IF($A21="","",1) | H21: =IF($A21="","",IF(OR($D21="ZORUNLU",$D21="HAZIRLIK"),1,0))
G22: =IF($A22="","",1) | H22: =IF($A22="","",IF(OR($D22="ZORUNLU",$D22="HAZIRLIK"),1,0))
G23: =IF($A23="","",1) | H23: =IF($A23="","",IF(OR($D23="ZORUNLU",$D23="HAZIRLIK"),1,0))
G24: =IF($A24="","",1) | H24: =IF($A24="","",IF(OR($D24="ZORUNLU",$D24="HAZIRLIK"),1,0))
G25: =IF($A25="","",1) | H25: =IF($A25="","",IF(OR($D25="ZORUNLU",$D25="HAZIRLIK"),1,0))
... G205: =IF($A205="","",1) | H205: =IF($A205="","",IF(OR($D205="ZORUNLU",$D205="HAZIRLIK"),1,0))

Sheet EYLEM_PLANI
A1: EYLEM PLANI — e-Belge Zorunluluk Radarı
A3: Geçiş eylemleri — durum makinesi + yetim + geçiş + zincir
A5: EylemId | B5: KaynakBelgeId | C5: Tarih | D5: Termin | E5: OncekiDurum | F5: Durum | G5: Sorumlu | H5: Aciklama | I5: IlkSkor | J5: HedefSkor | K5: Tutar | L5: YasGun | M5: YasKova | N5: YetimBayrak | O5: GecisUyarisi | P5: ZincirBayrak | Q5: KayitDolu
A6: EYL-00001 | B6: EBV-00001 | C6: 46240 | D6: 46238 | F6: PLANLANDI | G6: Sorumlu 2 | H6: e-Belge geçiş eylemi 1 | I6: 50 | J6: 42 | K6: 9000 | L6: =IF($A6="","",IF($C6="","",raporTarihi-$C6)) | M6: =IF($A6="","",IF($L6="","",IF($L6<=7,"0-7",IF($L6<=30,"8-30",IF($L6<=60,"31-60","60+"))))) | N6: =IF($A6="","",IF($B6="","YETİM",IF(COUNTIF(tblEnvanter[BelgeId],$B6)=0,"YETİM",""))) | O6: =IF(OR($A6="",$E6=""),"",IF(OR($E6&"|"&$F6="",COUNTIF(ListeIzinliGecis,$E6&"|"&$F6)>0),"","GEÇERSİZ GEÇİŞ")) | P6: =IF($A6="","",IF(OR($I6="",$J6=""),"",IF(ABS($J6-$I6)>zincirTolerans,"ZİNCİR KIRIK","OK"))) | Q6: =IF($A6="","",1)
A7: EYL-00002 | B7: EBV-00002 | C7: 46235 | D7: 46239 | E7: PLANLANDI | F7: DEVAM | G7: Sorumlu 3 | H7: e-Belge geçiş eylemi 2 | I7: 60 | J7: 44 | K7: 10800 | L7: =IF($A7="","",IF($C7="","",raporTarihi-$C7)) | M7: =IF($A7="","",IF($L7="","",IF($L7<=7,"0-7",IF($L7<=30,"8-30",IF($L7<=60,"31-60","60+"))))) | N7: =IF($A7="","",IF($B7="","YETİM",IF(COUNTIF(tblEnvanter[BelgeId],$B7)=0,"YETİM",""))) | O7: =IF(OR($A7="",$E7=""),"",IF(OR($E7&"|"&$F7="",COUNTIF(ListeIzinliGecis,$E7&"|"&$F7)>0),"","GEÇERSİZ GEÇİŞ")) | P7: =IF($A7="","",IF(OR($I7="",$J7=""),"",IF(ABS($J7-$I7)>zincirTolerans,"ZİNCİR KIRIK","OK"))) | Q7: =IF($A7="","",1)
A8: EYL-00003 | B8: EBV-00003 | C8: 46230 | D8: 46240 | E8: DEVAM | F8: BEKLIYOR | G8: Sorumlu 4 | H8: e-Belge geçiş eylemi 3 | I8: 70 | J8: 46 | K8: 12600 | L8: =IF($A8="","",IF($C8="","",raporTarihi-$C8)) | M8: =IF($A8="","",IF($L8="","",IF($L8<=7,"0-7",IF($L8<=30,"8-30",IF($L8<=60,"31-60","60+"))))) | N8: =IF($A8="","",IF($B8="","YETİM",IF(COUNTIF(tblEnvanter[BelgeId],$B8)=0,"YETİM",""))) | O8: =IF(OR($A8="",$E8=""),"",IF(OR($E8&"|"&$F8="",COUNTIF(ListeIzinliGecis,$E8&"|"&$F8)>0),"","GEÇERSİZ GEÇİŞ")) | P8: =IF($A8="","",IF(OR($I8="",$J8=""),"",IF(ABS($J8-$I8)>zincirTolerans,"ZİNCİR KIRIK","OK"))) | Q8: =IF($A8="","",1)
A9: EYL-00004 | B9: EBV-00004 | C9: 46225 | D9: 46241 | E9: BEKLIYOR | F9: TAMAMLANDI | G9: Sorumlu 5 | H9: e-Belge geçiş eylemi 4 | I9: 80 | J9: 80 | K9: 14400 | L9: =IF($A9="","",IF($C9="","",raporTarihi-$C9)) | M9: =IF($A9="","",IF($L9="","",IF($L9<=7,"0-7",IF($L9<=30,"8-30",IF($L9<=60,"31-60","60+"))))) | N9: =IF($A9="","",IF($B9="","YETİM",IF(COUNTIF(tblEnvanter[BelgeId],$B9)=0,"YETİM",""))) | O9: =IF(OR($A9="",$E9=""),"",IF(OR($E9&"|"&$F9="",COUNTIF(ListeIzinliGecis,$E9&"|"&$F9)>0),"","GEÇERSİZ GEÇİŞ")) | P9: =IF($A9="","",IF(OR($I9="",$J9=""),"",IF(ABS($J9-$I9)>zincirTolerans,"ZİNCİR KIRIK","OK"))) | Q9: =IF($A9="","",1)
A10: EYL-00005 | B10: EBV-00005 | C10: 46220 | D10: 46242 | E10: DEVAM | F10: IPTAL | G10: Sorumlu 1 | H10: e-Belge geçiş eylemi 5 | I10: 40 | J10: 32 | K10: 7200 | L10: =IF($A10="","",IF($C10="","",raporTarihi-$C10)) | M10: =IF($A10="","",IF($L10="","",IF($L10<=7,"0-7",IF($L10<=30,"8-30",IF($L10<=60,"31-60","60+"))))) | N10: =IF($A10="","",IF($B10="","YETİM",IF(COUNTIF(tblEnvanter[BelgeId],$B10)=0,"YETİM",""))) | O10: =IF(OR($A10="",$E10=""),"",IF(OR($E10&"|"&$F10="",COUNTIF(ListeIzinliGecis,$E10&"|"&$F10)>0),"","GEÇERSİZ GEÇİŞ")) | P10: =IF($A10="","",IF(OR($I10="",$J10=""),"",IF(ABS($J10-$I10)>zincirTolerans,"ZİNCİR KIRIK","OK"))) | Q10: =IF($A10="","",1)
A11: EYL-00006 | B11: EBV-00006 | C11: 46215 | D11: 46243 | E11: PLANLANDI | F11: DEVAM | G11: Sorumlu 2 | H11: e-Belge geçiş eylemi 6 | I11: 50 | J11: 34 | K11: 9000 | L11: =IF($A11="","",IF($C11="","",raporTarihi-$C11)) | M11: =IF($A11="","",IF($L11="","",IF($L11<=7,"0-7",IF($L11<=30,"8-30",IF($L11<=60,"31-60","60+"))))) | N11: =IF($A11="","",IF($B11="","YETİM",IF(COUNTIF(tblEnvanter[BelgeId],$B11)=0,"YETİM",""))) | O11: =IF(OR($A11="",$E11=""),"",IF(OR($E11&"|"&$F11="",COUNTIF(ListeIzinliGecis,$E11&"|"&$F11)>0),"","GEÇERSİZ GEÇİŞ")) | P11: =IF($A11="","",IF(OR($I11="",$J11=""),"",IF(ABS($J11-$I11)>zincirTolerans,"ZİNCİR KIRIK","OK"))) | Q11: =IF($A11="","",1)
A12: EYL-00007 | B12: EBV-00007 | C12: 46210 | D12: 46244 | E12: DEVAM | F12: BEKLIYOR | G12: Sorumlu 3 | H12: e-Belge geçiş eylemi 7 | I12: 60 | J12: 36 | K12: 10800 | L12: =IF($A12="","",IF($C12="","",raporTarihi-$C12)) | M12: =IF($A12="","",IF($L12="","",IF($L12<=7,"0-7",IF($L12<=30,"8-30",IF($L12<=60,"31-60","60+"))))) | N12: =IF($A12="","",IF($B12="","YETİM",IF(COUNTIF(tblEnvanter[BelgeId],$B12)=0,"YETİM",""))) | O12: =IF(OR($A12="",$E12=""),"",IF(OR($E12&"|"&$F12="",COUNTIF(ListeIzinliGecis,$E12&"|"&$F12)>0),"","GEÇERSİZ GEÇİŞ")) | P12: =IF($A12="","",IF(OR($I12="",$J12=""),"",IF(ABS($J12-$I12)>zincirTolerans,"ZİNCİR KIRIK","OK"))) | Q12: =IF($A12="","",1)
A13: EYL-00008 | B13: EBV-00008 | C13: 46205 | D13: 46245 | E13: PLANLANDI | F13: PLANLANDI | G13: Sorumlu 4 | H13: e-Belge geçiş eylemi 8 | I13: 70 | J13: 120 | K13: 12600 | L13: =IF($A13="","",IF($C13="","",raporTarihi-$C13)) | M13: =IF($A13="","",IF($L13="","",IF($L13<=7,"0-7",IF($L13<=30,"8-30",IF($L13<=60,"31-60","60+"))))) | N13: =IF($A13="","",IF($B13="","YETİM",IF(COUNTIF(tblEnvanter[BelgeId],$B13)=0,"YETİM",""))) | O13: =IF(OR($A13="",$E13=""),"",IF(OR($E13&"|"&$F13="",COUNTIF(ListeIzinliGecis,$E13&"|"&$F13)>0),"","GEÇERSİZ GEÇİŞ")) | P13: =IF($A13="","",IF(OR($I13="",$J13=""),"",IF(ABS($J13-$I13)>zincirTolerans,"ZİNCİR KIRIK","OK"))) | Q13: =IF($A13="","",1)
A14: EYL-00009 | B14: EBV-00001 | C14: 46200 | D14: 46246 | F14: PLANLANDI | G14: Sorumlu 5 | H14: e-Belge geçiş eylemi 9 | I14: 80 | J14: 72 | K14: 14400 | L14: =IF($A14="","",IF($C14="","",raporTarihi-$C14)) | M14: =IF($A14="","",IF($L14="","",IF($L14<=7,"0-7",IF($L14<=30,"8-30",IF($L14<=60,"31-60","60+"))))) | N14: =IF($A14="","",IF($B14="","YETİM",IF(COUNTIF(tblEnvanter[BelgeId],$B14)=0,"YETİM",""))) | O14: =IF(OR($A14="",$E14=""),"",IF(OR($E14&"|"&$F14="",COUNTIF(ListeIzinliGecis,$E14&"|"&$F14)>0),"","GEÇERSİZ GEÇİŞ")) | P14: =IF($A14="","",IF(OR($I14="",$J14=""),"",IF(ABS($J14-$I14)>zincirTolerans,"ZİNCİR KIRIK","OK"))) | Q14: =IF($A14="","",1)
A15: EYL-00010 | B15: EBV-00002 | C15: 46195 | D15: 46247 | E15: PLANLANDI | F15: TAMAMLANDI | G15: Sorumlu 1 | H15: e-Belge geçiş eylemi 10 | I15: 40 | J15: 24 | K15: 7200 | L15: =IF($A15="","",IF($C15="","",raporTarihi-$C15)) | M15: =IF($A15="","",IF($L15="","",IF($L15<=7,"0-7",IF($L15<=30,"8-30",IF($L15<=60,"31-60","60+"))))) | N15: =IF($A15="","",IF($B15="","YETİM",IF(COUNTIF(tblEnvanter[BelgeId],$B15)=0,"YETİM",""))) | O15: =IF(OR($A15="",$E15=""),"",IF(OR($E15&"|"&$F15="",COUNTIF(ListeIzinliGecis,$E15&"|"&$F15)>0),"","GEÇERSİZ GEÇİŞ")) | P15: =IF($A15="","",IF(OR($I15="",$J15=""),"",IF(ABS($J15-$I15)>zincirTolerans,"ZİNCİR KIRIK","OK"))) | Q15: =IF($A15="","",1)
A16: EYL-00011 | B16: EBV-00003 | C16: 46190 | D16: 46248 | E16: DEVAM | F16: BEKLIYOR | G16: Sorumlu 2 | H16: e-Belge geçiş eylemi 11 | I16: 50 | J16: 100 | K16: 9000 | L16: =IF($A16="","",IF($C16="","",raporTarihi-$C16)) | M16: =IF($A16="","",IF($L16="","",IF($L16<=7,"0-7",IF($L16<=30,"8-30",IF($L16<=60,"31-60","60+"))))) | N16: =IF($A16="","",IF($B16="","YETİM",IF(COUNTIF(tblEnvanter[BelgeId],$B16)=0,"YETİM",""))) | O16: =IF(OR($A16="",$E16=""),"",IF(OR($E16&"|"&$F16="",COUNTIF(ListeIzinliGecis,$E16&"|"&$F16)>0),"","GEÇERSİZ GEÇİŞ")) | P16: =IF($A16="","",IF(OR($I16="",$J16=""),"",IF(ABS($J16-$I16)>zincirTolerans,"ZİNCİR KIRIK","OK"))) | Q16: =IF($A16="","",1)
A17: EYL-00012 | C17: 46185 | D17: 46249 | E17: BEKLIYOR | F17: TAMAMLANDI | G17: Sorumlu 3 | H17: e-Belge geçiş eylemi 12 | I17: 60 | J17: 60 | K17: 10800 | L17: =IF($A17="","",IF($C17="","",raporTarihi-$C17)) | M17: =IF($A17="","",IF($L17="","",IF($L17<=7,"0-7",IF($L17<=30,"8-30",IF($L17<=60,"31-60","60+"))))) | N17: =IF($A17="","",IF($B17="","YETİM",IF(COUNTIF(tblEnvanter[BelgeId],$B17)=0,"YETİM",""))) | O17: =IF(OR($A17="",$E17=""),"",IF(OR($E17&"|"&$F17="",COUNTIF(ListeIzinliGecis,$E17&"|"&$F17)>0),"","GEÇERSİZ GEÇİŞ")) | P17: =IF($A17="","",IF(OR($I17="",$J17=""),"",IF(ABS($J17-$I17)>zincirTolerans,"ZİNCİR KIRIK","OK"))) | Q17: =IF($A17="","",1)
A18: EYL-00013 | B18: EBV-00005 | C18: 46180 | D18: 46250 | E18: DEVAM | F18: IPTAL | G18: Sorumlu 4 | H18: e-Belge geçiş eylemi 13 | I18: 70 | J18: 62 | K18: 12600 | L18: =IF($A18="","",IF($C18="","",raporTarihi-$C18)) | M18: =IF($A18="","",IF($L18="","",IF($L18<=7,"0-7",IF($L18<=30,"8-30",IF($L18<=60,"31-60","60+"))))) | N18: =IF($A18="","",IF($B18="","YETİM",IF(COUNTIF(tblEnvanter[BelgeId],$B18)=0,"YETİM",""))) | O18: =IF(OR($A18="",$E18=""),"",IF(OR($E18&"|"&$F18="",COUNTIF(ListeIzinliGecis,$E18&"|"&$F18)>0),"","GEÇERSİZ GEÇİŞ")) | P18: =IF($A18="","",IF(OR($I18="",$J18=""),"",IF(ABS($J18-$I18)>zincirTolerans,"ZİNCİR KIRIK","OK"))) | Q18: =IF($A18="","",1)
A19: EYL-00014 | B19: EBV-00006 | C19: 46175 | D19: 46251 | E19: TAMAMLANDI | F19: DEVAM | G19: Sorumlu 5 | H19: e-Belge geçiş eylemi 14 | I19: 80 | J19: 64 | K19: 14400 | L19: =IF($A19="","",IF($C19="","",raporTarihi-$C19)) | M19: =IF($A19="","",IF($L19="","",IF($L19<=7,"0-7",IF($L19<=30,"8-30",IF($L19<=60,"31-60","60+"))))) | N19: =IF($A19="","",IF($B19="","YETİM",IF(COUNTIF(tblEnvanter[BelgeId],$B19)=0,"YETİM",""))) | O19: =IF(OR($A19="",$E19=""),"",IF(OR($E19&"|"&$F19="",COUNTIF(ListeIzinliGecis,$E19&"|"&$F19)>0),"","GEÇERSİZ GEÇİŞ")) | P19: =IF($A19="","",IF(OR($I19="",$J19=""),"",IF(ABS($J19-$I19)>zincirTolerans,"ZİNCİR KIRIK","OK"))) | Q19: =IF($A19="","",1)
A20: EYL-00015 | B20: EBV-99999 | C20: 46170 | D20: 46252 | E20: DEVAM | F20: BEKLIYOR | G20: Sorumlu 1 | H20: e-Belge geçiş eylemi 15 | I20: 40 | J20: 16 | K20: 7200 | L20: =IF($A20="","",IF($C20="","",raporTarihi-$C20)) | M20: =IF($A20="","",IF($L20="","",IF($L20<=7,"0-7",IF($L20<=30,"8-30",IF($L20<=60,"31-60","60+"))))) | N20: =IF($A20="","",IF($B20="","YETİM",IF(COUNTIF(tblEnvanter[BelgeId],$B20)=0,"YETİM",""))) | O20: =IF(OR($A20="",$E20=""),"",IF(OR($E20&"|"&$F20="",COUNTIF(ListeIzinliGecis,$E20&"|"&$F20)>0),"","GEÇERSİZ GEÇİŞ")) | P20: =IF($A20="","",IF(OR($I20="",$J20=""),"",IF(ABS($J20-$I20)>zincirTolerans,"ZİNCİR KIRIK","OK"))) | Q20: =IF($A20="","",1)
A21: EYL-00016 | B21: EBV-00008 | C21: 46165 | D21: 46253 | E21: PLANLANDI | F21: PLANLANDI | G21: Sorumlu 2 | H21: e-Belge geçiş eylemi 16 | I21: 50 | J21: 50 | K21: 9000 | L21: =IF($A21="","",IF($C21="","",raporTarihi-$C21)) | M21: =IF($A21="","",IF($L21="","",IF($L21<=7,"0-7",IF($L21<=30,"8-30",IF($L21<=60,"31-60","60+"))))) | N21: =IF($A21="","",IF($B21="","YETİM",IF(COUNTIF(tblEnvanter[BelgeId],$B21)=0,"YETİM",""))) | O21: =IF(OR($A21="",$E21=""),"",IF(OR($E21&"|"&$F21="",COUNTIF(ListeIzinliGecis,$E21&"|"&$F21)>0),"","GEÇERSİZ GEÇİŞ")) | P21: =IF($A21="","",IF(OR($I21="",$J21=""),"",IF(ABS($J21-$I21)>zincirTolerans,"ZİNCİR KIRIK","OK"))) | Q21: =IF($A21="","",1)
L22: =IF($A22="","",IF($C22="","",raporTarihi-$C22)) | M22: =IF($A22="","",IF($L22="","",IF($L22<=7,"0-7",IF($L22<=30,"8-30",IF($L22<=60,"31-60","60+"))))) | N22: =IF($A22="","",IF($B22="","YETİM",IF(COUNTIF(tblEnvanter[BelgeId],$B22)=0,"YETİM",""))) | O22: =IF(OR($A22="",$E22=""),"",IF(OR($E22&"|"&$F22="",COUNTIF(ListeIzinliGecis,$E22&"|"&$F22)>0),"","GEÇERSİZ GEÇİŞ")) | P22: =IF($A22="","",IF(OR($I22="",$J22=""),"",IF(ABS($J22-$I22)>zincirTolerans,"ZİNCİR KIRIK","OK"))) | Q22: =IF($A22="","",1)
L23: =IF($A23="","",IF($C23="","",raporTarihi-$C23)) | M23: =IF($A23="","",IF($L23="","",IF($L23<=7,"0-7",IF($L23<=30,"8-30",IF($L23<=60,"31-60","60+"))))) | N23: =IF($A23="","",IF($B23="","YETİM",IF(COUNTIF(tblEnvanter[BelgeId],$B23)=0,"YETİM",""))) | O23: =IF(OR($A23="",$E23=""),"",IF(OR($E23&"|"&$F23="",COUNTIF(ListeIzinliGecis,$E23&"|"&$F23)>0),"","GEÇERSİZ GEÇİŞ")) | P23: =IF($A23="","",IF(OR($I23="",$J23=""),"",IF(ABS($J23-$I23)>zincirTolerans,"ZİNCİR KIRIK","OK"))) | Q23: =IF($A23="","",1)
L24: =IF($A24="","",IF($C24="","",raporTarihi-$C24)) | M24: =IF($A24="","",IF($L24="","",IF($L24<=7,"0-7",IF($L24<=30,"8-30",IF($L24<=60,"31-60","60+"))))) | N24: =IF($A24="","",IF($B24="","YETİM",IF(COUNTIF(tblEnvanter[BelgeId],$B24)=0,"YETİM",""))) | O24: =IF(OR($A24="",$E24=""),"",IF(OR($E24&"|"&$F24="",COUNTIF(ListeIzinliGecis,$E24&"|"&$F24)>0),"","GEÇERSİZ GEÇİŞ")) | P24: =IF($A24="","",IF(OR($I24="",$J24=""),"",IF(ABS($J24-$I24)>zincirTolerans,"ZİNCİR KIRIK","OK"))) | Q24: =IF($A24="","",1)
L25: =IF($A25="","",IF($C25="","",raporTarihi-$C25)) | M25: =IF($A25="","",IF($L25="","",IF($L25<=7,"0-7",IF($L25<=30,"8-30",IF($L25<=60,"31-60","60+"))))) | N25: =IF($A25="","",IF($B25="","YETİM",IF(COUNTIF(tblEnvanter[BelgeId],$B25)=0,"YETİM",""))) | O25: =IF(OR($A25="",$E25=""),"",IF(OR($E25&"|"&$F25="",COUNTIF(ListeIzinliGecis,$E25&"|"&$F25)>0),"","GEÇERSİZ GEÇİŞ")) | P25: =IF($A25="","",IF(OR($I25="",$J25=""),"",IF(ABS($J25-$I25)>zincirTolerans,"ZİNCİR KIRIK","OK"))) | Q25: =IF($A25="","",1)
L26: =IF($A26="","",IF($C26="","",raporTarihi-$C26)) | M26: =IF($A26="","",IF($L26="","",IF($L26<=7,"0-7",IF($L26<=30,"8-30",IF($L26<=60,"31-60","60+"))))) | N26: =IF($A26="","",IF($B26="","YETİM",IF(COUNTIF(tblEnvanter[BelgeId],$B26)=0,"YETİM",""))) | O26: =IF(OR($A26="",$E26=""),"",IF(OR($E26&"|"&$F26="",COUNTIF(ListeIzinliGecis,$E26&"|"&$F26)>0),"","GEÇERSİZ GEÇİŞ")) | P26: =IF($A26="","",IF(OR($I26="",$J26=""),"",IF(ABS($J26-$I26)>zincirTolerans,"ZİNCİR KIRIK","OK"))) | Q26: =IF($A26="","",1)
L27: =IF($A27="","",IF($C27="","",raporTarihi-$C27)) | M27: =IF($A27="","",IF($L27="","",IF($L27<=7,"0-7",IF($L27<=30,"8-30",IF($L27<=60,"31-60","60+"))))) | N27: =IF($A27="","",IF($B27="","YETİM",IF(COUNTIF(tblEnvanter[BelgeId],$B27)=0,"YETİM",""))) | O27: =IF(OR($A27="",$E27=""),"",IF(OR($E27&"|"&$F27="",COUNTIF(ListeIzinliGecis,$E27&"|"&$F27)>0),"","GEÇERSİZ GEÇİŞ")) | P27: =IF($A27="","",IF(OR($I27="",$J27=""),"",IF(ABS($J27-$I27)>zincirTolerans,"ZİNCİR KIRIK","OK"))) | Q27: =IF($A27="","",1)
L28: =IF($A28="","",IF($C28="","",raporTarihi-$C28)) | M28: =IF($A28="","",IF($L28="","",IF($L28<=7,"0-7",IF($L28<=30,"8-30",IF($L28<=60,"31-60","60+"))))) | N28: =IF($A28="","",IF($B28="","YETİM",IF(COUNTIF(tblEnvanter[BelgeId],$B28)=0,"YETİM",""))) | O28: =IF(OR($A28="",$E28=""),"",IF(OR($E28&"|"&$F28="",COUNTIF(ListeIzinliGecis,$E28&"|"&$F28)>0),"","GEÇERSİZ GEÇİŞ")) | P28: =IF($A28="","",IF(OR($I28="",$J28=""),"",IF(ABS($J28-$I28)>zincirTolerans,"ZİNCİR KIRIK","OK"))) | Q28: =IF($A28="","",1)
L29: =IF($A29="","",IF($C29="","",raporTarihi-$C29)) | M29: =IF($A29="","",IF($L29="","",IF($L29<=7,"0-7",IF($L29<=30,"8-30",IF($L29<=60,"31-60","60+"))))) | N29: =IF($A29="","",IF($B29="","YETİM",IF(COUNTIF(tblEnvanter[BelgeId],$B29)=0,"YETİM",""))) | O29: =IF(OR($A29="",$E29=""),"",IF(OR($E29&"|"&$F29="",COUNTIF(ListeIzinliGecis,$E29&"|"&$F29)>0),"","GEÇERSİZ GEÇİŞ")) | P29: =IF($A29="","",IF(OR($I29="",$J29=""),"",IF(ABS($J29-$I29)>zincirTolerans,"ZİNCİR KIRIK","OK"))) | Q29: =IF($A29="","",1)
L30: =IF($A30="","",IF($C30="","",raporTarihi-$C30)) | M30: =IF($A30="","",IF($L30="","",IF($L30<=7,"0-7",IF($L30<=30,"8-30",IF($L30<=60,"31-60","60+"))))) | N30: =IF($A30="","",IF($B30="","YETİM",IF(COUNTIF(tblEnvanter[BelgeId],$B30)=0,"YETİM",""))) | O30: =IF(OR($A30="",$E30=""),"",IF(OR($E30&"|"&$F30="",COUNTIF(ListeIzinliGecis,$E30&"|"&$F30)>0),"","GEÇERSİZ GEÇİŞ")) | P30: =IF($A30="","",IF(OR($I30="",$J30=""),"",IF(ABS($J30-$I30)>zincirTolerans,"ZİNCİR KIRIK","OK"))) | Q30: =IF($A30="","",1)
L31: =IF($A31="","",IF($C31="","",raporTarihi-$C31)) | M31: =IF($A31="","",IF($L31="","",IF($L31<=7,"0-7",IF($L31<=30,"8-30",IF($L31<=60,"31-60","60+"))))) | N31: =IF($A31="","",IF($B31="","YETİM",IF(COUNTIF(tblEnvanter[BelgeId],$B31)=0,"YETİM",""))) | O31: =IF(OR($A31="",$E31=""),"",IF(OR($E31&"|"&$F31="",COUNTIF(ListeIzinliGecis,$E31&"|"&$F31)>0),"","GEÇERSİZ GEÇİŞ")) | P31: =IF($A31="","",IF(OR($I31="",$J31=""),"",IF(ABS($J31-$I31)>zincirTolerans,"ZİNCİR KIRIK","OK"))) | Q31: =IF($A31="","",1)
L32: =IF($A32="","",IF($C32="","",raporTarihi-$C32)) | M32: =IF($A32="","",IF($L32="","",IF($L32<=7,"0-7",IF($L32<=30,"8-30",IF($L32<=60,"31-60","60+"))))) | N32: =IF($A32="","",IF($B32="","YETİM",IF(COUNTIF(tblEnvanter[BelgeId],$B32)=0,"YETİM",""))) | O32: =IF(OR($A32="",$E32=""),"",IF(OR($E32&"|"&$F32="",COUNTIF(ListeIzinliGecis,$E32&"|"&$F32)>0),"","GEÇERSİZ GEÇİŞ")) | P32: =IF($A32="","",IF(OR($I32="",$J32=""),"",IF(ABS($J32-$I32)>zincirTolerans,"ZİNCİR KIRIK","OK"))) | Q32: =IF($A32="","",1)
L33: =IF($A33="","",IF($C33="","",raporTarihi-$C33)) | M33: =IF($A33="","",IF($L33="","",IF($L33<=7,"0-7",IF($L33<=30,"8-30",IF($L33<=60,"31-60","60+"))))) | N33: =IF($A33="","",IF($B33="","YETİM",IF(COUNTIF(tblEnvanter[BelgeId],$B33)=0,"YETİM",""))) | O33: =IF(OR($A33="",$E33=""),"",IF(OR($E33&"|"&$F33="",COUNTIF(ListeIzinliGecis,$E33&"|"&$F33)>0),"","GEÇERSİZ GEÇİŞ")) | P33: =IF($A33="","",IF(OR($I33="",$J33=""),"",IF(ABS($J33-$I33)>zincirTolerans,"ZİNCİR KIRIK","OK"))) | Q33: =IF($A33="","",1)
... L205: =IF($A205="","",IF($C205="","",raporTarihi-$C205)) | M205: =IF($A205="","",IF($L205="","",IF($L205<=7,"0-7",IF($L205<=30,"8-30",IF($L205<=60,"31-60","60+"))))) | N205: =IF($A205="","",IF($B205="","YETİM",IF(COUNTIF(tblEnvanter[BelgeId],$B205)=0,"YETİM",""))) | O205: =IF(OR($A205="",$E205=""),"",IF(OR($E205&"|"&$F205="",COUNTIF(ListeIzinliGecis,$E205&"|"&$F205)>0),"","GEÇERSİZ GEÇİŞ")) | P205: =IF($A205="","",IF(OR($I205="",$J205=""),"",IF(ABS($J205-$I205)>zincirTolerans,"ZİNCİR KIRIK","OK"))) | Q205: =IF($A205="","",1)

Sheet AKIS
A1: AKIS — e-Belge Zorunluluk Radarı
A3: Eylem akış özeti — KAYNAK_KART_ID / yetim / kuyruk
A5: KAYNAK_KART_ID kontrolü
A6: Yetim (YETİM) adet | B6: =COUNTIF(tblEylem[YetimBayrak],"YETİM")
A7: Geçersiz geçiş | B7: =COUNTIF(tblEylem[GecisUyarisi],"GEÇERSİZ GEÇİŞ")
A8: Zincir kırık | B8: =COUNTIF(tblEylem[ZincirBayrak],"ZİNCİR KIRIK")
A10: Kuyruk | B10: Adet | C10: Tutar
A11: Planlandı | B11: =COUNTIFS(tblEylem[durum],"PLANLANDI",tblEylem[tutar],">0") | C11: =SUMIFS(tblEylem[tutar],tblEylem[durum],"PLANLANDI")
A12: Devam | B12: =COUNTIFS(tblEylem[durum],"DEVAM",tblEylem[tutar],">0") | C12: =SUMIFS(tblEylem[tutar],tblEylem[durum],"DEVAM")
A13: Bekliyor | B13: =COUNTIFS(tblEylem[durum],"BEKLIYOR",tblEylem[tutar],">0") | C13: =SUMIFS(tblEylem[tutar],tblEylem[durum],"BEKLIYOR")
A15: Kapalı (Tamamlandı+İptal) kuyruktan düşer
A16: Tamamlandı | B16: =COUNTIFS(tblEylem[durum],"TAMAMLANDI",tblEylem[tutar],">0")
A17: İptal | B17: =COUNTIFS(tblEylem[durum],"IPTAL",tblEylem[tutar],">0")

Sheet SENARYO
A1: SENARYO — e-Belge Zorunluluk Radarı
A3: Senaryo ve duyarlılık
A5: Senaryo | B5: Ciro Çarpanı | C5: Zorunlu Adet | D5: Karar | G5: AdetDemo
A6: İyimser | B6: =IFERROR(ebr_senaryoIyi+N(GIRDI!B9)*0,0.9) | C6: =IFERROR(MOTOR!G35,0) | D6: =IF(COUNTA(tblGirdi[Alan Anahtarı])=0,"VERİ YOK",IF(C6=0,"EŞİK ALTI","ZORUNLU")) | G6: 2
A7: Baz | B7: =IFERROR(1+N(GIRDI!B9)*0,1) | C7: =IFERROR(ebr_zorunluAdet,0) | D7: =IF(COUNTA(tblGirdi[Alan Anahtarı])=0,"VERİ YOK",IF(C7=0,"EŞİK ALTI","ZORUNLU")) | G7: 3
A8: Kötümser | B8: =IFERROR(ebr_senaryoKotu+N(GIRDI!B9)*0,1.1) | C8: =IFERROR(MOTOR!G36,0) | D8: =IF(COUNTA(tblGirdi[Alan Anahtarı])=0,"VERİ YOK",IF(C8=0,"EŞİK ALTI","ZORUNLU")) | G8: 4
A9: M-SEN eşik artışı | B9: =IFERROR(1+N(GIRDI!B9)*0,1) | C9: =IFERROR(MOTOR!G38,0) | D9: =IF(COUNTA(tblGirdi[Alan Anahtarı])=0,"VERİ YOK",IF(C9=0,"EŞİK ALTI","ZORUNLU")) | G9: 2
A11: Senaryo bant (kötümser−iyimser) | B11: =IFERROR(C8-C6,0)
A12: Senaryo yorumu | B12: =_xlfn.TEXTJOIN("; ",TRUE,"İyimser ",TEXT(C6,"0")," · Baz ",TEXT(C7,"0")," · Kötümser ",TEXT(C8,"0")," · Bant ",TEXT(B11,"0"))
A14: Duyarlılık (tornado)
A15: Değişken | B15: Etki | C15: Sıra
A16: Tornado ciro etkisi | B16: =IFERROR(MOTOR!G42,0) | C16: =IFERROR(IF(B16>=MAX(B16:B18),1,IF(B16=MEDIAN(B16:B18),2,3)),3)
A17: Tornado eşik etkisi | B17: =IFERROR(MOTOR!G43,0) | C17: =IFERROR(IF(B17>=MAX(B16:B18),1,IF(B17=MEDIAN(B16:B18),2,3)),3)
A18: Tornado yorum etkisi | B18: =IFERROR(MOTOR!G44,0) | C18: =IFERROR(IF(B18>=MAX(B16:B18),1,IF(B18=MEDIAN(B16:B18),2,3)),3)
A19: Duyarlılık sıra özeti | B19: =IFERROR(CONCATENATE("1)",INDEX(A16:A18,MATCH(1,C16:C18,0))," 2)",INDEX(A16:A18,MATCH(2,C16:C18,0))),"-")
A20: Duyarlılık yorumu | B20: =_xlfn.TEXTJOIN("; ",TRUE,"En yüksek etki ",TEXT(MAX(B16:B18),"0")," — öncelik bu değişkende")
A22: M-SEN kural değişimi farkı | B22: =IFERROR(MOTOR!G39,0)
A23: M-SEN yorumu | B23: =_xlfn.TEXTJOIN("; ",TRUE,"Eşik artışı senaryosunda zorunlu adet farkı ",TEXT(B22,"0"))
A25: Tahmin aralığı | B25: =MOTOR!G41 | C25: =ebr_zorunluAdet | D25: =MOTOR!G40
A28: 1 | B28: =C6
A29: 2 | B29: =C7
A30: 3 | B30: =C8
A31: 4 | B31: =C9
A32: Tahmin sonraki | B32: =IFERROR(FORECAST.LINEAR(5,B28:B31,A28:A31),0)
A33: Tahmin yorumu | B33: =_xlfn.TEXTJOIN("; ",TRUE,"Tahmin ",TEXT(B32,"0")," · Alt ",TEXT(B25,"0")," · Üst ",TEXT(D25,"0"))

Sheet VAKALAR
A1: VAKALAR — e-Belge Zorunluluk Radarı
A3: Tebliğ tarzı altın vakalar
A5: vaka_id | B5: aciklama | C5: girdi_ozeti | D5: beklenen_sonuc | E5: hesaplanan | F5: fark | G5: durum | H5: kaynak
A6: V-001 | B6: Ciro 4.5M — e-Fatura zorunlu | C6: ciro=vaka_ciro_1; eşik=EBR-001/2025 | D6: 1 | E6: =IFERROR(IF(vaka_ciro_1>=INDEX(tblKurallar[deger_2025],MATCH("EBR-001",tblKurallar[kural_id],0)),1,0),0) | F6: =IFERROR(D6-E6,0) | G6: =IFERROR(IF(ABS(F6)<=ebr_tolerans,"TUTARLI","KIRIK"),"KIRIK") | H6: GİB e-Fatura örnek
A7: V-002 | B7: Ciro 400K — e-Arşiv altı | C7: ciro=vaka_ciro_2; eşik=EBR-002/2025 | D7: 0 | E7: =IFERROR(IF(vaka_ciro_2>=INDEX(tblKurallar[deger_2025],MATCH("EBR-002",tblKurallar[kural_id],0)),1,0),0) | F7: =IFERROR(D7-E7,0) | G7: =IFERROR(IF(ABS(F7)<=ebr_tolerans,"TUTARLI","KIRIK"),"KIRIK") | H7: GİB e-Arşiv örnek
A8: V-003 | B8: Ciro 600K — e-Arşiv zorunlu | C8: ciro=vaka_ciro_3; eşik=EBR-002/2025 | D8: 1 | E8: =IFERROR(IF(vaka_ciro_3>=INDEX(tblKurallar[deger_2025],MATCH("EBR-002",tblKurallar[kural_id],0)),1,0),0) | F8: =IFERROR(D8-E8,0) | G8: =IFERROR(IF(ABS(F8)<=ebr_tolerans,"TUTARLI","KIRIK"),"KIRIK") | H8: GİB e-Arşiv örnek
A9: V-004 | B9: Ciro 11M — e-İrsaliye zorunlu | C9: ciro=vaka_ciro_4; eşik=EBR-004/2025 | D9: 1 | E9: =IFERROR(IF(vaka_ciro_4>=INDEX(tblKurallar[deger_2025],MATCH("EBR-004",tblKurallar[kural_id],0)),1,0),0) | F9: =IFERROR(D9-E9,0) | G9: =IFERROR(IF(ABS(F9)<=ebr_tolerans,"TUTARLI","KIRIK"),"KIRIK") | H9: GİB e-İrsaliye örnek
A12: Vaka durum özeti | B12: =_xlfn.TEXTJOIN(" | ",TRUE,IF(G6="TUTARLI","V1 OK",G6),IF(G7="TUTARLI","V2 OK",G7),IF(G8="TUTARLI","V3 OK",G8),IF(G9="TUTARLI","V4 OK",G9))
A13: Vaka fark toplamı | B13: =IFERROR(SUM(F6:F9),0)

Sheet KANIT_RAPORU
A1: KANIT RAPORU — e-Belge Zorunluluk Radarı
A3: Denetim Kanıt Raporu — e-Belge Zorunluluk
A4: Ürün | B4: e-Belge Zorunluluk Radarı
A5: Sürüm | B5: 1.0.0
A6: Rapor türü | B6: Kanıt çıktısı — müşteriye/imza için
A7: Ortam | B7: Çevrimdışı · makro yok · telemetri yok
A8: Firma | B8: =GIRDI!B6
A9: Karar | B9: =ebr_kararMetni
A10: Gerekçe | B10: =ebr_kararGerekce
A12: Brüt Satış | B12: =ebr_ciro
A13: Zorunlu Adet | B13: =ebr_zorunluAdet
A14: Madde Atıf | B14: =ebr_maddeAtifMetni
A15: Kanıt Özeti | B15: =ebr_kanitRaporu
