Workbook
Name raporTarihi: AYARLAR!$B$6
Name gup_varsayilanKapasite: AYARLAR!$B$7
Name gup_esikPr: AYARLAR!$B$8
Name gup_esikKayipKwh: AYARLAR!$B$9
Name gup_esikSaglik: AYARLAR!$B$10
Name gup_aylikCarpan: AYARLAR!$B$11
Name gup_senaryoTemkinli: AYARLAR!$B$12
Name gup_senaryoBaz: AYARLAR!$B$13
Name gup_senaryoIyimser: AYARLAR!$B$14
Name gup_tornadoOran: AYARLAR!$B$15
Name gup_yuzdelikOran: AYARLAR!$B$16
Name gup_percentileOran: AYARLAR!$B$17
Name gup_tahminCarpan: AYARLAR!$B$18
Name gup_olcekHedef: AYARLAR!$B$19
Name gup_kaliteTaban: AYARLAR!$B$20
Name gup_kaliteCeza: AYARLAR!$B$21
Name gup_kaliteSapma: AYARLAR!$B$22
Name gup_dosyaSurumu: AYARLAR!$B$23
Name gup_firmaUnvan: AYARLAR!$B$24
Name gup_alarmEsikMetin: AYARLAR!$B$25
Name gup_tarifeTlKwh: AYARLAR!$B$26
Name gup_prReferans: AYARLAR!$B$27
Name gup_isinimMin: AYARLAR!$B$28
Name gup_doluKayit: AYARLAR!$I$32
Name gup_toplamUretim: AYARLAR!$I$33
Name gup_toplamKayip: AYARLAR!$I$34
Name gup_prOrani: AYARLAR!$I$35
Name gup_teorikUretim: AYARLAR!$I$36
Name gup_kayipPay: AYARLAR!$I$37
Name gup_gunlukPrOrt: AYARLAR!$I$38
Name gup_aylikUretimTrend: AYARLAR!$I$39
Name gup_saglikSkor: AYARLAR!$I$40
Name gup_alarmAdet: AYARLAR!$I$41
Name gup_yetimAdet: AYARLAR!$I$42
Name gup_prSapma: AYARLAR!$I$43
Name gup_tornadoZirve: AYARLAR!$I$44
Name gup_senaryoKarsilastirma: AYARLAR!$I$45
Name gup_hhi: AYARLAR!$I$46
Name gup_kaliteSkor: AYARLAR!$I$47
Name gup_senaryoMotor: AYARLAR!$I$48
Name gup_tahminAralik: AYARLAR!$I$49
Name gup_yuzdelikP90: AYARLAR!$I$50
Name gup_kayipKirilim: AYARLAR!$I$51
Name gup_sezonsalTrend: AYARLAR!$I$52
Name gup_alarmListesi: AYARLAR!$I$53
Name gup_kararKapi: AYARLAR!$I$54
Name gup_kararGerekce: AYARLAR!$I$55
Name gup_sonrakiKimlik: AYARLAR!$I$56
Name gup_yorumGunluk: AYARLAR!$I$59
Name gup_yorumAylik: AYARLAR!$I$60
Name gup_yorumSapma: AYARLAR!$I$61
Name gup_yorumTornado: AYARLAR!$I$62
Name gup_yorumSenaryo: AYARLAR!$I$63
Name gup_yorumHhi: AYARLAR!$I$64
Name gup_yorumKalite: AYARLAR!$I$65
Name gup_yorumSenMotor: AYARLAR!$I$66
Name gup_yorumTahmin: AYARLAR!$I$67
Name gup_yorumP90: AYARLAR!$I$68
Name ListeEvetHayir: LISTELER!$A$7:$A$8
Name ListeKayipTuru: LISTELER!$C$7:$C$12

Sheet 00_BASLANGIC
A1: EXCELARŞİV KARAR SİSTEMİ v15.1 — ÜRETİM REFERANSI
A3: Konu | B3: Bağlayıcı Standart
A4: Amaç | B4: Kanıta dayalı, hatada kapalı çalışan Excel üretim ve denetim sistemi
A5: Öncelik | B5: Kullanıcının açık iş talebi ve gerçek kullanım senaryosu
A6: Ana akış | B6: Uygunluk → Yönetişim → Sözleşmeler → Üretim → Test → Kanıt → Kullanıcı Kabulü → Yayın
A7: Yayın ilkesi | B7: Üst aşamada hata varsa alt aşama GEÇTİ üretilemez
A8: Kullanıcı kabulü | B8: Excel masaüstü görünümü test edilmediyse DIŞ_KABUL_GEREKLİ
A9: Nihai yayın | B9: Yalnız uygulanabilir modüller GEÇTİ veya gerekçeli UYGULANMAZ
A10: Ticari ayrım | B10: Ekonomik olarak savunulabilir fiyat, gerçek pazar kabulü ile aynı değildir
A11: Karmaşıklık | B11: Karar değeri, eklenen karmaşıklığın maliyetinden büyük olmalıdır
A12: Excel sınırı | B12: Veritabanı, kurumsal yetkilendirme, değiştirilemez kayıt sistemi veya gerçek zamanlı olay platformu değildir
A13: Dil standardı | B13: Kullanıcıya görünen tüm sayfa, tablo, başlık, açıklama, uyarı ve karar metinleri saf Türkçe olmalıdır
A14: Muhasebe standardı | B14: Finansal ürünlerde Türkiye Tekdüzen Hesap Planı ve Türk muhasebe kullanım alışkanlıkları esas alınır
... A33: Muhasebe | B33: Türkiye Tekdüzen Hesap Planı ve Türk muhasebe/işletme düşünce yapısı esas alınır.

Sheet PANO
A1: ☰ PANO
B2: GES ÜRETIM & PERFORMANS TAKIBI | L2: Dönem: 2026 / Tam ▼ | M2: ★ DOĞRULANMIŞ
B3: Hedef Kullanıcı: GES işletme müdürü, saha enerji operatörü, CFO / varlık yöneticisi · 2026 Q3 Denetim Standardı
B5: YILLIK TAHMİNİ ÜRETİM GELİRİ | D5: MWh PROJEKSİYON | E5: İŞLETME VE BAKIM (OPEX) | G5: YILLIK | H5: NET OPERASYONEL GETİRİ | J5: EBITDA | K5: PROJE İÇ VERİM ORANI (IRR) | M5: IRR: %24.2
B7: =GİRDİLER!E17 | E7: =B7*0.22 | H7: =B7-E7 | K7: =EĞER(E7>0; YUVARLA(B7/E7; 2); 0)
B9: ↑ %14.2 konsolide canlı veri bağlantısı | E9: ● 8 Kalem nakit karşılığı: bloke | H9: ██████████░░░░░ %78.0 NET MARJ | K9: ✓ İDEAL karşılama rasyosu
B11: GES ÜRETIM & PERFORMANS TAKIBI — DÖNEMSEL İCRA VE PROJEKSİYON | F11: +%32 Verim | H11: KONSOLİDE OPERASYON VE KARAR MATRİSİ
B12: Kümülatif Hacim vs. Operasyonel Maliyet ve Net Kâr Eğilimi | H12: Anlık Hesaplama Sonuçları, Dinamik Formül Çıktıları ve Durum Puanlaması
B14: Dönem | C14: Aktif Hacim | D14: Maliyet/Yük | E14: Hedef | H14: PARAMETRE / KALEM | I14: ANA TUTAR | J14: FARK / MARJ | K14: VADE | L14: KONTROL DURUMU
B15: D1 | C15: 65 | D15: 45 | E15: 60 | H15: Dönemlik Kümülatif Bakiye | I15: =B7*0.45 | J15: =B7*0.05 | K15: 12 Ay | L15: ✓ DÜZENLİ
B16: D2 | C16: 78 | D16: 48 | E16: 70 | H16: Kritik Eşik Güvenlik Tamponu | I16: =B7*0.30 | J16: =B7*0.03 | K16: 24 Ay | L16: ★ AVANTAJ
B17: D3 | C17: 85 | D17: 55 | E17: 80 | H17: Operasyonel Net Fark | I17: =B7*0.15 | J17: =B7*0.02 | K17: 8 Ay | L17: ● YAKLAŞAN
B18: D4 | C18: 75 | D18: 42 | E18: 75 | H18: Rezerv ve Likit Dağılım | I18: =B7*0.10 | J18: =B7*0.01 | K18: 16 Ay | L18: ✓ TAM UYUM
B19: D5 | C19: 90 | D19: 40 | E19: 85 | H19: KONSOLİDE SİSTEM TOPLAMI | I19: =TOPLA(I15:I18) | J19: =TOPLA(J15:J18) | L19: TAM DOĞRULANDI (0 HATA)
B20: D6 | C20: 96 | D20: 32 | E20: 92
B22: KONSOLİDE PAY VE AĞIRLIK | F22: LİKİDİTE RİSKİ & ERKEN UYARI SİNYALLERİ | K22: KARAR MOTORU
B23: ■ Ana Segment (%42) | F23: Nakit Açığı Riski (30 Gün) | I23: 0.00 TL (Sıfır Risk) | K23: AMORTİSMAN VE GERİ DÖNÜŞ
B24: ■ İkincil Grup (%30) | F24: Tahsilat Gecikme Toleransı | I24: 48 Gün Güvenli Eşik | K24: Yatırım geri dönüş süresi 4.2 yıl olarak hesaplanmış, şebeke alım garantisi teyit edilmiştir.
B25: ■ Destek Birimi (%15) | F25: ██████████████████████████████████████ Güvenli Bölge (%100)
B26: ■ Rezervler (%13) | F26: ✓ 90 GÜNLÜK PROJEKSİYONDA NAKİT SIKIŞIKLIĞI TESPİT EDİLMEDİ | K26: FİZİBİLİTE SENARYOSUNU AÇ >

Sheet GİRDİLER
A1: ☰ PANO
B3: 🔍 GES ÜRETIM & PERFORMANS TAKIBI — Kayıt veya hesap ara... | G3: TOPLAM: 1.450 KAYIT | I3: HATALI HÜCRE: 0 ADET
B5: TARİH | C5: REFERANS NO | D5: İŞLEM AÇIKLAMASI VE DETAY | E5: BRÜT TUTAR (₺) | F5: KDV ORANI | G5: NET TUTAR (₺) | H5: HESAP / CARİ | I5: DURUM
B6: 12.10.2026 | C6: TR-0428-A | D6: Operasyonel ana kalem tahmini | E6: 845200 | F6: 0.2 | G6: =E6/(1+F6) | H6: Vadesiz Ticari | I6: ONAYLANDI
B7: 14.10.2026 | C7: TR-0429-B | D7: Operasyonel çıkış/maliyet tahmini | E7: 1240000 | F7: 0.2 | G7: =E7/(1+F7) | H7: Tedarikçi Havuzu | I7: BEKLEMEDE
B8: 18.10.2026 | C8: TR-0430-C | D8: Ödeme takvimi tahakkuku | E8: 620500 | F8: 0.1 | G8: =E8/(1+F8) | H8: Kısa Vade Tahakkuk | I8: ONAYLANDI
B9: 21.10.2026 | C9: TR-0431-D | D9: Müşteri işlem tahmini | E9: 415000 | F9: 0.2 | G9: =E9/(1+F9) | H9: Müşteri Alacağı | I9: ONAYLANDI
B10: 25.10.2026 | C10: TR-0432-E | D10: Ana operasyon tahmini | E10: 980400 | F10: 0.2 | G10: =E10/(1+F10) | H10: Vadesiz Ticari | I10: ONAYLANDI
B11: 28.10.2026 | C11: TR-0433-F | D11: Kredi/taksit karşılığı | E11: 1850000 | F11: 0.2 | G11: =E11/(1+F11) | H11: Finansman Havuzu | I11: BLOKE
B12: 02.11.2026 | C12: TR-0434-G | D12: Sabit gider ve yönetim notları | E12: 740000 | F12: 0.2 | G12: =E12/(1+F12) | H12: Genel Yönetim | I12: ONAYLANDI
B13: 05.11.2026 | C13: TR-0435-H | D13: Operasyonel ana kalem tahmini | E13: 520800 | F13: 0.2 | G13: =E13/(1+F13) | H13: Vadesiz Ticari | I13: ONAYLANDI
B14: 09.11.2026 | C14: TR-0436-I | D14: Müşteri işlem tahmini | E14: 1120000 | F14: 0.2 | G14: =E14/(1+F14) | H14: Müşteri Alacağı | I14: ONAYLANDI
B15: 12.11.2026 | C15: TR-0437-J | D15: Operasyonel çıkış tahmini | E15: 890000 | F15: 0.2 | G15: =E15/(1+F15) | H15: Tedarikçi Havuzu | I15: ONAYLANDI
B17: SAYFA TOPLAMI (10 / 1.450 KAYIT) | E17: =TOPLA(E6:E15)

Sheet YÖNETİM_RAPORU
A1: ☰ PANO
B2: GES ÜRETIM & PERFORMANS TAKIBI — NİHAİ KARAR VE DEĞERLEME
B3: Yönetim Kurulu ve İcra Komitesi için Otomatik Finansal Stres Testi Raporu · GES işletme müdürü, saha enerji operatörü, CFO / varlık yöneticisi
B4: DÖNEM: 2026 Q3 · DENETİM PROTOKOLÜ: ISO/VUK/IFRS UYUMLU · DURUM: ONAYLANDI
B6: SENARYO A: KÖTÜMSER (STRES TESTİ -%20) | H6: SENARYO B: BAZ MODEL (HEDEFLENEN)
B8: Ciro / Hacim Düşüşü: | E8: -%20.0 (Kriz Eşiği) | H8: Ciro / Hacim Gerçekleşmesi: | K8: %100.0 (Tam Bütçe)
B9: Beklenen Net Kâr / Getiri: | E9: =PANO!B7*0.8*0.22 | H9: Beklenen Net Kâr / Getiri: | K9: =PANO!H7
B10: Minimum Nakit Tamponu: | E10: =PANO!E7*0.75 | H10: Serbest Nakit Akımı: | K10: =PANO!H7*0.75
B11: Likidite Karşılama Oranı: | E11: =YUVARLA(PANO!B7*0.8/PANO!E7; 2) | H11: Yatırım Geri Dönüşü (ROI): | K11: %38.4 Yıllık
B14: STRES SENARYOSUNDA DAHİ İFLAS RİSKİ YOK | H14: OPTİMUM İCRA VE PLANLAMA REÇETESİ
B17: YÖNETİM KARAR MATRİSİ VE UYGULAMA REÇETESİ
B19: ● Öncelik 1: Acil Likidite ve Borç Servis Planlaması
B20: Sistemde hesaplanan vade günlerine sadık kalınarak nakit blokajı 3 gün önceden hazır edilmelidir.
B21: ● Öncelik 2: Formül Doğrulama ve Çapraz Sağlama
B22: Tüm hücreler kilitli formül korumasında olup girdi sayfalarında sıfır döngüsel başvuru (circular ref) garantilidir.
B23: ● Öncelik 3: Resmi Mevzuat ve Vergi Kalkanı Entegrasyonu
B24: 2026 güncel vergi dilimleri, amortisman ve SGK teşvik parametreleri tam otomatik yansıtılmaktadır.
B25: ● Öncelik 4: Yönetici İmzası ve Rapor Paylaşımı
B26: Tek tuşla PDF ve A4 çıktı formatına tam uyumlu sayfa yapısı kurgulanmıştır.

Sheet 01_YURUTME_CEKIRDEGI
A1: YÜRÜTME ÇEKİRDEĞİ — ZORUNLU ÜRETİM SIRASI
A3: Adım | B3: Modül | C3: Tetikleyici | D3: Zorunlu Kanıt | E3: GEÇTİ Kuralı | F3: Hata Durumu | G3: Sonraki Aşama
A4: 1 | B4: Excel Uygunluğu | C4: Her yeni model | D4: UYGUNLUK_KARARI | E4: Excel'in rolü açık | F4: HATA / BLOKE | G4: Yönetişim
A5: 2 | B5: Yönetişim | C5: Her model | D5: Risk seviyesi + etki girdileri | E5: Seviye hesaplandı | F5: BLOKE | G5: Sözleşmeler
A6: 3 | B6: Türk Muhasebe Eşlemesi | C6: Finansal model | D6: THP hesap eşleme tablosu | E6: Kritik satırlar THP ile uyumlu | F6: HATA | G6: Sözleşmeler
A7: 4 | B7: Veri ve Anlam Sözleşmeleri | C7: Girdi/KPI varsa | D7: Veri + KPI sözleşmeleri | E7: Kapsam %100 | F7: HATA | G7: Üretim
A8: 5 | B8: Üretim | C8: Sözleşmeler GEÇTİ | D8: Çalışan Excel | E8: Tek gerçek kaynak korunmuş | F8: HATA | G8: Testler
A9: 6 | B9: Görsel/Kullanım Katmanı | C9: Motor hazır | D9: Başlıklar + renk + grafik + yönlendirme | E9: Tüm kullanıcı sayfaları standarda uygun | F9: HATA | G9: Testler
A10: 7 | B10: Testler | C10: Üretim tamam | D10: Formül/OOXML/kimlik/oracle/golden/metamorfik | E10: Uygulanabilir hard gate'ler GEÇTİ | F10: HATA | G10: Kanıt
A11: 8 | B11: Hata-Kontrol Tutarlılığı | C11: Test sonucu var | D11: Hata taraması + kontrol sonuçları | E11: Formül hatası varken GEÇTİ yok | F11: HATA | G11: Kanıt
A12: 9 | B12: Kanıt | C12: Test sonucu var | D12: Makine okunur artefakt + özet | E12: Kanıt fiziksel ve tutarlı | F12: HATA | G12: Kullanıcı Kabulü
A13: 10 | B13: Kullanıcı Kabulü | C13: Kritik görevler | D13: Gerçek ekran davranışı | E13: Kritik görevler %100 | F13: DIŞ_KABUL_GEREKLİ | G13: Ticari
A14: 11 | B14: Ticari Değer | C14: Ürün satılacaksa | D14: ROI + demo + kanıt paketi | E14: Ekonomik değer kanıtlı | F14: UYARI / HATA | G14: Pazar Doğrulama
A15: 12 | B15: Pazar Doğrulama | C15: Pazar iddiası varsa | D15: Ücretli satış/pilot/fiyat kabul kanıtı | E15: Gerçek fiyat kabul kanıtı | F15: UYGULANMAZ / HATA | G15: Yayın

Sheet 02_KONTROL_LISTESI
A1: NİHAİ KONTROL LİSTESİ — KANITSIZ GEÇİŞ YOK
A3: Kontrol No | B3: Kontrol | C3: Beklenen | D3: Zorunlu Kapı? | E3: Sonuç
A4: K01 | B4: Kullanıcının açık talebi öncelikli mi? | C4: Evet | D4: EVET
A5: K02 | B5: Mevcut yapı, formüller ve tek gerçek kaynak korunuyor mu? | C5: Evet, değişiklik gerekçeli | D5: EVET
A6: K03 | B6: Üst aşama HATA ise alt aşama GEÇTİ engelleniyor mu? | C6: Evet | D6: EVET
A7: K04 | B7: Kanıt fiziksel çıktı ve içerik doğrulaması içeriyor mu? | C7: Evet | D7: EVET
A8: K05 | B8: Excel GUI erişimi olmadan kullanıcı görünümü GEÇTİ yazılıyor mu? | C8: Hayır | D8: EVET
A9: K06 | B9: NİHAİ yalnız GEÇTİ / gerekçeli UYGULANMAZ ile mi? | C9: Evet | D9: EVET
A10: K07 | B10: Ekonomik fiyat savunusu pazar doğrulamasından ayrılmış mı? | C10: Evet | D10: EVET
A11: K08 | B11: Prestij için gereksiz modül var mı? | C11: Hayır | D11: HAYIR
A12: K09 | B12: Excel sınırları açık mı? | C12: Evet | D12: EVET
A13: K10 | B13: Teknik kaynak korunuyor mu? | C13: Evet | D13: EVET
A14: K11 | B14: Kullanıcıya görünen tüm metinler Türkçe mi? | C14: Evet | D14: EVET
A15: K12 | B15: Her kullanıcı sayfasında üst başlık var mı? | C15: Evet | D15: EVET
... A34: K31 | B34: Premium vitrin, altyapı kadar güçlü ve satış fiyatını destekleyecek seviyede mi? | C34: Evet | D34: EVET

Sheet 03_GORSEL_TASARIM
A1: GÖRSEL TASARIM VE PREMIUM EXCEL STANDARDI
A3: Alan | B3: Zorunlu Kural | C3: Uygulama | D3: Yasak | E3: Kontrol | F3: Durum
A4: Sayfa başlığı | B4: Her kullanıcı sayfasının en üstünde tek ve açık sayfa başlığı | C4: A1'den başlayan koyu lacivert başlık bandı | D4: Başlıksız sayfa | E4: Başlık kapsama = %100 | F4: ZORUNLU
A5: Sekme renkleri | B5: Sayfalar işlevine göre renk kodlanır | C5: Girdi=mavi, hesap=gri, rapor=lacivert, kontrol=kırmızı, kılavuz=altın | D5: Rastgele renk | E5: Renk semantiği tutarlı | F5: ZORUNLU
A6: Kolon düzeni | B6: Veri blokları bitişik kolonlarda ilerler | C6: Gereksiz boş kolon bırakma; yalnız gerçek bölüm ayrımı varsa kontrollü boşluk | D6: A:C veri, D boş, E:F veri gibi parçalı yapı | E6: Boş kolon taraması | F6: ZORUNLU
A7: Girdi hücreleri | B7: Kullanıcının değiştireceği alan açıkça görünür | C7: Açık sarı dolgu + mavi yazı | D7: Formülle aynı görünüm | E7: Girdi/formül ayrımı | F7: ZORUNLU
A8: Formüller | B8: Hesap hücreleri kullanıcı girdisinden ayrılır | C8: Siyah yazı; sayfalar arası bağlantı yeşil yazı | D8: Hard-code gizleme | E8: Formül sınıfı kontrolü | F8: ZORUNLU
A9: Grafik sayısı | B9: Yönetici ekranında en fazla 3 ana karar grafiği | C9: Trend, karşılaştırma, köprü/dağılım; iş kararına bağlı | D9: Grafik kalabalığı | E9: Grafik başına karar sorusu | F9: ZORUNLU
A10: Grafik stili | B10: Kurumsal ve yüksek okunabilirlik | C10: Beyaz zemin, ince gridline, tek vurgu rengi, açık birim/başlık | D10: 3B, gölge, neon, gökkuşağı renkleri | E10: Görsel inceleme | F10: ZORUNLU
A11: Grafik başlığı | B11: Grafik 'neyi' değil 'ne anlama geldiğini' söyler | C11: Örn: 'Nakit 2028'de kritik eşiğin altına iniyor' | D11: 'Nakit Grafiği' gibi anlamsız başlık | E11: Başlık karar testi | F11: ZORUNLU
A12: Birimler | B12: Tüm finansal görsellerde birim açık | C12: TL, bin TL, milyon TL, %, gün, x | D12: Birim belirsizliği | E12: Birim kapsama %100 | F12: ZORUNLU
A13: Sıfır/negatif | B13: Finansal format standardı | C13: Sıfır='-', negatif kırmızı parantez | D13: -500 veya 0,00 kalabalığı | E13: Format kontrolü | F13: ZORUNLU
A14: Yazı tipi | B14: Tek aile | C14: Aptos veya Segoe UI | D14: Karışık font | E14: Tek font kontrolü | F14: ZORUNLU
... A22: Premium vitrin | B22: Görsel kalite ürün değerinin zorunlu parçasıdır | C22: Kaliteli grafik, gerçek KPI kartı, finansal hiyerarşi, tab rengi, fonksiyonel navigasyon | D22: Sadece doğru hesap yapıp çıplak/varsayılan Excel görünümü bırakmak | E22: Görsel release incelemesi | F22: ZORUNLU

Sheet 04_MUHASEBE_THP
A1: TÜRKİYE MUHASEBE VE TEKDÜZEN HESAP PLANI STANDARDI
A3: Konu | B3: Zorunlu Standart | C3: Örnek Türkçe Ad | D3: THP / Mantık | E3: Hata Riski | F3: Kontrol
A4: Dil | B4: Kullanıcıya görünen finansal terimler Türkçe | C4: Hasılat, Satışların Maliyeti, Brüt Kâr, Faaliyet Giderleri | D4: Türk işletme kullanımına uygun | E4: İngilizce jargon | F4: Terminoloji taraması
A5: Gelir Tablosu | B5: Türk sunum sırası kullanılır | C5: Net Satışlar → Satışların Maliyeti → Brüt Kâr → Faaliyet Giderleri → Faaliyet Kârı | D5: 600/610/611; 620-623; 63x | E5: Yanlış sınıflama | F5: Hesap eşleme
A6: Bilanço | B6: Dönen/Duran Varlık ve Kısa/Uzun Vadeli Yükümlülük ayrımı | C6: Hazır Değerler, Ticari Alacaklar, Stoklar, Mali Borçlar | D6: 1xx / 2xx / 3xx / 4xx / 5xx | E6: Vade sınıfı hatası | F6: Bilanço eşitliği
A7: Nakit Akışı | B7: İşletme/Yatırım/Finansman nakit akışları ayrılır | C7: Faaliyetlerden Nakit, Yatırım Harcamaları, Finansman Nakit Akışı | D7: Dolaylı/doğrudan yöntem açık seçilir | E7: Kâr = nakit sanılması | F7: Nakit devri
A8: Ticari Alacaklar | B8: Cari ve vade mantığı korunur | C8: 120 Alıcılar | D8: 120 | E8: Tahakkuk/nakit karışması | F8: Alacak devir kontrolü
A9: Ticari Borçlar | B9: Tedarikçi borcu ayrı izlenir | C9: 320 Satıcılar | D9: 320 | E9: Gider/ödeme karışması | F9: Borç devir kontrolü
A10: Kasa/Banka | B10: Hazır değerler ayrı izlenir | C10: 100 Kasa, 102 Bankalar | D10: 100 / 102 | E10: Virmanla toplam nakdin değişmesi | F10: Virman değişmezi
A11: Stok | B11: Dikeye uygun stok türü | C11: 150 İlk Madde ve Malzeme, 153 Ticari Mallar | D11: 15x | E11: Maliyet ve stok hareketinin kopması | F11: Stok devri
A12: Maddi Duran Varlık | B12: Yatırım harcaması ve amortisman bağlantılı | C12: 253 Tesis Makine Cihazlar, 255 Demirbaşlar, 257 Birikmiş Amortismanlar | D12: 25x | E12: Yatırım/gider karışması | F12: Net defter değeri devri
A13: Mali Borçlar | B13: Kısa/uzun vadeli borç ayrımı | C13: 300 Banka Kredileri / 400 Banka Kredileri | D13: 300 / 400 | E13: Vade sınıfı yanlış | F13: Borç devri
A14: Özkaynak | B14: Sermaye ve geçmiş yıl kârları ayrı | C14: 500 Sermaye, 570 Geçmiş Yıllar Kârları, 590 Dönem Net Kârı | D14: 5xx | E14: Net kâr bağının kopması | F14: Özkaynak devri
... A18: İstisna | B18: TFRS özel ürün varsa fark açık yazılır | C18: Tekdüzen raporlama ≠ TFRS finansal tablo sunumu | D18: Amaç belirtilir | E18: Standartları karıştırma | F18: Model amacı kontrolü

Sheet 05_KARAR_SATIS
A1: KARAR, GÜVEN VE SATIŞA HAZIRLIK STANDARDI
A3: Alan | B3: Müşteri Sorusu | C3: Zorunlu Ürün Davranışı | D3: Kanıt | E3: Başarısızlık Durumu | F3: Kapı
A4: 5 saniye | B4: Bu ürün neyi çözüyor? | C4: İlk ekranda hedef kullanıcı + pahalı problem + sonuç görünür | D4: Başlık + alt mesaj + gerçek ekran | E4: Ürün yalnız teknik isim | F4: HATA
A5: Acı | B5: Sorun bana neye mal oluyor? | C5: Mümkünse müşterinin kendi verisiyle parasal/zaman etkisi hesaplanır | D5: ROI/acı hesaplama yöntemi | E5: Uydurma tasarruf | F5: HATA
A6: Karar | B6: Bu bilgiyle ne yapacağım? | C6: Her kritik KPI aksiyona bağlanır | D6: KARAR_KUYRUGU | E6: Sadece rapor | F6: HATA
A7: Güven | B7: Bu sayıya neden inanayım? | C7: Kaynak, formül mantığı, kontrol ve son doğrulama görünür | D7: Kontroller + kaynak izi + sürüm | E7: Prestij kelimesi | F7: HATA
A8: Referans | B8: Müşteri yorumu yoksa ne göstereceğim? | C8: Önce/Sonra + Karar Vakası + Hata Önleme Vakası üretilir | D8: Demo/örnek çıktı | E8: Kanıtsız iddia | F8: HATA
A9: Senaryo | B9: Ne olursa işler bozulur? | C9: Baz/Aşağı/Yukarı veya uygun stres senaryosu | D9: Senaryo karşılaştırma | E9: Dekoratif senaryo | F9: HATA
A10: Ters stres | B10: Hangi eşikte karar kırılır? | C10: En az bir kritik sürücü için kırılma eşiği | D10: Kırılma eşiği tablosu | E10: Sadece +/- %10 | F10: UYARI/HATA
A11: Hata tutarlılığı | B11: Formül hata verirse ne olur? | C11: Kontrol GEÇTİ veremez; BLOKE/HATA üretir | D11: Hata taraması | E11: Hata + GEÇTİ birlikte | F11: HATA
A12: Karar motoru | B12: Ne oldu, neden oldu? | C12: Sorun + neden + parasal etki + aksiyon + son tarih | D12: Karar tablosu | E12: Boş sayfa / isim düzeyi modül | F12: HATA
A13: Yönetici özeti | B13: 5 saniyede ne görmeliyim? | C13: Bugün / ne değişti / ne bozulacak / neden / ne yapmalıyım / güven | D13: Yönetici özeti ekranı | E13: KPI kutusu yığını | F13: HATA
A14: Teklif | B14: Neden satın almalıyım? | C14: Dosya özellikleri yerine sonuç ve kaçınılan maliyet sunulur | D14: Ürün sayfası kanıt eşlemesi | E14: Özellik listesiyle satış | F14: HATA
... A19: Pazar kanıtı | B19: Piyasa gerçekten ödüyor mu? | C19: Satış/pilot/LOI/fiyat kabulü olmadan pazar doğrulandı yazılmaz | D19: Gerçek işlem kanıtı | E19: Tahmini talep = satış kabulü | F19: HATA

Sheet KAPAK
A1: KAPAK — GES Üretim & Performans Takibi
A3: GES Üretim & Performans Takibi
A4: GES santrallerinde günlük üretim, ışınım ve kayıp verisinden PR oranını hesaplar; kayıp kırılımı ve varlık sağlık skoru üretir; UYGUN / DİKKAT / KRİTİK / VERİ YOK kararı verir.
A6: Bu ürün ne sağlar?
A7: • PR oranı = üretim / (ışınım × kapasite) — IEC 61724 mantığı
A8: • Günlük saha girişi en fazla 6 manuel alan — 30 saniye hedefi
A9: • Varlık sağlık skoru formülle veriden türer (sabit skor yok)
A10: • 12 aylık sezonsal üretim-PR zinciri ve alarm eşiği kuyruğu
A11: • Makrosuz, çevrimdışı; SCADA / API bağı yok
A13: Kimler için?
A14: • Saha enerji operatörü — günlük üretim-ışınım-kayıp satırı
A15: • GES işletme müdürü — PR panosu ve karar
... A21: Sürüm 1.0.0 | Kod: GUP-PRO | Lisans: Tek kullanıcı | ExcelArşiv

Sheet VARLIKLAR
A1: VARLIKLAR — GES Üretim & Performans Takibi
A3: GES santral kartları — her varlığın tek kimliği vardır
A4: Sonraki Kimlik | B4: =gup_sonrakiKimlik
A5: VarlikId | B5: SantralAd | C5: Tip | D5: KapasiteKwp_kwp | E5: InverterAdet_adet | F5: Konum | G5: HedefPr_oran | H5: Aktif | I5: ToplamUretimKwh | J5: OrtPr | K5: ToplamKayipKwh | L5: SaglikSkor
A6: GES-00001 | B6: Ankara Cati A | C6: Cati | D6: 120 | E6: 4 | F6: Ankara | G6: 0.78 | H6: EVET | I6: =IF($A6="","",SUMIF(tblGunluk[VarlikId],$A6,tblGunluk[UretimKwh_kwh])) | J6: =IF($A6="","",IFERROR(AVERAGEIF(tblGunluk[VarlikId],$A6,tblGunluk[FormulPr_oran]),0)) | K6: =IF($A6="","",SUMIF(tblGunluk[VarlikId],$A6,tblGunluk[KayipKwh_kwh])) | L6: =IF($A6="","",MAX(0,MIN(100,gup_kaliteTaban-IF($J6<gup_esikPr,gup_kaliteCeza,0)-COUNTIFS(tblGunluk[VarlikId],$A6,tblGunluk[AlarmBayrak],"ALARM")*gup_kaliteSapma-IF($H6="HAYIR",gup_kaliteCeza,0))))
A7: GES-00002 | B7: Konya Saha B | C7: Saha | D7: 850 | E7: 12 | F7: Konya | G7: 0.8 | H7: EVET | I7: =IF($A7="","",SUMIF(tblGunluk[VarlikId],$A7,tblGunluk[UretimKwh_kwh])) | J7: =IF($A7="","",IFERROR(AVERAGEIF(tblGunluk[VarlikId],$A7,tblGunluk[FormulPr_oran]),0)) | K7: =IF($A7="","",SUMIF(tblGunluk[VarlikId],$A7,tblGunluk[KayipKwh_kwh])) | L7: =IF($A7="","",MAX(0,MIN(100,gup_kaliteTaban-IF($J7<gup_esikPr,gup_kaliteCeza,0)-COUNTIFS(tblGunluk[VarlikId],$A7,tblGunluk[AlarmBayrak],"ALARM")*gup_kaliteSapma-IF($H7="HAYIR",gup_kaliteCeza,0))))
A8: GES-00003 | B8: Izmir Cati C | C8: Cati | D8: 95 | E8: 3 | F8: Izmir | G8: 0.76 | H8: EVET | I8: =IF($A8="","",SUMIF(tblGunluk[VarlikId],$A8,tblGunluk[UretimKwh_kwh])) | J8: =IF($A8="","",IFERROR(AVERAGEIF(tblGunluk[VarlikId],$A8,tblGunluk[FormulPr_oran]),0)) | K8: =IF($A8="","",SUMIF(tblGunluk[VarlikId],$A8,tblGunluk[KayipKwh_kwh])) | L8: =IF($A8="","",MAX(0,MIN(100,gup_kaliteTaban-IF($J8<gup_esikPr,gup_kaliteCeza,0)-COUNTIFS(tblGunluk[VarlikId],$A8,tblGunluk[AlarmBayrak],"ALARM")*gup_kaliteSapma-IF($H8="HAYIR",gup_kaliteCeza,0))))
A9: GES-00004 | B9: Antalya Saha D | C9: Saha | D9: 1200 | E9: 16 | F9: Antalya | G9: 0.82 | H9: EVET | I9: =IF($A9="","",SUMIF(tblGunluk[VarlikId],$A9,tblGunluk[UretimKwh_kwh])) | J9: =IF($A9="","",IFERROR(AVERAGEIF(tblGunluk[VarlikId],$A9,tblGunluk[FormulPr_oran]),0)) | K9: =IF($A9="","",SUMIF(tblGunluk[VarlikId],$A9,tblGunluk[KayipKwh_kwh])) | L9: =IF($A9="","",MAX(0,MIN(100,gup_kaliteTaban-IF($J9<gup_esikPr,gup_kaliteCeza,0)-COUNTIFS(tblGunluk[VarlikId],$A9,tblGunluk[AlarmBayrak],"ALARM")*gup_kaliteSapma-IF($H9="HAYIR",gup_kaliteCeza,0))))
A10: GES-00005 | B10: Bursa Cati E | C10: Cati | D10: 64 | E10: 2 | F10: Bursa | G10: 0.75 | H10: EVET | I10: =IF($A10="","",SUMIF(tblGunluk[VarlikId],$A10,tblGunluk[UretimKwh_kwh])) | J10: =IF($A10="","",IFERROR(AVERAGEIF(tblGunluk[VarlikId],$A10,tblGunluk[FormulPr_oran]),0)) | K10: =IF($A10="","",SUMIF(tblGunluk[VarlikId],$A10,tblGunluk[KayipKwh_kwh])) | L10: =IF($A10="","",MAX(0,MIN(100,gup_kaliteTaban-IF($J10<gup_esikPr,gup_kaliteCeza,0)-COUNTIFS(tblGunluk[VarlikId],$A10,tblGunluk[AlarmBayrak],"ALARM")*gup_kaliteSapma-IF($H10="HAYIR",gup_kaliteCeza,0))))
A11: GES-00006 | B11: Gaziantep Saha F | C11: Saha | D11: 520 | E11: 8 | F11: Gaziantep | G11: 0.79 | H11: EVET | I11: =IF($A11="","",SUMIF(tblGunluk[VarlikId],$A11,tblGunluk[UretimKwh_kwh])) | J11: =IF($A11="","",IFERROR(AVERAGEIF(tblGunluk[VarlikId],$A11,tblGunluk[FormulPr_oran]),0)) | K11: =IF($A11="","",SUMIF(tblGunluk[VarlikId],$A11,tblGunluk[KayipKwh_kwh])) | L11: =IF($A11="","",MAX(0,MIN(100,gup_kaliteTaban-IF($J11<gup_esikPr,gup_kaliteCeza,0)-COUNTIFS(tblGunluk[VarlikId],$A11,tblGunluk[AlarmBayrak],"ALARM")*gup_kaliteSapma-IF($H11="HAYIR",gup_kaliteCeza,0))))
A12: GES-00007 | B12: Mersin Cati G | C12: Cati | D12: 110 | E12: 4 | F12: Mersin | G12: 0.77 | H12: EVET | I12: =IF($A12="","",SUMIF(tblGunluk[VarlikId],$A12,tblGunluk[UretimKwh_kwh])) | J12: =IF($A12="","",IFERROR(AVERAGEIF(tblGunluk[VarlikId],$A12,tblGunluk[FormulPr_oran]),0)) | K12: =IF($A12="","",SUMIF(tblGunluk[VarlikId],$A12,tblGunluk[KayipKwh_kwh])) | L12: =IF($A12="","",MAX(0,MIN(100,gup_kaliteTaban-IF($J12<gup_esikPr,gup_kaliteCeza,0)-COUNTIFS(tblGunluk[VarlikId],$A12,tblGunluk[AlarmBayrak],"ALARM")*gup_kaliteSapma-IF($H12="HAYIR",gup_kaliteCeza,0))))
A13: GES-00008 | B13: Eskisehir Saha H | C13: Saha | D13: 380 | E13: 6 | F13: Eskisehir | G13: 0.78 | H13: EVET | I13: =IF($A13="","",SUMIF(tblGunluk[VarlikId],$A13,tblGunluk[UretimKwh_kwh])) | J13: =IF($A13="","",IFERROR(AVERAGEIF(tblGunluk[VarlikId],$A13,tblGunluk[FormulPr_oran]),0)) | K13: =IF($A13="","",SUMIF(tblGunluk[VarlikId],$A13,tblGunluk[KayipKwh_kwh])) | L13: =IF($A13="","",MAX(0,MIN(100,gup_kaliteTaban-IF($J13<gup_esikPr,gup_kaliteCeza,0)-COUNTIFS(tblGunluk[VarlikId],$A13,tblGunluk[AlarmBayrak],"ALARM")*gup_kaliteSapma-IF($H13="HAYIR",gup_kaliteCeza,0))))
I14: =IF($A14="","",SUMIF(tblGunluk[VarlikId],$A14,tblGunluk[UretimKwh_kwh])) | J14: =IF($A14="","",IFERROR(AVERAGEIF(tblGunluk[VarlikId],$A14,tblGunluk[FormulPr_oran]),0)) | K14: =IF($A14="","",SUMIF(tblGunluk[VarlikId],$A14,tblGunluk[KayipKwh_kwh])) | L14: =IF($A14="","",MAX(0,MIN(100,gup_kaliteTaban-IF($J14<gup_esikPr,gup_kaliteCeza,0)-COUNTIFS(tblGunluk[VarlikId],$A14,tblGunluk[AlarmBayrak],"ALARM")*gup_kaliteSapma-IF($H14="HAYIR",gup_kaliteCeza,0))))
I15: =IF($A15="","",SUMIF(tblGunluk[VarlikId],$A15,tblGunluk[UretimKwh_kwh])) | J15: =IF($A15="","",IFERROR(AVERAGEIF(tblGunluk[VarlikId],$A15,tblGunluk[FormulPr_oran]),0)) | K15: =IF($A15="","",SUMIF(tblGunluk[VarlikId],$A15,tblGunluk[KayipKwh_kwh])) | L15: =IF($A15="","",MAX(0,MIN(100,gup_kaliteTaban-IF($J15<gup_esikPr,gup_kaliteCeza,0)-COUNTIFS(tblGunluk[VarlikId],$A15,tblGunluk[AlarmBayrak],"ALARM")*gup_kaliteSapma-IF($H15="HAYIR",gup_kaliteCeza,0))))
I16: =IF($A16="","",SUMIF(tblGunluk[VarlikId],$A16,tblGunluk[UretimKwh_kwh])) | J16: =IF($A16="","",IFERROR(AVERAGEIF(tblGunluk[VarlikId],$A16,tblGunluk[FormulPr_oran]),0)) | K16: =IF($A16="","",SUMIF(tblGunluk[VarlikId],$A16,tblGunluk[KayipKwh_kwh])) | L16: =IF($A16="","",MAX(0,MIN(100,gup_kaliteTaban-IF($J16<gup_esikPr,gup_kaliteCeza,0)-COUNTIFS(tblGunluk[VarlikId],$A16,tblGunluk[AlarmBayrak],"ALARM")*gup_kaliteSapma-IF($H16="HAYIR",gup_kaliteCeza,0))))
I17: =IF($A17="","",SUMIF(tblGunluk[VarlikId],$A17,tblGunluk[UretimKwh_kwh])) | J17: =IF($A17="","",IFERROR(AVERAGEIF(tblGunluk[VarlikId],$A17,tblGunluk[FormulPr_oran]),0)) | K17: =IF($A17="","",SUMIF(tblGunluk[VarlikId],$A17,tblGunluk[KayipKwh_kwh])) | L17: =IF($A17="","",MAX(0,MIN(100,gup_kaliteTaban-IF($J17<gup_esikPr,gup_kaliteCeza,0)-COUNTIFS(tblGunluk[VarlikId],$A17,tblGunluk[AlarmBayrak],"ALARM")*gup_kaliteSapma-IF($H17="HAYIR",gup_kaliteCeza,0))))
I18: =IF($A18="","",SUMIF(tblGunluk[VarlikId],$A18,tblGunluk[UretimKwh_kwh])) | J18: =IF($A18="","",IFERROR(AVERAGEIF(tblGunluk[VarlikId],$A18,tblGunluk[FormulPr_oran]),0)) | K18: =IF($A18="","",SUMIF(tblGunluk[VarlikId],$A18,tblGunluk[KayipKwh_kwh])) | L18: =IF($A18="","",MAX(0,MIN(100,gup_kaliteTaban-IF($J18<gup_esikPr,gup_kaliteCeza,0)-COUNTIFS(tblGunluk[VarlikId],$A18,tblGunluk[AlarmBayrak],"ALARM")*gup_kaliteSapma-IF($H18="HAYIR",gup_kaliteCeza,0))))
I19: =IF($A19="","",SUMIF(tblGunluk[VarlikId],$A19,tblGunluk[UretimKwh_kwh])) | J19: =IF($A19="","",IFERROR(AVERAGEIF(tblGunluk[VarlikId],$A19,tblGunluk[FormulPr_oran]),0)) | K19: =IF($A19="","",SUMIF(tblGunluk[VarlikId],$A19,tblGunluk[KayipKwh_kwh])) | L19: =IF($A19="","",MAX(0,MIN(100,gup_kaliteTaban-IF($J19<gup_esikPr,gup_kaliteCeza,0)-COUNTIFS(tblGunluk[VarlikId],$A19,tblGunluk[AlarmBayrak],"ALARM")*gup_kaliteSapma-IF($H19="HAYIR",gup_kaliteCeza,0))))
I20: =IF($A20="","",SUMIF(tblGunluk[VarlikId],$A20,tblGunluk[UretimKwh_kwh])) | J20: =IF($A20="","",IFERROR(AVERAGEIF(tblGunluk[VarlikId],$A20,tblGunluk[FormulPr_oran]),0)) | K20: =IF($A20="","",SUMIF(tblGunluk[VarlikId],$A20,tblGunluk[KayipKwh_kwh])) | L20: =IF($A20="","",MAX(0,MIN(100,gup_kaliteTaban-IF($J20<gup_esikPr,gup_kaliteCeza,0)-COUNTIFS(tblGunluk[VarlikId],$A20,tblGunluk[AlarmBayrak],"ALARM")*gup_kaliteSapma-IF($H20="HAYIR",gup_kaliteCeza,0))))
I21: =IF($A21="","",SUMIF(tblGunluk[VarlikId],$A21,tblGunluk[UretimKwh_kwh])) | J21: =IF($A21="","",IFERROR(AVERAGEIF(tblGunluk[VarlikId],$A21,tblGunluk[FormulPr_oran]),0)) | K21: =IF($A21="","",SUMIF(tblGunluk[VarlikId],$A21,tblGunluk[KayipKwh_kwh])) | L21: =IF($A21="","",MAX(0,MIN(100,gup_kaliteTaban-IF($J21<gup_esikPr,gup_kaliteCeza,0)-COUNTIFS(tblGunluk[VarlikId],$A21,tblGunluk[AlarmBayrak],"ALARM")*gup_kaliteSapma-IF($H21="HAYIR",gup_kaliteCeza,0))))
I22: =IF($A22="","",SUMIF(tblGunluk[VarlikId],$A22,tblGunluk[UretimKwh_kwh])) | J22: =IF($A22="","",IFERROR(AVERAGEIF(tblGunluk[VarlikId],$A22,tblGunluk[FormulPr_oran]),0)) | K22: =IF($A22="","",SUMIF(tblGunluk[VarlikId],$A22,tblGunluk[KayipKwh_kwh])) | L22: =IF($A22="","",MAX(0,MIN(100,gup_kaliteTaban-IF($J22<gup_esikPr,gup_kaliteCeza,0)-COUNTIFS(tblGunluk[VarlikId],$A22,tblGunluk[AlarmBayrak],"ALARM")*gup_kaliteSapma-IF($H22="HAYIR",gup_kaliteCeza,0))))
I23: =IF($A23="","",SUMIF(tblGunluk[VarlikId],$A23,tblGunluk[UretimKwh_kwh])) | J23: =IF($A23="","",IFERROR(AVERAGEIF(tblGunluk[VarlikId],$A23,tblGunluk[FormulPr_oran]),0)) | K23: =IF($A23="","",SUMIF(tblGunluk[VarlikId],$A23,tblGunluk[KayipKwh_kwh])) | L23: =IF($A23="","",MAX(0,MIN(100,gup_kaliteTaban-IF($J23<gup_esikPr,gup_kaliteCeza,0)-COUNTIFS(tblGunluk[VarlikId],$A23,tblGunluk[AlarmBayrak],"ALARM")*gup_kaliteSapma-IF($H23="HAYIR",gup_kaliteCeza,0))))
I24: =IF($A24="","",SUMIF(tblGunluk[VarlikId],$A24,tblGunluk[UretimKwh_kwh])) | J24: =IF($A24="","",IFERROR(AVERAGEIF(tblGunluk[VarlikId],$A24,tblGunluk[FormulPr_oran]),0)) | K24: =IF($A24="","",SUMIF(tblGunluk[VarlikId],$A24,tblGunluk[KayipKwh_kwh])) | L24: =IF($A24="","",MAX(0,MIN(100,gup_kaliteTaban-IF($J24<gup_esikPr,gup_kaliteCeza,0)-COUNTIFS(tblGunluk[VarlikId],$A24,tblGunluk[AlarmBayrak],"ALARM")*gup_kaliteSapma-IF($H24="HAYIR",gup_kaliteCeza,0))))
I25: =IF($A25="","",SUMIF(tblGunluk[VarlikId],$A25,tblGunluk[UretimKwh_kwh])) | J25: =IF($A25="","",IFERROR(AVERAGEIF(tblGunluk[VarlikId],$A25,tblGunluk[FormulPr_oran]),0)) | K25: =IF($A25="","",SUMIF(tblGunluk[VarlikId],$A25,tblGunluk[KayipKwh_kwh])) | L25: =IF($A25="","",MAX(0,MIN(100,gup_kaliteTaban-IF($J25<gup_esikPr,gup_kaliteCeza,0)-COUNTIFS(tblGunluk[VarlikId],$A25,tblGunluk[AlarmBayrak],"ALARM")*gup_kaliteSapma-IF($H25="HAYIR",gup_kaliteCeza,0))))
... I255: =IF($A255="","",SUMIF(tblGunluk[VarlikId],$A255,tblGunluk[UretimKwh_kwh])) | J255: =IF($A255="","",IFERROR(AVERAGEIF(tblGunluk[VarlikId],$A255,tblGunluk[FormulPr_oran]),0)) | K255: =IF($A255="","",SUMIF(tblGunluk[VarlikId],$A255,tblGunluk[KayipKwh_kwh])) | L255: =IF($A255="","",MAX(0,MIN(100,gup_kaliteTaban-IF($J255<gup_esikPr,gup_kaliteCeza,0)-COUNTIFS(tblGunluk[VarlikId],$A255,tblGunluk[AlarmBayrak],"ALARM")*gup_kaliteSapma-IF($H255="HAYIR",gup_kaliteCeza,0))))

Sheet GUNLUK_GIRIS
A1: GUNLUK GIRIS — GES Üretim & Performans Takibi
A3: GÜNLÜK saha girişi — satır başına en fazla 6 manuel alan (S02)
A5: SatirId | B5: VarlikId | C5: Tarih | D5: UretimKwh_kwh | E5: IsinimKwhm2_kwhm2 | F5: KayipKwh_kwh | G5: KayipTuru | H5: FormulKapasite_kwp | I5: FormulTeorik_kwh | J5: FormulPr_oran | K5: FormulKayipPay_oran | L5: FormulNet_kwh | M5: SaglikSkor_puan | N5: AlarmBayrak | O5: FormulKayitDolu | P5: FormulYetim
A6: GUP-00001 | B6: GES-00001 | C6: 46242 | D6: 341.9 | E6: 3.85 | F6: 120.1 | G6: GOLGE | H6: =IF($A6="","",IFERROR(SUMIF(tblVarliklar[VarlikId],$B6,tblVarliklar[KapasiteKwp_kwp]),gup_varsayilanKapasite)) | I6: =IF($A6="","",$E6*$H6) | J6: =IF(OR($A6="",$I6=0),"",$D6/$I6) | K6: =IF(OR($A6="",$I6=0),"",$F6/$I6) | L6: =IF($A6="","",$D6) | M6: =IF($A6="","",MAX(0,MIN(100,gup_kaliteTaban-IF($J6<gup_esikPr,gup_kaliteCeza,0)-IF($F6>gup_esikKayipKwh,gup_kaliteSapma,0)-IF($P6="YETIM",gup_kaliteCeza,0)))) | N6: =IF($A6="","",IF(OR($J6<gup_esikPr,$F6>gup_esikKayipKwh,$M6<gup_esikSaglik),"ALARM","UYGUN")) | O6: =IF($A6="","",1) | P6: =IF($A6="","",IF(OR($B6="",COUNTIF(tblVarliklar[VarlikId],$B6)=0),"YETIM","TAMAM"))
A7: GUP-00002 | B7: GES-00002 | C7: 46239 | D7: 2907 | E7: 4.5 | F7: 918 | G7: INVERTER | H7: =IF($A7="","",IFERROR(SUMIF(tblVarliklar[VarlikId],$B7,tblVarliklar[KapasiteKwp_kwp]),gup_varsayilanKapasite)) | I7: =IF($A7="","",$E7*$H7) | J7: =IF(OR($A7="",$I7=0),"",$D7/$I7) | K7: =IF(OR($A7="",$I7=0),"",$F7/$I7) | L7: =IF($A7="","",$D7) | M7: =IF($A7="","",MAX(0,MIN(100,gup_kaliteTaban-IF($J7<gup_esikPr,gup_kaliteCeza,0)-IF($F7>gup_esikKayipKwh,gup_kaliteSapma,0)-IF($P7="YETIM",gup_kaliteCeza,0)))) | N7: =IF($A7="","",IF(OR($J7<gup_esikPr,$F7>gup_esikKayipKwh,$M7<gup_esikSaglik),"ALARM","UYGUN")) | O7: =IF($A7="","",1) | P7: =IF($A7="","",IF(OR($B7="",COUNTIF(tblVarliklar[VarlikId],$B7)=0),"YETIM","TAMAM"))
A8: GUP-00003 | B8: GES-00003 | C8: 46236 | D8: 337.1 | E8: 4.55 | F8: 95.1 | G8: ARIZA | H8: =IF($A8="","",IFERROR(SUMIF(tblVarliklar[VarlikId],$B8,tblVarliklar[KapasiteKwp_kwp]),gup_varsayilanKapasite)) | I8: =IF($A8="","",$E8*$H8) | J8: =IF(OR($A8="",$I8=0),"",$D8/$I8) | K8: =IF(OR($A8="",$I8=0),"",$F8/$I8) | L8: =IF($A8="","",$D8) | M8: =IF($A8="","",MAX(0,MIN(100,gup_kaliteTaban-IF($J8<gup_esikPr,gup_kaliteCeza,0)-IF($F8>gup_esikKayipKwh,gup_kaliteSapma,0)-IF($P8="YETIM",gup_kaliteCeza,0)))) | N8: =IF($A8="","",IF(OR($J8<gup_esikPr,$F8>gup_esikKayipKwh,$M8<gup_esikSaglik),"ALARM","UYGUN")) | O8: =IF($A8="","",1) | P8: =IF($A8="","",IF(OR($B8="",COUNTIF(tblVarliklar[VarlikId],$B8)=0),"YETIM","TAMAM"))
A9: GUP-00004 | B9: GES-00004 | C9: 46233 | D9: 4992 | E9: 5.2 | F9: 1248 | G9: ISINIM | H9: =IF($A9="","",IFERROR(SUMIF(tblVarliklar[VarlikId],$B9,tblVarliklar[KapasiteKwp_kwp]),gup_varsayilanKapasite)) | I9: =IF($A9="","",$E9*$H9) | J9: =IF(OR($A9="",$I9=0),"",$D9/$I9) | K9: =IF(OR($A9="",$I9=0),"",$F9/$I9) | L9: =IF($A9="","",$D9) | M9: =IF($A9="","",MAX(0,MIN(100,gup_kaliteTaban-IF($J9<gup_esikPr,gup_kaliteCeza,0)-IF($F9>gup_esikKayipKwh,gup_kaliteSapma,0)-IF($P9="YETIM",gup_kaliteCeza,0)))) | N9: =IF($A9="","",IF(OR($J9<gup_esikPr,$F9>gup_esikKayipKwh,$M9<gup_esikSaglik),"ALARM","UYGUN")) | O9: =IF($A9="","",1) | P9: =IF($A9="","",IF(OR($B9="",COUNTIF(tblVarliklar[VarlikId],$B9)=0),"YETIM","TAMAM"))
A10: GUP-00005 | B10: GES-00005 | C10: 46230 | D10: 269.6 | E10: 5.85 | F10: 104.8 | G10: DIGER | H10: =IF($A10="","",IFERROR(SUMIF(tblVarliklar[VarlikId],$B10,tblVarliklar[KapasiteKwp_kwp]),gup_varsayilanKapasite)) | I10: =IF($A10="","",$E10*$H10) | J10: =IF(OR($A10="",$I10=0),"",$D10/$I10) | K10: =IF(OR($A10="",$I10=0),"",$F10/$I10) | L10: =IF($A10="","",$D10) | M10: =IF($A10="","",MAX(0,MIN(100,gup_kaliteTaban-IF($J10<gup_esikPr,gup_kaliteCeza,0)-IF($F10>gup_esikKayipKwh,gup_kaliteSapma,0)-IF($P10="YETIM",gup_kaliteCeza,0)))) | N10: =IF($A10="","",IF(OR($J10<gup_esikPr,$F10>gup_esikKayipKwh,$M10<gup_esikSaglik),"ALARM","UYGUN")) | O10: =IF($A10="","",1) | P10: =IF($A10="","",IF(OR($B10="",COUNTIF(tblVarliklar[VarlikId],$B10)=0),"YETIM","TAMAM"))
A11: GUP-00006 | B11: GES-00006 | C11: 46227 | D11: 2270.3 | E11: 5.9 | F11: 797.7 | G11: KIRLENME | H11: =IF($A11="","",IFERROR(SUMIF(tblVarliklar[VarlikId],$B11,tblVarliklar[KapasiteKwp_kwp]),gup_varsayilanKapasite)) | I11: =IF($A11="","",$E11*$H11) | J11: =IF(OR($A11="",$I11=0),"",$D11/$I11) | K11: =IF(OR($A11="",$I11=0),"",$F11/$I11) | L11: =IF($A11="","",$D11) | M11: =IF($A11="","",MAX(0,MIN(100,gup_kaliteTaban-IF($J11<gup_esikPr,gup_kaliteCeza,0)-IF($F11>gup_esikKayipKwh,gup_kaliteSapma,0)-IF($P11="YETIM",gup_kaliteCeza,0)))) | N11: =IF($A11="","",IF(OR($J11<gup_esikPr,$F11>gup_esikKayipKwh,$M11<gup_esikSaglik),"ALARM","UYGUN")) | O11: =IF($A11="","",1) | P11: =IF($A11="","",IF(OR($B11="",COUNTIF(tblVarliklar[VarlikId],$B11)=0),"YETIM","TAMAM"))
A12: GUP-00007 | B12: GES-00007 | C12: 46224 | D12: 284.2 | E12: 3.4 | F12: 89.8 | G12: GOLGE | H12: =IF($A12="","",IFERROR(SUMIF(tblVarliklar[VarlikId],$B12,tblVarliklar[KapasiteKwp_kwp]),gup_varsayilanKapasite)) | I12: =IF($A12="","",$E12*$H12) | J12: =IF(OR($A12="",$I12=0),"",$D12/$I12) | K12: =IF(OR($A12="",$I12=0),"",$F12/$I12) | L12: =IF($A12="","",$D12) | M12: =IF($A12="","",MAX(0,MIN(100,gup_kaliteTaban-IF($J12<gup_esikPr,gup_kaliteCeza,0)-IF($F12>gup_esikKayipKwh,gup_kaliteSapma,0)-IF($P12="YETIM",gup_kaliteCeza,0)))) | N12: =IF($A12="","",IF(OR($J12<gup_esikPr,$F12>gup_esikKayipKwh,$M12<gup_esikSaglik),"ALARM","UYGUN")) | O12: =IF($A12="","",1) | P12: =IF($A12="","",IF(OR($B12="",COUNTIF(tblVarliklar[VarlikId],$B12)=0),"YETIM","TAMAM"))
A13: GUP-00008 | B13: GES-00008 | C13: 46221 | D13: 1200.4 | E13: 4.05 | F13: 338.6 | G13: INVERTER | H13: =IF($A13="","",IFERROR(SUMIF(tblVarliklar[VarlikId],$B13,tblVarliklar[KapasiteKwp_kwp]),gup_varsayilanKapasite)) | I13: =IF($A13="","",$E13*$H13) | J13: =IF(OR($A13="",$I13=0),"",$D13/$I13) | K13: =IF(OR($A13="",$I13=0),"",$F13/$I13) | L13: =IF($A13="","",$D13) | M13: =IF($A13="","",MAX(0,MIN(100,gup_kaliteTaban-IF($J13<gup_esikPr,gup_kaliteCeza,0)-IF($F13>gup_esikKayipKwh,gup_kaliteSapma,0)-IF($P13="YETIM",gup_kaliteCeza,0)))) | N13: =IF($A13="","",IF(OR($J13<gup_esikPr,$F13>gup_esikKayipKwh,$M13<gup_esikSaglik),"ALARM","UYGUN")) | O13: =IF($A13="","",1) | P13: =IF($A13="","",IF(OR($B13="",COUNTIF(tblVarliklar[VarlikId],$B13)=0),"YETIM","TAMAM"))
A14: GUP-00009 | B14: GES-00001 | C14: 46218 | D14: 393.6 | E14: 4.1 | F14: 98.4 | G14: ARIZA | H14: =IF($A14="","",IFERROR(SUMIF(tblVarliklar[VarlikId],$B14,tblVarliklar[KapasiteKwp_kwp]),gup_varsayilanKapasite)) | I14: =IF($A14="","",$E14*$H14) | J14: =IF(OR($A14="",$I14=0),"",$D14/$I14) | K14: =IF(OR($A14="",$I14=0),"",$F14/$I14) | L14: =IF($A14="","",$D14) | M14: =IF($A14="","",MAX(0,MIN(100,gup_kaliteTaban-IF($J14<gup_esikPr,gup_kaliteCeza,0)-IF($F14>gup_esikKayipKwh,gup_kaliteSapma,0)-IF($P14="YETIM",gup_kaliteCeza,0)))) | N14: =IF($A14="","",IF(OR($J14<gup_esikPr,$F14>gup_esikKayipKwh,$M14<gup_esikSaglik),"ALARM","UYGUN")) | O14: =IF($A14="","",1) | P14: =IF($A14="","",IF(OR($B14="",COUNTIF(tblVarliklar[VarlikId],$B14)=0),"YETIM","TAMAM"))
A15: GUP-00010 | B15: GES-00002 | C15: 46215 | D15: 2907 | E15: 4.75 | F15: 1130.5 | G15: ISINIM | H15: =IF($A15="","",IFERROR(SUMIF(tblVarliklar[VarlikId],$B15,tblVarliklar[KapasiteKwp_kwp]),gup_varsayilanKapasite)) | I15: =IF($A15="","",$E15*$H15) | J15: =IF(OR($A15="",$I15=0),"",$D15/$I15) | K15: =IF(OR($A15="",$I15=0),"",$F15/$I15) | L15: =IF($A15="","",$D15) | M15: =IF($A15="","",MAX(0,MIN(100,gup_kaliteTaban-IF($J15<gup_esikPr,gup_kaliteCeza,0)-IF($F15>gup_esikKayipKwh,gup_kaliteSapma,0)-IF($P15="YETIM",gup_kaliteCeza,0)))) | N15: =IF($A15="","",IF(OR($J15<gup_esikPr,$F15>gup_esikKayipKwh,$M15<gup_esikSaglik),"ALARM","UYGUN")) | O15: =IF($A15="","",1) | P15: =IF($A15="","",IF(OR($B15="",COUNTIF(tblVarliklar[VarlikId],$B15)=0),"YETIM","TAMAM"))
A16: GUP-00011 | B16: GES-00003 | C16: 46212 | D16: 379.6 | E16: 5.4 | F16: 133.4 | G16: DIGER | H16: =IF($A16="","",IFERROR(SUMIF(tblVarliklar[VarlikId],$B16,tblVarliklar[KapasiteKwp_kwp]),gup_varsayilanKapasite)) | I16: =IF($A16="","",$E16*$H16) | J16: =IF(OR($A16="",$I16=0),"",$D16/$I16) | K16: =IF(OR($A16="",$I16=0),"",$F16/$I16) | L16: =IF($A16="","",$D16) | M16: =IF($A16="","",MAX(0,MIN(100,gup_kaliteTaban-IF($J16<gup_esikPr,gup_kaliteCeza,0)-IF($F16>gup_esikKayipKwh,gup_kaliteSapma,0)-IF($P16="YETIM",gup_kaliteCeza,0)))) | N16: =IF($A16="","",IF(OR($J16<gup_esikPr,$F16>gup_esikKayipKwh,$M16<gup_esikSaglik),"ALARM","UYGUN")) | O16: =IF($A16="","",1) | P16: =IF($A16="","",IF(OR($B16="",COUNTIF(tblVarliklar[VarlikId],$B16)=0),"YETIM","TAMAM"))
A17: GUP-00012 | B17: GES-00004 | C17: 46209 | D17: 3597 | E17: 5.45 | F17: 2943 | G17: KIRLENME | H17: =IF($A17="","",IFERROR(SUMIF(tblVarliklar[VarlikId],$B17,tblVarliklar[KapasiteKwp_kwp]),gup_varsayilanKapasite)) | I17: =IF($A17="","",$E17*$H17) | J17: =IF(OR($A17="",$I17=0),"",$D17/$I17) | K17: =IF(OR($A17="",$I17=0),"",$F17/$I17) | L17: =IF($A17="","",$D17) | M17: =IF($A17="","",MAX(0,MIN(100,gup_kaliteTaban-IF($J17<gup_esikPr,gup_kaliteCeza,0)-IF($F17>gup_esikKayipKwh,gup_kaliteSapma,0)-IF($P17="YETIM",gup_kaliteCeza,0)))) | N17: =IF($A17="","",IF(OR($J17<gup_esikPr,$F17>gup_esikKayipKwh,$M17<gup_esikSaglik),"ALARM","UYGUN")) | O17: =IF($A17="","",1) | P17: =IF($A17="","",IF(OR($B17="",COUNTIF(tblVarliklar[VarlikId],$B17)=0),"YETIM","TAMAM"))
... A34: GUP-00029 | B34: GES-00005 | C34: 46158 | D34: 207.4 | E34: 4.05 | F34: 51.8 | G34: DIGER | H34: =IF($A34="","",IFERROR(SUMIF(tblVarliklar[VarlikId],$B34,tblVarliklar[KapasiteKwp_kwp]),gup_varsayilanKapasite)) | I34: =IF($A34="","",$E34*$H34) | J34: =IF(OR($A34="",$I34=0),"",$D34/$I34) | K34: =IF(OR($A34="",$I34=0),"",$F34/$I34) | L34: =IF($A34="","",$D34) | M34: =IF($A34="","",MAX(0,MIN(100,gup_kaliteTaban-IF($J34<gup_esikPr,gup_kaliteCeza,0)-IF($F34>gup_esikKayipKwh,gup_kaliteSapma,0)-IF($P34="YETIM",gup_kaliteCeza,0)))) | N34: =IF($A34="","",IF(OR($J34<gup_esikPr,$F34>gup_esikKayipKwh,$M34<gup_esikSaglik),"ALARM","UYGUN")) | O34: =IF($A34="","",1) | P34: =IF($A34="","",IF(OR($B34="",COUNTIF(tblVarliklar[VarlikId],$B34)=0),"YETIM","TAMAM"))
A35: GUP-00030 | C35: 46155 | D35: 1535 | E35: 4.1 | F35: 597 | G35: KIRLENME | H35: =IF($A35="","",IFERROR(SUMIF(tblVarliklar[VarlikId],$B35,tblVarliklar[KapasiteKwp_kwp]),gup_varsayilanKapasite)) | I35: =IF($A35="","",$E35*$H35) | J35: =IF(OR($A35="",$I35=0),"",$D35/$I35) | K35: =IF(OR($A35="",$I35=0),"",$F35/$I35) | L35: =IF($A35="","",$D35) | M35: =IF($A35="","",MAX(0,MIN(100,gup_kaliteTaban-IF($J35<gup_esikPr,gup_kaliteCeza,0)-IF($F35>gup_esikKayipKwh,gup_kaliteSapma,0)-IF($P35="YETIM",gup_kaliteCeza,0)))) | N35: =IF($A35="","",IF(OR($J35<gup_esikPr,$F35>gup_esikKayipKwh,$M35<gup_esikSaglik),"ALARM","UYGUN")) | O35: =IF($A35="","",1) | P35: =IF($A35="","",IF(OR($B35="",COUNTIF(tblVarliklar[VarlikId],$B35)=0),"YETIM","TAMAM"))
A36: GUP-00031 | B36: GES-00007 | C36: 46152 | D36: 386.6 | E36: 4.75 | F36: 135.9 | G36: GOLGE | H36: =IF($A36="","",IFERROR(SUMIF(tblVarliklar[VarlikId],$B36,tblVarliklar[KapasiteKwp_kwp]),gup_varsayilanKapasite)) | I36: =IF($A36="","",$E36*$H36) | J36: =IF(OR($A36="",$I36=0),"",$D36/$I36) | K36: =IF(OR($A36="",$I36=0),"",$F36/$I36) | L36: =IF($A36="","",$D36) | M36: =IF($A36="","",MAX(0,MIN(100,gup_kaliteTaban-IF($J36<gup_esikPr,gup_kaliteCeza,0)-IF($F36>gup_esikKayipKwh,gup_kaliteSapma,0)-IF($P36="YETIM",gup_kaliteCeza,0)))) | N36: =IF($A36="","",IF(OR($J36<gup_esikPr,$F36>gup_esikKayipKwh,$M36<gup_esikSaglik),"ALARM","UYGUN")) | O36: =IF($A36="","",1) | P36: =IF($A36="","",IF(OR($B36="",COUNTIF(tblVarliklar[VarlikId],$B36)=0),"YETIM","TAMAM"))
A37: GUP-00032 | B37: GES-00008 | C37: 46149 | D37: 1559.5 | E37: 5.4 | F37: 492.5 | G37: INVERTER | H37: =IF($A37="","",IFERROR(SUMIF(tblVarliklar[VarlikId],$B37,tblVarliklar[KapasiteKwp_kwp]),gup_varsayilanKapasite)) | I37: =IF($A37="","",$E37*$H37) | J37: =IF(OR($A37="",$I37=0),"",$D37/$I37) | K37: =IF(OR($A37="",$I37=0),"",$F37/$I37) | L37: =IF($A37="","",$D37) | M37: =IF($A37="","",MAX(0,MIN(100,gup_kaliteTaban-IF($J37<gup_esikPr,gup_kaliteCeza,0)-IF($F37>gup_esikKayipKwh,gup_kaliteSapma,0)-IF($P37="YETIM",gup_kaliteCeza,0)))) | N37: =IF($A37="","",IF(OR($J37<gup_esikPr,$F37>gup_esikKayipKwh,$M37<gup_esikSaglik),"ALARM","UYGUN")) | O37: =IF($A37="","",1) | P37: =IF($A37="","",IF(OR($B37="",COUNTIF(tblVarliklar[VarlikId],$B37)=0),"YETIM","TAMAM"))
A38: GUP-00033 | B38: GES-99999 | C38: 46146 | D38: 510.1 | E38: 5.45 | F38: 143.9 | G38: ARIZA | H38: =IF($A38="","",IFERROR(SUMIF(tblVarliklar[VarlikId],$B38,tblVarliklar[KapasiteKwp_kwp]),gup_varsayilanKapasite)) | I38: =IF($A38="","",$E38*$H38) | J38: =IF(OR($A38="",$I38=0),"",$D38/$I38) | K38: =IF(OR($A38="",$I38=0),"",$F38/$I38) | L38: =IF($A38="","",$D38) | M38: =IF($A38="","",MAX(0,MIN(100,gup_kaliteTaban-IF($J38<gup_esikPr,gup_kaliteCeza,0)-IF($F38>gup_esikKayipKwh,gup_kaliteSapma,0)-IF($P38="YETIM",gup_kaliteCeza,0)))) | N38: =IF($A38="","",IF(OR($J38<gup_esikPr,$F38>gup_esikKayipKwh,$M38<gup_esikSaglik),"ALARM","UYGUN")) | O38: =IF($A38="","",1) | P38: =IF($A38="","",IF(OR($B38="",COUNTIF(tblVarliklar[VarlikId],$B38)=0),"YETIM","TAMAM"))
A39: GUP-00034 | B39: GES-00002 | C39: 46143 | D39: 4148 | E39: 6.1 | F39: 1037 | G39: ISINIM | H39: =IF($A39="","",IFERROR(SUMIF(tblVarliklar[VarlikId],$B39,tblVarliklar[KapasiteKwp_kwp]),gup_varsayilanKapasite)) | I39: =IF($A39="","",$E39*$H39) | J39: =IF(OR($A39="",$I39=0),"",$D39/$I39) | K39: =IF(OR($A39="",$I39=0),"",$F39/$I39) | L39: =IF($A39="","",$D39) | M39: =IF($A39="","",MAX(0,MIN(100,gup_kaliteTaban-IF($J39<gup_esikPr,gup_kaliteCeza,0)-IF($F39>gup_esikKayipKwh,gup_kaliteSapma,0)-IF($P39="YETIM",gup_kaliteCeza,0)))) | N39: =IF($A39="","",IF(OR($J39<gup_esikPr,$F39>gup_esikKayipKwh,$M39<gup_esikSaglik),"ALARM","UYGUN")) | O39: =IF($A39="","",1) | P39: =IF($A39="","",IF(OR($B39="",COUNTIF(tblVarliklar[VarlikId],$B39)=0),"YETIM","TAMAM"))
A40: GUP-00035 | B40: GES-00003 | C40: 46140 | D40: 246.2 | E40: 3.6 | F40: 95.8 | G40: DIGER | H40: =IF($A40="","",IFERROR(SUMIF(tblVarliklar[VarlikId],$B40,tblVarliklar[KapasiteKwp_kwp]),gup_varsayilanKapasite)) | I40: =IF($A40="","",$E40*$H40) | J40: =IF(OR($A40="",$I40=0),"",$D40/$I40) | K40: =IF(OR($A40="",$I40=0),"",$F40/$I40) | L40: =IF($A40="","",$D40) | M40: =IF($A40="","",MAX(0,MIN(100,gup_kaliteTaban-IF($J40<gup_esikPr,gup_kaliteCeza,0)-IF($F40>gup_esikKayipKwh,gup_kaliteSapma,0)-IF($P40="YETIM",gup_kaliteCeza,0)))) | N40: =IF($A40="","",IF(OR($J40<gup_esikPr,$F40>gup_esikKayipKwh,$M40<gup_esikSaglik),"ALARM","UYGUN")) | O40: =IF($A40="","",1) | P40: =IF($A40="","",IF(OR($B40="",COUNTIF(tblVarliklar[VarlikId],$B40)=0),"YETIM","TAMAM"))
A41: GUP-00036 | B41: GES-00004 | C41: 46137 | D41: 3241.2 | E41: 3.65 | F41: 1138.8 | G41: KIRLENME | H41: =IF($A41="","",IFERROR(SUMIF(tblVarliklar[VarlikId],$B41,tblVarliklar[KapasiteKwp_kwp]),gup_varsayilanKapasite)) | I41: =IF($A41="","",$E41*$H41) | J41: =IF(OR($A41="",$I41=0),"",$D41/$I41) | K41: =IF(OR($A41="",$I41=0),"",$F41/$I41) | L41: =IF($A41="","",$D41) | M41: =IF($A41="","",MAX(0,MIN(100,gup_kaliteTaban-IF($J41<gup_esikPr,gup_kaliteCeza,0)-IF($F41>gup_esikKayipKwh,gup_kaliteSapma,0)-IF($P41="YETIM",gup_kaliteCeza,0)))) | N41: =IF($A41="","",IF(OR($J41<gup_esikPr,$F41>gup_esikKayipKwh,$M41<gup_esikSaglik),"ALARM","UYGUN")) | O41: =IF($A41="","",1) | P41: =IF($A41="","",IF(OR($B41="",COUNTIF(tblVarliklar[VarlikId],$B41)=0),"YETIM","TAMAM"))
H42: =IF($A42="","",IFERROR(SUMIF(tblVarliklar[VarlikId],$B42,tblVarliklar[KapasiteKwp_kwp]),gup_varsayilanKapasite)) | I42: =IF($A42="","",$E42*$H42) | J42: =IF(OR($A42="",$I42=0),"",$D42/$I42) | K42: =IF(OR($A42="",$I42=0),"",$F42/$I42) | L42: =IF($A42="","",$D42) | M42: =IF($A42="","",MAX(0,MIN(100,gup_kaliteTaban-IF($J42<gup_esikPr,gup_kaliteCeza,0)-IF($F42>gup_esikKayipKwh,gup_kaliteSapma,0)-IF($P42="YETIM",gup_kaliteCeza,0)))) | N42: =IF($A42="","",IF(OR($J42<gup_esikPr,$F42>gup_esikKayipKwh,$M42<gup_esikSaglik),"ALARM","UYGUN")) | O42: =IF($A42="","",1) | P42: =IF($A42="","",IF(OR($B42="",COUNTIF(tblVarliklar[VarlikId],$B42)=0),"YETIM","TAMAM"))
H43: =IF($A43="","",IFERROR(SUMIF(tblVarliklar[VarlikId],$B43,tblVarliklar[KapasiteKwp_kwp]),gup_varsayilanKapasite)) | I43: =IF($A43="","",$E43*$H43) | J43: =IF(OR($A43="",$I43=0),"",$D43/$I43) | K43: =IF(OR($A43="",$I43=0),"",$F43/$I43) | L43: =IF($A43="","",$D43) | M43: =IF($A43="","",MAX(0,MIN(100,gup_kaliteTaban-IF($J43<gup_esikPr,gup_kaliteCeza,0)-IF($F43>gup_esikKayipKwh,gup_kaliteSapma,0)-IF($P43="YETIM",gup_kaliteCeza,0)))) | N43: =IF($A43="","",IF(OR($J43<gup_esikPr,$F43>gup_esikKayipKwh,$M43<gup_esikSaglik),"ALARM","UYGUN")) | O43: =IF($A43="","",1) | P43: =IF($A43="","",IF(OR($B43="",COUNTIF(tblVarliklar[VarlikId],$B43)=0),"YETIM","TAMAM"))
H44: =IF($A44="","",IFERROR(SUMIF(tblVarliklar[VarlikId],$B44,tblVarliklar[KapasiteKwp_kwp]),gup_varsayilanKapasite)) | I44: =IF($A44="","",$E44*$H44) | J44: =IF(OR($A44="",$I44=0),"",$D44/$I44) | K44: =IF(OR($A44="",$I44=0),"",$F44/$I44) | L44: =IF($A44="","",$D44) | M44: =IF($A44="","",MAX(0,MIN(100,gup_kaliteTaban-IF($J44<gup_esikPr,gup_kaliteCeza,0)-IF($F44>gup_esikKayipKwh,gup_kaliteSapma,0)-IF($P44="YETIM",gup_kaliteCeza,0)))) | N44: =IF($A44="","",IF(OR($J44<gup_esikPr,$F44>gup_esikKayipKwh,$M44<gup_esikSaglik),"ALARM","UYGUN")) | O44: =IF($A44="","",1) | P44: =IF($A44="","",IF(OR($B44="",COUNTIF(tblVarliklar[VarlikId],$B44)=0),"YETIM","TAMAM"))
H45: =IF($A45="","",IFERROR(SUMIF(tblVarliklar[VarlikId],$B45,tblVarliklar[KapasiteKwp_kwp]),gup_varsayilanKapasite)) | I45: =IF($A45="","",$E45*$H45) | J45: =IF(OR($A45="",$I45=0),"",$D45/$I45) | K45: =IF(OR($A45="",$I45=0),"",$F45/$I45) | L45: =IF($A45="","",$D45) | M45: =IF($A45="","",MAX(0,MIN(100,gup_kaliteTaban-IF($J45<gup_esikPr,gup_kaliteCeza,0)-IF($F45>gup_esikKayipKwh,gup_kaliteSapma,0)-IF($P45="YETIM",gup_kaliteCeza,0)))) | N45: =IF($A45="","",IF(OR($J45<gup_esikPr,$F45>gup_esikKayipKwh,$M45<gup_esikSaglik),"ALARM","UYGUN")) | O45: =IF($A45="","",1) | P45: =IF($A45="","",IF(OR($B45="",COUNTIF(tblVarliklar[VarlikId],$B45)=0),"YETIM","TAMAM"))
H46: =IF($A46="","",IFERROR(SUMIF(tblVarliklar[VarlikId],$B46,tblVarliklar[KapasiteKwp_kwp]),gup_varsayilanKapasite)) | I46: =IF($A46="","",$E46*$H46) | J46: =IF(OR($A46="",$I46=0),"",$D46/$I46) | K46: =IF(OR($A46="",$I46=0),"",$F46/$I46) | L46: =IF($A46="","",$D46) | M46: =IF($A46="","",MAX(0,MIN(100,gup_kaliteTaban-IF($J46<gup_esikPr,gup_kaliteCeza,0)-IF($F46>gup_esikKayipKwh,gup_kaliteSapma,0)-IF($P46="YETIM",gup_kaliteCeza,0)))) | N46: =IF($A46="","",IF(OR($J46<gup_esikPr,$F46>gup_esikKayipKwh,$M46<gup_esikSaglik),"ALARM","UYGUN")) | O46: =IF($A46="","",1) | P46: =IF($A46="","",IF(OR($B46="",COUNTIF(tblVarliklar[VarlikId],$B46)=0),"YETIM","TAMAM"))
H47: =IF($A47="","",IFERROR(SUMIF(tblVarliklar[VarlikId],$B47,tblVarliklar[KapasiteKwp_kwp]),gup_varsayilanKapasite)) | I47: =IF($A47="","",$E47*$H47) | J47: =IF(OR($A47="",$I47=0),"",$D47/$I47) | K47: =IF(OR($A47="",$I47=0),"",$F47/$I47) | L47: =IF($A47="","",$D47) | M47: =IF($A47="","",MAX(0,MIN(100,gup_kaliteTaban-IF($J47<gup_esikPr,gup_kaliteCeza,0)-IF($F47>gup_esikKayipKwh,gup_kaliteSapma,0)-IF($P47="YETIM",gup_kaliteCeza,0)))) | N47: =IF($A47="","",IF(OR($J47<gup_esikPr,$F47>gup_esikKayipKwh,$M47<gup_esikSaglik),"ALARM","UYGUN")) | O47: =IF($A47="","",1) | P47: =IF($A47="","",IF(OR($B47="",COUNTIF(tblVarliklar[VarlikId],$B47)=0),"YETIM","TAMAM"))
H48: =IF($A48="","",IFERROR(SUMIF(tblVarliklar[VarlikId],$B48,tblVarliklar[KapasiteKwp_kwp]),gup_varsayilanKapasite)) | I48: =IF($A48="","",$E48*$H48) | J48: =IF(OR($A48="",$I48=0),"",$D48/$I48) | K48: =IF(OR($A48="",$I48=0),"",$F48/$I48) | L48: =IF($A48="","",$D48) | M48: =IF($A48="","",MAX(0,MIN(100,gup_kaliteTaban-IF($J48<gup_esikPr,gup_kaliteCeza,0)-IF($F48>gup_esikKayipKwh,gup_kaliteSapma,0)-IF($P48="YETIM",gup_kaliteCeza,0)))) | N48: =IF($A48="","",IF(OR($J48<gup_esikPr,$F48>gup_esikKayipKwh,$M48<gup_esikSaglik),"ALARM","UYGUN")) | O48: =IF($A48="","",1) | P48: =IF($A48="","",IF(OR($B48="",COUNTIF(tblVarliklar[VarlikId],$B48)=0),"YETIM","TAMAM"))
H49: =IF($A49="","",IFERROR(SUMIF(tblVarliklar[VarlikId],$B49,tblVarliklar[KapasiteKwp_kwp]),gup_varsayilanKapasite)) | I49: =IF($A49="","",$E49*$H49) | J49: =IF(OR($A49="",$I49=0),"",$D49/$I49) | K49: =IF(OR($A49="",$I49=0),"",$F49/$I49) | L49: =IF($A49="","",$D49) | M49: =IF($A49="","",MAX(0,MIN(100,gup_kaliteTaban-IF($J49<gup_esikPr,gup_kaliteCeza,0)-IF($F49>gup_esikKayipKwh,gup_kaliteSapma,0)-IF($P49="YETIM",gup_kaliteCeza,0)))) | N49: =IF($A49="","",IF(OR($J49<gup_esikPr,$F49>gup_esikKayipKwh,$M49<gup_esikSaglik),"ALARM","UYGUN")) | O49: =IF($A49="","",1) | P49: =IF($A49="","",IF(OR($B49="",COUNTIF(tblVarliklar[VarlikId],$B49)=0),"YETIM","TAMAM"))
H50: =IF($A50="","",IFERROR(SUMIF(tblVarliklar[VarlikId],$B50,tblVarliklar[KapasiteKwp_kwp]),gup_varsayilanKapasite)) | I50: =IF($A50="","",$E50*$H50) | J50: =IF(OR($A50="",$I50=0),"",$D50/$I50) | K50: =IF(OR($A50="",$I50=0),"",$F50/$I50) | L50: =IF($A50="","",$D50) | M50: =IF($A50="","",MAX(0,MIN(100,gup_kaliteTaban-IF($J50<gup_esikPr,gup_kaliteCeza,0)-IF($F50>gup_esikKayipKwh,gup_kaliteSapma,0)-IF($P50="YETIM",gup_kaliteCeza,0)))) | N50: =IF($A50="","",IF(OR($J50<gup_esikPr,$F50>gup_esikKayipKwh,$M50<gup_esikSaglik),"ALARM","UYGUN")) | O50: =IF($A50="","",1) | P50: =IF($A50="","",IF(OR($B50="",COUNTIF(tblVarliklar[VarlikId],$B50)=0),"YETIM","TAMAM"))
H51: =IF($A51="","",IFERROR(SUMIF(tblVarliklar[VarlikId],$B51,tblVarliklar[KapasiteKwp_kwp]),gup_varsayilanKapasite)) | I51: =IF($A51="","",$E51*$H51) | J51: =IF(OR($A51="",$I51=0),"",$D51/$I51) | K51: =IF(OR($A51="",$I51=0),"",$F51/$I51) | L51: =IF($A51="","",$D51) | M51: =IF($A51="","",MAX(0,MIN(100,gup_kaliteTaban-IF($J51<gup_esikPr,gup_kaliteCeza,0)-IF($F51>gup_esikKayipKwh,gup_kaliteSapma,0)-IF($P51="YETIM",gup_kaliteCeza,0)))) | N51: =IF($A51="","",IF(OR($J51<gup_esikPr,$F51>gup_esikKayipKwh,$M51<gup_esikSaglik),"ALARM","UYGUN")) | O51: =IF($A51="","",1) | P51: =IF($A51="","",IF(OR($B51="",COUNTIF(tblVarliklar[VarlikId],$B51)=0),"YETIM","TAMAM"))
H52: =IF($A52="","",IFERROR(SUMIF(tblVarliklar[VarlikId],$B52,tblVarliklar[KapasiteKwp_kwp]),gup_varsayilanKapasite)) | I52: =IF($A52="","",$E52*$H52) | J52: =IF(OR($A52="",$I52=0),"",$D52/$I52) | K52: =IF(OR($A52="",$I52=0),"",$F52/$I52) | L52: =IF($A52="","",$D52) | M52: =IF($A52="","",MAX(0,MIN(100,gup_kaliteTaban-IF($J52<gup_esikPr,gup_kaliteCeza,0)-IF($F52>gup_esikKayipKwh,gup_kaliteSapma,0)-IF($P52="YETIM",gup_kaliteCeza,0)))) | N52: =IF($A52="","",IF(OR($J52<gup_esikPr,$F52>gup_esikKayipKwh,$M52<gup_esikSaglik),"ALARM","UYGUN")) | O52: =IF($A52="","",1) | P52: =IF($A52="","",IF(OR($B52="",COUNTIF(tblVarliklar[VarlikId],$B52)=0),"YETIM","TAMAM"))
H53: =IF($A53="","",IFERROR(SUMIF(tblVarliklar[VarlikId],$B53,tblVarliklar[KapasiteKwp_kwp]),gup_varsayilanKapasite)) | I53: =IF($A53="","",$E53*$H53) | J53: =IF(OR($A53="",$I53=0),"",$D53/$I53) | K53: =IF(OR($A53="",$I53=0),"",$F53/$I53) | L53: =IF($A53="","",$D53) | M53: =IF($A53="","",MAX(0,MIN(100,gup_kaliteTaban-IF($J53<gup_esikPr,gup_kaliteCeza,0)-IF($F53>gup_esikKayipKwh,gup_kaliteSapma,0)-IF($P53="YETIM",gup_kaliteCeza,0)))) | N53: =IF($A53="","",IF(OR($J53<gup_esikPr,$F53>gup_esikKayipKwh,$M53<gup_esikSaglik),"ALARM","UYGUN")) | O53: =IF($A53="","",1) | P53: =IF($A53="","",IF(OR($B53="",COUNTIF(tblVarliklar[VarlikId],$B53)=0),"YETIM","TAMAM"))
... H255: =IF($A255="","",IFERROR(SUMIF(tblVarliklar[VarlikId],$B255,tblVarliklar[KapasiteKwp_kwp]),gup_varsayilanKapasite)) | I255: =IF($A255="","",$E255*$H255) | J255: =IF(OR($A255="",$I255=0),"",$D255/$I255) | K255: =IF(OR($A255="",$I255=0),"",$F255/$I255) | L255: =IF($A255="","",$D255) | M255: =IF($A255="","",MAX(0,MIN(100,gup_kaliteTaban-IF($J255<gup_esikPr,gup_kaliteCeza,0)-IF($F255>gup_esikKayipKwh,gup_kaliteSapma,0)-IF($P255="YETIM",gup_kaliteCeza,0)))) | N255: =IF($A255="","",IF(OR($J255<gup_esikPr,$F255>gup_esikKayipKwh,$M255<gup_esikSaglik),"ALARM","UYGUN")) | O255: =IF($A255="","",1) | P255: =IF($A255="","",IF(OR($B255="",COUNTIF(tblVarliklar[VarlikId],$B255)=0),"YETIM","TAMAM"))

Sheet DONEM_ANALIZ
A1: DONEM ANALIZ — GES Üretim & Performans Takibi
A3: 12 aylık sezonsallık — üretim ve PR zinciri (S03)
A5: Ay | B5: Ay_Anahtari | C5: Uretim kWh | D5: Kayip kWh | E5: PR Ort | F5: Sezonsal Etiket
A6: Ocak | B6: Ay_1 | C6: 82000 | D6: 18000 | E6: 0.68 | F6: 12_AY_SEZONSAL
A7: Subat | B7: Ay_2 | C7: 95000 | D7: 20000 | E7: 0.7 | F7: 12_AY_SEZONSAL
A8: Mart | B8: Ay_3 | C8: 128000 | D8: 22000 | E8: 0.74 | F8: 12_AY_SEZONSAL
A9: Nisan | B9: Ay_4 | C9: 155000 | D9: 24000 | E9: 0.76 | F9: 12_AY_SEZONSAL
A10: Mayis | B10: Ay_5 | C10: 178000 | D10: 26000 | E10: 0.78 | F10: 12_AY_SEZONSAL
A11: Haziran | B11: Ay_6 | C11: 195000 | D11: 28000 | E11: 0.8 | F11: 12_AY_SEZONSAL
A12: Temmuz | B12: Ay_7 | C12: 210000 | D12: 30000 | E12: 0.81 | F12: 12_AY_SEZONSAL
A13: Agustos | B13: Ay_8 | C13: 205000 | D13: 29000 | E13: 0.8 | F13: 12_AY_SEZONSAL
A14: Eylul | B14: Ay_9 | C14: 168000 | D14: 25000 | E14: 0.77 | F14: 12_AY_SEZONSAL
A15: Ekim | B15: Ay_10 | C15: 132000 | D15: 21000 | E15: 0.74 | F15: 12_AY_SEZONSAL
A16: Kasim | B16: Ay_11 | C16: 98000 | D16: 19000 | E16: 0.7 | F16: 12_AY_SEZONSAL
A17: Aralik | B17: Ay_12 | C17: 78000 | D17: 17000 | E17: 0.67 | F17: 12_AY_SEZONSAL
A20: Sezonsal Trend Özeti | B20: =gup_sezonsalTrend
A22: 12 Ay Toplam Üretim | B22: =SUM(C6:C17)
A23: 12 Ay Toplam Kayıp | B23: =SUM(D6:D17)
A24: 12 Ay Ort PR | B24: =AVERAGE(E6:E17)
A25: Canlı dönem üretim | B25: =gup_toplamUretim
A26: Canlı dönem PR | B26: =gup_prOrani

Sheet HESAP
A1: HESAP — GES Üretim & Performans Takibi
A3: Hesap motoru — ≥40 adım; sabitler AYARLAR'dan
A5: Adım | B5: Açıklama | C5: Değer
A6: H01 | B6: Toplam günlük kayıt | C6: =COUNTA(tblGunluk[SatirId])
A7: H02 | B7: Dolu kayıt | C7: =SUM(tblGunluk[FormulKayitDolu])
A8: H03 | B8: Toplam üretim kWh | C8: =SUM(tblGunluk[UretimKwh_kwh])
A9: H04 | B9: Toplam ışınım | C9: =SUM(tblGunluk[IsinimKwhm2_kwhm2])
A10: H05 | B10: Toplam kayıp kWh | C10: =SUM(tblGunluk[KayipKwh_kwh])
A11: H06 | B11: Toplam teorik kWh | C11: =SUM(tblGunluk[FormulTeorik_kwh])
A12: H07 | B12: PR oranı | C12: =IFERROR(C8/MAX(C11,1),0)
A13: H08 | B13: Kayıp payı | C13: =IFERROR(C10/MAX(C11,1),0)
A14: H09 | B14: Net üretim | C14: =SUM(tblGunluk[FormulNet_kwh])
A15: H10 | B15: Aktif santral adet | C15: =COUNTIF(tblVarliklar[Aktif],"EVET")
A16: H11 | B16: Toplam santral kart | C16: =COUNTA(tblVarliklar[VarlikId])
A17: H12 | B17: Alarm adet | C17: =COUNTIF(tblGunluk[AlarmBayrak],"ALARM")
A18: H13 | B18: Yetim kayıt | C18: =COUNTIF(tblGunluk[FormulYetim],"YETIM")
A19: H14 | B19: Ortalama sağlık skor | C19: =IFERROR(AVERAGEIF(tblGunluk[SaglikSkor_puan],">0"),0)
A20: H15 | B20: Min sağlık skor | C20: =IFERROR(MIN(tblGunluk[SaglikSkor_puan]),0)
A21: H16 | B21: PR eşik altı adet | C21: =COUNTIFS(tblGunluk[FormulPr_oran],"<"&gup_esikPr,tblGunluk[FormulKayitDolu],">0")
A22: H17 | B22: Kayıp eşik aşımı | C22: =COUNTIFS(tblGunluk[KayipKwh_kwh],">"&gup_esikKayipKwh,tblGunluk[FormulKayitDolu],">0")
A23: H18 | B23: Düşük sağlık adet | C23: =COUNTIFS(tblGunluk[SaglikSkor_puan],"<"&gup_esikSaglik,tblGunluk[FormulKayitDolu],">0")
A24: H19 | B24: Günlük PR ort | C24: =IFERROR(AVERAGEIF(tblGunluk[FormulPr_oran],">0"),0)
A25: H20 | B25: Aylık üretim proxy | C25: =C8*gup_aylikCarpan
A26: H21 | B26: PR sapma | C26: =IFERROR(ABS(C12-gup_esikPr),0)
A27: H22 | B27: Kirlenme kayıp pay | C27: =IFERROR(COUNTIF(tblGunluk[KayipTuru],"KIRLENME")/MAX(C7,1),0)
A28: H23 | B28: Gölge kayıp pay | C28: =IFERROR(COUNTIF(tblGunluk[KayipTuru],"GOLGE")/MAX(C7,1),0)
A29: H24 | B29: İnverter kayıp pay | C29: =IFERROR(COUNTIF(tblGunluk[KayipTuru],"INVERTER")/MAX(C7,1),0)
A30: H25 | B30: Arıza kayıp pay | C30: =IFERROR(COUNTIF(tblGunluk[KayipTuru],"ARIZA")/MAX(C7,1),0)
A31: H26 | B31: Temkinli senaryo | C31: =C8*gup_senaryoTemkinli
A32: H27 | B32: Baz senaryo | C32: =C8*gup_senaryoBaz
A33: H28 | B33: İyimser senaryo | C33: =C8*gup_senaryoIyimser
A34: H29 | B34: Senaryo farkı | C34: =C33-C31
A35: H30 | B35: Tornado ışınım etki | C35: =C9*gup_tornadoOran*gup_varsayilanKapasite
A36: H31 | B36: Tornado kayıp etki | C36: =C10*gup_tornadoOran
A37: H32 | B37: Tornado PR etki | C37: =C8*gup_tornadoOran
A38: H33 | B38: Tornado zirve | C38: =MAX(C35,C36,C37)
A39: H34 | B39: HHI proxy | C39: =IFERROR(C27^2+C28^2+C29^2+C30^2,0)
A40: H35 | B40: Kalite skor | C40: =MAX(0,gup_kaliteTaban-C21*gup_kaliteCeza-C22*gup_kaliteSapma-C23*gup_kaliteSapma)
