Workbook
Name DolarKuru: [1]Ürünlerim!$G$2
Name EuroKuru: [1]Ürünlerim!$G$3
Name Lst_Banka_Kasa: [2]!Tbl_Banka_Kasa[Banka-Kasa]
Name Lst_Cariler: [1]!Tablo3[Cari Adı]
Name lst_EmlakTipi: [8]!tbl_ayar_EmlakTipi[Emlak Tipi]
Name Lst_Maliye_Kategorileri: OFFSET([2]Pvt_Listeler!$A$3,1,0,COUNTA([2]Pvt_Listeler!$A:$A)-1,1)
Name lst_Müşteriler: [8]!Tablo1[İsim Soyisim]
Name Lst_Nakit_Vadeli: [1]!Tablo13[Nakit / Vadeli Seçimi]
Name Lst_Ödeme_Yön: [2]!Tbl_Ödeme_Yön[Ödeme Yöntemi]
Name lst_Satılık_Kiralık: [8]!tbl_ayar_Satılık[Satılık/Kiralık]
Name Lst_Satış_Per: [4]!Tablo2[Ad Soyad]
Name Lst_Servis: [2]!Tbl_Sektör_Kategori[Servis]
Name Lst_TümHisseler: [5]!TÜM_HİSSELER_1[Menkul]
Name Lst_Ürün_Ailesi: [2]!Tbl_Ürün_Ailesi[Ürün Ailesi]
Name Lst_Ürünler: [1]!Tablo4[Ürün Adı]
Name Lst_Ürünlerim: [6]!Tablo2[Ürün Adı]
Name Lst_Yıl_Ay: [2]!Tablo8[Tarihler]
Name oran: [7]Ürün_Fiyat_Listesi!$E$3
Name rng_maxyear: Calc!$B$4
Name rng_minyear: Calc!$B$3
Name rng_seconds: Calc!$H$2
Name rng_shownyear: Calc!$B$6
Name Sütun_Aralığı: OFFSET(Data!$A$1,1,MATCH(Calc!$B$6,Data!$1:$1,0)-1,COUNTA(Data!$B:$B)-1,1)

Sheet Data
A1: Region | B1: Country Name | C1: 1960 | D1: 1961 | E1: 1962 | F1: 1963 | G1: 1964 | H1: 1965 | I1: 1966 | J1: 1967 | K1: 1968 | L1: 1969 | M1: 1970 | N1: 1971 | O1: 1972 | P1: 1973 | Q1: 1974 | R1: 1975 | S1: 1976 | T1: 1977 | U1: 1978 | V1: 1979 | W1: 1980 | X1: 1981 | Y1: 1982 | Z1: 1983 | AA1: 1984 | AB1: 1985 | AC1: 1986 | AD1: 1987 | AE1: 1988 | AF1: 1989 | AG1: 1990 | AH1: 1991 | AI1: 1992 | AJ1: 1993 | AK1: 1994 | AL1: 1995 | AM1: 1996 | AN1: 1997 | AO1: 1998 | AP1: 1999 | AQ1: 2000 | AR1: 2001 | AS1: 2002 | AT1: 2003 | AU1: 2004 | AV1: 2005 | AW1: 2006 | AX1: 2007 | AY1: 2008 | AZ1: 2009 | BA1: 2010 | BB1: 2011 | BC1: 2012 | BD1: 2013 | BE1: 2014 | BF1: 2015 | BG1: 2016 | BH1: 2017
A2: Asia | B2: Afghanistan | C2: 755783 | D2: 796042 | E2: 838885 | F2: 884370 | G2: 932848 | H2: 984301 | I2: 1038888 | J2: 1096387 | K2: 1157782 | L2: 1223837 | M2: 1295415 | N2: 1372537 | O2: 1454693 | P2: 1540644 | Q2: 1628785 | R2: 1717441 | S2: 1807144 | T2: 1897014 | U2: 1982086 | V2: 2054820 | W2: 2119077 | X2: 2161996 | Y2: 2186182 | Z2: 2198724 | AA2: 2212453 | AB2: 2238426 | AC2: 2279257 | AD2: 2336671 | AE2: 2423356 | AF2: 2483662 | AG2: 2593995 | AH2: 2763231 | AI2: 2985692 | AJ2: 3236993 | AK2: 3482633 | AL2: 3697605 | AM2: 3870061 | AN2: 4008109 | AO2: 4130273 | AP2: 4266092 | AQ2: 4436299 | AR2: 4648055 | AS2: 4892951 | AT2: 5155686 | AU2: 5426770 | AV2: 5691823 | AW2: 5931413 | AX2: 6151939 | AY2: 6364968 | AZ2: 6588859 | BA2: 6837008 | BB2: 7114615 | BC2: 7416385 | BD2: 7733964 | BE2: 8054214 | BF2: 8367663 | BG2: 8670939 | BH2: 8971345
A3: Europe | B3: Albania | C3: 493982 | D3: 513592 | E3: 530766 | F3: 547928 | G3: 565248 | H3: 582374 | I3: 599300 | J3: 616687 | K3: 635924 | L3: 656733 | M3: 677801 | N3: 698647 | O3: 720649 | P3: 742333 | Q3: 764166 | R3: 786668 | S3: 809052 | T3: 832109 | U3: 854618 | V3: 876974 | W3: 902120 | X3: 927513 | Y3: 954645 | Z3: 982645 | AA3: 1011235 | AB3: 1040127 | AC3: 1068501 | AD3: 1098349 | AE3: 1127722 | AF3: 1167160 | AG3: 1197222 | AH3: 1198912 | AI3: 1209490 | AJ3: 1219882 | AK3: 1230218 | AL3: 1240399 | AM3: 1250518 | AN3: 1260414 | AO3: 1270214 | AP3: 1279853 | AQ3: 1289391 | AR3: 1298584 | AS3: 1327220 | AT3: 1354848 | AU3: 1381828 | AV3: 1407298 | AW3: 1430886 | AX3: 1452398 | AY3: 1473392 | AZ3: 1495260 | BA3: 1519519 | BB3: 1546929 | BC3: 1575788 | BD3: 1603505 | BE3: 1630119 | BF3: 1654503 | BG3: 1680247 | BH3: 1706345
A4: Africa | B4: Algeria | C4: 3394203 | D4: 3626403 | E4: 3882767 | F4: 4154288 | G4: 4443887 | H4: 4753164 | I4: 5041536 | J4: 5208671 | K4: 5383539 | L4: 5563573 | M4: 5747263 | N4: 5933927 | O4: 6124850 | P4: 6321297 | Q4: 6525328 | R4: 6738780 | S4: 6961531 | T4: 7240239 | U4: 7611660 | V4: 8004279 | W4: 8420028 | X4: 8858976 | Y4: 9321410 | Z4: 9805134 | AA4: 10307407 | AB4: 10824413 | AC4: 11355685 | AD4: 11892457 | AE4: 12421409 | AF4: 12956681 | AG4: 13496456 | AH4: 14039539 | AI4: 14584560 | AJ4: 15126562 | AK4: 15661352 | AL4: 16185540 | AM4: 16698037 | AN4: 17198083 | AO4: 17689675 | AP4: 18188015 | AQ4: 18684937 | AR4: 19180228 | AS4: 19677273 | AT4: 20182205 | AU4: 20703617 | AV4: 21248009 | AW4: 21818169 | AX4: 22414414 | AY4: 23041887 | AZ4: 23700349 | BA4: 24393852 | BB4: 25124194 | BC4: 25888503 | BD4: 26674438 | BE4: 27465760 | BF4: 28248180 | BG4: 29016679 | BH4: 29770548
A5: Oceania | B5: American Samoa | C5: 13251 | D5: 13652 | E5: 14163 | F5: 14769 | G5: 15416 | H5: 16072 | I5: 16721 | J5: 17371 | K5: 18009 | L5: 18624 | M5: 19209 | N5: 19760 | O5: 20281 | P5: 20767 | Q5: 21222 | R5: 21657 | S5: 22055 | T5: 22440 | U5: 22859 | V5: 23397 | W5: 24125 | X5: 25134 | Y5: 26312 | Z5: 27637 | AA5: 29059 | AB5: 30515 | AC5: 32019 | AD5: 33552 | AE5: 35087 | AF5: 36594 | AG5: 38076 | AH5: 39612 | AI5: 41058 | AJ5: 42429 | AK5: 43766 | AL5: 45086 | AM5: 46402 | AN5: 47673 | AO5: 48895 | AP5: 50032 | AQ5: 50956 | AR5: 51480 | AS5: 51915 | AT5: 52199 | AU5: 52270 | AV5: 52083 | AW5: 51612 | AX5: 50897 | AY5: 50072 | AZ5: 49309 | BA5: 48735 | BB5: 48406 | BC5: 48282 | BD5: 48310 | BE5: 48390 | BF5: 48449 | BG5: 48481 | BH5: 48502
A6: Europe | B6: Andorra | C6: 7839 | D6: 8766 | E6: 9754 | F6: 10811 | G6: 11915 | H6: 13067 | I6: 14262 | J6: 15494 | K6: 16765 | L6: 18083 | M6: 19458 | N6: 20902 | O6: 22401 | P6: 23917 | Q6: 25397 | R6: 26791 | S6: 28085 | T6: 29304 | U6: 30491 | V6: 31774 | W6: 33205 | X6: 34800 | Y6: 36561 | Z6: 38451 | AA6: 40421 | AB6: 42441 | AC6: 44342 | AD6: 46118 | AE6: 47926 | AF6: 49758 | AG6: 51627 | AH6: 53571 | AI6: 55546 | AJ6: 57380 | AK6: 58847 | AL6: 59803 | AM6: 60128 | AN6: 59940 | AO6: 59605 | AP6: 59649 | AQ6: 60417 | AR6: 61991 | AS6: 64194 | AT6: 66747 | AU6: 69192 | AV6: 71205 | AW6: 72736 | AX6: 73843 | AY6: 74640 | AZ6: 75097 | BA6: 75007 | BB6: 74309 | BC6: 73059 | BD6: 71527 | BE6: 70066 | BF6: 68921 | BG6: 68199 | BH6: 67845
A7: Africa | B7: Angola | C7: 588866 | D7: 621212 | E7: 657233 | F7: 695164 | G7: 734733 | H7: 775661 | I7: 818062 | J7: 862239 | K7: 908895 | L7: 958930 | M7: 1013543 | N7: 1082871 | O7: 1167455 | P7: 1259815 | Q7: 1360479 | R7: 1469505 | S7: 1587468 | T7: 1714663 | U7: 1852971 | V7: 2004142 | W7: 2169787 | X7: 2351525 | Y7: 2550003 | Z7: 2763060 | AA7: 2987103 | AB7: 3218571 | AC7: 3455744 | AD7: 3699560 | AE7: 3954242 | AF7: 4225990 | AG7: 4520960 | AH7: 4843119 | AI7: 5192396 | AJ7: 5564024 | AK7: 5951759 | AL7: 6302472 | AM7: 6657829 | AN7: 7020148 | AO7: 7397110 | AP7: 7798957 | AQ7: 8234766 | AR7: 8708000 | AS7: 9218787 | AT7: 9765197 | AU7: 10343506 | AV7: 10949424 | AW7: 11501748 | AX7: 12078709 | AY7: 12681825 | AZ7: 13311900 | BA7: 13970768 | BB7: 14659013 | BC7: 15375909 | BD7: 16119491 | BE7: 16887478 | BF7: 17675615 | BG7: 18483548 | BH7: 19311773
A8: Americas | B8: Antigua and Barbuda | C8: 21945 | D8: 21919 | E8: 21959 | F8: 22045 | G8: 22149 | H8: 22252 | I8: 22349 | J8: 22441 | K8: 22519 | L8: 22571 | M8: 22692 | N8: 23114 | O8: 23505 | P8: 23862 | Q8: 24196 | R8: 24502 | S8: 24792 | T8: 25052 | U8: 25265 | V8: 25395 | W8: 25424 | X8: 25352 | Y8: 25197 | Z8: 24973 | AA8: 24711 | AB8: 24438 | AC8: 24153 | AD8: 23870 | AE8: 23647 | AF8: 23549 | AG8: 23628 | AH8: 23870 | AI8: 24008 | AJ8: 24275 | AK8: 24624 | AL8: 25002 | AM8: 25403 | AN8: 25826 | AO8: 26235 | AP8: 26587 | AQ8: 26853 | AR8: 26997 | AS8: 26827 | AT8: 26593 | AU8: 26333 | AV8: 26078 | AW8: 25832 | AX8: 25589 | AY8: 25344 | AZ8: 25097 | BA8: 24837 | BB8: 24603 | BC8: 24703 | BD8: 24798 | BE8: 24892 | BF8: 24981 | BG8: 25085 | BH8: 25210
A9: Americas | B9: Argentina | C9: 15177907 | D9: 15550745 | E9: 15916161 | F9: 16283191 | G9: 16650738 | H9: 17017602 | I9: 17383414 | J9: 17749066 | K9: 18120768 | L9: 18505677 | M9: 18909948 | N9: 19327703 | O9: 19762667 | P9: 20210548 | Q9: 20661009 | R9: 21106169 | S9: 21543399 | T9: 21974571 | U9: 22405664 | V9: 22844170 | W9: 23296127 | X9: 23780333 | Y9: 24285074 | Z9: 24799122 | AA9: 25319368 | AB9: 25842013 | AC9: 26365972 | AD9: 26891584 | AE9: 27418228 | AF9: 27944438 | AG9: 28469636 | AH9: 28987585 | AI9: 29462392 | AJ9: 29933012 | AK9: 30397318 | AL9: 30852828 | AM9: 31298956 | AN9: 31735996 | AO9: 32167673 | AP9: 32599189 | AQ9: 33033754 | AR9: 33472924 | AS9: 33914775 | AT9: 34358150 | AU9: 34801606 | AV9: 35243074 | AW9: 35682119 | AX9: 36119493 | AY9: 36558177 | AZ9: 37001390 | BA9: 37451491 | BB9: 37903594 | BC9: 38358970 | BD9: 38817256 | BE9: 39275219 | BF9: 39728558 | BG9: 40176085 | BH9: 40618237
A10: Asia | B10: Armenia | C10: 960955 | D10: 1012429 | E10: 1065431 | F10: 1119584 | G10: 1174558 | H10: 1229978 | I10: 1285571 | J10: 1341277 | K10: 1397343 | L10: 1454160 | M10: 1511605 | N10: 1569625 | O10: 1628590 | P10: 1688028 | Q10: 1747461 | R10: 1801945 | S10: 1855659 | T10: 1908576 | U10: 1960876 | V10: 2007500 | W10: 2047386 | X10: 2085894 | Y10: 2122747 | Z10: 2159333 | AA10: 2197505 | AB10: 2238079 | AC10: 2282853 | AD10: 2330095 | AE10: 2372859 | AF10: 2393836 | AG10: 2385466 | AH10: 2353776 | AI10: 2302482 | AJ10: 2240025 | AK10: 2178117 | AL10: 2125280 | AM10: 2084084 | AN10: 2052297 | AO10: 2027670 | AP10: 2006224 | AQ10: 1984980 | AR10: 1964164 | AS10: 1948854 | AT10: 1935530 | AU10: 1921532 | AV10: 1906157 | AW10: 1888677 | AX10: 1869501 | AY10: 1850791 | AZ10: 1835406 | BA10: 1825366 | BB10: 1821393 | BC10: 1822527 | BD10: 1827656 | BE10: 1834174 | BF10: 1840158 | BG10: 1845032 | BH10: 1849202
A11: Americas | B11: Aruba | C11: 27526 | D11: 28141 | E11: 28532 | F11: 28761 | G11: 28924 | H11: 29082 | I11: 29253 | J11: 29416 | K11: 29575 | L11: 29738 | M11: 29900 | N11: 30082 | O11: 30275 | P11: 30470 | Q11: 30605 | R11: 30661 | S11: 30615 | T11: 30495 | U11: 30353 | V11: 30282 | W11: 30332 | X11: 30560 | Y11: 30943 | Z11: 31365 | AA11: 31676 | AB11: 31762 | AC11: 31560 | AD11: 31142 | AE11: 30753 | AF11: 30720 | AG11: 31273 | AH11: 32507 | AI11: 34116 | AJ11: 35953 | AK11: 37719 | AL11: 39172 | AM11: 40232 | AN11: 40970 | AO11: 41488 | AP11: 41945 | AQ11: 42444 | AR11: 43048 | AS11: 43670 | AT11: 44246 | AU11: 44669 | AV11: 44889 | AW11: 44881 | AX11: 44686 | AY11: 44375 | AZ11: 44052 | BA11: 43778 | BB11: 43822 | BC11: 44064 | BD11: 44360 | BE11: 44674 | BF11: 44979 | BG11: 45275 | BH11: 45572
A12: Oceania | B12: Australia | C12: 8378309 | D12: 8589875 | E12: 8832932 | F12: 9034955 | G12: 9245383 | H12: 9459784 | I12: 9709943 | J12: 9852991 | K12: 10048170 | L12: 10280809 | M12: 10505755 | N12: 10887779 | O12: 11110846 | P12: 11303156 | Q12: 11614598 | R12: 11780153 | S12: 11920613 | T12: 12077392 | U12: 12240482 | V12: 12395391 | W12: 12569300 | X12: 12792439 | Y12: 13002993 | Z12: 13162165 | AA12: 13307374 | AB12: 13486012 | AC12: 13704062 | AD12: 13909213 | AE12: 14133874 | AF12: 14370091 | AG12: 14579227 | AH12: 14761055 | AI12: 14920611 | AJ12: 15044687 | AK12: 15181749 | AL12: 15342767 | AM12: 15521685 | AN12: 15672048 | AO12: 15811356 | AP12: 15967866 | AQ12: 16133530 | AR12: 16326333 | AS12: 16550802 | AT12: 16780377 | AU12: 17000206 | AV12: 17250330 | AW12: 17531121 | AX12: 17666387 | AY12: 18049708 | AZ12: 18451611 | BA12: 18767085 | BB12: 19056040 | BC12: 19422528 | BD12: 19790208 | BE12: 20120012 | BF12: 20440360 | BG12: 20772874 | BH12: 21131467
... A61: Africa | B61: Equatorial Guinea | C61: 65202 | D61: 67699 | E61: 68888 | F61: 70177 | G61: 71700 | H61: 73515 | I61: 75752 | J61: 78296 | K61: 80681 | L61: 82263 | M61: 82618 | N61: 81586 | O61: 79396 | P61: 76514 | Q61: 73604 | R61: 71197 | S61: 69358 | T61: 68068 | U61: 67691 | V61: 68636 | W61: 71164 | X61: 75523 | Y61: 81541 | Z61: 88528 | AA61: 98140 | AB61: 107453 | AC61: 116082 | AD61: 124141 | AE61: 131882 | AF61: 139792 | AG61: 148308 | AH61: 157514 | AI61: 167340 | AJ61: 177853 | AK61: 189161 | AL61: 204442 | AM61: 221059 | AN61: 239057 | AO61: 258494 | AP61: 279336 | AQ61: 301583 | AR61: 325204 | AS61: 350350 | AT61: 377222 | AU61: 406137 | AV61: 437275 | AW61: 470822 | AX61: 506719 | AY61: 544889 | AZ61: 585086 | BA61: 627158 | BB61: 671026 | BC61: 716629 | BD61: 753680 | BE61: 791534 | BF61: 830013 | BG61: 868944 | BH61: 908248
A62: Africa | B62: Eritrea | C62: 136940 | D62: 144897 | E62: 153402 | F62: 162471 | G62: 172081 | H62: 182215 | I62: 192932 | J62: 204253 | K62: 212375 | L62: 220843 | M62: 229710 | N62: 238997 | O62: 248714 | P62: 258871 | Q62: 269450 | R62: 280484 | S62: 291979 | T62: 303893 | U62: 316367 | V62: 329481 | W62: 343279 | X62: 357709 | Y62: 372641 | Z62: 388202 | AA62: 406011 | AB62: 433814 | AC62: 463896 | AD62: 496028 | AE62: 528879 | AF62: 560260 | AG62: 588571 | AH62: 612637 | AI62: 632885 | AJ62: 651265 | AK62: 671238 | AL62: 695718 | AM62: 725898 | AN62: 761506 | AO62: 802928 | AP62: 849837 | AQ62: 902044 | AR62: 960135 | AS62: 1024425 | AT62: 1093218 | AU62: 1163915 | AV62: 1234321 | AW62: 1303401 | AX62: 1371306 | AY62: 1439096 | AZ62: 1490729 | BA62: 1544478 | BB62: 1600641
A63: Europe | B63: Estonia | C63: 697034 | D63: 714269 | E63: 733452 | F63: 753250 | G63: 773863 | H63: 794190 | I63: 812599 | J63: 828812 | K63: 846346 | L63: 865089 | M63: 883329 | N63: 901671 | O63: 919299 | P63: 935590 | Q63: 951152 | R63: 966085 | S63: 980438 | T63: 995091 | U63: 1009340 | V63: 1020447 | W63: 1029784 | X63: 1040236 | Y63: 1050928 | Z63: 1061357 | AA63: 1071506 | AB63: 1081872 | AC63: 1093150 | AD63: 1104917 | AE63: 1115040 | AF63: 1119881 | AG63: 1117738 | AH63: 1109251 | AI63: 1086348 | AJ63: 1055960 | AK63: 1030882 | AL63: 1009954 | AM63: 992487 | AN63: 978597 | AO63: 966608 | AP63: 966817 | AQ63: 969061 | AR63: 961159 | AS63: 953352 | AT63: 945646 | AU63: 938279 | AV63: 931205 | AW63: 924006 | AX63: 918084 | AY63: 913914 | AZ63: 910446 | BA63: 906655 | BB63: 902194 | BC63: 899089 | BD63: 897846 | BE63: 897427 | BF63: 899949 | BG63: 902145 | BH63: 903958
A64: Africa | B64: Eswatini | C64: 13663 | D64: 15496 | E64: 17551 | F64: 19861 | G64: 22474 | H64: 25427 | I64: 28713 | J64: 31793 | K64: 35223 | L64: 39027 | M64: 43258 | N64: 47961 | O64: 53192 | P64: 58971 | Q64: 65362 | R64: 72404 | S64: 80179 | T64: 85125 | U64: 89691 | V64: 94457 | W64: 99424 | X64: 104523 | Y64: 109795 | Z64: 115423 | AA64: 121695 | AB64: 128791 | AC64: 136870 | AD64: 145843 | AE64: 155369 | AF64: 164896 | AG64: 174015 | AH64: 182500 | AI64: 190430 | AJ64: 198056 | AK64: 205844 | AL64: 214122 | AM64: 223076 | AN64: 231732 | AO64: 235459 | AP64: 238581 | AQ64: 240805 | AR64: 241999 | AS64: 242399 | AT64: 242445 | AU64: 242729 | AV64: 243712 | AW64: 245505 | AX64: 248509 | AY64: 255479 | AZ64: 262842 | BA64: 270399 | BB64: 278134 | BC64: 285192 | BD64: 292422 | BE64: 299802 | BF64: 307330 | BG64: 315077 | BH64: 323014
A65: Africa | B65: Ethiopia | C65: 1424992 | D65: 1507634 | E65: 1596238 | F65: 1690640 | G65: 1791230 | H65: 1897784 | I65: 2010284 | J65: 2128778 | K65: 2225746 | L65: 2329033 | M65: 2440287 | N65: 2560710 | O65: 2690237 | P65: 2823906 | Q65: 2955520 | R65: 3080821 | S65: 3196686 | T65: 3305081 | U65: 3413645 | V65: 3533046 | W65: 3671076 | X65: 3832363 | Y65: 4015607 | Z65: 4219104 | AA65: 4438752 | AB65: 4672863 | AC65: 4919280 | AD65: 5179615 | AE65: 5456101 | AF65: 5751613 | AG65: 6068999 | AH65: 6410479 | AI65: 6774121 | AJ65: 7157356 | AK65: 7553599 | AL65: 7924237 | AM65: 8285270 | AN65: 8650119 | AO65: 9022892 | AP65: 9407067 | AQ65: 9807603 | AR65: 10223839 | AS65: 10657765 | AT65: 11106662 | AU65: 11569768 | AV65: 12046152 | AW65: 12536471 | AX65: 13054026 | AY65: 13733826 | AZ65: 14443888 | BA65: 15189225 | BB65: 15969792 | BC65: 16787864 | BD65: 17625395 | BE65: 18497740 | BF65: 19403333 | BG65: 20343419 | BH65: 21316856
A66: Europe | B66: Faroe Islands | C66: 7412 | D66: 7775 | E66: 8168 | F66: 8573 | G66: 8993 | H66: 9429 | I66: 9829 | J66: 10093 | K66: 10361 | L66: 10637 | M66: 10924 | N66: 11235 | O66: 11558 | P66: 11887 | Q66: 12222 | R66: 12557 | S66: 12895 | T66: 13235 | U66: 13386 | V66: 13478 | W66: 13570 | X66: 13659 | Y66: 13743 | Z66: 13827 | AA66: 13920 | AB66: 14021 | AC66: 14137 | AD66: 14265 | AE66: 14378 | AF66: 14445 | AG66: 14561 | AH66: 14785 | AI66: 15012 | AJ66: 15203 | AK66: 15415 | AL66: 15686 | AM66: 16038 | AN66: 16352 | AO66: 16608 | AP66: 16832 | AQ66: 17172 | AR66: 17668 | AS66: 18163 | AT66: 18573 | AU66: 18895 | AV66: 19208 | AW66: 19424 | AX66: 19544 | AY66: 19654 | AZ66: 19761 | BA66: 19870 | BB66: 19972 | BC66: 20063 | BD66: 20163 | BE66: 20270 | BF66: 20388 | BG66: 20520 | BH66: 20659
A67: Oceania | B67: Fiji | C67: 116761 | D67: 123157 | E67: 129943 | F67: 136982 | G67: 144103 | H67: 151142 | I67: 158044 | J67: 163958 | K67: 169558 | L67: 175175 | M67: 180925 | N67: 186842 | O67: 192905 | P67: 199091 | Q67: 205372 | R67: 211731 | S67: 218082 | T67: 223264 | U67: 228315 | V67: 233816 | W67: 239929 | X67: 246836 | Y67: 254383 | Z67: 261963 | AA67: 268744 | AB67: 274153 | AC67: 277898 | AD67: 283833 | AE67: 289781 | AF67: 295973 | AG67: 303189 | AH67: 311701 | AI67: 321310 | AJ67: 331706 | AK67: 342353 | AL67: 352821 | AM67: 363071 | AN67: 370519 | AO67: 377132 | AP67: 383206 | AQ67: 388641 | AR67: 393267 | AS67: 397176 | AT67: 400842 | AU67: 404913 | AV67: 409848 | AW67: 415890 | AX67: 422891 | AY67: 431335 | AZ67: 440109 | BA67: 448645 | BB67: 456807 | BC67: 464718 | BD67: 472460 | BE67: 480249 | BF67: 488237 | BG67: 496430 | BH67: 504745
A68: Europe | B68: Finland | C68: 2449145 | D68: 2512483 | E68: 2567399 | F68: 2623429 | G68: 2675999 | H68: 2722631 | I68: 2770510 | J68: 2823091 | K68: 2873315 | L68: 2908731 | M68: 2934402 | N68: 2975881 | O68: 3032758 | P68: 3088806 | Q68: 3143576 | R68: 3195817 | S68: 3243412 | T68: 3289888 | U68: 3336370 | V68: 3381500 | W68: 3428217 | X68: 3481318 | Y68: 3541666 | Z68: 3603091 | AA68: 3662085 | AB68: 3716264 | AC68: 3765683 | AD68: 3812087 | AE68: 3858255 | AF68: 3906513 | AG68: 3957581 | AH68: 4003120 | AI68: 4040047 | AJ68: 4073879 | AK68: 4105674 | AL68: 4135420 | AM68: 4162332 | AN68: 4187218 | AO68: 4210769 | AP68: 4232899 | AQ68: 4253964 | AR68: 4273258 | AS68: 4290649 | AT68: 4307931 | AU68: 4327463 | AV68: 4349276 | AW68: 4372951 | AX68: 4398523 | AY68: 4426008 | AZ68: 4454167 | BA68: 4492880 | BB68: 4543014 | BC68: 4593267 | BD68: 4629925 | BE68: 4651843 | BF68: 4669930 | BG68: 4686120 | BH68: 4702519
A69: Europe | B69: France | C69: 28968650 | D69: 29703735 | E69: 30550684 | F69: 31576957 | G69: 32586168 | H69: 33551445 | I69: 34459572 | J69: 35313433 | K69: 36015275 | L69: 36481398 | M69: 36973537 | N69: 37501984 | O69: 38056501 | P69: 38614520 | Q69: 39145575 | R69: 39564232 | S69: 39813654 | T69: 40015297 | U69: 40188949 | V69: 40361659 | W69: 40554832 | X69: 40773314 | Y69: 41014270 | Z69: 41274869 | AA69: 41548368 | AB69: 41830023 | AC69: 42121076 | AD69: 42422152 | AE69: 42726704 | AF69: 43026108 | AG69: 43332245 | AH69: 43467991 | AI69: 43785894 | AJ69: 44077099 | AK69: 44342923 | AL69: 44604027 | AM69: 44863823 | AN69: 45123550 | AO69: 45390693 | AP69: 45743988 | AQ69: 46214923 | AR69: 46709571 | AS69: 47206863 | AT69: 47699501 | AU69: 48209404 | AV69: 48730233 | AW69: 49228316 | AX69: 49690036 | AY69: 50127516 | AZ69: 50547202 | BA69: 50961407 | BB69: 51373797 | BC69: 51791128 | BD69: 52228040 | BE69: 52650998 | BF69: 53044946 | BG69: 53432321 | BH69: 53815732
A70: Oceania | B70: French Polynesia | C70: 33011 | D70: 34877 | E70: 36940 | F70: 39414 | G70: 42166 | H70: 45017 | I70: 47958 | J70: 50994 | K70: 54154 | L70: 57460 | M70: 60951 | N70: 64247 | O70: 67085 | P70: 70026 | Q70: 73036 | R70: 76088 | S70: 79178 | T70: 82167 | U70: 84553 | V70: 86992 | W70: 89512 | X70: 92102 | Y70: 94750 | Z70: 97440 | AA70: 100096 | AB70: 102731 | AC70: 105392 | AD70: 108046 | AE70: 110636 | AF70: 112849 | AG70: 114764 | AH70: 116381 | AI70: 117755 | AJ70: 119015 | AK70: 120348 | AL70: 121881 | AM70: 123660 | AN70: 125927 | AO70: 128359 | AP70: 130747 | AQ70: 132976 | AR70: 135033 | AS70: 136929 | AT70: 139761 | AU70: 143086 | AV70: 146348 | AW70: 149548 | AX70: 152669 | AY70: 155712 | AZ70: 158663 | BA70: 161541 | BB70: 164305 | BC70: 166986 | BD70: 168447 | BE70: 169789 | BF70: 171288 | BG70: 172984 | BH70: 174853
A71: Africa | B71: Gabon | C71: 86848 | D71: 92414 | E71: 99891 | F71: 108018 | G71: 116899 | H71: 126604 | I71: 137251 | J71: 148884 | K71: 161461 | L71: 174803 | M71: 188838 | N71: 205082 | O71: 222141 | P71: 240042 | Q71: 259014 | R71: 279189 | S71: 300655 | T71: 323320 | U71: 347262 | V71: 372395 | W71: 398719 | X71: 426125 | Y71: 447629 | Z71: 470083 | AA71: 493545 | AB71: 517990 | AC71: 543472 | AD71: 569961 | AE71: 598676 | AF71: 628176 | AG71: 658388 | AH71: 689275 | AI71: 720845 | AJ71: 752988 | AK71: 782574 | AL71: 812398 | AM71: 842781 | AN71: 873764 | AO71: 905426 | AP71: 937828 | AQ71: 971097 | AR71: 1005175 | AS71: 1040291 | AT71: 1076901 | AU71: 1115620 | AV71: 1156905 | AW71: 1200767 | AX71: 1247080 | AY71: 1296101 | AZ71: 1348027 | BA71: 1402921 | BB71: 1461068 | BC71: 1522001 | BD71: 1583861 | BE71: 1644081 | BF71: 1700832 | BG71: 1753279 | BH71: 1801886
A72: Africa | B72: Gambia, The | C72: 44626 | D72: 46455 | E72: 48075 | F72: 50042 | G72: 53963 | H72: 58257 | I72: 62994 | J72: 68192 | K72: 73924 | L72: 80230 | M72: 87203 | N72: 94938 | O72: 103516 | P72: 112379 | Q72: 119680 | R72: 127277 | S72: 135138 | T72: 143329 | U72: 152020 | V72: 161416 | W72: 171725 | X72: 182970 | Y72: 195195 | Z72: 208758 | AA72: 224402 | AB72: 241731 | AC72: 261016 | AD72: 282200 | AE72: 304805 | AF72: 328012 | AG72: 351247 | AH72: 374195 | AI72: 396982 | AJ72: 419336 | AK72: 440362 | AL72: 462336 | AM72: 485381 | AN72: 509425 | AO72: 534696 | AP72: 561381 | AQ72: 589659 | AR72: 619684 | AS72: 651518 | AT72: 684613 | AU72: 717300 | AV72: 751275 | AW72: 786528 | AX72: 823135 | AY72: 861181 | AZ72: 900725 | BA72: 941884 | BB72: 984669 | BC72: 1029103 | BD72: 1075061 | BE72: 1122480 | BF72: 1171287 | BG72: 1221429 | BH72: 1272923
A73: Asia | B73: Georgia | C73: 1570123 | D73: 1613251 | E73: 1656450 | F73: 1699844 | G73: 1743144 | H73: 1785661 | I73: 1825872 | J73: 1863779 | K73: 1900892 | L73: 1939040 | M73: 1977799 | N73: 2017973 | O73: 2058158 | P73: 2096177 | Q73: 2134443 | R73: 2170431 | S73: 2206460 | T73: 2241969 | U73: 2275678 | V73: 2310615 | W73: 2345408 | X73: 2379998 | Y73: 2415679 | Z73: 2452585 | AA73: 2489286 | AB73: 2527012 | AC73: 2565458 | AD73: 2602758 | AE73: 2644850 | AF73: 2655120 | AG73: 2642925 | AH73: 2650025 | AI73: 2658933 | AJ73: 2667710 | AK73: 2629153 | AL73: 2548833 | AM73: 2474230 | AN73: 2418062 | AO73: 2383654 | AP73: 2354437 | AQ73: 2325705 | AR73: 2298386 | AS73: 2284854 | AT73: 2272218 | AU73: 2259104 | AV73: 2246050 | AW73: 2233109 | AX73: 2219751 | AY73: 2207030 | AZ73: 2193867 | BA73: 2180304 | BB73: 2166861 | BC73: 2153590 | BD73: 2140426 | BE73: 2126887 | BF73: 2135400 | BG73: 2151132 | BH73: 2164505
A74: Europe | B74: Germany | C74: 51978188 | D74: 52609561 | E74: 53122383 | F74: 53664331 | G74: 54147106 | H74: 54659677 | I74: 55166778 | J74: 55468832 | K74: 55765529 | L74: 56259360 | M74: 56496072 | N74: 56645245 | O74: 56961784 | P74: 57186457 | Q74: 57253758 | R74: 57085531 | S74: 56885943 | T74: 56801863 | U74: 56796181 | V74: 56865826 | W74: 57028530 | X74: 57229147 | Y74: 57267174 | Z74: 57114118 | AA74: 56792461 | AB74: 56485448 | AC74: 56438249 | AD74: 56695484 | AE74: 57044790 | AF74: 57469536 | AG74: 58079842 | AH74: 58625381 | AI74: 59146205 | AJ74: 59647492 | AK74: 60028206 | AL74: 60378049 | AM74: 60725922 | AN74: 60986289 | AO74: 61167004 | AP74: 61376500 | AQ74: 61629857 | AR74: 61902439 | AS74: 62174878 | AT74: 62376854 | AU74: 62529997 | AV74: 62660267 | AW74: 62753557 | AX74: 62833410 | AY74: 62875807 | AZ74: 62877220 | BA74: 62940432 | BB74: 61940177 | BC74: 62064608 | BD74: 62242278 | BE74: 62510392 | BF74: 63062064 | BG74: 63592936 | BH74: 63890984
... A105: Asia | B105: Korea, Rep. | C105: 6930929 | D105: 7351204 | E105: 7811004 | F105: 8289479 | G105: 8779189 | H105: 9286249 | I105: 9815880 | J105: 10537106 | K105: 11362681 | L105: 12225296 | M105: 13123306 | N105: 13896560 | O105: 14639182 | P105: 15391092 | Q105: 16159311 | R105: 16946391 | S105: 17823527 | T105: 18743336 | U105: 19679806 | V105: 20636698 | W105: 21623805 | X105: 22617087 | Y105: 23619800 | Z105: 24621925 | AA105: 25577374 | AB105: 26473134 | AC105: 27480866 | AD105: 28537079 | AE105: 29585374 | AF105: 30626132 | AG105: 31656393 | AH105: 32459655 | AI105: 33169705 | AJ105: 33872973 | AK105: 34575766 | AL105: 35280305 | AM105: 35810625 | AN105: 36259672 | AO105: 36633453 | AP105: 37006183 | AQ105: 37428328 | AR105: 37867709 | AS105: 38258247 | AT105: 38626122 | AU105: 38947802 | AV105: 39195731 | AW105: 39490771 | AX105: 39740941 | AY105: 40093884 | AZ105: 40351067 | BA105: 40602657 | BB105: 40909592 | BC105: 41089082 | BD105: 41240244 | BE105: 41463573 | BF105: 41645542 | BG105: 41797024 | BH105: 41946498
A106: Asia | B106: Kuwait | C106: 201925 | D106: 228374 | E106: 259338 | F106: 294457 | G106: 333133 | H106: 375400 | I106: 423643 | J106: 475255 | K106: 529320 | L106: 584571 | M106: 639688 | N106: 692539 | O106: 745146 | P106: 798607 | Q106: 854640 | R106: 916132 | S106: 988403 | T106: 1063822 | U106: 1141669 | V106: 1220766 | W106: 1300697 | X106: 1380509 | Y106: 1457118 | Z106: 1533756 | AA106: 1615282 | AB106: 1702527 | AC106: 1797859 | AD106: 1902633 | AE106: 1997006 | AF106: 2054155 | AG106: 2057077 | AH106: 1994704 | AL106: 1579984 | AM106: 1604408 | AN106: 1690047 | AO106: 1812572 | AP106: 1934795 | AQ106: 2030234 | AR106: 2107414 | AS106: 2143833 | AT106: 2169118 | AU106: 2207939 | AV106: 2276623 | AW106: 2377258 | AX106: 2503410 | AY106: 2652340 | AZ106: 2818939 | BA106: 2998083 | BB106: 3191051 | BC106: 3395556 | BD106: 3598385 | BE106: 3782450 | BF106: 3935794 | BG106: 4052584 | BH106: 4136528
A107: Asia | B107: Kyrgyz Republic | C107: 742514 | D107: 778534 | E107: 813050 | F107: 849091 | G107: 886206 | H107: 922554 | I107: 960953 | J107: 999643 | K107: 1039135 | L107: 1077271 | M107: 1108956 | N107: 1136657 | O107: 1165888 | P107: 1195196 | Q107: 1226436 | R107: 1257236 | S107: 1287423 | T107: 1317380 | U107: 1346753 | V107: 1373807 | W107: 1397293 | X107: 1421871 | Y107: 1448346 | Z107: 1476863 | AA107: 1504955 | AB107: 1531357 | AC107: 1558567 | AD107: 1586429 | AE107: 1612568 | AF107: 1639650 | AG107: 1658864 | AH107: 1673404 | AI107: 1679864 | AJ107: 1667475 | AK107: 1654017 | AL107: 1657660 | AM107: 1669279 | AN107: 1680607 | AO107: 1693186 | AP107: 1708661 | AQ107: 1729037 | AR107: 1745422 | AS107: 1761468 | AT107: 1779932 | AU107: 1801551 | AV107: 1821882 | AW107: 1841521 | AX107: 1859060 | AY107: 1876703 | AZ107: 1899444 | BA107: 1923436 | BB107: 1949521 | BC107: 1986238 | BD107: 2031430 | BE107: 2079480 | BF107: 2131200 | BG107: 2185215 | BH107: 2240912
A108: Asia | B108: Lao PDR | C108: 168526 | D108: 174062 | E108: 179800 | F108: 185733 | G108: 191896 | H108: 198303 | I108: 204892 | J108: 217032 | K108: 229963 | L108: 243805 | M108: 258761 | N108: 274983 | O108: 292465 | P108: 309357 | Q108: 324131 | R108: 338145 | S108: 351145 | T108: 363256 | U108: 375286 | V108: 388311 | W108: 403260 | X108: 420407 | Y108: 439781 | Z108: 461166 | AA108: 484305 | AB108: 509077 | AC108: 535643 | AD108: 563866 | AE108: 593637 | AF108: 624817 | AG108: 657380 | AH108: 691263 | AI108: 726366 | AJ108: 762379 | AK108: 798944 | AL108: 843167 | AM108: 903892 | AN108: 966806 | AO108: 1032161 | AP108: 1100198 | AQ108: 1171221 | AR108: 1244972 | AS108: 1321764 | AT108: 1401944 | AU108: 1486506 | AV108: 1564290 | AW108: 1623079 | AX108: 1684742 | AY108: 1748659 | AZ108: 1813313 | BA108: 1877880 | BB108: 1941847 | BC108: 2005638 | BD108: 2069945 | BE108: 2136474 | BF108: 2206306 | BG108: 2279998 | BH108: 2357012
A109: Europe | B109: Latvia | C109: 1121298 | D109: 1155193 | E109: 1188070 | F109: 1221599 | G109: 1255757 | H109: 1287767 | I109: 1315521 | J109: 1343866 | K109: 1375002 | L109: 1404638 | M109: 1432319 | N109: 1459887 | O109: 1488241 | P109: 1517255 | Q109: 1547223 | R109: 1575779 | S109: 1601843 | T109: 1627400 | U109: 1652200 | V109: 1671120 | W109: 1685226 | X109: 1699098 | Y109: 1714098 | Z109: 1731364 | AA109: 1749443 | AB109: 1768075 | AC109: 1788258 | AD109: 1810950 | AE109: 1833841 | AF109: 1845533 | AG109: 1844232 | AH109: 1834229 | AI109: 1800024 | AJ109: 1763518 | AK109: 1736816 | AL109: 1708476 | AM109: 1686883 | AN109: 1668936 | AO109: 1649682 | AP109: 1630787 | AQ109: 1611520 | AR109: 1588107 | AS109: 1567452 | AT109: 1551233 | AU109: 1536660 | AV109: 1522383 | AW109: 1507751 | AX109: 1494021 | AY109: 1476965 | AZ109: 1452351 | BA109: 1423002 | BB109: 1397904 | BC109: 1381242 | BD109: 1367090 | BE109: 1354815 | BF109: 1344323 | BG109: 1332897 | BH109: 1321159
A110: Asia | B110: Lebanon | C110: 764260 | D110: 821153 | E110: 880852 | F110: 942369 | G110: 1004417 | H110: 1065737 | I110: 1125238 | J110: 1182811 | K110: 1240370 | L110: 1300758 | M110: 1366372 | N110: 1437081 | O110: 1512393 | P110: 1589254 | Q110: 1661765 | R110: 1725146 | S110: 1776936 | T110: 1818074 | U110: 1852033 | V110: 1884336 | W110: 1919371 | X110: 1959168 | Y110: 2002872 | Z110: 2047858 | AA110: 2089847 | AB110: 2125796 | AC110: 2153979 | AD110: 2176378 | AE110: 2198914 | AF110: 2215239 | AG110: 2246747 | AH110: 2297535 | AI110: 2365228 | AJ110: 2441272 | AK110: 2513303 | AL110: 2572925 | AM110: 2614677 | AN110: 2642965 | AO110: 2670836 | AP110: 2711085 | AQ110: 2782415 | AR110: 2893443 | AS110: 3038095 | AT110: 3196806 | AU110: 3341494 | AV110: 3453690 | AW110: 3520238 | AX110: 3551180 | AY110: 3578338 | AZ110: 3647168 | BA110: 3787799 | BB110: 4014088 | BC110: 4308540 | BD110: 4631890 | BE110: 4927916 | BF110: 5155504 | BG110: 5301846 | BH110: 5378567
A111: Africa | B111: Lesotho | C111: 29908 | D111: 34312 | E111: 39380 | F111: 45193 | G111: 51845 | H111: 59436 | I111: 67273 | J111: 72135 | K111: 77356 | L111: 82945 | M111: 88925 | N111: 95312 | O111: 101972 | P111: 108879 | Q111: 116375 | R111: 124522 | S111: 132282 | T111: 136481 | U111: 140884 | V111: 145412 | W111: 150009 | X111: 154659 | Y111: 159359 | Z111: 164034 | AA111: 168609 | AB111: 173012 | AC111: 178558 | AD111: 189066 | AE111: 199999 | AF111: 211581 | AG111: 224022 | AH111: 237446 | AI111: 251835 | AJ111: 267008 | AK111: 282687 | AL111: 298638 | AM111: 314042 | AN111: 326769 | AO111: 339486 | AP111: 352303 | AQ111: 365293 | AR111: 378455 | AS111: 391819 | AT111: 405428 | AU111: 419406 | AV111: 433754 | AW111: 448564 | AX111: 461952 | AY111: 475903 | AZ111: 490526 | BA111: 506016 | BB111: 522440 | BC111: 537195 | BD111: 552652 | BE111: 568676 | BF111: 585153 | BG111: 602018 | BH111: 619305
A112: Africa | B112: Liberia | C112: 208737 | D112: 220879 | E112: 233733 | F112: 247325 | G112: 261740 | H112: 277007 | I112: 293200 | J112: 310379 | K112: 328638 | L112: 348017 | M112: 368652 | N112: 390598 | O112: 413952 | P112: 438784 | Q112: 465317 | R112: 493711 | S112: 523614 | T112: 554892 | U112: 588216 | V112: 624446 | W112: 664063 | X112: 707875 | Y112: 755300 | Z112: 803186 | AA112: 860052 | AB112: 929051 | AC112: 989856 | AD112: 1042204 | AE112: 1086767 | AF112: 1125744 | AG112: 1162328 | AH112: 1194955 | AI112: 1112885 | AJ112: 1040309 | AK112: 985931 | AL112: 952972 | AM112: 941418 | AN112: 1021311 | AO112: 1113437 | AP112: 1202860 | AQ112: 1278737 | AR112: 1336228 | AS112: 1378809 | AT112: 1413554 | AU112: 1451812 | AV112: 1501829 | AW112: 1566254 | AX112: 1642015 | AY112: 1724830 | AZ112: 1808379 | BA112: 1887717 | BB112: 1961536 | BC112: 2031529 | BD112: 2099640 | BE112: 2168892 | BF112: 2241711 | BG112: 2318631 | BH112: 2398934
A113: Africa | B113: Libya | C113: 395751 | D113: 422411 | E113: 451116 | F113: 482119 | G113: 515758 | H113: 583535 | I113: 661916 | J113: 748526 | K113: 843704 | L113: 947351 | M113: 1059744 | N113: 1180739 | O113: 1310191 | P113: 1446980 | Q113: 1553514 | R113: 1660751 | S113: 1771545 | T113: 1885646 | U113: 2003887 | V113: 2127329 | W113: 2256652 | X113: 2392023 | Y113: 2532831 | Z113: 2676858 | AA113: 2821276 | AB113: 2922768 | AC113: 3016116 | AD113: 3105292 | AE113: 3191227 | AF113: 3275646 | AG113: 3359573 | AH113: 3443529 | AI113: 3526949 | AJ113: 3608599 | AK113: 3686889 | AL113: 3760790 | AM113: 3829689 | AN113: 3894958 | AO113: 3958609 | AP113: 4023343 | AQ113: 4091098 | AR113: 4162142 | AS113: 4235679 | AT113: 4311254 | AU113: 4388044 | AV113: 4465004 | AW113: 4543585 | AX113: 4623269 | AY113: 4699126 | AZ113: 4764444 | BA113: 4815137 | BB113: 4848087 | BC113: 4866376 | BD113: 4879698 | BE113: 4901804 | BF113: 4942449 | BG113: 5005653 | BH113: 5088027
A114: Europe | B114: Liechtenstein | C114: 3371 | D114: 3432 | E114: 3476 | F114: 3524 | G114: 3576 | H114: 3631 | I114: 3690 | J114: 3753 | K114: 3815 | L114: 3874 | M114: 3924 | N114: 3990 | O114: 4066 | P114: 4139 | Q114: 4213 | R114: 4294 | S114: 4382 | T114: 4473 | U114: 4567 | V114: 4653 | W114: 4727 | X114: 4769 | Y114: 4784 | Z114: 4791 | AA114: 4797 | AB114: 4802 | AC114: 4811 | AD114: 4821 | AE114: 4833 | AF114: 4847 | AG114: 4866 | AH114: 4896 | AI114: 4937 | AJ114: 4982 | AK114: 5030 | AL114: 5082 | AM114: 5103 | AN114: 5092 | AO114: 5080 | AP114: 5062 | AQ114: 5036 | AR114: 5038 | AS114: 5071 | AT114: 5097 | AU114: 5118 | AV114: 5137 | AW114: 5153 | AX114: 5167 | AY114: 5180 | AZ114: 5193 | BA114: 5207 | BB114: 5226 | BC114: 5250 | BD114: 5280 | BE114: 5314 | BF114: 5350 | BG114: 5387 | BH114: 5429
A115: Europe | B115: Lithuania | C115: 1096416 | D115: 1141928 | E115: 1186429 | F115: 1230140 | G115: 1275080 | H115: 1320810 | I115: 1367610 | J115: 1415159 | K115: 1462669 | L115: 1507983 | M115: 1555873 | N115: 1612378 | O115: 1670055 | P115: 1726365 | Q115: 1782668 | R115: 1838525 | S115: 1894509 | T115: 1950350 | U115: 2005471 | V115: 2050971 | W115: 2087446 | X115: 2126573 | Y115: 2168688 | Z115: 2213306 | AA115: 2258826 | AB115: 2305300 | AC115: 2354675 | AD115: 2406331 | AE115: 2459117 | AF115: 2492104 | AG115: 2499110 | AH115: 2501142 | AI115: 2496245 | AJ115: 2482228 | AK115: 2462904 | AL115: 2441841 | AM115: 2421184 | AN115: 2401277 | AO115: 2381814 | AP115: 2362861 | AQ115: 2344199 | AR115: 2322637 | AS115: 2300933 | AT115: 2279211 | AU115: 2250685 | AV115: 2213967 | AW115: 2181225 | AX115: 2157761 | AY115: 2137953 | AZ115: 2114156 | BA115: 2067653 | BB115: 2020994 | BC115: 1997745 | BD115: 1981238 | BE115: 1967853 | BF115: 1952971 | BG115: 1932212 | BH115: 1909164
A116: Europe | B116: Luxembourg | C116: 218385 | D116: 221560 | E116: 225946 | F116: 229959 | G116: 234207 | H116: 238541 | I116: 241914 | J116: 244349 | K116: 246598 | L116: 249419 | M116: 252255 | N116: 256528 | O116: 261780 | P116: 266787 | Q116: 272384 | R116: 277458 | S116: 280890 | T116: 283399 | U116: 285895 | V116: 288518 | W116: 291473 | X116: 293802 | Y116: 294251 | Z116: 294534 | AA116: 295042 | AB116: 295818 | AC116: 297355 | AD116: 299492 | AE116: 301882 | AF116: 305040 | AG116: 309096 | AH116: 313973 | AI116: 319732 | AJ116: 325361 | AK116: 332341 | AL116: 338722 | AM116: 343082 | AN116: 347217 | AO116: 352047 | AP116: 359223 | AQ116: 367434 | AR116: 374603 | AS116: 380583 | AT116: 387241 | AU116: 394773 | AV116: 402818 | AW116: 411237 | AX116: 419557 | AY116: 429035 | AZ116: 438935 | BA116: 448892 | BB116: 460842 | BC116: 473864 | BD116: 486709 | BE116: 500042 | BF116: 513663 | BG116: 526490 | BH116: 543862
A117: Asia | B117: Macao SAR, China | C117: 159891 | D117: 162501 | E117: 168358 | F117: 176462 | G117: 185782 | H117: 195461 | I117: 205446 | J117: 215699 | K117: 225350 | L117: 233321 | M117: 238888 | N117: 241794 | O117: 242292 | P117: 240954 | Q117: 238758 | R117: 236532 | S117: 234387 | T117: 232361 | U117: 231186 | V117: 231735 | W117: 234591 | X117: 240153 | Y117: 248428 | Z117: 258606 | AA117: 269937 | AB117: 281814 | AC117: 294157 | AD117: 306968 | AE117: 319757 | AF117: 331942 | AG117: 343120 | AH117: 353074 | AI117: 361875 | AJ117: 369852 | AK117: 377548 | AL117: 385339 | AM117: 393488 | AN117: 401564 | AO117: 409837 | AP117: 418604 | AQ117: 427979 | AR117: 438081 | AS117: 448896 | AT117: 460147 | AU117: 471453 | AV117: 482559 | AW117: 493320 | AX117: 503823 | AY117: 514348 | AZ117: 525313 | BA117: 536969 | BB117: 549439 | BC117: 562531 | BD117: 575841 | BE117: 588781 | BF117: 600942 | BG117: 612167 | BH117: 622567
A118: Europe | B118: Macedonia, FYR | C118: 506445 | D118: 530905 | E118: 556983 | F118: 584162 | G118: 612702 | H118: 642626 | I118: 674297 | J118: 707589 | K118: 741943 | L118: 776357 | M118: 810135 | N118: 839249 | O118: 856892 | P118: 874006 | Q118: 891985 | R118: 911764 | S118: 933788 | T118: 957558 | U118: 982219 | V118: 1006329 | W118: 1028849 | X118: 1048562 | Y118: 1064239 | Z118: 1078352 | AA118: 1091378 | AB118: 1103635 | AC118: 1115347 | AD118: 1126352 | AE118: 1136544 | AF118: 1145664 | AG118: 1153600 | AH118: 1160779 | AI118: 1168616 | AJ118: 1176350 | AK118: 1184939 | AL118: 1181760 | AM118: 1181331 | AN118: 1183203 | AO118: 1186409 | AP118: 1189473 | AQ118: 1191346 | AR118: 1191774 | AS118: 1191042 | AT118: 1189365 | AU118: 1187142 | AV118: 1185316 | AW118: 1183894 | AX118: 1182764 | AY118: 1182023 | AZ118: 1181804 | BA118: 1182164 | BB118: 1183165 | BC118: 1184793 | BD118: 1187094 | BE118: 1190072 | BF118: 1193689 | BG118: 1198005 | BH118: 1202983
...

Sheet Calc
G2: Saniye | H2: 1
A3: Min Yıl | B3: =MIN(Data!$C$1:$XFD$1) -> 1960 | D3: Ülke Adı | E3: Değer
A4: Mak Yıl | B4: =MAX(Data!$C$1:$XFD$1) -> 2017 | D4: {=_xlfn.XLOOKUP(E4,Sütun_Aralığı,Data!$B$2:$B$216)} -> USA | E4: =LARGE(Sütun_Aralığı,ROW(A1)) -> 126462473
D5: {=_xlfn.XLOOKUP(E5,Sütun_Aralığı,Data!$B$2:$B$216)} -> China | E5: =LARGE(Sütun_Aralığı,ROW(A2)) -> 108085352
A6: Gösterilen Yıl | B6: 1960 | D6: {=_xlfn.XLOOKUP(E6,Sütun_Aralığı,Data!$B$2:$B$216)} -> India | E6: =LARGE(Sütun_Aralığı,ROW(A3)) -> 80564904
D7: {=_xlfn.XLOOKUP(E7,Sütun_Aralığı,Data!$B$2:$B$216)} -> Russia | E7: =LARGE(Sütun_Aralığı,ROW(A4)) -> 64421857
D8: {=_xlfn.XLOOKUP(E8,Sütun_Aralığı,Data!$B$2:$B$216)} -> Japan | E8: =LARGE(Sütun_Aralığı,ROW(A5)) -> 58526962
D9: {=_xlfn.XLOOKUP(E9,Sütun_Aralığı,Data!$B$2:$B$216)} -> Germany | E9: =LARGE(Sütun_Aralığı,ROW(A6)) -> 51978188
D10: {=_xlfn.XLOOKUP(E10,Sütun_Aralığı,Data!$B$2:$B$216)} -> UK | E10: =LARGE(Sütun_Aralığı,ROW(A7)) -> 41104656
D11: {=_xlfn.XLOOKUP(E11,Sütun_Aralığı,Data!$B$2:$B$216)} -> Brazil | E11: =LARGE(Sütun_Aralığı,ROW(A8)) -> 33315843
D12: {=_xlfn.XLOOKUP(E12,Sütun_Aralığı,Data!$B$2:$B$216)} -> Italy | E12: =LARGE(Sütun_Aralığı,ROW(A9)) -> 29799044
D13: {=_xlfn.XLOOKUP(E13,Sütun_Aralığı,Data!$B$2:$B$216)} -> France | E13: =LARGE(Sütun_Aralığı,ROW(A10)) -> 28968650
D14: {=_xlfn.XLOOKUP(E14,Sütun_Aralığı,Data!$B$2:$B$216)} -> Ukraine | E14: =LARGE(Sütun_Aralığı,ROW(A11)) -> 19962473
D15: {=_xlfn.XLOOKUP(E15,Sütun_Aralığı,Data!$B$2:$B$216)} -> Mexico | E15: =LARGE(Sütun_Aralığı,ROW(A12)) -> 19374507
D16: {=_xlfn.XLOOKUP(E16,Sütun_Aralığı,Data!$B$2:$B$216)} -> Spain | E16: =LARGE(Sütun_Aralığı,ROW(A13)) -> 17227480
D17: {=_xlfn.XLOOKUP(E17,Sütun_Aralığı,Data!$B$2:$B$216)} -> Argentina | E17: =LARGE(Sütun_Aralığı,ROW(A14)) -> 15177907
D18: {=_xlfn.XLOOKUP(E18,Sütun_Aralığı,Data!$B$2:$B$216)} -> Poland | E18: =LARGE(Sütun_Aralığı,ROW(A15)) -> 14193968
D19: Toplam | E19: =SUM(E4:E18) -> 709164264
