Workbook
Name CurRate: Plan!$I$5
Name DolarKuru: [1]Ürünlerim!$G$2
Name EuroKuru: [1]Ürünlerim!$G$3
Name Lst_Banka_Kasa: [2]!Tbl_Banka_Kasa[Banka-Kasa]
Name Lst_Cariler: [1]!Tablo3[Cari Adı]
Name lst_EmlakTipi: [3]!tbl_ayar_EmlakTipi[Emlak Tipi]
Name Lst_Maliye_Kategorileri: OFFSET([2]Pvt_Listeler!$A$3,1,0,COUNTA([2]Pvt_Listeler!$A:$A)-1,1)
Name lst_Müşteriler: [3]!Tablo1[İsim Soyisim]
Name Lst_Nakit_Vadeli: [1]!Tablo13[Nakit / Vadeli Seçimi]
Name Lst_Ödeme_Yön: [2]!Tbl_Ödeme_Yön[Ödeme Yöntemi]
Name lst_Satılık_Kiralık: [3]!tbl_ayar_Satılık[Satılık/Kiralık]
Name Lst_Satış_Per: [5]!Tablo2[Ad Soyad]
Name Lst_Servis: [2]!Tbl_Sektör_Kategori[Servis]
Name Lst_TümHisseler: [6]!TÜM_HİSSELER_1[Menkul]
Name Lst_Ürün_Ailesi: [2]!Tbl_Ürün_Ailesi[Ürün Ailesi]
Name Lst_Ürünler: [1]!Tablo4[Ürün Adı]
Name Lst_Ürünlerim: [7]!Tablo2[Ürün Adı]
Name Lst_Yıl_Ay: [2]!Tablo8[Tarihler]
Name oran: [8]Ürün_Fiyat_Listesi!$E$3

Sheet Plan
B4: TATİL PLANIM
B5: Yalnızca Beyaz kalan alanları doldurunuz | H5: Dolar /TRY Kurunu Giriniz | I5: 20
B8: GİDİŞ | C8: Vize&Pasaport | D8: Evden Limana Ulaşım | E8: Kalkış Limanı ve Zamanı | F8: Limandan Limana Ulaşım (Gidiş) | G8: Varış Limanı ve Zamanı | H8: Limandan Konaklamaya Ulaşım | I8: Konaklama
C12: 250 | D12: 50 | E12: 45209.625 | F12: TURKISH AIRLINES | G12: 45210.417 | H12: 350 | I12: 4 | K12: Kaç Gece ?
C13: =C12/CurRate -> 12.5 | D13: =D12/CurRate -> 2.5 | E13: ISTANBUL HAVALİMANI | F13: 2500 | G13: NEW YORK | H13: =H12/CurRate -> 17.5 | I13: 500 | K13: Gecelik Konaklama Maliyeti
F14: =F13/CurRate -> 125 | I14: =I13/CurRate -> 25
B17: GEZME | C17: Mutlaka Yapılması Gerekenler | D17: Yiyecek & İçecek | E17: Hediyelik & Ekstralar | F17: Diğer Giderler | G17: Diğer Giderler 2 | H17: Diğer Giderler 3 | I17: Diğer Giderler 4
C21: 2500 | D21: 750 | E21: 250 | F21: 250 | G21: 250 | H21: 250 | I21: 250
C22: =C21/CurRate -> 125 | D22: =D21/CurRate -> 37.5 | E22: =E21/CurRate -> 12.5 | F22: =F21/CurRate -> 12.5 | G22: =G21/CurRate -> 12.5 | H22: =H21/CurRate -> 12.5 | I22: =I21/CurRate -> 12.5
B26: DÖNÜŞ | C26: Konaklama İlave Ücretler | D26: Konaklamadan Limana Ulaşım | E26: Kalkış Limanı | F26: Limandan Limana Ulaşım (Dönüş) | G26: Varış Limanı | H26: Limandan Eve Ulaşım | I26: Ev
C30: 500 | D30: 150 | E30: NEW YORK | F30: AMERICAN AIRLINES | G30: İSTANBUL HAVALİMANI | H30: 50
C31: =C30/CurRate -> 25 | D31: =D30/CurRate -> 7.5 | E31: 45216.375 | F31: 2750 | G31: 45217.542 | H31: =H30/CurRate -> 2.5
F32: =F31/CurRate -> 137.5

Sheet Rapor
B5: EV | E5: Tatil Yeri
B6: Kalkış | C6: =Plan!E13 -> ISTANBUL HAVALİMANI | E6: Kalkış | F6: =Plan!E30 -> NEW YORK
B7: Varış | C7: =Plan!G13 -> NEW YORK | E7: Varış | F7: =Plan!G30 -> İSTANBUL HAVALİMANI
B8: Kalkış Saati | C8: =Plan!E12 -> 45209.625 | E8: Kalkış Saati | F8: =Plan!E31 -> 45216.375
B9: Varış Saati | C9: =Plan!G12 -> 45210.417 | E9: Varış Saati | F9: =Plan!G31 -> 45217.542
B10: Havayolu | C10: =Plan!F12 -> TURKISH AIRLINES | E10: Havayolu | F10: =Plan!F30 -> AMERICAN AIRLINES
B12: BÜTÇE DETAYI
A14: 15 | B14: Toplam | E14: =SUM(E28,E24,E15) -> 11850 | F14: =E14*(1/CurRate) -> 592.5
A15: 1 | B15: Seyehat | E15: =SUM(E16:E22) -> 6100 | F15: =E15*(1/CurRate) -> 305
A16: 2 | B16: =Plan!C8 -> Vize&Pasaport | E16: =Plan!C12 -> 250 | F16: =E16*(1/CurRate) -> 12.5
A17: 3 | B17: =Plan!D8 -> Evden Limana Ulaşım | E17: =Plan!D12 -> 50 | F17: =E17*(1/CurRate) -> 2.5
A18: 4 | B18: =Plan!F8 -> Limandan Limana Ulaşım (Gidiş) | E18: =Plan!F13 -> 2500 | F18: =E18*(1/CurRate) -> 125
A19: 5 | B19: =Plan!H8 -> Limandan Konaklamaya Ulaşım | E19: =Plan!H12 -> 350 | F19: =E19*(1/CurRate) -> 17.5
A20: 6 | B20: =Plan!D26 -> Konaklamadan Limana Ulaşım | E20: =Plan!D30 -> 150 | F20: =E20*(1/CurRate) -> 7.5
A21: 7 | B21: =Plan!F26 -> Limandan Limana Ulaşım (Dönüş) | E21: =Plan!F31 -> 2750 | F21: =E21*(1/CurRate) -> 137.5
A22: 8 | B22: =Plan!H26 -> Limandan Eve Ulaşım | E22: =Plan!H30 -> 50 | F22: =E22*(1/CurRate) -> 2.5
A24: 9 | B24: Konaklama | E24: =E25 -> 2000 | F24: =E24*(1/CurRate) -> 100
A25: 10 | B25: ="Konaklama - "&Plan!I12&" Gece" -> Konaklama - 4 Gece | E25: =Plan!I13*Plan!I12 -> 2000 | F25: =E25*(1/CurRate) -> 100
A26: 10 | B26: =Plan!C26 -> Konaklama İlave Ücretler | E26: =Plan!C30 -> 500 | F26: =E26*(1/CurRate) -> 25
A28: 11 | B28: Gezme & Görme | E28: =SUM(E29:E32) -> 3750 | F28: =E28*(1/CurRate) -> 187.5
A29: 12 | B29: =Plan!C17 -> Mutlaka Yapılması Gerekenler | E29: =Plan!C21 -> 2500 | F29: =E29*(1/CurRate) -> 125
A30: 13 | B30: =Plan!D17 -> Yiyecek & İçecek | E30: =Plan!D21 -> 750 | F30: =E30*(1/CurRate) -> 37.5
A31: 14 | B31: =Plan!E17 -> Hediyelik & Ekstralar | E31: =Plan!E21 -> 250 | F31: =E31*(1/CurRate) -> 12.5
B32: =Plan!F17 -> Diğer Giderler | E32: =Plan!F21 -> 250 | F32: =E32*(1/CurRate) -> 12.5
B33: =Plan!G17 -> Diğer Giderler 2 | E33: =Plan!G21 -> 250 | F33: =E33*(1/CurRate) -> 12.5
B34: =Plan!H17 -> Diğer Giderler 3 | E34: =Plan!H21 -> 250 | F34: =E34*(1/CurRate) -> 12.5
B35: =Plan!I17 -> Diğer Giderler 4 | E35: =Plan!I21 -> 250 | F35: =E35*(1/CurRate) -> 12.5
B36: NOTLARIM
B38: 1
B39: 2
B40: 3
B41: 4
B42: 5
B43: 6
B44: 7
B45: 8
B46: 9
B47: 10
B48: 11
B49: 12
...
