Workbook
Name DolarKuru: [2]Ürünlerim!$G$2
Name EuroKuru: [2]Ürünlerim!$G$3
Name ListMonths: Veriler!$C$41:$C$52
Name Lst_Banka_Kasa: [3]!Tbl_Banka_Kasa[Banka-Kasa]
Name Lst_Cariler: [2]!Tablo3[Cari Adı]
Name lst_EmlakTipi: [4]!tbl_ayar_EmlakTipi[Emlak Tipi]
Name Lst_Maliye_Kategorileri: OFFSET([3]Pvt_Listeler!$A$3,1,0,COUNTA([3]Pvt_Listeler!$A:$A)-1,1)
Name lst_Müşteriler: [4]!Tablo1[İsim Soyisim]
Name Lst_Nakit_Vadeli: [2]!Tablo13[Nakit / Vadeli Seçimi]
Name Lst_Ödeme_Yön: [3]!Tbl_Ödeme_Yön[Ödeme Yöntemi]
Name lst_Satılık_Kiralık: [4]!tbl_ayar_Satılık[Satılık/Kiralık]
Name Lst_Satış_Per: [6]!Tablo2[Ad Soyad]
Name Lst_Servis: [3]!Tbl_Sektör_Kategori[Servis]
Name Lst_TümHisseler: [7]!TÜM_HİSSELER_1[Menkul]
Name Lst_Ürün_Ailesi: [3]!Tbl_Ürün_Ailesi[Ürün Ailesi]
Name Lst_Ürünler: [2]!Tablo4[Ürün Adı]
Name Lst_Ürünlerim: [1]!Tablo2[Ürün Adı]
Name Lst_Yıl_Ay: [3]!Tablo8[Tarihler]
Name oran: [8]Ürün_Fiyat_Listesi!$E$3

Sheet DashBoard
AJ3: =+#REF! -> #REF! | AK3: =+Veriler!Q14 -> 0.2645098
AJ4: =+Veriler!Q14 -> 0.2645098 | AK4: =+#REF! -> #REF!
B5: Genel Durum | J5: Net kar Marjı % | N5: Gelir ve Giderler | V5: =INDEX(calc!T4:AE4,1,X10) -> APR
X10: 4 | Z10: Ocak | AA10: =Veriler!Q21 -> 5200
Z11: Şubat
Z12: Mart
Z13: Nisan | AA13: =B17-AA10 -> -100
Z14: Mayıs
B15: =+Veriler!D7 -> Gelir | F15: =+Veriler!D15 -> Giderler | J15: Gelir Bütçesinin %'si | N15: =+Veriler!D19 -> Alacak Hesapları | R15: =+Veriler!D20 -> Ödenecek Hesaplar | Z15: Haziran
Z16: Temmuz
B17: =Veriler!Q7 -> 5100 | F17: =Veriler!Q15 -> 2974 | N17: =Veriler!Q19 -> 1068 | R17: =Veriler!Q20 -> 1200 | Z17: Ağustos
Z18: Eylül
Z19: Ekim
Z20: Kasım
Z21: Aralık
B22: =+Veriler!D13 -> Net Kâr | F22: =+Veriler!D16 -> Ay Sonundaki Nakit | J22: Giderler Bütçesinin %'si | N22: =+Veriler!D17 -> Hızlı Oran | R22: =+Veriler!D18 -> Cari Oran
AA23: Budget | AB23: =Veriler!Q23 -> 3650
B24: =Veriler!Q13 -> 1349 | F24: =Veriler!Q16 -> 4482 | N24: =Veriler!Q17 -> 2.11 | R24: =Veriler!Q18 -> 4.08 | AA24: Balance | AB24: =F17-AB23 -> -676

Sheet Veriler
D5: Gösterge | E5: Ocak | F5: Şubat | G5: Mart | H5: Nisan | I5: Mayıs | J5: Haziran | K5: Temmuz | L5: Ağustos | M5: Eylül | N5: Ekim | O5: Kasım | P5: Aralık | Q5: Toplam
D6: Gösterge | E6: JAN | F6: FEB | G6: MAR | H6: APR | I6: MAY | J6: JUN | K6: JUL | L6: AUG | M6: SEP | N6: OCT | O6: NOV | P6: DEC | Q6: Toplam | S6: Seçili dönem ile T-1 dönemi arasında varyans | T6: Seçilen Ay
D7: Gelir | E7: 4501 | F7: 4800 | G7: 4300 | H7: 5100 | I7: 4800 | J7: 5200 | K7: 5100 | L7: 4100 | M7: 5200 | N7: 5184 | O7: 4800 | P7: 4625 | Q7: =IF($T$7=$C$53,SUM(E7:P7),IF($E$6=$T$7,E7,IF($F$6=$T$7,F7,IF($G$6=$T$7,G7,IF($H$6=$T$7,H7,IF($I$6=$T$7,I7,IF($J$6=$T$7,J7,IF($K$6=$T$7,K7,IF($L$6=$T$7,L7,IF($M$6=$T$7,M7,IF($N$6=$T$7,N7,IF($O$6=$T$7,O7,P7)))))))))))) -> 5100 | S7: =IFERROR(IF($T$7=$E$6,0,IF($T$7=$F$6,F7/E7-1,IF($T$7=$G$6,G7/F7-1,IF($T$7=$H$6,H7/G7-1,IF($T$7=$I$6,I7/H7-1,IF($T$7=$J$6,J7/I7-1,IF($T$7=$K$6,K7/J7-1,IF($T$7=$L$6,L7/K7-1,IF($T$7=$M$6,M7/L7-1,IF($T$7=$N$6,N7/M7-1,IF($T$7=$O$6,O7/N7-1,IF($T$7=$P$6,P7/O7-1,"")))))))))))),0) -> 0.18604651 | T7: =DashBoard!V5 -> APR
D8: Satılan Malların Maliyeti | E8: 1250 | F8: 1259 | G8: 1255 | H8: 1252 | I8: 1235 | J8: 1242 | K8: 1226 | L8: 1237 | M8: 1262 | N8: 1201 | O8: 1236 | P8: 1224 | Q8: =IF($T$7=$C$53,SUM(E8:P8),IF($E$6=$T$7,E8,IF($F$6=$T$7,F8,IF($G$6=$T$7,G8,IF($H$6=$T$7,H8,IF($I$6=$T$7,I8,IF($J$6=$T$7,J8,IF($K$6=$T$7,K8,IF($L$6=$T$7,L8,IF($M$6=$T$7,M8,IF($N$6=$T$7,N8,IF($O$6=$T$7,O8,P8)))))))))))) -> 1252 | S8: =IFERROR(IF($T$7=$E$6,0,IF($T$7=$F$6,F8/E8-1,IF($T$7=$G$6,G8/F8-1,IF($T$7=$H$6,H8/G8-1,IF($T$7=$I$6,I8/H8-1,IF($T$7=$J$6,J8/I8-1,IF($T$7=$K$6,K8/J8-1,IF($T$7=$L$6,L8/K8-1,IF($T$7=$M$6,M8/L8-1,IF($T$7=$N$6,N8/M8-1,IF($T$7=$O$6,O8/N8-1,IF($T$7=$P$6,P8/O8-1,"")))))))))))),0) -> -0.0023904382
D9: Brüt Kâr | E9: =E7-E8 -> 3251 | F9: =F7-F8 -> 3541 | G9: =G7-G8 -> 3045 | H9: =H7-H8 -> 3848 | I9: =I7-I8 -> 3565 | J9: =J7-J8 -> 3958 | K9: =K7-K8 -> 3874 | L9: =L7-L8 -> 2863 | ... Q9: =Q7-Q8 -> 3848 | S9: =IFERROR(IF($T$7=$E$6,0,IF($T$7=$F$6,F9/E9-1,IF($T$7=$G$6,G9/F9-1,IF($T$7=$H$6,H9/G9-1,IF($T$7=$I$6,I9/H9-1,IF($T$7=$J$6,J9/I9-1,IF($T$7=$K$6,K9/J9-1,IF($T$7=$L$6,L9/K9-1,IF($T$7=$M$6,M9/L9-1,IF($T$7=$N$6,N9/M9-1,IF($T$7=$O$6,O9/N9-1,IF($T$7=$P$6,P9/O9-1,"")))))))))))),0) -> 0.263711
D10: Toplam Faaliyet Giderleri | E10: 1751 | F10: 1800 | G10: 1785 | H10: 1722 | I10: 1744 | J10: 1751 | K10: 1794 | L10: 1850 | M10: 2002 | N10: 1738 | O10: 1558 | P10: 1444 | Q10: =IF($T$7=$C$53,SUM(E10:P10),IF($E$6=$T$7,E10,IF($F$6=$T$7,F10,IF($G$6=$T$7,G10,IF($H$6=$T$7,H10,IF($I$6=$T$7,I10,IF($J$6=$T$7,J10,IF($K$6=$T$7,K10,IF($L$6=$T$7,L10,IF($M$6=$T$7,M10,IF($N$6=$T$7,N10,IF($O$6=$T$7,O10,P10)))))))))))) -> 1722 | S10: =IFERROR(IF($T$7=$E$6,0,IF($T$7=$F$6,F10/E10-1,IF($T$7=$G$6,G10/F10-1,IF($T$7=$H$6,H10/G10-1,IF($T$7=$I$6,I10/H10-1,IF($T$7=$J$6,J10/I10-1,IF($T$7=$K$6,K10/J10-1,IF($T$7=$L$6,L10/K10-1,IF($T$7=$M$6,M10/L10-1,IF($T$7=$N$6,N10/M10-1,IF($T$7=$O$6,O10/N10-1,IF($T$7=$P$6,P10/O10-1,"")))))))))))),0) -> -0.035294118
D11: Faaliyet Kârı (EBIT) | E11: =E9-E10 -> 1500 | F11: =F9-F10 -> 1741 | G11: =G9-G10 -> 1260 | H11: =H9-H10 -> 2126 | I11: =I9-I10 -> 1821 | J11: =J9-J10 -> 2207 | K11: =K9-K10 -> 2080 | L11: =L9-L10 -> 1013 | ... P11: =P9-P10 -> 1957 | Q11: =+Q9-Q10 -> 2126 | S11: =IFERROR(IF($T$7=$E$6,0,IF($T$7=$F$6,F11/E11-1,IF($T$7=$G$6,G11/F11-1,IF($T$7=$H$6,H11/G11-1,IF($T$7=$I$6,I11/H11-1,IF($T$7=$J$6,J11/I11-1,IF($T$7=$K$6,K11/J11-1,IF($T$7=$L$6,L11/K11-1,IF($T$7=$M$6,M11/L11-1,IF($T$7=$N$6,N11/M11-1,IF($T$7=$O$6,O11/N11-1,IF($T$7=$P$6,P11/O11-1,"")))))))))))),0) -> 0.68730159
D12: Vergiler | E12: 800 | F12: 1000 | G12: 962 | H12: 777 | I12: 1001 | J12: 750 | K12: 999 | L12: 888 | M12: 911 | N12: 781 | O12: 874 | P12: 980 | Q12: =IF($T$7=$C$53,SUM(E12:P12),IF($E$6=$T$7,E12,IF($F$6=$T$7,F12,IF($G$6=$T$7,G12,IF($H$6=$T$7,H12,IF($I$6=$T$7,I12,IF($J$6=$T$7,J12,IF($K$6=$T$7,K12,IF($L$6=$T$7,L12,IF($M$6=$T$7,M12,IF($N$6=$T$7,N12,IF($O$6=$T$7,O12,P12)))))))))))) -> 777 | S12: =IFERROR(IF($T$7=$E$6,0,IF($T$7=$F$6,F12/E12-1,IF($T$7=$G$6,G12/F12-1,IF($T$7=$H$6,H12/G12-1,IF($T$7=$I$6,I12/H12-1,IF($T$7=$J$6,J12/I12-1,IF($T$7=$K$6,K12/J12-1,IF($T$7=$L$6,L12/K12-1,IF($T$7=$M$6,M12/L12-1,IF($T$7=$N$6,N12/M12-1,IF($T$7=$O$6,O12/N12-1,IF($T$7=$P$6,P12/O12-1,"")))))))))))),0) -> -0.19230769
D13: Net Kâr | E13: =E11-E12 -> 700 | F13: =F11-F12 -> 741 | G13: =G11-G12 -> 298 | H13: =H11-H12 -> 1349 | I13: =I11-I12 -> 820 | J13: =J11-J12 -> 1457 | K13: =K11-K12 -> 1081 | L13: =L11-L12 -> 125 | ... P13: =P11-P12 -> 977 | Q13: =+Q11-Q12 -> 1349 | S13: =IFERROR(IF($T$7=$E$6,0,IF($T$7=$F$6,F13/E13-1,IF($T$7=$G$6,G13/F13-1,IF($T$7=$H$6,H13/G13-1,IF($T$7=$I$6,I13/H13-1,IF($T$7=$J$6,J13/I13-1,IF($T$7=$K$6,K13/J13-1,IF($T$7=$L$6,L13/K13-1,IF($T$7=$M$6,M13/L13-1,IF($T$7=$N$6,N13/M13-1,IF($T$7=$O$6,O13/N13-1,IF($T$7=$P$6,P13/O13-1,"")))))))))))),0) -> 3.5268456
D14: Net Kâr Marjı (%) | E14: =IFERROR(E13/E7,0) -> 0.155521 | F14: =IFERROR(F13/F7,0) -> 0.154375 | G14: =IFERROR(G13/G7,0) -> 0.069302326 | H14: =IFERROR(H13/H7,0) -> 0.2645098 | I14: =IFERROR(I13/I7,0) -> 0.17083333 | J14: =IFERROR(J13/J7,0) -> 0.28019231 | K14: =IFERROR(K13/K7,0) -> 0.21196078 | L14: =IFERROR(L13/L7,0) -> 0.030487805 | ... P14: =IFERROR(P13/P7,0) -> 0.21124324 | Q14: =IF($T$7=$C$53,SUM(E14:P14),IF($E$6=$T$7,E14,IF($F$6=$T$7,F14,IF($G$6=$T$7,G14,IF($H$6=$T$7,H14,IF($I$6=$T$7,I14,IF($J$6=$T$7,J14,IF($K$6=$T$7,K14,IF($L$6=$T$7,L14,IF($M$6=$T$7,M14,IF($N$6=$T$7,N14,IF($O$6=$T$7,O14,P14)))))))))))) -> 0.2645098 | S14: =IFERROR(IF($T$7=$E$6,0,IF($T$7=$F$6,F14/E14-1,IF($T$7=$G$6,G14/F14-1,IF($T$7=$H$6,H14/G14-1,IF($T$7=$I$6,I14/H14-1,IF($T$7=$J$6,J14/I14-1,IF($T$7=$K$6,K14/J14-1,IF($T$7=$L$6,L14/K14-1,IF($T$7=$M$6,M14/L14-1,IF($T$7=$N$6,N14/M14-1,IF($T$7=$O$6,O14/N14-1,IF($T$7=$P$6,P14/O14-1,"")))))))))))),0) -> 2.8167522
D15: Giderler | E15: =E8+E10 -> 3001 | F15: =F8+F10 -> 3059 | G15: =G8+G10 -> 3040 | H15: =H8+H10 -> 2974 | I15: =I8+I10 -> 2979 | J15: =J8+J10 -> 2993 | K15: =K8+K10 -> 3020 | L15: =L8+L10 -> 3087 | ... P15: =P8+P10 -> 2668 | Q15: =Q10+Q8 -> 2974 | S15: =IFERROR(IF($T$7=$E$6,0,IF($T$7=$F$6,F15/E15-1,IF($T$7=$G$6,G15/F15-1,IF($T$7=$H$6,H15/G15-1,IF($T$7=$I$6,I15/H15-1,IF($T$7=$J$6,J15/I15-1,IF($T$7=$K$6,K15/J15-1,IF($T$7=$L$6,L15/K15-1,IF($T$7=$M$6,M15/L15-1,IF($T$7=$N$6,N15/M15-1,IF($T$7=$O$6,O15/N15-1,IF($T$7=$P$6,P15/O15-1,"")))))))))))),0) -> -0.021710526
D16: Ay Sonundaki Nakit | E16: 4385 | F16: 4167 | G16: 4711 | H16: 4482 | I16: 4299 | J16: 4999 | K16: 4889 | L16: 4721 | M16: 4321 | N16: 4927 | O16: 4288 | P16: 4677 | Q16: =IF($T$7=$C$53,SUM(E16:P16),IF($E$6=$T$7,E16,IF($F$6=$T$7,F16,IF($G$6=$T$7,G16,IF($H$6=$T$7,H16,IF($I$6=$T$7,I16,IF($J$6=$T$7,J16,IF($K$6=$T$7,K16,IF($L$6=$T$7,L16,IF($M$6=$T$7,M16,IF($N$6=$T$7,N16,IF($O$6=$T$7,O16,P16)))))))))))) -> 4482 | S16: =IFERROR(IF($T$7=$E$6,0,IF($T$7=$F$6,F16/E16-1,IF($T$7=$G$6,G16/F16-1,IF($T$7=$H$6,H16/G16-1,IF($T$7=$I$6,I16/H16-1,IF($T$7=$J$6,J16/I16-1,IF($T$7=$K$6,K16/J16-1,IF($T$7=$L$6,L16/K16-1,IF($T$7=$M$6,M16/L16-1,IF($T$7=$N$6,N16/M16-1,IF($T$7=$O$6,O16/N16-1,IF($T$7=$P$6,P16/O16-1,"")))))))))))),0) -> -0.048609637
D17: Hızlı Oran | E17: 1.33 | F17: 1.47 | G17: 1.89 | H17: 2.11 | I17: 1.94 | J17: 1.68 | K17: 1.45 | L17: 1.22 | M17: 1.11 | N17: 1.55 | O17: 1.76 | P17: 1.33 | Q17: =IF($T$7=$C$53,#REF!,IF($E$6=$T$7,E17,IF($F$6=$T$7,F17,IF($G$6=$T$7,G17,IF($H$6=$T$7,H17,IF($I$6=$T$7,I17,IF($J$6=$T$7,J17,IF($K$6=$T$7,K17,IF($L$6=$T$7,L17,IF($M$6=$T$7,M17,IF($N$6=$T$7,N17,IF($O$6=$T$7,O17,P17)))))))))))) -> 2.11 | S17: =IFERROR(IF($T$7=$E$6,0,IF($T$7=$F$6,F17/E17-1,IF($T$7=$G$6,G17/F17-1,IF($T$7=$H$6,H17/G17-1,IF($T$7=$I$6,I17/H17-1,IF($T$7=$J$6,J17/I17-1,IF($T$7=$K$6,K17/J17-1,IF($T$7=$L$6,L17/K17-1,IF($T$7=$M$6,M17/L17-1,IF($T$7=$N$6,N17/M17-1,IF($T$7=$O$6,O17/N17-1,IF($T$7=$P$6,P17/O17-1,"")))))))))))),0) -> 0.11640212
D18: Cari Oran | E18: 4.11 | F18: 3.66 | G18: 4.01 | H18: 4.08 | I18: 4.11 | J18: 2.99 | K18: 3.22 | L18: 3.66 | M18: 3.12 | N18: 3.55 | O18: 3.88 | P18: 3.99 | Q18: =IF($T$7=$C$53,SUM(E18:P18),IF($E$6=$T$7,E18,IF($F$6=$T$7,F18,IF($G$6=$T$7,G18,IF($H$6=$T$7,H18,IF($I$6=$T$7,I18,IF($J$6=$T$7,J18,IF($K$6=$T$7,K18,IF($L$6=$T$7,L18,IF($M$6=$T$7,M18,IF($N$6=$T$7,N18,IF($O$6=$T$7,O18,P18)))))))))))) -> 4.08 | S18: =IFERROR(IF($T$7=$E$6,0,IF($T$7=$F$6,F18/E18-1,IF($T$7=$G$6,G18/F18-1,IF($T$7=$H$6,H18/G18-1,IF($T$7=$I$6,I18/H18-1,IF($T$7=$J$6,J18/I18-1,IF($T$7=$K$6,K18/J18-1,IF($T$7=$L$6,L18/K18-1,IF($T$7=$M$6,M18/L18-1,IF($T$7=$N$6,N18/M18-1,IF($T$7=$O$6,O18/N18-1,IF($T$7=$P$6,P18/O18-1,"")))))))))))),0) -> 0.017456359
D19: Alacak Hesapları | E19: 1060 | F19: 991 | G19: 1050 | H19: 1068 | I19: 1028 | J19: 1020 | K19: 1052 | L19: 1016 | M19: 1024 | N19: 1067 | O19: 1021 | P19: 1003 | Q19: =IF($T$7=$C$53,SUM(E19:P19),IF($E$6=$T$7,E19,IF($F$6=$T$7,F19,IF($G$6=$T$7,G19,IF($H$6=$T$7,H19,IF($I$6=$T$7,I19,IF($J$6=$T$7,J19,IF($K$6=$T$7,K19,IF($L$6=$T$7,L19,IF($M$6=$T$7,M19,IF($N$6=$T$7,N19,IF($O$6=$T$7,O19,P19)))))))))))) -> 1068 | S19: =IFERROR(IF($T$7=$E$6,0,IF($T$7=$F$6,F19/E19-1,IF($T$7=$G$6,G19/F19-1,IF($T$7=$H$6,H19/G19-1,IF($T$7=$I$6,I19/H19-1,IF($T$7=$J$6,J19/I19-1,IF($T$7=$K$6,K19/J19-1,IF($T$7=$L$6,L19/K19-1,IF($T$7=$M$6,M19/L19-1,IF($T$7=$N$6,N19/M19-1,IF($T$7=$O$6,O19/N19-1,IF($T$7=$P$6,P19/O19-1,"")))))))))))),0) -> 0.017142857
D20: Ödenecek Hesaplar | E20: 884 | F20: 867 | G20: 904 | H20: 1200 | I20: 977 | J20: 888 | K20: 901 | L20: 970 | M20: 830 | N20: 913 | O20: 802 | P20: 801 | Q20: =IF($T$7=$C$53,SUM(E20:P20),IF($E$6=$T$7,E20,IF($F$6=$T$7,F20,IF($G$6=$T$7,G20,IF($H$6=$T$7,H20,IF($I$6=$T$7,I20,IF($J$6=$T$7,J20,IF($K$6=$T$7,K20,IF($L$6=$T$7,L20,IF($M$6=$T$7,M20,IF($N$6=$T$7,N20,IF($O$6=$T$7,O20,P20)))))))))))) -> 1200 | S20: =IFERROR(IF($T$7=$E$6,0,IF($T$7=$F$6,F20/E20-1,IF($T$7=$G$6,G20/F20-1,IF($T$7=$H$6,H20/G20-1,IF($T$7=$I$6,I20/H20-1,IF($T$7=$J$6,J20/I20-1,IF($T$7=$K$6,K20/J20-1,IF($T$7=$L$6,L20/K20-1,IF($T$7=$M$6,M20/L20-1,IF($T$7=$N$6,N20/M20-1,IF($T$7=$O$6,O20/N20-1,IF($T$7=$P$6,P20/O20-1,"")))))))))))),0) -> 0.32743363
D21: Gelir Bütçesi | E21: 4718 | F21: 5111 | G21: 4888 | H21: 5200 | I21: 5222 | J21: 5288 | K21: 5311 | L21: 4999 | M21: 5388 | N21: 5488 | O21: 5500 | P21: 4999 | Q21: =IF($T$7=$C$53,SUM(E21:P21),IF($E$6=$T$7,E21,IF($F$6=$T$7,F21,IF($G$6=$T$7,G21,IF($H$6=$T$7,H21,IF($I$6=$T$7,I21,IF($J$6=$T$7,J21,IF($K$6=$T$7,K21,IF($L$6=$T$7,L21,IF($M$6=$T$7,M21,IF($N$6=$T$7,N21,IF($O$6=$T$7,O21,P21)))))))))))) -> 5200 | S21: =IFERROR(IF($T$7=$E$6,0,IF($T$7=$F$6,F21/E21-1,IF($T$7=$G$6,G21/F21-1,IF($T$7=$H$6,H21/G21-1,IF($T$7=$I$6,I21/H21-1,IF($T$7=$J$6,J21/I21-1,IF($T$7=$K$6,K21/J21-1,IF($T$7=$L$6,L21/K21-1,IF($T$7=$M$6,M21/L21-1,IF($T$7=$N$6,N21/M21-1,IF($T$7=$O$6,O21/N21-1,IF($T$7=$P$6,P21/O21-1,"")))))))))))),0) -> 0.063829787
D22: Gelir Bütçesinin %'si | E22: =IFERROR(IF(E21="","",E7/E21),0) -> 0.95400593 | F22: =IFERROR(IF(F21="","",F7/F21),0) -> 0.93915085 | G22: =IFERROR(IF(G21="","",G7/G21),0) -> 0.8797054 | H22: =IFERROR(IF(H21="","",H7/H21),0) -> 0.98076923 | I22: =IFERROR(IF(I21="","",I7/I21),0) -> 0.91918805 | J22: =IFERROR(IF(J21="","",J7/J21),0) -> 0.98335855 | K22: =IFERROR(IF(K21="","",K7/K21),0) -> 0.96027114 | L22: =IFERROR(IF(L21="","",L7/L21),0) -> 0.82016403 | ... Q22: =IFERROR(IF(Q21="","",Q7/Q21),0) -> 0.98076923 | S22: =IFERROR(IF($T$7=$E$6,0,IF($T$7=$F$6,F22/E22-1,IF($T$7=$G$6,G22/F22-1,IF($T$7=$H$6,H22/G22-1,IF($T$7=$I$6,I22/H22-1,IF($T$7=$J$6,J22/I22-1,IF($T$7=$K$6,K22/J22-1,IF($T$7=$L$6,L22/K22-1,IF($T$7=$M$6,M22/L22-1,IF($T$7=$N$6,N22/M22-1,IF($T$7=$O$6,O22/N22-1,IF($T$7=$P$6,P22/O22-1,"")))))))))))),0) -> 0.11488372
D23: Giderler Bütçesi | E23: 3662 | F23: 3674 | G23: 3568 | H23: 3650 | I23: 3568 | J23: 3595 | K23: 3515 | L23: 3561 | M23: 3558 | N23: 3530 | O23: 3592 | P23: 3556 | Q23: =IF($T$7=$C$53,SUM(E23:P23),IF($E$6=$T$7,E23,IF($F$6=$T$7,F23,IF($G$6=$T$7,G23,IF($H$6=$T$7,H23,IF($I$6=$T$7,I23,IF($J$6=$T$7,J23,IF($K$6=$T$7,K23,IF($L$6=$T$7,L23,IF($M$6=$T$7,M23,IF($N$6=$T$7,N23,IF($O$6=$T$7,O23,P23)))))))))))) -> 3650 | S23: =IFERROR(IF($T$7=$E$6,0,IF($T$7=$F$6,F23/E23-1,IF($T$7=$G$6,G23/F23-1,IF($T$7=$H$6,H23/G23-1,IF($T$7=$I$6,I23/H23-1,IF($T$7=$J$6,J23/I23-1,IF($T$7=$K$6,K23/J23-1,IF($T$7=$L$6,L23/K23-1,IF($T$7=$M$6,M23/L23-1,IF($T$7=$N$6,N23/M23-1,IF($T$7=$O$6,O23/N23-1,IF($T$7=$P$6,P23/O23-1,"")))))))))))),0) -> 0.022982063
D24: Giderler Bütçesinin %'si | E24: =IFERROR(IF(E23="","",E15/E23),0) -> 0.81949754 | F24: =IFERROR(IF(F23="","",F15/F23),0) -> 0.83260751 | G24: =IFERROR(IF(G23="","",G15/G23),0) -> 0.85201794 | H24: =IFERROR(IF(H23="","",H15/H23),0) -> 0.81479452 | I24: =IFERROR(IF(I23="","",I15/I23),0) -> 0.83492152 | J24: =IFERROR(IF(J23="","",J15/J23),0) -> 0.8325452 | K24: =IFERROR(IF(K23="","",K15/K23),0) -> 0.85917496 | L24: =IFERROR(IF(L23="","",L15/L23),0) -> 0.86689132 | ... Q24: =IFERROR(IF(Q23="","",Q15/Q23),0) -> 0.81479452 | S24: =IFERROR(IF($T$7=$E$6,0,IF($T$7=$F$6,F24/E24-1,IF($T$7=$G$6,G24/F24-1,IF($T$7=$H$6,H24/G24-1,IF($T$7=$I$6,I24/H24-1,IF($T$7=$J$6,J24/I24-1,IF($T$7=$K$6,K24/J24-1,IF($T$7=$L$6,L24/K24-1,IF($T$7=$M$6,M24/L24-1,IF($T$7=$N$6,N24/M24-1,IF($T$7=$O$6,O24/N24-1,IF($T$7=$P$6,P24/O24-1,"")))))))))))),0) -> -0.043688536
D32: % Net Profit Target | F32: 0.14
C37: =D15 -> Giderler | G37: =-G15 -> -3040 | H37: =-H15 -> -2974 | I37: =-I15 -> -2979 | J37: =-J15 -> -2993 | K37: =-K15 -> -3020 | L37: =-L15 -> -3087 | M37: =-M15 -> -3264 | N37: =-N15 -> -2939 | ... Q37: =-Q15 -> -2974
C40: Months
C41: JAN
C42: FEB
C43: MAR
C44: APR
C45: MAY
C46: JUN
C47: JUL
C48: AUG
C49: SEP
C50: OCT
C51: NOV
... C53: All

Sheet calc
C2: ID | E2: KPIs | G2: Value
C4: 1 | E4: =Veriler!D7 -> Gelir | G4: =Veriler!S7 -> 0.18604651 | T4: JAN | U4: FEB | V4: MAR | W4: APR | X4: MAY | Y4: JUN | Z4: JUL | AA4: AUG | AB4: SEP | AC4: OCT | AD4: NOV | AE4: DEC
C5: 2 | E5: =Veriler!D13 -> Net Kâr | G5: =Veriler!S13 -> 3.5268456 | S5: Gelir | T5: =+Veriler!E7 -> 4501 | U5: =+Veriler!F7 -> 4800 | V5: =+Veriler!G7 -> 4300 | W5: =+Veriler!H7 -> 5100 | X5: =+Veriler!I7 -> 4800 | Y5: =+Veriler!J7 -> 5200 | Z5: =+Veriler!K7 -> 5100 | AA5: =+Veriler!L7 -> 4100 | ... AE5: =+Veriler!P7 -> 4625
C6: 3 | E6: =Veriler!D14 -> Net Kâr Marjı (%) | G6: =Veriler!S14 -> 2.8167522 | S6: Gider | T6: =+Veriler!E15 -> 3001 | U6: =+Veriler!F15 -> 3059 | V6: =+Veriler!G15 -> 3040 | W6: =+Veriler!H15 -> 2974 | X6: =+Veriler!I15 -> 2979 | Y6: =+Veriler!J15 -> 2993 | Z6: =+Veriler!K15 -> 3020 | AA6: =+Veriler!L15 -> 3087 | ... AE6: =+Veriler!P15 -> 2668
C7: 4 | E7: =Veriler!D15 -> Giderler | G7: =Veriler!S15 -> -0.021710526
C8: 5 | E8: =Veriler!D16 -> Ay Sonundaki Nakit | G8: =Veriler!S16 -> -0.048609637
C9: 6 | E9: =Veriler!D17 -> Hızlı Oran | G9: =Veriler!S17 -> 0.11640212
C10: 7 | E10: =Veriler!D18 -> Cari Oran | G10: =Veriler!S18 -> 0.017456359
C11: 8 | E11: =Veriler!D19 -> Alacak Hesapları | G11: =Veriler!S19 -> 0.017142857
C12: 9 | E12: =Veriler!D20 -> Ödenecek Hesaplar | G12: =Veriler!S20 -> 0.32743363
C13: 10 | E13: =Veriler!D22 -> Gelir Bütçesinin %'si | G13: =+Veriler!S22 -> 0.11488372
C14: 11 | E14: =Veriler!D24 -> Giderler Bütçesinin %'si | G14: =Veriler!S24 -> -0.043688536
C15: 12 | E15: Net Profit vs Target | G15: =N38-G20 -> 0.1245098
E19: Net Kar Marjı Fiili | G19: =Veriler!Q14 -> 0.2645098
E20: Net Kar Marjı Hedefi | G20: =Veriler!F32 -> 0.14
N38: =G19 -> 0.2645098
G40: Expense
C41: Income
C42: =Veriler!Q22 -> 0.98076923 | H42: =+Veriler!Q24 -> 0.81479452 | J42: =+Veriler!S24 -> -0.043688536
C43: =100%-C42 -> 0.019230769 | H43: =100%-H42 -> 0.18520548 | J43: =100%-J42 -> 1.0436885

Sheet Statement
C3: Gelir Tablosu
C4: Toplam Gelir | D4: =DashBoard!B17 -> 5100
C5: Satılan Malların Maliyeti | D5: =-Veriler!Q8 -> -1252
C6: Brüt Kar | D6: =+Veriler!Q9 -> 3848
C7: Toplam Faaliyet Giderleri | D7: =-Veriler!Q10 -> -1722
C8: Faaliyet Karı (EBIT) | D8: =+Veriler!Q11 -> 2126
C9: Vergiler | D9: =-Veriler!Q12 -> -777
C10: Net Kâr | D10: =SUM(D4:D9) -> 7323

Sheet ChartsDataSheet
A1: Gauge Chart Name: | B1: AV | C1: 1 | D1: 2 | E1: 3 | F1: min | G1: max | H1: diff | I1: Format | J1: Decimals | K1: Labels size | L1: AV size | M1: ref 2E | N1: ref 1E | O1: color 1 | P1: color 2 | Q1: color 3 | R1: Skin | S1: Sheet Name | T1: Sheet Index | U1: Attached | V1: Reference | W1: color AV | X1: Description | Y1: Size | Z1: PV | AA1: 1 | AB1: 2 | AC1: 3 | AD1: min | AE1: max | AF1: diff | AG1: TextBoxDiff | AH1: color PV | AI1: ref 4S | AJ1: ref 4E | AK1: ref 5E | AL1: ref 6E | AM1: ref 7E | AN1: ref 8E | AO1: ref 9E | AP1: ref 10E | AQ1: ref 11E | AR1: ref 12E | AS1: color 4 | AT1: color 5 | AU1: color 6 | AV1: color 7 | AW1: color 8 | AX1: color 9 | AY1: color 10 | AZ1: color 11 | BA1: color 12 | BB1: Zones Count | BC1: Hform | BD1: Reverse? | BE1: 1 | BF1: 2 | BG1: 3 | BH1: 1 | BI1: 2 | BJ1: 3 | BK1: color LB | BL1: color A | BM1: color D | CW1: Variance Chart Name: | CX1: Sheet Name | CY1: Sheet Index | CZ1: Attached | DA1: Reference | DB1: Data 1 | DC1: Data 2 | DD1: Diff | DE1: Series 1 | DF1: Series 2 | DG1: Data 1 | DH1: Data 2 | DI1: Diff | DJ1: Series 1 | DK1: Series 2 | BES1: Sales Funnel Chart Name: | BET1: Sheet Name | BEU1: Sheet Index | BEV1: Attached | BEW1: Reference | BEX1: Series 1 | BIO1: TL Chart Name: | BIP1: AV | BIQ1: Green | BIR1: Yellow | BIS1: AV Val. | BIT1: Size 1 | BIU1: Size 2 | BIV1: Size 3 | BIW1: Format | BIX1: Decimals | BIY1: ForeColor | BIZ1: Border | BJA1: Off Light | BJB1: Text | BJC1: Color 1 | BJD1: Color 2 | BJE1: Color 3 | BJF1: Model | BJG1: Sheet Name | BJH1: Sheet Index | BJI1: Attached | BJJ1: Reference | BJK1: Minim | BJL1: Maxim | BUC1: VarianceActualHorizontal: | BUD1: Sheet Name | BUE1: Sheet Index | BUF1: Attached | BUG1: Reference | BUH1: Data 1 | BUI1: Data 2 | BUJ1: Data 3 | BUK1: Data 4 | BUL1: Data 5 | BUM1: Data 6 | BUN1: Data 7 | BUO1: Data 8 | BUP1: Data 9 | BUQ1: Data 10 | BUR1: Data 11 | BUS1: Data 12 | BUT1: Data 13 | BUU1: Data 14 | BUV1: Data 15 | BUW1: Data 16 | BUX1: Data 17 | BUY1: Data 18 | BUZ1: Data 19 | BVA1: Data 20 | BVB1: Data 21 | BVC1: Data 22 | BVD1: Data 23 | BVE1: Data 24 | BVF1: Data 25 | BVG1: Data 26 | BVH1: Data 27 | BVI1: Data 28 | BVJ1: Data 29 | BVK1: Data 30 | BVL1: Data 31 | BVM1: Data 32 | BVN1: Data 33 | BVO1: Data 34 | BVP1: Data 35 | BVQ1: Data 36 | BVR1: Data 37 | BVS1: Data 38 | BVT1: Data 39 | BVU1: Data 40 | BVV1: Data 41 | BVW1: Data 42 | BVX1: Data 43 | BVY1: Data 44 | BVZ1: Data 45 | BWA1: Data 46 | BWB1: Data 47 | BWC1: Data 48 | BWD1: Data 49 | BWE1: Data 50 | BWF1: Data 51 | BWG1: Data 52 | BWH1: Data 53 | BWI1: Data 54 | BWJ1: Data 55 | BWK1: Data 56 | BWL1: Data 57 | BWM1: Data 58 | BWN1: Data 59 | BWO1: Data 60 | BWP1: Data 61 | BWQ1: Data 62 | BWR1: Data 63 | BWS1: Data 64 | BWT1: Data 65 | BWU1: Data 66 | BWV1: Data 67 | BWW1: Data 68 | BWX1: Data 69 | BWY1: Data 70 | BWZ1: Data 71 | BXA1: Data 72 | BXB1: Data 73 | BXC1: Data 74 | BXD1: Data 75 | BXE1: Data 76 | BXF1: Data 77 | BXG1: Data 78 | BXH1: Data 79 | BXI1: Data 80 | BXJ1: Data 81 | BXK1: Data 82 | BXL1: Data 83 | BXM1: Data 84 | BXN1: Data 85 | BXO1: Data 86 | BXP1: Data 87 | BXQ1: Data 88 | BXR1: Data 89 | BXS1: Data 90 | BXT1: Data 91 | BXU1: Data 92 | BXV1: Data 93 | BXW1: Data 94 | BXX1: Data 95 | BXY1: WaterFallChart Name: | BXZ1: Sheet Name | BYA1: Sheet Index | BYB1: Attached | BYC1: Reference | BYD1: Labels | BYE1: Values | BYF1: Cumulative | BYG1: Start - End | BYH1: Before | BYI1: After | BYJ1: Data label position | CBU1: MekkoChart Name: | CBV1: Sheet Name | CBW1: Sheet Index | CBX1: Attached | CBY1: Reference | CFQ1: OrgChart Name: | CFR1: Sheet Name | CFS1: Sheet Index | CFT1: Attached | CFU1: Reference | CJM1: RadialBarChart Name: | CJN1: Sheet Name | CJO1: Sheet Index | CJP1: Attached | CJQ1: Reference | CJR1: MaxValue | CJS1: Value 1 | CJT1: Desc 1 | CJU1: v 1 | CJV1: i 1 | CJW1: Value 2 | CJX1: Desc 2 | CJY1: v 2 | CJZ1: i 2 | CKA1: Value 3 | CKB1: Desc 3 | CKC1: v 3 | CKD1: i 3 | CKE1: Value 4 | CKF1: Desc 4 | CKG1: v 4 | CKH1: i 4 | CKI1: Value 5 | CKJ1: Desc 5 | CKK1: v 5 | CKL1: i 5 | CKM1: Value 6 | CKN1: Desc 6 | CKO1: v 6 | CKP1: i 6 | CKQ1: Value 7 | CKR1: Desc 7 | CKS1: v 7 | CKT1: i 7 | CKU1: Value 8 | CKV1: Desc 8 | CKW1: v 8 | CKX1: i 8 | CKY1: Value 9 | CKZ1: Desc 9 | CLA1: v 9 | CLB1: i 9 | CLC1: Value 10 | CLD1: Desc 10 | CLE1: v 10 | CLF1: i 10 | CNI1: Sales Funnel2 Chart Name: | CNJ1: Sheet Name | CNK1: Sheet Index | CNL1: Attached | CNM1: Reference | CNN1: Colors | CNO1: DataText | CNP1: DataValue | CNQ1: x | CNR1: Label | CNS1: Value | CNT1: Low | CNU1: High | CNV1: x2 | CNW1: yLabel | CNX1: yPercent | CNY1: LabelPercent | CNZ1: xxx | COA1: xxx | COB1: xxx
A2: G2_sample | B2: =DashBoard!$AK$4 -> #REF! | C2: =100*B2-F2 -> #REF! | D2: =H2/50 -> 0.6 | E2: =1.5*H2-C2-D2 -> #REF! | F2: 0 | G2: 30 | H2: =G2-F2 -> 30 | I2: Per | J2: 1 | K2: 9 | L2: 15 | M2: 20 | N2: 10 | O2: 255 | P2: 65535 | Q2: 49152 | R2: Skin 5 | S2: =SUBSTITUTE(MID(_xlfn.FORMULATEXT(V2),2,FIND("!",_xlfn.FORMULATEXT(V2),1)-2), "'","") -> DashBoard | T2: =_xlfn.SHEET( DashBoard!$NTR$1000003) -> 2 | V2: =DashBoard!$NTR$1000003 -> 0 | W2: 128 | X2: Net Profit Margin vs Target | Y2: 13 | Z2: =DashBoard!$AK$3 -> 0.2645098 | AA2: =100*Z2-AD2 -> 26.45098 | AB2: =AF2/50 -> 0.6 | AC2: =1.5*AF2-AA2-AB2 -> 17.94902 | AD2: 0 | AE2: 30 | AF2: =AE2-AD2 -> 30 | AG2: =B2-Z2 -> #REF! | AH2: 0 | BB2: 3 | BC2: 430 | BD2: FALSE | BE2: =E2 -> #REF! | BF2: =D2 -> 0.6 | BG2: =C2 -> #REF! | BH2: =AC2 -> 17.94902 | BI2: =AB2 -> 0.6 | BJ2: =AA2 -> 26.45098 | BK2: 0 | BL2: 0 | BM2: 0 | BIO2: TL_484 | BIP2: =55 -> 55 | BIQ2: 30 | BIR2: 70 | BIS2: =VALUE(BIP2) -> 55 | BIT2: =IF(BIS2>=BIR2,1,0) -> 0 | BIU2: =IF(AND(BIS2>BIQ2,BIS2<BIR2),1,0) -> 1 | BIV2: =IF(BIS2<=BIQ2,1,0) -> 0 | BIW2: Num | BIX2: 0 | BIY2: 2500134 | BIZ2: 8421504 | BJA2: 0 | BJB2: 16777215 | BJC2: 255 | BJD2: 65535 | BJE2: 49152 | BJF2: TL_V1 | BJG2: =SUBSTITUTE(MID(_xlfn.FORMULATEXT(BJJ2),2,FIND("!",_xlfn.FORMULATEXT(BJJ2),1)-2), "'","") -> DashBoard | BJH2: =_xlfn.SHEET( DashBoard!$NTP$1000001) -> 2 | BJJ2: =DashBoard!$NTP$1000001 -> 0 | BJK2: 0 | BJL2: 100 | BUC2: VAH_1 | BUD2: =SUBSTITUTE(MID(_xlfn.FORMULATEXT(BUG2),2,FIND("!",_xlfn.FORMULATEXT(BUG2),1)-2), "'","") -> #REF | BUE2: =_xlfn.SHEET(#REF!) -> #REF! | BUG2: =#REF! -> #REF! | BXY2: WAT_1 | BXZ2: =SUBSTITUTE(MID(_xlfn.FORMULATEXT(BYC2),2,FIND("!",_xlfn.FORMULATEXT(BYC2),1)-2), "'","") -> Statement | BYA2: =_xlfn.SHEET( Statement!$NTP$1000000) -> 5 | BYC2: =Statement!$NTP$1000000 -> 0 | BYD2: =Statement!$C$4 -> Toplam Gelir | BYE2: =Statement!$D$4 -> 5100 | BYF2: =BYE2 -> 5100 | BYG2: =BYE2 -> 5100 | CJM2: RBC_1 | CJN2: =SUBSTITUTE(MID(_xlfn.FORMULATEXT(CJQ2),2,FIND("!",_xlfn.FORMULATEXT(CJQ2),1)-2), "'","") -> DashBoard | CJO2: =_xlfn.SHEET( DashBoard!$NTR$1000003) -> 2 | CJQ2: =DashBoard!$NTR$1000003 -> 0 | CJR2: =MAX( DashBoard!$AK$3:$AK$4) -> #REF! | CJS2: =DashBoard!$AK$3 -> 0.2645098 | CJU2: =0.75*CJS2/CJR2 -> #REF! | CJV2: =1-CJU2 -> #REF! | CJW2: =DashBoard!$AK$4 -> #REF! | CJY2: =0.75*CJW2/CJR2 -> #REF! | CJZ2: =1-CJY2 -> #REF!
A3: G1_44 | B3: =55 -> 55 | C3: =B3-F3 -> 55 | D3: =H3/50 -> 2 | E3: =1.5*H3-C3-D3 -> 93 | F3: 0 | G3: 100 | H3: =G3-F3 -> 100 | I3: Num | J3: 0 | K3: 9 | L3: 15 | M3: 70 | N3: 30 | O3: 255 | P3: 65535 | Q3: 49152 | R3: Skin 1 | S3: =SUBSTITUTE(MID(_xlfn.FORMULATEXT(V3),2,FIND("!",_xlfn.FORMULATEXT(V3),1)-2), "'","") -> DashBoard | T3: =_xlfn.SHEET( DashBoard!$NTP$1000001) -> 2 | V3: =DashBoard!$NTP$1000001 -> 0 | W3: 0 | X3: Description | Y3: 13 | BB3: 3 | BC3: 430 | BD3: FALSE | BE3: =E3 -> 93 | BF3: =D3 -> 2 | BG3: =C3 -> 55 | BK3: 0 | BL3: 0 | BM3: 0 | CW3: VR_1 | CX3: =SUBSTITUTE(MID(_xlfn.FORMULATEXT(DA3),2,FIND("!",_xlfn.FORMULATEXT(DA3),1)-2), "'","") -> calc | CY3: =_xlfn.SHEET( calc!$NTP$1000000) -> 4 | DA3: =calc!$NTP$1000000 -> 0 | DB3: =calc!$T$5 -> 4501 | DC3: =calc!$T$6 -> 3001 | DD3: =DC3-DB3 -> -1500 | DE3: =IF(DD3<0,DD3,"") -> -1500 | DF3: =IF(DD3>0,DD3,"") | DG3: =calc!$U$5 -> 4800 | DH3: =calc!$U$6 -> 3059 | DI3: =DH3-DG3 -> -1741 | DJ3: =IF(DI3<0,DI3,"") -> -1741 | DK3: =IF(DI3>0,DI3,"") | DL3: =calc!$V$5 -> 4300 | DM3: =calc!$V$6 -> 3040 | DN3: =DM3-DL3 -> -1260 | DO3: =IF(DN3<0,DN3,"") -> -1260 | DP3: =IF(DN3>0,DN3,"") | DQ3: =calc!$W$5 -> 5100 | DR3: =calc!$W$6 -> 2974 | DS3: =DR3-DQ3 -> -2126 | DT3: =IF(DS3<0,DS3,"") -> -2126 | DU3: =IF(DS3>0,DS3,"") | DV3: =calc!$X$5 -> 4800 | DW3: =calc!$X$6 -> 2979 | DX3: =DW3-DV3 -> -1821 | DY3: =IF(DX3<0,DX3,"") -> -1821 | DZ3: =IF(DX3>0,DX3,"") | EA3: =calc!$Y$5 -> 5200 | EB3: =calc!$Y$6 -> 2993 | EC3: =EB3-EA3 -> -2207 | ED3: =IF(EC3<0,EC3,"") -> -2207 | EE3: =IF(EC3>0,EC3,"") | EF3: =calc!$Z$5 -> 5100 | EG3: =calc!$Z$6 -> 3020 | EH3: =EG3-EF3 -> -2080 | EI3: =IF(EH3<0,EH3,"") -> -2080 | EJ3: =IF(EH3>0,EH3,"") | EK3: =calc!$AA$5 -> 4100 | EL3: =calc!$AA$6 -> 3087 | EM3: =EL3-EK3 -> -1013 | EN3: =IF(EM3<0,EM3,"") -> -1013 | EO3: =IF(EM3>0,EM3,"") | EP3: =calc!$AB$5 -> 5200 | EQ3: =calc!$AB$6 -> 3264 | ER3: =EQ3-EP3 -> -1936 | ES3: =IF(ER3<0,ER3,"") -> -1936 | ET3: =IF(ER3>0,ER3,"") | EU3: =calc!$AC$5 -> 5184 | EV3: =calc!$AC$6 -> 2939 | EW3: =EV3-EU3 -> -2245 | EX3: =IF(EW3<0,EW3,"") -> -2245 | EY3: =IF(EW3>0,EW3,"") | EZ3: =calc!$AD$5 -> 4800 | FA3: =calc!$AD$6 -> 2794 | FB3: =FA3-EZ3 -> -2006 | FC3: =IF(FB3<0,FB3,"") -> -2006 | FD3: =IF(FB3>0,FB3,"") | FE3: =calc!$AE$5 -> 4625 | FF3: =calc!$AE$6 -> 2668 | FG3: =FF3-FE3 -> -1957 | FH3: =IF(FG3<0,FG3,"") -> -1957 | FI3: =IF(FG3>0,FG3,"") | BUC3: VAH_1 | BUD3: =SUBSTITUTE(MID(_xlfn.FORMULATEXT(BUG3),2,FIND("!",_xlfn.FORMULATEXT(BUG3),1)-2), "'","") -> #REF | BUE3: =_xlfn.SHEET(#REF!) -> #REF! | BUG3: =#REF! -> #REF! | BUH3: =Veriler!#REF! -> #REF! | BUI3: =Veriler!#REF! -> #REF! | BUJ3: =Veriler!G$7 -> 4300 | BUK3: =Veriler!H$7 -> 5100 | BUL3: =Veriler!I$7 -> 4800 | BUM3: =Veriler!J$7 -> 5200 | BUN3: =Veriler!K$7 -> 5100 | BUO3: =Veriler!L$7 -> 4100 | BUP3: =Veriler!M$7 -> 5200 | BUQ3: =Veriler!N$7 -> 5184 | ... BUS3: =Veriler!P$7 -> 4625 | BXY3: WAT_1 | BXZ3: =SUBSTITUTE(MID(_xlfn.FORMULATEXT(BYC3),2,FIND("!",_xlfn.FORMULATEXT(BYC3),1)-2), "'","") -> Statement | BYA3: =_xlfn.SHEET( Statement!$NTP$1000000) -> 5 | BYC3: =Statement!$NTP$1000000 -> 0 | BYD3: =Statement!$C$5 -> Satılan Malların Maliyeti | BYE3: =Statement!$D$5 -> -1252 | BYF3: =BYF2+BYE3 -> 3848 | BYH3: =BYF2 -> 5100 | BYI3: =BYF3 -> 3848 | BYJ3: =MAX(BYH3:BYI3) -> 5100 | CJM3: RBC_1 | CJN3: =SUBSTITUTE(MID(_xlfn.FORMULATEXT(CJQ3),2,FIND("!",_xlfn.FORMULATEXT(CJQ3),1)-2), "'","") -> calc | CJO3: =_xlfn.SHEET( calc!$NTO$999995) -> 4 | CJQ3: =calc!$NTO$999995 -> 0 | CJR3: =MAX( calc!$G$19:$G$20) -> 0.2645098 | CJS3: =calc!$G$19 -> 0.2645098 | CJU3: =0.75*CJS3/CJR3 -> 0.75 | CJV3: =1-CJU3 -> 0.25 | CJW3: =calc!$G$20 -> 0.14 | CJY3: =0.75*CJW3/CJR3 -> 0.39696071 | CJZ3: =1-CJY3 -> 0.60303929
BUC4: VAH_1 | BUD4: =SUBSTITUTE(MID(_xlfn.FORMULATEXT(BUG4),2,FIND("!",_xlfn.FORMULATEXT(BUG4),1)-2), "'","") -> #REF | BUE4: =_xlfn.SHEET(#REF!) -> #REF! | BUG4: =#REF! -> #REF! | BUH4: =Veriler!#REF! -> #REF! | BUI4: =Veriler!#REF! -> #REF! | BUJ4: =Veriler!G$15 -> 3040 | BUK4: =Veriler!H$15 -> 2974 | BUL4: =Veriler!I$15 -> 2979 | BUM4: =Veriler!J$15 -> 2993 | BUN4: =Veriler!K$15 -> 3020 | BUO4: =Veriler!L$15 -> 3087 | BUP4: =Veriler!M$15 -> 3264 | BUQ4: =Veriler!N$15 -> 2939 | ... BUS4: =Veriler!P$15 -> 2668 | BXY4: WAT_1 | BXZ4: =SUBSTITUTE(MID(_xlfn.FORMULATEXT(BYC4),2,FIND("!",_xlfn.FORMULATEXT(BYC4),1)-2), "'","") -> Statement | BYA4: =_xlfn.SHEET( Statement!$NTP$1000000) -> 5 | BYC4: =Statement!$NTP$1000000 -> 0 | BYD4: =Statement!$C$6 -> Brüt Kar | BYE4: =Statement!$D$6 -> 3848 | BYF4: =BYF3+BYE4 -> 7696 | BYH4: =BYF3 -> 3848 | BYI4: =BYF4 -> 7696 | BYJ4: =MAX(BYH4:BYI4) -> 7696
BUC5: VAH_1 | BUD5: =SUBSTITUTE(MID(_xlfn.FORMULATEXT(BUG5),2,FIND("!",_xlfn.FORMULATEXT(BUG5),1)-2), "'","") -> #REF | BUE5: =_xlfn.SHEET(#REF!) -> #REF! | BUG5: =#REF! -> #REF! | BUH5: Calculations: | BXY5: WAT_1 | BXZ5: =SUBSTITUTE(MID(_xlfn.FORMULATEXT(BYC5),2,FIND("!",_xlfn.FORMULATEXT(BYC5),1)-2), "'","") -> Statement | BYA5: =_xlfn.SHEET( Statement!$NTP$1000000) -> 5 | BYC5: =Statement!$NTP$1000000 -> 0 | BYD5: =Statement!$C$7 -> Toplam Faaliyet Giderleri | BYE5: =Statement!$D$7 -> -1722 | BYF5: =BYF4+BYE5 -> 5974 | BYH5: =BYF4 -> 7696 | BYI5: =BYF5 -> 5974 | BYJ5: =MAX(BYH5:BYI5) -> 7696
BUC6: VAH_1 | BUD6: =SUBSTITUTE(MID(_xlfn.FORMULATEXT(BUG6),2,FIND("!",_xlfn.FORMULATEXT(BUG6),1)-2), "'","") -> #REF | BUE6: =_xlfn.SHEET(#REF!) -> #REF! | BUG6: =#REF! -> #REF! | BUH6: Green | BUI6: Green | BUJ6: Green | BUK6: Green | BUL6: Green | BUM6: Green | BUN6: Green | BUO6: Green | BUP6: Green | BUQ6: Green | BUR6: Green | BUS6: Green | BXY6: WAT_1 | BXZ6: =SUBSTITUTE(MID(_xlfn.FORMULATEXT(BYC6),2,FIND("!",_xlfn.FORMULATEXT(BYC6),1)-2), "'","") -> Statement | BYA6: =_xlfn.SHEET( Statement!$NTP$1000000) -> 5 | BYC6: =Statement!$NTP$1000000 -> 0 | BYD6: =Statement!$C$8 -> Faaliyet Karı (EBIT) | BYE6: =Statement!$D$8 -> 2126 | BYF6: =BYF5+BYE6 -> 8100 | BYH6: =BYF5 -> 5974 | BYI6: =BYF6 -> 8100 | BYJ6: =MAX(BYH6:BYI6) -> 8100
BUC7: VAH_1 | BUD7: =SUBSTITUTE(MID(_xlfn.FORMULATEXT(BUG7),2,FIND("!",_xlfn.FORMULATEXT(BUG7),1)-2), "'","") -> #REF | BUE7: =_xlfn.SHEET(#REF!) -> #REF! | BUG7: =#REF! -> #REF! | BUH7: =CONCATENATE(BUH6," ",BUH8) -> Green 1 | BUI7: =CONCATENATE(BUI6," ",BUI8) -> Green 2 | BUJ7: =CONCATENATE(BUJ6," ",BUJ8) -> Green 3 | BUK7: =CONCATENATE(BUK6," ",BUK8) -> Green 4 | BUL7: =CONCATENATE(BUL6," ",BUL8) -> Green 5 | BUM7: =CONCATENATE(BUM6," ",BUM8) -> Green 6 | BUN7: =CONCATENATE(BUN6," ",BUN8) -> Green 7 | BUO7: =CONCATENATE(BUO6," ",BUO8) -> Green 8 | ... BUS7: =CONCATENATE(BUS6," ",BUS8) -> Green 12 | BXY7: WAT_1 | BXZ7: =SUBSTITUTE(MID(_xlfn.FORMULATEXT(BYC7),2,FIND("!",_xlfn.FORMULATEXT(BYC7),1)-2), "'","") -> Statement | BYA7: =_xlfn.SHEET( Statement!$NTP$1000000) -> 5 | BYC7: =Statement!$NTP$1000000 -> 0 | BYD7: =Statement!$C$9 -> Vergiler | BYE7: =Statement!$D$9 -> -777 | BYF7: =BYF6+BYE7 -> 7323 | BYH7: =BYF6 -> 8100 | BYI7: =BYF7 -> 7323 | BYJ7: =MAX(BYH7:BYI7) -> 8100
BUC8: VAH_1 | BUD8: =SUBSTITUTE(MID(_xlfn.FORMULATEXT(BUG8),2,FIND("!",_xlfn.FORMULATEXT(BUG8),1)-2), "'","") -> #REF | BUE8: =_xlfn.SHEET(#REF!) -> #REF! | BUG8: =#REF! -> #REF! | BUH8: 1 | BUI8: =BUH8+1 -> 2 | BUJ8: =BUI8+1 -> 3 | BUK8: =BUJ8+1 -> 4 | BUL8: =BUK8+1 -> 5 | BUM8: =BUL8+1 -> 6 | BUN8: =BUM8+1 -> 7 | BUO8: =BUN8+1 -> 8 | BUP8: =BUO8+1 -> 9 | ... BUS8: =BUR8+1 -> 12 | BXY8: WAT_1 | BXZ8: =SUBSTITUTE(MID(_xlfn.FORMULATEXT(BYC8),2,FIND("!",_xlfn.FORMULATEXT(BYC8),1)-2), "'","") -> Statement | BYA8: =_xlfn.SHEET( Statement!$NTP$1000000) -> 5 | BYC8: =Statement!$NTP$1000000 -> 0 | BYD8: =Statement!$C$10 -> Net Kâr | BYG8: =BYF7 -> 7323
BUC9: VAH_1 | BUD9: =SUBSTITUTE(MID(_xlfn.FORMULATEXT(BUG9),2,FIND("!",_xlfn.FORMULATEXT(BUG9),1)-2), "'","") -> #REF | BUE9: =_xlfn.SHEET(#REF!) -> #REF! | BUG9: =#REF! -> #REF! | BUH9: =BUH8 -> 1 | BUI9: =BUI8 -> 2 | BUJ9: =BUJ8 -> 3 | BUK9: =BUK8 -> 4 | BUL9: =BUL8 -> 5 | BUM9: =BUM8 -> 6 | BUN9: =BUN8 -> 7 | BUO9: =BUO8 -> 8 | ... BUS9: =BUS8 -> 12
BUC10: VAH_1 | BUD10: =SUBSTITUTE(MID(_xlfn.FORMULATEXT(BUG10),2,FIND("!",_xlfn.FORMULATEXT(BUG10),1)-2), "'","") -> #REF | BUE10: =_xlfn.SHEET(#REF!) -> #REF! | BUG10: =#REF! -> #REF! | BUH10: =IF(BUH4>BUH3,BUH3,0) -> #REF! | BUI10: =IF(BUI4>BUI3,BUI3,0) -> #REF! | BUJ10: =IF(BUJ4>BUJ3,BUJ3,0) -> 0 | BUK10: =IF(BUK4>BUK3,BUK3,0) -> 0 | BUL10: =IF(BUL4>BUL3,BUL3,0) -> 0 | BUM10: =IF(BUM4>BUM3,BUM3,0) -> 0 | BUN10: =IF(BUN4>BUN3,BUN3,0) -> 0 | BUO10: =IF(BUO4>BUO3,BUO3,0) -> 0 | ... BUS10: =IF(BUS4>BUS3,BUS3,0) -> 0
BUC11: VAH_1 | BUD11: =SUBSTITUTE(MID(_xlfn.FORMULATEXT(BUG11),2,FIND("!",_xlfn.FORMULATEXT(BUG11),1)-2), "'","") -> #REF | BUE11: =_xlfn.SHEET(#REF!) -> #REF! | BUG11: =#REF! -> #REF! | BUH11: =IF(BUH4>BUH3,BUH4,0) -> #REF! | BUI11: =IF(BUI4>BUI3,BUI4,0) -> #REF! | BUJ11: =IF(BUJ4>BUJ3,BUJ4,0) -> 0 | BUK11: =IF(BUK4>BUK3,BUK4,0) -> 0 | BUL11: =IF(BUL4>BUL3,BUL4,0) -> 0 | BUM11: =IF(BUM4>BUM3,BUM4,0) -> 0 | BUN11: =IF(BUN4>BUN3,BUN4,0) -> 0 | BUO11: =IF(BUO4>BUO3,BUO4,0) -> 0 | ... BUS11: =IF(BUS4>BUS3,BUS4,0) -> 0
BUC12: VAH_1 | BUD12: =SUBSTITUTE(MID(_xlfn.FORMULATEXT(BUG12),2,FIND("!",_xlfn.FORMULATEXT(BUG12),1)-2), "'","") -> #REF | BUE12: =_xlfn.SHEET(#REF!) -> #REF! | BUG12: =#REF! -> #REF! | BUH12: Red | BUI12: Red | BUJ12: Red | BUK12: Red | BUL12: Red | BUM12: Red | BUN12: Red | BUO12: Red | BUP12: Red | BUQ12: Red | BUR12: Red | BUS12: Red
BUC13: VAH_1 | BUD13: =SUBSTITUTE(MID(_xlfn.FORMULATEXT(BUG13),2,FIND("!",_xlfn.FORMULATEXT(BUG13),1)-2), "'","") -> #REF | BUE13: =_xlfn.SHEET(#REF!) -> #REF! | BUG13: =#REF! -> #REF! | BUH13: =CONCATENATE(BUH12," ",BUH14) -> Red 1 | BUI13: =CONCATENATE(BUI12," ",BUI14) -> Red 2 | BUJ13: =CONCATENATE(BUJ12," ",BUJ14) -> Red 3 | BUK13: =CONCATENATE(BUK12," ",BUK14) -> Red 4 | BUL13: =CONCATENATE(BUL12," ",BUL14) -> Red 5 | BUM13: =CONCATENATE(BUM12," ",BUM14) -> Red 6 | BUN13: =CONCATENATE(BUN12," ",BUN14) -> Red 7 | BUO13: =CONCATENATE(BUO12," ",BUO14) -> Red 8 | ... BUS13: =CONCATENATE(BUS12," ",BUS14) -> Red 12
BUC14: VAH_1 | BUD14: =SUBSTITUTE(MID(_xlfn.FORMULATEXT(BUG14),2,FIND("!",_xlfn.FORMULATEXT(BUG14),1)-2), "'","") -> #REF | BUE14: =_xlfn.SHEET(#REF!) -> #REF! | BUG14: =#REF! -> #REF! | BUH14: =BUH8 -> 1 | BUI14: =BUI8 -> 2 | BUJ14: =BUJ8 -> 3 | BUK14: =BUK8 -> 4 | BUL14: =BUL8 -> 5 | BUM14: =BUM8 -> 6 | BUN14: =BUN8 -> 7 | BUO14: =BUO8 -> 8 | ... BUS14: =BUS8 -> 12
BUC15: VAH_1 | BUD15: =SUBSTITUTE(MID(_xlfn.FORMULATEXT(BUG15),2,FIND("!",_xlfn.FORMULATEXT(BUG15),1)-2), "'","") -> #REF | BUE15: =_xlfn.SHEET(#REF!) -> #REF! | BUG15: =#REF! -> #REF! | BUH15: =BUH8 -> 1 | BUI15: =BUI8 -> 2 | BUJ15: =BUJ8 -> 3 | BUK15: =BUK8 -> 4 | BUL15: =BUL8 -> 5 | BUM15: =BUM8 -> 6 | BUN15: =BUN8 -> 7 | BUO15: =BUO8 -> 8 | ... BUS15: =BUS8 -> 12
BUC16: VAH_1 | BUD16: =SUBSTITUTE(MID(_xlfn.FORMULATEXT(BUG16),2,FIND("!",_xlfn.FORMULATEXT(BUG16),1)-2), "'","") -> #REF | BUE16: =_xlfn.SHEET(#REF!) -> #REF! | BUG16: =#REF! -> #REF! | BUH16: =IF(BUH3>BUH4,BUH3,0) -> #REF! | BUI16: =IF(BUI3>BUI4,BUI3,0) -> #REF! | BUJ16: =IF(BUJ3>BUJ4,BUJ3,0) -> 4300 | BUK16: =IF(BUK3>BUK4,BUK3,0) -> 5100 | BUL16: =IF(BUL3>BUL4,BUL3,0) -> 4800 | BUM16: =IF(BUM3>BUM4,BUM3,0) -> 5200 | BUN16: =IF(BUN3>BUN4,BUN3,0) -> 5100 | BUO16: =IF(BUO3>BUO4,BUO3,0) -> 4100 | ... BUS16: =IF(BUS3>BUS4,BUS3,0) -> 4625
BUC17: VAH_1 | BUD17: =SUBSTITUTE(MID(_xlfn.FORMULATEXT(BUG17),2,FIND("!",_xlfn.FORMULATEXT(BUG17),1)-2), "'","") -> #REF | BUE17: =_xlfn.SHEET(#REF!) -> #REF! | BUG17: =#REF! -> #REF! | BUH17: =IF(BUH3>BUH4,BUH4,0) -> #REF! | BUI17: =IF(BUI3>BUI4,BUI4,0) -> #REF! | BUJ17: =IF(BUJ3>BUJ4,BUJ4,0) -> 3040 | BUK17: =IF(BUK3>BUK4,BUK4,0) -> 2974 | BUL17: =IF(BUL3>BUL4,BUL4,0) -> 2979 | BUM17: =IF(BUM3>BUM4,BUM4,0) -> 2993 | BUN17: =IF(BUN3>BUN4,BUN4,0) -> 3020 | BUO17: =IF(BUO3>BUO4,BUO4,0) -> 3087 | ... BUS17: =IF(BUS3>BUS4,BUS4,0) -> 2668
BUC18: VAH_1 | BUD18: =SUBSTITUTE(MID(_xlfn.FORMULATEXT(BUG18),2,FIND("!",_xlfn.FORMULATEXT(BUG18),1)-2), "'","") -> #REF | BUE18: =_xlfn.SHEET(#REF!) -> #REF! | BUG18: =#REF! -> #REF! | BUH18: Actual | BUI18: Actual | BUJ18: Actual | BUK18: Actual | BUL18: Actual | BUM18: Actual | BUN18: Actual | BUO18: Actual | BUP18: Actual | BUQ18: Actual | BUR18: Actual | BUS18: Actual
BUC19: VAH_1 | BUD19: =SUBSTITUTE(MID(_xlfn.FORMULATEXT(BUG19),2,FIND("!",_xlfn.FORMULATEXT(BUG19),1)-2), "'","") -> #REF | BUE19: =_xlfn.SHEET(#REF!) -> #REF! | BUG19: =#REF! -> #REF! | BUH19: =CONCATENATE(BUH18," ",BUH8) -> Actual 1 | BUI19: =CONCATENATE(BUI18," ",BUI8) -> Actual 2 | BUJ19: =CONCATENATE(BUJ18," ",BUJ8) -> Actual 3 | BUK19: =CONCATENATE(BUK18," ",BUK8) -> Actual 4 | BUL19: =CONCATENATE(BUL18," ",BUL8) -> Actual 5 | BUM19: =CONCATENATE(BUM18," ",BUM8) -> Actual 6 | BUN19: =CONCATENATE(BUN18," ",BUN8) -> Actual 7 | BUO19: =CONCATENATE(BUO18," ",BUO8) -> Actual 8 | ... BUS19: =CONCATENATE(BUS18," ",BUS8) -> Actual 12
BUC20: VAH_1 | BUD20: =SUBSTITUTE(MID(_xlfn.FORMULATEXT(BUG20),2,FIND("!",_xlfn.FORMULATEXT(BUG20),1)-2), "'","") -> #REF | BUE20: =_xlfn.SHEET(#REF!) -> #REF! | BUG20: =#REF! -> #REF! | BUH20: =BUH8-0.25 -> 0.75 | BUI20: =BUI8-0.25 -> 1.75 | BUJ20: =BUJ8-0.25 -> 2.75 | BUK20: =BUK8-0.25 -> 3.75 | BUL20: =BUL8-0.25 -> 4.75 | BUM20: =BUM8-0.25 -> 5.75 | BUN20: =BUN8-0.25 -> 6.75 | BUO20: =BUO8-0.25 -> 7.75 | ... BUS20: =BUS8-0.25 -> 11.75
BUC21: VAH_1 | BUD21: =SUBSTITUTE(MID(_xlfn.FORMULATEXT(BUG21),2,FIND("!",_xlfn.FORMULATEXT(BUG21),1)-2), "'","") -> #REF | BUE21: =_xlfn.SHEET(#REF!) -> #REF! | BUG21: =#REF! -> #REF! | BUH21: =BUH8-0.25 -> 0.75 | BUI21: =BUI8-0.25 -> 1.75 | BUJ21: =BUJ8-0.25 -> 2.75 | BUK21: =BUK8-0.25 -> 3.75 | BUL21: =BUL8-0.25 -> 4.75 | BUM21: =BUM8-0.25 -> 5.75 | BUN21: =BUN8-0.25 -> 6.75 | BUO21: =BUO8-0.25 -> 7.75 | ... BUS21: =BUS8-0.25 -> 11.75
BUC22: VAH_1 | BUD22: =SUBSTITUTE(MID(_xlfn.FORMULATEXT(BUG22),2,FIND("!",_xlfn.FORMULATEXT(BUG22),1)-2), "'","") -> #REF | BUE22: =_xlfn.SHEET(#REF!) -> #REF! | BUG22: =#REF! -> #REF! | BUH22: 0 | BUI22: 0 | BUJ22: 0 | BUK22: 0 | BUL22: 0 | BUM22: 0 | BUN22: 0 | BUO22: 0 | BUP22: 0 | BUQ22: 0 | BUR22: 0 | BUS22: 0
BUC23: VAH_1 | BUD23: =SUBSTITUTE(MID(_xlfn.FORMULATEXT(BUG23),2,FIND("!",_xlfn.FORMULATEXT(BUG23),1)-2), "'","") -> #REF | BUE23: =_xlfn.SHEET(#REF!) -> #REF! | BUG23: =#REF! -> #REF! | BUH23: =IF(BUH4=0,"",BUH4) -> #REF! | BUI23: =IF(BUI4=0,"",BUI4) -> #REF! | BUJ23: =IF(BUJ4=0,"",BUJ4) -> 3040 | BUK23: =IF(BUK4=0,"",BUK4) -> 2974 | BUL23: =IF(BUL4=0,"",BUL4) -> 2979 | BUM23: =IF(BUM4=0,"",BUM4) -> 2993 | BUN23: =IF(BUN4=0,"",BUN4) -> 3020 | BUO23: =IF(BUO4=0,"",BUO4) -> 3087 | ... BUS23: =IF(BUS4=0,"",BUS4) -> 2668
BUC24: VAH_1 | BUD24: =SUBSTITUTE(MID(_xlfn.FORMULATEXT(BUG24),2,FIND("!",_xlfn.FORMULATEXT(BUG24),1)-2), "'","") -> #REF | BUE24: =_xlfn.SHEET(#REF!) -> #REF! | BUG24: =#REF! -> #REF! | BUH24: Zero Line | BUI24: Zero Line | BUJ24: Zero Line | BUK24: Zero Line | BUL24: Zero Line | BUM24: Zero Line | BUN24: Zero Line | BUO24: Zero Line | BUP24: Zero Line | BUQ24: Zero Line | BUR24: Zero Line | BUS24: Zero Line
BUC25: VAH_1 | BUD25: =SUBSTITUTE(MID(_xlfn.FORMULATEXT(BUG25),2,FIND("!",_xlfn.FORMULATEXT(BUG25),1)-2), "'","") -> #REF | BUE25: =_xlfn.SHEET(#REF!) -> #REF! | BUG25: =#REF! -> #REF! | BUH25: =BUH8-0.23 -> 0.77 | BUI25: =BUI8+0.22 -> 2.22 | BUJ25: =BUJ8+0.22 -> 3.22 | BUK25: =BUK8+0.22 -> 4.22 | BUL25: =BUL8+0.22 -> 5.22 | BUM25: =BUM8+0.22 -> 6.22 | BUN25: =BUN8+0.22 -> 7.22 | BUO25: =BUO8+0.22 -> 8.22 | BUP25: =BUP8+0.22 -> 9.22 | ... BUS25: =BUS8+0.22 -> 12.22
BUC26: VAH_1 | BUD26: =SUBSTITUTE(MID(_xlfn.FORMULATEXT(BUG26),2,FIND("!",_xlfn.FORMULATEXT(BUG26),1)-2), "'","") -> #REF | BUE26: =_xlfn.SHEET(#REF!) -> #REF! | BUG26: =#REF! -> #REF! | BUH26: 0 | BUI26: 0 | BUJ26: 0 | BUK26: 0 | BUL26: 0 | BUM26: 0 | BUN26: 0 | BUO26: 0 | BUP26: 0 | BUQ26: 0 | BUR26: 0 | BUS26: 0
BUC27: VAH_1 | BUD27: =SUBSTITUTE(MID(_xlfn.FORMULATEXT(BUG27),2,FIND("!",_xlfn.FORMULATEXT(BUG27),1)-2), "'","") -> #REF | BUE27: =_xlfn.SHEET(#REF!) -> #REF! | BUG27: =#REF! -> #REF! | BUH27: Var | BUI27: Var | BUJ27: Var | BUK27: Var | BUL27: Var | BUM27: Var | BUN27: Var | BUO27: Var | BUP27: Var | BUQ27: Var | BUR27: Var | BUS27: Var
BUC28: VAH_1 | BUD28: =SUBSTITUTE(MID(_xlfn.FORMULATEXT(BUG28),2,FIND("!",_xlfn.FORMULATEXT(BUG28),1)-2), "'","") -> #REF | BUE28: =_xlfn.SHEET(#REF!) -> #REF! | BUG28: =#REF! -> #REF! | BUH28: =CONCATENATE(BUH27," ",BUH29) -> Var 1 | BUI28: =CONCATENATE(BUI27," ",BUI29) -> Var 2 | BUJ28: =CONCATENATE(BUJ27," ",BUJ29) -> Var 3 | BUK28: =CONCATENATE(BUK27," ",BUK29) -> Var 4 | BUL28: =CONCATENATE(BUL27," ",BUL29) -> Var 5 | BUM28: =CONCATENATE(BUM27," ",BUM29) -> Var 6 | BUN28: =CONCATENATE(BUN27," ",BUN29) -> Var 7 | BUO28: =CONCATENATE(BUO27," ",BUO29) -> Var 8 | ... BUS28: =CONCATENATE(BUS27," ",BUS29) -> Var 12
BUC29: VAH_1 | BUD29: =SUBSTITUTE(MID(_xlfn.FORMULATEXT(BUG29),2,FIND("!",_xlfn.FORMULATEXT(BUG29),1)-2), "'","") -> #REF | BUE29: =_xlfn.SHEET(#REF!) -> #REF! | BUG29: =#REF! -> #REF! | BUH29: =BUH8 -> 1 | BUI29: =BUI8 -> 2 | BUJ29: =BUJ8 -> 3 | BUK29: =BUK8 -> 4 | BUL29: =BUL8 -> 5 | BUM29: =BUM8 -> 6 | BUN29: =BUN8 -> 7 | BUO29: =BUO8 -> 8 | ... BUS29: =BUS8 -> 12
BUC30: VAH_1 | BUD30: =SUBSTITUTE(MID(_xlfn.FORMULATEXT(BUG30),2,FIND("!",_xlfn.FORMULATEXT(BUG30),1)-2), "'","") -> #REF | BUE30: =_xlfn.SHEET(#REF!) -> #REF! | BUG30: =#REF! -> #REF! | BUH30: =MAX(BUH3:BUH4) -> #REF! | BUI30: =MAX(BUI3:BUI4) -> #REF! | BUJ30: =MAX(BUJ3:BUJ4) -> 4300 | BUK30: =MAX(BUK3:BUK4) -> 5100 | BUL30: =MAX(BUL3:BUL4) -> 4800 | BUM30: =MAX(BUM3:BUM4) -> 5200 | BUN30: =MAX(BUN3:BUN4) -> 5100 | BUO30: =MAX(BUO3:BUO4) -> 4100 | ... BUS30: =MAX(BUS3:BUS4) -> 4625
BUC31: VAH_1 | BUD31: =SUBSTITUTE(MID(_xlfn.FORMULATEXT(BUG31),2,FIND("!",_xlfn.FORMULATEXT(BUG31),1)-2), "'","") -> #REF | BUE31: =_xlfn.SHEET(#REF!) -> #REF! | BUG31: =#REF! -> #REF! | BUH31: =IF(BUH4-BUH3=0,"",BUH4-BUH3) -> #REF! | BUI31: =IF(BUI4-BUI3=0,"",BUI4-BUI3) -> #REF! | BUJ31: =IF(BUJ4-BUJ3=0,"",BUJ4-BUJ3) -> -1260 | BUK31: =IF(BUK4-BUK3=0,"",BUK4-BUK3) -> -2126 | BUL31: =IF(BUL4-BUL3=0,"",BUL4-BUL3) -> -1821 | BUM31: =IF(BUM4-BUM3=0,"",BUM4-BUM3) -> -2207 | BUN31: =IF(BUN4-BUN3=0,"",BUN4-BUN3) -> -2080 | BUO31: =IF(BUO4-BUO3=0,"",BUO4-BUO3) -> -1013 | ... BUS31: =IF(BUS4-BUS3=0,"",BUS4-BUS3) -> -1957
BUC32: VAH_2 | BUD32: =SUBSTITUTE(MID(_xlfn.FORMULATEXT(BUG32),2,FIND("!",_xlfn.FORMULATEXT(BUG32),1)-2), "'","") -> #REF | BUE32: =_xlfn.SHEET(#REF!) -> #REF! | BUG32: =#REF! -> #REF!
BUC33: VAH_2 | BUD33: =SUBSTITUTE(MID(_xlfn.FORMULATEXT(BUG33),2,FIND("!",_xlfn.FORMULATEXT(BUG33),1)-2), "'","") -> #REF | BUE33: =_xlfn.SHEET(#REF!) -> #REF! | BUG33: =#REF! -> #REF! | BUH33: =Veriler!#REF! -> #REF! | BUI33: =Veriler!#REF! -> #REF! | BUJ33: =Veriler!G$7 -> 4300 | BUK33: =Veriler!H$7 -> 5100 | BUL33: =Veriler!I$7 -> 4800 | BUM33: =Veriler!J$7 -> 5200 | BUN33: =Veriler!K$7 -> 5100 | BUO33: =Veriler!L$7 -> 4100 | BUP33: =Veriler!M$7 -> 5200 | BUQ33: =Veriler!N$7 -> 5184 | ... BUS33: =Veriler!P$7 -> 4625
BUC34: VAH_2 | BUD34: =SUBSTITUTE(MID(_xlfn.FORMULATEXT(BUG34),2,FIND("!",_xlfn.FORMULATEXT(BUG34),1)-2), "'","") -> #REF | BUE34: =_xlfn.SHEET(#REF!) -> #REF! | BUG34: =#REF! -> #REF! | BUH34: =Veriler!#REF! -> #REF! | BUI34: =Veriler!#REF! -> #REF! | BUJ34: =Veriler!G$15 -> 3040 | BUK34: =Veriler!H$15 -> 2974 | BUL34: =Veriler!I$15 -> 2979 | BUM34: =Veriler!J$15 -> 2993 | BUN34: =Veriler!K$15 -> 3020 | BUO34: =Veriler!L$15 -> 3087 | BUP34: =Veriler!M$15 -> 3264 | BUQ34: =Veriler!N$15 -> 2939 | ... BUS34: =Veriler!P$15 -> 2668
BUC35: VAH_2 | BUD35: =SUBSTITUTE(MID(_xlfn.FORMULATEXT(BUG35),2,FIND("!",_xlfn.FORMULATEXT(BUG35),1)-2), "'","") -> #REF | BUE35: =_xlfn.SHEET(#REF!) -> #REF! | BUG35: =#REF! -> #REF! | BUH35: Calculations:
BUC36: VAH_2 | BUD36: =SUBSTITUTE(MID(_xlfn.FORMULATEXT(BUG36),2,FIND("!",_xlfn.FORMULATEXT(BUG36),1)-2), "'","") -> #REF | BUE36: =_xlfn.SHEET(#REF!) -> #REF! | BUG36: =#REF! -> #REF! | BUH36: Green | BUI36: Green | BUJ36: Green | BUK36: Green | BUL36: Green | BUM36: Green | BUN36: Green | BUO36: Green | BUP36: Green | BUQ36: Green | BUR36: Green | BUS36: Green
BUC37: VAH_2 | BUD37: =SUBSTITUTE(MID(_xlfn.FORMULATEXT(BUG37),2,FIND("!",_xlfn.FORMULATEXT(BUG37),1)-2), "'","") -> #REF | BUE37: =_xlfn.SHEET(#REF!) -> #REF! | BUG37: =#REF! -> #REF! | BUH37: =CONCATENATE(BUH36," ",BUH38) -> Green 1 | BUI37: =CONCATENATE(BUI36," ",BUI38) -> Green 2 | BUJ37: =CONCATENATE(BUJ36," ",BUJ38) -> Green 3 | BUK37: =CONCATENATE(BUK36," ",BUK38) -> Green 4 | BUL37: =CONCATENATE(BUL36," ",BUL38) -> Green 5 | BUM37: =CONCATENATE(BUM36," ",BUM38) -> Green 6 | BUN37: =CONCATENATE(BUN36," ",BUN38) -> Green 7 | BUO37: =CONCATENATE(BUO36," ",BUO38) -> Green 8 | ... BUS37: =CONCATENATE(BUS36," ",BUS38) -> Green 12
BUC38: VAH_2 | BUD38: =SUBSTITUTE(MID(_xlfn.FORMULATEXT(BUG38),2,FIND("!",_xlfn.FORMULATEXT(BUG38),1)-2), "'","") -> #REF | BUE38: =_xlfn.SHEET(#REF!) -> #REF! | BUG38: =#REF! -> #REF! | BUH38: 1 | BUI38: =BUH38+1 -> 2 | BUJ38: =BUI38+1 -> 3 | BUK38: =BUJ38+1 -> 4 | BUL38: =BUK38+1 -> 5 | BUM38: =BUL38+1 -> 6 | BUN38: =BUM38+1 -> 7 | BUO38: =BUN38+1 -> 8 | BUP38: =BUO38+1 -> 9 | ... BUS38: =BUR38+1 -> 12
BUC39: VAH_2 | BUD39: =SUBSTITUTE(MID(_xlfn.FORMULATEXT(BUG39),2,FIND("!",_xlfn.FORMULATEXT(BUG39),1)-2), "'","") -> #REF | BUE39: =_xlfn.SHEET(#REF!) -> #REF! | BUG39: =#REF! -> #REF! | BUH39: =BUH38 -> 1 | BUI39: =BUI38 -> 2 | BUJ39: =BUJ38 -> 3 | BUK39: =BUK38 -> 4 | BUL39: =BUL38 -> 5 | BUM39: =BUM38 -> 6 | BUN39: =BUN38 -> 7 | BUO39: =BUO38 -> 8 | ... BUS39: =BUS38 -> 12
BUC40: VAH_2 | BUD40: =SUBSTITUTE(MID(_xlfn.FORMULATEXT(BUG40),2,FIND("!",_xlfn.FORMULATEXT(BUG40),1)-2), "'","") -> #REF | BUE40: =_xlfn.SHEET(#REF!) -> #REF! | BUG40: =#REF! -> #REF! | BUH40: =IF(BUH34>BUH33,BUH33,0) -> #REF! | BUI40: =IF(BUI34>BUI33,BUI33,0) -> #REF! | BUJ40: =IF(BUJ34>BUJ33,BUJ33,0) -> 0 | BUK40: =IF(BUK34>BUK33,BUK33,0) -> 0 | BUL40: =IF(BUL34>BUL33,BUL33,0) -> 0 | BUM40: =IF(BUM34>BUM33,BUM33,0) -> 0 | BUN40: =IF(BUN34>BUN33,BUN33,0) -> 0 | BUO40: =IF(BUO34>BUO33,BUO33,0) -> 0 | ... BUS40: =IF(BUS34>BUS33,BUS33,0) -> 0
...
