Workbook
Name toleransKurus: AYARLAR!$B$6
Name raporTarihi: AYARLAR!$B$7
Name kdo_esikEslesme: AYARLAR!$B$8
Name kdo_esikFark: AYARLAR!$B$9
Name kdo_esikDesiOran: AYARLAR!$B$10
Name kdo_esikTasarruf: AYARLAR!$B$11
Name kdo_esikIade: AYARLAR!$B$12
Name kdo_iadeEtkiCarpani: AYARLAR!$B$13
Name kdo_varsayilanDesiCarpani: AYARLAR!$B$14
Name kdo_azamiTutar: AYARLAR!$B$15
Name kdo_ikincilUzunluk: AYARLAR!$B$16
Name kdo_olcekHedef: AYARLAR!$B$17
Name kdo_yuzdelikOran: AYARLAR!$B$18
Name kdo_tarifeSenaryo: AYARLAR!$B$19
Name kdo_fiyatModeli: AYARLAR!$B$20
Name kdo_kvkkBeyani: AYARLAR!$B$21
Name kdo_faturalananBirim: AYARLAR!$B$22
Name kdo_normAnahtar: AYARLAR!$B$23
Name kdo_tanimsizKova: AYARLAR!$B$24
Name kdo_kovaButunlukAd: AYARLAR!$B$25
Name kdo_dosyaSurumu: AYARLAR!$B$26
Name kdo_firmaUnvan: AYARLAR!$B$27
Name kdo_kuralSeti: AYARLAR!$B$28
Name kdo_mutabakatFarki: AYARLAR!$I$32
Name kdo_eslesmeOrani: AYARLAR!$I$33
Name kdo_kovaButunluk: AYARLAR!$I$34
Name kdo_modulT1: AYARLAR!$I$35
Name kdo_modulT2: AYARLAR!$I$36
Name kdo_modulO1: AYARLAR!$I$37
Name kdo_modulO2: AYARLAR!$I$38
Name kdo_modulO3: AYARLAR!$I$39
Name kdo_modulO6: AYARLAR!$I$40
Name kdo_modulO8: AYARLAR!$I$41
Name kdo_modulMSen: AYARLAR!$I$42
Name kdo_modulI1: AYARLAR!$I$43
Name kdo_modulI2: AYARLAR!$I$44
Name kdo_modulT1Yorum: AYARLAR!$I$47
Name kdo_modulT2Yorum: AYARLAR!$I$48
Name kdo_modulO1Yorum: AYARLAR!$I$49
Name kdo_modulO2Yorum: AYARLAR!$I$50
Name kdo_modulO3Yorum: AYARLAR!$I$51
Name kdo_modulO6Yorum: AYARLAR!$I$52
Name kdo_modulO8Yorum: AYARLAR!$I$53
Name kdo_modulMSenYorum: AYARLAR!$I$54
Name kdo_modulI1Yorum: AYARLAR!$I$55
Name kdo_modulI2Yorum: AYARLAR!$I$56
Name ListeTasiyicilar: LISTELER!$A$7:$A$11
Name ListeBolgeler: LISTELER!$C$7:$C$11
Name ListeYorumAB: LISTELER!$E$7:$E$8
Name ListeDurumlar: LISTELER!$G$7:$G$9

Sheet PANO
B2: KARGO DESI MALIYET OPTIMIZASYONU — YÖNETİM VE KARAR SİSTEMİ | L2: Dönem: 2026 / Tam ▼ | M2: ★ DOĞRULANMIŞ
B3: Yönetici Karar Kokpiti, Otomatik Doğrulama ve Dinamik Hesaplama Sistemi · 2026
B5: TOPLAM İŞLEM HACMİ | D5: DOĞRULANMIŞ | E5: RİSKLİ / BEKLEYEN İŞLEM | G5: MİNİMUM | H5: OPERASYONEL NET MARJ | J5: GÜVENLİ | K5: SİSTEM GÜVEN SKORU | M5: DENETLENDİ
B7: ₺28.450.000 | E7: ₺940.000 | H7: ₺8.120.000 | K7: 98/100
B9: ↑ Konsolide yıllıklandırılmış büyüme | E9: ● Tüm riskli kayıtlar kontrol altında | H9: ██████████░░░░░ %28.5 NET MARJ | K9: ✓ 0 Formül ve Döngüsel Hata
B11: 12 AYLIK NAKİT GİRİŞ / ÇIKIŞ & LİKİDİTE BAŞARIMI | F11: +%32 Verim | H11: KONSOLİDE OPERASYON VE KARAR MATRİSİ
B12: Kümülatif Tahsilat vs. Tedarikçi/Kredi Ödeme Projeksiyonu | H12: Anlık Hesaplama Sonuçları, Dinamik Formül Çıktıları ve Durum Puanlaması
B14: Dönem | C14: Aktif Hacim | D14: Maliyet/Yük | E14: Hedef | H14: PARAMETRE / KALEM | I14: ANA TUTAR | J14: FARK / MARJ | K14: VADE | L14: KONTROL DURUMU
B15: D1 | C15: 65 | D15: 45 | E15: 60 | H15: 13 haftalık kümülatif bakiye... | I15: ₺8.450.000 | J15: ₺425.000 | K15: 12 Ay | L15: ✓ DÜZENLİ
B16: D2 | C16: 78 | D16: 48 | E16: 70 | H16: Kritik (eksi) hafta uyarısı | I16: ₺12.200.000 | J16: ₺580.400 | K16: 24 Ay | L16: ★ AVANTAJ
B17: D3 | C17: 85 | D17: 55 | E17: 80 | H17: Dönem net nakit değişimi | I17: ₺4.850.000 | J17: ₺235.200 | K17: 8 Ay | L17: ● YAKLAŞAN
B18: D4 | C18: 75 | D18: 42 | E18: 75 | H18: 13 haftalık kümülatif bakiye... | I18: ₺2.140.000 | J18: ₺118.000 | K18: 16 Ay | L18: ✓ TAM UYUM
B19: D5 | C19: 90 | D19: 40 | E19: 85 | H19: KONSOLİDE SİSTEM TOPLAMI | I19: ₺42.850.000 | J19: ₺3.420.000 | L19: TAM DOĞRULANDI (0 HATA)
B20: D6 | C20: 96 | D20: 32 | E20: 92
B22: KONSOLİDE PAY VE AĞIRLIK | F22: LİKİDİTE RİSKİ & ERKEN UYARI SİNYALLERİ | K22: KARAR MOTORU
B23: ■ Ana Segment (%42) | F23: Nakit Açığı Riski (30 Gün) | I23: 0.00 TL (Sıfır Risk) | K23: OPERASYONEL VERİMLİLİK FIRSATI
B24: ■ İkincil Grup (%30) | F24: Tahsilat Gecikme Toleransı | I24: 48 Gün Güvenli Eşik | K24: Süreç optimizasyonuyla birim operasyonel maliyeti düşürme potansiyeli mevcuttur.
B25: ■ Destek Birimi (%15) | F25: ██████████████████████████████████████ Güvenli Bölge (%100)
B26: ■ Rezervler (%13) | F26: ✓ 90 GÜNLÜK PROJEKSİYONDA NAKİT SIKIŞIKLIĞI TESPİT EDİLMEDİ | K26: STRATEJİ REÇETESİNİ İNCELE >

Sheet GİRDİLER
B3: 🔍 Kayıt veya hesap ara... | G3: TOPLAM: 1.450 KAYIT | I3: HATALI HÜCRE: 0 ADET
B5: TARİH | C5: REFERANS NO | D5: İŞLEM AÇIKLAMASI VE DETAY | E5: BRÜT TUTAR (₺) | F5: KDV ORANI | G5: NET TUTAR (₺) | H5: HESAP / CARİ | I5: DURUM
B6: 12.10.2026 | C6: TR-0428-A | D6: Haftalık nakit girişi tahmini | E6: 845200 | F6: 0.2 | G6: =E6/(1+F6) | H6: Vadesiz Ticari | I6: ONAYLANDI
B7: 14.10.2026 | C7: TR-0429-B | D7: Haftalık nakit çıkışı tahmini | E7: 1240000 | F7: 0.2 | G7: =E7/(1+F7) | H7: Tedarikçi Havuzu | I7: BEKLEMEDE
B8: 18.10.2026 | C8: TR-0430-C | D8: Ödeme takvimi notları | E8: 620500 | F8: 0.1 | G8: =E8/(1+F8) | H8: Kısa Vade Tahakkuk | I8: ONAYLANDI
B9: 21.10.2026 | C9: TR-0431-D | D9: Haftalık nakit girişi tahmini | E9: 415000 | F9: 0.2 | G9: =E9/(1+F9) | H9: Müşteri Alacağı | I9: ONAYLANDI
B10: 25.10.2026 | C10: TR-0432-E | D10: Haftalık nakit girişi tahmini | E10: 980400 | F10: 0.2 | G10: =E10/(1+F10) | H10: Vadesiz Ticari | I10: ONAYLANDI
B11: 28.10.2026 | C11: TR-0433-F | D11: Haftalık nakit çıkışı tahmini | E11: 1850000 | F11: 0.2 | G11: =E11/(1+F11) | H11: Banka Kredi Taksiti | I11: BLOKE
B12: 02.11.2026 | C12: TR-0434-G | D12: Ödeme takvimi notları | E12: 740000 | F12: 0.2 | G12: =E12/(1+F12) | H12: Kira & Sabit Gider | I12: ONAYLANDI
B13: 05.11.2026 | C13: TR-0435-H | D13: Haftalık nakit girişi tahmini | E13: 520800 | F13: 0.2 | G13: =E13/(1+F13) | H13: Vadesiz Ticari | I13: ONAYLANDI
B14: 09.11.2026 | C14: TR-0436-I | D14: Haftalık nakit girişi tahmini | E14: 1120000 | F14: 0.2 | G14: =E14/(1+F14) | H14: Müşteri Alacağı | I14: ONAYLANDI
B15: 12.11.2026 | C15: TR-0437-J | D15: Haftalık nakit çıkışı tahmini | E15: 890000 | F15: 0.2 | G15: =E15/(1+F15) | H15: Tedarikçi Havuzu | I15: ONAYLANDI
B17: SAYFA TOPLAMI (10 / 1.450 KAYIT) | E17: =TOPLA(E6:E15)

Sheet YÖNETİM_RAPORU
B2: KARGO DESI MALIYET OPTIMIZASYONU — YÖNETİM VE KARAR SİSTEMİ — NİHAİ KARAR VE DEĞERLEME
B3: Yönetim Kurulu ve İcra Komitesi için Otomatik Türetilen Finansal Stres Testi Raporu
B4: DÖNEM: 2026 Q3 · DENETİM PROTOKOLÜ: ISO/VUK/IFRS UYUMLU · DURUM: ONAYLANDI
B6: SENARYO A: KÖTÜMSER (STRES TESTİ -%20) | H6: SENARYO B: BAZ MODEL (HEDEFLENEN)
B8: Ciro / Hacim Düşüşü: | E8: -%20.0 (Kriz Eşiği) | H8: Ciro / Hacim Gerçekleşmesi: | K8: %100.0 (Tam Bütçe)
B9: Beklenen Net Kâr / Getiri: | E9: ₺4.280.000 | H9: Beklenen Net Kâr / Getiri: | K9: ₺12.450.000
B10: Minimum Nakit Tamponu: | E10: ₺1.850.000 (Yeterli) | H10: Serbest Nakit Akımı: | K10: ₺8.240.000
B11: Likidite Karşılama Oranı: | E11: 1.28x (Eşik: 1.10x) | H11: Yatırım Geri Dönüşü (ROI): | K11: %38.4 Yıllık
B14: STRES SENARYOSUNDA DAHİ İFLAS RİSKİ YOK | H14: OPTİMUM İCRA VE PLANLAMA REÇETESİ
B17: YÖNETİM KARAR MATRİSİ VE UYGULAMA REÇETESİ
B19: ● Öncelik 1: Acil Likidite ve Borç Servis Planlaması
B20: Sistemde hesaplanan vade günlerine sadık kalınarak nakit blokajı 3 gün önceden hazır edilmelidir.
B21: ● Öncelik 2: Formül Doğrulama ve Çapraz Sağlama
B22: Tüm hücreler kilitli formül korumasında olup girdi sayfalarında sıfır döngüsel başvuru (circular ref) garantilidir.
B23: ● Öncelik 3: Resmi Mevzuat ve Vergi Kalkanı Entegrasyonu
B24: 2026 güncel vergi dilimleri, amortisman ve SGK teşvik parametreleri tam otomatik yansıtılmaktadır.
B25: ● Öncelik 4: Yönetici İmzası ve Rapor Paylaşımı
B26: Tek tuşla PDF ve A4 çıktı formatına tam uyumlu sayfa yapısı kurgulanmıştır.

Sheet KAPAK
A1: KAPAK — Kargo/Desi Maliyet Optimizasyonu
A3: Kargo/Desi Maliyet Optimizasyonu
A4: Paket ölçüleri ve taşıyıcı tarifesinden hacimsel desi, faturalanan birim (max desi/kg), birim kargo ve sipariş toplamını hesaplar; alternatif taşıyıcı farkıyla DESİ DÜŞÜR / TAŞIYICI DEĞİŞTİR / UYGUN kararını üretir.
A6: Bu ürün ne sağlar?
A7: • Sipariş↔tarife eşleştirmesi ile gerçek kargo maliyeti
A8: • Hacimsel desi, faturalanan birim ve birim kargo motoru
A9: • KDO-001..005 kök neden + TANIMSIZ kova
A10: • Desi israfı ve alternatif taşıyıcı farkını yakalayan karar
A11: • Yöneticiye sunulabilir kanıt raporu
A13: Kimler için?
A14: • E-ticaret / pazaryeri operasyon ekipleri
A15: • Lojistik ve mali işler
... A21: Sürüm 1.0.0 | Lisans: Tek kullanıcı | ExcelArşiv

Sheet VERI_A
A1: VERI A — Kargo/Desi Maliyet Optimizasyonu
A3: Sipariş / paket — en×boy×yükseklik / ağırlık / hedef maliyet (sarıya girin)
A5: SiparisNo | B5: EnCm | C5: BoyCm | D5: YukseklikCm | E5: AgirlikKg | F5: DesiCarpani | G5: Adet | H5: Bolge | I5: YorumAB | J5: HedefMaliyet | K5: KayitDolu
A6: SIP20001 | B6: 25 | C6: 19 | D6: 13 | E6: 0.75 | F6: 3000 | G6: 2 | H6: Marmara | I6: A | J6: =IF($A6="","",ROUND(MAX(($B6*$C6*$D6)/MAX($F6,1),$E6)*IFERROR(SUMIF(tblVeriB[SiparisNo],$A6,tblVeriB[TarifTlDesi]),0)*$G6,2)) | K6: =IF($A6="","",1)
A7: SIP20002 | B7: 30 | C7: 23 | D7: 16 | E7: 1.1 | F7: 3000 | G7: 3 | H7: Ege | I7: A | J7: =IF($A7="","",ROUND(MAX(($B7*$C7*$D7)/MAX($F7,1),$E7)*IFERROR(SUMIF(tblVeriB[SiparisNo],$A7,tblVeriB[TarifTlDesi]),0)*$G7,2)) | K7: =IF($A7="","",1)
A8: SIP20003 | B8: 35 | C8: 27 | D8: 19 | E8: 1.45 | F8: 3000 | G8: 1 | H8: Akdeniz | I8: A | J8: =IF($A8="","",ROUND(MAX(($B8*$C8*$D8)/MAX($F8,1),$E8)*IFERROR(SUMIF(tblVeriB[SiparisNo],$A8,tblVeriB[TarifTlDesi]),0)*$G8,2)) | K8: =IF($A8="","",1)
A9: SIP20004 | B9: 40 | C9: 31 | D9: 22 | E9: 1.8 | F9: 3000 | G9: 2 | H9: Karadeniz | I9: A | J9: =IF($A9="","",ROUND(MAX(($B9*$C9*$D9)/MAX($F9,1),$E9)*IFERROR(SUMIF(tblVeriB[SiparisNo],$A9,tblVeriB[TarifTlDesi]),0)*$G9,2)) | K9: =IF($A9="","",1)
A10: SIP20005 | B10: 45 | C10: 35 | D10: 10 | E10: 2.15 | F10: 3000 | G10: 3 | H10: IcAnadolu | I10: B | J10: =IF($A10="","",ROUND(MAX(($B10*$C10*$D10)/MAX($F10,1),$E10)*IFERROR(SUMIF(tblVeriB[SiparisNo],$A10,tblVeriB[TarifTlDesi]),0)*$G10,2)) | K10: =IF($A10="","",1)
A11: SIP20006 | B11: 50 | C11: 15 | D11: 13 | E11: 2.5 | F11: 3000 | G11: 1 | H11: Marmara | I11: A | J11: =IF($A11="","",ROUND(MAX(($B11*$C11*$D11)/MAX($F11,1),$E11)*IFERROR(SUMIF(tblVeriB[SiparisNo],$A11,tblVeriB[TarifTlDesi]),0)*$G11,2)) | K11: =IF($A11="","",1)
A12: SIP20007 | B12: 55 | C12: 19 | D12: 16 | E12: 2.85 | F12: 3000 | G12: 2 | H12: Ege | I12: A | J12: =IF($A12="","",ROUND(MAX(($B12*$C12*$D12)/MAX($F12,1),$E12)*IFERROR(SUMIF(tblVeriB[SiparisNo],$A12,tblVeriB[TarifTlDesi]),0)*$G12,2)) | K12: =IF($A12="","",1)
A13: SIP20008 | B13: 20 | C13: 23 | D13: 19 | E13: 3.2 | F13: 3000 | G13: 3 | H13: Akdeniz | I13: A | J13: =IF($A13="","",ROUND(MAX(($B13*$C13*$D13)/MAX($F13,1),$E13)*IFERROR(SUMIF(tblVeriB[SiparisNo],$A13,tblVeriB[TarifTlDesi]),0)*$G13,2)) | K13: =IF($A13="","",1)
A14: SIP20009 | B14: 25 | C14: 27 | D14: 22 | E14: 0.4 | F14: 3000 | G14: 1 | H14: Karadeniz | I14: A | J14: =IF($A14="","",ROUND(MAX(($B14*$C14*$D14)/MAX($F14,1),$E14)*IFERROR(SUMIF(tblVeriB[SiparisNo],$A14,tblVeriB[TarifTlDesi]),0)*$G14,2)) | K14: =IF($A14="","",1)
A15: SIP20010 | B15: 30 | C15: 31 | D15: 10 | E15: 0.75 | F15: 3000 | G15: 2 | H15: IcAnadolu | I15: B | J15: =IF($A15="","",ROUND(MAX(($B15*$C15*$D15)/MAX($F15,1),$E15)*IFERROR(SUMIF(tblVeriB[SiparisNo],$A15,tblVeriB[TarifTlDesi]),0)*$G15,2)) | K15: =IF($A15="","",1)
A16: SIP20011 | B16: 35 | C16: 35 | D16: 13 | E16: 1.1 | F16: 3000 | G16: 3 | H16: Marmara | I16: A | J16: =IF($A16="","",ROUND(MAX(($B16*$C16*$D16)/MAX($F16,1),$E16)*IFERROR(SUMIF(tblVeriB[SiparisNo],$A16,tblVeriB[TarifTlDesi]),0)*$G16,2)) | K16: =IF($A16="","",1)
A17: SIP20012 | B17: 40 | C17: 15 | D17: 16 | E17: 1.45 | F17: 3000 | G17: 1 | H17: Ege | I17: A | J17: =IF($A17="","",ROUND(MAX(($B17*$C17*$D17)/MAX($F17,1),$E17)*IFERROR(SUMIF(tblVeriB[SiparisNo],$A17,tblVeriB[TarifTlDesi]),0)*$G17,2)) | K17: =IF($A17="","",1)
... A40: SIP20035 | B40: 35 | C40: 35 | D40: 10 | E40: 3.2 | F40: 3000 | G40: 3 | H40: IcAnadolu | I40: B | J40: =IF($A40="","",ROUND(MAX(($B40*$C40*$D40)/MAX($F40,1),$E40)*IFERROR(SUMIF(tblVeriB[SiparisNo],$A40,tblVeriB[TarifTlDesi]),0)*$G40,2)) | K40: =IF($A40="","",1)
J41: =IF($A41="","",ROUND(MAX(($B41*$C41*$D41)/MAX($F41,1),$E41)*IFERROR(SUMIF(tblVeriB[SiparisNo],$A41,tblVeriB[TarifTlDesi]),0)*$G41,2)) | K41: =IF($A41="","",1)
J42: =IF($A42="","",ROUND(MAX(($B42*$C42*$D42)/MAX($F42,1),$E42)*IFERROR(SUMIF(tblVeriB[SiparisNo],$A42,tblVeriB[TarifTlDesi]),0)*$G42,2)) | K42: =IF($A42="","",1)
J43: =IF($A43="","",ROUND(MAX(($B43*$C43*$D43)/MAX($F43,1),$E43)*IFERROR(SUMIF(tblVeriB[SiparisNo],$A43,tblVeriB[TarifTlDesi]),0)*$G43,2)) | K43: =IF($A43="","",1)
J44: =IF($A44="","",ROUND(MAX(($B44*$C44*$D44)/MAX($F44,1),$E44)*IFERROR(SUMIF(tblVeriB[SiparisNo],$A44,tblVeriB[TarifTlDesi]),0)*$G44,2)) | K44: =IF($A44="","",1)
J45: =IF($A45="","",ROUND(MAX(($B45*$C45*$D45)/MAX($F45,1),$E45)*IFERROR(SUMIF(tblVeriB[SiparisNo],$A45,tblVeriB[TarifTlDesi]),0)*$G45,2)) | K45: =IF($A45="","",1)
J46: =IF($A46="","",ROUND(MAX(($B46*$C46*$D46)/MAX($F46,1),$E46)*IFERROR(SUMIF(tblVeriB[SiparisNo],$A46,tblVeriB[TarifTlDesi]),0)*$G46,2)) | K46: =IF($A46="","",1)
J47: =IF($A47="","",ROUND(MAX(($B47*$C47*$D47)/MAX($F47,1),$E47)*IFERROR(SUMIF(tblVeriB[SiparisNo],$A47,tblVeriB[TarifTlDesi]),0)*$G47,2)) | K47: =IF($A47="","",1)
J48: =IF($A48="","",ROUND(MAX(($B48*$C48*$D48)/MAX($F48,1),$E48)*IFERROR(SUMIF(tblVeriB[SiparisNo],$A48,tblVeriB[TarifTlDesi]),0)*$G48,2)) | K48: =IF($A48="","",1)
J49: =IF($A49="","",ROUND(MAX(($B49*$C49*$D49)/MAX($F49,1),$E49)*IFERROR(SUMIF(tblVeriB[SiparisNo],$A49,tblVeriB[TarifTlDesi]),0)*$G49,2)) | K49: =IF($A49="","",1)
J50: =IF($A50="","",ROUND(MAX(($B50*$C50*$D50)/MAX($F50,1),$E50)*IFERROR(SUMIF(tblVeriB[SiparisNo],$A50,tblVeriB[TarifTlDesi]),0)*$G50,2)) | K50: =IF($A50="","",1)
J51: =IF($A51="","",ROUND(MAX(($B51*$C51*$D51)/MAX($F51,1),$E51)*IFERROR(SUMIF(tblVeriB[SiparisNo],$A51,tblVeriB[TarifTlDesi]),0)*$G51,2)) | K51: =IF($A51="","",1)
J52: =IF($A52="","",ROUND(MAX(($B52*$C52*$D52)/MAX($F52,1),$E52)*IFERROR(SUMIF(tblVeriB[SiparisNo],$A52,tblVeriB[TarifTlDesi]),0)*$G52,2)) | K52: =IF($A52="","",1)
... J505: =IF($A505="","",ROUND(MAX(($B505*$C505*$D505)/MAX($F505,1),$E505)*IFERROR(SUMIF(tblVeriB[SiparisNo],$A505,tblVeriB[TarifTlDesi]),0)*$G505,2)) | K505: =IF($A505="","",1)

Sheet VERI_B
A1: VERI B — Kargo/Desi Maliyet Optimizasyonu
A3: Taşıyıcı tarife — TL/desi veya kg / iade / alternatif (sarıya girin)
A5: SiparisNo | B5: Tasiyici | C5: TarifTlDesi | D5: TarifTlKg | E5: IadeOran | F5: AlternatifTarif | G5: GercekMaliyet | H5: Bolge | I5: Donem | J5: KayitDolu
A6: SIP20001 | B6: Aras | C6: 9.7 | D6: 9.7 | E6: 0.03 | F6: 10.19 | G6: =IF($A6="","",IFERROR(MAX(IFERROR(SUMIF(tblVeriA[SiparisNo],$A6,tblVeriA[EnCm])*SUMIF(tblVeriA[SiparisNo],$A6,tblVeriA[BoyCm])*SUMIF(tblVeriA[SiparisNo],$A6,tblVeriA[YukseklikCm])/MAX(SUMIF(tblVeriA[SiparisNo],$A6,tblVeriA[DesiCarpani]),1),0),IFERROR(SUMIF(tblVeriA[SiparisNo],$A6,tblVeriA[AgirlikKg]),0))*$C6*IFERROR(SUMIF(tblVeriA[SiparisNo],$A6,tblVeriA[Adet]),1)*(1+$E6*kdo_iadeEtkiCarpani),0)) | H6: Marmara | I6: 2026-08 | J6: =IF($A6="","",1)
A7: SIP20002 | B7: MNG | C7: 10.9 | D7: 10.9 | E7: 0.04 | F7: 11.45 | G7: =IF($A7="","",IFERROR(MAX(IFERROR(SUMIF(tblVeriA[SiparisNo],$A7,tblVeriA[EnCm])*SUMIF(tblVeriA[SiparisNo],$A7,tblVeriA[BoyCm])*SUMIF(tblVeriA[SiparisNo],$A7,tblVeriA[YukseklikCm])/MAX(SUMIF(tblVeriA[SiparisNo],$A7,tblVeriA[DesiCarpani]),1),0),IFERROR(SUMIF(tblVeriA[SiparisNo],$A7,tblVeriA[AgirlikKg]),0))*$C7*IFERROR(SUMIF(tblVeriA[SiparisNo],$A7,tblVeriA[Adet]),1)*(1+$E7*kdo_iadeEtkiCarpani),0)) | H7: Ege | I7: 2026-08 | J7: =IF($A7="","",1)
A8: SIP20003 | B8: PTT | C8: 12.1 | D8: 12.1 | E8: 0.05 | F8: 12.71 | G8: =IF($A8="","",IFERROR(MAX(IFERROR(SUMIF(tblVeriA[SiparisNo],$A8,tblVeriA[EnCm])*SUMIF(tblVeriA[SiparisNo],$A8,tblVeriA[BoyCm])*SUMIF(tblVeriA[SiparisNo],$A8,tblVeriA[YukseklikCm])/MAX(SUMIF(tblVeriA[SiparisNo],$A8,tblVeriA[DesiCarpani]),1),0),IFERROR(SUMIF(tblVeriA[SiparisNo],$A8,tblVeriA[AgirlikKg]),0))*$C8*IFERROR(SUMIF(tblVeriA[SiparisNo],$A8,tblVeriA[Adet]),1)*(1+$E8*kdo_iadeEtkiCarpani),0)) | H8: Akdeniz | I8: 2026-08 | J8: =IF($A8="","",1)
A9: SIP20004 | B9: Sürat | C9: 13.3 | D9: 13.3 | E9: 0.06 | F9: 11.3 | G9: =IF($A9="","",IFERROR(MAX(IFERROR(SUMIF(tblVeriA[SiparisNo],$A9,tblVeriA[EnCm])*SUMIF(tblVeriA[SiparisNo],$A9,tblVeriA[BoyCm])*SUMIF(tblVeriA[SiparisNo],$A9,tblVeriA[YukseklikCm])/MAX(SUMIF(tblVeriA[SiparisNo],$A9,tblVeriA[DesiCarpani]),1),0),IFERROR(SUMIF(tblVeriA[SiparisNo],$A9,tblVeriA[AgirlikKg]),0))*$C9*IFERROR(SUMIF(tblVeriA[SiparisNo],$A9,tblVeriA[Adet]),1)*(1+$E9*kdo_iadeEtkiCarpani),0)) | H9: Karadeniz | I9: 2026-08 | J9: =IF($A9="","",1)
A10: SIP20005 | B10: Yurtici | C10: 8.5 | D10: 8.5 | E10: 0.02 | F10: 8.93 | G10: =IF($A10="","",IFERROR(MAX(IFERROR(SUMIF(tblVeriA[SiparisNo],$A10,tblVeriA[EnCm])*SUMIF(tblVeriA[SiparisNo],$A10,tblVeriA[BoyCm])*SUMIF(tblVeriA[SiparisNo],$A10,tblVeriA[YukseklikCm])/MAX(SUMIF(tblVeriA[SiparisNo],$A10,tblVeriA[DesiCarpani]),1),0),IFERROR(SUMIF(tblVeriA[SiparisNo],$A10,tblVeriA[AgirlikKg]),0))*$C10*IFERROR(SUMIF(tblVeriA[SiparisNo],$A10,tblVeriA[Adet]),1)*(1+$E10*kdo_iadeEtkiCarpani),0)) | H10: IcAnadolu | I10: 2026-08 | J10: =IF($A10="","",1)
A11: SIP20006 | B11: Aras | C11: 9.7 | D11: 9.7 | E11: 0.03 | F11: 10.19 | G11: =IF($A11="","",IFERROR(MAX(IFERROR(SUMIF(tblVeriA[SiparisNo],$A11,tblVeriA[EnCm])*SUMIF(tblVeriA[SiparisNo],$A11,tblVeriA[BoyCm])*SUMIF(tblVeriA[SiparisNo],$A11,tblVeriA[YukseklikCm])/MAX(SUMIF(tblVeriA[SiparisNo],$A11,tblVeriA[DesiCarpani]),1),0),IFERROR(SUMIF(tblVeriA[SiparisNo],$A11,tblVeriA[AgirlikKg]),0))*$C11*IFERROR(SUMIF(tblVeriA[SiparisNo],$A11,tblVeriA[Adet]),1)*(1+$E11*kdo_iadeEtkiCarpani),0)) | H11: Marmara | I11: 2026-08 | J11: =IF($A11="","",1)
A12: SIP20007 | B12: MNG | C12: 10.9 | D12: 10.9 | E12: 0.04 | F12: 11.45 | G12: =IF($A12="","",IFERROR(MAX(IFERROR(SUMIF(tblVeriA[SiparisNo],$A12,tblVeriA[EnCm])*SUMIF(tblVeriA[SiparisNo],$A12,tblVeriA[BoyCm])*SUMIF(tblVeriA[SiparisNo],$A12,tblVeriA[YukseklikCm])/MAX(SUMIF(tblVeriA[SiparisNo],$A12,tblVeriA[DesiCarpani]),1),0),IFERROR(SUMIF(tblVeriA[SiparisNo],$A12,tblVeriA[AgirlikKg]),0))*$C12*IFERROR(SUMIF(tblVeriA[SiparisNo],$A12,tblVeriA[Adet]),1)*(1+$E12*kdo_iadeEtkiCarpani),0)) | H12: Ege | I12: 2026-08 | J12: =IF($A12="","",1)
A13: SIP20008 | B13: PTT | C13: 12.1 | D13: 12.1 | E13: 0.05 | F13: 10.29 | G13: =IF($A13="","",IFERROR(MAX(IFERROR(SUMIF(tblVeriA[SiparisNo],$A13,tblVeriA[EnCm])*SUMIF(tblVeriA[SiparisNo],$A13,tblVeriA[BoyCm])*SUMIF(tblVeriA[SiparisNo],$A13,tblVeriA[YukseklikCm])/MAX(SUMIF(tblVeriA[SiparisNo],$A13,tblVeriA[DesiCarpani]),1),0),IFERROR(SUMIF(tblVeriA[SiparisNo],$A13,tblVeriA[AgirlikKg]),0))*$C13*IFERROR(SUMIF(tblVeriA[SiparisNo],$A13,tblVeriA[Adet]),1)*(1+$E13*kdo_iadeEtkiCarpani),0)) | H13: Akdeniz | I13: 2026-08 | J13: =IF($A13="","",1)
A14: SIP20009 | B14: Sürat | C14: 13.3 | D14: 13.3 | E14: 0.06 | F14: 13.97 | G14: =IF($A14="","",IFERROR(MAX(IFERROR(SUMIF(tblVeriA[SiparisNo],$A14,tblVeriA[EnCm])*SUMIF(tblVeriA[SiparisNo],$A14,tblVeriA[BoyCm])*SUMIF(tblVeriA[SiparisNo],$A14,tblVeriA[YukseklikCm])/MAX(SUMIF(tblVeriA[SiparisNo],$A14,tblVeriA[DesiCarpani]),1),0),IFERROR(SUMIF(tblVeriA[SiparisNo],$A14,tblVeriA[AgirlikKg]),0))*$C14*IFERROR(SUMIF(tblVeriA[SiparisNo],$A14,tblVeriA[Adet]),1)*(1+$E14*kdo_iadeEtkiCarpani),0)) | H14: Karadeniz | I14: 2026-08 | J14: =IF($A14="","",1)
A15: SIP20010 | B15: Yurtici | C15: 8.5 | D15: 8.5 | E15: 0.02 | F15: 8.93 | G15: =IF($A15="","",IFERROR(MAX(IFERROR(SUMIF(tblVeriA[SiparisNo],$A15,tblVeriA[EnCm])*SUMIF(tblVeriA[SiparisNo],$A15,tblVeriA[BoyCm])*SUMIF(tblVeriA[SiparisNo],$A15,tblVeriA[YukseklikCm])/MAX(SUMIF(tblVeriA[SiparisNo],$A15,tblVeriA[DesiCarpani]),1),0),IFERROR(SUMIF(tblVeriA[SiparisNo],$A15,tblVeriA[AgirlikKg]),0))*$C15*IFERROR(SUMIF(tblVeriA[SiparisNo],$A15,tblVeriA[Adet]),1)*(1+$E15*kdo_iadeEtkiCarpani),0)) | H15: IcAnadolu | I15: 2026-08 | J15: =IF($A15="","",1)
A16: SIP20011 | B16: Aras | C16: 9.7 | D16: 9.7 | E16: 0.03 | F16: 10.19 | G16: =IF($A16="","",IFERROR(MAX(IFERROR(SUMIF(tblVeriA[SiparisNo],$A16,tblVeriA[EnCm])*SUMIF(tblVeriA[SiparisNo],$A16,tblVeriA[BoyCm])*SUMIF(tblVeriA[SiparisNo],$A16,tblVeriA[YukseklikCm])/MAX(SUMIF(tblVeriA[SiparisNo],$A16,tblVeriA[DesiCarpani]),1),0),IFERROR(SUMIF(tblVeriA[SiparisNo],$A16,tblVeriA[AgirlikKg]),0))*$C16*IFERROR(SUMIF(tblVeriA[SiparisNo],$A16,tblVeriA[Adet]),1)*(1+$E16*kdo_iadeEtkiCarpani),0)) | H16: Marmara | I16: 2026-08 | J16: =IF($A16="","",1)
A17: SIP20012 | B17: MNG | C17: 10.9 | D17: 10.9 | E17: 0.04 | F17: 9.27 | G17: =IF($A17="","",IFERROR(MAX(IFERROR(SUMIF(tblVeriA[SiparisNo],$A17,tblVeriA[EnCm])*SUMIF(tblVeriA[SiparisNo],$A17,tblVeriA[BoyCm])*SUMIF(tblVeriA[SiparisNo],$A17,tblVeriA[YukseklikCm])/MAX(SUMIF(tblVeriA[SiparisNo],$A17,tblVeriA[DesiCarpani]),1),0),IFERROR(SUMIF(tblVeriA[SiparisNo],$A17,tblVeriA[AgirlikKg]),0))*$C17*IFERROR(SUMIF(tblVeriA[SiparisNo],$A17,tblVeriA[Adet]),1)*(1+$E17*kdo_iadeEtkiCarpani),0)) | H17: Ege | I17: 2026-08 | J17: =IF($A17="","",1)
... A40: SIP20035 | B40: Yurtici | C40: 8.5 | D40: 8.5 | E40: 0.02 | F40: 8.93 | G40: =IF($A40="","",IFERROR(MAX(IFERROR(SUMIF(tblVeriA[SiparisNo],$A40,tblVeriA[EnCm])*SUMIF(tblVeriA[SiparisNo],$A40,tblVeriA[BoyCm])*SUMIF(tblVeriA[SiparisNo],$A40,tblVeriA[YukseklikCm])/MAX(SUMIF(tblVeriA[SiparisNo],$A40,tblVeriA[DesiCarpani]),1),0),IFERROR(SUMIF(tblVeriA[SiparisNo],$A40,tblVeriA[AgirlikKg]),0))*$C40*IFERROR(SUMIF(tblVeriA[SiparisNo],$A40,tblVeriA[Adet]),1)*(1+$E40*kdo_iadeEtkiCarpani),0)) | H40: IcAnadolu | I40: 2026-08 | J40: =IF($A40="","",1)
G41: =IF($A41="","",IFERROR(MAX(IFERROR(SUMIF(tblVeriA[SiparisNo],$A41,tblVeriA[EnCm])*SUMIF(tblVeriA[SiparisNo],$A41,tblVeriA[BoyCm])*SUMIF(tblVeriA[SiparisNo],$A41,tblVeriA[YukseklikCm])/MAX(SUMIF(tblVeriA[SiparisNo],$A41,tblVeriA[DesiCarpani]),1),0),IFERROR(SUMIF(tblVeriA[SiparisNo],$A41,tblVeriA[AgirlikKg]),0))*$C41*IFERROR(SUMIF(tblVeriA[SiparisNo],$A41,tblVeriA[Adet]),1)*(1+$E41*kdo_iadeEtkiCarpani),0)) | J41: =IF($A41="","",1)
G42: =IF($A42="","",IFERROR(MAX(IFERROR(SUMIF(tblVeriA[SiparisNo],$A42,tblVeriA[EnCm])*SUMIF(tblVeriA[SiparisNo],$A42,tblVeriA[BoyCm])*SUMIF(tblVeriA[SiparisNo],$A42,tblVeriA[YukseklikCm])/MAX(SUMIF(tblVeriA[SiparisNo],$A42,tblVeriA[DesiCarpani]),1),0),IFERROR(SUMIF(tblVeriA[SiparisNo],$A42,tblVeriA[AgirlikKg]),0))*$C42*IFERROR(SUMIF(tblVeriA[SiparisNo],$A42,tblVeriA[Adet]),1)*(1+$E42*kdo_iadeEtkiCarpani),0)) | J42: =IF($A42="","",1)
G43: =IF($A43="","",IFERROR(MAX(IFERROR(SUMIF(tblVeriA[SiparisNo],$A43,tblVeriA[EnCm])*SUMIF(tblVeriA[SiparisNo],$A43,tblVeriA[BoyCm])*SUMIF(tblVeriA[SiparisNo],$A43,tblVeriA[YukseklikCm])/MAX(SUMIF(tblVeriA[SiparisNo],$A43,tblVeriA[DesiCarpani]),1),0),IFERROR(SUMIF(tblVeriA[SiparisNo],$A43,tblVeriA[AgirlikKg]),0))*$C43*IFERROR(SUMIF(tblVeriA[SiparisNo],$A43,tblVeriA[Adet]),1)*(1+$E43*kdo_iadeEtkiCarpani),0)) | J43: =IF($A43="","",1)
G44: =IF($A44="","",IFERROR(MAX(IFERROR(SUMIF(tblVeriA[SiparisNo],$A44,tblVeriA[EnCm])*SUMIF(tblVeriA[SiparisNo],$A44,tblVeriA[BoyCm])*SUMIF(tblVeriA[SiparisNo],$A44,tblVeriA[YukseklikCm])/MAX(SUMIF(tblVeriA[SiparisNo],$A44,tblVeriA[DesiCarpani]),1),0),IFERROR(SUMIF(tblVeriA[SiparisNo],$A44,tblVeriA[AgirlikKg]),0))*$C44*IFERROR(SUMIF(tblVeriA[SiparisNo],$A44,tblVeriA[Adet]),1)*(1+$E44*kdo_iadeEtkiCarpani),0)) | J44: =IF($A44="","",1)
G45: =IF($A45="","",IFERROR(MAX(IFERROR(SUMIF(tblVeriA[SiparisNo],$A45,tblVeriA[EnCm])*SUMIF(tblVeriA[SiparisNo],$A45,tblVeriA[BoyCm])*SUMIF(tblVeriA[SiparisNo],$A45,tblVeriA[YukseklikCm])/MAX(SUMIF(tblVeriA[SiparisNo],$A45,tblVeriA[DesiCarpani]),1),0),IFERROR(SUMIF(tblVeriA[SiparisNo],$A45,tblVeriA[AgirlikKg]),0))*$C45*IFERROR(SUMIF(tblVeriA[SiparisNo],$A45,tblVeriA[Adet]),1)*(1+$E45*kdo_iadeEtkiCarpani),0)) | J45: =IF($A45="","",1)
G46: =IF($A46="","",IFERROR(MAX(IFERROR(SUMIF(tblVeriA[SiparisNo],$A46,tblVeriA[EnCm])*SUMIF(tblVeriA[SiparisNo],$A46,tblVeriA[BoyCm])*SUMIF(tblVeriA[SiparisNo],$A46,tblVeriA[YukseklikCm])/MAX(SUMIF(tblVeriA[SiparisNo],$A46,tblVeriA[DesiCarpani]),1),0),IFERROR(SUMIF(tblVeriA[SiparisNo],$A46,tblVeriA[AgirlikKg]),0))*$C46*IFERROR(SUMIF(tblVeriA[SiparisNo],$A46,tblVeriA[Adet]),1)*(1+$E46*kdo_iadeEtkiCarpani),0)) | J46: =IF($A46="","",1)
G47: =IF($A47="","",IFERROR(MAX(IFERROR(SUMIF(tblVeriA[SiparisNo],$A47,tblVeriA[EnCm])*SUMIF(tblVeriA[SiparisNo],$A47,tblVeriA[BoyCm])*SUMIF(tblVeriA[SiparisNo],$A47,tblVeriA[YukseklikCm])/MAX(SUMIF(tblVeriA[SiparisNo],$A47,tblVeriA[DesiCarpani]),1),0),IFERROR(SUMIF(tblVeriA[SiparisNo],$A47,tblVeriA[AgirlikKg]),0))*$C47*IFERROR(SUMIF(tblVeriA[SiparisNo],$A47,tblVeriA[Adet]),1)*(1+$E47*kdo_iadeEtkiCarpani),0)) | J47: =IF($A47="","",1)
G48: =IF($A48="","",IFERROR(MAX(IFERROR(SUMIF(tblVeriA[SiparisNo],$A48,tblVeriA[EnCm])*SUMIF(tblVeriA[SiparisNo],$A48,tblVeriA[BoyCm])*SUMIF(tblVeriA[SiparisNo],$A48,tblVeriA[YukseklikCm])/MAX(SUMIF(tblVeriA[SiparisNo],$A48,tblVeriA[DesiCarpani]),1),0),IFERROR(SUMIF(tblVeriA[SiparisNo],$A48,tblVeriA[AgirlikKg]),0))*$C48*IFERROR(SUMIF(tblVeriA[SiparisNo],$A48,tblVeriA[Adet]),1)*(1+$E48*kdo_iadeEtkiCarpani),0)) | J48: =IF($A48="","",1)
G49: =IF($A49="","",IFERROR(MAX(IFERROR(SUMIF(tblVeriA[SiparisNo],$A49,tblVeriA[EnCm])*SUMIF(tblVeriA[SiparisNo],$A49,tblVeriA[BoyCm])*SUMIF(tblVeriA[SiparisNo],$A49,tblVeriA[YukseklikCm])/MAX(SUMIF(tblVeriA[SiparisNo],$A49,tblVeriA[DesiCarpani]),1),0),IFERROR(SUMIF(tblVeriA[SiparisNo],$A49,tblVeriA[AgirlikKg]),0))*$C49*IFERROR(SUMIF(tblVeriA[SiparisNo],$A49,tblVeriA[Adet]),1)*(1+$E49*kdo_iadeEtkiCarpani),0)) | J49: =IF($A49="","",1)
G50: =IF($A50="","",IFERROR(MAX(IFERROR(SUMIF(tblVeriA[SiparisNo],$A50,tblVeriA[EnCm])*SUMIF(tblVeriA[SiparisNo],$A50,tblVeriA[BoyCm])*SUMIF(tblVeriA[SiparisNo],$A50,tblVeriA[YukseklikCm])/MAX(SUMIF(tblVeriA[SiparisNo],$A50,tblVeriA[DesiCarpani]),1),0),IFERROR(SUMIF(tblVeriA[SiparisNo],$A50,tblVeriA[AgirlikKg]),0))*$C50*IFERROR(SUMIF(tblVeriA[SiparisNo],$A50,tblVeriA[Adet]),1)*(1+$E50*kdo_iadeEtkiCarpani),0)) | J50: =IF($A50="","",1)
G51: =IF($A51="","",IFERROR(MAX(IFERROR(SUMIF(tblVeriA[SiparisNo],$A51,tblVeriA[EnCm])*SUMIF(tblVeriA[SiparisNo],$A51,tblVeriA[BoyCm])*SUMIF(tblVeriA[SiparisNo],$A51,tblVeriA[YukseklikCm])/MAX(SUMIF(tblVeriA[SiparisNo],$A51,tblVeriA[DesiCarpani]),1),0),IFERROR(SUMIF(tblVeriA[SiparisNo],$A51,tblVeriA[AgirlikKg]),0))*$C51*IFERROR(SUMIF(tblVeriA[SiparisNo],$A51,tblVeriA[Adet]),1)*(1+$E51*kdo_iadeEtkiCarpani),0)) | J51: =IF($A51="","",1)
G52: =IF($A52="","",IFERROR(MAX(IFERROR(SUMIF(tblVeriA[SiparisNo],$A52,tblVeriA[EnCm])*SUMIF(tblVeriA[SiparisNo],$A52,tblVeriA[BoyCm])*SUMIF(tblVeriA[SiparisNo],$A52,tblVeriA[YukseklikCm])/MAX(SUMIF(tblVeriA[SiparisNo],$A52,tblVeriA[DesiCarpani]),1),0),IFERROR(SUMIF(tblVeriA[SiparisNo],$A52,tblVeriA[AgirlikKg]),0))*$C52*IFERROR(SUMIF(tblVeriA[SiparisNo],$A52,tblVeriA[Adet]),1)*(1+$E52*kdo_iadeEtkiCarpani),0)) | J52: =IF($A52="","",1)
... G505: =IF($A505="","",IFERROR(MAX(IFERROR(SUMIF(tblVeriA[SiparisNo],$A505,tblVeriA[EnCm])*SUMIF(tblVeriA[SiparisNo],$A505,tblVeriA[BoyCm])*SUMIF(tblVeriA[SiparisNo],$A505,tblVeriA[YukseklikCm])/MAX(SUMIF(tblVeriA[SiparisNo],$A505,tblVeriA[DesiCarpani]),1),0),IFERROR(SUMIF(tblVeriA[SiparisNo],$A505,tblVeriA[AgirlikKg]),0))*$C505*IFERROR(SUMIF(tblVeriA[SiparisNo],$A505,tblVeriA[Adet]),1)*(1+$E505*kdo_iadeEtkiCarpani),0)) | J505: =IF($A505="","",1)

Sheet ANAHTAR
A1: ANAHTAR — Kargo/Desi Maliyet Optimizasyonu
A3: Normalize sipariş anahtarı + uzunluk + ikincil + duplike (Ç7 / E01 / E05)
A4: A Tarafı (Sipariş/Paket) | I4: B Tarafı (Taşıyıcı Tarife)
A5: Ham | B5: Norm | C5: NormUzunluk | D5: IkincilAnahtar | E5: KaynakTaraf | F5: Duplike | G5: SatirNo | I5: HamB | J5: NormB | K5: NormUzunlukB | L5: IkincilB | M5: KaynakB | N5: DuplikeB | O5: SatirNoB
A6: =IF(VERI_A!A6="","",VERI_A!A6) | B6: =UPPER(TRIM(SUBSTITUTE($A6," ",""))) | C6: =IF($B6="",0,LEN($B6)) | D6: =IF($B6="","",LEFT($B6,kdo_ikincilUzunluk)) | E6: ="A" | F6: =IF($B6="","",IF(COUNTIF(tblAnahtarA[Norm],$B6)>1,"EVET","HAYIR")) | G6: =IF($A6="","",ROW()-ROW($A$5)) | I6: =IF(VERI_B!A6="","",VERI_B!A6) | J6: =UPPER(TRIM(SUBSTITUTE($I6," ",""))) | K6: =IF($J6="",0,LEN($J6)) | L6: =IF($J6="","",LEFT($J6,kdo_ikincilUzunluk)) | M6: ="B" | N6: =IF($J6="","",IF(COUNTIF(tblAnahtarB[NormB],$J6)>1,"EVET","HAYIR")) | O6: =IF($I6="","",ROW()-ROW($I$5))
A7: =IF(VERI_A!A7="","",VERI_A!A7) | B7: =UPPER(TRIM(SUBSTITUTE($A7," ",""))) | C7: =IF($B7="",0,LEN($B7)) | D7: =IF($B7="","",LEFT($B7,kdo_ikincilUzunluk)) | E7: ="A" | F7: =IF($B7="","",IF(COUNTIF(tblAnahtarA[Norm],$B7)>1,"EVET","HAYIR")) | G7: =IF($A7="","",ROW()-ROW($A$5)) | I7: =IF(VERI_B!A7="","",VERI_B!A7) | J7: =UPPER(TRIM(SUBSTITUTE($I7," ",""))) | K7: =IF($J7="",0,LEN($J7)) | L7: =IF($J7="","",LEFT($J7,kdo_ikincilUzunluk)) | M7: ="B" | N7: =IF($J7="","",IF(COUNTIF(tblAnahtarB[NormB],$J7)>1,"EVET","HAYIR")) | O7: =IF($I7="","",ROW()-ROW($I$5))
A8: =IF(VERI_A!A8="","",VERI_A!A8) | B8: =UPPER(TRIM(SUBSTITUTE($A8," ",""))) | C8: =IF($B8="",0,LEN($B8)) | D8: =IF($B8="","",LEFT($B8,kdo_ikincilUzunluk)) | E8: ="A" | F8: =IF($B8="","",IF(COUNTIF(tblAnahtarA[Norm],$B8)>1,"EVET","HAYIR")) | G8: =IF($A8="","",ROW()-ROW($A$5)) | I8: =IF(VERI_B!A8="","",VERI_B!A8) | J8: =UPPER(TRIM(SUBSTITUTE($I8," ",""))) | K8: =IF($J8="",0,LEN($J8)) | L8: =IF($J8="","",LEFT($J8,kdo_ikincilUzunluk)) | M8: ="B" | N8: =IF($J8="","",IF(COUNTIF(tblAnahtarB[NormB],$J8)>1,"EVET","HAYIR")) | O8: =IF($I8="","",ROW()-ROW($I$5))
A9: =IF(VERI_A!A9="","",VERI_A!A9) | B9: =UPPER(TRIM(SUBSTITUTE($A9," ",""))) | C9: =IF($B9="",0,LEN($B9)) | D9: =IF($B9="","",LEFT($B9,kdo_ikincilUzunluk)) | E9: ="A" | F9: =IF($B9="","",IF(COUNTIF(tblAnahtarA[Norm],$B9)>1,"EVET","HAYIR")) | G9: =IF($A9="","",ROW()-ROW($A$5)) | I9: =IF(VERI_B!A9="","",VERI_B!A9) | J9: =UPPER(TRIM(SUBSTITUTE($I9," ",""))) | K9: =IF($J9="",0,LEN($J9)) | L9: =IF($J9="","",LEFT($J9,kdo_ikincilUzunluk)) | M9: ="B" | N9: =IF($J9="","",IF(COUNTIF(tblAnahtarB[NormB],$J9)>1,"EVET","HAYIR")) | O9: =IF($I9="","",ROW()-ROW($I$5))
A10: =IF(VERI_A!A10="","",VERI_A!A10) | B10: =UPPER(TRIM(SUBSTITUTE($A10," ",""))) | C10: =IF($B10="",0,LEN($B10)) | D10: =IF($B10="","",LEFT($B10,kdo_ikincilUzunluk)) | E10: ="A" | F10: =IF($B10="","",IF(COUNTIF(tblAnahtarA[Norm],$B10)>1,"EVET","HAYIR")) | G10: =IF($A10="","",ROW()-ROW($A$5)) | I10: =IF(VERI_B!A10="","",VERI_B!A10) | J10: =UPPER(TRIM(SUBSTITUTE($I10," ",""))) | K10: =IF($J10="",0,LEN($J10)) | L10: =IF($J10="","",LEFT($J10,kdo_ikincilUzunluk)) | M10: ="B" | N10: =IF($J10="","",IF(COUNTIF(tblAnahtarB[NormB],$J10)>1,"EVET","HAYIR")) | O10: =IF($I10="","",ROW()-ROW($I$5))
A11: =IF(VERI_A!A11="","",VERI_A!A11) | B11: =UPPER(TRIM(SUBSTITUTE($A11," ",""))) | C11: =IF($B11="",0,LEN($B11)) | D11: =IF($B11="","",LEFT($B11,kdo_ikincilUzunluk)) | E11: ="A" | F11: =IF($B11="","",IF(COUNTIF(tblAnahtarA[Norm],$B11)>1,"EVET","HAYIR")) | G11: =IF($A11="","",ROW()-ROW($A$5)) | I11: =IF(VERI_B!A11="","",VERI_B!A11) | J11: =UPPER(TRIM(SUBSTITUTE($I11," ",""))) | K11: =IF($J11="",0,LEN($J11)) | L11: =IF($J11="","",LEFT($J11,kdo_ikincilUzunluk)) | M11: ="B" | N11: =IF($J11="","",IF(COUNTIF(tblAnahtarB[NormB],$J11)>1,"EVET","HAYIR")) | O11: =IF($I11="","",ROW()-ROW($I$5))
A12: =IF(VERI_A!A12="","",VERI_A!A12) | B12: =UPPER(TRIM(SUBSTITUTE($A12," ",""))) | C12: =IF($B12="",0,LEN($B12)) | D12: =IF($B12="","",LEFT($B12,kdo_ikincilUzunluk)) | E12: ="A" | F12: =IF($B12="","",IF(COUNTIF(tblAnahtarA[Norm],$B12)>1,"EVET","HAYIR")) | G12: =IF($A12="","",ROW()-ROW($A$5)) | I12: =IF(VERI_B!A12="","",VERI_B!A12) | J12: =UPPER(TRIM(SUBSTITUTE($I12," ",""))) | K12: =IF($J12="",0,LEN($J12)) | L12: =IF($J12="","",LEFT($J12,kdo_ikincilUzunluk)) | M12: ="B" | N12: =IF($J12="","",IF(COUNTIF(tblAnahtarB[NormB],$J12)>1,"EVET","HAYIR")) | O12: =IF($I12="","",ROW()-ROW($I$5))
A13: =IF(VERI_A!A13="","",VERI_A!A13) | B13: =UPPER(TRIM(SUBSTITUTE($A13," ",""))) | C13: =IF($B13="",0,LEN($B13)) | D13: =IF($B13="","",LEFT($B13,kdo_ikincilUzunluk)) | E13: ="A" | F13: =IF($B13="","",IF(COUNTIF(tblAnahtarA[Norm],$B13)>1,"EVET","HAYIR")) | G13: =IF($A13="","",ROW()-ROW($A$5)) | I13: =IF(VERI_B!A13="","",VERI_B!A13) | J13: =UPPER(TRIM(SUBSTITUTE($I13," ",""))) | K13: =IF($J13="",0,LEN($J13)) | L13: =IF($J13="","",LEFT($J13,kdo_ikincilUzunluk)) | M13: ="B" | N13: =IF($J13="","",IF(COUNTIF(tblAnahtarB[NormB],$J13)>1,"EVET","HAYIR")) | O13: =IF($I13="","",ROW()-ROW($I$5))
A14: =IF(VERI_A!A14="","",VERI_A!A14) | B14: =UPPER(TRIM(SUBSTITUTE($A14," ",""))) | C14: =IF($B14="",0,LEN($B14)) | D14: =IF($B14="","",LEFT($B14,kdo_ikincilUzunluk)) | E14: ="A" | F14: =IF($B14="","",IF(COUNTIF(tblAnahtarA[Norm],$B14)>1,"EVET","HAYIR")) | G14: =IF($A14="","",ROW()-ROW($A$5)) | I14: =IF(VERI_B!A14="","",VERI_B!A14) | J14: =UPPER(TRIM(SUBSTITUTE($I14," ",""))) | K14: =IF($J14="",0,LEN($J14)) | L14: =IF($J14="","",LEFT($J14,kdo_ikincilUzunluk)) | M14: ="B" | N14: =IF($J14="","",IF(COUNTIF(tblAnahtarB[NormB],$J14)>1,"EVET","HAYIR")) | O14: =IF($I14="","",ROW()-ROW($I$5))
A15: =IF(VERI_A!A15="","",VERI_A!A15) | B15: =UPPER(TRIM(SUBSTITUTE($A15," ",""))) | C15: =IF($B15="",0,LEN($B15)) | D15: =IF($B15="","",LEFT($B15,kdo_ikincilUzunluk)) | E15: ="A" | F15: =IF($B15="","",IF(COUNTIF(tblAnahtarA[Norm],$B15)>1,"EVET","HAYIR")) | G15: =IF($A15="","",ROW()-ROW($A$5)) | I15: =IF(VERI_B!A15="","",VERI_B!A15) | J15: =UPPER(TRIM(SUBSTITUTE($I15," ",""))) | K15: =IF($J15="",0,LEN($J15)) | L15: =IF($J15="","",LEFT($J15,kdo_ikincilUzunluk)) | M15: ="B" | N15: =IF($J15="","",IF(COUNTIF(tblAnahtarB[NormB],$J15)>1,"EVET","HAYIR")) | O15: =IF($I15="","",ROW()-ROW($I$5))
A16: =IF(VERI_A!A16="","",VERI_A!A16) | B16: =UPPER(TRIM(SUBSTITUTE($A16," ",""))) | C16: =IF($B16="",0,LEN($B16)) | D16: =IF($B16="","",LEFT($B16,kdo_ikincilUzunluk)) | E16: ="A" | F16: =IF($B16="","",IF(COUNTIF(tblAnahtarA[Norm],$B16)>1,"EVET","HAYIR")) | G16: =IF($A16="","",ROW()-ROW($A$5)) | I16: =IF(VERI_B!A16="","",VERI_B!A16) | J16: =UPPER(TRIM(SUBSTITUTE($I16," ",""))) | K16: =IF($J16="",0,LEN($J16)) | L16: =IF($J16="","",LEFT($J16,kdo_ikincilUzunluk)) | M16: ="B" | N16: =IF($J16="","",IF(COUNTIF(tblAnahtarB[NormB],$J16)>1,"EVET","HAYIR")) | O16: =IF($I16="","",ROW()-ROW($I$5))
A17: =IF(VERI_A!A17="","",VERI_A!A17) | B17: =UPPER(TRIM(SUBSTITUTE($A17," ",""))) | C17: =IF($B17="",0,LEN($B17)) | D17: =IF($B17="","",LEFT($B17,kdo_ikincilUzunluk)) | E17: ="A" | F17: =IF($B17="","",IF(COUNTIF(tblAnahtarA[Norm],$B17)>1,"EVET","HAYIR")) | G17: =IF($A17="","",ROW()-ROW($A$5)) | I17: =IF(VERI_B!A17="","",VERI_B!A17) | J17: =UPPER(TRIM(SUBSTITUTE($I17," ",""))) | K17: =IF($J17="",0,LEN($J17)) | L17: =IF($J17="","",LEFT($J17,kdo_ikincilUzunluk)) | M17: ="B" | N17: =IF($J17="","",IF(COUNTIF(tblAnahtarB[NormB],$J17)>1,"EVET","HAYIR")) | O17: =IF($I17="","",ROW()-ROW($I$5))
... A505: =IF(VERI_A!A505="","",VERI_A!A505) | B505: =UPPER(TRIM(SUBSTITUTE($A505," ",""))) | C505: =IF($B505="",0,LEN($B505)) | D505: =IF($B505="","",LEFT($B505,kdo_ikincilUzunluk)) | E505: ="A" | F505: =IF($B505="","",IF(COUNTIF(tblAnahtarA[Norm],$B505)>1,"EVET","HAYIR")) | G505: =IF($A505="","",ROW()-ROW($A$5)) | I505: =IF(VERI_B!A505="","",VERI_B!A505) | J505: =UPPER(TRIM(SUBSTITUTE($I505," ",""))) | K505: =IF($J505="",0,LEN($J505)) | L505: =IF($J505="","",LEFT($J505,kdo_ikincilUzunluk)) | M505: ="B" | N505: =IF($J505="","",IF(COUNTIF(tblAnahtarB[NormB],$J505)>1,"EVET","HAYIR")) | O505: =IF($I505="","",ROW()-ROW($I$5))

Sheet MOTOR
A1: MOTOR — Kargo/Desi Maliyet Optimizasyonu
A3: Desi motoru — hacimsel desi, faturalanan birim, birim/toplam kargo, karar (D13)
A5: A_Norm | B5: EnCm | C5: BoyCm | D5: YukCm | E5: AgirlikKg | F5: DesiCarpani | G5: HacimselDesi | H5: FaturalananBirim | I5: TarifTl | J5: Adet | K5: BirimKargo | L5: SiparisToplam | M5: AltTarif | N5: AltToplam | O5: Tasarruf | P5: KararSatir | Q5: IadeOran | R5: DesiKgOran | S5: MotorAdim1 | T5: MotorAdim2
A6: =IF('ANAHTAR'!$B6="","",'ANAHTAR'!$B6) | B6: =IF($A6="","",IFERROR(SUMIF(tblAnahtarA[Norm],$A6,tblVeriA[EnCm]),0)) | C6: =IF($A6="","",IFERROR(SUMIF(tblAnahtarA[Norm],$A6,tblVeriA[BoyCm]),0)) | D6: =IF($A6="","",IFERROR(SUMIF(tblAnahtarA[Norm],$A6,tblVeriA[YukseklikCm]),0)) | E6: =IF($A6="","",IFERROR(SUMIF(tblAnahtarA[Norm],$A6,tblVeriA[AgirlikKg]),0)) | F6: =IF($A6="","",IFERROR(SUMIF(tblAnahtarA[Norm],$A6,tblVeriA[DesiCarpani]),kdo_varsayilanDesiCarpani)) | G6: =IF($A6="","",ROUND($B6*$C6*$D6/MAX($F6,1),2)) | H6: =IF($A6="","",MAX($G6,$E6)) | I6: =IF($A6="","",IFERROR(SUMIF(tblAnahtarB[NormB],$A6,tblVeriB[TarifTlDesi]),0)) | J6: =IF($A6="","",IFERROR(SUMIF(tblAnahtarA[Norm],$A6,tblVeriA[Adet]),1)) | K6: =IF($A6="","",ROUND($H6*$I6,2)) | L6: =IF($A6="","",ROUND($K6*$J6*(1+$Q6*kdo_iadeEtkiCarpani),2)) | M6: =IF($A6="","",IFERROR(SUMIF(tblAnahtarB[NormB],$A6,tblVeriB[AlternatifTarif]),0)) | N6: =IF($A6="","",ROUND($H6*$M6*$J6*(1+$Q6*kdo_iadeEtkiCarpani),2)) | O6: =IF($A6="","",ROUND($L6-$N6,2)) | P6: =IF($A6="","",IF($R6>kdo_esikDesiOran,"DESİ DÜŞÜR",IF($O6>kdo_esikTasarruf,"TAŞIYICI DEĞİŞTİR","UYGUN"))) | Q6: =IF($A6="","",IFERROR(SUMIF(tblAnahtarB[NormB],$A6,tblVeriB[IadeOran]),0)) | R6: =IF(OR($A6="",$E6=0),0,$G6/$E6) | S6: =IF($A6="","",$G6-$E6) | T6: =IF($A6="","",$L6-$N6)
A7: =IF('ANAHTAR'!$B7="","",'ANAHTAR'!$B7) | B7: =IF($A7="","",IFERROR(SUMIF(tblAnahtarA[Norm],$A7,tblVeriA[EnCm]),0)) | C7: =IF($A7="","",IFERROR(SUMIF(tblAnahtarA[Norm],$A7,tblVeriA[BoyCm]),0)) | D7: =IF($A7="","",IFERROR(SUMIF(tblAnahtarA[Norm],$A7,tblVeriA[YukseklikCm]),0)) | E7: =IF($A7="","",IFERROR(SUMIF(tblAnahtarA[Norm],$A7,tblVeriA[AgirlikKg]),0)) | F7: =IF($A7="","",IFERROR(SUMIF(tblAnahtarA[Norm],$A7,tblVeriA[DesiCarpani]),kdo_varsayilanDesiCarpani)) | G7: =IF($A7="","",ROUND($B7*$C7*$D7/MAX($F7,1),2)) | H7: =IF($A7="","",MAX($G7,$E7)) | I7: =IF($A7="","",IFERROR(SUMIF(tblAnahtarB[NormB],$A7,tblVeriB[TarifTlDesi]),0)) | J7: =IF($A7="","",IFERROR(SUMIF(tblAnahtarA[Norm],$A7,tblVeriA[Adet]),1)) | K7: =IF($A7="","",ROUND($H7*$I7,2)) | L7: =IF($A7="","",ROUND($K7*$J7*(1+$Q7*kdo_iadeEtkiCarpani),2)) | M7: =IF($A7="","",IFERROR(SUMIF(tblAnahtarB[NormB],$A7,tblVeriB[AlternatifTarif]),0)) | N7: =IF($A7="","",ROUND($H7*$M7*$J7*(1+$Q7*kdo_iadeEtkiCarpani),2)) | O7: =IF($A7="","",ROUND($L7-$N7,2)) | P7: =IF($A7="","",IF($R7>kdo_esikDesiOran,"DESİ DÜŞÜR",IF($O7>kdo_esikTasarruf,"TAŞIYICI DEĞİŞTİR","UYGUN"))) | Q7: =IF($A7="","",IFERROR(SUMIF(tblAnahtarB[NormB],$A7,tblVeriB[IadeOran]),0)) | R7: =IF(OR($A7="",$E7=0),0,$G7/$E7) | S7: =IF($A7="","",$G7-$E7) | T7: =IF($A7="","",$L7-$N7)
A8: =IF('ANAHTAR'!$B8="","",'ANAHTAR'!$B8) | B8: =IF($A8="","",IFERROR(SUMIF(tblAnahtarA[Norm],$A8,tblVeriA[EnCm]),0)) | C8: =IF($A8="","",IFERROR(SUMIF(tblAnahtarA[Norm],$A8,tblVeriA[BoyCm]),0)) | D8: =IF($A8="","",IFERROR(SUMIF(tblAnahtarA[Norm],$A8,tblVeriA[YukseklikCm]),0)) | E8: =IF($A8="","",IFERROR(SUMIF(tblAnahtarA[Norm],$A8,tblVeriA[AgirlikKg]),0)) | F8: =IF($A8="","",IFERROR(SUMIF(tblAnahtarA[Norm],$A8,tblVeriA[DesiCarpani]),kdo_varsayilanDesiCarpani)) | G8: =IF($A8="","",ROUND($B8*$C8*$D8/MAX($F8,1),2)) | H8: =IF($A8="","",MAX($G8,$E8)) | I8: =IF($A8="","",IFERROR(SUMIF(tblAnahtarB[NormB],$A8,tblVeriB[TarifTlDesi]),0)) | J8: =IF($A8="","",IFERROR(SUMIF(tblAnahtarA[Norm],$A8,tblVeriA[Adet]),1)) | K8: =IF($A8="","",ROUND($H8*$I8,2)) | L8: =IF($A8="","",ROUND($K8*$J8*(1+$Q8*kdo_iadeEtkiCarpani),2)) | M8: =IF($A8="","",IFERROR(SUMIF(tblAnahtarB[NormB],$A8,tblVeriB[AlternatifTarif]),0)) | N8: =IF($A8="","",ROUND($H8*$M8*$J8*(1+$Q8*kdo_iadeEtkiCarpani),2)) | O8: =IF($A8="","",ROUND($L8-$N8,2)) | P8: =IF($A8="","",IF($R8>kdo_esikDesiOran,"DESİ DÜŞÜR",IF($O8>kdo_esikTasarruf,"TAŞIYICI DEĞİŞTİR","UYGUN"))) | Q8: =IF($A8="","",IFERROR(SUMIF(tblAnahtarB[NormB],$A8,tblVeriB[IadeOran]),0)) | R8: =IF(OR($A8="",$E8=0),0,$G8/$E8) | S8: =IF($A8="","",$G8-$E8) | T8: =IF($A8="","",$L8-$N8)
A9: =IF('ANAHTAR'!$B9="","",'ANAHTAR'!$B9) | B9: =IF($A9="","",IFERROR(SUMIF(tblAnahtarA[Norm],$A9,tblVeriA[EnCm]),0)) | C9: =IF($A9="","",IFERROR(SUMIF(tblAnahtarA[Norm],$A9,tblVeriA[BoyCm]),0)) | D9: =IF($A9="","",IFERROR(SUMIF(tblAnahtarA[Norm],$A9,tblVeriA[YukseklikCm]),0)) | E9: =IF($A9="","",IFERROR(SUMIF(tblAnahtarA[Norm],$A9,tblVeriA[AgirlikKg]),0)) | F9: =IF($A9="","",IFERROR(SUMIF(tblAnahtarA[Norm],$A9,tblVeriA[DesiCarpani]),kdo_varsayilanDesiCarpani)) | G9: =IF($A9="","",ROUND($B9*$C9*$D9/MAX($F9,1),2)) | H9: =IF($A9="","",MAX($G9,$E9)) | I9: =IF($A9="","",IFERROR(SUMIF(tblAnahtarB[NormB],$A9,tblVeriB[TarifTlDesi]),0)) | J9: =IF($A9="","",IFERROR(SUMIF(tblAnahtarA[Norm],$A9,tblVeriA[Adet]),1)) | K9: =IF($A9="","",ROUND($H9*$I9,2)) | L9: =IF($A9="","",ROUND($K9*$J9*(1+$Q9*kdo_iadeEtkiCarpani),2)) | M9: =IF($A9="","",IFERROR(SUMIF(tblAnahtarB[NormB],$A9,tblVeriB[AlternatifTarif]),0)) | N9: =IF($A9="","",ROUND($H9*$M9*$J9*(1+$Q9*kdo_iadeEtkiCarpani),2)) | O9: =IF($A9="","",ROUND($L9-$N9,2)) | P9: =IF($A9="","",IF($R9>kdo_esikDesiOran,"DESİ DÜŞÜR",IF($O9>kdo_esikTasarruf,"TAŞIYICI DEĞİŞTİR","UYGUN"))) | Q9: =IF($A9="","",IFERROR(SUMIF(tblAnahtarB[NormB],$A9,tblVeriB[IadeOran]),0)) | R9: =IF(OR($A9="",$E9=0),0,$G9/$E9) | S9: =IF($A9="","",$G9-$E9) | T9: =IF($A9="","",$L9-$N9)
A10: =IF('ANAHTAR'!$B10="","",'ANAHTAR'!$B10) | B10: =IF($A10="","",IFERROR(SUMIF(tblAnahtarA[Norm],$A10,tblVeriA[EnCm]),0)) | C10: =IF($A10="","",IFERROR(SUMIF(tblAnahtarA[Norm],$A10,tblVeriA[BoyCm]),0)) | D10: =IF($A10="","",IFERROR(SUMIF(tblAnahtarA[Norm],$A10,tblVeriA[YukseklikCm]),0)) | E10: =IF($A10="","",IFERROR(SUMIF(tblAnahtarA[Norm],$A10,tblVeriA[AgirlikKg]),0)) | F10: =IF($A10="","",IFERROR(SUMIF(tblAnahtarA[Norm],$A10,tblVeriA[DesiCarpani]),kdo_varsayilanDesiCarpani)) | G10: =IF($A10="","",ROUND($B10*$C10*$D10/MAX($F10,1),2)) | H10: =IF($A10="","",MAX($G10,$E10)) | I10: =IF($A10="","",IFERROR(SUMIF(tblAnahtarB[NormB],$A10,tblVeriB[TarifTlDesi]),0)) | J10: =IF($A10="","",IFERROR(SUMIF(tblAnahtarA[Norm],$A10,tblVeriA[Adet]),1)) | K10: =IF($A10="","",ROUND($H10*$I10,2)) | L10: =IF($A10="","",ROUND($K10*$J10*(1+$Q10*kdo_iadeEtkiCarpani),2)) | M10: =IF($A10="","",IFERROR(SUMIF(tblAnahtarB[NormB],$A10,tblVeriB[AlternatifTarif]),0)) | N10: =IF($A10="","",ROUND($H10*$M10*$J10*(1+$Q10*kdo_iadeEtkiCarpani),2)) | O10: =IF($A10="","",ROUND($L10-$N10,2)) | P10: =IF($A10="","",IF($R10>kdo_esikDesiOran,"DESİ DÜŞÜR",IF($O10>kdo_esikTasarruf,"TAŞIYICI DEĞİŞTİR","UYGUN"))) | Q10: =IF($A10="","",IFERROR(SUMIF(tblAnahtarB[NormB],$A10,tblVeriB[IadeOran]),0)) | R10: =IF(OR($A10="",$E10=0),0,$G10/$E10) | S10: =IF($A10="","",$G10-$E10) | T10: =IF($A10="","",$L10-$N10)
A11: =IF('ANAHTAR'!$B11="","",'ANAHTAR'!$B11) | B11: =IF($A11="","",IFERROR(SUMIF(tblAnahtarA[Norm],$A11,tblVeriA[EnCm]),0)) | C11: =IF($A11="","",IFERROR(SUMIF(tblAnahtarA[Norm],$A11,tblVeriA[BoyCm]),0)) | D11: =IF($A11="","",IFERROR(SUMIF(tblAnahtarA[Norm],$A11,tblVeriA[YukseklikCm]),0)) | E11: =IF($A11="","",IFERROR(SUMIF(tblAnahtarA[Norm],$A11,tblVeriA[AgirlikKg]),0)) | F11: =IF($A11="","",IFERROR(SUMIF(tblAnahtarA[Norm],$A11,tblVeriA[DesiCarpani]),kdo_varsayilanDesiCarpani)) | G11: =IF($A11="","",ROUND($B11*$C11*$D11/MAX($F11,1),2)) | H11: =IF($A11="","",MAX($G11,$E11)) | I11: =IF($A11="","",IFERROR(SUMIF(tblAnahtarB[NormB],$A11,tblVeriB[TarifTlDesi]),0)) | J11: =IF($A11="","",IFERROR(SUMIF(tblAnahtarA[Norm],$A11,tblVeriA[Adet]),1)) | K11: =IF($A11="","",ROUND($H11*$I11,2)) | L11: =IF($A11="","",ROUND($K11*$J11*(1+$Q11*kdo_iadeEtkiCarpani),2)) | M11: =IF($A11="","",IFERROR(SUMIF(tblAnahtarB[NormB],$A11,tblVeriB[AlternatifTarif]),0)) | N11: =IF($A11="","",ROUND($H11*$M11*$J11*(1+$Q11*kdo_iadeEtkiCarpani),2)) | O11: =IF($A11="","",ROUND($L11-$N11,2)) | P11: =IF($A11="","",IF($R11>kdo_esikDesiOran,"DESİ DÜŞÜR",IF($O11>kdo_esikTasarruf,"TAŞIYICI DEĞİŞTİR","UYGUN"))) | Q11: =IF($A11="","",IFERROR(SUMIF(tblAnahtarB[NormB],$A11,tblVeriB[IadeOran]),0)) | R11: =IF(OR($A11="",$E11=0),0,$G11/$E11) | S11: =IF($A11="","",$G11-$E11) | T11: =IF($A11="","",$L11-$N11)
A12: =IF('ANAHTAR'!$B12="","",'ANAHTAR'!$B12) | B12: =IF($A12="","",IFERROR(SUMIF(tblAnahtarA[Norm],$A12,tblVeriA[EnCm]),0)) | C12: =IF($A12="","",IFERROR(SUMIF(tblAnahtarA[Norm],$A12,tblVeriA[BoyCm]),0)) | D12: =IF($A12="","",IFERROR(SUMIF(tblAnahtarA[Norm],$A12,tblVeriA[YukseklikCm]),0)) | E12: =IF($A12="","",IFERROR(SUMIF(tblAnahtarA[Norm],$A12,tblVeriA[AgirlikKg]),0)) | F12: =IF($A12="","",IFERROR(SUMIF(tblAnahtarA[Norm],$A12,tblVeriA[DesiCarpani]),kdo_varsayilanDesiCarpani)) | G12: =IF($A12="","",ROUND($B12*$C12*$D12/MAX($F12,1),2)) | H12: =IF($A12="","",MAX($G12,$E12)) | I12: =IF($A12="","",IFERROR(SUMIF(tblAnahtarB[NormB],$A12,tblVeriB[TarifTlDesi]),0)) | J12: =IF($A12="","",IFERROR(SUMIF(tblAnahtarA[Norm],$A12,tblVeriA[Adet]),1)) | K12: =IF($A12="","",ROUND($H12*$I12,2)) | L12: =IF($A12="","",ROUND($K12*$J12*(1+$Q12*kdo_iadeEtkiCarpani),2)) | M12: =IF($A12="","",IFERROR(SUMIF(tblAnahtarB[NormB],$A12,tblVeriB[AlternatifTarif]),0)) | N12: =IF($A12="","",ROUND($H12*$M12*$J12*(1+$Q12*kdo_iadeEtkiCarpani),2)) | O12: =IF($A12="","",ROUND($L12-$N12,2)) | P12: =IF($A12="","",IF($R12>kdo_esikDesiOran,"DESİ DÜŞÜR",IF($O12>kdo_esikTasarruf,"TAŞIYICI DEĞİŞTİR","UYGUN"))) | Q12: =IF($A12="","",IFERROR(SUMIF(tblAnahtarB[NormB],$A12,tblVeriB[IadeOran]),0)) | R12: =IF(OR($A12="",$E12=0),0,$G12/$E12) | S12: =IF($A12="","",$G12-$E12) | T12: =IF($A12="","",$L12-$N12)
A13: =IF('ANAHTAR'!$B13="","",'ANAHTAR'!$B13) | B13: =IF($A13="","",IFERROR(SUMIF(tblAnahtarA[Norm],$A13,tblVeriA[EnCm]),0)) | C13: =IF($A13="","",IFERROR(SUMIF(tblAnahtarA[Norm],$A13,tblVeriA[BoyCm]),0)) | D13: =IF($A13="","",IFERROR(SUMIF(tblAnahtarA[Norm],$A13,tblVeriA[YukseklikCm]),0)) | E13: =IF($A13="","",IFERROR(SUMIF(tblAnahtarA[Norm],$A13,tblVeriA[AgirlikKg]),0)) | F13: =IF($A13="","",IFERROR(SUMIF(tblAnahtarA[Norm],$A13,tblVeriA[DesiCarpani]),kdo_varsayilanDesiCarpani)) | G13: =IF($A13="","",ROUND($B13*$C13*$D13/MAX($F13,1),2)) | H13: =IF($A13="","",MAX($G13,$E13)) | I13: =IF($A13="","",IFERROR(SUMIF(tblAnahtarB[NormB],$A13,tblVeriB[TarifTlDesi]),0)) | J13: =IF($A13="","",IFERROR(SUMIF(tblAnahtarA[Norm],$A13,tblVeriA[Adet]),1)) | K13: =IF($A13="","",ROUND($H13*$I13,2)) | L13: =IF($A13="","",ROUND($K13*$J13*(1+$Q13*kdo_iadeEtkiCarpani),2)) | M13: =IF($A13="","",IFERROR(SUMIF(tblAnahtarB[NormB],$A13,tblVeriB[AlternatifTarif]),0)) | N13: =IF($A13="","",ROUND($H13*$M13*$J13*(1+$Q13*kdo_iadeEtkiCarpani),2)) | O13: =IF($A13="","",ROUND($L13-$N13,2)) | P13: =IF($A13="","",IF($R13>kdo_esikDesiOran,"DESİ DÜŞÜR",IF($O13>kdo_esikTasarruf,"TAŞIYICI DEĞİŞTİR","UYGUN"))) | Q13: =IF($A13="","",IFERROR(SUMIF(tblAnahtarB[NormB],$A13,tblVeriB[IadeOran]),0)) | R13: =IF(OR($A13="",$E13=0),0,$G13/$E13) | S13: =IF($A13="","",$G13-$E13) | T13: =IF($A13="","",$L13-$N13)
A14: =IF('ANAHTAR'!$B14="","",'ANAHTAR'!$B14) | B14: =IF($A14="","",IFERROR(SUMIF(tblAnahtarA[Norm],$A14,tblVeriA[EnCm]),0)) | C14: =IF($A14="","",IFERROR(SUMIF(tblAnahtarA[Norm],$A14,tblVeriA[BoyCm]),0)) | D14: =IF($A14="","",IFERROR(SUMIF(tblAnahtarA[Norm],$A14,tblVeriA[YukseklikCm]),0)) | E14: =IF($A14="","",IFERROR(SUMIF(tblAnahtarA[Norm],$A14,tblVeriA[AgirlikKg]),0)) | F14: =IF($A14="","",IFERROR(SUMIF(tblAnahtarA[Norm],$A14,tblVeriA[DesiCarpani]),kdo_varsayilanDesiCarpani)) | G14: =IF($A14="","",ROUND($B14*$C14*$D14/MAX($F14,1),2)) | H14: =IF($A14="","",MAX($G14,$E14)) | I14: =IF($A14="","",IFERROR(SUMIF(tblAnahtarB[NormB],$A14,tblVeriB[TarifTlDesi]),0)) | J14: =IF($A14="","",IFERROR(SUMIF(tblAnahtarA[Norm],$A14,tblVeriA[Adet]),1)) | K14: =IF($A14="","",ROUND($H14*$I14,2)) | L14: =IF($A14="","",ROUND($K14*$J14*(1+$Q14*kdo_iadeEtkiCarpani),2)) | M14: =IF($A14="","",IFERROR(SUMIF(tblAnahtarB[NormB],$A14,tblVeriB[AlternatifTarif]),0)) | N14: =IF($A14="","",ROUND($H14*$M14*$J14*(1+$Q14*kdo_iadeEtkiCarpani),2)) | O14: =IF($A14="","",ROUND($L14-$N14,2)) | P14: =IF($A14="","",IF($R14>kdo_esikDesiOran,"DESİ DÜŞÜR",IF($O14>kdo_esikTasarruf,"TAŞIYICI DEĞİŞTİR","UYGUN"))) | Q14: =IF($A14="","",IFERROR(SUMIF(tblAnahtarB[NormB],$A14,tblVeriB[IadeOran]),0)) | R14: =IF(OR($A14="",$E14=0),0,$G14/$E14) | S14: =IF($A14="","",$G14-$E14) | T14: =IF($A14="","",$L14-$N14)
A15: =IF('ANAHTAR'!$B15="","",'ANAHTAR'!$B15) | B15: =IF($A15="","",IFERROR(SUMIF(tblAnahtarA[Norm],$A15,tblVeriA[EnCm]),0)) | C15: =IF($A15="","",IFERROR(SUMIF(tblAnahtarA[Norm],$A15,tblVeriA[BoyCm]),0)) | D15: =IF($A15="","",IFERROR(SUMIF(tblAnahtarA[Norm],$A15,tblVeriA[YukseklikCm]),0)) | E15: =IF($A15="","",IFERROR(SUMIF(tblAnahtarA[Norm],$A15,tblVeriA[AgirlikKg]),0)) | F15: =IF($A15="","",IFERROR(SUMIF(tblAnahtarA[Norm],$A15,tblVeriA[DesiCarpani]),kdo_varsayilanDesiCarpani)) | G15: =IF($A15="","",ROUND($B15*$C15*$D15/MAX($F15,1),2)) | H15: =IF($A15="","",MAX($G15,$E15)) | I15: =IF($A15="","",IFERROR(SUMIF(tblAnahtarB[NormB],$A15,tblVeriB[TarifTlDesi]),0)) | J15: =IF($A15="","",IFERROR(SUMIF(tblAnahtarA[Norm],$A15,tblVeriA[Adet]),1)) | K15: =IF($A15="","",ROUND($H15*$I15,2)) | L15: =IF($A15="","",ROUND($K15*$J15*(1+$Q15*kdo_iadeEtkiCarpani),2)) | M15: =IF($A15="","",IFERROR(SUMIF(tblAnahtarB[NormB],$A15,tblVeriB[AlternatifTarif]),0)) | N15: =IF($A15="","",ROUND($H15*$M15*$J15*(1+$Q15*kdo_iadeEtkiCarpani),2)) | O15: =IF($A15="","",ROUND($L15-$N15,2)) | P15: =IF($A15="","",IF($R15>kdo_esikDesiOran,"DESİ DÜŞÜR",IF($O15>kdo_esikTasarruf,"TAŞIYICI DEĞİŞTİR","UYGUN"))) | Q15: =IF($A15="","",IFERROR(SUMIF(tblAnahtarB[NormB],$A15,tblVeriB[IadeOran]),0)) | R15: =IF(OR($A15="",$E15=0),0,$G15/$E15) | S15: =IF($A15="","",$G15-$E15) | T15: =IF($A15="","",$L15-$N15)
A16: =IF('ANAHTAR'!$B16="","",'ANAHTAR'!$B16) | B16: =IF($A16="","",IFERROR(SUMIF(tblAnahtarA[Norm],$A16,tblVeriA[EnCm]),0)) | C16: =IF($A16="","",IFERROR(SUMIF(tblAnahtarA[Norm],$A16,tblVeriA[BoyCm]),0)) | D16: =IF($A16="","",IFERROR(SUMIF(tblAnahtarA[Norm],$A16,tblVeriA[YukseklikCm]),0)) | E16: =IF($A16="","",IFERROR(SUMIF(tblAnahtarA[Norm],$A16,tblVeriA[AgirlikKg]),0)) | F16: =IF($A16="","",IFERROR(SUMIF(tblAnahtarA[Norm],$A16,tblVeriA[DesiCarpani]),kdo_varsayilanDesiCarpani)) | G16: =IF($A16="","",ROUND($B16*$C16*$D16/MAX($F16,1),2)) | H16: =IF($A16="","",MAX($G16,$E16)) | I16: =IF($A16="","",IFERROR(SUMIF(tblAnahtarB[NormB],$A16,tblVeriB[TarifTlDesi]),0)) | J16: =IF($A16="","",IFERROR(SUMIF(tblAnahtarA[Norm],$A16,tblVeriA[Adet]),1)) | K16: =IF($A16="","",ROUND($H16*$I16,2)) | L16: =IF($A16="","",ROUND($K16*$J16*(1+$Q16*kdo_iadeEtkiCarpani),2)) | M16: =IF($A16="","",IFERROR(SUMIF(tblAnahtarB[NormB],$A16,tblVeriB[AlternatifTarif]),0)) | N16: =IF($A16="","",ROUND($H16*$M16*$J16*(1+$Q16*kdo_iadeEtkiCarpani),2)) | O16: =IF($A16="","",ROUND($L16-$N16,2)) | P16: =IF($A16="","",IF($R16>kdo_esikDesiOran,"DESİ DÜŞÜR",IF($O16>kdo_esikTasarruf,"TAŞIYICI DEĞİŞTİR","UYGUN"))) | Q16: =IF($A16="","",IFERROR(SUMIF(tblAnahtarB[NormB],$A16,tblVeriB[IadeOran]),0)) | R16: =IF(OR($A16="",$E16=0),0,$G16/$E16) | S16: =IF($A16="","",$G16-$E16) | T16: =IF($A16="","",$L16-$N16)
A17: =IF('ANAHTAR'!$B17="","",'ANAHTAR'!$B17) | B17: =IF($A17="","",IFERROR(SUMIF(tblAnahtarA[Norm],$A17,tblVeriA[EnCm]),0)) | C17: =IF($A17="","",IFERROR(SUMIF(tblAnahtarA[Norm],$A17,tblVeriA[BoyCm]),0)) | D17: =IF($A17="","",IFERROR(SUMIF(tblAnahtarA[Norm],$A17,tblVeriA[YukseklikCm]),0)) | E17: =IF($A17="","",IFERROR(SUMIF(tblAnahtarA[Norm],$A17,tblVeriA[AgirlikKg]),0)) | F17: =IF($A17="","",IFERROR(SUMIF(tblAnahtarA[Norm],$A17,tblVeriA[DesiCarpani]),kdo_varsayilanDesiCarpani)) | G17: =IF($A17="","",ROUND($B17*$C17*$D17/MAX($F17,1),2)) | H17: =IF($A17="","",MAX($G17,$E17)) | I17: =IF($A17="","",IFERROR(SUMIF(tblAnahtarB[NormB],$A17,tblVeriB[TarifTlDesi]),0)) | J17: =IF($A17="","",IFERROR(SUMIF(tblAnahtarA[Norm],$A17,tblVeriA[Adet]),1)) | K17: =IF($A17="","",ROUND($H17*$I17,2)) | L17: =IF($A17="","",ROUND($K17*$J17*(1+$Q17*kdo_iadeEtkiCarpani),2)) | M17: =IF($A17="","",IFERROR(SUMIF(tblAnahtarB[NormB],$A17,tblVeriB[AlternatifTarif]),0)) | N17: =IF($A17="","",ROUND($H17*$M17*$J17*(1+$Q17*kdo_iadeEtkiCarpani),2)) | O17: =IF($A17="","",ROUND($L17-$N17,2)) | P17: =IF($A17="","",IF($R17>kdo_esikDesiOran,"DESİ DÜŞÜR",IF($O17>kdo_esikTasarruf,"TAŞIYICI DEĞİŞTİR","UYGUN"))) | Q17: =IF($A17="","",IFERROR(SUMIF(tblAnahtarB[NormB],$A17,tblVeriB[IadeOran]),0)) | R17: =IF(OR($A17="",$E17=0),0,$G17/$E17) | S17: =IF($A17="","",$G17-$E17) | T17: =IF($A17="","",$L17-$N17)
... A505: =IF('ANAHTAR'!$B505="","",'ANAHTAR'!$B505) | B505: =IF($A505="","",IFERROR(SUMIF(tblAnahtarA[Norm],$A505,tblVeriA[EnCm]),0)) | C505: =IF($A505="","",IFERROR(SUMIF(tblAnahtarA[Norm],$A505,tblVeriA[BoyCm]),0)) | D505: =IF($A505="","",IFERROR(SUMIF(tblAnahtarA[Norm],$A505,tblVeriA[YukseklikCm]),0)) | E505: =IF($A505="","",IFERROR(SUMIF(tblAnahtarA[Norm],$A505,tblVeriA[AgirlikKg]),0)) | F505: =IF($A505="","",IFERROR(SUMIF(tblAnahtarA[Norm],$A505,tblVeriA[DesiCarpani]),kdo_varsayilanDesiCarpani)) | G505: =IF($A505="","",ROUND($B505*$C505*$D505/MAX($F505,1),2)) | H505: =IF($A505="","",MAX($G505,$E505)) | I505: =IF($A505="","",IFERROR(SUMIF(tblAnahtarB[NormB],$A505,tblVeriB[TarifTlDesi]),0)) | J505: =IF($A505="","",IFERROR(SUMIF(tblAnahtarA[Norm],$A505,tblVeriA[Adet]),1)) | K505: =IF($A505="","",ROUND($H505*$I505,2)) | L505: =IF($A505="","",ROUND($K505*$J505*(1+$Q505*kdo_iadeEtkiCarpani),2)) | M505: =IF($A505="","",IFERROR(SUMIF(tblAnahtarB[NormB],$A505,tblVeriB[AlternatifTarif]),0)) | N505: =IF($A505="","",ROUND($H505*$M505*$J505*(1+$Q505*kdo_iadeEtkiCarpani),2)) | O505: =IF($A505="","",ROUND($L505-$N505,2)) | P505: =IF($A505="","",IF($R505>kdo_esikDesiOran,"DESİ DÜŞÜR",IF($O505>kdo_esikTasarruf,"TAŞIYICI DEĞİŞTİR","UYGUN"))) | Q505: =IF($A505="","",IFERROR(SUMIF(tblAnahtarB[NormB],$A505,tblVeriB[IadeOran]),0)) | R505: =IF(OR($A505="",$E505=0),0,$G505/$E505) | S505: =IF($A505="","",$G505-$E505) | T505: =IF($A505="","",$L505-$N505)

Sheet ESLESTIRME
A1: ESLESTIRME — Kargo/Desi Maliyet Optimizasyonu
A2: Kova Bütünlük Denetimi | C2: =IF(COUNTIF(tblEslesme[Kova],"eslesti")+COUNTIF(tblEslesme[Kova],"tolerans_icinde")+COUNTIF(tblEslesme[Kova],"tutar_farki")+COUNTIF(tblEslesme[Kova],"eslesmedi")=COUNTA(tblEslesme[A_Norm]),"BUTUN","KAYIP")
A3: Hedef maliyet ↔ gerçek maliyet dört kova — her A kaydı tek kovaya (E02)
A5: A_Norm | B5: B_Sayim | C5: B_Tutar | D5: A_Tutar | E5: Fark | F5: AbsFark | G5: Kova | H5: IkincilEslesme | I5: DuplikeBayrak | J5: FarkOran | K5: YuvarlakA | L5: YuvarlakB | M5: ToleransTest | N5: EsikUstu | O5: SiparisToplam | P5: MotorAdim
A6: =IF('ANAHTAR'!$B6="","",'ANAHTAR'!$B6) | B6: =IF($A6="","",COUNTIF(tblAnahtarB[NormB],$A6)) | C6: =IF($A6="","",IFERROR(SUMIF(tblMotor[A_Norm],$A6,tblMotor[SiparisToplam]),0)) | D6: =IF($A6="","",IFERROR(SUMIF(tblAnahtarA[Norm],$A6,tblVeriA[HedefMaliyet]),0)) | E6: =IF($A6="","",ROUND($D6,2)-ROUND($C6,2)) | F6: =IF($A6="","",ABS($E6)) | G6: =IF($A6="","",IF($B6=0,"eslesmedi",IF(ROUND($D6,2)=ROUND($C6,2),"eslesti",IF(ABS(ROUND($D6,2)-ROUND($C6,2))<=toleransKurus,"tolerans_icinde","tutar_farki")))) | H6: =IF($A6="","",IF($B6>0,"BIRINCIL",IF(COUNTIF(tblAnahtarB[IkincilB],'ANAHTAR'!$D6)>0,"IKINCIL","YOK"))) | I6: =IF($A6="","",'ANAHTAR'!$F6) | J6: =IF(OR($A6="",$D6=0),0,$F6/ABS($D6)) | K6: =IF($A6="","",ROUND($D6,2)) | L6: =IF($A6="","",ROUND($C6,2)) | M6: =IF($A6="","",IF($F6<=toleransKurus,1,0)) | N6: =IF($A6="","",IF($F6>kdo_esikFark,1,0)) | O6: =IF($A6="","",IFERROR(SUMIF(tblMotor[A_Norm],$A6,tblMotor[SiparisToplam]),0)) | P6: =IF($A6="","",$B6+$M6+$N6)
A7: =IF('ANAHTAR'!$B7="","",'ANAHTAR'!$B7) | B7: =IF($A7="","",COUNTIF(tblAnahtarB[NormB],$A7)) | C7: =IF($A7="","",IFERROR(SUMIF(tblMotor[A_Norm],$A7,tblMotor[SiparisToplam]),0)) | D7: =IF($A7="","",IFERROR(SUMIF(tblAnahtarA[Norm],$A7,tblVeriA[HedefMaliyet]),0)) | E7: =IF($A7="","",ROUND($D7,2)-ROUND($C7,2)) | F7: =IF($A7="","",ABS($E7)) | G7: =IF($A7="","",IF($B7=0,"eslesmedi",IF(ROUND($D7,2)=ROUND($C7,2),"eslesti",IF(ABS(ROUND($D7,2)-ROUND($C7,2))<=toleransKurus,"tolerans_icinde","tutar_farki")))) | H7: =IF($A7="","",IF($B7>0,"BIRINCIL",IF(COUNTIF(tblAnahtarB[IkincilB],'ANAHTAR'!$D7)>0,"IKINCIL","YOK"))) | I7: =IF($A7="","",'ANAHTAR'!$F7) | J7: =IF(OR($A7="",$D7=0),0,$F7/ABS($D7)) | K7: =IF($A7="","",ROUND($D7,2)) | L7: =IF($A7="","",ROUND($C7,2)) | M7: =IF($A7="","",IF($F7<=toleransKurus,1,0)) | N7: =IF($A7="","",IF($F7>kdo_esikFark,1,0)) | O7: =IF($A7="","",IFERROR(SUMIF(tblMotor[A_Norm],$A7,tblMotor[SiparisToplam]),0)) | P7: =IF($A7="","",$B7+$M7+$N7)
A8: =IF('ANAHTAR'!$B8="","",'ANAHTAR'!$B8) | B8: =IF($A8="","",COUNTIF(tblAnahtarB[NormB],$A8)) | C8: =IF($A8="","",IFERROR(SUMIF(tblMotor[A_Norm],$A8,tblMotor[SiparisToplam]),0)) | D8: =IF($A8="","",IFERROR(SUMIF(tblAnahtarA[Norm],$A8,tblVeriA[HedefMaliyet]),0)) | E8: =IF($A8="","",ROUND($D8,2)-ROUND($C8,2)) | F8: =IF($A8="","",ABS($E8)) | G8: =IF($A8="","",IF($B8=0,"eslesmedi",IF(ROUND($D8,2)=ROUND($C8,2),"eslesti",IF(ABS(ROUND($D8,2)-ROUND($C8,2))<=toleransKurus,"tolerans_icinde","tutar_farki")))) | H8: =IF($A8="","",IF($B8>0,"BIRINCIL",IF(COUNTIF(tblAnahtarB[IkincilB],'ANAHTAR'!$D8)>0,"IKINCIL","YOK"))) | I8: =IF($A8="","",'ANAHTAR'!$F8) | J8: =IF(OR($A8="",$D8=0),0,$F8/ABS($D8)) | K8: =IF($A8="","",ROUND($D8,2)) | L8: =IF($A8="","",ROUND($C8,2)) | M8: =IF($A8="","",IF($F8<=toleransKurus,1,0)) | N8: =IF($A8="","",IF($F8>kdo_esikFark,1,0)) | O8: =IF($A8="","",IFERROR(SUMIF(tblMotor[A_Norm],$A8,tblMotor[SiparisToplam]),0)) | P8: =IF($A8="","",$B8+$M8+$N8)
A9: =IF('ANAHTAR'!$B9="","",'ANAHTAR'!$B9) | B9: =IF($A9="","",COUNTIF(tblAnahtarB[NormB],$A9)) | C9: =IF($A9="","",IFERROR(SUMIF(tblMotor[A_Norm],$A9,tblMotor[SiparisToplam]),0)) | D9: =IF($A9="","",IFERROR(SUMIF(tblAnahtarA[Norm],$A9,tblVeriA[HedefMaliyet]),0)) | E9: =IF($A9="","",ROUND($D9,2)-ROUND($C9,2)) | F9: =IF($A9="","",ABS($E9)) | G9: =IF($A9="","",IF($B9=0,"eslesmedi",IF(ROUND($D9,2)=ROUND($C9,2),"eslesti",IF(ABS(ROUND($D9,2)-ROUND($C9,2))<=toleransKurus,"tolerans_icinde","tutar_farki")))) | H9: =IF($A9="","",IF($B9>0,"BIRINCIL",IF(COUNTIF(tblAnahtarB[IkincilB],'ANAHTAR'!$D9)>0,"IKINCIL","YOK"))) | I9: =IF($A9="","",'ANAHTAR'!$F9) | J9: =IF(OR($A9="",$D9=0),0,$F9/ABS($D9)) | K9: =IF($A9="","",ROUND($D9,2)) | L9: =IF($A9="","",ROUND($C9,2)) | M9: =IF($A9="","",IF($F9<=toleransKurus,1,0)) | N9: =IF($A9="","",IF($F9>kdo_esikFark,1,0)) | O9: =IF($A9="","",IFERROR(SUMIF(tblMotor[A_Norm],$A9,tblMotor[SiparisToplam]),0)) | P9: =IF($A9="","",$B9+$M9+$N9)
A10: =IF('ANAHTAR'!$B10="","",'ANAHTAR'!$B10) | B10: =IF($A10="","",COUNTIF(tblAnahtarB[NormB],$A10)) | C10: =IF($A10="","",IFERROR(SUMIF(tblMotor[A_Norm],$A10,tblMotor[SiparisToplam]),0)) | D10: =IF($A10="","",IFERROR(SUMIF(tblAnahtarA[Norm],$A10,tblVeriA[HedefMaliyet]),0)) | E10: =IF($A10="","",ROUND($D10,2)-ROUND($C10,2)) | F10: =IF($A10="","",ABS($E10)) | G10: =IF($A10="","",IF($B10=0,"eslesmedi",IF(ROUND($D10,2)=ROUND($C10,2),"eslesti",IF(ABS(ROUND($D10,2)-ROUND($C10,2))<=toleransKurus,"tolerans_icinde","tutar_farki")))) | H10: =IF($A10="","",IF($B10>0,"BIRINCIL",IF(COUNTIF(tblAnahtarB[IkincilB],'ANAHTAR'!$D10)>0,"IKINCIL","YOK"))) | I10: =IF($A10="","",'ANAHTAR'!$F10) | J10: =IF(OR($A10="",$D10=0),0,$F10/ABS($D10)) | K10: =IF($A10="","",ROUND($D10,2)) | L10: =IF($A10="","",ROUND($C10,2)) | M10: =IF($A10="","",IF($F10<=toleransKurus,1,0)) | N10: =IF($A10="","",IF($F10>kdo_esikFark,1,0)) | O10: =IF($A10="","",IFERROR(SUMIF(tblMotor[A_Norm],$A10,tblMotor[SiparisToplam]),0)) | P10: =IF($A10="","",$B10+$M10+$N10)
A11: =IF('ANAHTAR'!$B11="","",'ANAHTAR'!$B11) | B11: =IF($A11="","",COUNTIF(tblAnahtarB[NormB],$A11)) | C11: =IF($A11="","",IFERROR(SUMIF(tblMotor[A_Norm],$A11,tblMotor[SiparisToplam]),0)) | D11: =IF($A11="","",IFERROR(SUMIF(tblAnahtarA[Norm],$A11,tblVeriA[HedefMaliyet]),0)) | E11: =IF($A11="","",ROUND($D11,2)-ROUND($C11,2)) | F11: =IF($A11="","",ABS($E11)) | G11: =IF($A11="","",IF($B11=0,"eslesmedi",IF(ROUND($D11,2)=ROUND($C11,2),"eslesti",IF(ABS(ROUND($D11,2)-ROUND($C11,2))<=toleransKurus,"tolerans_icinde","tutar_farki")))) | H11: =IF($A11="","",IF($B11>0,"BIRINCIL",IF(COUNTIF(tblAnahtarB[IkincilB],'ANAHTAR'!$D11)>0,"IKINCIL","YOK"))) | I11: =IF($A11="","",'ANAHTAR'!$F11) | J11: =IF(OR($A11="",$D11=0),0,$F11/ABS($D11)) | K11: =IF($A11="","",ROUND($D11,2)) | L11: =IF($A11="","",ROUND($C11,2)) | M11: =IF($A11="","",IF($F11<=toleransKurus,1,0)) | N11: =IF($A11="","",IF($F11>kdo_esikFark,1,0)) | O11: =IF($A11="","",IFERROR(SUMIF(tblMotor[A_Norm],$A11,tblMotor[SiparisToplam]),0)) | P11: =IF($A11="","",$B11+$M11+$N11)
