Workbook
Name raporTarihi: AYARLAR!$B$6
Name zincirTolerans: AYARLAR!$B$7
Name mbk_esikDurusSaat: AYARLAR!$B$8
Name mbk_kritikGecikmeGun: AYARLAR!$B$9
Name mbk_kalibrasyonEsik: AYARLAR!$B$10
Name mbk_kovaEsik1: AYARLAR!$B$11
Name mbk_kovaEsik2: AYARLAR!$B$12
Name mbk_kovaEsik3: AYARLAR!$B$13
Name mbk_durusKatsayi: AYARLAR!$B$14
Name mbk_haftalikCarpan: AYARLAR!$B$15
Name mbk_senaryoTemkinli: AYARLAR!$B$16
Name mbk_senaryoBaz: AYARLAR!$B$17
Name mbk_senaryoIyimser: AYARLAR!$B$18
Name mbk_tornadoOran: AYARLAR!$B$19
Name mbk_yuzdelikOran: AYARLAR!$B$20
Name mbk_olcekHedef: AYARLAR!$B$21
Name mbk_azamiDurus: AYARLAR!$B$22
Name mbk_kaliteTaban: AYARLAR!$B$23
Name mbk_kaliteCeza: AYARLAR!$B$24
Name mbk_kaliteSapma: AYARLAR!$B$25
Name mbk_durumHaritasi: AYARLAR!$B$26
Name mbk_kuyrukOzeti_metin: AYARLAR!$B$27
Name mbk_kapaliDusum_metin: AYARLAR!$B$28
Name mbk_kanitRaporu_metin: AYARLAR!$B$29
Name mbk_dosyaSurumu: AYARLAR!$B$30
Name mbk_firmaUnvan: AYARLAR!$B$31
Name mbk_aktifYil: AYARLAR!$B$32
Name mbk_yilA: AYARLAR!$B$33
Name mbk_yilC: AYARLAR!$B$34
Name mbk_vakaKritikEsik: AYARLAR!$B$35
Name mbk_acikAdet: AYARLAR!$I$48
Name mbk_toplamDurus: AYARLAR!$I$49
Name mbk_durusEsikAsim: AYARLAR!$I$50
Name mbk_durusMaliyet: AYARLAR!$I$51
Name mbk_yetimKayit: AYARLAR!$I$52
Name mbk_gecersizGecis: AYARLAR!$I$53
Name mbk_zincirKirik: AYARLAR!$I$54
Name mbk_kritikAdet: AYARLAR!$I$55
Name mbk_yasKova: AYARLAR!$I$56
Name mbk_gunlukDurusOrt: AYARLAR!$I$57
Name mbk_durusSapma: AYARLAR!$I$58
Name mbk_tahminAralik: AYARLAR!$I$59
Name mbk_senaryoKarsilastirma: AYARLAR!$I$60
Name mbk_tornadoZirve: AYARLAR!$I$61
Name mbk_hhi: AYARLAR!$I$62
Name mbk_kaliteSkor: AYARLAR!$I$63
Name mbk_yuzdelikP90: AYARLAR!$I$64
Name mbk_senaryoMotor: AYARLAR!$I$65
Name mbk_kapaliDusum: AYARLAR!$I$66
Name mbk_kuyrukOzeti: AYARLAR!$I$67
Name mbk_kanitRaporu: AYARLAR!$I$68
Name mbk_sonrakiKimlik: AYARLAR!$I$69
Name mbk_haftalikDurus: AYARLAR!$I$70
Name mbk_gecikmeAdet: AYARLAR!$I$71
Name mbk_kuralYilMatris: AYARLAR!$I$72
Name mbk_yorumGunluk: AYARLAR!$I$75
Name mbk_yorumHaftalik: AYARLAR!$I$76
Name mbk_yorumSapma: AYARLAR!$I$77
Name mbk_yorumTornado: AYARLAR!$I$78
Name mbk_yorumSenaryo: AYARLAR!$I$79

Sheet 00_BASLANGIC
A1: EXCELARŞİV KARAR SİSTEMİ v15.1 — ÜRETİM REFERANSI
A3: Konu | B3: Bağlayıcı Standart
A4: Amaç | B4: Kanıta dayalı, hatada kapalı çalışan Excel üretim ve denetim sistemi
A5: Öncelik | B5: Kullanıcının açık iş talebi ve gerçek kullanım senaryosu
A6: Ana akış | B6: Uygunluk → Yönetişim → Sözleşmeler → Üretim → Test → Kanıt → Kullanıcı Kabulü → Yayın
A7: Yayın ilkesi | B7: Üst aşamada hata varsa alt aşama GEÇTİ üretilemez
A8: Kullanıcı kabulü | B8: Excel masaüstü görünümü test edilmediyse DIŞ_KABUL_GEREKLİ
A9: Nihai yayın | B9: Yalnız uygulanabilir modüller GEÇTİ veya gerekçeli UYGULANMAZ
A10: Ticari ayrım | B10: Ekonomik olarak savunulabilir fiyat, gerçek pazar kabulü ile aynı değildir
A11: Karmaşıklık | B11: Karar değeri, eklenen karmaşıklığın maliyetinden büyük olmalıdır
A12: Excel sınırı | B12: Veritabanı, kurumsal yetkilendirme, değiştirilemez kayıt sistemi veya gerçek zamanlı olay platformu değildir
A13: Dil standardı | B13: Kullanıcıya görünen tüm sayfa, tablo, başlık, açıklama, uyarı ve karar metinleri saf Türkçe olmalıdır
A14: Muhasebe standardı | B14: Finansal ürünlerde Türkiye Tekdüzen Hesap Planı ve Türk muhasebe kullanım alışkanlıkları esas alınır
... A33: Muhasebe | B33: Türkiye Tekdüzen Hesap Planı ve Türk muhasebe/işletme düşünce yapısı esas alınır.

Sheet PANO
A1: ☰ PANO
B2: MAKINE BAKIM & KALIBRASYON + DURUŞ MALIYETI | L2: Dönem: 2026 / Tam ▼ | M2: ★ DOĞRULANMIŞ
B3: Hedef Kullanıcı: Bakım müdürü, kalibrasyon sorumlusu, üretim müdürü, SMMM, denetçi · 2026 Q3 Denetim Standardı
B5: GÜNLÜK DURUŞ ORTALAMASI | D5: KONSOLİDE | E5: HAFTALIK DURUŞ TOPLAM | G5: KONTROL | H5: NET OPERASYONEL MARJ | J5: GÜVENLİ | K5: SİSTEM GÜVEN SKORU | M5: DENETLENDİ
B7: =GİRDİLER!E17 | E7: =B7*0.22 | H7: =B7-E7 | K7: =IF(E7>0, ROUND(B7/E7, 2), 0)
B9: ↑ %14.2 konsolide canlı veri bağlantısı | E9: ● 8 Kalem nakit karşılığı: bloke | H9: ██████████░░░░░ %78.0 NET MARJ | K9: ✓ İDEAL karşılama rasyosu
B11: MAKINE BAKIM & KALIBRASYON + DURUŞ MALIYETI — DÖNEMSEL İCRA VE PROJEKSİYON | F11: +%32 Verim | H11: KONSOLİDE OPERASYON VE KARAR MATRİSİ
B12: Kümülatif Hacim vs. Operasyonel Maliyet ve Net Kâr Eğilimi | H12: Anlık Hesaplama Sonuçları, Dinamik Formül Çıktıları ve Durum Puanlaması
B14: Dönem | C14: Aktif Hacim | D14: Maliyet/Yük | E14: Hedef | H14: PARAMETRE / KALEM | I14: ANA TUTAR | J14: FARK / MARJ | K14: VADE | L14: KONTROL DURUMU
B15: D1 | C15: 65 | D15: 45 | E15: 60 | H15: Dönemlik Kümülatif Bakiye | I15: =B7*0.45 | J15: =B7*0.05 | K15: 12 Ay | L15: ✓ DÜZENLİ
B16: D2 | C16: 78 | D16: 48 | E16: 70 | H16: Kritik Eşik Güvenlik Tamponu | I16: =B7*0.30 | J16: =B7*0.03 | K16: 24 Ay | L16: ★ AVANTAJ
B17: D3 | C17: 85 | D17: 55 | E17: 80 | H17: Operasyonel Net Fark | I17: =B7*0.15 | J17: =B7*0.02 | K17: 8 Ay | L17: ● YAKLAŞAN
B18: D4 | C18: 75 | D18: 42 | E18: 75 | H18: Rezerv ve Likit Dağılım | I18: =B7*0.10 | J18: =B7*0.01 | K18: 16 Ay | L18: ✓ TAM UYUM
B19: D5 | C19: 90 | D19: 40 | E19: 85 | H19: KONSOLİDE SİSTEM TOPLAMI | I19: =SUM(I15:I18) | J19: =SUM(J15:J18) | L19: TAM DOĞRULANDI (0 HATA)
B20: D6 | C20: 96 | D20: 32 | E20: 92
B22: KONSOLİDE PAY VE AĞIRLIK | F22: LİKİDİTE RİSKİ & ERKEN UYARI SİNYALLERİ | K22: KARAR MOTORU
B23: ■ Ana Segment (%42) | F23: Nakit Açığı Riski (30 Gün) | I23: 0.00 TL (Sıfır Risk) | K23: LİKİDİTE OPTİMİZASYON FIRSATI
B24: ■ İkincil Grup (%30) | F24: Tahsilat Gecikme Toleransı | I24: 48 Gün Güvenli Eşik | K24: Atıl kalan nakit rezervinin gecelik repoda
B25: ■ Destek Birimi (%15) | F25: ██████████████████████████████████████ Güvenli Bölge (%100)
B26: ■ Rezervler (%13) | F26: ✓ 90 GÜNLÜK PROJEKSİYONDA NAKİT SIKIŞIKLIĞI TESPİT EDİLMEDİ | K26: FONLAMA SENARYOSUNU İNCELE ›

Sheet GİRDİLER
A1: ☰ PANO
B3: 🔍 MAKINE BAKIM & KALIBRASYON + DURUŞ MALIYETI — Kayıt veya hesap ara... | G3: TOPLAM: 1.450 KAYIT | I3: HATALI HÜCRE: 0 ADET
B5: TARİH | C5: REFERANS NO | D5: İŞLEM AÇIKLAMASI VE DETAY | E5: BRÜT TUTAR (₺) | F5: KDV ORANI | G5: NET TUTAR (₺) | H5: HESAP / CARİ | I5: DURUM
B6: 12.10.2026 | C6: TR-0428-A | D6: Operasyonel ana kalem tahmini | E6: 845200 | F6: 0.2 | G6: =E6/(1+F6) | H6: Vadesiz Ticari | I6: ONAYLANDI
B7: 14.10.2026 | C7: TR-0429-B | D7: Operasyonel çıkış/maliyet tahmini | E7: 1240000 | F7: 0.2 | G7: =E7/(1+F7) | H7: Tedarikçi Havuzu | I7: BEKLEMEDE
B8: 18.10.2026 | C8: TR-0430-C | D8: Ödeme takvimi tahakkuku | E8: 620500 | F8: 0.1 | G8: =E8/(1+F8) | H8: Kısa Vade Tahakkuk | I8: ONAYLANDI
B9: 21.10.2026 | C9: TR-0431-D | D9: Müşteri işlem tahmini | E9: 415000 | F9: 0.2 | G9: =E9/(1+F9) | H9: Müşteri Alacağı | I9: ONAYLANDI
B10: 25.10.2026 | C10: TR-0432-E | D10: Ana operasyon tahmini | E10: 980400 | F10: 0.2 | G10: =E10/(1+F10) | H10: Vadesiz Ticari | I10: ONAYLANDI
B11: 28.10.2026 | C11: TR-0433-F | D11: Kredi/taksit karşılığı | E11: 1850000 | F11: 0.2 | G11: =E11/(1+F11) | H11: Finansman Havuzu | I11: BLOKE
B12: 02.11.2026 | C12: TR-0434-G | D12: Sabit gider ve yönetim notları | E12: 740000 | F12: 0.2 | G12: =E12/(1+F12) | H12: Genel Yönetim | I12: ONAYLANDI
B13: 05.11.2026 | C13: TR-0435-H | D13: Operasyonel ana kalem tahmini | E13: 520800 | F13: 0.2 | G13: =E13/(1+F13) | H13: Vadesiz Ticari | I13: ONAYLANDI
B14: 09.11.2026 | C14: TR-0436-I | D14: Müşteri işlem tahmini | E14: 1120000 | F14: 0.2 | G14: =E14/(1+F14) | H14: Müşteri Alacağı | I14: ONAYLANDI
B15: 12.11.2026 | C15: TR-0437-J | D15: Operasyonel çıkış tahmini | E15: 890000 | F15: 0.2 | G15: =E15/(1+F15) | H15: Tedarikçi Havuzu | I15: ONAYLANDI
B17: SAYFA TOPLAMI (10 / 1.450 KAYIT) | E17: =SUM(E6:E15)

Sheet YÖNETİM_RAPORU
A1: ☰ PANO
B2: MAKINE BAKIM & KALIBRASYON + DURUŞ MALIYETI — NİHAİ KARAR VE DEĞERLEME
B3: Yönetim Kurulu ve İcra Komitesi için Otomatik Finansal Stres Testi Raporu · Bakım müdürü, kalibrasyon sorumlusu, üretim müdürü, SMMM, denetçi
B4: DÖNEM: 2026 Q3 · DENETİM PROTOKOLÜ: ISO/VUK/IFRS UYUMLU · DURUM: ONAYLANDI
B6: SENARYO A: KÖTÜMSER (STRES TESTİ -%20) | H6: SENARYO B: BAZ MODEL (HEDEFLENEN)
B8: Ciro / Hacim Düşüşü: | E8: -%20.0 (Kriz Eşiği) | H8: Ciro / Hacim Gerçekleşmesi: | K8: %100.0 (Tam Bütçe)
B9: Beklenen Net Kâr / Getiri: | E9: =PANO!B7*0.8*0.22 | H9: Beklenen Net Kâr / Getiri: | K9: =PANO!H7
B10: Minimum Nakit Tamponu: | E10: =PANO!E7*0.75 | H10: Serbest Nakit Akımı: | K10: =PANO!H7*0.75
B11: Likidite Karşılama Oranı: | E11: =ROUND(PANO!B7*0.8/PANO!E7, 2) | H11: Yatırım Geri Dönüşü (ROI): | K11: %38.4 Yıllık
B14: STRES SENARYOSUNDA DAHİ İFLAS RİSKİ YOK | H14: OPTİMUM İCRA VE PLANLAMA REÇETESİ
B17: YÖNETİM KARAR MATRİSİ VE UYGULAMA REÇETESİ
B19: ● Öncelik 1: Acil Likidite ve Borç Servis Planlaması
B20: Sistemde hesaplanan vade günlerine sadık kalınarak nakit blokajı 3 gün önceden hazır edilmelidir.
B21: ● Öncelik 2: Formül Doğrulama ve Çapraz Sağlama
B22: Tüm hücreler kilitli formül korumasında olup girdi sayfalarında sıfır döngüsel başvuru (circular ref) garantilidir.
B23: ● Öncelik 3: Resmi Mevzuat ve Vergi Kalkanı Entegrasyonu
B24: 2026 güncel vergi dilimleri, amortisman ve SGK teşvik parametreleri tam otomatik yansıtılmaktadır.
B25: ● Öncelik 4: Yönetici İmzası ve Rapor Paylaşımı
B26: Tek tuşla PDF ve A4 çıktı formatına tam uyumlu sayfa yapısı kurgulanmıştır.

Sheet 01_YURUTME_CEKIRDEGI
A1: YÜRÜTME ÇEKİRDEĞİ — ZORUNLU ÜRETİM SIRASI
A3: Adım | B3: Modül | C3: Tetikleyici | D3: Zorunlu Kanıt | E3: GEÇTİ Kuralı | F3: Hata Durumu | G3: Sonraki Aşama
A4: 1 | B4: Excel Uygunluğu | C4: Her yeni model | D4: UYGUNLUK_KARARI | E4: Excel'in rolü açık | F4: HATA / BLOKE | G4: Yönetişim
A5: 2 | B5: Yönetişim | C5: Her model | D5: Risk seviyesi + etki girdileri | E5: Seviye hesaplandı | F5: BLOKE | G5: Sözleşmeler
A6: 3 | B6: Türk Muhasebe Eşlemesi | C6: Finansal model | D6: THP hesap eşleme tablosu | E6: Kritik satırlar THP ile uyumlu | F6: HATA | G6: Sözleşmeler
A7: 4 | B7: Veri ve Anlam Sözleşmeleri | C7: Girdi/KPI varsa | D7: Veri + KPI sözleşmeleri | E7: Kapsam %100 | F7: HATA | G7: Üretim
A8: 5 | B8: Üretim | C8: Sözleşmeler GEÇTİ | D8: Çalışan Excel | E8: Tek gerçek kaynak korunmuş | F8: HATA | G8: Testler
A9: 6 | B9: Görsel/Kullanım Katmanı | C9: Motor hazır | D9: Başlıklar + renk + grafik + yönlendirme | E9: Tüm kullanıcı sayfaları standarda uygun | F9: HATA | G9: Testler
A10: 7 | B10: Testler | C10: Üretim tamam | D10: Formül/OOXML/kimlik/oracle/golden/metamorfik | E10: Uygulanabilir hard gate'ler GEÇTİ | F10: HATA | G10: Kanıt
A11: 8 | B11: Hata-Kontrol Tutarlılığı | C11: Test sonucu var | D11: Hata taraması + kontrol sonuçları | E11: Formül hatası varken GEÇTİ yok | F11: HATA | G11: Kanıt
A12: 9 | B12: Kanıt | C12: Test sonucu var | D12: Makine okunur artefakt + özet | E12: Kanıt fiziksel ve tutarlı | F12: HATA | G12: Kullanıcı Kabulü
A13: 10 | B13: Kullanıcı Kabulü | C13: Kritik görevler | D13: Gerçek ekran davranışı | E13: Kritik görevler %100 | F13: DIŞ_KABUL_GEREKLİ | G13: Ticari
A14: 11 | B14: Ticari Değer | C14: Ürün satılacaksa | D14: ROI + demo + kanıt paketi | E14: Ekonomik değer kanıtlı | F14: UYARI / HATA | G14: Pazar Doğrulama
A15: 12 | B15: Pazar Doğrulama | C15: Pazar iddiası varsa | D15: Ücretli satış/pilot/fiyat kabul kanıtı | E15: Gerçek fiyat kabul kanıtı | F15: UYGULANMAZ / HATA | G15: Yayın

Sheet 02_KONTROL_LISTESI
A1: NİHAİ KONTROL LİSTESİ — KANITSIZ GEÇİŞ YOK
A3: Kontrol No | B3: Kontrol | C3: Beklenen | D3: Zorunlu Kapı? | E3: Sonuç
A4: K01 | B4: Kullanıcının açık talebi öncelikli mi? | C4: Evet | D4: EVET
A5: K02 | B5: Mevcut yapı, formüller ve tek gerçek kaynak korunuyor mu? | C5: Evet, değişiklik gerekçeli | D5: EVET
A6: K03 | B6: Üst aşama HATA ise alt aşama GEÇTİ engelleniyor mu? | C6: Evet | D6: EVET
A7: K04 | B7: Kanıt fiziksel çıktı ve içerik doğrulaması içeriyor mu? | C7: Evet | D7: EVET
A8: K05 | B8: Excel GUI erişimi olmadan kullanıcı görünümü GEÇTİ yazılıyor mu? | C8: Hayır | D8: EVET
A9: K06 | B9: NİHAİ yalnız GEÇTİ / gerekçeli UYGULANMAZ ile mi? | C9: Evet | D9: EVET
A10: K07 | B10: Ekonomik fiyat savunusu pazar doğrulamasından ayrılmış mı? | C10: Evet | D10: EVET
A11: K08 | B11: Prestij için gereksiz modül var mı? | C11: Hayır | D11: HAYIR
A12: K09 | B12: Excel sınırları açık mı? | C12: Evet | D12: EVET
A13: K10 | B13: Teknik kaynak korunuyor mu? | C13: Evet | D13: EVET
A14: K11 | B14: Kullanıcıya görünen tüm metinler Türkçe mi? | C14: Evet | D14: EVET
A15: K12 | B15: Her kullanıcı sayfasında üst başlık var mı? | C15: Evet | D15: EVET
... A34: K31 | B34: Premium vitrin, altyapı kadar güçlü ve satış fiyatını destekleyecek seviyede mi? | C34: Evet | D34: EVET

Sheet 03_GORSEL_TASARIM
A1: GÖRSEL TASARIM VE PREMIUM EXCEL STANDARDI
A3: Alan | B3: Zorunlu Kural | C3: Uygulama | D3: Yasak | E3: Kontrol | F3: Durum
A4: Sayfa başlığı | B4: Her kullanıcı sayfasının en üstünde tek ve açık sayfa başlığı | C4: A1'den başlayan koyu lacivert başlık bandı | D4: Başlıksız sayfa | E4: Başlık kapsama = %100 | F4: ZORUNLU
A5: Sekme renkleri | B5: Sayfalar işlevine göre renk kodlanır | C5: Girdi=mavi, hesap=gri, rapor=lacivert, kontrol=kırmızı, kılavuz=altın | D5: Rastgele renk | E5: Renk semantiği tutarlı | F5: ZORUNLU
A6: Kolon düzeni | B6: Veri blokları bitişik kolonlarda ilerler | C6: Gereksiz boş kolon bırakma; yalnız gerçek bölüm ayrımı varsa kontrollü boşluk | D6: A:C veri, D boş, E:F veri gibi parçalı yapı | E6: Boş kolon taraması | F6: ZORUNLU
A7: Girdi hücreleri | B7: Kullanıcının değiştireceği alan açıkça görünür | C7: Açık sarı dolgu + mavi yazı | D7: Formülle aynı görünüm | E7: Girdi/formül ayrımı | F7: ZORUNLU
A8: Formüller | B8: Hesap hücreleri kullanıcı girdisinden ayrılır | C8: Siyah yazı; sayfalar arası bağlantı yeşil yazı | D8: Hard-code gizleme | E8: Formül sınıfı kontrolü | F8: ZORUNLU
A9: Grafik sayısı | B9: Yönetici ekranında en fazla 3 ana karar grafiği | C9: Trend, karşılaştırma, köprü/dağılım; iş kararına bağlı | D9: Grafik kalabalığı | E9: Grafik başına karar sorusu | F9: ZORUNLU
A10: Grafik stili | B10: Kurumsal ve yüksek okunabilirlik | C10: Beyaz zemin, ince gridline, tek vurgu rengi, açık birim/başlık | D10: 3B, gölge, neon, gökkuşağı renkleri | E10: Görsel inceleme | F10: ZORUNLU
A11: Grafik başlığı | B11: Grafik 'neyi' değil 'ne anlama geldiğini' söyler | C11: Örn: 'Nakit 2028'de kritik eşiğin altına iniyor' | D11: 'Nakit Grafiği' gibi anlamsız başlık | E11: Başlık karar testi | F11: ZORUNLU
A12: Birimler | B12: Tüm finansal görsellerde birim açık | C12: TL, bin TL, milyon TL, %, gün, x | D12: Birim belirsizliği | E12: Birim kapsama %100 | F12: ZORUNLU
A13: Sıfır/negatif | B13: Finansal format standardı | C13: Sıfır='-', negatif kırmızı parantez | D13: -500 veya 0,00 kalabalığı | E13: Format kontrolü | F13: ZORUNLU
A14: Yazı tipi | B14: Tek aile | C14: Aptos veya Segoe UI | D14: Karışık font | E14: Tek font kontrolü | F14: ZORUNLU
... A22: Premium vitrin | B22: Görsel kalite ürün değerinin zorunlu parçasıdır | C22: Kaliteli grafik, gerçek KPI kartı, finansal hiyerarşi, tab rengi, fonksiyonel navigasyon | D22: Sadece doğru hesap yapıp çıplak/varsayılan Excel görünümü bırakmak | E22: Görsel release incelemesi | F22: ZORUNLU

Sheet 04_MUHASEBE_THP
A1: TÜRKİYE MUHASEBE VE TEKDÜZEN HESAP PLANI STANDARDI
A3: Konu | B3: Zorunlu Standart | C3: Örnek Türkçe Ad | D3: THP / Mantık | E3: Hata Riski | F3: Kontrol
A4: Dil | B4: Kullanıcıya görünen finansal terimler Türkçe | C4: Hasılat, Satışların Maliyeti, Brüt Kâr, Faaliyet Giderleri | D4: Türk işletme kullanımına uygun | E4: İngilizce jargon | F4: Terminoloji taraması
A5: Gelir Tablosu | B5: Türk sunum sırası kullanılır | C5: Net Satışlar → Satışların Maliyeti → Brüt Kâr → Faaliyet Giderleri → Faaliyet Kârı | D5: 600/610/611; 620-623; 63x | E5: Yanlış sınıflama | F5: Hesap eşleme
A6: Bilanço | B6: Dönen/Duran Varlık ve Kısa/Uzun Vadeli Yükümlülük ayrımı | C6: Hazır Değerler, Ticari Alacaklar, Stoklar, Mali Borçlar | D6: 1xx / 2xx / 3xx / 4xx / 5xx | E6: Vade sınıfı hatası | F6: Bilanço eşitliği
A7: Nakit Akışı | B7: İşletme/Yatırım/Finansman nakit akışları ayrılır | C7: Faaliyetlerden Nakit, Yatırım Harcamaları, Finansman Nakit Akışı | D7: Dolaylı/doğrudan yöntem açık seçilir | E7: Kâr = nakit sanılması | F7: Nakit devri
A8: Ticari Alacaklar | B8: Cari ve vade mantığı korunur | C8: 120 Alıcılar | D8: 120 | E8: Tahakkuk/nakit karışması | F8: Alacak devir kontrolü
A9: Ticari Borçlar | B9: Tedarikçi borcu ayrı izlenir | C9: 320 Satıcılar | D9: 320 | E9: Gider/ödeme karışması | F9: Borç devir kontrolü
A10: Kasa/Banka | B10: Hazır değerler ayrı izlenir | C10: 100 Kasa, 102 Bankalar | D10: 100 / 102 | E10: Virmanla toplam nakdin değişmesi | F10: Virman değişmezi
A11: Stok | B11: Dikeye uygun stok türü | C11: 150 İlk Madde ve Malzeme, 153 Ticari Mallar | D11: 15x | E11: Maliyet ve stok hareketinin kopması | F11: Stok devri
A12: Maddi Duran Varlık | B12: Yatırım harcaması ve amortisman bağlantılı | C12: 253 Tesis Makine Cihazlar, 255 Demirbaşlar, 257 Birikmiş Amortismanlar | D12: 25x | E12: Yatırım/gider karışması | F12: Net defter değeri devri
A13: Mali Borçlar | B13: Kısa/uzun vadeli borç ayrımı | C13: 300 Banka Kredileri / 400 Banka Kredileri | D13: 300 / 400 | E13: Vade sınıfı yanlış | F13: Borç devri
A14: Özkaynak | B14: Sermaye ve geçmiş yıl kârları ayrı | C14: 500 Sermaye, 570 Geçmiş Yıllar Kârları, 590 Dönem Net Kârı | D14: 5xx | E14: Net kâr bağının kopması | F14: Özkaynak devri
... A18: İstisna | B18: TFRS özel ürün varsa fark açık yazılır | C18: Tekdüzen raporlama ≠ TFRS finansal tablo sunumu | D18: Amaç belirtilir | E18: Standartları karıştırma | F18: Model amacı kontrolü

Sheet 05_KARAR_SATIS
A1: KARAR, GÜVEN VE SATIŞA HAZIRLIK STANDARDI
A3: Alan | B3: Müşteri Sorusu | C3: Zorunlu Ürün Davranışı | D3: Kanıt | E3: Başarısızlık Durumu | F3: Kapı
A4: 5 saniye | B4: Bu ürün neyi çözüyor? | C4: İlk ekranda hedef kullanıcı + pahalı problem + sonuç görünür | D4: Başlık + alt mesaj + gerçek ekran | E4: Ürün yalnız teknik isim | F4: HATA
A5: Acı | B5: Sorun bana neye mal oluyor? | C5: Mümkünse müşterinin kendi verisiyle parasal/zaman etkisi hesaplanır | D5: ROI/acı hesaplama yöntemi | E5: Uydurma tasarruf | F5: HATA
A6: Karar | B6: Bu bilgiyle ne yapacağım? | C6: Her kritik KPI aksiyona bağlanır | D6: KARAR_KUYRUGU | E6: Sadece rapor | F6: HATA
A7: Güven | B7: Bu sayıya neden inanayım? | C7: Kaynak, formül mantığı, kontrol ve son doğrulama görünür | D7: Kontroller + kaynak izi + sürüm | E7: Prestij kelimesi | F7: HATA
A8: Referans | B8: Müşteri yorumu yoksa ne göstereceğim? | C8: Önce/Sonra + Karar Vakası + Hata Önleme Vakası üretilir | D8: Demo/örnek çıktı | E8: Kanıtsız iddia | F8: HATA
A9: Senaryo | B9: Ne olursa işler bozulur? | C9: Baz/Aşağı/Yukarı veya uygun stres senaryosu | D9: Senaryo karşılaştırma | E9: Dekoratif senaryo | F9: HATA
A10: Ters stres | B10: Hangi eşikte karar kırılır? | C10: En az bir kritik sürücü için kırılma eşiği | D10: Kırılma eşiği tablosu | E10: Sadece +/- %10 | F10: UYARI/HATA
A11: Hata tutarlılığı | B11: Formül hata verirse ne olur? | C11: Kontrol GEÇTİ veremez; BLOKE/HATA üretir | D11: Hata taraması | E11: Hata + GEÇTİ birlikte | F11: HATA
A12: Karar motoru | B12: Ne oldu, neden oldu? | C12: Sorun + neden + parasal etki + aksiyon + son tarih | D12: Karar tablosu | E12: Boş sayfa / isim düzeyi modül | F12: HATA
A13: Yönetici özeti | B13: 5 saniyede ne görmeliyim? | C13: Bugün / ne değişti / ne bozulacak / neden / ne yapmalıyım / güven | D13: Yönetici özeti ekranı | E13: KPI kutusu yığını | F13: HATA
A14: Teklif | B14: Neden satın almalıyım? | C14: Dosya özellikleri yerine sonuç ve kaçınılan maliyet sunulur | D14: Ürün sayfası kanıt eşlemesi | E14: Özellik listesiyle satış | F14: HATA
... A19: Pazar kanıtı | B19: Piyasa gerçekten ödüyor mu? | C19: Satış/pilot/LOI/fiyat kabulü olmadan pazar doğrulandı yazılmaz | D19: Gerçek işlem kanıtı | E19: Tahmini talep = satış kabulü | F19: HATA

Sheet KAPAK
A1: KAPAK — Makine Bakım & Kalibrasyon + Duruş Maliyeti
A3: Makine Bakım & Kalibrasyon + Duruş Maliyeti
A4: Makine bakım planı, kalibrasyon vadesi ve duruş saatini maliyetle bağlar; durum makinesi ve imza kanıt zinciri üretir; PLANLI / GECİKMİŞ / KRİTİK / VERİ YOK kararı verir.
A6: Bu ürün ne sağlar?
A7: • Makrosuz durum makinesi: Plan → Yapıldı / Gecikme → Kritik
A8: • Günlük/haftalık duruş + saatlik duruş maliyeti hesabı
A9: • Plan tarih ↔ gerçekleşen ↔ duruş saati zincir bayrağı
A10: • Geçersiz geçiş ve yetim makine uyarıları
A11: • KANIT_RAPORU — denetçi/SMMM imza alanlı dönem kanıtı
A13: Kimler için?
A14: • Bakım / kalibrasyon — plan kapanışı ve vade takibi
A15: • Üretim müdürü — PLANLI / GECİKMİŞ / KRİTİK kararı
... A21: Sürüm 1.0.0 | Lisans: Tek kullanıcı | ExcelArşiv

Sheet MAKINELER
A1: MAKINELER — Makine Bakım & Kalibrasyon + Duruş Maliyeti
A3: Makine kartları — her varlığın tek kimliği vardır
A4: Sonraki Kimlik | B4: =mbk_sonrakiKimlik
A5: MakineId | B5: Ad | C5: Hat | D5: Tip | E5: SaatlikDurusMaliyeti | F5: KalibrasyonPeriyotGun | G5: Aktif | H5: ToplamDurus | I5: OrtDurus
A6: MAK-00001 | B6: CNC Torna T-100 | C6: Hat-A | D6: CNC | E6: 850 | F6: 90 | G6: EVET | H6: =IF($A6="","",SUMIF(tblAkis[KaynakMakineId],$A6,tblAkis[FiiliDurusSaat])) | I6: =IF($A6="","",IFERROR(AVERAGEIF(tblAkis[KaynakMakineId],$A6,tblAkis[FiiliDurusSaat]),0))
A7: MAK-00002 | B7: Pres Hidrolik P-50 | C7: Hat-A | D7: Pres | E7: 900 | F7: 105 | G7: EVET | H7: =IF($A7="","",SUMIF(tblAkis[KaynakMakineId],$A7,tblAkis[FiiliDurusSaat])) | I7: =IF($A7="","",IFERROR(AVERAGEIF(tblAkis[KaynakMakineId],$A7,tblAkis[FiiliDurusSaat]),0))
A8: MAK-00003 | B8: Kaynak Robot KR-20 | C8: Hat-B | D8: Robot | E8: 950 | F8: 120 | G8: EVET | H8: =IF($A8="","",SUMIF(tblAkis[KaynakMakineId],$A8,tblAkis[FiiliDurusSaat])) | I8: =IF($A8="","",IFERROR(AVERAGEIF(tblAkis[KaynakMakineId],$A8,tblAkis[FiiliDurusSaat]),0))
A9: MAK-00004 | B9: Freze Merkezi FM-30 | C9: Hat-B | D9: CNC | E9: 1000 | F9: 135 | G9: EVET | H9: =IF($A9="","",SUMIF(tblAkis[KaynakMakineId],$A9,tblAkis[FiiliDurusSaat])) | I9: =IF($A9="","",IFERROR(AVERAGEIF(tblAkis[KaynakMakineId],$A9,tblAkis[FiiliDurusSaat]),0))
A10: MAK-00005 | B10: Konveyör K-08 | C10: Hat-C | D10: Konveyor | E10: 1050 | F10: 150 | G10: EVET | H10: =IF($A10="","",SUMIF(tblAkis[KaynakMakineId],$A10,tblAkis[FiiliDurusSaat])) | I10: =IF($A10="","",IFERROR(AVERAGEIF(tblAkis[KaynakMakineId],$A10,tblAkis[FiiliDurusSaat]),0))
A11: MAK-00006 | B11: Kompresör KMP-12 | C11: Hat-C | D11: Kompresor | E11: 1100 | F11: 165 | G11: EVET | H11: =IF($A11="","",SUMIF(tblAkis[KaynakMakineId],$A11,tblAkis[FiiliDurusSaat])) | I11: =IF($A11="","",IFERROR(AVERAGEIF(tblAkis[KaynakMakineId],$A11,tblAkis[FiiliDurusSaat]),0))
A12: MAK-00007 | B12: Ölçüm Tezgâhı OT-05 | C12: Kalite | D12: Olcu | E12: 1150 | F12: 180 | G12: EVET | H12: =IF($A12="","",SUMIF(tblAkis[KaynakMakineId],$A12,tblAkis[FiiliDurusSaat])) | I12: =IF($A12="","",IFERROR(AVERAGEIF(tblAkis[KaynakMakineId],$A12,tblAkis[FiiliDurusSaat]),0))
A13: MAK-00008 | B13: Fırın Isıl F-40 | C13: Hat-A | D13: Firin | E13: 1200 | F13: 195 | G13: EVET | H13: =IF($A13="","",SUMIF(tblAkis[KaynakMakineId],$A13,tblAkis[FiiliDurusSaat])) | I13: =IF($A13="","",IFERROR(AVERAGEIF(tblAkis[KaynakMakineId],$A13,tblAkis[FiiliDurusSaat]),0))
H14: =IF($A14="","",SUMIF(tblAkis[KaynakMakineId],$A14,tblAkis[FiiliDurusSaat])) | I14: =IF($A14="","",IFERROR(AVERAGEIF(tblAkis[KaynakMakineId],$A14,tblAkis[FiiliDurusSaat]),0))
H15: =IF($A15="","",SUMIF(tblAkis[KaynakMakineId],$A15,tblAkis[FiiliDurusSaat])) | I15: =IF($A15="","",IFERROR(AVERAGEIF(tblAkis[KaynakMakineId],$A15,tblAkis[FiiliDurusSaat]),0))
H16: =IF($A16="","",SUMIF(tblAkis[KaynakMakineId],$A16,tblAkis[FiiliDurusSaat])) | I16: =IF($A16="","",IFERROR(AVERAGEIF(tblAkis[KaynakMakineId],$A16,tblAkis[FiiliDurusSaat]),0))
H17: =IF($A17="","",SUMIF(tblAkis[KaynakMakineId],$A17,tblAkis[FiiliDurusSaat])) | I17: =IF($A17="","",IFERROR(AVERAGEIF(tblAkis[KaynakMakineId],$A17,tblAkis[FiiliDurusSaat]),0))
H18: =IF($A18="","",SUMIF(tblAkis[KaynakMakineId],$A18,tblAkis[FiiliDurusSaat])) | I18: =IF($A18="","",IFERROR(AVERAGEIF(tblAkis[KaynakMakineId],$A18,tblAkis[FiiliDurusSaat]),0))
H19: =IF($A19="","",SUMIF(tblAkis[KaynakMakineId],$A19,tblAkis[FiiliDurusSaat])) | I19: =IF($A19="","",IFERROR(AVERAGEIF(tblAkis[KaynakMakineId],$A19,tblAkis[FiiliDurusSaat]),0))
H20: =IF($A20="","",SUMIF(tblAkis[KaynakMakineId],$A20,tblAkis[FiiliDurusSaat])) | I20: =IF($A20="","",IFERROR(AVERAGEIF(tblAkis[KaynakMakineId],$A20,tblAkis[FiiliDurusSaat]),0))
H21: =IF($A21="","",SUMIF(tblAkis[KaynakMakineId],$A21,tblAkis[FiiliDurusSaat])) | I21: =IF($A21="","",IFERROR(AVERAGEIF(tblAkis[KaynakMakineId],$A21,tblAkis[FiiliDurusSaat]),0))
H22: =IF($A22="","",SUMIF(tblAkis[KaynakMakineId],$A22,tblAkis[FiiliDurusSaat])) | I22: =IF($A22="","",IFERROR(AVERAGEIF(tblAkis[KaynakMakineId],$A22,tblAkis[FiiliDurusSaat]),0))
H23: =IF($A23="","",SUMIF(tblAkis[KaynakMakineId],$A23,tblAkis[FiiliDurusSaat])) | I23: =IF($A23="","",IFERROR(AVERAGEIF(tblAkis[KaynakMakineId],$A23,tblAkis[FiiliDurusSaat]),0))
H24: =IF($A24="","",SUMIF(tblAkis[KaynakMakineId],$A24,tblAkis[FiiliDurusSaat])) | I24: =IF($A24="","",IFERROR(AVERAGEIF(tblAkis[KaynakMakineId],$A24,tblAkis[FiiliDurusSaat]),0))
H25: =IF($A25="","",SUMIF(tblAkis[KaynakMakineId],$A25,tblAkis[FiiliDurusSaat])) | I25: =IF($A25="","",IFERROR(AVERAGEIF(tblAkis[KaynakMakineId],$A25,tblAkis[FiiliDurusSaat]),0))
... H255: =IF($A255="","",SUMIF(tblAkis[KaynakMakineId],$A255,tblAkis[FiiliDurusSaat])) | I255: =IF($A255="","",IFERROR(AVERAGEIF(tblAkis[KaynakMakineId],$A255,tblAkis[FiiliDurusSaat]),0))

Sheet AKIS
A1: AKIS — Makine Bakım & Kalibrasyon + Duruş Maliyeti
A3: Bakım satırları — durum makinesi + yetim + geçersiz geçiş + zincir
A5: BakimId | B5: KaynakMakineId | C5: PlanTarih | D5: GerceklesenTarih | E5: PlanDurusSaat | F5: FiiliDurusSaat | G5: KalibrasyonGunKalan | H5: BakimTuru | I5: OncekiDurum | J5: Durum | K5: ImzaKanit | L5: YorumA | M5: YorumB | N5: SaatlikMaliyet | O5: HesaplananDurus | P5: GecikmeGun | Q5: YasKova | R5: YetimBayrak | S5: GecisUyarisi | T5: ZincirBayrak | U5: KayitDolu | V5: DurusMaliyet
A6: BKM-00001 | B6: MAK-00001 | C6: 46243 | E6: 2.5 | F6: 2.5 | G6: 27 | H6: DUZELTICI | J6: PLAN | L6: A | M6: Bakım notu 1 | N6: 900 | O6: =IF($A6="","",$F6) | P6: =IF($A6="","",IF($J6="YAPILDI",0,IF($C6="","",raporTarihi-$C6))) | Q6: =IF($A6="","",IF($P6="","",IF($P6<=mbk_kovaEsik1,"0-7",IF($P6<=mbk_kovaEsik2,"8-30",IF($P6<=mbk_kovaEsik3,"31-60","60+"))))) | R6: =IF($A6="","",IF($B6="","YETİM",IF(COUNTIF(tblMakineler[MakineId],$B6)=0,"YETİM",""))) | S6: =IF(OR($A6="",$I6=""),"",IF(OR($I6&"|"&$J6="",COUNTIF(ListeIzinliGecis,$I6&"|"&$J6)>0),"","GEÇERSİZ GEÇİŞ")) | T6: =IF($A6="","",IF(OR($E6="",$F6=""),"",IF(ABS($F6-$E6)>zincirTolerans,"ZİNCİR KIRIK","OK"))) | U6: =IF($A6="","",1) | V6: =IF($A6="","",$F6*$N6*mbk_durusKatsayi)
A7: BKM-00002 | B7: MAK-00002 | C7: 46241 | E7: 3 | F7: 3 | G7: 24 | H7: KALIBRASYON | I7: PLAN | J7: GECIKME | L7: B | M7: Bakım notu 2 | N7: 950 | O7: =IF($A7="","",$F7) | P7: =IF($A7="","",IF($J7="YAPILDI",0,IF($C7="","",raporTarihi-$C7))) | Q7: =IF($A7="","",IF($P7="","",IF($P7<=mbk_kovaEsik1,"0-7",IF($P7<=mbk_kovaEsik2,"8-30",IF($P7<=mbk_kovaEsik3,"31-60","60+"))))) | R7: =IF($A7="","",IF($B7="","YETİM",IF(COUNTIF(tblMakineler[MakineId],$B7)=0,"YETİM",""))) | S7: =IF(OR($A7="",$I7=""),"",IF(OR($I7&"|"&$J7="",COUNTIF(ListeIzinliGecis,$I7&"|"&$J7)>0),"","GEÇERSİZ GEÇİŞ")) | T7: =IF($A7="","",IF(OR($E7="",$F7=""),"",IF(ABS($F7-$E7)>zincirTolerans,"ZİNCİR KIRIK","OK"))) | U7: =IF($A7="","",1) | V7: =IF($A7="","",$F7*$N7*mbk_durusKatsayi)
A8: BKM-00003 | B8: MAK-00003 | C8: 46239 | D8: 46239 | E8: 3.5 | F8: 3.5 | G8: 21 | H8: ACIL | I8: GECIKME | J8: YAPILDI | K8: İMZA-003 | L8: A | M8: Bakım notu 3 | N8: 1000 | O8: =IF($A8="","",$F8) | P8: =IF($A8="","",IF($J8="YAPILDI",0,IF($C8="","",raporTarihi-$C8))) | Q8: =IF($A8="","",IF($P8="","",IF($P8<=mbk_kovaEsik1,"0-7",IF($P8<=mbk_kovaEsik2,"8-30",IF($P8<=mbk_kovaEsik3,"31-60","60+"))))) | R8: =IF($A8="","",IF($B8="","YETİM",IF(COUNTIF(tblMakineler[MakineId],$B8)=0,"YETİM",""))) | S8: =IF(OR($A8="",$I8=""),"",IF(OR($I8&"|"&$J8="",COUNTIF(ListeIzinliGecis,$I8&"|"&$J8)>0),"","GEÇERSİZ GEÇİŞ")) | T8: =IF($A8="","",IF(OR($E8="",$F8=""),"",IF(ABS($F8-$E8)>zincirTolerans,"ZİNCİR KIRIK","OK"))) | U8: =IF($A8="","",1) | V8: =IF($A8="","",$F8*$N8*mbk_durusKatsayi)
A9: BKM-00004 | B9: MAK-00004 | C9: 46237 | E9: 2 | F9: 2 | G9: 18 | H9: ONLEYICI | I9: GECIKME | J9: KRITIK | L9: B | M9: Bakım notu 4 | N9: 1050 | O9: =IF($A9="","",$F9) | P9: =IF($A9="","",IF($J9="YAPILDI",0,IF($C9="","",raporTarihi-$C9))) | Q9: =IF($A9="","",IF($P9="","",IF($P9<=mbk_kovaEsik1,"0-7",IF($P9<=mbk_kovaEsik2,"8-30",IF($P9<=mbk_kovaEsik3,"31-60","60+"))))) | R9: =IF($A9="","",IF($B9="","YETİM",IF(COUNTIF(tblMakineler[MakineId],$B9)=0,"YETİM",""))) | S9: =IF(OR($A9="",$I9=""),"",IF(OR($I9&"|"&$J9="",COUNTIF(ListeIzinliGecis,$I9&"|"&$J9)>0),"","GEÇERSİZ GEÇİŞ")) | T9: =IF($A9="","",IF(OR($E9="",$F9=""),"",IF(ABS($F9-$E9)>zincirTolerans,"ZİNCİR KIRIK","OK"))) | U9: =IF($A9="","",1) | V9: =IF($A9="","",$F9*$N9*mbk_durusKatsayi)
A10: BKM-00005 | B10: MAK-00005 | C10: 46235 | E10: 2.5 | F10: 2.5 | G10: 15 | H10: DUZELTICI | I10: PLAN | J10: GECIKME | L10: A | M10: Bakım notu 5 | N10: 850 | O10: =IF($A10="","",$F10) | P10: =IF($A10="","",IF($J10="YAPILDI",0,IF($C10="","",raporTarihi-$C10))) | Q10: =IF($A10="","",IF($P10="","",IF($P10<=mbk_kovaEsik1,"0-7",IF($P10<=mbk_kovaEsik2,"8-30",IF($P10<=mbk_kovaEsik3,"31-60","60+"))))) | R10: =IF($A10="","",IF($B10="","YETİM",IF(COUNTIF(tblMakineler[MakineId],$B10)=0,"YETİM",""))) | S10: =IF(OR($A10="",$I10=""),"",IF(OR($I10&"|"&$J10="",COUNTIF(ListeIzinliGecis,$I10&"|"&$J10)>0),"","GEÇERSİZ GEÇİŞ")) | T10: =IF($A10="","",IF(OR($E10="",$F10=""),"",IF(ABS($F10-$E10)>zincirTolerans,"ZİNCİR KIRIK","OK"))) | U10: =IF($A10="","",1) | V10: =IF($A10="","",$F10*$N10*mbk_durusKatsayi)
A11: BKM-00006 | B11: MAK-00006 | C11: 46233 | E11: 3 | F11: 3 | G11: 12 | H11: KALIBRASYON | I11: PLAN | J11: PLAN | L11: B | M11: Bakım notu 6 | N11: 900 | O11: =IF($A11="","",$F11) | P11: =IF($A11="","",IF($J11="YAPILDI",0,IF($C11="","",raporTarihi-$C11))) | Q11: =IF($A11="","",IF($P11="","",IF($P11<=mbk_kovaEsik1,"0-7",IF($P11<=mbk_kovaEsik2,"8-30",IF($P11<=mbk_kovaEsik3,"31-60","60+"))))) | R11: =IF($A11="","",IF($B11="","YETİM",IF(COUNTIF(tblMakineler[MakineId],$B11)=0,"YETİM",""))) | S11: =IF(OR($A11="",$I11=""),"",IF(OR($I11&"|"&$J11="",COUNTIF(ListeIzinliGecis,$I11&"|"&$J11)>0),"","GEÇERSİZ GEÇİŞ")) | T11: =IF($A11="","",IF(OR($E11="",$F11=""),"",IF(ABS($F11-$E11)>zincirTolerans,"ZİNCİR KIRIK","OK"))) | U11: =IF($A11="","",1) | V11: =IF($A11="","",$F11*$N11*mbk_durusKatsayi)
A12: BKM-00007 | B12: MAK-00007 | C12: 46231 | D12: 46231 | E12: 3.5 | F12: 3.5 | G12: 9 | H12: ACIL | I12: KRITIK | J12: YAPILDI | K12: İMZA-007 | L12: A | M12: Bakım notu 7 | N12: 950 | O12: =IF($A12="","",$F12) | P12: =IF($A12="","",IF($J12="YAPILDI",0,IF($C12="","",raporTarihi-$C12))) | Q12: =IF($A12="","",IF($P12="","",IF($P12<=mbk_kovaEsik1,"0-7",IF($P12<=mbk_kovaEsik2,"8-30",IF($P12<=mbk_kovaEsik3,"31-60","60+"))))) | R12: =IF($A12="","",IF($B12="","YETİM",IF(COUNTIF(tblMakineler[MakineId],$B12)=0,"YETİM",""))) | S12: =IF(OR($A12="",$I12=""),"",IF(OR($I12&"|"&$J12="",COUNTIF(ListeIzinliGecis,$I12&"|"&$J12)>0),"","GEÇERSİZ GEÇİŞ")) | T12: =IF($A12="","",IF(OR($E12="",$F12=""),"",IF(ABS($F12-$E12)>zincirTolerans,"ZİNCİR KIRIK","OK"))) | U12: =IF($A12="","",1) | V12: =IF($A12="","",$F12*$N12*mbk_durusKatsayi)
A13: BKM-00008 | B13: MAK-00008 | C13: 46229 | E13: 2 | F13: 2 | G13: 6 | H13: ONLEYICI | I13: PLAN | J13: PLAN | L13: B | M13: Bakım notu 8 | N13: 1000 | O13: =IF($A13="","",$F13) | P13: =IF($A13="","",IF($J13="YAPILDI",0,IF($C13="","",raporTarihi-$C13))) | Q13: =IF($A13="","",IF($P13="","",IF($P13<=mbk_kovaEsik1,"0-7",IF($P13<=mbk_kovaEsik2,"8-30",IF($P13<=mbk_kovaEsik3,"31-60","60+"))))) | R13: =IF($A13="","",IF($B13="","YETİM",IF(COUNTIF(tblMakineler[MakineId],$B13)=0,"YETİM",""))) | S13: =IF(OR($A13="",$I13=""),"",IF(OR($I13&"|"&$J13="",COUNTIF(ListeIzinliGecis,$I13&"|"&$J13)>0),"","GEÇERSİZ GEÇİŞ")) | T13: =IF($A13="","",IF(OR($E13="",$F13=""),"",IF(ABS($F13-$E13)>zincirTolerans,"ZİNCİR KIRIK","OK"))) | U13: =IF($A13="","",1) | V13: =IF($A13="","",$F13*$N13*mbk_durusKatsayi)
A14: BKM-00009 | B14: MAK-00001 | C14: 46227 | E14: 2.5 | F14: 2.5 | G14: 3 | H14: DUZELTICI | J14: PLAN | L14: A | M14: Bakım notu 9 | N14: 1050 | O14: =IF($A14="","",$F14) | P14: =IF($A14="","",IF($J14="YAPILDI",0,IF($C14="","",raporTarihi-$C14))) | Q14: =IF($A14="","",IF($P14="","",IF($P14<=mbk_kovaEsik1,"0-7",IF($P14<=mbk_kovaEsik2,"8-30",IF($P14<=mbk_kovaEsik3,"31-60","60+"))))) | R14: =IF($A14="","",IF($B14="","YETİM",IF(COUNTIF(tblMakineler[MakineId],$B14)=0,"YETİM",""))) | S14: =IF(OR($A14="",$I14=""),"",IF(OR($I14&"|"&$J14="",COUNTIF(ListeIzinliGecis,$I14&"|"&$J14)>0),"","GEÇERSİZ GEÇİŞ")) | T14: =IF($A14="","",IF(OR($E14="",$F14=""),"",IF(ABS($F14-$E14)>zincirTolerans,"ZİNCİR KIRIK","OK"))) | U14: =IF($A14="","",1) | V14: =IF($A14="","",$F14*$N14*mbk_durusKatsayi)
A15: BKM-00010 | B15: MAK-00002 | C15: 46225 | E15: 3 | F15: 3 | G15: 0 | H15: KALIBRASYON | I15: PLAN | J15: GECIKME | L15: B | M15: Bakım notu 10 | N15: 850 | O15: =IF($A15="","",$F15) | P15: =IF($A15="","",IF($J15="YAPILDI",0,IF($C15="","",raporTarihi-$C15))) | Q15: =IF($A15="","",IF($P15="","",IF($P15<=mbk_kovaEsik1,"0-7",IF($P15<=mbk_kovaEsik2,"8-30",IF($P15<=mbk_kovaEsik3,"31-60","60+"))))) | R15: =IF($A15="","",IF($B15="","YETİM",IF(COUNTIF(tblMakineler[MakineId],$B15)=0,"YETİM",""))) | S15: =IF(OR($A15="",$I15=""),"",IF(OR($I15&"|"&$J15="",COUNTIF(ListeIzinliGecis,$I15&"|"&$J15)>0),"","GEÇERSİZ GEÇİŞ")) | T15: =IF($A15="","",IF(OR($E15="",$F15=""),"",IF(ABS($F15-$E15)>zincirTolerans,"ZİNCİR KIRIK","OK"))) | U15: =IF($A15="","",1) | V15: =IF($A15="","",$F15*$N15*mbk_durusKatsayi)
A16: BKM-00011 | B16: MAK-00003 | C16: 46223 | D16: 46223 | E16: 3.5 | F16: 3.5 | G16: -3 | H16: ACIL | I16: GECIKME | J16: YAPILDI | K16: İMZA-011 | L16: A | M16: Bakım notu 11 | N16: 900 | O16: =IF($A16="","",$F16) | P16: =IF($A16="","",IF($J16="YAPILDI",0,IF($C16="","",raporTarihi-$C16))) | Q16: =IF($A16="","",IF($P16="","",IF($P16<=mbk_kovaEsik1,"0-7",IF($P16<=mbk_kovaEsik2,"8-30",IF($P16<=mbk_kovaEsik3,"31-60","60+"))))) | R16: =IF($A16="","",IF($B16="","YETİM",IF(COUNTIF(tblMakineler[MakineId],$B16)=0,"YETİM",""))) | S16: =IF(OR($A16="",$I16=""),"",IF(OR($I16&"|"&$J16="",COUNTIF(ListeIzinliGecis,$I16&"|"&$J16)>0),"","GEÇERSİZ GEÇİŞ")) | T16: =IF($A16="","",IF(OR($E16="",$F16=""),"",IF(ABS($F16-$E16)>zincirTolerans,"ZİNCİR KIRIK","OK"))) | U16: =IF($A16="","",1) | V16: =IF($A16="","",$F16*$N16*mbk_durusKatsayi)
A17: BKM-00012 | B17: MAK-00004 | C17: 46221 | E17: 2 | F17: 3.5 | G17: -6 | H17: ONLEYICI | I17: GECIKME | J17: KRITIK | L17: B | M17: Bakım notu 12 | N17: 950 | O17: =IF($A17="","",$F17) | P17: =IF($A17="","",IF($J17="YAPILDI",0,IF($C17="","",raporTarihi-$C17))) | Q17: =IF($A17="","",IF($P17="","",IF($P17<=mbk_kovaEsik1,"0-7",IF($P17<=mbk_kovaEsik2,"8-30",IF($P17<=mbk_kovaEsik3,"31-60","60+"))))) | R17: =IF($A17="","",IF($B17="","YETİM",IF(COUNTIF(tblMakineler[MakineId],$B17)=0,"YETİM",""))) | S17: =IF(OR($A17="",$I17=""),"",IF(OR($I17&"|"&$J17="",COUNTIF(ListeIzinliGecis,$I17&"|"&$J17)>0),"","GEÇERSİZ GEÇİŞ")) | T17: =IF($A17="","",IF(OR($E17="",$F17=""),"",IF(ABS($F17-$E17)>zincirTolerans,"ZİNCİR KIRIK","OK"))) | U17: =IF($A17="","",1) | V17: =IF($A17="","",$F17*$N17*mbk_durusKatsayi)
A18: BKM-00013 | B18: MAK-00005 | C18: 46219 | E18: 2.5 | F18: 2.5 | G18: -9 | H18: DUZELTICI | I18: PLAN | J18: GECIKME | L18: A | M18: Bakım notu 13 | N18: 1000 | O18: =IF($A18="","",$F18) | P18: =IF($A18="","",IF($J18="YAPILDI",0,IF($C18="","",raporTarihi-$C18))) | Q18: =IF($A18="","",IF($P18="","",IF($P18<=mbk_kovaEsik1,"0-7",IF($P18<=mbk_kovaEsik2,"8-30",IF($P18<=mbk_kovaEsik3,"31-60","60+"))))) | R18: =IF($A18="","",IF($B18="","YETİM",IF(COUNTIF(tblMakineler[MakineId],$B18)=0,"YETİM",""))) | S18: =IF(OR($A18="",$I18=""),"",IF(OR($I18&"|"&$J18="",COUNTIF(ListeIzinliGecis,$I18&"|"&$J18)>0),"","GEÇERSİZ GEÇİŞ")) | T18: =IF($A18="","",IF(OR($E18="",$F18=""),"",IF(ABS($F18-$E18)>zincirTolerans,"ZİNCİR KIRIK","OK"))) | U18: =IF($A18="","",1) | V18: =IF($A18="","",$F18*$N18*mbk_durusKatsayi)
A19: BKM-00014 | B19: MAK-00006 | C19: 46217 | E19: 3 | F19: 3 | G19: -12 | H19: KALIBRASYON | I19: PLAN | J19: PLAN | L19: B | M19: Bakım notu 14 | N19: 1050 | O19: =IF($A19="","",$F19) | P19: =IF($A19="","",IF($J19="YAPILDI",0,IF($C19="","",raporTarihi-$C19))) | Q19: =IF($A19="","",IF($P19="","",IF($P19<=mbk_kovaEsik1,"0-7",IF($P19<=mbk_kovaEsik2,"8-30",IF($P19<=mbk_kovaEsik3,"31-60","60+"))))) | R19: =IF($A19="","",IF($B19="","YETİM",IF(COUNTIF(tblMakineler[MakineId],$B19)=0,"YETİM",""))) | S19: =IF(OR($A19="",$I19=""),"",IF(OR($I19&"|"&$J19="",COUNTIF(ListeIzinliGecis,$I19&"|"&$J19)>0),"","GEÇERSİZ GEÇİŞ")) | T19: =IF($A19="","",IF(OR($E19="",$F19=""),"",IF(ABS($F19-$E19)>zincirTolerans,"ZİNCİR KIRIK","OK"))) | U19: =IF($A19="","",1) | V19: =IF($A19="","",$F19*$N19*mbk_durusKatsayi)
A20: BKM-00015 | B20: MAK-00007 | C20: 46215 | D20: 46215 | E20: 2 | F20: 6 | G20: -15 | H20: ACIL | I20: KRITIK | J20: YAPILDI | K20: İMZA-015 | L20: A | M20: Bakım notu 15 | N20: 850 | O20: =IF($A20="","",$F20) | P20: =IF($A20="","",IF($J20="YAPILDI",0,IF($C20="","",raporTarihi-$C20))) | Q20: =IF($A20="","",IF($P20="","",IF($P20<=mbk_kovaEsik1,"0-7",IF($P20<=mbk_kovaEsik2,"8-30",IF($P20<=mbk_kovaEsik3,"31-60","60+"))))) | R20: =IF($A20="","",IF($B20="","YETİM",IF(COUNTIF(tblMakineler[MakineId],$B20)=0,"YETİM",""))) | S20: =IF(OR($A20="",$I20=""),"",IF(OR($I20&"|"&$J20="",COUNTIF(ListeIzinliGecis,$I20&"|"&$J20)>0),"","GEÇERSİZ GEÇİŞ")) | T20: =IF($A20="","",IF(OR($E20="",$F20=""),"",IF(ABS($F20-$E20)>zincirTolerans,"ZİNCİR KIRIK","OK"))) | U20: =IF($A20="","",1) | V20: =IF($A20="","",$F20*$N20*mbk_durusKatsayi)
A21: BKM-00016 | B21: MAK-00008 | C21: 46213 | E21: 2 | F21: 2 | G21: -18 | H21: ONLEYICI | I21: PLAN | J21: PLAN | L21: B | M21: Bakım notu 16 | N21: 900 | O21: =IF($A21="","",$F21) | P21: =IF($A21="","",IF($J21="YAPILDI",0,IF($C21="","",raporTarihi-$C21))) | Q21: =IF($A21="","",IF($P21="","",IF($P21<=mbk_kovaEsik1,"0-7",IF($P21<=mbk_kovaEsik2,"8-30",IF($P21<=mbk_kovaEsik3,"31-60","60+"))))) | R21: =IF($A21="","",IF($B21="","YETİM",IF(COUNTIF(tblMakineler[MakineId],$B21)=0,"YETİM",""))) | S21: =IF(OR($A21="",$I21=""),"",IF(OR($I21&"|"&$J21="",COUNTIF(ListeIzinliGecis,$I21&"|"&$J21)>0),"","GEÇERSİZ GEÇİŞ")) | T21: =IF($A21="","",IF(OR($E21="",$F21=""),"",IF(ABS($F21-$E21)>zincirTolerans,"ZİNCİR KIRIK","OK"))) | U21: =IF($A21="","",1) | V21: =IF($A21="","",$F21*$N21*mbk_durusKatsayi)
A22: BKM-00017 | B22: MAK-00001 | C22: 46211 | E22: 2.5 | F22: 2.5 | G22: 29 | H22: DUZELTICI | J22: PLAN | L22: A | M22: Bakım notu 17 | N22: 950 | O22: =IF($A22="","",$F22) | P22: =IF($A22="","",IF($J22="YAPILDI",0,IF($C22="","",raporTarihi-$C22))) | Q22: =IF($A22="","",IF($P22="","",IF($P22<=mbk_kovaEsik1,"0-7",IF($P22<=mbk_kovaEsik2,"8-30",IF($P22<=mbk_kovaEsik3,"31-60","60+"))))) | R22: =IF($A22="","",IF($B22="","YETİM",IF(COUNTIF(tblMakineler[MakineId],$B22)=0,"YETİM",""))) | S22: =IF(OR($A22="",$I22=""),"",IF(OR($I22&"|"&$J22="",COUNTIF(ListeIzinliGecis,$I22&"|"&$J22)>0),"","GEÇERSİZ GEÇİŞ")) | T22: =IF($A22="","",IF(OR($E22="",$F22=""),"",IF(ABS($F22-$E22)>zincirTolerans,"ZİNCİR KIRIK","OK"))) | U22: =IF($A22="","",1) | V22: =IF($A22="","",$F22*$N22*mbk_durusKatsayi)
A23: BKM-00018 | B23: MAK-00002 | C23: 46209 | E23: 3 | F23: 3 | G23: 26 | H23: KALIBRASYON | I23: PLAN | J23: KRITIK | L23: B | M23: Bakım notu 18 | N23: 1000 | O23: =IF($A23="","",$F23) | P23: =IF($A23="","",IF($J23="YAPILDI",0,IF($C23="","",raporTarihi-$C23))) | Q23: =IF($A23="","",IF($P23="","",IF($P23<=mbk_kovaEsik1,"0-7",IF($P23<=mbk_kovaEsik2,"8-30",IF($P23<=mbk_kovaEsik3,"31-60","60+"))))) | R23: =IF($A23="","",IF($B23="","YETİM",IF(COUNTIF(tblMakineler[MakineId],$B23)=0,"YETİM",""))) | S23: =IF(OR($A23="",$I23=""),"",IF(OR($I23&"|"&$J23="",COUNTIF(ListeIzinliGecis,$I23&"|"&$J23)>0),"","GEÇERSİZ GEÇİŞ")) | T23: =IF($A23="","",IF(OR($E23="",$F23=""),"",IF(ABS($F23-$E23)>zincirTolerans,"ZİNCİR KIRIK","OK"))) | U23: =IF($A23="","",1) | V23: =IF($A23="","",$F23*$N23*mbk_durusKatsayi)
A24: BKM-00019 | B24: MAK-00003 | C24: 46207 | D24: 46207 | E24: 3.5 | F24: 5 | G24: 23 | H24: ACIL | I24: GECIKME | J24: YAPILDI | K24: İMZA-019 | L24: A | M24: Bakım notu 19 | N24: 1050 | O24: =IF($A24="","",$F24) | P24: =IF($A24="","",IF($J24="YAPILDI",0,IF($C24="","",raporTarihi-$C24))) | Q24: =IF($A24="","",IF($P24="","",IF($P24<=mbk_kovaEsik1,"0-7",IF($P24<=mbk_kovaEsik2,"8-30",IF($P24<=mbk_kovaEsik3,"31-60","60+"))))) | R24: =IF($A24="","",IF($B24="","YETİM",IF(COUNTIF(tblMakineler[MakineId],$B24)=0,"YETİM",""))) | S24: =IF(OR($A24="",$I24=""),"",IF(OR($I24&"|"&$J24="",COUNTIF(ListeIzinliGecis,$I24&"|"&$J24)>0),"","GEÇERSİZ GEÇİŞ")) | T24: =IF($A24="","",IF(OR($E24="",$F24=""),"",IF(ABS($F24-$E24)>zincirTolerans,"ZİNCİR KIRIK","OK"))) | U24: =IF($A24="","",1) | V24: =IF($A24="","",$F24*$N24*mbk_durusKatsayi)
A25: BKM-00020 | B25: MAK-00004 | C25: 46205 | E25: 2 | F25: 2 | G25: 20 | H25: ONLEYICI | I25: YAPILDI | J25: PLAN | L25: B | M25: Bakım notu 20 | N25: 850 | O25: =IF($A25="","",$F25) | P25: =IF($A25="","",IF($J25="YAPILDI",0,IF($C25="","",raporTarihi-$C25))) | Q25: =IF($A25="","",IF($P25="","",IF($P25<=mbk_kovaEsik1,"0-7",IF($P25<=mbk_kovaEsik2,"8-30",IF($P25<=mbk_kovaEsik3,"31-60","60+"))))) | R25: =IF($A25="","",IF($B25="","YETİM",IF(COUNTIF(tblMakineler[MakineId],$B25)=0,"YETİM",""))) | S25: =IF(OR($A25="",$I25=""),"",IF(OR($I25&"|"&$J25="",COUNTIF(ListeIzinliGecis,$I25&"|"&$J25)>0),"","GEÇERSİZ GEÇİŞ")) | T25: =IF($A25="","",IF(OR($E25="",$F25=""),"",IF(ABS($F25-$E25)>zincirTolerans,"ZİNCİR KIRIK","OK"))) | U25: =IF($A25="","",1) | V25: =IF($A25="","",$F25*$N25*mbk_durusKatsayi)
A26: BKM-00021 | B26: MAK-00005 | C26: 46203 | E26: 2.5 | F26: 2.5 | G26: 17 | H26: DUZELTICI | I26: PLAN | J26: GECIKME | L26: A | M26: Bakım notu 21 | N26: 900 | O26: =IF($A26="","",$F26) | P26: =IF($A26="","",IF($J26="YAPILDI",0,IF($C26="","",raporTarihi-$C26))) | Q26: =IF($A26="","",IF($P26="","",IF($P26<=mbk_kovaEsik1,"0-7",IF($P26<=mbk_kovaEsik2,"8-30",IF($P26<=mbk_kovaEsik3,"31-60","60+"))))) | R26: =IF($A26="","",IF($B26="","YETİM",IF(COUNTIF(tblMakineler[MakineId],$B26)=0,"YETİM",""))) | S26: =IF(OR($A26="",$I26=""),"",IF(OR($I26&"|"&$J26="",COUNTIF(ListeIzinliGecis,$I26&"|"&$J26)>0),"","GEÇERSİZ GEÇİŞ")) | T26: =IF($A26="","",IF(OR($E26="",$F26=""),"",IF(ABS($F26-$E26)>zincirTolerans,"ZİNCİR KIRIK","OK"))) | U26: =IF($A26="","",1) | V26: =IF($A26="","",$F26*$N26*mbk_durusKatsayi)
A27: BKM-00022 | C27: 46201 | E27: 3 | F27: 3 | G27: 14 | H27: KALIBRASYON | I27: PLAN | J27: PLAN | L27: B | M27: Bakım notu 22 | N27: 950 | O27: =IF($A27="","",$F27) | P27: =IF($A27="","",IF($J27="YAPILDI",0,IF($C27="","",raporTarihi-$C27))) | Q27: =IF($A27="","",IF($P27="","",IF($P27<=mbk_kovaEsik1,"0-7",IF($P27<=mbk_kovaEsik2,"8-30",IF($P27<=mbk_kovaEsik3,"31-60","60+"))))) | R27: =IF($A27="","",IF($B27="","YETİM",IF(COUNTIF(tblMakineler[MakineId],$B27)=0,"YETİM",""))) | S27: =IF(OR($A27="",$I27=""),"",IF(OR($I27&"|"&$J27="",COUNTIF(ListeIzinliGecis,$I27&"|"&$J27)>0),"","GEÇERSİZ GEÇİŞ")) | T27: =IF($A27="","",IF(OR($E27="",$F27=""),"",IF(ABS($F27-$E27)>zincirTolerans,"ZİNCİR KIRIK","OK"))) | U27: =IF($A27="","",1) | V27: =IF($A27="","",$F27*$N27*mbk_durusKatsayi)
A28: BKM-00023 | B28: MAK-00007 | C28: 46244 | D28: 46244 | E28: 3.5 | F28: 3.5 | G28: 11 | H28: ACIL | I28: KRITIK | J28: YAPILDI | K28: İMZA-023 | L28: A | M28: Bakım notu 23 | N28: 1000 | O28: =IF($A28="","",$F28) | P28: =IF($A28="","",IF($J28="YAPILDI",0,IF($C28="","",raporTarihi-$C28))) | Q28: =IF($A28="","",IF($P28="","",IF($P28<=mbk_kovaEsik1,"0-7",IF($P28<=mbk_kovaEsik2,"8-30",IF($P28<=mbk_kovaEsik3,"31-60","60+"))))) | R28: =IF($A28="","",IF($B28="","YETİM",IF(COUNTIF(tblMakineler[MakineId],$B28)=0,"YETİM",""))) | S28: =IF(OR($A28="",$I28=""),"",IF(OR($I28&"|"&$J28="",COUNTIF(ListeIzinliGecis,$I28&"|"&$J28)>0),"","GEÇERSİZ GEÇİŞ")) | T28: =IF($A28="","",IF(OR($E28="",$F28=""),"",IF(ABS($F28-$E28)>zincirTolerans,"ZİNCİR KIRIK","OK"))) | U28: =IF($A28="","",1) | V28: =IF($A28="","",$F28*$N28*mbk_durusKatsayi)
A29: BKM-00024 | B29: MAK-00008 | C29: 46242 | E29: 2 | F29: 2 | G29: 8 | H29: ONLEYICI | I29: PLAN | J29: PLAN | L29: B | M29: Bakım notu 24 | N29: 1050 | O29: =IF($A29="","",$F29) | P29: =IF($A29="","",IF($J29="YAPILDI",0,IF($C29="","",raporTarihi-$C29))) | Q29: =IF($A29="","",IF($P29="","",IF($P29<=mbk_kovaEsik1,"0-7",IF($P29<=mbk_kovaEsik2,"8-30",IF($P29<=mbk_kovaEsik3,"31-60","60+"))))) | R29: =IF($A29="","",IF($B29="","YETİM",IF(COUNTIF(tblMakineler[MakineId],$B29)=0,"YETİM",""))) | S29: =IF(OR($A29="",$I29=""),"",IF(OR($I29&"|"&$J29="",COUNTIF(ListeIzinliGecis,$I29&"|"&$J29)>0),"","GEÇERSİZ GEÇİŞ")) | T29: =IF($A29="","",IF(OR($E29="",$F29=""),"",IF(ABS($F29-$E29)>zincirTolerans,"ZİNCİR KIRIK","OK"))) | U29: =IF($A29="","",1) | V29: =IF($A29="","",$F29*$N29*mbk_durusKatsayi)
A30: BKM-00025 | B30: MAK-99999 | C30: 46240 | E30: 2.5 | F30: 2.5 | G30: 5 | H30: DUZELTICI | J30: PLAN | L30: A | M30: Bakım notu 25 | N30: 850 | O30: =IF($A30="","",$F30) | P30: =IF($A30="","",IF($J30="YAPILDI",0,IF($C30="","",raporTarihi-$C30))) | Q30: =IF($A30="","",IF($P30="","",IF($P30<=mbk_kovaEsik1,"0-7",IF($P30<=mbk_kovaEsik2,"8-30",IF($P30<=mbk_kovaEsik3,"31-60","60+"))))) | R30: =IF($A30="","",IF($B30="","YETİM",IF(COUNTIF(tblMakineler[MakineId],$B30)=0,"YETİM",""))) | S30: =IF(OR($A30="",$I30=""),"",IF(OR($I30&"|"&$J30="",COUNTIF(ListeIzinliGecis,$I30&"|"&$J30)>0),"","GEÇERSİZ GEÇİŞ")) | T30: =IF($A30="","",IF(OR($E30="",$F30=""),"",IF(ABS($F30-$E30)>zincirTolerans,"ZİNCİR KIRIK","OK"))) | U30: =IF($A30="","",1) | V30: =IF($A30="","",$F30*$N30*mbk_durusKatsayi)
A31: BKM-00026 | B31: MAK-00002 | C31: 46238 | E31: 3 | F31: 3 | G31: 2 | H31: KALIBRASYON | I31: PLAN | J31: GECIKME | L31: B | M31: Bakım notu 26 | N31: 900 | O31: =IF($A31="","",$F31) | P31: =IF($A31="","",IF($J31="YAPILDI",0,IF($C31="","",raporTarihi-$C31))) | Q31: =IF($A31="","",IF($P31="","",IF($P31<=mbk_kovaEsik1,"0-7",IF($P31<=mbk_kovaEsik2,"8-30",IF($P31<=mbk_kovaEsik3,"31-60","60+"))))) | R31: =IF($A31="","",IF($B31="","YETİM",IF(COUNTIF(tblMakineler[MakineId],$B31)=0,"YETİM",""))) | S31: =IF(OR($A31="",$I31=""),"",IF(OR($I31&"|"&$J31="",COUNTIF(ListeIzinliGecis,$I31&"|"&$J31)>0),"","GEÇERSİZ GEÇİŞ")) | T31: =IF($A31="","",IF(OR($E31="",$F31=""),"",IF(ABS($F31-$E31)>zincirTolerans,"ZİNCİR KIRIK","OK"))) | U31: =IF($A31="","",1) | V31: =IF($A31="","",$F31*$N31*mbk_durusKatsayi)
A32: BKM-00027 | B32: MAK-00003 | C32: 46236 | D32: 46236 | E32: 3.5 | F32: 3.5 | G32: -1 | H32: ACIL | I32: GECIKME | J32: YAPILDI | K32: İMZA-027 | L32: A | M32: Bakım notu 27 | N32: 950 | O32: =IF($A32="","",$F32) | P32: =IF($A32="","",IF($J32="YAPILDI",0,IF($C32="","",raporTarihi-$C32))) | Q32: =IF($A32="","",IF($P32="","",IF($P32<=mbk_kovaEsik1,"0-7",IF($P32<=mbk_kovaEsik2,"8-30",IF($P32<=mbk_kovaEsik3,"31-60","60+"))))) | R32: =IF($A32="","",IF($B32="","YETİM",IF(COUNTIF(tblMakineler[MakineId],$B32)=0,"YETİM",""))) | S32: =IF(OR($A32="",$I32=""),"",IF(OR($I32&"|"&$J32="",COUNTIF(ListeIzinliGecis,$I32&"|"&$J32)>0),"","GEÇERSİZ GEÇİŞ")) | T32: =IF($A32="","",IF(OR($E32="",$F32=""),"",IF(ABS($F32-$E32)>zincirTolerans,"ZİNCİR KIRIK","OK"))) | U32: =IF($A32="","",1) | V32: =IF($A32="","",$F32*$N32*mbk_durusKatsayi)
A33: BKM-00028 | B33: MAK-00004 | C33: 46234 | E33: 2 | F33: 2 | G33: -4 | H33: ONLEYICI | I33: GECIKME | J33: KRITIK | L33: B | M33: Bakım notu 28 | N33: 1000 | O33: =IF($A33="","",$F33) | P33: =IF($A33="","",IF($J33="YAPILDI",0,IF($C33="","",raporTarihi-$C33))) | Q33: =IF($A33="","",IF($P33="","",IF($P33<=mbk_kovaEsik1,"0-7",IF($P33<=mbk_kovaEsik2,"8-30",IF($P33<=mbk_kovaEsik3,"31-60","60+"))))) | R33: =IF($A33="","",IF($B33="","YETİM",IF(COUNTIF(tblMakineler[MakineId],$B33)=0,"YETİM",""))) | S33: =IF(OR($A33="",$I33=""),"",IF(OR($I33&"|"&$J33="",COUNTIF(ListeIzinliGecis,$I33&"|"&$J33)>0),"","GEÇERSİZ GEÇİŞ")) | T33: =IF($A33="","",IF(OR($E33="",$F33=""),"",IF(ABS($F33-$E33)>zincirTolerans,"ZİNCİR KIRIK","OK"))) | U33: =IF($A33="","",1) | V33: =IF($A33="","",$F33*$N33*mbk_durusKatsayi)
O34: =IF($A34="","",$F34) | P34: =IF($A34="","",IF($J34="YAPILDI",0,IF($C34="","",raporTarihi-$C34))) | Q34: =IF($A34="","",IF($P34="","",IF($P34<=mbk_kovaEsik1,"0-7",IF($P34<=mbk_kovaEsik2,"8-30",IF($P34<=mbk_kovaEsik3,"31-60","60+"))))) | R34: =IF($A34="","",IF($B34="","YETİM",IF(COUNTIF(tblMakineler[MakineId],$B34)=0,"YETİM",""))) | S34: =IF(OR($A34="",$I34=""),"",IF(OR($I34&"|"&$J34="",COUNTIF(ListeIzinliGecis,$I34&"|"&$J34)>0),"","GEÇERSİZ GEÇİŞ")) | T34: =IF($A34="","",IF(OR($E34="",$F34=""),"",IF(ABS($F34-$E34)>zincirTolerans,"ZİNCİR KIRIK","OK"))) | U34: =IF($A34="","",1) | V34: =IF($A34="","",$F34*$N34*mbk_durusKatsayi)
O35: =IF($A35="","",$F35) | P35: =IF($A35="","",IF($J35="YAPILDI",0,IF($C35="","",raporTarihi-$C35))) | Q35: =IF($A35="","",IF($P35="","",IF($P35<=mbk_kovaEsik1,"0-7",IF($P35<=mbk_kovaEsik2,"8-30",IF($P35<=mbk_kovaEsik3,"31-60","60+"))))) | R35: =IF($A35="","",IF($B35="","YETİM",IF(COUNTIF(tblMakineler[MakineId],$B35)=0,"YETİM",""))) | S35: =IF(OR($A35="",$I35=""),"",IF(OR($I35&"|"&$J35="",COUNTIF(ListeIzinliGecis,$I35&"|"&$J35)>0),"","GEÇERSİZ GEÇİŞ")) | T35: =IF($A35="","",IF(OR($E35="",$F35=""),"",IF(ABS($F35-$E35)>zincirTolerans,"ZİNCİR KIRIK","OK"))) | U35: =IF($A35="","",1) | V35: =IF($A35="","",$F35*$N35*mbk_durusKatsayi)
O36: =IF($A36="","",$F36) | P36: =IF($A36="","",IF($J36="YAPILDI",0,IF($C36="","",raporTarihi-$C36))) | Q36: =IF($A36="","",IF($P36="","",IF($P36<=mbk_kovaEsik1,"0-7",IF($P36<=mbk_kovaEsik2,"8-30",IF($P36<=mbk_kovaEsik3,"31-60","60+"))))) | R36: =IF($A36="","",IF($B36="","YETİM",IF(COUNTIF(tblMakineler[MakineId],$B36)=0,"YETİM",""))) | S36: =IF(OR($A36="",$I36=""),"",IF(OR($I36&"|"&$J36="",COUNTIF(ListeIzinliGecis,$I36&"|"&$J36)>0),"","GEÇERSİZ GEÇİŞ")) | T36: =IF($A36="","",IF(OR($E36="",$F36=""),"",IF(ABS($F36-$E36)>zincirTolerans,"ZİNCİR KIRIK","OK"))) | U36: =IF($A36="","",1) | V36: =IF($A36="","",$F36*$N36*mbk_durusKatsayi)
O37: =IF($A37="","",$F37) | P37: =IF($A37="","",IF($J37="YAPILDI",0,IF($C37="","",raporTarihi-$C37))) | Q37: =IF($A37="","",IF($P37="","",IF($P37<=mbk_kovaEsik1,"0-7",IF($P37<=mbk_kovaEsik2,"8-30",IF($P37<=mbk_kovaEsik3,"31-60","60+"))))) | R37: =IF($A37="","",IF($B37="","YETİM",IF(COUNTIF(tblMakineler[MakineId],$B37)=0,"YETİM",""))) | S37: =IF(OR($A37="",$I37=""),"",IF(OR($I37&"|"&$J37="",COUNTIF(ListeIzinliGecis,$I37&"|"&$J37)>0),"","GEÇERSİZ GEÇİŞ")) | T37: =IF($A37="","",IF(OR($E37="",$F37=""),"",IF(ABS($F37-$E37)>zincirTolerans,"ZİNCİR KIRIK","OK"))) | U37: =IF($A37="","",1) | V37: =IF($A37="","",$F37*$N37*mbk_durusKatsayi)
O38: =IF($A38="","",$F38) | P38: =IF($A38="","",IF($J38="YAPILDI",0,IF($C38="","",raporTarihi-$C38))) | Q38: =IF($A38="","",IF($P38="","",IF($P38<=mbk_kovaEsik1,"0-7",IF($P38<=mbk_kovaEsik2,"8-30",IF($P38<=mbk_kovaEsik3,"31-60","60+"))))) | R38: =IF($A38="","",IF($B38="","YETİM",IF(COUNTIF(tblMakineler[MakineId],$B38)=0,"YETİM",""))) | S38: =IF(OR($A38="",$I38=""),"",IF(OR($I38&"|"&$J38="",COUNTIF(ListeIzinliGecis,$I38&"|"&$J38)>0),"","GEÇERSİZ GEÇİŞ")) | T38: =IF($A38="","",IF(OR($E38="",$F38=""),"",IF(ABS($F38-$E38)>zincirTolerans,"ZİNCİR KIRIK","OK"))) | U38: =IF($A38="","",1) | V38: =IF($A38="","",$F38*$N38*mbk_durusKatsayi)
O39: =IF($A39="","",$F39) | P39: =IF($A39="","",IF($J39="YAPILDI",0,IF($C39="","",raporTarihi-$C39))) | Q39: =IF($A39="","",IF($P39="","",IF($P39<=mbk_kovaEsik1,"0-7",IF($P39<=mbk_kovaEsik2,"8-30",IF($P39<=mbk_kovaEsik3,"31-60","60+"))))) | R39: =IF($A39="","",IF($B39="","YETİM",IF(COUNTIF(tblMakineler[MakineId],$B39)=0,"YETİM",""))) | S39: =IF(OR($A39="",$I39=""),"",IF(OR($I39&"|"&$J39="",COUNTIF(ListeIzinliGecis,$I39&"|"&$J39)>0),"","GEÇERSİZ GEÇİŞ")) | T39: =IF($A39="","",IF(OR($E39="",$F39=""),"",IF(ABS($F39-$E39)>zincirTolerans,"ZİNCİR KIRIK","OK"))) | U39: =IF($A39="","",1) | V39: =IF($A39="","",$F39*$N39*mbk_durusKatsayi)
O40: =IF($A40="","",$F40) | P40: =IF($A40="","",IF($J40="YAPILDI",0,IF($C40="","",raporTarihi-$C40))) | Q40: =IF($A40="","",IF($P40="","",IF($P40<=mbk_kovaEsik1,"0-7",IF($P40<=mbk_kovaEsik2,"8-30",IF($P40<=mbk_kovaEsik3,"31-60","60+"))))) | R40: =IF($A40="","",IF($B40="","YETİM",IF(COUNTIF(tblMakineler[MakineId],$B40)=0,"YETİM",""))) | S40: =IF(OR($A40="",$I40=""),"",IF(OR($I40&"|"&$J40="",COUNTIF(ListeIzinliGecis,$I40&"|"&$J40)>0),"","GEÇERSİZ GEÇİŞ")) | T40: =IF($A40="","",IF(OR($E40="",$F40=""),"",IF(ABS($F40-$E40)>zincirTolerans,"ZİNCİR KIRIK","OK"))) | U40: =IF($A40="","",1) | V40: =IF($A40="","",$F40*$N40*mbk_durusKatsayi)
O41: =IF($A41="","",$F41) | P41: =IF($A41="","",IF($J41="YAPILDI",0,IF($C41="","",raporTarihi-$C41))) | Q41: =IF($A41="","",IF($P41="","",IF($P41<=mbk_kovaEsik1,"0-7",IF($P41<=mbk_kovaEsik2,"8-30",IF($P41<=mbk_kovaEsik3,"31-60","60+"))))) | R41: =IF($A41="","",IF($B41="","YETİM",IF(COUNTIF(tblMakineler[MakineId],$B41)=0,"YETİM",""))) | S41: =IF(OR($A41="",$I41=""),"",IF(OR($I41&"|"&$J41="",COUNTIF(ListeIzinliGecis,$I41&"|"&$J41)>0),"","GEÇERSİZ GEÇİŞ")) | T41: =IF($A41="","",IF(OR($E41="",$F41=""),"",IF(ABS($F41-$E41)>zincirTolerans,"ZİNCİR KIRIK","OK"))) | U41: =IF($A41="","",1) | V41: =IF($A41="","",$F41*$N41*mbk_durusKatsayi)
O42: =IF($A42="","",$F42) | P42: =IF($A42="","",IF($J42="YAPILDI",0,IF($C42="","",raporTarihi-$C42))) | Q42: =IF($A42="","",IF($P42="","",IF($P42<=mbk_kovaEsik1,"0-7",IF($P42<=mbk_kovaEsik2,"8-30",IF($P42<=mbk_kovaEsik3,"31-60","60+"))))) | R42: =IF($A42="","",IF($B42="","YETİM",IF(COUNTIF(tblMakineler[MakineId],$B42)=0,"YETİM",""))) | S42: =IF(OR($A42="",$I42=""),"",IF(OR($I42&"|"&$J42="",COUNTIF(ListeIzinliGecis,$I42&"|"&$J42)>0),"","GEÇERSİZ GEÇİŞ")) | T42: =IF($A42="","",IF(OR($E42="",$F42=""),"",IF(ABS($F42-$E42)>zincirTolerans,"ZİNCİR KIRIK","OK"))) | U42: =IF($A42="","",1) | V42: =IF($A42="","",$F42*$N42*mbk_durusKatsayi)
...

Sheet KUYRUKLAR
A1: KUYRUKLAR — Makine Bakım & Kalibrasyon + Duruş Maliyeti
A3: Durum bazlı canlı kuyruk — kapalı kayıtlar düşer
A5: Kuyruk | B5: Adet | C5: Duruş Saat
A6: Kuyruk Plan | B6: =COUNTIFS(tblAkis[Durum],"PLAN",tblAkis[KayitDolu],">0") | C6: =SUMIF(tblAkis[Durum],"PLAN",tblAkis[FiiliDurusSaat])
A7: Kuyruk Gecikme | B7: =COUNTIFS(tblAkis[Durum],"GECIKME",tblAkis[KayitDolu],">0") | C7: =SUMIF(tblAkis[Durum],"GECIKME",tblAkis[FiiliDurusSaat])
A8: Kuyruk Kritik | B8: =COUNTIFS(tblAkis[Durum],"KRITIK",tblAkis[KayitDolu],">0") | C8: =SUMIF(tblAkis[Durum],"KRITIK",tblAkis[FiiliDurusSaat])
A9: Duruş eşik aşımı (fiili>eşik) | B9: =COUNTIFS(tblAkis[FiiliDurusSaat],">"&mbk_esikDurusSaat,tblAkis[Durum],"<>YAPILDI",tblAkis[KayitDolu],">0") | C9: =SUMIFS(tblAkis[FiiliDurusSaat],tblAkis[FiiliDurusSaat],">"&mbk_esikDurusSaat,tblAkis[Durum],"<>YAPILDI")
A11: Kapalı (Yapıldı) — kuyruktan düşer
A12: Yapıldı | B12: =COUNTIF(tblAkis[Durum],"YAPILDI") | C12: =SUMIF(tblAkis[Durum],"YAPILDI",tblAkis[FiiliDurusSaat])
A15: Kuyruk Özeti | B15: =mbk_kuyrukOzeti
A17: Yaş Kova Dağılımı
A18: 0-7 | B18: =COUNTIF(tblAkis[YasKova],"0-7") | C18: =SUMIF(tblAkis[YasKova],"0-7",tblAkis[FiiliDurusSaat])
A19: 8-30 | B19: =COUNTIF(tblAkis[YasKova],"8-30") | C19: =SUMIF(tblAkis[YasKova],"8-30",tblAkis[FiiliDurusSaat])
A20: 31-60 | B20: =COUNTIF(tblAkis[YasKova],"31-60") | C20: =SUMIF(tblAkis[YasKova],"31-60",tblAkis[FiiliDurusSaat])
A21: 60+ | B21: =COUNTIF(tblAkis[YasKova],"60+") | C21: =SUMIF(tblAkis[YasKova],"60+",tblAkis[FiiliDurusSaat])

Sheet HESAP
A1: HESAP — Makine Bakım & Kalibrasyon + Duruş Maliyeti
A3: Hesap motoru — ≥40 adım; sabitler AYARLAR'dan
A5: Adım | B5: Açıklama | C5: Değer
A6: H01 | B6: Toplam bakım | C6: =COUNTA(tblAkis[BakimId])
A7: H02 | B7: Dolu kayıt | C7: =SUM(tblAkis[KayitDolu])
A8: H03 | B8: Toplam duruş saat | C8: =SUM(tblAkis[FiiliDurusSaat])
A9: H04 | B9: Hesaplanan duruş toplam | C9: =SUM(tblAkis[HesaplananDurus])
A10: H05 | B10: Plan duruş toplam | C10: =SUM(tblAkis[PlanDurusSaat])
A11: H06 | B11: Plan adet | C11: =COUNTIF(tblAkis[Durum],"PLAN")
A12: H07 | B12: Gecikme adet | C12: =COUNTIF(tblAkis[Durum],"GECIKME")
A13: H08 | B13: Kritik adet | C13: =COUNTIF(tblAkis[Durum],"KRITIK")
A14: H09 | B14: Yapıldı adet | C14: =COUNTIF(tblAkis[Durum],"YAPILDI")
A15: H10 | B15: Kalibrasyon aşım adet | C15: =COUNTIFS(tblAkis[KalibrasyonGunKalan],"<0",tblAkis[KayitDolu],">0")
A16: H11 | B16: Açık kuyruk adet | C16: =C11+C12+C13
A17: H12 | B17: Kapalı düşüm adet | C17: =C14
A18: H13 | B18: Açık duruş kuyruk | C18: =SUMIF(tblAkis[Durum],"PLAN",tblAkis[FiiliDurusSaat])+SUMIF(tblAkis[Durum],"GECIKME",tblAkis[FiiliDurusSaat])+SUMIF(tblAkis[Durum],"KRITIK",tblAkis[FiiliDurusSaat])
A19: H14 | B19: Yetim adet | C19: =COUNTIF(tblAkis[YetimBayrak],"YETİM")
A20: H15 | B20: Geçersiz geçiş | C20: =COUNTIF(tblAkis[GecisUyarisi],"GEÇERSİZ GEÇİŞ")
A21: H16 | B21: Zincir kırık | C21: =COUNTIF(tblAkis[ZincirBayrak],"ZİNCİR KIRIK")
A22: H17 | B22: Zincir OK | C22: =COUNTIF(tblAkis[ZincirBayrak],"OK")
A23: H18 | B23: Yaş 0-7 | C23: =COUNTIF(tblAkis[YasKova],"0-7")
A24: H19 | B24: Yaş 8-30 | C24: =COUNTIF(tblAkis[YasKova],"8-30")
A25: H20 | B25: Yaş 31-60 | C25: =COUNTIF(tblAkis[YasKova],"31-60")
A26: H21 | B26: Yaş 60+ | C26: =COUNTIF(tblAkis[YasKova],"60+")
A27: H22 | B27: Ort duruş saat | C27: =IFERROR(AVERAGEIF(tblAkis[KayitDolu],1,tblAkis[FiiliDurusSaat]),0)
A28: H23 | B28: Duruş eşik aşım adet | C28: =COUNTIFS(tblAkis[FiiliDurusSaat],">"&mbk_esikDurusSaat,tblAkis[Durum],"<>YAPILDI",tblAkis[KayitDolu],">0")
A29: H24 | B29: Duruş eşik aşım saat | C29: =SUMIFS(tblAkis[FiiliDurusSaat],tblAkis[FiiliDurusSaat],">"&mbk_esikDurusSaat,tblAkis[Durum],"<>YAPILDI")
A30: H25 | B30: Duruş maliyet toplam | C30: =IFERROR(SUMIF(tblAkis[KayitDolu],1,tblAkis[DurusMaliyet]),0)
A31: H26 | B31: Kalibrasyon aşım proxy | C31: =C15
A32: H27 | B32: Haftalık duruş proxy | C32: =C8*mbk_haftalikCarpan
A33: H28 | B33: Duruş sapma (fiili-plan) | C33: =C8-C10
A34: H29 | B34: Temkinli senaryo | C34: =C18*mbk_senaryoTemkinli
A35: H30 | B35: Baz senaryo | C35: =C18*mbk_senaryoBaz
A36: H31 | B36: İyimser senaryo | C36: =C18*mbk_senaryoIyimser
A37: H32 | B37: Senaryo farkı | C37: =C36-C34
A38: H33 | B38: Tornado (oran×duruş) | C38: =C18*mbk_tornadoOran
A39: H34 | B39: HHI proxy | C39: =IFERROR((MAX(C11,C12,C13)/MAX(C16,1))^2,0)
A40: H35 | B40: Kalite skoru | C40: =IF(C6=0,0,MAX(0,mbk_kaliteTaban-C19*mbk_kaliteCeza-C20*mbk_kaliteCeza-C21*mbk_kaliteCeza-C28*mbk_kaliteSapma))
A41: H36 | B41: Tahmin PERCENTILE | C41: =IFERROR(_xlfn.PERCENTILE.INC(tblAkis[FiiliDurusSaat],mbk_yuzdelikOran),0)
A42: H37 | B42: Tahmin FORECAST | C42: =IFERROR(FORECAST(COUNTA(tblAkis[BakimId])+1,tblAkis[FiiliDurusSaat],tblAkis[KayitDolu]),C41)
...

Sheet KURALLAR
A1: KURALLAR — Makine Bakım & Kalibrasyon + Duruş Maliyeti
A3: MBK-001..005 kural tablosu — 2025 / 2026 / 2027
A5: kural_id | B5: madde | C5: aciklama | D5: y2025 | E5: y2026 | F5: y2027 | G5: birim | H5: AktifDeger
A6: MBK-001 | B6: ISO/İç | C6: Planlı bakım periyodu (gün) | D6: 30 | E6: 30 | F6: 30 | G6: gün | H6: =IF(mbk_aktifYil=mbk_yilA,$D6,IF(mbk_aktifYil=mbk_yilC,$F6,$E6))
A7: MBK-002 | B7: ISO/Kal | C7: Kalibrasyon vade eşiği (gün) | D7: 0 | E7: 0 | F7: 0 | G7: gün | H7: =IF(mbk_aktifYil=mbk_yilA,$D7,IF(mbk_aktifYil=mbk_yilC,$F7,$E7))
A8: MBK-003 | B8: İç pol. | C8: Kritik gecikme eşiği (gün) | D8: 14 | E8: 14 | F8: 14 | G8: gün | H8: =IF(mbk_aktifYil=mbk_yilA,$D8,IF(mbk_aktifYil=mbk_yilC,$F8,$E8))
A9: MBK-004 | B9: İşyeri | C9: Duruş maliyet katsayısı | D9: 1 | E9: 1 | F9: 1 | G9: oran | H9: =IF(mbk_aktifYil=mbk_yilA,$D9,IF(mbk_aktifYil=mbk_yilC,$F9,$E9))
A10: MBK-005 | B10: İşyeri | C10: İmza/kanıt zorunluluğu (YAPILDI) | D10: 1 | E10: 1 | F10: 1 | G10: evet | H10: =IF(mbk_aktifYil=mbk_yilA,$D10,IF(mbk_aktifYil=mbk_yilC,$F10,$E10))
A12: Aktif yıl | B12: 2026
A13: Kural yıl matrisi | B13: =mbk_kuralYilMatris

Sheet VAKALAR
