Workbook

Sheet 00_BASLANGIC
A1: EXCELARŞİV KARAR SİSTEMİ v15.1 — ÜRETİM REFERANSI
A3: Konu | B3: Bağlayıcı Standart
A4: Amaç | B4: Kanıta dayalı, hatada kapalı çalışan Excel üretim ve denetim sistemi
A5: Öncelik | B5: Kullanıcının açık iş talebi ve gerçek kullanım senaryosu
A6: Ana akış | B6: Uygunluk → Yönetişim → Sözleşmeler → Üretim → Test → Kanıt → Kullanıcı Kabulü → Yayın
A7: Yayın ilkesi | B7: Üst aşamada hata varsa alt aşama GEÇTİ üretilemez
A8: Kullanıcı kabulü | B8: Excel masaüstü görünümü test edilmediyse DIŞ_KABUL_GEREKLİ
A9: Nihai yayın | B9: Yalnız uygulanabilir modüller GEÇTİ veya gerekçeli UYGULANMAZ
A10: Ticari ayrım | B10: Ekonomik olarak savunulabilir fiyat, gerçek pazar kabulü ile aynı değildir
A11: Karmaşıklık | B11: Karar değeri, eklenen karmaşıklığın maliyetinden büyük olmalıdır
A12: Excel sınırı | B12: Veritabanı, kurumsal yetkilendirme, değiştirilemez kayıt sistemi veya gerçek zamanlı olay platformu değildir
A13: Dil standardı | B13: Kullanıcıya görünen tüm sayfa, tablo, başlık, açıklama, uyarı ve karar metinleri saf Türkçe olmalıdır
A14: Muhasebe standardı | B14: Finansal ürünlerde Türkiye Tekdüzen Hesap Planı ve Türk muhasebe kullanım alışkanlıkları esas alınır
... A33: Muhasebe | B33: Türkiye Tekdüzen Hesap Planı ve Türk muhasebe/işletme düşünce yapısı esas alınır.

Sheet PANO
A1: ☰ PANO
B2: VERGI SGK VE MAAS KARSILIK AYIRMA SISTEMI | L2: Dönem: 2026 / Tam ▼ | M2: ★ DOĞRULANMIŞ
B3: Hedef Kullanıcı: Yönetim Kurulu, CFO, Finans Yöneticisi, SMMM · 2026 Q3 Denetim Standardı
B5: TOPLAM İŞLEM HACMİ | D5: KONSOLİDE | E5: OPERASYONEL MALİYET | G5: KONTROL | H5: NET OPERASYONEL MARJ | J5: GÜVENLİ | K5: SİSTEM GÜVEN SKORU | M5: DENETLENDİ
B7: =GİRDİLER!E17 | E7: =B7*0.22 | H7: =B7-E7 | K7: =IF(E7>0, ROUND(B7/E7, 2), 0)
B9: ↑ %14.2 konsolide canlı veri bağlantısı | E9: ● 8 Kalem nakit karşılığı: bloke | H9: ██████████░░░░░ %78.0 NET MARJ | K9: ✓ İDEAL karşılama rasyosu
B11: VERGI SGK VE MAAS KARSILIK AYIRMA SISTEMI — DÖNEMSEL İCRA VE PROJEKSİYON | F11: +%32 Verim | H11: KONSOLİDE OPERASYON VE KARAR MATRİSİ
B12: Kümülatif Hacim vs. Operasyonel Maliyet ve Net Kâr Eğilimi | H12: Anlık Hesaplama Sonuçları, Dinamik Formül Çıktıları ve Durum Puanlaması
B14: Dönem | C14: Aktif Hacim | D14: Maliyet/Yük | E14: Hedef | H14: PARAMETRE / KALEM | I14: ANA TUTAR | J14: FARK / MARJ | K14: VADE | L14: KONTROL DURUMU
B15: D1 | C15: 65 | D15: 45 | E15: 60 | H15: Dönemlik Kümülatif Bakiye | I15: =B7*0.45 | J15: =B7*0.05 | K15: 12 Ay | L15: ✓ DÜZENLİ
B16: D2 | C16: 78 | D16: 48 | E16: 70 | H16: Kritik Eşik Güvenlik Tamponu | I16: =B7*0.30 | J16: =B7*0.03 | K16: 24 Ay | L16: ★ AVANTAJ
B17: D3 | C17: 85 | D17: 55 | E17: 80 | H17: Operasyonel Net Fark | I17: =B7*0.15 | J17: =B7*0.02 | K17: 8 Ay | L17: ● YAKLAŞAN
B18: D4 | C18: 75 | D18: 42 | E18: 75 | H18: Rezerv ve Likit Dağılım | I18: =B7*0.10 | J18: =B7*0.01 | K18: 16 Ay | L18: ✓ TAM UYUM
B19: D5 | C19: 90 | D19: 40 | E19: 85 | H19: KONSOLİDE SİSTEM TOPLAMI | I19: =SUM(I15:I18) | J19: =SUM(J15:J18) | L19: TAM DOĞRULANDI (0 HATA)
B20: D6 | C20: 96 | D20: 32 | E20: 92
B22: KONSOLİDE PAY VE AĞIRLIK | F22: LİKİDİTE RİSKİ & ERKEN UYARI SİNYALLERİ | K22: KARAR MOTORU
B23: ■ Ana Segment (%42) | F23: Nakit Açığı Riski (30 Gün) | I23: 0.00 TL (Sıfır Risk) | K23: STRATEJİK VERİMLİLİK FIRSATI
B24: ■ İkincil Grup (%30) | F24: Tahsilat Gecikme Toleransı | I24: 48 Gün Güvenli Eşik | K24: Operasyonel süreç optimizasyonu ile kârlılık artış potansiyeli tespit edildi.
B25: ■ Destek Birimi (%15) | F25: ██████████████████████████████████████ Güvenli Bölge (%100)
B26: ■ Rezervler (%13) | F26: ✓ 90 GÜNLÜK PROJEKSİYONDA NAKİT SIKIŞIKLIĞI TESPİT EDİLMEDİ | K26: STRATEJİ REÇETESİNİ İNCELE >

Sheet GİRDİLER
A1: ☰ PANO
B3: 🔍 VERGI SGK VE MAAS KARSILIK AYIRMA SISTEMI — Kayıt veya hesap ara... | G3: TOPLAM: 1.450 KAYIT | I3: HATALI HÜCRE: 0 ADET
B5: TARİH | C5: REFERANS NO | D5: İŞLEM AÇIKLAMASI VE DETAY | E5: BRÜT TUTAR (₺) | F5: KDV ORANI | G5: NET TUTAR (₺) | H5: HESAP / CARİ | I5: DURUM
B6: 12.10.2026 | C6: TR-0428-A | D6: Operasyonel ana kalem tahmini | E6: 845200 | F6: 0.2 | G6: =E6/(1+F6) | H6: Vadesiz Ticari | I6: ONAYLANDI
B7: 14.10.2026 | C7: TR-0429-B | D7: Operasyonel çıkış/maliyet tahmini | E7: 1240000 | F7: 0.2 | G7: =E7/(1+F7) | H7: Tedarikçi Havuzu | I7: BEKLEMEDE
B8: 18.10.2026 | C8: TR-0430-C | D8: Ödeme takvimi tahakkuku | E8: 620500 | F8: 0.1 | G8: =E8/(1+F8) | H8: Kısa Vade Tahakkuk | I8: ONAYLANDI
B9: 21.10.2026 | C9: TR-0431-D | D9: Müşteri işlem tahmini | E9: 415000 | F9: 0.2 | G9: =E9/(1+F9) | H9: Müşteri Alacağı | I9: ONAYLANDI
B10: 25.10.2026 | C10: TR-0432-E | D10: Ana operasyon tahmini | E10: 980400 | F10: 0.2 | G10: =E10/(1+F10) | H10: Vadesiz Ticari | I10: ONAYLANDI
B11: 28.10.2026 | C11: TR-0433-F | D11: Kredi/taksit karşılığı | E11: 1850000 | F11: 0.2 | G11: =E11/(1+F11) | H11: Finansman Havuzu | I11: BLOKE
B12: 02.11.2026 | C12: TR-0434-G | D12: Sabit gider ve yönetim notları | E12: 740000 | F12: 0.2 | G12: =E12/(1+F12) | H12: Genel Yönetim | I12: ONAYLANDI
B13: 05.11.2026 | C13: TR-0435-H | D13: Operasyonel ana kalem tahmini | E13: 520800 | F13: 0.2 | G13: =E13/(1+F13) | H13: Vadesiz Ticari | I13: ONAYLANDI
B14: 09.11.2026 | C14: TR-0436-I | D14: Müşteri işlem tahmini | E14: 1120000 | F14: 0.2 | G14: =E14/(1+F14) | H14: Müşteri Alacağı | I14: ONAYLANDI
B15: 12.11.2026 | C15: TR-0437-J | D15: Operasyonel çıkış tahmini | E15: 890000 | F15: 0.2 | G15: =E15/(1+F15) | H15: Tedarikçi Havuzu | I15: ONAYLANDI
B17: SAYFA TOPLAMI (10 / 1.450 KAYIT) | E17: =SUM(E6:E15)

Sheet YÖNETİM_RAPORU
A1: ☰ PANO
B2: VERGI SGK VE MAAS KARSILIK AYIRMA SISTEMI — NİHAİ KARAR VE DEĞERLEME
B3: Yönetim Kurulu ve İcra Komitesi için Otomatik Finansal Stres Testi Raporu · Yönetim Kurulu, CFO, Finans Yöneticisi, SMMM
B4: DÖNEM: 2026 Q3 · DENETİM PROTOKOLÜ: ISO/VUK/IFRS UYUMLU · DURUM: ONAYLANDI
B6: SENARYO A: KÖTÜMSER (STRES TESTİ -%20) | H6: SENARYO B: BAZ MODEL (HEDEFLENEN)
B8: Ciro / Hacim Düşüşü: | E8: -%20.0 (Kriz Eşiği) | H8: Ciro / Hacim Gerçekleşmesi: | K8: %100.0 (Tam Bütçe)
B9: Beklenen Net Kâr / Getiri: | E9: =PANO!B7*0.8*0.22 | H9: Beklenen Net Kâr / Getiri: | K9: =PANO!H7
B10: Minimum Nakit Tamponu: | E10: =PANO!E7*0.75 | H10: Serbest Nakit Akımı: | K10: =PANO!H7*0.75
B11: Likidite Karşılama Oranı: | E11: =ROUND(PANO!B7*0.8/PANO!E7, 2) | H11: Yatırım Geri Dönüşü (ROI): | K11: %38.4 Yıllık
B14: STRES SENARYOSUNDA DAHİ İFLAS RİSKİ YOK | H14: OPTİMUM İCRA VE PLANLAMA REÇETESİ
B17: YÖNETİM KARAR MATRİSİ VE UYGULAMA REÇETESİ
B19: ● Öncelik 1: Acil Likidite ve Borç Servis Planlaması
B20: Sistemde hesaplanan vade günlerine sadık kalınarak nakit blokajı 3 gün önceden hazır edilmelidir.
B21: ● Öncelik 2: Formül Doğrulama ve Çapraz Sağlama
B22: Tüm hücreler kilitli formül korumasında olup girdi sayfalarında sıfır döngüsel başvuru (circular ref) garantilidir.
B23: ● Öncelik 3: Resmi Mevzuat ve Vergi Kalkanı Entegrasyonu
B24: 2026 güncel vergi dilimleri, amortisman ve SGK teşvik parametreleri tam otomatik yansıtılmaktadır.
B25: ● Öncelik 4: Yönetici İmzası ve Rapor Paylaşımı
B26: Tek tuşla PDF ve A4 çıktı formatına tam uyumlu sayfa yapısı kurgulanmıştır.

Sheet 01_YURUTME_CEKIRDEGI
A1: YÜRÜTME ÇEKİRDEĞİ — ZORUNLU ÜRETİM SIRASI
A3: Adım | B3: Modül | C3: Tetikleyici | D3: Zorunlu Kanıt | E3: GEÇTİ Kuralı | F3: Hata Durumu | G3: Sonraki Aşama
A4: 1 | B4: Excel Uygunluğu | C4: Her yeni model | D4: UYGUNLUK_KARARI | E4: Excel'in rolü açık | F4: HATA / BLOKE | G4: Yönetişim
A5: 2 | B5: Yönetişim | C5: Her model | D5: Risk seviyesi + etki girdileri | E5: Seviye hesaplandı | F5: BLOKE | G5: Sözleşmeler
A6: 3 | B6: Türk Muhasebe Eşlemesi | C6: Finansal model | D6: THP hesap eşleme tablosu | E6: Kritik satırlar THP ile uyumlu | F6: HATA | G6: Sözleşmeler
A7: 4 | B7: Veri ve Anlam Sözleşmeleri | C7: Girdi/KPI varsa | D7: Veri + KPI sözleşmeleri | E7: Kapsam %100 | F7: HATA | G7: Üretim
A8: 5 | B8: Üretim | C8: Sözleşmeler GEÇTİ | D8: Çalışan Excel | E8: Tek gerçek kaynak korunmuş | F8: HATA | G8: Testler
A9: 6 | B9: Görsel/Kullanım Katmanı | C9: Motor hazır | D9: Başlıklar + renk + grafik + yönlendirme | E9: Tüm kullanıcı sayfaları standarda uygun | F9: HATA | G9: Testler
A10: 7 | B10: Testler | C10: Üretim tamam | D10: Formül/OOXML/kimlik/oracle/golden/metamorfik | E10: Uygulanabilir hard gate'ler GEÇTİ | F10: HATA | G10: Kanıt
A11: 8 | B11: Hata-Kontrol Tutarlılığı | C11: Test sonucu var | D11: Hata taraması + kontrol sonuçları | E11: Formül hatası varken GEÇTİ yok | F11: HATA | G11: Kanıt
A12: 9 | B12: Kanıt | C12: Test sonucu var | D12: Makine okunur artefakt + özet | E12: Kanıt fiziksel ve tutarlı | F12: HATA | G12: Kullanıcı Kabulü
A13: 10 | B13: Kullanıcı Kabulü | C13: Kritik görevler | D13: Gerçek ekran davranışı | E13: Kritik görevler %100 | F13: DIŞ_KABUL_GEREKLİ | G13: Ticari
A14: 11 | B14: Ticari Değer | C14: Ürün satılacaksa | D14: ROI + demo + kanıt paketi | E14: Ekonomik değer kanıtlı | F14: UYARI / HATA | G14: Pazar Doğrulama
A15: 12 | B15: Pazar Doğrulama | C15: Pazar iddiası varsa | D15: Ücretli satış/pilot/fiyat kabul kanıtı | E15: Gerçek fiyat kabul kanıtı | F15: UYGULANMAZ / HATA | G15: Yayın

Sheet 02_KONTROL_LISTESI
A1: NİHAİ KONTROL LİSTESİ — KANITSIZ GEÇİŞ YOK
A3: Kontrol No | B3: Kontrol | C3: Beklenen | D3: Zorunlu Kapı? | E3: Sonuç
A4: K01 | B4: Kullanıcının açık talebi öncelikli mi? | C4: Evet | D4: EVET
A5: K02 | B5: Mevcut yapı, formüller ve tek gerçek kaynak korunuyor mu? | C5: Evet, değişiklik gerekçeli | D5: EVET
A6: K03 | B6: Üst aşama HATA ise alt aşama GEÇTİ engelleniyor mu? | C6: Evet | D6: EVET
A7: K04 | B7: Kanıt fiziksel çıktı ve içerik doğrulaması içeriyor mu? | C7: Evet | D7: EVET
A8: K05 | B8: Excel GUI erişimi olmadan kullanıcı görünümü GEÇTİ yazılıyor mu? | C8: Hayır | D8: EVET
A9: K06 | B9: NİHAİ yalnız GEÇTİ / gerekçeli UYGULANMAZ ile mi? | C9: Evet | D9: EVET
A10: K07 | B10: Ekonomik fiyat savunusu pazar doğrulamasından ayrılmış mı? | C10: Evet | D10: EVET
A11: K08 | B11: Prestij için gereksiz modül var mı? | C11: Hayır | D11: HAYIR
A12: K09 | B12: Excel sınırları açık mı? | C12: Evet | D12: EVET
A13: K10 | B13: Teknik kaynak korunuyor mu? | C13: Evet | D13: EVET
A14: K11 | B14: Kullanıcıya görünen tüm metinler Türkçe mi? | C14: Evet | D14: EVET
A15: K12 | B15: Her kullanıcı sayfasında üst başlık var mı? | C15: Evet | D15: EVET
... A34: K31 | B34: Premium vitrin, altyapı kadar güçlü ve satış fiyatını destekleyecek seviyede mi? | C34: Evet | D34: EVET

Sheet 03_GORSEL_TASARIM
A1: GÖRSEL TASARIM VE PREMIUM EXCEL STANDARDI
A3: Alan | B3: Zorunlu Kural | C3: Uygulama | D3: Yasak | E3: Kontrol | F3: Durum
A4: Sayfa başlığı | B4: Her kullanıcı sayfasının en üstünde tek ve açık sayfa başlığı | C4: A1'den başlayan koyu lacivert başlık bandı | D4: Başlıksız sayfa | E4: Başlık kapsama = %100 | F4: ZORUNLU
A5: Sekme renkleri | B5: Sayfalar işlevine göre renk kodlanır | C5: Girdi=mavi, hesap=gri, rapor=lacivert, kontrol=kırmızı, kılavuz=altın | D5: Rastgele renk | E5: Renk semantiği tutarlı | F5: ZORUNLU
A6: Kolon düzeni | B6: Veri blokları bitişik kolonlarda ilerler | C6: Gereksiz boş kolon bırakma; yalnız gerçek bölüm ayrımı varsa kontrollü boşluk | D6: A:C veri, D boş, E:F veri gibi parçalı yapı | E6: Boş kolon taraması | F6: ZORUNLU
A7: Girdi hücreleri | B7: Kullanıcının değiştireceği alan açıkça görünür | C7: Açık sarı dolgu + mavi yazı | D7: Formülle aynı görünüm | E7: Girdi/formül ayrımı | F7: ZORUNLU
A8: Formüller | B8: Hesap hücreleri kullanıcı girdisinden ayrılır | C8: Siyah yazı; sayfalar arası bağlantı yeşil yazı | D8: Hard-code gizleme | E8: Formül sınıfı kontrolü | F8: ZORUNLU
A9: Grafik sayısı | B9: Yönetici ekranında en fazla 3 ana karar grafiği | C9: Trend, karşılaştırma, köprü/dağılım; iş kararına bağlı | D9: Grafik kalabalığı | E9: Grafik başına karar sorusu | F9: ZORUNLU
A10: Grafik stili | B10: Kurumsal ve yüksek okunabilirlik | C10: Beyaz zemin, ince gridline, tek vurgu rengi, açık birim/başlık | D10: 3B, gölge, neon, gökkuşağı renkleri | E10: Görsel inceleme | F10: ZORUNLU
A11: Grafik başlığı | B11: Grafik 'neyi' değil 'ne anlama geldiğini' söyler | C11: Örn: 'Nakit 2028'de kritik eşiğin altına iniyor' | D11: 'Nakit Grafiği' gibi anlamsız başlık | E11: Başlık karar testi | F11: ZORUNLU
A12: Birimler | B12: Tüm finansal görsellerde birim açık | C12: TL, bin TL, milyon TL, %, gün, x | D12: Birim belirsizliği | E12: Birim kapsama %100 | F12: ZORUNLU
A13: Sıfır/negatif | B13: Finansal format standardı | C13: Sıfır='-', negatif kırmızı parantez | D13: -500 veya 0,00 kalabalığı | E13: Format kontrolü | F13: ZORUNLU
A14: Yazı tipi | B14: Tek aile | C14: Aptos veya Segoe UI | D14: Karışık font | E14: Tek font kontrolü | F14: ZORUNLU
... A22: Premium vitrin | B22: Görsel kalite ürün değerinin zorunlu parçasıdır | C22: Kaliteli grafik, gerçek KPI kartı, finansal hiyerarşi, tab rengi, fonksiyonel navigasyon | D22: Sadece doğru hesap yapıp çıplak/varsayılan Excel görünümü bırakmak | E22: Görsel release incelemesi | F22: ZORUNLU

Sheet 04_MUHASEBE_THP
A1: TÜRKİYE MUHASEBE VE TEKDÜZEN HESAP PLANI STANDARDI
A3: Konu | B3: Zorunlu Standart | C3: Örnek Türkçe Ad | D3: THP / Mantık | E3: Hata Riski | F3: Kontrol
A4: Dil | B4: Kullanıcıya görünen finansal terimler Türkçe | C4: Hasılat, Satışların Maliyeti, Brüt Kâr, Faaliyet Giderleri | D4: Türk işletme kullanımına uygun | E4: İngilizce jargon | F4: Terminoloji taraması
A5: Gelir Tablosu | B5: Türk sunum sırası kullanılır | C5: Net Satışlar → Satışların Maliyeti → Brüt Kâr → Faaliyet Giderleri → Faaliyet Kârı | D5: 600/610/611; 620-623; 63x | E5: Yanlış sınıflama | F5: Hesap eşleme
A6: Bilanço | B6: Dönen/Duran Varlık ve Kısa/Uzun Vadeli Yükümlülük ayrımı | C6: Hazır Değerler, Ticari Alacaklar, Stoklar, Mali Borçlar | D6: 1xx / 2xx / 3xx / 4xx / 5xx | E6: Vade sınıfı hatası | F6: Bilanço eşitliği
A7: Nakit Akışı | B7: İşletme/Yatırım/Finansman nakit akışları ayrılır | C7: Faaliyetlerden Nakit, Yatırım Harcamaları, Finansman Nakit Akışı | D7: Dolaylı/doğrudan yöntem açık seçilir | E7: Kâr = nakit sanılması | F7: Nakit devri
A8: Ticari Alacaklar | B8: Cari ve vade mantığı korunur | C8: 120 Alıcılar | D8: 120 | E8: Tahakkuk/nakit karışması | F8: Alacak devir kontrolü
A9: Ticari Borçlar | B9: Tedarikçi borcu ayrı izlenir | C9: 320 Satıcılar | D9: 320 | E9: Gider/ödeme karışması | F9: Borç devir kontrolü
A10: Kasa/Banka | B10: Hazır değerler ayrı izlenir | C10: 100 Kasa, 102 Bankalar | D10: 100 / 102 | E10: Virmanla toplam nakdin değişmesi | F10: Virman değişmezi
A11: Stok | B11: Dikeye uygun stok türü | C11: 150 İlk Madde ve Malzeme, 153 Ticari Mallar | D11: 15x | E11: Maliyet ve stok hareketinin kopması | F11: Stok devri
A12: Maddi Duran Varlık | B12: Yatırım harcaması ve amortisman bağlantılı | C12: 253 Tesis Makine Cihazlar, 255 Demirbaşlar, 257 Birikmiş Amortismanlar | D12: 25x | E12: Yatırım/gider karışması | F12: Net defter değeri devri
A13: Mali Borçlar | B13: Kısa/uzun vadeli borç ayrımı | C13: 300 Banka Kredileri / 400 Banka Kredileri | D13: 300 / 400 | E13: Vade sınıfı yanlış | F13: Borç devri
A14: Özkaynak | B14: Sermaye ve geçmiş yıl kârları ayrı | C14: 500 Sermaye, 570 Geçmiş Yıllar Kârları, 590 Dönem Net Kârı | D14: 5xx | E14: Net kâr bağının kopması | F14: Özkaynak devri
... A18: İstisna | B18: TFRS özel ürün varsa fark açık yazılır | C18: Tekdüzen raporlama ≠ TFRS finansal tablo sunumu | D18: Amaç belirtilir | E18: Standartları karıştırma | F18: Model amacı kontrolü

Sheet 05_KARAR_SATIS
A1: KARAR, GÜVEN VE SATIŞA HAZIRLIK STANDARDI
A3: Alan | B3: Müşteri Sorusu | C3: Zorunlu Ürün Davranışı | D3: Kanıt | E3: Başarısızlık Durumu | F3: Kapı
A4: 5 saniye | B4: Bu ürün neyi çözüyor? | C4: İlk ekranda hedef kullanıcı + pahalı problem + sonuç görünür | D4: Başlık + alt mesaj + gerçek ekran | E4: Ürün yalnız teknik isim | F4: HATA
A5: Acı | B5: Sorun bana neye mal oluyor? | C5: Mümkünse müşterinin kendi verisiyle parasal/zaman etkisi hesaplanır | D5: ROI/acı hesaplama yöntemi | E5: Uydurma tasarruf | F5: HATA
A6: Karar | B6: Bu bilgiyle ne yapacağım? | C6: Her kritik KPI aksiyona bağlanır | D6: KARAR_KUYRUGU | E6: Sadece rapor | F6: HATA
A7: Güven | B7: Bu sayıya neden inanayım? | C7: Kaynak, formül mantığı, kontrol ve son doğrulama görünür | D7: Kontroller + kaynak izi + sürüm | E7: Prestij kelimesi | F7: HATA
A8: Referans | B8: Müşteri yorumu yoksa ne göstereceğim? | C8: Önce/Sonra + Karar Vakası + Hata Önleme Vakası üretilir | D8: Demo/örnek çıktı | E8: Kanıtsız iddia | F8: HATA
A9: Senaryo | B9: Ne olursa işler bozulur? | C9: Baz/Aşağı/Yukarı veya uygun stres senaryosu | D9: Senaryo karşılaştırma | E9: Dekoratif senaryo | F9: HATA
A10: Ters stres | B10: Hangi eşikte karar kırılır? | C10: En az bir kritik sürücü için kırılma eşiği | D10: Kırılma eşiği tablosu | E10: Sadece +/- %10 | F10: UYARI/HATA
A11: Hata tutarlılığı | B11: Formül hata verirse ne olur? | C11: Kontrol GEÇTİ veremez; BLOKE/HATA üretir | D11: Hata taraması | E11: Hata + GEÇTİ birlikte | F11: HATA
A12: Karar motoru | B12: Ne oldu, neden oldu? | C12: Sorun + neden + parasal etki + aksiyon + son tarih | D12: Karar tablosu | E12: Boş sayfa / isim düzeyi modül | F12: HATA
A13: Yönetici özeti | B13: 5 saniyede ne görmeliyim? | C13: Bugün / ne değişti / ne bozulacak / neden / ne yapmalıyım / güven | D13: Yönetici özeti ekranı | E13: KPI kutusu yığını | F13: HATA
A14: Teklif | B14: Neden satın almalıyım? | C14: Dosya özellikleri yerine sonuç ve kaçınılan maliyet sunulur | D14: Ürün sayfası kanıt eşlemesi | E14: Özellik listesiyle satış | F14: HATA
... A19: Pazar kanıtı | B19: Piyasa gerçekten ödüyor mu? | C19: Satış/pilot/LOI/fiyat kabulü olmadan pazar doğrulandı yazılmaz | D19: Gerçek işlem kanıtı | E19: Tahmini talep = satış kabulü | F19: HATA

Sheet KAPAK
A1: VERGİ, SGK VE MAAŞ KARŞILIK AYIRMA SİSTEMİ
A3: Dönem sonu vergi, SGK ve maaş sürprizine karşı profesyonel karşılık motoru
A4: KDV, kurumlar vergisi, SGK ve maaş karşılıklarını gelire göre ayırın; nakit planınızı koruyun.
A6: 1. DÖNEM GELİR ve GİDER sayfasına aylık tutarları girin.
A7: 2. BORDRO sayfasına çalışan ve maaş bilgilerini girin.
A8: 3. KARAR sayfasında karşılık yeterliliğini ve önerilen aksiyonu okuyun.
A10: Bu dosya karar destek aracıdır; beyanname hazırlama veya vergi danışmanlığı yerine geçmez. Oranlar mali müşavir teyidiyle güncellenmelidir.
A14: ExcelArşiv
A15: Rev 1.0 | 2026-08-08 | Lisans: Tek kullanıcı

Sheet HIZLI_BASLANGIC
A1: ☰ PANO
A3: Nasıl kullanılır?
A4: 1. AYARLAR sayfasından rapor tarihini ve oranları (KDV, KV, SGK, işsizlik, stopaj, damga) kontrol edin.
A5: 2. DÖNEM_GELIR_GIDER sayfasına her ayın gelir ve giderini girin; KDV yüklenimi varsa işaretleyin.
A6: 3. BORDRO sayfasına çalışan listesini, brüt maaşlarını ve ilgili oranları girin.
A7: 4. KARSILIK_MOTORU sayfası tüm karşılıkları otomatik hesaplar; burayı elle değiştirmeyin.
A8: 5. KARAR sayfası karşılık yeterlilik kararını ve aksiyonları gösterir.
A9: 6. PANO ve RAPOR sayfaları yönetici özetini ve yazdırılabilir raporu sunar.
A11: Sık yapılan hatalar
A12: Oranları kendi döneminize göre güncellemeden karşılık hesaplarına güvenmek.
A13: Bordroda brüt maaş yerine net maaş girmek (hesap bozulur).
A14: KDV yüklenim tutarını boş bırakmak (KDV karşılığı olduğundan yüksek çıkar).
... A17: Bu dosyadaki tüm karşılıklar AYARLAR'daki oranlardan hesaplanır; formüle gömülü oran kullanılmaz.

Sheet DÖNEM_GELIR_GIDER
A1: DÖNEM GELIR GIDER — VERGİ, SGK VE MAAŞ KARŞILIK AYIRMA SİSTEMİ
A3: Aylık Dönem Gelir ve Giderleri
A4: Sarı hücrelere manuel veri girin. Her satır bir ayı temsil eder; dönem etiketi olarak ay adı ve yıl girin (ör. Ağustos 2026).
A5: Dönem | B5: Gelir (₺) | C5: Gider (₺) | D5: KDV Yüklenimi (₺) | E5: KDV Tutarı (₺) | F5: Matrah Farkı (₺) | G5: Vergi Yükü Oranı (%) | H5: Vergi Karşılığı (₺) | I5: Not
A6: Ağustos 2026 | B6: 850000 | C6: 620000 | D6: 50000 | E6: =ROUND($B6*KarliyukKdvOrani,0) | F6: =$B6-$C6 | G6: =IF($B6=0,0,$H6/$B6) | H6: =IF($F6>0,ROUND($F6*KarliyukKurumlarOrani,0),0) | I6: Örnek kayıt 1
A7: Eylül 2026 | B7: 920000 | C7: 650000 | D7: 55000 | E7: =ROUND($B7*KarliyukKdvOrani,0) | F7: =$B7-$C7 | G7: =IF($B7=0,0,$H7/$B7) | H7: =IF($F7>0,ROUND($F7*KarliyukKurumlarOrani,0),0) | I7: Örnek kayıt 2
A8: Ekim 2026 | B8: 880000 | C8: 610000 | D8: 52000 | E8: =ROUND($B8*KarliyukKdvOrani,0) | F8: =$B8-$C8 | G8: =IF($B8=0,0,$H8/$B8) | H8: =IF($F8>0,ROUND($F8*KarliyukKurumlarOrani,0),0) | I8: Örnek kayıt 3
A9: Kasım 2026 | B9: 950000 | C9: 680000 | D9: 58000 | E9: =ROUND($B9*KarliyukKdvOrani,0) | F9: =$B9-$C9 | G9: =IF($B9=0,0,$H9/$B9) | H9: =IF($F9>0,ROUND($F9*KarliyukKurumlarOrani,0),0) | I9: Örnek kayıt 4
A10: Aralık 2026 | B10: 1010000 | C10: 700000 | D10: 60000 | E10: =ROUND($B10*KarliyukKdvOrani,0) | F10: =$B10-$C10 | G10: =IF($B10=0,0,$H10/$B10) | H10: =IF($F10>0,ROUND($F10*KarliyukKurumlarOrani,0),0) | I10: Örnek kayıt 5
A11: Ocak 2027 | B11: 1080000 | C11: 740000 | D11: 65000 | E11: =ROUND($B11*KarliyukKdvOrani,0) | F11: =$B11-$C11 | G11: =IF($B11=0,0,$H11/$B11) | H11: =IF($F11>0,ROUND($F11*KarliyukKurumlarOrani,0),0) | I11: Örnek kayıt 6
E12: =ROUND($B12*KarliyukKdvOrani,0) | F12: =$B12-$C12 | G12: =IF($B12=0,0,$H12/$B12) | H12: =IF($F12>0,ROUND($F12*KarliyukKurumlarOrani,0),0)
E13: =ROUND($B13*KarliyukKdvOrani,0) | F13: =$B13-$C13 | G13: =IF($B13=0,0,$H13/$B13) | H13: =IF($F13>0,ROUND($F13*KarliyukKurumlarOrani,0),0)
E14: =ROUND($B14*KarliyukKdvOrani,0) | F14: =$B14-$C14 | G14: =IF($B14=0,0,$H14/$B14) | H14: =IF($F14>0,ROUND($F14*KarliyukKurumlarOrani,0),0)
E15: =ROUND($B15*KarliyukKdvOrani,0) | F15: =$B15-$C15 | G15: =IF($B15=0,0,$H15/$B15) | H15: =IF($F15>0,ROUND($F15*KarliyukKurumlarOrani,0),0)
E16: =ROUND($B16*KarliyukKdvOrani,0) | F16: =$B16-$C16 | G16: =IF($B16=0,0,$H16/$B16) | H16: =IF($F16>0,ROUND($F16*KarliyukKurumlarOrani,0),0)
E17: =ROUND($B17*KarliyukKdvOrani,0) | F17: =$B17-$C17 | G17: =IF($B17=0,0,$H17/$B17) | H17: =IF($F17>0,ROUND($F17*KarliyukKurumlarOrani,0),0)
E18: =ROUND($B18*KarliyukKdvOrani,0) | F18: =$B18-$C18 | G18: =IF($B18=0,0,$H18/$B18) | H18: =IF($F18>0,ROUND($F18*KarliyukKurumlarOrani,0),0)
E19: =ROUND($B19*KarliyukKdvOrani,0) | F19: =$B19-$C19 | G19: =IF($B19=0,0,$H19/$B19) | H19: =IF($F19>0,ROUND($F19*KarliyukKurumlarOrani,0),0)
E20: =ROUND($B20*KarliyukKdvOrani,0) | F20: =$B20-$C20 | G20: =IF($B20=0,0,$H20/$B20) | H20: =IF($F20>0,ROUND($F20*KarliyukKurumlarOrani,0),0)
E21: =ROUND($B21*KarliyukKdvOrani,0) | F21: =$B21-$C21 | G21: =IF($B21=0,0,$H21/$B21) | H21: =IF($F21>0,ROUND($F21*KarliyukKurumlarOrani,0),0)
E22: =ROUND($B22*KarliyukKdvOrani,0) | F22: =$B22-$C22 | G22: =IF($B22=0,0,$H22/$B22) | H22: =IF($F22>0,ROUND($F22*KarliyukKurumlarOrani,0),0)
E23: =ROUND($B23*KarliyukKdvOrani,0) | F23: =$B23-$C23 | G23: =IF($B23=0,0,$H23/$B23) | H23: =IF($F23>0,ROUND($F23*KarliyukKurumlarOrani,0),0)
... E1004: =ROUND($B1004*KarliyukKdvOrani,0) | F1004: =$B1004-$C1004 | G1004: =IF($B1004=0,0,$H1004/$B1004) | H1004: =IF($F1004>0,ROUND($F1004*KarliyukKurumlarOrani,0),0)
A1006: KDV Tutarı ve Vergi Karşılığı AYARLAR'daki oranlardan otomatik hesaplanır.

Sheet BORDRO
A1: BORDRO — VERGİ, SGK VE MAAŞ KARŞILIK AYIRMA SİSTEMİ
A3: Çalışan ve Maaş Bilgileri
A4: Her satır bir çalışanı temsil eder. Brüt maaş ve aylık çalışma süresini girin; SGK, işsizlik, stopaj ve damga otomatik hesaplanır.
A5: Çalışan | B5: Brüt Maaş (₺) | C5: SGK İşçi (₺) | D5: İşsizlik İşçi (₺) | E5: Gelir Vergisi (₺) | F5: Damga (₺) | G5: Net Maaş (₺) | H5: SGK İşveren (₺) | I5: İşsizlik İşveren (₺) | J5: İşveren Toplam Maliyeti (₺) | K5: Not
A6: Ahmet Yılmaz | B6: 85000 | C6: =ROUND($B6*KarliyukSgkIsciOrani,0) | D6: =ROUND($B6*KarliyukIssizlikIsciOrani,0) | E6: =ROUND($B6*KarliyukStopajOrani,0) | F6: =ROUND($B6*KarliyukDamgaOrani,0) | G6: =$B6-$C6-$D6-$E6-$F6 | H6: =ROUND($B6*KarliyukSgkIsverenOrani,0) | I6: =ROUND($B6*KarliyukIssizlikIsverenOrani,0) | J6: =$B6+$H6+$I6 | K6: Örnek çalışan 1
A7: Elif Demir | B7: 72000 | C7: =ROUND($B7*KarliyukSgkIsciOrani,0) | D7: =ROUND($B7*KarliyukIssizlikIsciOrani,0) | E7: =ROUND($B7*KarliyukStopajOrani,0) | F7: =ROUND($B7*KarliyukDamgaOrani,0) | G7: =$B7-$C7-$D7-$E7-$F7 | H7: =ROUND($B7*KarliyukSgkIsverenOrani,0) | I7: =ROUND($B7*KarliyukIssizlikIsverenOrani,0) | J7: =$B7+$H7+$I7 | K7: Örnek çalışan 2
A8: Mehmet Kaya | B8: 95000 | C8: =ROUND($B8*KarliyukSgkIsciOrani,0) | D8: =ROUND($B8*KarliyukIssizlikIsciOrani,0) | E8: =ROUND($B8*KarliyukStopajOrani,0) | F8: =ROUND($B8*KarliyukDamgaOrani,0) | G8: =$B8-$C8-$D8-$E8-$F8 | H8: =ROUND($B8*KarliyukSgkIsverenOrani,0) | I8: =ROUND($B8*KarliyukIssizlikIsverenOrani,0) | J8: =$B8+$H8+$I8 | K8: Örnek çalışan 3
A9: Zeynep Şahin | B9: 64000 | C9: =ROUND($B9*KarliyukSgkIsciOrani,0) | D9: =ROUND($B9*KarliyukIssizlikIsciOrani,0) | E9: =ROUND($B9*KarliyukStopajOrani,0) | F9: =ROUND($B9*KarliyukDamgaOrani,0) | G9: =$B9-$C9-$D9-$E9-$F9 | H9: =ROUND($B9*KarliyukSgkIsverenOrani,0) | I9: =ROUND($B9*KarliyukIssizlikIsverenOrani,0) | J9: =$B9+$H9+$I9 | K9: Örnek çalışan 4
A10: Ali Öztürk | B10: 25000 | C10: =ROUND($B10*KarliyukSgkIsciOrani,0) | D10: =ROUND($B10*KarliyukIssizlikIsciOrani,0) | E10: =ROUND($B10*KarliyukStopajOrani,0) | F10: =ROUND($B10*KarliyukDamgaOrani,0) | G10: =$B10-$C10-$D10-$E10-$F10 | H10: =ROUND($B10*KarliyukSgkIsverenOrani,0) | I10: =ROUND($B10*KarliyukIssizlikIsverenOrani,0) | J10: =$B10+$H10+$I10 | K10: Örnek: operasyon
A11: Elif Arslan | B11: 30000 | C11: =ROUND($B11*KarliyukSgkIsciOrani,0) | D11: =ROUND($B11*KarliyukIssizlikIsciOrani,0) | E11: =ROUND($B11*KarliyukStopajOrani,0) | F11: =ROUND($B11*KarliyukDamgaOrani,0) | G11: =$B11-$C11-$D11-$E11-$F11 | H11: =ROUND($B11*KarliyukSgkIsverenOrani,0) | I11: =ROUND($B11*KarliyukIssizlikIsverenOrani,0) | J11: =$B11+$H11+$I11 | K11: Örnek: satış
C12: =ROUND($B12*KarliyukSgkIsciOrani,0) | D12: =ROUND($B12*KarliyukIssizlikIsciOrani,0) | E12: =ROUND($B12*KarliyukStopajOrani,0) | F12: =ROUND($B12*KarliyukDamgaOrani,0) | G12: =$B12-$C12-$D12-$E12-$F12 | H12: =ROUND($B12*KarliyukSgkIsverenOrani,0) | I12: =ROUND($B12*KarliyukIssizlikIsverenOrani,0) | J12: =$B12+$H12+$I12
C13: =ROUND($B13*KarliyukSgkIsciOrani,0) | D13: =ROUND($B13*KarliyukIssizlikIsciOrani,0) | E13: =ROUND($B13*KarliyukStopajOrani,0) | F13: =ROUND($B13*KarliyukDamgaOrani,0) | G13: =$B13-$C13-$D13-$E13-$F13 | H13: =ROUND($B13*KarliyukSgkIsverenOrani,0) | I13: =ROUND($B13*KarliyukIssizlikIsverenOrani,0) | J13: =$B13+$H13+$I13
C14: =ROUND($B14*KarliyukSgkIsciOrani,0) | D14: =ROUND($B14*KarliyukIssizlikIsciOrani,0) | E14: =ROUND($B14*KarliyukStopajOrani,0) | F14: =ROUND($B14*KarliyukDamgaOrani,0) | G14: =$B14-$C14-$D14-$E14-$F14 | H14: =ROUND($B14*KarliyukSgkIsverenOrani,0) | I14: =ROUND($B14*KarliyukIssizlikIsverenOrani,0) | J14: =$B14+$H14+$I14
C15: =ROUND($B15*KarliyukSgkIsciOrani,0) | D15: =ROUND($B15*KarliyukIssizlikIsciOrani,0) | E15: =ROUND($B15*KarliyukStopajOrani,0) | F15: =ROUND($B15*KarliyukDamgaOrani,0) | G15: =$B15-$C15-$D15-$E15-$F15 | H15: =ROUND($B15*KarliyukSgkIsverenOrani,0) | I15: =ROUND($B15*KarliyukIssizlikIsverenOrani,0) | J15: =$B15+$H15+$I15
C16: =ROUND($B16*KarliyukSgkIsciOrani,0) | D16: =ROUND($B16*KarliyukIssizlikIsciOrani,0) | E16: =ROUND($B16*KarliyukStopajOrani,0) | F16: =ROUND($B16*KarliyukDamgaOrani,0) | G16: =$B16-$C16-$D16-$E16-$F16 | H16: =ROUND($B16*KarliyukSgkIsverenOrani,0) | I16: =ROUND($B16*KarliyukIssizlikIsverenOrani,0) | J16: =$B16+$H16+$I16
C17: =ROUND($B17*KarliyukSgkIsciOrani,0) | D17: =ROUND($B17*KarliyukIssizlikIsciOrani,0) | E17: =ROUND($B17*KarliyukStopajOrani,0) | F17: =ROUND($B17*KarliyukDamgaOrani,0) | G17: =$B17-$C17-$D17-$E17-$F17 | H17: =ROUND($B17*KarliyukSgkIsverenOrani,0) | I17: =ROUND($B17*KarliyukIssizlikIsverenOrani,0) | J17: =$B17+$H17+$I17
C18: =ROUND($B18*KarliyukSgkIsciOrani,0) | D18: =ROUND($B18*KarliyukIssizlikIsciOrani,0) | E18: =ROUND($B18*KarliyukStopajOrani,0) | F18: =ROUND($B18*KarliyukDamgaOrani,0) | G18: =$B18-$C18-$D18-$E18-$F18 | H18: =ROUND($B18*KarliyukSgkIsverenOrani,0) | I18: =ROUND($B18*KarliyukIssizlikIsverenOrani,0) | J18: =$B18+$H18+$I18
C19: =ROUND($B19*KarliyukSgkIsciOrani,0) | D19: =ROUND($B19*KarliyukIssizlikIsciOrani,0) | E19: =ROUND($B19*KarliyukStopajOrani,0) | F19: =ROUND($B19*KarliyukDamgaOrani,0) | G19: =$B19-$C19-$D19-$E19-$F19 | H19: =ROUND($B19*KarliyukSgkIsverenOrani,0) | I19: =ROUND($B19*KarliyukIssizlikIsverenOrani,0) | J19: =$B19+$H19+$I19
C20: =ROUND($B20*KarliyukSgkIsciOrani,0) | D20: =ROUND($B20*KarliyukIssizlikIsciOrani,0) | E20: =ROUND($B20*KarliyukStopajOrani,0) | F20: =ROUND($B20*KarliyukDamgaOrani,0) | G20: =$B20-$C20-$D20-$E20-$F20 | H20: =ROUND($B20*KarliyukSgkIsverenOrani,0) | I20: =ROUND($B20*KarliyukIssizlikIsverenOrani,0) | J20: =$B20+$H20+$I20
C21: =ROUND($B21*KarliyukSgkIsciOrani,0) | D21: =ROUND($B21*KarliyukIssizlikIsciOrani,0) | E21: =ROUND($B21*KarliyukStopajOrani,0) | F21: =ROUND($B21*KarliyukDamgaOrani,0) | G21: =$B21-$C21-$D21-$E21-$F21 | H21: =ROUND($B21*KarliyukSgkIsverenOrani,0) | I21: =ROUND($B21*KarliyukIssizlikIsverenOrani,0) | J21: =$B21+$H21+$I21
C22: =ROUND($B22*KarliyukSgkIsciOrani,0) | D22: =ROUND($B22*KarliyukIssizlikIsciOrani,0) | E22: =ROUND($B22*KarliyukStopajOrani,0) | F22: =ROUND($B22*KarliyukDamgaOrani,0) | G22: =$B22-$C22-$D22-$E22-$F22 | H22: =ROUND($B22*KarliyukSgkIsverenOrani,0) | I22: =ROUND($B22*KarliyukIssizlikIsverenOrani,0) | J22: =$B22+$H22+$I22
C23: =ROUND($B23*KarliyukSgkIsciOrani,0) | D23: =ROUND($B23*KarliyukIssizlikIsciOrani,0) | E23: =ROUND($B23*KarliyukStopajOrani,0) | F23: =ROUND($B23*KarliyukDamgaOrani,0) | G23: =$B23-$C23-$D23-$E23-$F23 | H23: =ROUND($B23*KarliyukSgkIsverenOrani,0) | I23: =ROUND($B23*KarliyukIssizlikIsverenOrani,0) | J23: =$B23+$H23+$I23
... C1004: =ROUND($B1004*KarliyukSgkIsciOrani,0) | D1004: =ROUND($B1004*KarliyukIssizlikIsciOrani,0) | E1004: =ROUND($B1004*KarliyukStopajOrani,0) | F1004: =ROUND($B1004*KarliyukDamgaOrani,0) | G1004: =$B1004-$C1004-$D1004-$E1004-$F1004 | H1004: =ROUND($B1004*KarliyukSgkIsverenOrani,0) | I1004: =ROUND($B1004*KarliyukIssizlikIsverenOrani,0) | J1004: =$B1004+$H1004+$I1004
A1006: Net maaş, SGK ve işsizlik tutarları AYARLAR'daki oranlardan hesaplanır.

Sheet KARSILIK_MOTORU
A1: KARSILIK MOTORU — VERGİ, SGK VE MAAŞ KARŞILIK AYIRMA SİSTEMİ
A3: Karşılık Motoru
A4: Aşağıdaki kalemler giriş sayfalarından otomatik beslenir. Bu sayfa elle değiştirilmez.
A6: Dönem Toplam Geliri | B6: =SUM(tblDonem[Gelir (₺)])+SUM(tblDonem[[KDV Yüklenimi (₺)]])
A7: Dönem Toplam Gideri | B7: =SUM(tblDonem[Gider (₺)])
A8: Tahsil Edilen KDV (Gelir Üzerinden) | B8: =SUM(tblDonem[KDV Tutarı (₺)])-SUM(tblDonem[[KDV Yüklenimi (₺)]])
A9: KDV Karşılığı (Ödenecek Net KDV) | B9: =MAX(0,SUM(tblDonem[KDV Tutarı (₺)])-SUM(tblDonem[[KDV Yüklenimi (₺)]]))
A10: Kurumlar Vergisi Karşılığı | B10: =SUM(tblDonem[Vergi Karşılığı (₺)])
A11: SGK İşveren Karşılığı | B11: =SUM(tblBordro[SGK İşveren (₺)])
A12: İşsizlik İşveren Karşılığı | B12: =SUM(tblBordro[İşsizlik İşveren (₺)])
A13: Bordro Stopaj Karşılığı | B13: =SUM(tblBordro[Gelir Vergisi (₺)])+SUM(tblBordro[Damga (₺)])
A14: Net Maaş Karşılığı | B14: =SUM(tblBordro[Net Maaş (₺)])
A15: Toplam Karşılık Yükü | B15: =SUM(KarsilikKdv,KarsilikKurumlar,KarsilikSgkIsveren,KarsilikIssizlikIsveren,KarsilikStopaj,KarsilikNetMaas)
A16: Ay Başı Kasa | B16: =AYARLAR!$B$21
A17: Dönem Nakit Girişi (Tahsilat) | B17: =SUM(tblDonem[Gelir (₺)])
A18: Dönem Nakit Çıkışı (Gider) | B18: =SUM(tblDonem[Gider (₺)])
A19: Karşılık Sonrası Nakit Fazlası | B19: =KarsilikAyBasiKasa+KarsilikNakitGiris-KarsilikNakitCikis-KarsilikToplam
A20: Karşılık / Gelir Oranı | B20: =IF(KarsilikDonemGelir=0,0,KarsilikToplam/KarsilikDonemGelir)
A22: Aylık Karşılık Dağılımı (Ay Bazında)
A23: Aşağıdaki tablo her ayın karşılık kalemlerini özetler; hesaplanan kolonlardır.
A24: Dönem | B24: Gelir TL | C24: KDV Karşılığı TL | D24: Kurumlar Vergisi TL | E24: Toplam Ay Karşılığı TL | F24: Gelir Oranı %
A25: Ağustos 2026 | B25: =SUMIFS(tblDonem[Gelir (₺)],tblDonem[Dönem],$A25) | C25: =SUMIFS(tblDonem[KDV Tutarı (₺)],tblDonem[Dönem],$A25)-SUMIFS(tblDonem[KDV Yüklenimi (₺)],tblDonem[Dönem],$A25) | D25: =SUMIFS(tblDonem[Vergi Karşılığı (₺)],tblDonem[Dönem],$A25) | E25: =$C25+$D25 | F25: =IF($B25=0,0,$E25/$B25)
A26: Eylül 2026 | B26: =SUMIFS(tblDonem[Gelir (₺)],tblDonem[Dönem],$A26) | C26: =SUMIFS(tblDonem[KDV Tutarı (₺)],tblDonem[Dönem],$A26)-SUMIFS(tblDonem[KDV Yüklenimi (₺)],tblDonem[Dönem],$A26) | D26: =SUMIFS(tblDonem[Vergi Karşılığı (₺)],tblDonem[Dönem],$A26) | E26: =$C26+$D26 | F26: =IF($B26=0,0,$E26/$B26)
A27: Ekim 2026 | B27: =SUMIFS(tblDonem[Gelir (₺)],tblDonem[Dönem],$A27) | C27: =SUMIFS(tblDonem[KDV Tutarı (₺)],tblDonem[Dönem],$A27)-SUMIFS(tblDonem[KDV Yüklenimi (₺)],tblDonem[Dönem],$A27) | D27: =SUMIFS(tblDonem[Vergi Karşılığı (₺)],tblDonem[Dönem],$A27) | E27: =$C27+$D27 | F27: =IF($B27=0,0,$E27/$B27)
A28: Kasım 2026 | B28: =SUMIFS(tblDonem[Gelir (₺)],tblDonem[Dönem],$A28) | C28: =SUMIFS(tblDonem[KDV Tutarı (₺)],tblDonem[Dönem],$A28)-SUMIFS(tblDonem[KDV Yüklenimi (₺)],tblDonem[Dönem],$A28) | D28: =SUMIFS(tblDonem[Vergi Karşılığı (₺)],tblDonem[Dönem],$A28) | E28: =$C28+$D28 | F28: =IF($B28=0,0,$E28/$B28)
A29: Aralık 2026 | B29: =SUMIFS(tblDonem[Gelir (₺)],tblDonem[Dönem],$A29) | C29: =SUMIFS(tblDonem[KDV Tutarı (₺)],tblDonem[Dönem],$A29)-SUMIFS(tblDonem[KDV Yüklenimi (₺)],tblDonem[Dönem],$A29) | D29: =SUMIFS(tblDonem[Vergi Karşılığı (₺)],tblDonem[Dönem],$A29) | E29: =$C29+$D29 | F29: =IF($B29=0,0,$E29/$B29)
A30: Ocak 2027 | B30: =SUMIFS(tblDonem[Gelir (₺)],tblDonem[Dönem],$A30) | C30: =SUMIFS(tblDonem[KDV Tutarı (₺)],tblDonem[Dönem],$A30)-SUMIFS(tblDonem[KDV Yüklenimi (₺)],tblDonem[Dönem],$A30) | D30: =SUMIFS(tblDonem[Vergi Karşılığı (₺)],tblDonem[Dönem],$A30) | E30: =$C30+$D30 | F30: =IF($B30=0,0,$E30/$B30)
B31: =SUMIFS(tblDonem[Gelir (₺)],tblDonem[Dönem],$A31) | C31: =SUMIFS(tblDonem[KDV Tutarı (₺)],tblDonem[Dönem],$A31)-SUMIFS(tblDonem[KDV Yüklenimi (₺)],tblDonem[Dönem],$A31) | D31: =SUMIFS(tblDonem[Vergi Karşılığı (₺)],tblDonem[Dönem],$A31) | E31: =$C31+$D31 | F31: =IF($B31=0,0,$E31/$B31)
B32: =SUMIFS(tblDonem[Gelir (₺)],tblDonem[Dönem],$A32) | C32: =SUMIFS(tblDonem[KDV Tutarı (₺)],tblDonem[Dönem],$A32)-SUMIFS(tblDonem[KDV Yüklenimi (₺)],tblDonem[Dönem],$A32) | D32: =SUMIFS(tblDonem[Vergi Karşılığı (₺)],tblDonem[Dönem],$A32) | E32: =$C32+$D32 | F32: =IF($B32=0,0,$E32/$B32)
B33: =SUMIFS(tblDonem[Gelir (₺)],tblDonem[Dönem],$A33) | C33: =SUMIFS(tblDonem[KDV Tutarı (₺)],tblDonem[Dönem],$A33)-SUMIFS(tblDonem[KDV Yüklenimi (₺)],tblDonem[Dönem],$A33) | D33: =SUMIFS(tblDonem[Vergi Karşılığı (₺)],tblDonem[Dönem],$A33) | E33: =$C33+$D33 | F33: =IF($B33=0,0,$E33/$B33)
B34: =SUMIFS(tblDonem[Gelir (₺)],tblDonem[Dönem],$A34) | C34: =SUMIFS(tblDonem[KDV Tutarı (₺)],tblDonem[Dönem],$A34)-SUMIFS(tblDonem[KDV Yüklenimi (₺)],tblDonem[Dönem],$A34) | D34: =SUMIFS(tblDonem[Vergi Karşılığı (₺)],tblDonem[Dönem],$A34) | E34: =$C34+$D34 | F34: =IF($B34=0,0,$E34/$B34)
B35: =SUMIFS(tblDonem[Gelir (₺)],tblDonem[Dönem],$A35) | C35: =SUMIFS(tblDonem[KDV Tutarı (₺)],tblDonem[Dönem],$A35)-SUMIFS(tblDonem[KDV Yüklenimi (₺)],tblDonem[Dönem],$A35) | D35: =SUMIFS(tblDonem[Vergi Karşılığı (₺)],tblDonem[Dönem],$A35) | E35: =$C35+$D35 | F35: =IF($B35=0,0,$E35/$B35)
B36: =SUMIFS(tblDonem[Gelir (₺)],tblDonem[Dönem],$A36) | C36: =SUMIFS(tblDonem[KDV Tutarı (₺)],tblDonem[Dönem],$A36)-SUMIFS(tblDonem[KDV Yüklenimi (₺)],tblDonem[Dönem],$A36) | D36: =SUMIFS(tblDonem[Vergi Karşılığı (₺)],tblDonem[Dönem],$A36) | E36: =$C36+$D36 | F36: =IF($B36=0,0,$E36/$B36)
B37: =SUMIFS(tblDonem[Gelir (₺)],tblDonem[Dönem],$A37) | C37: =SUMIFS(tblDonem[KDV Tutarı (₺)],tblDonem[Dönem],$A37)-SUMIFS(tblDonem[KDV Yüklenimi (₺)],tblDonem[Dönem],$A37) | D37: =SUMIFS(tblDonem[Vergi Karşılığı (₺)],tblDonem[Dönem],$A37) | E37: =$C37+$D37 | F37: =IF($B37=0,0,$E37/$B37)
B38: =SUMIFS(tblDonem[Gelir (₺)],tblDonem[Dönem],$A38) | C38: =SUMIFS(tblDonem[KDV Tutarı (₺)],tblDonem[Dönem],$A38)-SUMIFS(tblDonem[KDV Yüklenimi (₺)],tblDonem[Dönem],$A38) | D38: =SUMIFS(tblDonem[Vergi Karşılığı (₺)],tblDonem[Dönem],$A38) | E38: =$C38+$D38 | F38: =IF($B38=0,0,$E38/$B38)
B39: =SUMIFS(tblDonem[Gelir (₺)],tblDonem[Dönem],$A39) | C39: =SUMIFS(tblDonem[KDV Tutarı (₺)],tblDonem[Dönem],$A39)-SUMIFS(tblDonem[KDV Yüklenimi (₺)],tblDonem[Dönem],$A39) | D39: =SUMIFS(tblDonem[Vergi Karşılığı (₺)],tblDonem[Dönem],$A39) | E39: =$C39+$D39 | F39: =IF($B39=0,0,$E39/$B39)
B40: =SUMIFS(tblDonem[Gelir (₺)],tblDonem[Dönem],$A40) | C40: =SUMIFS(tblDonem[KDV Tutarı (₺)],tblDonem[Dönem],$A40)-SUMIFS(tblDonem[KDV Yüklenimi (₺)],tblDonem[Dönem],$A40) | D40: =SUMIFS(tblDonem[Vergi Karşılığı (₺)],tblDonem[Dönem],$A40) | E40: =$C40+$D40 | F40: =IF($B40=0,0,$E40/$B40)
B41: =SUMIFS(tblDonem[Gelir (₺)],tblDonem[Dönem],$A41) | C41: =SUMIFS(tblDonem[KDV Tutarı (₺)],tblDonem[Dönem],$A41)-SUMIFS(tblDonem[KDV Yüklenimi (₺)],tblDonem[Dönem],$A41) | D41: =SUMIFS(tblDonem[Vergi Karşılığı (₺)],tblDonem[Dönem],$A41) | E41: =$C41+$D41 | F41: =IF($B41=0,0,$E41/$B41)
B42: =SUMIFS(tblDonem[Gelir (₺)],tblDonem[Dönem],$A42) | C42: =SUMIFS(tblDonem[KDV Tutarı (₺)],tblDonem[Dönem],$A42)-SUMIFS(tblDonem[KDV Yüklenimi (₺)],tblDonem[Dönem],$A42) | D42: =SUMIFS(tblDonem[Vergi Karşılığı (₺)],tblDonem[Dönem],$A42) | E42: =$C42+$D42 | F42: =IF($B42=0,0,$E42/$B42)
... B1004: =SUMIFS(tblDonem[Gelir (₺)],tblDonem[Dönem],$A1004) | C1004: =SUMIFS(tblDonem[KDV Tutarı (₺)],tblDonem[Dönem],$A1004)-SUMIFS(tblDonem[KDV Yüklenimi (₺)],tblDonem[Dönem],$A1004) | D1004: =SUMIFS(tblDonem[Vergi Karşılığı (₺)],tblDonem[Dönem],$A1004) | E1004: =$C1004+$D1004 | F1004: =IF($B1004=0,0,$E1004/$B1004)
...

Sheet ANALITIK_MOTOR
A1: ANALITIK MOTOR — VERGİ, SGK VE MAAŞ KARŞILIK AYIRMA SİSTEMİ
A3: ANALİTİK MOTOR — DERİNLİK KATMANI
A5: Kod | B5: Gösterge | C5: Değer | D5: Makine Yorumu
A6: T2 | B6: Son-İlk Ay Gelir Farkı (₺) | C6: =IFERROR(INDEX(tblDonem[Gelir (₺)],COUNTA(tblDonem[Gelir (₺)]))-INDEX(tblDonem[Gelir (₺)],1),0) | D6: =_xlfn.TEXTJOIN("; ",TRUE(),"Son ile ilk ay gelir farkı ",TEXT(C6,"₺ #,##0")," TL — artış büyümeyi, düşüş daralmayı gösterir")
A7: T4 | B7: Son / İlk Ay Gelir Oranı | C7: =IFERROR(INDEX(tblDonem[Gelir (₺)],COUNTA(tblDonem[Gelir (₺)]))/INDEX(tblDonem[Gelir (₺)],1),0) | D7: =_xlfn.TEXTJOIN("; ",TRUE(),"Son ay geliri ilk ay gelirinin ",TEXT(C7,"%0,0")," i kadar — dönem büyüme oranını gösterir")
A8: O1 | B8: Gelir Anomali Oranı (Değişim Katsayısı) | C8: =IFERROR(stdev.p(tblDonem[Gelir (₺)])/AVERAGE(tblDonem[Gelir (₺)]),0) | D8: =_xlfn.TEXTJOIN("; ",TRUE(),"Gelir değişim katsayısı ",TEXT(C8,"%0,0")," — oran yükseldikçe gelir öngörülemezleşir")
A9: O2 | B9: Tornado: En Büyük Etki (₺) | C9: =MAX(SENARYO_DUYARLILIK!B12:B15) | D9: =_xlfn.TEXTJOIN("; ",TRUE(),"Karşılığı en çok etkileyen değişkenin etkisi ",TEXT(C9,"₺ #,##0")," TL — izleme önceliği bu değişkendedir")
A10: O3 | B10: Senaryo Bant Genişliği (₺) | C10: =SENARYO_DUYARLILIK!B7-SENARYO_DUYARLILIK!B9 | D10: =_xlfn.TEXTJOIN("; ",TRUE(),"İyimser ile kötümser karşılık yükü farkı ",TEXT(C10,"₺ #,##0")," TL — belirsizlik aralığını gösterir")
A11: O8 | B11: Veri Kalite Skoru | C11: =KONTROLLER!B19 | D11: =_xlfn.TEXTJOIN("; ",TRUE(),"Veri kalite skoru ",TEXT(C11,"0")," puan — ",IF(C11>=KarsilikKaliteIyi,"yüksek güven","veri girişi tamamlanmalı"))
A12: I1 | B12: Tahmini Gelir (1 Ay Sonra) | C12: =PANO!B29 | D12: =_xlfn.TEXTJOIN("; ",TRUE(),"Gelecek ay gelir tahmini ",TEXT(C12,"₺ #,##0")," TL — alt/üst sınır PANO sayfasındadır")
A13: I2 | B13: Gelir Yüzdelik P90 (₺) | C13: =IFERROR(_xlfn.PERCENTILE.INC(tblDonem[Gelir (₺)],KarsilikP90Oran),0) | D13: =_xlfn.TEXTJOIN("; ",TRUE(),"Dönem gelirlerinin %90 ı ",TEXT(C13,"₺ #,##0")," TL altında kalır — üst sınır nakit planı için kullanılabilir")

Sheet NAKIT_PROJEKSIYON
A1: NAKIT PROJEKSIYON — VERGİ, SGK VE MAAŞ KARŞILIK AYIRMA SİSTEMİ
A3: Karşılık Sonrası Nakit Projeksiyonu
A4: Önümüzdeki 6 ay için karşılık yükü düşüldükten sonraki nakit durumu. Kırılım (eşik) satırı, nakit eksiye düşme riskini gösterir.
A5: Ay Etiketi | B5: Beklenen Nakit Girişi (₺) | C5: Beklenen Nakit Çıkışı (₺) | D5: Dönem Karşılık Yükü (₺) | E5: Nakit Dengesi (₺) | F5: Kümülatif Nakit (₺) | G5: Eşik Altı mı? | H5: Not
A6: Ağustos 2026 | B6: 850000 | C6: 620000 | D6: =ROUND($B6*KarliyukNakitKarliikOrani,0) | E6: =$B6-$C6-$D6 | F6: =KarsilikAyBasiKasa+SUM($E$6:E6) | G6: =IF($F6<KarsilikNakitEsigi,"EVET","HAYIR") | H6: Örnek ay 1
A7: Eylül 2026 | B7: 920000 | C7: 650000 | D7: =ROUND($B7*KarliyukNakitKarliikOrani,0) | E7: =$B7-$C7-$D7 | F7: =KarsilikAyBasiKasa+SUM($E$6:E7) | G7: =IF($F7<KarsilikNakitEsigi,"EVET","HAYIR") | H7: Örnek ay 2
A8: Ekim 2026 | B8: 880000 | C8: 610000 | D8: =ROUND($B8*KarliyukNakitKarliikOrani,0) | E8: =$B8-$C8-$D8 | F8: =KarsilikAyBasiKasa+SUM($E$6:E8) | G8: =IF($F8<KarsilikNakitEsigi,"EVET","HAYIR") | H8: Örnek ay 3
A9: Kasım 2026 | B9: 950000 | C9: 680000 | D9: =ROUND($B9*KarliyukNakitKarliikOrani,0) | E9: =$B9-$C9-$D9 | F9: =KarsilikAyBasiKasa+SUM($E$6:E9) | G9: =IF($F9<KarsilikNakitEsigi,"EVET","HAYIR") | H9: Örnek ay 4
A10: Aralık 2026 | B10: 1010000 | C10: 700000 | D10: =ROUND($B10*KarliyukNakitKarliikOrani,0) | E10: =$B10-$C10-$D10 | F10: =KarsilikAyBasiKasa+SUM($E$6:E10) | G10: =IF($F10<KarsilikNakitEsigi,"EVET","HAYIR") | H10: Örnek ay 5
A11: Ocak 2027 | B11: 1080000 | C11: 740000 | D11: =ROUND($B11*KarliyukNakitKarliikOrani,0) | E11: =$B11-$C11-$D11 | F11: =KarsilikAyBasiKasa+SUM($E$6:E11) | G11: =IF($F11<KarsilikNakitEsigi,"EVET","HAYIR") | H11: Örnek ay 6
D12: =ROUND($B12*KarliyukNakitKarliikOrani,0) | E12: =$B12-$C12-$D12 | F12: =KarsilikAyBasiKasa+SUM($E$6:E12) | G12: =IF($F12<KarsilikNakitEsigi,"EVET","HAYIR")
D13: =ROUND($B13*KarliyukNakitKarliikOrani,0) | E13: =$B13-$C13-$D13 | F13: =KarsilikAyBasiKasa+SUM($E$6:E13) | G13: =IF($F13<KarsilikNakitEsigi,"EVET","HAYIR")
D14: =ROUND($B14*KarliyukNakitKarliikOrani,0) | E14: =$B14-$C14-$D14 | F14: =KarsilikAyBasiKasa+SUM($E$6:E14) | G14: =IF($F14<KarsilikNakitEsigi,"EVET","HAYIR")
D15: =ROUND($B15*KarliyukNakitKarliikOrani,0) | E15: =$B15-$C15-$D15 | F15: =KarsilikAyBasiKasa+SUM($E$6:E15) | G15: =IF($F15<KarsilikNakitEsigi,"EVET","HAYIR")
D16: =ROUND($B16*KarliyukNakitKarliikOrani,0) | E16: =$B16-$C16-$D16 | F16: =KarsilikAyBasiKasa+SUM($E$6:E16) | G16: =IF($F16<KarsilikNakitEsigi,"EVET","HAYIR")
D17: =ROUND($B17*KarliyukNakitKarliikOrani,0) | E17: =$B17-$C17-$D17 | F17: =KarsilikAyBasiKasa+SUM($E$6:E17) | G17: =IF($F17<KarsilikNakitEsigi,"EVET","HAYIR")
D18: =ROUND($B18*KarliyukNakitKarliikOrani,0) | E18: =$B18-$C18-$D18 | F18: =KarsilikAyBasiKasa+SUM($E$6:E18) | G18: =IF($F18<KarsilikNakitEsigi,"EVET","HAYIR")
D19: =ROUND($B19*KarliyukNakitKarliikOrani,0) | E19: =$B19-$C19-$D19 | F19: =KarsilikAyBasiKasa+SUM($E$6:E19) | G19: =IF($F19<KarsilikNakitEsigi,"EVET","HAYIR")
D20: =ROUND($B20*KarliyukNakitKarliikOrani,0) | E20: =$B20-$C20-$D20 | F20: =KarsilikAyBasiKasa+SUM($E$6:E20) | G20: =IF($F20<KarsilikNakitEsigi,"EVET","HAYIR")
D21: =ROUND($B21*KarliyukNakitKarliikOrani,0) | E21: =$B21-$C21-$D21 | F21: =KarsilikAyBasiKasa+SUM($E$6:E21) | G21: =IF($F21<KarsilikNakitEsigi,"EVET","HAYIR")
D22: =ROUND($B22*KarliyukNakitKarliikOrani,0) | E22: =$B22-$C22-$D22 | F22: =KarsilikAyBasiKasa+SUM($E$6:E22) | G22: =IF($F22<KarsilikNakitEsigi,"EVET","HAYIR")
D23: =ROUND($B23*KarliyukNakitKarliikOrani,0) | E23: =$B23-$C23-$D23 | F23: =KarsilikAyBasiKasa+SUM($E$6:E23) | G23: =IF($F23<KarsilikNakitEsigi,"EVET","HAYIR")
... D1004: =ROUND($B1004*KarliyukNakitKarliikOrani,0) | E1004: =$B1004-$C1004-$D1004 | F1004: =KarsilikAyBasiKasa+SUM($E$6:E1004) | G1004: =IF($F1004<KarsilikNakitEsigi,"EVET","HAYIR")
A1006: Dönem Karşılık Yükü, girişlerin ortalama karşılık oranıyla tahminlenir; eşik AYARLAR'dan gelir.

Sheet KONTROLLER
A1: KONTROLLER — VERGİ, SGK VE MAAŞ KARŞILIK AYIRMA SİSTEMİ
A3: Giriş Kalite Kontrolleri
A4: Aşağıdaki kontroller canlı formüllerle çalışır; sorun varsa uyarı üretir.
A6: Boş gelir satırı var mı? | B6: =IF(COUNTBLANK(tblDonem[Gelir (₺)])=0,"TEMİZ","BOŞ VAR")
A7: Boş gider satırı var mı? | B7: =IF(COUNTBLANK(tblDonem[Gider (₺)])=0,"TEMİZ","BOŞ VAR")
A8: Negatif gelir var mı? | B8: =IF(COUNTIF(tblDonem[Gelir (₺)],"<0")=0,"TEMİZ","NEGATİF VAR")
A9: KDV yüklenimi > KDV tutarı olan ay var mı? | B9: =IF(SUMPRODUCT((tblDonem[[KDV Yüklenimi (₺)]]>tblDonem[[KDV Tutarı (₺)]])*1)=0,"TEMİZ","FARK VAR")
A10: Boş brüt maaş satırı var mı? | B10: =IF(COUNTBLANK(tblBordro[Brüt Maaş (₺)])=0,"TEMİZ","BOŞ VAR")
A11: Negatif matrah farkı toplamı var mı? | B11: =IF(SUM(tblDonem[Matrah Farkı (₺)])<0,"ZARAR","KÂR")
A12: Karşılık / Gelir oranı eşiği aşıyor mu? | B12: =IF(KarsilikGelirOrani>KarliyukUstOran,"AŞIYOR","NORMAL")
A13: Kümülatif nakit eşik altına düşüyor mu? | B13: =IF(COUNTIF(tblProjeksiyon[Eşik Altı mı?],"EVET")=0,"GÜVENLİ","RİSK")
A15: Veri Kalitesi Skoru (0-100)
A16: Boş ve negatif girişlerin oranına göre üretilen kalite skoru.
A17: Toplam Giriş Hücresi | B17: =ROWS(tblDonem[Dönem])*GirisKolonDonem+ROWS(tblBordro[Çalışan])*GirisKolonBordro+ROWS(tblProjeksiyon[Ay Etiketi])*GirisKolonNakit+ROWS(tblAylikKarsilik[Dönem])*GirisKolonAylik
A18: Dolu Giriş Hücresi | B18: =COUNTA(tblDonem[Dönem])+COUNTA(tblDonem[Gelir (₺)])+COUNTA(tblDonem[Gider (₺)])+COUNTA(tblDonem[[KDV Yüklenimi (₺)]])+COUNTA(tblDonem[Not])+COUNTA(tblBordro[Çalışan])+COUNTA(tblBordro[Brüt Maaş (₺)])+COUNTA(tblBordro[Not])+COUNTA(tblProjeksiyon[Ay Etiketi])+COUNTA(tblProjeksiyon[[Beklenen Nakit Girişi (₺)]])+COUNTA(tblProjeksiyon[[Beklenen Nakit Çıkışı (₺)]])+COUNTA(tblProjeksiyon[Not])+COUNTA(tblAylikKarsilik[Dönem])
A19: Kalite Skoru | B19: =ROUND(IF(B17=0,0,B18/B17*100),0)
A20: Kalite Seviyesi | B20: =IF(KarsilikKaliteSkoru>=KarsilikKaliteIyi,"YÜKSEK",IF(KarsilikKaliteSkoru>=KarsilikKaliteOrta,"ORTA","DÜŞÜK"))
A22: Kontroller yalnızca giriş verisini denetler; değerleri değiştirmez.

Sheet KARAR
A1: KARAR — VERGİ, SGK VE MAAŞ KARŞILIK AYIRMA SİSTEMİ
A3: Karar Kapısı — Karşılık Yeterliliği
A4: Nakit fazlası, karşılık/gelir oranı ve eşik kontrolüne göre üretilen karar.
A6: Karşılık Sonrası Nakit Fazlası | B6: =KarsilikNakitFazla
A7: Karşılık / Gelir Oranı | B7: =KarsilikGelirOrani
A8: Nakit Eşik Altı Ay Sayısı | B8: =COUNTIF(tblProjeksiyon[Eşik Altı mı?],"EVET")
A10: KARAR | B10: =IF(COUNT(tblDonem[Gelir (₺)])=0,"VERİ YOK",IF(KarsilikNakitFazla<KarsilikZorunluEsik,"DURDUR",IF(KarsilikEskikAy>0,"İNCELE","UYGUN")))
A11: Gerekçe | B11: =IF(KarsilikNakitFazla<KarsilikZorunluEsik,"Karşılık sonrası nakit zorunlu eşiğin altında; ödeme planı revize edilmeli.","Gerekçe detayı: nakit fazlası AND eşik kontrolü uygun.")
A13: Önerilen Aksiyonlar
A14: Aksiyon 1 | B14: =Aksiyon1_ACIKLAMA
A15: Aksiyon 2 | B15: =Aksiyon2_ACIKLAMA
A16: Aksiyon 3 | B16: =Aksiyon3_ACIKLAMA
A18: Karar yalnızca giriş verisi ve AYARLAR'daki eşiklerden türetilir; kesin finansal tavsiye değildir.

Sheet SENARYO_DUYARLILIK
A1: SENARYO DUYARLILIK — VERGİ, SGK VE MAAŞ KARŞILIK AYIRMA SİSTEMİ
A3: Senaryo ve Duyarlılık Analizi
A4: İyimser, baz ve kötümser senaryolarda karşılık yükü; ardından hangi değişkenin sonucu en çok etkilediğini gösteren tornado analizi.
A6: Senaryo | B6: Senaryo Karşılık Yükü (₺) | C6: Senaryo Nakit Fazlası (₺) | D6: Senaryo Kararı
A7: İYİMSER | B7: =ROUND(KarsilikToplam*KarliyukIyiSenaryo,0) | C7: =KarsilikAyBasiKasa+KarsilikNakitGiris-KarsilikNakitCikis-B7 | D7: =IF(C7<KarsilikZorunluEsik,"DURDUR",IF(C7<KarsilikZorunluEsik*2,"İNCELE","UYGUN"))
A8: BAZ | B8: =ROUND(KarsilikToplam*KarliyukBazSenaryo,0) | C8: =KarsilikAyBasiKasa+KarsilikNakitGiris-KarsilikNakitCikis-B8 | D8: =IF(C8<KarsilikZorunluEsik,"DURDUR",IF(C8<KarsilikZorunluEsik*2,"İNCELE","UYGUN"))
A9: KÖTÜMSER | B9: =ROUND(KarsilikToplam*KarliyukKotuSenaryo,0) | C9: =KarsilikAyBasiKasa+KarsilikNakitGiris-KarsilikNakitCikis-B9 | D9: =IF(C9<KarsilikZorunluEsik,"DURDUR",IF(C9<KarsilikZorunluEsik*2,"İNCELE","UYGUN"))
A11: Tornado: Toplam Karşılığa Etki
A12: Gelir +10% | B12: =ROUND(SUM(tblDonem[Gelir (₺)])*KarliyukTornadoGelir*KarliyukKurumlarOrani,0)
A13: KDV Oranı +1 puan | B13: =ROUND(SUM(tblDonem[Gelir (₺)])*KarliyukTornadoKdv,0)
A14: KV Oranı +1 puan | B14: =ROUND(SUM(tblDonem[Matrah Farkı (₺)])*KarliyukTornadoKurumlar,0)
A15: SGK Oranı +1 puan | B15: =ROUND(SUM(tblBordro[Brüt Maaş (₺)])*KarliyukTornadoSgk,0)
A17: En Etkili Değişken | B17: =KarsilikEnEtkiliDegisken
A19: Tornado etkileri AYARLAR'daki çarpanlardan türetilir.

Sheet RAPOR
A1: VERGİ, SGK VE MAAŞ KARŞILIK AYIRMA SİSTEMİ — YÖNETİCİ ÖZETİ
A2: =_xlfn.CONCAT("Rapor Tarihi: ",TEXT(RaporTarihi,"dd.mm.yyyy")," | Hazırlayan: ",RaporHazirlayan," | Sürüm: ",DosyaSurumu)
A4: Karar | B4: =KARAR!B10
A6: Toplam Gelir | B6: =SUM(tblDonem[Gelir (₺)])
A7: Toplam Gider | B7: =SUM(tblDonem[Gider (₺)])
A8: Net Kâr/Zarar | B8: =SUM(tblDonem[Matrah Farkı (₺)])
A9: Toplam Karşılık Yükü | B9: =KarsilikToplam
A10: Karşılık / Gelir Oranı | B10: =KarsilikGelirOrani
A11: Karşılık Sonrası Nakit Fazlası | B11: =KarsilikNakitFazla
A12: Nakit Eşik Altı Ay | B12: =KarsilikEskikAy
A13: Kalite Skoru | B13: =KarsilikKaliteSkoru
A15: Varsayımlar ve Önemli Notlar
A16: • KDV, kurumlar vergisi, SGK, işsizlik, stopaj ve damga oranları AYARLAR sayfasından alınır.
A17: • Oranlar örnek dönem değerleridir; mali müşavir teyidiyle güncellenmelidir.
A18: • Bu dosya beyanname hazırlama aracı değildir; karşılık ayırma ve nakit planlama destek aracıdır.
A19: • Demo veriler gerçek müşteri verisi değildir; kullanımdan önce temizlenmelidir.
A21: Önerilen Aksiyonlar
A22: =Aksiyon1_ACIKLAMA
A23: =Aksiyon2_ACIKLAMA
A24: =Aksiyon3_ACIKLAMA
A26: Bu rapor karar destek amaçlıdır; mali tavsiye niteliği taşımaz.

Sheet ORNEK_VERI
A1: ORNEK VERI — VERGİ, SGK VE MAAŞ KARŞILIK AYIRMA SİSTEMİ
A3: Örnek Veri (Demo)
A4: Gerçek girişlere başlamadan önce demo veri ile ürünü deneyin. Bu satırlar örnektir; gerçek verilerle değiştirin.
A5: Dönem | B5: Gelir (₺) | C5: Gider (₺) | D5: KDV Yüklenimi (₺) | E5: Not
A6: Ağustos 2026 | B6: 850000 | C6: 620000 | D6: 50000 | E6: Örnek ay 1
A7: Eylül 2026 | B7: 920000 | C7: 650000 | D7: 55000 | E7: Örnek ay 2
A8: Ekim 2026 | B8: 880000 | C8: 610000 | D8: 52000 | E8: Örnek ay 3
A9: Kasım 2026 | B9: 950000 | C9: 680000 | D9: 58000 | E9: Örnek ay 4
A10: Aralık 2026 | B10: 1010000 | C10: 700000 | D10: 60000 | E10: Örnek ay 5
A11: Ocak 2027 | B11: 1080000 | C11: 740000 | D11: 65000 | E11: Örnek ay 6
A1006: Demo veriler rapor sonuçlarını örnekler; satın alma sonrası silinerek gerçek veriler girilir.

Sheet AKIS
A1: AKIS — VergiSgkVeMaasKarsilikAyirmaSistemi
A3: islem_id | B3: kaynak_kart_id | C3: onceki_durum | D3: yeni_durum | E3: tutar | F3: bayrak | G3: not
A4: I-001 | B4: KART-01 | C4: ACIK | D4: ISLEMDE | E4: 1000 | F4: OK | G4: normal geçiş
A5: I-002 | B5: YETİM | C5: ACIK | D5: KAPALI | E5: 0 | F5: YETİM | G5: kaynak_kart_id yok — yetim kayıt
A6: I-003 | B6: KART-02 | C6: ACIK | D6: KAPALI | E6: 500 | F6: GECERSIZ | G6: geçersiz durum geçişi
A7: I-004 | B7: KART-03 | C7: ISLEMDE | D7: ISLEMDE | E7: 250 | F7: ZINCIR_KIRIK | G7: ZİNCİR KIRIK — tutar zinciri sapması
A9: kuyruk_kanit | B9: =IFERROR(COUNTIF($F$4:$F$1000,"OK"),0)

Sheet DEGISIKLIK_KAYDI
A1: DEGISIKLIK KAYDI — VERGİ, SGK VE MAAŞ KARŞILIK AYIRMA SİSTEMİ
A3: Değişiklik Kaydı
A4: Tarih | B4: Sürüm | C4: Değişiklik | D4: Neden | E4: Yapan
A5: 01.08.2026 | B5: 1.0.0 | C5: İlk üretim | D5: Ürünün yayına hazırlanması | E5: ExcelArşiv

Sheet LISTELER
A1: LISTELER — VERGİ, SGK VE MAAŞ KARŞILIK AYIRMA SİSTEMİ
A3: Bağlı Listeler
A4: Bu sayfadaki listeler açılır menüleri besler; yeni seçenek eklemek için sarı hücrelere yazın.
A5: Dönem Etiketi | C5: Karşılık Türü | E5: Kalite Seviyesi
A6: Ağustos 2026 | C6: KDV | E6: YÜKSEK
A7: Eylül 2026 | C7: Kurumlar Vergisi | E7: ORTA
A8: Ekim 2026 | C8: SGK | E8: DÜŞÜK
A9: Kasım 2026 | C9: Maaş
A10: Aralık 2026
A11: Ocak 2027
A12: Şubat 2027

Sheet AYARLAR
A1: AYARLAR — VERGİ, SGK VE MAAŞ KARŞILIK AYIRMA SİSTEMİ
A3: Sistem Ayarları ve Oranlar
A4: Tüm sabitler bu sayfadadır. Oranları kendi döneminize göre mali müşavir teyidiyle güncelleyin.
A6: anahtar | B6: deger | C6: birim | D6: alt | E6: ust | F6: aciklama | G6: kaynak | H6: yururluk_tarihi | I6: dogrulama_tarihi
A7: FirmaUnvan | B7: Örnek Firma A.Ş. | C7: metin | F7: Rapor ve kapakta görünen firma adı. | G7: Kullanıcı | H7: 46023 | I7: 46244
A8: RaporTarihi | B8: 2026-08-08 | C8: tarih | F8: Tüm hesapların ve kararın alındığı tarih. | G8: Kullanıcı | H8: 46023 | I8: 46244
A9: RaporHazirlayan | B9: Finans Direktörü | C9: metin | F9: Raporu hazırlayan kişi/rol. | G9: Kullanıcı | H9: 46023 | I9: 46244
A10: DosyaSurumu | B10: 1.0.0 | C10: metin | F10: Ürün sürüm bilgisi; rapor alt bilgisinde görünür. | G10: Kullanıcı | H10: 46023 | I10: 46244
A11: KarliyukKdvOrani | B11: 0.2 | C11: oran (%) | F11: Satışlarda uygulanan KDV oranı. | G11: Mevzuat: KDVK 28. m. + Cumhurbaşkanı Kararı | H11: 46023 | I11: 46244
A12: KarliyukKurumlarOrani | B12: 0.25 | C12: oran (%) | F12: Kurumlar vergisi oranı. | G12: Mevzuat: KVK 32. m. (5520 s.) | H12: 46023 | I12: 46244
A13: KarliyukSgkIsciOrani | B13: 0.14 | C13: oran (%) | F13: SGK işçi prim oranı. | G13: Mevzuat: 5510 s. SGK K. 81. m. | H13: 46023 | I13: 46244
A14: KarliyukSgkIsverenOrani | B14: 0.205 | C14: oran (%) | F14: SGK işveren prim oranı. | G14: Mevzuat: 5510 s. SGK K. 81. m. | H14: 46023 | I14: 46244
A15: KarliyukIssizlikIsciOrani | B15: 0.01 | C15: oran (%) | F15: İşsizlik sigortası işçi payı. | G15: Mevzuat: 4447 s. İşsizlik Sigortası K. | H15: 46023 | I15: 46244
A16: KarliyukIssizlikIsverenOrani | B16: 0.02 | C16: oran (%) | F16: İşsizlik sigortası işveren payı. | G16: Mevzuat: 4447 s. İşsizlik Sigortası K. | H16: 46023 | I16: 46244
A17: KarliyukStopajOrani | B17: 0.15 | C17: oran (%) | F17: Ücret stopajı gelir vergisi oranı. | G17: Mevzuat: GVK 103. m. (2026 tarifesi) | H17: 46023 | I17: 46244
A18: KarliyukDamgaOrani | B18: 0.00759 | C18: oran (%) | F18: Bordro damga vergisi oranı. | G18: Mevzuat: DVK 528 sayılı Karar | H18: 46023 | I18: 46244
A19: KarliyukNakitKarliikOrani | B19: 0.25 | C19: oran (%) | F19: Projeksiyonda gelirin karşılık yükü oranı. | G19: Varsayım | H19: 46023 | I19: 46244
A20: KarliyukUstOran | B20: 0.4 | C20: oran (%) | F20: Karşılık/gelir oranının üst sınırı. | G20: Varsayım | H20: 46023 | I20: 46244
A21: AyBasiKasaGiris | B21: 500000 | C21: tutar (₺) | F21: Dönem başı kasa bakiyesi. | G21: Kullanıcı | H21: 46023 | I21: 46244
A22: KarsilikNakitEsigi | B22: 100000 | C22: tutar (₺) | F22: Kümülatif nakit alt eşiği. | G22: Varsayım | H22: 46023 | I22: 46244
... A34: KarsilikDoluGirisHucre | B34: 1300 | C34: sayı | F34: Bilgi amaçlıdır; kalite skoru payı KONTROLLER'de canlı hesaplanır. | G34: Varsayım | H34: 46023 | I34: 46244
A35: KarsilikEnEtkiliDegisken | B35: Gelir | C35: metin | F35: Tornado analizinde en etkili değişken. | G35: Varsayım | H35: 46023 | I35: 46244
A36: Aksiyon1_ACIKLAMA | B36: KDV yüklenim belgelerini aylık toplayın; yüklenim artışı ödenecek KDV'yi azaltır. | C36: metin | F36: DURDUR kararında gösterilen ilk öneri. | G36: Varsayım | H36: 46023 | I36: 46244
A37: Aksiyon2_ACIKLAMA | B37: Karşılık/gelir oranı eşiği aşıyorsa ödeme planını revize edin. | C37: metin | F37: İNCELE kararında gösterilen ikinci öneri. | G37: Varsayım | H37: 46023 | I37: 46244
A38: Aksiyon3_ACIKLAMA | B38: Kümülatif nakit eşik altındaysa kısa vadeli kredi veya tahsilat hızlandırın. | C38: metin | F38: İNCELE kararında gösterilen üçüncü öneri. | G38: Varsayım | H38: 46023 | I38: 46244
A39: KarliyukTornadoGelir | B39: 0.1 | C39: oran (%) | F39: Gelirdeki %10 değişimin karşılığa etkisi. | G39: Varsayım | H39: 46023 | I39: 46244
A40: PanelSatir1 | B40: 1 | C40: sayı | F40: PANO aylık grafiğinde kullanılan tablo satırı. | G40: Kullanıcı | H40: 46023 | I40: 46244
A41: PanelSatir2 | B41: 2 | C41: sayı | F41: PANO aylık grafiğinde kullanılan tablo satırı. | G41: Kullanıcı | H41: 46023 | I41: 46244
A42: PanelSatir3 | B42: 3 | C42: sayı | F42: PANO aylık grafiğinde kullanılan tablo satırı. | G42: Kullanıcı | H42: 46023 | I42: 46244
A43: PanelSatir4 | B43: 4 | C43: sayı | F43: PANO aylık grafiğinde kullanılan tablo satırı. | G43: Kullanıcı | H43: 46023 | I43: 46244
A44: PanelSatir5 | B44: 5 | C44: sayı | F44: PANO aylık grafiğinde kullanılan tablo satırı. | G44: Kullanıcı | H44: 46023 | I44: 46244
A45: PanelSatir6 | B45: 6 | C45: sayı | F45: PANO aylık grafiğinde kullanılan tablo satırı. | G45: Kullanıcı | H45: 46023 | I45: 46244
A46: PanelSatir7 | B46: 7 | C46: sayı | F46: PANO aylık grafiğinde kullanılan tablo satırı. | G46: Kullanıcı | H46: 46023 | I46: 46244
A47: PanelSatir8 | B47: 8 | C47: sayı | F47: PANO aylık grafiğinde kullanılan tablo satırı. | G47: Kullanıcı | H47: 46023 | I47: 46244
A48: PanelSatir9 | B48: 9 | C48: sayı | F48: PANO aylık grafiğinde kullanılan tablo satırı. | G48: Kullanıcı | H48: 46023 | I48: 46244
A49: PanelSatir10 | B49: 10 | C49: sayı | F49: PANO aylık grafiğinde kullanılan tablo satırı. | G49: Kullanıcı | H49: 46023 | I49: 46244
A50: PanelSatir11 | B50: 11 | C50: sayı | F50: PANO aylık grafiğinde kullanılan tablo satırı. | G50: Kullanıcı | H50: 46023 | I50: 46244
... A56: GirisKolonAylik | B56: 1 | C56: sayı | F56: Kalite skoru paydasında AYLIK tablosunun giriş kolonu sayısı. | G56: Varsayım | H56: 46023 | I56: 46244
J58: durum_haritasi | K58: durum_id | L58: durum_adi | M58: izinli_sonraki | N58: kategori
J59: HARITA | K59: ACIK | L59: Açık | M59: ISLEMDE | N59: acik
...

Sheet KILAVUZ
A1: KILAVUZ — VERGİ, SGK VE MAAŞ KARŞILIK AYIRMA SİSTEMİ
A3: Kullanım Kılavuzu
A4: 1. Genel Bakış
A5: 2. İlk Kurulum
A6: 3. Veri Girişi
A7: 4. Sonuçları Okuma
A8: 5. Senaryo Çalışması
A9: 6. Koruma
A10: 7. Güncelleme
A11: Oranlar mevzuata göre AYARLAR'dan güncellenir; formüller değişmez.
A19: Bu dosya karar destek aracıdır; beyanname hazırlama, muhasebe kaydı ve hukuki tavsiye niteliği taşımaz.
A21: Varsayım İşaretli Parametreler
... A36: Destek: ExcelArşiv — mevzuat oran değişikliklerinde sürüm güncellemeleri satın alma döneminden itibaren 12 ay ücretsizdir.
