Workbook
Name raporTarihi: AYARLAR!$B$6
Name zincirTolerans: AYARLAR!$B$7
Name soa_esikOluGun: AYARLAR!$B$8
Name soa_esikOluNakit: AYARLAR!$B$9
Name soa_esikOluAdet: AYARLAR!$B$10
Name soa_esikSiparis: AYARLAR!$B$11
Name soa_kovaEsik1: AYARLAR!$B$12
Name soa_kovaEsik2: AYARLAR!$B$13
Name soa_kovaEsik3: AYARLAR!$B$14
Name soa_hedefStokGunu: AYARLAR!$B$15
Name soa_senaryoTemkinli: AYARLAR!$B$16
Name soa_senaryoBaz: AYARLAR!$B$17
Name soa_senaryoIyimser: AYARLAR!$B$18
Name soa_tornadoOran: AYARLAR!$B$19
Name soa_yuzdelikOran: AYARLAR!$B$20
Name soa_olcekHedef: AYARLAR!$B$21
Name soa_azamiMiktar: AYARLAR!$B$22
Name soa_durumHaritasi: AYARLAR!$B$23
Name soa_kuyrukOzeti_metin: AYARLAR!$B$24
Name soa_kapaliDusum_metin: AYARLAR!$B$25
Name soa_kanitRaporu_metin: AYARLAR!$B$26
Name soa_dosyaSurumu: AYARLAR!$B$27
Name soa_firmaUnvan: AYARLAR!$B$28
Name soa_kuralSOA001: AYARLAR!$B$29
Name soa_kuralSOA002: AYARLAR!$B$30
Name soa_kuralSOA003: AYARLAR!$B$31
Name soa_kuralSOA004: AYARLAR!$B$32
Name soa_kuralSOA005: AYARLAR!$B$33
Name soa_oluStokNakit: AYARLAR!$I$48
Name soa_onerilenSiparis: AYARLAR!$I$49
Name soa_oluAdet: AYARLAR!$I$50
Name soa_stokGunuSapma: AYARLAR!$I$51
Name soa_yetimKayit: AYARLAR!$I$52
Name soa_gecersizGecis: AYARLAR!$I$53
Name soa_zincirKirik: AYARLAR!$I$54
Name soa_tahminAralik: AYARLAR!$I$55
Name soa_senaryoKarsilastirma: AYARLAR!$I$56
Name soa_tornadoZirve: AYARLAR!$I$57
Name soa_hhi: AYARLAR!$I$58
Name soa_kaliteSkor: AYARLAR!$I$59
Name soa_yuzdelikP90: AYARLAR!$I$60
Name soa_senaryoMotor: AYARLAR!$I$61
Name soa_kapaliDusum: AYARLAR!$I$62
Name soa_kuyrukOzeti: AYARLAR!$I$63
Name soa_kanitRaporu: AYARLAR!$I$64
Name soa_sonrakiKimlik: AYARLAR!$I$65
Name soa_kararMetni: AYARLAR!$I$66
Name soa_yorumOlu: AYARLAR!$I$69
Name soa_yorumSiparis: AYARLAR!$I$70
Name soa_yorumSapma: AYARLAR!$I$71
Name soa_yorumTornado: AYARLAR!$I$72
Name soa_yorumSenaryo: AYARLAR!$I$73
Name soa_yorumHhi: AYARLAR!$I$74
Name soa_yorumKalite: AYARLAR!$I$75
Name soa_yorumSenMotor: AYARLAR!$I$76
Name soa_yorumTahmin: AYARLAR!$I$77
Name soa_yorumP90: AYARLAR!$I$78
Name ListeDurumlar: LISTELER!$A$7:$A$10
Name ListeIzinliGecis: LISTELER!$C$7:$C$11
Name ListeEvetHayir: LISTELER!$E$7:$E$8

Sheet 00_BASLANGIC
A1: EXCELARŞİV KARAR SİSTEMİ v15.1 — ÜRETİM REFERANSI
A3: Konu | B3: Bağlayıcı Standart
A4: Amaç | B4: Kanıta dayalı, hatada kapalı çalışan Excel üretim ve denetim sistemi
A5: Öncelik | B5: Kullanıcının açık iş talebi ve gerçek kullanım senaryosu
A6: Ana akış | B6: Uygunluk → Yönetişim → Sözleşmeler → Üretim → Test → Kanıt → Kullanıcı Kabulü → Yayın
A7: Yayın ilkesi | B7: Üst aşamada hata varsa alt aşama GEÇTİ üretilemez
A8: Kullanıcı kabulü | B8: Excel masaüstü görünümü test edilmediyse DIŞ_KABUL_GEREKLİ
A9: Nihai yayın | B9: Yalnız uygulanabilir modüller GEÇTİ veya gerekçeli UYGULANMAZ
A10: Ticari ayrım | B10: Ekonomik olarak savunulabilir fiyat, gerçek pazar kabulü ile aynı değildir
A11: Karmaşıklık | B11: Karar değeri, eklenen karmaşıklığın maliyetinden büyük olmalıdır
A12: Excel sınırı | B12: Veritabanı, kurumsal yetkilendirme, değiştirilemez kayıt sistemi veya gerçek zamanlı olay platformu değildir
A13: Dil standardı | B13: Kullanıcıya görünen tüm sayfa, tablo, başlık, açıklama, uyarı ve karar metinleri saf Türkçe olmalıdır
A14: Muhasebe standardı | B14: Finansal ürünlerde Türkiye Tekdüzen Hesap Planı ve Türk muhasebe kullanım alışkanlıkları esas alınır
... A33: Muhasebe | B33: Türkiye Tekdüzen Hesap Planı ve Türk muhasebe/işletme düşünce yapısı esas alınır.

Sheet PANO
A1: ☰ PANO
B2: STOK OPTIMIZASYON + ABC + ÖLÜ STOK NAKIT | L2: Dönem: 2026 / Tam ▼ | M2: ★ DOĞRULANMIŞ
B3: Hedef Kullanıcı: Satın alma, depo planlama, fabrika müdürü, SMMM · 2026 Q3 Denetim Standardı
B5: TOPLAM NAKİT HAVUZU | D5: 4 HESAP | E5: BU AY ÖDENECEK ÇIKIŞ | G5: VADE: 4 GÜN | H5: NET SERBEST LİKİDİTE | J5: GÜVENLİ | K5: DSCR / NAKİT DÖNGÜSÜ | M5: EŞİK: 1.30x
B7: =GİRDİLER!E17 | E7: =B7*0.22 | H7: =B7-E7 | K7: =EĞER(E7>0; YUVARLA(B7/E7; 2); 0)
B9: ↑ %14.2 konsolide canlı veri bağlantısı | E9: ● 8 Kalem nakit karşılığı: bloke | H9: ██████████░░░░░ %78.0 NET MARJ | K9: ✓ İDEAL karşılama rasyosu
B11: STOK OPTIMIZASYON + ABC + ÖLÜ STOK NAKIT — DÖNEMSEL İCRA VE PROJEKSİYON | F11: +%32 Verim | H11: KONSOLİDE OPERASYON VE KARAR MATRİSİ
B12: Kümülatif Hacim vs. Operasyonel Maliyet ve Net Kâr Eğilimi | H12: Anlık Hesaplama Sonuçları, Dinamik Formül Çıktıları ve Durum Puanlaması
B14: Dönem | C14: Aktif Hacim | D14: Maliyet/Yük | E14: Hedef | H14: PARAMETRE / KALEM | I14: ANA TUTAR | J14: FARK / MARJ | K14: VADE | L14: KONTROL DURUMU
B15: D1 | C15: 65 | D15: 45 | E15: 60 | H15: Dönemlik Kümülatif Bakiye | I15: =B7*0.45 | J15: =B7*0.05 | K15: 12 Ay | L15: ✓ DÜZENLİ
B16: D2 | C16: 78 | D16: 48 | E16: 70 | H16: Kritik Eşik Güvenlik Tamponu | I16: =B7*0.30 | J16: =B7*0.03 | K16: 24 Ay | L16: ★ AVANTAJ
B17: D3 | C17: 85 | D17: 55 | E17: 80 | H17: Operasyonel Net Fark | I17: =B7*0.15 | J17: =B7*0.02 | K17: 8 Ay | L17: ● YAKLAŞAN
B18: D4 | C18: 75 | D18: 42 | E18: 75 | H18: Rezerv ve Likit Dağılım | I18: =B7*0.10 | J18: =B7*0.01 | K18: 16 Ay | L18: ✓ TAM UYUM
B19: D5 | C19: 90 | D19: 40 | E19: 85 | H19: KONSOLİDE SİSTEM TOPLAMI | I19: =TOPLA(I15:I18) | J19: =TOPLA(J15:J18) | L19: TAM DOĞRULANDI (0 HATA)
B20: D6 | C20: 96 | D20: 32 | E20: 92
B22: KONSOLİDE PAY VE AĞIRLIK | F22: LİKİDİTE RİSKİ & ERKEN UYARI SİNYALLERİ | K22: KARAR MOTORU
B23: ■ Ana Segment (%42) | F23: Nakit Açığı Riski (30 Gün) | I23: 0.00 TL (Sıfır Risk) | K23: LİKİDİTE OPTİMİZASYON FIRSATI
B24: ■ İkincil Grup (%30) | F24: Tahsilat Gecikme Toleransı | I24: 48 Gün Güvenli Eşik | K24: Atıl kalan nakit rezervinin değerlendirilmesiyle ek finansal getiri imkanı.
B25: ■ Destek Birimi (%15) | F25: ██████████████████████████████████████ Güvenli Bölge (%100)
B26: ■ Rezervler (%13) | F26: ✓ 90 GÜNLÜK PROJEKSİYONDA NAKİT SIKIŞIKLIĞI TESPİT EDİLMEDİ | K26: FONLAMA SENARYOSUNU İNCELE >

Sheet GİRDİLER
A1: ☰ PANO
B3: 🔍 STOK OPTIMIZASYON + ABC + ÖLÜ STOK NAKIT — Kayıt veya hesap ara... | G3: TOPLAM: 1.450 KAYIT | I3: HATALI HÜCRE: 0 ADET
B5: TARİH | C5: REFERANS NO | D5: İŞLEM AÇIKLAMASI VE DETAY | E5: BRÜT TUTAR (₺) | F5: KDV ORANI | G5: NET TUTAR (₺) | H5: HESAP / CARİ | I5: DURUM
B6: 12.10.2026 | C6: TR-0428-A | D6: Operasyonel ana kalem tahmini | E6: 845200 | F6: 0.2 | G6: =E6/(1+F6) | H6: Vadesiz Ticari | I6: ONAYLANDI
B7: 14.10.2026 | C7: TR-0429-B | D7: Operasyonel çıkış/maliyet tahmini | E7: 1240000 | F7: 0.2 | G7: =E7/(1+F7) | H7: Tedarikçi Havuzu | I7: BEKLEMEDE
B8: 18.10.2026 | C8: TR-0430-C | D8: Ödeme takvimi tahakkuku | E8: 620500 | F8: 0.1 | G8: =E8/(1+F8) | H8: Kısa Vade Tahakkuk | I8: ONAYLANDI
B9: 21.10.2026 | C9: TR-0431-D | D9: Müşteri işlem tahmini | E9: 415000 | F9: 0.2 | G9: =E9/(1+F9) | H9: Müşteri Alacağı | I9: ONAYLANDI
B10: 25.10.2026 | C10: TR-0432-E | D10: Ana operasyon tahmini | E10: 980400 | F10: 0.2 | G10: =E10/(1+F10) | H10: Vadesiz Ticari | I10: ONAYLANDI
B11: 28.10.2026 | C11: TR-0433-F | D11: Kredi/taksit karşılığı | E11: 1850000 | F11: 0.2 | G11: =E11/(1+F11) | H11: Finansman Havuzu | I11: BLOKE
B12: 02.11.2026 | C12: TR-0434-G | D12: Sabit gider ve yönetim notları | E12: 740000 | F12: 0.2 | G12: =E12/(1+F12) | H12: Genel Yönetim | I12: ONAYLANDI
B13: 05.11.2026 | C13: TR-0435-H | D13: Operasyonel ana kalem tahmini | E13: 520800 | F13: 0.2 | G13: =E13/(1+F13) | H13: Vadesiz Ticari | I13: ONAYLANDI
B14: 09.11.2026 | C14: TR-0436-I | D14: Müşteri işlem tahmini | E14: 1120000 | F14: 0.2 | G14: =E14/(1+F14) | H14: Müşteri Alacağı | I14: ONAYLANDI
B15: 12.11.2026 | C15: TR-0437-J | D15: Operasyonel çıkış tahmini | E15: 890000 | F15: 0.2 | G15: =E15/(1+F15) | H15: Tedarikçi Havuzu | I15: ONAYLANDI
B17: SAYFA TOPLAMI (10 / 1.450 KAYIT) | E17: =TOPLA(E6:E15)

Sheet YÖNETİM_RAPORU
A1: ☰ PANO
B2: STOK OPTIMIZASYON + ABC + ÖLÜ STOK NAKIT — NİHAİ KARAR VE DEĞERLEME
B3: Yönetim Kurulu ve İcra Komitesi için Otomatik Finansal Stres Testi Raporu · Satın alma, depo planlama, fabrika müdürü, SMMM
B4: DÖNEM: 2026 Q3 · DENETİM PROTOKOLÜ: ISO/VUK/IFRS UYUMLU · DURUM: ONAYLANDI
B6: SENARYO A: KÖTÜMSER (STRES TESTİ -%20) | H6: SENARYO B: BAZ MODEL (HEDEFLENEN)
B8: Ciro / Hacim Düşüşü: | E8: -%20.0 (Kriz Eşiği) | H8: Ciro / Hacim Gerçekleşmesi: | K8: %100.0 (Tam Bütçe)
B9: Beklenen Net Kâr / Getiri: | E9: =PANO!B7*0.8*0.22 | H9: Beklenen Net Kâr / Getiri: | K9: =PANO!H7
B10: Minimum Nakit Tamponu: | E10: =PANO!E7*0.75 | H10: Serbest Nakit Akımı: | K10: =PANO!H7*0.75
B11: Likidite Karşılama Oranı: | E11: =YUVARLA(PANO!B7*0.8/PANO!E7; 2) | H11: Yatırım Geri Dönüşü (ROI): | K11: %38.4 Yıllık
B14: STRES SENARYOSUNDA DAHİ İFLAS RİSKİ YOK | H14: OPTİMUM İCRA VE PLANLAMA REÇETESİ
B17: YÖNETİM KARAR MATRİSİ VE UYGULAMA REÇETESİ
B19: ● Öncelik 1: Acil Likidite ve Borç Servis Planlaması
B20: Sistemde hesaplanan vade günlerine sadık kalınarak nakit blokajı 3 gün önceden hazır edilmelidir.
B21: ● Öncelik 2: Formül Doğrulama ve Çapraz Sağlama
B22: Tüm hücreler kilitli formül korumasında olup girdi sayfalarında sıfır döngüsel başvuru (circular ref) garantilidir.
B23: ● Öncelik 3: Resmi Mevzuat ve Vergi Kalkanı Entegrasyonu
B24: 2026 güncel vergi dilimleri, amortisman ve SGK teşvik parametreleri tam otomatik yansıtılmaktadır.
B25: ● Öncelik 4: Yönetici İmzası ve Rapor Paylaşımı
B26: Tek tuşla PDF ve A4 çıktı formatına tam uyumlu sayfa yapısı kurgulanmıştır.

Sheet 01_YURUTME_CEKIRDEGI
A1: YÜRÜTME ÇEKİRDEĞİ — ZORUNLU ÜRETİM SIRASI
A3: Adım | B3: Modül | C3: Tetikleyici | D3: Zorunlu Kanıt | E3: GEÇTİ Kuralı | F3: Hata Durumu | G3: Sonraki Aşama
A4: 1 | B4: Excel Uygunluğu | C4: Her yeni model | D4: UYGUNLUK_KARARI | E4: Excel'in rolü açık | F4: HATA / BLOKE | G4: Yönetişim
A5: 2 | B5: Yönetişim | C5: Her model | D5: Risk seviyesi + etki girdileri | E5: Seviye hesaplandı | F5: BLOKE | G5: Sözleşmeler
A6: 3 | B6: Türk Muhasebe Eşlemesi | C6: Finansal model | D6: THP hesap eşleme tablosu | E6: Kritik satırlar THP ile uyumlu | F6: HATA | G6: Sözleşmeler
A7: 4 | B7: Veri ve Anlam Sözleşmeleri | C7: Girdi/KPI varsa | D7: Veri + KPI sözleşmeleri | E7: Kapsam %100 | F7: HATA | G7: Üretim
A8: 5 | B8: Üretim | C8: Sözleşmeler GEÇTİ | D8: Çalışan Excel | E8: Tek gerçek kaynak korunmuş | F8: HATA | G8: Testler
A9: 6 | B9: Görsel/Kullanım Katmanı | C9: Motor hazır | D9: Başlıklar + renk + grafik + yönlendirme | E9: Tüm kullanıcı sayfaları standarda uygun | F9: HATA | G9: Testler
A10: 7 | B10: Testler | C10: Üretim tamam | D10: Formül/OOXML/kimlik/oracle/golden/metamorfik | E10: Uygulanabilir hard gate'ler GEÇTİ | F10: HATA | G10: Kanıt
A11: 8 | B11: Hata-Kontrol Tutarlılığı | C11: Test sonucu var | D11: Hata taraması + kontrol sonuçları | E11: Formül hatası varken GEÇTİ yok | F11: HATA | G11: Kanıt
A12: 9 | B12: Kanıt | C12: Test sonucu var | D12: Makine okunur artefakt + özet | E12: Kanıt fiziksel ve tutarlı | F12: HATA | G12: Kullanıcı Kabulü
A13: 10 | B13: Kullanıcı Kabulü | C13: Kritik görevler | D13: Gerçek ekran davranışı | E13: Kritik görevler %100 | F13: DIŞ_KABUL_GEREKLİ | G13: Ticari
A14: 11 | B14: Ticari Değer | C14: Ürün satılacaksa | D14: ROI + demo + kanıt paketi | E14: Ekonomik değer kanıtlı | F14: UYARI / HATA | G14: Pazar Doğrulama
A15: 12 | B15: Pazar Doğrulama | C15: Pazar iddiası varsa | D15: Ücretli satış/pilot/fiyat kabul kanıtı | E15: Gerçek fiyat kabul kanıtı | F15: UYGULANMAZ / HATA | G15: Yayın

Sheet 02_KONTROL_LISTESI
A1: NİHAİ KONTROL LİSTESİ — KANITSIZ GEÇİŞ YOK
A3: Kontrol No | B3: Kontrol | C3: Beklenen | D3: Zorunlu Kapı? | E3: Sonuç
A4: K01 | B4: Kullanıcının açık talebi öncelikli mi? | C4: Evet | D4: EVET
A5: K02 | B5: Mevcut yapı, formüller ve tek gerçek kaynak korunuyor mu? | C5: Evet, değişiklik gerekçeli | D5: EVET
A6: K03 | B6: Üst aşama HATA ise alt aşama GEÇTİ engelleniyor mu? | C6: Evet | D6: EVET
A7: K04 | B7: Kanıt fiziksel çıktı ve içerik doğrulaması içeriyor mu? | C7: Evet | D7: EVET
A8: K05 | B8: Excel GUI erişimi olmadan kullanıcı görünümü GEÇTİ yazılıyor mu? | C8: Hayır | D8: EVET
A9: K06 | B9: NİHAİ yalnız GEÇTİ / gerekçeli UYGULANMAZ ile mi? | C9: Evet | D9: EVET
A10: K07 | B10: Ekonomik fiyat savunusu pazar doğrulamasından ayrılmış mı? | C10: Evet | D10: EVET
A11: K08 | B11: Prestij için gereksiz modül var mı? | C11: Hayır | D11: HAYIR
A12: K09 | B12: Excel sınırları açık mı? | C12: Evet | D12: EVET
A13: K10 | B13: Teknik kaynak korunuyor mu? | C13: Evet | D13: EVET
A14: K11 | B14: Kullanıcıya görünen tüm metinler Türkçe mi? | C14: Evet | D14: EVET
A15: K12 | B15: Her kullanıcı sayfasında üst başlık var mı? | C15: Evet | D15: EVET
... A34: K31 | B34: Premium vitrin, altyapı kadar güçlü ve satış fiyatını destekleyecek seviyede mi? | C34: Evet | D34: EVET

Sheet 03_GORSEL_TASARIM
A1: GÖRSEL TASARIM VE PREMIUM EXCEL STANDARDI
A3: Alan | B3: Zorunlu Kural | C3: Uygulama | D3: Yasak | E3: Kontrol | F3: Durum
A4: Sayfa başlığı | B4: Her kullanıcı sayfasının en üstünde tek ve açık sayfa başlığı | C4: A1'den başlayan koyu lacivert başlık bandı | D4: Başlıksız sayfa | E4: Başlık kapsama = %100 | F4: ZORUNLU
A5: Sekme renkleri | B5: Sayfalar işlevine göre renk kodlanır | C5: Girdi=mavi, hesap=gri, rapor=lacivert, kontrol=kırmızı, kılavuz=altın | D5: Rastgele renk | E5: Renk semantiği tutarlı | F5: ZORUNLU
A6: Kolon düzeni | B6: Veri blokları bitişik kolonlarda ilerler | C6: Gereksiz boş kolon bırakma; yalnız gerçek bölüm ayrımı varsa kontrollü boşluk | D6: A:C veri, D boş, E:F veri gibi parçalı yapı | E6: Boş kolon taraması | F6: ZORUNLU
A7: Girdi hücreleri | B7: Kullanıcının değiştireceği alan açıkça görünür | C7: Açık sarı dolgu + mavi yazı | D7: Formülle aynı görünüm | E7: Girdi/formül ayrımı | F7: ZORUNLU
A8: Formüller | B8: Hesap hücreleri kullanıcı girdisinden ayrılır | C8: Siyah yazı; sayfalar arası bağlantı yeşil yazı | D8: Hard-code gizleme | E8: Formül sınıfı kontrolü | F8: ZORUNLU
A9: Grafik sayısı | B9: Yönetici ekranında en fazla 3 ana karar grafiği | C9: Trend, karşılaştırma, köprü/dağılım; iş kararına bağlı | D9: Grafik kalabalığı | E9: Grafik başına karar sorusu | F9: ZORUNLU
A10: Grafik stili | B10: Kurumsal ve yüksek okunabilirlik | C10: Beyaz zemin, ince gridline, tek vurgu rengi, açık birim/başlık | D10: 3B, gölge, neon, gökkuşağı renkleri | E10: Görsel inceleme | F10: ZORUNLU
A11: Grafik başlığı | B11: Grafik 'neyi' değil 'ne anlama geldiğini' söyler | C11: Örn: 'Nakit 2028'de kritik eşiğin altına iniyor' | D11: 'Nakit Grafiği' gibi anlamsız başlık | E11: Başlık karar testi | F11: ZORUNLU
A12: Birimler | B12: Tüm finansal görsellerde birim açık | C12: TL, bin TL, milyon TL, %, gün, x | D12: Birim belirsizliği | E12: Birim kapsama %100 | F12: ZORUNLU
A13: Sıfır/negatif | B13: Finansal format standardı | C13: Sıfır='-', negatif kırmızı parantez | D13: -500 veya 0,00 kalabalığı | E13: Format kontrolü | F13: ZORUNLU
A14: Yazı tipi | B14: Tek aile | C14: Aptos veya Segoe UI | D14: Karışık font | E14: Tek font kontrolü | F14: ZORUNLU
... A22: Premium vitrin | B22: Görsel kalite ürün değerinin zorunlu parçasıdır | C22: Kaliteli grafik, gerçek KPI kartı, finansal hiyerarşi, tab rengi, fonksiyonel navigasyon | D22: Sadece doğru hesap yapıp çıplak/varsayılan Excel görünümü bırakmak | E22: Görsel release incelemesi | F22: ZORUNLU

Sheet 04_MUHASEBE_THP
A1: TÜRKİYE MUHASEBE VE TEKDÜZEN HESAP PLANI STANDARDI
A3: Konu | B3: Zorunlu Standart | C3: Örnek Türkçe Ad | D3: THP / Mantık | E3: Hata Riski | F3: Kontrol
A4: Dil | B4: Kullanıcıya görünen finansal terimler Türkçe | C4: Hasılat, Satışların Maliyeti, Brüt Kâr, Faaliyet Giderleri | D4: Türk işletme kullanımına uygun | E4: İngilizce jargon | F4: Terminoloji taraması
A5: Gelir Tablosu | B5: Türk sunum sırası kullanılır | C5: Net Satışlar → Satışların Maliyeti → Brüt Kâr → Faaliyet Giderleri → Faaliyet Kârı | D5: 600/610/611; 620-623; 63x | E5: Yanlış sınıflama | F5: Hesap eşleme
A6: Bilanço | B6: Dönen/Duran Varlık ve Kısa/Uzun Vadeli Yükümlülük ayrımı | C6: Hazır Değerler, Ticari Alacaklar, Stoklar, Mali Borçlar | D6: 1xx / 2xx / 3xx / 4xx / 5xx | E6: Vade sınıfı hatası | F6: Bilanço eşitliği
A7: Nakit Akışı | B7: İşletme/Yatırım/Finansman nakit akışları ayrılır | C7: Faaliyetlerden Nakit, Yatırım Harcamaları, Finansman Nakit Akışı | D7: Dolaylı/doğrudan yöntem açık seçilir | E7: Kâr = nakit sanılması | F7: Nakit devri
A8: Ticari Alacaklar | B8: Cari ve vade mantığı korunur | C8: 120 Alıcılar | D8: 120 | E8: Tahakkuk/nakit karışması | F8: Alacak devir kontrolü
A9: Ticari Borçlar | B9: Tedarikçi borcu ayrı izlenir | C9: 320 Satıcılar | D9: 320 | E9: Gider/ödeme karışması | F9: Borç devir kontrolü
A10: Kasa/Banka | B10: Hazır değerler ayrı izlenir | C10: 100 Kasa, 102 Bankalar | D10: 100 / 102 | E10: Virmanla toplam nakdin değişmesi | F10: Virman değişmezi
A11: Stok | B11: Dikeye uygun stok türü | C11: 150 İlk Madde ve Malzeme, 153 Ticari Mallar | D11: 15x | E11: Maliyet ve stok hareketinin kopması | F11: Stok devri
A12: Maddi Duran Varlık | B12: Yatırım harcaması ve amortisman bağlantılı | C12: 253 Tesis Makine Cihazlar, 255 Demirbaşlar, 257 Birikmiş Amortismanlar | D12: 25x | E12: Yatırım/gider karışması | F12: Net defter değeri devri
A13: Mali Borçlar | B13: Kısa/uzun vadeli borç ayrımı | C13: 300 Banka Kredileri / 400 Banka Kredileri | D13: 300 / 400 | E13: Vade sınıfı yanlış | F13: Borç devri
A14: Özkaynak | B14: Sermaye ve geçmiş yıl kârları ayrı | C14: 500 Sermaye, 570 Geçmiş Yıllar Kârları, 590 Dönem Net Kârı | D14: 5xx | E14: Net kâr bağının kopması | F14: Özkaynak devri
... A18: İstisna | B18: TFRS özel ürün varsa fark açık yazılır | C18: Tekdüzen raporlama ≠ TFRS finansal tablo sunumu | D18: Amaç belirtilir | E18: Standartları karıştırma | F18: Model amacı kontrolü

Sheet 05_KARAR_SATIS
A1: KARAR, GÜVEN VE SATIŞA HAZIRLIK STANDARDI
A3: Alan | B3: Müşteri Sorusu | C3: Zorunlu Ürün Davranışı | D3: Kanıt | E3: Başarısızlık Durumu | F3: Kapı
A4: 5 saniye | B4: Bu ürün neyi çözüyor? | C4: İlk ekranda hedef kullanıcı + pahalı problem + sonuç görünür | D4: Başlık + alt mesaj + gerçek ekran | E4: Ürün yalnız teknik isim | F4: HATA
A5: Acı | B5: Sorun bana neye mal oluyor? | C5: Mümkünse müşterinin kendi verisiyle parasal/zaman etkisi hesaplanır | D5: ROI/acı hesaplama yöntemi | E5: Uydurma tasarruf | F5: HATA
A6: Karar | B6: Bu bilgiyle ne yapacağım? | C6: Her kritik KPI aksiyona bağlanır | D6: KARAR_KUYRUGU | E6: Sadece rapor | F6: HATA
A7: Güven | B7: Bu sayıya neden inanayım? | C7: Kaynak, formül mantığı, kontrol ve son doğrulama görünür | D7: Kontroller + kaynak izi + sürüm | E7: Prestij kelimesi | F7: HATA
A8: Referans | B8: Müşteri yorumu yoksa ne göstereceğim? | C8: Önce/Sonra + Karar Vakası + Hata Önleme Vakası üretilir | D8: Demo/örnek çıktı | E8: Kanıtsız iddia | F8: HATA
A9: Senaryo | B9: Ne olursa işler bozulur? | C9: Baz/Aşağı/Yukarı veya uygun stres senaryosu | D9: Senaryo karşılaştırma | E9: Dekoratif senaryo | F9: HATA
A10: Ters stres | B10: Hangi eşikte karar kırılır? | C10: En az bir kritik sürücü için kırılma eşiği | D10: Kırılma eşiği tablosu | E10: Sadece +/- %10 | F10: UYARI/HATA
A11: Hata tutarlılığı | B11: Formül hata verirse ne olur? | C11: Kontrol GEÇTİ veremez; BLOKE/HATA üretir | D11: Hata taraması | E11: Hata + GEÇTİ birlikte | F11: HATA
A12: Karar motoru | B12: Ne oldu, neden oldu? | C12: Sorun + neden + parasal etki + aksiyon + son tarih | D12: Karar tablosu | E12: Boş sayfa / isim düzeyi modül | F12: HATA
A13: Yönetici özeti | B13: 5 saniyede ne görmeliyim? | C13: Bugün / ne değişti / ne bozulacak / neden / ne yapmalıyım / güven | D13: Yönetici özeti ekranı | E13: KPI kutusu yığını | F13: HATA
A14: Teklif | B14: Neden satın almalıyım? | C14: Dosya özellikleri yerine sonuç ve kaçınılan maliyet sunulur | D14: Ürün sayfası kanıt eşlemesi | E14: Özellik listesiyle satış | F14: HATA
... A19: Pazar kanıtı | B19: Piyasa gerçekten ödüyor mu? | C19: Satış/pilot/LOI/fiyat kabulü olmadan pazar doğrulandı yazılmaz | D19: Gerçek işlem kanıtı | E19: Tahmini talep = satış kabulü | F19: HATA

Sheet KAPAK
A1: KAPAK — Stok Optimizasyon + ABC + Ölü Stok Nakit
A3: Stok Optimizasyon + ABC + Ölü Stok Nakit
A4: Stok sayımını ABC sınıfı ve ölü stok nakit zinciri ile yönetir; önerilen siparişi görünür kılar; SİPARİŞ / BEKLE / ÖLÜ STOK ERİT kararı üretir.
A6: Bu ürün ne sağlar?
A7: • Makrosuz durum makinesi: Sayım → ABC → Aksiyon → Kapalı
A8: • Stok adet × birim maliyet ↔ kontrol nakit zinciri (ZİNCİR KIRIK bayrağı)
A9: • Ölü stok nakit + stok günü + önerilen sipariş kuyruğu
A10: • Geçersiz geçiş ve yetim SKU uyarıları
A11: • Dönemsel stok kanıt raporu — yönetici/SMMM dosyasına uygun
A13: Kimler için?
A14: • Satın alma / depo planlama — ABC sınıfı ve önerilen sipariş
A15: • Fabrika müdürü — SİPARİŞ / BEKLE / ÖLÜ STOK ERİT kararı
... A21: Sürüm 1.0.0 | Lisans: Tek kullanıcı | ExcelArşiv

Sheet KARTLAR
A1: KARTLAR — Stok Optimizasyon + ABC + Ölü Stok Nakit
A3: SKU kartları — her kaydın tek kimliği vardır
A4: Sonraki Kimlik | B4: =soa_sonrakiKimlik
A5: KartId | B5: Unvan | C5: Sinif | D5: Depo | E5: MinStok | F5: RiskNotu | G5: Aktif | H5: ToplamStok | I5: OrtStokGunu
A6: SKU-00001 | B6: Çelik Sac 2mm | C6: Hammadde | D6: Merkez | E6: 50 | F6: Normal | G6: EVET | H6: =IF($A6="","",SUMIF(tblAkis[KaynakKartId],$A6,tblAkis[StokAdet])) | I6: =IF($A6="","",IFERROR(AVERAGEIF(tblAkis[KaynakKartId],$A6,tblAkis[StokGunu]),0))
A7: SKU-00002 | B7: Motor Rulman 6205 | C7: Yedek Parça | D7: Merkez | E7: 60 | F7: Normal | G7: EVET | H7: =IF($A7="","",SUMIF(tblAkis[KaynakKartId],$A7,tblAkis[StokAdet])) | I7: =IF($A7="","",IFERROR(AVERAGEIF(tblAkis[KaynakKartId],$A7,tblAkis[StokGunu]),0))
A8: SKU-00003 | B8: Ambalaj Karton A | C8: Ambalaj | D8: Yan Depo | E8: 70 | F8: Normal | G8: EVET | H8: =IF($A8="","",SUMIF(tblAkis[KaynakKartId],$A8,tblAkis[StokAdet])) | I8: =IF($A8="","",IFERROR(AVERAGEIF(tblAkis[KaynakKartId],$A8,tblAkis[StokGunu]),0))
A9: SKU-00004 | B9: Vida M8 Set | C9: Sarf | D9: Merkez | E9: 80 | F9: Normal | G9: EVET | H9: =IF($A9="","",SUMIF(tblAkis[KaynakKartId],$A9,tblAkis[StokAdet])) | I9: =IF($A9="","",IFERROR(AVERAGEIF(tblAkis[KaynakKartId],$A9,tblAkis[StokGunu]),0))
A10: SKU-00005 | B10: Hidrolik Yağ 20L | C10: Sarf | D10: Yan Depo | E10: 90 | F10: Normal | G10: EVET | H10: =IF($A10="","",SUMIF(tblAkis[KaynakKartId],$A10,tblAkis[StokAdet])) | I10: =IF($A10="","",IFERROR(AVERAGEIF(tblAkis[KaynakKartId],$A10,tblAkis[StokGunu]),0))
A11: SKU-00006 | B11: PLC Modül S7 | C11: Yedek Parça | D11: Kritik | E11: 100 | F11: Normal | G11: EVET | H11: =IF($A11="","",SUMIF(tblAkis[KaynakKartId],$A11,tblAkis[StokAdet])) | I11: =IF($A11="","",IFERROR(AVERAGEIF(tblAkis[KaynakKartId],$A11,tblAkis[StokGunu]),0))
A12: SKU-00007 | B12: Kayış Profil B | C12: Yedek Parça | D12: Merkez | E12: 110 | F12: Normal | G12: EVET | H12: =IF($A12="","",SUMIF(tblAkis[KaynakKartId],$A12,tblAkis[StokAdet])) | I12: =IF($A12="","",IFERROR(AVERAGEIF(tblAkis[KaynakKartId],$A12,tblAkis[StokGunu]),0))
A13: SKU-00008 | B13: Etiket Rulo | C13: Ambalaj | D13: Yan Depo | E13: 120 | F13: Normal | G13: EVET | H13: =IF($A13="","",SUMIF(tblAkis[KaynakKartId],$A13,tblAkis[StokAdet])) | I13: =IF($A13="","",IFERROR(AVERAGEIF(tblAkis[KaynakKartId],$A13,tblAkis[StokGunu]),0))
H14: =IF($A14="","",SUMIF(tblAkis[KaynakKartId],$A14,tblAkis[StokAdet])) | I14: =IF($A14="","",IFERROR(AVERAGEIF(tblAkis[KaynakKartId],$A14,tblAkis[StokGunu]),0))
H15: =IF($A15="","",SUMIF(tblAkis[KaynakKartId],$A15,tblAkis[StokAdet])) | I15: =IF($A15="","",IFERROR(AVERAGEIF(tblAkis[KaynakKartId],$A15,tblAkis[StokGunu]),0))
H16: =IF($A16="","",SUMIF(tblAkis[KaynakKartId],$A16,tblAkis[StokAdet])) | I16: =IF($A16="","",IFERROR(AVERAGEIF(tblAkis[KaynakKartId],$A16,tblAkis[StokGunu]),0))
H17: =IF($A17="","",SUMIF(tblAkis[KaynakKartId],$A17,tblAkis[StokAdet])) | I17: =IF($A17="","",IFERROR(AVERAGEIF(tblAkis[KaynakKartId],$A17,tblAkis[StokGunu]),0))
H18: =IF($A18="","",SUMIF(tblAkis[KaynakKartId],$A18,tblAkis[StokAdet])) | I18: =IF($A18="","",IFERROR(AVERAGEIF(tblAkis[KaynakKartId],$A18,tblAkis[StokGunu]),0))
H19: =IF($A19="","",SUMIF(tblAkis[KaynakKartId],$A19,tblAkis[StokAdet])) | I19: =IF($A19="","",IFERROR(AVERAGEIF(tblAkis[KaynakKartId],$A19,tblAkis[StokGunu]),0))
H20: =IF($A20="","",SUMIF(tblAkis[KaynakKartId],$A20,tblAkis[StokAdet])) | I20: =IF($A20="","",IFERROR(AVERAGEIF(tblAkis[KaynakKartId],$A20,tblAkis[StokGunu]),0))
H21: =IF($A21="","",SUMIF(tblAkis[KaynakKartId],$A21,tblAkis[StokAdet])) | I21: =IF($A21="","",IFERROR(AVERAGEIF(tblAkis[KaynakKartId],$A21,tblAkis[StokGunu]),0))
H22: =IF($A22="","",SUMIF(tblAkis[KaynakKartId],$A22,tblAkis[StokAdet])) | I22: =IF($A22="","",IFERROR(AVERAGEIF(tblAkis[KaynakKartId],$A22,tblAkis[StokGunu]),0))
H23: =IF($A23="","",SUMIF(tblAkis[KaynakKartId],$A23,tblAkis[StokAdet])) | I23: =IF($A23="","",IFERROR(AVERAGEIF(tblAkis[KaynakKartId],$A23,tblAkis[StokGunu]),0))
H24: =IF($A24="","",SUMIF(tblAkis[KaynakKartId],$A24,tblAkis[StokAdet])) | I24: =IF($A24="","",IFERROR(AVERAGEIF(tblAkis[KaynakKartId],$A24,tblAkis[StokGunu]),0))
H25: =IF($A25="","",SUMIF(tblAkis[KaynakKartId],$A25,tblAkis[StokAdet])) | I25: =IF($A25="","",IFERROR(AVERAGEIF(tblAkis[KaynakKartId],$A25,tblAkis[StokGunu]),0))
... H255: =IF($A255="","",SUMIF(tblAkis[KaynakKartId],$A255,tblAkis[StokAdet])) | I255: =IF($A255="","",IFERROR(AVERAGEIF(tblAkis[KaynakKartId],$A255,tblAkis[StokGunu]),0))

Sheet AKIS
A1: AKIS — Stok Optimizasyon + ABC + Ölü Stok Nakit
A3: Stok sayım/ABC satırları — durum makinesi + yetim + geçersiz geçiş + zincir
A5: IslemId | B5: KaynakKartId | C5: SkuKod | D5: SayimTarihi | E5: SonHareket | F5: OncekiDurum | G5: Durum | H5: StokAdet | I5: BirimMaliyet | J5: KontrolNakit | K5: OnerilenSiparis | L5: StokGunu | M5: AbcSinif | N5: YorumA | O5: YorumB | P5: HesaplananNakit | Q5: OluBayrak | R5: YasGun | S5: YasKova | T5: YetimBayrak | U5: GecisUyarisi | V5: ZincirBayrak | W5: KayitDolu | X5: SiparisTl
A6: SOA-00001 | B6: SKU-00001 | C6: STK-2026-0001 | D6: 46243 | E6: 46228 | G6: SAYIM | H6: 240 | I6: 26 | J6: 6240 | K6: 79 | L6: 17 | M6: A | N6: A | O6: Stok notu 1 | P6: =IF($A6="","",$H6*$I6) | Q6: =IF(OR($A6="",$G6="KAPALI"),"",IF($L6>soa_esikOluGun,"ÖLÜ","")) | R6: =IF($A6="","",IF($E6="","",raporTarihi-$E6)) | S6: =IF($A6="","",IF($R6="","",IF($R6<=soa_kovaEsik1,"0-7",IF($R6<=soa_kovaEsik2,"8-30",IF($R6<=soa_kovaEsik3,"31-90","90+"))))) | T6: =IF($A6="","",IF($B6="","YETİM",IF(COUNTIF(tblKartlar[KartId],$B6)=0,"YETİM",""))) | U6: =IF(OR($A6="",$F6=""),"",IF(OR($F6&"|"&$G6="",COUNTIF(ListeIzinliGecis,$F6&"|"&$G6)>0),"","GEÇERSİZ GEÇİŞ")) | V6: =IF($A6="","",IF(OR($P6="",$J6=""),"",IF(ABS($J6-$P6)>zincirTolerans,"ZİNCİR KIRIK","OK"))) | W6: =IF($A6="","",1) | X6: =IF($A6="","",$K6*$I6)
A7: SOA-00002 | B7: SKU-00002 | C7: STK-2026-0002 | D7: 46241 | E7: 46221 | F7: SAYIM | G7: ABC | H7: 280 | I7: 27 | J7: 7560 | K7: 78 | L7: 24 | M7: B | N7: B | O7: Stok notu 2 | P7: =IF($A7="","",$H7*$I7) | Q7: =IF(OR($A7="",$G7="KAPALI"),"",IF($L7>soa_esikOluGun,"ÖLÜ","")) | R7: =IF($A7="","",IF($E7="","",raporTarihi-$E7)) | S7: =IF($A7="","",IF($R7="","",IF($R7<=soa_kovaEsik1,"0-7",IF($R7<=soa_kovaEsik2,"8-30",IF($R7<=soa_kovaEsik3,"31-90","90+"))))) | T7: =IF($A7="","",IF($B7="","YETİM",IF(COUNTIF(tblKartlar[KartId],$B7)=0,"YETİM",""))) | U7: =IF(OR($A7="",$F7=""),"",IF(OR($F7&"|"&$G7="",COUNTIF(ListeIzinliGecis,$F7&"|"&$G7)>0),"","GEÇERSİZ GEÇİŞ")) | V7: =IF($A7="","",IF(OR($P7="",$J7=""),"",IF(ABS($J7-$P7)>zincirTolerans,"ZİNCİR KIRIK","OK"))) | W7: =IF($A7="","",1) | X7: =IF($A7="","",$K7*$I7)
A8: SOA-00003 | B8: SKU-00003 | C8: STK-2026-0003 | D8: 46239 | E8: 46214 | F8: ABC | G8: AKSIYON | H8: 320 | I8: 28 | J8: 8960 | K8: 77 | L8: 31 | M8: C | N8: A | O8: Stok notu 3 | P8: =IF($A8="","",$H8*$I8) | Q8: =IF(OR($A8="",$G8="KAPALI"),"",IF($L8>soa_esikOluGun,"ÖLÜ","")) | R8: =IF($A8="","",IF($E8="","",raporTarihi-$E8)) | S8: =IF($A8="","",IF($R8="","",IF($R8<=soa_kovaEsik1,"0-7",IF($R8<=soa_kovaEsik2,"8-30",IF($R8<=soa_kovaEsik3,"31-90","90+"))))) | T8: =IF($A8="","",IF($B8="","YETİM",IF(COUNTIF(tblKartlar[KartId],$B8)=0,"YETİM",""))) | U8: =IF(OR($A8="",$F8=""),"",IF(OR($F8&"|"&$G8="",COUNTIF(ListeIzinliGecis,$F8&"|"&$G8)>0),"","GEÇERSİZ GEÇİŞ")) | V8: =IF($A8="","",IF(OR($P8="",$J8=""),"",IF(ABS($J8-$P8)>zincirTolerans,"ZİNCİR KIRIK","OK"))) | W8: =IF($A8="","",1) | X8: =IF($A8="","",$K8*$I8)
A9: SOA-00004 | B9: SKU-00004 | C9: STK-2026-0004 | D9: 46237 | E9: 46207 | F9: AKSIYON | G9: KAPALI | H9: 360 | I9: 29 | J9: 10440 | K9: 0 | L9: 38 | M9: A | N9: B | O9: Stok notu 4 | P9: =IF($A9="","",$H9*$I9) | Q9: =IF(OR($A9="",$G9="KAPALI"),"",IF($L9>soa_esikOluGun,"ÖLÜ","")) | R9: =IF($A9="","",IF($E9="","",raporTarihi-$E9)) | S9: =IF($A9="","",IF($R9="","",IF($R9<=soa_kovaEsik1,"0-7",IF($R9<=soa_kovaEsik2,"8-30",IF($R9<=soa_kovaEsik3,"31-90","90+"))))) | T9: =IF($A9="","",IF($B9="","YETİM",IF(COUNTIF(tblKartlar[KartId],$B9)=0,"YETİM",""))) | U9: =IF(OR($A9="",$F9=""),"",IF(OR($F9&"|"&$G9="",COUNTIF(ListeIzinliGecis,$F9&"|"&$G9)>0),"","GEÇERSİZ GEÇİŞ")) | V9: =IF($A9="","",IF(OR($P9="",$J9=""),"",IF(ABS($J9-$P9)>zincirTolerans,"ZİNCİR KIRIK","OK"))) | W9: =IF($A9="","",1) | X9: =IF($A9="","",$K9*$I9)
A10: SOA-00005 | B10: SKU-00005 | C10: STK-2026-0005 | D10: 46235 | E10: 46200 | F10: SAYIM | G10: ABC | H10: 400 | I10: 30 | J10: 12000 | K10: 75 | L10: 45 | M10: B | N10: A | O10: Stok notu 5 | P10: =IF($A10="","",$H10*$I10) | Q10: =IF(OR($A10="",$G10="KAPALI"),"",IF($L10>soa_esikOluGun,"ÖLÜ","")) | R10: =IF($A10="","",IF($E10="","",raporTarihi-$E10)) | S10: =IF($A10="","",IF($R10="","",IF($R10<=soa_kovaEsik1,"0-7",IF($R10<=soa_kovaEsik2,"8-30",IF($R10<=soa_kovaEsik3,"31-90","90+"))))) | T10: =IF($A10="","",IF($B10="","YETİM",IF(COUNTIF(tblKartlar[KartId],$B10)=0,"YETİM",""))) | U10: =IF(OR($A10="",$F10=""),"",IF(OR($F10&"|"&$G10="",COUNTIF(ListeIzinliGecis,$F10&"|"&$G10)>0),"","GEÇERSİZ GEÇİŞ")) | V10: =IF($A10="","",IF(OR($P10="",$J10=""),"",IF(ABS($J10-$P10)>zincirTolerans,"ZİNCİR KIRIK","OK"))) | W10: =IF($A10="","",1) | X10: =IF($A10="","",$K10*$I10)
A11: SOA-00006 | B11: SKU-00006 | C11: STK-2026-0006 | D11: 46233 | E11: 46193 | F11: ABC | G11: AKSIYON | H11: 440 | I11: 31 | J11: 13640 | K11: 74 | L11: 52 | M11: C | N11: B | O11: Stok notu 6 | P11: =IF($A11="","",$H11*$I11) | Q11: =IF(OR($A11="",$G11="KAPALI"),"",IF($L11>soa_esikOluGun,"ÖLÜ","")) | R11: =IF($A11="","",IF($E11="","",raporTarihi-$E11)) | S11: =IF($A11="","",IF($R11="","",IF($R11<=soa_kovaEsik1,"0-7",IF($R11<=soa_kovaEsik2,"8-30",IF($R11<=soa_kovaEsik3,"31-90","90+"))))) | T11: =IF($A11="","",IF($B11="","YETİM",IF(COUNTIF(tblKartlar[KartId],$B11)=0,"YETİM",""))) | U11: =IF(OR($A11="",$F11=""),"",IF(OR($F11&"|"&$G11="",COUNTIF(ListeIzinliGecis,$F11&"|"&$G11)>0),"","GEÇERSİZ GEÇİŞ")) | V11: =IF($A11="","",IF(OR($P11="",$J11=""),"",IF(ABS($J11-$P11)>zincirTolerans,"ZİNCİR KIRIK","OK"))) | W11: =IF($A11="","",1) | X11: =IF($A11="","",$K11*$I11)
A12: SOA-00007 | B12: SKU-00007 | C12: STK-2026-0007 | D12: 46231 | E12: 46186 | F12: SAYIM | G12: SAYIM | H12: 480 | I12: 32 | J12: 15360 | K12: 73 | L12: 59 | M12: A | N12: A | O12: Stok notu 7 | P12: =IF($A12="","",$H12*$I12) | Q12: =IF(OR($A12="",$G12="KAPALI"),"",IF($L12>soa_esikOluGun,"ÖLÜ","")) | R12: =IF($A12="","",IF($E12="","",raporTarihi-$E12)) | S12: =IF($A12="","",IF($R12="","",IF($R12<=soa_kovaEsik1,"0-7",IF($R12<=soa_kovaEsik2,"8-30",IF($R12<=soa_kovaEsik3,"31-90","90+"))))) | T12: =IF($A12="","",IF($B12="","YETİM",IF(COUNTIF(tblKartlar[KartId],$B12)=0,"YETİM",""))) | U12: =IF(OR($A12="",$F12=""),"",IF(OR($F12&"|"&$G12="",COUNTIF(ListeIzinliGecis,$F12&"|"&$G12)>0),"","GEÇERSİZ GEÇİŞ")) | V12: =IF($A12="","",IF(OR($P12="",$J12=""),"",IF(ABS($J12-$P12)>zincirTolerans,"ZİNCİR KIRIK","OK"))) | W12: =IF($A12="","",1) | X12: =IF($A12="","",$K12*$I12)
A13: SOA-00008 | B13: SKU-00008 | C13: STK-2026-0008 | D13: 46229 | E13: 46127 | F13: SAYIM | G13: ABC | H13: 520 | I13: 33 | J13: 17160 | K13: 0 | L13: 118 | M13: B | N13: B | O13: Stok notu 8 | P13: =IF($A13="","",$H13*$I13) | Q13: =IF(OR($A13="",$G13="KAPALI"),"",IF($L13>soa_esikOluGun,"ÖLÜ","")) | R13: =IF($A13="","",IF($E13="","",raporTarihi-$E13)) | S13: =IF($A13="","",IF($R13="","",IF($R13<=soa_kovaEsik1,"0-7",IF($R13<=soa_kovaEsik2,"8-30",IF($R13<=soa_kovaEsik3,"31-90","90+"))))) | T13: =IF($A13="","",IF($B13="","YETİM",IF(COUNTIF(tblKartlar[KartId],$B13)=0,"YETİM",""))) | U13: =IF(OR($A13="",$F13=""),"",IF(OR($F13&"|"&$G13="",COUNTIF(ListeIzinliGecis,$F13&"|"&$G13)>0),"","GEÇERSİZ GEÇİŞ")) | V13: =IF($A13="","",IF(OR($P13="",$J13=""),"",IF(ABS($J13-$P13)>zincirTolerans,"ZİNCİR KIRIK","OK"))) | W13: =IF($A13="","",1) | X13: =IF($A13="","",$K13*$I13)
A14: SOA-00009 | B14: SKU-00001 | C14: STK-2026-0009 | D14: 46227 | E14: 46172 | G14: SAYIM | H14: 560 | I14: 34 | J14: 19040 | K14: 71 | L14: 73 | M14: A | N14: A | O14: Stok notu 9 | P14: =IF($A14="","",$H14*$I14) | Q14: =IF(OR($A14="",$G14="KAPALI"),"",IF($L14>soa_esikOluGun,"ÖLÜ","")) | R14: =IF($A14="","",IF($E14="","",raporTarihi-$E14)) | S14: =IF($A14="","",IF($R14="","",IF($R14<=soa_kovaEsik1,"0-7",IF($R14<=soa_kovaEsik2,"8-30",IF($R14<=soa_kovaEsik3,"31-90","90+"))))) | T14: =IF($A14="","",IF($B14="","YETİM",IF(COUNTIF(tblKartlar[KartId],$B14)=0,"YETİM",""))) | U14: =IF(OR($A14="",$F14=""),"",IF(OR($F14&"|"&$G14="",COUNTIF(ListeIzinliGecis,$F14&"|"&$G14)>0),"","GEÇERSİZ GEÇİŞ")) | V14: =IF($A14="","",IF(OR($P14="",$J14=""),"",IF(ABS($J14-$P14)>zincirTolerans,"ZİNCİR KIRIK","OK"))) | W14: =IF($A14="","",1) | X14: =IF($A14="","",$K14*$I14)
A15: SOA-00010 | B15: SKU-00002 | C15: STK-2026-0010 | D15: 46245 | E15: 46165 | F15: SAYIM | G15: ABC | H15: 600 | I15: 35 | J15: 21000 | K15: 70 | L15: 80 | M15: B | N15: B | O15: Stok notu 10 | P15: =IF($A15="","",$H15*$I15) | Q15: =IF(OR($A15="",$G15="KAPALI"),"",IF($L15>soa_esikOluGun,"ÖLÜ","")) | R15: =IF($A15="","",IF($E15="","",raporTarihi-$E15)) | S15: =IF($A15="","",IF($R15="","",IF($R15<=soa_kovaEsik1,"0-7",IF($R15<=soa_kovaEsik2,"8-30",IF($R15<=soa_kovaEsik3,"31-90","90+"))))) | T15: =IF($A15="","",IF($B15="","YETİM",IF(COUNTIF(tblKartlar[KartId],$B15)=0,"YETİM",""))) | U15: =IF(OR($A15="",$F15=""),"",IF(OR($F15&"|"&$G15="",COUNTIF(ListeIzinliGecis,$F15&"|"&$G15)>0),"","GEÇERSİZ GEÇİŞ")) | V15: =IF($A15="","",IF(OR($P15="",$J15=""),"",IF(ABS($J15-$P15)>zincirTolerans,"ZİNCİR KIRIK","OK"))) | W15: =IF($A15="","",1) | X15: =IF($A15="","",$K15*$I15)
A16: SOA-00011 | B16: SKU-00003 | C16: STK-2026-0011 | D16: 46243 | E16: 46158 | F16: ABC | G16: AKSIYON | H16: 640 | I16: 36 | J16: 23040 | K16: 69 | L16: 87 | M16: C | N16: A | O16: Stok notu 11 | P16: =IF($A16="","",$H16*$I16) | Q16: =IF(OR($A16="",$G16="KAPALI"),"",IF($L16>soa_esikOluGun,"ÖLÜ","")) | R16: =IF($A16="","",IF($E16="","",raporTarihi-$E16)) | S16: =IF($A16="","",IF($R16="","",IF($R16<=soa_kovaEsik1,"0-7",IF($R16<=soa_kovaEsik2,"8-30",IF($R16<=soa_kovaEsik3,"31-90","90+"))))) | T16: =IF($A16="","",IF($B16="","YETİM",IF(COUNTIF(tblKartlar[KartId],$B16)=0,"YETİM",""))) | U16: =IF(OR($A16="",$F16=""),"",IF(OR($F16&"|"&$G16="",COUNTIF(ListeIzinliGecis,$F16&"|"&$G16)>0),"","GEÇERSİZ GEÇİŞ")) | V16: =IF($A16="","",IF(OR($P16="",$J16=""),"",IF(ABS($J16-$P16)>zincirTolerans,"ZİNCİR KIRIK","OK"))) | W16: =IF($A16="","",1) | X16: =IF($A16="","",$K16*$I16)
A17: SOA-00012 | B17: SKU-00004 | C17: STK-2026-0012 | D17: 46241 | E17: 46151 | F17: AKSIYON | G17: KAPALI | H17: 680 | I17: 37 | J17: 26010 | K17: 0 | L17: 94 | M17: A | N17: B | O17: Stok notu 12 | P17: =IF($A17="","",$H17*$I17) | Q17: =IF(OR($A17="",$G17="KAPALI"),"",IF($L17>soa_esikOluGun,"ÖLÜ","")) | R17: =IF($A17="","",IF($E17="","",raporTarihi-$E17)) | S17: =IF($A17="","",IF($R17="","",IF($R17<=soa_kovaEsik1,"0-7",IF($R17<=soa_kovaEsik2,"8-30",IF($R17<=soa_kovaEsik3,"31-90","90+"))))) | T17: =IF($A17="","",IF($B17="","YETİM",IF(COUNTIF(tblKartlar[KartId],$B17)=0,"YETİM",""))) | U17: =IF(OR($A17="",$F17=""),"",IF(OR($F17&"|"&$G17="",COUNTIF(ListeIzinliGecis,$F17&"|"&$G17)>0),"","GEÇERSİZ GEÇİŞ")) | V17: =IF($A17="","",IF(OR($P17="",$J17=""),"",IF(ABS($J17-$P17)>zincirTolerans,"ZİNCİR KIRIK","OK"))) | W17: =IF($A17="","",1) | X17: =IF($A17="","",$K17*$I17)
A18: SOA-00013 | B18: SKU-00005 | C18: STK-2026-0013 | D18: 46239 | E18: 46144 | F18: SAYIM | G18: ABC | H18: 720 | I18: 38 | J18: 27360 | K18: 0 | L18: 101 | M18: B | N18: A | O18: Stok notu 13 | P18: =IF($A18="","",$H18*$I18) | Q18: =IF(OR($A18="",$G18="KAPALI"),"",IF($L18>soa_esikOluGun,"ÖLÜ","")) | R18: =IF($A18="","",IF($E18="","",raporTarihi-$E18)) | S18: =IF($A18="","",IF($R18="","",IF($R18<=soa_kovaEsik1,"0-7",IF($R18<=soa_kovaEsik2,"8-30",IF($R18<=soa_kovaEsik3,"31-90","90+"))))) | T18: =IF($A18="","",IF($B18="","YETİM",IF(COUNTIF(tblKartlar[KartId],$B18)=0,"YETİM",""))) | U18: =IF(OR($A18="",$F18=""),"",IF(OR($F18&"|"&$G18="",COUNTIF(ListeIzinliGecis,$F18&"|"&$G18)>0),"","GEÇERSİZ GEÇİŞ")) | V18: =IF($A18="","",IF(OR($P18="",$J18=""),"",IF(ABS($J18-$P18)>zincirTolerans,"ZİNCİR KIRIK","OK"))) | W18: =IF($A18="","",1) | X18: =IF($A18="","",$K18*$I18)
A19: SOA-00014 | B19: SKU-00006 | C19: STK-2026-0014 | D19: 46237 | E19: 46137 | F19: ABC | G19: AKSIYON | H19: 760 | I19: 39 | J19: 29640 | K19: 0 | L19: 108 | M19: C | N19: B | O19: Stok notu 14 | P19: =IF($A19="","",$H19*$I19) | Q19: =IF(OR($A19="",$G19="KAPALI"),"",IF($L19>soa_esikOluGun,"ÖLÜ","")) | R19: =IF($A19="","",IF($E19="","",raporTarihi-$E19)) | S19: =IF($A19="","",IF($R19="","",IF($R19<=soa_kovaEsik1,"0-7",IF($R19<=soa_kovaEsik2,"8-30",IF($R19<=soa_kovaEsik3,"31-90","90+"))))) | T19: =IF($A19="","",IF($B19="","YETİM",IF(COUNTIF(tblKartlar[KartId],$B19)=0,"YETİM",""))) | U19: =IF(OR($A19="",$F19=""),"",IF(OR($F19&"|"&$G19="",COUNTIF(ListeIzinliGecis,$F19&"|"&$G19)>0),"","GEÇERSİZ GEÇİŞ")) | V19: =IF($A19="","",IF(OR($P19="",$J19=""),"",IF(ABS($J19-$P19)>zincirTolerans,"ZİNCİR KIRIK","OK"))) | W19: =IF($A19="","",1) | X19: =IF($A19="","",$K19*$I19)
A20: SOA-00015 | B20: SKU-00007 | C20: STK-2026-0015 | D20: 46235 | E20: 46120 | F20: SAYIM | G20: SAYIM | H20: 800 | I20: 40 | J20: 32000 | K20: 0 | L20: 125 | M20: A | N20: A | O20: Stok notu 15 | P20: =IF($A20="","",$H20*$I20) | Q20: =IF(OR($A20="",$G20="KAPALI"),"",IF($L20>soa_esikOluGun,"ÖLÜ","")) | R20: =IF($A20="","",IF($E20="","",raporTarihi-$E20)) | S20: =IF($A20="","",IF($R20="","",IF($R20<=soa_kovaEsik1,"0-7",IF($R20<=soa_kovaEsik2,"8-30",IF($R20<=soa_kovaEsik3,"31-90","90+"))))) | T20: =IF($A20="","",IF($B20="","YETİM",IF(COUNTIF(tblKartlar[KartId],$B20)=0,"YETİM",""))) | U20: =IF(OR($A20="",$F20=""),"",IF(OR($F20&"|"&$G20="",COUNTIF(ListeIzinliGecis,$F20&"|"&$G20)>0),"","GEÇERSİZ GEÇİŞ")) | V20: =IF($A20="","",IF(OR($P20="",$J20=""),"",IF(ABS($J20-$P20)>zincirTolerans,"ZİNCİR KIRIK","OK"))) | W20: =IF($A20="","",1) | X20: =IF($A20="","",$K20*$I20)
A21: SOA-00016 | B21: SKU-00008 | C21: STK-2026-0016 | D21: 46233 | E21: 46123 | F21: SAYIM | G21: ABC | H21: 840 | I21: 41 | J21: 34440 | K21: 0 | L21: 122 | M21: B | N21: B | O21: Stok notu 16 | P21: =IF($A21="","",$H21*$I21) | Q21: =IF(OR($A21="",$G21="KAPALI"),"",IF($L21>soa_esikOluGun,"ÖLÜ","")) | R21: =IF($A21="","",IF($E21="","",raporTarihi-$E21)) | S21: =IF($A21="","",IF($R21="","",IF($R21<=soa_kovaEsik1,"0-7",IF($R21<=soa_kovaEsik2,"8-30",IF($R21<=soa_kovaEsik3,"31-90","90+"))))) | T21: =IF($A21="","",IF($B21="","YETİM",IF(COUNTIF(tblKartlar[KartId],$B21)=0,"YETİM",""))) | U21: =IF(OR($A21="",$F21=""),"",IF(OR($F21&"|"&$G21="",COUNTIF(ListeIzinliGecis,$F21&"|"&$G21)>0),"","GEÇERSİZ GEÇİŞ")) | V21: =IF($A21="","",IF(OR($P21="",$J21=""),"",IF(ABS($J21-$P21)>zincirTolerans,"ZİNCİR KIRIK","OK"))) | W21: =IF($A21="","",1) | X21: =IF($A21="","",$K21*$I21)
A22: SOA-00017 | B22: SKU-00001 | C22: STK-2026-0017 | D22: 46231 | E22: 46116 | G22: SAYIM | H22: 880 | I22: 42 | J22: 36960 | K22: 0 | L22: 129 | M22: A | N22: A | O22: Stok notu 17 | P22: =IF($A22="","",$H22*$I22) | Q22: =IF(OR($A22="",$G22="KAPALI"),"",IF($L22>soa_esikOluGun,"ÖLÜ","")) | R22: =IF($A22="","",IF($E22="","",raporTarihi-$E22)) | S22: =IF($A22="","",IF($R22="","",IF($R22<=soa_kovaEsik1,"0-7",IF($R22<=soa_kovaEsik2,"8-30",IF($R22<=soa_kovaEsik3,"31-90","90+"))))) | T22: =IF($A22="","",IF($B22="","YETİM",IF(COUNTIF(tblKartlar[KartId],$B22)=0,"YETİM",""))) | U22: =IF(OR($A22="",$F22=""),"",IF(OR($F22&"|"&$G22="",COUNTIF(ListeIzinliGecis,$F22&"|"&$G22)>0),"","GEÇERSİZ GEÇİŞ")) | V22: =IF($A22="","",IF(OR($P22="",$J22=""),"",IF(ABS($J22-$P22)>zincirTolerans,"ZİNCİR KIRIK","OK"))) | W22: =IF($A22="","",1) | X22: =IF($A22="","",$K22*$I22)
A23: SOA-00018 | B23: SKU-00002 | C23: STK-2026-0018 | D23: 46229 | E23: 46229 | F23: SAYIM | G23: AKSIYON | H23: 920 | I23: 43 | J23: 39560 | K23: 62 | L23: 16 | M23: B | N23: B | O23: Stok notu 18 | P23: =IF($A23="","",$H23*$I23) | Q23: =IF(OR($A23="",$G23="KAPALI"),"",IF($L23>soa_esikOluGun,"ÖLÜ","")) | R23: =IF($A23="","",IF($E23="","",raporTarihi-$E23)) | S23: =IF($A23="","",IF($R23="","",IF($R23<=soa_kovaEsik1,"0-7",IF($R23<=soa_kovaEsik2,"8-30",IF($R23<=soa_kovaEsik3,"31-90","90+"))))) | T23: =IF($A23="","",IF($B23="","YETİM",IF(COUNTIF(tblKartlar[KartId],$B23)=0,"YETİM",""))) | U23: =IF(OR($A23="",$F23=""),"",IF(OR($F23&"|"&$G23="",COUNTIF(ListeIzinliGecis,$F23&"|"&$G23)>0),"","GEÇERSİZ GEÇİŞ")) | V23: =IF($A23="","",IF(OR($P23="",$J23=""),"",IF(ABS($J23-$P23)>zincirTolerans,"ZİNCİR KIRIK","OK"))) | W23: =IF($A23="","",1) | X23: =IF($A23="","",$K23*$I23)
A24: SOA-00019 | B24: SKU-00003 | C24: STK-2026-0019 | D24: 46227 | E24: 46222 | F24: ABC | G24: AKSIYON | H24: 960 | I24: 44 | J24: 43090 | K24: 61 | L24: 23 | M24: C | N24: A | O24: Stok notu 19 | P24: =IF($A24="","",$H24*$I24) | Q24: =IF(OR($A24="",$G24="KAPALI"),"",IF($L24>soa_esikOluGun,"ÖLÜ","")) | R24: =IF($A24="","",IF($E24="","",raporTarihi-$E24)) | S24: =IF($A24="","",IF($R24="","",IF($R24<=soa_kovaEsik1,"0-7",IF($R24<=soa_kovaEsik2,"8-30",IF($R24<=soa_kovaEsik3,"31-90","90+"))))) | T24: =IF($A24="","",IF($B24="","YETİM",IF(COUNTIF(tblKartlar[KartId],$B24)=0,"YETİM",""))) | U24: =IF(OR($A24="",$F24=""),"",IF(OR($F24&"|"&$G24="",COUNTIF(ListeIzinliGecis,$F24&"|"&$G24)>0),"","GEÇERSİZ GEÇİŞ")) | V24: =IF($A24="","",IF(OR($P24="",$J24=""),"",IF(ABS($J24-$P24)>zincirTolerans,"ZİNCİR KIRIK","OK"))) | W24: =IF($A24="","",1) | X24: =IF($A24="","",$K24*$I24)
A25: SOA-00020 | B25: SKU-00004 | C25: STK-2026-0020 | D25: 46245 | E25: 46215 | F25: KAPALI | G25: SAYIM | H25: 1000 | I25: 45 | J25: 45000 | K25: 60 | L25: 30 | M25: A | N25: B | O25: Stok notu 20 | P25: =IF($A25="","",$H25*$I25) | Q25: =IF(OR($A25="",$G25="KAPALI"),"",IF($L25>soa_esikOluGun,"ÖLÜ","")) | R25: =IF($A25="","",IF($E25="","",raporTarihi-$E25)) | S25: =IF($A25="","",IF($R25="","",IF($R25<=soa_kovaEsik1,"0-7",IF($R25<=soa_kovaEsik2,"8-30",IF($R25<=soa_kovaEsik3,"31-90","90+"))))) | T25: =IF($A25="","",IF($B25="","YETİM",IF(COUNTIF(tblKartlar[KartId],$B25)=0,"YETİM",""))) | U25: =IF(OR($A25="",$F25=""),"",IF(OR($F25&"|"&$G25="",COUNTIF(ListeIzinliGecis,$F25&"|"&$G25)>0),"","GEÇERSİZ GEÇİŞ")) | V25: =IF($A25="","",IF(OR($P25="",$J25=""),"",IF(ABS($J25-$P25)>zincirTolerans,"ZİNCİR KIRIK","OK"))) | W25: =IF($A25="","",1) | X25: =IF($A25="","",$K25*$I25)
A26: SOA-00021 | B26: SKU-00005 | C26: STK-2026-0021 | D26: 46243 | E26: 46208 | F26: SAYIM | G26: ABC | H26: 1040 | I26: 46 | J26: 47840 | K26: 59 | L26: 37 | M26: B | N26: A | O26: Stok notu 21 | P26: =IF($A26="","",$H26*$I26) | Q26: =IF(OR($A26="",$G26="KAPALI"),"",IF($L26>soa_esikOluGun,"ÖLÜ","")) | R26: =IF($A26="","",IF($E26="","",raporTarihi-$E26)) | S26: =IF($A26="","",IF($R26="","",IF($R26<=soa_kovaEsik1,"0-7",IF($R26<=soa_kovaEsik2,"8-30",IF($R26<=soa_kovaEsik3,"31-90","90+"))))) | T26: =IF($A26="","",IF($B26="","YETİM",IF(COUNTIF(tblKartlar[KartId],$B26)=0,"YETİM",""))) | U26: =IF(OR($A26="",$F26=""),"",IF(OR($F26&"|"&$G26="",COUNTIF(ListeIzinliGecis,$F26&"|"&$G26)>0),"","GEÇERSİZ GEÇİŞ")) | V26: =IF($A26="","",IF(OR($P26="",$J26=""),"",IF(ABS($J26-$P26)>zincirTolerans,"ZİNCİR KIRIK","OK"))) | W26: =IF($A26="","",1) | X26: =IF($A26="","",$K26*$I26)
A27: SOA-00022 | C27: STK-2026-0022 | D27: 46241 | E27: 46201 | F27: ABC | G27: AKSIYON | H27: 1080 | I27: 47 | J27: 50760 | K27: 58 | L27: 44 | M27: C | N27: B | O27: Stok notu 22 | P27: =IF($A27="","",$H27*$I27) | Q27: =IF(OR($A27="",$G27="KAPALI"),"",IF($L27>soa_esikOluGun,"ÖLÜ","")) | R27: =IF($A27="","",IF($E27="","",raporTarihi-$E27)) | S27: =IF($A27="","",IF($R27="","",IF($R27<=soa_kovaEsik1,"0-7",IF($R27<=soa_kovaEsik2,"8-30",IF($R27<=soa_kovaEsik3,"31-90","90+"))))) | T27: =IF($A27="","",IF($B27="","YETİM",IF(COUNTIF(tblKartlar[KartId],$B27)=0,"YETİM",""))) | U27: =IF(OR($A27="",$F27=""),"",IF(OR($F27&"|"&$G27="",COUNTIF(ListeIzinliGecis,$F27&"|"&$G27)>0),"","GEÇERSİZ GEÇİŞ")) | V27: =IF($A27="","",IF(OR($P27="",$J27=""),"",IF(ABS($J27-$P27)>zincirTolerans,"ZİNCİR KIRIK","OK"))) | W27: =IF($A27="","",1) | X27: =IF($A27="","",$K27*$I27)
A28: SOA-00023 | B28: SKU-00007 | C28: STK-2026-0023 | D28: 46239 | E28: 46194 | F28: SAYIM | G28: SAYIM | H28: 1120 | I28: 48 | J28: 53760 | K28: 57 | L28: 51 | M28: A | N28: A | O28: Stok notu 23 | P28: =IF($A28="","",$H28*$I28) | Q28: =IF(OR($A28="",$G28="KAPALI"),"",IF($L28>soa_esikOluGun,"ÖLÜ","")) | R28: =IF($A28="","",IF($E28="","",raporTarihi-$E28)) | S28: =IF($A28="","",IF($R28="","",IF($R28<=soa_kovaEsik1,"0-7",IF($R28<=soa_kovaEsik2,"8-30",IF($R28<=soa_kovaEsik3,"31-90","90+"))))) | T28: =IF($A28="","",IF($B28="","YETİM",IF(COUNTIF(tblKartlar[KartId],$B28)=0,"YETİM",""))) | U28: =IF(OR($A28="",$F28=""),"",IF(OR($F28&"|"&$G28="",COUNTIF(ListeIzinliGecis,$F28&"|"&$G28)>0),"","GEÇERSİZ GEÇİŞ")) | V28: =IF($A28="","",IF(OR($P28="",$J28=""),"",IF(ABS($J28-$P28)>zincirTolerans,"ZİNCİR KIRIK","OK"))) | W28: =IF($A28="","",1) | X28: =IF($A28="","",$K28*$I28)
A29: SOA-00024 | B29: SKU-00008 | C29: STK-2026-0024 | D29: 46237 | E29: 46111 | F29: SAYIM | G29: ABC | H29: 1160 | I29: 49 | J29: 56840 | K29: 0 | L29: 134 | M29: B | N29: B | O29: Stok notu 24 | P29: =IF($A29="","",$H29*$I29) | Q29: =IF(OR($A29="",$G29="KAPALI"),"",IF($L29>soa_esikOluGun,"ÖLÜ","")) | R29: =IF($A29="","",IF($E29="","",raporTarihi-$E29)) | S29: =IF($A29="","",IF($R29="","",IF($R29<=soa_kovaEsik1,"0-7",IF($R29<=soa_kovaEsik2,"8-30",IF($R29<=soa_kovaEsik3,"31-90","90+"))))) | T29: =IF($A29="","",IF($B29="","YETİM",IF(COUNTIF(tblKartlar[KartId],$B29)=0,"YETİM",""))) | U29: =IF(OR($A29="",$F29=""),"",IF(OR($F29&"|"&$G29="",COUNTIF(ListeIzinliGecis,$F29&"|"&$G29)>0),"","GEÇERSİZ GEÇİŞ")) | V29: =IF($A29="","",IF(OR($P29="",$J29=""),"",IF(ABS($J29-$P29)>zincirTolerans,"ZİNCİR KIRIK","OK"))) | W29: =IF($A29="","",1) | X29: =IF($A29="","",$K29*$I29)
A30: SOA-00025 | B30: SKU-99999 | C30: STK-2026-0025 | D30: 46235 | E30: 46180 | G30: SAYIM | H30: 1200 | I30: 50 | J30: 60000 | K30: 55 | L30: 65 | M30: A | N30: A | O30: Stok notu 25 | P30: =IF($A30="","",$H30*$I30) | Q30: =IF(OR($A30="",$G30="KAPALI"),"",IF($L30>soa_esikOluGun,"ÖLÜ","")) | R30: =IF($A30="","",IF($E30="","",raporTarihi-$E30)) | S30: =IF($A30="","",IF($R30="","",IF($R30<=soa_kovaEsik1,"0-7",IF($R30<=soa_kovaEsik2,"8-30",IF($R30<=soa_kovaEsik3,"31-90","90+"))))) | T30: =IF($A30="","",IF($B30="","YETİM",IF(COUNTIF(tblKartlar[KartId],$B30)=0,"YETİM",""))) | U30: =IF(OR($A30="",$F30=""),"",IF(OR($F30&"|"&$G30="",COUNTIF(ListeIzinliGecis,$F30&"|"&$G30)>0),"","GEÇERSİZ GEÇİŞ")) | V30: =IF($A30="","",IF(OR($P30="",$J30=""),"",IF(ABS($J30-$P30)>zincirTolerans,"ZİNCİR KIRIK","OK"))) | W30: =IF($A30="","",1) | X30: =IF($A30="","",$K30*$I30)
A31: SOA-00026 | B31: SKU-00002 | C31: STK-2026-0026 | D31: 46233 | E31: 46173 | F31: SAYIM | G31: ABC | H31: 1240 | I31: 51 | J31: 63240 | K31: 54 | L31: 72 | M31: B | N31: B | O31: Stok notu 26 | P31: =IF($A31="","",$H31*$I31) | Q31: =IF(OR($A31="",$G31="KAPALI"),"",IF($L31>soa_esikOluGun,"ÖLÜ","")) | R31: =IF($A31="","",IF($E31="","",raporTarihi-$E31)) | S31: =IF($A31="","",IF($R31="","",IF($R31<=soa_kovaEsik1,"0-7",IF($R31<=soa_kovaEsik2,"8-30",IF($R31<=soa_kovaEsik3,"31-90","90+"))))) | T31: =IF($A31="","",IF($B31="","YETİM",IF(COUNTIF(tblKartlar[KartId],$B31)=0,"YETİM",""))) | U31: =IF(OR($A31="",$F31=""),"",IF(OR($F31&"|"&$G31="",COUNTIF(ListeIzinliGecis,$F31&"|"&$G31)>0),"","GEÇERSİZ GEÇİŞ")) | V31: =IF($A31="","",IF(OR($P31="",$J31=""),"",IF(ABS($J31-$P31)>zincirTolerans,"ZİNCİR KIRIK","OK"))) | W31: =IF($A31="","",1) | X31: =IF($A31="","",$K31*$I31)
A32: SOA-00027 | B32: SKU-00003 | C32: STK-2026-0027 | D32: 46231 | E32: 46166 | F32: ABC | G32: AKSIYON | H32: 1280 | I32: 52 | J32: 66560 | K32: 53 | L32: 79 | M32: C | N32: A | O32: Stok notu 27 | P32: =IF($A32="","",$H32*$I32) | Q32: =IF(OR($A32="",$G32="KAPALI"),"",IF($L32>soa_esikOluGun,"ÖLÜ","")) | R32: =IF($A32="","",IF($E32="","",raporTarihi-$E32)) | S32: =IF($A32="","",IF($R32="","",IF($R32<=soa_kovaEsik1,"0-7",IF($R32<=soa_kovaEsik2,"8-30",IF($R32<=soa_kovaEsik3,"31-90","90+"))))) | T32: =IF($A32="","",IF($B32="","YETİM",IF(COUNTIF(tblKartlar[KartId],$B32)=0,"YETİM",""))) | U32: =IF(OR($A32="",$F32=""),"",IF(OR($F32&"|"&$G32="",COUNTIF(ListeIzinliGecis,$F32&"|"&$G32)>0),"","GEÇERSİZ GEÇİŞ")) | V32: =IF($A32="","",IF(OR($P32="",$J32=""),"",IF(ABS($J32-$P32)>zincirTolerans,"ZİNCİR KIRIK","OK"))) | W32: =IF($A32="","",1) | X32: =IF($A32="","",$K32*$I32)
A33: SOA-00028 | B33: SKU-00004 | C33: STK-2026-0028 | D33: 46229 | E33: 46159 | F33: AKSIYON | G33: KAPALI | H33: 1320 | I33: 53 | J33: 69960 | K33: 0 | L33: 86 | M33: A | N33: B | O33: Stok notu 28 | P33: =IF($A33="","",$H33*$I33) | Q33: =IF(OR($A33="",$G33="KAPALI"),"",IF($L33>soa_esikOluGun,"ÖLÜ","")) | R33: =IF($A33="","",IF($E33="","",raporTarihi-$E33)) | S33: =IF($A33="","",IF($R33="","",IF($R33<=soa_kovaEsik1,"0-7",IF($R33<=soa_kovaEsik2,"8-30",IF($R33<=soa_kovaEsik3,"31-90","90+"))))) | T33: =IF($A33="","",IF($B33="","YETİM",IF(COUNTIF(tblKartlar[KartId],$B33)=0,"YETİM",""))) | U33: =IF(OR($A33="",$F33=""),"",IF(OR($F33&"|"&$G33="",COUNTIF(ListeIzinliGecis,$F33&"|"&$G33)>0),"","GEÇERSİZ GEÇİŞ")) | V33: =IF($A33="","",IF(OR($P33="",$J33=""),"",IF(ABS($J33-$P33)>zincirTolerans,"ZİNCİR KIRIK","OK"))) | W33: =IF($A33="","",1) | X33: =IF($A33="","",$K33*$I33)
P34: =IF($A34="","",$H34*$I34) | Q34: =IF(OR($A34="",$G34="KAPALI"),"",IF($L34>soa_esikOluGun,"ÖLÜ","")) | R34: =IF($A34="","",IF($E34="","",raporTarihi-$E34)) | S34: =IF($A34="","",IF($R34="","",IF($R34<=soa_kovaEsik1,"0-7",IF($R34<=soa_kovaEsik2,"8-30",IF($R34<=soa_kovaEsik3,"31-90","90+"))))) | T34: =IF($A34="","",IF($B34="","YETİM",IF(COUNTIF(tblKartlar[KartId],$B34)=0,"YETİM",""))) | U34: =IF(OR($A34="",$F34=""),"",IF(OR($F34&"|"&$G34="",COUNTIF(ListeIzinliGecis,$F34&"|"&$G34)>0),"","GEÇERSİZ GEÇİŞ")) | V34: =IF($A34="","",IF(OR($P34="",$J34=""),"",IF(ABS($J34-$P34)>zincirTolerans,"ZİNCİR KIRIK","OK"))) | W34: =IF($A34="","",1) | X34: =IF($A34="","",$K34*$I34)
P35: =IF($A35="","",$H35*$I35) | Q35: =IF(OR($A35="",$G35="KAPALI"),"",IF($L35>soa_esikOluGun,"ÖLÜ","")) | R35: =IF($A35="","",IF($E35="","",raporTarihi-$E35)) | S35: =IF($A35="","",IF($R35="","",IF($R35<=soa_kovaEsik1,"0-7",IF($R35<=soa_kovaEsik2,"8-30",IF($R35<=soa_kovaEsik3,"31-90","90+"))))) | T35: =IF($A35="","",IF($B35="","YETİM",IF(COUNTIF(tblKartlar[KartId],$B35)=0,"YETİM",""))) | U35: =IF(OR($A35="",$F35=""),"",IF(OR($F35&"|"&$G35="",COUNTIF(ListeIzinliGecis,$F35&"|"&$G35)>0),"","GEÇERSİZ GEÇİŞ")) | V35: =IF($A35="","",IF(OR($P35="",$J35=""),"",IF(ABS($J35-$P35)>zincirTolerans,"ZİNCİR KIRIK","OK"))) | W35: =IF($A35="","",1) | X35: =IF($A35="","",$K35*$I35)
P36: =IF($A36="","",$H36*$I36) | Q36: =IF(OR($A36="",$G36="KAPALI"),"",IF($L36>soa_esikOluGun,"ÖLÜ","")) | R36: =IF($A36="","",IF($E36="","",raporTarihi-$E36)) | S36: =IF($A36="","",IF($R36="","",IF($R36<=soa_kovaEsik1,"0-7",IF($R36<=soa_kovaEsik2,"8-30",IF($R36<=soa_kovaEsik3,"31-90","90+"))))) | T36: =IF($A36="","",IF($B36="","YETİM",IF(COUNTIF(tblKartlar[KartId],$B36)=0,"YETİM",""))) | U36: =IF(OR($A36="",$F36=""),"",IF(OR($F36&"|"&$G36="",COUNTIF(ListeIzinliGecis,$F36&"|"&$G36)>0),"","GEÇERSİZ GEÇİŞ")) | V36: =IF($A36="","",IF(OR($P36="",$J36=""),"",IF(ABS($J36-$P36)>zincirTolerans,"ZİNCİR KIRIK","OK"))) | W36: =IF($A36="","",1) | X36: =IF($A36="","",$K36*$I36)
P37: =IF($A37="","",$H37*$I37) | Q37: =IF(OR($A37="",$G37="KAPALI"),"",IF($L37>soa_esikOluGun,"ÖLÜ","")) | R37: =IF($A37="","",IF($E37="","",raporTarihi-$E37)) | S37: =IF($A37="","",IF($R37="","",IF($R37<=soa_kovaEsik1,"0-7",IF($R37<=soa_kovaEsik2,"8-30",IF($R37<=soa_kovaEsik3,"31-90","90+"))))) | T37: =IF($A37="","",IF($B37="","YETİM",IF(COUNTIF(tblKartlar[KartId],$B37)=0,"YETİM",""))) | U37: =IF(OR($A37="",$F37=""),"",IF(OR($F37&"|"&$G37="",COUNTIF(ListeIzinliGecis,$F37&"|"&$G37)>0),"","GEÇERSİZ GEÇİŞ")) | V37: =IF($A37="","",IF(OR($P37="",$J37=""),"",IF(ABS($J37-$P37)>zincirTolerans,"ZİNCİR KIRIK","OK"))) | W37: =IF($A37="","",1) | X37: =IF($A37="","",$K37*$I37)
P38: =IF($A38="","",$H38*$I38) | Q38: =IF(OR($A38="",$G38="KAPALI"),"",IF($L38>soa_esikOluGun,"ÖLÜ","")) | R38: =IF($A38="","",IF($E38="","",raporTarihi-$E38)) | S38: =IF($A38="","",IF($R38="","",IF($R38<=soa_kovaEsik1,"0-7",IF($R38<=soa_kovaEsik2,"8-30",IF($R38<=soa_kovaEsik3,"31-90","90+"))))) | T38: =IF($A38="","",IF($B38="","YETİM",IF(COUNTIF(tblKartlar[KartId],$B38)=0,"YETİM",""))) | U38: =IF(OR($A38="",$F38=""),"",IF(OR($F38&"|"&$G38="",COUNTIF(ListeIzinliGecis,$F38&"|"&$G38)>0),"","GEÇERSİZ GEÇİŞ")) | V38: =IF($A38="","",IF(OR($P38="",$J38=""),"",IF(ABS($J38-$P38)>zincirTolerans,"ZİNCİR KIRIK","OK"))) | W38: =IF($A38="","",1) | X38: =IF($A38="","",$K38*$I38)
P39: =IF($A39="","",$H39*$I39) | Q39: =IF(OR($A39="",$G39="KAPALI"),"",IF($L39>soa_esikOluGun,"ÖLÜ","")) | R39: =IF($A39="","",IF($E39="","",raporTarihi-$E39)) | S39: =IF($A39="","",IF($R39="","",IF($R39<=soa_kovaEsik1,"0-7",IF($R39<=soa_kovaEsik2,"8-30",IF($R39<=soa_kovaEsik3,"31-90","90+"))))) | T39: =IF($A39="","",IF($B39="","YETİM",IF(COUNTIF(tblKartlar[KartId],$B39)=0,"YETİM",""))) | U39: =IF(OR($A39="",$F39=""),"",IF(OR($F39&"|"&$G39="",COUNTIF(ListeIzinliGecis,$F39&"|"&$G39)>0),"","GEÇERSİZ GEÇİŞ")) | V39: =IF($A39="","",IF(OR($P39="",$J39=""),"",IF(ABS($J39-$P39)>zincirTolerans,"ZİNCİR KIRIK","OK"))) | W39: =IF($A39="","",1) | X39: =IF($A39="","",$K39*$I39)
P40: =IF($A40="","",$H40*$I40) | Q40: =IF(OR($A40="",$G40="KAPALI"),"",IF($L40>soa_esikOluGun,"ÖLÜ","")) | R40: =IF($A40="","",IF($E40="","",raporTarihi-$E40)) | S40: =IF($A40="","",IF($R40="","",IF($R40<=soa_kovaEsik1,"0-7",IF($R40<=soa_kovaEsik2,"8-30",IF($R40<=soa_kovaEsik3,"31-90","90+"))))) | T40: =IF($A40="","",IF($B40="","YETİM",IF(COUNTIF(tblKartlar[KartId],$B40)=0,"YETİM",""))) | U40: =IF(OR($A40="",$F40=""),"",IF(OR($F40&"|"&$G40="",COUNTIF(ListeIzinliGecis,$F40&"|"&$G40)>0),"","GEÇERSİZ GEÇİŞ")) | V40: =IF($A40="","",IF(OR($P40="",$J40=""),"",IF(ABS($J40-$P40)>zincirTolerans,"ZİNCİR KIRIK","OK"))) | W40: =IF($A40="","",1) | X40: =IF($A40="","",$K40*$I40)
P41: =IF($A41="","",$H41*$I41) | Q41: =IF(OR($A41="",$G41="KAPALI"),"",IF($L41>soa_esikOluGun,"ÖLÜ","")) | R41: =IF($A41="","",IF($E41="","",raporTarihi-$E41)) | S41: =IF($A41="","",IF($R41="","",IF($R41<=soa_kovaEsik1,"0-7",IF($R41<=soa_kovaEsik2,"8-30",IF($R41<=soa_kovaEsik3,"31-90","90+"))))) | T41: =IF($A41="","",IF($B41="","YETİM",IF(COUNTIF(tblKartlar[KartId],$B41)=0,"YETİM",""))) | U41: =IF(OR($A41="",$F41=""),"",IF(OR($F41&"|"&$G41="",COUNTIF(ListeIzinliGecis,$F41&"|"&$G41)>0),"","GEÇERSİZ GEÇİŞ")) | V41: =IF($A41="","",IF(OR($P41="",$J41=""),"",IF(ABS($J41-$P41)>zincirTolerans,"ZİNCİR KIRIK","OK"))) | W41: =IF($A41="","",1) | X41: =IF($A41="","",$K41*$I41)
P42: =IF($A42="","",$H42*$I42) | Q42: =IF(OR($A42="",$G42="KAPALI"),"",IF($L42>soa_esikOluGun,"ÖLÜ","")) | R42: =IF($A42="","",IF($E42="","",raporTarihi-$E42)) | S42: =IF($A42="","",IF($R42="","",IF($R42<=soa_kovaEsik1,"0-7",IF($R42<=soa_kovaEsik2,"8-30",IF($R42<=soa_kovaEsik3,"31-90","90+"))))) | T42: =IF($A42="","",IF($B42="","YETİM",IF(COUNTIF(tblKartlar[KartId],$B42)=0,"YETİM",""))) | U42: =IF(OR($A42="",$F42=""),"",IF(OR($F42&"|"&$G42="",COUNTIF(ListeIzinliGecis,$F42&"|"&$G42)>0),"","GEÇERSİZ GEÇİŞ")) | V42: =IF($A42="","",IF(OR($P42="",$J42=""),"",IF(ABS($J42-$P42)>zincirTolerans,"ZİNCİR KIRIK","OK"))) | W42: =IF($A42="","",1) | X42: =IF($A42="","",$K42*$I42)
...

Sheet KUYRUKLAR
A1: KUYRUKLAR — Stok Optimizasyon + ABC + Ölü Stok Nakit
A3: Durum bazlı canlı kuyruk — kapalı kayıtlar düşer
A5: Kuyruk | B5: Adet | C5: Nakit
A6: Kuyruk Sayım | B6: =COUNTIFS(tblAkis[Durum],"SAYIM",tblAkis[StokAdet],">0") | C6: =SUMIFS(tblAkis[HesaplananNakit],tblAkis[Durum],"SAYIM")
A7: Kuyruk ABC | B7: =COUNTIFS(tblAkis[Durum],"ABC",tblAkis[StokAdet],">0") | C7: =SUMIFS(tblAkis[HesaplananNakit],tblAkis[Durum],"ABC")
A8: Kuyruk Aksiyon | B8: =COUNTIFS(tblAkis[Durum],"AKSIYON",tblAkis[StokAdet],">0") | C8: =SUMIFS(tblAkis[HesaplananNakit],tblAkis[Durum],"AKSIYON")
A9: Kuyruk Ölü Stok | B9: =COUNTIFS(tblAkis[OluBayrak],"ÖLÜ",tblAkis[Durum],"<>KAPALI") | C9: =SUMIFS(tblAkis[HesaplananNakit],tblAkis[OluBayrak],"ÖLÜ",tblAkis[Durum],"<>KAPALI")
A12: Kapalı — kuyruktan düşer
A13: Kapalı | B13: =COUNTIF(tblAkis[Durum],"KAPALI") | C13: =SUMIF(tblAkis[Durum],"KAPALI",tblAkis[HesaplananNakit])
A15: Kuyruk Özeti | B15: =soa_kuyrukOzeti
A17: Yaş Kova Dağılımı
A18: 0-7 | B18: =COUNTIF(tblAkis[YasKova],"0-7") | C18: =SUMIF(tblAkis[YasKova],"0-7",tblAkis[HesaplananNakit])
A19: 8-30 | B19: =COUNTIF(tblAkis[YasKova],"8-30") | C19: =SUMIF(tblAkis[YasKova],"8-30",tblAkis[HesaplananNakit])
A20: 31-90 | B20: =COUNTIF(tblAkis[YasKova],"31-90") | C20: =SUMIF(tblAkis[YasKova],"31-90",tblAkis[HesaplananNakit])
A21: 90+ | B21: =COUNTIF(tblAkis[YasKova],"90+") | C21: =SUMIF(tblAkis[YasKova],"90+",tblAkis[HesaplananNakit])

Sheet HESAP
A1: HESAP — Stok Optimizasyon + ABC + Ölü Stok Nakit
A3: Hesap motoru — ≥40 adım; sabitler AYARLAR'dan
A5: Adım | B5: Açıklama | C5: Değer
A6: H01 | B6: Toplam işlem | C6: =COUNTA(tblAkis[IslemId])
A7: H02 | B7: Dolu kayıt | C7: =SUM(tblAkis[KayitDolu])
A8: H03 | B8: Ölü stok nakit | C8: =SUMIFS(tblAkis[HesaplananNakit],tblAkis[OluBayrak],"ÖLÜ",tblAkis[Durum],"<>KAPALI")
A9: H04 | B9: Stok adet toplam | C9: =SUM(tblAkis[StokAdet])
A10: H05 | B10: Kontrol nakit toplam | C10: =SUM(tblAkis[KontrolNakit])
A11: H06 | B11: Hesaplanan nakit toplam | C11: =SUM(tblAkis[HesaplananNakit])
A12: H07 | B12: Sayım adet | C12: =COUNTIF(tblAkis[Durum],"SAYIM")
A13: H08 | B13: ABC adet | C13: =COUNTIF(tblAkis[Durum],"ABC")
A14: H09 | B14: Aksiyon adet | C14: =COUNTIF(tblAkis[Durum],"AKSIYON")
A15: H10 | B15: Ölü bayrak adet | C15: =COUNTIFS(tblAkis[OluBayrak],"ÖLÜ",tblAkis[Durum],"<>KAPALI")
A16: H11 | B16: Kapalı adet | C16: =COUNTIF(tblAkis[Durum],"KAPALI")
A17: H12 | B17: Açık kuyruk adet | C17: =C12+C13+C14
A18: H13 | B18: Kapalı düşüm adet | C18: =C16
A19: H14 | B19: Yetim adet | C19: =COUNTIF(tblAkis[YetimBayrak],"YETİM")
A20: H15 | B20: Geçersiz geçiş | C20: =COUNTIF(tblAkis[GecisUyarisi],"GEÇERSİZ GEÇİŞ")
A21: H16 | B21: Zincir kırık | C21: =COUNTIF(tblAkis[ZincirBayrak],"ZİNCİR KIRIK")
A22: H17 | B22: Zincir OK | C22: =COUNTIF(tblAkis[ZincirBayrak],"OK")
A23: H18 | B23: Yaş 0-7 | C23: =COUNTIF(tblAkis[YasKova],"0-7")
A24: H19 | B24: Yaş 8-30 | C24: =COUNTIF(tblAkis[YasKova],"8-30")
A25: H20 | B25: Yaş 31-90 | C25: =COUNTIF(tblAkis[YasKova],"31-90")
A26: H21 | B26: Yaş 90+ | C26: =COUNTIF(tblAkis[YasKova],"90+")
A27: H22 | B27: Ort stok günü | C27: =IFERROR(AVERAGEIF(tblAkis[KayitDolu],1,tblAkis[StokGunu]),0)
A28: H23 | B28: Ölü stok adet | C28: =C15
A29: H24 | B29: Ölü stok nakit (T1) | C29: =C8
A30: H25 | B30: Önerilen sipariş ort | C30: =IFERROR(AVERAGEIF(tblAkis[KayitDolu],1,tblAkis[OnerilenSiparis]),0)
A31: H26 | B31: Stok günü sapma | C31: =C27-soa_hedefStokGunu
A32: H27 | B32: Toplam stok nakit | C32: =C11
A33: H28 | B33: Temkinli senaryo | C33: =C32*soa_senaryoTemkinli
A34: H29 | B34: Baz senaryo | C34: =C32*soa_senaryoBaz
A35: H30 | B35: İyimser senaryo | C35: =C32*soa_senaryoIyimser
A36: H31 | B36: Senaryo farkı | C36: =C35-C33
A37: H32 | B37: Tornado (oran×nakit) | C37: =C32*soa_tornadoOran
A38: H33 | B38: HHI proxy | C38: =IFERROR((MAX(C12,C13,C14)/MAX(C17,1))^2,0)
A39: H34 | B39: Kalite skoru | C39: =IF(C6=0,0,MAX(0,100-C19*10-C20*10-C21*10-C28*0.1))
A40: H35 | B40: Tahmin PERCENTILE | C40: =IFERROR(_xlfn.PERCENTILE.INC(tblAkis[StokAdet],soa_yuzdelikOran),0)
