Workbook
Name toleransKurus: AYARLAR!$B$6
Name raporTarihi: AYARLAR!$B$7
Name dbe_esikEslesme: AYARLAR!$B$8
Name dbe_esikFark: AYARLAR!$B$9
Name dbe_azamiTutar: AYARLAR!$B$10
Name dbe_ikincilUzunluk: AYARLAR!$B$11
Name dbe_olcekHedef: AYARLAR!$B$12
Name dbe_anomaliZ: AYARLAR!$B$13
Name dbe_yuzdelikOran: AYARLAR!$B$14
Name dbe_kdvOran: AYARLAR!$B$15
Name dbe_duyarlilikCarpan: AYARLAR!$B$16
Name dbe_toleransSenaryo: AYARLAR!$B$17
Name dbe_yuvarlamaEsik: AYARLAR!$B$18
Name dbe_guvenBolum: AYARLAR!$B$19
Name dbe_riskFarkAgirlik: AYARLAR!$B$20
Name dbe_riskEslesmezAgirlik: AYARLAR!$B$21
Name dbe_esikHataCok: AYARLAR!$B$22
Name dbe_vknUzunluk: AYARLAR!$B$23
Name dbe_normAnahtar: AYARLAR!$B$24
Name dbe_kolonHarita: AYARLAR!$B$25
Name dbe_tanimsizKova: AYARLAR!$B$26
Name dbe_kvkkBeyani: AYARLAR!$B$27
Name dbe_kanitRaporu: AYARLAR!$B$28
Name dbe_dosyaSurumu: AYARLAR!$B$29
Name dbe_firmaUnvan: AYARLAR!$B$30
Name dbe_fiyatModeli: AYARLAR!$B$31
Name dbe_yapistirCalistir: AYARLAR!$B$32
Name dbe_hataListesi: AYARLAR!$I$28
Name dbe_mutabakatFarki: AYARLAR!$I$29
Name dbe_eslesmeOrani: AYARLAR!$I$30
Name dbe_kovaButunluk: AYARLAR!$I$31
Name dbe_kararKapi: AYARLAR!$I$32
Name dbe_modulT1: AYARLAR!$I$33
Name dbe_modulT2: AYARLAR!$I$34
Name dbe_modulO1: AYARLAR!$I$35
Name dbe_modulO2: AYARLAR!$I$36
Name dbe_modulO3: AYARLAR!$I$37
Name dbe_modulO6: AYARLAR!$I$38
Name dbe_modulO8: AYARLAR!$I$39
Name dbe_modulI1: AYARLAR!$I$40
Name dbe_modulI2: AYARLAR!$I$41
Name dbe_modulT1Yorum: AYARLAR!$I$44
Name dbe_modulT2Yorum: AYARLAR!$I$45
Name dbe_modulO1Yorum: AYARLAR!$I$46
Name dbe_modulO2Yorum: AYARLAR!$I$47
Name dbe_modulO3Yorum: AYARLAR!$I$48
Name dbe_modulO6Yorum: AYARLAR!$I$49
Name dbe_modulO8Yorum: AYARLAR!$I$50
Name dbe_modulI1Yorum: AYARLAR!$I$51
Name dbe_modulI2Yorum: AYARLAR!$I$52
Name ListeBelgeTipleri: LISTELER!$A$7:$A$11
Name ListeDurumlar: LISTELER!$C$7:$C$10

Sheet PANO
B2: DEFTER BEYAN E ARSIV AKTARIM — YÖNETİM VE KARAR SİSTEMİ | L2: Dönem: 2026 / Tam ▼ | M2: ★ DOĞRULANMIŞ
B3: Yönetici Karar Kokpiti, Otomatik Doğrulama ve Dinamik Hesaplama Sistemi · 2026
B5: TOPLAM İŞLEM HACMİ | D5: DOĞRULANMIŞ | E5: RİSKLİ / BEKLEYEN İŞLEM | G5: MİNİMUM | H5: OPERASYONEL NET MARJ | J5: GÜVENLİ | K5: SİSTEM GÜVEN SKORU | M5: DENETLENDİ
B7: ₺28.450.000 | E7: ₺940.000 | H7: ₺8.120.000 | K7: 98/100
B9: ↑ Konsolide yıllıklandırılmış büyüme | E9: ● Tüm riskli kayıtlar kontrol altında | H9: ██████████░░░░░ %28.5 NET MARJ | K9: ✓ 0 Formül ve Döngüsel Hata
B11: 12 AYLIK NAKİT GİRİŞ / ÇIKIŞ & LİKİDİTE BAŞARIMI | F11: +%32 Verim | H11: KONSOLİDE OPERASYON VE KARAR MATRİSİ
B12: Kümülatif Tahsilat vs. Tedarikçi/Kredi Ödeme Projeksiyonu | H12: Anlık Hesaplama Sonuçları, Dinamik Formül Çıktıları ve Durum Puanlaması
B14: Dönem | C14: Aktif Hacim | D14: Maliyet/Yük | E14: Hedef | H14: PARAMETRE / KALEM | I14: ANA TUTAR | J14: FARK / MARJ | K14: VADE | L14: KONTROL DURUMU
B15: D1 | C15: 65 | D15: 45 | E15: 60 | H15: 13 haftalık kümülatif bakiye... | I15: ₺8.450.000 | J15: ₺425.000 | K15: 12 Ay | L15: ✓ DÜZENLİ
B16: D2 | C16: 78 | D16: 48 | E16: 70 | H16: Kritik (eksi) hafta uyarısı | I16: ₺12.200.000 | J16: ₺580.400 | K16: 24 Ay | L16: ★ AVANTAJ
B17: D3 | C17: 85 | D17: 55 | E17: 80 | H17: Dönem net nakit değişimi | I17: ₺4.850.000 | J17: ₺235.200 | K17: 8 Ay | L17: ● YAKLAŞAN
B18: D4 | C18: 75 | D18: 42 | E18: 75 | H18: 13 haftalık kümülatif bakiye... | I18: ₺2.140.000 | J18: ₺118.000 | K18: 16 Ay | L18: ✓ TAM UYUM
B19: D5 | C19: 90 | D19: 40 | E19: 85 | H19: KONSOLİDE SİSTEM TOPLAMI | I19: ₺42.850.000 | J19: ₺3.420.000 | L19: TAM DOĞRULANDI (0 HATA)
B20: D6 | C20: 96 | D20: 32 | E20: 92
B22: KONSOLİDE PAY VE AĞIRLIK | F22: LİKİDİTE RİSKİ & ERKEN UYARI SİNYALLERİ | K22: KARAR MOTORU
B23: ■ Ana Segment (%42) | F23: Nakit Açığı Riski (30 Gün) | I23: 0.00 TL (Sıfır Risk) | K23: OPERASYONEL VERİMLİLİK FIRSATI
B24: ■ İkincil Grup (%30) | F24: Tahsilat Gecikme Toleransı | I24: 48 Gün Güvenli Eşik | K24: Süreç optimizasyonuyla birim operasyonel maliyeti düşürme potansiyeli mevcuttur.
B25: ■ Destek Birimi (%15) | F25: ██████████████████████████████████████ Güvenli Bölge (%100)
B26: ■ Rezervler (%13) | F26: ✓ 90 GÜNLÜK PROJEKSİYONDA NAKİT SIKIŞIKLIĞI TESPİT EDİLMEDİ | K26: STRATEJİ REÇETESİNİ İNCELE >

Sheet GİRDİLER
B3: 🔍 Kayıt veya hesap ara... | G3: TOPLAM: 1.450 KAYIT | I3: HATALI HÜCRE: 0 ADET
B5: TARİH | C5: REFERANS NO | D5: İŞLEM AÇIKLAMASI VE DETAY | E5: BRÜT TUTAR (₺) | F5: KDV ORANI | G5: NET TUTAR (₺) | H5: HESAP / CARİ | I5: DURUM
B6: 12.10.2026 | C6: TR-0428-A | D6: Haftalık nakit girişi tahmini | E6: 845200 | F6: 0.2 | G6: =E6/(1+F6) | H6: Vadesiz Ticari | I6: ONAYLANDI
B7: 14.10.2026 | C7: TR-0429-B | D7: Haftalık nakit çıkışı tahmini | E7: 1240000 | F7: 0.2 | G7: =E7/(1+F7) | H7: Tedarikçi Havuzu | I7: BEKLEMEDE
B8: 18.10.2026 | C8: TR-0430-C | D8: Ödeme takvimi notları | E8: 620500 | F8: 0.1 | G8: =E8/(1+F8) | H8: Kısa Vade Tahakkuk | I8: ONAYLANDI
B9: 21.10.2026 | C9: TR-0431-D | D9: Haftalık nakit girişi tahmini | E9: 415000 | F9: 0.2 | G9: =E9/(1+F9) | H9: Müşteri Alacağı | I9: ONAYLANDI
B10: 25.10.2026 | C10: TR-0432-E | D10: Haftalık nakit girişi tahmini | E10: 980400 | F10: 0.2 | G10: =E10/(1+F10) | H10: Vadesiz Ticari | I10: ONAYLANDI
B11: 28.10.2026 | C11: TR-0433-F | D11: Haftalık nakit çıkışı tahmini | E11: 1850000 | F11: 0.2 | G11: =E11/(1+F11) | H11: Banka Kredi Taksiti | I11: BLOKE
B12: 02.11.2026 | C12: TR-0434-G | D12: Ödeme takvimi notları | E12: 740000 | F12: 0.2 | G12: =E12/(1+F12) | H12: Kira & Sabit Gider | I12: ONAYLANDI
B13: 05.11.2026 | C13: TR-0435-H | D13: Haftalık nakit girişi tahmini | E13: 520800 | F13: 0.2 | G13: =E13/(1+F13) | H13: Vadesiz Ticari | I13: ONAYLANDI
B14: 09.11.2026 | C14: TR-0436-I | D14: Haftalık nakit girişi tahmini | E14: 1120000 | F14: 0.2 | G14: =E14/(1+F14) | H14: Müşteri Alacağı | I14: ONAYLANDI
B15: 12.11.2026 | C15: TR-0437-J | D15: Haftalık nakit çıkışı tahmini | E15: 890000 | F15: 0.2 | G15: =E15/(1+F15) | H15: Tedarikçi Havuzu | I15: ONAYLANDI
B17: SAYFA TOPLAMI (10 / 1.450 KAYIT) | E17: =TOPLA(E6:E15)

Sheet YÖNETİM_RAPORU
B2: DEFTER BEYAN E ARSIV AKTARIM — YÖNETİM VE KARAR SİSTEMİ — NİHAİ KARAR VE DEĞERLEME
B3: Yönetim Kurulu ve İcra Komitesi için Otomatik Türetilen Finansal Stres Testi Raporu
B4: DÖNEM: 2026 Q3 · DENETİM PROTOKOLÜ: ISO/VUK/IFRS UYUMLU · DURUM: ONAYLANDI
B6: SENARYO A: KÖTÜMSER (STRES TESTİ -%20) | H6: SENARYO B: BAZ MODEL (HEDEFLENEN)
B8: Ciro / Hacim Düşüşü: | E8: -%20.0 (Kriz Eşiği) | H8: Ciro / Hacim Gerçekleşmesi: | K8: %100.0 (Tam Bütçe)
B9: Beklenen Net Kâr / Getiri: | E9: ₺4.280.000 | H9: Beklenen Net Kâr / Getiri: | K9: ₺12.450.000
B10: Minimum Nakit Tamponu: | E10: ₺1.850.000 (Yeterli) | H10: Serbest Nakit Akımı: | K10: ₺8.240.000
B11: Likidite Karşılama Oranı: | E11: 1.28x (Eşik: 1.10x) | H11: Yatırım Geri Dönüşü (ROI): | K11: %38.4 Yıllık
B14: STRES SENARYOSUNDA DAHİ İFLAS RİSKİ YOK | H14: OPTİMUM İCRA VE PLANLAMA REÇETESİ
B17: YÖNETİM KARAR MATRİSİ VE UYGULAMA REÇETESİ
B19: ● Öncelik 1: Acil Likidite ve Borç Servis Planlaması
B20: Sistemde hesaplanan vade günlerine sadık kalınarak nakit blokajı 3 gün önceden hazır edilmelidir.
B21: ● Öncelik 2: Formül Doğrulama ve Çapraz Sağlama
B22: Tüm hücreler kilitli formül korumasında olup girdi sayfalarında sıfır döngüsel başvuru (circular ref) garantilidir.
B23: ● Öncelik 3: Resmi Mevzuat ve Vergi Kalkanı Entegrasyonu
B24: 2026 güncel vergi dilimleri, amortisman ve SGK teşvik parametreleri tam otomatik yansıtılmaktadır.
B25: ● Öncelik 4: Yönetici İmzası ve Rapor Paylaşımı
B26: Tek tuşla PDF ve A4 çıktı formatına tam uyumlu sayfa yapısı kurgulanmıştır.

Sheet KAPAK
A1: KAPAK — Defter Beyan e-Arşiv Aktarım Düzenleyici
A3: Defter Beyan e-Arşiv Aktarım Düzenleyici
A4: e-Arşiv satırlarını Defter Beyan Sistemi (DBS) kolonlarına eşler; zorunlu alan ve format hatalarını listeler; dört kovaya ayırır. XML, API ve makro yoktur — satır yapıştırırsınız.
A6: Bu ürün ne sağlar?
A7: • DBS kolon haritası AYARLAR'da tek tabloda (dbe_kolonHarita)
A8: • HATA_LISTE: zorunlu alan / format / VKN / tutar hataları
A9: • Fatura numarası normalize (UPPER TRIM boşluk sil) + tarih+tutar ikincil
A10: • Eşleşti / tolerans / tutar farkı / eşleşmedi — dört kova bütünlüğü
A11: • VERİ YOK / UYGUN / İNCELE / DURDUR karar kapısı — hata sayısına göre
A13: Kimler için?
A14: • SMMM ve Defter Beyan mükellefleri
A15: • Muhasebe ekipleri — dönem kapanışı öncesi aktarım
... A21: Sürüm 1.0.0 | Lisans: Tek kullanıcı | ExcelArşiv

Sheet VERI_A
A1: VERI A — Defter Beyan e-Arşiv Aktarım Düzenleyici
A3: e-Arşiv satır yapıştır — sarı hücrelere girin (XML/API yok)
A5: FaturaNo | B5: Tarih | C5: VKN | D5: Unvan | E5: Matrah | F5: KDV | G5: Toplam | H5: BelgeTipi | I5: Donem | J5: Aciklama | K5: KayitDolu
A6: EAR2026100001 | B6: 46209 | C6: 1000000001 | D6: Ornek Firma 1 Ltd. | E6: 1047.5 | F6: 209.5 | G6: 1257 | H6: IADE | I6: 2026-08 | J6: e-Arşiv satırı | K6: =IF($A6="","",1)
A7: EAR2026100002 | B7: 46210 | C7: 1000000002 | D7: Ornek Firma 2 Ltd. | E7: 1095 | F7: 219 | G7: 1314 | H7: ISTISNA | I7: 2026-08 | J7: e-Arşiv satırı | K7: =IF($A7="","",1)
A8: EAR202 6100003 | B8: 46211 | C8: 1000000003 | D8: Ornek Firma 3 Ltd. | E8: 1142.5 | F8: 228.5 | G8: 1371 | H8: TEVKIFAT | I8: 2026-08 | J8: e-Arşiv satırı | K8: =IF($A8="","",1)
A9: EAR2026100004 | B9: 46212 | C9: 1000000004 | D9: Ornek Firma 4 Ltd. | E9: 1190 | F9: 238 | G9: 1428 | H9: DIGER | I9: 2026-08 | J9: e-Arşiv satırı | K9: =IF($A9="","",1)
A10: EAR202610000 | B10: 46213 | C10: 1000000005 | D10: Ornek Firma 5 Ltd. | E10: 1237.5 | F10: 247.5 | G10: 1485 | H10: SATIS | I10: 2026-08 | J10: e-Arşiv satırı | K10: =IF($A10="","",1)
A11: EAR2026100006 | B11: 46214 | C11: 1000000006 | D11: Ornek Firma 6 Ltd. | E11: 1285 | F11: 257 | G11: 1542 | H11: IADE | I11: 2026-08 | J11: e-Arşiv satırı | K11: =IF($A11="","",1)
A12: EAR202 6100007 | B12: 46215 | C12: 1000000007 | D12: Ornek Firma 7 Ltd. | E12: 1332.5 | F12: 266.5 | G12: 1599 | H12: ISTISNA | I12: 2026-08 | J12: e-Arşiv satırı | K12: =IF($A12="","",1)
A13: EAR2026100008 | B13: 46216 | C13: 1000000008 | D13: Ornek Firma 8 Ltd. | E13: 1380 | F13: 276 | G13: 1656 | H13: TEVKIFAT | I13: 2026-08 | J13: e-Arşiv satırı | K13: =IF($A13="","",1)
A14: EAR202610000 | B14: 46217 | C14: 1000000009 | D14: Ornek Firma 9 Ltd. | E14: 1427.5 | F14: 285.5 | G14: 1713 | H14: DIGER | I14: 2026-08 | J14: e-Arşiv satırı | K14: =IF($A14="","",1)
A15: EAR2026100010 | B15: 46218 | C15: 1000000010 | D15: Ornek Firma 10 Ltd. | E15: 1475 | F15: 295 | G15: 1770 | H15: SATIS | I15: 2026-08 | J15: e-Arşiv satırı | K15: =IF($A15="","",1)
A16: EAR202 6100011 | B16: 46219 | C16: 1000000011 | D16: Ornek Firma 11 Ltd. | E16: 1522.5 | F16: 304.5 | G16: 1827 | H16: IADE | I16: 2026-08 | J16: e-Arşiv satırı | K16: =IF($A16="","",1)
A17: EAR2026100012 | B17: 46220 | C17: 1000000012 | D17: Ornek Firma 12 Ltd. | E17: 1570 | F17: 314 | G17: 1884 | H17: ISTISNA | I17: 2026-08 | J17: e-Arşiv satırı | K17: =IF($A17="","",1)
... A29: EAR2026100024 | B29: 46232 | C29: 1000000024 | D29: Ornek Firma 24 Ltd. | E29: 2140 | F29: 428 | G29: 2568 | H29: DIGER | I29: 2026-08 | J29: e-Arşiv satırı | K29: =IF($A29="","",1)
A30: EAR2026100025 | C30: 1000000025 | D30: Ornek Firma 25 Ltd. | E30: 2187.5 | F30: 437.5 | G30: 2625 | H30: SATIS | I30: 2026-08 | J30: e-Arşiv satırı | K30: =IF($A30="","",1)
A31: EAR2026100026 | B31: 46234 | C31: 1000000026 | D31: Ornek Firma 26 Ltd. | E31: 2235 | F31: 447 | G31: 2682 | H31: IADE | I31: 2026-08 | J31: e-Arşiv satırı | K31: =IF($A31="","",1)
A32: EAR2026100027 | B32: 46235 | C32: 1000000027 | D32: Ornek Firma 27 Ltd. | E32: 2282.5 | F32: 456.5 | G32: 2739 | H32: ISTISNA | I32: 2026-08 | J32: e-Arşiv satırı | K32: =IF($A32="","",1)
A33: EAR2026100028 | B33: 46236 | C33: 1000000028 | D33: Ornek Firma 28 Ltd. | E33: 2330 | F33: 466 | G33: 2796 | H33: TEVKIFAT | I33: 2026-08 | J33: e-Arşiv satırı | K33: =IF($A33="","",1)
A34: EAR2026100029 | B34: 46237 | C34: 1000000029 | D34: Ornek Firma 29 Ltd. | E34: 2377.5 | F34: 475.5 | G34: -2853 | H34: DIGER | I34: 2026-08 | J34: e-Arşiv satırı | K34: =IF($A34="","",1)
A35: EAR2026100030 | B35: 46238 | C35: 1000000030 | D35: Ornek Firma 30 Ltd. | E35: 2425 | F35: 485 | G35: 2910 | H35: SATIS | I35: 2026-08 | J35: e-Arşiv satırı | K35: =IF($A35="","",1)
A36: EAR2026100031 | B36: 46239 | C36: 1000000031 | D36: Ornek Firma 31 Ltd. | E36: 2472.5 | F36: 494.5 | G36: 2967 | H36: IADE | I36: 2026-08 | J36: e-Arşiv satırı | K36: =IF($A36="","",1)
A37: EAR2026100032 | B37: 46240 | C37: 1000000032 | D37: Ornek Firma 32 Ltd. | E37: 2520 | F37: 504 | G37: 3024 | H37: ISTISNA | I37: 2026-08 | J37: e-Arşiv satırı | K37: =IF($A37="","",1)
A38: EAR2026100033 | B38: 46241 | C38: 1000000033 | D38: Ornek Firma 33 Ltd. | E38: 2567.5 | F38: 513.5 | G38: 3081 | H38: TEVKIFAT | I38: 2026-08 | J38: e-Arşiv satırı | K38: =IF($A38="","",1)
A39: EAR2026100034 | B39: 46242 | C39: 1000000034 | D39: Ornek Firma 34 Ltd. | E39: 2615 | F39: 523 | G39: 3138 | H39: DIGER | I39: 2026-08 | J39: e-Arşiv satırı | K39: =IF($A39="","",1)
A40: EAR2026100035 | B40: 46243 | C40: 1000000035 | D40: Ornek Firma 35 Ltd. | E40: 2662.5 | F40: 532.5 | G40: 3195 | H40: SATIS | I40: 2026-08 | J40: e-Arşiv satırı | K40: =IF($A40="","",1)
A41: EAR2026100036 | B41: 46244 | C41: 1000000036 | D41: Ornek Firma 36 Ltd. | E41: 2710 | F41: 542 | G41: 3252 | H41: IADE | I41: 2026-08 | J41: e-Arşiv satırı | K41: =IF($A41="","",1)
A42: EAR2026100037 | B42: 46245 | C42: 1000000037 | D42: Ornek Firma 37 Ltd. | E42: 2757.5 | F42: 551.5 | G42: 3309 | H42: ISTISNA | I42: 2026-08 | J42: e-Arşiv satırı | K42: =IF($A42="","",1)
... A45: EAR2026100040 | B45: 46248 | C45: 1000000040 | D45: Ornek Firma 40 Ltd. | E45: 2900 | F45: 580 | G45: 3480 | H45: SATIS | I45: 2026-08 | J45: e-Arşiv satırı | K45: =IF($A45="","",1)
K46: =IF($A46="","",1)
K47: =IF($A47="","",1)
K48: =IF($A48="","",1)
K49: =IF($A49="","",1)
K50: =IF($A50="","",1)
K51: =IF($A51="","",1)
K52: =IF($A52="","",1)
K53: =IF($A53="","",1)
K54: =IF($A54="","",1)
K55: =IF($A55="","",1)
...

Sheet VERI_B
A1: VERI B — Defter Beyan e-Arşiv Aktarım Düzenleyici
A3: DBS hedef satırları — Defter Beyan kolon düzeni
A5: BelgeNo | B5: BelgeTarihi | C5: Tutar | D5: HesapKodu | E5: Aciklama | F5: Donem | G5: VKN | H5: Durum | I5: KayitDolu
A6: EAR2026100001 | B6: 46209 | C6: 1257 | D6: 600.000 | E6: DBS aktarım | F6: 2026-08 | G6: 1000000001 | H6: Acik | I6: =IF($A6="","",1)
A7: EAR2026100002 | B7: 46210 | C7: 1314 | D7: 600.001 | E7: DBS aktarım | F7: 2026-08 | G7: 1000000002 | H7: Acik | I7: =IF($A7="","",1)
A8: EAR2026100003 | B8: 46211 | C8: 1371 | D8: 600.002 | E8: DBS aktarım | F8: 2026-08 | G8: 1000000003 | H8: Acik | I8: =IF($A8="","",1)
A9: EAR2026100004 | B9: 46212 | C9: 1428 | D9: 600.003 | E9: DBS aktarım | F9: 2026-08 | G9: 1000000004 | H9: Acik | I9: =IF($A9="","",1)
A10: EAR2026100005 | B10: 46213 | C10: 1485 | D10: 600.004 | E10: DBS aktarım | F10: 2026-08 | G10: 1000000005 | H10: Acik | I10: =IF($A10="","",1)
A11: EAR2026100006 | B11: 46214 | C11: 1542 | D11: 600.005 | E11: DBS aktarım | F11: 2026-08 | G11: 1000000006 | H11: Acik | I11: =IF($A11="","",1)
A12: EAR2026100007 | B12: 46215 | C12: 1599 | D12: 600.006 | E12: DBS aktarım | F12: 2026-08 | G12: 1000000007 | H12: Acik | I12: =IF($A12="","",1)
A13: EAR2026100008 | B13: 46216 | C13: 1643.5 | D13: 600.007 | E13: DBS aktarım | F13: 2026-08 | G13: 1000000008 | H13: Acik | I13: =IF($A13="","",1)
A14: EAR2026100009 | B14: 46217 | C14: 1713 | D14: 600.008 | E14: DBS aktarım | F14: 2026-08 | G14: 1000000009 | H14: Acik | I14: =IF($A14="","",1)
A15: EAR2026100010 | B15: 46218 | C15: 1770 | D15: 600.009 | E15: DBS aktarım | F15: 2026-08 | G15: 1000000010 | H15: Acik | I15: =IF($A15="","",1)
A16: EAR2026100011 | B16: 46219 | C16: 1827.03 | D16: 600.010 | E16: DBS aktarım | F16: 2026-08 | G16: 1000000011 | H16: Acik | I16: =IF($A16="","",1)
A17: EAR2026100012 | B17: 46220 | C17: 1884 | D17: 600.011 | E17: DBS aktarım | F17: 2026-08 | G17: 1000000012 | H17: Acik | I17: =IF($A17="","",1)
... A45: EAR2026100040 | B45: 46248 | C45: 3467.5 | D45: 600.039 | E45: DBS aktarım | F45: 2026-08 | G45: 1000000040 | H45: Acik | I45: =IF($A45="","",1)
I46: =IF($A46="","",1)
I47: =IF($A47="","",1)
I48: =IF($A48="","",1)
I49: =IF($A49="","",1)
I50: =IF($A50="","",1)
I51: =IF($A51="","",1)
I52: =IF($A52="","",1)
I53: =IF($A53="","",1)
I54: =IF($A54="","",1)
I55: =IF($A55="","",1)
I56: =IF($A56="","",1)
I57: =IF($A57="","",1)
... I1005: =IF($A1005="","",1)

Sheet ANAHTAR
A1: ANAHTAR — Defter Beyan e-Arşiv Aktarım Düzenleyici
A3: Fatura numarası normalize + uzunluk + tarih+tutar ikincil + duplike (Ç7 / E01)
A4: A Tarafı (e-Arşiv) | I4: B Tarafı (DBS)
A5: Ham | B5: Norm | C5: NormUzunluk | D5: IkincilAnahtar | E5: KaynakTaraf | F5: Duplike | G5: SatirNo | I5: HamB | J5: NormB | K5: NormUzunlukB | L5: IkincilB | M5: KaynakB | N5: DuplikeB | O5: SatirNoB
A6: =IF(VERI_A!A6="","",VERI_A!A6) | B6: =UPPER(TRIM(SUBSTITUTE($A6," ",""))) | C6: =IF($B6="",0,LEN($B6)) | D6: =IF($A6="","",TEXT(IFERROR(INDEX(tblVeriA[Tarih],ROW()-ROW(tblVeriA[[#Headers]])),""),"yyyymmdd")&"|"&TEXT(IFERROR(INDEX(tblVeriA[Toplam],ROW()-ROW(tblVeriA[[#Headers]])),0),"0.00")) | E6: ="A" | F6: =IF($B6="","",IF(COUNTIF(tblAnahtarA[Norm],$B6)>1,"EVET","HAYIR")) | G6: =IF($A6="","",ROW()-ROW($A$5)) | I6: =IF(VERI_B!A6="","",VERI_B!A6) | J6: =UPPER(TRIM(SUBSTITUTE($I6," ",""))) | K6: =IF($J6="",0,LEN($J6)) | L6: =IF($I6="","",TEXT(IFERROR(INDEX(tblVeriB[BelgeTarihi],ROW()-ROW(tblVeriB[[#Headers]])),""),"yyyymmdd")&"|"&TEXT(IFERROR(INDEX(tblVeriB[Tutar],ROW()-ROW(tblVeriB[[#Headers]])),0),"0.00")) | M6: ="B" | N6: =IF($J6="","",IF(COUNTIF(tblAnahtarB[NormB],$J6)>1,"EVET","HAYIR")) | O6: =IF($I6="","",ROW()-ROW($I$5))
A7: =IF(VERI_A!A7="","",VERI_A!A7) | B7: =UPPER(TRIM(SUBSTITUTE($A7," ",""))) | C7: =IF($B7="",0,LEN($B7)) | D7: =IF($A7="","",TEXT(IFERROR(INDEX(tblVeriA[Tarih],ROW()-ROW(tblVeriA[[#Headers]])),""),"yyyymmdd")&"|"&TEXT(IFERROR(INDEX(tblVeriA[Toplam],ROW()-ROW(tblVeriA[[#Headers]])),0),"0.00")) | E7: ="A" | F7: =IF($B7="","",IF(COUNTIF(tblAnahtarA[Norm],$B7)>1,"EVET","HAYIR")) | G7: =IF($A7="","",ROW()-ROW($A$5)) | I7: =IF(VERI_B!A7="","",VERI_B!A7) | J7: =UPPER(TRIM(SUBSTITUTE($I7," ",""))) | K7: =IF($J7="",0,LEN($J7)) | L7: =IF($I7="","",TEXT(IFERROR(INDEX(tblVeriB[BelgeTarihi],ROW()-ROW(tblVeriB[[#Headers]])),""),"yyyymmdd")&"|"&TEXT(IFERROR(INDEX(tblVeriB[Tutar],ROW()-ROW(tblVeriB[[#Headers]])),0),"0.00")) | M7: ="B" | N7: =IF($J7="","",IF(COUNTIF(tblAnahtarB[NormB],$J7)>1,"EVET","HAYIR")) | O7: =IF($I7="","",ROW()-ROW($I$5))
A8: =IF(VERI_A!A8="","",VERI_A!A8) | B8: =UPPER(TRIM(SUBSTITUTE($A8," ",""))) | C8: =IF($B8="",0,LEN($B8)) | D8: =IF($A8="","",TEXT(IFERROR(INDEX(tblVeriA[Tarih],ROW()-ROW(tblVeriA[[#Headers]])),""),"yyyymmdd")&"|"&TEXT(IFERROR(INDEX(tblVeriA[Toplam],ROW()-ROW(tblVeriA[[#Headers]])),0),"0.00")) | E8: ="A" | F8: =IF($B8="","",IF(COUNTIF(tblAnahtarA[Norm],$B8)>1,"EVET","HAYIR")) | G8: =IF($A8="","",ROW()-ROW($A$5)) | I8: =IF(VERI_B!A8="","",VERI_B!A8) | J8: =UPPER(TRIM(SUBSTITUTE($I8," ",""))) | K8: =IF($J8="",0,LEN($J8)) | L8: =IF($I8="","",TEXT(IFERROR(INDEX(tblVeriB[BelgeTarihi],ROW()-ROW(tblVeriB[[#Headers]])),""),"yyyymmdd")&"|"&TEXT(IFERROR(INDEX(tblVeriB[Tutar],ROW()-ROW(tblVeriB[[#Headers]])),0),"0.00")) | M8: ="B" | N8: =IF($J8="","",IF(COUNTIF(tblAnahtarB[NormB],$J8)>1,"EVET","HAYIR")) | O8: =IF($I8="","",ROW()-ROW($I$5))
A9: =IF(VERI_A!A9="","",VERI_A!A9) | B9: =UPPER(TRIM(SUBSTITUTE($A9," ",""))) | C9: =IF($B9="",0,LEN($B9)) | D9: =IF($A9="","",TEXT(IFERROR(INDEX(tblVeriA[Tarih],ROW()-ROW(tblVeriA[[#Headers]])),""),"yyyymmdd")&"|"&TEXT(IFERROR(INDEX(tblVeriA[Toplam],ROW()-ROW(tblVeriA[[#Headers]])),0),"0.00")) | E9: ="A" | F9: =IF($B9="","",IF(COUNTIF(tblAnahtarA[Norm],$B9)>1,"EVET","HAYIR")) | G9: =IF($A9="","",ROW()-ROW($A$5)) | I9: =IF(VERI_B!A9="","",VERI_B!A9) | J9: =UPPER(TRIM(SUBSTITUTE($I9," ",""))) | K9: =IF($J9="",0,LEN($J9)) | L9: =IF($I9="","",TEXT(IFERROR(INDEX(tblVeriB[BelgeTarihi],ROW()-ROW(tblVeriB[[#Headers]])),""),"yyyymmdd")&"|"&TEXT(IFERROR(INDEX(tblVeriB[Tutar],ROW()-ROW(tblVeriB[[#Headers]])),0),"0.00")) | M9: ="B" | N9: =IF($J9="","",IF(COUNTIF(tblAnahtarB[NormB],$J9)>1,"EVET","HAYIR")) | O9: =IF($I9="","",ROW()-ROW($I$5))
A10: =IF(VERI_A!A10="","",VERI_A!A10) | B10: =UPPER(TRIM(SUBSTITUTE($A10," ",""))) | C10: =IF($B10="",0,LEN($B10)) | D10: =IF($A10="","",TEXT(IFERROR(INDEX(tblVeriA[Tarih],ROW()-ROW(tblVeriA[[#Headers]])),""),"yyyymmdd")&"|"&TEXT(IFERROR(INDEX(tblVeriA[Toplam],ROW()-ROW(tblVeriA[[#Headers]])),0),"0.00")) | E10: ="A" | F10: =IF($B10="","",IF(COUNTIF(tblAnahtarA[Norm],$B10)>1,"EVET","HAYIR")) | G10: =IF($A10="","",ROW()-ROW($A$5)) | I10: =IF(VERI_B!A10="","",VERI_B!A10) | J10: =UPPER(TRIM(SUBSTITUTE($I10," ",""))) | K10: =IF($J10="",0,LEN($J10)) | L10: =IF($I10="","",TEXT(IFERROR(INDEX(tblVeriB[BelgeTarihi],ROW()-ROW(tblVeriB[[#Headers]])),""),"yyyymmdd")&"|"&TEXT(IFERROR(INDEX(tblVeriB[Tutar],ROW()-ROW(tblVeriB[[#Headers]])),0),"0.00")) | M10: ="B" | N10: =IF($J10="","",IF(COUNTIF(tblAnahtarB[NormB],$J10)>1,"EVET","HAYIR")) | O10: =IF($I10="","",ROW()-ROW($I$5))
A11: =IF(VERI_A!A11="","",VERI_A!A11) | B11: =UPPER(TRIM(SUBSTITUTE($A11," ",""))) | C11: =IF($B11="",0,LEN($B11)) | D11: =IF($A11="","",TEXT(IFERROR(INDEX(tblVeriA[Tarih],ROW()-ROW(tblVeriA[[#Headers]])),""),"yyyymmdd")&"|"&TEXT(IFERROR(INDEX(tblVeriA[Toplam],ROW()-ROW(tblVeriA[[#Headers]])),0),"0.00")) | E11: ="A" | F11: =IF($B11="","",IF(COUNTIF(tblAnahtarA[Norm],$B11)>1,"EVET","HAYIR")) | G11: =IF($A11="","",ROW()-ROW($A$5)) | I11: =IF(VERI_B!A11="","",VERI_B!A11) | J11: =UPPER(TRIM(SUBSTITUTE($I11," ",""))) | K11: =IF($J11="",0,LEN($J11)) | L11: =IF($I11="","",TEXT(IFERROR(INDEX(tblVeriB[BelgeTarihi],ROW()-ROW(tblVeriB[[#Headers]])),""),"yyyymmdd")&"|"&TEXT(IFERROR(INDEX(tblVeriB[Tutar],ROW()-ROW(tblVeriB[[#Headers]])),0),"0.00")) | M11: ="B" | N11: =IF($J11="","",IF(COUNTIF(tblAnahtarB[NormB],$J11)>1,"EVET","HAYIR")) | O11: =IF($I11="","",ROW()-ROW($I$5))
A12: =IF(VERI_A!A12="","",VERI_A!A12) | B12: =UPPER(TRIM(SUBSTITUTE($A12," ",""))) | C12: =IF($B12="",0,LEN($B12)) | D12: =IF($A12="","",TEXT(IFERROR(INDEX(tblVeriA[Tarih],ROW()-ROW(tblVeriA[[#Headers]])),""),"yyyymmdd")&"|"&TEXT(IFERROR(INDEX(tblVeriA[Toplam],ROW()-ROW(tblVeriA[[#Headers]])),0),"0.00")) | E12: ="A" | F12: =IF($B12="","",IF(COUNTIF(tblAnahtarA[Norm],$B12)>1,"EVET","HAYIR")) | G12: =IF($A12="","",ROW()-ROW($A$5)) | I12: =IF(VERI_B!A12="","",VERI_B!A12) | J12: =UPPER(TRIM(SUBSTITUTE($I12," ",""))) | K12: =IF($J12="",0,LEN($J12)) | L12: =IF($I12="","",TEXT(IFERROR(INDEX(tblVeriB[BelgeTarihi],ROW()-ROW(tblVeriB[[#Headers]])),""),"yyyymmdd")&"|"&TEXT(IFERROR(INDEX(tblVeriB[Tutar],ROW()-ROW(tblVeriB[[#Headers]])),0),"0.00")) | M12: ="B" | N12: =IF($J12="","",IF(COUNTIF(tblAnahtarB[NormB],$J12)>1,"EVET","HAYIR")) | O12: =IF($I12="","",ROW()-ROW($I$5))
A13: =IF(VERI_A!A13="","",VERI_A!A13) | B13: =UPPER(TRIM(SUBSTITUTE($A13," ",""))) | C13: =IF($B13="",0,LEN($B13)) | D13: =IF($A13="","",TEXT(IFERROR(INDEX(tblVeriA[Tarih],ROW()-ROW(tblVeriA[[#Headers]])),""),"yyyymmdd")&"|"&TEXT(IFERROR(INDEX(tblVeriA[Toplam],ROW()-ROW(tblVeriA[[#Headers]])),0),"0.00")) | E13: ="A" | F13: =IF($B13="","",IF(COUNTIF(tblAnahtarA[Norm],$B13)>1,"EVET","HAYIR")) | G13: =IF($A13="","",ROW()-ROW($A$5)) | I13: =IF(VERI_B!A13="","",VERI_B!A13) | J13: =UPPER(TRIM(SUBSTITUTE($I13," ",""))) | K13: =IF($J13="",0,LEN($J13)) | L13: =IF($I13="","",TEXT(IFERROR(INDEX(tblVeriB[BelgeTarihi],ROW()-ROW(tblVeriB[[#Headers]])),""),"yyyymmdd")&"|"&TEXT(IFERROR(INDEX(tblVeriB[Tutar],ROW()-ROW(tblVeriB[[#Headers]])),0),"0.00")) | M13: ="B" | N13: =IF($J13="","",IF(COUNTIF(tblAnahtarB[NormB],$J13)>1,"EVET","HAYIR")) | O13: =IF($I13="","",ROW()-ROW($I$5))
A14: =IF(VERI_A!A14="","",VERI_A!A14) | B14: =UPPER(TRIM(SUBSTITUTE($A14," ",""))) | C14: =IF($B14="",0,LEN($B14)) | D14: =IF($A14="","",TEXT(IFERROR(INDEX(tblVeriA[Tarih],ROW()-ROW(tblVeriA[[#Headers]])),""),"yyyymmdd")&"|"&TEXT(IFERROR(INDEX(tblVeriA[Toplam],ROW()-ROW(tblVeriA[[#Headers]])),0),"0.00")) | E14: ="A" | F14: =IF($B14="","",IF(COUNTIF(tblAnahtarA[Norm],$B14)>1,"EVET","HAYIR")) | G14: =IF($A14="","",ROW()-ROW($A$5)) | I14: =IF(VERI_B!A14="","",VERI_B!A14) | J14: =UPPER(TRIM(SUBSTITUTE($I14," ",""))) | K14: =IF($J14="",0,LEN($J14)) | L14: =IF($I14="","",TEXT(IFERROR(INDEX(tblVeriB[BelgeTarihi],ROW()-ROW(tblVeriB[[#Headers]])),""),"yyyymmdd")&"|"&TEXT(IFERROR(INDEX(tblVeriB[Tutar],ROW()-ROW(tblVeriB[[#Headers]])),0),"0.00")) | M14: ="B" | N14: =IF($J14="","",IF(COUNTIF(tblAnahtarB[NormB],$J14)>1,"EVET","HAYIR")) | O14: =IF($I14="","",ROW()-ROW($I$5))
A15: =IF(VERI_A!A15="","",VERI_A!A15) | B15: =UPPER(TRIM(SUBSTITUTE($A15," ",""))) | C15: =IF($B15="",0,LEN($B15)) | D15: =IF($A15="","",TEXT(IFERROR(INDEX(tblVeriA[Tarih],ROW()-ROW(tblVeriA[[#Headers]])),""),"yyyymmdd")&"|"&TEXT(IFERROR(INDEX(tblVeriA[Toplam],ROW()-ROW(tblVeriA[[#Headers]])),0),"0.00")) | E15: ="A" | F15: =IF($B15="","",IF(COUNTIF(tblAnahtarA[Norm],$B15)>1,"EVET","HAYIR")) | G15: =IF($A15="","",ROW()-ROW($A$5)) | I15: =IF(VERI_B!A15="","",VERI_B!A15) | J15: =UPPER(TRIM(SUBSTITUTE($I15," ",""))) | K15: =IF($J15="",0,LEN($J15)) | L15: =IF($I15="","",TEXT(IFERROR(INDEX(tblVeriB[BelgeTarihi],ROW()-ROW(tblVeriB[[#Headers]])),""),"yyyymmdd")&"|"&TEXT(IFERROR(INDEX(tblVeriB[Tutar],ROW()-ROW(tblVeriB[[#Headers]])),0),"0.00")) | M15: ="B" | N15: =IF($J15="","",IF(COUNTIF(tblAnahtarB[NormB],$J15)>1,"EVET","HAYIR")) | O15: =IF($I15="","",ROW()-ROW($I$5))
A16: =IF(VERI_A!A16="","",VERI_A!A16) | B16: =UPPER(TRIM(SUBSTITUTE($A16," ",""))) | C16: =IF($B16="",0,LEN($B16)) | D16: =IF($A16="","",TEXT(IFERROR(INDEX(tblVeriA[Tarih],ROW()-ROW(tblVeriA[[#Headers]])),""),"yyyymmdd")&"|"&TEXT(IFERROR(INDEX(tblVeriA[Toplam],ROW()-ROW(tblVeriA[[#Headers]])),0),"0.00")) | E16: ="A" | F16: =IF($B16="","",IF(COUNTIF(tblAnahtarA[Norm],$B16)>1,"EVET","HAYIR")) | G16: =IF($A16="","",ROW()-ROW($A$5)) | I16: =IF(VERI_B!A16="","",VERI_B!A16) | J16: =UPPER(TRIM(SUBSTITUTE($I16," ",""))) | K16: =IF($J16="",0,LEN($J16)) | L16: =IF($I16="","",TEXT(IFERROR(INDEX(tblVeriB[BelgeTarihi],ROW()-ROW(tblVeriB[[#Headers]])),""),"yyyymmdd")&"|"&TEXT(IFERROR(INDEX(tblVeriB[Tutar],ROW()-ROW(tblVeriB[[#Headers]])),0),"0.00")) | M16: ="B" | N16: =IF($J16="","",IF(COUNTIF(tblAnahtarB[NormB],$J16)>1,"EVET","HAYIR")) | O16: =IF($I16="","",ROW()-ROW($I$5))
A17: =IF(VERI_A!A17="","",VERI_A!A17) | B17: =UPPER(TRIM(SUBSTITUTE($A17," ",""))) | C17: =IF($B17="",0,LEN($B17)) | D17: =IF($A17="","",TEXT(IFERROR(INDEX(tblVeriA[Tarih],ROW()-ROW(tblVeriA[[#Headers]])),""),"yyyymmdd")&"|"&TEXT(IFERROR(INDEX(tblVeriA[Toplam],ROW()-ROW(tblVeriA[[#Headers]])),0),"0.00")) | E17: ="A" | F17: =IF($B17="","",IF(COUNTIF(tblAnahtarA[Norm],$B17)>1,"EVET","HAYIR")) | G17: =IF($A17="","",ROW()-ROW($A$5)) | I17: =IF(VERI_B!A17="","",VERI_B!A17) | J17: =UPPER(TRIM(SUBSTITUTE($I17," ",""))) | K17: =IF($J17="",0,LEN($J17)) | L17: =IF($I17="","",TEXT(IFERROR(INDEX(tblVeriB[BelgeTarihi],ROW()-ROW(tblVeriB[[#Headers]])),""),"yyyymmdd")&"|"&TEXT(IFERROR(INDEX(tblVeriB[Tutar],ROW()-ROW(tblVeriB[[#Headers]])),0),"0.00")) | M17: ="B" | N17: =IF($J17="","",IF(COUNTIF(tblAnahtarB[NormB],$J17)>1,"EVET","HAYIR")) | O17: =IF($I17="","",ROW()-ROW($I$5))
... A1005: =IF(VERI_A!A1005="","",VERI_A!A1005) | B1005: =UPPER(TRIM(SUBSTITUTE($A1005," ",""))) | C1005: =IF($B1005="",0,LEN($B1005)) | D1005: =IF($A1005="","",TEXT(IFERROR(INDEX(tblVeriA[Tarih],ROW()-ROW(tblVeriA[[#Headers]])),""),"yyyymmdd")&"|"&TEXT(IFERROR(INDEX(tblVeriA[Toplam],ROW()-ROW(tblVeriA[[#Headers]])),0),"0.00")) | E1005: ="A" | F1005: =IF($B1005="","",IF(COUNTIF(tblAnahtarA[Norm],$B1005)>1,"EVET","HAYIR")) | G1005: =IF($A1005="","",ROW()-ROW($A$5)) | I1005: =IF(VERI_B!A1005="","",VERI_B!A1005) | J1005: =UPPER(TRIM(SUBSTITUTE($I1005," ",""))) | K1005: =IF($J1005="",0,LEN($J1005)) | L1005: =IF($I1005="","",TEXT(IFERROR(INDEX(tblVeriB[BelgeTarihi],ROW()-ROW(tblVeriB[[#Headers]])),""),"yyyymmdd")&"|"&TEXT(IFERROR(INDEX(tblVeriB[Tutar],ROW()-ROW(tblVeriB[[#Headers]])),0),"0.00")) | M1005: ="B" | N1005: =IF($J1005="","",IF(COUNTIF(tblAnahtarB[NormB],$J1005)>1,"EVET","HAYIR")) | O1005: =IF($I1005="","",ROW()-ROW($I$5))

Sheet MOTOR
A1: MOTOR — Defter Beyan e-Arşiv Aktarım Düzenleyici
A3: Hesaplama motoru — ara adımlar (sabit skor yok, veriden türer)
A5: Adim | B5: Aciklama | C5: Deger
A6: 1 | B6: A kayit sayisi | C6: =COUNTA(tblVeriA[FaturaNo])
A7: 2 | B7: B kayit sayisi | C7: =COUNTA(tblVeriB[BelgeNo])
A8: 3 | B8: A toplam tutar | C8: =IFERROR(SUM(tblVeriA[Toplam]),0)
A9: 4 | B9: B toplam tutar | C9: =IFERROR(SUM(tblVeriB[Tutar]),0)
A10: 5 | B10: Mutabakat farki | C10: =C8-C9
A11: 6 | B11: Abs mutabakat farki | C11: =ABS(C10)
A12: 7 | B12: Eslesme adet | C12: =COUNTIF(tblEslesme[Kova],"eslesti")
A13: 8 | B13: Tolerans adet | C13: =COUNTIF(tblEslesme[Kova],"tolerans_icinde")
A14: 9 | B14: Tutar farki adet | C14: =COUNTIF(tblEslesme[Kova],"tutar_farki")
A15: 10 | B15: Eslesmedi adet | C15: =COUNTIF(tblEslesme[Kova],"eslesmedi")
A16: 11 | B16: Kova toplam | C16: =C12+C13+C14+C15
A17: 12 | B17: Norm kayit | C17: =COUNTA(tblEslesme[A_Norm])
A18: 13 | B18: Eslesme orani | C18: =IF(C17=0,0,(C12+C13)/C17)
A19: 14 | B19: Kova butunluk | C19: =IF(C16=C17,"BUTUN","KAYIP")
A20: 15 | B20: Ortalama tutar farki | C20: =IFERROR(IF(C14=0,0,SUMIF(tblEslesme[Kova],"tutar_farki",tblEslesme[AbsFark])/C14),0)
A21: 16 | B21: Anomali sayisi | C21: =COUNTIF(tblEslesme[EsikUstu],1)
A22: 17 | B22: Duplike A | C22: =COUNTIF(tblAnahtarA[Duplike],"EVET")
A23: 18 | B23: Duplike B | C23: =COUNTIF(tblAnahtarB[DuplikeB],"EVET")
A24: 19 | B24: Tanimsiz kok | C24: =COUNTIF(tblKok[KokNeden],"TANIMSIZ")
A25: 20 | B25: Matrah toplam | C25: =IFERROR(SUM(tblVeriA[Matrah]),0)
A26: 21 | B26: KDV toplam | C26: =IFERROR(SUM(tblVeriA[KDV]),0)
A27: 22 | B27: KDV oran kontrol | C27: =IFERROR(IF(C25=0,0,C26/C25),0)
A28: 23 | B28: Pareto fark payi | C28: =IFERROR(IF(SUM(tblEslesme[AbsFark])=0,0,MAX(tblEslesme[AbsFark])/SUM(tblEslesme[AbsFark])),0)
A29: 24 | B29: Yuzdelik P90 | C29: =IFERROR(PERCENTILE(tblEslesme[AbsFark],dbe_yuzdelikOran),0)
A30: 25 | B30: Tahmin aralik | C30: =IFERROR(PERCENTILE(tblVeriA[Toplam],dbe_yuzdelikOran),0)
A31: 26 | B31: Tornado zirve | C31: =IFERROR(MAX(PANO!K25:K29),0)
A32: 27 | B32: Veri hazirlik | C32: =IF(C6=0,0,C6/(C6+C7))
A33: 28 | B33: Esik alti mi | C33: =IF(C18<dbe_esikEslesme,1,0)
A34: 29 | B34: Fark esik ustu | C34: =IF(C11>dbe_esikFark,1,0)
A35: 30 | B35: Negatif A | C35: =COUNTIF(tblVeriA[Toplam],"<0")
A36: 31 | B36: Negatif B | C36: =COUNTIF(tblVeriB[Tutar],"<0")
A37: 32 | B37: Azami asimi A | C37: =COUNTIF(tblVeriA[Toplam],">"&dbe_azamiTutar)
A38: 33 | B38: Azami asimi B | C38: =COUNTIF(tblVeriB[Tutar],">"&dbe_azamiTutar)
A39: 34 | B39: Ikincil eslesme | C39: =COUNTIF(tblEslesme[IkincilEslesme],"IKINCIL")
A40: 35 | B40: Birincil eslesme | C40: =COUNTIF(tblEslesme[IkincilEslesme],"BIRINCIL")
A41: 36 | B41: Net katki | C41: =IFERROR(SUM(tblEslesme[NetKatki]),0)
A42: 37 | B42: Kalite skoru | C42: =IF(C17=0,0,ROUND(100*(C12+C13)/MAX(C17,1),0))
...

Sheet ESLESTIRME
A1: ESLESTIRME — Defter Beyan e-Arşiv Aktarım Düzenleyici
A2: Kova Bütünlük Denetimi | C2: =IF(COUNTIF(tblEslesme[Kova],"eslesti")+COUNTIF(tblEslesme[Kova],"tolerans_icinde")+COUNTIF(tblEslesme[Kova],"tutar_farki")+COUNTIF(tblEslesme[Kova],"eslesmedi")=COUNTA(tblEslesme[A_Norm]),"BUTUN","KAYIP")
A3: Dört kova motoru — her A kaydı tek kovaya düşer (E02)
A5: A_Norm | B5: B_Sayim | C5: B_Tutar | D5: A_Tutar | E5: Fark | F5: AbsFark | G5: Kova | H5: IkincilEslesme | I5: DuplikeBayrak | J5: FarkOran | K5: YuvarlakA | L5: YuvarlakB | M5: ToleransTest | N5: EsikUstu | O5: NetKatki | P5: MotorAdim
A6: =IF('ANAHTAR'!$B6="","",'ANAHTAR'!$B6) | B6: =IF($A6="","",COUNTIF(tblAnahtarB[NormB],$A6)) | C6: =IF($A6="","",SUMIF(tblAnahtarB[NormB],$A6,tblVeriB[Tutar])) | D6: =IF($A6="","",SUMIF(tblAnahtarA[Norm],$A6,tblVeriA[Toplam])) | E6: =IF($A6="","",ROUND($D6,2)-ROUND($C6,2)) | F6: =IF($A6="","",ABS($E6)) | G6: =IF($A6="","",IF($B6=0,"eslesmedi",IF(ROUND($D6,2)=ROUND($C6,2),"eslesti",IF(ABS(ROUND($D6,2)-ROUND($C6,2))<=toleransKurus,"tolerans_icinde","tutar_farki")))) | H6: =IF($A6="","",IF($B6>0,"BIRINCIL",IF(COUNTIF(tblAnahtarB[IkincilB],'ANAHTAR'!$D6)>0,"IKINCIL","YOK"))) | I6: =IF($A6="","",'ANAHTAR'!$F6) | J6: =IF(OR($A6="",$D6=0),0,$F6/ABS($D6)) | K6: =IF($A6="","",ROUND($D6,2)) | L6: =IF($A6="","",ROUND($C6,2)) | M6: =IF($A6="","",IF($F6<=toleransKurus,1,0)) | N6: =IF($A6="","",IF($F6>dbe_esikFark,1,0)) | O6: =IF($A6="","",IF($G6="eslesti",$D6,0)) | P6: =IF($A6="","",$B6+$M6+$N6)
A7: =IF('ANAHTAR'!$B7="","",'ANAHTAR'!$B7) | B7: =IF($A7="","",COUNTIF(tblAnahtarB[NormB],$A7)) | C7: =IF($A7="","",SUMIF(tblAnahtarB[NormB],$A7,tblVeriB[Tutar])) | D7: =IF($A7="","",SUMIF(tblAnahtarA[Norm],$A7,tblVeriA[Toplam])) | E7: =IF($A7="","",ROUND($D7,2)-ROUND($C7,2)) | F7: =IF($A7="","",ABS($E7)) | G7: =IF($A7="","",IF($B7=0,"eslesmedi",IF(ROUND($D7,2)=ROUND($C7,2),"eslesti",IF(ABS(ROUND($D7,2)-ROUND($C7,2))<=toleransKurus,"tolerans_icinde","tutar_farki")))) | H7: =IF($A7="","",IF($B7>0,"BIRINCIL",IF(COUNTIF(tblAnahtarB[IkincilB],'ANAHTAR'!$D7)>0,"IKINCIL","YOK"))) | I7: =IF($A7="","",'ANAHTAR'!$F7) | J7: =IF(OR($A7="",$D7=0),0,$F7/ABS($D7)) | K7: =IF($A7="","",ROUND($D7,2)) | L7: =IF($A7="","",ROUND($C7,2)) | M7: =IF($A7="","",IF($F7<=toleransKurus,1,0)) | N7: =IF($A7="","",IF($F7>dbe_esikFark,1,0)) | O7: =IF($A7="","",IF($G7="eslesti",$D7,0)) | P7: =IF($A7="","",$B7+$M7+$N7)
A8: =IF('ANAHTAR'!$B8="","",'ANAHTAR'!$B8) | B8: =IF($A8="","",COUNTIF(tblAnahtarB[NormB],$A8)) | C8: =IF($A8="","",SUMIF(tblAnahtarB[NormB],$A8,tblVeriB[Tutar])) | D8: =IF($A8="","",SUMIF(tblAnahtarA[Norm],$A8,tblVeriA[Toplam])) | E8: =IF($A8="","",ROUND($D8,2)-ROUND($C8,2)) | F8: =IF($A8="","",ABS($E8)) | G8: =IF($A8="","",IF($B8=0,"eslesmedi",IF(ROUND($D8,2)=ROUND($C8,2),"eslesti",IF(ABS(ROUND($D8,2)-ROUND($C8,2))<=toleransKurus,"tolerans_icinde","tutar_farki")))) | H8: =IF($A8="","",IF($B8>0,"BIRINCIL",IF(COUNTIF(tblAnahtarB[IkincilB],'ANAHTAR'!$D8)>0,"IKINCIL","YOK"))) | I8: =IF($A8="","",'ANAHTAR'!$F8) | J8: =IF(OR($A8="",$D8=0),0,$F8/ABS($D8)) | K8: =IF($A8="","",ROUND($D8,2)) | L8: =IF($A8="","",ROUND($C8,2)) | M8: =IF($A8="","",IF($F8<=toleransKurus,1,0)) | N8: =IF($A8="","",IF($F8>dbe_esikFark,1,0)) | O8: =IF($A8="","",IF($G8="eslesti",$D8,0)) | P8: =IF($A8="","",$B8+$M8+$N8)
A9: =IF('ANAHTAR'!$B9="","",'ANAHTAR'!$B9) | B9: =IF($A9="","",COUNTIF(tblAnahtarB[NormB],$A9)) | C9: =IF($A9="","",SUMIF(tblAnahtarB[NormB],$A9,tblVeriB[Tutar])) | D9: =IF($A9="","",SUMIF(tblAnahtarA[Norm],$A9,tblVeriA[Toplam])) | E9: =IF($A9="","",ROUND($D9,2)-ROUND($C9,2)) | F9: =IF($A9="","",ABS($E9)) | G9: =IF($A9="","",IF($B9=0,"eslesmedi",IF(ROUND($D9,2)=ROUND($C9,2),"eslesti",IF(ABS(ROUND($D9,2)-ROUND($C9,2))<=toleransKurus,"tolerans_icinde","tutar_farki")))) | H9: =IF($A9="","",IF($B9>0,"BIRINCIL",IF(COUNTIF(tblAnahtarB[IkincilB],'ANAHTAR'!$D9)>0,"IKINCIL","YOK"))) | I9: =IF($A9="","",'ANAHTAR'!$F9) | J9: =IF(OR($A9="",$D9=0),0,$F9/ABS($D9)) | K9: =IF($A9="","",ROUND($D9,2)) | L9: =IF($A9="","",ROUND($C9,2)) | M9: =IF($A9="","",IF($F9<=toleransKurus,1,0)) | N9: =IF($A9="","",IF($F9>dbe_esikFark,1,0)) | O9: =IF($A9="","",IF($G9="eslesti",$D9,0)) | P9: =IF($A9="","",$B9+$M9+$N9)
A10: =IF('ANAHTAR'!$B10="","",'ANAHTAR'!$B10) | B10: =IF($A10="","",COUNTIF(tblAnahtarB[NormB],$A10)) | C10: =IF($A10="","",SUMIF(tblAnahtarB[NormB],$A10,tblVeriB[Tutar])) | D10: =IF($A10="","",SUMIF(tblAnahtarA[Norm],$A10,tblVeriA[Toplam])) | E10: =IF($A10="","",ROUND($D10,2)-ROUND($C10,2)) | F10: =IF($A10="","",ABS($E10)) | G10: =IF($A10="","",IF($B10=0,"eslesmedi",IF(ROUND($D10,2)=ROUND($C10,2),"eslesti",IF(ABS(ROUND($D10,2)-ROUND($C10,2))<=toleransKurus,"tolerans_icinde","tutar_farki")))) | H10: =IF($A10="","",IF($B10>0,"BIRINCIL",IF(COUNTIF(tblAnahtarB[IkincilB],'ANAHTAR'!$D10)>0,"IKINCIL","YOK"))) | I10: =IF($A10="","",'ANAHTAR'!$F10) | J10: =IF(OR($A10="",$D10=0),0,$F10/ABS($D10)) | K10: =IF($A10="","",ROUND($D10,2)) | L10: =IF($A10="","",ROUND($C10,2)) | M10: =IF($A10="","",IF($F10<=toleransKurus,1,0)) | N10: =IF($A10="","",IF($F10>dbe_esikFark,1,0)) | O10: =IF($A10="","",IF($G10="eslesti",$D10,0)) | P10: =IF($A10="","",$B10+$M10+$N10)
A11: =IF('ANAHTAR'!$B11="","",'ANAHTAR'!$B11) | B11: =IF($A11="","",COUNTIF(tblAnahtarB[NormB],$A11)) | C11: =IF($A11="","",SUMIF(tblAnahtarB[NormB],$A11,tblVeriB[Tutar])) | D11: =IF($A11="","",SUMIF(tblAnahtarA[Norm],$A11,tblVeriA[Toplam])) | E11: =IF($A11="","",ROUND($D11,2)-ROUND($C11,2)) | F11: =IF($A11="","",ABS($E11)) | G11: =IF($A11="","",IF($B11=0,"eslesmedi",IF(ROUND($D11,2)=ROUND($C11,2),"eslesti",IF(ABS(ROUND($D11,2)-ROUND($C11,2))<=toleransKurus,"tolerans_icinde","tutar_farki")))) | H11: =IF($A11="","",IF($B11>0,"BIRINCIL",IF(COUNTIF(tblAnahtarB[IkincilB],'ANAHTAR'!$D11)>0,"IKINCIL","YOK"))) | I11: =IF($A11="","",'ANAHTAR'!$F11) | J11: =IF(OR($A11="",$D11=0),0,$F11/ABS($D11)) | K11: =IF($A11="","",ROUND($D11,2)) | L11: =IF($A11="","",ROUND($C11,2)) | M11: =IF($A11="","",IF($F11<=toleransKurus,1,0)) | N11: =IF($A11="","",IF($F11>dbe_esikFark,1,0)) | O11: =IF($A11="","",IF($G11="eslesti",$D11,0)) | P11: =IF($A11="","",$B11+$M11+$N11)
A12: =IF('ANAHTAR'!$B12="","",'ANAHTAR'!$B12) | B12: =IF($A12="","",COUNTIF(tblAnahtarB[NormB],$A12)) | C12: =IF($A12="","",SUMIF(tblAnahtarB[NormB],$A12,tblVeriB[Tutar])) | D12: =IF($A12="","",SUMIF(tblAnahtarA[Norm],$A12,tblVeriA[Toplam])) | E12: =IF($A12="","",ROUND($D12,2)-ROUND($C12,2)) | F12: =IF($A12="","",ABS($E12)) | G12: =IF($A12="","",IF($B12=0,"eslesmedi",IF(ROUND($D12,2)=ROUND($C12,2),"eslesti",IF(ABS(ROUND($D12,2)-ROUND($C12,2))<=toleransKurus,"tolerans_icinde","tutar_farki")))) | H12: =IF($A12="","",IF($B12>0,"BIRINCIL",IF(COUNTIF(tblAnahtarB[IkincilB],'ANAHTAR'!$D12)>0,"IKINCIL","YOK"))) | I12: =IF($A12="","",'ANAHTAR'!$F12) | J12: =IF(OR($A12="",$D12=0),0,$F12/ABS($D12)) | K12: =IF($A12="","",ROUND($D12,2)) | L12: =IF($A12="","",ROUND($C12,2)) | M12: =IF($A12="","",IF($F12<=toleransKurus,1,0)) | N12: =IF($A12="","",IF($F12>dbe_esikFark,1,0)) | O12: =IF($A12="","",IF($G12="eslesti",$D12,0)) | P12: =IF($A12="","",$B12+$M12+$N12)
A13: =IF('ANAHTAR'!$B13="","",'ANAHTAR'!$B13) | B13: =IF($A13="","",COUNTIF(tblAnahtarB[NormB],$A13)) | C13: =IF($A13="","",SUMIF(tblAnahtarB[NormB],$A13,tblVeriB[Tutar])) | D13: =IF($A13="","",SUMIF(tblAnahtarA[Norm],$A13,tblVeriA[Toplam])) | E13: =IF($A13="","",ROUND($D13,2)-ROUND($C13,2)) | F13: =IF($A13="","",ABS($E13)) | G13: =IF($A13="","",IF($B13=0,"eslesmedi",IF(ROUND($D13,2)=ROUND($C13,2),"eslesti",IF(ABS(ROUND($D13,2)-ROUND($C13,2))<=toleransKurus,"tolerans_icinde","tutar_farki")))) | H13: =IF($A13="","",IF($B13>0,"BIRINCIL",IF(COUNTIF(tblAnahtarB[IkincilB],'ANAHTAR'!$D13)>0,"IKINCIL","YOK"))) | I13: =IF($A13="","",'ANAHTAR'!$F13) | J13: =IF(OR($A13="",$D13=0),0,$F13/ABS($D13)) | K13: =IF($A13="","",ROUND($D13,2)) | L13: =IF($A13="","",ROUND($C13,2)) | M13: =IF($A13="","",IF($F13<=toleransKurus,1,0)) | N13: =IF($A13="","",IF($F13>dbe_esikFark,1,0)) | O13: =IF($A13="","",IF($G13="eslesti",$D13,0)) | P13: =IF($A13="","",$B13+$M13+$N13)
A14: =IF('ANAHTAR'!$B14="","",'ANAHTAR'!$B14) | B14: =IF($A14="","",COUNTIF(tblAnahtarB[NormB],$A14)) | C14: =IF($A14="","",SUMIF(tblAnahtarB[NormB],$A14,tblVeriB[Tutar])) | D14: =IF($A14="","",SUMIF(tblAnahtarA[Norm],$A14,tblVeriA[Toplam])) | E14: =IF($A14="","",ROUND($D14,2)-ROUND($C14,2)) | F14: =IF($A14="","",ABS($E14)) | G14: =IF($A14="","",IF($B14=0,"eslesmedi",IF(ROUND($D14,2)=ROUND($C14,2),"eslesti",IF(ABS(ROUND($D14,2)-ROUND($C14,2))<=toleransKurus,"tolerans_icinde","tutar_farki")))) | H14: =IF($A14="","",IF($B14>0,"BIRINCIL",IF(COUNTIF(tblAnahtarB[IkincilB],'ANAHTAR'!$D14)>0,"IKINCIL","YOK"))) | I14: =IF($A14="","",'ANAHTAR'!$F14) | J14: =IF(OR($A14="",$D14=0),0,$F14/ABS($D14)) | K14: =IF($A14="","",ROUND($D14,2)) | L14: =IF($A14="","",ROUND($C14,2)) | M14: =IF($A14="","",IF($F14<=toleransKurus,1,0)) | N14: =IF($A14="","",IF($F14>dbe_esikFark,1,0)) | O14: =IF($A14="","",IF($G14="eslesti",$D14,0)) | P14: =IF($A14="","",$B14+$M14+$N14)
A15: =IF('ANAHTAR'!$B15="","",'ANAHTAR'!$B15) | B15: =IF($A15="","",COUNTIF(tblAnahtarB[NormB],$A15)) | C15: =IF($A15="","",SUMIF(tblAnahtarB[NormB],$A15,tblVeriB[Tutar])) | D15: =IF($A15="","",SUMIF(tblAnahtarA[Norm],$A15,tblVeriA[Toplam])) | E15: =IF($A15="","",ROUND($D15,2)-ROUND($C15,2)) | F15: =IF($A15="","",ABS($E15)) | G15: =IF($A15="","",IF($B15=0,"eslesmedi",IF(ROUND($D15,2)=ROUND($C15,2),"eslesti",IF(ABS(ROUND($D15,2)-ROUND($C15,2))<=toleransKurus,"tolerans_icinde","tutar_farki")))) | H15: =IF($A15="","",IF($B15>0,"BIRINCIL",IF(COUNTIF(tblAnahtarB[IkincilB],'ANAHTAR'!$D15)>0,"IKINCIL","YOK"))) | I15: =IF($A15="","",'ANAHTAR'!$F15) | J15: =IF(OR($A15="",$D15=0),0,$F15/ABS($D15)) | K15: =IF($A15="","",ROUND($D15,2)) | L15: =IF($A15="","",ROUND($C15,2)) | M15: =IF($A15="","",IF($F15<=toleransKurus,1,0)) | N15: =IF($A15="","",IF($F15>dbe_esikFark,1,0)) | O15: =IF($A15="","",IF($G15="eslesti",$D15,0)) | P15: =IF($A15="","",$B15+$M15+$N15)
A16: =IF('ANAHTAR'!$B16="","",'ANAHTAR'!$B16) | B16: =IF($A16="","",COUNTIF(tblAnahtarB[NormB],$A16)) | C16: =IF($A16="","",SUMIF(tblAnahtarB[NormB],$A16,tblVeriB[Tutar])) | D16: =IF($A16="","",SUMIF(tblAnahtarA[Norm],$A16,tblVeriA[Toplam])) | E16: =IF($A16="","",ROUND($D16,2)-ROUND($C16,2)) | F16: =IF($A16="","",ABS($E16)) | G16: =IF($A16="","",IF($B16=0,"eslesmedi",IF(ROUND($D16,2)=ROUND($C16,2),"eslesti",IF(ABS(ROUND($D16,2)-ROUND($C16,2))<=toleransKurus,"tolerans_icinde","tutar_farki")))) | H16: =IF($A16="","",IF($B16>0,"BIRINCIL",IF(COUNTIF(tblAnahtarB[IkincilB],'ANAHTAR'!$D16)>0,"IKINCIL","YOK"))) | I16: =IF($A16="","",'ANAHTAR'!$F16) | J16: =IF(OR($A16="",$D16=0),0,$F16/ABS($D16)) | K16: =IF($A16="","",ROUND($D16,2)) | L16: =IF($A16="","",ROUND($C16,2)) | M16: =IF($A16="","",IF($F16<=toleransKurus,1,0)) | N16: =IF($A16="","",IF($F16>dbe_esikFark,1,0)) | O16: =IF($A16="","",IF($G16="eslesti",$D16,0)) | P16: =IF($A16="","",$B16+$M16+$N16)
A17: =IF('ANAHTAR'!$B17="","",'ANAHTAR'!$B17) | B17: =IF($A17="","",COUNTIF(tblAnahtarB[NormB],$A17)) | C17: =IF($A17="","",SUMIF(tblAnahtarB[NormB],$A17,tblVeriB[Tutar])) | D17: =IF($A17="","",SUMIF(tblAnahtarA[Norm],$A17,tblVeriA[Toplam])) | E17: =IF($A17="","",ROUND($D17,2)-ROUND($C17,2)) | F17: =IF($A17="","",ABS($E17)) | G17: =IF($A17="","",IF($B17=0,"eslesmedi",IF(ROUND($D17,2)=ROUND($C17,2),"eslesti",IF(ABS(ROUND($D17,2)-ROUND($C17,2))<=toleransKurus,"tolerans_icinde","tutar_farki")))) | H17: =IF($A17="","",IF($B17>0,"BIRINCIL",IF(COUNTIF(tblAnahtarB[IkincilB],'ANAHTAR'!$D17)>0,"IKINCIL","YOK"))) | I17: =IF($A17="","",'ANAHTAR'!$F17) | J17: =IF(OR($A17="",$D17=0),0,$F17/ABS($D17)) | K17: =IF($A17="","",ROUND($D17,2)) | L17: =IF($A17="","",ROUND($C17,2)) | M17: =IF($A17="","",IF($F17<=toleransKurus,1,0)) | N17: =IF($A17="","",IF($F17>dbe_esikFark,1,0)) | O17: =IF($A17="","",IF($G17="eslesti",$D17,0)) | P17: =IF($A17="","",$B17+$M17+$N17)
... A1005: =IF('ANAHTAR'!$B1005="","",'ANAHTAR'!$B1005) | B1005: =IF($A1005="","",COUNTIF(tblAnahtarB[NormB],$A1005)) | C1005: =IF($A1005="","",SUMIF(tblAnahtarB[NormB],$A1005,tblVeriB[Tutar])) | D1005: =IF($A1005="","",SUMIF(tblAnahtarA[Norm],$A1005,tblVeriA[Toplam])) | E1005: =IF($A1005="","",ROUND($D1005,2)-ROUND($C1005,2)) | F1005: =IF($A1005="","",ABS($E1005)) | G1005: =IF($A1005="","",IF($B1005=0,"eslesmedi",IF(ROUND($D1005,2)=ROUND($C1005,2),"eslesti",IF(ABS(ROUND($D1005,2)-ROUND($C1005,2))<=toleransKurus,"tolerans_icinde","tutar_farki")))) | H1005: =IF($A1005="","",IF($B1005>0,"BIRINCIL",IF(COUNTIF(tblAnahtarB[IkincilB],'ANAHTAR'!$D1005)>0,"IKINCIL","YOK"))) | I1005: =IF($A1005="","",'ANAHTAR'!$F1005) | J1005: =IF(OR($A1005="",$D1005=0),0,$F1005/ABS($D1005)) | K1005: =IF($A1005="","",ROUND($D1005,2)) | L1005: =IF($A1005="","",ROUND($C1005,2)) | M1005: =IF($A1005="","",IF($F1005<=toleransKurus,1,0)) | N1005: =IF($A1005="","",IF($F1005>dbe_esikFark,1,0)) | O1005: =IF($A1005="","",IF($G1005="eslesti",$D1005,0)) | P1005: =IF($A1005="","",$B1005+$M1005+$N1005)

Sheet HATA_LISTE
A1: HATA LISTE — Defter Beyan e-Arşiv Aktarım Düzenleyici
A3: Zorunlu alan / format / VKN / tutar hataları — aktarım öncesi temizle
A4: Özet | B4: =dbe_hataListesi | C4: adet hata satırı
A5: SatirNo | B5: FaturaNo | C5: HataKodu | D5: Aciklama | E5: Siddet | F5: KokNeden | G5: KayitDolu
A6: =IF('VERI_A'!$A6="","",ROW()-ROW(tblVeriA[[#Headers]])) | B6: =IF('VERI_A'!$A6="","",'VERI_A'!$A6) | C6: =IF($B6="","",IF(OR('VERI_A'!$B6="",'VERI_A'!$B6=0),"TARIH_BOS",IF(LEN(TRIM('VERI_A'!$C6&""))<>dbe_vknUzunluk,"VKN_UZUNLUK",IF('VERI_A'!$G6<0,"TUTAR_NEGATIF",IF('VERI_A'!$I6="","DONEM_EKSIK","")))) | D6: =IF($C6="","",IF($C6="TARIH_BOS","Belge tarihi zorunlu",IF($C6="VKN_UZUNLUK","VKN 10 hane olmalı",IF($C6="TUTAR_NEGATIF","Toplam negatif olamaz",IF($C6="DONEM_EKSIK","Dönem zorunlu","Elle incele")))) | E6: =IF($C6="","",IF(OR($C6="TUTAR_NEGATIF",$C6="TARIH_BOS"),"YUKSEK","ORTA")) | F6: =IF($C6="","",IF(OR($C6="TARIH_BOS",$C6="VKN_UZUNLUK",$C6="TUTAR_NEGATIF",$C6="DONEM_EKSIK"),$C6,"TANIMSIZ")) | G6: =IF($C6="","",1)
A7: =IF('VERI_A'!$A7="","",ROW()-ROW(tblVeriA[[#Headers]])) | B7: =IF('VERI_A'!$A7="","",'VERI_A'!$A7) | C7: =IF($B7="","",IF(OR('VERI_A'!$B7="",'VERI_A'!$B7=0),"TARIH_BOS",IF(LEN(TRIM('VERI_A'!$C7&""))<>dbe_vknUzunluk,"VKN_UZUNLUK",IF('VERI_A'!$G7<0,"TUTAR_NEGATIF",IF('VERI_A'!$I7="","DONEM_EKSIK","")))) | D7: =IF($C7="","",IF($C7="TARIH_BOS","Belge tarihi zorunlu",IF($C7="VKN_UZUNLUK","VKN 10 hane olmalı",IF($C7="TUTAR_NEGATIF","Toplam negatif olamaz",IF($C7="DONEM_EKSIK","Dönem zorunlu","Elle incele")))) | E7: =IF($C7="","",IF(OR($C7="TUTAR_NEGATIF",$C7="TARIH_BOS"),"YUKSEK","ORTA")) | F7: =IF($C7="","",IF(OR($C7="TARIH_BOS",$C7="VKN_UZUNLUK",$C7="TUTAR_NEGATIF",$C7="DONEM_EKSIK"),$C7,"TANIMSIZ")) | G7: =IF($C7="","",1)
A8: =IF('VERI_A'!$A8="","",ROW()-ROW(tblVeriA[[#Headers]])) | B8: =IF('VERI_A'!$A8="","",'VERI_A'!$A8) | C8: =IF($B8="","",IF(OR('VERI_A'!$B8="",'VERI_A'!$B8=0),"TARIH_BOS",IF(LEN(TRIM('VERI_A'!$C8&""))<>dbe_vknUzunluk,"VKN_UZUNLUK",IF('VERI_A'!$G8<0,"TUTAR_NEGATIF",IF('VERI_A'!$I8="","DONEM_EKSIK","")))) | D8: =IF($C8="","",IF($C8="TARIH_BOS","Belge tarihi zorunlu",IF($C8="VKN_UZUNLUK","VKN 10 hane olmalı",IF($C8="TUTAR_NEGATIF","Toplam negatif olamaz",IF($C8="DONEM_EKSIK","Dönem zorunlu","Elle incele")))) | E8: =IF($C8="","",IF(OR($C8="TUTAR_NEGATIF",$C8="TARIH_BOS"),"YUKSEK","ORTA")) | F8: =IF($C8="","",IF(OR($C8="TARIH_BOS",$C8="VKN_UZUNLUK",$C8="TUTAR_NEGATIF",$C8="DONEM_EKSIK"),$C8,"TANIMSIZ")) | G8: =IF($C8="","",1)
A9: =IF('VERI_A'!$A9="","",ROW()-ROW(tblVeriA[[#Headers]])) | B9: =IF('VERI_A'!$A9="","",'VERI_A'!$A9) | C9: =IF($B9="","",IF(OR('VERI_A'!$B9="",'VERI_A'!$B9=0),"TARIH_BOS",IF(LEN(TRIM('VERI_A'!$C9&""))<>dbe_vknUzunluk,"VKN_UZUNLUK",IF('VERI_A'!$G9<0,"TUTAR_NEGATIF",IF('VERI_A'!$I9="","DONEM_EKSIK","")))) | D9: =IF($C9="","",IF($C9="TARIH_BOS","Belge tarihi zorunlu",IF($C9="VKN_UZUNLUK","VKN 10 hane olmalı",IF($C9="TUTAR_NEGATIF","Toplam negatif olamaz",IF($C9="DONEM_EKSIK","Dönem zorunlu","Elle incele")))) | E9: =IF($C9="","",IF(OR($C9="TUTAR_NEGATIF",$C9="TARIH_BOS"),"YUKSEK","ORTA")) | F9: =IF($C9="","",IF(OR($C9="TARIH_BOS",$C9="VKN_UZUNLUK",$C9="TUTAR_NEGATIF",$C9="DONEM_EKSIK"),$C9,"TANIMSIZ")) | G9: =IF($C9="","",1)
A10: =IF('VERI_A'!$A10="","",ROW()-ROW(tblVeriA[[#Headers]])) | B10: =IF('VERI_A'!$A10="","",'VERI_A'!$A10) | C10: =IF($B10="","",IF(OR('VERI_A'!$B10="",'VERI_A'!$B10=0),"TARIH_BOS",IF(LEN(TRIM('VERI_A'!$C10&""))<>dbe_vknUzunluk,"VKN_UZUNLUK",IF('VERI_A'!$G10<0,"TUTAR_NEGATIF",IF('VERI_A'!$I10="","DONEM_EKSIK","")))) | D10: =IF($C10="","",IF($C10="TARIH_BOS","Belge tarihi zorunlu",IF($C10="VKN_UZUNLUK","VKN 10 hane olmalı",IF($C10="TUTAR_NEGATIF","Toplam negatif olamaz",IF($C10="DONEM_EKSIK","Dönem zorunlu","Elle incele")))) | E10: =IF($C10="","",IF(OR($C10="TUTAR_NEGATIF",$C10="TARIH_BOS"),"YUKSEK","ORTA")) | F10: =IF($C10="","",IF(OR($C10="TARIH_BOS",$C10="VKN_UZUNLUK",$C10="TUTAR_NEGATIF",$C10="DONEM_EKSIK"),$C10,"TANIMSIZ")) | G10: =IF($C10="","",1)
A11: =IF('VERI_A'!$A11="","",ROW()-ROW(tblVeriA[[#Headers]])) | B11: =IF('VERI_A'!$A11="","",'VERI_A'!$A11) | C11: =IF($B11="","",IF(OR('VERI_A'!$B11="",'VERI_A'!$B11=0),"TARIH_BOS",IF(LEN(TRIM('VERI_A'!$C11&""))<>dbe_vknUzunluk,"VKN_UZUNLUK",IF('VERI_A'!$G11<0,"TUTAR_NEGATIF",IF('VERI_A'!$I11="","DONEM_EKSIK","")))) | D11: =IF($C11="","",IF($C11="TARIH_BOS","Belge tarihi zorunlu",IF($C11="VKN_UZUNLUK","VKN 10 hane olmalı",IF($C11="TUTAR_NEGATIF","Toplam negatif olamaz",IF($C11="DONEM_EKSIK","Dönem zorunlu","Elle incele")))) | E11: =IF($C11="","",IF(OR($C11="TUTAR_NEGATIF",$C11="TARIH_BOS"),"YUKSEK","ORTA")) | F11: =IF($C11="","",IF(OR($C11="TARIH_BOS",$C11="VKN_UZUNLUK",$C11="TUTAR_NEGATIF",$C11="DONEM_EKSIK"),$C11,"TANIMSIZ")) | G11: =IF($C11="","",1)
A12: =IF('VERI_A'!$A12="","",ROW()-ROW(tblVeriA[[#Headers]])) | B12: =IF('VERI_A'!$A12="","",'VERI_A'!$A12) | C12: =IF($B12="","",IF(OR('VERI_A'!$B12="",'VERI_A'!$B12=0),"TARIH_BOS",IF(LEN(TRIM('VERI_A'!$C12&""))<>dbe_vknUzunluk,"VKN_UZUNLUK",IF('VERI_A'!$G12<0,"TUTAR_NEGATIF",IF('VERI_A'!$I12="","DONEM_EKSIK","")))) | D12: =IF($C12="","",IF($C12="TARIH_BOS","Belge tarihi zorunlu",IF($C12="VKN_UZUNLUK","VKN 10 hane olmalı",IF($C12="TUTAR_NEGATIF","Toplam negatif olamaz",IF($C12="DONEM_EKSIK","Dönem zorunlu","Elle incele")))) | E12: =IF($C12="","",IF(OR($C12="TUTAR_NEGATIF",$C12="TARIH_BOS"),"YUKSEK","ORTA")) | F12: =IF($C12="","",IF(OR($C12="TARIH_BOS",$C12="VKN_UZUNLUK",$C12="TUTAR_NEGATIF",$C12="DONEM_EKSIK"),$C12,"TANIMSIZ")) | G12: =IF($C12="","",1)
A13: =IF('VERI_A'!$A13="","",ROW()-ROW(tblVeriA[[#Headers]])) | B13: =IF('VERI_A'!$A13="","",'VERI_A'!$A13) | C13: =IF($B13="","",IF(OR('VERI_A'!$B13="",'VERI_A'!$B13=0),"TARIH_BOS",IF(LEN(TRIM('VERI_A'!$C13&""))<>dbe_vknUzunluk,"VKN_UZUNLUK",IF('VERI_A'!$G13<0,"TUTAR_NEGATIF",IF('VERI_A'!$I13="","DONEM_EKSIK","")))) | D13: =IF($C13="","",IF($C13="TARIH_BOS","Belge tarihi zorunlu",IF($C13="VKN_UZUNLUK","VKN 10 hane olmalı",IF($C13="TUTAR_NEGATIF","Toplam negatif olamaz",IF($C13="DONEM_EKSIK","Dönem zorunlu","Elle incele")))) | E13: =IF($C13="","",IF(OR($C13="TUTAR_NEGATIF",$C13="TARIH_BOS"),"YUKSEK","ORTA")) | F13: =IF($C13="","",IF(OR($C13="TARIH_BOS",$C13="VKN_UZUNLUK",$C13="TUTAR_NEGATIF",$C13="DONEM_EKSIK"),$C13,"TANIMSIZ")) | G13: =IF($C13="","",1)
A14: =IF('VERI_A'!$A14="","",ROW()-ROW(tblVeriA[[#Headers]])) | B14: =IF('VERI_A'!$A14="","",'VERI_A'!$A14) | C14: =IF($B14="","",IF(OR('VERI_A'!$B14="",'VERI_A'!$B14=0),"TARIH_BOS",IF(LEN(TRIM('VERI_A'!$C14&""))<>dbe_vknUzunluk,"VKN_UZUNLUK",IF('VERI_A'!$G14<0,"TUTAR_NEGATIF",IF('VERI_A'!$I14="","DONEM_EKSIK","")))) | D14: =IF($C14="","",IF($C14="TARIH_BOS","Belge tarihi zorunlu",IF($C14="VKN_UZUNLUK","VKN 10 hane olmalı",IF($C14="TUTAR_NEGATIF","Toplam negatif olamaz",IF($C14="DONEM_EKSIK","Dönem zorunlu","Elle incele")))) | E14: =IF($C14="","",IF(OR($C14="TUTAR_NEGATIF",$C14="TARIH_BOS"),"YUKSEK","ORTA")) | F14: =IF($C14="","",IF(OR($C14="TARIH_BOS",$C14="VKN_UZUNLUK",$C14="TUTAR_NEGATIF",$C14="DONEM_EKSIK"),$C14,"TANIMSIZ")) | G14: =IF($C14="","",1)
A15: =IF('VERI_A'!$A15="","",ROW()-ROW(tblVeriA[[#Headers]])) | B15: =IF('VERI_A'!$A15="","",'VERI_A'!$A15) | C15: =IF($B15="","",IF(OR('VERI_A'!$B15="",'VERI_A'!$B15=0),"TARIH_BOS",IF(LEN(TRIM('VERI_A'!$C15&""))<>dbe_vknUzunluk,"VKN_UZUNLUK",IF('VERI_A'!$G15<0,"TUTAR_NEGATIF",IF('VERI_A'!$I15="","DONEM_EKSIK","")))) | D15: =IF($C15="","",IF($C15="TARIH_BOS","Belge tarihi zorunlu",IF($C15="VKN_UZUNLUK","VKN 10 hane olmalı",IF($C15="TUTAR_NEGATIF","Toplam negatif olamaz",IF($C15="DONEM_EKSIK","Dönem zorunlu","Elle incele")))) | E15: =IF($C15="","",IF(OR($C15="TUTAR_NEGATIF",$C15="TARIH_BOS"),"YUKSEK","ORTA")) | F15: =IF($C15="","",IF(OR($C15="TARIH_BOS",$C15="VKN_UZUNLUK",$C15="TUTAR_NEGATIF",$C15="DONEM_EKSIK"),$C15,"TANIMSIZ")) | G15: =IF($C15="","",1)
A16: =IF('VERI_A'!$A16="","",ROW()-ROW(tblVeriA[[#Headers]])) | B16: =IF('VERI_A'!$A16="","",'VERI_A'!$A16) | C16: =IF($B16="","",IF(OR('VERI_A'!$B16="",'VERI_A'!$B16=0),"TARIH_BOS",IF(LEN(TRIM('VERI_A'!$C16&""))<>dbe_vknUzunluk,"VKN_UZUNLUK",IF('VERI_A'!$G16<0,"TUTAR_NEGATIF",IF('VERI_A'!$I16="","DONEM_EKSIK","")))) | D16: =IF($C16="","",IF($C16="TARIH_BOS","Belge tarihi zorunlu",IF($C16="VKN_UZUNLUK","VKN 10 hane olmalı",IF($C16="TUTAR_NEGATIF","Toplam negatif olamaz",IF($C16="DONEM_EKSIK","Dönem zorunlu","Elle incele")))) | E16: =IF($C16="","",IF(OR($C16="TUTAR_NEGATIF",$C16="TARIH_BOS"),"YUKSEK","ORTA")) | F16: =IF($C16="","",IF(OR($C16="TARIH_BOS",$C16="VKN_UZUNLUK",$C16="TUTAR_NEGATIF",$C16="DONEM_EKSIK"),$C16,"TANIMSIZ")) | G16: =IF($C16="","",1)
A17: =IF('VERI_A'!$A17="","",ROW()-ROW(tblVeriA[[#Headers]])) | B17: =IF('VERI_A'!$A17="","",'VERI_A'!$A17) | C17: =IF($B17="","",IF(OR('VERI_A'!$B17="",'VERI_A'!$B17=0),"TARIH_BOS",IF(LEN(TRIM('VERI_A'!$C17&""))<>dbe_vknUzunluk,"VKN_UZUNLUK",IF('VERI_A'!$G17<0,"TUTAR_NEGATIF",IF('VERI_A'!$I17="","DONEM_EKSIK","")))) | D17: =IF($C17="","",IF($C17="TARIH_BOS","Belge tarihi zorunlu",IF($C17="VKN_UZUNLUK","VKN 10 hane olmalı",IF($C17="TUTAR_NEGATIF","Toplam negatif olamaz",IF($C17="DONEM_EKSIK","Dönem zorunlu","Elle incele")))) | E17: =IF($C17="","",IF(OR($C17="TUTAR_NEGATIF",$C17="TARIH_BOS"),"YUKSEK","ORTA")) | F17: =IF($C17="","",IF(OR($C17="TARIH_BOS",$C17="VKN_UZUNLUK",$C17="TUTAR_NEGATIF",$C17="DONEM_EKSIK"),$C17,"TANIMSIZ")) | G17: =IF($C17="","",1)
... A1005: =IF('VERI_A'!$A1005="","",ROW()-ROW(tblVeriA[[#Headers]])) | B1005: =IF('VERI_A'!$A1005="","",'VERI_A'!$A1005) | C1005: =IF($B1005="","",IF(OR('VERI_A'!$B1005="",'VERI_A'!$B1005=0),"TARIH_BOS",IF(LEN(TRIM('VERI_A'!$C1005&""))<>dbe_vknUzunluk,"VKN_UZUNLUK",IF('VERI_A'!$G1005<0,"TUTAR_NEGATIF",IF('VERI_A'!$I1005="","DONEM_EKSIK","")))) | D1005: =IF($C1005="","",IF($C1005="TARIH_BOS","Belge tarihi zorunlu",IF($C1005="VKN_UZUNLUK","VKN 10 hane olmalı",IF($C1005="TUTAR_NEGATIF","Toplam negatif olamaz",IF($C1005="DONEM_EKSIK","Dönem zorunlu","Elle incele")))) | E1005: =IF($C1005="","",IF(OR($C1005="TUTAR_NEGATIF",$C1005="TARIH_BOS"),"YUKSEK","ORTA")) | F1005: =IF($C1005="","",IF(OR($C1005="TARIH_BOS",$C1005="VKN_UZUNLUK",$C1005="TUTAR_NEGATIF",$C1005="DONEM_EKSIK"),$C1005,"TANIMSIZ")) | G1005: =IF($C1005="","",1)

Sheet KOK_NEDEN
A1: KOK NEDEN — Defter Beyan e-Arşiv Aktarım Düzenleyici
A3: Öncelik kurallı kök neden — eşleşmeyen fark TANIMSIZ (E04)
A4: Kural Önceliği
A5: Sira | B5: NedenKodu | C5: Test | D5: Aciklama
A6: 1 | B6: KDV_ORAN | C6: ABS(fark-kdv)<=toleransKurus | D6: Fark KDV tutarına yakın
A7: 2 | B7: MATRAH | C7: ABS(fark-matrah*oran)<=toleransKurus | D7: Matrah sapması şüphesi
A8: 3 | B8: YUVARLAMA | C8: AbsFark<=1 | D8: Kuruş/lira yuvarlama farkı
A9: 4 | B9: VKN_UYUMSUZ | C9: vkn_a<>vkn_b | D9: VKN uyuşmazlığı
A10: 5 | B10: TARIH | C10: tarih_farki>0 | D10: Tarih uyuşmazlığı şüphesi
A11: 6 | B11: TANIMSIZ | C11: TRUE | D11: Hiçbir kurala girmedi — elle incele
A13: TANIMSIZ kovası görünür tutulur — zorla sınıflandırma yok. Elle inceleyin.
A14: Satır Sınıflandırması
A15: A_Norm | B15: Kova | C15: AbsFark | D15: KDV | E15: Matrah | F15: YuvarlamaBayrak | G15: VKN | H15: KokNeden
A16: =IF('ESLESTIRME'!$A16="","",'ESLESTIRME'!$A16) | B16: =IF($A16="","",IFERROR(INDEX(tblEslesme[Kova],MATCH($A16,tblEslesme[A_Norm],0)),"")) | C16: =IF($A16="","",IFERROR(INDEX(tblEslesme[AbsFark],MATCH($A16,tblEslesme[A_Norm],0)),0)) | D16: =IF($A16="","",IFERROR(SUMIF(tblAnahtarA[Norm],$A16,tblVeriA[KDV]),0)) | E16: =IF($A16="","",IFERROR(SUMIF(tblAnahtarA[Norm],$A16,tblVeriA[Matrah]),0)) | F16: =IF($A16="","",IF($C16<=dbe_yuvarlamaEsik,1,0)) | G16: =IF($A16="","",IFERROR(INDEX(tblVeriA[VKN],MATCH($A16,tblAnahtarA[Norm],0)),"")) | H16: =IF(OR($A16="",$B16<>"tutar_farki"),"",IF(ABS($C16-$D16)<=toleransKurus,"KDV_ORAN",IF(ABS($C16-$E16*dbe_kdvOran)<=toleransKurus,"MATRAH",IF($F16=1,"YUVARLAMA","TANIMSIZ"))))
A17: =IF('ESLESTIRME'!$A17="","",'ESLESTIRME'!$A17) | B17: =IF($A17="","",IFERROR(INDEX(tblEslesme[Kova],MATCH($A17,tblEslesme[A_Norm],0)),"")) | C17: =IF($A17="","",IFERROR(INDEX(tblEslesme[AbsFark],MATCH($A17,tblEslesme[A_Norm],0)),0)) | D17: =IF($A17="","",IFERROR(SUMIF(tblAnahtarA[Norm],$A17,tblVeriA[KDV]),0)) | E17: =IF($A17="","",IFERROR(SUMIF(tblAnahtarA[Norm],$A17,tblVeriA[Matrah]),0)) | F17: =IF($A17="","",IF($C17<=dbe_yuvarlamaEsik,1,0)) | G17: =IF($A17="","",IFERROR(INDEX(tblVeriA[VKN],MATCH($A17,tblAnahtarA[Norm],0)),"")) | H17: =IF(OR($A17="",$B17<>"tutar_farki"),"",IF(ABS($C17-$D17)<=toleransKurus,"KDV_ORAN",IF(ABS($C17-$E17*dbe_kdvOran)<=toleransKurus,"MATRAH",IF($F17=1,"YUVARLAMA","TANIMSIZ"))))
A18: =IF('ESLESTIRME'!$A18="","",'ESLESTIRME'!$A18) | B18: =IF($A18="","",IFERROR(INDEX(tblEslesme[Kova],MATCH($A18,tblEslesme[A_Norm],0)),"")) | C18: =IF($A18="","",IFERROR(INDEX(tblEslesme[AbsFark],MATCH($A18,tblEslesme[A_Norm],0)),0)) | D18: =IF($A18="","",IFERROR(SUMIF(tblAnahtarA[Norm],$A18,tblVeriA[KDV]),0)) | E18: =IF($A18="","",IFERROR(SUMIF(tblAnahtarA[Norm],$A18,tblVeriA[Matrah]),0)) | F18: =IF($A18="","",IF($C18<=dbe_yuvarlamaEsik,1,0)) | G18: =IF($A18="","",IFERROR(INDEX(tblVeriA[VKN],MATCH($A18,tblAnahtarA[Norm],0)),"")) | H18: =IF(OR($A18="",$B18<>"tutar_farki"),"",IF(ABS($C18-$D18)<=toleransKurus,"KDV_ORAN",IF(ABS($C18-$E18*dbe_kdvOran)<=toleransKurus,"MATRAH",IF($F18=1,"YUVARLAMA","TANIMSIZ"))))
A19: =IF('ESLESTIRME'!$A19="","",'ESLESTIRME'!$A19) | B19: =IF($A19="","",IFERROR(INDEX(tblEslesme[Kova],MATCH($A19,tblEslesme[A_Norm],0)),"")) | C19: =IF($A19="","",IFERROR(INDEX(tblEslesme[AbsFark],MATCH($A19,tblEslesme[A_Norm],0)),0)) | D19: =IF($A19="","",IFERROR(SUMIF(tblAnahtarA[Norm],$A19,tblVeriA[KDV]),0)) | E19: =IF($A19="","",IFERROR(SUMIF(tblAnahtarA[Norm],$A19,tblVeriA[Matrah]),0)) | F19: =IF($A19="","",IF($C19<=dbe_yuvarlamaEsik,1,0)) | G19: =IF($A19="","",IFERROR(INDEX(tblVeriA[VKN],MATCH($A19,tblAnahtarA[Norm],0)),"")) | H19: =IF(OR($A19="",$B19<>"tutar_farki"),"",IF(ABS($C19-$D19)<=toleransKurus,"KDV_ORAN",IF(ABS($C19-$E19*dbe_kdvOran)<=toleransKurus,"MATRAH",IF($F19=1,"YUVARLAMA","TANIMSIZ"))))
A20: =IF('ESLESTIRME'!$A20="","",'ESLESTIRME'!$A20) | B20: =IF($A20="","",IFERROR(INDEX(tblEslesme[Kova],MATCH($A20,tblEslesme[A_Norm],0)),"")) | C20: =IF($A20="","",IFERROR(INDEX(tblEslesme[AbsFark],MATCH($A20,tblEslesme[A_Norm],0)),0)) | D20: =IF($A20="","",IFERROR(SUMIF(tblAnahtarA[Norm],$A20,tblVeriA[KDV]),0)) | E20: =IF($A20="","",IFERROR(SUMIF(tblAnahtarA[Norm],$A20,tblVeriA[Matrah]),0)) | F20: =IF($A20="","",IF($C20<=dbe_yuvarlamaEsik,1,0)) | G20: =IF($A20="","",IFERROR(INDEX(tblVeriA[VKN],MATCH($A20,tblAnahtarA[Norm],0)),"")) | H20: =IF(OR($A20="",$B20<>"tutar_farki"),"",IF(ABS($C20-$D20)<=toleransKurus,"KDV_ORAN",IF(ABS($C20-$E20*dbe_kdvOran)<=toleransKurus,"MATRAH",IF($F20=1,"YUVARLAMA","TANIMSIZ"))))
A21: =IF('ESLESTIRME'!$A21="","",'ESLESTIRME'!$A21) | B21: =IF($A21="","",IFERROR(INDEX(tblEslesme[Kova],MATCH($A21,tblEslesme[A_Norm],0)),"")) | C21: =IF($A21="","",IFERROR(INDEX(tblEslesme[AbsFark],MATCH($A21,tblEslesme[A_Norm],0)),0)) | D21: =IF($A21="","",IFERROR(SUMIF(tblAnahtarA[Norm],$A21,tblVeriA[KDV]),0)) | E21: =IF($A21="","",IFERROR(SUMIF(tblAnahtarA[Norm],$A21,tblVeriA[Matrah]),0)) | F21: =IF($A21="","",IF($C21<=dbe_yuvarlamaEsik,1,0)) | G21: =IF($A21="","",IFERROR(INDEX(tblVeriA[VKN],MATCH($A21,tblAnahtarA[Norm],0)),"")) | H21: =IF(OR($A21="",$B21<>"tutar_farki"),"",IF(ABS($C21-$D21)<=toleransKurus,"KDV_ORAN",IF(ABS($C21-$E21*dbe_kdvOran)<=toleransKurus,"MATRAH",IF($F21=1,"YUVARLAMA","TANIMSIZ"))))
