Workbook
Name raporTarihi: AYARLAR!$B$6
Name ddl_esikDoluluk: AYARLAR!$B$7
Name ddl_esikVerim: AYARLAR!$B$8
Name ddl_esikSaglik: AYARLAR!$B$9
Name ddl_varsayilanKapasitePalet: AYARLAR!$B$10
Name ddl_verimCarpan: AYARLAR!$B$11
Name ddl_aylikCarpan: AYARLAR!$B$12
Name ddl_senaryoTemkinli: AYARLAR!$B$13
Name ddl_senaryoBaz: AYARLAR!$B$14
Name ddl_senaryoIyimser: AYARLAR!$B$15
Name ddl_tornadoOran: AYARLAR!$B$16
Name ddl_yuzdelikOran: AYARLAR!$B$17
Name ddl_percentileOran: AYARLAR!$B$18
Name ddl_tahminCarpan: AYARLAR!$B$19
Name ddl_olcekHedef: AYARLAR!$B$20
Name ddl_kaliteTaban: AYARLAR!$B$21
Name ddl_kaliteCeza: AYARLAR!$B$22
Name ddl_kaliteSapma: AYARLAR!$B$23
Name ddl_dosyaSurumu: AYARLAR!$B$24
Name ddl_firmaUnvan: AYARLAR!$B$25
Name ddl_alarmEsikMetin: AYARLAR!$B$26
Name ddl_doluKayit: AYARLAR!$I$32
Name ddl_ortDoluluk: AYARLAR!$I$33
Name ddl_toplamPalet: AYARLAR!$I$34
Name ddl_toplamPick: AYARLAR!$I$35
Name ddl_ortVerim: AYARLAR!$I$36
Name ddl_kapasiteKullanim: AYARLAR!$I$37
Name ddl_bosPalet: AYARLAR!$I$38
Name ddl_aktifLokasyon: AYARLAR!$I$39
Name ddl_saglikSkor: AYARLAR!$I$40
Name ddl_alarmAdet: AYARLAR!$I$41
Name ddl_yetimAdet: AYARLAR!$I$42
Name ddl_gunlukDolulukOrt: AYARLAR!$I$43
Name ddl_aylikDolulukTrend: AYARLAR!$I$44
Name ddl_dolulukSapma: AYARLAR!$I$45
Name ddl_tornadoZirve: AYARLAR!$I$46
Name ddl_senaryoKarsilastirma: AYARLAR!$I$47
Name ddl_hhi: AYARLAR!$I$48
Name ddl_kaliteSkor: AYARLAR!$I$49
Name ddl_senaryoMotor: AYARLAR!$I$50
Name ddl_tahminAralik: AYARLAR!$I$51
Name ddl_yuzdelikP90: AYARLAR!$I$52
Name ddl_sezonsalTrend: AYARLAR!$I$53
Name ddl_alarmListesi: AYARLAR!$I$54
Name ddl_kararKapi: AYARLAR!$I$55
Name ddl_kararGerekce: AYARLAR!$I$56
Name ddl_sonrakiKimlik: AYARLAR!$I$57
Name ddl_yorumGunluk: AYARLAR!$I$60
Name ddl_yorumAylik: AYARLAR!$I$61
Name ddl_yorumSapma: AYARLAR!$I$62
Name ddl_yorumTornado: AYARLAR!$I$63
Name ddl_yorumSenaryo: AYARLAR!$I$64
Name ddl_yorumHhi: AYARLAR!$I$65
Name ddl_yorumKalite: AYARLAR!$I$66
Name ddl_yorumSenMotor: AYARLAR!$I$67
Name ddl_yorumTahmin: AYARLAR!$I$68
Name ddl_yorumP90: AYARLAR!$I$69
Name ListeEvetHayir: LISTELER!$A$7:$A$8
Name ListeOlayTuru: LISTELER!$C$7:$C$12
Name ListeLokasyonTipi: LISTELER!$E$7:$E$9

Sheet 00_BASLANGIC
A1: EXCELARŞİV KARAR SİSTEMİ v15.1 — ÜRETİM REFERANSI
A3: Konu | B3: Bağlayıcı Standart
A4: Amaç | B4: Kanıta dayalı, hatada kapalı çalışan Excel üretim ve denetim sistemi
A5: Öncelik | B5: Kullanıcının açık iş talebi ve gerçek kullanım senaryosu
A6: Ana akış | B6: Uygunluk → Yönetişim → Sözleşmeler → Üretim → Test → Kanıt → Kullanıcı Kabulü → Yayın
A7: Yayın ilkesi | B7: Üst aşamada hata varsa alt aşama GEÇTİ üretilemez
A8: Kullanıcı kabulü | B8: Excel masaüstü görünümü test edilmediyse DIŞ_KABUL_GEREKLİ
A9: Nihai yayın | B9: Yalnız uygulanabilir modüller GEÇTİ veya gerekçeli UYGULANMAZ
A10: Ticari ayrım | B10: Ekonomik olarak savunulabilir fiyat, gerçek pazar kabulü ile aynı değildir
A11: Karmaşıklık | B11: Karar değeri, eklenen karmaşıklığın maliyetinden büyük olmalıdır
A12: Excel sınırı | B12: Veritabanı, kurumsal yetkilendirme, değiştirilemez kayıt sistemi veya gerçek zamanlı olay platformu değildir
A13: Dil standardı | B13: Kullanıcıya görünen tüm sayfa, tablo, başlık, açıklama, uyarı ve karar metinleri saf Türkçe olmalıdır
A14: Muhasebe standardı | B14: Finansal ürünlerde Türkiye Tekdüzen Hesap Planı ve Türk muhasebe kullanım alışkanlıkları esas alınır
... A33: Muhasebe | B33: Türkiye Tekdüzen Hesap Planı ve Türk muhasebe/işletme düşünce yapısı esas alınır.

Sheet PANO
A1: ☰ PANO
B2: DEPO DOLULUK & LOKASYON OPTIMIZASYONU | L2: Dönem: 2026 / Tam ▼ | M2: ★ DOĞRULANMIŞ
B3: Hedef Kullanıcı: Depo müdürü, WMS operasyon, lojistik planlama, CFO · 2026 Q3 Denetim Standardı
B5: GÜNLÜK DOLULUK ORTALAMASI | D5: KONSOLİDE | E5: AYLIK DOLULUK TREND | G5: KONTROL | H5: NET OPERASYONEL MARJ | J5: GÜVENLİ | K5: SİSTEM GÜVEN SKORU | M5: DENETLENDİ
B7: =GİRDİLER!E17 | E7: =B7*0.22 | H7: =B7-E7 | K7: =IF(E7>0, ROUND(B7/E7, 2), 0)
B9: ↑ %14.2 konsolide canlı veri bağlantısı | E9: ● 8 Kalem nakit karşılığı: bloke | H9: ██████████░░░░░ %78.0 NET MARJ | K9: ✓ İDEAL karşılama rasyosu
B11: DEPO DOLULUK & LOKASYON OPTIMIZASYONU — DÖNEMSEL İCRA VE PROJEKSİYON | F11: +%32 Verim | H11: KONSOLİDE OPERASYON VE KARAR MATRİSİ
B12: Kümülatif Hacim vs. Operasyonel Maliyet ve Net Kâr Eğilimi | H12: Anlık Hesaplama Sonuçları, Dinamik Formül Çıktıları ve Durum Puanlaması
B14: Dönem | C14: Aktif Hacim | D14: Maliyet/Yük | E14: Hedef | H14: PARAMETRE / KALEM | I14: ANA TUTAR | J14: FARK / MARJ | K14: VADE | L14: KONTROL DURUMU
B15: D1 | C15: 65 | D15: 45 | E15: 60 | H15: Dönemlik Kümülatif Bakiye | I15: =B7*0.45 | J15: =B7*0.05 | K15: 12 Ay | L15: ✓ DÜZENLİ
B16: D2 | C16: 78 | D16: 48 | E16: 70 | H16: Kritik Eşik Güvenlik Tamponu | I16: =B7*0.30 | J16: =B7*0.03 | K16: 24 Ay | L16: ★ AVANTAJ
B17: D3 | C17: 85 | D17: 55 | E17: 80 | H17: Operasyonel Net Fark | I17: =B7*0.15 | J17: =B7*0.02 | K17: 8 Ay | L17: ● YAKLAŞAN
B18: D4 | C18: 75 | D18: 42 | E18: 75 | H18: Rezerv ve Likit Dağılım | I18: =B7*0.10 | J18: =B7*0.01 | K18: 16 Ay | L18: ✓ TAM UYUM
B19: D5 | C19: 90 | D19: 40 | E19: 85 | H19: KONSOLİDE SİSTEM TOPLAMI | I19: =SUM(I15:I18) | J19: =SUM(J15:J18) | L19: TAM DOĞRULANDI (0 HATA)
B20: D6 | C20: 96 | D20: 32 | E20: 92
B22: KONSOLİDE PAY VE AĞIRLIK | F22: LİKİDİTE RİSKİ & ERKEN UYARI SİNYALLERİ | K22: KARAR MOTORU
B23: ■ Ana Segment (%42) | F23: Nakit Açığı Riski (30 Gün) | I23: 0.00 TL (Sıfır Risk) | K23: LİKİDİTE OPTİMİZASYON FIRSATI
B24: ■ İkincil Grup (%30) | F24: Tahsilat Gecikme Toleransı | I24: 48 Gün Güvenli Eşik | K24: Atıl kalan nakit rezervinin gecelik repoda
B25: ■ Destek Birimi (%15) | F25: ██████████████████████████████████████ Güvenli Bölge (%100)
B26: ■ Rezervler (%13) | F26: ✓ 90 GÜNLÜK PROJEKSİYONDA NAKİT SIKIŞIKLIĞI TESPİT EDİLMEDİ | K26: FONLAMA SENARYOSUNU İNCELE ›

Sheet GİRDİLER
A1: ☰ PANO
B3: 🔍 DEPO DOLULUK & LOKASYON OPTIMIZASYONU — Kayıt veya hesap ara... | G3: TOPLAM: 1.450 KAYIT | I3: HATALI HÜCRE: 0 ADET
B5: TARİH | C5: REFERANS NO | D5: İŞLEM AÇIKLAMASI VE DETAY | E5: BRÜT TUTAR (₺) | F5: KDV ORANI | G5: NET TUTAR (₺) | H5: HESAP / CARİ | I5: DURUM
B6: 12.10.2026 | C6: TR-0428-A | D6: Operasyonel ana kalem tahmini | E6: 845200 | F6: 0.2 | G6: =E6/(1+F6) | H6: Vadesiz Ticari | I6: ONAYLANDI
B7: 14.10.2026 | C7: TR-0429-B | D7: Operasyonel çıkış/maliyet tahmini | E7: 1240000 | F7: 0.2 | G7: =E7/(1+F7) | H7: Tedarikçi Havuzu | I7: BEKLEMEDE
B8: 18.10.2026 | C8: TR-0430-C | D8: Ödeme takvimi tahakkuku | E8: 620500 | F8: 0.1 | G8: =E8/(1+F8) | H8: Kısa Vade Tahakkuk | I8: ONAYLANDI
B9: 21.10.2026 | C9: TR-0431-D | D9: Müşteri işlem tahmini | E9: 415000 | F9: 0.2 | G9: =E9/(1+F9) | H9: Müşteri Alacağı | I9: ONAYLANDI
B10: 25.10.2026 | C10: TR-0432-E | D10: Ana operasyon tahmini | E10: 980400 | F10: 0.2 | G10: =E10/(1+F10) | H10: Vadesiz Ticari | I10: ONAYLANDI
B11: 28.10.2026 | C11: TR-0433-F | D11: Kredi/taksit karşılığı | E11: 1850000 | F11: 0.2 | G11: =E11/(1+F11) | H11: Finansman Havuzu | I11: BLOKE
B12: 02.11.2026 | C12: TR-0434-G | D12: Sabit gider ve yönetim notları | E12: 740000 | F12: 0.2 | G12: =E12/(1+F12) | H12: Genel Yönetim | I12: ONAYLANDI
B13: 05.11.2026 | C13: TR-0435-H | D13: Operasyonel ana kalem tahmini | E13: 520800 | F13: 0.2 | G13: =E13/(1+F13) | H13: Vadesiz Ticari | I13: ONAYLANDI
B14: 09.11.2026 | C14: TR-0436-I | D14: Müşteri işlem tahmini | E14: 1120000 | F14: 0.2 | G14: =E14/(1+F14) | H14: Müşteri Alacağı | I14: ONAYLANDI
B15: 12.11.2026 | C15: TR-0437-J | D15: Operasyonel çıkış tahmini | E15: 890000 | F15: 0.2 | G15: =E15/(1+F15) | H15: Tedarikçi Havuzu | I15: ONAYLANDI
B17: SAYFA TOPLAMI (10 / 1.450 KAYIT) | E17: =SUM(E6:E15)

Sheet YÖNETİM_RAPORU
A1: ☰ PANO
B2: DEPO DOLULUK & LOKASYON OPTIMIZASYONU — NİHAİ KARAR VE DEĞERLEME
B3: Yönetim Kurulu ve İcra Komitesi için Otomatik Finansal Stres Testi Raporu · Depo müdürü, WMS operasyon, lojistik planlama, CFO
B4: DÖNEM: 2026 Q3 · DENETİM PROTOKOLÜ: ISO/VUK/IFRS UYUMLU · DURUM: ONAYLANDI
B6: SENARYO A: KÖTÜMSER (STRES TESTİ -%20) | H6: SENARYO B: BAZ MODEL (HEDEFLENEN)
B8: Ciro / Hacim Düşüşü: | E8: -%20.0 (Kriz Eşiği) | H8: Ciro / Hacim Gerçekleşmesi: | K8: %100.0 (Tam Bütçe)
B9: Beklenen Net Kâr / Getiri: | E9: =PANO!B7*0.8*0.22 | H9: Beklenen Net Kâr / Getiri: | K9: =PANO!H7
B10: Minimum Nakit Tamponu: | E10: =PANO!E7*0.75 | H10: Serbest Nakit Akımı: | K10: =PANO!H7*0.75
B11: Likidite Karşılama Oranı: | E11: =ROUND(PANO!B7*0.8/PANO!E7, 2) | H11: Yatırım Geri Dönüşü (ROI): | K11: %38.4 Yıllık
B14: STRES SENARYOSUNDA DAHİ İFLAS RİSKİ YOK | H14: OPTİMUM İCRA VE PLANLAMA REÇETESİ
B17: YÖNETİM KARAR MATRİSİ VE UYGULAMA REÇETESİ
B19: ● Öncelik 1: Acil Likidite ve Borç Servis Planlaması
B20: Sistemde hesaplanan vade günlerine sadık kalınarak nakit blokajı 3 gün önceden hazır edilmelidir.
B21: ● Öncelik 2: Formül Doğrulama ve Çapraz Sağlama
B22: Tüm hücreler kilitli formül korumasında olup girdi sayfalarında sıfır döngüsel başvuru (circular ref) garantilidir.
B23: ● Öncelik 3: Resmi Mevzuat ve Vergi Kalkanı Entegrasyonu
B24: 2026 güncel vergi dilimleri, amortisman ve SGK teşvik parametreleri tam otomatik yansıtılmaktadır.
B25: ● Öncelik 4: Yönetici İmzası ve Rapor Paylaşımı
B26: Tek tuşla PDF ve A4 çıktı formatına tam uyumlu sayfa yapısı kurgulanmıştır.

Sheet 01_YURUTME_CEKIRDEGI
A1: YÜRÜTME ÇEKİRDEĞİ — ZORUNLU ÜRETİM SIRASI
A3: Adım | B3: Modül | C3: Tetikleyici | D3: Zorunlu Kanıt | E3: GEÇTİ Kuralı | F3: Hata Durumu | G3: Sonraki Aşama
A4: 1 | B4: Excel Uygunluğu | C4: Her yeni model | D4: UYGUNLUK_KARARI | E4: Excel'in rolü açık | F4: HATA / BLOKE | G4: Yönetişim
A5: 2 | B5: Yönetişim | C5: Her model | D5: Risk seviyesi + etki girdileri | E5: Seviye hesaplandı | F5: BLOKE | G5: Sözleşmeler
A6: 3 | B6: Türk Muhasebe Eşlemesi | C6: Finansal model | D6: THP hesap eşleme tablosu | E6: Kritik satırlar THP ile uyumlu | F6: HATA | G6: Sözleşmeler
A7: 4 | B7: Veri ve Anlam Sözleşmeleri | C7: Girdi/KPI varsa | D7: Veri + KPI sözleşmeleri | E7: Kapsam %100 | F7: HATA | G7: Üretim
A8: 5 | B8: Üretim | C8: Sözleşmeler GEÇTİ | D8: Çalışan Excel | E8: Tek gerçek kaynak korunmuş | F8: HATA | G8: Testler
A9: 6 | B9: Görsel/Kullanım Katmanı | C9: Motor hazır | D9: Başlıklar + renk + grafik + yönlendirme | E9: Tüm kullanıcı sayfaları standarda uygun | F9: HATA | G9: Testler
A10: 7 | B10: Testler | C10: Üretim tamam | D10: Formül/OOXML/kimlik/oracle/golden/metamorfik | E10: Uygulanabilir hard gate'ler GEÇTİ | F10: HATA | G10: Kanıt
A11: 8 | B11: Hata-Kontrol Tutarlılığı | C11: Test sonucu var | D11: Hata taraması + kontrol sonuçları | E11: Formül hatası varken GEÇTİ yok | F11: HATA | G11: Kanıt
A12: 9 | B12: Kanıt | C12: Test sonucu var | D12: Makine okunur artefakt + özet | E12: Kanıt fiziksel ve tutarlı | F12: HATA | G12: Kullanıcı Kabulü
A13: 10 | B13: Kullanıcı Kabulü | C13: Kritik görevler | D13: Gerçek ekran davranışı | E13: Kritik görevler %100 | F13: DIŞ_KABUL_GEREKLİ | G13: Ticari
A14: 11 | B14: Ticari Değer | C14: Ürün satılacaksa | D14: ROI + demo + kanıt paketi | E14: Ekonomik değer kanıtlı | F14: UYARI / HATA | G14: Pazar Doğrulama
A15: 12 | B15: Pazar Doğrulama | C15: Pazar iddiası varsa | D15: Ücretli satış/pilot/fiyat kabul kanıtı | E15: Gerçek fiyat kabul kanıtı | F15: UYGULANMAZ / HATA | G15: Yayın

Sheet 02_KONTROL_LISTESI
A1: NİHAİ KONTROL LİSTESİ — KANITSIZ GEÇİŞ YOK
A3: Kontrol No | B3: Kontrol | C3: Beklenen | D3: Zorunlu Kapı? | E3: Sonuç
A4: K01 | B4: Kullanıcının açık talebi öncelikli mi? | C4: Evet | D4: EVET
A5: K02 | B5: Mevcut yapı, formüller ve tek gerçek kaynak korunuyor mu? | C5: Evet, değişiklik gerekçeli | D5: EVET
A6: K03 | B6: Üst aşama HATA ise alt aşama GEÇTİ engelleniyor mu? | C6: Evet | D6: EVET
A7: K04 | B7: Kanıt fiziksel çıktı ve içerik doğrulaması içeriyor mu? | C7: Evet | D7: EVET
A8: K05 | B8: Excel GUI erişimi olmadan kullanıcı görünümü GEÇTİ yazılıyor mu? | C8: Hayır | D8: EVET
A9: K06 | B9: NİHAİ yalnız GEÇTİ / gerekçeli UYGULANMAZ ile mi? | C9: Evet | D9: EVET
A10: K07 | B10: Ekonomik fiyat savunusu pazar doğrulamasından ayrılmış mı? | C10: Evet | D10: EVET
A11: K08 | B11: Prestij için gereksiz modül var mı? | C11: Hayır | D11: HAYIR
A12: K09 | B12: Excel sınırları açık mı? | C12: Evet | D12: EVET
A13: K10 | B13: Teknik kaynak korunuyor mu? | C13: Evet | D13: EVET
A14: K11 | B14: Kullanıcıya görünen tüm metinler Türkçe mi? | C14: Evet | D14: EVET
A15: K12 | B15: Her kullanıcı sayfasında üst başlık var mı? | C15: Evet | D15: EVET
... A34: K31 | B34: Premium vitrin, altyapı kadar güçlü ve satış fiyatını destekleyecek seviyede mi? | C34: Evet | D34: EVET

Sheet 03_GORSEL_TASARIM
A1: GÖRSEL TASARIM VE PREMIUM EXCEL STANDARDI
A3: Alan | B3: Zorunlu Kural | C3: Uygulama | D3: Yasak | E3: Kontrol | F3: Durum
A4: Sayfa başlığı | B4: Her kullanıcı sayfasının en üstünde tek ve açık sayfa başlığı | C4: A1'den başlayan koyu lacivert başlık bandı | D4: Başlıksız sayfa | E4: Başlık kapsama = %100 | F4: ZORUNLU
A5: Sekme renkleri | B5: Sayfalar işlevine göre renk kodlanır | C5: Girdi=mavi, hesap=gri, rapor=lacivert, kontrol=kırmızı, kılavuz=altın | D5: Rastgele renk | E5: Renk semantiği tutarlı | F5: ZORUNLU
A6: Kolon düzeni | B6: Veri blokları bitişik kolonlarda ilerler | C6: Gereksiz boş kolon bırakma; yalnız gerçek bölüm ayrımı varsa kontrollü boşluk | D6: A:C veri, D boş, E:F veri gibi parçalı yapı | E6: Boş kolon taraması | F6: ZORUNLU
A7: Girdi hücreleri | B7: Kullanıcının değiştireceği alan açıkça görünür | C7: Açık sarı dolgu + mavi yazı | D7: Formülle aynı görünüm | E7: Girdi/formül ayrımı | F7: ZORUNLU
A8: Formüller | B8: Hesap hücreleri kullanıcı girdisinden ayrılır | C8: Siyah yazı; sayfalar arası bağlantı yeşil yazı | D8: Hard-code gizleme | E8: Formül sınıfı kontrolü | F8: ZORUNLU
A9: Grafik sayısı | B9: Yönetici ekranında en fazla 3 ana karar grafiği | C9: Trend, karşılaştırma, köprü/dağılım; iş kararına bağlı | D9: Grafik kalabalığı | E9: Grafik başına karar sorusu | F9: ZORUNLU
A10: Grafik stili | B10: Kurumsal ve yüksek okunabilirlik | C10: Beyaz zemin, ince gridline, tek vurgu rengi, açık birim/başlık | D10: 3B, gölge, neon, gökkuşağı renkleri | E10: Görsel inceleme | F10: ZORUNLU
A11: Grafik başlığı | B11: Grafik 'neyi' değil 'ne anlama geldiğini' söyler | C11: Örn: 'Nakit 2028'de kritik eşiğin altına iniyor' | D11: 'Nakit Grafiği' gibi anlamsız başlık | E11: Başlık karar testi | F11: ZORUNLU
A12: Birimler | B12: Tüm finansal görsellerde birim açık | C12: TL, bin TL, milyon TL, %, gün, x | D12: Birim belirsizliği | E12: Birim kapsama %100 | F12: ZORUNLU
A13: Sıfır/negatif | B13: Finansal format standardı | C13: Sıfır='-', negatif kırmızı parantez | D13: -500 veya 0,00 kalabalığı | E13: Format kontrolü | F13: ZORUNLU
A14: Yazı tipi | B14: Tek aile | C14: Aptos veya Segoe UI | D14: Karışık font | E14: Tek font kontrolü | F14: ZORUNLU
... A22: Premium vitrin | B22: Görsel kalite ürün değerinin zorunlu parçasıdır | C22: Kaliteli grafik, gerçek KPI kartı, finansal hiyerarşi, tab rengi, fonksiyonel navigasyon | D22: Sadece doğru hesap yapıp çıplak/varsayılan Excel görünümü bırakmak | E22: Görsel release incelemesi | F22: ZORUNLU

Sheet 04_MUHASEBE_THP
A1: TÜRKİYE MUHASEBE VE TEKDÜZEN HESAP PLANI STANDARDI
A3: Konu | B3: Zorunlu Standart | C3: Örnek Türkçe Ad | D3: THP / Mantık | E3: Hata Riski | F3: Kontrol
A4: Dil | B4: Kullanıcıya görünen finansal terimler Türkçe | C4: Hasılat, Satışların Maliyeti, Brüt Kâr, Faaliyet Giderleri | D4: Türk işletme kullanımına uygun | E4: İngilizce jargon | F4: Terminoloji taraması
A5: Gelir Tablosu | B5: Türk sunum sırası kullanılır | C5: Net Satışlar → Satışların Maliyeti → Brüt Kâr → Faaliyet Giderleri → Faaliyet Kârı | D5: 600/610/611; 620-623; 63x | E5: Yanlış sınıflama | F5: Hesap eşleme
A6: Bilanço | B6: Dönen/Duran Varlık ve Kısa/Uzun Vadeli Yükümlülük ayrımı | C6: Hazır Değerler, Ticari Alacaklar, Stoklar, Mali Borçlar | D6: 1xx / 2xx / 3xx / 4xx / 5xx | E6: Vade sınıfı hatası | F6: Bilanço eşitliği
A7: Nakit Akışı | B7: İşletme/Yatırım/Finansman nakit akışları ayrılır | C7: Faaliyetlerden Nakit, Yatırım Harcamaları, Finansman Nakit Akışı | D7: Dolaylı/doğrudan yöntem açık seçilir | E7: Kâr = nakit sanılması | F7: Nakit devri
A8: Ticari Alacaklar | B8: Cari ve vade mantığı korunur | C8: 120 Alıcılar | D8: 120 | E8: Tahakkuk/nakit karışması | F8: Alacak devir kontrolü
A9: Ticari Borçlar | B9: Tedarikçi borcu ayrı izlenir | C9: 320 Satıcılar | D9: 320 | E9: Gider/ödeme karışması | F9: Borç devir kontrolü
A10: Kasa/Banka | B10: Hazır değerler ayrı izlenir | C10: 100 Kasa, 102 Bankalar | D10: 100 / 102 | E10: Virmanla toplam nakdin değişmesi | F10: Virman değişmezi
A11: Stok | B11: Dikeye uygun stok türü | C11: 150 İlk Madde ve Malzeme, 153 Ticari Mallar | D11: 15x | E11: Maliyet ve stok hareketinin kopması | F11: Stok devri
A12: Maddi Duran Varlık | B12: Yatırım harcaması ve amortisman bağlantılı | C12: 253 Tesis Makine Cihazlar, 255 Demirbaşlar, 257 Birikmiş Amortismanlar | D12: 25x | E12: Yatırım/gider karışması | F12: Net defter değeri devri
A13: Mali Borçlar | B13: Kısa/uzun vadeli borç ayrımı | C13: 300 Banka Kredileri / 400 Banka Kredileri | D13: 300 / 400 | E13: Vade sınıfı yanlış | F13: Borç devri
A14: Özkaynak | B14: Sermaye ve geçmiş yıl kârları ayrı | C14: 500 Sermaye, 570 Geçmiş Yıllar Kârları, 590 Dönem Net Kârı | D14: 5xx | E14: Net kâr bağının kopması | F14: Özkaynak devri
... A18: İstisna | B18: TFRS özel ürün varsa fark açık yazılır | C18: Tekdüzen raporlama ≠ TFRS finansal tablo sunumu | D18: Amaç belirtilir | E18: Standartları karıştırma | F18: Model amacı kontrolü

Sheet 05_KARAR_SATIS
A1: KARAR, GÜVEN VE SATIŞA HAZIRLIK STANDARDI
A3: Alan | B3: Müşteri Sorusu | C3: Zorunlu Ürün Davranışı | D3: Kanıt | E3: Başarısızlık Durumu | F3: Kapı
A4: 5 saniye | B4: Bu ürün neyi çözüyor? | C4: İlk ekranda hedef kullanıcı + pahalı problem + sonuç görünür | D4: Başlık + alt mesaj + gerçek ekran | E4: Ürün yalnız teknik isim | F4: HATA
A5: Acı | B5: Sorun bana neye mal oluyor? | C5: Mümkünse müşterinin kendi verisiyle parasal/zaman etkisi hesaplanır | D5: ROI/acı hesaplama yöntemi | E5: Uydurma tasarruf | F5: HATA
A6: Karar | B6: Bu bilgiyle ne yapacağım? | C6: Her kritik KPI aksiyona bağlanır | D6: KARAR_KUYRUGU | E6: Sadece rapor | F6: HATA
A7: Güven | B7: Bu sayıya neden inanayım? | C7: Kaynak, formül mantığı, kontrol ve son doğrulama görünür | D7: Kontroller + kaynak izi + sürüm | E7: Prestij kelimesi | F7: HATA
A8: Referans | B8: Müşteri yorumu yoksa ne göstereceğim? | C8: Önce/Sonra + Karar Vakası + Hata Önleme Vakası üretilir | D8: Demo/örnek çıktı | E8: Kanıtsız iddia | F8: HATA
A9: Senaryo | B9: Ne olursa işler bozulur? | C9: Baz/Aşağı/Yukarı veya uygun stres senaryosu | D9: Senaryo karşılaştırma | E9: Dekoratif senaryo | F9: HATA
A10: Ters stres | B10: Hangi eşikte karar kırılır? | C10: En az bir kritik sürücü için kırılma eşiği | D10: Kırılma eşiği tablosu | E10: Sadece +/- %10 | F10: UYARI/HATA
A11: Hata tutarlılığı | B11: Formül hata verirse ne olur? | C11: Kontrol GEÇTİ veremez; BLOKE/HATA üretir | D11: Hata taraması | E11: Hata + GEÇTİ birlikte | F11: HATA
A12: Karar motoru | B12: Ne oldu, neden oldu? | C12: Sorun + neden + parasal etki + aksiyon + son tarih | D12: Karar tablosu | E12: Boş sayfa / isim düzeyi modül | F12: HATA
A13: Yönetici özeti | B13: 5 saniyede ne görmeliyim? | C13: Bugün / ne değişti / ne bozulacak / neden / ne yapmalıyım / güven | D13: Yönetici özeti ekranı | E13: KPI kutusu yığını | F13: HATA
A14: Teklif | B14: Neden satın almalıyım? | C14: Dosya özellikleri yerine sonuç ve kaçınılan maliyet sunulur | D14: Ürün sayfası kanıt eşlemesi | E14: Özellik listesiyle satış | F14: HATA
... A19: Pazar kanıtı | B19: Piyasa gerçekten ödüyor mu? | C19: Satış/pilot/LOI/fiyat kabulü olmadan pazar doğrulandı yazılmaz | D19: Gerçek işlem kanıtı | E19: Tahmini talep = satış kabulü | F19: HATA

Sheet KAPAK
A1: KAPAK — Depo Doluluk & Lokasyon Optimizasyonu
A3: Depo Doluluk & Lokasyon Optimizasyonu
A4: Depo lokasyonlarında doluluk yüzdesini ve koridor verimini izler; günlük saha girişi ≤6 alan; lokasyon sağlık skoru ve alarm kuyruğu üretir; UYGUN / DİKKAT / KRİTİK / VERİ YOK kararı verir.
A6: Bu ürün ne sağlar?
A7: • Lokasyon bazlı doluluk % ve koridor verim skoru
A8: • Günlük saha girişi en fazla 6 alan — 30 saniye hedefi
A9: • Lokasyon sağlık skoru formülle veriden türer (sabit skor yok)
A10: • 12 aylık sezonsal doluluk zinciri ve alarm eşiği kuyruğu
A11: • Makrosuz, çevrimdışı; WMS/API bağı yok
A13: Kimler için?
A14: • Saha / depo operatörü — günlük doluluk-palet-pick satırı
A15: • Depo müdürü — doluluk % ve karar panosu
... A21: Sürüm 1.0.0 | Kod: DDL-PRO | Lisans: Tek kullanıcı | ExcelArşiv

Sheet VARLIKLAR
A1: VARLIKLAR — Depo Doluluk & Lokasyon Optimizasyonu
A3: Lokasyon kartları — her varlığın tek kimliği vardır
A4: Sonraki Kimlik | B4: =ddl_sonrakiKimlik
A5: VarlikId | B5: KoridorAd | C5: Bolge | D5: Tip | E5: KapasiteM3_m3 | F5: KapasitePalet_adet | G5: HedefDolulukPct_pct | H5: Aktif | I5: OrtDoluluk | J5: OrtPick | K5: OrtVerim | L5: SaglikSkor
A6: LOC-00001 | B6: K-A01 | C6: Kuzey | D6: Raf | E6: 140 | F6: 90 | G6: 0.85 | H6: EVET | I6: =IF($A6="","",IFERROR(AVERAGEIF(tblGunluk[VarlikId],$A6,tblGunluk[DolulukPct_pct]),0)) | J6: =IF($A6="","",IFERROR(AVERAGEIF(tblGunluk[VarlikId],$A6,tblGunluk[PickAdet_adet]),0)) | K6: =IF($A6="","",IFERROR(AVERAGEIF(tblGunluk[VarlikId],$A6,tblGunluk[FormulVerim_pct]),0)) | L6: =IF($A6="","",MAX(0,MIN(100,ddl_kaliteTaban-IF($I6>ddl_esikDoluluk,ddl_kaliteCeza,0)-IF($K6<ddl_esikVerim,ddl_kaliteCeza,0)-COUNTIFS(tblGunluk[VarlikId],$A6,tblGunluk[AlarmBayrak],"ALARM")*ddl_kaliteSapma-IF($H6="HAYIR",ddl_kaliteCeza,0))))
A7: LOC-00002 | B7: K-A02 | C7: Kuzey | D7: Raf | E7: 120 | F7: 80 | G7: 0.85 | H7: EVET | I7: =IF($A7="","",IFERROR(AVERAGEIF(tblGunluk[VarlikId],$A7,tblGunluk[DolulukPct_pct]),0)) | J7: =IF($A7="","",IFERROR(AVERAGEIF(tblGunluk[VarlikId],$A7,tblGunluk[PickAdet_adet]),0)) | K7: =IF($A7="","",IFERROR(AVERAGEIF(tblGunluk[VarlikId],$A7,tblGunluk[FormulVerim_pct]),0)) | L7: =IF($A7="","",MAX(0,MIN(100,ddl_kaliteTaban-IF($I7>ddl_esikDoluluk,ddl_kaliteCeza,0)-IF($K7<ddl_esikVerim,ddl_kaliteCeza,0)-COUNTIFS(tblGunluk[VarlikId],$A7,tblGunluk[AlarmBayrak],"ALARM")*ddl_kaliteSapma-IF($H7="HAYIR",ddl_kaliteCeza,0))))
A8: LOC-00003 | B8: K-B01 | C8: Guney | D8: Zemin | E8: 200 | F8: 120 | G8: 0.8 | H8: EVET | I8: =IF($A8="","",IFERROR(AVERAGEIF(tblGunluk[VarlikId],$A8,tblGunluk[DolulukPct_pct]),0)) | J8: =IF($A8="","",IFERROR(AVERAGEIF(tblGunluk[VarlikId],$A8,tblGunluk[PickAdet_adet]),0)) | K8: =IF($A8="","",IFERROR(AVERAGEIF(tblGunluk[VarlikId],$A8,tblGunluk[FormulVerim_pct]),0)) | L8: =IF($A8="","",MAX(0,MIN(100,ddl_kaliteTaban-IF($I8>ddl_esikDoluluk,ddl_kaliteCeza,0)-IF($K8<ddl_esikVerim,ddl_kaliteCeza,0)-COUNTIFS(tblGunluk[VarlikId],$A8,tblGunluk[AlarmBayrak],"ALARM")*ddl_kaliteSapma-IF($H8="HAYIR",ddl_kaliteCeza,0))))
A9: LOC-00004 | B9: K-B02 | C9: Guney | D9: Raf | E9: 110 | F9: 70 | G9: 0.85 | H9: EVET | I9: =IF($A9="","",IFERROR(AVERAGEIF(tblGunluk[VarlikId],$A9,tblGunluk[DolulukPct_pct]),0)) | J9: =IF($A9="","",IFERROR(AVERAGEIF(tblGunluk[VarlikId],$A9,tblGunluk[PickAdet_adet]),0)) | K9: =IF($A9="","",IFERROR(AVERAGEIF(tblGunluk[VarlikId],$A9,tblGunluk[FormulVerim_pct]),0)) | L9: =IF($A9="","",MAX(0,MIN(100,ddl_kaliteTaban-IF($I9>ddl_esikDoluluk,ddl_kaliteCeza,0)-IF($K9<ddl_esikVerim,ddl_kaliteCeza,0)-COUNTIFS(tblGunluk[VarlikId],$A9,tblGunluk[AlarmBayrak],"ALARM")*ddl_kaliteSapma-IF($H9="HAYIR",ddl_kaliteCeza,0))))
A10: LOC-00005 | B10: K-C01 | C10: Dogu | D10: Mezanin | E10: 90 | F10: 55 | G10: 0.8 | H10: EVET | I10: =IF($A10="","",IFERROR(AVERAGEIF(tblGunluk[VarlikId],$A10,tblGunluk[DolulukPct_pct]),0)) | J10: =IF($A10="","",IFERROR(AVERAGEIF(tblGunluk[VarlikId],$A10,tblGunluk[PickAdet_adet]),0)) | K10: =IF($A10="","",IFERROR(AVERAGEIF(tblGunluk[VarlikId],$A10,tblGunluk[FormulVerim_pct]),0)) | L10: =IF($A10="","",MAX(0,MIN(100,ddl_kaliteTaban-IF($I10>ddl_esikDoluluk,ddl_kaliteCeza,0)-IF($K10<ddl_esikVerim,ddl_kaliteCeza,0)-COUNTIFS(tblGunluk[VarlikId],$A10,tblGunluk[AlarmBayrak],"ALARM")*ddl_kaliteSapma-IF($H10="HAYIR",ddl_kaliteCeza,0))))
A11: LOC-00006 | B11: K-C02 | C11: Dogu | D11: Raf | E11: 130 | F11: 85 | G11: 0.85 | H11: EVET | I11: =IF($A11="","",IFERROR(AVERAGEIF(tblGunluk[VarlikId],$A11,tblGunluk[DolulukPct_pct]),0)) | J11: =IF($A11="","",IFERROR(AVERAGEIF(tblGunluk[VarlikId],$A11,tblGunluk[PickAdet_adet]),0)) | K11: =IF($A11="","",IFERROR(AVERAGEIF(tblGunluk[VarlikId],$A11,tblGunluk[FormulVerim_pct]),0)) | L11: =IF($A11="","",MAX(0,MIN(100,ddl_kaliteTaban-IF($I11>ddl_esikDoluluk,ddl_kaliteCeza,0)-IF($K11<ddl_esikVerim,ddl_kaliteCeza,0)-COUNTIFS(tblGunluk[VarlikId],$A11,tblGunluk[AlarmBayrak],"ALARM")*ddl_kaliteSapma-IF($H11="HAYIR",ddl_kaliteCeza,0))))
A12: LOC-00007 | B12: K-D01 | C12: Bati | D12: Zemin | E12: 180 | F12: 110 | G12: 0.75 | H12: EVET | I12: =IF($A12="","",IFERROR(AVERAGEIF(tblGunluk[VarlikId],$A12,tblGunluk[DolulukPct_pct]),0)) | J12: =IF($A12="","",IFERROR(AVERAGEIF(tblGunluk[VarlikId],$A12,tblGunluk[PickAdet_adet]),0)) | K12: =IF($A12="","",IFERROR(AVERAGEIF(tblGunluk[VarlikId],$A12,tblGunluk[FormulVerim_pct]),0)) | L12: =IF($A12="","",MAX(0,MIN(100,ddl_kaliteTaban-IF($I12>ddl_esikDoluluk,ddl_kaliteCeza,0)-IF($K12<ddl_esikVerim,ddl_kaliteCeza,0)-COUNTIFS(tblGunluk[VarlikId],$A12,tblGunluk[AlarmBayrak],"ALARM")*ddl_kaliteSapma-IF($H12="HAYIR",ddl_kaliteCeza,0))))
A13: LOC-00008 | B13: K-D02 | C13: Bati | D13: Raf | E13: 100 | F13: 65 | G13: 0.85 | H13: EVET | I13: =IF($A13="","",IFERROR(AVERAGEIF(tblGunluk[VarlikId],$A13,tblGunluk[DolulukPct_pct]),0)) | J13: =IF($A13="","",IFERROR(AVERAGEIF(tblGunluk[VarlikId],$A13,tblGunluk[PickAdet_adet]),0)) | K13: =IF($A13="","",IFERROR(AVERAGEIF(tblGunluk[VarlikId],$A13,tblGunluk[FormulVerim_pct]),0)) | L13: =IF($A13="","",MAX(0,MIN(100,ddl_kaliteTaban-IF($I13>ddl_esikDoluluk,ddl_kaliteCeza,0)-IF($K13<ddl_esikVerim,ddl_kaliteCeza,0)-COUNTIFS(tblGunluk[VarlikId],$A13,tblGunluk[AlarmBayrak],"ALARM")*ddl_kaliteSapma-IF($H13="HAYIR",ddl_kaliteCeza,0))))
I14: =IF($A14="","",IFERROR(AVERAGEIF(tblGunluk[VarlikId],$A14,tblGunluk[DolulukPct_pct]),0)) | J14: =IF($A14="","",IFERROR(AVERAGEIF(tblGunluk[VarlikId],$A14,tblGunluk[PickAdet_adet]),0)) | K14: =IF($A14="","",IFERROR(AVERAGEIF(tblGunluk[VarlikId],$A14,tblGunluk[FormulVerim_pct]),0)) | L14: =IF($A14="","",MAX(0,MIN(100,ddl_kaliteTaban-IF($I14>ddl_esikDoluluk,ddl_kaliteCeza,0)-IF($K14<ddl_esikVerim,ddl_kaliteCeza,0)-COUNTIFS(tblGunluk[VarlikId],$A14,tblGunluk[AlarmBayrak],"ALARM")*ddl_kaliteSapma-IF($H14="HAYIR",ddl_kaliteCeza,0))))
I15: =IF($A15="","",IFERROR(AVERAGEIF(tblGunluk[VarlikId],$A15,tblGunluk[DolulukPct_pct]),0)) | J15: =IF($A15="","",IFERROR(AVERAGEIF(tblGunluk[VarlikId],$A15,tblGunluk[PickAdet_adet]),0)) | K15: =IF($A15="","",IFERROR(AVERAGEIF(tblGunluk[VarlikId],$A15,tblGunluk[FormulVerim_pct]),0)) | L15: =IF($A15="","",MAX(0,MIN(100,ddl_kaliteTaban-IF($I15>ddl_esikDoluluk,ddl_kaliteCeza,0)-IF($K15<ddl_esikVerim,ddl_kaliteCeza,0)-COUNTIFS(tblGunluk[VarlikId],$A15,tblGunluk[AlarmBayrak],"ALARM")*ddl_kaliteSapma-IF($H15="HAYIR",ddl_kaliteCeza,0))))
I16: =IF($A16="","",IFERROR(AVERAGEIF(tblGunluk[VarlikId],$A16,tblGunluk[DolulukPct_pct]),0)) | J16: =IF($A16="","",IFERROR(AVERAGEIF(tblGunluk[VarlikId],$A16,tblGunluk[PickAdet_adet]),0)) | K16: =IF($A16="","",IFERROR(AVERAGEIF(tblGunluk[VarlikId],$A16,tblGunluk[FormulVerim_pct]),0)) | L16: =IF($A16="","",MAX(0,MIN(100,ddl_kaliteTaban-IF($I16>ddl_esikDoluluk,ddl_kaliteCeza,0)-IF($K16<ddl_esikVerim,ddl_kaliteCeza,0)-COUNTIFS(tblGunluk[VarlikId],$A16,tblGunluk[AlarmBayrak],"ALARM")*ddl_kaliteSapma-IF($H16="HAYIR",ddl_kaliteCeza,0))))
I17: =IF($A17="","",IFERROR(AVERAGEIF(tblGunluk[VarlikId],$A17,tblGunluk[DolulukPct_pct]),0)) | J17: =IF($A17="","",IFERROR(AVERAGEIF(tblGunluk[VarlikId],$A17,tblGunluk[PickAdet_adet]),0)) | K17: =IF($A17="","",IFERROR(AVERAGEIF(tblGunluk[VarlikId],$A17,tblGunluk[FormulVerim_pct]),0)) | L17: =IF($A17="","",MAX(0,MIN(100,ddl_kaliteTaban-IF($I17>ddl_esikDoluluk,ddl_kaliteCeza,0)-IF($K17<ddl_esikVerim,ddl_kaliteCeza,0)-COUNTIFS(tblGunluk[VarlikId],$A17,tblGunluk[AlarmBayrak],"ALARM")*ddl_kaliteSapma-IF($H17="HAYIR",ddl_kaliteCeza,0))))
I18: =IF($A18="","",IFERROR(AVERAGEIF(tblGunluk[VarlikId],$A18,tblGunluk[DolulukPct_pct]),0)) | J18: =IF($A18="","",IFERROR(AVERAGEIF(tblGunluk[VarlikId],$A18,tblGunluk[PickAdet_adet]),0)) | K18: =IF($A18="","",IFERROR(AVERAGEIF(tblGunluk[VarlikId],$A18,tblGunluk[FormulVerim_pct]),0)) | L18: =IF($A18="","",MAX(0,MIN(100,ddl_kaliteTaban-IF($I18>ddl_esikDoluluk,ddl_kaliteCeza,0)-IF($K18<ddl_esikVerim,ddl_kaliteCeza,0)-COUNTIFS(tblGunluk[VarlikId],$A18,tblGunluk[AlarmBayrak],"ALARM")*ddl_kaliteSapma-IF($H18="HAYIR",ddl_kaliteCeza,0))))
I19: =IF($A19="","",IFERROR(AVERAGEIF(tblGunluk[VarlikId],$A19,tblGunluk[DolulukPct_pct]),0)) | J19: =IF($A19="","",IFERROR(AVERAGEIF(tblGunluk[VarlikId],$A19,tblGunluk[PickAdet_adet]),0)) | K19: =IF($A19="","",IFERROR(AVERAGEIF(tblGunluk[VarlikId],$A19,tblGunluk[FormulVerim_pct]),0)) | L19: =IF($A19="","",MAX(0,MIN(100,ddl_kaliteTaban-IF($I19>ddl_esikDoluluk,ddl_kaliteCeza,0)-IF($K19<ddl_esikVerim,ddl_kaliteCeza,0)-COUNTIFS(tblGunluk[VarlikId],$A19,tblGunluk[AlarmBayrak],"ALARM")*ddl_kaliteSapma-IF($H19="HAYIR",ddl_kaliteCeza,0))))
I20: =IF($A20="","",IFERROR(AVERAGEIF(tblGunluk[VarlikId],$A20,tblGunluk[DolulukPct_pct]),0)) | J20: =IF($A20="","",IFERROR(AVERAGEIF(tblGunluk[VarlikId],$A20,tblGunluk[PickAdet_adet]),0)) | K20: =IF($A20="","",IFERROR(AVERAGEIF(tblGunluk[VarlikId],$A20,tblGunluk[FormulVerim_pct]),0)) | L20: =IF($A20="","",MAX(0,MIN(100,ddl_kaliteTaban-IF($I20>ddl_esikDoluluk,ddl_kaliteCeza,0)-IF($K20<ddl_esikVerim,ddl_kaliteCeza,0)-COUNTIFS(tblGunluk[VarlikId],$A20,tblGunluk[AlarmBayrak],"ALARM")*ddl_kaliteSapma-IF($H20="HAYIR",ddl_kaliteCeza,0))))
I21: =IF($A21="","",IFERROR(AVERAGEIF(tblGunluk[VarlikId],$A21,tblGunluk[DolulukPct_pct]),0)) | J21: =IF($A21="","",IFERROR(AVERAGEIF(tblGunluk[VarlikId],$A21,tblGunluk[PickAdet_adet]),0)) | K21: =IF($A21="","",IFERROR(AVERAGEIF(tblGunluk[VarlikId],$A21,tblGunluk[FormulVerim_pct]),0)) | L21: =IF($A21="","",MAX(0,MIN(100,ddl_kaliteTaban-IF($I21>ddl_esikDoluluk,ddl_kaliteCeza,0)-IF($K21<ddl_esikVerim,ddl_kaliteCeza,0)-COUNTIFS(tblGunluk[VarlikId],$A21,tblGunluk[AlarmBayrak],"ALARM")*ddl_kaliteSapma-IF($H21="HAYIR",ddl_kaliteCeza,0))))
I22: =IF($A22="","",IFERROR(AVERAGEIF(tblGunluk[VarlikId],$A22,tblGunluk[DolulukPct_pct]),0)) | J22: =IF($A22="","",IFERROR(AVERAGEIF(tblGunluk[VarlikId],$A22,tblGunluk[PickAdet_adet]),0)) | K22: =IF($A22="","",IFERROR(AVERAGEIF(tblGunluk[VarlikId],$A22,tblGunluk[FormulVerim_pct]),0)) | L22: =IF($A22="","",MAX(0,MIN(100,ddl_kaliteTaban-IF($I22>ddl_esikDoluluk,ddl_kaliteCeza,0)-IF($K22<ddl_esikVerim,ddl_kaliteCeza,0)-COUNTIFS(tblGunluk[VarlikId],$A22,tblGunluk[AlarmBayrak],"ALARM")*ddl_kaliteSapma-IF($H22="HAYIR",ddl_kaliteCeza,0))))
I23: =IF($A23="","",IFERROR(AVERAGEIF(tblGunluk[VarlikId],$A23,tblGunluk[DolulukPct_pct]),0)) | J23: =IF($A23="","",IFERROR(AVERAGEIF(tblGunluk[VarlikId],$A23,tblGunluk[PickAdet_adet]),0)) | K23: =IF($A23="","",IFERROR(AVERAGEIF(tblGunluk[VarlikId],$A23,tblGunluk[FormulVerim_pct]),0)) | L23: =IF($A23="","",MAX(0,MIN(100,ddl_kaliteTaban-IF($I23>ddl_esikDoluluk,ddl_kaliteCeza,0)-IF($K23<ddl_esikVerim,ddl_kaliteCeza,0)-COUNTIFS(tblGunluk[VarlikId],$A23,tblGunluk[AlarmBayrak],"ALARM")*ddl_kaliteSapma-IF($H23="HAYIR",ddl_kaliteCeza,0))))
I24: =IF($A24="","",IFERROR(AVERAGEIF(tblGunluk[VarlikId],$A24,tblGunluk[DolulukPct_pct]),0)) | J24: =IF($A24="","",IFERROR(AVERAGEIF(tblGunluk[VarlikId],$A24,tblGunluk[PickAdet_adet]),0)) | K24: =IF($A24="","",IFERROR(AVERAGEIF(tblGunluk[VarlikId],$A24,tblGunluk[FormulVerim_pct]),0)) | L24: =IF($A24="","",MAX(0,MIN(100,ddl_kaliteTaban-IF($I24>ddl_esikDoluluk,ddl_kaliteCeza,0)-IF($K24<ddl_esikVerim,ddl_kaliteCeza,0)-COUNTIFS(tblGunluk[VarlikId],$A24,tblGunluk[AlarmBayrak],"ALARM")*ddl_kaliteSapma-IF($H24="HAYIR",ddl_kaliteCeza,0))))
I25: =IF($A25="","",IFERROR(AVERAGEIF(tblGunluk[VarlikId],$A25,tblGunluk[DolulukPct_pct]),0)) | J25: =IF($A25="","",IFERROR(AVERAGEIF(tblGunluk[VarlikId],$A25,tblGunluk[PickAdet_adet]),0)) | K25: =IF($A25="","",IFERROR(AVERAGEIF(tblGunluk[VarlikId],$A25,tblGunluk[FormulVerim_pct]),0)) | L25: =IF($A25="","",MAX(0,MIN(100,ddl_kaliteTaban-IF($I25>ddl_esikDoluluk,ddl_kaliteCeza,0)-IF($K25<ddl_esikVerim,ddl_kaliteCeza,0)-COUNTIFS(tblGunluk[VarlikId],$A25,tblGunluk[AlarmBayrak],"ALARM")*ddl_kaliteSapma-IF($H25="HAYIR",ddl_kaliteCeza,0))))
... I255: =IF($A255="","",IFERROR(AVERAGEIF(tblGunluk[VarlikId],$A255,tblGunluk[DolulukPct_pct]),0)) | J255: =IF($A255="","",IFERROR(AVERAGEIF(tblGunluk[VarlikId],$A255,tblGunluk[PickAdet_adet]),0)) | K255: =IF($A255="","",IFERROR(AVERAGEIF(tblGunluk[VarlikId],$A255,tblGunluk[FormulVerim_pct]),0)) | L255: =IF($A255="","",MAX(0,MIN(100,ddl_kaliteTaban-IF($I255>ddl_esikDoluluk,ddl_kaliteCeza,0)-IF($K255<ddl_esikVerim,ddl_kaliteCeza,0)-COUNTIFS(tblGunluk[VarlikId],$A255,tblGunluk[AlarmBayrak],"ALARM")*ddl_kaliteSapma-IF($H255="HAYIR",ddl_kaliteCeza,0))))

Sheet GUNLUK_GIRIS
A1: GUNLUK GIRIS — Depo Doluluk & Lokasyon Optimizasyonu
A3: GÜNLÜK saha girişi — satır başına en fazla 6 manuel alan (S02)
A5: SatirId | B5: VarlikId | C5: Tarih | D5: DolulukPct_pct | E5: PaletAdet_adet | F5: PickAdet_adet | G5: OlayTuru | H5: FormulKapasite_pct | I5: FormulVerim_pct | J5: FormulBosPalet_adet | K5: SaglikSkor_puan | L5: AlarmBayrak | M5: FormulKayitDolu_adet | N5: FormulYetim
A6: GLG-00001 | B6: LOC-00001 | C6: 46242 | D6: 0.63 | E6: 57 | F6: 31 | G6: MAL_KABUL | H6: =IF($A6="","",IFERROR($E6/IFERROR(SUMIF(tblVarliklar[VarlikId],$B6,tblVarliklar[KapasitePalet_adet]),ddl_varsayilanKapasitePalet),0)) | I6: =IF($A6="","",IFERROR($F6/MAX($E6,1)*ddl_verimCarpan,0)) | J6: =IF($A6="","",IFERROR(IFERROR(SUMIF(tblVarliklar[VarlikId],$B6,tblVarliklar[KapasitePalet_adet]),ddl_varsayilanKapasitePalet)-$E6,0)) | K6: =IF($A6="","",MAX(0,MIN(100,ddl_kaliteTaban-IF($D6>ddl_esikDoluluk,ddl_kaliteCeza,0)-IF($I6<ddl_esikVerim,ddl_kaliteSapma,0)-IF($N6="YETIM",ddl_kaliteCeza,0)))) | L6: =IF($A6="","",IF(OR($D6>ddl_esikDoluluk,$I6<ddl_esikVerim,$K6<ddl_esikSaglik),"ALARM","UYGUN")) | M6: =IF($A6="","",1) | N6: =IF($A6="","",IF(OR($B6="",COUNTIF(tblVarliklar[VarlikId],$B6)=0),"YETIM","TAMAM"))
A7: GLG-00002 | B7: LOC-00002 | C7: 46239 | D7: 0.71 | E7: 58 | F7: 42 | G7: TOPLAMA | H7: =IF($A7="","",IFERROR($E7/IFERROR(SUMIF(tblVarliklar[VarlikId],$B7,tblVarliklar[KapasitePalet_adet]),ddl_varsayilanKapasitePalet),0)) | I7: =IF($A7="","",IFERROR($F7/MAX($E7,1)*ddl_verimCarpan,0)) | J7: =IF($A7="","",IFERROR(IFERROR(SUMIF(tblVarliklar[VarlikId],$B7,tblVarliklar[KapasitePalet_adet]),ddl_varsayilanKapasitePalet)-$E7,0)) | K7: =IF($A7="","",MAX(0,MIN(100,ddl_kaliteTaban-IF($D7>ddl_esikDoluluk,ddl_kaliteCeza,0)-IF($I7<ddl_esikVerim,ddl_kaliteSapma,0)-IF($N7="YETIM",ddl_kaliteCeza,0)))) | L7: =IF($A7="","",IF(OR($D7>ddl_esikDoluluk,$I7<ddl_esikVerim,$K7<ddl_esikSaglik),"ALARM","UYGUN")) | M7: =IF($A7="","",1) | N7: =IF($A7="","",IF(OR($B7="",COUNTIF(tblVarliklar[VarlikId],$B7)=0),"YETIM","TAMAM"))
A8: GLG-00003 | B8: LOC-00003 | C8: 46236 | D8: 0.7 | E8: 87 | F8: 53 | G8: SEVK | H8: =IF($A8="","",IFERROR($E8/IFERROR(SUMIF(tblVarliklar[VarlikId],$B8,tblVarliklar[KapasitePalet_adet]),ddl_varsayilanKapasitePalet),0)) | I8: =IF($A8="","",IFERROR($F8/MAX($E8,1)*ddl_verimCarpan,0)) | J8: =IF($A8="","",IFERROR(IFERROR(SUMIF(tblVarliklar[VarlikId],$B8,tblVarliklar[KapasitePalet_adet]),ddl_varsayilanKapasitePalet)-$E8,0)) | K8: =IF($A8="","",MAX(0,MIN(100,ddl_kaliteTaban-IF($D8>ddl_esikDoluluk,ddl_kaliteCeza,0)-IF($I8<ddl_esikVerim,ddl_kaliteSapma,0)-IF($N8="YETIM",ddl_kaliteCeza,0)))) | L8: =IF($A8="","",IF(OR($D8>ddl_esikDoluluk,$I8<ddl_esikVerim,$K8<ddl_esikSaglik),"ALARM","UYGUN")) | M8: =IF($A8="","",1) | N8: =IF($A8="","",IF(OR($B8="",COUNTIF(tblVarliklar[VarlikId],$B8)=0),"YETIM","TAMAM"))
A9: GLG-00004 | B9: LOC-00004 | C9: 46233 | D9: 0.78 | E9: 54 | F9: 64 | G9: STOK_DUZELTME | H9: =IF($A9="","",IFERROR($E9/IFERROR(SUMIF(tblVarliklar[VarlikId],$B9,tblVarliklar[KapasitePalet_adet]),ddl_varsayilanKapasitePalet),0)) | I9: =IF($A9="","",IFERROR($F9/MAX($E9,1)*ddl_verimCarpan,0)) | J9: =IF($A9="","",IFERROR(IFERROR(SUMIF(tblVarliklar[VarlikId],$B9,tblVarliklar[KapasitePalet_adet]),ddl_varsayilanKapasitePalet)-$E9,0)) | K9: =IF($A9="","",MAX(0,MIN(100,ddl_kaliteTaban-IF($D9>ddl_esikDoluluk,ddl_kaliteCeza,0)-IF($I9<ddl_esikVerim,ddl_kaliteSapma,0)-IF($N9="YETIM",ddl_kaliteCeza,0)))) | L9: =IF($A9="","",IF(OR($D9>ddl_esikDoluluk,$I9<ddl_esikVerim,$K9<ddl_esikSaglik),"ALARM","UYGUN")) | M9: =IF($A9="","",1) | N9: =IF($A9="","",IF(OR($B9="",COUNTIF(tblVarliklar[VarlikId],$B9)=0),"YETIM","TAMAM"))
A10: GLG-00005 | B10: LOC-00005 | C10: 46230 | D10: 0.86 | E10: 48 | F10: 60 | G10: DIGER | H10: =IF($A10="","",IFERROR($E10/IFERROR(SUMIF(tblVarliklar[VarlikId],$B10,tblVarliklar[KapasitePalet_adet]),ddl_varsayilanKapasitePalet),0)) | I10: =IF($A10="","",IFERROR($F10/MAX($E10,1)*ddl_verimCarpan,0)) | J10: =IF($A10="","",IFERROR(IFERROR(SUMIF(tblVarliklar[VarlikId],$B10,tblVarliklar[KapasitePalet_adet]),ddl_varsayilanKapasitePalet)-$E10,0)) | K10: =IF($A10="","",MAX(0,MIN(100,ddl_kaliteTaban-IF($D10>ddl_esikDoluluk,ddl_kaliteCeza,0)-IF($I10<ddl_esikVerim,ddl_kaliteSapma,0)-IF($N10="YETIM",ddl_kaliteCeza,0)))) | L10: =IF($A10="","",IF(OR($D10>ddl_esikDoluluk,$I10<ddl_esikVerim,$K10<ddl_esikSaglik),"ALARM","UYGUN")) | M10: =IF($A10="","",1) | N10: =IF($A10="","",IF(OR($B10="",COUNTIF(tblVarliklar[VarlikId],$B10)=0),"YETIM","TAMAM"))
A11: GLG-00006 | B11: LOC-00006 | C11: 46227 | D11: 0.85 | E11: 74 | F11: 71 | G11: SAYIM | H11: =IF($A11="","",IFERROR($E11/IFERROR(SUMIF(tblVarliklar[VarlikId],$B11,tblVarliklar[KapasitePalet_adet]),ddl_varsayilanKapasitePalet),0)) | I11: =IF($A11="","",IFERROR($F11/MAX($E11,1)*ddl_verimCarpan,0)) | J11: =IF($A11="","",IFERROR(IFERROR(SUMIF(tblVarliklar[VarlikId],$B11,tblVarliklar[KapasitePalet_adet]),ddl_varsayilanKapasitePalet)-$E11,0)) | K11: =IF($A11="","",MAX(0,MIN(100,ddl_kaliteTaban-IF($D11>ddl_esikDoluluk,ddl_kaliteCeza,0)-IF($I11<ddl_esikVerim,ddl_kaliteSapma,0)-IF($N11="YETIM",ddl_kaliteCeza,0)))) | L11: =IF($A11="","",IF(OR($D11>ddl_esikDoluluk,$I11<ddl_esikVerim,$K11<ddl_esikSaglik),"ALARM","UYGUN")) | M11: =IF($A11="","",1) | N11: =IF($A11="","",IF(OR($B11="",COUNTIF(tblVarliklar[VarlikId],$B11)=0),"YETIM","TAMAM"))
A12: GLG-00007 | B12: LOC-00007 | C12: 46224 | D12: 0.58 | E12: 66 | F12: 82 | G12: MAL_KABUL | H12: =IF($A12="","",IFERROR($E12/IFERROR(SUMIF(tblVarliklar[VarlikId],$B12,tblVarliklar[KapasitePalet_adet]),ddl_varsayilanKapasitePalet),0)) | I12: =IF($A12="","",IFERROR($F12/MAX($E12,1)*ddl_verimCarpan,0)) | J12: =IF($A12="","",IFERROR(IFERROR(SUMIF(tblVarliklar[VarlikId],$B12,tblVarliklar[KapasitePalet_adet]),ddl_varsayilanKapasitePalet)-$E12,0)) | K12: =IF($A12="","",MAX(0,MIN(100,ddl_kaliteTaban-IF($D12>ddl_esikDoluluk,ddl_kaliteCeza,0)-IF($I12<ddl_esikVerim,ddl_kaliteSapma,0)-IF($N12="YETIM",ddl_kaliteCeza,0)))) | L12: =IF($A12="","",IF(OR($D12>ddl_esikDoluluk,$I12<ddl_esikVerim,$K12<ddl_esikSaglik),"ALARM","UYGUN")) | M12: =IF($A12="","",1) | N12: =IF($A12="","",IF(OR($B12="",COUNTIF(tblVarliklar[VarlikId],$B12)=0),"YETIM","TAMAM"))
A13: GLG-00008 | B13: LOC-00008 | C13: 46221 | D13: 0.66 | E13: 42 | F13: 93 | G13: TOPLAMA | H13: =IF($A13="","",IFERROR($E13/IFERROR(SUMIF(tblVarliklar[VarlikId],$B13,tblVarliklar[KapasitePalet_adet]),ddl_varsayilanKapasitePalet),0)) | I13: =IF($A13="","",IFERROR($F13/MAX($E13,1)*ddl_verimCarpan,0)) | J13: =IF($A13="","",IFERROR(IFERROR(SUMIF(tblVarliklar[VarlikId],$B13,tblVarliklar[KapasitePalet_adet]),ddl_varsayilanKapasitePalet)-$E13,0)) | K13: =IF($A13="","",MAX(0,MIN(100,ddl_kaliteTaban-IF($D13>ddl_esikDoluluk,ddl_kaliteCeza,0)-IF($I13<ddl_esikVerim,ddl_kaliteSapma,0)-IF($N13="YETIM",ddl_kaliteCeza,0)))) | L13: =IF($A13="","",IF(OR($D13>ddl_esikDoluluk,$I13<ddl_esikVerim,$K13<ddl_esikSaglik),"ALARM","UYGUN")) | M13: =IF($A13="","",1) | N13: =IF($A13="","",IF(OR($B13="",COUNTIF(tblVarliklar[VarlikId],$B13)=0),"YETIM","TAMAM"))
A14: GLG-00009 | B14: LOC-00001 | C14: 46218 | D14: 0.65 | E14: 59 | F14: 32 | G14: SEVK | H14: =IF($A14="","",IFERROR($E14/IFERROR(SUMIF(tblVarliklar[VarlikId],$B14,tblVarliklar[KapasitePalet_adet]),ddl_varsayilanKapasitePalet),0)) | I14: =IF($A14="","",IFERROR($F14/MAX($E14,1)*ddl_verimCarpan,0)) | J14: =IF($A14="","",IFERROR(IFERROR(SUMIF(tblVarliklar[VarlikId],$B14,tblVarliklar[KapasitePalet_adet]),ddl_varsayilanKapasitePalet)-$E14,0)) | K14: =IF($A14="","",MAX(0,MIN(100,ddl_kaliteTaban-IF($D14>ddl_esikDoluluk,ddl_kaliteCeza,0)-IF($I14<ddl_esikVerim,ddl_kaliteSapma,0)-IF($N14="YETIM",ddl_kaliteCeza,0)))) | L14: =IF($A14="","",IF(OR($D14>ddl_esikDoluluk,$I14<ddl_esikVerim,$K14<ddl_esikSaglik),"ALARM","UYGUN")) | M14: =IF($A14="","",1) | N14: =IF($A14="","",IF(OR($B14="",COUNTIF(tblVarliklar[VarlikId],$B14)=0),"YETIM","TAMAM"))
A15: GLG-00010 | B15: LOC-00002 | C15: 46215 | D15: 0.73 | E15: 60 | F15: 28 | G15: STOK_DUZELTME | H15: =IF($A15="","",IFERROR($E15/IFERROR(SUMIF(tblVarliklar[VarlikId],$B15,tblVarliklar[KapasitePalet_adet]),ddl_varsayilanKapasitePalet),0)) | I15: =IF($A15="","",IFERROR($F15/MAX($E15,1)*ddl_verimCarpan,0)) | J15: =IF($A15="","",IFERROR(IFERROR(SUMIF(tblVarliklar[VarlikId],$B15,tblVarliklar[KapasitePalet_adet]),ddl_varsayilanKapasitePalet)-$E15,0)) | K15: =IF($A15="","",MAX(0,MIN(100,ddl_kaliteTaban-IF($D15>ddl_esikDoluluk,ddl_kaliteCeza,0)-IF($I15<ddl_esikVerim,ddl_kaliteSapma,0)-IF($N15="YETIM",ddl_kaliteCeza,0)))) | L15: =IF($A15="","",IF(OR($D15>ddl_esikDoluluk,$I15<ddl_esikVerim,$K15<ddl_esikSaglik),"ALARM","UYGUN")) | M15: =IF($A15="","",1) | N15: =IF($A15="","",IF(OR($B15="",COUNTIF(tblVarliklar[VarlikId],$B15)=0),"YETIM","TAMAM"))
A16: GLG-00011 | B16: LOC-00003 | C16: 46212 | D16: 0.81 | E16: 100 | F16: 39 | G16: DIGER | H16: =IF($A16="","",IFERROR($E16/IFERROR(SUMIF(tblVarliklar[VarlikId],$B16,tblVarliklar[KapasitePalet_adet]),ddl_varsayilanKapasitePalet),0)) | I16: =IF($A16="","",IFERROR($F16/MAX($E16,1)*ddl_verimCarpan,0)) | J16: =IF($A16="","",IFERROR(IFERROR(SUMIF(tblVarliklar[VarlikId],$B16,tblVarliklar[KapasitePalet_adet]),ddl_varsayilanKapasitePalet)-$E16,0)) | K16: =IF($A16="","",MAX(0,MIN(100,ddl_kaliteTaban-IF($D16>ddl_esikDoluluk,ddl_kaliteCeza,0)-IF($I16<ddl_esikVerim,ddl_kaliteSapma,0)-IF($N16="YETIM",ddl_kaliteCeza,0)))) | L16: =IF($A16="","",IF(OR($D16>ddl_esikDoluluk,$I16<ddl_esikVerim,$K16<ddl_esikSaglik),"ALARM","UYGUN")) | M16: =IF($A16="","",1) | N16: =IF($A16="","",IF(OR($B16="",COUNTIF(tblVarliklar[VarlikId],$B16)=0),"YETIM","TAMAM"))
A17: GLG-00012 | B17: LOC-00004 | C17: 46209 | D17: 0.8 | E17: 56 | F17: 50 | G17: SAYIM | H17: =IF($A17="","",IFERROR($E17/IFERROR(SUMIF(tblVarliklar[VarlikId],$B17,tblVarliklar[KapasitePalet_adet]),ddl_varsayilanKapasitePalet),0)) | I17: =IF($A17="","",IFERROR($F17/MAX($E17,1)*ddl_verimCarpan,0)) | J17: =IF($A17="","",IFERROR(IFERROR(SUMIF(tblVarliklar[VarlikId],$B17,tblVarliklar[KapasitePalet_adet]),ddl_varsayilanKapasitePalet)-$E17,0)) | K17: =IF($A17="","",MAX(0,MIN(100,ddl_kaliteTaban-IF($D17>ddl_esikDoluluk,ddl_kaliteCeza,0)-IF($I17<ddl_esikVerim,ddl_kaliteSapma,0)-IF($N17="YETIM",ddl_kaliteCeza,0)))) | L17: =IF($A17="","",IF(OR($D17>ddl_esikDoluluk,$I17<ddl_esikVerim,$K17<ddl_esikSaglik),"ALARM","UYGUN")) | M17: =IF($A17="","",1) | N17: =IF($A17="","",IF(OR($B17="",COUNTIF(tblVarliklar[VarlikId],$B17)=0),"YETIM","TAMAM"))
... A34: GLG-00029 | B34: LOC-00005 | C34: 46158 | D34: 0.66 | E34: 37 | F34: 48 | G34: DIGER | H34: =IF($A34="","",IFERROR($E34/IFERROR(SUMIF(tblVarliklar[VarlikId],$B34,tblVarliklar[KapasitePalet_adet]),ddl_varsayilanKapasitePalet),0)) | I34: =IF($A34="","",IFERROR($F34/MAX($E34,1)*ddl_verimCarpan,0)) | J34: =IF($A34="","",IFERROR(IFERROR(SUMIF(tblVarliklar[VarlikId],$B34,tblVarliklar[KapasitePalet_adet]),ddl_varsayilanKapasitePalet)-$E34,0)) | K34: =IF($A34="","",MAX(0,MIN(100,ddl_kaliteTaban-IF($D34>ddl_esikDoluluk,ddl_kaliteCeza,0)-IF($I34<ddl_esikVerim,ddl_kaliteSapma,0)-IF($N34="YETIM",ddl_kaliteCeza,0)))) | L34: =IF($A34="","",IF(OR($D34>ddl_esikDoluluk,$I34<ddl_esikVerim,$K34<ddl_esikSaglik),"ALARM","UYGUN")) | M34: =IF($A34="","",1) | N34: =IF($A34="","",IF(OR($B34="",COUNTIF(tblVarliklar[VarlikId],$B34)=0),"YETIM","TAMAM"))
A35: GLG-00030 | C35: 46155 | D35: 0.65 | E35: 57 | F35: 44 | G35: SAYIM | H35: =IF($A35="","",IFERROR($E35/IFERROR(SUMIF(tblVarliklar[VarlikId],$B35,tblVarliklar[KapasitePalet_adet]),ddl_varsayilanKapasitePalet),0)) | I35: =IF($A35="","",IFERROR($F35/MAX($E35,1)*ddl_verimCarpan,0)) | J35: =IF($A35="","",IFERROR(IFERROR(SUMIF(tblVarliklar[VarlikId],$B35,tblVarliklar[KapasitePalet_adet]),ddl_varsayilanKapasitePalet)-$E35,0)) | K35: =IF($A35="","",MAX(0,MIN(100,ddl_kaliteTaban-IF($D35>ddl_esikDoluluk,ddl_kaliteCeza,0)-IF($I35<ddl_esikVerim,ddl_kaliteSapma,0)-IF($N35="YETIM",ddl_kaliteCeza,0)))) | L35: =IF($A35="","",IF(OR($D35>ddl_esikDoluluk,$I35<ddl_esikVerim,$K35<ddl_esikSaglik),"ALARM","UYGUN")) | M35: =IF($A35="","",1) | N35: =IF($A35="","",IF(OR($B35="",COUNTIF(tblVarliklar[VarlikId],$B35)=0),"YETIM","TAMAM"))
A36: GLG-00031 | B36: LOC-00007 | C36: 46152 | D36: 0.73 | E36: 83 | F36: 55 | G36: MAL_KABUL | H36: =IF($A36="","",IFERROR($E36/IFERROR(SUMIF(tblVarliklar[VarlikId],$B36,tblVarliklar[KapasitePalet_adet]),ddl_varsayilanKapasitePalet),0)) | I36: =IF($A36="","",IFERROR($F36/MAX($E36,1)*ddl_verimCarpan,0)) | J36: =IF($A36="","",IFERROR(IFERROR(SUMIF(tblVarliklar[VarlikId],$B36,tblVarliklar[KapasitePalet_adet]),ddl_varsayilanKapasitePalet)-$E36,0)) | K36: =IF($A36="","",MAX(0,MIN(100,ddl_kaliteTaban-IF($D36>ddl_esikDoluluk,ddl_kaliteCeza,0)-IF($I36<ddl_esikVerim,ddl_kaliteSapma,0)-IF($N36="YETIM",ddl_kaliteCeza,0)))) | L36: =IF($A36="","",IF(OR($D36>ddl_esikDoluluk,$I36<ddl_esikVerim,$K36<ddl_esikSaglik),"ALARM","UYGUN")) | M36: =IF($A36="","",1) | N36: =IF($A36="","",IF(OR($B36="",COUNTIF(tblVarliklar[VarlikId],$B36)=0),"YETIM","TAMAM"))
A37: GLG-00032 | B37: LOC-00008 | C37: 46149 | D37: 0.81 | E37: 52 | F37: 66 | G37: TOPLAMA | H37: =IF($A37="","",IFERROR($E37/IFERROR(SUMIF(tblVarliklar[VarlikId],$B37,tblVarliklar[KapasitePalet_adet]),ddl_varsayilanKapasitePalet),0)) | I37: =IF($A37="","",IFERROR($F37/MAX($E37,1)*ddl_verimCarpan,0)) | J37: =IF($A37="","",IFERROR(IFERROR(SUMIF(tblVarliklar[VarlikId],$B37,tblVarliklar[KapasitePalet_adet]),ddl_varsayilanKapasitePalet)-$E37,0)) | K37: =IF($A37="","",MAX(0,MIN(100,ddl_kaliteTaban-IF($D37>ddl_esikDoluluk,ddl_kaliteCeza,0)-IF($I37<ddl_esikVerim,ddl_kaliteSapma,0)-IF($N37="YETIM",ddl_kaliteCeza,0)))) | L37: =IF($A37="","",IF(OR($D37>ddl_esikDoluluk,$I37<ddl_esikVerim,$K37<ddl_esikSaglik),"ALARM","UYGUN")) | M37: =IF($A37="","",1) | N37: =IF($A37="","",IF(OR($B37="",COUNTIF(tblVarliklar[VarlikId],$B37)=0),"YETIM","TAMAM"))
A38: GLG-00033 | B38: LOC-99999 | C38: 46146 | D38: 0.8 | E38: 73 | F38: 77 | G38: SEVK | H38: =IF($A38="","",IFERROR($E38/IFERROR(SUMIF(tblVarliklar[VarlikId],$B38,tblVarliklar[KapasitePalet_adet]),ddl_varsayilanKapasitePalet),0)) | I38: =IF($A38="","",IFERROR($F38/MAX($E38,1)*ddl_verimCarpan,0)) | J38: =IF($A38="","",IFERROR(IFERROR(SUMIF(tblVarliklar[VarlikId],$B38,tblVarliklar[KapasitePalet_adet]),ddl_varsayilanKapasitePalet)-$E38,0)) | K38: =IF($A38="","",MAX(0,MIN(100,ddl_kaliteTaban-IF($D38>ddl_esikDoluluk,ddl_kaliteCeza,0)-IF($I38<ddl_esikVerim,ddl_kaliteSapma,0)-IF($N38="YETIM",ddl_kaliteCeza,0)))) | L38: =IF($A38="","",IF(OR($D38>ddl_esikDoluluk,$I38<ddl_esikVerim,$K38<ddl_esikSaglik),"ALARM","UYGUN")) | M38: =IF($A38="","",1) | N38: =IF($A38="","",IF(OR($B38="",COUNTIF(tblVarliklar[VarlikId],$B38)=0),"YETIM","TAMAM"))
A39: GLG-00034 | B39: LOC-00002 | C39: 46143 | D39: 0.88 | E39: 72 | F39: 88 | G39: STOK_DUZELTME | H39: =IF($A39="","",IFERROR($E39/IFERROR(SUMIF(tblVarliklar[VarlikId],$B39,tblVarliklar[KapasitePalet_adet]),ddl_varsayilanKapasitePalet),0)) | I39: =IF($A39="","",IFERROR($F39/MAX($E39,1)*ddl_verimCarpan,0)) | J39: =IF($A39="","",IFERROR(IFERROR(SUMIF(tblVarliklar[VarlikId],$B39,tblVarliklar[KapasitePalet_adet]),ddl_varsayilanKapasitePalet)-$E39,0)) | K39: =IF($A39="","",MAX(0,MIN(100,ddl_kaliteTaban-IF($D39>ddl_esikDoluluk,ddl_kaliteCeza,0)-IF($I39<ddl_esikVerim,ddl_kaliteSapma,0)-IF($N39="YETIM",ddl_kaliteCeza,0)))) | L39: =IF($A39="","",IF(OR($D39>ddl_esikDoluluk,$I39<ddl_esikVerim,$K39<ddl_esikSaglik),"ALARM","UYGUN")) | M39: =IF($A39="","",1) | N39: =IF($A39="","",IF(OR($B39="",COUNTIF(tblVarliklar[VarlikId],$B39)=0),"YETIM","TAMAM"))
A40: GLG-00035 | B40: LOC-00003 | C40: 46140 | D40: 0.61 | E40: 76 | F40: 84 | G40: DIGER | H40: =IF($A40="","",IFERROR($E40/IFERROR(SUMIF(tblVarliklar[VarlikId],$B40,tblVarliklar[KapasitePalet_adet]),ddl_varsayilanKapasitePalet),0)) | I40: =IF($A40="","",IFERROR($F40/MAX($E40,1)*ddl_verimCarpan,0)) | J40: =IF($A40="","",IFERROR(IFERROR(SUMIF(tblVarliklar[VarlikId],$B40,tblVarliklar[KapasitePalet_adet]),ddl_varsayilanKapasitePalet)-$E40,0)) | K40: =IF($A40="","",MAX(0,MIN(100,ddl_kaliteTaban-IF($D40>ddl_esikDoluluk,ddl_kaliteCeza,0)-IF($I40<ddl_esikVerim,ddl_kaliteSapma,0)-IF($N40="YETIM",ddl_kaliteCeza,0)))) | L40: =IF($A40="","",IF(OR($D40>ddl_esikDoluluk,$I40<ddl_esikVerim,$K40<ddl_esikSaglik),"ALARM","UYGUN")) | M40: =IF($A40="","",1) | N40: =IF($A40="","",IF(OR($B40="",COUNTIF(tblVarliklar[VarlikId],$B40)=0),"YETIM","TAMAM"))
A41: GLG-00036 | B41: LOC-00004 | C41: 46137 | D41: 0.6 | E41: 42 | F41: 23 | G41: SAYIM | H41: =IF($A41="","",IFERROR($E41/IFERROR(SUMIF(tblVarliklar[VarlikId],$B41,tblVarliklar[KapasitePalet_adet]),ddl_varsayilanKapasitePalet),0)) | I41: =IF($A41="","",IFERROR($F41/MAX($E41,1)*ddl_verimCarpan,0)) | J41: =IF($A41="","",IFERROR(IFERROR(SUMIF(tblVarliklar[VarlikId],$B41,tblVarliklar[KapasitePalet_adet]),ddl_varsayilanKapasitePalet)-$E41,0)) | K41: =IF($A41="","",MAX(0,MIN(100,ddl_kaliteTaban-IF($D41>ddl_esikDoluluk,ddl_kaliteCeza,0)-IF($I41<ddl_esikVerim,ddl_kaliteSapma,0)-IF($N41="YETIM",ddl_kaliteCeza,0)))) | L41: =IF($A41="","",IF(OR($D41>ddl_esikDoluluk,$I41<ddl_esikVerim,$K41<ddl_esikSaglik),"ALARM","UYGUN")) | M41: =IF($A41="","",1) | N41: =IF($A41="","",IF(OR($B41="",COUNTIF(tblVarliklar[VarlikId],$B41)=0),"YETIM","TAMAM"))
H42: =IF($A42="","",IFERROR($E42/IFERROR(SUMIF(tblVarliklar[VarlikId],$B42,tblVarliklar[KapasitePalet_adet]),ddl_varsayilanKapasitePalet),0)) | I42: =IF($A42="","",IFERROR($F42/MAX($E42,1)*ddl_verimCarpan,0)) | J42: =IF($A42="","",IFERROR(IFERROR(SUMIF(tblVarliklar[VarlikId],$B42,tblVarliklar[KapasitePalet_adet]),ddl_varsayilanKapasitePalet)-$E42,0)) | K42: =IF($A42="","",MAX(0,MIN(100,ddl_kaliteTaban-IF($D42>ddl_esikDoluluk,ddl_kaliteCeza,0)-IF($I42<ddl_esikVerim,ddl_kaliteSapma,0)-IF($N42="YETIM",ddl_kaliteCeza,0)))) | L42: =IF($A42="","",IF(OR($D42>ddl_esikDoluluk,$I42<ddl_esikVerim,$K42<ddl_esikSaglik),"ALARM","UYGUN")) | M42: =IF($A42="","",1) | N42: =IF($A42="","",IF(OR($B42="",COUNTIF(tblVarliklar[VarlikId],$B42)=0),"YETIM","TAMAM"))
H43: =IF($A43="","",IFERROR($E43/IFERROR(SUMIF(tblVarliklar[VarlikId],$B43,tblVarliklar[KapasitePalet_adet]),ddl_varsayilanKapasitePalet),0)) | I43: =IF($A43="","",IFERROR($F43/MAX($E43,1)*ddl_verimCarpan,0)) | J43: =IF($A43="","",IFERROR(IFERROR(SUMIF(tblVarliklar[VarlikId],$B43,tblVarliklar[KapasitePalet_adet]),ddl_varsayilanKapasitePalet)-$E43,0)) | K43: =IF($A43="","",MAX(0,MIN(100,ddl_kaliteTaban-IF($D43>ddl_esikDoluluk,ddl_kaliteCeza,0)-IF($I43<ddl_esikVerim,ddl_kaliteSapma,0)-IF($N43="YETIM",ddl_kaliteCeza,0)))) | L43: =IF($A43="","",IF(OR($D43>ddl_esikDoluluk,$I43<ddl_esikVerim,$K43<ddl_esikSaglik),"ALARM","UYGUN")) | M43: =IF($A43="","",1) | N43: =IF($A43="","",IF(OR($B43="",COUNTIF(tblVarliklar[VarlikId],$B43)=0),"YETIM","TAMAM"))
H44: =IF($A44="","",IFERROR($E44/IFERROR(SUMIF(tblVarliklar[VarlikId],$B44,tblVarliklar[KapasitePalet_adet]),ddl_varsayilanKapasitePalet),0)) | I44: =IF($A44="","",IFERROR($F44/MAX($E44,1)*ddl_verimCarpan,0)) | J44: =IF($A44="","",IFERROR(IFERROR(SUMIF(tblVarliklar[VarlikId],$B44,tblVarliklar[KapasitePalet_adet]),ddl_varsayilanKapasitePalet)-$E44,0)) | K44: =IF($A44="","",MAX(0,MIN(100,ddl_kaliteTaban-IF($D44>ddl_esikDoluluk,ddl_kaliteCeza,0)-IF($I44<ddl_esikVerim,ddl_kaliteSapma,0)-IF($N44="YETIM",ddl_kaliteCeza,0)))) | L44: =IF($A44="","",IF(OR($D44>ddl_esikDoluluk,$I44<ddl_esikVerim,$K44<ddl_esikSaglik),"ALARM","UYGUN")) | M44: =IF($A44="","",1) | N44: =IF($A44="","",IF(OR($B44="",COUNTIF(tblVarliklar[VarlikId],$B44)=0),"YETIM","TAMAM"))
H45: =IF($A45="","",IFERROR($E45/IFERROR(SUMIF(tblVarliklar[VarlikId],$B45,tblVarliklar[KapasitePalet_adet]),ddl_varsayilanKapasitePalet),0)) | I45: =IF($A45="","",IFERROR($F45/MAX($E45,1)*ddl_verimCarpan,0)) | J45: =IF($A45="","",IFERROR(IFERROR(SUMIF(tblVarliklar[VarlikId],$B45,tblVarliklar[KapasitePalet_adet]),ddl_varsayilanKapasitePalet)-$E45,0)) | K45: =IF($A45="","",MAX(0,MIN(100,ddl_kaliteTaban-IF($D45>ddl_esikDoluluk,ddl_kaliteCeza,0)-IF($I45<ddl_esikVerim,ddl_kaliteSapma,0)-IF($N45="YETIM",ddl_kaliteCeza,0)))) | L45: =IF($A45="","",IF(OR($D45>ddl_esikDoluluk,$I45<ddl_esikVerim,$K45<ddl_esikSaglik),"ALARM","UYGUN")) | M45: =IF($A45="","",1) | N45: =IF($A45="","",IF(OR($B45="",COUNTIF(tblVarliklar[VarlikId],$B45)=0),"YETIM","TAMAM"))
H46: =IF($A46="","",IFERROR($E46/IFERROR(SUMIF(tblVarliklar[VarlikId],$B46,tblVarliklar[KapasitePalet_adet]),ddl_varsayilanKapasitePalet),0)) | I46: =IF($A46="","",IFERROR($F46/MAX($E46,1)*ddl_verimCarpan,0)) | J46: =IF($A46="","",IFERROR(IFERROR(SUMIF(tblVarliklar[VarlikId],$B46,tblVarliklar[KapasitePalet_adet]),ddl_varsayilanKapasitePalet)-$E46,0)) | K46: =IF($A46="","",MAX(0,MIN(100,ddl_kaliteTaban-IF($D46>ddl_esikDoluluk,ddl_kaliteCeza,0)-IF($I46<ddl_esikVerim,ddl_kaliteSapma,0)-IF($N46="YETIM",ddl_kaliteCeza,0)))) | L46: =IF($A46="","",IF(OR($D46>ddl_esikDoluluk,$I46<ddl_esikVerim,$K46<ddl_esikSaglik),"ALARM","UYGUN")) | M46: =IF($A46="","",1) | N46: =IF($A46="","",IF(OR($B46="",COUNTIF(tblVarliklar[VarlikId],$B46)=0),"YETIM","TAMAM"))
H47: =IF($A47="","",IFERROR($E47/IFERROR(SUMIF(tblVarliklar[VarlikId],$B47,tblVarliklar[KapasitePalet_adet]),ddl_varsayilanKapasitePalet),0)) | I47: =IF($A47="","",IFERROR($F47/MAX($E47,1)*ddl_verimCarpan,0)) | J47: =IF($A47="","",IFERROR(IFERROR(SUMIF(tblVarliklar[VarlikId],$B47,tblVarliklar[KapasitePalet_adet]),ddl_varsayilanKapasitePalet)-$E47,0)) | K47: =IF($A47="","",MAX(0,MIN(100,ddl_kaliteTaban-IF($D47>ddl_esikDoluluk,ddl_kaliteCeza,0)-IF($I47<ddl_esikVerim,ddl_kaliteSapma,0)-IF($N47="YETIM",ddl_kaliteCeza,0)))) | L47: =IF($A47="","",IF(OR($D47>ddl_esikDoluluk,$I47<ddl_esikVerim,$K47<ddl_esikSaglik),"ALARM","UYGUN")) | M47: =IF($A47="","",1) | N47: =IF($A47="","",IF(OR($B47="",COUNTIF(tblVarliklar[VarlikId],$B47)=0),"YETIM","TAMAM"))
H48: =IF($A48="","",IFERROR($E48/IFERROR(SUMIF(tblVarliklar[VarlikId],$B48,tblVarliklar[KapasitePalet_adet]),ddl_varsayilanKapasitePalet),0)) | I48: =IF($A48="","",IFERROR($F48/MAX($E48,1)*ddl_verimCarpan,0)) | J48: =IF($A48="","",IFERROR(IFERROR(SUMIF(tblVarliklar[VarlikId],$B48,tblVarliklar[KapasitePalet_adet]),ddl_varsayilanKapasitePalet)-$E48,0)) | K48: =IF($A48="","",MAX(0,MIN(100,ddl_kaliteTaban-IF($D48>ddl_esikDoluluk,ddl_kaliteCeza,0)-IF($I48<ddl_esikVerim,ddl_kaliteSapma,0)-IF($N48="YETIM",ddl_kaliteCeza,0)))) | L48: =IF($A48="","",IF(OR($D48>ddl_esikDoluluk,$I48<ddl_esikVerim,$K48<ddl_esikSaglik),"ALARM","UYGUN")) | M48: =IF($A48="","",1) | N48: =IF($A48="","",IF(OR($B48="",COUNTIF(tblVarliklar[VarlikId],$B48)=0),"YETIM","TAMAM"))
H49: =IF($A49="","",IFERROR($E49/IFERROR(SUMIF(tblVarliklar[VarlikId],$B49,tblVarliklar[KapasitePalet_adet]),ddl_varsayilanKapasitePalet),0)) | I49: =IF($A49="","",IFERROR($F49/MAX($E49,1)*ddl_verimCarpan,0)) | J49: =IF($A49="","",IFERROR(IFERROR(SUMIF(tblVarliklar[VarlikId],$B49,tblVarliklar[KapasitePalet_adet]),ddl_varsayilanKapasitePalet)-$E49,0)) | K49: =IF($A49="","",MAX(0,MIN(100,ddl_kaliteTaban-IF($D49>ddl_esikDoluluk,ddl_kaliteCeza,0)-IF($I49<ddl_esikVerim,ddl_kaliteSapma,0)-IF($N49="YETIM",ddl_kaliteCeza,0)))) | L49: =IF($A49="","",IF(OR($D49>ddl_esikDoluluk,$I49<ddl_esikVerim,$K49<ddl_esikSaglik),"ALARM","UYGUN")) | M49: =IF($A49="","",1) | N49: =IF($A49="","",IF(OR($B49="",COUNTIF(tblVarliklar[VarlikId],$B49)=0),"YETIM","TAMAM"))
H50: =IF($A50="","",IFERROR($E50/IFERROR(SUMIF(tblVarliklar[VarlikId],$B50,tblVarliklar[KapasitePalet_adet]),ddl_varsayilanKapasitePalet),0)) | I50: =IF($A50="","",IFERROR($F50/MAX($E50,1)*ddl_verimCarpan,0)) | J50: =IF($A50="","",IFERROR(IFERROR(SUMIF(tblVarliklar[VarlikId],$B50,tblVarliklar[KapasitePalet_adet]),ddl_varsayilanKapasitePalet)-$E50,0)) | K50: =IF($A50="","",MAX(0,MIN(100,ddl_kaliteTaban-IF($D50>ddl_esikDoluluk,ddl_kaliteCeza,0)-IF($I50<ddl_esikVerim,ddl_kaliteSapma,0)-IF($N50="YETIM",ddl_kaliteCeza,0)))) | L50: =IF($A50="","",IF(OR($D50>ddl_esikDoluluk,$I50<ddl_esikVerim,$K50<ddl_esikSaglik),"ALARM","UYGUN")) | M50: =IF($A50="","",1) | N50: =IF($A50="","",IF(OR($B50="",COUNTIF(tblVarliklar[VarlikId],$B50)=0),"YETIM","TAMAM"))
H51: =IF($A51="","",IFERROR($E51/IFERROR(SUMIF(tblVarliklar[VarlikId],$B51,tblVarliklar[KapasitePalet_adet]),ddl_varsayilanKapasitePalet),0)) | I51: =IF($A51="","",IFERROR($F51/MAX($E51,1)*ddl_verimCarpan,0)) | J51: =IF($A51="","",IFERROR(IFERROR(SUMIF(tblVarliklar[VarlikId],$B51,tblVarliklar[KapasitePalet_adet]),ddl_varsayilanKapasitePalet)-$E51,0)) | K51: =IF($A51="","",MAX(0,MIN(100,ddl_kaliteTaban-IF($D51>ddl_esikDoluluk,ddl_kaliteCeza,0)-IF($I51<ddl_esikVerim,ddl_kaliteSapma,0)-IF($N51="YETIM",ddl_kaliteCeza,0)))) | L51: =IF($A51="","",IF(OR($D51>ddl_esikDoluluk,$I51<ddl_esikVerim,$K51<ddl_esikSaglik),"ALARM","UYGUN")) | M51: =IF($A51="","",1) | N51: =IF($A51="","",IF(OR($B51="",COUNTIF(tblVarliklar[VarlikId],$B51)=0),"YETIM","TAMAM"))
H52: =IF($A52="","",IFERROR($E52/IFERROR(SUMIF(tblVarliklar[VarlikId],$B52,tblVarliklar[KapasitePalet_adet]),ddl_varsayilanKapasitePalet),0)) | I52: =IF($A52="","",IFERROR($F52/MAX($E52,1)*ddl_verimCarpan,0)) | J52: =IF($A52="","",IFERROR(IFERROR(SUMIF(tblVarliklar[VarlikId],$B52,tblVarliklar[KapasitePalet_adet]),ddl_varsayilanKapasitePalet)-$E52,0)) | K52: =IF($A52="","",MAX(0,MIN(100,ddl_kaliteTaban-IF($D52>ddl_esikDoluluk,ddl_kaliteCeza,0)-IF($I52<ddl_esikVerim,ddl_kaliteSapma,0)-IF($N52="YETIM",ddl_kaliteCeza,0)))) | L52: =IF($A52="","",IF(OR($D52>ddl_esikDoluluk,$I52<ddl_esikVerim,$K52<ddl_esikSaglik),"ALARM","UYGUN")) | M52: =IF($A52="","",1) | N52: =IF($A52="","",IF(OR($B52="",COUNTIF(tblVarliklar[VarlikId],$B52)=0),"YETIM","TAMAM"))
H53: =IF($A53="","",IFERROR($E53/IFERROR(SUMIF(tblVarliklar[VarlikId],$B53,tblVarliklar[KapasitePalet_adet]),ddl_varsayilanKapasitePalet),0)) | I53: =IF($A53="","",IFERROR($F53/MAX($E53,1)*ddl_verimCarpan,0)) | J53: =IF($A53="","",IFERROR(IFERROR(SUMIF(tblVarliklar[VarlikId],$B53,tblVarliklar[KapasitePalet_adet]),ddl_varsayilanKapasitePalet)-$E53,0)) | K53: =IF($A53="","",MAX(0,MIN(100,ddl_kaliteTaban-IF($D53>ddl_esikDoluluk,ddl_kaliteCeza,0)-IF($I53<ddl_esikVerim,ddl_kaliteSapma,0)-IF($N53="YETIM",ddl_kaliteCeza,0)))) | L53: =IF($A53="","",IF(OR($D53>ddl_esikDoluluk,$I53<ddl_esikVerim,$K53<ddl_esikSaglik),"ALARM","UYGUN")) | M53: =IF($A53="","",1) | N53: =IF($A53="","",IF(OR($B53="",COUNTIF(tblVarliklar[VarlikId],$B53)=0),"YETIM","TAMAM"))
... H255: =IF($A255="","",IFERROR($E255/IFERROR(SUMIF(tblVarliklar[VarlikId],$B255,tblVarliklar[KapasitePalet_adet]),ddl_varsayilanKapasitePalet),0)) | I255: =IF($A255="","",IFERROR($F255/MAX($E255,1)*ddl_verimCarpan,0)) | J255: =IF($A255="","",IFERROR(IFERROR(SUMIF(tblVarliklar[VarlikId],$B255,tblVarliklar[KapasitePalet_adet]),ddl_varsayilanKapasitePalet)-$E255,0)) | K255: =IF($A255="","",MAX(0,MIN(100,ddl_kaliteTaban-IF($D255>ddl_esikDoluluk,ddl_kaliteCeza,0)-IF($I255<ddl_esikVerim,ddl_kaliteSapma,0)-IF($N255="YETIM",ddl_kaliteCeza,0)))) | L255: =IF($A255="","",IF(OR($D255>ddl_esikDoluluk,$I255<ddl_esikVerim,$K255<ddl_esikSaglik),"ALARM","UYGUN")) | M255: =IF($A255="","",1) | N255: =IF($A255="","",IF(OR($B255="",COUNTIF(tblVarliklar[VarlikId],$B255)=0),"YETIM","TAMAM"))
