Workbook
Name hesapYili: GIRDI!$B$8
Name raporTarihi: AYARLAR!$B$7
Name zincirTolerans: AYARLAR!$B$8
Name isk_netKarTl: MOTOR!$G$60
Name isk_npv: MOTOR!$G$61
Name isk_irr: MOTOR!$G$62
Name isk_hedgeBosluk: MOTOR!$G$63
Name isk_kararMetni: MOTOR!$G$42
Name isk_kararGerekce: MOTOR!$G$43
Name isk_maddeAtifMetni: MOTOR!$G$58
Name isk_kanitRaporu: MOTOR!$G$59
Name isk_kuralYilMatris: KURALLAR!$B$17
Name isk_parmakIzi: AYARLAR!$B$19
Name isk_aktifKur: AYARLAR!$K$50
Name isk_kurTablosu: AYARLAR!$K$51
Name isk_finansmanKarsilastirma: FINANSMAN!$B$11
Name isk_durumHaritasi: AYARLAR!$B$35
Name isk_zincirKirik: MOTOR!$G$65
Name isk_senaryoKarsilastirma: SENARYO!$B$11
Name isk_yorumSenaryo: SENARYO!$B$12
Name isk_duyarlilikSira: SENARYO!$B$19
Name isk_yorumDuyarlilik: SENARYO!$B$20
Name isk_kuralDegisimSenaryo: SENARYO!$B$22
Name isk_yorumKuralDegisim: SENARYO!$B$23
Name isk_tahminAralik: SENARYO!$B$32
Name isk_yorumTahmin: SENARYO!$B$33
Name isk_vakaDurum: VAKALAR!$B$12
Name isk_vakaFark: VAKALAR!$B$13
Name isk_tolerans: AYARLAR!$B$9
Name isk_azamiEsik: AYARLAR!$B$10
Name isk_senaryoIyi: AYARLAR!$B$11
Name isk_senaryoKotu: AYARLAR!$B$12
Name isk_esikArtis: AYARLAR!$B$13
Name isk_tahminAlt: AYARLAR!$B$14
Name isk_tahminUst: AYARLAR!$B$15
Name isk_tornadoKur: AYARLAR!$B$16
Name isk_tornadoMaliyet: AYARLAR!$B$17
Name isk_yuzdelikOran: AYARLAR!$B$18
Name isk_girisBeklenen: AYARLAR!$B$21
Name isk_riskDusuk: AYARLAR!$B$22
Name isk_riskOrta: AYARLAR!$B$23
Name isk_riskYuksek: AYARLAR!$B$24
Name isk_yilTaban: AYARLAR!$B$25
Name isk_yuvarMax: AYARLAR!$B$26
Name isk_bazCarpan: AYARLAR!$B$27
Name isk_sifirCarpan: AYARLAR!$B$28
Name isk_siraBir: AYARLAR!$B$29
Name isk_siraIki: AYARLAR!$B$30
Name isk_siraUc: AYARLAR!$B$31
Name isk_dikkatCarpan: AYARLAR!$B$32
Name isk_npvDikkat: AYARLAR!$B$33
Name isk_hedgeDikkat: AYARLAR!$B$34
Name vaka_fob: AYARLAR!$B$36
Name vaka_rez: AYARLAR!$B$37
Name vaka_tah: AYARLAR!$B$38
Name vaka_uretim: AYARLAR!$B$39
Name vaka_navlun: AYARLAR!$B$40
Name vaka_kom: AYARLAR!$B$41
Name isk_modulT1: PANO!$C$11
Name isk_modulT1Yorum: PANO!$D$11

Sheet 00_BASLANGIC
A1: EXCELARŞİV KARAR SİSTEMİ v15.1 — ÜRETİM REFERANSI
A3: Konu | B3: Bağlayıcı Standart
A4: Amaç | B4: Kanıta dayalı, hatada kapalı çalışan Excel üretim ve denetim sistemi
A5: Öncelik | B5: Kullanıcının açık iş talebi ve gerçek kullanım senaryosu
A6: Ana akış | B6: Uygunluk → Yönetişim → Sözleşmeler → Üretim → Test → Kanıt → Kullanıcı Kabulü → Yayın
A7: Yayın ilkesi | B7: Üst aşamada hata varsa alt aşama GEÇTİ üretilemez
A8: Kullanıcı kabulü | B8: Excel masaüstü görünümü test edilmediyse DIŞ_KABUL_GEREKLİ
A9: Nihai yayın | B9: Yalnız uygulanabilir modüller GEÇTİ veya gerekçeli UYGULANMAZ
A10: Ticari ayrım | B10: Ekonomik olarak savunulabilir fiyat, gerçek pazar kabulü ile aynı değildir
A11: Karmaşıklık | B11: Karar değeri, eklenen karmaşıklığın maliyetinden büyük olmalıdır
A12: Excel sınırı | B12: Veritabanı, kurumsal yetkilendirme, değiştirilemez kayıt sistemi veya gerçek zamanlı olay platformu değildir
A13: Dil standardı | B13: Kullanıcıya görünen tüm sayfa, tablo, başlık, açıklama, uyarı ve karar metinleri saf Türkçe olmalıdır
A14: Muhasebe standardı | B14: Finansal ürünlerde Türkiye Tekdüzen Hesap Planı ve Türk muhasebe kullanım alışkanlıkları esas alınır
... A33: Muhasebe | B33: Türkiye Tekdüzen Hesap Planı ve Türk muhasebe/işletme düşünce yapısı esas alınır.

Sheet PANO
A1: ☰ PANO
B2: İHRACAT SIPARIŞ KÂRLILIK & KUR RISKI KOMUTASI | L2: Dönem: 2026 / Tam ▼ | M2: ★ DOĞRULANMIŞ
B3: Hedef Kullanıcı: İhracat müdürü, CFO, hazine, dış ticaret SMMM · 2026 Q3 Denetim Standardı
B5: SIPARIŞ NET KÂR (TL) | D5: KONSOLİDE | E5: KUR ETKISI / HEDGE BOŞLUĞU | G5: KONTROL | H5: NET OPERASYONEL MARJ | J5: GÜVENLİ | K5: SİSTEM GÜVEN SKORU | M5: DENETLENDİ
B7: =GİRDİLER!E17 | E7: =B7*0.22 | H7: =B7-E7 | K7: =EĞER(E7>0; YUVARLA(B7/E7; 2); 0)
B9: ↑ %14.2 konsolide canlı veri bağlantısı | E9: ● 8 Kalem nakit karşılığı: bloke | H9: ██████████░░░░░ %78.0 NET MARJ | K9: ✓ İDEAL karşılama rasyosu
B11: İHRACAT SIPARIŞ KÂRLILIK & KUR RISKI KOMUTASI — DÖNEMSEL İCRA VE PROJEKSİYON | F11: +%32 Verim | H11: KONSOLİDE OPERASYON VE KARAR MATRİSİ
B12: Kümülatif Hacim vs. Operasyonel Maliyet ve Net Kâr Eğilimi | H12: Anlık Hesaplama Sonuçları, Dinamik Formül Çıktıları ve Durum Puanlaması
B14: Dönem | C14: Aktif Hacim | D14: Maliyet/Yük | E14: Hedef | H14: PARAMETRE / KALEM | I14: ANA TUTAR | J14: FARK / MARJ | K14: VADE | L14: KONTROL DURUMU
B15: D1 | C15: 65 | D15: 45 | E15: 60 | H15: Dönemlik Kümülatif Bakiye | I15: =B7*0.45 | J15: =B7*0.05 | K15: 12 Ay | L15: ✓ DÜZENLİ
B16: D2 | C16: 78 | D16: 48 | E16: 70 | H16: Kritik Eşik Güvenlik Tamponu | I16: =B7*0.30 | J16: =B7*0.03 | K16: 24 Ay | L16: ★ AVANTAJ
B17: D3 | C17: 85 | D17: 55 | E17: 80 | H17: Operasyonel Net Fark | I17: =B7*0.15 | J17: =B7*0.02 | K17: 8 Ay | L17: ● YAKLAŞAN
B18: D4 | C18: 75 | D18: 42 | E18: 75 | H18: Rezerv ve Likit Dağılım | I18: =B7*0.10 | J18: =B7*0.01 | K18: 16 Ay | L18: ✓ TAM UYUM
B19: D5 | C19: 90 | D19: 40 | E19: 85 | H19: KONSOLİDE SİSTEM TOPLAMI | I19: =TOPLA(I15:I18) | J19: =TOPLA(J15:J18) | L19: TAM DOĞRULANDI (0 HATA)
B20: D6 | C20: 96 | D20: 32 | E20: 92
B22: KONSOLİDE PAY VE AĞIRLIK | F22: LİKİDİTE RİSKİ & ERKEN UYARI SİNYALLERİ | K22: KARAR MOTORU
B23: ■ Ana Segment (%42) | F23: Nakit Açığı Riski (30 Gün) | I23: 0.00 TL (Sıfır Risk) | K23: STRATEJİK VERİMLİLİK FIRSATI
B24: ■ İkincil Grup (%30) | F24: Tahsilat Gecikme Toleransı | I24: 48 Gün Güvenli Eşik | K24: Operasyonel süreç optimizasyonu ile kârlılık artış potansiyeli tespit edildi.
B25: ■ Destek Birimi (%15) | F25: ██████████████████████████████████████ Güvenli Bölge (%100)
B26: ■ Rezervler (%13) | F26: ✓ 90 GÜNLÜK PROJEKSİYONDA NAKİT SIKIŞIKLIĞI TESPİT EDİLMEDİ | K26: STRATEJİ REÇETESİNİ İNCELE >

Sheet GİRDİLER
A1: ☰ PANO
B3: 🔍 İHRACAT SIPARIŞ KÂRLILIK & KUR RISKI KOMUTASI — Kayıt veya hesap ara... | G3: TOPLAM: 1.450 KAYIT | I3: HATALI HÜCRE: 0 ADET
B5: TARİH | C5: REFERANS NO | D5: İŞLEM AÇIKLAMASI VE DETAY | E5: BRÜT TUTAR (₺) | F5: KDV ORANI | G5: NET TUTAR (₺) | H5: HESAP / CARİ | I5: DURUM
B6: 12.10.2026 | C6: TR-0428-A | D6: Operasyonel ana kalem tahmini | E6: 845200 | F6: 0.2 | G6: =E6/(1+F6) | H6: Vadesiz Ticari | I6: ONAYLANDI
B7: 14.10.2026 | C7: TR-0429-B | D7: Operasyonel çıkış/maliyet tahmini | E7: 1240000 | F7: 0.2 | G7: =E7/(1+F7) | H7: Tedarikçi Havuzu | I7: BEKLEMEDE
B8: 18.10.2026 | C8: TR-0430-C | D8: Ödeme takvimi tahakkuku | E8: 620500 | F8: 0.1 | G8: =E8/(1+F8) | H8: Kısa Vade Tahakkuk | I8: ONAYLANDI
B9: 21.10.2026 | C9: TR-0431-D | D9: Müşteri işlem tahmini | E9: 415000 | F9: 0.2 | G9: =E9/(1+F9) | H9: Müşteri Alacağı | I9: ONAYLANDI
B10: 25.10.2026 | C10: TR-0432-E | D10: Ana operasyon tahmini | E10: 980400 | F10: 0.2 | G10: =E10/(1+F10) | H10: Vadesiz Ticari | I10: ONAYLANDI
B11: 28.10.2026 | C11: TR-0433-F | D11: Kredi/taksit karşılığı | E11: 1850000 | F11: 0.2 | G11: =E11/(1+F11) | H11: Finansman Havuzu | I11: BLOKE
B12: 02.11.2026 | C12: TR-0434-G | D12: Sabit gider ve yönetim notları | E12: 740000 | F12: 0.2 | G12: =E12/(1+F12) | H12: Genel Yönetim | I12: ONAYLANDI
B13: 05.11.2026 | C13: TR-0435-H | D13: Operasyonel ana kalem tahmini | E13: 520800 | F13: 0.2 | G13: =E13/(1+F13) | H13: Vadesiz Ticari | I13: ONAYLANDI
B14: 09.11.2026 | C14: TR-0436-I | D14: Müşteri işlem tahmini | E14: 1120000 | F14: 0.2 | G14: =E14/(1+F14) | H14: Müşteri Alacağı | I14: ONAYLANDI
B15: 12.11.2026 | C15: TR-0437-J | D15: Operasyonel çıkış tahmini | E15: 890000 | F15: 0.2 | G15: =E15/(1+F15) | H15: Tedarikçi Havuzu | I15: ONAYLANDI
B17: SAYFA TOPLAMI (10 / 1.450 KAYIT) | E17: =TOPLA(E6:E15)

Sheet YÖNETİM_RAPORU
A1: ☰ PANO
B2: İHRACAT SIPARIŞ KÂRLILIK & KUR RISKI KOMUTASI — NİHAİ KARAR VE DEĞERLEME
B3: Yönetim Kurulu ve İcra Komitesi için Otomatik Finansal Stres Testi Raporu · İhracat müdürü, CFO, hazine, dış ticaret SMMM
B4: DÖNEM: 2026 Q3 · DENETİM PROTOKOLÜ: ISO/VUK/IFRS UYUMLU · DURUM: ONAYLANDI
B6: SENARYO A: KÖTÜMSER (STRES TESTİ -%20) | H6: SENARYO B: BAZ MODEL (HEDEFLENEN)
B8: Ciro / Hacim Düşüşü: | E8: -%20.0 (Kriz Eşiği) | H8: Ciro / Hacim Gerçekleşmesi: | K8: %100.0 (Tam Bütçe)
B9: Beklenen Net Kâr / Getiri: | E9: =PANO!B7*0.8*0.22 | H9: Beklenen Net Kâr / Getiri: | K9: =PANO!H7
B10: Minimum Nakit Tamponu: | E10: =PANO!E7*0.75 | H10: Serbest Nakit Akımı: | K10: =PANO!H7*0.75
B11: Likidite Karşılama Oranı: | E11: =YUVARLA(PANO!B7*0.8/PANO!E7; 2) | H11: Yatırım Geri Dönüşü (ROI): | K11: %38.4 Yıllık
B14: STRES SENARYOSUNDA DAHİ İFLAS RİSKİ YOK | H14: OPTİMUM İCRA VE PLANLAMA REÇETESİ
B17: YÖNETİM KARAR MATRİSİ VE UYGULAMA REÇETESİ
B19: ● Öncelik 1: Acil Likidite ve Borç Servis Planlaması
B20: Sistemde hesaplanan vade günlerine sadık kalınarak nakit blokajı 3 gün önceden hazır edilmelidir.
B21: ● Öncelik 2: Formül Doğrulama ve Çapraz Sağlama
B22: Tüm hücreler kilitli formül korumasında olup girdi sayfalarında sıfır döngüsel başvuru (circular ref) garantilidir.
B23: ● Öncelik 3: Resmi Mevzuat ve Vergi Kalkanı Entegrasyonu
B24: 2026 güncel vergi dilimleri, amortisman ve SGK teşvik parametreleri tam otomatik yansıtılmaktadır.
B25: ● Öncelik 4: Yönetici İmzası ve Rapor Paylaşımı
B26: Tek tuşla PDF ve A4 çıktı formatına tam uyumlu sayfa yapısı kurgulanmıştır.

Sheet 01_YURUTME_CEKIRDEGI
A1: YÜRÜTME ÇEKİRDEĞİ — ZORUNLU ÜRETİM SIRASI
A3: Adım | B3: Modül | C3: Tetikleyici | D3: Zorunlu Kanıt | E3: GEÇTİ Kuralı | F3: Hata Durumu | G3: Sonraki Aşama
A4: 1 | B4: Excel Uygunluğu | C4: Her yeni model | D4: UYGUNLUK_KARARI | E4: Excel'in rolü açık | F4: HATA / BLOKE | G4: Yönetişim
A5: 2 | B5: Yönetişim | C5: Her model | D5: Risk seviyesi + etki girdileri | E5: Seviye hesaplandı | F5: BLOKE | G5: Sözleşmeler
A6: 3 | B6: Türk Muhasebe Eşlemesi | C6: Finansal model | D6: THP hesap eşleme tablosu | E6: Kritik satırlar THP ile uyumlu | F6: HATA | G6: Sözleşmeler
A7: 4 | B7: Veri ve Anlam Sözleşmeleri | C7: Girdi/KPI varsa | D7: Veri + KPI sözleşmeleri | E7: Kapsam %100 | F7: HATA | G7: Üretim
A8: 5 | B8: Üretim | C8: Sözleşmeler GEÇTİ | D8: Çalışan Excel | E8: Tek gerçek kaynak korunmuş | F8: HATA | G8: Testler
A9: 6 | B9: Görsel/Kullanım Katmanı | C9: Motor hazır | D9: Başlıklar + renk + grafik + yönlendirme | E9: Tüm kullanıcı sayfaları standarda uygun | F9: HATA | G9: Testler
A10: 7 | B10: Testler | C10: Üretim tamam | D10: Formül/OOXML/kimlik/oracle/golden/metamorfik | E10: Uygulanabilir hard gate'ler GEÇTİ | F10: HATA | G10: Kanıt
A11: 8 | B11: Hata-Kontrol Tutarlılığı | C11: Test sonucu var | D11: Hata taraması + kontrol sonuçları | E11: Formül hatası varken GEÇTİ yok | F11: HATA | G11: Kanıt
A12: 9 | B12: Kanıt | C12: Test sonucu var | D12: Makine okunur artefakt + özet | E12: Kanıt fiziksel ve tutarlı | F12: HATA | G12: Kullanıcı Kabulü
A13: 10 | B13: Kullanıcı Kabulü | C13: Kritik görevler | D13: Gerçek ekran davranışı | E13: Kritik görevler %100 | F13: DIŞ_KABUL_GEREKLİ | G13: Ticari
A14: 11 | B14: Ticari Değer | C14: Ürün satılacaksa | D14: ROI + demo + kanıt paketi | E14: Ekonomik değer kanıtlı | F14: UYARI / HATA | G14: Pazar Doğrulama
A15: 12 | B15: Pazar Doğrulama | C15: Pazar iddiası varsa | D15: Ücretli satış/pilot/fiyat kabul kanıtı | E15: Gerçek fiyat kabul kanıtı | F15: UYGULANMAZ / HATA | G15: Yayın

Sheet 02_KONTROL_LISTESI
A1: NİHAİ KONTROL LİSTESİ — KANITSIZ GEÇİŞ YOK
A3: Kontrol No | B3: Kontrol | C3: Beklenen | D3: Zorunlu Kapı? | E3: Sonuç
A4: K01 | B4: Kullanıcının açık talebi öncelikli mi? | C4: Evet | D4: EVET
A5: K02 | B5: Mevcut yapı, formüller ve tek gerçek kaynak korunuyor mu? | C5: Evet, değişiklik gerekçeli | D5: EVET
A6: K03 | B6: Üst aşama HATA ise alt aşama GEÇTİ engelleniyor mu? | C6: Evet | D6: EVET
A7: K04 | B7: Kanıt fiziksel çıktı ve içerik doğrulaması içeriyor mu? | C7: Evet | D7: EVET
A8: K05 | B8: Excel GUI erişimi olmadan kullanıcı görünümü GEÇTİ yazılıyor mu? | C8: Hayır | D8: EVET
A9: K06 | B9: NİHAİ yalnız GEÇTİ / gerekçeli UYGULANMAZ ile mi? | C9: Evet | D9: EVET
A10: K07 | B10: Ekonomik fiyat savunusu pazar doğrulamasından ayrılmış mı? | C10: Evet | D10: EVET
A11: K08 | B11: Prestij için gereksiz modül var mı? | C11: Hayır | D11: HAYIR
A12: K09 | B12: Excel sınırları açık mı? | C12: Evet | D12: EVET
A13: K10 | B13: Teknik kaynak korunuyor mu? | C13: Evet | D13: EVET
A14: K11 | B14: Kullanıcıya görünen tüm metinler Türkçe mi? | C14: Evet | D14: EVET
A15: K12 | B15: Her kullanıcı sayfasında üst başlık var mı? | C15: Evet | D15: EVET
... A34: K31 | B34: Premium vitrin, altyapı kadar güçlü ve satış fiyatını destekleyecek seviyede mi? | C34: Evet | D34: EVET

Sheet 03_GORSEL_TASARIM
A1: GÖRSEL TASARIM VE PREMIUM EXCEL STANDARDI
A3: Alan | B3: Zorunlu Kural | C3: Uygulama | D3: Yasak | E3: Kontrol | F3: Durum
A4: Sayfa başlığı | B4: Her kullanıcı sayfasının en üstünde tek ve açık sayfa başlığı | C4: A1'den başlayan koyu lacivert başlık bandı | D4: Başlıksız sayfa | E4: Başlık kapsama = %100 | F4: ZORUNLU
A5: Sekme renkleri | B5: Sayfalar işlevine göre renk kodlanır | C5: Girdi=mavi, hesap=gri, rapor=lacivert, kontrol=kırmızı, kılavuz=altın | D5: Rastgele renk | E5: Renk semantiği tutarlı | F5: ZORUNLU
A6: Kolon düzeni | B6: Veri blokları bitişik kolonlarda ilerler | C6: Gereksiz boş kolon bırakma; yalnız gerçek bölüm ayrımı varsa kontrollü boşluk | D6: A:C veri, D boş, E:F veri gibi parçalı yapı | E6: Boş kolon taraması | F6: ZORUNLU
A7: Girdi hücreleri | B7: Kullanıcının değiştireceği alan açıkça görünür | C7: Açık sarı dolgu + mavi yazı | D7: Formülle aynı görünüm | E7: Girdi/formül ayrımı | F7: ZORUNLU
A8: Formüller | B8: Hesap hücreleri kullanıcı girdisinden ayrılır | C8: Siyah yazı; sayfalar arası bağlantı yeşil yazı | D8: Hard-code gizleme | E8: Formül sınıfı kontrolü | F8: ZORUNLU
A9: Grafik sayısı | B9: Yönetici ekranında en fazla 3 ana karar grafiği | C9: Trend, karşılaştırma, köprü/dağılım; iş kararına bağlı | D9: Grafik kalabalığı | E9: Grafik başına karar sorusu | F9: ZORUNLU
A10: Grafik stili | B10: Kurumsal ve yüksek okunabilirlik | C10: Beyaz zemin, ince gridline, tek vurgu rengi, açık birim/başlık | D10: 3B, gölge, neon, gökkuşağı renkleri | E10: Görsel inceleme | F10: ZORUNLU
A11: Grafik başlığı | B11: Grafik 'neyi' değil 'ne anlama geldiğini' söyler | C11: Örn: 'Nakit 2028'de kritik eşiğin altına iniyor' | D11: 'Nakit Grafiği' gibi anlamsız başlık | E11: Başlık karar testi | F11: ZORUNLU
A12: Birimler | B12: Tüm finansal görsellerde birim açık | C12: TL, bin TL, milyon TL, %, gün, x | D12: Birim belirsizliği | E12: Birim kapsama %100 | F12: ZORUNLU
A13: Sıfır/negatif | B13: Finansal format standardı | C13: Sıfır='-', negatif kırmızı parantez | D13: -500 veya 0,00 kalabalığı | E13: Format kontrolü | F13: ZORUNLU
A14: Yazı tipi | B14: Tek aile | C14: Aptos veya Segoe UI | D14: Karışık font | E14: Tek font kontrolü | F14: ZORUNLU
... A22: Premium vitrin | B22: Görsel kalite ürün değerinin zorunlu parçasıdır | C22: Kaliteli grafik, gerçek KPI kartı, finansal hiyerarşi, tab rengi, fonksiyonel navigasyon | D22: Sadece doğru hesap yapıp çıplak/varsayılan Excel görünümü bırakmak | E22: Görsel release incelemesi | F22: ZORUNLU

Sheet 04_MUHASEBE_THP
A1: TÜRKİYE MUHASEBE VE TEKDÜZEN HESAP PLANI STANDARDI
A3: Konu | B3: Zorunlu Standart | C3: Örnek Türkçe Ad | D3: THP / Mantık | E3: Hata Riski | F3: Kontrol
A4: Dil | B4: Kullanıcıya görünen finansal terimler Türkçe | C4: Hasılat, Satışların Maliyeti, Brüt Kâr, Faaliyet Giderleri | D4: Türk işletme kullanımına uygun | E4: İngilizce jargon | F4: Terminoloji taraması
A5: Gelir Tablosu | B5: Türk sunum sırası kullanılır | C5: Net Satışlar → Satışların Maliyeti → Brüt Kâr → Faaliyet Giderleri → Faaliyet Kârı | D5: 600/610/611; 620-623; 63x | E5: Yanlış sınıflama | F5: Hesap eşleme
A6: Bilanço | B6: Dönen/Duran Varlık ve Kısa/Uzun Vadeli Yükümlülük ayrımı | C6: Hazır Değerler, Ticari Alacaklar, Stoklar, Mali Borçlar | D6: 1xx / 2xx / 3xx / 4xx / 5xx | E6: Vade sınıfı hatası | F6: Bilanço eşitliği
A7: Nakit Akışı | B7: İşletme/Yatırım/Finansman nakit akışları ayrılır | C7: Faaliyetlerden Nakit, Yatırım Harcamaları, Finansman Nakit Akışı | D7: Dolaylı/doğrudan yöntem açık seçilir | E7: Kâr = nakit sanılması | F7: Nakit devri
A8: Ticari Alacaklar | B8: Cari ve vade mantığı korunur | C8: 120 Alıcılar | D8: 120 | E8: Tahakkuk/nakit karışması | F8: Alacak devir kontrolü
A9: Ticari Borçlar | B9: Tedarikçi borcu ayrı izlenir | C9: 320 Satıcılar | D9: 320 | E9: Gider/ödeme karışması | F9: Borç devir kontrolü
A10: Kasa/Banka | B10: Hazır değerler ayrı izlenir | C10: 100 Kasa, 102 Bankalar | D10: 100 / 102 | E10: Virmanla toplam nakdin değişmesi | F10: Virman değişmezi
A11: Stok | B11: Dikeye uygun stok türü | C11: 150 İlk Madde ve Malzeme, 153 Ticari Mallar | D11: 15x | E11: Maliyet ve stok hareketinin kopması | F11: Stok devri
A12: Maddi Duran Varlık | B12: Yatırım harcaması ve amortisman bağlantılı | C12: 253 Tesis Makine Cihazlar, 255 Demirbaşlar, 257 Birikmiş Amortismanlar | D12: 25x | E12: Yatırım/gider karışması | F12: Net defter değeri devri
A13: Mali Borçlar | B13: Kısa/uzun vadeli borç ayrımı | C13: 300 Banka Kredileri / 400 Banka Kredileri | D13: 300 / 400 | E13: Vade sınıfı yanlış | F13: Borç devri
A14: Özkaynak | B14: Sermaye ve geçmiş yıl kârları ayrı | C14: 500 Sermaye, 570 Geçmiş Yıllar Kârları, 590 Dönem Net Kârı | D14: 5xx | E14: Net kâr bağının kopması | F14: Özkaynak devri
... A18: İstisna | B18: TFRS özel ürün varsa fark açık yazılır | C18: Tekdüzen raporlama ≠ TFRS finansal tablo sunumu | D18: Amaç belirtilir | E18: Standartları karıştırma | F18: Model amacı kontrolü

Sheet 05_KARAR_SATIS
A1: KARAR, GÜVEN VE SATIŞA HAZIRLIK STANDARDI
A3: Alan | B3: Müşteri Sorusu | C3: Zorunlu Ürün Davranışı | D3: Kanıt | E3: Başarısızlık Durumu | F3: Kapı
A4: 5 saniye | B4: Bu ürün neyi çözüyor? | C4: İlk ekranda hedef kullanıcı + pahalı problem + sonuç görünür | D4: Başlık + alt mesaj + gerçek ekran | E4: Ürün yalnız teknik isim | F4: HATA
A5: Acı | B5: Sorun bana neye mal oluyor? | C5: Mümkünse müşterinin kendi verisiyle parasal/zaman etkisi hesaplanır | D5: ROI/acı hesaplama yöntemi | E5: Uydurma tasarruf | F5: HATA
A6: Karar | B6: Bu bilgiyle ne yapacağım? | C6: Her kritik KPI aksiyona bağlanır | D6: KARAR_KUYRUGU | E6: Sadece rapor | F6: HATA
A7: Güven | B7: Bu sayıya neden inanayım? | C7: Kaynak, formül mantığı, kontrol ve son doğrulama görünür | D7: Kontroller + kaynak izi + sürüm | E7: Prestij kelimesi | F7: HATA
A8: Referans | B8: Müşteri yorumu yoksa ne göstereceğim? | C8: Önce/Sonra + Karar Vakası + Hata Önleme Vakası üretilir | D8: Demo/örnek çıktı | E8: Kanıtsız iddia | F8: HATA
A9: Senaryo | B9: Ne olursa işler bozulur? | C9: Baz/Aşağı/Yukarı veya uygun stres senaryosu | D9: Senaryo karşılaştırma | E9: Dekoratif senaryo | F9: HATA
A10: Ters stres | B10: Hangi eşikte karar kırılır? | C10: En az bir kritik sürücü için kırılma eşiği | D10: Kırılma eşiği tablosu | E10: Sadece +/- %10 | F10: UYARI/HATA
A11: Hata tutarlılığı | B11: Formül hata verirse ne olur? | C11: Kontrol GEÇTİ veremez; BLOKE/HATA üretir | D11: Hata taraması | E11: Hata + GEÇTİ birlikte | F11: HATA
A12: Karar motoru | B12: Ne oldu, neden oldu? | C12: Sorun + neden + parasal etki + aksiyon + son tarih | D12: Karar tablosu | E12: Boş sayfa / isim düzeyi modül | F12: HATA
A13: Yönetici özeti | B13: 5 saniyede ne görmeliyim? | C13: Bugün / ne değişti / ne bozulacak / neden / ne yapmalıyım / güven | D13: Yönetici özeti ekranı | E13: KPI kutusu yığını | F13: HATA
A14: Teklif | B14: Neden satın almalıyım? | C14: Dosya özellikleri yerine sonuç ve kaçınılan maliyet sunulur | D14: Ürün sayfası kanıt eşlemesi | E14: Özellik listesiyle satış | F14: HATA
... A19: Pazar kanıtı | B19: Piyasa gerçekten ödüyor mu? | C19: Satış/pilot/LOI/fiyat kabulü olmadan pazar doğrulandı yazılmaz | D19: Gerçek işlem kanıtı | E19: Tahmini talep = satış kabulü | F19: HATA

Sheet KAPAK
A1: KAPAK — İhracat Sipariş Kârlılık & Kur Riski Komutası
A3: İhracat Sipariş Kârlılık & Kur Riski Komutası
A4: İhracat siparişinin net kârını (TL), hedge boşluğunu ve kur riskini hesaplayın; YATIRIM YAPILIR / YATIRIM YAPMA kararını üretin.
A6: Bu ürün ne sağlar?
A7: • Sipariş durum makinesi (TEKLIF→…→KAPALI) + yetim / geçersiz geçiş / ZİNCİR KIRIK
A8: • FOB gelir − üretim − navlun − komisyon + kur farkı = net kâr (TL)
A9: • Hedge oranı vs asgari hedge → açık kur pozisyonu boşluğu
A10: • İşletme sermayesi CAPEX/OPEX + öz kaynak / kredi + NPV/IRR tornado
A11: • Kötümser YATIRIM YAPMA yolu + KANIT_RAPORU
A13: Kimler için?
A14: • İhracat operasyon — sipariş satırını durum makinesinde yönetmek
A15: • CFO / hazine — net kâr + kur riski ile sipariş kabul kararı
... A21: Sürüm 1.0.0 | 2026 | ExcelArşiv | Lisans: Tek kullanıcı | Kod: ISK-PRO

Sheet HIZLI_BASLANGIC
A1: HIZLI BASLANGIC — İhracat Sipariş Kârlılık & Kur Riski Komutası
A3: Üç adımda sonuç
A5: Adım 1 — Girdiler | B5: GIRDI'de FOB, maliyet, hedge ve kurları sarı hücrelere girin; AKIS'te sipariş satırlarını işleyin.
A6: Adım 2 — Karar | B6: PANO ve KARAR'da net kâr, hedge boşluğu, NPV/IRR ve YATIRIM YAPILIR / YATIRIM YAPMA görün.
A7: Adım 3 — Kanıt | B7: KANIT_RAPORU'nu yazdırın; KUYRUKLAR ve SENARYO ile doğrulayın.
A9: Formüller
A10: Gelir_TL = FOB×tahsilat_kur | Maliyet_TL = (üretim+navlun)×rezervasyon_kur | Kur farkı = FOB×(tahsilat−rezervasyon) | Net = Gelir − maliyet − komisyon + kur farkı
A12: Sarı = manuel giriş | Yeşil = formül çıktısı | Şifre 1234 formül alanlarını korur.

Sheet GIRDI
A1: GIRDI — İhracat Sipariş Kârlılık & Kur Riski Komutası
A3: İhracat sipariş girdileri
A4: Sarı hücreler manuel giriştir. Oranlar KURALLAR'dan; kur AYARLAR kur tablosundan.
A5: Alan | B5: Değer | C5: Birim
A6: Şirket / Sipariş | B6: Örnek İhracat Sanayi A.Ş. | C6: metin
A7: Dönem | B7: 2026-Q3 | C7: metin
A8: Hesap Yılı | B8: 2026 | C8: yıl
A9: Döviz Cinsi | B9: USD | C9: metin
A10: FOB [döviz] | B10: 200000 | C10: adet/döviz
A11: Miktar [adet] | B11: 2000 | C11: adet/döviz
A12: Üretim maliyeti [döviz] | B12: 110000 | C12: adet/döviz
A13: Çıkış navlunu [döviz] | B13: 8000 | C13: adet/döviz
A14: Komisyon oranı (giriş) | B14: 0.03 | C14: %
A15: Hedge oranı | B15: 0.6 | C15: %
A16: Tahsilat kuru | B16: 32 | C16: kur
A17: Hedef marj (giriş) | B17: 0.18 | C17: %
A18: Yıllık tekrar [adet] | B18: 4 | C18: adet/döviz
A19: CAPEX / işletme sermayesi [₺] | B19: 600000 | C19: ₺
A20: WACC [%] | B20: 0.2 | C20: %
A21: NPV dönem [yıl] | B21: 3 | C21: yıl
... A23: Öz kaynak oranı [%] | B23: 0.45 | C23: %
A25: Aktif kur / rezervasyon (ayna) | B25: =IFERROR(isk_aktifKur,0)
A26: Asgari hedge (ayna) | B26: =IFERROR(INDEX(CHOOSE(MAX(1,MIN(3,IF(OR(hesapYili="",hesapYili=0),1,hesapYili-isk_yilTaban))),tblKurallar[deger_2025],tblKurallar[deger_2026],tblKurallar[deger_2027]),MATCH("ISK-001",tblKurallar[kural_id],0)),0)
A27: Net kâr TL (ayna) | B27: =IFERROR(isk_netKarTl,0)
A28: Giriş doluluk | B28: =IFERROR(IF(OR(COUNTA(B6:B23)=0,isk_girisBeklenen=0),0,ROUND(COUNTA(B6:B23)/isk_girisBeklenen*100,0)),0)
A30: Giriş tablosu (otomasyon / boş-mod)
A31: Alan Anahtarı | B31: Değer | C31: Birim | D31: Zorunlu | E31: Kaynak | F31: Kontrol
A32: sirket_adi | B32: Örnek İhracat Sanayi A.Ş. | C32: metin | D32: Evet | E32: GIRDI | F32: =IF($A32="","",IF($B32="","EKSİK","TAM"))
A33: donem | B33: 2026-Q3 | C33: metin | D33: Evet | E33: GIRDI | F33: =IF($A33="","",IF($B33="","EKSİK","TAM"))
A34: hesapYili | B34: 2026 | C34: yıl | D34: Evet | E34: GIRDI | F34: =IF($A34="","",IF($B34="","EKSİK","TAM"))
A35: parabirimi | B35: USD | C35: kod | D35: Evet | E35: GIRDI | F35: =IF($A35="","",IF($B35="","EKSİK","TAM"))
A36: fob_doviz | B36: 200000 | C36: döviz | D36: Evet | E36: GIRDI | F36: =IF($A36="","",IF($B36="","EKSİK","TAM"))
A37: miktar | B37: 2000 | C37: adet | D37: Evet | E37: GIRDI | F37: =IF($A37="","",IF($B37="","EKSİK","TAM"))
A38: uretim_maliyet | B38: 110000 | C38: döviz | D38: Evet | E38: GIRDI | F38: =IF($A38="","",IF($B38="","EKSİK","TAM"))
A39: navlun_cikis | B39: 8000 | C39: döviz | D39: Evet | E39: GIRDI | F39: =IF($A39="","",IF($B39="","EKSİK","TAM"))
A40: komisyon_oran | B40: 0.03 | C40: oran | D40: Evet | E40: GIRDI | F40: =IF($A40="","",IF($B40="","EKSİK","TAM"))
A41: hedge_oran | B41: 0.6 | C41: oran | D41: Evet | E41: GIRDI | F41: =IF($A41="","",IF($B41="","EKSİK","TAM"))
A42: tahsilat_kur | B42: 32 | C42: kur | D42: Evet | E42: GIRDI | F42: =IF($A42="","",IF($B42="","EKSİK","TAM"))
A43: hedef_marj | B43: 0.18 | C43: oran | D43: Evet | E43: GIRDI | F43: =IF($A43="","",IF($B43="","EKSİK","TAM"))
A44: yillik_tekrar | B44: 4 | C44: adet | D44: Evet | E44: GIRDI | F44: =IF($A44="","",IF($B44="","EKSİK","TAM"))
...

Sheet KARTLAR
A1: KARTLAR — İhracat Sipariş Kârlılık & Kur Riski Komutası
A3: Alıcı / müşteri kartları — AKIS kaynak kimliği
A5: KartId | B5: Unvan | C5: Ulke | D5: ParaBirimi | E5: RiskNotu | F5: Aktif | G5: Kontrol
A6: MUS-001 | B6: Nordic Trade GmbH | C6: DE | D6: EUR | E6: Düşük | F6: Evet | G6: =IF($A6="","",IF($B6="","EKSİK","TAM"))
A7: MUS-002 | B7: Atlantic Buyers LLC | C7: US | D7: USD | E7: Orta | F7: Evet | G7: =IF($A7="","",IF($B7="","EKSİK","TAM"))
A8: MUS-003 | B8: Gulf Export Co | C8: AE | D8: USD | E8: Yüksek | F8: Evet | G8: =IF($A8="","",IF($B8="","EKSİK","TAM"))
G9: =IF($A9="","",IF($B9="","EKSİK","TAM"))
G10: =IF($A10="","",IF($B10="","EKSİK","TAM"))
G11: =IF($A11="","",IF($B11="","EKSİK","TAM"))
G12: =IF($A12="","",IF($B12="","EKSİK","TAM"))
G13: =IF($A13="","",IF($B13="","EKSİK","TAM"))
G14: =IF($A14="","",IF($B14="","EKSİK","TAM"))
G15: =IF($A15="","",IF($B15="","EKSİK","TAM"))
G16: =IF($A16="","",IF($B16="","EKSİK","TAM"))
G17: =IF($A17="","",IF($B17="","EKSİK","TAM"))
G18: =IF($A18="","",IF($B18="","EKSİK","TAM"))
G19: =IF($A19="","",IF($B19="","EKSİK","TAM"))
G20: =IF($A20="","",IF($B20="","EKSİK","TAM"))
... G1004: =IF($A1004="","",IF($B1004="","EKSİK","TAM"))

Sheet AKIS
A1: AKIS — İhracat Sipariş Kârlılık & Kur Riski Komutası
A3: Sipariş satırları — durum makinesi + yetim + geçersiz geçiş + zincir
A5: IslemId | B5: KaynakKartId | C5: OncekiDurum | D5: Durum | E5: FobDoviz | F5: MaliyetDoviz | G5: Tutar | H5: HedgeOran | I5: YetimBayrak | J5: GecisUyarisi | K5: ZincirBayrak | L5: KayitDolu
A6: SIP-00001 | B6: MUS-001 | D6: ONAY | E6: 80000 | F6: 45000 | G6: 80000 | H6: 0.7 | I6: =IF($A6="","",IF($B6="","YETİM",IF(COUNTIF(tblKartlar[KartId],$B6)=0,"YETİM",""))) | J6: =IF(OR($A6="",$C6=""),"",IF(OR($C6&"|"&$D6="",COUNTIF(ListeIzinliGecis,$C6&"|"&$D6)>0),"","GEÇERSİZ GEÇİŞ")) | K6: =IF($A6="","",IF(OR($E6="",$G6=""),"",IF(ABS($G6-$E6)>zincirTolerans,"ZİNCİR KIRIK","OK"))) | L6: =IF($A6="","",1)
A7: SIP-00002 | B7: MUS-002 | C7: TEKLIF | D7: URETIM | E7: 60000 | F7: 38000 | G7: 60000 | H7: 0.5 | I7: =IF($A7="","",IF($B7="","YETİM",IF(COUNTIF(tblKartlar[KartId],$B7)=0,"YETİM",""))) | J7: =IF(OR($A7="",$C7=""),"",IF(OR($C7&"|"&$D7="",COUNTIF(ListeIzinliGecis,$C7&"|"&$D7)>0),"","GEÇERSİZ GEÇİŞ")) | K7: =IF($A7="","",IF(OR($E7="",$G7=""),"",IF(ABS($G7-$E7)>zincirTolerans,"ZİNCİR KIRIK","OK"))) | L7: =IF($A7="","",1)
A8: SIP-00003 | B8: MUS-001 | C8: SEVK | D8: TAHSILAT | E8: 40000 | F8: 22000 | G8: 40000 | H8: 0.8 | I8: =IF($A8="","",IF($B8="","YETİM",IF(COUNTIF(tblKartlar[KartId],$B8)=0,"YETİM",""))) | J8: =IF(OR($A8="",$C8=""),"",IF(OR($C8&"|"&$D8="",COUNTIF(ListeIzinliGecis,$C8&"|"&$D8)>0),"","GEÇERSİZ GEÇİŞ")) | K8: =IF($A8="","",IF(OR($E8="",$G8=""),"",IF(ABS($G8-$E8)>zincirTolerans,"ZİNCİR KIRIK","OK"))) | L8: =IF($A8="","",1)
A9: SIP-00004 | C9: TEKLIF | D9: ONAY | E9: 20000 | F9: 12000 | G9: 20000 | H9: 0.4 | I9: =IF($A9="","",IF($B9="","YETİM",IF(COUNTIF(tblKartlar[KartId],$B9)=0,"YETİM",""))) | J9: =IF(OR($A9="",$C9=""),"",IF(OR($C9&"|"&$D9="",COUNTIF(ListeIzinliGecis,$C9&"|"&$D9)>0),"","GEÇERSİZ GEÇİŞ")) | K9: =IF($A9="","",IF(OR($E9="",$G9=""),"",IF(ABS($G9-$E9)>zincirTolerans,"ZİNCİR KIRIK","OK"))) | L9: =IF($A9="","",1)
I10: =IF($A10="","",IF($B10="","YETİM",IF(COUNTIF(tblKartlar[KartId],$B10)=0,"YETİM",""))) | J10: =IF(OR($A10="",$C10=""),"",IF(OR($C10&"|"&$D10="",COUNTIF(ListeIzinliGecis,$C10&"|"&$D10)>0),"","GEÇERSİZ GEÇİŞ")) | K10: =IF($A10="","",IF(OR($E10="",$G10=""),"",IF(ABS($G10-$E10)>zincirTolerans,"ZİNCİR KIRIK","OK"))) | L10: =IF($A10="","",1)
I11: =IF($A11="","",IF($B11="","YETİM",IF(COUNTIF(tblKartlar[KartId],$B11)=0,"YETİM",""))) | J11: =IF(OR($A11="",$C11=""),"",IF(OR($C11&"|"&$D11="",COUNTIF(ListeIzinliGecis,$C11&"|"&$D11)>0),"","GEÇERSİZ GEÇİŞ")) | K11: =IF($A11="","",IF(OR($E11="",$G11=""),"",IF(ABS($G11-$E11)>zincirTolerans,"ZİNCİR KIRIK","OK"))) | L11: =IF($A11="","",1)
I12: =IF($A12="","",IF($B12="","YETİM",IF(COUNTIF(tblKartlar[KartId],$B12)=0,"YETİM",""))) | J12: =IF(OR($A12="",$C12=""),"",IF(OR($C12&"|"&$D12="",COUNTIF(ListeIzinliGecis,$C12&"|"&$D12)>0),"","GEÇERSİZ GEÇİŞ")) | K12: =IF($A12="","",IF(OR($E12="",$G12=""),"",IF(ABS($G12-$E12)>zincirTolerans,"ZİNCİR KIRIK","OK"))) | L12: =IF($A12="","",1)
I13: =IF($A13="","",IF($B13="","YETİM",IF(COUNTIF(tblKartlar[KartId],$B13)=0,"YETİM",""))) | J13: =IF(OR($A13="",$C13=""),"",IF(OR($C13&"|"&$D13="",COUNTIF(ListeIzinliGecis,$C13&"|"&$D13)>0),"","GEÇERSİZ GEÇİŞ")) | K13: =IF($A13="","",IF(OR($E13="",$G13=""),"",IF(ABS($G13-$E13)>zincirTolerans,"ZİNCİR KIRIK","OK"))) | L13: =IF($A13="","",1)
I14: =IF($A14="","",IF($B14="","YETİM",IF(COUNTIF(tblKartlar[KartId],$B14)=0,"YETİM",""))) | J14: =IF(OR($A14="",$C14=""),"",IF(OR($C14&"|"&$D14="",COUNTIF(ListeIzinliGecis,$C14&"|"&$D14)>0),"","GEÇERSİZ GEÇİŞ")) | K14: =IF($A14="","",IF(OR($E14="",$G14=""),"",IF(ABS($G14-$E14)>zincirTolerans,"ZİNCİR KIRIK","OK"))) | L14: =IF($A14="","",1)
I15: =IF($A15="","",IF($B15="","YETİM",IF(COUNTIF(tblKartlar[KartId],$B15)=0,"YETİM",""))) | J15: =IF(OR($A15="",$C15=""),"",IF(OR($C15&"|"&$D15="",COUNTIF(ListeIzinliGecis,$C15&"|"&$D15)>0),"","GEÇERSİZ GEÇİŞ")) | K15: =IF($A15="","",IF(OR($E15="",$G15=""),"",IF(ABS($G15-$E15)>zincirTolerans,"ZİNCİR KIRIK","OK"))) | L15: =IF($A15="","",1)
I16: =IF($A16="","",IF($B16="","YETİM",IF(COUNTIF(tblKartlar[KartId],$B16)=0,"YETİM",""))) | J16: =IF(OR($A16="",$C16=""),"",IF(OR($C16&"|"&$D16="",COUNTIF(ListeIzinliGecis,$C16&"|"&$D16)>0),"","GEÇERSİZ GEÇİŞ")) | K16: =IF($A16="","",IF(OR($E16="",$G16=""),"",IF(ABS($G16-$E16)>zincirTolerans,"ZİNCİR KIRIK","OK"))) | L16: =IF($A16="","",1)
I17: =IF($A17="","",IF($B17="","YETİM",IF(COUNTIF(tblKartlar[KartId],$B17)=0,"YETİM",""))) | J17: =IF(OR($A17="",$C17=""),"",IF(OR($C17&"|"&$D17="",COUNTIF(ListeIzinliGecis,$C17&"|"&$D17)>0),"","GEÇERSİZ GEÇİŞ")) | K17: =IF($A17="","",IF(OR($E17="",$G17=""),"",IF(ABS($G17-$E17)>zincirTolerans,"ZİNCİR KIRIK","OK"))) | L17: =IF($A17="","",1)
I18: =IF($A18="","",IF($B18="","YETİM",IF(COUNTIF(tblKartlar[KartId],$B18)=0,"YETİM",""))) | J18: =IF(OR($A18="",$C18=""),"",IF(OR($C18&"|"&$D18="",COUNTIF(ListeIzinliGecis,$C18&"|"&$D18)>0),"","GEÇERSİZ GEÇİŞ")) | K18: =IF($A18="","",IF(OR($E18="",$G18=""),"",IF(ABS($G18-$E18)>zincirTolerans,"ZİNCİR KIRIK","OK"))) | L18: =IF($A18="","",1)
I19: =IF($A19="","",IF($B19="","YETİM",IF(COUNTIF(tblKartlar[KartId],$B19)=0,"YETİM",""))) | J19: =IF(OR($A19="",$C19=""),"",IF(OR($C19&"|"&$D19="",COUNTIF(ListeIzinliGecis,$C19&"|"&$D19)>0),"","GEÇERSİZ GEÇİŞ")) | K19: =IF($A19="","",IF(OR($E19="",$G19=""),"",IF(ABS($G19-$E19)>zincirTolerans,"ZİNCİR KIRIK","OK"))) | L19: =IF($A19="","",1)
I20: =IF($A20="","",IF($B20="","YETİM",IF(COUNTIF(tblKartlar[KartId],$B20)=0,"YETİM",""))) | J20: =IF(OR($A20="",$C20=""),"",IF(OR($C20&"|"&$D20="",COUNTIF(ListeIzinliGecis,$C20&"|"&$D20)>0),"","GEÇERSİZ GEÇİŞ")) | K20: =IF($A20="","",IF(OR($E20="",$G20=""),"",IF(ABS($G20-$E20)>zincirTolerans,"ZİNCİR KIRIK","OK"))) | L20: =IF($A20="","",1)
I21: =IF($A21="","",IF($B21="","YETİM",IF(COUNTIF(tblKartlar[KartId],$B21)=0,"YETİM",""))) | J21: =IF(OR($A21="",$C21=""),"",IF(OR($C21&"|"&$D21="",COUNTIF(ListeIzinliGecis,$C21&"|"&$D21)>0),"","GEÇERSİZ GEÇİŞ")) | K21: =IF($A21="","",IF(OR($E21="",$G21=""),"",IF(ABS($G21-$E21)>zincirTolerans,"ZİNCİR KIRIK","OK"))) | L21: =IF($A21="","",1)
... I1004: =IF($A1004="","",IF($B1004="","YETİM",IF(COUNTIF(tblKartlar[KartId],$B1004)=0,"YETİM",""))) | J1004: =IF(OR($A1004="",$C1004=""),"",IF(OR($C1004&"|"&$D1004="",COUNTIF(ListeIzinliGecis,$C1004&"|"&$D1004)>0),"","GEÇERSİZ GEÇİŞ")) | K1004: =IF($A1004="","",IF(OR($E1004="",$G1004=""),"",IF(ABS($G1004-$E1004)>zincirTolerans,"ZİNCİR KIRIK","OK"))) | L1004: =IF($A1004="","",1)

Sheet KUYRUKLAR
A1: KUYRUKLAR — İhracat Sipariş Kârlılık & Kur Riski Komutası
A3: Durum bazlı canlı kuyruk — kapalı kayıtlar düşer
A5: Kuyruk | B5: Adet | C5: Tutar
A6: Kuyruk TEKLIF | B6: =COUNTIFS(tblAkis[Durum],"TEKLIF",tblAkis[Tutar],">0") | C6: =SUMIFS(tblAkis[Tutar],tblAkis[Durum],"TEKLIF")
A7: Kuyruk ONAY | B7: =COUNTIFS(tblAkis[Durum],"ONAY",tblAkis[Tutar],">0") | C7: =SUMIFS(tblAkis[Tutar],tblAkis[Durum],"ONAY")
A8: Kuyruk URETIM | B8: =COUNTIFS(tblAkis[Durum],"URETIM",tblAkis[Tutar],">0") | C8: =SUMIFS(tblAkis[Tutar],tblAkis[Durum],"URETIM")
A9: Kuyruk SEVK | B9: =COUNTIFS(tblAkis[Durum],"SEVK",tblAkis[Tutar],">0") | C9: =SUMIFS(tblAkis[Tutar],tblAkis[Durum],"SEVK")
A10: Kuyruk TAHSILAT | B10: =COUNTIFS(tblAkis[Durum],"TAHSILAT",tblAkis[Tutar],">0") | C10: =SUMIFS(tblAkis[Tutar],tblAkis[Durum],"TAHSILAT")
A12: Açık toplam (kapalı düşer) | B12: =COUNTIFS(tblAkis[Durum],"<>KAPALI",tblAkis[Durum],"<>IPTAL",tblAkis[Tutar],">0") | C12: =SUMIFS(tblAkis[Tutar],tblAkis[Durum],"<>KAPALI")-SUMIFS(tblAkis[Tutar],tblAkis[Durum],"IPTAL")
A13: Kapalı / iptal adet | B13: =COUNTIF(tblAkis[Durum],"KAPALI")+COUNTIF(tblAkis[Durum],"IPTAL")
A14: Yetim adet | B14: =COUNTIF(tblAkis[YetimBayrak],"YETİM")
A15: Geçersiz geçiş | B15: =COUNTIF(tblAkis[GecisUyarisi],"GEÇERSİZ GEÇİŞ")
A16: ZİNCİR KIRIK | B16: =COUNTIF(tblAkis[ZincirBayrak],"ZİNCİR KIRIK")
A18: Kuyruk özeti | B18: =_xlfn.TEXTJOIN(" | ",TRUE,"Açık",B12,"Yetim",B14,"Geçiş",B15,"Zincir",B16)
A20: KuyrukDemo
A21: ONAY | B21: 1
A22: URETIM | B22: 1
A23: TAHSILAT | B23: 1
A24: TEKLIF | B24: 0

Sheet VARSAYIMLAR
A1: VARSAYIMLAR — İhracat Sipariş Kârlılık & Kur Riski Komutası
A3: Varsayımlar — kaynak + güven (F02)
A5: varsayim_id | B5: ad | C5: deger | D5: birim | E5: kaynak | F5: guven | G5: tornado | H5: kontrol
A6: V01 | B6: Rezervasyon kuru | C6: 34 | D6: kur | E6: TCMB / kur tablosu | F6: sert | G6: Evet | H6: =IF($A6="","",IF(OR($E6="",$F6=""),"EKSİK","TAM"))
A7: V02 | B7: Tahsilat kuru | C7: 32 | D7: kur | E7: Hazine tahmini | F7: yumuşak | G7: Evet | H7: =IF($A7="","",IF(OR($E7="",$F7=""),"EKSİK","TAM"))
A8: V03 | B8: Hedge oranı | C8: 0.6 | D8: oran | E8: Hazine politikası | F8: sert | G8: Evet | H8: =IF($A8="","",IF(OR($E8="",$F8=""),"EKSİK","TAM"))
A9: V04 | B9: Asgari hedge | C9: 0.8 | D9: oran | E9: ISK-001 | F9: sert | G9: Hayır | H9: =IF($A9="","",IF(OR($E9="",$F9=""),"EKSİK","TAM"))
A10: V05 | B10: Komisyon | C10: 0.03 | D10: oran | E10: ISK-004 | F10: sert | G10: Hayır | H10: =IF($A10="","",IF(OR($E10="",$F10=""),"EKSİK","TAM"))
A11: V06 | B11: Kur şoku | C11: 0.1 | D11: oran | E11: ISK-003 | F11: yumuşak | G11: Evet | H11: =IF($A11="","",IF(OR($E11="",$F11=""),"EKSİK","TAM"))
A12: V07 | B12: WACC | C12: 0.2 | D12: oran | E12: CFO varsayımı | F12: yumuşak | G12: Hayır | H12: =IF($A12="","",IF(OR($E12="",$F12=""),"EKSİK","TAM"))
A13: V08 | B13: İşletme sermayesi CAPEX | C13: 600000 | D13: TL | E13: Nakit planı | F13: yumuşak | G13: Hayır | H13: =IF($A13="","",IF(OR($E13="",$F13=""),"EKSİK","TAM"))

Sheet KURALLAR
A1: KURALLAR — İhracat Sipariş Kârlılık & Kur Riski Komutası
A3: Kural motoru — ISK-001…005 (yıl yan yana)
A5: kural_id | B5: madde | C5: kural_adi | D5: kosul_metni | E5: parametre_adi | F5: deger_2025 | G5: deger_2026 | H5: deger_2027 | I5: yururluk | J5: kaynak | K5: kontrol
A6: ISK-001 | B6: Hazine politikası | C6: Asgari hedge oranı | D6: Açık döviz pozisyonu için asgari kapsama | E6: asgari_hedge | F6: 0.75 | G6: 0.8 | H6: 0.8 | I6: 01.01.2025 | J6: İç hazine politikası | K6: =IF($A6="","",IF($J6="","EKSİK","TAM"))
A7: ISK-002 | B7: Satış politikası | C7: Hedef ihracat marjı | D7: Net kâr / gelir alt sınırı | E7: hedef_marj | F7: 0.18 | G7: 0.18 | H7: 0.18 | I7: 01.01.2025 | J7: CFO marj politikası | K7: =IF($A7="","",IF($J7="","EKSİK","TAM"))
A8: ISK-003 | B8: Kur stres | C8: Kur şoku oranı | D8: Kötümser kur düşüşü | E8: kur_soku | F8: 0.08 | G8: 0.1 | H8: 0.12 | I8: 01.01.2025 | J8: Hazine stres testi | K8: =IF($A8="","",IF($J8="","EKSİK","TAM"))
A9: ISK-004 | B9: Komisyon | C9: Satış komisyonu oranı | D9: FOB üzerinden komisyon | E9: komisyon | F9: 0.025 | G9: 0.03 | H9: 0.03 | I9: 01.01.2025 | J9: Satış sözleşmesi | K9: =IF($A9="","",IF($J9="","EKSİK","TAM"))
A10: ISK-005 | B10: Yuvarlama | C10: Yuvarlama basamağı | D10: TL yuvarlama ondalığı | E10: yuvarlama | F10: 0 | G10: 0 | H10: 0 | I10: 01.01.2025 | J10: Ürün mimarisi | K10: =IF($A10="","",IF($J10="","EKSİK","TAM"))
A12: Belirsizlik: hedge etkinlik yorumu — kullanıcı kendi banka teyidini girmelidir.
A14: Yıl matrisi özeti | B14: =IFERROR(_xlfn.TEXTJOIN(" | ",TRUE,"ISK-001",IFERROR(INDEX(tblKurallar[deger_2026],MATCH("ISK-001",tblKurallar[kural_id],0)),0),"ISK-002",IFERROR(INDEX(tblKurallar[deger_2026],MATCH("ISK-002",tblKurallar[kural_id],0)),0)),"-")
A17: Kural yıl matrisi (ad tanımı) | B17: =IFERROR(B14,"-")

Sheet MOTOR
A1: MOTOR — İhracat Sipariş Kârlılık & Kur Riski Komutası
A3: Hesap zinciri — sipariş kârı + kur riski + NPV
A4: Oranlar tblKurallar'dan; kur tblKur'dan çekilir.
A6: adim | B6: ad | C6: formul | D6: birim | E6: ne_ise_yarar | F6: kural_id | G6: deger
A7: 1 | B7: Hesap yılı oku | C7: =IFERROR(hesapYili,0) | D7: yıl | E7: Aktif kural yılı | F7: ISK-005 | G7: =IFERROR(hesapYili,0)
A8: 2 | B8: Asgari hedge | C8: =IFERROR(INDEX(CHOOSE(MAX(1,MIN(3,IF(OR(hesapYili="",hesapYili=0),1,hesapYili-isk_yilTaban))),tblKurallar[deger_2025],tblKurallar[deger_2026],tblKurallar[deger_2027]),MATCH("ISK-001",tblKurallar[kural_id],0)),0) | D8: oran | E8: Asgari hedge oranı | F8: ISK-001 | G8: =IFERROR(INDEX(CHOOSE(MAX(1,MIN(3,IF(OR(hesapYili="",hesapYili=0),1,hesapYili-isk_yilTaban))),tblKurallar[deger_2025],tblKurallar[deger_2026],tblKurallar[deger_2027]),MATCH("ISK-001",tblKurallar[kural_id],0)),0)
A9: 3 | B9: Hedef marj kural | C9: =IFERROR(INDEX(CHOOSE(MAX(1,MIN(3,IF(OR(hesapYili="",hesapYili=0),1,hesapYili-isk_yilTaban))),tblKurallar[deger_2025],tblKurallar[deger_2026],tblKurallar[deger_2027]),MATCH("ISK-002",tblKurallar[kural_id],0)),0) | D9: oran | E9: Hedef net marj | F9: ISK-002 | G9: =IFERROR(INDEX(CHOOSE(MAX(1,MIN(3,IF(OR(hesapYili="",hesapYili=0),1,hesapYili-isk_yilTaban))),tblKurallar[deger_2025],tblKurallar[deger_2026],tblKurallar[deger_2027]),MATCH("ISK-002",tblKurallar[kural_id],0)),0)
A10: 4 | B10: Kur şoku oranı | C10: =IFERROR(INDEX(CHOOSE(MAX(1,MIN(3,IF(OR(hesapYili="",hesapYili=0),1,hesapYili-isk_yilTaban))),tblKurallar[deger_2025],tblKurallar[deger_2026],tblKurallar[deger_2027]),MATCH("ISK-003",tblKurallar[kural_id],0)),0) | D10: oran | E10: Kötümser kur şoku | F10: ISK-003 | G10: =IFERROR(INDEX(CHOOSE(MAX(1,MIN(3,IF(OR(hesapYili="",hesapYili=0),1,hesapYili-isk_yilTaban))),tblKurallar[deger_2025],tblKurallar[deger_2026],tblKurallar[deger_2027]),MATCH("ISK-003",tblKurallar[kural_id],0)),0)
A11: 5 | B11: Komisyon kural | C11: =IFERROR(INDEX(CHOOSE(MAX(1,MIN(3,IF(OR(hesapYili="",hesapYili=0),1,hesapYili-isk_yilTaban))),tblKurallar[deger_2025],tblKurallar[deger_2026],tblKurallar[deger_2027]),MATCH("ISK-004",tblKurallar[kural_id],0)),0) | D11: oran | E11: Komisyon oranı | F11: ISK-004 | G11: =IFERROR(INDEX(CHOOSE(MAX(1,MIN(3,IF(OR(hesapYili="",hesapYili=0),1,hesapYili-isk_yilTaban))),tblKurallar[deger_2025],tblKurallar[deger_2026],tblKurallar[deger_2027]),MATCH("ISK-004",tblKurallar[kural_id],0)),0)
A12: 6 | B12: Yuvarlama ondalık | C12: =IFERROR(INDEX(CHOOSE(MAX(1,MIN(3,IF(OR(hesapYili="",hesapYili=0),1,hesapYili-isk_yilTaban))),tblKurallar[deger_2025],tblKurallar[deger_2026],tblKurallar[deger_2027]),MATCH("ISK-005",tblKurallar[kural_id],0)),0) | D12: adet | E12: Yuvarlama basamağı | F12: ISK-005 | G12: =IFERROR(INDEX(CHOOSE(MAX(1,MIN(3,IF(OR(hesapYili="",hesapYili=0),1,hesapYili-isk_yilTaban))),tblKurallar[deger_2025],tblKurallar[deger_2026],tblKurallar[deger_2027]),MATCH("ISK-005",tblKurallar[kural_id],0)),0)
A13: 7 | B13: Aktif / rezervasyon kur | C13: =IFERROR(isk_aktifKur,0) | D13: kur | E13: Kur tablosu aktif kur | F13: ISK-005 | G13: =IFERROR(isk_aktifKur,0)
A14: 8 | B14: FOB döviz | C14: =IFERROR(GIRDI!B10,0) | D14: döviz | E14: FOB tutarı | F14: ISK-002 | G14: =IFERROR(GIRDI!B10,0)
A15: 9 | B15: Miktar | C15: =IFERROR(GIRDI!B11,0) | D15: adet | E15: Sipariş miktarı | F15: ISK-005 | G15: =IFERROR(GIRDI!B11,0)
A16: 10 | B16: Üretim maliyet döviz | C16: =IFERROR(GIRDI!B12,0) | D16: döviz | E16: Üretim maliyeti | F16: ISK-002 | G16: =IFERROR(GIRDI!B12,0)
A17: 11 | B17: Navlun çıkış döviz | C17: =IFERROR(GIRDI!B13,0) | D17: döviz | E17: Çıkış navlunu | F17: ISK-002 | G17: =IFERROR(GIRDI!B13,0)
A18: 12 | B18: Komisyon giriş | C18: =IFERROR(GIRDI!B14,0) | D18: oran | E18: Komisyon (giriş) | F18: ISK-004 | G18: =IFERROR(GIRDI!B14,0)
A19: 13 | B19: Hedge oranı | C19: =IFERROR(GIRDI!B15,0) | D19: oran | E19: Kapsanan oran | F19: ISK-001 | G19: =IFERROR(GIRDI!B15,0)
A20: 14 | B20: Tahsilat kuru | C20: =IFERROR(GIRDI!B16,0) | D20: kur | E20: Tahsilat kuru | F20: ISK-003 | G20: =IFERROR(GIRDI!B16,0)
A21: 15 | B21: Hedef marj giriş | C21: =IFERROR(GIRDI!B17,0) | D21: oran | E21: Hedef marj (giriş) | F21: ISK-002 | G21: =IFERROR(GIRDI!B17,0)
A22: 16 | B22: Yıllık tekrar | C22: =IFERROR(GIRDI!B18,0) | D22: adet | E22: Yıllık sipariş adedi | F22: ISK-005 | G22: =IFERROR(GIRDI!B18,0)
A23: 17 | B23: CAPEX / YATIRIM | C23: =IFERROR(GIRDI!B19,0) | D23: TL | E23: İşletme sermayesi | F23: ISK-005 | G23: =IFERROR(GIRDI!B19,0)
A24: 18 | B24: WACC | C24: =IFERROR(GIRDI!B20,0) | D24: oran | E24: İskonto oranı | F24: ISK-005 | G24: =IFERROR(GIRDI!B20,0)
A25: 19 | B25: NPV dönem | C25: =IFERROR(GIRDI!B21,0) | D25: adet | E25: Nakit akışı yılı | F25: ISK-005 | G25: =IFERROR(GIRDI!B21,0)
... A27: 21 | B27: Öz kaynak oranı | C27: =IFERROR(GIRDI!B23,0) | D27: oran | E27: Öz kaynak payı | F27: ISK-005 | G27: =IFERROR(GIRDI!B23,0)
A28: 22 | B28: Gelir TL (tahsilat) | C28: =IFERROR(ROUND(G14*G20,MAX(0,MIN(isk_yuvarMax,IFERROR(N(G12),0)))),0) | D28: TL | E28: FOB×tahsilat kur | F28: ISK-002 | G28: =IFERROR(ROUND(G14*G20,MAX(0,MIN(isk_yuvarMax,IFERROR(N(G12),0)))),0)
A29: 23 | B29: Maliyet TL (rezervasyon) | C29: =IFERROR(ROUND((G16+G17)*G13,MAX(0,MIN(isk_yuvarMax,IFERROR(N(G12),0)))),0) | D29: TL | E29: (üretim+navlun)×rezervasyon | F29: ISK-002 | G29: =IFERROR(ROUND((G16+G17)*G13,MAX(0,MIN(isk_yuvarMax,IFERROR(N(G12),0)))),0)
A30: 24 | B30: Komisyon TL | C30: =IFERROR(ROUND(G14*G13*G18,MAX(0,MIN(isk_yuvarMax,IFERROR(N(G12),0)))),0) | D30: TL | E30: FOB×rezervasyon×komisyon | F30: ISK-004 | G30: =IFERROR(ROUND(G14*G13*G18,MAX(0,MIN(isk_yuvarMax,IFERROR(N(G12),0)))),0)
A31: 25 | B31: Kur farkı TL | C31: =IFERROR(ROUND(G14*(G20-G13),MAX(0,MIN(isk_yuvarMax,IFERROR(N(G12),0)))),0) | D31: TL | E31: FOB×(tahsilat−rezervasyon) | F31: ISK-003 | G31: =IFERROR(ROUND(G14*(G20-G13),MAX(0,MIN(isk_yuvarMax,IFERROR(N(G12),0)))),0)
A32: 26 | B32: Net kâr TL | C32: =IFERROR(G28-G29-G30+G31,0) | D32: TL | E32: Gelir−maliyet−komisyon+kur farkı | F32: ISK-002 | G32: =IFERROR(G28-G29-G30+G31,0)
A33: 27 | B33: Net marj | C33: =IFERROR(IF(G28=0,0,G32/G28),0) | D33: oran | E33: Net kâr / gelir | F33: ISK-002 | G33: =IFERROR(IF(G28=0,0,G32/G28),0)
A34: 28 | B34: Açık pozisyon döviz | C34: =IFERROR(G14*(isk_bazCarpan-G19),0) | D34: döviz | E34: Hedge edilmemiş FOB | F34: ISK-001 | G34: =IFERROR(G14*(isk_bazCarpan-G19),0)
A35: 29 | B35: Hedge boşluğu | C35: =IFERROR(MAX(0,G8-G19),0) | D35: oran | E35: Asgari−gerçek hedge | F35: ISK-001 | G35: =IFERROR(MAX(0,G8-G19),0)
A36: 30 | B36: Kur riski TL | C36: =IFERROR(ROUND(G34*G13*G10,MAX(0,MIN(isk_yuvarMax,IFERROR(N(G12),0)))),0) | D36: TL | E36: Açık×kur×şok | F36: ISK-003 | G36: =IFERROR(ROUND(G34*G13*G10,MAX(0,MIN(isk_yuvarMax,IFERROR(N(G12),0)))),0)
A37: 31 | B37: OPEX / ISLETME yıllık | C37: =IFERROR(ABS(G29)*G22,0) | D37: TL | E37: Maliyet×yıllık tekrar | F37: ISK-005 | G37: =IFERROR(ABS(G29)*G22,0)
A38: 32 | B38: Yıllık net katkı | C38: =IFERROR(G32*G22,0) | D38: TL | E38: Net kâr × yıllık tekrar | F38: ISK-002 | G38: =IFERROR(G32*G22,0)
A39: 33 | B39: NPV (baz) | C39: =IFERROR(IF(OR(G25<=0,G24=""),0,IF(G24=0,ROUND(G38*G25-G23,MAX(0,MIN(isk_yuvarMax,IFERROR(N(G12),0)))),ROUND(G38*(1-POWER(1+G24,-G25))/G24-G23,MAX(0,MIN(isk_yuvarMax,IFERROR(N(G12),0)))))),0) | D39: TL | E39: NPV nakit − CAPEX | F39: ISK-005 | G39: =IFERROR(IF(OR(G25<=0,G24=""),0,IF(G24=0,ROUND(G38*G25-G23,MAX(0,MIN(isk_yuvarMax,IFERROR(N(G12),0)))),ROUND(G38*(1-POWER(1+G24,-G25))/G24-G23,MAX(0,MIN(isk_yuvarMax,IFERROR(N(G12),0)))))),0)
A40: 34 | B40: IRR yaklaşımı | C40: =IFERROR(IF(OR(G23<=0,G38<=0,G25<=0),0,ROUND(G38/G23-isk_bazCarpan/G25,4)),0) | D40: oran | E40: Kabaca IRR göstergesi | F40: ISK-005 | G40: =IFERROR(IF(OR(G23<=0,G38<=0,G25<=0),0,ROUND(G38/G23-isk_bazCarpan/G25,4)),0)
A41: 35 | B41: Karar kodu | C41: =IFERROR(IF(COUNTA(tblGirdi[Alan Anahtarı])=0,"VERI_YOK",IF(OR(G14<=0,G13<=0,G20<=0),"YAPMA",IF(OR(G39<0,G35>isk_hedgeDikkat,G33<G9*isk_dikkatCarpan),"YAPMA",IF(OR(G33<G9,G39<isk_npvDikkat,G35>0),"DIKKAT","YAPILIR")))),"") | D41: kod | E41: Karar kodu | F41: ISK-002 | G41: =IFERROR(IF(COUNTA(tblGirdi[Alan Anahtarı])=0,"VERI_YOK",IF(OR(G14<=0,G13<=0,G20<=0),"YAPMA",IF(OR(G39<0,G35>isk_hedgeDikkat,G33<G9*isk_dikkatCarpan),"YAPMA",IF(OR(G33<G9,G39<isk_npvDikkat,G35>0),"DIKKAT","YAPILIR")))),"")
A42: 36 | B42: Karar metni | C42: =IFERROR(IF(G41="VERI_YOK","VERİ YOK",IF(G41="YAPILIR","YATIRIM YAPILIR",IF(G41="DIKKAT","DİKKAT","YATIRIM YAPMA"))),"") | D42: metin | E42: Kullanıcıya karar | F42: ISK-002 | G42: =IFERROR(IF(G41="VERI_YOK","VERİ YOK",IF(G41="YAPILIR","YATIRIM YAPILIR",IF(G41="DIKKAT","DİKKAT","YATIRIM YAPMA"))),"")
A43: 37 | B43: Gerekçe | C43: =IFERROR(IF(G41="VERI_YOK","Giriş tablosu boş — hesap yapılamaz.",IF(G41="YAPILIR","NPV pozitif, marj hedef üstü, hedge yeterli; sipariş kabul uygun.",IF(G41="DIKKAT","Marj, hedge boşluğu veya NPV dikkat bandında; kuru gözden geçirin.","NPV negatif, marj düşük veya kur riski yüksek; YATIRIM YAPMA."))),"") | D43: metin | E43: Gerekçe cümlesi | F43: ISK-002 | G43: =IFERROR(IF(G41="VERI_YOK","Giriş tablosu boş — hesap yapılamaz.",IF(G41="YAPILIR","NPV pozitif, marj hedef üstü, hedge yeterli; sipariş kabul uygun.",IF(G41="DIKKAT","Marj, hedge boşluğu veya NPV dikkat bandında; kuru gözden geçirin.","NPV negatif, marj düşük veya kur riski yüksek; YATIRIM YAPMA."))),"")
...

Sheet FINANSMAN
A1: FINANSMAN — İhracat Sipariş Kârlılık & Kur Riski Komutası
A3: Finansman senaryoları — OZ_KAYNAK ve KREDI
A5: Senaryo | B5: Pay | C5: Tutar [₺] | D5: Faiz / maliyet | E5: NPV etkisi
A6: OZ_KAYNAK | B6: =GIRDI!B23 | C6: =GIRDI!B19*B6 | D6: =IFERROR(GIRDI!B23*isk_sifirCarpan,0) | E6: =IFERROR(MOTOR!G39,0)
A7: KREDI | B7: =isk_bazCarpan-GIRDI!B23 | C7: =GIRDI!B19*B7 | D7: =GIRDI!B22 | E7: =IFERROR(MOTOR!G39-C7*D7*GIRDI!B21,0)
A9: CAPEX / YATIRIM toplam | B9: =GIRDI!B19
A10: OPEX / ISLETME yıllık | B10: =IFERROR(MOTOR!G37,0)
A11: Finansman karşılaştırma | B11: =IFERROR(_xlfn.TEXTJOIN(" | ",TRUE,"OZ_KAYNAK NPV ",TEXT(E6,"₺ #,##0")," · KREDI NPV ",TEXT(E7,"₺ #,##0")),"-")
A13: FinansDemo
A14: OZ_KAYNAK | B14: 270000
A15: KREDI | B15: 330000

Sheet SENARYO
A1: SENARYO — İhracat Sipariş Kârlılık & Kur Riski Komutası
A3: Senaryo ve duyarlılık (tornado)
A5: Senaryo | B5: Çarpan | C5: Net kâr | D5: NPV | E5: Karar | G5: NpvDemo
A6: İyimser | B6: =IFERROR(isk_senaryoIyi+N(GIRDI!B10)*isk_sifirCarpan,0) | C6: =IFERROR(MOTOR!G46,0) | D6: =IFERROR(MOTOR!G48,0) | E6: =IF(COUNTA(tblGirdi[Alan Anahtarı])=0,"VERİ YOK",IF(D6<0,"YATIRIM YAPMA","YATIRIM YAPILIR")) | G6: 1800000
A7: Baz | B7: =IFERROR(isk_bazCarpan+N(GIRDI!B10)*isk_sifirCarpan,1) | C7: =IFERROR(isk_netKarTl,0) | D7: =IFERROR(isk_npv,0) | E7: =IF(COUNTA(tblGirdi[Alan Anahtarı])=0,"VERİ YOK",IFERROR(isk_kararMetni,"-")) | G7: 900000
A8: Kötümser | B8: =IFERROR(isk_senaryoKotu+N(GIRDI!B10)*isk_sifirCarpan,0) | C8: =IFERROR(MOTOR!G47,0) | D8: =IFERROR(MOTOR!G49,0) | E8: =IF(COUNTA(tblGirdi[Alan Anahtarı])=0,"VERİ YOK",IFERROR(MOTOR!G50,"YATIRIM YAPMA")) | G8: -250000
A9: M-SEN kur+ | B9: =IFERROR(isk_bazCarpan+N(GIRDI!B10)*isk_sifirCarpan,1) | C9: =IFERROR(isk_netKarTl-MOTOR!G52,0) | D9: =IFERROR(MOTOR!G39,0) | E9: =IF(COUNTA(tblGirdi[Alan Anahtarı])=0,"VERİ YOK",IF(MOTOR!G53=1,"YATIRIM YAPILIR","DİKKAT")) | G9: 700000
A11: Senaryo NPV bant (iyimser−kötümser) | B11: =IFERROR(D6-D8,0)
A12: Senaryo yorumu | B12: =IFERROR(_xlfn.TEXTJOIN("; ",TRUE,"İyimser NPV ",TEXT(D6,"₺ #,##0")," · Baz ",TEXT(D7,"₺ #,##0")," · Kötümser ",TEXT(D8,"₺ #,##0")),"-")
A14: Duyarlılık (tornado)
A15: Değişken | B15: Etki [₺] | C15: Sıra | E15: EtkiDemo
A16: Tornado kur etkisi | B16: =IFERROR(MOTOR!G54,0) | C16: =IFERROR(IF(B16>=MAX(B16:B18),isk_siraBir,IF(B16=MEDIAN(B16:B18),isk_siraIki,isk_siraUc)),isk_siraUc) | E16: 220000
A17: Tornado hedge etkisi | B17: =IFERROR(MOTOR!G55,0) | C17: =IFERROR(IF(B17>=MAX(B16:B18),isk_siraBir,IF(B17=MEDIAN(B16:B18),isk_siraIki,isk_siraUc)),isk_siraUc) | E17: 160000
A18: Tornado maliyet etkisi | B18: =IFERROR(MOTOR!G56,0) | C18: =IFERROR(IF(B18>=MAX(B16:B18),isk_siraBir,IF(B18=MEDIAN(B16:B18),isk_siraIki,isk_siraUc)),isk_siraUc) | E18: 95000
A19: Duyarlılık sıra özeti | B19: =IFERROR(CONCATENATE("1)",INDEX(A16:A18,MATCH(isk_siraBir,C16:C18,0))," 2)",INDEX(A16:A18,MATCH(isk_siraIki,C16:C18,0))),"-")
A20: Duyarlılık yorumu | B20: =_xlfn.TEXTJOIN("; ",TRUE,"En yüksek etki ",TEXT(MAX(B16:B18),"₺ #,##0")," — öncelik bu değişkende")
A22: M-SEN kur değişimi bayrağı | B22: =MOTOR!G53
A23: M-SEN yorumu | B23: =_xlfn.TEXTJOIN("; ",TRUE,"Sıkı kur şoku (+",TEXT(isk_esikArtis,"0.0%"),") uygunluk ",TEXT(B22,"0"))
A25: Tahmin alt | B25: =IFERROR(isk_netKarTl*isk_tahminAlt,0) | C25: =IFERROR(isk_netKarTl,0) | D25: =IFERROR(isk_netKarTl*isk_tahminUst,0)
A26: Tahmin (AVERAGE / STDEV)
A27: Seri nokta | D27: TrendDemo
A28: 1 | B28: =C6 | D28: 1100000
A29: 2 | B29: =C7 | D29: 1250000
A30: 3 | B30: =C8 | D30: 980000
A31: 4 | B31: =C9 | D31: 1250000
A32: Tahmin sonraki | B32: =IFERROR(IF(OR(COUNT(B28:B31)<2,STDEV(B28:B31)=0),AVERAGE(B28:B31),AVERAGE(B28:B31)+STDEV(B28:B31)*0),0)
A33: Tahmin yorumu | B33: =_xlfn.TEXTJOIN("; ",TRUE,"Tahmin ",TEXT(B32,"₺ #,##0")," · Alt ",TEXT(B25,"₺ #,##0")," · Üst ",TEXT(D25,"₺ #,##0"))

Sheet KARAR
A1: KARAR — İhracat Sipariş Kârlılık & Kur Riski Komutası
A3: Sipariş / yatırım karar kapısı
A5: Karar | B5: =isk_kararMetni
A6: Gerekçe | B6: =isk_kararGerekce
A8: NPV [₺] | B8: =isk_npv
A9: IRR | B9: =isk_irr
A10: Net kâr [₺] | B10: =isk_netKarTl
A11: Kötümser karar | B11: =IFERROR(MOTOR!G50,"YATIRIM YAPMA")
A13: CAPEX / YATIRIM | B13: =GIRDI!B19
A14: OPEX / ISLETME yıllık | B14: =IFERROR(MOTOR!G37,0)
A15: Hedge boşluğu | B15: =isk_hedgeBosluk
A17: Boş girişte karar daima VERİ YOK olur. Kötümser NPV negatifse YATIRIM YAPMA üretilir.

Sheet VAKALAR
A1: VAKALAR — İhracat Sipariş Kârlılık & Kur Riski Komutası
A3: Altın vakalar — ihracat kâr / kur
A5: vaka_id | B5: aciklama | C5: girdi_ozeti | D5: beklenen_sonuc | E5: hesaplanan | F5: fark | G5: durum | H5: kaynak
A6: V-001 | B6: Gelir TL = FOB × tahsilat kur | C6: fob=vaka_fob; tah=vaka_tah | D6: 6400000 | E6: =IF($A6="","",IFERROR(INDEX($E$6:$E$9,MATCH($A6,$A$6:$A$9,0)),0)) | F6: =IF($A6="","",IFERROR($E6-$D6,0)) | G6: =IF($A6="","",IFERROR(IF(ABS($F6)<=isk_tolerans,"TUTARLI","KIRIK"),"KIRIK")) | H6: Gelir TL
A7: V-002 | B7: Maliyet TL = (üretim+navlun)×rezervasyon | C7: uretim+navlun; rez=vaka_rez | D7: 4012000 | E7: =IF($A7="","",IFERROR(INDEX($E$6:$E$9,MATCH($A7,$A$6:$A$9,0)),0)) | F7: =IF($A7="","",IFERROR($E7-$D7,0)) | G7: =IF($A7="","",IFERROR(IF(ABS($F7)<=isk_tolerans,"TUTARLI","KIRIK"),"KIRIK")) | H7: Maliyet
A8: V-003 | B8: Kur farkı = FOB×(tah−rez) | C8: tah-rez | D8: -400000 | E8: =IF($A8="","",IFERROR(INDEX($E$6:$E$9,MATCH($A8,$A$6:$A$9,0)),0)) | F8: =IF($A8="","",IFERROR($E8-$D8,0)) | G8: =IF($A8="","",IFERROR(IF(ABS($F8)<=isk_tolerans,"TUTARLI","KIRIK"),"KIRIK")) | H8: Kur farkı
A9: V-004 | B9: Net kâr = gelir−maliyet−komisyon+kur farkı | C9: komisyon=vaka_kom | D9: 1784000 | E9: =IF($A9="","",IFERROR(INDEX($E$6:$E$9,MATCH($A9,$A$6:$A$9,0)),0)) | F9: =IF($A9="","",IFERROR($E9-$D9,0)) | G9: =IF($A9="","",IFERROR(IF(ABS($F9)<=isk_tolerans,"TUTARLI","KIRIK"),"KIRIK")) | H9: Net kâr
A12: Vaka durumu özeti | B12: =IFERROR(IF(COUNTIF(G6:G9,"KIRIK")>0,"KIRIK","TUTARLI"),"KIRIK")
A13: Toplam mutlak fark | B13: =IFERROR(SUM(ABS(F6),ABS(F7),ABS(F8),ABS(F9)),0)

Sheet KANIT_RAPORU
A1: KANIT RAPORU — İhracat Sipariş Kârlılık & Kur Riski Komutası
A3: KANIT RAPORU — İhracat Sipariş Kârlılık & Kur Riski
A4: CFO / hazine / SMMM dosyası
A6: Şirket | B6: =GIRDI!B6
A7: Dönem | B7: =GIRDI!B7
A8: Hesap yılı | B8: =hesapYili
A9: Rapor tarihi | B9: =raporTarihi
A10: Aktif kur | B10: =isk_aktifKur
A12: Net kâr [₺] | B12: =isk_netKarTl
A13: Hedge boşluğu | B13: =isk_hedgeBosluk
A14: Kur riski [₺] | B14: =MOTOR!G36
A15: NPV [₺] | B15: =isk_npv
A16: IRR | B16: =isk_irr
A18: Karar | B18: =isk_kararMetni
A19: Gerekçe | B19: =isk_kararGerekce
A21: Madde / kural atıfı | B21: =isk_maddeAtifMetni
A23: Kanıt özeti | B23: =isk_kanitRaporu
A25: Parmak izi | B25: =isk_parmakIzi
A28: Hazırlayan
A29: Onaylayan
A32: Bu çıktı karar destek amaçlıdır; bağlayıcı yatırım veya döviz tavsiyesi değildir.

Sheet KONTROLLER
A1: KONTROLLER — İhracat Sipariş Kârlılık & Kur Riski Komutası
A3: Dosya sağlık kontrolleri
A5: Giriş dolu mu? | B5: =IFERROR(IF(COUNTA(tblGirdi[Alan Anahtarı])=0,"BOŞ","DOLU"),"BOŞ")
A6: Hesap yılı geçerli mi? | B6: =IFERROR(IF(AND(N(hesapYili)>N(isk_yilTaban),N(hesapYili)<=N(isk_yilTaban)+3),"TEMİZ","HATALI"),"HATALI")
A7: Kur > 0? | B7: =IFERROR(IF(isk_aktifKur>0,"TEMİZ","HATALI"),"HATALI")
A8: FOB > 0? | B8: =IFERROR(IF(MOTOR!G14>0,"TEMİZ","HATALI"),"HATALI")
A9: Net kâr kontrol | B9: =IFERROR(IF(MOTOR!G32<-isk_azamiEsik,"NEGATİF","NORMAL"),"NORMAL")
A10: Vaka durumu | B10: =IFERROR(isk_vakaDurum,"KIRIK")
A11: Hedge boşluğu? | B11: =IF(IFERROR(MOTOR!G35,0)>0,"AŞIYOR","NORMAL")
A13: Sağlık skoru | B13: =IFERROR(ROUND((COUNTIF(B5:B11,"TEMİZ")+COUNTIF(B5:B11,"DOLU")+COUNTIF(B5:B11,"NORMAL")+COUNTIF(B5:B11,"TUTARLI"))/7*100,0),0)
A15: Net kâr | B15: =IFERROR(isk_netKarTl,0)
A16: NPV | B16: =IFERROR(isk_npv,0)
A17: IRR | B17: =IFERROR(isk_irr,0)
A18: Karar | B18: =IFERROR(isk_kararMetni,"-")

Sheet ORNEK_VERI
A1: ORNEK VERI — İhracat Sipariş Kârlılık & Kur Riski Komutası
A3: Örnek ihracat sipariş verileri
A5: Senaryo | B5: FOB | C5: Miktar | D5: Üretim | E5: Navlun | F5: RezKur | G5: TahKur | H5: Hedge | I5: Komisyon | J5: CAPEX | K5: Yıl | L5: Net Ornek
A6: Demo ana | B6: 200000 | C6: 2000 | D6: 110000 | E6: 8000 | F6: 34 | G6: 32 | H6: 0.6 | I6: 0.03 | J6: 600000 | K6: 2026 | L6: =IF($A6="","",IFERROR(ROUND($B6*$G6-($D6+$E6)*$F6-$B6*$F6*$I6+$B6*($G6-$F6),0),0))
A7: Güçlü hedge | B7: 200000 | C7: 2000 | D7: 110000 | E7: 8000 | F7: 34 | G7: 33 | H7: 0.9 | I7: 0.03 | J7: 500000 | K7: 2026 | L7: =IF($A7="","",IFERROR(ROUND($B7*$G7-($D7+$E7)*$F7-$B7*$F7*$I7+$B7*($G7-$F7),0),0))
A8: Kur şoku | B8: 200000 | C8: 2000 | D8: 110000 | E8: 8000 | F8: 34 | G8: 28 | H8: 0.4 | I8: 0.03 | J8: 700000 | K8: 2026 | L8: =IF($A8="","",IFERROR(ROUND($B8*$G8-($D8+$E8)*$F8-$B8*$F8*$I8+$B8*($G8-$F8),0),0))
A9: 2025 geçiş | B9: 150000 | C9: 1500 | D9: 85000 | E9: 6000 | F9: 32 | G9: 31 | H9: 0.7 | I9: 0.025 | J9: 450000 | K9: 2025 | L9: =IF($A9="","",IFERROR(ROUND($B9*$G9-($D9+$E9)*$F9-$B9*$F9*$I9+$B9*($G9-$F9),0),0))
L10: =IF($A10="","",IFERROR(ROUND($B10*$G10-($D10+$E10)*$F10-$B10*$F10*$I10+$B10*($G10-$F10),0),0))
L11: =IF($A11="","",IFERROR(ROUND($B11*$G11-($D11+$E11)*$F11-$B11*$F11*$I11+$B11*($G11-$F11),0),0))
L12: =IF($A12="","",IFERROR(ROUND($B12*$G12-($D12+$E12)*$F12-$B12*$F12*$I12+$B12*($G12-$F12),0),0))
L13: =IF($A13="","",IFERROR(ROUND($B13*$G13-($D13+$E13)*$F13-$B13*$F13*$I13+$B13*($G13-$F13),0),0))
L14: =IF($A14="","",IFERROR(ROUND($B14*$G14-($D14+$E14)*$F14-$B14*$F14*$I14+$B14*($G14-$F14),0),0))
L15: =IF($A15="","",IFERROR(ROUND($B15*$G15-($D15+$E15)*$F15-$B15*$F15*$I15+$B15*($G15-$F15),0),0))
L16: =IF($A16="","",IFERROR(ROUND($B16*$G16-($D16+$E16)*$F16-$B16*$F16*$I16+$B16*($G16-$F16),0),0))
L17: =IF($A17="","",IFERROR(ROUND($B17*$G17-($D17+$E17)*$F17-$B17*$F17*$I17+$B17*($G17-$F17),0),0))
L18: =IF($A18="","",IFERROR(ROUND($B18*$G18-($D18+$E18)*$F18-$B18*$F18*$I18+$B18*($G18-$F18),0),0))
L19: =IF($A19="","",IFERROR(ROUND($B19*$G19-($D19+$E19)*$F19-$B19*$F19*$I19+$B19*($G19-$F19),0),0))
L20: =IF($A20="","",IFERROR(ROUND($B20*$G20-($D20+$E20)*$F20-$B20*$F20*$I20+$B20*($G20-$F20),0),0))
L21: =IF($A21="","",IFERROR(ROUND($B21*$G21-($D21+$E21)*$F21-$B21*$F21*$I21+$B21*($G21-$F21),0),0))
A22: OrnekNetDemo | L22: =IF($A22="","",IFERROR(ROUND($B22*$G22-($D22+$E22)*$F22-$B22*$F22*$I22+$B22*($G22-$F22),0),0))
A23: Demo ana | B23: 1784000 | L23: =IF($A23="","",IFERROR(ROUND($B23*$G23-($D23+$E23)*$F23-$B23*$F23*$I23+$B23*($G23-$F23),0),0))
A24: Güçlü hedge | B24: 2200000 | L24: =IF($A24="","",IFERROR(ROUND($B24*$G24-($D24+$E24)*$F24-$B24*$F24*$I24+$B24*($G24-$F24),0),0))
A25: Kur şoku | B25: 400000 | L25: =IF($A25="","",IFERROR(ROUND($B25*$G25-($D25+$E25)*$F25-$B25*$F25*$I25+$B25*($G25-$F25),0),0))
A26: 2025 geçiş | B26: 1100000 | L26: =IF($A26="","",IFERROR(ROUND($B26*$G26-($D26+$E26)*$F26-$B26*$F26*$I26+$B26*($G26-$F26),0),0))
L27: =IF($A27="","",IFERROR(ROUND($B27*$G27-($D27+$E27)*$F27-$B27*$F27*$I27+$B27*($G27-$F27),0),0))
L28: =IF($A28="","",IFERROR(ROUND($B28*$G28-($D28+$E28)*$F28-$B28*$F28*$I28+$B28*($G28-$F28),0),0))
L29: =IF($A29="","",IFERROR(ROUND($B29*$G29-($D29+$E29)*$F29-$B29*$F29*$I29+$B29*($G29-$F29),0),0))
L30: =IF($A30="","",IFERROR(ROUND($B30*$G30-($D30+$E30)*$F30-$B30*$F30*$I30+$B30*($G30-$F30),0),0))
L31: =IF($A31="","",IFERROR(ROUND($B31*$G31-($D31+$E31)*$F31-$B31*$F31*$I31+$B31*($G31-$F31),0),0))
L32: =IF($A32="","",IFERROR(ROUND($B32*$G32-($D32+$E32)*$F32-$B32*$F32*$I32+$B32*($G32-$F32),0),0))
L33: =IF($A33="","",IFERROR(ROUND($B33*$G33-($D33+$E33)*$F33-$B33*$F33*$I33+$B33*($G33-$F33),0),0))
L34: =IF($A34="","",IFERROR(ROUND($B34*$G34-($D34+$E34)*$F34-$B34*$F34*$I34+$B34*($G34-$F34),0),0))
L35: =IF($A35="","",IFERROR(ROUND($B35*$G35-($D35+$E35)*$F35-$B35*$F35*$I35+$B35*($G35-$F35),0),0))
L36: =IF($A36="","",IFERROR(ROUND($B36*$G36-($D36+$E36)*$F36-$B36*$F36*$I36+$B36*($G36-$F36),0),0))
L37: =IF($A37="","",IFERROR(ROUND($B37*$G37-($D37+$E37)*$F37-$B37*$F37*$I37+$B37*($G37-$F37),0),0))
L38: =IF($A38="","",IFERROR(ROUND($B38*$G38-($D38+$E38)*$F38-$B38*$F38*$I38+$B38*($G38-$F38),0),0))
... L1004: =IF($A1004="","",IFERROR(ROUND($B1004*$G1004-($D1004+$E1004)*$F1004-$B1004*$F1004*$I1004+$B1004*($G1004-$F1004),0),0))

Sheet LISTELER
A1: LISTELER — İhracat Sipariş Kârlılık & Kur Riski Komutası
A3: Doğrulama listeleri
A5: Yıl | C5: Döviz | E5: EvetHayır | G5: Durum | I5: IzinliGecis
A6: 2025 | C6: USD | E6: Evet | G6: TEKLIF | I6: TEKLIF|ONAY
A7: 2026 | C7: EUR | E7: Hayır | G7: ONAY | I7: TEKLIF|IPTAL
A8: 2027 | G8: URETIM | I8: ONAY|URETIM
G9: SEVK | I9: ONAY|IPTAL
G10: TAHSILAT | I10: URETIM|SEVK
G11: KAPALI | I11: URETIM|IPTAL
G12: IPTAL | I12: SEVK|TAHSILAT
I13: SEVK|IPTAL
I14: TAHSILAT|KAPALI

Sheet AYARLAR
A1: AYARLAR — İhracat Sipariş Kârlılık & Kur Riski Komutası
A3: Parametreler (tek kaynak) + kur tablosu + durum haritası
A5: anahtar | B5: deger | C5: birim | D5: aciklama | E5: kaynak | F5: yururluk_tarihi | G5: dogrulama_tarihi | H5: kontrol
A6: hesapYili | B6: 2026 | C6: yıl | D6: Aktif hesap yılı | E6: Kullanıcı / GIRDI | F6: 01.01.2025 | G6: 11.08.2026 | H6: =IF(A6="","",IF(B6="","EKSİK","TAM")) | J6: Durum haritası (izinli sonraki / kategori)
A7: raporTarihi | B7: 46245 | C7: tarih | D7: Rapor tarihi | E7: Üretim | F7: 01.01.2025 | G7: 11.08.2026 | H7: =IF(A7="","",IF(B7="","EKSİK","TAM")) | J7: durum_id | K7: durum_adi | L7: sira | M7: izinli_sonraki_durumlar | N7: kategori
A8: zincirTolerans | B8: 1 | C8: adet | D8: FOB/tutar zincir toleransı | E8: A04 | F8: 01.01.2025 | G8: 11.08.2026 | H8: =IF(A8="","",IF(B8="","EKSİK","TAM")) | J8: TEKLIF | K8: Teklif | L8: 1 | M8: ONAY|IPTAL | N8: acik
