Workbook
Name raporTarihi: AYARLAR!$B$6
Name zincirTolerans: AYARLAR!$B$7
Name ytk_esikGecikmeGun: AYARLAR!$B$8
Name ytk_esikGeciken: AYARLAR!$B$9
Name ytk_gecikmeOranGun: AYARLAR!$B$10
Name ytk_senaryoTemkinli: AYARLAR!$B$11
Name ytk_senaryoBaz: AYARLAR!$B$12
Name ytk_senaryoIyimser: AYARLAR!$B$13
Name ytk_tornadoOran: AYARLAR!$B$14
Name ytk_yuzdelikOran: AYARLAR!$B$15
Name ytk_olcekHedef: AYARLAR!$B$16
Name ytk_azamiTutar: AYARLAR!$B$17
Name ytk_eksikEsik: AYARLAR!$B$18
Name ytk_durumHaritasi: AYARLAR!$B$19
Name ytk_kuyrukOzeti_metin: AYARLAR!$B$20
Name ytk_kapaliDusum_metin: AYARLAR!$B$21
Name ytk_kanitRaporu_metin: AYARLAR!$B$22
Name ytk_dosyaSurumu: AYARLAR!$B$23
Name ytk_ymmUnvan: AYARLAR!$B$24
Name ytk_acikAdet: AYARLAR!$I$40
Name ytk_acikTutar: AYARLAR!$I$41
Name ytk_gecikenAdet: AYARLAR!$I$42
Name ytk_gecikmeMaliyeti: AYARLAR!$I$43
Name ytk_yetimKayit: AYARLAR!$I$44
Name ytk_gecersizGecis: AYARLAR!$I$45
Name ytk_zincirKirik: AYARLAR!$I$46
Name ytk_yasKova: AYARLAR!$I$47
Name ytk_tahminAralik: AYARLAR!$I$48
Name ytk_senaryoKarsilastirma: AYARLAR!$I$49
Name ytk_tornadoZirve: AYARLAR!$I$50
Name ytk_odemeOncelik: AYARLAR!$I$51
Name ytk_paretoGecikme: AYARLAR!$I$52
Name ytk_kapaliDusum: AYARLAR!$I$53
Name ytk_kuyrukOzeti: AYARLAR!$I$54
Name ytk_kanitRaporu: AYARLAR!$I$55
Name ytk_sonrakiKimlik: AYARLAR!$I$56
Name ytk_eksikKuyruk: AYARLAR!$I$57
Name ytk_modulO8: AYARLAR!$I$58
Name ytk_modulI2: AYARLAR!$I$59
Name ytk_eksikAdet: AYARLAR!$I$60
Name ytk_kritikEksik: AYARLAR!$I$61
Name ytk_yorumYas: AYARLAR!$I$64
Name ytk_yorumGecikme: AYARLAR!$I$65
Name ytk_yorumTahmin: AYARLAR!$I$66
Name ytk_yorumSenaryo: AYARLAR!$I$67
Name ytk_yorumTornado: AYARLAR!$I$68
Name ytk_yorumOncelik: AYARLAR!$I$69
Name ytk_yorumPareto: AYARLAR!$I$70
Name ytk_modulO8Yorum: AYARLAR!$I$71
Name ytk_modulI2Yorum: AYARLAR!$I$72
Name ytk_kararKapi: PANO!$B$4
Name ListeDurumlar: LISTELER!$A$7:$A$11
Name ListeIzinliGecis: LISTELER!$C$7:$C$12
Name ListeEvetHayir: LISTELER!$E$7:$E$8
Name ListeZorunluluk: LISTELER!$G$7:$G$9
Name ListeBelgeDurum: LISTELER!$I$7:$I$8
Name ListeKartlar: LISTELER!$K$7:$K$14

Sheet 00_BASLANGIC
A1: EXCELARŞİV KARAR SİSTEMİ v15.1 — ÜRETİM REFERANSI
A3: Konu | B3: Bağlayıcı Standart
A4: Amaç | B4: Kanıta dayalı, hatada kapalı çalışan Excel üretim ve denetim sistemi
A5: Öncelik | B5: Kullanıcının açık iş talebi ve gerçek kullanım senaryosu
A6: Ana akış | B6: Uygunluk → Yönetişim → Sözleşmeler → Üretim → Test → Kanıt → Kullanıcı Kabulü → Yayın
A7: Yayın ilkesi | B7: Üst aşamada hata varsa alt aşama GEÇTİ üretilemez
A8: Kullanıcı kabulü | B8: Excel masaüstü görünümü test edilmediyse DIŞ_KABUL_GEREKLİ
A9: Nihai yayın | B9: Yalnız uygulanabilir modüller GEÇTİ veya gerekçeli UYGULANMAZ
A10: Ticari ayrım | B10: Ekonomik olarak savunulabilir fiyat, gerçek pazar kabulü ile aynı değildir
A11: Karmaşıklık | B11: Karar değeri, eklenen karmaşıklığın maliyetinden büyük olmalıdır
A12: Excel sınırı | B12: Veritabanı, kurumsal yetkilendirme, değiştirilemez kayıt sistemi veya gerçek zamanlı olay platformu değildir
A13: Dil standardı | B13: Kullanıcıya görünen tüm sayfa, tablo, başlık, açıklama, uyarı ve karar metinleri saf Türkçe olmalıdır
A14: Muhasebe standardı | B14: Finansal ürünlerde Türkiye Tekdüzen Hesap Planı ve Türk muhasebe kullanım alışkanlıkları esas alınır
... A33: Muhasebe | B33: Türkiye Tekdüzen Hesap Planı ve Türk muhasebe/işletme düşünce yapısı esas alınır.

Sheet PANO
A1: ☰ PANO
B2: YMM TASDIK KONTROL ROBOTU | L2: Dönem: 2026 / Tam ▼ | M2: ★ DOĞRULANMIŞ
B3: Hedef Kullanıcı: YMM, SMMM, tasdik dosya sorumlusu · 2026 Q3 Denetim Standardı
B5: YAŞLANDIRMA | D5: KONSOLİDE | E5: GECIKME | G5: KONTROL | H5: NET OPERASYONEL MARJ | J5: GÜVENLİ | K5: SİSTEM GÜVEN SKORU | M5: DENETLENDİ
B7: =GİRDİLER!E17 | E7: =B7*0.22 | H7: =B7-E7 | K7: =IF(E7>0, ROUND(B7/E7, 2), 0)
B9: ↑ %14.2 konsolide canlı veri bağlantısı | E9: ● 8 Kalem nakit karşılığı: bloke | H9: ██████████░░░░░ %78.0 NET MARJ | K9: ✓ İDEAL karşılama rasyosu
B11: YMM TASDIK KONTROL ROBOTU — DÖNEMSEL İCRA VE PROJEKSİYON | F11: +%32 Verim | H11: KONSOLİDE OPERASYON VE KARAR MATRİSİ
B12: Kümülatif Hacim vs. Operasyonel Maliyet ve Net Kâr Eğilimi | H12: Anlık Hesaplama Sonuçları, Dinamik Formül Çıktıları ve Durum Puanlaması
B14: Dönem | C14: Aktif Hacim | D14: Maliyet/Yük | E14: Hedef | H14: PARAMETRE / KALEM | I14: ANA TUTAR | J14: FARK / MARJ | K14: VADE | L14: KONTROL DURUMU
B15: D1 | C15: 65 | D15: 45 | E15: 60 | H15: Dönemlik Kümülatif Bakiye | I15: =B7*0.45 | J15: =B7*0.05 | K15: 12 Ay | L15: ✓ DÜZENLİ
B16: D2 | C16: 78 | D16: 48 | E16: 70 | H16: Kritik Eşik Güvenlik Tamponu | I16: =B7*0.30 | J16: =B7*0.03 | K16: 24 Ay | L16: ★ AVANTAJ
B17: D3 | C17: 85 | D17: 55 | E17: 80 | H17: Operasyonel Net Fark | I17: =B7*0.15 | J17: =B7*0.02 | K17: 8 Ay | L17: ● YAKLAŞAN
B18: D4 | C18: 75 | D18: 42 | E18: 75 | H18: Rezerv ve Likit Dağılım | I18: =B7*0.10 | J18: =B7*0.01 | K18: 16 Ay | L18: ✓ TAM UYUM
B19: D5 | C19: 90 | D19: 40 | E19: 85 | H19: KONSOLİDE SİSTEM TOPLAMI | I19: =SUM(I15:I18) | J19: =SUM(J15:J18) | L19: TAM DOĞRULANDI (0 HATA)
B20: D6 | C20: 96 | D20: 32 | E20: 92
B22: KONSOLİDE PAY VE AĞIRLIK | F22: LİKİDİTE RİSKİ & ERKEN UYARI SİNYALLERİ | K22: KARAR MOTORU
B23: ■ Ana Segment (%42) | F23: Nakit Açığı Riski (30 Gün) | I23: 0.00 TL (Sıfır Risk) | K23: STRATEJİK VERİMLİLİK FIRSATI
B24: ■ İkincil Grup (%30) | F24: Tahsilat Gecikme Toleransı | I24: 48 Gün Güvenli Eşik | K24: Operasyonel süreç optimizasyonu ile kârlılık artış potansiyeli tespit edildi.
B25: ■ Destek Birimi (%15) | F25: ██████████████████████████████████████ Güvenli Bölge (%100)
B26: ■ Rezervler (%13) | F26: ✓ 90 GÜNLÜK PROJEKSİYONDA NAKİT SIKIŞIKLIĞI TESPİT EDİLMEDİ | K26: STRATEJİ REÇETESİNİ İNCELE >

Sheet GİRDİLER
A1: ☰ PANO
B3: 🔍 YMM TASDIK KONTROL ROBOTU — Kayıt veya hesap ara... | G3: TOPLAM: 1.450 KAYIT | I3: HATALI HÜCRE: 0 ADET
B5: TARİH | C5: REFERANS NO | D5: İŞLEM AÇIKLAMASI VE DETAY | E5: BRÜT TUTAR (₺) | F5: KDV ORANI | G5: NET TUTAR (₺) | H5: HESAP / CARİ | I5: DURUM
B6: 12.10.2026 | C6: TR-0428-A | D6: Operasyonel ana kalem tahmini | E6: 845200 | F6: 0.2 | G6: =E6/(1+F6) | H6: Vadesiz Ticari | I6: ONAYLANDI
B7: 14.10.2026 | C7: TR-0429-B | D7: Operasyonel çıkış/maliyet tahmini | E7: 1240000 | F7: 0.2 | G7: =E7/(1+F7) | H7: Tedarikçi Havuzu | I7: BEKLEMEDE
B8: 18.10.2026 | C8: TR-0430-C | D8: Ödeme takvimi tahakkuku | E8: 620500 | F8: 0.1 | G8: =E8/(1+F8) | H8: Kısa Vade Tahakkuk | I8: ONAYLANDI
B9: 21.10.2026 | C9: TR-0431-D | D9: Müşteri işlem tahmini | E9: 415000 | F9: 0.2 | G9: =E9/(1+F9) | H9: Müşteri Alacağı | I9: ONAYLANDI
B10: 25.10.2026 | C10: TR-0432-E | D10: Ana operasyon tahmini | E10: 980400 | F10: 0.2 | G10: =E10/(1+F10) | H10: Vadesiz Ticari | I10: ONAYLANDI
B11: 28.10.2026 | C11: TR-0433-F | D11: Kredi/taksit karşılığı | E11: 1850000 | F11: 0.2 | G11: =E11/(1+F11) | H11: Finansman Havuzu | I11: BLOKE
B12: 02.11.2026 | C12: TR-0434-G | D12: Sabit gider ve yönetim notları | E12: 740000 | F12: 0.2 | G12: =E12/(1+F12) | H12: Genel Yönetim | I12: ONAYLANDI
B13: 05.11.2026 | C13: TR-0435-H | D13: Operasyonel ana kalem tahmini | E13: 520800 | F13: 0.2 | G13: =E13/(1+F13) | H13: Vadesiz Ticari | I13: ONAYLANDI
B14: 09.11.2026 | C14: TR-0436-I | D14: Müşteri işlem tahmini | E14: 1120000 | F14: 0.2 | G14: =E14/(1+F14) | H14: Müşteri Alacağı | I14: ONAYLANDI
B15: 12.11.2026 | C15: TR-0437-J | D15: Operasyonel çıkış tahmini | E15: 890000 | F15: 0.2 | G15: =E15/(1+F15) | H15: Tedarikçi Havuzu | I15: ONAYLANDI
B17: SAYFA TOPLAMI (10 / 1.450 KAYIT) | E17: =SUM(E6:E15)

Sheet YÖNETİM_RAPORU
A1: ☰ PANO
B2: YMM TASDIK KONTROL ROBOTU — NİHAİ KARAR VE DEĞERLEME
B3: Yönetim Kurulu ve İcra Komitesi için Otomatik Finansal Stres Testi Raporu · YMM, SMMM, tasdik dosya sorumlusu
B4: DÖNEM: 2026 Q3 · DENETİM PROTOKOLÜ: ISO/VUK/IFRS UYUMLU · DURUM: ONAYLANDI
B6: SENARYO A: KÖTÜMSER (STRES TESTİ -%20) | H6: SENARYO B: BAZ MODEL (HEDEFLENEN)
B8: Ciro / Hacim Düşüşü: | E8: -%20.0 (Kriz Eşiği) | H8: Ciro / Hacim Gerçekleşmesi: | K8: %100.0 (Tam Bütçe)
B9: Beklenen Net Kâr / Getiri: | E9: =PANO!B7*0.8*0.22 | H9: Beklenen Net Kâr / Getiri: | K9: =PANO!H7
B10: Minimum Nakit Tamponu: | E10: =PANO!E7*0.75 | H10: Serbest Nakit Akımı: | K10: =PANO!H7*0.75
B11: Likidite Karşılama Oranı: | E11: =ROUND(PANO!B7*0.8/PANO!E7, 2) | H11: Yatırım Geri Dönüşü (ROI): | K11: %38.4 Yıllık
B14: STRES SENARYOSUNDA DAHİ İFLAS RİSKİ YOK | H14: OPTİMUM İCRA VE PLANLAMA REÇETESİ
B17: YÖNETİM KARAR MATRİSİ VE UYGULAMA REÇETESİ
B19: ● Öncelik 1: Acil Likidite ve Borç Servis Planlaması
B20: Sistemde hesaplanan vade günlerine sadık kalınarak nakit blokajı 3 gün önceden hazır edilmelidir.
B21: ● Öncelik 2: Formül Doğrulama ve Çapraz Sağlama
B22: Tüm hücreler kilitli formül korumasında olup girdi sayfalarında sıfır döngüsel başvuru (circular ref) garantilidir.
B23: ● Öncelik 3: Resmi Mevzuat ve Vergi Kalkanı Entegrasyonu
B24: 2026 güncel vergi dilimleri, amortisman ve SGK teşvik parametreleri tam otomatik yansıtılmaktadır.
B25: ● Öncelik 4: Yönetici İmzası ve Rapor Paylaşımı
B26: Tek tuşla PDF ve A4 çıktı formatına tam uyumlu sayfa yapısı kurgulanmıştır.

Sheet 01_YURUTME_CEKIRDEGI
A1: YÜRÜTME ÇEKİRDEĞİ — ZORUNLU ÜRETİM SIRASI
A3: Adım | B3: Modül | C3: Tetikleyici | D3: Zorunlu Kanıt | E3: GEÇTİ Kuralı | F3: Hata Durumu | G3: Sonraki Aşama
A4: 1 | B4: Excel Uygunluğu | C4: Her yeni model | D4: UYGUNLUK_KARARI | E4: Excel'in rolü açık | F4: HATA / BLOKE | G4: Yönetişim
A5: 2 | B5: Yönetişim | C5: Her model | D5: Risk seviyesi + etki girdileri | E5: Seviye hesaplandı | F5: BLOKE | G5: Sözleşmeler
A6: 3 | B6: Türk Muhasebe Eşlemesi | C6: Finansal model | D6: THP hesap eşleme tablosu | E6: Kritik satırlar THP ile uyumlu | F6: HATA | G6: Sözleşmeler
A7: 4 | B7: Veri ve Anlam Sözleşmeleri | C7: Girdi/KPI varsa | D7: Veri + KPI sözleşmeleri | E7: Kapsam %100 | F7: HATA | G7: Üretim
A8: 5 | B8: Üretim | C8: Sözleşmeler GEÇTİ | D8: Çalışan Excel | E8: Tek gerçek kaynak korunmuş | F8: HATA | G8: Testler
A9: 6 | B9: Görsel/Kullanım Katmanı | C9: Motor hazır | D9: Başlıklar + renk + grafik + yönlendirme | E9: Tüm kullanıcı sayfaları standarda uygun | F9: HATA | G9: Testler
A10: 7 | B10: Testler | C10: Üretim tamam | D10: Formül/OOXML/kimlik/oracle/golden/metamorfik | E10: Uygulanabilir hard gate'ler GEÇTİ | F10: HATA | G10: Kanıt
A11: 8 | B11: Hata-Kontrol Tutarlılığı | C11: Test sonucu var | D11: Hata taraması + kontrol sonuçları | E11: Formül hatası varken GEÇTİ yok | F11: HATA | G11: Kanıt
A12: 9 | B12: Kanıt | C12: Test sonucu var | D12: Makine okunur artefakt + özet | E12: Kanıt fiziksel ve tutarlı | F12: HATA | G12: Kullanıcı Kabulü
A13: 10 | B13: Kullanıcı Kabulü | C13: Kritik görevler | D13: Gerçek ekran davranışı | E13: Kritik görevler %100 | F13: DIŞ_KABUL_GEREKLİ | G13: Ticari
A14: 11 | B14: Ticari Değer | C14: Ürün satılacaksa | D14: ROI + demo + kanıt paketi | E14: Ekonomik değer kanıtlı | F14: UYARI / HATA | G14: Pazar Doğrulama
A15: 12 | B15: Pazar Doğrulama | C15: Pazar iddiası varsa | D15: Ücretli satış/pilot/fiyat kabul kanıtı | E15: Gerçek fiyat kabul kanıtı | F15: UYGULANMAZ / HATA | G15: Yayın

Sheet 02_KONTROL_LISTESI
A1: NİHAİ KONTROL LİSTESİ — KANITSIZ GEÇİŞ YOK
A3: Kontrol No | B3: Kontrol | C3: Beklenen | D3: Zorunlu Kapı? | E3: Sonuç
A4: K01 | B4: Kullanıcının açık talebi öncelikli mi? | C4: Evet | D4: EVET
A5: K02 | B5: Mevcut yapı, formüller ve tek gerçek kaynak korunuyor mu? | C5: Evet, değişiklik gerekçeli | D5: EVET
A6: K03 | B6: Üst aşama HATA ise alt aşama GEÇTİ engelleniyor mu? | C6: Evet | D6: EVET
A7: K04 | B7: Kanıt fiziksel çıktı ve içerik doğrulaması içeriyor mu? | C7: Evet | D7: EVET
A8: K05 | B8: Excel GUI erişimi olmadan kullanıcı görünümü GEÇTİ yazılıyor mu? | C8: Hayır | D8: EVET
A9: K06 | B9: NİHAİ yalnız GEÇTİ / gerekçeli UYGULANMAZ ile mi? | C9: Evet | D9: EVET
A10: K07 | B10: Ekonomik fiyat savunusu pazar doğrulamasından ayrılmış mı? | C10: Evet | D10: EVET
A11: K08 | B11: Prestij için gereksiz modül var mı? | C11: Hayır | D11: HAYIR
A12: K09 | B12: Excel sınırları açık mı? | C12: Evet | D12: EVET
A13: K10 | B13: Teknik kaynak korunuyor mu? | C13: Evet | D13: EVET
A14: K11 | B14: Kullanıcıya görünen tüm metinler Türkçe mi? | C14: Evet | D14: EVET
A15: K12 | B15: Her kullanıcı sayfasında üst başlık var mı? | C15: Evet | D15: EVET
... A34: K31 | B34: Premium vitrin, altyapı kadar güçlü ve satış fiyatını destekleyecek seviyede mi? | C34: Evet | D34: EVET

Sheet 03_GORSEL_TASARIM
A1: GÖRSEL TASARIM VE PREMIUM EXCEL STANDARDI
A3: Alan | B3: Zorunlu Kural | C3: Uygulama | D3: Yasak | E3: Kontrol | F3: Durum
A4: Sayfa başlığı | B4: Her kullanıcı sayfasının en üstünde tek ve açık sayfa başlığı | C4: A1'den başlayan koyu lacivert başlık bandı | D4: Başlıksız sayfa | E4: Başlık kapsama = %100 | F4: ZORUNLU
A5: Sekme renkleri | B5: Sayfalar işlevine göre renk kodlanır | C5: Girdi=mavi, hesap=gri, rapor=lacivert, kontrol=kırmızı, kılavuz=altın | D5: Rastgele renk | E5: Renk semantiği tutarlı | F5: ZORUNLU
A6: Kolon düzeni | B6: Veri blokları bitişik kolonlarda ilerler | C6: Gereksiz boş kolon bırakma; yalnız gerçek bölüm ayrımı varsa kontrollü boşluk | D6: A:C veri, D boş, E:F veri gibi parçalı yapı | E6: Boş kolon taraması | F6: ZORUNLU
A7: Girdi hücreleri | B7: Kullanıcının değiştireceği alan açıkça görünür | C7: Açık sarı dolgu + mavi yazı | D7: Formülle aynı görünüm | E7: Girdi/formül ayrımı | F7: ZORUNLU
A8: Formüller | B8: Hesap hücreleri kullanıcı girdisinden ayrılır | C8: Siyah yazı; sayfalar arası bağlantı yeşil yazı | D8: Hard-code gizleme | E8: Formül sınıfı kontrolü | F8: ZORUNLU
A9: Grafik sayısı | B9: Yönetici ekranında en fazla 3 ana karar grafiği | C9: Trend, karşılaştırma, köprü/dağılım; iş kararına bağlı | D9: Grafik kalabalığı | E9: Grafik başına karar sorusu | F9: ZORUNLU
A10: Grafik stili | B10: Kurumsal ve yüksek okunabilirlik | C10: Beyaz zemin, ince gridline, tek vurgu rengi, açık birim/başlık | D10: 3B, gölge, neon, gökkuşağı renkleri | E10: Görsel inceleme | F10: ZORUNLU
A11: Grafik başlığı | B11: Grafik 'neyi' değil 'ne anlama geldiğini' söyler | C11: Örn: 'Nakit 2028'de kritik eşiğin altına iniyor' | D11: 'Nakit Grafiği' gibi anlamsız başlık | E11: Başlık karar testi | F11: ZORUNLU
A12: Birimler | B12: Tüm finansal görsellerde birim açık | C12: TL, bin TL, milyon TL, %, gün, x | D12: Birim belirsizliği | E12: Birim kapsama %100 | F12: ZORUNLU
A13: Sıfır/negatif | B13: Finansal format standardı | C13: Sıfır='-', negatif kırmızı parantez | D13: -500 veya 0,00 kalabalığı | E13: Format kontrolü | F13: ZORUNLU
A14: Yazı tipi | B14: Tek aile | C14: Aptos veya Segoe UI | D14: Karışık font | E14: Tek font kontrolü | F14: ZORUNLU
... A22: Premium vitrin | B22: Görsel kalite ürün değerinin zorunlu parçasıdır | C22: Kaliteli grafik, gerçek KPI kartı, finansal hiyerarşi, tab rengi, fonksiyonel navigasyon | D22: Sadece doğru hesap yapıp çıplak/varsayılan Excel görünümü bırakmak | E22: Görsel release incelemesi | F22: ZORUNLU

Sheet 04_MUHASEBE_THP
A1: TÜRKİYE MUHASEBE VE TEKDÜZEN HESAP PLANI STANDARDI
A3: Konu | B3: Zorunlu Standart | C3: Örnek Türkçe Ad | D3: THP / Mantık | E3: Hata Riski | F3: Kontrol
A4: Dil | B4: Kullanıcıya görünen finansal terimler Türkçe | C4: Hasılat, Satışların Maliyeti, Brüt Kâr, Faaliyet Giderleri | D4: Türk işletme kullanımına uygun | E4: İngilizce jargon | F4: Terminoloji taraması
A5: Gelir Tablosu | B5: Türk sunum sırası kullanılır | C5: Net Satışlar → Satışların Maliyeti → Brüt Kâr → Faaliyet Giderleri → Faaliyet Kârı | D5: 600/610/611; 620-623; 63x | E5: Yanlış sınıflama | F5: Hesap eşleme
A6: Bilanço | B6: Dönen/Duran Varlık ve Kısa/Uzun Vadeli Yükümlülük ayrımı | C6: Hazır Değerler, Ticari Alacaklar, Stoklar, Mali Borçlar | D6: 1xx / 2xx / 3xx / 4xx / 5xx | E6: Vade sınıfı hatası | F6: Bilanço eşitliği
A7: Nakit Akışı | B7: İşletme/Yatırım/Finansman nakit akışları ayrılır | C7: Faaliyetlerden Nakit, Yatırım Harcamaları, Finansman Nakit Akışı | D7: Dolaylı/doğrudan yöntem açık seçilir | E7: Kâr = nakit sanılması | F7: Nakit devri
A8: Ticari Alacaklar | B8: Cari ve vade mantığı korunur | C8: 120 Alıcılar | D8: 120 | E8: Tahakkuk/nakit karışması | F8: Alacak devir kontrolü
A9: Ticari Borçlar | B9: Tedarikçi borcu ayrı izlenir | C9: 320 Satıcılar | D9: 320 | E9: Gider/ödeme karışması | F9: Borç devir kontrolü
A10: Kasa/Banka | B10: Hazır değerler ayrı izlenir | C10: 100 Kasa, 102 Bankalar | D10: 100 / 102 | E10: Virmanla toplam nakdin değişmesi | F10: Virman değişmezi
A11: Stok | B11: Dikeye uygun stok türü | C11: 150 İlk Madde ve Malzeme, 153 Ticari Mallar | D11: 15x | E11: Maliyet ve stok hareketinin kopması | F11: Stok devri
A12: Maddi Duran Varlık | B12: Yatırım harcaması ve amortisman bağlantılı | C12: 253 Tesis Makine Cihazlar, 255 Demirbaşlar, 257 Birikmiş Amortismanlar | D12: 25x | E12: Yatırım/gider karışması | F12: Net defter değeri devri
A13: Mali Borçlar | B13: Kısa/uzun vadeli borç ayrımı | C13: 300 Banka Kredileri / 400 Banka Kredileri | D13: 300 / 400 | E13: Vade sınıfı yanlış | F13: Borç devri
A14: Özkaynak | B14: Sermaye ve geçmiş yıl kârları ayrı | C14: 500 Sermaye, 570 Geçmiş Yıllar Kârları, 590 Dönem Net Kârı | D14: 5xx | E14: Net kâr bağının kopması | F14: Özkaynak devri
... A18: İstisna | B18: TFRS özel ürün varsa fark açık yazılır | C18: Tekdüzen raporlama ≠ TFRS finansal tablo sunumu | D18: Amaç belirtilir | E18: Standartları karıştırma | F18: Model amacı kontrolü

Sheet 05_KARAR_SATIS
A1: KARAR, GÜVEN VE SATIŞA HAZIRLIK STANDARDI
A3: Alan | B3: Müşteri Sorusu | C3: Zorunlu Ürün Davranışı | D3: Kanıt | E3: Başarısızlık Durumu | F3: Kapı
A4: 5 saniye | B4: Bu ürün neyi çözüyor? | C4: İlk ekranda hedef kullanıcı + pahalı problem + sonuç görünür | D4: Başlık + alt mesaj + gerçek ekran | E4: Ürün yalnız teknik isim | F4: HATA
A5: Acı | B5: Sorun bana neye mal oluyor? | C5: Mümkünse müşterinin kendi verisiyle parasal/zaman etkisi hesaplanır | D5: ROI/acı hesaplama yöntemi | E5: Uydurma tasarruf | F5: HATA
A6: Karar | B6: Bu bilgiyle ne yapacağım? | C6: Her kritik KPI aksiyona bağlanır | D6: KARAR_KUYRUGU | E6: Sadece rapor | F6: HATA
A7: Güven | B7: Bu sayıya neden inanayım? | C7: Kaynak, formül mantığı, kontrol ve son doğrulama görünür | D7: Kontroller + kaynak izi + sürüm | E7: Prestij kelimesi | F7: HATA
A8: Referans | B8: Müşteri yorumu yoksa ne göstereceğim? | C8: Önce/Sonra + Karar Vakası + Hata Önleme Vakası üretilir | D8: Demo/örnek çıktı | E8: Kanıtsız iddia | F8: HATA
A9: Senaryo | B9: Ne olursa işler bozulur? | C9: Baz/Aşağı/Yukarı veya uygun stres senaryosu | D9: Senaryo karşılaştırma | E9: Dekoratif senaryo | F9: HATA
A10: Ters stres | B10: Hangi eşikte karar kırılır? | C10: En az bir kritik sürücü için kırılma eşiği | D10: Kırılma eşiği tablosu | E10: Sadece +/- %10 | F10: UYARI/HATA
A11: Hata tutarlılığı | B11: Formül hata verirse ne olur? | C11: Kontrol GEÇTİ veremez; BLOKE/HATA üretir | D11: Hata taraması | E11: Hata + GEÇTİ birlikte | F11: HATA
A12: Karar motoru | B12: Ne oldu, neden oldu? | C12: Sorun + neden + parasal etki + aksiyon + son tarih | D12: Karar tablosu | E12: Boş sayfa / isim düzeyi modül | F12: HATA
A13: Yönetici özeti | B13: 5 saniyede ne görmeliyim? | C13: Bugün / ne değişti / ne bozulacak / neden / ne yapmalıyım / güven | D13: Yönetici özeti ekranı | E13: KPI kutusu yığını | F13: HATA
A14: Teklif | B14: Neden satın almalıyım? | C14: Dosya özellikleri yerine sonuç ve kaçınılan maliyet sunulur | D14: Ürün sayfası kanıt eşlemesi | E14: Özellik listesiyle satış | F14: HATA
... A19: Pazar kanıtı | B19: Piyasa gerçekten ödüyor mu? | C19: Satış/pilot/LOI/fiyat kabulü olmadan pazar doğrulandı yazılmaz | D19: Gerçek işlem kanıtı | E19: Tahmini talep = satış kabulü | F19: HATA

Sheet KAPAK
A1: KAPAK — YMM Tasdik Kontrol Robotu
A3: YMM Tasdik Kontrol Robotu
A4: YMM tasdik dosyasını kontrol listesi, eksik belge kuyruğu ve durum makinesi ile yönetir; boş veride VERİ YOK, kritik eksikte DURDUR kararı üretir.
A6: Bu ürün ne sağlar?
A7: • Makrosuz durum makinesi: Taslak → İnceleme → Eksik / Tasdik / Durdur
A8: • KONTROL_LISTE — belge bazlı zorunluluk ve eksik bayrağı
A9: • Eksik belge kuyruğu yaşlandırma (ytk_eksikKuyruk)
A10: • Kuyruk + yaşlandırma kovaları (0-7 / 8-30 / 31-60 / 60+)
A11: • Karar kapısı: VERİ YOK / TASDIK / EKSİK / DURDUR
A13: Kimler için?
A14: • Dosya sorumlusu — kontrol listesini ve belge kuyruğunu günceller
A15: • YMM — TASDIK / EKSİK / DURDUR kararını verir
... A21: Sürüm 1.0.0 | Lisans: Tek kullanıcı | ExcelArşiv

Sheet KARTLAR
A1: KARTLAR — YMM Tasdik Kontrol Robotu
A3: Mükellef / tasdik dosya kartları — her kaydın tek kimliği vardır
A4: Sonraki Kimlik | B4: =ytk_sonrakiKimlik
A5: KartId | B5: Unvan | C5: VKN | D5: Sehir | E5: TasdikTuru | F5: DosyaTutar | G5: RiskNotu | H5: Aktif | I5: EksikBelge | J5: ToplamIslem | K5: OrtGecikme
A6: MUK-00001 | B6: Demir Tekstil A.Ş. | C6: 1234567890 | D6: İstanbul | E6: KDV İadesi | F6: 450000 | G6: Normal | H6: EVET | I6: =IF($A6="","",COUNTIFS(tblKontrol[KaynakKartId],$A6,tblKontrol[BelgeDurum],"YOK")) | J6: =IF($A6="","",SUMIF(tblAkis[KaynakKartId],$A6,tblAkis[Tutar])) | K6: =IF($A6="","",IFERROR(AVERAGEIF(tblAkis[KaynakKartId],$A6,tblAkis[YasGun]),0))
A7: MUK-00002 | B7: Kaya Gıda Ltd. | C7: 2345678901 | D7: Ankara | E7: Yıllık Beyan | F7: 320000 | G7: Normal | H7: EVET | I7: =IF($A7="","",COUNTIFS(tblKontrol[KaynakKartId],$A7,tblKontrol[BelgeDurum],"YOK")) | J7: =IF($A7="","",SUMIF(tblAkis[KaynakKartId],$A7,tblAkis[Tutar])) | K7: =IF($A7="","",IFERROR(AVERAGEIF(tblAkis[KaynakKartId],$A7,tblAkis[YasGun]),0))
A8: MUK-00003 | B8: Yıldız İnşaat A.Ş. | C8: 3456789012 | D8: İzmir | E8: ÖTV Tasdik | F8: 780000 | G8: Normal | H8: EVET | I8: =IF($A8="","",COUNTIFS(tblKontrol[KaynakKartId],$A8,tblKontrol[BelgeDurum],"YOK")) | J8: =IF($A8="","",SUMIF(tblAkis[KaynakKartId],$A8,tblAkis[Tutar])) | K8: =IF($A8="","",IFERROR(AVERAGEIF(tblAkis[KaynakKartId],$A8,tblAkis[YasGun]),0))
A9: MUK-00004 | B9: Özkan Lojistik | C9: 4567890123 | D9: Bursa | E9: KDV İadesi | F9: 210000 | G9: Normal | H9: EVET | I9: =IF($A9="","",COUNTIFS(tblKontrol[KaynakKartId],$A9,tblKontrol[BelgeDurum],"YOK")) | J9: =IF($A9="","",SUMIF(tblAkis[KaynakKartId],$A9,tblAkis[Tutar])) | K9: =IF($A9="","",IFERROR(AVERAGEIF(tblAkis[KaynakKartId],$A9,tblAkis[YasGun]),0))
A10: MUK-00005 | B10: Arslan Enerji A.Ş. | C10: 5678901234 | D10: Antalya | E10: Yatırım İndirimi | F10: 950000 | G10: Normal | H10: EVET | I10: =IF($A10="","",COUNTIFS(tblKontrol[KaynakKartId],$A10,tblKontrol[BelgeDurum],"YOK")) | J10: =IF($A10="","",SUMIF(tblAkis[KaynakKartId],$A10,tblAkis[Tutar])) | K10: =IF($A10="","",IFERROR(AVERAGEIF(tblAkis[KaynakKartId],$A10,tblAkis[YasGun]),0))
A11: MUK-00006 | B11: Çelik Metal Ltd. | C11: 6789012345 | D11: Kocaeli | E11: KDV İadesi | F11: 280000 | G11: Normal | H11: EVET | I11: =IF($A11="","",COUNTIFS(tblKontrol[KaynakKartId],$A11,tblKontrol[BelgeDurum],"YOK")) | J11: =IF($A11="","",SUMIF(tblAkis[KaynakKartId],$A11,tblAkis[Tutar])) | K11: =IF($A11="","",IFERROR(AVERAGEIF(tblAkis[KaynakKartId],$A11,tblAkis[YasGun]),0))
A12: MUK-00007 | B12: Aydın Turizm A.Ş. | C12: 7890123456 | D12: Adana | E12: Yıllık Beyan | F12: 190000 | G12: Normal | H12: EVET | I12: =IF($A12="","",COUNTIFS(tblKontrol[KaynakKartId],$A12,tblKontrol[BelgeDurum],"YOK")) | J12: =IF($A12="","",SUMIF(tblAkis[KaynakKartId],$A12,tblAkis[Tutar])) | K12: =IF($A12="","",IFERROR(AVERAGEIF(tblAkis[KaynakKartId],$A12,tblAkis[YasGun]),0))
A13: MUK-00008 | B13: Şahin Kimya Ltd. | C13: 8901234567 | D13: Gaziantep | E13: ÖTV Tasdik | F13: 410000 | G13: Normal | H13: EVET | I13: =IF($A13="","",COUNTIFS(tblKontrol[KaynakKartId],$A13,tblKontrol[BelgeDurum],"YOK")) | J13: =IF($A13="","",SUMIF(tblAkis[KaynakKartId],$A13,tblAkis[Tutar])) | K13: =IF($A13="","",IFERROR(AVERAGEIF(tblAkis[KaynakKartId],$A13,tblAkis[YasGun]),0))
I14: =IF($A14="","",COUNTIFS(tblKontrol[KaynakKartId],$A14,tblKontrol[BelgeDurum],"YOK")) | J14: =IF($A14="","",SUMIF(tblAkis[KaynakKartId],$A14,tblAkis[Tutar])) | K14: =IF($A14="","",IFERROR(AVERAGEIF(tblAkis[KaynakKartId],$A14,tblAkis[YasGun]),0))
I15: =IF($A15="","",COUNTIFS(tblKontrol[KaynakKartId],$A15,tblKontrol[BelgeDurum],"YOK")) | J15: =IF($A15="","",SUMIF(tblAkis[KaynakKartId],$A15,tblAkis[Tutar])) | K15: =IF($A15="","",IFERROR(AVERAGEIF(tblAkis[KaynakKartId],$A15,tblAkis[YasGun]),0))
I16: =IF($A16="","",COUNTIFS(tblKontrol[KaynakKartId],$A16,tblKontrol[BelgeDurum],"YOK")) | J16: =IF($A16="","",SUMIF(tblAkis[KaynakKartId],$A16,tblAkis[Tutar])) | K16: =IF($A16="","",IFERROR(AVERAGEIF(tblAkis[KaynakKartId],$A16,tblAkis[YasGun]),0))
I17: =IF($A17="","",COUNTIFS(tblKontrol[KaynakKartId],$A17,tblKontrol[BelgeDurum],"YOK")) | J17: =IF($A17="","",SUMIF(tblAkis[KaynakKartId],$A17,tblAkis[Tutar])) | K17: =IF($A17="","",IFERROR(AVERAGEIF(tblAkis[KaynakKartId],$A17,tblAkis[YasGun]),0))
I18: =IF($A18="","",COUNTIFS(tblKontrol[KaynakKartId],$A18,tblKontrol[BelgeDurum],"YOK")) | J18: =IF($A18="","",SUMIF(tblAkis[KaynakKartId],$A18,tblAkis[Tutar])) | K18: =IF($A18="","",IFERROR(AVERAGEIF(tblAkis[KaynakKartId],$A18,tblAkis[YasGun]),0))
I19: =IF($A19="","",COUNTIFS(tblKontrol[KaynakKartId],$A19,tblKontrol[BelgeDurum],"YOK")) | J19: =IF($A19="","",SUMIF(tblAkis[KaynakKartId],$A19,tblAkis[Tutar])) | K19: =IF($A19="","",IFERROR(AVERAGEIF(tblAkis[KaynakKartId],$A19,tblAkis[YasGun]),0))
I20: =IF($A20="","",COUNTIFS(tblKontrol[KaynakKartId],$A20,tblKontrol[BelgeDurum],"YOK")) | J20: =IF($A20="","",SUMIF(tblAkis[KaynakKartId],$A20,tblAkis[Tutar])) | K20: =IF($A20="","",IFERROR(AVERAGEIF(tblAkis[KaynakKartId],$A20,tblAkis[YasGun]),0))
I21: =IF($A21="","",COUNTIFS(tblKontrol[KaynakKartId],$A21,tblKontrol[BelgeDurum],"YOK")) | J21: =IF($A21="","",SUMIF(tblAkis[KaynakKartId],$A21,tblAkis[Tutar])) | K21: =IF($A21="","",IFERROR(AVERAGEIF(tblAkis[KaynakKartId],$A21,tblAkis[YasGun]),0))
I22: =IF($A22="","",COUNTIFS(tblKontrol[KaynakKartId],$A22,tblKontrol[BelgeDurum],"YOK")) | J22: =IF($A22="","",SUMIF(tblAkis[KaynakKartId],$A22,tblAkis[Tutar])) | K22: =IF($A22="","",IFERROR(AVERAGEIF(tblAkis[KaynakKartId],$A22,tblAkis[YasGun]),0))
I23: =IF($A23="","",COUNTIFS(tblKontrol[KaynakKartId],$A23,tblKontrol[BelgeDurum],"YOK")) | J23: =IF($A23="","",SUMIF(tblAkis[KaynakKartId],$A23,tblAkis[Tutar])) | K23: =IF($A23="","",IFERROR(AVERAGEIF(tblAkis[KaynakKartId],$A23,tblAkis[YasGun]),0))
I24: =IF($A24="","",COUNTIFS(tblKontrol[KaynakKartId],$A24,tblKontrol[BelgeDurum],"YOK")) | J24: =IF($A24="","",SUMIF(tblAkis[KaynakKartId],$A24,tblAkis[Tutar])) | K24: =IF($A24="","",IFERROR(AVERAGEIF(tblAkis[KaynakKartId],$A24,tblAkis[YasGun]),0))
I25: =IF($A25="","",COUNTIFS(tblKontrol[KaynakKartId],$A25,tblKontrol[BelgeDurum],"YOK")) | J25: =IF($A25="","",SUMIF(tblAkis[KaynakKartId],$A25,tblAkis[Tutar])) | K25: =IF($A25="","",IFERROR(AVERAGEIF(tblAkis[KaynakKartId],$A25,tblAkis[YasGun]),0))
... I255: =IF($A255="","",COUNTIFS(tblKontrol[KaynakKartId],$A255,tblKontrol[BelgeDurum],"YOK")) | J255: =IF($A255="","",SUMIF(tblAkis[KaynakKartId],$A255,tblAkis[Tutar])) | K255: =IF($A255="","",IFERROR(AVERAGEIF(tblAkis[KaynakKartId],$A255,tblAkis[YasGun]),0))

Sheet AKIS
A1: AKIS — YMM Tasdik Kontrol Robotu
A3: Tasdik olay satırları — durum makinesi + yetim + geçersiz geçiş + zincir bayrakları
A5: IslemId | B5: KaynakKartId | C5: Tarih | D5: OncekiDurum | E5: Durum | F5: BasvuruTutar | G5: BelgeTutar | H5: KontrolTutar | I5: TasdikTutar | J5: ArsivTutar | K5: Tutar | L5: Donem | M5: Aciklama | N5: YasGun | O5: YasKova | P5: YetimBayrak | Q5: GecisUyarisi | R5: ZincirBayrak | S5: KayitDolu
A6: YTK-00001 | B6: MUK-00001 | C6: 46245 | E6: TASLAK | F6: 450000 | G6: 450000 | H6: 450000 | I6: 0 | J6: 0 | K6: 450000 | L6: 2026-08 | M6: Tasdik kontrol kalemi 1 | N6: =IF($A6="","",IF($C6="","",raporTarihi-$C6)) | O6: =IF($A6="","",IF($N6="","",IF($N6<=7,"0-7",IF($N6<=30,"8-30",IF($N6<=60,"31-60","60+"))))) | P6: =IF($A6="","",IF($B6="","YETİM",IF(COUNTIF(tblKartlar[KartId],$B6)=0,"YETİM",""))) | Q6: =IF(OR($A6="",$D6=""),"",IF(OR($D6&"|"&$E6="",COUNTIF(ListeIzinliGecis,$D6&"|"&$E6)>0),"","GEÇERSİZ GEÇİŞ")) | R6: =IF($A6="","",IF(OR($F6="",$G6=""),"",IF(ABS($G6-$F6)>zincirTolerans,"ZİNCİR KIRIK","OK"))) | S6: =IF($A6="","",1)
A7: YTK-00002 | B7: MUK-00002 | C7: 46242 | D7: TASLAK | E7: INCELEME | F7: 320000 | G7: 320000 | H7: 320000 | I7: 0 | J7: 0 | K7: 320000 | L7: 2026-08 | M7: Tasdik kontrol kalemi 2 | N7: =IF($A7="","",IF($C7="","",raporTarihi-$C7)) | O7: =IF($A7="","",IF($N7="","",IF($N7<=7,"0-7",IF($N7<=30,"8-30",IF($N7<=60,"31-60","60+"))))) | P7: =IF($A7="","",IF($B7="","YETİM",IF(COUNTIF(tblKartlar[KartId],$B7)=0,"YETİM",""))) | Q7: =IF(OR($A7="",$D7=""),"",IF(OR($D7&"|"&$E7="",COUNTIF(ListeIzinliGecis,$D7&"|"&$E7)>0),"","GEÇERSİZ GEÇİŞ")) | R7: =IF($A7="","",IF(OR($F7="",$G7=""),"",IF(ABS($G7-$F7)>zincirTolerans,"ZİNCİR KIRIK","OK"))) | S7: =IF($A7="","",1)
A8: YTK-00003 | B8: MUK-00003 | C8: 46239 | D8: INCELEME | E8: EKSIK | F8: 780000 | G8: 780000 | H8: 780000 | I8: 0 | J8: 0 | K8: 780000 | L8: 2026-08 | M8: Tasdik kontrol kalemi 3 | N8: =IF($A8="","",IF($C8="","",raporTarihi-$C8)) | O8: =IF($A8="","",IF($N8="","",IF($N8<=7,"0-7",IF($N8<=30,"8-30",IF($N8<=60,"31-60","60+"))))) | P8: =IF($A8="","",IF($B8="","YETİM",IF(COUNTIF(tblKartlar[KartId],$B8)=0,"YETİM",""))) | Q8: =IF(OR($A8="",$D8=""),"",IF(OR($D8&"|"&$E8="",COUNTIF(ListeIzinliGecis,$D8&"|"&$E8)>0),"","GEÇERSİZ GEÇİŞ")) | R8: =IF($A8="","",IF(OR($F8="",$G8=""),"",IF(ABS($G8-$F8)>zincirTolerans,"ZİNCİR KIRIK","OK"))) | S8: =IF($A8="","",1)
A9: YTK-00004 | B9: MUK-00004 | C9: 46236 | D9: INCELEME | E9: TASDIK | F9: 210000 | G9: 210000 | H9: 210000 | I9: 210000 | J9: 210000 | K9: 210000 | L9: 2026-08 | M9: Tasdik kontrol kalemi 4 | N9: =IF($A9="","",IF($C9="","",raporTarihi-$C9)) | O9: =IF($A9="","",IF($N9="","",IF($N9<=7,"0-7",IF($N9<=30,"8-30",IF($N9<=60,"31-60","60+"))))) | P9: =IF($A9="","",IF($B9="","YETİM",IF(COUNTIF(tblKartlar[KartId],$B9)=0,"YETİM",""))) | Q9: =IF(OR($A9="",$D9=""),"",IF(OR($D9&"|"&$E9="",COUNTIF(ListeIzinliGecis,$D9&"|"&$E9)>0),"","GEÇERSİZ GEÇİŞ")) | R9: =IF($A9="","",IF(OR($F9="",$G9=""),"",IF(ABS($G9-$F9)>zincirTolerans,"ZİNCİR KIRIK","OK"))) | S9: =IF($A9="","",1)
A10: YTK-00005 | B10: MUK-00005 | C10: 46233 | D10: INCELEME | E10: DURDUR | F10: 950000 | G10: 950000 | H10: 950000 | I10: 0 | J10: 0 | K10: 950000 | L10: 2026-08 | M10: Tasdik kontrol kalemi 5 | N10: =IF($A10="","",IF($C10="","",raporTarihi-$C10)) | O10: =IF($A10="","",IF($N10="","",IF($N10<=7,"0-7",IF($N10<=30,"8-30",IF($N10<=60,"31-60","60+"))))) | P10: =IF($A10="","",IF($B10="","YETİM",IF(COUNTIF(tblKartlar[KartId],$B10)=0,"YETİM",""))) | Q10: =IF(OR($A10="",$D10=""),"",IF(OR($D10&"|"&$E10="",COUNTIF(ListeIzinliGecis,$D10&"|"&$E10)>0),"","GEÇERSİZ GEÇİŞ")) | R10: =IF($A10="","",IF(OR($F10="",$G10=""),"",IF(ABS($G10-$F10)>zincirTolerans,"ZİNCİR KIRIK","OK"))) | S10: =IF($A10="","",1)
A11: YTK-00006 | B11: MUK-00006 | C11: 46230 | D11: EKSIK | E11: INCELEME | F11: 280000 | G11: 280000 | H11: 280000 | I11: 0 | J11: 0 | K11: 280000 | L11: 2026-08 | M11: Tasdik kontrol kalemi 6 | N11: =IF($A11="","",IF($C11="","",raporTarihi-$C11)) | O11: =IF($A11="","",IF($N11="","",IF($N11<=7,"0-7",IF($N11<=30,"8-30",IF($N11<=60,"31-60","60+"))))) | P11: =IF($A11="","",IF($B11="","YETİM",IF(COUNTIF(tblKartlar[KartId],$B11)=0,"YETİM",""))) | Q11: =IF(OR($A11="",$D11=""),"",IF(OR($D11&"|"&$E11="",COUNTIF(ListeIzinliGecis,$D11&"|"&$E11)>0),"","GEÇERSİZ GEÇİŞ")) | R11: =IF($A11="","",IF(OR($F11="",$G11=""),"",IF(ABS($G11-$F11)>zincirTolerans,"ZİNCİR KIRIK","OK"))) | S11: =IF($A11="","",1)
A12: YTK-00007 | B12: MUK-00007 | C12: 46227 | E12: TASLAK | F12: 190000 | G12: 190000 | H12: 190000 | I12: 0 | J12: 0 | K12: 190000 | L12: 2026-08 | M12: Tasdik kontrol kalemi 7 | N12: =IF($A12="","",IF($C12="","",raporTarihi-$C12)) | O12: =IF($A12="","",IF($N12="","",IF($N12<=7,"0-7",IF($N12<=30,"8-30",IF($N12<=60,"31-60","60+"))))) | P12: =IF($A12="","",IF($B12="","YETİM",IF(COUNTIF(tblKartlar[KartId],$B12)=0,"YETİM",""))) | Q12: =IF(OR($A12="",$D12=""),"",IF(OR($D12&"|"&$E12="",COUNTIF(ListeIzinliGecis,$D12&"|"&$E12)>0),"","GEÇERSİZ GEÇİŞ")) | R12: =IF($A12="","",IF(OR($F12="",$G12=""),"",IF(ABS($G12-$F12)>zincirTolerans,"ZİNCİR KIRIK","OK"))) | S12: =IF($A12="","",1)
A13: YTK-00008 | B13: MUK-00008 | C13: 46224 | D13: TASLAK | E13: INCELEME | F13: 410000 | G13: 410000 | H13: 410000 | I13: 0 | J13: 0 | K13: 410000 | L13: 2026-08 | M13: Tasdik kontrol kalemi 8 | N13: =IF($A13="","",IF($C13="","",raporTarihi-$C13)) | O13: =IF($A13="","",IF($N13="","",IF($N13<=7,"0-7",IF($N13<=30,"8-30",IF($N13<=60,"31-60","60+"))))) | P13: =IF($A13="","",IF($B13="","YETİM",IF(COUNTIF(tblKartlar[KartId],$B13)=0,"YETİM",""))) | Q13: =IF(OR($A13="",$D13=""),"",IF(OR($D13&"|"&$E13="",COUNTIF(ListeIzinliGecis,$D13&"|"&$E13)>0),"","GEÇERSİZ GEÇİŞ")) | R13: =IF($A13="","",IF(OR($F13="",$G13=""),"",IF(ABS($G13-$F13)>zincirTolerans,"ZİNCİR KIRIK","OK"))) | S13: =IF($A13="","",1)
A14: YTK-00009 | B14: MUK-00001 | C14: 46221 | E14: TASLAK | F14: 450000 | G14: 450000 | H14: 450000 | I14: 0 | J14: 0 | K14: 450000 | L14: 2026-08 | M14: Tasdik kontrol kalemi 9 | N14: =IF($A14="","",IF($C14="","",raporTarihi-$C14)) | O14: =IF($A14="","",IF($N14="","",IF($N14<=7,"0-7",IF($N14<=30,"8-30",IF($N14<=60,"31-60","60+"))))) | P14: =IF($A14="","",IF($B14="","YETİM",IF(COUNTIF(tblKartlar[KartId],$B14)=0,"YETİM",""))) | Q14: =IF(OR($A14="",$D14=""),"",IF(OR($D14&"|"&$E14="",COUNTIF(ListeIzinliGecis,$D14&"|"&$E14)>0),"","GEÇERSİZ GEÇİŞ")) | R14: =IF($A14="","",IF(OR($F14="",$G14=""),"",IF(ABS($G14-$F14)>zincirTolerans,"ZİNCİR KIRIK","OK"))) | S14: =IF($A14="","",1)
A15: YTK-00010 | B15: MUK-00002 | C15: 46218 | D15: TASLAK | E15: INCELEME | F15: 320000 | G15: 320000 | H15: 320000 | I15: 0 | J15: 0 | K15: 320000 | L15: 2026-08 | M15: Tasdik kontrol kalemi 10 | N15: =IF($A15="","",IF($C15="","",raporTarihi-$C15)) | O15: =IF($A15="","",IF($N15="","",IF($N15<=7,"0-7",IF($N15<=30,"8-30",IF($N15<=60,"31-60","60+"))))) | P15: =IF($A15="","",IF($B15="","YETİM",IF(COUNTIF(tblKartlar[KartId],$B15)=0,"YETİM",""))) | Q15: =IF(OR($A15="",$D15=""),"",IF(OR($D15&"|"&$E15="",COUNTIF(ListeIzinliGecis,$D15&"|"&$E15)>0),"","GEÇERSİZ GEÇİŞ")) | R15: =IF($A15="","",IF(OR($F15="",$G15=""),"",IF(ABS($G15-$F15)>zincirTolerans,"ZİNCİR KIRIK","OK"))) | S15: =IF($A15="","",1)
A16: YTK-00011 | B16: MUK-00003 | C16: 46215 | D16: INCELEME | E16: EKSIK | F16: 780000 | G16: 780000 | H16: 780000 | I16: 0 | J16: 0 | K16: 780000 | L16: 2026-08 | M16: Tasdik kontrol kalemi 11 | N16: =IF($A16="","",IF($C16="","",raporTarihi-$C16)) | O16: =IF($A16="","",IF($N16="","",IF($N16<=7,"0-7",IF($N16<=30,"8-30",IF($N16<=60,"31-60","60+"))))) | P16: =IF($A16="","",IF($B16="","YETİM",IF(COUNTIF(tblKartlar[KartId],$B16)=0,"YETİM",""))) | Q16: =IF(OR($A16="",$D16=""),"",IF(OR($D16&"|"&$E16="",COUNTIF(ListeIzinliGecis,$D16&"|"&$E16)>0),"","GEÇERSİZ GEÇİŞ")) | R16: =IF($A16="","",IF(OR($F16="",$G16=""),"",IF(ABS($G16-$F16)>zincirTolerans,"ZİNCİR KIRIK","OK"))) | S16: =IF($A16="","",1)
A17: YTK-00012 | B17: MUK-00004 | C17: 46212 | D17: INCELEME | E17: TASDIK | F17: 210000 | G17: 225000 | H17: 225000 | I17: 225000 | J17: 225000 | K17: 210000 | L17: 2026-08 | M17: Tasdik kontrol kalemi 12 | N17: =IF($A17="","",IF($C17="","",raporTarihi-$C17)) | O17: =IF($A17="","",IF($N17="","",IF($N17<=7,"0-7",IF($N17<=30,"8-30",IF($N17<=60,"31-60","60+"))))) | P17: =IF($A17="","",IF($B17="","YETİM",IF(COUNTIF(tblKartlar[KartId],$B17)=0,"YETİM",""))) | Q17: =IF(OR($A17="",$D17=""),"",IF(OR($D17&"|"&$E17="",COUNTIF(ListeIzinliGecis,$D17&"|"&$E17)>0),"","GEÇERSİZ GEÇİŞ")) | R17: =IF($A17="","",IF(OR($F17="",$G17=""),"",IF(ABS($G17-$F17)>zincirTolerans,"ZİNCİR KIRIK","OK"))) | S17: =IF($A17="","",1)
A18: YTK-00013 | B18: MUK-00005 | C18: 46209 | D18: INCELEME | E18: DURDUR | F18: 950000 | G18: 950000 | H18: 950000 | I18: 0 | J18: 0 | K18: 950000 | L18: 2026-08 | M18: Tasdik kontrol kalemi 13 | N18: =IF($A18="","",IF($C18="","",raporTarihi-$C18)) | O18: =IF($A18="","",IF($N18="","",IF($N18<=7,"0-7",IF($N18<=30,"8-30",IF($N18<=60,"31-60","60+"))))) | P18: =IF($A18="","",IF($B18="","YETİM",IF(COUNTIF(tblKartlar[KartId],$B18)=0,"YETİM",""))) | Q18: =IF(OR($A18="",$D18=""),"",IF(OR($D18&"|"&$E18="",COUNTIF(ListeIzinliGecis,$D18&"|"&$E18)>0),"","GEÇERSİZ GEÇİŞ")) | R18: =IF($A18="","",IF(OR($F18="",$G18=""),"",IF(ABS($G18-$F18)>zincirTolerans,"ZİNCİR KIRIK","OK"))) | S18: =IF($A18="","",1)
A19: YTK-00014 | B19: MUK-00006 | C19: 46206 | D19: EKSIK | E19: INCELEME | F19: 280000 | G19: 280000 | H19: 280000 | I19: 0 | J19: 0 | K19: 280000 | L19: 2026-08 | M19: Tasdik kontrol kalemi 14 | N19: =IF($A19="","",IF($C19="","",raporTarihi-$C19)) | O19: =IF($A19="","",IF($N19="","",IF($N19<=7,"0-7",IF($N19<=30,"8-30",IF($N19<=60,"31-60","60+"))))) | P19: =IF($A19="","",IF($B19="","YETİM",IF(COUNTIF(tblKartlar[KartId],$B19)=0,"YETİM",""))) | Q19: =IF(OR($A19="",$D19=""),"",IF(OR($D19&"|"&$E19="",COUNTIF(ListeIzinliGecis,$D19&"|"&$E19)>0),"","GEÇERSİZ GEÇİŞ")) | R19: =IF($A19="","",IF(OR($F19="",$G19=""),"",IF(ABS($G19-$F19)>zincirTolerans,"ZİNCİR KIRIK","OK"))) | S19: =IF($A19="","",1)
A20: YTK-00015 | B20: MUK-00007 | C20: 46203 | E20: TASLAK | F20: 190000 | G20: 190000 | H20: 190000 | I20: 0 | J20: 0 | K20: 190000 | L20: 2026-08 | M20: Tasdik kontrol kalemi 15 | N20: =IF($A20="","",IF($C20="","",raporTarihi-$C20)) | O20: =IF($A20="","",IF($N20="","",IF($N20<=7,"0-7",IF($N20<=30,"8-30",IF($N20<=60,"31-60","60+"))))) | P20: =IF($A20="","",IF($B20="","YETİM",IF(COUNTIF(tblKartlar[KartId],$B20)=0,"YETİM",""))) | Q20: =IF(OR($A20="",$D20=""),"",IF(OR($D20&"|"&$E20="",COUNTIF(ListeIzinliGecis,$D20&"|"&$E20)>0),"","GEÇERSİZ GEÇİŞ")) | R20: =IF($A20="","",IF(OR($F20="",$G20=""),"",IF(ABS($G20-$F20)>zincirTolerans,"ZİNCİR KIRIK","OK"))) | S20: =IF($A20="","",1)
A21: YTK-00016 | B21: MUK-00008 | C21: 46200 | D21: TASLAK | E21: INCELEME | F21: 410000 | G21: 410000 | H21: 410000 | I21: 0 | J21: 0 | K21: 410000 | L21: 2026-08 | M21: Tasdik kontrol kalemi 16 | N21: =IF($A21="","",IF($C21="","",raporTarihi-$C21)) | O21: =IF($A21="","",IF($N21="","",IF($N21<=7,"0-7",IF($N21<=30,"8-30",IF($N21<=60,"31-60","60+"))))) | P21: =IF($A21="","",IF($B21="","YETİM",IF(COUNTIF(tblKartlar[KartId],$B21)=0,"YETİM",""))) | Q21: =IF(OR($A21="",$D21=""),"",IF(OR($D21&"|"&$E21="",COUNTIF(ListeIzinliGecis,$D21&"|"&$E21)>0),"","GEÇERSİZ GEÇİŞ")) | R21: =IF($A21="","",IF(OR($F21="",$G21=""),"",IF(ABS($G21-$F21)>zincirTolerans,"ZİNCİR KIRIK","OK"))) | S21: =IF($A21="","",1)
A22: YTK-00017 | B22: MUK-00001 | C22: 46197 | E22: TASLAK | F22: 450000 | G22: 450000 | H22: 450000 | I22: 0 | J22: 0 | K22: 450000 | L22: 2026-08 | M22: Tasdik kontrol kalemi 17 | N22: =IF($A22="","",IF($C22="","",raporTarihi-$C22)) | O22: =IF($A22="","",IF($N22="","",IF($N22<=7,"0-7",IF($N22<=30,"8-30",IF($N22<=60,"31-60","60+"))))) | P22: =IF($A22="","",IF($B22="","YETİM",IF(COUNTIF(tblKartlar[KartId],$B22)=0,"YETİM",""))) | Q22: =IF(OR($A22="",$D22=""),"",IF(OR($D22&"|"&$E22="",COUNTIF(ListeIzinliGecis,$D22&"|"&$E22)>0),"","GEÇERSİZ GEÇİŞ")) | R22: =IF($A22="","",IF(OR($F22="",$G22=""),"",IF(ABS($G22-$F22)>zincirTolerans,"ZİNCİR KIRIK","OK"))) | S22: =IF($A22="","",1)
A23: YTK-00018 | B23: MUK-00002 | C23: 46194 | D23: TASLAK | E23: TASDIK | F23: 320000 | G23: 320000 | H23: 320000 | I23: 320000 | J23: 320000 | K23: 320000 | L23: 2026-08 | M23: Tasdik kontrol kalemi 18 | N23: =IF($A23="","",IF($C23="","",raporTarihi-$C23)) | O23: =IF($A23="","",IF($N23="","",IF($N23<=7,"0-7",IF($N23<=30,"8-30",IF($N23<=60,"31-60","60+"))))) | P23: =IF($A23="","",IF($B23="","YETİM",IF(COUNTIF(tblKartlar[KartId],$B23)=0,"YETİM",""))) | Q23: =IF(OR($A23="",$D23=""),"",IF(OR($D23&"|"&$E23="",COUNTIF(ListeIzinliGecis,$D23&"|"&$E23)>0),"","GEÇERSİZ GEÇİŞ")) | R23: =IF($A23="","",IF(OR($F23="",$G23=""),"",IF(ABS($G23-$F23)>zincirTolerans,"ZİNCİR KIRIK","OK"))) | S23: =IF($A23="","",1)
A24: YTK-00019 | B24: MUK-00003 | C24: 46191 | D24: INCELEME | E24: EKSIK | F24: 780000 | G24: 795000 | H24: 795000 | I24: 0 | J24: 0 | K24: 780000 | L24: 2026-08 | M24: Tasdik kontrol kalemi 19 | N24: =IF($A24="","",IF($C24="","",raporTarihi-$C24)) | O24: =IF($A24="","",IF($N24="","",IF($N24<=7,"0-7",IF($N24<=30,"8-30",IF($N24<=60,"31-60","60+"))))) | P24: =IF($A24="","",IF($B24="","YETİM",IF(COUNTIF(tblKartlar[KartId],$B24)=0,"YETİM",""))) | Q24: =IF(OR($A24="",$D24=""),"",IF(OR($D24&"|"&$E24="",COUNTIF(ListeIzinliGecis,$D24&"|"&$E24)>0),"","GEÇERSİZ GEÇİŞ")) | R24: =IF($A24="","",IF(OR($F24="",$G24=""),"",IF(ABS($G24-$F24)>zincirTolerans,"ZİNCİR KIRIK","OK"))) | S24: =IF($A24="","",1)
A25: YTK-00020 | B25: MUK-00004 | C25: 46188 | D25: TASDIK | E25: INCELEME | F25: 210000 | G25: 210000 | H25: 210000 | I25: 0 | J25: 0 | K25: 210000 | L25: 2026-08 | M25: Tasdik kontrol kalemi 20 | N25: =IF($A25="","",IF($C25="","",raporTarihi-$C25)) | O25: =IF($A25="","",IF($N25="","",IF($N25<=7,"0-7",IF($N25<=30,"8-30",IF($N25<=60,"31-60","60+"))))) | P25: =IF($A25="","",IF($B25="","YETİM",IF(COUNTIF(tblKartlar[KartId],$B25)=0,"YETİM",""))) | Q25: =IF(OR($A25="",$D25=""),"",IF(OR($D25&"|"&$E25="",COUNTIF(ListeIzinliGecis,$D25&"|"&$E25)>0),"","GEÇERSİZ GEÇİŞ")) | R25: =IF($A25="","",IF(OR($F25="",$G25=""),"",IF(ABS($G25-$F25)>zincirTolerans,"ZİNCİR KIRIK","OK"))) | S25: =IF($A25="","",1)
A26: YTK-00021 | B26: MUK-00005 | C26: 46185 | D26: INCELEME | E26: DURDUR | F26: 950000 | G26: 950000 | H26: 950000 | I26: 0 | J26: 0 | K26: 950000 | L26: 2026-08 | M26: Tasdik kontrol kalemi 21 | N26: =IF($A26="","",IF($C26="","",raporTarihi-$C26)) | O26: =IF($A26="","",IF($N26="","",IF($N26<=7,"0-7",IF($N26<=30,"8-30",IF($N26<=60,"31-60","60+"))))) | P26: =IF($A26="","",IF($B26="","YETİM",IF(COUNTIF(tblKartlar[KartId],$B26)=0,"YETİM",""))) | Q26: =IF(OR($A26="",$D26=""),"",IF(OR($D26&"|"&$E26="",COUNTIF(ListeIzinliGecis,$D26&"|"&$E26)>0),"","GEÇERSİZ GEÇİŞ")) | R26: =IF($A26="","",IF(OR($F26="",$G26=""),"",IF(ABS($G26-$F26)>zincirTolerans,"ZİNCİR KIRIK","OK"))) | S26: =IF($A26="","",1)
A27: YTK-00022 | C27: 46182 | D27: EKSIK | E27: INCELEME | F27: 280000 | G27: 280000 | H27: 280000 | I27: 0 | J27: 0 | K27: 280000 | L27: 2026-08 | M27: Tasdik kontrol kalemi 22 | N27: =IF($A27="","",IF($C27="","",raporTarihi-$C27)) | O27: =IF($A27="","",IF($N27="","",IF($N27<=7,"0-7",IF($N27<=30,"8-30",IF($N27<=60,"31-60","60+"))))) | P27: =IF($A27="","",IF($B27="","YETİM",IF(COUNTIF(tblKartlar[KartId],$B27)=0,"YETİM",""))) | Q27: =IF(OR($A27="",$D27=""),"",IF(OR($D27&"|"&$E27="",COUNTIF(ListeIzinliGecis,$D27&"|"&$E27)>0),"","GEÇERSİZ GEÇİŞ")) | R27: =IF($A27="","",IF(OR($F27="",$G27=""),"",IF(ABS($G27-$F27)>zincirTolerans,"ZİNCİR KIRIK","OK"))) | S27: =IF($A27="","",1)
A28: YTK-00023 | B28: MUK-00007 | C28: 46179 | E28: TASLAK | F28: 190000 | G28: 190000 | H28: 190000 | I28: 0 | J28: 0 | K28: 190000 | L28: 2026-08 | M28: Tasdik kontrol kalemi 23 | N28: =IF($A28="","",IF($C28="","",raporTarihi-$C28)) | O28: =IF($A28="","",IF($N28="","",IF($N28<=7,"0-7",IF($N28<=30,"8-30",IF($N28<=60,"31-60","60+"))))) | P28: =IF($A28="","",IF($B28="","YETİM",IF(COUNTIF(tblKartlar[KartId],$B28)=0,"YETİM",""))) | Q28: =IF(OR($A28="",$D28=""),"",IF(OR($D28&"|"&$E28="",COUNTIF(ListeIzinliGecis,$D28&"|"&$E28)>0),"","GEÇERSİZ GEÇİŞ")) | R28: =IF($A28="","",IF(OR($F28="",$G28=""),"",IF(ABS($G28-$F28)>zincirTolerans,"ZİNCİR KIRIK","OK"))) | S28: =IF($A28="","",1)
A29: YTK-00024 | B29: MUK-00008 | C29: 46176 | D29: TASLAK | E29: INCELEME | F29: 410000 | G29: 410000 | H29: 410000 | I29: 0 | J29: 0 | K29: 410000 | L29: 2026-08 | M29: Tasdik kontrol kalemi 24 | N29: =IF($A29="","",IF($C29="","",raporTarihi-$C29)) | O29: =IF($A29="","",IF($N29="","",IF($N29<=7,"0-7",IF($N29<=30,"8-30",IF($N29<=60,"31-60","60+"))))) | P29: =IF($A29="","",IF($B29="","YETİM",IF(COUNTIF(tblKartlar[KartId],$B29)=0,"YETİM",""))) | Q29: =IF(OR($A29="",$D29=""),"",IF(OR($D29&"|"&$E29="",COUNTIF(ListeIzinliGecis,$D29&"|"&$E29)>0),"","GEÇERSİZ GEÇİŞ")) | R29: =IF($A29="","",IF(OR($F29="",$G29=""),"",IF(ABS($G29-$F29)>zincirTolerans,"ZİNCİR KIRIK","OK"))) | S29: =IF($A29="","",1)
A30: YTK-00025 | B30: MUK-99999 | C30: 46248 | E30: TASLAK | F30: 450000 | G30: 450000 | H30: 450000 | I30: 0 | J30: 0 | K30: 450000 | L30: 2026-08 | M30: Tasdik kontrol kalemi 25 | N30: =IF($A30="","",IF($C30="","",raporTarihi-$C30)) | O30: =IF($A30="","",IF($N30="","",IF($N30<=7,"0-7",IF($N30<=30,"8-30",IF($N30<=60,"31-60","60+"))))) | P30: =IF($A30="","",IF($B30="","YETİM",IF(COUNTIF(tblKartlar[KartId],$B30)=0,"YETİM",""))) | Q30: =IF(OR($A30="",$D30=""),"",IF(OR($D30&"|"&$E30="",COUNTIF(ListeIzinliGecis,$D30&"|"&$E30)>0),"","GEÇERSİZ GEÇİŞ")) | R30: =IF($A30="","",IF(OR($F30="",$G30=""),"",IF(ABS($G30-$F30)>zincirTolerans,"ZİNCİR KIRIK","OK"))) | S30: =IF($A30="","",1)
A31: YTK-00026 | B31: MUK-00002 | C31: 46245 | D31: TASLAK | E31: INCELEME | F31: 320000 | G31: 320000 | H31: 320000 | I31: 0 | J31: 0 | K31: 320000 | L31: 2026-08 | M31: Tasdik kontrol kalemi 26 | N31: =IF($A31="","",IF($C31="","",raporTarihi-$C31)) | O31: =IF($A31="","",IF($N31="","",IF($N31<=7,"0-7",IF($N31<=30,"8-30",IF($N31<=60,"31-60","60+"))))) | P31: =IF($A31="","",IF($B31="","YETİM",IF(COUNTIF(tblKartlar[KartId],$B31)=0,"YETİM",""))) | Q31: =IF(OR($A31="",$D31=""),"",IF(OR($D31&"|"&$E31="",COUNTIF(ListeIzinliGecis,$D31&"|"&$E31)>0),"","GEÇERSİZ GEÇİŞ")) | R31: =IF($A31="","",IF(OR($F31="",$G31=""),"",IF(ABS($G31-$F31)>zincirTolerans,"ZİNCİR KIRIK","OK"))) | S31: =IF($A31="","",1)
A32: YTK-00027 | B32: MUK-00003 | C32: 46242 | D32: INCELEME | E32: EKSIK | F32: 780000 | G32: 780000 | H32: 780000 | I32: 0 | J32: 0 | K32: 780000 | L32: 2026-08 | M32: Tasdik kontrol kalemi 27 | N32: =IF($A32="","",IF($C32="","",raporTarihi-$C32)) | O32: =IF($A32="","",IF($N32="","",IF($N32<=7,"0-7",IF($N32<=30,"8-30",IF($N32<=60,"31-60","60+"))))) | P32: =IF($A32="","",IF($B32="","YETİM",IF(COUNTIF(tblKartlar[KartId],$B32)=0,"YETİM",""))) | Q32: =IF(OR($A32="",$D32=""),"",IF(OR($D32&"|"&$E32="",COUNTIF(ListeIzinliGecis,$D32&"|"&$E32)>0),"","GEÇERSİZ GEÇİŞ")) | R32: =IF($A32="","",IF(OR($F32="",$G32=""),"",IF(ABS($G32-$F32)>zincirTolerans,"ZİNCİR KIRIK","OK"))) | S32: =IF($A32="","",1)
A33: YTK-00028 | B33: MUK-00004 | C33: 46239 | D33: INCELEME | E33: TASDIK | F33: 210000 | G33: 210000 | H33: 210000 | I33: 210000 | J33: 210000 | K33: 210000 | L33: 2026-08 | M33: Tasdik kontrol kalemi 28 | N33: =IF($A33="","",IF($C33="","",raporTarihi-$C33)) | O33: =IF($A33="","",IF($N33="","",IF($N33<=7,"0-7",IF($N33<=30,"8-30",IF($N33<=60,"31-60","60+"))))) | P33: =IF($A33="","",IF($B33="","YETİM",IF(COUNTIF(tblKartlar[KartId],$B33)=0,"YETİM",""))) | Q33: =IF(OR($A33="",$D33=""),"",IF(OR($D33&"|"&$E33="",COUNTIF(ListeIzinliGecis,$D33&"|"&$E33)>0),"","GEÇERSİZ GEÇİŞ")) | R33: =IF($A33="","",IF(OR($F33="",$G33=""),"",IF(ABS($G33-$F33)>zincirTolerans,"ZİNCİR KIRIK","OK"))) | S33: =IF($A33="","",1)
N34: =IF($A34="","",IF($C34="","",raporTarihi-$C34)) | O34: =IF($A34="","",IF($N34="","",IF($N34<=7,"0-7",IF($N34<=30,"8-30",IF($N34<=60,"31-60","60+"))))) | P34: =IF($A34="","",IF($B34="","YETİM",IF(COUNTIF(tblKartlar[KartId],$B34)=0,"YETİM",""))) | Q34: =IF(OR($A34="",$D34=""),"",IF(OR($D34&"|"&$E34="",COUNTIF(ListeIzinliGecis,$D34&"|"&$E34)>0),"","GEÇERSİZ GEÇİŞ")) | R34: =IF($A34="","",IF(OR($F34="",$G34=""),"",IF(ABS($G34-$F34)>zincirTolerans,"ZİNCİR KIRIK","OK"))) | S34: =IF($A34="","",1)
N35: =IF($A35="","",IF($C35="","",raporTarihi-$C35)) | O35: =IF($A35="","",IF($N35="","",IF($N35<=7,"0-7",IF($N35<=30,"8-30",IF($N35<=60,"31-60","60+"))))) | P35: =IF($A35="","",IF($B35="","YETİM",IF(COUNTIF(tblKartlar[KartId],$B35)=0,"YETİM",""))) | Q35: =IF(OR($A35="",$D35=""),"",IF(OR($D35&"|"&$E35="",COUNTIF(ListeIzinliGecis,$D35&"|"&$E35)>0),"","GEÇERSİZ GEÇİŞ")) | R35: =IF($A35="","",IF(OR($F35="",$G35=""),"",IF(ABS($G35-$F35)>zincirTolerans,"ZİNCİR KIRIK","OK"))) | S35: =IF($A35="","",1)
N36: =IF($A36="","",IF($C36="","",raporTarihi-$C36)) | O36: =IF($A36="","",IF($N36="","",IF($N36<=7,"0-7",IF($N36<=30,"8-30",IF($N36<=60,"31-60","60+"))))) | P36: =IF($A36="","",IF($B36="","YETİM",IF(COUNTIF(tblKartlar[KartId],$B36)=0,"YETİM",""))) | Q36: =IF(OR($A36="",$D36=""),"",IF(OR($D36&"|"&$E36="",COUNTIF(ListeIzinliGecis,$D36&"|"&$E36)>0),"","GEÇERSİZ GEÇİŞ")) | R36: =IF($A36="","",IF(OR($F36="",$G36=""),"",IF(ABS($G36-$F36)>zincirTolerans,"ZİNCİR KIRIK","OK"))) | S36: =IF($A36="","",1)
N37: =IF($A37="","",IF($C37="","",raporTarihi-$C37)) | O37: =IF($A37="","",IF($N37="","",IF($N37<=7,"0-7",IF($N37<=30,"8-30",IF($N37<=60,"31-60","60+"))))) | P37: =IF($A37="","",IF($B37="","YETİM",IF(COUNTIF(tblKartlar[KartId],$B37)=0,"YETİM",""))) | Q37: =IF(OR($A37="",$D37=""),"",IF(OR($D37&"|"&$E37="",COUNTIF(ListeIzinliGecis,$D37&"|"&$E37)>0),"","GEÇERSİZ GEÇİŞ")) | R37: =IF($A37="","",IF(OR($F37="",$G37=""),"",IF(ABS($G37-$F37)>zincirTolerans,"ZİNCİR KIRIK","OK"))) | S37: =IF($A37="","",1)
N38: =IF($A38="","",IF($C38="","",raporTarihi-$C38)) | O38: =IF($A38="","",IF($N38="","",IF($N38<=7,"0-7",IF($N38<=30,"8-30",IF($N38<=60,"31-60","60+"))))) | P38: =IF($A38="","",IF($B38="","YETİM",IF(COUNTIF(tblKartlar[KartId],$B38)=0,"YETİM",""))) | Q38: =IF(OR($A38="",$D38=""),"",IF(OR($D38&"|"&$E38="",COUNTIF(ListeIzinliGecis,$D38&"|"&$E38)>0),"","GEÇERSİZ GEÇİŞ")) | R38: =IF($A38="","",IF(OR($F38="",$G38=""),"",IF(ABS($G38-$F38)>zincirTolerans,"ZİNCİR KIRIK","OK"))) | S38: =IF($A38="","",1)
N39: =IF($A39="","",IF($C39="","",raporTarihi-$C39)) | O39: =IF($A39="","",IF($N39="","",IF($N39<=7,"0-7",IF($N39<=30,"8-30",IF($N39<=60,"31-60","60+"))))) | P39: =IF($A39="","",IF($B39="","YETİM",IF(COUNTIF(tblKartlar[KartId],$B39)=0,"YETİM",""))) | Q39: =IF(OR($A39="",$D39=""),"",IF(OR($D39&"|"&$E39="",COUNTIF(ListeIzinliGecis,$D39&"|"&$E39)>0),"","GEÇERSİZ GEÇİŞ")) | R39: =IF($A39="","",IF(OR($F39="",$G39=""),"",IF(ABS($G39-$F39)>zincirTolerans,"ZİNCİR KIRIK","OK"))) | S39: =IF($A39="","",1)
N40: =IF($A40="","",IF($C40="","",raporTarihi-$C40)) | O40: =IF($A40="","",IF($N40="","",IF($N40<=7,"0-7",IF($N40<=30,"8-30",IF($N40<=60,"31-60","60+"))))) | P40: =IF($A40="","",IF($B40="","YETİM",IF(COUNTIF(tblKartlar[KartId],$B40)=0,"YETİM",""))) | Q40: =IF(OR($A40="",$D40=""),"",IF(OR($D40&"|"&$E40="",COUNTIF(ListeIzinliGecis,$D40&"|"&$E40)>0),"","GEÇERSİZ GEÇİŞ")) | R40: =IF($A40="","",IF(OR($F40="",$G40=""),"",IF(ABS($G40-$F40)>zincirTolerans,"ZİNCİR KIRIK","OK"))) | S40: =IF($A40="","",1)
N41: =IF($A41="","",IF($C41="","",raporTarihi-$C41)) | O41: =IF($A41="","",IF($N41="","",IF($N41<=7,"0-7",IF($N41<=30,"8-30",IF($N41<=60,"31-60","60+"))))) | P41: =IF($A41="","",IF($B41="","YETİM",IF(COUNTIF(tblKartlar[KartId],$B41)=0,"YETİM",""))) | Q41: =IF(OR($A41="",$D41=""),"",IF(OR($D41&"|"&$E41="",COUNTIF(ListeIzinliGecis,$D41&"|"&$E41)>0),"","GEÇERSİZ GEÇİŞ")) | R41: =IF($A41="","",IF(OR($F41="",$G41=""),"",IF(ABS($G41-$F41)>zincirTolerans,"ZİNCİR KIRIK","OK"))) | S41: =IF($A41="","",1)
N42: =IF($A42="","",IF($C42="","",raporTarihi-$C42)) | O42: =IF($A42="","",IF($N42="","",IF($N42<=7,"0-7",IF($N42<=30,"8-30",IF($N42<=60,"31-60","60+"))))) | P42: =IF($A42="","",IF($B42="","YETİM",IF(COUNTIF(tblKartlar[KartId],$B42)=0,"YETİM",""))) | Q42: =IF(OR($A42="",$D42=""),"",IF(OR($D42&"|"&$E42="",COUNTIF(ListeIzinliGecis,$D42&"|"&$E42)>0),"","GEÇERSİZ GEÇİŞ")) | R42: =IF($A42="","",IF(OR($F42="",$G42=""),"",IF(ABS($G42-$F42)>zincirTolerans,"ZİNCİR KIRIK","OK"))) | S42: =IF($A42="","",1)
...

Sheet KUYRUKLAR
A1: KUYRUKLAR — YMM Tasdik Kontrol Robotu
A3: Durum bazlı canlı kuyruk — kapalı kayıtlar düşer
A5: Kuyruk | B5: Adet | C5: Tutar
A6: İnceleme | B6: =COUNTIFS(tblAkis[durum],"INCELEME",tblAkis[tutar],">0") | C6: =SUMIFS(tblAkis[tutar],tblAkis[durum],"INCELEME")
A7: Eksik belge | B7: =COUNTIFS(tblAkis[durum],"EKSIK",tblAkis[tutar],">0") | C7: =SUMIFS(tblAkis[tutar],tblAkis[durum],"EKSIK")
A8: Taslak | B8: =COUNTIFS(tblAkis[durum],"TASLAK",tblAkis[tutar],">0") | C8: =SUMIFS(tblAkis[tutar],tblAkis[durum],"TASLAK")
A9: Geciken (açık, yaş>eşik) | B9: =COUNTIFS(tblAkis[YasGun],">"&ytk_esikGecikmeGun,tblAkis[Durum],"<>TASDIK",tblAkis[Durum],"<>DURDUR",tblAkis[Tutar],">0") | C9: =SUMIFS(tblAkis[Tutar],tblAkis[YasGun],">"&ytk_esikGecikmeGun,tblAkis[Durum],"<>TASDIK",tblAkis[Durum],"<>DURDUR")
A11: Kapalı (Tasdik+Durdur) — kuyruktan düşer
A12: Tasdik | B12: =COUNTIFS(tblAkis[durum],"TASDIK",tblAkis[tutar],">0") | C12: =SUMIFS(tblAkis[tutar],tblAkis[durum],"TASDIK")
A13: Durdur | B13: =COUNTIFS(tblAkis[durum],"DURDUR",tblAkis[tutar],">0") | C13: =SUMIFS(tblAkis[tutar],tblAkis[durum],"DURDUR")
A15: Eksik Belge Kuyruğu | B15: =ytk_eksikKuyruk
A17: Yaş Kova Dağılımı
A18: 0-7 | B18: =COUNTIF(tblAkis[YasKova],"0-7") | C18: =SUMIF(tblAkis[YasKova],"0-7",tblAkis[Tutar])
A19: 8-30 | B19: =COUNTIF(tblAkis[YasKova],"8-30") | C19: =SUMIF(tblAkis[YasKova],"8-30",tblAkis[Tutar])
A20: 31-60 | B20: =COUNTIF(tblAkis[YasKova],"31-60") | C20: =SUMIF(tblAkis[YasKova],"31-60",tblAkis[Tutar])
A21: 60+ | B21: =COUNTIF(tblAkis[YasKova],"60+") | C21: =SUMIF(tblAkis[YasKova],"60+",tblAkis[Tutar])

Sheet KONTROL_LISTE
A1: KONTROL LISTE — YMM Tasdik Kontrol Robotu
A3: YMM tasdik kontrol listesi — zorunluluk, eksik bayrağı, yaşlandırma
A4: Eksik Adet | B4: =COUNTIF(tblKontrol[BelgeDurum],"YOK") | C4: Kritik Eksik | D4: =COUNTIFS(tblKontrol[BelgeDurum],"YOK",tblKontrol[Zorunluluk],"KRITIK") | E4: Eksik Kuyruk Özeti | F4: =ytk_eksikKuyruk | H4: Yaş Kova (eksik)
A5: KontrolId | B5: KaynakKartId | C5: BelgeAdi | D5: Zorunluluk | E5: BelgeDurum | F5: Tarih | G5: Not | H5: 0-7 | I5: =COUNTIFS(tblKontrol[YasKova],"0-7",tblKontrol[BelgeDurum],"YOK") | J5: YetimBayrak | K5: EksikBayrak | L5: KayitDolu
A6: KNT-00001 | B6: MUK-00001 | C6: Başvuru dilekçesi | D6: KRITIK | E6: YOK | F6: 46241 | G6: Kontrol satırı 1 | H6: =IF($A6="","",IF($F6="","",raporTarihi-$F6)) | I6: =IF($A6="","",IF($H6="","",IF($H6<=7,"0-7",IF($H6<=30,"8-30",IF($H6<=60,"31-60","60+"))))) | J6: =IF($A6="","",IF($B6="","YETİM",IF(COUNTIF(tblKartlar[KartId],$B6)=0,"YETİM",""))) | K6: =IF($A6="","",IF($E6="YOK",IF($D6="KRITIK","KRİTİK EKSİK","EKSİK"),"TAM")) | L6: =IF($A6="","",1)
A7: KNT-00002 | B7: MUK-00001 | C7: Vergi levhası | D7: KRITIK | E7: YOK | F7: 46239 | G7: Kontrol satırı 2 | H7: =IF($A7="","",IF($F7="","",raporTarihi-$F7)) | I7: =IF($A7="","",IF($H7="","",IF($H7<=7,"0-7",IF($H7<=30,"8-30",IF($H7<=60,"31-60","60+"))))) | J7: =IF($A7="","",IF($B7="","YETİM",IF(COUNTIF(tblKartlar[KartId],$B7)=0,"YETİM",""))) | K7: =IF($A7="","",IF($E7="YOK",IF($D7="KRITIK","KRİTİK EKSİK","EKSİK"),"TAM")) | L7: =IF($A7="","",1)
A8: KNT-00003 | B8: MUK-00001 | C8: Faaliyet belgesi | D8: ZORUNLU | E8: VAR | F8: 46237 | G8: Kontrol satırı 3 | H8: =IF($A8="","",IF($F8="","",raporTarihi-$F8)) | I8: =IF($A8="","",IF($H8="","",IF($H8<=7,"0-7",IF($H8<=30,"8-30",IF($H8<=60,"31-60","60+"))))) | J8: =IF($A8="","",IF($B8="","YETİM",IF(COUNTIF(tblKartlar[KartId],$B8)=0,"YETİM",""))) | K8: =IF($A8="","",IF($E8="YOK",IF($D8="KRITIK","KRİTİK EKSİK","EKSİK"),"TAM")) | L8: =IF($A8="","",1)
A9: KNT-00004 | B9: MUK-00002 | C9: Başvuru dilekçesi | D9: KRITIK | E9: VAR | F9: 46235 | G9: Kontrol satırı 4 | H9: =IF($A9="","",IF($F9="","",raporTarihi-$F9)) | I9: =IF($A9="","",IF($H9="","",IF($H9<=7,"0-7",IF($H9<=30,"8-30",IF($H9<=60,"31-60","60+"))))) | J9: =IF($A9="","",IF($B9="","YETİM",IF(COUNTIF(tblKartlar[KartId],$B9)=0,"YETİM",""))) | K9: =IF($A9="","",IF($E9="YOK",IF($D9="KRITIK","KRİTİK EKSİK","EKSİK"),"TAM")) | L9: =IF($A9="","",1)
A10: KNT-00005 | B10: MUK-00002 | C10: Vergi levhası | D10: ZORUNLU | E10: YOK | F10: 46233 | G10: Kontrol satırı 5 | H10: =IF($A10="","",IF($F10="","",raporTarihi-$F10)) | I10: =IF($A10="","",IF($H10="","",IF($H10<=7,"0-7",IF($H10<=30,"8-30",IF($H10<=60,"31-60","60+"))))) | J10: =IF($A10="","",IF($B10="","YETİM",IF(COUNTIF(tblKartlar[KartId],$B10)=0,"YETİM",""))) | K10: =IF($A10="","",IF($E10="YOK",IF($D10="KRITIK","KRİTİK EKSİK","EKSİK"),"TAM")) | L10: =IF($A10="","",1)
A11: KNT-00006 | B11: MUK-00002 | C11: Faaliyet belgesi | D11: ZORUNLU | E11: VAR | F11: 46231 | G11: Kontrol satırı 6 | H11: =IF($A11="","",IF($F11="","",raporTarihi-$F11)) | I11: =IF($A11="","",IF($H11="","",IF($H11<=7,"0-7",IF($H11<=30,"8-30",IF($H11<=60,"31-60","60+"))))) | J11: =IF($A11="","",IF($B11="","YETİM",IF(COUNTIF(tblKartlar[KartId],$B11)=0,"YETİM",""))) | K11: =IF($A11="","",IF($E11="YOK",IF($D11="KRITIK","KRİTİK EKSİK","EKSİK"),"TAM")) | L11: =IF($A11="","",1)
A12: KNT-00007 | B12: MUK-00003 | C12: Başvuru dilekçesi | D12: KRITIK | E12: VAR | F12: 46229 | G12: Kontrol satırı 7 | H12: =IF($A12="","",IF($F12="","",raporTarihi-$F12)) | I12: =IF($A12="","",IF($H12="","",IF($H12<=7,"0-7",IF($H12<=30,"8-30",IF($H12<=60,"31-60","60+"))))) | J12: =IF($A12="","",IF($B12="","YETİM",IF(COUNTIF(tblKartlar[KartId],$B12)=0,"YETİM",""))) | K12: =IF($A12="","",IF($E12="YOK",IF($D12="KRITIK","KRİTİK EKSİK","EKSİK"),"TAM")) | L12: =IF($A12="","",1)
A13: KNT-00008 | B13: MUK-00003 | C13: Vergi levhası | D13: ZORUNLU | E13: VAR | F13: 46227 | G13: Kontrol satırı 8 | H13: =IF($A13="","",IF($F13="","",raporTarihi-$F13)) | I13: =IF($A13="","",IF($H13="","",IF($H13<=7,"0-7",IF($H13<=30,"8-30",IF($H13<=60,"31-60","60+"))))) | J13: =IF($A13="","",IF($B13="","YETİM",IF(COUNTIF(tblKartlar[KartId],$B13)=0,"YETİM",""))) | K13: =IF($A13="","",IF($E13="YOK",IF($D13="KRITIK","KRİTİK EKSİK","EKSİK"),"TAM")) | L13: =IF($A13="","",1)
A14: KNT-00009 | B14: MUK-00003 | C14: Faaliyet belgesi | D14: ZORUNLU | E14: YOK | F14: 46225 | G14: Kontrol satırı 9 | H14: =IF($A14="","",IF($F14="","",raporTarihi-$F14)) | I14: =IF($A14="","",IF($H14="","",IF($H14<=7,"0-7",IF($H14<=30,"8-30",IF($H14<=60,"31-60","60+"))))) | J14: =IF($A14="","",IF($B14="","YETİM",IF(COUNTIF(tblKartlar[KartId],$B14)=0,"YETİM",""))) | K14: =IF($A14="","",IF($E14="YOK",IF($D14="KRITIK","KRİTİK EKSİK","EKSİK"),"TAM")) | L14: =IF($A14="","",1)
A15: KNT-00010 | B15: MUK-00004 | C15: Başvuru dilekçesi | D15: KRITIK | E15: VAR | F15: 46223 | G15: Kontrol satırı 10 | H15: =IF($A15="","",IF($F15="","",raporTarihi-$F15)) | I15: =IF($A15="","",IF($H15="","",IF($H15<=7,"0-7",IF($H15<=30,"8-30",IF($H15<=60,"31-60","60+"))))) | J15: =IF($A15="","",IF($B15="","YETİM",IF(COUNTIF(tblKartlar[KartId],$B15)=0,"YETİM",""))) | K15: =IF($A15="","",IF($E15="YOK",IF($D15="KRITIK","KRİTİK EKSİK","EKSİK"),"TAM")) | L15: =IF($A15="","",1)
A16: KNT-00011 | B16: MUK-00004 | C16: Vergi levhası | D16: ZORUNLU | E16: VAR | F16: 46221 | G16: Kontrol satırı 11 | H16: =IF($A16="","",IF($F16="","",raporTarihi-$F16)) | I16: =IF($A16="","",IF($H16="","",IF($H16<=7,"0-7",IF($H16<=30,"8-30",IF($H16<=60,"31-60","60+"))))) | J16: =IF($A16="","",IF($B16="","YETİM",IF(COUNTIF(tblKartlar[KartId],$B16)=0,"YETİM",""))) | K16: =IF($A16="","",IF($E16="YOK",IF($D16="KRITIK","KRİTİK EKSİK","EKSİK"),"TAM")) | L16: =IF($A16="","",1)
A17: KNT-00012 | B17: MUK-00004 | C17: Faaliyet belgesi | D17: ZORUNLU | E17: VAR | F17: 46219 | G17: Kontrol satırı 12 | H17: =IF($A17="","",IF($F17="","",raporTarihi-$F17)) | I17: =IF($A17="","",IF($H17="","",IF($H17<=7,"0-7",IF($H17<=30,"8-30",IF($H17<=60,"31-60","60+"))))) | J17: =IF($A17="","",IF($B17="","YETİM",IF(COUNTIF(tblKartlar[KartId],$B17)=0,"YETİM",""))) | K17: =IF($A17="","",IF($E17="YOK",IF($D17="KRITIK","KRİTİK EKSİK","EKSİK"),"TAM")) | L17: =IF($A17="","",1)
... A29: KNT-00024 | B29: MUK-00008 | C29: Faaliyet belgesi | D29: ZORUNLU | E29: VAR | F29: 46195 | G29: Kontrol satırı 24 | H29: =IF($A29="","",IF($F29="","",raporTarihi-$F29)) | I29: =IF($A29="","",IF($H29="","",IF($H29<=7,"0-7",IF($H29<=30,"8-30",IF($H29<=60,"31-60","60+"))))) | J29: =IF($A29="","",IF($B29="","YETİM",IF(COUNTIF(tblKartlar[KartId],$B29)=0,"YETİM",""))) | K29: =IF($A29="","",IF($E29="YOK",IF($D29="KRITIK","KRİTİK EKSİK","EKSİK"),"TAM")) | L29: =IF($A29="","",1)
H30: =IF($A30="","",IF($F30="","",raporTarihi-$F30)) | I30: =IF($A30="","",IF($H30="","",IF($H30<=7,"0-7",IF($H30<=30,"8-30",IF($H30<=60,"31-60","60+"))))) | J30: =IF($A30="","",IF($B30="","YETİM",IF(COUNTIF(tblKartlar[KartId],$B30)=0,"YETİM",""))) | K30: =IF($A30="","",IF($E30="YOK",IF($D30="KRITIK","KRİTİK EKSİK","EKSİK"),"TAM")) | L30: =IF($A30="","",1)
