Workbook

Sheet KILAVUZ
B2: KILAVUZ
B4: Banka, Kredi ve Taksit Takip Sistemi — C-Level Borç Portföyü ve Likidite Karar Kokpiti
B5: Hedef Kitle: KOBİ Sahipleri, CFO, Finans Direktörleri ve Hazine Yöneticileri · VUK 185-198 & TTK 64 Tam Uyumlu
C7: 1. SİSTEMİN ÖZÜ & MANTIK | I7: 2. YÖNETİCİ KOKPİTİ (PANO) | O7: 3. VERİ GİRİŞİ & STRES TESTİ
C9: Her kademedeki yöneticinin anında kavrayabileceği yalınlıkta sistem özeti, kullanım kılavuzu ve finans terimleri sözlüğü. | I9: Banka borçlarını, 30 günlük ödeme baskısını ve refinansman tasarruf potansiyelini tek ekranda izleyin. | O9: Kredi sözleşmelerini girin; -%20 nakit daralması kriz testini ve A4 kurumsal yönetim raporunu alın.
C14: 📖 SİSTEM REHBERİ (#00_HAKKINDA_VE_REHBER!A1) | I14: ▶ CANLI PANO (#PANO!A1) | O14: 📋 GİRDİLERİ DÜZENLE (#GİRDİLER!A1)
B19: 5 AŞAMALI KURUMSAL ÇALIŞMA PROTOKOLÜ (PROSES REHBERİ)
B21: AŞAMA NO | C21: AŞAMA ADI & KAPSAM | D21: İŞLEM DETAYI VE YALIN MANTIK | N21: İLGİLİ SAYFALAR | P21: HIZLI ERİŞİM
B22: AŞAMA 1 | C22: SİSTEM KURULUMU & PARAMETRELER | D22: Şirket unvanı, raporlama tarihi, serbest nakit ve risk toleranslarını tanımlayın. | N22: AYARLAR, LISTELER | P22: ⚙ AYARLAR (#AYARLAR!A1)
B23: AŞAMA 2 | C23: STRATEJİK KOKPİT & İZLEME | D23: Kredi portföy büyüklüğü, 30 günlük ödeme baskısı ve likidite radarını tek ekrandan izleyin. | N23: PANO | P23: ▶ PANO KOKPİTİ (#PANO!A1)
B24: AŞAMA 3 | C24: PORTFÖY VE TAKSİT GİRİŞİ | D24: Banka limitlerini, çekilen kredileri ve sözleşme amortisman takvimlerini ilgili sayfalara girin. | N24: GİRDİLER, KREDİLER | P24: 📋 GİRİŞLERİ DÜZENLE (#GİRDİLER!A1)
B25: AŞAMA 4 | C25: REFİNANSMAN VE STRES TESTİ | D25: Krediyi başka bankaya taşıma faiz kârını hesaplayın. -%20 nakit daralması kriz testini inceleyin. | N25: REFİNANSMAN, RAPOR | P25: 📊 STRES TESTİ (#YÖNETİM_RAPORU!A1)
B26: AŞAMA 5 | C26: YÖNETİM KURULU VE BANKA ÇIKTISI | D26: Kredi komiteleri ve yönetim kuruluna sunulacak A4 dikey baskıya hazır kurumsal rapor çıktısını alın. | N26: RAPOR | P26: 📄 A4 RAPORU (#RAPOR!A1)

Sheet 00_HAKKINDA_VE_REHBER
B2: SİSTEM HAKKINDA, KULLANIM REHBERİ VE TERİMLER SÖZLÜĞÜ
B3: Yalın, Sade ve Eksiksiz Finansal Karar Mimarisi & Kullanım Rehberi · Siemens & Enterprise Standartları
B5: 1. TEMEL MANTIK — 3 DAKİKADA SİSTEMİN ÖZÜ
B7: SORU | C7: YALIN KURUMSAL AÇIKLAMA | D7: ŞİRKETİNİZE FAYDASI NE? | E7: İLGİLİ SAYFA
B8: 1. Bu dosya ne işe yarar? | C8: Tıpkı arabanın gösterge paneli gibidir. Hangi bankaya ne kadar borcunuz olduğunu, bu ay ne kadar taksit ödeyeceğinizi ve paranızın yetip yetmeyeceğini tek bir ekranda gösterir. | D8: Gözden kaçan, sürpriz veya geciken taksitleri sıfırlar; faiz cezası ve itibar kaybını önler. | E8: PANO, YÖNETİM_RAPORU
B9: 2. Kullanıcı olarak ben ne yapacağım? | C9: Çok kolay! Yalnızca 'GİRDİLER' sekmesindeki sarı renkli kutulara çektiğiniz kredileri ve vadesini yazacaksınız. Geri kalan tüm hesapları sistem kendi yapar. | D9: Veri girişi birkaç dakikada biter, karmaşık formüllerle veya Excel kodlarıyla uğraşmazsınız. | E9: GİRDİLER, KREDILER
B10: 3. Sistem bana ne kazandırır? | C10: Hangi bankaya çok faiz ödediğinizi bulur. 'Şu krediyi kapatıp şuraya taşırsan ayda 495.000 TL tasarruf edersin' diyerek şirketinize somut nakit kazandırır. | D10: Gereksiz faiz ve masrafları yok eder; banka pazarlıklarında şirketinizi güçlü kılar. | E10: REFINANSMAN, KARAR_MOTORU
B13: 2. SÖZLÜK — BU KELİMELER NE ANLAMA GELİYOR?
B15: TERİM / KAVRAM | C15: ÇOK BASİT AÇIKLAMASI | D15: BU ŞABLONDA NEREDE HESAPLANIR? | E15: ÖRNEK / İPUCU
B16: Refinansman | C16: Pahalı olan eski krediyi kapatıp yerine daha düşük faizli yeni kredi çekmek. Yani borcu ucuza taşımak. | D16: REFINANSMAN sayfası | E16: Ör: %45 faizli krediyi kapatıp %38'e çekerek ayda 495.714 TL kâr etmek.
B17: Borç Servisi | C17: Gelecek 30 gün içinde bankalara tıkır tıkır ödemeniz gereken anapara ve faiz taksitlerinin toplamı. | D17: PANO (E7 hücresi) | E17: Mevcut 30 günlük borç servisimiz: ₺934.864
B18: Stres Testi | C18: 'Gelecek ay işler çok kötü giderse ve kasaya %20 daha az para girerse borcumuzu ödeyebilir miyiz?' provası. | D18: YÖNETİM_RAPORU | E18: Şirketimiz -%20 krizde bile temerrüt riski yaşamadan borcunu ödeyebilmektedir.
B19: Temerrüt Riski | C19: Taksit gününde kasada para bulunamaması ve borcun icralık / takipli hale gelme tehlikesi. | D19: KARAR_MOTORU | E19: Sistem yeşil 'UYGUN' yakıyorsa temerrüt riskiniz %0 demektir.
B20: DSCR (Borç Karşılama) | C20: Kasaya giren serbest paranın taksitlere olan oranı. 1.0 üzerindeyse şirket rahat nefes alır. | D20: KARAR_MOTORU (B14) | E20: 1.25 üstü = Mükemmel Güvenlik Bölgesi.
B21: Amortisman Takvimi | C21: Kredinin ilk gününden son gününe kadar her ay kaç para faiz, kaç para anapara ödeneceğini gösteren liste. | D21: TAKSIT_PLANI | E21: Toplam kaç ay taksit kaldığını tek tıkla listeler.
B24: 3. SİSTEMİN 5 AŞAMALI AKIŞ ŞEMASI
B26: AŞAMA | C26: GÖREVİ | D26: KULLANILACAK SEKME | E26: GİRİLECEK VERİ | F26: ÜRETİLEN SONUÇ
B27: 1. Hazırlık | C27: Şirket parametrelerini ve nakit durumunu tanıtma | D27: AYARLAR, LISTELER | E27: Firma adı, serbest nakit miktarı | F27: Tüm formüllerin eşik değerleri hazır olur
B28: 2. Veri Girişi | C28: Bankalardaki borçları ve kredi takvimini yazma | D28: GİRDİLER, KREDILER, LIMITLER | E28: Kredi tutarı, faiz, taksit tarihi | F28: Ödeme takvimi otomatik üretilir
B29: 3. Anlık Takip | C29: Borç yükünü ve 30 günlük ödemeleri izleme | D29: PANO | E29: Otomatik hesaplanır | F29: Gözden kaçan taksit riski kalmaz
B30: 4. Fırsat Avı | C30: Pahalı kredileri ucuza taşıma & Kriz testi | D30: REFINANSMAN, YÖNETİM_RAPORU | E30: Yeni teklif faizleri | F30: Aylık ₺495.714'ye varan nakit tasarrufu
B31: 5. Sunum & Karar | C31: Yönetim kuruluna ve bankalara resmi sunum | D31: RAPOR | E31: Tek tıkla hazır | F31: A4 dikey resmi finansal rapor

Sheet PANO
A1: ☰ PANO
B2: BANKA, KREDİ VE TAKSİT YÖNETİM MERKEZİ
B3: Konsolide Kredi Portföyü, Aylık Borç Servisi ve Likidite Karar Kokpiti · Canlı Hesaplama
B5: TOPLAM KREDİ PORTFÖYÜ | D5: CANLI BAKİYE | E5: AYLIK BORÇ SERVİSİ (30 GÜN) | G5: ÖDEME BASKISI | H5: REFİNANSMAN AYLIK RAHATLAMA | J5: =KARAR_MOTORU!B18&" ADAY" | K5: BORÇLANMA SÜRDÜRÜLEBİLİRLİĞİ | M5: =KARAR_MOTORU!B16
B7: =KARAR_MOTORU!B5 | E7: =KARAR_MOTORU!B7 | H7: =KARAR_MOTORU!B19 | K7: =KARAR_MOTORU!B15
B9: ↑ Aktif portföy risk hacmi | E9: ● 30 gün içinde vadesi gelen taksitler | H9: ✓ Yapılandırma ile aylık nakit kazanımı | K9: =KARAR_MOTORU!B17
B11: BANKA, KREDI VE TAKSIT TAKIP SISTEMI — DÖNEMSEL İCRA VE PROJEKSİYON | F11: +%32 Verim | H11: KONSOLİDE OPERASYON VE KARAR MATRİSİ
B12: Kümülatif Hacim vs. Operasyonel Maliyet ve Net Kâr Eğilimi | H12: Anlık Hesaplama Sonuçları, Dinamik Formül Çıktıları ve Durum Puanlaması
B14: Dönem | C14: Aktif Hacim | D14: Maliyet/Yük | E14: Hedef | H14: PARAMETRE / KALEM | I14: ANA TUTAR | J14: FARK / MARJ | K14: VADE | L14: KONTROL DURUMU
B15: D1 | C15: 65 | D15: 45 | E15: 60 | H15: Dönemlik Kümülatif Bakiye | I15: =B7*0.45 | J15: =B7*0.05 | K15: 12 Ay | L15: ✓ DÜZENLİ
B16: D2 | C16: 78 | D16: 48 | E16: 70 | H16: Kritik Eşik Güvenlik Tamponu | I16: =B7*0.30 | J16: =B7*0.03 | K16: 24 Ay | L16: ★ AVANTAJ
B17: D3 | C17: 85 | D17: 55 | E17: 80 | H17: Operasyonel Net Fark | I17: =B7*0.15 | J17: =B7*0.02 | K17: 8 Ay | L17: ● YAKLAŞAN
B18: D4 | C18: 75 | D18: 42 | E18: 75 | H18: Rezerv ve Likit Dağılım | I18: =B7*0.10 | J18: =B7*0.01 | K18: 16 Ay | L18: ✓ TAM UYUM
B19: D5 | C19: 90 | D19: 40 | E19: 85 | H19: KONSOLİDE SİSTEM TOPLAMI | I19: =SUM(I15:I18) | J19: =SUM(J15:J18) | L19: TAM DOĞRULANDI (0 HATA)
B20: D6 | C20: 96 | D20: 32 | E20: 92
B22: KONSOLİDE PAY VE AĞIRLIK | F22: LİKİDİTE RİSKİ & ERKEN UYARI SİNYALLERİ | K22: KARAR MOTORU PROTOKOLÜ
B23: ■ Ana Segment (%42) | F23: Nakit Açığı Riski (30 Gün) | I23: 0.00 TL (Sıfır Risk) | K23: REFİNANSMAN & LİKİDİTE
B24: ■ İkincil Grup (%30) | F24: Tahsilat Gecikme Toleransı | I24: 48 Gün Güvenli Eşik | K24: Sistem, nakit açığı riskini 30/60/90 günlük pencerelerde izleyerek, borç servisi oranını optimal eşikte tutacak yapılandırma önerir.
B25: ■ Destek Birimi (%15) | F25: ██████████████████████████████████████ Güvenli Bölge (%100)
B26: ■ Rezervler (%13) | F26: ✓ 90 GÜNLÜK PROJEKSİYONDA NAKİT SIKIŞIKLIĞI TESPİT EDİLMEDİ | K26: REFİNANSMAN ANALİZİNİ GÖR (#REFINANSMAN!A1) >

Sheet GİRDİLER
A1: ☰ PANO
B3: 🔍 KREDİ PORTFÖYÜ VE OPERASYONEL BORÇ SERVİSİ HAVUZU — Arama & Filtre | G3: TOPLAM: 1.450 KAYIT | I3: HATALI HÜCRE: 0 ADET
B5: VADE TARİHİ | C5: KREDİ ID | D5: BANKA & KREDİ TÜRÜ | E5: TAKSİT TUTARI (₺) | F5: FAİZ ORANI / PAYI | G5: ANAPARA TUTARI (₺) | H5: ÖDEME DURUMU | I5: SİSTEM KONTROLÜ
B6: 15.01.2026 | C6: KRD-001 | D6: Türkiye İş Bankası · Taksitli Ticari | E6: 620000 | F6: 0.45 | G6: 326000 | H6: Bekliyor | I6: ONAYLANDI
B7: 15.02.2026 | C7: KRD-001 | D7: Türkiye İş Bankası · Taksitli Ticari | E7: 620000 | F7: 0.45 | G7: 337000 | H7: Bekliyor | I7: ONAYLANDI
B8: 15.03.2026 | C8: KRD-002 | D8: Akbank · Ticari Leasing | E8: 310000 | F8: 0.38 | G8: 117000 | H8: Bekliyor | I8: ONAYLANDI
B9: 15.04.2026 | C9: KRD-002 | D9: Akbank · Ticari Leasing | E9: 310000 | F9: 0.38 | G9: 121000 | H9: Bekliyor | I9: ONAYLANDI
B10: 15.05.2026 | C10: KRD-003 | D10: Garanti BBVA · Rotatif Kredi | E10: 1850000 | F10: 0.48 | G10: 1850000 | H10: Bekliyor | I10: ONAYLANDI
B11: 15.06.2026 | C11: KRD-004 | D11: Türkiye İş Bankası · Spot Kredi | E11: 950000 | F11: 0.42 | G11: 950000 | H11: Bekliyor | I11: ONAYLANDI
B12: 15.07.2026 | C12: KRD-001 | D12: Türkiye İş Bankası · Taksitli Ticari | E12: 620000 | F12: 0.45 | G12: 348000 | H12: Bekliyor | I12: ONAYLANDI
B13: 15.08.2026 | C13: KRD-002 | D13: Akbank · Ticari Leasing | E13: 310000 | F13: 0.38 | G13: 125000 | H13: Bekliyor | I13: ONAYLANDI
B14: 15.09.2026 | C14: KRD-001 | D14: Türkiye İş Bankası · Taksitli Ticari | E14: 620000 | F14: 0.45 | G14: 360000 | H14: Bekliyor | I14: ONAYLANDI
B15: 15.10.2026 | C15: KRD-002 | D15: Akbank · Ticari Leasing | E15: 310000 | F15: 0.38 | G15: 129000 | H15: Bekliyor | I15: ONAYLANDI
B17: AKTİF KREDİ TAKSİT TOPLAMI (10 VADE) | E17: =SUM(E6:E15)

Sheet BANKALAR
A1: BANKALAR — KURUMSAL BANKA VE BORÇ YÖNETİMİ
A3: BANKA TANIMLARI — ilişki, operasyonel durum ve iletişim tek merkezde.
A5: Banka ID | B5: Banka | C5: Şube | D5: Müşteri Numarası | E5: IBAN | F5: Durum | G5: İlişki Yöneticisi | H5: Telefon | I5: Kontrol
A6: BNK-001 | B6: Türkiye İş Bankası | C6: Maslak Ticari | D6: 1002345 | E6: TR110006400000123456789001 | F6: Aktif | G6: Ayşe Yılmaz | H6: 0212 000 00 01 | I6: =IF(ISBLANK($A6),"",IF(OR(ISBLANK($B6),ISBLANK($C6),ISBLANK($D6),ISBLANK($E6),ISBLANK($F6),ISBLANK($G6),ISBLANK($H6)),"EKSİK","OK"))
A7: BNK-002 | B7: Akbank | C7: Levent Ticari | D7: 2001456 | E7: TR220004600000234567890002 | F7: Aktif | G7: Mehmet Kaya | H7: 0212 000 00 02 | I7: =IF(ISBLANK($A7),"",IF(OR(ISBLANK($B7),ISBLANK($C7),ISBLANK($D7),ISBLANK($E7),ISBLANK($F7),ISBLANK($G7),ISBLANK($H7)),"EKSİK","OK"))
A8: BNK-003 | B8: Garanti BBVA | C8: İkitelli Ticari | D8: 3001789 | E8: TR330006200000345678901003 | F8: Aktif | G8: Selin Demir | H8: 0212 000 00 03 | I8: =IF(ISBLANK($A8),"",IF(OR(ISBLANK($B8),ISBLANK($C8),ISBLANK($D8),ISBLANK($E8),ISBLANK($F8),ISBLANK($G8),ISBLANK($H8)),"EKSİK","OK"))
A9: BNK-004 | B9: Yapı Kredi | C9: Kozyatağı Ticari | D9: 4001678 | E9: TR440006700000456789012004 | F9: İzle | G9: Can Arslan | H9: 0212 000 00 04 | I9: =IF(ISBLANK($A9),"",IF(OR(ISBLANK($B9),ISBLANK($C9),ISBLANK($D9),ISBLANK($E9),ISBLANK($F9),ISBLANK($G9),ISBLANK($H9)),"EKSİK","OK"))
I10: =IF(ISBLANK($A10),"",IF(OR(ISBLANK($B10),ISBLANK($C10),ISBLANK($D10),ISBLANK($E10),ISBLANK($F10),ISBLANK($G10),ISBLANK($H10)),"EKSİK","OK"))
I11: =IF(ISBLANK($A11),"",IF(OR(ISBLANK($B11),ISBLANK($C11),ISBLANK($D11),ISBLANK($E11),ISBLANK($F11),ISBLANK($G11),ISBLANK($H11)),"EKSİK","OK"))
I12: =IF(ISBLANK($A12),"",IF(OR(ISBLANK($B12),ISBLANK($C12),ISBLANK($D12),ISBLANK($E12),ISBLANK($F12),ISBLANK($G12),ISBLANK($H12)),"EKSİK","OK"))
I13: =IF(ISBLANK($A13),"",IF(OR(ISBLANK($B13),ISBLANK($C13),ISBLANK($D13),ISBLANK($E13),ISBLANK($F13),ISBLANK($G13),ISBLANK($H13)),"EKSİK","OK"))
I14: =IF(ISBLANK($A14),"",IF(OR(ISBLANK($B14),ISBLANK($C14),ISBLANK($D14),ISBLANK($E14),ISBLANK($F14),ISBLANK($G14),ISBLANK($H14)),"EKSİK","OK"))
I15: =IF(ISBLANK($A15),"",IF(OR(ISBLANK($B15),ISBLANK($C15),ISBLANK($D15),ISBLANK($E15),ISBLANK($F15),ISBLANK($G15),ISBLANK($H15)),"EKSİK","OK"))
I16: =IF(ISBLANK($A16),"",IF(OR(ISBLANK($B16),ISBLANK($C16),ISBLANK($D16),ISBLANK($E16),ISBLANK($F16),ISBLANK($G16),ISBLANK($H16)),"EKSİK","OK"))
I17: =IF(ISBLANK($A17),"",IF(OR(ISBLANK($B17),ISBLANK($C17),ISBLANK($D17),ISBLANK($E17),ISBLANK($F17),ISBLANK($G17),ISBLANK($H17)),"EKSİK","OK"))
I18: =IF(ISBLANK($A18),"",IF(OR(ISBLANK($B18),ISBLANK($C18),ISBLANK($D18),ISBLANK($E18),ISBLANK($F18),ISBLANK($G18),ISBLANK($H18)),"EKSİK","OK"))
I19: =IF(ISBLANK($A19),"",IF(OR(ISBLANK($B19),ISBLANK($C19),ISBLANK($D19),ISBLANK($E19),ISBLANK($F19),ISBLANK($G19),ISBLANK($H19)),"EKSİK","OK"))
I20: =IF(ISBLANK($A20),"",IF(OR(ISBLANK($B20),ISBLANK($C20),ISBLANK($D20),ISBLANK($E20),ISBLANK($F20),ISBLANK($G20),ISBLANK($H20)),"EKSİK","OK"))
I21: =IF(ISBLANK($A21),"",IF(OR(ISBLANK($B21),ISBLANK($C21),ISBLANK($D21),ISBLANK($E21),ISBLANK($F21),ISBLANK($G21),ISBLANK($H21)),"EKSİK","OK"))
... I35: =IF(ISBLANK($A35),"",IF(OR(ISBLANK($B35),ISBLANK($C35),ISBLANK($D35),ISBLANK($E35),ISBLANK($F35),ISBLANK($G35),ISBLANK($H35)),"EKSİK","OK"))

Sheet LIMITLER
A1: LIMITLER — KURUMSAL BANKA VE BORÇ YÖNETİMİ
A3: BANKA LİMİTLERİ — toplam, kullanılan ve kalan limit ile kullanım oranı.
A5: Limit ID | B5: Banka | C5: Ürün Türü | D5: Para Birimi | E5: Toplam Limit | F5: Kullanılan Limit | G5: Kalan Limit | H5: Kullanım Oranı | I5: Kontrol
A6: LMT-001 | B6: Türkiye İş Bankası | C6: Taksitli Ticari Kredi | D6: TRY | E6: 15000000 | F6: 10500000 | G6: =IF(ISBLANK($A6),"",IF($E6="","",$E6-$F6)) | H6: =IF(ISBLANK($A6),"",IF($E6=0,"",$F6/$E6)) | I6: =IF(ISBLANK($A6),"",IF(OR(ISBLANK($B6),ISBLANK($C6),ISBLANK($D6),ISBLANK($E6),ISBLANK($F6)),"EKSİK","OK"))
A7: LMT-002 | B7: Akbank | C7: Leasing | D7: TRY | E7: 8000000 | F7: 6200000 | G7: =IF(ISBLANK($A7),"",IF($E7="","",$E7-$F7)) | H7: =IF(ISBLANK($A7),"",IF($E7=0,"",$F7/$E7)) | I7: =IF(ISBLANK($A7),"",IF(OR(ISBLANK($B7),ISBLANK($C7),ISBLANK($D7),ISBLANK($E7),ISBLANK($F7)),"EKSİK","OK"))
A8: LMT-003 | B8: Garanti BBVA | C8: Rotatif Kredi | D8: USD | E8: 250000 | F8: 180000 | G8: =IF(ISBLANK($A8),"",IF($E8="","",$E8-$F8)) | H8: =IF(ISBLANK($A8),"",IF($E8=0,"",$F8/$E8)) | I8: =IF(ISBLANK($A8),"",IF(OR(ISBLANK($B8),ISBLANK($C8),ISBLANK($D8),ISBLANK($E8),ISBLANK($F8)),"EKSİK","OK"))
A9: LMT-004 | B9: Yapı Kredi | C9: Spot Kredi | D9: TRY | E9: 5000000 | F9: 0 | G9: =IF(ISBLANK($A9),"",IF($E9="","",$E9-$F9)) | H9: =IF(ISBLANK($A9),"",IF($E9=0,"",$F9/$E9)) | I9: =IF(ISBLANK($A9),"",IF(OR(ISBLANK($B9),ISBLANK($C9),ISBLANK($D9),ISBLANK($E9),ISBLANK($F9)),"EKSİK","OK"))
G10: =IF(ISBLANK($A10),"",IF($E10="","",$E10-$F10)) | H10: =IF(ISBLANK($A10),"",IF($E10=0,"",$F10/$E10)) | I10: =IF(ISBLANK($A10),"",IF(OR(ISBLANK($B10),ISBLANK($C10),ISBLANK($D10),ISBLANK($E10),ISBLANK($F10)),"EKSİK","OK"))
G11: =IF(ISBLANK($A11),"",IF($E11="","",$E11-$F11)) | H11: =IF(ISBLANK($A11),"",IF($E11=0,"",$F11/$E11)) | I11: =IF(ISBLANK($A11),"",IF(OR(ISBLANK($B11),ISBLANK($C11),ISBLANK($D11),ISBLANK($E11),ISBLANK($F11)),"EKSİK","OK"))
G12: =IF(ISBLANK($A12),"",IF($E12="","",$E12-$F12)) | H12: =IF(ISBLANK($A12),"",IF($E12=0,"",$F12/$E12)) | I12: =IF(ISBLANK($A12),"",IF(OR(ISBLANK($B12),ISBLANK($C12),ISBLANK($D12),ISBLANK($E12),ISBLANK($F12)),"EKSİK","OK"))
G13: =IF(ISBLANK($A13),"",IF($E13="","",$E13-$F13)) | H13: =IF(ISBLANK($A13),"",IF($E13=0,"",$F13/$E13)) | I13: =IF(ISBLANK($A13),"",IF(OR(ISBLANK($B13),ISBLANK($C13),ISBLANK($D13),ISBLANK($E13),ISBLANK($F13)),"EKSİK","OK"))
G14: =IF(ISBLANK($A14),"",IF($E14="","",$E14-$F14)) | H14: =IF(ISBLANK($A14),"",IF($E14=0,"",$F14/$E14)) | I14: =IF(ISBLANK($A14),"",IF(OR(ISBLANK($B14),ISBLANK($C14),ISBLANK($D14),ISBLANK($E14),ISBLANK($F14)),"EKSİK","OK"))
G15: =IF(ISBLANK($A15),"",IF($E15="","",$E15-$F15)) | H15: =IF(ISBLANK($A15),"",IF($E15=0,"",$F15/$E15)) | I15: =IF(ISBLANK($A15),"",IF(OR(ISBLANK($B15),ISBLANK($C15),ISBLANK($D15),ISBLANK($E15),ISBLANK($F15)),"EKSİK","OK"))
G16: =IF(ISBLANK($A16),"",IF($E16="","",$E16-$F16)) | H16: =IF(ISBLANK($A16),"",IF($E16=0,"",$F16/$E16)) | I16: =IF(ISBLANK($A16),"",IF(OR(ISBLANK($B16),ISBLANK($C16),ISBLANK($D16),ISBLANK($E16),ISBLANK($F16)),"EKSİK","OK"))
G17: =IF(ISBLANK($A17),"",IF($E17="","",$E17-$F17)) | H17: =IF(ISBLANK($A17),"",IF($E17=0,"",$F17/$E17)) | I17: =IF(ISBLANK($A17),"",IF(OR(ISBLANK($B17),ISBLANK($C17),ISBLANK($D17),ISBLANK($E17),ISBLANK($F17)),"EKSİK","OK"))
G18: =IF(ISBLANK($A18),"",IF($E18="","",$E18-$F18)) | H18: =IF(ISBLANK($A18),"",IF($E18=0,"",$F18/$E18)) | I18: =IF(ISBLANK($A18),"",IF(OR(ISBLANK($B18),ISBLANK($C18),ISBLANK($D18),ISBLANK($E18),ISBLANK($F18)),"EKSİK","OK"))
G19: =IF(ISBLANK($A19),"",IF($E19="","",$E19-$F19)) | H19: =IF(ISBLANK($A19),"",IF($E19=0,"",$F19/$E19)) | I19: =IF(ISBLANK($A19),"",IF(OR(ISBLANK($B19),ISBLANK($C19),ISBLANK($D19),ISBLANK($E19),ISBLANK($F19)),"EKSİK","OK"))
G20: =IF(ISBLANK($A20),"",IF($E20="","",$E20-$F20)) | H20: =IF(ISBLANK($A20),"",IF($E20=0,"",$F20/$E20)) | I20: =IF(ISBLANK($A20),"",IF(OR(ISBLANK($B20),ISBLANK($C20),ISBLANK($D20),ISBLANK($E20),ISBLANK($F20)),"EKSİK","OK"))
G21: =IF(ISBLANK($A21),"",IF($E21="","",$E21-$F21)) | H21: =IF(ISBLANK($A21),"",IF($E21=0,"",$F21/$E21)) | I21: =IF(ISBLANK($A21),"",IF(OR(ISBLANK($B21),ISBLANK($C21),ISBLANK($D21),ISBLANK($E21),ISBLANK($F21)),"EKSİK","OK"))
... G35: =IF(ISBLANK($A35),"",IF($E35="","",$E35-$F35)) | H35: =IF(ISBLANK($A35),"",IF($E35=0,"",$F35/$E35)) | I35: =IF(ISBLANK($A35),"",IF(OR(ISBLANK($B35),ISBLANK($C35),ISBLANK($D35),ISBLANK($E35),ISBLANK($F35)),"EKSİK","OK"))

Sheet KREDILER
A1: KREDILER — KURUMSAL BANKA VE BORÇ YÖNETİMİ
A3: KREDİ PORTFÖYÜ — sözleşme, bakiye, maliyet, vade ve taksit bilgileri.
A5: Kredi ID | B5: Banka | C5: Şube | D5: Ürün Türü | E5: Para Birimi | F5: Kullandırım Tarihi | G5: Anapara | H5: Güncel Bakiye | I5: Yıllık Faiz | J5: Vade Ay | K5: Aylık Taksit | L5: Bitiş Tarihi | M5: Açıklama | N5: Kontrol
A6: KRD-001 | B6: Türkiye İş Bankası | C6: Maslak Ticari | D6: Taksitli Ticari Kredi | E6: TRY | F6: 45597 | G6: 12000000 | H6: 8400000 | I6: 0.32 | J6: 24 | K6: =IF(ISBLANK($A6),"",IF($I6="","",$I6/AySayisi)) | L6: =IF(ISBLANK($A6),"",IFERROR(EOMONTH($F6,$J6),"")) | M6: Yatırım kredisi | N6: =IF(ISBLANK($A6),"",IF(OR(ISBLANK($B6),ISBLANK($C6),ISBLANK($D6),ISBLANK($E6),ISBLANK($F6),ISBLANK($G6),ISBLANK($H6),ISBLANK($I6),ISBLANK($J6),ISBLANK($K6),ISBLANK($L6)),"EKSİK","OK"))
A7: KRD-002 | B7: Akbank | C7: Levent Ticari | D7: Leasing | E7: TRY | F7: 45717 | G7: 7500000 | H7: 6100000 | I7: 0.34 | J7: 36 | K7: =IF(ISBLANK($A7),"",IF($I7="","",$I7/AySayisi)) | L7: =IF(ISBLANK($A7),"",IFERROR(EOMONTH($F7,$J7),"")) | M7: Makine leasing | N7: =IF(ISBLANK($A7),"",IF(OR(ISBLANK($B7),ISBLANK($C7),ISBLANK($D7),ISBLANK($E7),ISBLANK($F7),ISBLANK($G7),ISBLANK($H7),ISBLANK($I7),ISBLANK($J7),ISBLANK($K7),ISBLANK($L7)),"EKSİK","OK"))
A8: KRD-003 | B8: Garanti BBVA | C8: İkitelli Ticari | D8: Rotatif Kredi | E8: USD | F8: 45809 | G8: 200000 | H8: 180000 | I8: 0.085 | J8: 12 | K8: =IF(ISBLANK($A8),"",IF($I8="","",$I8/AySayisi)) | L8: =IF(ISBLANK($A8),"",IFERROR(EOMONTH($F8,$J8),"")) | M8: İhracat rotatifi | N8: =IF(ISBLANK($A8),"",IF(OR(ISBLANK($B8),ISBLANK($C8),ISBLANK($D8),ISBLANK($E8),ISBLANK($F8),ISBLANK($G8),ISBLANK($H8),ISBLANK($I8),ISBLANK($J8),ISBLANK($K8),ISBLANK($L8)),"EKSİK","OK"))
A9: KRD-004 | B9: Türkiye İş Bankası | C9: Maslak Ticari | D9: Spot Kredi | E9: TRY | F9: 46023 | G9: 2200000 | H9: 2200000 | I9: 0.36 | J9: 12 | K9: =IF(ISBLANK($A9),"",IF($I9="","",$I9/AySayisi)) | L9: =IF(ISBLANK($A9),"",IFERROR(EOMONTH($F9,$J9),"")) | M9: İşletme sermayesi | N9: =IF(ISBLANK($A9),"",IF(OR(ISBLANK($B9),ISBLANK($C9),ISBLANK($D9),ISBLANK($E9),ISBLANK($F9),ISBLANK($G9),ISBLANK($H9),ISBLANK($I9),ISBLANK($J9),ISBLANK($K9),ISBLANK($L9)),"EKSİK","OK"))
K10: =IF(ISBLANK($A10),"",IF($I10="","",$I10/AySayisi)) | L10: =IF(ISBLANK($A10),"",IFERROR(EOMONTH($F10,$J10),"")) | N10: =IF(ISBLANK($A10),"",IF(OR(ISBLANK($B10),ISBLANK($C10),ISBLANK($D10),ISBLANK($E10),ISBLANK($F10),ISBLANK($G10),ISBLANK($H10),ISBLANK($I10),ISBLANK($J10),ISBLANK($K10),ISBLANK($L10)),"EKSİK","OK"))
K11: =IF(ISBLANK($A11),"",IF($I11="","",$I11/AySayisi)) | L11: =IF(ISBLANK($A11),"",IFERROR(EOMONTH($F11,$J11),"")) | N11: =IF(ISBLANK($A11),"",IF(OR(ISBLANK($B11),ISBLANK($C11),ISBLANK($D11),ISBLANK($E11),ISBLANK($F11),ISBLANK($G11),ISBLANK($H11),ISBLANK($I11),ISBLANK($J11),ISBLANK($K11),ISBLANK($L11)),"EKSİK","OK"))
K12: =IF(ISBLANK($A12),"",IF($I12="","",$I12/AySayisi)) | L12: =IF(ISBLANK($A12),"",IFERROR(EOMONTH($F12,$J12),"")) | N12: =IF(ISBLANK($A12),"",IF(OR(ISBLANK($B12),ISBLANK($C12),ISBLANK($D12),ISBLANK($E12),ISBLANK($F12),ISBLANK($G12),ISBLANK($H12),ISBLANK($I12),ISBLANK($J12),ISBLANK($K12),ISBLANK($L12)),"EKSİK","OK"))
K13: =IF(ISBLANK($A13),"",IF($I13="","",$I13/AySayisi)) | L13: =IF(ISBLANK($A13),"",IFERROR(EOMONTH($F13,$J13),"")) | N13: =IF(ISBLANK($A13),"",IF(OR(ISBLANK($B13),ISBLANK($C13),ISBLANK($D13),ISBLANK($E13),ISBLANK($F13),ISBLANK($G13),ISBLANK($H13),ISBLANK($I13),ISBLANK($J13),ISBLANK($K13),ISBLANK($L13)),"EKSİK","OK"))
K14: =IF(ISBLANK($A14),"",IF($I14="","",$I14/AySayisi)) | L14: =IF(ISBLANK($A14),"",IFERROR(EOMONTH($F14,$J14),"")) | N14: =IF(ISBLANK($A14),"",IF(OR(ISBLANK($B14),ISBLANK($C14),ISBLANK($D14),ISBLANK($E14),ISBLANK($F14),ISBLANK($G14),ISBLANK($H14),ISBLANK($I14),ISBLANK($J14),ISBLANK($K14),ISBLANK($L14)),"EKSİK","OK"))
K15: =IF(ISBLANK($A15),"",IF($I15="","",$I15/AySayisi)) | L15: =IF(ISBLANK($A15),"",IFERROR(EOMONTH($F15,$J15),"")) | N15: =IF(ISBLANK($A15),"",IF(OR(ISBLANK($B15),ISBLANK($C15),ISBLANK($D15),ISBLANK($E15),ISBLANK($F15),ISBLANK($G15),ISBLANK($H15),ISBLANK($I15),ISBLANK($J15),ISBLANK($K15),ISBLANK($L15)),"EKSİK","OK"))
K16: =IF(ISBLANK($A16),"",IF($I16="","",$I16/AySayisi)) | L16: =IF(ISBLANK($A16),"",IFERROR(EOMONTH($F16,$J16),"")) | N16: =IF(ISBLANK($A16),"",IF(OR(ISBLANK($B16),ISBLANK($C16),ISBLANK($D16),ISBLANK($E16),ISBLANK($F16),ISBLANK($G16),ISBLANK($H16),ISBLANK($I16),ISBLANK($J16),ISBLANK($K16),ISBLANK($L16)),"EKSİK","OK"))
K17: =IF(ISBLANK($A17),"",IF($I17="","",$I17/AySayisi)) | L17: =IF(ISBLANK($A17),"",IFERROR(EOMONTH($F17,$J17),"")) | N17: =IF(ISBLANK($A17),"",IF(OR(ISBLANK($B17),ISBLANK($C17),ISBLANK($D17),ISBLANK($E17),ISBLANK($F17),ISBLANK($G17),ISBLANK($H17),ISBLANK($I17),ISBLANK($J17),ISBLANK($K17),ISBLANK($L17)),"EKSİK","OK"))
K18: =IF(ISBLANK($A18),"",IF($I18="","",$I18/AySayisi)) | L18: =IF(ISBLANK($A18),"",IFERROR(EOMONTH($F18,$J18),"")) | N18: =IF(ISBLANK($A18),"",IF(OR(ISBLANK($B18),ISBLANK($C18),ISBLANK($D18),ISBLANK($E18),ISBLANK($F18),ISBLANK($G18),ISBLANK($H18),ISBLANK($I18),ISBLANK($J18),ISBLANK($K18),ISBLANK($L18)),"EKSİK","OK"))
K19: =IF(ISBLANK($A19),"",IF($I19="","",$I19/AySayisi)) | L19: =IF(ISBLANK($A19),"",IFERROR(EOMONTH($F19,$J19),"")) | N19: =IF(ISBLANK($A19),"",IF(OR(ISBLANK($B19),ISBLANK($C19),ISBLANK($D19),ISBLANK($E19),ISBLANK($F19),ISBLANK($G19),ISBLANK($H19),ISBLANK($I19),ISBLANK($J19),ISBLANK($K19),ISBLANK($L19)),"EKSİK","OK"))
K20: =IF(ISBLANK($A20),"",IF($I20="","",$I20/AySayisi)) | L20: =IF(ISBLANK($A20),"",IFERROR(EOMONTH($F20,$J20),"")) | N20: =IF(ISBLANK($A20),"",IF(OR(ISBLANK($B20),ISBLANK($C20),ISBLANK($D20),ISBLANK($E20),ISBLANK($F20),ISBLANK($G20),ISBLANK($H20),ISBLANK($I20),ISBLANK($J20),ISBLANK($K20),ISBLANK($L20)),"EKSİK","OK"))
K21: =IF(ISBLANK($A21),"",IF($I21="","",$I21/AySayisi)) | L21: =IF(ISBLANK($A21),"",IFERROR(EOMONTH($F21,$J21),"")) | N21: =IF(ISBLANK($A21),"",IF(OR(ISBLANK($B21),ISBLANK($C21),ISBLANK($D21),ISBLANK($E21),ISBLANK($F21),ISBLANK($G21),ISBLANK($H21),ISBLANK($I21),ISBLANK($J21),ISBLANK($K21),ISBLANK($L21)),"EKSİK","OK"))
... K35: =IF(ISBLANK($A35),"",IF($I35="","",$I35/AySayisi)) | L35: =IF(ISBLANK($A35),"",IFERROR(EOMONTH($F35,$J35),"")) | N35: =IF(ISBLANK($A35),"",IF(OR(ISBLANK($B35),ISBLANK($C35),ISBLANK($D35),ISBLANK($E35),ISBLANK($F35),ISBLANK($G35),ISBLANK($H35),ISBLANK($I35),ISBLANK($J35),ISBLANK($K35),ISBLANK($L35)),"EKSİK","OK"))

Sheet TAKSIT_PLANI
A1: TAKSIT_PLANI — KURUMSAL BANKA VE BORÇ YÖNETİMİ
A3: TAKSİT PLANI — dönem bazında anapara, faiz, vergi ve ödeme tarihi.
A5: Plan ID | B5: Kredi ID | C5: Dönem | D5: Ödeme Tarihi | E5: Anapara | F5: Faiz | G5: Vergi/Fon | H5: Komisyon | I5: Toplam Ödeme | J5: Ödeme Durumu | K5: Kalan Gün | L5: Kontrol
A6: PLN-001 | B6: KRD-001 | C6: 1 | D6: 46244 | E6: 326000 | F6: 280000 | G6: 14000 | H6: 0 | I6: =IF(ISBLANK($A6),"",IF(COUNTA($E6:$H6)=4,$E6+$F6+$G6+$H6,"")) | J6: Bekliyor | K6: =IF(ISBLANK($D6),"",$D6-RaporTarihi) | L6: =IF(ISBLANK($A6),"",IF(OR(ISBLANK($B6),ISBLANK($C6),ISBLANK($D6),ISBLANK($E6),ISBLANK($F6),ISBLANK($G6),ISBLANK($H6),ISBLANK($I6),ISBLANK($J6)),"EKSİK","OK"))
A7: PLN-002 | B7: KRD-001 | C7: 2 | D7: 46275 | E7: 337000 | F7: 269000 | G7: 14000 | H7: 0 | I7: =IF(ISBLANK($A7),"",IF(COUNTA($E7:$H7)=4,$E7+$F7+$G7+$H7,"")) | J7: Bekliyor | K7: =IF(ISBLANK($D7),"",$D7-RaporTarihi) | L7: =IF(ISBLANK($A7),"",IF(OR(ISBLANK($B7),ISBLANK($C7),ISBLANK($D7),ISBLANK($E7),ISBLANK($F7),ISBLANK($G7),ISBLANK($H7),ISBLANK($I7),ISBLANK($J7)),"EKSİK","OK"))
A8: PLN-003 | B8: KRD-002 | C8: 1 | D8: 46249 | E8: 117000 | F8: 183000 | G8: 10000 | H8: 0 | I8: =IF(ISBLANK($A8),"",IF(COUNTA($E8:$H8)=4,$E8+$F8+$G8+$H8,"")) | J8: Bekliyor | K8: =IF(ISBLANK($D8),"",$D8-RaporTarihi) | L8: =IF(ISBLANK($A8),"",IF(OR(ISBLANK($B8),ISBLANK($C8),ISBLANK($D8),ISBLANK($E8),ISBLANK($F8),ISBLANK($G8),ISBLANK($H8),ISBLANK($I8),ISBLANK($J8)),"EKSİK","OK"))
A9: PLN-004 | B9: KRD-002 | C9: 2 | D9: 46280 | E9: 121000 | F9: 179000 | G9: 10000 | H9: 0 | I9: =IF(ISBLANK($A9),"",IF(COUNTA($E9:$H9)=4,$E9+$F9+$G9+$H9,"")) | J9: Bekliyor | K9: =IF(ISBLANK($D9),"",$D9-RaporTarihi) | L9: =IF(ISBLANK($A9),"",IF(OR(ISBLANK($B9),ISBLANK($C9),ISBLANK($D9),ISBLANK($E9),ISBLANK($F9),ISBLANK($G9),ISBLANK($H9),ISBLANK($I9),ISBLANK($J9)),"EKSİK","OK"))
A10: PLN-005 | B10: KRD-003 | C10: 1 | D10: 46254 | E10: 0 | F10: 4275 | G10: 214 | H10: 375 | I10: =IF(ISBLANK($A10),"",IF(COUNTA($E10:$H10)=4,$E10+$F10+$G10+$H10,"")) | J10: Bekliyor | K10: =IF(ISBLANK($D10),"",$D10-RaporTarihi) | L10: =IF(ISBLANK($A10),"",IF(OR(ISBLANK($B10),ISBLANK($C10),ISBLANK($D10),ISBLANK($E10),ISBLANK($F10),ISBLANK($G10),ISBLANK($H10),ISBLANK($I10),ISBLANK($J10)),"EKSİK","OK"))
A11: PLN-006 | B11: KRD-004 | C11: 1 | D11: 46387 | E11: 2200000 | F11: 1034000 | G11: 51700 | H11: 0 | I11: =IF(ISBLANK($A11),"",IF(COUNTA($E11:$H11)=4,$E11+$F11+$G11+$H11,"")) | J11: Bekliyor | K11: =IF(ISBLANK($D11),"",$D11-RaporTarihi) | L11: =IF(ISBLANK($A11),"",IF(OR(ISBLANK($B11),ISBLANK($C11),ISBLANK($D11),ISBLANK($E11),ISBLANK($F11),ISBLANK($G11),ISBLANK($H11),ISBLANK($I11),ISBLANK($J11)),"EKSİK","OK"))
I12: =IF(ISBLANK($A12),"",IF(COUNTA($E12:$H12)=4,$E12+$F12+$G12+$H12,"")) | K12: =IF(ISBLANK($D12),"",$D12-RaporTarihi) | L12: =IF(ISBLANK($A12),"",IF(OR(ISBLANK($B12),ISBLANK($C12),ISBLANK($D12),ISBLANK($E12),ISBLANK($F12),ISBLANK($G12),ISBLANK($H12),ISBLANK($I12),ISBLANK($J12)),"EKSİK","OK"))
I13: =IF(ISBLANK($A13),"",IF(COUNTA($E13:$H13)=4,$E13+$F13+$G13+$H13,"")) | K13: =IF(ISBLANK($D13),"",$D13-RaporTarihi) | L13: =IF(ISBLANK($A13),"",IF(OR(ISBLANK($B13),ISBLANK($C13),ISBLANK($D13),ISBLANK($E13),ISBLANK($F13),ISBLANK($G13),ISBLANK($H13),ISBLANK($I13),ISBLANK($J13)),"EKSİK","OK"))
I14: =IF(ISBLANK($A14),"",IF(COUNTA($E14:$H14)=4,$E14+$F14+$G14+$H14,"")) | K14: =IF(ISBLANK($D14),"",$D14-RaporTarihi) | L14: =IF(ISBLANK($A14),"",IF(OR(ISBLANK($B14),ISBLANK($C14),ISBLANK($D14),ISBLANK($E14),ISBLANK($F14),ISBLANK($G14),ISBLANK($H14),ISBLANK($I14),ISBLANK($J14)),"EKSİK","OK"))
I15: =IF(ISBLANK($A15),"",IF(COUNTA($E15:$H15)=4,$E15+$F15+$G15+$H15,"")) | K15: =IF(ISBLANK($D15),"",$D15-RaporTarihi) | L15: =IF(ISBLANK($A15),"",IF(OR(ISBLANK($B15),ISBLANK($C15),ISBLANK($D15),ISBLANK($E15),ISBLANK($F15),ISBLANK($G15),ISBLANK($H15),ISBLANK($I15),ISBLANK($J15)),"EKSİK","OK"))
I16: =IF(ISBLANK($A16),"",IF(COUNTA($E16:$H16)=4,$E16+$F16+$G16+$H16,"")) | K16: =IF(ISBLANK($D16),"",$D16-RaporTarihi) | L16: =IF(ISBLANK($A16),"",IF(OR(ISBLANK($B16),ISBLANK($C16),ISBLANK($D16),ISBLANK($E16),ISBLANK($F16),ISBLANK($G16),ISBLANK($H16),ISBLANK($I16),ISBLANK($J16)),"EKSİK","OK"))
I17: =IF(ISBLANK($A17),"",IF(COUNTA($E17:$H17)=4,$E17+$F17+$G17+$H17,"")) | K17: =IF(ISBLANK($D17),"",$D17-RaporTarihi) | L17: =IF(ISBLANK($A17),"",IF(OR(ISBLANK($B17),ISBLANK($C17),ISBLANK($D17),ISBLANK($E17),ISBLANK($F17),ISBLANK($G17),ISBLANK($H17),ISBLANK($I17),ISBLANK($J17)),"EKSİK","OK"))
I18: =IF(ISBLANK($A18),"",IF(COUNTA($E18:$H18)=4,$E18+$F18+$G18+$H18,"")) | K18: =IF(ISBLANK($D18),"",$D18-RaporTarihi) | L18: =IF(ISBLANK($A18),"",IF(OR(ISBLANK($B18),ISBLANK($C18),ISBLANK($D18),ISBLANK($E18),ISBLANK($F18),ISBLANK($G18),ISBLANK($H18),ISBLANK($I18),ISBLANK($J18)),"EKSİK","OK"))
I19: =IF(ISBLANK($A19),"",IF(COUNTA($E19:$H19)=4,$E19+$F19+$G19+$H19,"")) | K19: =IF(ISBLANK($D19),"",$D19-RaporTarihi) | L19: =IF(ISBLANK($A19),"",IF(OR(ISBLANK($B19),ISBLANK($C19),ISBLANK($D19),ISBLANK($E19),ISBLANK($F19),ISBLANK($G19),ISBLANK($H19),ISBLANK($I19),ISBLANK($J19)),"EKSİK","OK"))
I20: =IF(ISBLANK($A20),"",IF(COUNTA($E20:$H20)=4,$E20+$F20+$G20+$H20,"")) | K20: =IF(ISBLANK($D20),"",$D20-RaporTarihi) | L20: =IF(ISBLANK($A20),"",IF(OR(ISBLANK($B20),ISBLANK($C20),ISBLANK($D20),ISBLANK($E20),ISBLANK($F20),ISBLANK($G20),ISBLANK($H20),ISBLANK($I20),ISBLANK($J20)),"EKSİK","OK"))
I21: =IF(ISBLANK($A21),"",IF(COUNTA($E21:$H21)=4,$E21+$F21+$G21+$H21,"")) | K21: =IF(ISBLANK($D21),"",$D21-RaporTarihi) | L21: =IF(ISBLANK($A21),"",IF(OR(ISBLANK($B21),ISBLANK($C21),ISBLANK($D21),ISBLANK($E21),ISBLANK($F21),ISBLANK($G21),ISBLANK($H21),ISBLANK($I21),ISBLANK($J21)),"EKSİK","OK"))
I22: =IF(ISBLANK($A22),"",IF(COUNTA($E22:$H22)=4,$E22+$F22+$G22+$H22,"")) | K22: =IF(ISBLANK($D22),"",$D22-RaporTarihi) | L22: =IF(ISBLANK($A22),"",IF(OR(ISBLANK($B22),ISBLANK($C22),ISBLANK($D22),ISBLANK($E22),ISBLANK($F22),ISBLANK($G22),ISBLANK($H22),ISBLANK($I22),ISBLANK($J22)),"EKSİK","OK"))
I23: =IF(ISBLANK($A23),"",IF(COUNTA($E23:$H23)=4,$E23+$F23+$G23+$H23,"")) | K23: =IF(ISBLANK($D23),"",$D23-RaporTarihi) | L23: =IF(ISBLANK($A23),"",IF(OR(ISBLANK($B23),ISBLANK($C23),ISBLANK($D23),ISBLANK($E23),ISBLANK($F23),ISBLANK($G23),ISBLANK($H23),ISBLANK($I23),ISBLANK($J23)),"EKSİK","OK"))
... I35: =IF(ISBLANK($A35),"",IF(COUNTA($E35:$H35)=4,$E35+$F35+$G35+$H35,"")) | K35: =IF(ISBLANK($D35),"",$D35-RaporTarihi) | L35: =IF(ISBLANK($A35),"",IF(OR(ISBLANK($B35),ISBLANK($C35),ISBLANK($D35),ISBLANK($E35),ISBLANK($F35),ISBLANK($G35),ISBLANK($H35),ISBLANK($I35),ISBLANK($J35)),"EKSİK","OK"))

Sheet ODEME_TAKVIMI
A1: ODEME_TAKVIMI — KURUMSAL BANKA VE BORÇ YÖNETİMİ
A3: ÖDEME TAKVİMİ — yaklaşan taksitler 30 / 60 / 90 gün penceresinde.
A5: Kredi ID | B5: Banka | C5: Ödeme Tarihi | D5: Toplam Ödeme | E5: Kalan Gün | F5: Zaman Dilimi | G5: Ödeme Durumu
A6: =IF(ISBLANK(TAKSIT_PLANI!$A6),"",TAKSIT_PLANI!$B6) | B6: =IF(ISBLANK(TAKSIT_PLANI!$A6),"",IFERROR(INDEX(KREDILER!$B$6:$B$1000,MATCH(TAKSIT_PLANI!$B6,KREDILER!$A$6:$A$1000,0)),"")) | C6: =IF(ISBLANK(TAKSIT_PLANI!$A6),"",TAKSIT_PLANI!$D6) | D6: =IF(ISBLANK(TAKSIT_PLANI!$A6),"",TAKSIT_PLANI!$I6) | E6: =IF(ISBLANK(TAKSIT_PLANI!$A6),"",TAKSIT_PLANI!$K6) | F6: =IF(ISBLANK(TAKSIT_PLANI!$A6),"",IF(TAKSIT_PLANI!$K6<0,"Vadesi Geçmiş",IF(TAKSIT_PLANI!$K6<=30,"0-30 Gün",IF(TAKSIT_PLANI!$K6<=60,"31-60 Gün","61 Gün ve Üzeri")))) | G6: =IF(ISBLANK(TAKSIT_PLANI!$A6),"",TAKSIT_PLANI!$J6)
A7: =IF(ISBLANK(TAKSIT_PLANI!$A7),"",TAKSIT_PLANI!$B7) | B7: =IF(ISBLANK(TAKSIT_PLANI!$A7),"",IFERROR(INDEX(KREDILER!$B$6:$B$1000,MATCH(TAKSIT_PLANI!$B7,KREDILER!$A$6:$A$1000,0)),"")) | C7: =IF(ISBLANK(TAKSIT_PLANI!$A7),"",TAKSIT_PLANI!$D7) | D7: =IF(ISBLANK(TAKSIT_PLANI!$A7),"",TAKSIT_PLANI!$I7) | E7: =IF(ISBLANK(TAKSIT_PLANI!$A7),"",TAKSIT_PLANI!$K7) | F7: =IF(ISBLANK(TAKSIT_PLANI!$A7),"",IF(TAKSIT_PLANI!$K7<0,"Vadesi Geçmiş",IF(TAKSIT_PLANI!$K7<=30,"0-30 Gün",IF(TAKSIT_PLANI!$K7<=60,"31-60 Gün","61 Gün ve Üzeri")))) | G7: =IF(ISBLANK(TAKSIT_PLANI!$A7),"",TAKSIT_PLANI!$J7)
A8: =IF(ISBLANK(TAKSIT_PLANI!$A8),"",TAKSIT_PLANI!$B8) | B8: =IF(ISBLANK(TAKSIT_PLANI!$A8),"",IFERROR(INDEX(KREDILER!$B$6:$B$1000,MATCH(TAKSIT_PLANI!$B8,KREDILER!$A$6:$A$1000,0)),"")) | C8: =IF(ISBLANK(TAKSIT_PLANI!$A8),"",TAKSIT_PLANI!$D8) | D8: =IF(ISBLANK(TAKSIT_PLANI!$A8),"",TAKSIT_PLANI!$I8) | E8: =IF(ISBLANK(TAKSIT_PLANI!$A8),"",TAKSIT_PLANI!$K8) | F8: =IF(ISBLANK(TAKSIT_PLANI!$A8),"",IF(TAKSIT_PLANI!$K8<0,"Vadesi Geçmiş",IF(TAKSIT_PLANI!$K8<=30,"0-30 Gün",IF(TAKSIT_PLANI!$K8<=60,"31-60 Gün","61 Gün ve Üzeri")))) | G8: =IF(ISBLANK(TAKSIT_PLANI!$A8),"",TAKSIT_PLANI!$J8)
A9: =IF(ISBLANK(TAKSIT_PLANI!$A9),"",TAKSIT_PLANI!$B9) | B9: =IF(ISBLANK(TAKSIT_PLANI!$A9),"",IFERROR(INDEX(KREDILER!$B$6:$B$1000,MATCH(TAKSIT_PLANI!$B9,KREDILER!$A$6:$A$1000,0)),"")) | C9: =IF(ISBLANK(TAKSIT_PLANI!$A9),"",TAKSIT_PLANI!$D9) | D9: =IF(ISBLANK(TAKSIT_PLANI!$A9),"",TAKSIT_PLANI!$I9) | E9: =IF(ISBLANK(TAKSIT_PLANI!$A9),"",TAKSIT_PLANI!$K9) | F9: =IF(ISBLANK(TAKSIT_PLANI!$A9),"",IF(TAKSIT_PLANI!$K9<0,"Vadesi Geçmiş",IF(TAKSIT_PLANI!$K9<=30,"0-30 Gün",IF(TAKSIT_PLANI!$K9<=60,"31-60 Gün","61 Gün ve Üzeri")))) | G9: =IF(ISBLANK(TAKSIT_PLANI!$A9),"",TAKSIT_PLANI!$J9)
A10: =IF(ISBLANK(TAKSIT_PLANI!$A10),"",TAKSIT_PLANI!$B10) | B10: =IF(ISBLANK(TAKSIT_PLANI!$A10),"",IFERROR(INDEX(KREDILER!$B$6:$B$1000,MATCH(TAKSIT_PLANI!$B10,KREDILER!$A$6:$A$1000,0)),"")) | C10: =IF(ISBLANK(TAKSIT_PLANI!$A10),"",TAKSIT_PLANI!$D10) | D10: =IF(ISBLANK(TAKSIT_PLANI!$A10),"",TAKSIT_PLANI!$I10) | E10: =IF(ISBLANK(TAKSIT_PLANI!$A10),"",TAKSIT_PLANI!$K10) | F10: =IF(ISBLANK(TAKSIT_PLANI!$A10),"",IF(TAKSIT_PLANI!$K10<0,"Vadesi Geçmiş",IF(TAKSIT_PLANI!$K10<=30,"0-30 Gün",IF(TAKSIT_PLANI!$K10<=60,"31-60 Gün","61 Gün ve Üzeri")))) | G10: =IF(ISBLANK(TAKSIT_PLANI!$A10),"",TAKSIT_PLANI!$J10)
A11: =IF(ISBLANK(TAKSIT_PLANI!$A11),"",TAKSIT_PLANI!$B11) | B11: =IF(ISBLANK(TAKSIT_PLANI!$A11),"",IFERROR(INDEX(KREDILER!$B$6:$B$1000,MATCH(TAKSIT_PLANI!$B11,KREDILER!$A$6:$A$1000,0)),"")) | C11: =IF(ISBLANK(TAKSIT_PLANI!$A11),"",TAKSIT_PLANI!$D11) | D11: =IF(ISBLANK(TAKSIT_PLANI!$A11),"",TAKSIT_PLANI!$I11) | E11: =IF(ISBLANK(TAKSIT_PLANI!$A11),"",TAKSIT_PLANI!$K11) | F11: =IF(ISBLANK(TAKSIT_PLANI!$A11),"",IF(TAKSIT_PLANI!$K11<0,"Vadesi Geçmiş",IF(TAKSIT_PLANI!$K11<=30,"0-30 Gün",IF(TAKSIT_PLANI!$K11<=60,"31-60 Gün","61 Gün ve Üzeri")))) | G11: =IF(ISBLANK(TAKSIT_PLANI!$A11),"",TAKSIT_PLANI!$J11)
A12: =IF(ISBLANK(TAKSIT_PLANI!$A12),"",TAKSIT_PLANI!$B12) | B12: =IF(ISBLANK(TAKSIT_PLANI!$A12),"",IFERROR(INDEX(KREDILER!$B$6:$B$1000,MATCH(TAKSIT_PLANI!$B12,KREDILER!$A$6:$A$1000,0)),"")) | C12: =IF(ISBLANK(TAKSIT_PLANI!$A12),"",TAKSIT_PLANI!$D12) | D12: =IF(ISBLANK(TAKSIT_PLANI!$A12),"",TAKSIT_PLANI!$I12) | E12: =IF(ISBLANK(TAKSIT_PLANI!$A12),"",TAKSIT_PLANI!$K12) | F12: =IF(ISBLANK(TAKSIT_PLANI!$A12),"",IF(TAKSIT_PLANI!$K12<0,"Vadesi Geçmiş",IF(TAKSIT_PLANI!$K12<=30,"0-30 Gün",IF(TAKSIT_PLANI!$K12<=60,"31-60 Gün","61 Gün ve Üzeri")))) | G12: =IF(ISBLANK(TAKSIT_PLANI!$A12),"",TAKSIT_PLANI!$J12)
A13: =IF(ISBLANK(TAKSIT_PLANI!$A13),"",TAKSIT_PLANI!$B13) | B13: =IF(ISBLANK(TAKSIT_PLANI!$A13),"",IFERROR(INDEX(KREDILER!$B$6:$B$1000,MATCH(TAKSIT_PLANI!$B13,KREDILER!$A$6:$A$1000,0)),"")) | C13: =IF(ISBLANK(TAKSIT_PLANI!$A13),"",TAKSIT_PLANI!$D13) | D13: =IF(ISBLANK(TAKSIT_PLANI!$A13),"",TAKSIT_PLANI!$I13) | E13: =IF(ISBLANK(TAKSIT_PLANI!$A13),"",TAKSIT_PLANI!$K13) | F13: =IF(ISBLANK(TAKSIT_PLANI!$A13),"",IF(TAKSIT_PLANI!$K13<0,"Vadesi Geçmiş",IF(TAKSIT_PLANI!$K13<=30,"0-30 Gün",IF(TAKSIT_PLANI!$K13<=60,"31-60 Gün","61 Gün ve Üzeri")))) | G13: =IF(ISBLANK(TAKSIT_PLANI!$A13),"",TAKSIT_PLANI!$J13)
A14: =IF(ISBLANK(TAKSIT_PLANI!$A14),"",TAKSIT_PLANI!$B14) | B14: =IF(ISBLANK(TAKSIT_PLANI!$A14),"",IFERROR(INDEX(KREDILER!$B$6:$B$1000,MATCH(TAKSIT_PLANI!$B14,KREDILER!$A$6:$A$1000,0)),"")) | C14: =IF(ISBLANK(TAKSIT_PLANI!$A14),"",TAKSIT_PLANI!$D14) | D14: =IF(ISBLANK(TAKSIT_PLANI!$A14),"",TAKSIT_PLANI!$I14) | E14: =IF(ISBLANK(TAKSIT_PLANI!$A14),"",TAKSIT_PLANI!$K14) | F14: =IF(ISBLANK(TAKSIT_PLANI!$A14),"",IF(TAKSIT_PLANI!$K14<0,"Vadesi Geçmiş",IF(TAKSIT_PLANI!$K14<=30,"0-30 Gün",IF(TAKSIT_PLANI!$K14<=60,"31-60 Gün","61 Gün ve Üzeri")))) | G14: =IF(ISBLANK(TAKSIT_PLANI!$A14),"",TAKSIT_PLANI!$J14)
A15: =IF(ISBLANK(TAKSIT_PLANI!$A15),"",TAKSIT_PLANI!$B15) | B15: =IF(ISBLANK(TAKSIT_PLANI!$A15),"",IFERROR(INDEX(KREDILER!$B$6:$B$1000,MATCH(TAKSIT_PLANI!$B15,KREDILER!$A$6:$A$1000,0)),"")) | C15: =IF(ISBLANK(TAKSIT_PLANI!$A15),"",TAKSIT_PLANI!$D15) | D15: =IF(ISBLANK(TAKSIT_PLANI!$A15),"",TAKSIT_PLANI!$I15) | E15: =IF(ISBLANK(TAKSIT_PLANI!$A15),"",TAKSIT_PLANI!$K15) | F15: =IF(ISBLANK(TAKSIT_PLANI!$A15),"",IF(TAKSIT_PLANI!$K15<0,"Vadesi Geçmiş",IF(TAKSIT_PLANI!$K15<=30,"0-30 Gün",IF(TAKSIT_PLANI!$K15<=60,"31-60 Gün","61 Gün ve Üzeri")))) | G15: =IF(ISBLANK(TAKSIT_PLANI!$A15),"",TAKSIT_PLANI!$J15)
A16: =IF(ISBLANK(TAKSIT_PLANI!$A16),"",TAKSIT_PLANI!$B16) | B16: =IF(ISBLANK(TAKSIT_PLANI!$A16),"",IFERROR(INDEX(KREDILER!$B$6:$B$1000,MATCH(TAKSIT_PLANI!$B16,KREDILER!$A$6:$A$1000,0)),"")) | C16: =IF(ISBLANK(TAKSIT_PLANI!$A16),"",TAKSIT_PLANI!$D16) | D16: =IF(ISBLANK(TAKSIT_PLANI!$A16),"",TAKSIT_PLANI!$I16) | E16: =IF(ISBLANK(TAKSIT_PLANI!$A16),"",TAKSIT_PLANI!$K16) | F16: =IF(ISBLANK(TAKSIT_PLANI!$A16),"",IF(TAKSIT_PLANI!$K16<0,"Vadesi Geçmiş",IF(TAKSIT_PLANI!$K16<=30,"0-30 Gün",IF(TAKSIT_PLANI!$K16<=60,"31-60 Gün","61 Gün ve Üzeri")))) | G16: =IF(ISBLANK(TAKSIT_PLANI!$A16),"",TAKSIT_PLANI!$J16)
A17: =IF(ISBLANK(TAKSIT_PLANI!$A17),"",TAKSIT_PLANI!$B17) | B17: =IF(ISBLANK(TAKSIT_PLANI!$A17),"",IFERROR(INDEX(KREDILER!$B$6:$B$1000,MATCH(TAKSIT_PLANI!$B17,KREDILER!$A$6:$A$1000,0)),"")) | C17: =IF(ISBLANK(TAKSIT_PLANI!$A17),"",TAKSIT_PLANI!$D17) | D17: =IF(ISBLANK(TAKSIT_PLANI!$A17),"",TAKSIT_PLANI!$I17) | E17: =IF(ISBLANK(TAKSIT_PLANI!$A17),"",TAKSIT_PLANI!$K17) | F17: =IF(ISBLANK(TAKSIT_PLANI!$A17),"",IF(TAKSIT_PLANI!$K17<0,"Vadesi Geçmiş",IF(TAKSIT_PLANI!$K17<=30,"0-30 Gün",IF(TAKSIT_PLANI!$K17<=60,"31-60 Gün","61 Gün ve Üzeri")))) | G17: =IF(ISBLANK(TAKSIT_PLANI!$A17),"",TAKSIT_PLANI!$J17)
... A35: =IF(ISBLANK(TAKSIT_PLANI!$A35),"",TAKSIT_PLANI!$B35) | B35: =IF(ISBLANK(TAKSIT_PLANI!$A35),"",IFERROR(INDEX(KREDILER!$B$6:$B$1000,MATCH(TAKSIT_PLANI!$B35,KREDILER!$A$6:$A$1000,0)),"")) | C35: =IF(ISBLANK(TAKSIT_PLANI!$A35),"",TAKSIT_PLANI!$D35) | D35: =IF(ISBLANK(TAKSIT_PLANI!$A35),"",TAKSIT_PLANI!$I35) | E35: =IF(ISBLANK(TAKSIT_PLANI!$A35),"",TAKSIT_PLANI!$K35) | F35: =IF(ISBLANK(TAKSIT_PLANI!$A35),"",IF(TAKSIT_PLANI!$K35<0,"Vadesi Geçmiş",IF(TAKSIT_PLANI!$K35<=30,"0-30 Gün",IF(TAKSIT_PLANI!$K35<=60,"31-60 Gün","61 Gün ve Üzeri")))) | G35: =IF(ISBLANK(TAKSIT_PLANI!$A35),"",TAKSIT_PLANI!$J35)

Sheet MASRAF_KOMISYON
A1: MASRAF KOMISYON — BANKA, KREDİ VE TAKSİT TAKİP SİSTEMİ
A3: MASRAF VE KOMİSYONLAR — tahsis, sigorta, komisyon ve diğer finansman maliyetleri.
A5: Masraf ID | B5: Kredi ID | C5: Banka | D5: Masraf Türü | E5: İşlem Tarihi | F5: Belge Numarası | G5: Tutar | H5: Para Birimi | I5: Kontrol
A6: MSF-001 | B6: KRD-001 | C6: Türkiye İş Bankası | D6: Tahsis Ücreti | E6: 45597 | F6: FTR-1001 | G6: 60000 | H6: TRY | I6: =IF(ISBLANK($A6),"",IF(OR(ISBLANK($B6),ISBLANK($C6),ISBLANK($D6),ISBLANK($E6),ISBLANK($F6),ISBLANK($G6),ISBLANK($H6)),"EKSİK","OK"))
A7: MSF-002 | B7: KRD-002 | C7: Akbank | D7: Sigorta | E7: 45717 | F7: POL-2001 | G7: 70000 | H7: TRY | I7: =IF(ISBLANK($A7),"",IF(OR(ISBLANK($B7),ISBLANK($C7),ISBLANK($D7),ISBLANK($E7),ISBLANK($F7),ISBLANK($G7),ISBLANK($H7)),"EKSİK","OK"))
A8: MSF-003 | B8: KRD-003 | C8: Garanti BBVA | D8: Komisyon | E8: 45809 | F8: FTR-3001 | G8: 1500 | H8: USD | I8: =IF(ISBLANK($A8),"",IF(OR(ISBLANK($B8),ISBLANK($C8),ISBLANK($D8),ISBLANK($E8),ISBLANK($F8),ISBLANK($G8),ISBLANK($H8)),"EKSİK","OK"))
I9: =IF(ISBLANK($A9),"",IF(OR(ISBLANK($B9),ISBLANK($C9),ISBLANK($D9),ISBLANK($E9),ISBLANK($F9),ISBLANK($G9),ISBLANK($H9)),"EKSİK","OK"))
I10: =IF(ISBLANK($A10),"",IF(OR(ISBLANK($B10),ISBLANK($C10),ISBLANK($D10),ISBLANK($E10),ISBLANK($F10),ISBLANK($G10),ISBLANK($H10)),"EKSİK","OK"))
I11: =IF(ISBLANK($A11),"",IF(OR(ISBLANK($B11),ISBLANK($C11),ISBLANK($D11),ISBLANK($E11),ISBLANK($F11),ISBLANK($G11),ISBLANK($H11)),"EKSİK","OK"))
I12: =IF(ISBLANK($A12),"",IF(OR(ISBLANK($B12),ISBLANK($C12),ISBLANK($D12),ISBLANK($E12),ISBLANK($F12),ISBLANK($G12),ISBLANK($H12)),"EKSİK","OK"))
I13: =IF(ISBLANK($A13),"",IF(OR(ISBLANK($B13),ISBLANK($C13),ISBLANK($D13),ISBLANK($E13),ISBLANK($F13),ISBLANK($G13),ISBLANK($H13)),"EKSİK","OK"))
I14: =IF(ISBLANK($A14),"",IF(OR(ISBLANK($B14),ISBLANK($C14),ISBLANK($D14),ISBLANK($E14),ISBLANK($F14),ISBLANK($G14),ISBLANK($H14)),"EKSİK","OK"))
I15: =IF(ISBLANK($A15),"",IF(OR(ISBLANK($B15),ISBLANK($C15),ISBLANK($D15),ISBLANK($E15),ISBLANK($F15),ISBLANK($G15),ISBLANK($H15)),"EKSİK","OK"))
I16: =IF(ISBLANK($A16),"",IF(OR(ISBLANK($B16),ISBLANK($C16),ISBLANK($D16),ISBLANK($E16),ISBLANK($F16),ISBLANK($G16),ISBLANK($H16)),"EKSİK","OK"))
I17: =IF(ISBLANK($A17),"",IF(OR(ISBLANK($B17),ISBLANK($C17),ISBLANK($D17),ISBLANK($E17),ISBLANK($F17),ISBLANK($G17),ISBLANK($H17)),"EKSİK","OK"))
I18: =IF(ISBLANK($A18),"",IF(OR(ISBLANK($B18),ISBLANK($C18),ISBLANK($D18),ISBLANK($E18),ISBLANK($F18),ISBLANK($G18),ISBLANK($H18)),"EKSİK","OK"))
I19: =IF(ISBLANK($A19),"",IF(OR(ISBLANK($B19),ISBLANK($C19),ISBLANK($D19),ISBLANK($E19),ISBLANK($F19),ISBLANK($G19),ISBLANK($H19)),"EKSİK","OK"))
I20: =IF(ISBLANK($A20),"",IF(OR(ISBLANK($B20),ISBLANK($C20),ISBLANK($D20),ISBLANK($E20),ISBLANK($F20),ISBLANK($G20),ISBLANK($H20)),"EKSİK","OK"))
... I35: =IF(ISBLANK($A35),"",IF(OR(ISBLANK($B35),ISBLANK($C35),ISBLANK($D35),ISBLANK($E35),ISBLANK($F35),ISBLANK($G35),ISBLANK($H35)),"EKSİK","OK"))

Sheet TEMINATLAR
A1: TEMINATLAR — BANKA, KREDİ VE TAKSİT TAKİP SİSTEMİ
A3: TEMİNAT YÖNETİMİ — değer, geçerlilik ve kredi bağlantısı.
A5: Teminat ID | B5: Kredi ID | C5: Banka | D5: Teminat Türü | E5: Açıklama | F5: Ekspertiz Değeri | G5: Para Birimi | H5: Değerleme Tarihi | I5: Geçerlilik Bitişi | J5: Kontrol
A6: TMN-001 | B6: KRD-001 | C6: Türkiye İş Bankası | D6: Gayrimenkul İpoteği | E6: İstanbul fabrika binası | F6: 15000000 | G6: TRY | H6: 45992 | I6: 47088 | J6: =IF(ISBLANK($A6),"",IF(OR(ISBLANK($B6),ISBLANK($C6),ISBLANK($D6),ISBLANK($E6),ISBLANK($F6),ISBLANK($G6),ISBLANK($H6),ISBLANK($I6)),"EKSİK","OK"))
A7: TMN-002 | B7: KRD-002 | C7: Akbank | D7: Taşıt Rehni | E7: Üretim makineleri | F7: 8500000 | G7: TRY | H7: 45992 | I7: 46722 | J7: =IF(ISBLANK($A7),"",IF(OR(ISBLANK($B7),ISBLANK($C7),ISBLANK($D7),ISBLANK($E7),ISBLANK($F7),ISBLANK($G7),ISBLANK($H7),ISBLANK($I7)),"EKSİK","OK"))
A8: TMN-003 | B8: KRD-003 | C8: Garanti BBVA | D8: Alacak Temliki | E8: İhracat alacak havuzu | F8: 3500000 | G8: TRY | H8: 46023 | I8: 46388 | J8: =IF(ISBLANK($A8),"",IF(OR(ISBLANK($B8),ISBLANK($C8),ISBLANK($D8),ISBLANK($E8),ISBLANK($F8),ISBLANK($G8),ISBLANK($H8),ISBLANK($I8)),"EKSİK","OK"))
J9: =IF(ISBLANK($A9),"",IF(OR(ISBLANK($B9),ISBLANK($C9),ISBLANK($D9),ISBLANK($E9),ISBLANK($F9),ISBLANK($G9),ISBLANK($H9),ISBLANK($I9)),"EKSİK","OK"))
J10: =IF(ISBLANK($A10),"",IF(OR(ISBLANK($B10),ISBLANK($C10),ISBLANK($D10),ISBLANK($E10),ISBLANK($F10),ISBLANK($G10),ISBLANK($H10),ISBLANK($I10)),"EKSİK","OK"))
J11: =IF(ISBLANK($A11),"",IF(OR(ISBLANK($B11),ISBLANK($C11),ISBLANK($D11),ISBLANK($E11),ISBLANK($F11),ISBLANK($G11),ISBLANK($H11),ISBLANK($I11)),"EKSİK","OK"))
J12: =IF(ISBLANK($A12),"",IF(OR(ISBLANK($B12),ISBLANK($C12),ISBLANK($D12),ISBLANK($E12),ISBLANK($F12),ISBLANK($G12),ISBLANK($H12),ISBLANK($I12)),"EKSİK","OK"))
J13: =IF(ISBLANK($A13),"",IF(OR(ISBLANK($B13),ISBLANK($C13),ISBLANK($D13),ISBLANK($E13),ISBLANK($F13),ISBLANK($G13),ISBLANK($H13),ISBLANK($I13)),"EKSİK","OK"))
J14: =IF(ISBLANK($A14),"",IF(OR(ISBLANK($B14),ISBLANK($C14),ISBLANK($D14),ISBLANK($E14),ISBLANK($F14),ISBLANK($G14),ISBLANK($H14),ISBLANK($I14)),"EKSİK","OK"))
J15: =IF(ISBLANK($A15),"",IF(OR(ISBLANK($B15),ISBLANK($C15),ISBLANK($D15),ISBLANK($E15),ISBLANK($F15),ISBLANK($G15),ISBLANK($H15),ISBLANK($I15)),"EKSİK","OK"))
J16: =IF(ISBLANK($A16),"",IF(OR(ISBLANK($B16),ISBLANK($C16),ISBLANK($D16),ISBLANK($E16),ISBLANK($F16),ISBLANK($G16),ISBLANK($H16),ISBLANK($I16)),"EKSİK","OK"))
J17: =IF(ISBLANK($A17),"",IF(OR(ISBLANK($B17),ISBLANK($C17),ISBLANK($D17),ISBLANK($E17),ISBLANK($F17),ISBLANK($G17),ISBLANK($H17),ISBLANK($I17)),"EKSİK","OK"))
J18: =IF(ISBLANK($A18),"",IF(OR(ISBLANK($B18),ISBLANK($C18),ISBLANK($D18),ISBLANK($E18),ISBLANK($F18),ISBLANK($G18),ISBLANK($H18),ISBLANK($I18)),"EKSİK","OK"))
J19: =IF(ISBLANK($A19),"",IF(OR(ISBLANK($B19),ISBLANK($C19),ISBLANK($D19),ISBLANK($E19),ISBLANK($F19),ISBLANK($G19),ISBLANK($H19),ISBLANK($I19)),"EKSİK","OK"))
J20: =IF(ISBLANK($A20),"",IF(OR(ISBLANK($B20),ISBLANK($C20),ISBLANK($D20),ISBLANK($E20),ISBLANK($F20),ISBLANK($G20),ISBLANK($H20),ISBLANK($I20)),"EKSİK","OK"))
... J35: =IF(ISBLANK($A35),"",IF(OR(ISBLANK($B35),ISBLANK($C35),ISBLANK($D35),ISBLANK($E35),ISBLANK($F35),ISBLANK($G35),ISBLANK($H35),ISBLANK($I35)),"EKSİK","OK"))

Sheet YENI_TEKLIFLER
A1: YENI TEKLIFLER — BANKA, KREDİ VE TAKSİT TAKİP SİSTEMİ
A3: YENİ KREDİ TEKLİFLERİ — tutar, faiz, masraf ve aylık taksit karşılaştırması.
A5: Teklif ID | B5: Hedef Kredi ID | C5: Banka | D5: Tutar | E5: Para Birimi | F5: Vade Ay | G5: Nominal Faiz | H5: Toplam Masraf | I5: Aylık Taksit | J5: Öngörülen Maliyet | K5: Kontrol
A6: TKL-001 | B6: KRD-001 | C6: QNB Finansbank | D6: 8600000 | E6: TRY | F6: 30 | G6: 0.36 | H6: 180000 | I6: =IF(ISBLANK($A6),"",IF($D6="","",ROUND($D6/MAX(1,$F6),0))) | J6: =IF(ISBLANK($A6),"",IF($D6="","",$D6+$H6)) | K6: =IF(ISBLANK($A6),"",IF(OR(ISBLANK($B6),ISBLANK($C6),ISBLANK($D6),ISBLANK($E6),ISBLANK($F6),ISBLANK($G6),ISBLANK($H6)),"EKSİK","OK"))
A7: TKL-002 | B7: KRD-002 | C7: Vakıfbank | D7: 6200000 | E7: TRY | F7: 42 | G7: 0.34 | H7: 160000 | I7: =IF(ISBLANK($A7),"",IF($D7="","",ROUND($D7/MAX(1,$F7),0))) | J7: =IF(ISBLANK($A7),"",IF($D7="","",$D7+$H7)) | K7: =IF(ISBLANK($A7),"",IF(OR(ISBLANK($B7),ISBLANK($C7),ISBLANK($D7),ISBLANK($E7),ISBLANK($F7),ISBLANK($G7),ISBLANK($H7)),"EKSİK","OK"))
A8: TKL-003 | B8: KRD-003 | C8: Halkbank | D8: 190000 | E8: USD | F8: 24 | G8: 0.085 | H8: 6000 | I8: =IF(ISBLANK($A8),"",IF($D8="","",ROUND($D8/MAX(1,$F8),0))) | J8: =IF(ISBLANK($A8),"",IF($D8="","",$D8+$H8)) | K8: =IF(ISBLANK($A8),"",IF(OR(ISBLANK($B8),ISBLANK($C8),ISBLANK($D8),ISBLANK($E8),ISBLANK($F8),ISBLANK($G8),ISBLANK($H8)),"EKSİK","OK"))
I9: =IF(ISBLANK($A9),"",IF($D9="","",ROUND($D9/MAX(1,$F9),0))) | J9: =IF(ISBLANK($A9),"",IF($D9="","",$D9+$H9)) | K9: =IF(ISBLANK($A9),"",IF(OR(ISBLANK($B9),ISBLANK($C9),ISBLANK($D9),ISBLANK($E9),ISBLANK($F9),ISBLANK($G9),ISBLANK($H9)),"EKSİK","OK"))
I10: =IF(ISBLANK($A10),"",IF($D10="","",ROUND($D10/MAX(1,$F10),0))) | J10: =IF(ISBLANK($A10),"",IF($D10="","",$D10+$H10)) | K10: =IF(ISBLANK($A10),"",IF(OR(ISBLANK($B10),ISBLANK($C10),ISBLANK($D10),ISBLANK($E10),ISBLANK($F10),ISBLANK($G10),ISBLANK($H10)),"EKSİK","OK"))
I11: =IF(ISBLANK($A11),"",IF($D11="","",ROUND($D11/MAX(1,$F11),0))) | J11: =IF(ISBLANK($A11),"",IF($D11="","",$D11+$H11)) | K11: =IF(ISBLANK($A11),"",IF(OR(ISBLANK($B11),ISBLANK($C11),ISBLANK($D11),ISBLANK($E11),ISBLANK($F11),ISBLANK($G11),ISBLANK($H11)),"EKSİK","OK"))
I12: =IF(ISBLANK($A12),"",IF($D12="","",ROUND($D12/MAX(1,$F12),0))) | J12: =IF(ISBLANK($A12),"",IF($D12="","",$D12+$H12)) | K12: =IF(ISBLANK($A12),"",IF(OR(ISBLANK($B12),ISBLANK($C12),ISBLANK($D12),ISBLANK($E12),ISBLANK($F12),ISBLANK($G12),ISBLANK($H12)),"EKSİK","OK"))
I13: =IF(ISBLANK($A13),"",IF($D13="","",ROUND($D13/MAX(1,$F13),0))) | J13: =IF(ISBLANK($A13),"",IF($D13="","",$D13+$H13)) | K13: =IF(ISBLANK($A13),"",IF(OR(ISBLANK($B13),ISBLANK($C13),ISBLANK($D13),ISBLANK($E13),ISBLANK($F13),ISBLANK($G13),ISBLANK($H13)),"EKSİK","OK"))
I14: =IF(ISBLANK($A14),"",IF($D14="","",ROUND($D14/MAX(1,$F14),0))) | J14: =IF(ISBLANK($A14),"",IF($D14="","",$D14+$H14)) | K14: =IF(ISBLANK($A14),"",IF(OR(ISBLANK($B14),ISBLANK($C14),ISBLANK($D14),ISBLANK($E14),ISBLANK($F14),ISBLANK($G14),ISBLANK($H14)),"EKSİK","OK"))
I15: =IF(ISBLANK($A15),"",IF($D15="","",ROUND($D15/MAX(1,$F15),0))) | J15: =IF(ISBLANK($A15),"",IF($D15="","",$D15+$H15)) | K15: =IF(ISBLANK($A15),"",IF(OR(ISBLANK($B15),ISBLANK($C15),ISBLANK($D15),ISBLANK($E15),ISBLANK($F15),ISBLANK($G15),ISBLANK($H15)),"EKSİK","OK"))
I16: =IF(ISBLANK($A16),"",IF($D16="","",ROUND($D16/MAX(1,$F16),0))) | J16: =IF(ISBLANK($A16),"",IF($D16="","",$D16+$H16)) | K16: =IF(ISBLANK($A16),"",IF(OR(ISBLANK($B16),ISBLANK($C16),ISBLANK($D16),ISBLANK($E16),ISBLANK($F16),ISBLANK($G16),ISBLANK($H16)),"EKSİK","OK"))
I17: =IF(ISBLANK($A17),"",IF($D17="","",ROUND($D17/MAX(1,$F17),0))) | J17: =IF(ISBLANK($A17),"",IF($D17="","",$D17+$H17)) | K17: =IF(ISBLANK($A17),"",IF(OR(ISBLANK($B17),ISBLANK($C17),ISBLANK($D17),ISBLANK($E17),ISBLANK($F17),ISBLANK($G17),ISBLANK($H17)),"EKSİK","OK"))
I18: =IF(ISBLANK($A18),"",IF($D18="","",ROUND($D18/MAX(1,$F18),0))) | J18: =IF(ISBLANK($A18),"",IF($D18="","",$D18+$H18)) | K18: =IF(ISBLANK($A18),"",IF(OR(ISBLANK($B18),ISBLANK($C18),ISBLANK($D18),ISBLANK($E18),ISBLANK($F18),ISBLANK($G18),ISBLANK($H18)),"EKSİK","OK"))
I19: =IF(ISBLANK($A19),"",IF($D19="","",ROUND($D19/MAX(1,$F19),0))) | J19: =IF(ISBLANK($A19),"",IF($D19="","",$D19+$H19)) | K19: =IF(ISBLANK($A19),"",IF(OR(ISBLANK($B19),ISBLANK($C19),ISBLANK($D19),ISBLANK($E19),ISBLANK($F19),ISBLANK($G19),ISBLANK($H19)),"EKSİK","OK"))
I20: =IF(ISBLANK($A20),"",IF($D20="","",ROUND($D20/MAX(1,$F20),0))) | J20: =IF(ISBLANK($A20),"",IF($D20="","",$D20+$H20)) | K20: =IF(ISBLANK($A20),"",IF(OR(ISBLANK($B20),ISBLANK($C20),ISBLANK($D20),ISBLANK($E20),ISBLANK($F20),ISBLANK($G20),ISBLANK($H20)),"EKSİK","OK"))
... I35: =IF(ISBLANK($A35),"",IF($D35="","",ROUND($D35/MAX(1,$F35),0))) | J35: =IF(ISBLANK($A35),"",IF($D35="","",$D35+$H35)) | K35: =IF(ISBLANK($A35),"",IF(OR(ISBLANK($B35),ISBLANK($C35),ISBLANK($D35),ISBLANK($E35),ISBLANK($F35),ISBLANK($G35),ISBLANK($H35)),"EKSİK","OK"))

Sheet REFINANSMAN
A1: REFINANSMAN — KURUMSAL BANKA VE BORÇ YÖNETİMİ
A3: REFİNANSMAN ANALİZİ — aylık taksit rahatlaması ve toplam maliyet.
A5: Teklif ID | B5: Hedef Kredi ID | C5: Mevcut Aylık Taksit | D5: Yeni Aylık Taksit | E5: Aylık Taksit Farkı | F5: Nakit Rahatlaması | G5: Yeni Toplam Maliyet | H5: Mevcut Kalan Anapara | I5: Karar | J5: Kontrol
A6: =IF(ISBLANK(YENI_TEKLIFLER!$A6),"",YENI_TEKLIFLER!$A6) | B6: =IF(ISBLANK(YENI_TEKLIFLER!$A6),"",YENI_TEKLIFLER!$B6) | C6: =IF(ISBLANK(YENI_TEKLIFLER!$A6),"",SUMIFS(TAKSIT_PLANI!$I$6:$I$1000,TAKSIT_PLANI!$B$6:$B$1000,YENI_TEKLIFLER!$B6,TAKSIT_PLANI!$C$6:$C$1000,1)) | D6: =IF(ISBLANK(YENI_TEKLIFLER!$A6),"",YENI_TEKLIFLER!$I6) | E6: =IF(ISBLANK(YENI_TEKLIFLER!$A6),"",$C6-$D6) | F6: =IF(ISBLANK(YENI_TEKLIFLER!$A6),"",MAX(0,$E6)) | G6: =IF(ISBLANK(YENI_TEKLIFLER!$A6),"",YENI_TEKLIFLER!$J6) | H6: =IF(ISBLANK(YENI_TEKLIFLER!$A6),"",INDEX(KREDILER!$H$6:$H$1000,MATCH(YENI_TEKLIFLER!$B6,KREDILER!$A$6:$A$1000,0))) | I6: =IF(ISBLANK(YENI_TEKLIFLER!$A6),"",IF($E6>0,"ADAY","DEĞİL")) | J6: =IF(ISBLANK(YENI_TEKLIFLER!$A6),"",IF(OR(ISBLANK($B6),ISBLANK($C6),ISBLANK($D6),ISBLANK($E6),ISBLANK($F6),ISBLANK($G6),ISBLANK($H6)),"EKSİK","OK"))
A7: =IF(ISBLANK(YENI_TEKLIFLER!$A7),"",YENI_TEKLIFLER!$A7) | B7: =IF(ISBLANK(YENI_TEKLIFLER!$A7),"",YENI_TEKLIFLER!$B7) | C7: =IF(ISBLANK(YENI_TEKLIFLER!$A7),"",SUMIFS(TAKSIT_PLANI!$I$6:$I$1000,TAKSIT_PLANI!$B$6:$B$1000,YENI_TEKLIFLER!$B7,TAKSIT_PLANI!$C$6:$C$1000,1)) | D7: =IF(ISBLANK(YENI_TEKLIFLER!$A7),"",YENI_TEKLIFLER!$I7) | E7: =IF(ISBLANK(YENI_TEKLIFLER!$A7),"",$C7-$D7) | F7: =IF(ISBLANK(YENI_TEKLIFLER!$A7),"",MAX(0,$E7)) | G7: =IF(ISBLANK(YENI_TEKLIFLER!$A7),"",YENI_TEKLIFLER!$J7) | H7: =IF(ISBLANK(YENI_TEKLIFLER!$A7),"",INDEX(KREDILER!$H$6:$H$1000,MATCH(YENI_TEKLIFLER!$B7,KREDILER!$A$6:$A$1000,0))) | I7: =IF(ISBLANK(YENI_TEKLIFLER!$A7),"",IF($E7>0,"ADAY","DEĞİL")) | J7: =IF(ISBLANK(YENI_TEKLIFLER!$A7),"",IF(OR(ISBLANK($B7),ISBLANK($C7),ISBLANK($D7),ISBLANK($E7),ISBLANK($F7),ISBLANK($G7),ISBLANK($H7)),"EKSİK","OK"))
A8: =IF(ISBLANK(YENI_TEKLIFLER!$A8),"",YENI_TEKLIFLER!$A8) | B8: =IF(ISBLANK(YENI_TEKLIFLER!$A8),"",YENI_TEKLIFLER!$B8) | C8: =IF(ISBLANK(YENI_TEKLIFLER!$A8),"",SUMIFS(TAKSIT_PLANI!$I$6:$I$1000,TAKSIT_PLANI!$B$6:$B$1000,YENI_TEKLIFLER!$B8,TAKSIT_PLANI!$C$6:$C$1000,1)) | D8: =IF(ISBLANK(YENI_TEKLIFLER!$A8),"",YENI_TEKLIFLER!$I8) | E8: =IF(ISBLANK(YENI_TEKLIFLER!$A8),"",$C8-$D8) | F8: =IF(ISBLANK(YENI_TEKLIFLER!$A8),"",MAX(0,$E8)) | G8: =IF(ISBLANK(YENI_TEKLIFLER!$A8),"",YENI_TEKLIFLER!$J8) | H8: =IF(ISBLANK(YENI_TEKLIFLER!$A8),"",INDEX(KREDILER!$H$6:$H$1000,MATCH(YENI_TEKLIFLER!$B8,KREDILER!$A$6:$A$1000,0))) | I8: =IF(ISBLANK(YENI_TEKLIFLER!$A8),"",IF($E8>0,"ADAY","DEĞİL")) | J8: =IF(ISBLANK(YENI_TEKLIFLER!$A8),"",IF(OR(ISBLANK($B8),ISBLANK($C8),ISBLANK($D8),ISBLANK($E8),ISBLANK($F8),ISBLANK($G8),ISBLANK($H8)),"EKSİK","OK"))
A9: =IF(ISBLANK(YENI_TEKLIFLER!$A9),"",YENI_TEKLIFLER!$A9) | B9: =IF(ISBLANK(YENI_TEKLIFLER!$A9),"",YENI_TEKLIFLER!$B9) | C9: =IF(ISBLANK(YENI_TEKLIFLER!$A9),"",SUMIFS(TAKSIT_PLANI!$I$6:$I$1000,TAKSIT_PLANI!$B$6:$B$1000,YENI_TEKLIFLER!$B9,TAKSIT_PLANI!$C$6:$C$1000,1)) | D9: =IF(ISBLANK(YENI_TEKLIFLER!$A9),"",YENI_TEKLIFLER!$I9) | E9: =IF(ISBLANK(YENI_TEKLIFLER!$A9),"",$C9-$D9) | F9: =IF(ISBLANK(YENI_TEKLIFLER!$A9),"",MAX(0,$E9)) | G9: =IF(ISBLANK(YENI_TEKLIFLER!$A9),"",YENI_TEKLIFLER!$J9) | H9: =IF(ISBLANK(YENI_TEKLIFLER!$A9),"",INDEX(KREDILER!$H$6:$H$1000,MATCH(YENI_TEKLIFLER!$B9,KREDILER!$A$6:$A$1000,0))) | I9: =IF(ISBLANK(YENI_TEKLIFLER!$A9),"",IF($E9>0,"ADAY","DEĞİL")) | J9: =IF(ISBLANK(YENI_TEKLIFLER!$A9),"",IF(OR(ISBLANK($B9),ISBLANK($C9),ISBLANK($D9),ISBLANK($E9),ISBLANK($F9),ISBLANK($G9),ISBLANK($H9)),"EKSİK","OK"))
A10: =IF(ISBLANK(YENI_TEKLIFLER!$A10),"",YENI_TEKLIFLER!$A10) | B10: =IF(ISBLANK(YENI_TEKLIFLER!$A10),"",YENI_TEKLIFLER!$B10) | C10: =IF(ISBLANK(YENI_TEKLIFLER!$A10),"",SUMIFS(TAKSIT_PLANI!$I$6:$I$1000,TAKSIT_PLANI!$B$6:$B$1000,YENI_TEKLIFLER!$B10,TAKSIT_PLANI!$C$6:$C$1000,1)) | D10: =IF(ISBLANK(YENI_TEKLIFLER!$A10),"",YENI_TEKLIFLER!$I10) | E10: =IF(ISBLANK(YENI_TEKLIFLER!$A10),"",$C10-$D10) | F10: =IF(ISBLANK(YENI_TEKLIFLER!$A10),"",MAX(0,$E10)) | G10: =IF(ISBLANK(YENI_TEKLIFLER!$A10),"",YENI_TEKLIFLER!$J10) | H10: =IF(ISBLANK(YENI_TEKLIFLER!$A10),"",INDEX(KREDILER!$H$6:$H$1000,MATCH(YENI_TEKLIFLER!$B10,KREDILER!$A$6:$A$1000,0))) | I10: =IF(ISBLANK(YENI_TEKLIFLER!$A10),"",IF($E10>0,"ADAY","DEĞİL")) | J10: =IF(ISBLANK(YENI_TEKLIFLER!$A10),"",IF(OR(ISBLANK($B10),ISBLANK($C10),ISBLANK($D10),ISBLANK($E10),ISBLANK($F10),ISBLANK($G10),ISBLANK($H10)),"EKSİK","OK"))
A11: =IF(ISBLANK(YENI_TEKLIFLER!$A11),"",YENI_TEKLIFLER!$A11) | B11: =IF(ISBLANK(YENI_TEKLIFLER!$A11),"",YENI_TEKLIFLER!$B11) | C11: =IF(ISBLANK(YENI_TEKLIFLER!$A11),"",SUMIFS(TAKSIT_PLANI!$I$6:$I$1000,TAKSIT_PLANI!$B$6:$B$1000,YENI_TEKLIFLER!$B11,TAKSIT_PLANI!$C$6:$C$1000,1)) | D11: =IF(ISBLANK(YENI_TEKLIFLER!$A11),"",YENI_TEKLIFLER!$I11) | E11: =IF(ISBLANK(YENI_TEKLIFLER!$A11),"",$C11-$D11) | F11: =IF(ISBLANK(YENI_TEKLIFLER!$A11),"",MAX(0,$E11)) | G11: =IF(ISBLANK(YENI_TEKLIFLER!$A11),"",YENI_TEKLIFLER!$J11) | H11: =IF(ISBLANK(YENI_TEKLIFLER!$A11),"",INDEX(KREDILER!$H$6:$H$1000,MATCH(YENI_TEKLIFLER!$B11,KREDILER!$A$6:$A$1000,0))) | I11: =IF(ISBLANK(YENI_TEKLIFLER!$A11),"",IF($E11>0,"ADAY","DEĞİL")) | J11: =IF(ISBLANK(YENI_TEKLIFLER!$A11),"",IF(OR(ISBLANK($B11),ISBLANK($C11),ISBLANK($D11),ISBLANK($E11),ISBLANK($F11),ISBLANK($G11),ISBLANK($H11)),"EKSİK","OK"))
A12: =IF(ISBLANK(YENI_TEKLIFLER!$A12),"",YENI_TEKLIFLER!$A12) | B12: =IF(ISBLANK(YENI_TEKLIFLER!$A12),"",YENI_TEKLIFLER!$B12) | C12: =IF(ISBLANK(YENI_TEKLIFLER!$A12),"",SUMIFS(TAKSIT_PLANI!$I$6:$I$1000,TAKSIT_PLANI!$B$6:$B$1000,YENI_TEKLIFLER!$B12,TAKSIT_PLANI!$C$6:$C$1000,1)) | D12: =IF(ISBLANK(YENI_TEKLIFLER!$A12),"",YENI_TEKLIFLER!$I12) | E12: =IF(ISBLANK(YENI_TEKLIFLER!$A12),"",$C12-$D12) | F12: =IF(ISBLANK(YENI_TEKLIFLER!$A12),"",MAX(0,$E12)) | G12: =IF(ISBLANK(YENI_TEKLIFLER!$A12),"",YENI_TEKLIFLER!$J12) | H12: =IF(ISBLANK(YENI_TEKLIFLER!$A12),"",INDEX(KREDILER!$H$6:$H$1000,MATCH(YENI_TEKLIFLER!$B12,KREDILER!$A$6:$A$1000,0))) | I12: =IF(ISBLANK(YENI_TEKLIFLER!$A12),"",IF($E12>0,"ADAY","DEĞİL")) | J12: =IF(ISBLANK(YENI_TEKLIFLER!$A12),"",IF(OR(ISBLANK($B12),ISBLANK($C12),ISBLANK($D12),ISBLANK($E12),ISBLANK($F12),ISBLANK($G12),ISBLANK($H12)),"EKSİK","OK"))
A13: =IF(ISBLANK(YENI_TEKLIFLER!$A13),"",YENI_TEKLIFLER!$A13) | B13: =IF(ISBLANK(YENI_TEKLIFLER!$A13),"",YENI_TEKLIFLER!$B13) | C13: =IF(ISBLANK(YENI_TEKLIFLER!$A13),"",SUMIFS(TAKSIT_PLANI!$I$6:$I$1000,TAKSIT_PLANI!$B$6:$B$1000,YENI_TEKLIFLER!$B13,TAKSIT_PLANI!$C$6:$C$1000,1)) | D13: =IF(ISBLANK(YENI_TEKLIFLER!$A13),"",YENI_TEKLIFLER!$I13) | E13: =IF(ISBLANK(YENI_TEKLIFLER!$A13),"",$C13-$D13) | F13: =IF(ISBLANK(YENI_TEKLIFLER!$A13),"",MAX(0,$E13)) | G13: =IF(ISBLANK(YENI_TEKLIFLER!$A13),"",YENI_TEKLIFLER!$J13) | H13: =IF(ISBLANK(YENI_TEKLIFLER!$A13),"",INDEX(KREDILER!$H$6:$H$1000,MATCH(YENI_TEKLIFLER!$B13,KREDILER!$A$6:$A$1000,0))) | I13: =IF(ISBLANK(YENI_TEKLIFLER!$A13),"",IF($E13>0,"ADAY","DEĞİL")) | J13: =IF(ISBLANK(YENI_TEKLIFLER!$A13),"",IF(OR(ISBLANK($B13),ISBLANK($C13),ISBLANK($D13),ISBLANK($E13),ISBLANK($F13),ISBLANK($G13),ISBLANK($H13)),"EKSİK","OK"))
A14: =IF(ISBLANK(YENI_TEKLIFLER!$A14),"",YENI_TEKLIFLER!$A14) | B14: =IF(ISBLANK(YENI_TEKLIFLER!$A14),"",YENI_TEKLIFLER!$B14) | C14: =IF(ISBLANK(YENI_TEKLIFLER!$A14),"",SUMIFS(TAKSIT_PLANI!$I$6:$I$1000,TAKSIT_PLANI!$B$6:$B$1000,YENI_TEKLIFLER!$B14,TAKSIT_PLANI!$C$6:$C$1000,1)) | D14: =IF(ISBLANK(YENI_TEKLIFLER!$A14),"",YENI_TEKLIFLER!$I14) | E14: =IF(ISBLANK(YENI_TEKLIFLER!$A14),"",$C14-$D14) | F14: =IF(ISBLANK(YENI_TEKLIFLER!$A14),"",MAX(0,$E14)) | G14: =IF(ISBLANK(YENI_TEKLIFLER!$A14),"",YENI_TEKLIFLER!$J14) | H14: =IF(ISBLANK(YENI_TEKLIFLER!$A14),"",INDEX(KREDILER!$H$6:$H$1000,MATCH(YENI_TEKLIFLER!$B14,KREDILER!$A$6:$A$1000,0))) | I14: =IF(ISBLANK(YENI_TEKLIFLER!$A14),"",IF($E14>0,"ADAY","DEĞİL")) | J14: =IF(ISBLANK(YENI_TEKLIFLER!$A14),"",IF(OR(ISBLANK($B14),ISBLANK($C14),ISBLANK($D14),ISBLANK($E14),ISBLANK($F14),ISBLANK($G14),ISBLANK($H14)),"EKSİK","OK"))
A15: =IF(ISBLANK(YENI_TEKLIFLER!$A15),"",YENI_TEKLIFLER!$A15) | B15: =IF(ISBLANK(YENI_TEKLIFLER!$A15),"",YENI_TEKLIFLER!$B15) | C15: =IF(ISBLANK(YENI_TEKLIFLER!$A15),"",SUMIFS(TAKSIT_PLANI!$I$6:$I$1000,TAKSIT_PLANI!$B$6:$B$1000,YENI_TEKLIFLER!$B15,TAKSIT_PLANI!$C$6:$C$1000,1)) | D15: =IF(ISBLANK(YENI_TEKLIFLER!$A15),"",YENI_TEKLIFLER!$I15) | E15: =IF(ISBLANK(YENI_TEKLIFLER!$A15),"",$C15-$D15) | F15: =IF(ISBLANK(YENI_TEKLIFLER!$A15),"",MAX(0,$E15)) | G15: =IF(ISBLANK(YENI_TEKLIFLER!$A15),"",YENI_TEKLIFLER!$J15) | H15: =IF(ISBLANK(YENI_TEKLIFLER!$A15),"",INDEX(KREDILER!$H$6:$H$1000,MATCH(YENI_TEKLIFLER!$B15,KREDILER!$A$6:$A$1000,0))) | I15: =IF(ISBLANK(YENI_TEKLIFLER!$A15),"",IF($E15>0,"ADAY","DEĞİL")) | J15: =IF(ISBLANK(YENI_TEKLIFLER!$A15),"",IF(OR(ISBLANK($B15),ISBLANK($C15),ISBLANK($D15),ISBLANK($E15),ISBLANK($F15),ISBLANK($G15),ISBLANK($H15)),"EKSİK","OK"))
A16: =IF(ISBLANK(YENI_TEKLIFLER!$A16),"",YENI_TEKLIFLER!$A16) | B16: =IF(ISBLANK(YENI_TEKLIFLER!$A16),"",YENI_TEKLIFLER!$B16) | C16: =IF(ISBLANK(YENI_TEKLIFLER!$A16),"",SUMIFS(TAKSIT_PLANI!$I$6:$I$1000,TAKSIT_PLANI!$B$6:$B$1000,YENI_TEKLIFLER!$B16,TAKSIT_PLANI!$C$6:$C$1000,1)) | D16: =IF(ISBLANK(YENI_TEKLIFLER!$A16),"",YENI_TEKLIFLER!$I16) | E16: =IF(ISBLANK(YENI_TEKLIFLER!$A16),"",$C16-$D16) | F16: =IF(ISBLANK(YENI_TEKLIFLER!$A16),"",MAX(0,$E16)) | G16: =IF(ISBLANK(YENI_TEKLIFLER!$A16),"",YENI_TEKLIFLER!$J16) | H16: =IF(ISBLANK(YENI_TEKLIFLER!$A16),"",INDEX(KREDILER!$H$6:$H$1000,MATCH(YENI_TEKLIFLER!$B16,KREDILER!$A$6:$A$1000,0))) | I16: =IF(ISBLANK(YENI_TEKLIFLER!$A16),"",IF($E16>0,"ADAY","DEĞİL")) | J16: =IF(ISBLANK(YENI_TEKLIFLER!$A16),"",IF(OR(ISBLANK($B16),ISBLANK($C16),ISBLANK($D16),ISBLANK($E16),ISBLANK($F16),ISBLANK($G16),ISBLANK($H16)),"EKSİK","OK"))
