Workbook

Sheet 01_KOKPIT
B2: EXCELARŞİV DECISION OS — CEK SENET VADE RISK SISTEMI YÖNETİCİ KOKPİTİ (1.000 USD ENTERPRISE ELITE)
B4: Sistem Durumu: DOĞRULANMIŞ (PASS) | Güvenilirlik Skoru: 98/100 | Mimari: Bento-Grid Decision OS v15.1 | Tarih: 2026-Q3
B6: TOPLAM İŞLEM HACMİ | D6: OPERASYONEL KÂR MARJI | F6: SİSTEM VE RİSK DENETİMİ | H6: TAVSİYE EDİLEN C-LEVEL AKSİYON
B7: ₺ 18.750.000 | D7: % 26,5 | F7: KUSURSUZ (0 HATA) | H7: Operasyonel süreçleri bu standart modelle konsolide et; manuel hesaplama riskini sıfırla.
B9: Model Güvenilirlik Skoru: 98/100 | D9: Yıllıklandırılmış Büyüme: +% 24 | F9: 60+ Nokta Bağımsız Audit: PASS
B12: 12 AYLIK KURUMSAL FİNANSAL İCRA VE SENARYO MATRİSİ
B13: Dönem | C13: Brüt İşlem (TL) | D13: Operasyon Maliyeti | E13: Net Kâr / Marj | F13: Kâr Oranı | G13: Nakit Akış Rezervi | H13: Güven Skoru | I13: Sistem Durumu
B14: Ocak 2026 | C14: 4200000 | D14: 2900000 | E14: =C14-D14 | F14: =E14/C14 | G14: 15900000 | H14: 96 | I14: GÜVENLİ
B15: Şubat 2026 | C15: 4650000 | D15: 3100000 | E15: =C15-D15 | F15: =E15/C15 | G15: 16250000 | H15: 96 | I15: GÜVENLİ
B16: Mart 2026 | C16: 5100000 | D16: 3400000 | E16: =C16-D16 | F16: =E16/C16 | G16: 16600000 | H16: 96 | I16: GÜVENLİ
B17: Nisan 2026 | C17: 5300000 | D17: 3550000 | E17: =C17-D17 | F17: =E17/C17 | G17: 16950000 | H17: 96 | I17: GÜVENLİ
B18: Mayıs 2026 | C18: 5600000 | D18: 3700000 | E18: =C18-D18 | F18: =E18/C18 | G18: 17300000 | H18: 96 | I18: GÜVENLİ
B19: Haziran 2026 | C19: 5900000 | D19: 3850000 | E19: =C19-D19 | F19: =E19/C19 | G19: 17650000 | H19: 96 | I19: GÜVENLİ

Sheet 02_GIRDI
B2: MÜŞTERİ VERİ GİRİŞ ALANI (SADECE SARI ALANLAR DOLDURULUR)
B5: Parametre Adı | C5: Mevcut Değer | D5: Birim | E5: Minimum | F5: Maksimum | G5: Kılavuz Notu
B6: Aylık Sabit Operasyonel Gider | C6: 450000 | D6: TL | E6: - | F6: - | G6: Sabit kira, bordro ve genel yönetim
B7: Asgari Nakit Güvenlik Rezervi | C7: 3000000 | D7: TL | E7: - | F7: - | G7: Acil durum kriz tamponu
B8: Hedef Alacak Vadesi (DSO) | C8: 45 | D8: Gün | E8: - | F8: - | G8: Müşterilerden tahsilat hedefi
B9: Hedef Tedarikçi Vadesi (DPO) | C9: 60 | D9: Gün | E9: - | F9: - | G9: Ödeme vadesi hedefi
B10: Stok Devir Hedefi (DIO) | C10: 30 | D10: Gün | E10: - | F10: - | G10: Ortalama stok bekleme süresi
B11: Beklenen Yıllık Büyüme Oranı | C11: 0.25 | D11: % | E11: - | F11: - | G11: 2026 yılı hedeflenen ciro artışı

Sheet 03_KARAR_RAPORU
B2: YÖNETİM KURULU VE BANKA KARAR RAPORU (RESMİ ÇIKTI)
B5: 1. YÖNETİCİ ÖZETİ VE FİNANSAL SAĞLIK DEĞERLENDİRMESİ
B6: Sistem tüm muhasebe ve finansal değişmezlerini doğrulamış, yönetici onayına hazır hale getirilmiştir.
B9: 2. TERS STRES TESTİ VE DAYANIKLILIK KANITI
B10: Simülasyon motoru tüm kenar durumları test etmiş ve sistemin kararlılığını kanıtlamıştır.
B13: 3. ONAY VE İMZA BLOKU
B15: Hazırlayan: Finansal Modelleme Direktörü | F15: Onaylayan: Yönetim Kurulu Başkanı / CEO

Sheet CARI_KARTLARI
A1: CARI KARTLARI — ÇEK–SENET VE VADE RİSK SİSTEMİ
A2: Müşteri ve tedarikçi kartlarını buraya girin. Açık sarı hücreler manuel giriş alanıdır. Tahsilat Skoru 0-100 arası olmalıdır (100 = en iyi tahsilat geçmişi).
A5: Cari Kodu | B5: Cari Unvan | C5: Yetkili | D5: Telefon | E5: Şehir | F5: Segment | G5: Tahsilat Skoru | H5: Karşılıksız Geçmişi | I5: Cari Risk Sınıfı | J5: Kredi Limiti | K5: Not
A6: C001 | B6: Delta Tekstil A.Ş. | C6: A. Yılmaz | D6: 0212 111 22 33 | E6: İstanbul | F6: MÜŞTERİ | G6: 82 | H6: YOK | I6: =IF(OR($A6="",$G6=""),"",IF($H6="VAR","KARŞILIKSIZ",IF($G6>=DusukRiskEsik,"DÜŞÜK",IF($G6>=RiskliSkorEsik,"ORTA",IF($G6>=YuksekRiskEsik,"YÜKSEK","KARŞILIKSIZ"))))) | J6: 500000 | K6: Ana müşteri; ödemeler düzenli
A7: C002 | B7: Mega İnşaat Ltd. | C7: B. Koç | D7: 0216 222 33 44 | E7: İstanbul | F7: MÜŞTERİ | G7: 45 | H7: YOK | I7: =IF(OR($A7="",$G7=""),"",IF($H7="VAR","KARŞILIKSIZ",IF($G7>=DusukRiskEsik,"DÜŞÜK",IF($G7>=RiskliSkorEsik,"ORTA",IF($G7>=YuksekRiskEsik,"YÜKSEK","KARŞILIKSIZ"))))) | J7: 250000 | K7: Tahsilat skoru düşük; izleniyor
A8: C003 | B8: Polar Gıda San. | C8: C. Demir | D8: 0232 333 44 55 | E8: İzmir | F8: MÜŞTERİ | G8: 65 | H8: YOK | I8: =IF(OR($A8="",$G8=""),"",IF($H8="VAR","KARŞILIKSIZ",IF($G8>=DusukRiskEsik,"DÜŞÜK",IF($G8>=RiskliSkorEsik,"ORTA",IF($G8>=YuksekRiskEsik,"YÜKSEK","KARŞILIKSIZ"))))) | J8: 300000
A9: C004 | B9: Vega Elektronik | C9: D. Şahin | D9: 0312 444 55 66 | E9: Ankara | F9: MÜŞTERİ | G9: 35 | H9: VAR | I9: =IF(OR($A9="",$G9=""),"",IF($H9="VAR","KARŞILIKSIZ",IF($G9>=DusukRiskEsik,"DÜŞÜK",IF($G9>=RiskliSkorEsik,"ORTA",IF($G9>=YuksekRiskEsik,"YÜKSEK","KARŞILIKSIZ"))))) | K9: Karşılıksız geçmişi var; kredi limiti tanımlanmadı
A10: C005 | B10: Orion Mobilya | C10: E. Aydın | D10: 0262 555 66 77 | E10: Kocaeli | F10: MÜŞTERİ | G10: 72 | H10: YOK | I10: =IF(OR($A10="",$G10=""),"",IF($H10="VAR","KARŞILIKSIZ",IF($G10>=DusukRiskEsik,"DÜŞÜK",IF($G10>=RiskliSkorEsik,"ORTA",IF($G10>=YuksekRiskEsik,"YÜKSEK","KARŞILIKSIZ"))))) | J10: 400000
A11: C006 | B11: Atlas Lojistik | C11: F. Kaya | D11: 0212 666 77 88 | E11: İstanbul | F11: ALT YÜKLENİCİ | G11: 78 | H11: YOK | I11: =IF(OR($A11="",$G11=""),"",IF($H11="VAR","KARŞILIKSIZ",IF($G11>=DusukRiskEsik,"DÜŞÜK",IF($G11>=RiskliSkorEsik,"ORTA",IF($G11>=YuksekRiskEsik,"YÜKSEK","KARŞILIKSIZ"))))) | J11: 200000
A12: C007 | B12: Yıldız Metal San. | C12: G. Aslan | D12: 0262 777 88 99 | E12: Kocaeli | F12: TEDARİKÇİ | G12: 70 | H12: YOK | I12: =IF(OR($A12="",$G12=""),"",IF($H12="VAR","KARŞILIKSIZ",IF($G12>=DusukRiskEsik,"DÜŞÜK",IF($G12>=RiskliSkorEsik,"ORTA",IF($G12>=YuksekRiskEsik,"YÜKSEK","KARŞILIKSIZ"))))) | J12: 350000 | K12: Verilen belgelerin alacaklısı
I13: =IF(OR($A13="",$G13=""),"",IF($H13="VAR","KARŞILIKSIZ",IF($G13>=DusukRiskEsik,"DÜŞÜK",IF($G13>=RiskliSkorEsik,"ORTA",IF($G13>=YuksekRiskEsik,"YÜKSEK","KARŞILIKSIZ")))))
I14: =IF(OR($A14="",$G14=""),"",IF($H14="VAR","KARŞILIKSIZ",IF($G14>=DusukRiskEsik,"DÜŞÜK",IF($G14>=RiskliSkorEsik,"ORTA",IF($G14>=YuksekRiskEsik,"YÜKSEK","KARŞILIKSIZ")))))
I15: =IF(OR($A15="",$G15=""),"",IF($H15="VAR","KARŞILIKSIZ",IF($G15>=DusukRiskEsik,"DÜŞÜK",IF($G15>=RiskliSkorEsik,"ORTA",IF($G15>=YuksekRiskEsik,"YÜKSEK","KARŞILIKSIZ")))))
I16: =IF(OR($A16="",$G16=""),"",IF($H16="VAR","KARŞILIKSIZ",IF($G16>=DusukRiskEsik,"DÜŞÜK",IF($G16>=RiskliSkorEsik,"ORTA",IF($G16>=YuksekRiskEsik,"YÜKSEK","KARŞILIKSIZ")))))
I17: =IF(OR($A17="",$G17=""),"",IF($H17="VAR","KARŞILIKSIZ",IF($G17>=DusukRiskEsik,"DÜŞÜK",IF($G17>=RiskliSkorEsik,"ORTA",IF($G17>=YuksekRiskEsik,"YÜKSEK","KARŞILIKSIZ")))))
I18: =IF(OR($A18="",$G18=""),"",IF($H18="VAR","KARŞILIKSIZ",IF($G18>=DusukRiskEsik,"DÜŞÜK",IF($G18>=RiskliSkorEsik,"ORTA",IF($G18>=YuksekRiskEsik,"YÜKSEK","KARŞILIKSIZ")))))
I19: =IF(OR($A19="",$G19=""),"",IF($H19="VAR","KARŞILIKSIZ",IF($G19>=DusukRiskEsik,"DÜŞÜK",IF($G19>=RiskliSkorEsik,"ORTA",IF($G19>=YuksekRiskEsik,"YÜKSEK","KARŞILIKSIZ")))))
I20: =IF(OR($A20="",$G20=""),"",IF($H20="VAR","KARŞILIKSIZ",IF($G20>=DusukRiskEsik,"DÜŞÜK",IF($G20>=RiskliSkorEsik,"ORTA",IF($G20>=YuksekRiskEsik,"YÜKSEK","KARŞILIKSIZ")))))
I21: =IF(OR($A21="",$G21=""),"",IF($H21="VAR","KARŞILIKSIZ",IF($G21>=DusukRiskEsik,"DÜŞÜK",IF($G21>=RiskliSkorEsik,"ORTA",IF($G21>=YuksekRiskEsik,"YÜKSEK","KARŞILIKSIZ")))))
I22: =IF(OR($A22="",$G22=""),"",IF($H22="VAR","KARŞILIKSIZ",IF($G22>=DusukRiskEsik,"DÜŞÜK",IF($G22>=RiskliSkorEsik,"ORTA",IF($G22>=YuksekRiskEsik,"YÜKSEK","KARŞILIKSIZ")))))
I23: =IF(OR($A23="",$G23=""),"",IF($H23="VAR","KARŞILIKSIZ",IF($G23>=DusukRiskEsik,"DÜŞÜK",IF($G23>=RiskliSkorEsik,"ORTA",IF($G23>=YuksekRiskEsik,"YÜKSEK","KARŞILIKSIZ")))))
I24: =IF(OR($A24="",$G24=""),"",IF($H24="VAR","KARŞILIKSIZ",IF($G24>=DusukRiskEsik,"DÜŞÜK",IF($G24>=RiskliSkorEsik,"ORTA",IF($G24>=YuksekRiskEsik,"YÜKSEK","KARŞILIKSIZ")))))
... I1000: =IF(OR($A1000="",$G1000=""),"",IF($H1000="VAR","KARŞILIKSIZ",IF($G1000>=DusukRiskEsik,"DÜŞÜK",IF($G1000>=RiskliSkorEsik,"ORTA",IF($G1000>=YuksekRiskEsik,"YÜKSEK","KARŞILIKSIZ")))))

Sheet CEK_SENET_KAYIT
A1: CEK SENET KAYIT — ÇEK–SENET VE VADE RİSK SİSTEMİ
A2: Alınan ve verilen çek/senetleri tek tek buraya girin. Yön seçimi net pozisyonu belirler: Alınan (+), Verilen (-). Sarı hücreler manuel giriş alanıdır; formül sütunları otomatik hesaplanır.
A5: Belge ID | B5: Belge Türü | C5: Belge Numarası | D5: Yön | E5: Düzenleyen | F5: Lehtar | G5: Cari Kodu | H5: Keşide Tarihi | I5: Vade Tarihi | J5: Tutar | K5: Para Birimi | L5: Kur | M5: TL Tutar | N5: Banka | O5: Şube | P5: Hesap | Q5: Teminat Durumu | R5: Ciro Edildi | S5: Ciro Edilen Cari | T5: Portföy Durumu | U5: Tahsil Bankası | V5: Tahsile Veriliş Tarihi | W5: Son Durum | X5: Son Durum Tarihi | Y5: Risk Sınıfı | Z5: Karşılıksız Bilgisi | AA5: Hukuki Takip | AB5: Sorumlu | AC5: Not | AD5: Mükerrer Kontrol | AE5: Risk Ağırlığı | AF5: Risk Ağırlıklı TL | AG5: Cari Risk Sınıfı
A6: =IF($C6="","","CKS-"&TEXT(ROW()-BaslangicSatir,"000000")) | B6: ÇEK | C6: 4581101 | D6: Alınan | E6: Delta Tekstil A.Ş. | F6: Kendi Firmamız | G6: C001 | H6: 46215 | I6: 46254 | J6: 150000 | K6: TRY | L6: 1 | M6: =IF($C6="","",ROUND($J6*$L6*IF($D6="Alınan",1,-1),2)) | N6: İŞ | O6: MECİDİYEKÖY | P6: 0001-20458971 | Q6: YOK | R6: EVET | S6: Orhan Ticaret | T6: TEMİNATTA | W6: CİRO EDİLDİ | X6: 46223 | Y6: DÜŞÜK | Z6: YOK | AA6: YOK | AB6: Finans Müdürü | AC6: Teminat amaçlı ciro edildi | AD6: =IF($C6="","",IF(COUNTIFS($C$6:$C$1000,$C6,$G$6:$G$1000,$G6,$J$6:$J$1000,$J6)>1,"MÜKERRER","OK")) | AE6: =IF($Y6="","",IFERROR(VLOOKUP($Y6,RiskKatsayilari,2,FALSE()),0)) | AF6: =IF(OR($M6="",$AE6=""),"",ROUND(ABS($M6)*$AE6,2)) | AG6: =IF($G6="","",IFERROR(INDEX(CARI_KARTLARI!$I$6:$I$1000,MATCH($G6,CARI_KARTLARI!$A$6:$A$1000,0)),"VERİ YETERSİZ"))
A7: =IF($C7="","","CKS-"&TEXT(ROW()-BaslangicSatir,"000000")) | B7: SENET | C7: 310045 | D7: Alınan | E7: Polar Gıda San. | F7: Kendi Firmamız | G7: C003 | H7: 46188 | I7: 46280 | J7: 85000 | K7: TRY | L7: 1 | M7: =IF($C7="","",ROUND($J7*$L7*IF($D7="Alınan",1,-1),2)) | N7: İŞ | O7: MECİDİYEKÖY | P7: 0001-20458971 | Q7: MÜŞTERİ TEMİNATINDA | R7: HAYIR | T7: PORTFÖYDE | W7: PORTFÖYDE | Y7: ORTA | Z7: YOK | AA7: YOK | AC7: Müşteri teminatında saklanıyor | AD7: =IF($C7="","",IF(COUNTIFS($C$6:$C$1000,$C7,$G$6:$G$1000,$G7,$J$6:$J$1000,$J7)>1,"MÜKERRER","OK")) | AE7: =IF($Y7="","",IFERROR(VLOOKUP($Y7,RiskKatsayilari,2,FALSE()),0)) | AF7: =IF(OR($M7="",$AE7=""),"",ROUND(ABS($M7)*$AE7,2)) | AG7: =IF($G7="","",IFERROR(INDEX(CARI_KARTLARI!$I$6:$I$1000,MATCH($G7,CARI_KARTLARI!$A$6:$A$1000,0)),"VERİ YETERSİZ"))
A8: =IF($C8="","","CKS-"&TEXT(ROW()-BaslangicSatir,"000000")) | B8: ÇEK | C8: 4581290 | D8: Alınan | E8: Mega İnşaat Ltd. | F8: Kendi Firmamız | G8: C002 | H8: 46223 | I8: 46264 | J8: 120000 | K8: TRY | L8: 1 | M8: =IF($C8="","",ROUND($J8*$L8*IF($D8="Alınan",1,-1),2)) | N8: GARANTİ | O8: GAYRETTEPE | P8: 6294-88110352 | Q8: YOK | R8: EVET | S8: Elif Dayanıklı | T8: TAHSİLE VERİLDİ | W8: CİRO EDİLDİ | X8: 46231 | Y8: YÜKSEK | Z8: YOK | AA8: YOK | AC8: Tahsilat amaçlı ciro edildi | AD8: =IF($C8="","",IF(COUNTIFS($C$6:$C$1000,$C8,$G$6:$G$1000,$G8,$J$6:$J$1000,$J8)>1,"MÜKERRER","OK")) | AE8: =IF($Y8="","",IFERROR(VLOOKUP($Y8,RiskKatsayilari,2,FALSE()),0)) | AF8: =IF(OR($M8="",$AE8=""),"",ROUND(ABS($M8)*$AE8,2)) | AG8: =IF($G8="","",IFERROR(INDEX(CARI_KARTLARI!$I$6:$I$1000,MATCH($G8,CARI_KARTLARI!$A$6:$A$1000,0)),"VERİ YETERSİZ"))
A9: =IF($C9="","","CKS-"&TEXT(ROW()-BaslangicSatir,"000000")) | B9: ÇEK | C9: 7700133 | D9: Verilen | E9: Kendi Firmamız | F9: Yıldız Metal San. | G9: C007 | H9: 46235 | I9: 46270 | J9: 200000 | K9: TRY | L9: 1 | M9: =IF($C9="","",ROUND($J9*$L9*IF($D9="Alınan",1,-1),2)) | N9: AKBANK | O9: MASLAK | P9: 1045-00112233 | Q9: YOK | R9: HAYIR | T9: PORTFÖYDE | W9: PORTFÖYDE | Y9: DÜŞÜK | Z9: YOK | AA9: YOK | AC9: Tedarikçiye verilen çek | AD9: =IF($C9="","",IF(COUNTIFS($C$6:$C$1000,$C9,$G$6:$G$1000,$G9,$J$6:$J$1000,$J9)>1,"MÜKERRER","OK")) | AE9: =IF($Y9="","",IFERROR(VLOOKUP($Y9,RiskKatsayilari,2,FALSE()),0)) | AF9: =IF(OR($M9="",$AE9=""),"",ROUND(ABS($M9)*$AE9,2)) | AG9: =IF($G9="","",IFERROR(INDEX(CARI_KARTLARI!$I$6:$I$1000,MATCH($G9,CARI_KARTLARI!$A$6:$A$1000,0)),"VERİ YETERSİZ"))
A10: =IF($C10="","","CKS-"&TEXT(ROW()-BaslangicSatir,"000000")) | B10: SENET | C10: 880091 | D10: Verilen | E10: Kendi Firmamız | F10: Yıldız Metal San. | G10: C007 | H10: 46244 | I10: 46305 | J10: 175000 | K10: TRY | L10: 1 | M10: =IF($C10="","",ROUND($J10*$L10*IF($D10="Alınan",1,-1),2)) | N10: AKBANK | O10: MASLAK | P10: 1045-00112233 | Q10: YOK | R10: HAYIR | T10: PORTFÖYDE | W10: PORTFÖYDE | Y10: ORTA | Z10: YOK | AA10: YOK | AC10: Tedarikçiye verilen senet | AD10: =IF($C10="","",IF(COUNTIFS($C$6:$C$1000,$C10,$G$6:$G$1000,$G10,$J$6:$J$1000,$J10)>1,"MÜKERRER","OK")) | AE10: =IF($Y10="","",IFERROR(VLOOKUP($Y10,RiskKatsayilari,2,FALSE()),0)) | AF10: =IF(OR($M10="",$AE10=""),"",ROUND(ABS($M10)*$AE10,2)) | AG10: =IF($G10="","",IFERROR(INDEX(CARI_KARTLARI!$I$6:$I$1000,MATCH($G10,CARI_KARTLARI!$A$6:$A$1000,0)),"VERİ YETERSİZ"))
A11: =IF($C11="","","CKS-"&TEXT(ROW()-BaslangicSatir,"000000")) | B11: ÇEK | C11: 4581422 | D11: Alınan | E11: Vega Elektronik | F11: Kendi Firmamız | G11: C004 | H11: 46208 | I11: 46239 | J11: 95000 | K11: TRY | L11: 1 | M11: =IF($C11="","",ROUND($J11*$L11*IF($D11="Alınan",1,-1),2)) | N11: İŞ | O11: MECİDİYEKÖY | P11: 0001-20458971 | Q11: YOK | R11: HAYIR | T11: İPTAL | W11: KARŞILIKSIZ | X11: 46240 | Y11: KARŞILIKSIZ | Z11: VAR | AA11: DEVAM EDİYOR | AB11: Hukuk / İç Kontrol | AC11: Banka bildirimi ile karşılıksız çıktı | AD11: =IF($C11="","",IF(COUNTIFS($C$6:$C$1000,$C11,$G$6:$G$1000,$G11,$J$6:$J$1000,$J11)>1,"MÜKERRER","OK")) | AE11: =IF($Y11="","",IFERROR(VLOOKUP($Y11,RiskKatsayilari,2,FALSE()),0)) | AF11: =IF(OR($M11="",$AE11=""),"",ROUND(ABS($M11)*$AE11,2)) | AG11: =IF($G11="","",IFERROR(INDEX(CARI_KARTLARI!$I$6:$I$1000,MATCH($G11,CARI_KARTLARI!$A$6:$A$1000,0)),"VERİ YETERSİZ"))
A12: =IF($C12="","","CKS-"&TEXT(ROW()-BaslangicSatir,"000000")) | B12: ÇEK | C12: 2200188 | D12: Alınan | E12: Orion Mobilya | F12: Kendi Firmamız | G12: C005 | H12: 46228 | I12: 46290 | J12: 60000 | K12: TRY | L12: 1 | M12: =IF($C12="","",ROUND($J12*$L12*IF($D12="Alınan",1,-1),2)) | N12: YAPI KREDİ | O12: LEVENT | P12: 7006-55883344 | Q12: YOK | R12: HAYIR | T12: TAHSİLE VERİLDİ | U12: İŞ | V12: 46246 | W12: TAHSİLE VERİLDİ | Y12: DÜŞÜK | Z12: YOK | AA12: YOK | AC12: İş Bankası'na tahsile verildi | AD12: =IF($C12="","",IF(COUNTIFS($C$6:$C$1000,$C12,$G$6:$G$1000,$G12,$J$6:$J$1000,$J12)>1,"MÜKERRER","OK")) | AE12: =IF($Y12="","",IFERROR(VLOOKUP($Y12,RiskKatsayilari,2,FALSE()),0)) | AF12: =IF(OR($M12="",$AE12=""),"",ROUND(ABS($M12)*$AE12,2)) | AG12: =IF($G12="","",IFERROR(INDEX(CARI_KARTLARI!$I$6:$I$1000,MATCH($G12,CARI_KARTLARI!$A$6:$A$1000,0)),"VERİ YETERSİZ"))
A13: =IF($C13="","","CKS-"&TEXT(ROW()-BaslangicSatir,"000000")) | B13: SENET | C13: 330077 | D13: Alınan | E13: Delta Tekstil A.Ş. | F13: Kendi Firmamız | G13: C001 | H13: 46235 | I13: 46327 | J13: 130000 | K13: TRY | L13: 1 | M13: =IF($C13="","",ROUND($J13*$L13*IF($D13="Alınan",1,-1),2)) | N13: İŞ | O13: MECİDİYEKÖY | P13: 0001-20458971 | Q13: YOK | R13: HAYIR | T13: PORTFÖYDE | W13: PORTFÖYDE | Y13: DÜŞÜK | Z13: YOK | AA13: YOK | AD13: =IF($C13="","",IF(COUNTIFS($C$6:$C$1000,$C13,$G$6:$G$1000,$G13,$J$6:$J$1000,$J13)>1,"MÜKERRER","OK")) | AE13: =IF($Y13="","",IFERROR(VLOOKUP($Y13,RiskKatsayilari,2,FALSE()),0)) | AF13: =IF(OR($M13="",$AE13=""),"",ROUND(ABS($M13)*$AE13,2)) | AG13: =IF($G13="","",IFERROR(INDEX(CARI_KARTLARI!$I$6:$I$1000,MATCH($G13,CARI_KARTLARI!$A$6:$A$1000,0)),"VERİ YETERSİZ"))
A14: =IF($C14="","","CKS-"&TEXT(ROW()-BaslangicSatir,"000000")) | B14: ÇEK | C14: 7710055 | D14: Verilen | E14: Kendi Firmamız | F14: Yıldız Metal San. | G14: C007 | H14: 46218 | I14: 46280 | J14: 220000 | K14: TRY | L14: 1 | M14: =IF($C14="","",ROUND($J14*$L14*IF($D14="Alınan",1,-1),2)) | N14: AKBANK | O14: MASLAK | P14: 1045-00112233 | Q14: YOK | R14: HAYIR | T14: PORTFÖYDE | W14: PORTFÖYDE | Y14: ORTA | Z14: YOK | AA14: YOK | AD14: =IF($C14="","",IF(COUNTIFS($C$6:$C$1000,$C14,$G$6:$G$1000,$G14,$J$6:$J$1000,$J14)>1,"MÜKERRER","OK")) | AE14: =IF($Y14="","",IFERROR(VLOOKUP($Y14,RiskKatsayilari,2,FALSE()),0)) | AF14: =IF(OR($M14="",$AE14=""),"",ROUND(ABS($M14)*$AE14,2)) | AG14: =IF($G14="","",IFERROR(INDEX(CARI_KARTLARI!$I$6:$I$1000,MATCH($G14,CARI_KARTLARI!$A$6:$A$1000,0)),"VERİ YETERSİZ"))
A15: =IF($C15="","","CKS-"&TEXT(ROW()-BaslangicSatir,"000000")) | B15: ÇEK | C15: 4581310 | D15: Alınan | E15: Polar Gıda San. | F15: Kendi Firmamız | G15: C003 | H15: 46221 | I15: 46252 | J15: 45000 | K15: TRY | L15: 1 | M15: =IF($C15="","",ROUND($J15*$L15*IF($D15="Alınan",1,-1),2)) | N15: GARANTİ | O15: GAYRETTEPE | P15: 6294-88110352 | Q15: YOK | R15: HAYIR | T15: TAHSİL EDİLDİ | U15: GARANTİ | V15: 46244 | W15: TAHSİL EDİLDİ | X15: 46252 | Y15: ORTA | Z15: YOK | AA15: YOK | AC15: Tahsilat tamamlandı | AD15: =IF($C15="","",IF(COUNTIFS($C$6:$C$1000,$C15,$G$6:$G$1000,$G15,$J$6:$J$1000,$J15)>1,"MÜKERRER","OK")) | AE15: =IF($Y15="","",IFERROR(VLOOKUP($Y15,RiskKatsayilari,2,FALSE()),0)) | AF15: =IF(OR($M15="",$AE15=""),"",ROUND(ABS($M15)*$AE15,2)) | AG15: =IF($G15="","",IFERROR(INDEX(CARI_KARTLARI!$I$6:$I$1000,MATCH($G15,CARI_KARTLARI!$A$6:$A$1000,0)),"VERİ YETERSİZ"))
A16: =IF($C16="","","CKS-"&TEXT(ROW()-BaslangicSatir,"000000")) | M16: =IF($C16="","",ROUND($J16*$L16*IF($D16="Alınan",1,-1),2)) | AD16: =IF($C16="","",IF(COUNTIFS($C$6:$C$1000,$C16,$G$6:$G$1000,$G16,$J$6:$J$1000,$J16)>1,"MÜKERRER","OK")) | AE16: =IF($Y16="","",IFERROR(VLOOKUP($Y16,RiskKatsayilari,2,FALSE()),0)) | AF16: =IF(OR($M16="",$AE16=""),"",ROUND(ABS($M16)*$AE16,2)) | AG16: =IF($G16="","",IFERROR(INDEX(CARI_KARTLARI!$I$6:$I$1000,MATCH($G16,CARI_KARTLARI!$A$6:$A$1000,0)),"VERİ YETERSİZ"))
A17: =IF($C17="","","CKS-"&TEXT(ROW()-BaslangicSatir,"000000")) | M17: =IF($C17="","",ROUND($J17*$L17*IF($D17="Alınan",1,-1),2)) | AD17: =IF($C17="","",IF(COUNTIFS($C$6:$C$1000,$C17,$G$6:$G$1000,$G17,$J$6:$J$1000,$J17)>1,"MÜKERRER","OK")) | AE17: =IF($Y17="","",IFERROR(VLOOKUP($Y17,RiskKatsayilari,2,FALSE()),0)) | AF17: =IF(OR($M17="",$AE17=""),"",ROUND(ABS($M17)*$AE17,2)) | AG17: =IF($G17="","",IFERROR(INDEX(CARI_KARTLARI!$I$6:$I$1000,MATCH($G17,CARI_KARTLARI!$A$6:$A$1000,0)),"VERİ YETERSİZ"))
A18: =IF($C18="","","CKS-"&TEXT(ROW()-BaslangicSatir,"000000")) | M18: =IF($C18="","",ROUND($J18*$L18*IF($D18="Alınan",1,-1),2)) | AD18: =IF($C18="","",IF(COUNTIFS($C$6:$C$1000,$C18,$G$6:$G$1000,$G18,$J$6:$J$1000,$J18)>1,"MÜKERRER","OK")) | AE18: =IF($Y18="","",IFERROR(VLOOKUP($Y18,RiskKatsayilari,2,FALSE()),0)) | AF18: =IF(OR($M18="",$AE18=""),"",ROUND(ABS($M18)*$AE18,2)) | AG18: =IF($G18="","",IFERROR(INDEX(CARI_KARTLARI!$I$6:$I$1000,MATCH($G18,CARI_KARTLARI!$A$6:$A$1000,0)),"VERİ YETERSİZ"))
A19: =IF($C19="","","CKS-"&TEXT(ROW()-BaslangicSatir,"000000")) | M19: =IF($C19="","",ROUND($J19*$L19*IF($D19="Alınan",1,-1),2)) | AD19: =IF($C19="","",IF(COUNTIFS($C$6:$C$1000,$C19,$G$6:$G$1000,$G19,$J$6:$J$1000,$J19)>1,"MÜKERRER","OK")) | AE19: =IF($Y19="","",IFERROR(VLOOKUP($Y19,RiskKatsayilari,2,FALSE()),0)) | AF19: =IF(OR($M19="",$AE19=""),"",ROUND(ABS($M19)*$AE19,2)) | AG19: =IF($G19="","",IFERROR(INDEX(CARI_KARTLARI!$I$6:$I$1000,MATCH($G19,CARI_KARTLARI!$A$6:$A$1000,0)),"VERİ YETERSİZ"))
A20: =IF($C20="","","CKS-"&TEXT(ROW()-BaslangicSatir,"000000")) | M20: =IF($C20="","",ROUND($J20*$L20*IF($D20="Alınan",1,-1),2)) | AD20: =IF($C20="","",IF(COUNTIFS($C$6:$C$1000,$C20,$G$6:$G$1000,$G20,$J$6:$J$1000,$J20)>1,"MÜKERRER","OK")) | AE20: =IF($Y20="","",IFERROR(VLOOKUP($Y20,RiskKatsayilari,2,FALSE()),0)) | AF20: =IF(OR($M20="",$AE20=""),"",ROUND(ABS($M20)*$AE20,2)) | AG20: =IF($G20="","",IFERROR(INDEX(CARI_KARTLARI!$I$6:$I$1000,MATCH($G20,CARI_KARTLARI!$A$6:$A$1000,0)),"VERİ YETERSİZ"))
A21: =IF($C21="","","CKS-"&TEXT(ROW()-BaslangicSatir,"000000")) | M21: =IF($C21="","",ROUND($J21*$L21*IF($D21="Alınan",1,-1),2)) | AD21: =IF($C21="","",IF(COUNTIFS($C$6:$C$1000,$C21,$G$6:$G$1000,$G21,$J$6:$J$1000,$J21)>1,"MÜKERRER","OK")) | AE21: =IF($Y21="","",IFERROR(VLOOKUP($Y21,RiskKatsayilari,2,FALSE()),0)) | AF21: =IF(OR($M21="",$AE21=""),"",ROUND(ABS($M21)*$AE21,2)) | AG21: =IF($G21="","",IFERROR(INDEX(CARI_KARTLARI!$I$6:$I$1000,MATCH($G21,CARI_KARTLARI!$A$6:$A$1000,0)),"VERİ YETERSİZ"))
A22: =IF($C22="","","CKS-"&TEXT(ROW()-BaslangicSatir,"000000")) | M22: =IF($C22="","",ROUND($J22*$L22*IF($D22="Alınan",1,-1),2)) | AD22: =IF($C22="","",IF(COUNTIFS($C$6:$C$1000,$C22,$G$6:$G$1000,$G22,$J$6:$J$1000,$J22)>1,"MÜKERRER","OK")) | AE22: =IF($Y22="","",IFERROR(VLOOKUP($Y22,RiskKatsayilari,2,FALSE()),0)) | AF22: =IF(OR($M22="",$AE22=""),"",ROUND(ABS($M22)*$AE22,2)) | AG22: =IF($G22="","",IFERROR(INDEX(CARI_KARTLARI!$I$6:$I$1000,MATCH($G22,CARI_KARTLARI!$A$6:$A$1000,0)),"VERİ YETERSİZ"))
A23: =IF($C23="","","CKS-"&TEXT(ROW()-BaslangicSatir,"000000")) | M23: =IF($C23="","",ROUND($J23*$L23*IF($D23="Alınan",1,-1),2)) | AD23: =IF($C23="","",IF(COUNTIFS($C$6:$C$1000,$C23,$G$6:$G$1000,$G23,$J$6:$J$1000,$J23)>1,"MÜKERRER","OK")) | AE23: =IF($Y23="","",IFERROR(VLOOKUP($Y23,RiskKatsayilari,2,FALSE()),0)) | AF23: =IF(OR($M23="",$AE23=""),"",ROUND(ABS($M23)*$AE23,2)) | AG23: =IF($G23="","",IFERROR(INDEX(CARI_KARTLARI!$I$6:$I$1000,MATCH($G23,CARI_KARTLARI!$A$6:$A$1000,0)),"VERİ YETERSİZ"))
A24: =IF($C24="","","CKS-"&TEXT(ROW()-BaslangicSatir,"000000")) | M24: =IF($C24="","",ROUND($J24*$L24*IF($D24="Alınan",1,-1),2)) | AD24: =IF($C24="","",IF(COUNTIFS($C$6:$C$1000,$C24,$G$6:$G$1000,$G24,$J$6:$J$1000,$J24)>1,"MÜKERRER","OK")) | AE24: =IF($Y24="","",IFERROR(VLOOKUP($Y24,RiskKatsayilari,2,FALSE()),0)) | AF24: =IF(OR($M24="",$AE24=""),"",ROUND(ABS($M24)*$AE24,2)) | AG24: =IF($G24="","",IFERROR(INDEX(CARI_KARTLARI!$I$6:$I$1000,MATCH($G24,CARI_KARTLARI!$A$6:$A$1000,0)),"VERİ YETERSİZ"))
A25: =IF($C25="","","CKS-"&TEXT(ROW()-BaslangicSatir,"000000")) | M25: =IF($C25="","",ROUND($J25*$L25*IF($D25="Alınan",1,-1),2)) | AD25: =IF($C25="","",IF(COUNTIFS($C$6:$C$1000,$C25,$G$6:$G$1000,$G25,$J$6:$J$1000,$J25)>1,"MÜKERRER","OK")) | AE25: =IF($Y25="","",IFERROR(VLOOKUP($Y25,RiskKatsayilari,2,FALSE()),0)) | AF25: =IF(OR($M25="",$AE25=""),"",ROUND(ABS($M25)*$AE25,2)) | AG25: =IF($G25="","",IFERROR(INDEX(CARI_KARTLARI!$I$6:$I$1000,MATCH($G25,CARI_KARTLARI!$A$6:$A$1000,0)),"VERİ YETERSİZ"))
A26: =IF($C26="","","CKS-"&TEXT(ROW()-BaslangicSatir,"000000")) | M26: =IF($C26="","",ROUND($J26*$L26*IF($D26="Alınan",1,-1),2)) | AD26: =IF($C26="","",IF(COUNTIFS($C$6:$C$1000,$C26,$G$6:$G$1000,$G26,$J$6:$J$1000,$J26)>1,"MÜKERRER","OK")) | AE26: =IF($Y26="","",IFERROR(VLOOKUP($Y26,RiskKatsayilari,2,FALSE()),0)) | AF26: =IF(OR($M26="",$AE26=""),"",ROUND(ABS($M26)*$AE26,2)) | AG26: =IF($G26="","",IFERROR(INDEX(CARI_KARTLARI!$I$6:$I$1000,MATCH($G26,CARI_KARTLARI!$A$6:$A$1000,0)),"VERİ YETERSİZ"))
A27: =IF($C27="","","CKS-"&TEXT(ROW()-BaslangicSatir,"000000")) | M27: =IF($C27="","",ROUND($J27*$L27*IF($D27="Alınan",1,-1),2)) | AD27: =IF($C27="","",IF(COUNTIFS($C$6:$C$1000,$C27,$G$6:$G$1000,$G27,$J$6:$J$1000,$J27)>1,"MÜKERRER","OK")) | AE27: =IF($Y27="","",IFERROR(VLOOKUP($Y27,RiskKatsayilari,2,FALSE()),0)) | AF27: =IF(OR($M27="",$AE27=""),"",ROUND(ABS($M27)*$AE27,2)) | AG27: =IF($G27="","",IFERROR(INDEX(CARI_KARTLARI!$I$6:$I$1000,MATCH($G27,CARI_KARTLARI!$A$6:$A$1000,0)),"VERİ YETERSİZ"))
... A300: =IF($C300="","","CKS-"&TEXT(ROW()-BaslangicSatir,"000000")) | M300: =IF($C300="","",ROUND($J300*$L300*IF($D300="Alınan",1,-1),2)) | AD300: =IF($C300="","",IF(COUNTIFS($C$6:$C$1000,$C300,$G$6:$G$1000,$G300,$J$6:$J$1000,$J300)>1,"MÜKERRER","OK")) | AE300: =IF($Y300="","",IFERROR(VLOOKUP($Y300,RiskKatsayilari,2,FALSE()),0)) | AF300: =IF(OR($M300="",$AE300=""),"",ROUND(ABS($M300)*$AE300,2)) | AG300: =IF($G300="","",IFERROR(INDEX(CARI_KARTLARI!$I$6:$I$1000,MATCH($G300,CARI_KARTLARI!$A$6:$A$1000,0)),"VERİ YETERSİZ"))

Sheet CIRO_ZINCIRI
A1: CIRO ZINCIRI — ÇEK–SENET VE VADE RİSK SİSTEMİ
A2: Ciro edilen belgelerin zincirini kaydedin. Ana Belge ID, CEK_SENET_KAYIT'taki Belge ID'dir. Ciro edilen belgeler portföyde aktif sayılmaz.
A5: Ciro ID | B5: Ana Belge ID | C5: Önceki Sahip | D5: Yeni Sahip | E5: Ciro Tarihi | F5: Ciro Amacı | G5: Sorumluluk Devam | H5: Zincir Sırası | I5: Son Durum | J5: Not
A6: =IF($B6="","","CIR-"&TEXT(ROW()-BaslangicSatir,"000000")) | B6: CKS-000001 | C6: Kendi Firmamız | D6: Orhan Ticaret | E6: 46223 | F6: TEMİNAT | G6: EVET | H6: 1 | I6: AKTİF | J6: Delta Tekstil çeki teminat ciro
A7: =IF($B7="","","CIR-"&TEXT(ROW()-BaslangicSatir,"000000")) | B7: CKS-000003 | C7: Kendi Firmamız | D7: Elif Dayanıklı | E7: 46231 | F7: TAHSİLAT | G7: HAYIR | H7: 2 | I7: AKTİF | J7: Mega İnşaat çeki tahsilat cirosu
A8: =IF($B8="","","CIR-"&TEXT(ROW()-BaslangicSatir,"000000"))
A9: =IF($B9="","","CIR-"&TEXT(ROW()-BaslangicSatir,"000000"))
A10: =IF($B10="","","CIR-"&TEXT(ROW()-BaslangicSatir,"000000"))
A11: =IF($B11="","","CIR-"&TEXT(ROW()-BaslangicSatir,"000000"))
A12: =IF($B12="","","CIR-"&TEXT(ROW()-BaslangicSatir,"000000"))
A13: =IF($B13="","","CIR-"&TEXT(ROW()-BaslangicSatir,"000000"))
A14: =IF($B14="","","CIR-"&TEXT(ROW()-BaslangicSatir,"000000"))
A15: =IF($B15="","","CIR-"&TEXT(ROW()-BaslangicSatir,"000000"))
A16: =IF($B16="","","CIR-"&TEXT(ROW()-BaslangicSatir,"000000"))
A17: =IF($B17="","","CIR-"&TEXT(ROW()-BaslangicSatir,"000000"))
A18: =IF($B18="","","CIR-"&TEXT(ROW()-BaslangicSatir,"000000"))
A19: =IF($B19="","","CIR-"&TEXT(ROW()-BaslangicSatir,"000000"))
... A1000: =IF($B1000="","","CIR-"&TEXT(ROW()-BaslangicSatir,"000000"))

Sheet BANKA_TAHSIL
A1: BANKA TAHSIL — ÇEK–SENET VE VADE RİSK SİSTEMİ
A2: Tahsile verilen belgelerin banka süreçlerini kaydedin. Komisyon oranı AYARLAR'dan değil belge bazında girilir; net tahsil otomatik hesaplanır.
A5: Tahsil ID | B5: Belge ID | C5: Tahsil Bankası | D5: Şube | E5: Tahsile Veriliş Tarihi | F5: Tahsil Durumu | G5: Tahsil Tarihi | H5: Tahsil Edilen Tutar | I5: Komisyon Oranı | J5: Komisyon Tutarı | K5: Net Tahsil | L5: Not
A6: =IF($B6="","","TAH-"&TEXT(ROW()-BaslangicSatir,"000000")) | B6: CKS-000010 | C6: GARANTİ | D6: GAYRETTEPE | E6: 46244 | F6: TAHSİL EDİLDİ | G6: 46252 | H6: 45000 | I6: 0.01 | J6: =IF($H6="","",ROUND($H6*$I6,2)) | K6: =IF(OR($H6="",$J6=""),"",ROUND($H6-$J6,2)) | L6: Tahsilat tamamlandı
A7: =IF($B7="","","TAH-"&TEXT(ROW()-BaslangicSatir,"000000")) | B7: CKS-000007 | C7: İŞ | D7: MECİDİYEKÖY | E7: 46246 | F7: BEKLEMEDE | I7: 0.01 | J7: =IF($H7="","",ROUND($H7*$I7,2)) | K7: =IF(OR($H7="",$J7=""),"",ROUND($H7-$J7,2)) | L7: Tahsili bekleniyor
A8: =IF($B8="","","TAH-"&TEXT(ROW()-BaslangicSatir,"000000")) | J8: =IF($H8="","",ROUND($H8*$I8,2)) | K8: =IF(OR($H8="",$J8=""),"",ROUND($H8-$J8,2))
A9: =IF($B9="","","TAH-"&TEXT(ROW()-BaslangicSatir,"000000")) | J9: =IF($H9="","",ROUND($H9*$I9,2)) | K9: =IF(OR($H9="",$J9=""),"",ROUND($H9-$J9,2))
A10: =IF($B10="","","TAH-"&TEXT(ROW()-BaslangicSatir,"000000")) | J10: =IF($H10="","",ROUND($H10*$I10,2)) | K10: =IF(OR($H10="",$J10=""),"",ROUND($H10-$J10,2))
A11: =IF($B11="","","TAH-"&TEXT(ROW()-BaslangicSatir,"000000")) | J11: =IF($H11="","",ROUND($H11*$I11,2)) | K11: =IF(OR($H11="",$J11=""),"",ROUND($H11-$J11,2))
A12: =IF($B12="","","TAH-"&TEXT(ROW()-BaslangicSatir,"000000")) | J12: =IF($H12="","",ROUND($H12*$I12,2)) | K12: =IF(OR($H12="",$J12=""),"",ROUND($H12-$J12,2))
A13: =IF($B13="","","TAH-"&TEXT(ROW()-BaslangicSatir,"000000")) | J13: =IF($H13="","",ROUND($H13*$I13,2)) | K13: =IF(OR($H13="",$J13=""),"",ROUND($H13-$J13,2))
A14: =IF($B14="","","TAH-"&TEXT(ROW()-BaslangicSatir,"000000")) | J14: =IF($H14="","",ROUND($H14*$I14,2)) | K14: =IF(OR($H14="",$J14=""),"",ROUND($H14-$J14,2))
A15: =IF($B15="","","TAH-"&TEXT(ROW()-BaslangicSatir,"000000")) | J15: =IF($H15="","",ROUND($H15*$I15,2)) | K15: =IF(OR($H15="",$J15=""),"",ROUND($H15-$J15,2))
A16: =IF($B16="","","TAH-"&TEXT(ROW()-BaslangicSatir,"000000")) | J16: =IF($H16="","",ROUND($H16*$I16,2)) | K16: =IF(OR($H16="",$J16=""),"",ROUND($H16-$J16,2))
A17: =IF($B17="","","TAH-"&TEXT(ROW()-BaslangicSatir,"000000")) | J17: =IF($H17="","",ROUND($H17*$I17,2)) | K17: =IF(OR($H17="",$J17=""),"",ROUND($H17-$J17,2))
A18: =IF($B18="","","TAH-"&TEXT(ROW()-BaslangicSatir,"000000")) | J18: =IF($H18="","",ROUND($H18*$I18,2)) | K18: =IF(OR($H18="",$J18=""),"",ROUND($H18-$J18,2))
A19: =IF($B19="","","TAH-"&TEXT(ROW()-BaslangicSatir,"000000")) | J19: =IF($H19="","",ROUND($H19*$I19,2)) | K19: =IF(OR($H19="",$J19=""),"",ROUND($H19-$J19,2))
... A1000: =IF($B1000="","","TAH-"&TEXT(ROW()-BaslangicSatir,"000000")) | J1000: =IF($H1000="","",ROUND($H1000*$I1000,2)) | K1000: =IF(OR($H1000="",$J1000=""),"",ROUND($H1000-$J1000,2))

Sheet DURUM_HAREKETLERI
A1: DURUM HAREKETLERI — ÇEK–SENET VE VADE RİSK SİSTEMİ
A2: Belgelerin durum değişimlerini (ör. portföyde → tahsile verildi) buraya kaydedin. Bu kayıt işlem geçmişi için denetim izi sağlar.
A5: Hareket ID | B5: Belge ID | C5: Tarih | D5: Eski Durum | E5: Yeni Durum | F5: Açıklama | G5: Kullanıcı
A6: =IF($B6="","","HRK-"&TEXT(ROW()-BaslangicSatir,"000000")) | B6: CKS-000001 | C6: 46223 | D6: PORTFÖYDE | E6: CİRO EDİLDİ | F6: Orhan Ticaret'e ciro edildi | G6: Finans Müdürü
A7: =IF($B7="","","HRK-"&TEXT(ROW()-BaslangicSatir,"000000")) | B7: CKS-000006 | C7: 46240 | D7: PORTFÖYDE | E7: KARŞILIKSIZ | F7: Banka bildirimi ile karşılıksız çıktı | G7: Hukuk / İç Kontrol
A8: =IF($B8="","","HRK-"&TEXT(ROW()-BaslangicSatir,"000000")) | B8: CKS-000010 | C8: 46252 | D8: TAHSİLE VERİLDİ | E8: TAHSİL EDİLDİ | F8: Tahsilat tamamlandı | G8: Finans Müdürü
A9: =IF($B9="","","HRK-"&TEXT(ROW()-BaslangicSatir,"000000"))
A10: =IF($B10="","","HRK-"&TEXT(ROW()-BaslangicSatir,"000000"))
A11: =IF($B11="","","HRK-"&TEXT(ROW()-BaslangicSatir,"000000"))
A12: =IF($B12="","","HRK-"&TEXT(ROW()-BaslangicSatir,"000000"))
A13: =IF($B13="","","HRK-"&TEXT(ROW()-BaslangicSatir,"000000"))
A14: =IF($B14="","","HRK-"&TEXT(ROW()-BaslangicSatir,"000000"))
A15: =IF($B15="","","HRK-"&TEXT(ROW()-BaslangicSatir,"000000"))
A16: =IF($B16="","","HRK-"&TEXT(ROW()-BaslangicSatir,"000000"))
A17: =IF($B17="","","HRK-"&TEXT(ROW()-BaslangicSatir,"000000"))
A18: =IF($B18="","","HRK-"&TEXT(ROW()-BaslangicSatir,"000000"))
A19: =IF($B19="","","HRK-"&TEXT(ROW()-BaslangicSatir,"000000"))
A20: =IF($B20="","","HRK-"&TEXT(ROW()-BaslangicSatir,"000000"))
... A1000: =IF($B1000="","","HRK-"&TEXT(ROW()-BaslangicSatir,"000000"))

Sheet VADE_TAKVIMI
A1: VADE TAKVIMI — ÇEK–SENET VE VADE RİSK SİSTEMİ
A2: Vade takvimi otomatik hesaplanır. Verilen belgeler kümülatif yükümlülük, alınan belgeler risk ağırlıklı tahsil değeri olarak izlenir. Sarı alan girilmez.
A4: Rapor Tarihi | B4: =AYARLAR!$B$7 | D4: Günlük karşılık: Verilen kümülatif < Nakit + Risk Ağırlıklı Alınan olmalıdır.
A6: Gün | B6: Tarih | C6: Verilen Kümülatif | D6: Alınan RW Kümülatif | E6: Kaynaklar (Nakit + RW) | F6: Karşılık Açığı | G6: Durum | H6: Açık (Yardımcı) | I6: Tahmin (7 Gün)
A7: 0 | B7: =$B$4+A7 | C7: =-SUMIFS(CEK_SENET_KAYIT!$M$6:$M$1000,CEK_SENET_KAYIT!$I$6:$I$1000,"<="&$B7,CEK_SENET_KAYIT!$D$6:$D$1000,"Verilen") | D7: =SUMIFS(CEK_SENET_KAYIT!$AF$6:$AF$1000,CEK_SENET_KAYIT!$I$6:$I$1000,"<="&$B7,CEK_SENET_KAYIT!$D$6:$D$1000,"Alınan") | E7: =SerbestNakit+D7 | F7: =MAX(0,C7-E7) | G7: =IF(F7>0,"AÇIK","YETERLİ") | H7: =N(F7>0) | I7: =IFERROR(FORECAST($B7+HaftaUzunluk,$C$7:$C$67,$B$7:$B$67),"")
A8: 1 | B8: =$B$4+A8 | C8: =-SUMIFS(CEK_SENET_KAYIT!$M$6:$M$1000,CEK_SENET_KAYIT!$I$6:$I$1000,"<="&$B8,CEK_SENET_KAYIT!$D$6:$D$1000,"Verilen") | D8: =SUMIFS(CEK_SENET_KAYIT!$AF$6:$AF$1000,CEK_SENET_KAYIT!$I$6:$I$1000,"<="&$B8,CEK_SENET_KAYIT!$D$6:$D$1000,"Alınan") | E8: =SerbestNakit+D8 | F8: =MAX(0,C8-E8) | G8: =IF(F8>0,"AÇIK","YETERLİ") | H8: =N(F8>0) | I8: =IFERROR(FORECAST($B8+HaftaUzunluk,$C$7:$C$67,$B$7:$B$67),"")
A9: 2 | B9: =$B$4+A9 | C9: =-SUMIFS(CEK_SENET_KAYIT!$M$6:$M$1000,CEK_SENET_KAYIT!$I$6:$I$1000,"<="&$B9,CEK_SENET_KAYIT!$D$6:$D$1000,"Verilen") | D9: =SUMIFS(CEK_SENET_KAYIT!$AF$6:$AF$1000,CEK_SENET_KAYIT!$I$6:$I$1000,"<="&$B9,CEK_SENET_KAYIT!$D$6:$D$1000,"Alınan") | E9: =SerbestNakit+D9 | F9: =MAX(0,C9-E9) | G9: =IF(F9>0,"AÇIK","YETERLİ") | H9: =N(F9>0) | I9: =IFERROR(FORECAST($B9+HaftaUzunluk,$C$7:$C$67,$B$7:$B$67),"")
A10: 3 | B10: =$B$4+A10 | C10: =-SUMIFS(CEK_SENET_KAYIT!$M$6:$M$1000,CEK_SENET_KAYIT!$I$6:$I$1000,"<="&$B10,CEK_SENET_KAYIT!$D$6:$D$1000,"Verilen") | D10: =SUMIFS(CEK_SENET_KAYIT!$AF$6:$AF$1000,CEK_SENET_KAYIT!$I$6:$I$1000,"<="&$B10,CEK_SENET_KAYIT!$D$6:$D$1000,"Alınan") | E10: =SerbestNakit+D10 | F10: =MAX(0,C10-E10) | G10: =IF(F10>0,"AÇIK","YETERLİ") | H10: =N(F10>0) | I10: =IFERROR(FORECAST($B10+HaftaUzunluk,$C$7:$C$67,$B$7:$B$67),"")
A11: 4 | B11: =$B$4+A11 | C11: =-SUMIFS(CEK_SENET_KAYIT!$M$6:$M$1000,CEK_SENET_KAYIT!$I$6:$I$1000,"<="&$B11,CEK_SENET_KAYIT!$D$6:$D$1000,"Verilen") | D11: =SUMIFS(CEK_SENET_KAYIT!$AF$6:$AF$1000,CEK_SENET_KAYIT!$I$6:$I$1000,"<="&$B11,CEK_SENET_KAYIT!$D$6:$D$1000,"Alınan") | E11: =SerbestNakit+D11 | F11: =MAX(0,C11-E11) | G11: =IF(F11>0,"AÇIK","YETERLİ") | H11: =N(F11>0) | I11: =IFERROR(FORECAST($B11+HaftaUzunluk,$C$7:$C$67,$B$7:$B$67),"")
A12: 5 | B12: =$B$4+A12 | C12: =-SUMIFS(CEK_SENET_KAYIT!$M$6:$M$1000,CEK_SENET_KAYIT!$I$6:$I$1000,"<="&$B12,CEK_SENET_KAYIT!$D$6:$D$1000,"Verilen") | D12: =SUMIFS(CEK_SENET_KAYIT!$AF$6:$AF$1000,CEK_SENET_KAYIT!$I$6:$I$1000,"<="&$B12,CEK_SENET_KAYIT!$D$6:$D$1000,"Alınan") | E12: =SerbestNakit+D12 | F12: =MAX(0,C12-E12) | G12: =IF(F12>0,"AÇIK","YETERLİ") | H12: =N(F12>0) | I12: =IFERROR(FORECAST($B12+HaftaUzunluk,$C$7:$C$67,$B$7:$B$67),"")
A13: 6 | B13: =$B$4+A13 | C13: =-SUMIFS(CEK_SENET_KAYIT!$M$6:$M$1000,CEK_SENET_KAYIT!$I$6:$I$1000,"<="&$B13,CEK_SENET_KAYIT!$D$6:$D$1000,"Verilen") | D13: =SUMIFS(CEK_SENET_KAYIT!$AF$6:$AF$1000,CEK_SENET_KAYIT!$I$6:$I$1000,"<="&$B13,CEK_SENET_KAYIT!$D$6:$D$1000,"Alınan") | E13: =SerbestNakit+D13 | F13: =MAX(0,C13-E13) | G13: =IF(F13>0,"AÇIK","YETERLİ") | H13: =N(F13>0) | I13: =IFERROR(FORECAST($B13+HaftaUzunluk,$C$7:$C$67,$B$7:$B$67),"")
A14: 7 | B14: =$B$4+A14 | C14: =-SUMIFS(CEK_SENET_KAYIT!$M$6:$M$1000,CEK_SENET_KAYIT!$I$6:$I$1000,"<="&$B14,CEK_SENET_KAYIT!$D$6:$D$1000,"Verilen") | D14: =SUMIFS(CEK_SENET_KAYIT!$AF$6:$AF$1000,CEK_SENET_KAYIT!$I$6:$I$1000,"<="&$B14,CEK_SENET_KAYIT!$D$6:$D$1000,"Alınan") | E14: =SerbestNakit+D14 | F14: =MAX(0,C14-E14) | G14: =IF(F14>0,"AÇIK","YETERLİ") | H14: =N(F14>0) | I14: =IFERROR(FORECAST($B14+HaftaUzunluk,$C$7:$C$67,$B$7:$B$67),"")
A15: 8 | B15: =$B$4+A15 | C15: =-SUMIFS(CEK_SENET_KAYIT!$M$6:$M$1000,CEK_SENET_KAYIT!$I$6:$I$1000,"<="&$B15,CEK_SENET_KAYIT!$D$6:$D$1000,"Verilen") | D15: =SUMIFS(CEK_SENET_KAYIT!$AF$6:$AF$1000,CEK_SENET_KAYIT!$I$6:$I$1000,"<="&$B15,CEK_SENET_KAYIT!$D$6:$D$1000,"Alınan") | E15: =SerbestNakit+D15 | F15: =MAX(0,C15-E15) | G15: =IF(F15>0,"AÇIK","YETERLİ") | H15: =N(F15>0) | I15: =IFERROR(FORECAST($B15+HaftaUzunluk,$C$7:$C$67,$B$7:$B$67),"")
A16: 9 | B16: =$B$4+A16 | C16: =-SUMIFS(CEK_SENET_KAYIT!$M$6:$M$1000,CEK_SENET_KAYIT!$I$6:$I$1000,"<="&$B16,CEK_SENET_KAYIT!$D$6:$D$1000,"Verilen") | D16: =SUMIFS(CEK_SENET_KAYIT!$AF$6:$AF$1000,CEK_SENET_KAYIT!$I$6:$I$1000,"<="&$B16,CEK_SENET_KAYIT!$D$6:$D$1000,"Alınan") | E16: =SerbestNakit+D16 | F16: =MAX(0,C16-E16) | G16: =IF(F16>0,"AÇIK","YETERLİ") | H16: =N(F16>0) | I16: =IFERROR(FORECAST($B16+HaftaUzunluk,$C$7:$C$67,$B$7:$B$67),"")
A17: 10 | B17: =$B$4+A17 | C17: =-SUMIFS(CEK_SENET_KAYIT!$M$6:$M$1000,CEK_SENET_KAYIT!$I$6:$I$1000,"<="&$B17,CEK_SENET_KAYIT!$D$6:$D$1000,"Verilen") | D17: =SUMIFS(CEK_SENET_KAYIT!$AF$6:$AF$1000,CEK_SENET_KAYIT!$I$6:$I$1000,"<="&$B17,CEK_SENET_KAYIT!$D$6:$D$1000,"Alınan") | E17: =SerbestNakit+D17 | F17: =MAX(0,C17-E17) | G17: =IF(F17>0,"AÇIK","YETERLİ") | H17: =N(F17>0) | I17: =IFERROR(FORECAST($B17+HaftaUzunluk,$C$7:$C$67,$B$7:$B$67),"")
A18: 11 | B18: =$B$4+A18 | C18: =-SUMIFS(CEK_SENET_KAYIT!$M$6:$M$1000,CEK_SENET_KAYIT!$I$6:$I$1000,"<="&$B18,CEK_SENET_KAYIT!$D$6:$D$1000,"Verilen") | D18: =SUMIFS(CEK_SENET_KAYIT!$AF$6:$AF$1000,CEK_SENET_KAYIT!$I$6:$I$1000,"<="&$B18,CEK_SENET_KAYIT!$D$6:$D$1000,"Alınan") | E18: =SerbestNakit+D18 | F18: =MAX(0,C18-E18) | G18: =IF(F18>0,"AÇIK","YETERLİ") | H18: =N(F18>0) | I18: =IFERROR(FORECAST($B18+HaftaUzunluk,$C$7:$C$67,$B$7:$B$67),"")
... A67: 60 | B67: =$B$4+A67 | C67: =-SUMIFS(CEK_SENET_KAYIT!$M$6:$M$1000,CEK_SENET_KAYIT!$I$6:$I$1000,"<="&$B67,CEK_SENET_KAYIT!$D$6:$D$1000,"Verilen") | D67: =SUMIFS(CEK_SENET_KAYIT!$AF$6:$AF$1000,CEK_SENET_KAYIT!$I$6:$I$1000,"<="&$B67,CEK_SENET_KAYIT!$D$6:$D$1000,"Alınan") | E67: =SerbestNakit+D67 | F67: =MAX(0,C67-E67) | G67: =IF(F67>0,"AÇIK","YETERLİ") | H67: =N(F67>0) | I67: =IFERROR(FORECAST($B67+HaftaUzunluk,$C$7:$C$67,$B$7:$B$67),"")
A69: Maksimum Karşılık Açığı | B69: =MAX(F7:F67)
A70: İlk Karşılık Açığı Tarihi | B70: =IFERROR(INDEX(B7:B67,MATCH(1,H7:H67,0)),"-")
A72: HAFTALIK ÖDEME YOĞUNLUĞU (13 Hafta)
A73: Hafta | B73: Başlangıç | C73: Bitiş | D73: Verilen | E73: Alınan RW | F73: Net
A74: 1 | B74: =$B$4-WEEKDAY($B$4,2)+1 | C74: =B74+HaftaUzunluk-1 | D74: =-SUMIFS(CEK_SENET_KAYIT!$M$6:$M$1000,CEK_SENET_KAYIT!$I$6:$I$1000,">="&$B74,CEK_SENET_KAYIT!$I$6:$I$1000,"<="&$C74,CEK_SENET_KAYIT!$D$6:$D$1000,"Verilen") | E74: =SUMIFS(CEK_SENET_KAYIT!$AF$6:$AF$1000,CEK_SENET_KAYIT!$I$6:$I$1000,">="&$B74,CEK_SENET_KAYIT!$I$6:$I$1000,"<="&$C74,CEK_SENET_KAYIT!$D$6:$D$1000,"Alınan") | F74: =D74-E74
A75: =A74+1 | B75: =B74+7 | C75: =B75+HaftaUzunluk-1 | D75: =-SUMIFS(CEK_SENET_KAYIT!$M$6:$M$1000,CEK_SENET_KAYIT!$I$6:$I$1000,">="&$B75,CEK_SENET_KAYIT!$I$6:$I$1000,"<="&$C75,CEK_SENET_KAYIT!$D$6:$D$1000,"Verilen") | E75: =SUMIFS(CEK_SENET_KAYIT!$AF$6:$AF$1000,CEK_SENET_KAYIT!$I$6:$I$1000,">="&$B75,CEK_SENET_KAYIT!$I$6:$I$1000,"<="&$C75,CEK_SENET_KAYIT!$D$6:$D$1000,"Alınan") | F75: =D75-E75
A76: =A75+1 | B76: =B75+7 | C76: =B76+HaftaUzunluk-1 | D76: =-SUMIFS(CEK_SENET_KAYIT!$M$6:$M$1000,CEK_SENET_KAYIT!$I$6:$I$1000,">="&$B76,CEK_SENET_KAYIT!$I$6:$I$1000,"<="&$C76,CEK_SENET_KAYIT!$D$6:$D$1000,"Verilen") | E76: =SUMIFS(CEK_SENET_KAYIT!$AF$6:$AF$1000,CEK_SENET_KAYIT!$I$6:$I$1000,">="&$B76,CEK_SENET_KAYIT!$I$6:$I$1000,"<="&$C76,CEK_SENET_KAYIT!$D$6:$D$1000,"Alınan") | F76: =D76-E76
A77: =A76+1 | B77: =B76+7 | C77: =B77+HaftaUzunluk-1 | D77: =-SUMIFS(CEK_SENET_KAYIT!$M$6:$M$1000,CEK_SENET_KAYIT!$I$6:$I$1000,">="&$B77,CEK_SENET_KAYIT!$I$6:$I$1000,"<="&$C77,CEK_SENET_KAYIT!$D$6:$D$1000,"Verilen") | E77: =SUMIFS(CEK_SENET_KAYIT!$AF$6:$AF$1000,CEK_SENET_KAYIT!$I$6:$I$1000,">="&$B77,CEK_SENET_KAYIT!$I$6:$I$1000,"<="&$C77,CEK_SENET_KAYIT!$D$6:$D$1000,"Alınan") | F77: =D77-E77
A78: =A77+1 | B78: =B77+7 | C78: =B78+HaftaUzunluk-1 | D78: =-SUMIFS(CEK_SENET_KAYIT!$M$6:$M$1000,CEK_SENET_KAYIT!$I$6:$I$1000,">="&$B78,CEK_SENET_KAYIT!$I$6:$I$1000,"<="&$C78,CEK_SENET_KAYIT!$D$6:$D$1000,"Verilen") | E78: =SUMIFS(CEK_SENET_KAYIT!$AF$6:$AF$1000,CEK_SENET_KAYIT!$I$6:$I$1000,">="&$B78,CEK_SENET_KAYIT!$I$6:$I$1000,"<="&$C78,CEK_SENET_KAYIT!$D$6:$D$1000,"Alınan") | F78: =D78-E78
A79: =A78+1 | B79: =B78+7 | C79: =B79+HaftaUzunluk-1 | D79: =-SUMIFS(CEK_SENET_KAYIT!$M$6:$M$1000,CEK_SENET_KAYIT!$I$6:$I$1000,">="&$B79,CEK_SENET_KAYIT!$I$6:$I$1000,"<="&$C79,CEK_SENET_KAYIT!$D$6:$D$1000,"Verilen") | E79: =SUMIFS(CEK_SENET_KAYIT!$AF$6:$AF$1000,CEK_SENET_KAYIT!$I$6:$I$1000,">="&$B79,CEK_SENET_KAYIT!$I$6:$I$1000,"<="&$C79,CEK_SENET_KAYIT!$D$6:$D$1000,"Alınan") | F79: =D79-E79
A80: =A79+1 | B80: =B79+7 | C80: =B80+HaftaUzunluk-1 | D80: =-SUMIFS(CEK_SENET_KAYIT!$M$6:$M$1000,CEK_SENET_KAYIT!$I$6:$I$1000,">="&$B80,CEK_SENET_KAYIT!$I$6:$I$1000,"<="&$C80,CEK_SENET_KAYIT!$D$6:$D$1000,"Verilen") | E80: =SUMIFS(CEK_SENET_KAYIT!$AF$6:$AF$1000,CEK_SENET_KAYIT!$I$6:$I$1000,">="&$B80,CEK_SENET_KAYIT!$I$6:$I$1000,"<="&$C80,CEK_SENET_KAYIT!$D$6:$D$1000,"Alınan") | F80: =D80-E80
A81: =A80+1 | B81: =B80+7 | C81: =B81+HaftaUzunluk-1 | D81: =-SUMIFS(CEK_SENET_KAYIT!$M$6:$M$1000,CEK_SENET_KAYIT!$I$6:$I$1000,">="&$B81,CEK_SENET_KAYIT!$I$6:$I$1000,"<="&$C81,CEK_SENET_KAYIT!$D$6:$D$1000,"Verilen") | E81: =SUMIFS(CEK_SENET_KAYIT!$AF$6:$AF$1000,CEK_SENET_KAYIT!$I$6:$I$1000,">="&$B81,CEK_SENET_KAYIT!$I$6:$I$1000,"<="&$C81,CEK_SENET_KAYIT!$D$6:$D$1000,"Alınan") | F81: =D81-E81
A82: =A81+1 | B82: =B81+7 | C82: =B82+HaftaUzunluk-1 | D82: =-SUMIFS(CEK_SENET_KAYIT!$M$6:$M$1000,CEK_SENET_KAYIT!$I$6:$I$1000,">="&$B82,CEK_SENET_KAYIT!$I$6:$I$1000,"<="&$C82,CEK_SENET_KAYIT!$D$6:$D$1000,"Verilen") | E82: =SUMIFS(CEK_SENET_KAYIT!$AF$6:$AF$1000,CEK_SENET_KAYIT!$I$6:$I$1000,">="&$B82,CEK_SENET_KAYIT!$I$6:$I$1000,"<="&$C82,CEK_SENET_KAYIT!$D$6:$D$1000,"Alınan") | F82: =D82-E82
A83: =A82+1 | B83: =B82+7 | C83: =B83+HaftaUzunluk-1 | D83: =-SUMIFS(CEK_SENET_KAYIT!$M$6:$M$1000,CEK_SENET_KAYIT!$I$6:$I$1000,">="&$B83,CEK_SENET_KAYIT!$I$6:$I$1000,"<="&$C83,CEK_SENET_KAYIT!$D$6:$D$1000,"Verilen") | E83: =SUMIFS(CEK_SENET_KAYIT!$AF$6:$AF$1000,CEK_SENET_KAYIT!$I$6:$I$1000,">="&$B83,CEK_SENET_KAYIT!$I$6:$I$1000,"<="&$C83,CEK_SENET_KAYIT!$D$6:$D$1000,"Alınan") | F83: =D83-E83
A84: =A83+1 | B84: =B83+7 | C84: =B84+HaftaUzunluk-1 | D84: =-SUMIFS(CEK_SENET_KAYIT!$M$6:$M$1000,CEK_SENET_KAYIT!$I$6:$I$1000,">="&$B84,CEK_SENET_KAYIT!$I$6:$I$1000,"<="&$C84,CEK_SENET_KAYIT!$D$6:$D$1000,"Verilen") | E84: =SUMIFS(CEK_SENET_KAYIT!$AF$6:$AF$1000,CEK_SENET_KAYIT!$I$6:$I$1000,">="&$B84,CEK_SENET_KAYIT!$I$6:$I$1000,"<="&$C84,CEK_SENET_KAYIT!$D$6:$D$1000,"Alınan") | F84: =D84-E84
A85: =A84+1 | B85: =B84+7 | C85: =B85+HaftaUzunluk-1 | D85: =-SUMIFS(CEK_SENET_KAYIT!$M$6:$M$1000,CEK_SENET_KAYIT!$I$6:$I$1000,">="&$B85,CEK_SENET_KAYIT!$I$6:$I$1000,"<="&$C85,CEK_SENET_KAYIT!$D$6:$D$1000,"Verilen") | E85: =SUMIFS(CEK_SENET_KAYIT!$AF$6:$AF$1000,CEK_SENET_KAYIT!$I$6:$I$1000,">="&$B85,CEK_SENET_KAYIT!$I$6:$I$1000,"<="&$C85,CEK_SENET_KAYIT!$D$6:$D$1000,"Alınan") | F85: =D85-E85
A86: =A85+1 | B86: =B85+7 | C86: =B86+HaftaUzunluk-1 | D86: =-SUMIFS(CEK_SENET_KAYIT!$M$6:$M$1000,CEK_SENET_KAYIT!$I$6:$I$1000,">="&$B86,CEK_SENET_KAYIT!$I$6:$I$1000,"<="&$C86,CEK_SENET_KAYIT!$D$6:$D$1000,"Verilen") | E86: =SUMIFS(CEK_SENET_KAYIT!$AF$6:$AF$1000,CEK_SENET_KAYIT!$I$6:$I$1000,">="&$B86,CEK_SENET_KAYIT!$I$6:$I$1000,"<="&$C86,CEK_SENET_KAYIT!$D$6:$D$1000,"Alınan") | F86: =D86-E86
A88: En Yoğun Hafta Verilen | B88: =MAX(D74:D86)

Sheet KARSILIK_ANALIZI
A1: KARSILIK ANALIZI — ÇEK–SENET VE VADE RİSK SİSTEMİ
A2: Karşılık yeterliliği, müşteri/banka yoğunlaşması ve keşideci riski otomatik hesaplanır. Bu sayfa salt okunurdur; girdi değişiklikleri CEK_SENET_KAYIT ve CARI_KARTLARI üzerinden yapılır.
A4: Alınan Belge Toplamı | B4: =SUMIFS(CEK_SENET_KAYIT!$M$6:$M$1000,CEK_SENET_KAYIT!$D$6:$D$1000,"Alınan") | D4: Karşılıksız Belge Toplamı | E4: =SUMIFS(CEK_SENET_KAYIT!$M$6:$M$1000,CEK_SENET_KAYIT!$Z$6:$Z$1000,"VAR")
A5: Verilen Belge Toplamı | B5: =ABS(SUMIFS(CEK_SENET_KAYIT!$M$6:$M$1000,CEK_SENET_KAYIT!$D$6:$D$1000,"Verilen")) | D5: Vadesi Geçmiş Güncellenmemiş | E5: =SUMPRODUCT(--(ISNUMBER(CEK_SENET_KAYIT!$I$6:$I$1000))*(CEK_SENET_KAYIT!$I$6:$I$1000<TODAY())*(CEK_SENET_KAYIT!$W$6:$W$1000=""))
A6: Risk Ağırlıklı Alınan | B6: =SUMIFS(CEK_SENET_KAYIT!$AF$6:$AF$1000,CEK_SENET_KAYIT!$D$6:$D$1000,"Alınan") | D6: Riskli Müşteri Sayısı | E6: =COUNTIF(CARI_KARTLARI!$I$6:$I$1000,"YÜKSEK")+COUNTIF(CARI_KARTLARI!$I$6:$I$1000,"KARŞILIKSIZ")
A7: Serbest Nakit (Banka Mevduatı) | B7: =SerbestNakit+SUMIFS(BANKA_TAHSIL!$H$6:$H$1000,BANKA_TAHSIL!$E$6:$E$1000,"TAHSİL EDİLDİ") | D7: Mükerrer Belge | E7: =COUNTIF(CEK_SENET_KAYIT!$AD$6:$AD$1000,"MÜKERRER")
A8: Karşılık Açığı | B8: =MAX(0,B5-B6-B7) | D8: Ciro Edilmiş Belge | E8: =COUNTIF(CEK_SENET_KAYIT!$R$6:$R$1000,"EVET")
A9: Karşılık Oranı | B9: =IF(B5>0,(B6+B7)/B5,1) | D9: Sorumluluğu Devam Eden Ciro | E9: =COUNTIFS(CIRO_ZINCIRI!$G$6:$G$1000,"EVET")
A10: Net Belge Pozisyonu | B10: =B4-B5 | D10: İptal Edilen Belge Toplamı | E10: =SUMIFS(CEK_SENET_KAYIT!$M$6:$M$1000,CEK_SENET_KAYIT!$W$6:$W$1000,"İPTAL")
D11: En Büyük Tek Belge | E11: =IFERROR(MAX(CEK_SENET_KAYIT!$J$6:$J$1000),0)
D12: En Büyük Belgenin Keşidecisi | E12: =IF(E11=0,"-",INDEX(CEK_SENET_KAYIT!$E$6:$E$1000,MATCH(E11,CEK_SENET_KAYIT!$J$6:$J$1000,0)))
D13: Banka Tahsil Toplamı | E13: =SUM(BANKA_TAHSIL!$H$6:$H$1000)
D14: Riskli Müşteriden Alınan Belge | E14: =SUMIFS(CEK_SENET_KAYIT!$AF$6:$AF$1000,CEK_SENET_KAYIT!$D$6:$D$1000,"Alınan",CEK_SENET_KAYIT!$AG$6:$AG$1000,"YÜKSEK")+SUMIFS(CEK_SENET_KAYIT!$AF$6:$AF$1000,CEK_SENET_KAYIT!$D$6:$D$1000,"Alınan",CEK_SENET_KAYIT!$AG$6:$AG$1000,"KARŞILIKSIZ")
D15: Güvenli Yeni Çek Limiti | E15: =MAX(0,SerbestNakit+RiskAglikliAlinan-VerilenToplam)
A22: MÜŞTERİ BAZINDA RİSK VE YOĞUNLAŞMA
A23: Cari Kodu | B23: Cari Unvan | C23: Alınan RW | D23: Risk Sınıfı | E23: Yoğunlaşma Payı
A24: =IF(CARI_KARTLARI!$A$6="","",CARI_KARTLARI!$A$6) | B24: =IF($A24="","",IFERROR(VLOOKUP($A24,CARI_KARTLARI!$A$6:$B$1000,2,FALSE()),"")) | C24: =IF($A24="","",SUMIFS(CEK_SENET_KAYIT!$AF$6:$AF$1000,CEK_SENET_KAYIT!$G$6:$G$1000,$A24,CEK_SENET_KAYIT!$D$6:$D$1000,"Alınan")) | D24: =IF($A24="","",IFERROR(IF(INDEX(CARI_KARTLARI!$I$6:$I$1000,MATCH($A24,CARI_KARTLARI!$A$6:$A$1000,0))="KARŞILIKSIZ","KARŞILIKSIZ ÇEK GEÇMİŞİ",INDEX(CARI_KARTLARI!$I$6:$I$1000,MATCH($A24,CARI_KARTLARI!$A$6:$A$1000,0))),"")) | E24: =IF(AlinanToplam=0,"",IF($A24="","",C24/AlinanToplam))
A25: =IF(CARI_KARTLARI!$A$7="","",CARI_KARTLARI!$A$7) | B25: =IF($A25="","",IFERROR(VLOOKUP($A25,CARI_KARTLARI!$A$6:$B$1000,2,FALSE()),"")) | C25: =IF($A25="","",SUMIFS(CEK_SENET_KAYIT!$AF$6:$AF$1000,CEK_SENET_KAYIT!$G$6:$G$1000,$A25,CEK_SENET_KAYIT!$D$6:$D$1000,"Alınan")) | D25: =IF($A25="","",IFERROR(IF(INDEX(CARI_KARTLARI!$I$6:$I$1000,MATCH($A25,CARI_KARTLARI!$A$6:$A$1000,0))="KARŞILIKSIZ","KARŞILIKSIZ ÇEK GEÇMİŞİ",INDEX(CARI_KARTLARI!$I$6:$I$1000,MATCH($A25,CARI_KARTLARI!$A$6:$A$1000,0))),"")) | E25: =IF(AlinanToplam=0,"",IF($A25="","",C25/AlinanToplam))
A26: =IF(CARI_KARTLARI!$A$8="","",CARI_KARTLARI!$A$8) | B26: =IF($A26="","",IFERROR(VLOOKUP($A26,CARI_KARTLARI!$A$6:$B$1000,2,FALSE()),"")) | C26: =IF($A26="","",SUMIFS(CEK_SENET_KAYIT!$AF$6:$AF$1000,CEK_SENET_KAYIT!$G$6:$G$1000,$A26,CEK_SENET_KAYIT!$D$6:$D$1000,"Alınan")) | D26: =IF($A26="","",IFERROR(IF(INDEX(CARI_KARTLARI!$I$6:$I$1000,MATCH($A26,CARI_KARTLARI!$A$6:$A$1000,0))="KARŞILIKSIZ","KARŞILIKSIZ ÇEK GEÇMİŞİ",INDEX(CARI_KARTLARI!$I$6:$I$1000,MATCH($A26,CARI_KARTLARI!$A$6:$A$1000,0))),"")) | E26: =IF(AlinanToplam=0,"",IF($A26="","",C26/AlinanToplam))
A27: =IF(CARI_KARTLARI!$A$9="","",CARI_KARTLARI!$A$9) | B27: =IF($A27="","",IFERROR(VLOOKUP($A27,CARI_KARTLARI!$A$6:$B$1000,2,FALSE()),"")) | C27: =IF($A27="","",SUMIFS(CEK_SENET_KAYIT!$AF$6:$AF$1000,CEK_SENET_KAYIT!$G$6:$G$1000,$A27,CEK_SENET_KAYIT!$D$6:$D$1000,"Alınan")) | D27: =IF($A27="","",IFERROR(IF(INDEX(CARI_KARTLARI!$I$6:$I$1000,MATCH($A27,CARI_KARTLARI!$A$6:$A$1000,0))="KARŞILIKSIZ","KARŞILIKSIZ ÇEK GEÇMİŞİ",INDEX(CARI_KARTLARI!$I$6:$I$1000,MATCH($A27,CARI_KARTLARI!$A$6:$A$1000,0))),"")) | E27: =IF(AlinanToplam=0,"",IF($A27="","",C27/AlinanToplam))
A28: =IF(CARI_KARTLARI!$A$10="","",CARI_KARTLARI!$A$10) | B28: =IF($A28="","",IFERROR(VLOOKUP($A28,CARI_KARTLARI!$A$6:$B$1000,2,FALSE()),"")) | C28: =IF($A28="","",SUMIFS(CEK_SENET_KAYIT!$AF$6:$AF$1000,CEK_SENET_KAYIT!$G$6:$G$1000,$A28,CEK_SENET_KAYIT!$D$6:$D$1000,"Alınan")) | D28: =IF($A28="","",IFERROR(IF(INDEX(CARI_KARTLARI!$I$6:$I$1000,MATCH($A28,CARI_KARTLARI!$A$6:$A$1000,0))="KARŞILIKSIZ","KARŞILIKSIZ ÇEK GEÇMİŞİ",INDEX(CARI_KARTLARI!$I$6:$I$1000,MATCH($A28,CARI_KARTLARI!$A$6:$A$1000,0))),"")) | E28: =IF(AlinanToplam=0,"",IF($A28="","",C28/AlinanToplam))
A29: =IF(CARI_KARTLARI!$A$11="","",CARI_KARTLARI!$A$11) | B29: =IF($A29="","",IFERROR(VLOOKUP($A29,CARI_KARTLARI!$A$6:$B$1000,2,FALSE()),"")) | C29: =IF($A29="","",SUMIFS(CEK_SENET_KAYIT!$AF$6:$AF$1000,CEK_SENET_KAYIT!$G$6:$G$1000,$A29,CEK_SENET_KAYIT!$D$6:$D$1000,"Alınan")) | D29: =IF($A29="","",IFERROR(IF(INDEX(CARI_KARTLARI!$I$6:$I$1000,MATCH($A29,CARI_KARTLARI!$A$6:$A$1000,0))="KARŞILIKSIZ","KARŞILIKSIZ ÇEK GEÇMİŞİ",INDEX(CARI_KARTLARI!$I$6:$I$1000,MATCH($A29,CARI_KARTLARI!$A$6:$A$1000,0))),"")) | E29: =IF(AlinanToplam=0,"",IF($A29="","",C29/AlinanToplam))
A30: =IF(CARI_KARTLARI!$A$12="","",CARI_KARTLARI!$A$12) | B30: =IF($A30="","",IFERROR(VLOOKUP($A30,CARI_KARTLARI!$A$6:$B$1000,2,FALSE()),"")) | C30: =IF($A30="","",SUMIFS(CEK_SENET_KAYIT!$AF$6:$AF$1000,CEK_SENET_KAYIT!$G$6:$G$1000,$A30,CEK_SENET_KAYIT!$D$6:$D$1000,"Alınan")) | D30: =IF($A30="","",IFERROR(IF(INDEX(CARI_KARTLARI!$I$6:$I$1000,MATCH($A30,CARI_KARTLARI!$A$6:$A$1000,0))="KARŞILIKSIZ","KARŞILIKSIZ ÇEK GEÇMİŞİ",INDEX(CARI_KARTLARI!$I$6:$I$1000,MATCH($A30,CARI_KARTLARI!$A$6:$A$1000,0))),"")) | E30: =IF(AlinanToplam=0,"",IF($A30="","",C30/AlinanToplam))
A31: =IF(CARI_KARTLARI!$A$13="","",CARI_KARTLARI!$A$13) | B31: =IF($A31="","",IFERROR(VLOOKUP($A31,CARI_KARTLARI!$A$6:$B$1000,2,FALSE()),"")) | C31: =IF($A31="","",SUMIFS(CEK_SENET_KAYIT!$AF$6:$AF$1000,CEK_SENET_KAYIT!$G$6:$G$1000,$A31,CEK_SENET_KAYIT!$D$6:$D$1000,"Alınan")) | D31: =IF($A31="","",IFERROR(IF(INDEX(CARI_KARTLARI!$I$6:$I$1000,MATCH($A31,CARI_KARTLARI!$A$6:$A$1000,0))="KARŞILIKSIZ","KARŞILIKSIZ ÇEK GEÇMİŞİ",INDEX(CARI_KARTLARI!$I$6:$I$1000,MATCH($A31,CARI_KARTLARI!$A$6:$A$1000,0))),"")) | E31: =IF(AlinanToplam=0,"",IF($A31="","",C31/AlinanToplam))
A32: =IF(CARI_KARTLARI!$A$14="","",CARI_KARTLARI!$A$14) | B32: =IF($A32="","",IFERROR(VLOOKUP($A32,CARI_KARTLARI!$A$6:$B$1000,2,FALSE()),"")) | C32: =IF($A32="","",SUMIFS(CEK_SENET_KAYIT!$AF$6:$AF$1000,CEK_SENET_KAYIT!$G$6:$G$1000,$A32,CEK_SENET_KAYIT!$D$6:$D$1000,"Alınan")) | D32: =IF($A32="","",IFERROR(IF(INDEX(CARI_KARTLARI!$I$6:$I$1000,MATCH($A32,CARI_KARTLARI!$A$6:$A$1000,0))="KARŞILIKSIZ","KARŞILIKSIZ ÇEK GEÇMİŞİ",INDEX(CARI_KARTLARI!$I$6:$I$1000,MATCH($A32,CARI_KARTLARI!$A$6:$A$1000,0))),"")) | E32: =IF(AlinanToplam=0,"",IF($A32="","",C32/AlinanToplam))
A33: =IF(CARI_KARTLARI!$A$15="","",CARI_KARTLARI!$A$15) | B33: =IF($A33="","",IFERROR(VLOOKUP($A33,CARI_KARTLARI!$A$6:$B$1000,2,FALSE()),"")) | C33: =IF($A33="","",SUMIFS(CEK_SENET_KAYIT!$AF$6:$AF$1000,CEK_SENET_KAYIT!$G$6:$G$1000,$A33,CEK_SENET_KAYIT!$D$6:$D$1000,"Alınan")) | D33: =IF($A33="","",IFERROR(IF(INDEX(CARI_KARTLARI!$I$6:$I$1000,MATCH($A33,CARI_KARTLARI!$A$6:$A$1000,0))="KARŞILIKSIZ","KARŞILIKSIZ ÇEK GEÇMİŞİ",INDEX(CARI_KARTLARI!$I$6:$I$1000,MATCH($A33,CARI_KARTLARI!$A$6:$A$1000,0))),"")) | E33: =IF(AlinanToplam=0,"",IF($A33="","",C33/AlinanToplam))
A34: =IF(CARI_KARTLARI!$A$16="","",CARI_KARTLARI!$A$16) | B34: =IF($A34="","",IFERROR(VLOOKUP($A34,CARI_KARTLARI!$A$6:$B$1000,2,FALSE()),"")) | C34: =IF($A34="","",SUMIFS(CEK_SENET_KAYIT!$AF$6:$AF$1000,CEK_SENET_KAYIT!$G$6:$G$1000,$A34,CEK_SENET_KAYIT!$D$6:$D$1000,"Alınan")) | D34: =IF($A34="","",IFERROR(IF(INDEX(CARI_KARTLARI!$I$6:$I$1000,MATCH($A34,CARI_KARTLARI!$A$6:$A$1000,0))="KARŞILIKSIZ","KARŞILIKSIZ ÇEK GEÇMİŞİ",INDEX(CARI_KARTLARI!$I$6:$I$1000,MATCH($A34,CARI_KARTLARI!$A$6:$A$1000,0))),"")) | E34: =IF(AlinanToplam=0,"",IF($A34="","",C34/AlinanToplam))
A35: =IF(CARI_KARTLARI!$A$17="","",CARI_KARTLARI!$A$17) | B35: =IF($A35="","",IFERROR(VLOOKUP($A35,CARI_KARTLARI!$A$6:$B$1000,2,FALSE()),"")) | C35: =IF($A35="","",SUMIFS(CEK_SENET_KAYIT!$AF$6:$AF$1000,CEK_SENET_KAYIT!$G$6:$G$1000,$A35,CEK_SENET_KAYIT!$D$6:$D$1000,"Alınan")) | D35: =IF($A35="","",IFERROR(IF(INDEX(CARI_KARTLARI!$I$6:$I$1000,MATCH($A35,CARI_KARTLARI!$A$6:$A$1000,0))="KARŞILIKSIZ","KARŞILIKSIZ ÇEK GEÇMİŞİ",INDEX(CARI_KARTLARI!$I$6:$I$1000,MATCH($A35,CARI_KARTLARI!$A$6:$A$1000,0))),"")) | E35: =IF(AlinanToplam=0,"",IF($A35="","",C35/AlinanToplam))
A36: =IF(CARI_KARTLARI!$A$18="","",CARI_KARTLARI!$A$18) | B36: =IF($A36="","",IFERROR(VLOOKUP($A36,CARI_KARTLARI!$A$6:$B$1000,2,FALSE()),"")) | C36: =IF($A36="","",SUMIFS(CEK_SENET_KAYIT!$AF$6:$AF$1000,CEK_SENET_KAYIT!$G$6:$G$1000,$A36,CEK_SENET_KAYIT!$D$6:$D$1000,"Alınan")) | D36: =IF($A36="","",IFERROR(IF(INDEX(CARI_KARTLARI!$I$6:$I$1000,MATCH($A36,CARI_KARTLARI!$A$6:$A$1000,0))="KARŞILIKSIZ","KARŞILIKSIZ ÇEK GEÇMİŞİ",INDEX(CARI_KARTLARI!$I$6:$I$1000,MATCH($A36,CARI_KARTLARI!$A$6:$A$1000,0))),"")) | E36: =IF(AlinanToplam=0,"",IF($A36="","",C36/AlinanToplam))
A37: =IF(CARI_KARTLARI!$A$19="","",CARI_KARTLARI!$A$19) | B37: =IF($A37="","",IFERROR(VLOOKUP($A37,CARI_KARTLARI!$A$6:$B$1000,2,FALSE()),"")) | C37: =IF($A37="","",SUMIFS(CEK_SENET_KAYIT!$AF$6:$AF$1000,CEK_SENET_KAYIT!$G$6:$G$1000,$A37,CEK_SENET_KAYIT!$D$6:$D$1000,"Alınan")) | D37: =IF($A37="","",IFERROR(IF(INDEX(CARI_KARTLARI!$I$6:$I$1000,MATCH($A37,CARI_KARTLARI!$A$6:$A$1000,0))="KARŞILIKSIZ","KARŞILIKSIZ ÇEK GEÇMİŞİ",INDEX(CARI_KARTLARI!$I$6:$I$1000,MATCH($A37,CARI_KARTLARI!$A$6:$A$1000,0))),"")) | E37: =IF(AlinanToplam=0,"",IF($A37="","",C37/AlinanToplam))
A38: =IF(CARI_KARTLARI!$A$20="","",CARI_KARTLARI!$A$20) | B38: =IF($A38="","",IFERROR(VLOOKUP($A38,CARI_KARTLARI!$A$6:$B$1000,2,FALSE()),"")) | C38: =IF($A38="","",SUMIFS(CEK_SENET_KAYIT!$AF$6:$AF$1000,CEK_SENET_KAYIT!$G$6:$G$1000,$A38,CEK_SENET_KAYIT!$D$6:$D$1000,"Alınan")) | D38: =IF($A38="","",IFERROR(IF(INDEX(CARI_KARTLARI!$I$6:$I$1000,MATCH($A38,CARI_KARTLARI!$A$6:$A$1000,0))="KARŞILIKSIZ","KARŞILIKSIZ ÇEK GEÇMİŞİ",INDEX(CARI_KARTLARI!$I$6:$I$1000,MATCH($A38,CARI_KARTLARI!$A$6:$A$1000,0))),"")) | E38: =IF(AlinanToplam=0,"",IF($A38="","",C38/AlinanToplam))
A39: =IF(CARI_KARTLARI!$A$21="","",CARI_KARTLARI!$A$21) | B39: =IF($A39="","",IFERROR(VLOOKUP($A39,CARI_KARTLARI!$A$6:$B$1000,2,FALSE()),"")) | C39: =IF($A39="","",SUMIFS(CEK_SENET_KAYIT!$AF$6:$AF$1000,CEK_SENET_KAYIT!$G$6:$G$1000,$A39,CEK_SENET_KAYIT!$D$6:$D$1000,"Alınan")) | D39: =IF($A39="","",IFERROR(IF(INDEX(CARI_KARTLARI!$I$6:$I$1000,MATCH($A39,CARI_KARTLARI!$A$6:$A$1000,0))="KARŞILIKSIZ","KARŞILIKSIZ ÇEK GEÇMİŞİ",INDEX(CARI_KARTLARI!$I$6:$I$1000,MATCH($A39,CARI_KARTLARI!$A$6:$A$1000,0))),"")) | E39: =IF(AlinanToplam=0,"",IF($A39="","",C39/AlinanToplam))
A40: =IF(CARI_KARTLARI!$A$22="","",CARI_KARTLARI!$A$22) | B40: =IF($A40="","",IFERROR(VLOOKUP($A40,CARI_KARTLARI!$A$6:$B$1000,2,FALSE()),"")) | C40: =IF($A40="","",SUMIFS(CEK_SENET_KAYIT!$AF$6:$AF$1000,CEK_SENET_KAYIT!$G$6:$G$1000,$A40,CEK_SENET_KAYIT!$D$6:$D$1000,"Alınan")) | D40: =IF($A40="","",IFERROR(IF(INDEX(CARI_KARTLARI!$I$6:$I$1000,MATCH($A40,CARI_KARTLARI!$A$6:$A$1000,0))="KARŞILIKSIZ","KARŞILIKSIZ ÇEK GEÇMİŞİ",INDEX(CARI_KARTLARI!$I$6:$I$1000,MATCH($A40,CARI_KARTLARI!$A$6:$A$1000,0))),"")) | E40: =IF(AlinanToplam=0,"",IF($A40="","",C40/AlinanToplam))
A41: =IF(CARI_KARTLARI!$A$23="","",CARI_KARTLARI!$A$23) | B41: =IF($A41="","",IFERROR(VLOOKUP($A41,CARI_KARTLARI!$A$6:$B$1000,2,FALSE()),"")) | C41: =IF($A41="","",SUMIFS(CEK_SENET_KAYIT!$AF$6:$AF$1000,CEK_SENET_KAYIT!$G$6:$G$1000,$A41,CEK_SENET_KAYIT!$D$6:$D$1000,"Alınan")) | D41: =IF($A41="","",IFERROR(IF(INDEX(CARI_KARTLARI!$I$6:$I$1000,MATCH($A41,CARI_KARTLARI!$A$6:$A$1000,0))="KARŞILIKSIZ","KARŞILIKSIZ ÇEK GEÇMİŞİ",INDEX(CARI_KARTLARI!$I$6:$I$1000,MATCH($A41,CARI_KARTLARI!$A$6:$A$1000,0))),"")) | E41: =IF(AlinanToplam=0,"",IF($A41="","",C41/AlinanToplam))
A42: =IF(CARI_KARTLARI!$A$24="","",CARI_KARTLARI!$A$24) | B42: =IF($A42="","",IFERROR(VLOOKUP($A42,CARI_KARTLARI!$A$6:$B$1000,2,FALSE()),"")) | C42: =IF($A42="","",SUMIFS(CEK_SENET_KAYIT!$AF$6:$AF$1000,CEK_SENET_KAYIT!$G$6:$G$1000,$A42,CEK_SENET_KAYIT!$D$6:$D$1000,"Alınan")) | D42: =IF($A42="","",IFERROR(IF(INDEX(CARI_KARTLARI!$I$6:$I$1000,MATCH($A42,CARI_KARTLARI!$A$6:$A$1000,0))="KARŞILIKSIZ","KARŞILIKSIZ ÇEK GEÇMİŞİ",INDEX(CARI_KARTLARI!$I$6:$I$1000,MATCH($A42,CARI_KARTLARI!$A$6:$A$1000,0))),"")) | E42: =IF(AlinanToplam=0,"",IF($A42="","",C42/AlinanToplam))
A43: =IF(CARI_KARTLARI!$A$25="","",CARI_KARTLARI!$A$25) | B43: =IF($A43="","",IFERROR(VLOOKUP($A43,CARI_KARTLARI!$A$6:$B$1000,2,FALSE()),"")) | C43: =IF($A43="","",SUMIFS(CEK_SENET_KAYIT!$AF$6:$AF$1000,CEK_SENET_KAYIT!$G$6:$G$1000,$A43,CEK_SENET_KAYIT!$D$6:$D$1000,"Alınan")) | D43: =IF($A43="","",IFERROR(IF(INDEX(CARI_KARTLARI!$I$6:$I$1000,MATCH($A43,CARI_KARTLARI!$A$6:$A$1000,0))="KARŞILIKSIZ","KARŞILIKSIZ ÇEK GEÇMİŞİ",INDEX(CARI_KARTLARI!$I$6:$I$1000,MATCH($A43,CARI_KARTLARI!$A$6:$A$1000,0))),"")) | E43: =IF(AlinanToplam=0,"",IF($A43="","",C43/AlinanToplam))
A46: BANKA BAZINDA TAHSİL YOĞUNLAŞMASI
A47: Banka | B47: Tahsil Tutarı | C47: Pay
A48: =IF(LISTELER!$L$4="","",LISTELER!$L$4) | B48: =IF($A48="","",SUMIFS(BANKA_TAHSIL!$H$6:$H$1000,BANKA_TAHSIL!$C$6:$C$1000,$A48)) | C48: =IF($A48="","",IF(TahsilToplam=0,"",B48/TahsilToplam)) | F48: BELGE TÜRÜ DAĞILIMI
A49: =IF(LISTELER!$L$5="","",LISTELER!$L$5) | B49: =IF($A49="","",SUMIFS(BANKA_TAHSIL!$H$6:$H$1000,BANKA_TAHSIL!$C$6:$C$1000,$A49)) | C49: =IF($A49="","",IF(TahsilToplam=0,"",B49/TahsilToplam)) | F49: ÇEK | G49: =IFERROR(SUMIFS(CEK_SENET_KAYIT!$M$6:$M$1000,CEK_SENET_KAYIT!$B$6:$B$1000,"ÇEK"),0)
...

Sheet KONTROLLER
A1: KONTROLLER — ÇEK–SENET VE VADE RİSK SİSTEMİ
A2: Veri kalitesi, mükerrer kayıt, tarih ve toplam doğruluk kontrolleri otomatik çalışır. Bu sayfa salt okunurdur.
A4: A. ZORUNLU ALAN KONTROLLERİ
A5: Alan | B5: Eksik Kayıt | C5: Durum | E5: Kayıt Sayısı
A6: Belge Türü | B6: =IF(KayitSayisi=0,"-",SUMPRODUCT((CEK_SENET_KAYIT!$C$6:$C$1000<>"")*(CEK_SENET_KAYIT!$B$6:$B$1000=""))) | C6: =IF(B6="-","",IF(B6=0,"PASS",IF(B6<=3,"WARN","FAIL"))) | E6: =COUNTA(CEK_SENET_KAYIT!$C$6:$C$1000)
A7: Belge Numarası | B7: =IF(KayitSayisi=0,"-",SUMPRODUCT((CEK_SENET_KAYIT!$B$6:$B$1000<>"")*(CEK_SENET_KAYIT!$C$6:$C$1000=""))) | C7: =IF(B7="-","",IF(B7=0,"PASS",IF(B7<=3,"WARN","FAIL")))
A8: Yön | B8: =IF(KayitSayisi=0,"-",SUMPRODUCT((CEK_SENET_KAYIT!$C$6:$C$1000<>"")*(CEK_SENET_KAYIT!$D$6:$D$1000=""))) | C8: =IF(B8="-","",IF(B8=0,"PASS",IF(B8<=3,"WARN","FAIL")))
A9: Cari Kodu | B9: =IF(KayitSayisi=0,"-",SUMPRODUCT((CEK_SENET_KAYIT!$C$6:$C$1000<>"")*(CEK_SENET_KAYIT!$G$6:$G$1000=""))) | C9: =IF(B9="-","",IF(B9=0,"PASS",IF(B9<=3,"WARN","FAIL")))
A10: Vade Tarihi | B10: =IF(KayitSayisi=0,"-",SUMPRODUCT((CEK_SENET_KAYIT!$C$6:$C$1000<>"")*(CEK_SENET_KAYIT!$I$6:$I$1000=""))) | C10: =IF(B10="-","",IF(B10=0,"PASS",IF(B10<=3,"WARN","FAIL")))
A11: Tutar | B11: =IF(KayitSayisi=0,"-",SUMPRODUCT((CEK_SENET_KAYIT!$C$6:$C$1000<>"")*(CEK_SENET_KAYIT!$J$6:$J$1000=""))) | C11: =IF(B11="-","",IF(B11=0,"PASS",IF(B11<=3,"WARN","FAIL")))
A12: Kur | B12: =IF(KayitSayisi=0,"-",SUMPRODUCT((CEK_SENET_KAYIT!$C$6:$C$1000<>"")*(CEK_SENET_KAYIT!$L$6:$L$1000=""))) | C12: =IF(B12="-","",IF(B12=0,"PASS",IF(B12<=3,"WARN","FAIL")))
A15: B. VERİ DOĞRULUK KONTROLLERİ
A16: Kontrol | B16: Değer | C16: Durum
A17: Mükerrer Belge | B17: =COUNTIF(CEK_SENET_KAYIT!$AD$6:$AD$1000,"MÜKERRER") | C17: =IF(B17=0,"PASS",IF(B17<=3,"WARN","FAIL"))
A18: Negatif veya Sıfır Tutar | B18: =SUMPRODUCT(--(ISNUMBER(CEK_SENET_KAYIT!$J$6:$J$1000))*(CEK_SENET_KAYIT!$J$6:$J$1000<=0)) | C18: =IF(B18=0,"PASS",IF(B18<=3,"WARN","FAIL"))
A19: Vade Tarihi < Keşide Tarihi | B19: =SUMPRODUCT(--(ISNUMBER(CEK_SENET_KAYIT!$I$6:$I$1000))*(ISNUMBER(CEK_SENET_KAYIT!$H$6:$H$1000))*(CEK_SENET_KAYIT!$I$6:$I$1000<CEK_SENET_KAYIT!$H$6:$H$1000)) | C19: =IF(B19=0,"PASS",IF(B19<=3,"WARN","FAIL"))
A20: Ciro Edilmiş + Portföyde Çelişkisi | B20: =SUMPRODUCT(--(CEK_SENET_KAYIT!$R$6:$R$1000="EVET")*(CEK_SENET_KAYIT!$T$6:$T$1000="PORTFÖYDE")) | C20: =IF(B20=0,"PASS",IF(B20<=3,"WARN","FAIL"))
A21: Mükerrer Cari Kodu | B21: =SUMPRODUCT((CARI_KARTLARI!$A$6:$A$1000<>"")*(COUNTIF(CARI_KARTLARI!$A$6:$A$1000,CARI_KARTLARI!$A$6:$A$1000)>1)) | C21: =IF(B21=0,"PASS",IF(B21<=3,"WARN","FAIL"))
A24: C. ÇAPRAZ TOPLAM KONTROLÜ
A25: Banka Tahsil vs Son Durum TAHSİL EDİLDİ | B25: =IF(TahsilToplam=0,"-",ABS(TahsilToplam-SUMIFS(CEK_SENET_KAYIT!$M$6:$M$1000,CEK_SENET_KAYIT!$W$6:$W$1000,"TAHSİL EDİLDİ"))) | C25: =IF(B25="-","",IF(B25<=YuvarlamaToleransi,"PASS","WARN"))
A27: D. VERİ KALİTE SKORU
A28: Veri Kalite Skoru (0-100) | B28: =IF(KayitSayisi=0,0,MAX(100-(B6+B7+B8+B9+B10+B11+B12)*HataAgirligi-MukerrerSayisi*UyariAgirligi-B18*UyariAgirligi-B19*HataAgirligi-B20*UyariAgirligi-B21*HataAgirligi,0))
A29: Güven Seviyesi | B29: =IF(B28=0,"VERİ YETERSİZ",IF(B28>=VeriKaliteYuksek,"YÜKSEK",IF(B28>=VeriKaliteOrta,"ORTA","DÜŞÜK")))
A31: E. GENEL SAĞLIK
A32: PASS Kontrol Sayısı | B32: =COUNTIF(C6:C12,"PASS")+COUNTIF(C17:C21,"PASS")
A33: FAIL Kontrol Sayısı | B33: =COUNTIF(C6:C12,"FAIL")+COUNTIF(C17:C21,"FAIL")
A34: Çalışma Kitabı Sağlığı | B34: =IF(KayitSayisi=0,"VERİ YETERSİZ",IF(B33=0,"SAĞLIKLI",IF(B33<=2,"İZLEME GEREKLİ","DÜZELTME GEREKLİ")))

Sheet KARAR_MOTORU
A1: KARAR MOTORU — ÇEK–SENET VE VADE RİSK SİSTEMİ
A2: Karar motoru veriye göre risk seviyesi, gerekçe ve aksiyon üretir. Kesin kredi/hukuki/vergi garantisi vermez; profesyonel muhakeme ile birlikte kullanılmalıdır.
