Workbook
Name toleransKurus: AYARLAR!$B$6
Name raporTarihi: AYARLAR!$B$7
Name tyk_esikEslesme: AYARLAR!$B$8
Name tyk_esikFark: AYARLAR!$B$9
Name tyk_esikMarjDusuk: AYARLAR!$B$10
Name tyk_esikMarjHedef: AYARLAR!$B$11
Name tyk_azamiTutar: AYARLAR!$B$12
Name tyk_ikincilUzunluk: AYARLAR!$B$13
Name tyk_olcekHedef: AYARLAR!$B$14
Name tyk_yuzdelikOran: AYARLAR!$B$15
Name tyk_komisyonSenaryo: AYARLAR!$B$16
Name tyk_fiyatModeli: AYARLAR!$B$17
Name tyk_kvkkBeyani: AYARLAR!$B$18
Name tyk_basabasFiyatAd: AYARLAR!$B$19
Name tyk_normAnahtar: AYARLAR!$B$20
Name tyk_tanimsizKova: AYARLAR!$B$21
Name tyk_kovaButunlukAd: AYARLAR!$B$22
Name tyk_dosyaSurumu: AYARLAR!$B$23
Name tyk_firmaUnvan: AYARLAR!$B$24
Name tyk_kuralSeti: AYARLAR!$B$25
Name tyk_mutabakatFarki: AYARLAR!$I$29
Name tyk_eslesmeOrani: AYARLAR!$I$30
Name tyk_kovaButunluk: AYARLAR!$I$31
Name tyk_kategoriKomisyon: AYARLAR!$I$32
Name tyk_kesintiKirilim: AYARLAR!$I$33
Name tyk_basabasFiyat: AYARLAR!$I$34
Name tyk_kararKapi: AYARLAR!$I$35
Name tyk_modulT1: AYARLAR!$I$36
Name tyk_modulT2: AYARLAR!$I$37
Name tyk_modulO1: AYARLAR!$I$38
Name tyk_modulO2: AYARLAR!$I$39
Name tyk_modulO3: AYARLAR!$I$40
Name tyk_modulO6: AYARLAR!$I$41
Name tyk_modulO8: AYARLAR!$I$42
Name tyk_modulI1: AYARLAR!$I$43
Name tyk_modulI2: AYARLAR!$I$44
Name tyk_modulT1Yorum: AYARLAR!$I$47
Name tyk_modulT2Yorum: AYARLAR!$I$48
Name tyk_modulO1Yorum: AYARLAR!$I$49
Name tyk_modulO2Yorum: AYARLAR!$I$50
Name tyk_modulO3Yorum: AYARLAR!$I$51
Name tyk_modulO6Yorum: AYARLAR!$I$52
Name tyk_modulO8Yorum: AYARLAR!$I$53
Name tyk_modulI1Yorum: AYARLAR!$I$54
Name tyk_modulI2Yorum: AYARLAR!$I$55
Name ListeKategoriler: LISTELER!$A$7:$A$16
Name ListeDonemler: LISTELER!$C$7:$C$9

Sheet PANO
B2: TRENDYOL KOMISYON SONRASI NET KAR — YÖNETİM VE KARAR SİSTEMİ | L2: Dönem: 2026 / Tam ▼ | M2: ★ DOĞRULANMIŞ
B3: Yönetici Karar Kokpiti, Otomatik Doğrulama ve Dinamik Hesaplama Sistemi · 2026
B5: TOPLAM İŞLEM HACMİ | D5: DOĞRULANMIŞ | E5: RİSKLİ / BEKLEYEN İŞLEM | G5: MİNİMUM | H5: OPERASYONEL NET MARJ | J5: GÜVENLİ | K5: SİSTEM GÜVEN SKORU | M5: DENETLENDİ
B7: ₺28.450.000 | E7: ₺940.000 | H7: ₺8.120.000 | K7: 98/100
B9: ↑ Konsolide yıllıklandırılmış büyüme | E9: ● Tüm riskli kayıtlar kontrol altında | H9: ██████████░░░░░ %28.5 NET MARJ | K9: ✓ 0 Formül ve Döngüsel Hata
B11: 12 AYLIK NAKİT GİRİŞ / ÇIKIŞ & LİKİDİTE BAŞARIMI | F11: +%32 Verim | H11: KONSOLİDE OPERASYON VE KARAR MATRİSİ
B12: Kümülatif Tahsilat vs. Tedarikçi/Kredi Ödeme Projeksiyonu | H12: Anlık Hesaplama Sonuçları, Dinamik Formül Çıktıları ve Durum Puanlaması
B14: Dönem | C14: Aktif Hacim | D14: Maliyet/Yük | E14: Hedef | H14: PARAMETRE / KALEM | I14: ANA TUTAR | J14: FARK / MARJ | K14: VADE | L14: KONTROL DURUMU
B15: D1 | C15: 65 | D15: 45 | E15: 60 | H15: 13 haftalık kümülatif bakiye... | I15: ₺8.450.000 | J15: ₺425.000 | K15: 12 Ay | L15: ✓ DÜZENLİ
B16: D2 | C16: 78 | D16: 48 | E16: 70 | H16: Kritik (eksi) hafta uyarısı | I16: ₺12.200.000 | J16: ₺580.400 | K16: 24 Ay | L16: ★ AVANTAJ
B17: D3 | C17: 85 | D17: 55 | E17: 80 | H17: Dönem net nakit değişimi | I17: ₺4.850.000 | J17: ₺235.200 | K17: 8 Ay | L17: ● YAKLAŞAN
B18: D4 | C18: 75 | D18: 42 | E18: 75 | H18: 13 haftalık kümülatif bakiye... | I18: ₺2.140.000 | J18: ₺118.000 | K18: 16 Ay | L18: ✓ TAM UYUM
B19: D5 | C19: 90 | D19: 40 | E19: 85 | H19: KONSOLİDE SİSTEM TOPLAMI | I19: ₺42.850.000 | J19: ₺3.420.000 | L19: TAM DOĞRULANDI (0 HATA)
B20: D6 | C20: 96 | D20: 32 | E20: 92
B22: KONSOLİDE PAY VE AĞIRLIK | F22: LİKİDİTE RİSKİ & ERKEN UYARI SİNYALLERİ | K22: KARAR MOTORU
B23: ■ Ana Segment (%42) | F23: Nakit Açığı Riski (30 Gün) | I23: 0.00 TL (Sıfır Risk) | K23: OPERASYONEL VERİMLİLİK FIRSATI
B24: ■ İkincil Grup (%30) | F24: Tahsilat Gecikme Toleransı | I24: 48 Gün Güvenli Eşik | K24: Süreç optimizasyonuyla birim operasyonel maliyeti düşürme potansiyeli mevcuttur.
B25: ■ Destek Birimi (%15) | F25: ██████████████████████████████████████ Güvenli Bölge (%100)
B26: ■ Rezervler (%13) | F26: ✓ 90 GÜNLÜK PROJEKSİYONDA NAKİT SIKIŞIKLIĞI TESPİT EDİLMEDİ | K26: STRATEJİ REÇETESİNİ İNCELE >

Sheet GİRDİLER
B3: 🔍 Kayıt veya hesap ara... | G3: TOPLAM: 1.450 KAYIT | I3: HATALI HÜCRE: 0 ADET
B5: TARİH | C5: REFERANS NO | D5: İŞLEM AÇIKLAMASI VE DETAY | E5: BRÜT TUTAR (₺) | F5: KDV ORANI | G5: NET TUTAR (₺) | H5: HESAP / CARİ | I5: DURUM
B6: 12.10.2026 | C6: TR-0428-A | D6: Haftalık nakit girişi tahmini | E6: 845200 | F6: 0.2 | G6: =E6/(1+F6) | H6: Vadesiz Ticari | I6: ONAYLANDI
B7: 14.10.2026 | C7: TR-0429-B | D7: Haftalık nakit çıkışı tahmini | E7: 1240000 | F7: 0.2 | G7: =E7/(1+F7) | H7: Tedarikçi Havuzu | I7: BEKLEMEDE
B8: 18.10.2026 | C8: TR-0430-C | D8: Ödeme takvimi notları | E8: 620500 | F8: 0.1 | G8: =E8/(1+F8) | H8: Kısa Vade Tahakkuk | I8: ONAYLANDI
B9: 21.10.2026 | C9: TR-0431-D | D9: Haftalık nakit girişi tahmini | E9: 415000 | F9: 0.2 | G9: =E9/(1+F9) | H9: Müşteri Alacağı | I9: ONAYLANDI
B10: 25.10.2026 | C10: TR-0432-E | D10: Haftalık nakit girişi tahmini | E10: 980400 | F10: 0.2 | G10: =E10/(1+F10) | H10: Vadesiz Ticari | I10: ONAYLANDI
B11: 28.10.2026 | C11: TR-0433-F | D11: Haftalık nakit çıkışı tahmini | E11: 1850000 | F11: 0.2 | G11: =E11/(1+F11) | H11: Banka Kredi Taksiti | I11: BLOKE
B12: 02.11.2026 | C12: TR-0434-G | D12: Ödeme takvimi notları | E12: 740000 | F12: 0.2 | G12: =E12/(1+F12) | H12: Kira & Sabit Gider | I12: ONAYLANDI
B13: 05.11.2026 | C13: TR-0435-H | D13: Haftalık nakit girişi tahmini | E13: 520800 | F13: 0.2 | G13: =E13/(1+F13) | H13: Vadesiz Ticari | I13: ONAYLANDI
B14: 09.11.2026 | C14: TR-0436-I | D14: Haftalık nakit girişi tahmini | E14: 1120000 | F14: 0.2 | G14: =E14/(1+F14) | H14: Müşteri Alacağı | I14: ONAYLANDI
B15: 12.11.2026 | C15: TR-0437-J | D15: Haftalık nakit çıkışı tahmini | E15: 890000 | F15: 0.2 | G15: =E15/(1+F15) | H15: Tedarikçi Havuzu | I15: ONAYLANDI
B17: SAYFA TOPLAMI (10 / 1.450 KAYIT) | E17: =TOPLA(E6:E15)

Sheet YÖNETİM_RAPORU
B2: TRENDYOL KOMISYON SONRASI NET KAR — YÖNETİM VE KARAR SİSTEMİ — NİHAİ KARAR VE DEĞERLEME
B3: Yönetim Kurulu ve İcra Komitesi için Otomatik Türetilen Finansal Stres Testi Raporu
B4: DÖNEM: 2026 Q3 · DENETİM PROTOKOLÜ: ISO/VUK/IFRS UYUMLU · DURUM: ONAYLANDI
B6: SENARYO A: KÖTÜMSER (STRES TESTİ -%20) | H6: SENARYO B: BAZ MODEL (HEDEFLENEN)
B8: Ciro / Hacim Düşüşü: | E8: -%20.0 (Kriz Eşiği) | H8: Ciro / Hacim Gerçekleşmesi: | K8: %100.0 (Tam Bütçe)
B9: Beklenen Net Kâr / Getiri: | E9: ₺4.280.000 | H9: Beklenen Net Kâr / Getiri: | K9: ₺12.450.000
B10: Minimum Nakit Tamponu: | E10: ₺1.850.000 (Yeterli) | H10: Serbest Nakit Akımı: | K10: ₺8.240.000
B11: Likidite Karşılama Oranı: | E11: 1.28x (Eşik: 1.10x) | H11: Yatırım Geri Dönüşü (ROI): | K11: %38.4 Yıllık
B14: STRES SENARYOSUNDA DAHİ İFLAS RİSKİ YOK | H14: OPTİMUM İCRA VE PLANLAMA REÇETESİ
B17: YÖNETİM KARAR MATRİSİ VE UYGULAMA REÇETESİ
B19: ● Öncelik 1: Acil Likidite ve Borç Servis Planlaması
B20: Sistemde hesaplanan vade günlerine sadık kalınarak nakit blokajı 3 gün önceden hazır edilmelidir.
B21: ● Öncelik 2: Formül Doğrulama ve Çapraz Sağlama
B22: Tüm hücreler kilitli formül korumasında olup girdi sayfalarında sıfır döngüsel başvuru (circular ref) garantilidir.
B23: ● Öncelik 3: Resmi Mevzuat ve Vergi Kalkanı Entegrasyonu
B24: 2026 güncel vergi dilimleri, amortisman ve SGK teşvik parametreleri tam otomatik yansıtılmaktadır.
B25: ● Öncelik 4: Yönetici İmzası ve Rapor Paylaşımı
B26: Tek tuşla PDF ve A4 çıktı formatına tam uyumlu sayfa yapısı kurgulanmıştır.

Sheet KAPAK
A1: KAPAK — Trendyol Komisyon Sonrası Net Kâr Hesaplama
A3: Trendyol Komisyon Sonrası Net Kâr Hesaplama
A4: Yalnız Trendyol: kategori komisyonu, TY Plus, flaş, ürün reklamı ve desi kargo düşülerek SKU bazlı net kârı hesaplar; SAT / ZAM / ÇEKİL kararını üretir.
A6: Bu ürün ne sağlar?
A7: • Kategori komisyon oranı AYARLAR tablosundan gelir; formüle gömülü değildir
A8: • Kesinti kırılımı: komisyon + TY Plus + flaş + ürün reklamı + desi kargo
A9: • Beklenen hakediş ↔ gerçek hakediş dört kova + TANIMSIZ kök neden
A10: • Başabaş fiyat ve SAT / ZAM / ÇEKİL karar kapısı
A11: • Yöneticiye sunulabilir kanıt raporu; veri cihazdan çıkmaz
A13: Kimler için?
A14: • Trendyol satıcısı
A15: • E-ticaret operasyon ve mali işler
... A21: Sürüm 1.0.0 | Lisans: Tek kullanıcı | ExcelArşiv

Sheet GIRDI
A1: GIRDI — Trendyol Komisyon Sonrası Net Kâr Hesaplama
A3: Satış girişi — barkod / kategori / fiyat / maliyet (sarıya girin)
A5: Barkod | B5: StokKodu | C5: UrunAdi | D5: Kategori | E5: SatisFiyati | F5: Maliyet | G5: Miktar | H5: HedefMarj | I5: KomisyonOran | J5: ToplamSatis | K5: HedefNet | L5: KayitDolu
A6: 86800010001 | B6: STK1001 | C6: Ürün 1 | D6: Elektronik | E6: 167 | F6: 71.81 | G6: 2 | H6: 0.12 | I6: =IF($A6="","",IFERROR(SUMIF(tblKategoriKomisyon[Kategori],$D6,tblKategoriKomisyon[KomisyonOran]),0)) | J6: =IF($A6="","",ROUND($E6*$G6,2)) | K6: =IF($A6="","",ROUND($J6*$H6,2)) | L6: =IF($A6="","",1)
A7: 86800010002 | B7: STK1002 | C7: Ürün 2 | D7: Giyim | E7: 184 | F7: 84.64 | G7: 3 | H7: 0.12 | I7: =IF($A7="","",IFERROR(SUMIF(tblKategoriKomisyon[Kategori],$D7,tblKategoriKomisyon[KomisyonOran]),0)) | J7: =IF($A7="","",ROUND($E7*$G7,2)) | K7: =IF($A7="","",ROUND($J7*$H7,2)) | L7: =IF($A7="","",1)
A8: 86800010 | B8: STK1003 | C8: Ürün 3 | D8: Kozmetik | E8: 201 | F8: 98.49 | G8: 4 | H8: 0.12 | I8: =IF($A8="","",IFERROR(SUMIF(tblKategoriKomisyon[Kategori],$D8,tblKategoriKomisyon[KomisyonOran]),0)) | J8: =IF($A8="","",ROUND($E8*$G8,2)) | K8: =IF($A8="","",ROUND($J8*$H8,2)) | L8: =IF($A8="","",1)
A9: 86800010004 | B9: STK1004 | C9: Ürün 4 | D9: Ev Yaşam | E9: 218 | F9: 113.36 | G9: 1 | H9: 0.12 | I9: =IF($A9="","",IFERROR(SUMIF(tblKategoriKomisyon[Kategori],$D9,tblKategoriKomisyon[KomisyonOran]),0)) | J9: =IF($A9="","",ROUND($E9*$G9,2)) | K9: =IF($A9="","",ROUND($J9*$H9,2)) | L9: =IF($A9="","",1)
A10: 86800010005 | B10: STK1005 | C10: Ürün 5 | D10: Süpermarket | E10: 235 | F10: 94 | G10: 2 | H10: 0.12 | I10: =IF($A10="","",IFERROR(SUMIF(tblKategoriKomisyon[Kategori],$D10,tblKategoriKomisyon[KomisyonOran]),0)) | J10: =IF($A10="","",ROUND($E10*$G10,2)) | K10: =IF($A10="","",ROUND($J10*$H10,2)) | L10: =IF($A10="","",1)
A11: 86800010006 | B11: STK1006 | C11: Ürün 6 | D11: Kitap | E11: 252 | F11: 108.36 | G11: 3 | H11: 0.12 | I11: =IF($A11="","",IFERROR(SUMIF(tblKategoriKomisyon[Kategori],$D11,tblKategoriKomisyon[KomisyonOran]),0)) | J11: =IF($A11="","",ROUND($E11*$G11,2)) | K11: =IF($A11="","",ROUND($J11*$H11,2)) | L11: =IF($A11="","",1)
A12: 86800010 | B12: STK1007 | C12: Ürün 7 | D12: Spor | E12: 269 | F12: 123.74 | G12: 4 | H12: 0.12 | I12: =IF($A12="","",IFERROR(SUMIF(tblKategoriKomisyon[Kategori],$D12,tblKategoriKomisyon[KomisyonOran]),0)) | J12: =IF($A12="","",ROUND($E12*$G12,2)) | K12: =IF($A12="","",ROUND($J12*$H12,2)) | L12: =IF($A12="","",1)
A13: 86800010008 | B13: STK1008 | C13: Ürün 8 | D13: Oyuncak | E13: 286 | F13: 140.14 | G13: 1 | H13: 0.12 | I13: =IF($A13="","",IFERROR(SUMIF(tblKategoriKomisyon[Kategori],$D13,tblKategoriKomisyon[KomisyonOran]),0)) | J13: =IF($A13="","",ROUND($E13*$G13,2)) | K13: =IF($A13="","",ROUND($J13*$H13,2)) | L13: =IF($A13="","",1)
A14: 86800010009 | B14: STK1009 | C14: Ürün 9 | D14: Ayakkabı | E14: 303 | F14: 157.56 | G14: 2 | H14: 0.12 | I14: =IF($A14="","",IFERROR(SUMIF(tblKategoriKomisyon[Kategori],$D14,tblKategoriKomisyon[KomisyonOran]),0)) | J14: =IF($A14="","",ROUND($E14*$G14,2)) | K14: =IF($A14="","",ROUND($J14*$H14,2)) | L14: =IF($A14="","",1)
A15: 86800010010 | B15: STK1010 | C15: Ürün 10 | D15: Aksesuar | E15: 320 | F15: 128 | G15: 3 | H15: 0.12 | I15: =IF($A15="","",IFERROR(SUMIF(tblKategoriKomisyon[Kategori],$D15,tblKategoriKomisyon[KomisyonOran]),0)) | J15: =IF($A15="","",ROUND($E15*$G15,2)) | K15: =IF($A15="","",ROUND($J15*$H15,2)) | L15: =IF($A15="","",1)
A16: 86800010 | B16: STK1011 | C16: Ürün 11 | D16: Elektronik | E16: 337 | F16: 144.91 | G16: 4 | H16: 0.12 | I16: =IF($A16="","",IFERROR(SUMIF(tblKategoriKomisyon[Kategori],$D16,tblKategoriKomisyon[KomisyonOran]),0)) | J16: =IF($A16="","",ROUND($E16*$G16,2)) | K16: =IF($A16="","",ROUND($J16*$H16,2)) | L16: =IF($A16="","",1)
A17: 86800010012 | B17: STK1012 | C17: Ürün 12 | D17: Giyim | E17: 354 | F17: 162.84 | G17: 1 | H17: 0.12 | I17: =IF($A17="","",IFERROR(SUMIF(tblKategoriKomisyon[Kategori],$D17,tblKategoriKomisyon[KomisyonOran]),0)) | J17: =IF($A17="","",ROUND($E17*$G17,2)) | K17: =IF($A17="","",ROUND($J17*$H17,2)) | L17: =IF($A17="","",1)
... A40: 86800010035 | B40: STK1035 | C40: Ürün 35 | D40: Süpermarket | E40: 745 | F40: 298 | G40: 4 | H40: 0.12 | I40: =IF($A40="","",IFERROR(SUMIF(tblKategoriKomisyon[Kategori],$D40,tblKategoriKomisyon[KomisyonOran]),0)) | J40: =IF($A40="","",ROUND($E40*$G40,2)) | K40: =IF($A40="","",ROUND($J40*$H40,2)) | L40: =IF($A40="","",1)
I41: =IF($A41="","",IFERROR(SUMIF(tblKategoriKomisyon[Kategori],$D41,tblKategoriKomisyon[KomisyonOran]),0)) | J41: =IF($A41="","",ROUND($E41*$G41,2)) | K41: =IF($A41="","",ROUND($J41*$H41,2)) | L41: =IF($A41="","",1)
I42: =IF($A42="","",IFERROR(SUMIF(tblKategoriKomisyon[Kategori],$D42,tblKategoriKomisyon[KomisyonOran]),0)) | J42: =IF($A42="","",ROUND($E42*$G42,2)) | K42: =IF($A42="","",ROUND($J42*$H42,2)) | L42: =IF($A42="","",1)
I43: =IF($A43="","",IFERROR(SUMIF(tblKategoriKomisyon[Kategori],$D43,tblKategoriKomisyon[KomisyonOran]),0)) | J43: =IF($A43="","",ROUND($E43*$G43,2)) | K43: =IF($A43="","",ROUND($J43*$H43,2)) | L43: =IF($A43="","",1)
I44: =IF($A44="","",IFERROR(SUMIF(tblKategoriKomisyon[Kategori],$D44,tblKategoriKomisyon[KomisyonOran]),0)) | J44: =IF($A44="","",ROUND($E44*$G44,2)) | K44: =IF($A44="","",ROUND($J44*$H44,2)) | L44: =IF($A44="","",1)
I45: =IF($A45="","",IFERROR(SUMIF(tblKategoriKomisyon[Kategori],$D45,tblKategoriKomisyon[KomisyonOran]),0)) | J45: =IF($A45="","",ROUND($E45*$G45,2)) | K45: =IF($A45="","",ROUND($J45*$H45,2)) | L45: =IF($A45="","",1)
I46: =IF($A46="","",IFERROR(SUMIF(tblKategoriKomisyon[Kategori],$D46,tblKategoriKomisyon[KomisyonOran]),0)) | J46: =IF($A46="","",ROUND($E46*$G46,2)) | K46: =IF($A46="","",ROUND($J46*$H46,2)) | L46: =IF($A46="","",1)
I47: =IF($A47="","",IFERROR(SUMIF(tblKategoriKomisyon[Kategori],$D47,tblKategoriKomisyon[KomisyonOran]),0)) | J47: =IF($A47="","",ROUND($E47*$G47,2)) | K47: =IF($A47="","",ROUND($J47*$H47,2)) | L47: =IF($A47="","",1)
I48: =IF($A48="","",IFERROR(SUMIF(tblKategoriKomisyon[Kategori],$D48,tblKategoriKomisyon[KomisyonOran]),0)) | J48: =IF($A48="","",ROUND($E48*$G48,2)) | K48: =IF($A48="","",ROUND($J48*$H48,2)) | L48: =IF($A48="","",1)
I49: =IF($A49="","",IFERROR(SUMIF(tblKategoriKomisyon[Kategori],$D49,tblKategoriKomisyon[KomisyonOran]),0)) | J49: =IF($A49="","",ROUND($E49*$G49,2)) | K49: =IF($A49="","",ROUND($J49*$H49,2)) | L49: =IF($A49="","",1)
I50: =IF($A50="","",IFERROR(SUMIF(tblKategoriKomisyon[Kategori],$D50,tblKategoriKomisyon[KomisyonOran]),0)) | J50: =IF($A50="","",ROUND($E50*$G50,2)) | K50: =IF($A50="","",ROUND($J50*$H50,2)) | L50: =IF($A50="","",1)
I51: =IF($A51="","",IFERROR(SUMIF(tblKategoriKomisyon[Kategori],$D51,tblKategoriKomisyon[KomisyonOran]),0)) | J51: =IF($A51="","",ROUND($E51*$G51,2)) | K51: =IF($A51="","",ROUND($J51*$H51,2)) | L51: =IF($A51="","",1)
I52: =IF($A52="","",IFERROR(SUMIF(tblKategoriKomisyon[Kategori],$D52,tblKategoriKomisyon[KomisyonOran]),0)) | J52: =IF($A52="","",ROUND($E52*$G52,2)) | K52: =IF($A52="","",ROUND($J52*$H52,2)) | L52: =IF($A52="","",1)
... I505: =IF($A505="","",IFERROR(SUMIF(tblKategoriKomisyon[Kategori],$D505,tblKategoriKomisyon[KomisyonOran]),0)) | J505: =IF($A505="","",ROUND($E505*$G505,2)) | K505: =IF($A505="","",ROUND($J505*$H505,2)) | L505: =IF($A505="","",1)

Sheet HAKEDIS
A1: HAKEDIS — Trendyol Komisyon Sonrası Net Kâr Hesaplama
A3: Trendyol hakediş — TY Plus / flaş / reklam / desi / gerçek ödeme
A5: Barkod | B5: TyPlus | C5: FlasKesinti | D5: UrunReklam | E5: DesiKargo | F5: GercekHakedis | G5: Donem | H5: KayitDolu
A6: 86800010001 | B6: 8.02 | C6: 0 | D6: 5 | E6: 33.9 | F6: 215.27 | G6: 2026-07 | H6: =IF($A6="","",1)
A7: 86800010002 | B7: 13.25 | C7: 0 | D7: 5 | E7: 38.4 | F7: 376.67 | G7: 2026-08 | H7: =IF($A7="","",1)
A8: 86800010003 | B8: 19.3 | C8: 0 | D8: 24.5 | E8: 42.9 | F8: 556.5 | G8: 2026-06 | H8: =IF($A8="","",1)
A9: 86800010004 | B9: 5.23 | C9: 0 | D9: 5 | E9: 47.4 | F9: 121.13 | G9: 2026-07 | H9: =IF($A9="","",1)
A10: 86800010005 | B10: 11.28 | C10: 14.1 | D10: 5 | E10: 51.9 | F10: 331.32 | G10: 2026-08 | H10: =IF($A10="","",1)
A11: 86800010006 | B11: 18.14 | C11: 0 | D11: 29 | E11: 29.4 | F11: 566.06 | G11: 2026-06 | H11: =IF($A11="","",1)
A12: 86800010007 | B12: 25.82 | C12: 0 | D12: 5 | E12: 33.9 | F12: 817.6 | G12: 2026-07 | H12: =IF($A12="","",1)
A13: 86800010008 | B13: 6.86 | C13: 0 | D13: 5 | E13: 38.4 | F13: 149.26 | G13: 2026-08 | H13: =IF($A13="","",1)
A14: 86800010009 | B14: 14.54 | C14: 0 | D14: 33.5 | E14: 42.9 | F14: 384.77 | G14: 2026-06 | H14: =IF($A14="","",1)
A15: 86800010010 | B15: 23.04 | C15: 28.8 | D15: 5 | E15: 47.4 | F15: 644.56 | G15: 2026-07 | H15: =IF($A15="","",1)
A16: 86800010011 | B16: 32.35 | C16: 0 | D16: 5 | E16: 51.9 | F16: 968.96 | G16: 2026-08 | H16: =IF($A16="","",1)
A17: 86800010012 | B17: 8.5 | C17: 0 | D17: 38 | E17: 29.4 | F17: 201.99 | G17: 2026-06 | H17: =IF($A17="","",1)
... A40: 86800010035 | B40: 71.52 | C40: 89.4 | D40: 5 | E40: 51.9 | F40: 2404.58 | G40: 2026-08 | H40: =IF($A40="","",1)
H41: =IF($A41="","",1)
H42: =IF($A42="","",1)
H43: =IF($A43="","",1)
H44: =IF($A44="","",1)
H45: =IF($A45="","",1)
H46: =IF($A46="","",1)
H47: =IF($A47="","",1)
H48: =IF($A48="","",1)
H49: =IF($A49="","",1)
H50: =IF($A50="","",1)
H51: =IF($A51="","",1)
H52: =IF($A52="","",1)
... H505: =IF($A505="","",1)

Sheet ANAHTAR
A1: ANAHTAR — Trendyol Komisyon Sonrası Net Kâr Hesaplama
A3: Normalize barkod anahtarı + uzunluk + ikincil + duplike
A4: A Tarafı (Girdi) | I4: B Tarafı (Hakediş)
A5: Ham | B5: Norm | C5: NormUzunluk | D5: IkincilAnahtar | E5: KaynakTaraf | F5: Duplike | G5: SatirNo | I5: HamB | J5: NormB | K5: NormUzunlukB | L5: IkincilB | M5: KaynakB | N5: DuplikeB | O5: SatirNoB
A6: =IF(GIRDI!A6="","",GIRDI!A6) | B6: =UPPER(TRIM(SUBSTITUTE($A6," ",""))) | C6: =IF($B6="",0,LEN($B6)) | D6: =IF($B6="","",LEFT($B6,tyk_ikincilUzunluk)) | E6: ="A" | F6: =IF($B6="","",IF(COUNTIF(tblAnahtarA[Norm],$B6)>1,"EVET","HAYIR")) | G6: =IF($A6="","",ROW()-ROW($A$5)) | I6: =IF(HAKEDIS!A6="","",HAKEDIS!A6) | J6: =UPPER(TRIM(SUBSTITUTE($I6," ",""))) | K6: =IF($J6="",0,LEN($J6)) | L6: =IF($J6="","",LEFT($J6,tyk_ikincilUzunluk)) | M6: ="B" | N6: =IF($J6="","",IF(COUNTIF(tblAnahtarB[NormB],$J6)>1,"EVET","HAYIR")) | O6: =IF($I6="","",ROW()-ROW($I$5))
A7: =IF(GIRDI!A7="","",GIRDI!A7) | B7: =UPPER(TRIM(SUBSTITUTE($A7," ",""))) | C7: =IF($B7="",0,LEN($B7)) | D7: =IF($B7="","",LEFT($B7,tyk_ikincilUzunluk)) | E7: ="A" | F7: =IF($B7="","",IF(COUNTIF(tblAnahtarA[Norm],$B7)>1,"EVET","HAYIR")) | G7: =IF($A7="","",ROW()-ROW($A$5)) | I7: =IF(HAKEDIS!A7="","",HAKEDIS!A7) | J7: =UPPER(TRIM(SUBSTITUTE($I7," ",""))) | K7: =IF($J7="",0,LEN($J7)) | L7: =IF($J7="","",LEFT($J7,tyk_ikincilUzunluk)) | M7: ="B" | N7: =IF($J7="","",IF(COUNTIF(tblAnahtarB[NormB],$J7)>1,"EVET","HAYIR")) | O7: =IF($I7="","",ROW()-ROW($I$5))
A8: =IF(GIRDI!A8="","",GIRDI!A8) | B8: =UPPER(TRIM(SUBSTITUTE($A8," ",""))) | C8: =IF($B8="",0,LEN($B8)) | D8: =IF($B8="","",LEFT($B8,tyk_ikincilUzunluk)) | E8: ="A" | F8: =IF($B8="","",IF(COUNTIF(tblAnahtarA[Norm],$B8)>1,"EVET","HAYIR")) | G8: =IF($A8="","",ROW()-ROW($A$5)) | I8: =IF(HAKEDIS!A8="","",HAKEDIS!A8) | J8: =UPPER(TRIM(SUBSTITUTE($I8," ",""))) | K8: =IF($J8="",0,LEN($J8)) | L8: =IF($J8="","",LEFT($J8,tyk_ikincilUzunluk)) | M8: ="B" | N8: =IF($J8="","",IF(COUNTIF(tblAnahtarB[NormB],$J8)>1,"EVET","HAYIR")) | O8: =IF($I8="","",ROW()-ROW($I$5))
A9: =IF(GIRDI!A9="","",GIRDI!A9) | B9: =UPPER(TRIM(SUBSTITUTE($A9," ",""))) | C9: =IF($B9="",0,LEN($B9)) | D9: =IF($B9="","",LEFT($B9,tyk_ikincilUzunluk)) | E9: ="A" | F9: =IF($B9="","",IF(COUNTIF(tblAnahtarA[Norm],$B9)>1,"EVET","HAYIR")) | G9: =IF($A9="","",ROW()-ROW($A$5)) | I9: =IF(HAKEDIS!A9="","",HAKEDIS!A9) | J9: =UPPER(TRIM(SUBSTITUTE($I9," ",""))) | K9: =IF($J9="",0,LEN($J9)) | L9: =IF($J9="","",LEFT($J9,tyk_ikincilUzunluk)) | M9: ="B" | N9: =IF($J9="","",IF(COUNTIF(tblAnahtarB[NormB],$J9)>1,"EVET","HAYIR")) | O9: =IF($I9="","",ROW()-ROW($I$5))
A10: =IF(GIRDI!A10="","",GIRDI!A10) | B10: =UPPER(TRIM(SUBSTITUTE($A10," ",""))) | C10: =IF($B10="",0,LEN($B10)) | D10: =IF($B10="","",LEFT($B10,tyk_ikincilUzunluk)) | E10: ="A" | F10: =IF($B10="","",IF(COUNTIF(tblAnahtarA[Norm],$B10)>1,"EVET","HAYIR")) | G10: =IF($A10="","",ROW()-ROW($A$5)) | I10: =IF(HAKEDIS!A10="","",HAKEDIS!A10) | J10: =UPPER(TRIM(SUBSTITUTE($I10," ",""))) | K10: =IF($J10="",0,LEN($J10)) | L10: =IF($J10="","",LEFT($J10,tyk_ikincilUzunluk)) | M10: ="B" | N10: =IF($J10="","",IF(COUNTIF(tblAnahtarB[NormB],$J10)>1,"EVET","HAYIR")) | O10: =IF($I10="","",ROW()-ROW($I$5))
A11: =IF(GIRDI!A11="","",GIRDI!A11) | B11: =UPPER(TRIM(SUBSTITUTE($A11," ",""))) | C11: =IF($B11="",0,LEN($B11)) | D11: =IF($B11="","",LEFT($B11,tyk_ikincilUzunluk)) | E11: ="A" | F11: =IF($B11="","",IF(COUNTIF(tblAnahtarA[Norm],$B11)>1,"EVET","HAYIR")) | G11: =IF($A11="","",ROW()-ROW($A$5)) | I11: =IF(HAKEDIS!A11="","",HAKEDIS!A11) | J11: =UPPER(TRIM(SUBSTITUTE($I11," ",""))) | K11: =IF($J11="",0,LEN($J11)) | L11: =IF($J11="","",LEFT($J11,tyk_ikincilUzunluk)) | M11: ="B" | N11: =IF($J11="","",IF(COUNTIF(tblAnahtarB[NormB],$J11)>1,"EVET","HAYIR")) | O11: =IF($I11="","",ROW()-ROW($I$5))
A12: =IF(GIRDI!A12="","",GIRDI!A12) | B12: =UPPER(TRIM(SUBSTITUTE($A12," ",""))) | C12: =IF($B12="",0,LEN($B12)) | D12: =IF($B12="","",LEFT($B12,tyk_ikincilUzunluk)) | E12: ="A" | F12: =IF($B12="","",IF(COUNTIF(tblAnahtarA[Norm],$B12)>1,"EVET","HAYIR")) | G12: =IF($A12="","",ROW()-ROW($A$5)) | I12: =IF(HAKEDIS!A12="","",HAKEDIS!A12) | J12: =UPPER(TRIM(SUBSTITUTE($I12," ",""))) | K12: =IF($J12="",0,LEN($J12)) | L12: =IF($J12="","",LEFT($J12,tyk_ikincilUzunluk)) | M12: ="B" | N12: =IF($J12="","",IF(COUNTIF(tblAnahtarB[NormB],$J12)>1,"EVET","HAYIR")) | O12: =IF($I12="","",ROW()-ROW($I$5))
A13: =IF(GIRDI!A13="","",GIRDI!A13) | B13: =UPPER(TRIM(SUBSTITUTE($A13," ",""))) | C13: =IF($B13="",0,LEN($B13)) | D13: =IF($B13="","",LEFT($B13,tyk_ikincilUzunluk)) | E13: ="A" | F13: =IF($B13="","",IF(COUNTIF(tblAnahtarA[Norm],$B13)>1,"EVET","HAYIR")) | G13: =IF($A13="","",ROW()-ROW($A$5)) | I13: =IF(HAKEDIS!A13="","",HAKEDIS!A13) | J13: =UPPER(TRIM(SUBSTITUTE($I13," ",""))) | K13: =IF($J13="",0,LEN($J13)) | L13: =IF($J13="","",LEFT($J13,tyk_ikincilUzunluk)) | M13: ="B" | N13: =IF($J13="","",IF(COUNTIF(tblAnahtarB[NormB],$J13)>1,"EVET","HAYIR")) | O13: =IF($I13="","",ROW()-ROW($I$5))
A14: =IF(GIRDI!A14="","",GIRDI!A14) | B14: =UPPER(TRIM(SUBSTITUTE($A14," ",""))) | C14: =IF($B14="",0,LEN($B14)) | D14: =IF($B14="","",LEFT($B14,tyk_ikincilUzunluk)) | E14: ="A" | F14: =IF($B14="","",IF(COUNTIF(tblAnahtarA[Norm],$B14)>1,"EVET","HAYIR")) | G14: =IF($A14="","",ROW()-ROW($A$5)) | I14: =IF(HAKEDIS!A14="","",HAKEDIS!A14) | J14: =UPPER(TRIM(SUBSTITUTE($I14," ",""))) | K14: =IF($J14="",0,LEN($J14)) | L14: =IF($J14="","",LEFT($J14,tyk_ikincilUzunluk)) | M14: ="B" | N14: =IF($J14="","",IF(COUNTIF(tblAnahtarB[NormB],$J14)>1,"EVET","HAYIR")) | O14: =IF($I14="","",ROW()-ROW($I$5))
A15: =IF(GIRDI!A15="","",GIRDI!A15) | B15: =UPPER(TRIM(SUBSTITUTE($A15," ",""))) | C15: =IF($B15="",0,LEN($B15)) | D15: =IF($B15="","",LEFT($B15,tyk_ikincilUzunluk)) | E15: ="A" | F15: =IF($B15="","",IF(COUNTIF(tblAnahtarA[Norm],$B15)>1,"EVET","HAYIR")) | G15: =IF($A15="","",ROW()-ROW($A$5)) | I15: =IF(HAKEDIS!A15="","",HAKEDIS!A15) | J15: =UPPER(TRIM(SUBSTITUTE($I15," ",""))) | K15: =IF($J15="",0,LEN($J15)) | L15: =IF($J15="","",LEFT($J15,tyk_ikincilUzunluk)) | M15: ="B" | N15: =IF($J15="","",IF(COUNTIF(tblAnahtarB[NormB],$J15)>1,"EVET","HAYIR")) | O15: =IF($I15="","",ROW()-ROW($I$5))
A16: =IF(GIRDI!A16="","",GIRDI!A16) | B16: =UPPER(TRIM(SUBSTITUTE($A16," ",""))) | C16: =IF($B16="",0,LEN($B16)) | D16: =IF($B16="","",LEFT($B16,tyk_ikincilUzunluk)) | E16: ="A" | F16: =IF($B16="","",IF(COUNTIF(tblAnahtarA[Norm],$B16)>1,"EVET","HAYIR")) | G16: =IF($A16="","",ROW()-ROW($A$5)) | I16: =IF(HAKEDIS!A16="","",HAKEDIS!A16) | J16: =UPPER(TRIM(SUBSTITUTE($I16," ",""))) | K16: =IF($J16="",0,LEN($J16)) | L16: =IF($J16="","",LEFT($J16,tyk_ikincilUzunluk)) | M16: ="B" | N16: =IF($J16="","",IF(COUNTIF(tblAnahtarB[NormB],$J16)>1,"EVET","HAYIR")) | O16: =IF($I16="","",ROW()-ROW($I$5))
A17: =IF(GIRDI!A17="","",GIRDI!A17) | B17: =UPPER(TRIM(SUBSTITUTE($A17," ",""))) | C17: =IF($B17="",0,LEN($B17)) | D17: =IF($B17="","",LEFT($B17,tyk_ikincilUzunluk)) | E17: ="A" | F17: =IF($B17="","",IF(COUNTIF(tblAnahtarA[Norm],$B17)>1,"EVET","HAYIR")) | G17: =IF($A17="","",ROW()-ROW($A$5)) | I17: =IF(HAKEDIS!A17="","",HAKEDIS!A17) | J17: =UPPER(TRIM(SUBSTITUTE($I17," ",""))) | K17: =IF($J17="",0,LEN($J17)) | L17: =IF($J17="","",LEFT($J17,tyk_ikincilUzunluk)) | M17: ="B" | N17: =IF($J17="","",IF(COUNTIF(tblAnahtarB[NormB],$J17)>1,"EVET","HAYIR")) | O17: =IF($I17="","",ROW()-ROW($I$5))
... A505: =IF(GIRDI!A505="","",GIRDI!A505) | B505: =UPPER(TRIM(SUBSTITUTE($A505," ",""))) | C505: =IF($B505="",0,LEN($B505)) | D505: =IF($B505="","",LEFT($B505,tyk_ikincilUzunluk)) | E505: ="A" | F505: =IF($B505="","",IF(COUNTIF(tblAnahtarA[Norm],$B505)>1,"EVET","HAYIR")) | G505: =IF($A505="","",ROW()-ROW($A$5)) | I505: =IF(HAKEDIS!A505="","",HAKEDIS!A505) | J505: =UPPER(TRIM(SUBSTITUTE($I505," ",""))) | K505: =IF($J505="",0,LEN($J505)) | L505: =IF($J505="","",LEFT($J505,tyk_ikincilUzunluk)) | M505: ="B" | N505: =IF($J505="","",IF(COUNTIF(tblAnahtarB[NormB],$J505)>1,"EVET","HAYIR")) | O505: =IF($I505="","",ROW()-ROW($I$5))

Sheet MOTOR
A1: MOTOR — Trendyol Komisyon Sonrası Net Kâr Hesaplama
A3: Net kâr motoru — kesinti kırılımı, başabaş, satır kararı
A5: A_Norm | B5: Satis | C5: Maliyet | D5: Miktar | E5: KomisyonOran | F5: KomisyonTutar | G5: TyPlus | H5: FlasKesinti | I5: UrunReklam | J5: DesiKargo | K5: ToplamKesinti | L5: BrutKar | M5: NetKar | N5: Marj | O5: BasabasFiyat | P5: HedefNet | Q5: FarkHedef | R5: BeklenenHakedis | S5: KararSatir | T5: MotorAdim1 | U5: MotorAdim2 | V5: MotorAdim3
A6: =IF('ANAHTAR'!$B6="","",'ANAHTAR'!$B6) | B6: =IF($A6="","",IFERROR(SUMIF(tblAnahtarA[Norm],$A6,tblGirdi[ToplamSatis]),0)) | C6: =IF($A6="","",IFERROR(SUMIF(tblAnahtarA[Norm],$A6,tblGirdi[Maliyet])*IFERROR(SUMIF(tblAnahtarA[Norm],$A6,tblGirdi[Miktar]),1),0)) | D6: =IF($A6="","",IFERROR(SUMIF(tblAnahtarA[Norm],$A6,tblGirdi[Miktar]),0)) | E6: =IF($A6="","",IFERROR(SUMIF(tblAnahtarA[Norm],$A6,tblGirdi[KomisyonOran]),0)) | F6: =IF($A6="","",ROUND($B6*$E6,2)) | G6: =IF($A6="","",IFERROR(SUMIF(tblAnahtarB[NormB],$A6,tblHakedis[TyPlus]),0)) | H6: =IF($A6="","",IFERROR(SUMIF(tblAnahtarB[NormB],$A6,tblHakedis[FlasKesinti]),0)) | I6: =IF($A6="","",IFERROR(SUMIF(tblAnahtarB[NormB],$A6,tblHakedis[UrunReklam]),0)) | J6: =IF($A6="","",IFERROR(SUMIF(tblAnahtarB[NormB],$A6,tblHakedis[DesiKargo]),0)) | K6: =IF($A6="","",ROUND($F6+$G6+$H6+$I6+$J6,2)) | L6: =IF($A6="","",ROUND($B6-$C6,2)) | M6: =IF($A6="","",ROUND($B6-$C6-$K6,2)) | N6: =IF(OR($A6="",$B6=0),0,$M6/$B6) | O6: =IF($A6="","",IF((1-$E6)<=0,0,IF($D6=0,0,ROUND(($C6+$G6+$H6+$I6+$J6)/$D6/(1-$E6),2)))) | P6: =IF($A6="","",IFERROR(SUMIF(tblAnahtarA[Norm],$A6,tblGirdi[HedefNet]),0)) | Q6: =IF($A6="","",ROUND($M6-$P6,2)) | R6: =IF($A6="","",ROUND($B6-$K6,2)) | S6: =IF($A6="","",IF($N6<0,"ÇEKİL",IF($N6<tyk_esikMarjDusuk,"ZAM","SAT"))) | T6: =IF($A6="","",$L6-$F6) | U6: =IF($A6="","",$M6-$Q6) | V6: =IF($A6="","",$R6-$M6)
A7: =IF('ANAHTAR'!$B7="","",'ANAHTAR'!$B7) | B7: =IF($A7="","",IFERROR(SUMIF(tblAnahtarA[Norm],$A7,tblGirdi[ToplamSatis]),0)) | C7: =IF($A7="","",IFERROR(SUMIF(tblAnahtarA[Norm],$A7,tblGirdi[Maliyet])*IFERROR(SUMIF(tblAnahtarA[Norm],$A7,tblGirdi[Miktar]),1),0)) | D7: =IF($A7="","",IFERROR(SUMIF(tblAnahtarA[Norm],$A7,tblGirdi[Miktar]),0)) | E7: =IF($A7="","",IFERROR(SUMIF(tblAnahtarA[Norm],$A7,tblGirdi[KomisyonOran]),0)) | F7: =IF($A7="","",ROUND($B7*$E7,2)) | G7: =IF($A7="","",IFERROR(SUMIF(tblAnahtarB[NormB],$A7,tblHakedis[TyPlus]),0)) | H7: =IF($A7="","",IFERROR(SUMIF(tblAnahtarB[NormB],$A7,tblHakedis[FlasKesinti]),0)) | I7: =IF($A7="","",IFERROR(SUMIF(tblAnahtarB[NormB],$A7,tblHakedis[UrunReklam]),0)) | J7: =IF($A7="","",IFERROR(SUMIF(tblAnahtarB[NormB],$A7,tblHakedis[DesiKargo]),0)) | K7: =IF($A7="","",ROUND($F7+$G7+$H7+$I7+$J7,2)) | L7: =IF($A7="","",ROUND($B7-$C7,2)) | M7: =IF($A7="","",ROUND($B7-$C7-$K7,2)) | N7: =IF(OR($A7="",$B7=0),0,$M7/$B7) | O7: =IF($A7="","",IF((1-$E7)<=0,0,IF($D7=0,0,ROUND(($C7+$G7+$H7+$I7+$J7)/$D7/(1-$E7),2)))) | P7: =IF($A7="","",IFERROR(SUMIF(tblAnahtarA[Norm],$A7,tblGirdi[HedefNet]),0)) | Q7: =IF($A7="","",ROUND($M7-$P7,2)) | R7: =IF($A7="","",ROUND($B7-$K7,2)) | S7: =IF($A7="","",IF($N7<0,"ÇEKİL",IF($N7<tyk_esikMarjDusuk,"ZAM","SAT"))) | T7: =IF($A7="","",$L7-$F7) | U7: =IF($A7="","",$M7-$Q7) | V7: =IF($A7="","",$R7-$M7)
A8: =IF('ANAHTAR'!$B8="","",'ANAHTAR'!$B8) | B8: =IF($A8="","",IFERROR(SUMIF(tblAnahtarA[Norm],$A8,tblGirdi[ToplamSatis]),0)) | C8: =IF($A8="","",IFERROR(SUMIF(tblAnahtarA[Norm],$A8,tblGirdi[Maliyet])*IFERROR(SUMIF(tblAnahtarA[Norm],$A8,tblGirdi[Miktar]),1),0)) | D8: =IF($A8="","",IFERROR(SUMIF(tblAnahtarA[Norm],$A8,tblGirdi[Miktar]),0)) | E8: =IF($A8="","",IFERROR(SUMIF(tblAnahtarA[Norm],$A8,tblGirdi[KomisyonOran]),0)) | F8: =IF($A8="","",ROUND($B8*$E8,2)) | G8: =IF($A8="","",IFERROR(SUMIF(tblAnahtarB[NormB],$A8,tblHakedis[TyPlus]),0)) | H8: =IF($A8="","",IFERROR(SUMIF(tblAnahtarB[NormB],$A8,tblHakedis[FlasKesinti]),0)) | I8: =IF($A8="","",IFERROR(SUMIF(tblAnahtarB[NormB],$A8,tblHakedis[UrunReklam]),0)) | J8: =IF($A8="","",IFERROR(SUMIF(tblAnahtarB[NormB],$A8,tblHakedis[DesiKargo]),0)) | K8: =IF($A8="","",ROUND($F8+$G8+$H8+$I8+$J8,2)) | L8: =IF($A8="","",ROUND($B8-$C8,2)) | M8: =IF($A8="","",ROUND($B8-$C8-$K8,2)) | N8: =IF(OR($A8="",$B8=0),0,$M8/$B8) | O8: =IF($A8="","",IF((1-$E8)<=0,0,IF($D8=0,0,ROUND(($C8+$G8+$H8+$I8+$J8)/$D8/(1-$E8),2)))) | P8: =IF($A8="","",IFERROR(SUMIF(tblAnahtarA[Norm],$A8,tblGirdi[HedefNet]),0)) | Q8: =IF($A8="","",ROUND($M8-$P8,2)) | R8: =IF($A8="","",ROUND($B8-$K8,2)) | S8: =IF($A8="","",IF($N8<0,"ÇEKİL",IF($N8<tyk_esikMarjDusuk,"ZAM","SAT"))) | T8: =IF($A8="","",$L8-$F8) | U8: =IF($A8="","",$M8-$Q8) | V8: =IF($A8="","",$R8-$M8)
A9: =IF('ANAHTAR'!$B9="","",'ANAHTAR'!$B9) | B9: =IF($A9="","",IFERROR(SUMIF(tblAnahtarA[Norm],$A9,tblGirdi[ToplamSatis]),0)) | C9: =IF($A9="","",IFERROR(SUMIF(tblAnahtarA[Norm],$A9,tblGirdi[Maliyet])*IFERROR(SUMIF(tblAnahtarA[Norm],$A9,tblGirdi[Miktar]),1),0)) | D9: =IF($A9="","",IFERROR(SUMIF(tblAnahtarA[Norm],$A9,tblGirdi[Miktar]),0)) | E9: =IF($A9="","",IFERROR(SUMIF(tblAnahtarA[Norm],$A9,tblGirdi[KomisyonOran]),0)) | F9: =IF($A9="","",ROUND($B9*$E9,2)) | G9: =IF($A9="","",IFERROR(SUMIF(tblAnahtarB[NormB],$A9,tblHakedis[TyPlus]),0)) | H9: =IF($A9="","",IFERROR(SUMIF(tblAnahtarB[NormB],$A9,tblHakedis[FlasKesinti]),0)) | I9: =IF($A9="","",IFERROR(SUMIF(tblAnahtarB[NormB],$A9,tblHakedis[UrunReklam]),0)) | J9: =IF($A9="","",IFERROR(SUMIF(tblAnahtarB[NormB],$A9,tblHakedis[DesiKargo]),0)) | K9: =IF($A9="","",ROUND($F9+$G9+$H9+$I9+$J9,2)) | L9: =IF($A9="","",ROUND($B9-$C9,2)) | M9: =IF($A9="","",ROUND($B9-$C9-$K9,2)) | N9: =IF(OR($A9="",$B9=0),0,$M9/$B9) | O9: =IF($A9="","",IF((1-$E9)<=0,0,IF($D9=0,0,ROUND(($C9+$G9+$H9+$I9+$J9)/$D9/(1-$E9),2)))) | P9: =IF($A9="","",IFERROR(SUMIF(tblAnahtarA[Norm],$A9,tblGirdi[HedefNet]),0)) | Q9: =IF($A9="","",ROUND($M9-$P9,2)) | R9: =IF($A9="","",ROUND($B9-$K9,2)) | S9: =IF($A9="","",IF($N9<0,"ÇEKİL",IF($N9<tyk_esikMarjDusuk,"ZAM","SAT"))) | T9: =IF($A9="","",$L9-$F9) | U9: =IF($A9="","",$M9-$Q9) | V9: =IF($A9="","",$R9-$M9)
A10: =IF('ANAHTAR'!$B10="","",'ANAHTAR'!$B10) | B10: =IF($A10="","",IFERROR(SUMIF(tblAnahtarA[Norm],$A10,tblGirdi[ToplamSatis]),0)) | C10: =IF($A10="","",IFERROR(SUMIF(tblAnahtarA[Norm],$A10,tblGirdi[Maliyet])*IFERROR(SUMIF(tblAnahtarA[Norm],$A10,tblGirdi[Miktar]),1),0)) | D10: =IF($A10="","",IFERROR(SUMIF(tblAnahtarA[Norm],$A10,tblGirdi[Miktar]),0)) | E10: =IF($A10="","",IFERROR(SUMIF(tblAnahtarA[Norm],$A10,tblGirdi[KomisyonOran]),0)) | F10: =IF($A10="","",ROUND($B10*$E10,2)) | G10: =IF($A10="","",IFERROR(SUMIF(tblAnahtarB[NormB],$A10,tblHakedis[TyPlus]),0)) | H10: =IF($A10="","",IFERROR(SUMIF(tblAnahtarB[NormB],$A10,tblHakedis[FlasKesinti]),0)) | I10: =IF($A10="","",IFERROR(SUMIF(tblAnahtarB[NormB],$A10,tblHakedis[UrunReklam]),0)) | J10: =IF($A10="","",IFERROR(SUMIF(tblAnahtarB[NormB],$A10,tblHakedis[DesiKargo]),0)) | K10: =IF($A10="","",ROUND($F10+$G10+$H10+$I10+$J10,2)) | L10: =IF($A10="","",ROUND($B10-$C10,2)) | M10: =IF($A10="","",ROUND($B10-$C10-$K10,2)) | N10: =IF(OR($A10="",$B10=0),0,$M10/$B10) | O10: =IF($A10="","",IF((1-$E10)<=0,0,IF($D10=0,0,ROUND(($C10+$G10+$H10+$I10+$J10)/$D10/(1-$E10),2)))) | P10: =IF($A10="","",IFERROR(SUMIF(tblAnahtarA[Norm],$A10,tblGirdi[HedefNet]),0)) | Q10: =IF($A10="","",ROUND($M10-$P10,2)) | R10: =IF($A10="","",ROUND($B10-$K10,2)) | S10: =IF($A10="","",IF($N10<0,"ÇEKİL",IF($N10<tyk_esikMarjDusuk,"ZAM","SAT"))) | T10: =IF($A10="","",$L10-$F10) | U10: =IF($A10="","",$M10-$Q10) | V10: =IF($A10="","",$R10-$M10)
A11: =IF('ANAHTAR'!$B11="","",'ANAHTAR'!$B11) | B11: =IF($A11="","",IFERROR(SUMIF(tblAnahtarA[Norm],$A11,tblGirdi[ToplamSatis]),0)) | C11: =IF($A11="","",IFERROR(SUMIF(tblAnahtarA[Norm],$A11,tblGirdi[Maliyet])*IFERROR(SUMIF(tblAnahtarA[Norm],$A11,tblGirdi[Miktar]),1),0)) | D11: =IF($A11="","",IFERROR(SUMIF(tblAnahtarA[Norm],$A11,tblGirdi[Miktar]),0)) | E11: =IF($A11="","",IFERROR(SUMIF(tblAnahtarA[Norm],$A11,tblGirdi[KomisyonOran]),0)) | F11: =IF($A11="","",ROUND($B11*$E11,2)) | G11: =IF($A11="","",IFERROR(SUMIF(tblAnahtarB[NormB],$A11,tblHakedis[TyPlus]),0)) | H11: =IF($A11="","",IFERROR(SUMIF(tblAnahtarB[NormB],$A11,tblHakedis[FlasKesinti]),0)) | I11: =IF($A11="","",IFERROR(SUMIF(tblAnahtarB[NormB],$A11,tblHakedis[UrunReklam]),0)) | J11: =IF($A11="","",IFERROR(SUMIF(tblAnahtarB[NormB],$A11,tblHakedis[DesiKargo]),0)) | K11: =IF($A11="","",ROUND($F11+$G11+$H11+$I11+$J11,2)) | L11: =IF($A11="","",ROUND($B11-$C11,2)) | M11: =IF($A11="","",ROUND($B11-$C11-$K11,2)) | N11: =IF(OR($A11="",$B11=0),0,$M11/$B11) | O11: =IF($A11="","",IF((1-$E11)<=0,0,IF($D11=0,0,ROUND(($C11+$G11+$H11+$I11+$J11)/$D11/(1-$E11),2)))) | P11: =IF($A11="","",IFERROR(SUMIF(tblAnahtarA[Norm],$A11,tblGirdi[HedefNet]),0)) | Q11: =IF($A11="","",ROUND($M11-$P11,2)) | R11: =IF($A11="","",ROUND($B11-$K11,2)) | S11: =IF($A11="","",IF($N11<0,"ÇEKİL",IF($N11<tyk_esikMarjDusuk,"ZAM","SAT"))) | T11: =IF($A11="","",$L11-$F11) | U11: =IF($A11="","",$M11-$Q11) | V11: =IF($A11="","",$R11-$M11)
A12: =IF('ANAHTAR'!$B12="","",'ANAHTAR'!$B12) | B12: =IF($A12="","",IFERROR(SUMIF(tblAnahtarA[Norm],$A12,tblGirdi[ToplamSatis]),0)) | C12: =IF($A12="","",IFERROR(SUMIF(tblAnahtarA[Norm],$A12,tblGirdi[Maliyet])*IFERROR(SUMIF(tblAnahtarA[Norm],$A12,tblGirdi[Miktar]),1),0)) | D12: =IF($A12="","",IFERROR(SUMIF(tblAnahtarA[Norm],$A12,tblGirdi[Miktar]),0)) | E12: =IF($A12="","",IFERROR(SUMIF(tblAnahtarA[Norm],$A12,tblGirdi[KomisyonOran]),0)) | F12: =IF($A12="","",ROUND($B12*$E12,2)) | G12: =IF($A12="","",IFERROR(SUMIF(tblAnahtarB[NormB],$A12,tblHakedis[TyPlus]),0)) | H12: =IF($A12="","",IFERROR(SUMIF(tblAnahtarB[NormB],$A12,tblHakedis[FlasKesinti]),0)) | I12: =IF($A12="","",IFERROR(SUMIF(tblAnahtarB[NormB],$A12,tblHakedis[UrunReklam]),0)) | J12: =IF($A12="","",IFERROR(SUMIF(tblAnahtarB[NormB],$A12,tblHakedis[DesiKargo]),0)) | K12: =IF($A12="","",ROUND($F12+$G12+$H12+$I12+$J12,2)) | L12: =IF($A12="","",ROUND($B12-$C12,2)) | M12: =IF($A12="","",ROUND($B12-$C12-$K12,2)) | N12: =IF(OR($A12="",$B12=0),0,$M12/$B12) | O12: =IF($A12="","",IF((1-$E12)<=0,0,IF($D12=0,0,ROUND(($C12+$G12+$H12+$I12+$J12)/$D12/(1-$E12),2)))) | P12: =IF($A12="","",IFERROR(SUMIF(tblAnahtarA[Norm],$A12,tblGirdi[HedefNet]),0)) | Q12: =IF($A12="","",ROUND($M12-$P12,2)) | R12: =IF($A12="","",ROUND($B12-$K12,2)) | S12: =IF($A12="","",IF($N12<0,"ÇEKİL",IF($N12<tyk_esikMarjDusuk,"ZAM","SAT"))) | T12: =IF($A12="","",$L12-$F12) | U12: =IF($A12="","",$M12-$Q12) | V12: =IF($A12="","",$R12-$M12)
A13: =IF('ANAHTAR'!$B13="","",'ANAHTAR'!$B13) | B13: =IF($A13="","",IFERROR(SUMIF(tblAnahtarA[Norm],$A13,tblGirdi[ToplamSatis]),0)) | C13: =IF($A13="","",IFERROR(SUMIF(tblAnahtarA[Norm],$A13,tblGirdi[Maliyet])*IFERROR(SUMIF(tblAnahtarA[Norm],$A13,tblGirdi[Miktar]),1),0)) | D13: =IF($A13="","",IFERROR(SUMIF(tblAnahtarA[Norm],$A13,tblGirdi[Miktar]),0)) | E13: =IF($A13="","",IFERROR(SUMIF(tblAnahtarA[Norm],$A13,tblGirdi[KomisyonOran]),0)) | F13: =IF($A13="","",ROUND($B13*$E13,2)) | G13: =IF($A13="","",IFERROR(SUMIF(tblAnahtarB[NormB],$A13,tblHakedis[TyPlus]),0)) | H13: =IF($A13="","",IFERROR(SUMIF(tblAnahtarB[NormB],$A13,tblHakedis[FlasKesinti]),0)) | I13: =IF($A13="","",IFERROR(SUMIF(tblAnahtarB[NormB],$A13,tblHakedis[UrunReklam]),0)) | J13: =IF($A13="","",IFERROR(SUMIF(tblAnahtarB[NormB],$A13,tblHakedis[DesiKargo]),0)) | K13: =IF($A13="","",ROUND($F13+$G13+$H13+$I13+$J13,2)) | L13: =IF($A13="","",ROUND($B13-$C13,2)) | M13: =IF($A13="","",ROUND($B13-$C13-$K13,2)) | N13: =IF(OR($A13="",$B13=0),0,$M13/$B13) | O13: =IF($A13="","",IF((1-$E13)<=0,0,IF($D13=0,0,ROUND(($C13+$G13+$H13+$I13+$J13)/$D13/(1-$E13),2)))) | P13: =IF($A13="","",IFERROR(SUMIF(tblAnahtarA[Norm],$A13,tblGirdi[HedefNet]),0)) | Q13: =IF($A13="","",ROUND($M13-$P13,2)) | R13: =IF($A13="","",ROUND($B13-$K13,2)) | S13: =IF($A13="","",IF($N13<0,"ÇEKİL",IF($N13<tyk_esikMarjDusuk,"ZAM","SAT"))) | T13: =IF($A13="","",$L13-$F13) | U13: =IF($A13="","",$M13-$Q13) | V13: =IF($A13="","",$R13-$M13)
A14: =IF('ANAHTAR'!$B14="","",'ANAHTAR'!$B14) | B14: =IF($A14="","",IFERROR(SUMIF(tblAnahtarA[Norm],$A14,tblGirdi[ToplamSatis]),0)) | C14: =IF($A14="","",IFERROR(SUMIF(tblAnahtarA[Norm],$A14,tblGirdi[Maliyet])*IFERROR(SUMIF(tblAnahtarA[Norm],$A14,tblGirdi[Miktar]),1),0)) | D14: =IF($A14="","",IFERROR(SUMIF(tblAnahtarA[Norm],$A14,tblGirdi[Miktar]),0)) | E14: =IF($A14="","",IFERROR(SUMIF(tblAnahtarA[Norm],$A14,tblGirdi[KomisyonOran]),0)) | F14: =IF($A14="","",ROUND($B14*$E14,2)) | G14: =IF($A14="","",IFERROR(SUMIF(tblAnahtarB[NormB],$A14,tblHakedis[TyPlus]),0)) | H14: =IF($A14="","",IFERROR(SUMIF(tblAnahtarB[NormB],$A14,tblHakedis[FlasKesinti]),0)) | I14: =IF($A14="","",IFERROR(SUMIF(tblAnahtarB[NormB],$A14,tblHakedis[UrunReklam]),0)) | J14: =IF($A14="","",IFERROR(SUMIF(tblAnahtarB[NormB],$A14,tblHakedis[DesiKargo]),0)) | K14: =IF($A14="","",ROUND($F14+$G14+$H14+$I14+$J14,2)) | L14: =IF($A14="","",ROUND($B14-$C14,2)) | M14: =IF($A14="","",ROUND($B14-$C14-$K14,2)) | N14: =IF(OR($A14="",$B14=0),0,$M14/$B14) | O14: =IF($A14="","",IF((1-$E14)<=0,0,IF($D14=0,0,ROUND(($C14+$G14+$H14+$I14+$J14)/$D14/(1-$E14),2)))) | P14: =IF($A14="","",IFERROR(SUMIF(tblAnahtarA[Norm],$A14,tblGirdi[HedefNet]),0)) | Q14: =IF($A14="","",ROUND($M14-$P14,2)) | R14: =IF($A14="","",ROUND($B14-$K14,2)) | S14: =IF($A14="","",IF($N14<0,"ÇEKİL",IF($N14<tyk_esikMarjDusuk,"ZAM","SAT"))) | T14: =IF($A14="","",$L14-$F14) | U14: =IF($A14="","",$M14-$Q14) | V14: =IF($A14="","",$R14-$M14)
A15: =IF('ANAHTAR'!$B15="","",'ANAHTAR'!$B15) | B15: =IF($A15="","",IFERROR(SUMIF(tblAnahtarA[Norm],$A15,tblGirdi[ToplamSatis]),0)) | C15: =IF($A15="","",IFERROR(SUMIF(tblAnahtarA[Norm],$A15,tblGirdi[Maliyet])*IFERROR(SUMIF(tblAnahtarA[Norm],$A15,tblGirdi[Miktar]),1),0)) | D15: =IF($A15="","",IFERROR(SUMIF(tblAnahtarA[Norm],$A15,tblGirdi[Miktar]),0)) | E15: =IF($A15="","",IFERROR(SUMIF(tblAnahtarA[Norm],$A15,tblGirdi[KomisyonOran]),0)) | F15: =IF($A15="","",ROUND($B15*$E15,2)) | G15: =IF($A15="","",IFERROR(SUMIF(tblAnahtarB[NormB],$A15,tblHakedis[TyPlus]),0)) | H15: =IF($A15="","",IFERROR(SUMIF(tblAnahtarB[NormB],$A15,tblHakedis[FlasKesinti]),0)) | I15: =IF($A15="","",IFERROR(SUMIF(tblAnahtarB[NormB],$A15,tblHakedis[UrunReklam]),0)) | J15: =IF($A15="","",IFERROR(SUMIF(tblAnahtarB[NormB],$A15,tblHakedis[DesiKargo]),0)) | K15: =IF($A15="","",ROUND($F15+$G15+$H15+$I15+$J15,2)) | L15: =IF($A15="","",ROUND($B15-$C15,2)) | M15: =IF($A15="","",ROUND($B15-$C15-$K15,2)) | N15: =IF(OR($A15="",$B15=0),0,$M15/$B15) | O15: =IF($A15="","",IF((1-$E15)<=0,0,IF($D15=0,0,ROUND(($C15+$G15+$H15+$I15+$J15)/$D15/(1-$E15),2)))) | P15: =IF($A15="","",IFERROR(SUMIF(tblAnahtarA[Norm],$A15,tblGirdi[HedefNet]),0)) | Q15: =IF($A15="","",ROUND($M15-$P15,2)) | R15: =IF($A15="","",ROUND($B15-$K15,2)) | S15: =IF($A15="","",IF($N15<0,"ÇEKİL",IF($N15<tyk_esikMarjDusuk,"ZAM","SAT"))) | T15: =IF($A15="","",$L15-$F15) | U15: =IF($A15="","",$M15-$Q15) | V15: =IF($A15="","",$R15-$M15)
A16: =IF('ANAHTAR'!$B16="","",'ANAHTAR'!$B16) | B16: =IF($A16="","",IFERROR(SUMIF(tblAnahtarA[Norm],$A16,tblGirdi[ToplamSatis]),0)) | C16: =IF($A16="","",IFERROR(SUMIF(tblAnahtarA[Norm],$A16,tblGirdi[Maliyet])*IFERROR(SUMIF(tblAnahtarA[Norm],$A16,tblGirdi[Miktar]),1),0)) | D16: =IF($A16="","",IFERROR(SUMIF(tblAnahtarA[Norm],$A16,tblGirdi[Miktar]),0)) | E16: =IF($A16="","",IFERROR(SUMIF(tblAnahtarA[Norm],$A16,tblGirdi[KomisyonOran]),0)) | F16: =IF($A16="","",ROUND($B16*$E16,2)) | G16: =IF($A16="","",IFERROR(SUMIF(tblAnahtarB[NormB],$A16,tblHakedis[TyPlus]),0)) | H16: =IF($A16="","",IFERROR(SUMIF(tblAnahtarB[NormB],$A16,tblHakedis[FlasKesinti]),0)) | I16: =IF($A16="","",IFERROR(SUMIF(tblAnahtarB[NormB],$A16,tblHakedis[UrunReklam]),0)) | J16: =IF($A16="","",IFERROR(SUMIF(tblAnahtarB[NormB],$A16,tblHakedis[DesiKargo]),0)) | K16: =IF($A16="","",ROUND($F16+$G16+$H16+$I16+$J16,2)) | L16: =IF($A16="","",ROUND($B16-$C16,2)) | M16: =IF($A16="","",ROUND($B16-$C16-$K16,2)) | N16: =IF(OR($A16="",$B16=0),0,$M16/$B16) | O16: =IF($A16="","",IF((1-$E16)<=0,0,IF($D16=0,0,ROUND(($C16+$G16+$H16+$I16+$J16)/$D16/(1-$E16),2)))) | P16: =IF($A16="","",IFERROR(SUMIF(tblAnahtarA[Norm],$A16,tblGirdi[HedefNet]),0)) | Q16: =IF($A16="","",ROUND($M16-$P16,2)) | R16: =IF($A16="","",ROUND($B16-$K16,2)) | S16: =IF($A16="","",IF($N16<0,"ÇEKİL",IF($N16<tyk_esikMarjDusuk,"ZAM","SAT"))) | T16: =IF($A16="","",$L16-$F16) | U16: =IF($A16="","",$M16-$Q16) | V16: =IF($A16="","",$R16-$M16)
A17: =IF('ANAHTAR'!$B17="","",'ANAHTAR'!$B17) | B17: =IF($A17="","",IFERROR(SUMIF(tblAnahtarA[Norm],$A17,tblGirdi[ToplamSatis]),0)) | C17: =IF($A17="","",IFERROR(SUMIF(tblAnahtarA[Norm],$A17,tblGirdi[Maliyet])*IFERROR(SUMIF(tblAnahtarA[Norm],$A17,tblGirdi[Miktar]),1),0)) | D17: =IF($A17="","",IFERROR(SUMIF(tblAnahtarA[Norm],$A17,tblGirdi[Miktar]),0)) | E17: =IF($A17="","",IFERROR(SUMIF(tblAnahtarA[Norm],$A17,tblGirdi[KomisyonOran]),0)) | F17: =IF($A17="","",ROUND($B17*$E17,2)) | G17: =IF($A17="","",IFERROR(SUMIF(tblAnahtarB[NormB],$A17,tblHakedis[TyPlus]),0)) | H17: =IF($A17="","",IFERROR(SUMIF(tblAnahtarB[NormB],$A17,tblHakedis[FlasKesinti]),0)) | I17: =IF($A17="","",IFERROR(SUMIF(tblAnahtarB[NormB],$A17,tblHakedis[UrunReklam]),0)) | J17: =IF($A17="","",IFERROR(SUMIF(tblAnahtarB[NormB],$A17,tblHakedis[DesiKargo]),0)) | K17: =IF($A17="","",ROUND($F17+$G17+$H17+$I17+$J17,2)) | L17: =IF($A17="","",ROUND($B17-$C17,2)) | M17: =IF($A17="","",ROUND($B17-$C17-$K17,2)) | N17: =IF(OR($A17="",$B17=0),0,$M17/$B17) | O17: =IF($A17="","",IF((1-$E17)<=0,0,IF($D17=0,0,ROUND(($C17+$G17+$H17+$I17+$J17)/$D17/(1-$E17),2)))) | P17: =IF($A17="","",IFERROR(SUMIF(tblAnahtarA[Norm],$A17,tblGirdi[HedefNet]),0)) | Q17: =IF($A17="","",ROUND($M17-$P17,2)) | R17: =IF($A17="","",ROUND($B17-$K17,2)) | S17: =IF($A17="","",IF($N17<0,"ÇEKİL",IF($N17<tyk_esikMarjDusuk,"ZAM","SAT"))) | T17: =IF($A17="","",$L17-$F17) | U17: =IF($A17="","",$M17-$Q17) | V17: =IF($A17="","",$R17-$M17)
... A505: =IF('ANAHTAR'!$B505="","",'ANAHTAR'!$B505) | B505: =IF($A505="","",IFERROR(SUMIF(tblAnahtarA[Norm],$A505,tblGirdi[ToplamSatis]),0)) | C505: =IF($A505="","",IFERROR(SUMIF(tblAnahtarA[Norm],$A505,tblGirdi[Maliyet])*IFERROR(SUMIF(tblAnahtarA[Norm],$A505,tblGirdi[Miktar]),1),0)) | D505: =IF($A505="","",IFERROR(SUMIF(tblAnahtarA[Norm],$A505,tblGirdi[Miktar]),0)) | E505: =IF($A505="","",IFERROR(SUMIF(tblAnahtarA[Norm],$A505,tblGirdi[KomisyonOran]),0)) | F505: =IF($A505="","",ROUND($B505*$E505,2)) | G505: =IF($A505="","",IFERROR(SUMIF(tblAnahtarB[NormB],$A505,tblHakedis[TyPlus]),0)) | H505: =IF($A505="","",IFERROR(SUMIF(tblAnahtarB[NormB],$A505,tblHakedis[FlasKesinti]),0)) | I505: =IF($A505="","",IFERROR(SUMIF(tblAnahtarB[NormB],$A505,tblHakedis[UrunReklam]),0)) | J505: =IF($A505="","",IFERROR(SUMIF(tblAnahtarB[NormB],$A505,tblHakedis[DesiKargo]),0)) | K505: =IF($A505="","",ROUND($F505+$G505+$H505+$I505+$J505,2)) | L505: =IF($A505="","",ROUND($B505-$C505,2)) | M505: =IF($A505="","",ROUND($B505-$C505-$K505,2)) | N505: =IF(OR($A505="",$B505=0),0,$M505/$B505) | O505: =IF($A505="","",IF((1-$E505)<=0,0,IF($D505=0,0,ROUND(($C505+$G505+$H505+$I505+$J505)/$D505/(1-$E505),2)))) | P505: =IF($A505="","",IFERROR(SUMIF(tblAnahtarA[Norm],$A505,tblGirdi[HedefNet]),0)) | Q505: =IF($A505="","",ROUND($M505-$P505,2)) | R505: =IF($A505="","",ROUND($B505-$K505,2)) | S505: =IF($A505="","",IF($N505<0,"ÇEKİL",IF($N505<tyk_esikMarjDusuk,"ZAM","SAT"))) | T505: =IF($A505="","",$L505-$F505) | U505: =IF($A505="","",$M505-$Q505) | V505: =IF($A505="","",$R505-$M505)

Sheet ESLESTIRME
A1: ESLESTIRME — Trendyol Komisyon Sonrası Net Kâr Hesaplama
A2: Kova Bütünlük Denetimi | C2: =IF(COUNTIF(tblEslesme[Kova],"eslesti")+COUNTIF(tblEslesme[Kova],"tolerans_icinde")+COUNTIF(tblEslesme[Kova],"tutar_farki")+COUNTIF(tblEslesme[Kova],"eslesmedi")=COUNTA(tblEslesme[A_Norm]),"BUTUN","KAYIP")
A3: Beklenen hakediş ↔ gerçek hakediş dört kova — her A kaydı tek kovaya
A5: A_Norm | B5: B_Sayim | C5: B_Tutar | D5: A_Tutar | E5: Fark | F5: AbsFark | G5: Kova | H5: IkincilEslesme | I5: DuplikeBayrak | J5: FarkOran | K5: YuvarlakA | L5: YuvarlakB | M5: ToleransTest | N5: EsikUstu | O5: NetKatki | P5: MotorAdim
A6: =IF('ANAHTAR'!$B6="","",'ANAHTAR'!$B6) | B6: =IF($A6="","",COUNTIF(tblAnahtarB[NormB],$A6)) | C6: =IF($A6="","",IFERROR(SUMIF(tblAnahtarB[NormB],$A6,tblHakedis[GercekHakedis]),0)) | D6: =IF($A6="","",IFERROR(SUMIF(tblMotor[A_Norm],$A6,tblMotor[BeklenenHakedis]),0)) | E6: =IF($A6="","",ROUND($D6,2)-ROUND($C6,2)) | F6: =IF($A6="","",ABS($E6)) | G6: =IF($A6="","",IF($B6=0,"eslesmedi",IF(ROUND($D6,2)=ROUND($C6,2),"eslesti",IF(ABS(ROUND($D6,2)-ROUND($C6,2))<=toleransKurus,"tolerans_icinde","tutar_farki")))) | H6: =IF($A6="","",IF($B6>0,"BIRINCIL",IF(COUNTIF(tblAnahtarB[IkincilB],'ANAHTAR'!$D6)>0,"IKINCIL","YOK"))) | I6: =IF($A6="","",'ANAHTAR'!$F6) | J6: =IF(OR($A6="",$D6=0),0,$F6/ABS($D6)) | K6: =IF($A6="","",ROUND($D6,2)) | L6: =IF($A6="","",ROUND($C6,2)) | M6: =IF($A6="","",IF($F6<=toleransKurus,1,0)) | N6: =IF($A6="","",IF($F6>tyk_esikFark,1,0)) | O6: =IF($A6="","",IFERROR(SUMIF(tblMotor[A_Norm],$A6,tblMotor[NetKar]),0)) | P6: =IF($A6="","",$B6+$M6+$N6)
A7: =IF('ANAHTAR'!$B7="","",'ANAHTAR'!$B7) | B7: =IF($A7="","",COUNTIF(tblAnahtarB[NormB],$A7)) | C7: =IF($A7="","",IFERROR(SUMIF(tblAnahtarB[NormB],$A7,tblHakedis[GercekHakedis]),0)) | D7: =IF($A7="","",IFERROR(SUMIF(tblMotor[A_Norm],$A7,tblMotor[BeklenenHakedis]),0)) | E7: =IF($A7="","",ROUND($D7,2)-ROUND($C7,2)) | F7: =IF($A7="","",ABS($E7)) | G7: =IF($A7="","",IF($B7=0,"eslesmedi",IF(ROUND($D7,2)=ROUND($C7,2),"eslesti",IF(ABS(ROUND($D7,2)-ROUND($C7,2))<=toleransKurus,"tolerans_icinde","tutar_farki")))) | H7: =IF($A7="","",IF($B7>0,"BIRINCIL",IF(COUNTIF(tblAnahtarB[IkincilB],'ANAHTAR'!$D7)>0,"IKINCIL","YOK"))) | I7: =IF($A7="","",'ANAHTAR'!$F7) | J7: =IF(OR($A7="",$D7=0),0,$F7/ABS($D7)) | K7: =IF($A7="","",ROUND($D7,2)) | L7: =IF($A7="","",ROUND($C7,2)) | M7: =IF($A7="","",IF($F7<=toleransKurus,1,0)) | N7: =IF($A7="","",IF($F7>tyk_esikFark,1,0)) | O7: =IF($A7="","",IFERROR(SUMIF(tblMotor[A_Norm],$A7,tblMotor[NetKar]),0)) | P7: =IF($A7="","",$B7+$M7+$N7)
A8: =IF('ANAHTAR'!$B8="","",'ANAHTAR'!$B8) | B8: =IF($A8="","",COUNTIF(tblAnahtarB[NormB],$A8)) | C8: =IF($A8="","",IFERROR(SUMIF(tblAnahtarB[NormB],$A8,tblHakedis[GercekHakedis]),0)) | D8: =IF($A8="","",IFERROR(SUMIF(tblMotor[A_Norm],$A8,tblMotor[BeklenenHakedis]),0)) | E8: =IF($A8="","",ROUND($D8,2)-ROUND($C8,2)) | F8: =IF($A8="","",ABS($E8)) | G8: =IF($A8="","",IF($B8=0,"eslesmedi",IF(ROUND($D8,2)=ROUND($C8,2),"eslesti",IF(ABS(ROUND($D8,2)-ROUND($C8,2))<=toleransKurus,"tolerans_icinde","tutar_farki")))) | H8: =IF($A8="","",IF($B8>0,"BIRINCIL",IF(COUNTIF(tblAnahtarB[IkincilB],'ANAHTAR'!$D8)>0,"IKINCIL","YOK"))) | I8: =IF($A8="","",'ANAHTAR'!$F8) | J8: =IF(OR($A8="",$D8=0),0,$F8/ABS($D8)) | K8: =IF($A8="","",ROUND($D8,2)) | L8: =IF($A8="","",ROUND($C8,2)) | M8: =IF($A8="","",IF($F8<=toleransKurus,1,0)) | N8: =IF($A8="","",IF($F8>tyk_esikFark,1,0)) | O8: =IF($A8="","",IFERROR(SUMIF(tblMotor[A_Norm],$A8,tblMotor[NetKar]),0)) | P8: =IF($A8="","",$B8+$M8+$N8)
A9: =IF('ANAHTAR'!$B9="","",'ANAHTAR'!$B9) | B9: =IF($A9="","",COUNTIF(tblAnahtarB[NormB],$A9)) | C9: =IF($A9="","",IFERROR(SUMIF(tblAnahtarB[NormB],$A9,tblHakedis[GercekHakedis]),0)) | D9: =IF($A9="","",IFERROR(SUMIF(tblMotor[A_Norm],$A9,tblMotor[BeklenenHakedis]),0)) | E9: =IF($A9="","",ROUND($D9,2)-ROUND($C9,2)) | F9: =IF($A9="","",ABS($E9)) | G9: =IF($A9="","",IF($B9=0,"eslesmedi",IF(ROUND($D9,2)=ROUND($C9,2),"eslesti",IF(ABS(ROUND($D9,2)-ROUND($C9,2))<=toleransKurus,"tolerans_icinde","tutar_farki")))) | H9: =IF($A9="","",IF($B9>0,"BIRINCIL",IF(COUNTIF(tblAnahtarB[IkincilB],'ANAHTAR'!$D9)>0,"IKINCIL","YOK"))) | I9: =IF($A9="","",'ANAHTAR'!$F9) | J9: =IF(OR($A9="",$D9=0),0,$F9/ABS($D9)) | K9: =IF($A9="","",ROUND($D9,2)) | L9: =IF($A9="","",ROUND($C9,2)) | M9: =IF($A9="","",IF($F9<=toleransKurus,1,0)) | N9: =IF($A9="","",IF($F9>tyk_esikFark,1,0)) | O9: =IF($A9="","",IFERROR(SUMIF(tblMotor[A_Norm],$A9,tblMotor[NetKar]),0)) | P9: =IF($A9="","",$B9+$M9+$N9)
A10: =IF('ANAHTAR'!$B10="","",'ANAHTAR'!$B10) | B10: =IF($A10="","",COUNTIF(tblAnahtarB[NormB],$A10)) | C10: =IF($A10="","",IFERROR(SUMIF(tblAnahtarB[NormB],$A10,tblHakedis[GercekHakedis]),0)) | D10: =IF($A10="","",IFERROR(SUMIF(tblMotor[A_Norm],$A10,tblMotor[BeklenenHakedis]),0)) | E10: =IF($A10="","",ROUND($D10,2)-ROUND($C10,2)) | F10: =IF($A10="","",ABS($E10)) | G10: =IF($A10="","",IF($B10=0,"eslesmedi",IF(ROUND($D10,2)=ROUND($C10,2),"eslesti",IF(ABS(ROUND($D10,2)-ROUND($C10,2))<=toleransKurus,"tolerans_icinde","tutar_farki")))) | H10: =IF($A10="","",IF($B10>0,"BIRINCIL",IF(COUNTIF(tblAnahtarB[IkincilB],'ANAHTAR'!$D10)>0,"IKINCIL","YOK"))) | I10: =IF($A10="","",'ANAHTAR'!$F10) | J10: =IF(OR($A10="",$D10=0),0,$F10/ABS($D10)) | K10: =IF($A10="","",ROUND($D10,2)) | L10: =IF($A10="","",ROUND($C10,2)) | M10: =IF($A10="","",IF($F10<=toleransKurus,1,0)) | N10: =IF($A10="","",IF($F10>tyk_esikFark,1,0)) | O10: =IF($A10="","",IFERROR(SUMIF(tblMotor[A_Norm],$A10,tblMotor[NetKar]),0)) | P10: =IF($A10="","",$B10+$M10+$N10)
A11: =IF('ANAHTAR'!$B11="","",'ANAHTAR'!$B11) | B11: =IF($A11="","",COUNTIF(tblAnahtarB[NormB],$A11)) | C11: =IF($A11="","",IFERROR(SUMIF(tblAnahtarB[NormB],$A11,tblHakedis[GercekHakedis]),0)) | D11: =IF($A11="","",IFERROR(SUMIF(tblMotor[A_Norm],$A11,tblMotor[BeklenenHakedis]),0)) | E11: =IF($A11="","",ROUND($D11,2)-ROUND($C11,2)) | F11: =IF($A11="","",ABS($E11)) | G11: =IF($A11="","",IF($B11=0,"eslesmedi",IF(ROUND($D11,2)=ROUND($C11,2),"eslesti",IF(ABS(ROUND($D11,2)-ROUND($C11,2))<=toleransKurus,"tolerans_icinde","tutar_farki")))) | H11: =IF($A11="","",IF($B11>0,"BIRINCIL",IF(COUNTIF(tblAnahtarB[IkincilB],'ANAHTAR'!$D11)>0,"IKINCIL","YOK"))) | I11: =IF($A11="","",'ANAHTAR'!$F11) | J11: =IF(OR($A11="",$D11=0),0,$F11/ABS($D11)) | K11: =IF($A11="","",ROUND($D11,2)) | L11: =IF($A11="","",ROUND($C11,2)) | M11: =IF($A11="","",IF($F11<=toleransKurus,1,0)) | N11: =IF($A11="","",IF($F11>tyk_esikFark,1,0)) | O11: =IF($A11="","",IFERROR(SUMIF(tblMotor[A_Norm],$A11,tblMotor[NetKar]),0)) | P11: =IF($A11="","",$B11+$M11+$N11)
A12: =IF('ANAHTAR'!$B12="","",'ANAHTAR'!$B12) | B12: =IF($A12="","",COUNTIF(tblAnahtarB[NormB],$A12)) | C12: =IF($A12="","",IFERROR(SUMIF(tblAnahtarB[NormB],$A12,tblHakedis[GercekHakedis]),0)) | D12: =IF($A12="","",IFERROR(SUMIF(tblMotor[A_Norm],$A12,tblMotor[BeklenenHakedis]),0)) | E12: =IF($A12="","",ROUND($D12,2)-ROUND($C12,2)) | F12: =IF($A12="","",ABS($E12)) | G12: =IF($A12="","",IF($B12=0,"eslesmedi",IF(ROUND($D12,2)=ROUND($C12,2),"eslesti",IF(ABS(ROUND($D12,2)-ROUND($C12,2))<=toleransKurus,"tolerans_icinde","tutar_farki")))) | H12: =IF($A12="","",IF($B12>0,"BIRINCIL",IF(COUNTIF(tblAnahtarB[IkincilB],'ANAHTAR'!$D12)>0,"IKINCIL","YOK"))) | I12: =IF($A12="","",'ANAHTAR'!$F12) | J12: =IF(OR($A12="",$D12=0),0,$F12/ABS($D12)) | K12: =IF($A12="","",ROUND($D12,2)) | L12: =IF($A12="","",ROUND($C12,2)) | M12: =IF($A12="","",IF($F12<=toleransKurus,1,0)) | N12: =IF($A12="","",IF($F12>tyk_esikFark,1,0)) | O12: =IF($A12="","",IFERROR(SUMIF(tblMotor[A_Norm],$A12,tblMotor[NetKar]),0)) | P12: =IF($A12="","",$B12+$M12+$N12)
A13: =IF('ANAHTAR'!$B13="","",'ANAHTAR'!$B13) | B13: =IF($A13="","",COUNTIF(tblAnahtarB[NormB],$A13)) | C13: =IF($A13="","",IFERROR(SUMIF(tblAnahtarB[NormB],$A13,tblHakedis[GercekHakedis]),0)) | D13: =IF($A13="","",IFERROR(SUMIF(tblMotor[A_Norm],$A13,tblMotor[BeklenenHakedis]),0)) | E13: =IF($A13="","",ROUND($D13,2)-ROUND($C13,2)) | F13: =IF($A13="","",ABS($E13)) | G13: =IF($A13="","",IF($B13=0,"eslesmedi",IF(ROUND($D13,2)=ROUND($C13,2),"eslesti",IF(ABS(ROUND($D13,2)-ROUND($C13,2))<=toleransKurus,"tolerans_icinde","tutar_farki")))) | H13: =IF($A13="","",IF($B13>0,"BIRINCIL",IF(COUNTIF(tblAnahtarB[IkincilB],'ANAHTAR'!$D13)>0,"IKINCIL","YOK"))) | I13: =IF($A13="","",'ANAHTAR'!$F13) | J13: =IF(OR($A13="",$D13=0),0,$F13/ABS($D13)) | K13: =IF($A13="","",ROUND($D13,2)) | L13: =IF($A13="","",ROUND($C13,2)) | M13: =IF($A13="","",IF($F13<=toleransKurus,1,0)) | N13: =IF($A13="","",IF($F13>tyk_esikFark,1,0)) | O13: =IF($A13="","",IFERROR(SUMIF(tblMotor[A_Norm],$A13,tblMotor[NetKar]),0)) | P13: =IF($A13="","",$B13+$M13+$N13)
A14: =IF('ANAHTAR'!$B14="","",'ANAHTAR'!$B14) | B14: =IF($A14="","",COUNTIF(tblAnahtarB[NormB],$A14)) | C14: =IF($A14="","",IFERROR(SUMIF(tblAnahtarB[NormB],$A14,tblHakedis[GercekHakedis]),0)) | D14: =IF($A14="","",IFERROR(SUMIF(tblMotor[A_Norm],$A14,tblMotor[BeklenenHakedis]),0)) | E14: =IF($A14="","",ROUND($D14,2)-ROUND($C14,2)) | F14: =IF($A14="","",ABS($E14)) | G14: =IF($A14="","",IF($B14=0,"eslesmedi",IF(ROUND($D14,2)=ROUND($C14,2),"eslesti",IF(ABS(ROUND($D14,2)-ROUND($C14,2))<=toleransKurus,"tolerans_icinde","tutar_farki")))) | H14: =IF($A14="","",IF($B14>0,"BIRINCIL",IF(COUNTIF(tblAnahtarB[IkincilB],'ANAHTAR'!$D14)>0,"IKINCIL","YOK"))) | I14: =IF($A14="","",'ANAHTAR'!$F14) | J14: =IF(OR($A14="",$D14=0),0,$F14/ABS($D14)) | K14: =IF($A14="","",ROUND($D14,2)) | L14: =IF($A14="","",ROUND($C14,2)) | M14: =IF($A14="","",IF($F14<=toleransKurus,1,0)) | N14: =IF($A14="","",IF($F14>tyk_esikFark,1,0)) | O14: =IF($A14="","",IFERROR(SUMIF(tblMotor[A_Norm],$A14,tblMotor[NetKar]),0)) | P14: =IF($A14="","",$B14+$M14+$N14)
A15: =IF('ANAHTAR'!$B15="","",'ANAHTAR'!$B15) | B15: =IF($A15="","",COUNTIF(tblAnahtarB[NormB],$A15)) | C15: =IF($A15="","",IFERROR(SUMIF(tblAnahtarB[NormB],$A15,tblHakedis[GercekHakedis]),0)) | D15: =IF($A15="","",IFERROR(SUMIF(tblMotor[A_Norm],$A15,tblMotor[BeklenenHakedis]),0)) | E15: =IF($A15="","",ROUND($D15,2)-ROUND($C15,2)) | F15: =IF($A15="","",ABS($E15)) | G15: =IF($A15="","",IF($B15=0,"eslesmedi",IF(ROUND($D15,2)=ROUND($C15,2),"eslesti",IF(ABS(ROUND($D15,2)-ROUND($C15,2))<=toleransKurus,"tolerans_icinde","tutar_farki")))) | H15: =IF($A15="","",IF($B15>0,"BIRINCIL",IF(COUNTIF(tblAnahtarB[IkincilB],'ANAHTAR'!$D15)>0,"IKINCIL","YOK"))) | I15: =IF($A15="","",'ANAHTAR'!$F15) | J15: =IF(OR($A15="",$D15=0),0,$F15/ABS($D15)) | K15: =IF($A15="","",ROUND($D15,2)) | L15: =IF($A15="","",ROUND($C15,2)) | M15: =IF($A15="","",IF($F15<=toleransKurus,1,0)) | N15: =IF($A15="","",IF($F15>tyk_esikFark,1,0)) | O15: =IF($A15="","",IFERROR(SUMIF(tblMotor[A_Norm],$A15,tblMotor[NetKar]),0)) | P15: =IF($A15="","",$B15+$M15+$N15)
A16: =IF('ANAHTAR'!$B16="","",'ANAHTAR'!$B16) | B16: =IF($A16="","",COUNTIF(tblAnahtarB[NormB],$A16)) | C16: =IF($A16="","",IFERROR(SUMIF(tblAnahtarB[NormB],$A16,tblHakedis[GercekHakedis]),0)) | D16: =IF($A16="","",IFERROR(SUMIF(tblMotor[A_Norm],$A16,tblMotor[BeklenenHakedis]),0)) | E16: =IF($A16="","",ROUND($D16,2)-ROUND($C16,2)) | F16: =IF($A16="","",ABS($E16)) | G16: =IF($A16="","",IF($B16=0,"eslesmedi",IF(ROUND($D16,2)=ROUND($C16,2),"eslesti",IF(ABS(ROUND($D16,2)-ROUND($C16,2))<=toleransKurus,"tolerans_icinde","tutar_farki")))) | H16: =IF($A16="","",IF($B16>0,"BIRINCIL",IF(COUNTIF(tblAnahtarB[IkincilB],'ANAHTAR'!$D16)>0,"IKINCIL","YOK"))) | I16: =IF($A16="","",'ANAHTAR'!$F16) | J16: =IF(OR($A16="",$D16=0),0,$F16/ABS($D16)) | K16: =IF($A16="","",ROUND($D16,2)) | L16: =IF($A16="","",ROUND($C16,2)) | M16: =IF($A16="","",IF($F16<=toleransKurus,1,0)) | N16: =IF($A16="","",IF($F16>tyk_esikFark,1,0)) | O16: =IF($A16="","",IFERROR(SUMIF(tblMotor[A_Norm],$A16,tblMotor[NetKar]),0)) | P16: =IF($A16="","",$B16+$M16+$N16)
A17: =IF('ANAHTAR'!$B17="","",'ANAHTAR'!$B17) | B17: =IF($A17="","",COUNTIF(tblAnahtarB[NormB],$A17)) | C17: =IF($A17="","",IFERROR(SUMIF(tblAnahtarB[NormB],$A17,tblHakedis[GercekHakedis]),0)) | D17: =IF($A17="","",IFERROR(SUMIF(tblMotor[A_Norm],$A17,tblMotor[BeklenenHakedis]),0)) | E17: =IF($A17="","",ROUND($D17,2)-ROUND($C17,2)) | F17: =IF($A17="","",ABS($E17)) | G17: =IF($A17="","",IF($B17=0,"eslesmedi",IF(ROUND($D17,2)=ROUND($C17,2),"eslesti",IF(ABS(ROUND($D17,2)-ROUND($C17,2))<=toleransKurus,"tolerans_icinde","tutar_farki")))) | H17: =IF($A17="","",IF($B17>0,"BIRINCIL",IF(COUNTIF(tblAnahtarB[IkincilB],'ANAHTAR'!$D17)>0,"IKINCIL","YOK"))) | I17: =IF($A17="","",'ANAHTAR'!$F17) | J17: =IF(OR($A17="",$D17=0),0,$F17/ABS($D17)) | K17: =IF($A17="","",ROUND($D17,2)) | L17: =IF($A17="","",ROUND($C17,2)) | M17: =IF($A17="","",IF($F17<=toleransKurus,1,0)) | N17: =IF($A17="","",IF($F17>tyk_esikFark,1,0)) | O17: =IF($A17="","",IFERROR(SUMIF(tblMotor[A_Norm],$A17,tblMotor[NetKar]),0)) | P17: =IF($A17="","",$B17+$M17+$N17)
... A505: =IF('ANAHTAR'!$B505="","",'ANAHTAR'!$B505) | B505: =IF($A505="","",COUNTIF(tblAnahtarB[NormB],$A505)) | C505: =IF($A505="","",IFERROR(SUMIF(tblAnahtarB[NormB],$A505,tblHakedis[GercekHakedis]),0)) | D505: =IF($A505="","",IFERROR(SUMIF(tblMotor[A_Norm],$A505,tblMotor[BeklenenHakedis]),0)) | E505: =IF($A505="","",ROUND($D505,2)-ROUND($C505,2)) | F505: =IF($A505="","",ABS($E505)) | G505: =IF($A505="","",IF($B505=0,"eslesmedi",IF(ROUND($D505,2)=ROUND($C505,2),"eslesti",IF(ABS(ROUND($D505,2)-ROUND($C505,2))<=toleransKurus,"tolerans_icinde","tutar_farki")))) | H505: =IF($A505="","",IF($B505>0,"BIRINCIL",IF(COUNTIF(tblAnahtarB[IkincilB],'ANAHTAR'!$D505)>0,"IKINCIL","YOK"))) | I505: =IF($A505="","",'ANAHTAR'!$F505) | J505: =IF(OR($A505="",$D505=0),0,$F505/ABS($D505)) | K505: =IF($A505="","",ROUND($D505,2)) | L505: =IF($A505="","",ROUND($C505,2)) | M505: =IF($A505="","",IF($F505<=toleransKurus,1,0)) | N505: =IF($A505="","",IF($F505>tyk_esikFark,1,0)) | O505: =IF($A505="","",IFERROR(SUMIF(tblMotor[A_Norm],$A505,tblMotor[NetKar]),0)) | P505: =IF($A505="","",$B505+$M505+$N505)

Sheet KOK_NEDEN
A1: KOK NEDEN — Trendyol Komisyon Sonrası Net Kâr Hesaplama
A3: TYK-001..005 kök neden — eşleşmeyen fark TANIMSIZ
A4: Kural Önceliği
A5: Sira | B5: NedenKodu | C5: Test | D5: Aciklama
A6: 1 | B6: TYK-001 | C6: ABS(fark-komisyon)<=toleransKurus | D6: Kategori komisyon sapması
A7: 2 | B7: TYK-002 | C7: ABS(fark-typlus)<=toleransKurus | D7: TY Plus kesintisi
A8: 3 | B8: TYK-003 | C8: ABS(fark-flas)<=toleransKurus | D8: Flaş kampanya kesintisi
A9: 4 | B9: TYK-004 | C9: ABS(fark-reklam)<=toleransKurus | D9: Ürün reklamı kesintisi
A10: 5 | B10: TYK-005 | C10: ABS(fark-desi)<=toleransKurus | D10: Desi kargo kesintisi
A11: 6 | B11: TANIMSIZ | C11: TRUE | D11: Hiçbir kurala girmedi — elle incele
A13: TANIMSIZ kovası görünür tutulur — zorla sınıflandırma yok. Elle inceleyin.
A14: Satır Sınıflandırması
A15: A_Norm | B15: Kova | C15: AbsFark | D15: Komisyon | E15: TyPlus | F15: Flas | G15: Reklam | H15: Desi | I15: KokNeden
