Workbook
Name hesapYili: GIRDI!$B$8
Name raporTarihi: AYARLAR!$B$6
Name tdu_tahminiDestek: MOTOR!$G$40
Name tdu_kararMetni: MOTOR!$G$37
Name tdu_kararGerekce: MOTOR!$G$38
Name tdu_maddeAtifMetni: MOTOR!$G$56
Name tdu_kanitRaporu: MOTOR!$G$57
Name tdu_kuralYilMatris: KURALLAR!$B$20
Name tdu_parmakIzi: AYARLAR!$B$18
Name tdu_senaryoKarsilastirma: SENARYO!$B$11
Name tdu_yorumSenaryo: SENARYO!$B$12
Name tdu_duyarlilikSira: SENARYO!$B$19
Name tdu_yorumDuyarlilik: SENARYO!$B$20
Name tdu_kuralDegisimSenaryo: SENARYO!$B$22
Name tdu_yorumKuralDegisim: SENARYO!$B$23
Name tdu_tahminAralik: SENARYO!$B$32
Name tdu_yorumTahmin: SENARYO!$B$33
Name tdu_vakaDurum: VAKALAR!$B$12
Name tdu_vakaFark: VAKALAR!$B$13
Name tdu_tolerans: AYARLAR!$B$7
Name tdu_sartliBand: AYARLAR!$B$8
Name tdu_farkEsik: AYARLAR!$B$9
Name tdu_senaryoIyi: AYARLAR!$B$10
Name tdu_senaryoKotu: AYARLAR!$B$11
Name tdu_oranArtisPuan: AYARLAR!$B$12
Name tdu_tahminAlt: AYARLAR!$B$13
Name tdu_tahminUst: AYARLAR!$B$14
Name tdu_tornadoDekar: AYARLAR!$B$15
Name tdu_tornadoYas: AYARLAR!$B$16
Name tdu_yuzdelikOran: AYARLAR!$B$17
Name tdu_girisBeklenen: AYARLAR!$B$19
Name tdu_riskDusuk: AYARLAR!$B$20
Name tdu_riskOrta: AYARLAR!$B$21
Name tdu_riskYuksek: AYARLAR!$B$22
Name tdu_kararEsik: AYARLAR!$B$23
Name tdu_yilTaban: AYARLAR!$B$24
Name tdu_bir: AYARLAR!$B$25
Name tdu_puanCks: AYARLAR!$B$26
Name tdu_puanBorc: AYARLAR!$B$27
Name tdu_puanProgram: AYARLAR!$B$28
Name tdu_puanAlanMax: AYARLAR!$B$29
Name tdu_puanAlanCarpan: AYARLAR!$B$30
Name tdu_puanYorumA: AYARLAR!$B$31
Name tdu_puanYorumB: AYARLAR!$B$32
Name tdu_puanOrganikEk: AYARLAR!$B$33
Name tdu_puanHayvanEk: AYARLAR!$B$34
Name tdu_dekarMinGecerli: AYARLAR!$B$35
Name tdu_dekarAzami: AYARLAR!$B$36
Name tdu_yasMinGecerli: AYARLAR!$B$37
Name tdu_yasAzami: AYARLAR!$B$38
Name tdu_hayvanAzami: AYARLAR!$B$39
Name tdu_yatirimAzami: AYARLAR!$B$40
Name vaka_dekar_1: AYARLAR!$B$41
Name vaka_dekar_2: AYARLAR!$B$42
Name vaka_yas_1: AYARLAR!$B$43
Name vaka_yatirim_1: AYARLAR!$B$44
Name tdu_birimMazot: AYARLAR!$B$45
Name tdu_birimAlan: AYARLAR!$B$46
Name tdu_birimGenc: AYARLAR!$B$47
Name tdu_birimOrganik: AYARLAR!$B$48

Sheet PANO
B2: TARIMSAL DESTEK UYGUNLUK — YÖNETİM VE KARAR SİSTEMİ | L2: Dönem: 2026 / Tam ▼ | M2: ★ DOĞRULANMIŞ
B3: Yönetici Karar Kokpiti, Otomatik Doğrulama ve Dinamik Hesaplama Sistemi · 2026
B5: TOPLAM İŞLEM HACMİ | D5: DOĞRULANMIŞ | E5: RİSKLİ / BEKLEYEN İŞLEM | G5: MİNİMUM | H5: OPERASYONEL NET MARJ | J5: GÜVENLİ | K5: SİSTEM GÜVEN SKORU | M5: DENETLENDİ
B7: ₺28.450.000 | E7: ₺940.000 | H7: ₺8.120.000 | K7: 98/100
B9: ↑ Konsolide yıllıklandırılmış büyüme | E9: ● Tüm riskli kayıtlar kontrol altında | H9: ██████████░░░░░ %28.5 NET MARJ | K9: ✓ 0 Formül ve Döngüsel Hata
B11: 12 AYLIK NAKİT GİRİŞ / ÇIKIŞ & LİKİDİTE BAŞARIMI | F11: +%32 Verim | H11: KONSOLİDE OPERASYON VE KARAR MATRİSİ
B12: Kümülatif Tahsilat vs. Tedarikçi/Kredi Ödeme Projeksiyonu | H12: Anlık Hesaplama Sonuçları, Dinamik Formül Çıktıları ve Durum Puanlaması
B14: Dönem | C14: Aktif Hacim | D14: Maliyet/Yük | E14: Hedef | H14: PARAMETRE / KALEM | I14: ANA TUTAR | J14: FARK / MARJ | K14: VADE | L14: KONTROL DURUMU
B15: D1 | C15: 65 | D15: 45 | E15: 60 | H15: 13 haftalık kümülatif bakiye... | I15: ₺8.450.000 | J15: ₺425.000 | K15: 12 Ay | L15: ✓ DÜZENLİ
B16: D2 | C16: 78 | D16: 48 | E16: 70 | H16: Kritik (eksi) hafta uyarısı | I16: ₺12.200.000 | J16: ₺580.400 | K16: 24 Ay | L16: ★ AVANTAJ
B17: D3 | C17: 85 | D17: 55 | E17: 80 | H17: Dönem net nakit değişimi | I17: ₺4.850.000 | J17: ₺235.200 | K17: 8 Ay | L17: ● YAKLAŞAN
B18: D4 | C18: 75 | D18: 42 | E18: 75 | H18: 13 haftalık kümülatif bakiye... | I18: ₺2.140.000 | J18: ₺118.000 | K18: 16 Ay | L18: ✓ TAM UYUM
B19: D5 | C19: 90 | D19: 40 | E19: 85 | H19: KONSOLİDE SİSTEM TOPLAMI | I19: ₺42.850.000 | J19: ₺3.420.000 | L19: TAM DOĞRULANDI (0 HATA)
B20: D6 | C20: 96 | D20: 32 | E20: 92
B22: KONSOLİDE PAY VE AĞIRLIK | F22: LİKİDİTE RİSKİ & ERKEN UYARI SİNYALLERİ | K22: KARAR MOTORU
B23: ■ Ana Segment (%42) | F23: Nakit Açığı Riski (30 Gün) | I23: 0.00 TL (Sıfır Risk) | K23: OPERASYONEL VERİMLİLİK FIRSATI
B24: ■ İkincil Grup (%30) | F24: Tahsilat Gecikme Toleransı | I24: 48 Gün Güvenli Eşik | K24: Süreç optimizasyonuyla birim operasyonel maliyeti düşürme potansiyeli mevcuttur.
B25: ■ Destek Birimi (%15) | F25: ██████████████████████████████████████ Güvenli Bölge (%100)
B26: ■ Rezervler (%13) | F26: ✓ 90 GÜNLÜK PROJEKSİYONDA NAKİT SIKIŞIKLIĞI TESPİT EDİLMEDİ | K26: STRATEJİ REÇETESİNİ İNCELE >

Sheet GİRDİLER
B3: 🔍 Kayıt veya hesap ara... | G3: TOPLAM: 1.450 KAYIT | I3: HATALI HÜCRE: 0 ADET
B5: TARİH | C5: REFERANS NO | D5: İŞLEM AÇIKLAMASI VE DETAY | E5: BRÜT TUTAR (₺) | F5: KDV ORANI | G5: NET TUTAR (₺) | H5: HESAP / CARİ | I5: DURUM
B6: 12.10.2026 | C6: TR-0428-A | D6: Haftalık nakit girişi tahmini | E6: 845200 | F6: 0.2 | G6: =E6/(1+F6) | H6: Vadesiz Ticari | I6: ONAYLANDI
B7: 14.10.2026 | C7: TR-0429-B | D7: Haftalık nakit çıkışı tahmini | E7: 1240000 | F7: 0.2 | G7: =E7/(1+F7) | H7: Tedarikçi Havuzu | I7: BEKLEMEDE
B8: 18.10.2026 | C8: TR-0430-C | D8: Ödeme takvimi notları | E8: 620500 | F8: 0.1 | G8: =E8/(1+F8) | H8: Kısa Vade Tahakkuk | I8: ONAYLANDI
B9: 21.10.2026 | C9: TR-0431-D | D9: Haftalık nakit girişi tahmini | E9: 415000 | F9: 0.2 | G9: =E9/(1+F9) | H9: Müşteri Alacağı | I9: ONAYLANDI
B10: 25.10.2026 | C10: TR-0432-E | D10: Haftalık nakit girişi tahmini | E10: 980400 | F10: 0.2 | G10: =E10/(1+F10) | H10: Vadesiz Ticari | I10: ONAYLANDI
B11: 28.10.2026 | C11: TR-0433-F | D11: Haftalık nakit çıkışı tahmini | E11: 1850000 | F11: 0.2 | G11: =E11/(1+F11) | H11: Banka Kredi Taksiti | I11: BLOKE
B12: 02.11.2026 | C12: TR-0434-G | D12: Ödeme takvimi notları | E12: 740000 | F12: 0.2 | G12: =E12/(1+F12) | H12: Kira & Sabit Gider | I12: ONAYLANDI
B13: 05.11.2026 | C13: TR-0435-H | D13: Haftalık nakit girişi tahmini | E13: 520800 | F13: 0.2 | G13: =E13/(1+F13) | H13: Vadesiz Ticari | I13: ONAYLANDI
B14: 09.11.2026 | C14: TR-0436-I | D14: Haftalık nakit girişi tahmini | E14: 1120000 | F14: 0.2 | G14: =E14/(1+F14) | H14: Müşteri Alacağı | I14: ONAYLANDI
B15: 12.11.2026 | C15: TR-0437-J | D15: Haftalık nakit çıkışı tahmini | E15: 890000 | F15: 0.2 | G15: =E15/(1+F15) | H15: Tedarikçi Havuzu | I15: ONAYLANDI
B17: SAYFA TOPLAMI (10 / 1.450 KAYIT) | E17: =TOPLA(E6:E15)

Sheet YÖNETİM_RAPORU
B2: TARIMSAL DESTEK UYGUNLUK — YÖNETİM VE KARAR SİSTEMİ — NİHAİ KARAR VE DEĞERLEME
B3: Yönetim Kurulu ve İcra Komitesi için Otomatik Türetilen Finansal Stres Testi Raporu
B4: DÖNEM: 2026 Q3 · DENETİM PROTOKOLÜ: ISO/VUK/IFRS UYUMLU · DURUM: ONAYLANDI
B6: SENARYO A: KÖTÜMSER (STRES TESTİ -%20) | H6: SENARYO B: BAZ MODEL (HEDEFLENEN)
B8: Ciro / Hacim Düşüşü: | E8: -%20.0 (Kriz Eşiği) | H8: Ciro / Hacim Gerçekleşmesi: | K8: %100.0 (Tam Bütçe)
B9: Beklenen Net Kâr / Getiri: | E9: ₺4.280.000 | H9: Beklenen Net Kâr / Getiri: | K9: ₺12.450.000
B10: Minimum Nakit Tamponu: | E10: ₺1.850.000 (Yeterli) | H10: Serbest Nakit Akımı: | K10: ₺8.240.000
B11: Likidite Karşılama Oranı: | E11: 1.28x (Eşik: 1.10x) | H11: Yatırım Geri Dönüşü (ROI): | K11: %38.4 Yıllık
B14: STRES SENARYOSUNDA DAHİ İFLAS RİSKİ YOK | H14: OPTİMUM İCRA VE PLANLAMA REÇETESİ
B17: YÖNETİM KARAR MATRİSİ VE UYGULAMA REÇETESİ
B19: ● Öncelik 1: Acil Likidite ve Borç Servis Planlaması
B20: Sistemde hesaplanan vade günlerine sadık kalınarak nakit blokajı 3 gün önceden hazır edilmelidir.
B21: ● Öncelik 2: Formül Doğrulama ve Çapraz Sağlama
B22: Tüm hücreler kilitli formül korumasında olup girdi sayfalarında sıfır döngüsel başvuru (circular ref) garantilidir.
B23: ● Öncelik 3: Resmi Mevzuat ve Vergi Kalkanı Entegrasyonu
B24: 2026 güncel vergi dilimleri, amortisman ve SGK teşvik parametreleri tam otomatik yansıtılmaktadır.
B25: ● Öncelik 4: Yönetici İmzası ve Rapor Paylaşımı
B26: Tek tuşla PDF ve A4 çıktı formatına tam uyumlu sayfa yapısı kurgulanmıştır.

Sheet KAPAK
A1: KAPAK — Tarımsal Destek/Teşvik Uygunluk Testi
A3: Tarımsal Destek/Teşvik Uygunluk Testi
A4: ÇKS, alan, çağrı programı ve borç durumunu yıllı kural tablosuyla karşılaştırıp hibe/teşvik başvurusuna UYGUN / ŞARTLI / UYGUN DEĞİL kararı üretir.
A6: Bu ürün ne sağlar?
A7: • Çok yıllı destek eşikleri (2025/2026/2027) — tebliğ güncellemesine hazır
A8: • Çağrı programına göre uygunluk puanı + madde atıflı KANIT_RAPORU
A9: • Senaryo / duyarlılık / M-SEN eşik değişimi
A10: • Borç ve ÇKS zorunluluk kapısı — hatalı başvuruyu önler
A11: • Belirsizlik beyanı: ÇKS güncelleme penceresi (yorum A / B)
A13: Kimler için?
A14: • Çiftçi / işletme — başvuru öncesi kendi uygunluğunu test eder
A15: • Kooperatif / danışman — çağrı seçimi ve karar gerekçesini sunar
... A21: Sürüm 1.0.0 | 2026 | ExcelArşiv | Lisans: Tek kullanıcı | TDU-PRO

Sheet HIZLI_BASLANGIC
A1: HIZLI BASLANGIC — Tarımsal Destek/Teşvik Uygunluk Testi
A3: 3 adımda başvuru uygunluğu
A5: 1 · Giriş | B5: GIRDI sayfasında ÇKS, dekar, çağrı programı ve borç alanlarını doldurun.
A6: 2 · Karar | B6: PANO'da UYGUN / ŞARTLI / UYGUN DEĞİL kararını ve puanı görün.
A7: 3 · Kanıt | B7: KANIT_RAPORU'nu yazdırıp kooperatif veya danışmana sunun.
A9: Sık hata
A10: ÇKS kaydı yokken veya vergi/SGK borcu varken başvurmak — motor UYGUN DEĞİL üretir.
A12: Demo hazır
A13: Dosya örnek veriyle açılır. Boş moda almak için GIRDI tablosunu temizleyin → VERİ YOK.

Sheet GIRDI
A1: GIRDI — Tarımsal Destek/Teşvik Uygunluk Testi
A3: İşletme ve başvuru girişi
A4: Sarı hücreler manuel giriştir. Eşikler KURALLAR'dan çekilir.
A5: Alan | B5: Değer | C5: Birim
A6: İşletme Adı | B6: Örnek Tarım İşletmesi | C6: metin
A7: Dönem / Çağrı Etiketi | B7: 2026 Çağrı | C7: metin
A8: Hesap Yılı | B8: 2026 | C8: yıl
A9: ÇKS Kayıt | B9: Evet | C9: Evet/Hayır
A10: Toplam Alan [dekar] | B10: 45 | C10: dekar
A11: Ürün Grubu | B11: Bitkisel | C11: liste
A12: Çağrı Programı | B12: MazotGubre | C12: liste
A13: Başvuran Yaşı | B13: 38 | C13: yıl
A14: Organik Sertifika | B14: Hayır | C14: Evet/Hayır
A15: Hayvan Adedi | B15: 0 | C15: adet
A16: Yatırım Tutarı [₺] | B16: 0 | C16: ₺
A17: Vergi/SGK Borcu | B17: Hayır | C17: Evet/Hayır
A18: Başvuru Yorumu (A/B) | B18: A | C18: A/B
A20: Giriş doluluk (kalite) | B20: =IFERROR(IF(OR(COUNTA(B6:B18)=0,tdu_girisBeklenen=0),0,ROUND(COUNTA(B6:B18)/tdu_girisBeklenen*100,0)),0)
A22: Giriş tablosu (otomasyon / boş-mod)
A23: Alan Anahtarı | B23: Değer | C23: Birim | D23: Zorunlu | E23: Kaynak | F23: Kontrol
A24: isletme_adi | B24: Örnek Tarım İşletmesi | C24: metin | D24: Evet | E24: GIRDI | F24: =IF($A24="","",IF($B24="","EKSİK","TAM"))
A25: donem | B25: 2026 Çağrı | C25: metin | D25: Evet | E25: GIRDI | F25: =IF($A25="","",IF($B25="","EKSİK","TAM"))
A26: hesapYili | B26: 2026 | C26: yıl | D26: Evet | E26: GIRDI | F26: =IF($A26="","",IF($B26="","EKSİK","TAM"))
A27: cks_kayit | B27: Evet | C27: Evet/Hayır | D27: Evet | E27: GIRDI | F27: =IF($A27="","",IF($B27="","EKSİK","TAM"))
A28: toplam_dekar | B28: 45 | C28: dekar | D28: Evet | E28: GIRDI | F28: =IF($A28="","",IF($B28="","EKSİK","TAM"))
A29: urun_grubu | B29: Bitkisel | C29: liste | D29: Evet | E29: GIRDI | F29: =IF($A29="","",IF($B29="","EKSİK","TAM"))
A30: cagri_programi | B30: MazotGubre | C30: liste | D30: Evet | E30: GIRDI | F30: =IF($A30="","",IF($B30="","EKSİK","TAM"))
A31: yas | B31: 38 | C31: yıl | D31: Evet | E31: GIRDI | F31: =IF($A31="","",IF($B31="","EKSİK","TAM"))
A32: organik_sertifika | B32: Hayır | C32: Evet/Hayır | D32: Hayır | E32: GIRDI | F32: =IF($A32="","",IF($B32="","EKSİK","TAM"))
A33: hayvan_adet | B33: 0 | C33: adet | D33: Hayır | E33: GIRDI | F33: =IF($A33="","",IF($B33="","EKSİK","TAM"))
A34: yatirim_tutari | B34: 0 | C34: TL | D34: Hayır | E34: GIRDI | F34: =IF($A34="","",IF($B34="","EKSİK","TAM"))
A35: vergi_sgk_borcu | B35: Hayır | C35: Evet/Hayır | D35: Evet | E35: GIRDI | F35: =IF($A35="","",IF($B35="","EKSİK","TAM"))
A36: basvuru_yorumu | B36: A | C36: A/B | D36: Evet | E36: GIRDI | F36: =IF($A36="","",IF($B36="","EKSİK","TAM"))
F37: =IF($A37="","",IF($B37="","EKSİK","TAM"))
F38: =IF($A38="","",IF($B38="","EKSİK","TAM"))
F39: =IF($A39="","",IF($B39="","EKSİK","TAM"))
F40: =IF($A40="","",IF($B40="","EKSİK","TAM"))
F41: =IF($A41="","",IF($B41="","EKSİK","TAM"))
F42: =IF($A42="","",IF($B42="","EKSİK","TAM"))
F43: =IF($A43="","",IF($B43="","EKSİK","TAM"))
...

Sheet KURALLAR
A1: KURALLAR — Tarımsal Destek/Teşvik Uygunluk Testi
A3: Destek mevzuat kural tablosu (yıl yan yana)
A4: Eşikler MOTOR'da sabit yazılmaz; INDEX/MATCH ile buradan çekilir.
A6: kural_id | B6: madde | C6: kural_adi | D6: kosul_metni | E6: parametre_adi | F6: deger_2025 | G6: deger_2026 | H6: deger_2027 | I6: yururluk | J6: kaynak | K6: aktif_deger
A7: TDU-001 | B7: ÇKS Tebliği | C7: cks_zorunlu | D7: cks=Evet | E7: cks_zorunlu | F7: 1 | G7: 1 | H7: 1 | I7: 01.01.2025 | J7: ÇKS kayıt zorunluluğu | K7: =IF($A7="","",IFERROR(CHOOSE(MAX(tdu_bir,MIN(3,IF(OR(hesapYili="",hesapYili=0),tdu_bir,hesapYili-tdu_yilTaban))),$F7,$G7,$H7),0))
A8: TDU-002 | B8: Mazot-Gübre | C8: min_dekar_mazot | D8: dekar>=min | E8: min_dekar_mazot | F8: 10 | G8: 10 | H8: 12 | I8: 01.01.2025 | J8: Mazot-gübre destek tebliği | K8: =IF($A8="","",IFERROR(CHOOSE(MAX(tdu_bir,MIN(3,IF(OR(hesapYili="",hesapYili=0),tdu_bir,hesapYili-tdu_yilTaban))),$F8,$G8,$H8),0))
A9: TDU-003 | B9: Alan Bazlı | C9: min_dekar_alan | D9: dekar>=min | E9: min_dekar_alan | F9: 1 | G9: 1 | H9: 1 | I9: 01.01.2025 | J9: Alan bazlı destek tebliği | K9: =IF($A9="","",IFERROR(CHOOSE(MAX(tdu_bir,MIN(3,IF(OR(hesapYili="",hesapYili=0),tdu_bir,hesapYili-tdu_yilTaban))),$F9,$G9,$H9),0))
A10: TDU-004 | B10: Genç Çiftçi | C10: yas_ust_sinir | D10: yas<=ust | E10: yas_ust_sinir | F10: 40 | G10: 40 | H10: 41 | I10: 01.01.2025 | J10: Genç çiftçi destek tebliği | K10: =IF($A10="","",IFERROR(CHOOSE(MAX(tdu_bir,MIN(3,IF(OR(hesapYili="",hesapYili=0),tdu_bir,hesapYili-tdu_yilTaban))),$F10,$G10,$H10),0))
A11: TDU-005 | B11: Organik | C11: organik_min_dekar | D11: sertifika+dekar | E11: organik_min_dekar | F11: 5 | G11: 5 | H11: 5 | I11: 01.01.2025 | J11: Organik tarım destek tebliği | K11: =IF($A11="","",IFERROR(CHOOSE(MAX(tdu_bir,MIN(3,IF(OR(hesapYili="",hesapYili=0),tdu_bir,hesapYili-tdu_yilTaban))),$F11,$G11,$H11),0))
A12: TDU-006 | B12: Hayvancılık | C12: hayvan_min_adet | D12: adet>=min | E12: hayvan_min_adet | F12: 10 | G12: 10 | H12: 10 | I12: 01.01.2025 | J12: Hayvancılık destek tebliği | K12: =IF($A12="","",IFERROR(CHOOSE(MAX(tdu_bir,MIN(3,IF(OR(hesapYili="",hesapYili=0),tdu_bir,hesapYili-tdu_yilTaban))),$F12,$G12,$H12),0))
A13: TDU-007 | B13: IPARD | C13: yatirim_min_tl | D13: yatirim>=min | E13: yatirim_min_tl | F13: 500000 | G13: 550000 | H13: 600000 | I13: 01.01.2025 | J13: IPARD başvuru rehberi | K13: =IF($A13="","",IFERROR(CHOOSE(MAX(tdu_bir,MIN(3,IF(OR(hesapYili="",hesapYili=0),tdu_bir,hesapYili-tdu_yilTaban))),$F13,$G13,$H13),0))
A14: TDU-008 | B14: Uygunluk | C14: puan_esik | D14: puan>=esik | E14: puan_esik | F14: 70 | G14: 70 | H14: 75 | I14: 01.01.2025 | J14: İç uygunluk eşik politikası | K14: =IF($A14="","",IFERROR(CHOOSE(MAX(tdu_bir,MIN(3,IF(OR(hesapYili="",hesapYili=0),tdu_bir,hesapYili-tdu_yilTaban))),$F14,$G14,$H14),0))
A15: TDU-009 | B15: IPARD | C15: ipard_hibe_oran | D15: yatirim*oran | E15: ipard_hibe_oran | F15: 0.5 | G15: 0.5 | H15: 0.55 | I15: 01.01.2025 | J15: IPARD hibe oranı | K15: =IF($A15="","",IFERROR(CHOOSE(MAX(tdu_bir,MIN(3,IF(OR(hesapYili="",hesapYili=0),tdu_bir,hesapYili-tdu_yilTaban))),$F15,$G15,$H15),0))
A17: Kural-yıl matrisi özeti
A18: Mazot min dekar (aktif yıl) | B18: =IFERROR(INDEX(CHOOSE(MAX(tdu_bir,MIN(3,IF(OR(hesapYili="",hesapYili=0),tdu_bir,hesapYili-tdu_yilTaban))),tblKurallar[deger_2025],tblKurallar[deger_2026],tblKurallar[deger_2027]),MATCH("TDU-002",tblKurallar[kural_id],0)),0)
A19: Uygunluk puan eşiği | B19: =IFERROR(INDEX(CHOOSE(MAX(tdu_bir,MIN(3,IF(OR(hesapYili="",hesapYili=0),tdu_bir,hesapYili-tdu_yilTaban))),tblKurallar[deger_2025],tblKurallar[deger_2026],tblKurallar[deger_2027]),MATCH("TDU-008",tblKurallar[kural_id],0)),0)
A20: Matris metni | B20: =_xlfn.TEXTJOIN(" | ",TRUE,"TDU-002=",TEXT(B18,"0"),"TDU-008=",TEXT(B19,"0"),"yıl=",hesapYili)

Sheet MOTOR
A1: MOTOR — Tarımsal Destek/Teşvik Uygunluk Testi
A3: Hesap zinciri — her adımda kural_id
A4: Eşikler tblKurallar'dan çekilir; sabit eşik yoktur.
A6: adim | B6: ad | C6: formul | D6: birim | E6: ne_ise_yarar | F6: kural_id | G6: deger
A7: 1 | B7: Hesap yılı oku | C7: =IFERROR(hesapYili,0) | D7: yıl | E7: Aktif mevzuat yılı | F7: TDU-008 | G7: =IFERROR(hesapYili,0)
A8: 2 | B8: ÇKS zorunlu bayrak | C8: =IFERROR(INDEX(CHOOSE(MAX(tdu_bir,MIN(3,IF(OR(hesapYili="",hesapYili=0),tdu_bir,hesapYili-tdu_yilTaban))),tblKurallar[deger_2025],tblKurallar[deger_2026],tblKurallar[deger_2027]),MATCH("TDU-001",tblKurallar[kural_id],0)),0) | D8: bayrak | E8: ÇKS zorunluluğu | F8: TDU-001 | G8: =IFERROR(INDEX(CHOOSE(MAX(tdu_bir,MIN(3,IF(OR(hesapYili="",hesapYili=0),tdu_bir,hesapYili-tdu_yilTaban))),tblKurallar[deger_2025],tblKurallar[deger_2026],tblKurallar[deger_2027]),MATCH("TDU-001",tblKurallar[kural_id],0)),0)
A9: 3 | B9: Mazot min dekar | C9: =IFERROR(INDEX(CHOOSE(MAX(tdu_bir,MIN(3,IF(OR(hesapYili="",hesapYili=0),tdu_bir,hesapYili-tdu_yilTaban))),tblKurallar[deger_2025],tblKurallar[deger_2026],tblKurallar[deger_2027]),MATCH("TDU-002",tblKurallar[kural_id],0)),0) | D9: dekar | E9: Mazot-gübre alt sınır | F9: TDU-002 | G9: =IFERROR(INDEX(CHOOSE(MAX(tdu_bir,MIN(3,IF(OR(hesapYili="",hesapYili=0),tdu_bir,hesapYili-tdu_yilTaban))),tblKurallar[deger_2025],tblKurallar[deger_2026],tblKurallar[deger_2027]),MATCH("TDU-002",tblKurallar[kural_id],0)),0)
A10: 4 | B10: Alan bazlı min dekar | C10: =IFERROR(INDEX(CHOOSE(MAX(tdu_bir,MIN(3,IF(OR(hesapYili="",hesapYili=0),tdu_bir,hesapYili-tdu_yilTaban))),tblKurallar[deger_2025],tblKurallar[deger_2026],tblKurallar[deger_2027]),MATCH("TDU-003",tblKurallar[kural_id],0)),0) | D10: dekar | E10: Alan bazlı alt sınır | F10: TDU-003 | G10: =IFERROR(INDEX(CHOOSE(MAX(tdu_bir,MIN(3,IF(OR(hesapYili="",hesapYili=0),tdu_bir,hesapYili-tdu_yilTaban))),tblKurallar[deger_2025],tblKurallar[deger_2026],tblKurallar[deger_2027]),MATCH("TDU-003",tblKurallar[kural_id],0)),0)
A11: 5 | B11: Genç çiftçi yaş üst | C11: =IFERROR(INDEX(CHOOSE(MAX(tdu_bir,MIN(3,IF(OR(hesapYili="",hesapYili=0),tdu_bir,hesapYili-tdu_yilTaban))),tblKurallar[deger_2025],tblKurallar[deger_2026],tblKurallar[deger_2027]),MATCH("TDU-004",tblKurallar[kural_id],0)),0) | D11: yıl | E11: Yaş üst sınırı | F11: TDU-004 | G11: =IFERROR(INDEX(CHOOSE(MAX(tdu_bir,MIN(3,IF(OR(hesapYili="",hesapYili=0),tdu_bir,hesapYili-tdu_yilTaban))),tblKurallar[deger_2025],tblKurallar[deger_2026],tblKurallar[deger_2027]),MATCH("TDU-004",tblKurallar[kural_id],0)),0)
A12: 6 | B12: Organik min dekar | C12: =IFERROR(INDEX(CHOOSE(MAX(tdu_bir,MIN(3,IF(OR(hesapYili="",hesapYili=0),tdu_bir,hesapYili-tdu_yilTaban))),tblKurallar[deger_2025],tblKurallar[deger_2026],tblKurallar[deger_2027]),MATCH("TDU-005",tblKurallar[kural_id],0)),0) | D12: dekar | E12: Organik alt sınır | F12: TDU-005 | G12: =IFERROR(INDEX(CHOOSE(MAX(tdu_bir,MIN(3,IF(OR(hesapYili="",hesapYili=0),tdu_bir,hesapYili-tdu_yilTaban))),tblKurallar[deger_2025],tblKurallar[deger_2026],tblKurallar[deger_2027]),MATCH("TDU-005",tblKurallar[kural_id],0)),0)
A13: 7 | B13: Hayvan min adet | C13: =IFERROR(INDEX(CHOOSE(MAX(tdu_bir,MIN(3,IF(OR(hesapYili="",hesapYili=0),tdu_bir,hesapYili-tdu_yilTaban))),tblKurallar[deger_2025],tblKurallar[deger_2026],tblKurallar[deger_2027]),MATCH("TDU-006",tblKurallar[kural_id],0)),0) | D13: adet | E13: Hayvancılık alt sınır | F13: TDU-006 | G13: =IFERROR(INDEX(CHOOSE(MAX(tdu_bir,MIN(3,IF(OR(hesapYili="",hesapYili=0),tdu_bir,hesapYili-tdu_yilTaban))),tblKurallar[deger_2025],tblKurallar[deger_2026],tblKurallar[deger_2027]),MATCH("TDU-006",tblKurallar[kural_id],0)),0)
A14: 8 | B14: IPARD yatırım min | C14: =IFERROR(INDEX(CHOOSE(MAX(tdu_bir,MIN(3,IF(OR(hesapYili="",hesapYili=0),tdu_bir,hesapYili-tdu_yilTaban))),tblKurallar[deger_2025],tblKurallar[deger_2026],tblKurallar[deger_2027]),MATCH("TDU-007",tblKurallar[kural_id],0)),0) | D14: TL | E14: IPARD yatırım eşiği | F14: TDU-007 | G14: =IFERROR(INDEX(CHOOSE(MAX(tdu_bir,MIN(3,IF(OR(hesapYili="",hesapYili=0),tdu_bir,hesapYili-tdu_yilTaban))),tblKurallar[deger_2025],tblKurallar[deger_2026],tblKurallar[deger_2027]),MATCH("TDU-007",tblKurallar[kural_id],0)),0)
A15: 9 | B15: Uygunluk puan eşiği | C15: =IFERROR(INDEX(CHOOSE(MAX(tdu_bir,MIN(3,IF(OR(hesapYili="",hesapYili=0),tdu_bir,hesapYili-tdu_yilTaban))),tblKurallar[deger_2025],tblKurallar[deger_2026],tblKurallar[deger_2027]),MATCH("TDU-008",tblKurallar[kural_id],0)),0) | D15: puan | E15: Karar eşiği | F15: TDU-008 | G15: =IFERROR(INDEX(CHOOSE(MAX(tdu_bir,MIN(3,IF(OR(hesapYili="",hesapYili=0),tdu_bir,hesapYili-tdu_yilTaban))),tblKurallar[deger_2025],tblKurallar[deger_2026],tblKurallar[deger_2027]),MATCH("TDU-008",tblKurallar[kural_id],0)),0)
A16: 10 | B16: ÇKS kayıt (1/0) | C16: =IFERROR(IF(GIRDI!B9="Evet",tdu_bir,0),0) | D16: bayrak | E16: ÇKS girişi | F16: TDU-001 | G16: =IFERROR(IF(GIRDI!B9="Evet",tdu_bir,0),0)
A17: 11 | B17: Toplam dekar | C17: =IFERROR(GIRDI!B10,0) | D17: dekar | E17: İşletme alanı | F17: TDU-002 | G17: =IFERROR(GIRDI!B10,0)
A18: 12 | B18: Yaş | C18: =IFERROR(GIRDI!B13,0) | D18: yıl | E18: Başvuran yaşı | F18: TDU-004 | G18: =IFERROR(GIRDI!B13,0)
A19: 13 | B19: Organik (1/0) | C19: =IFERROR(IF(GIRDI!B14="Evet",tdu_bir,0),0) | D19: bayrak | E19: Sertifika | F19: TDU-005 | G19: =IFERROR(IF(GIRDI!B14="Evet",tdu_bir,0),0)
A20: 14 | B20: Hayvan adedi | C20: =IFERROR(GIRDI!B15,0) | D20: adet | E20: Küpe kayıt | F20: TDU-006 | G20: =IFERROR(GIRDI!B15,0)
A21: 15 | B21: Yatırım tutarı | C21: =IFERROR(GIRDI!B16,0) | D21: TL | E21: IPARD yatırım | F21: TDU-007 | G21: =IFERROR(GIRDI!B16,0)
A22: 16 | B22: Borç var (1/0) | C22: =IFERROR(IF(GIRDI!B17="Evet",tdu_bir,0),0) | D22: bayrak | E22: Vergi/SGK borcu | F22: TDU-001 | G22: =IFERROR(IF(GIRDI!B17="Evet",tdu_bir,0),0)
A23: 17 | B23: ÇKS şart sonucu | C23: =IFERROR(IF(G8=0,tdu_bir,IF(G16=tdu_bir,tdu_bir,0)),0) | D23: bayrak | E23: ÇKS geçti mi | F23: TDU-001 | G23: =IFERROR(IF(G8=0,tdu_bir,IF(G16=tdu_bir,tdu_bir,0)),0)
A24: 18 | B24: Borç blok | C24: =IFERROR(G22,0) | D24: bayrak | E24: Borç varsa blok | F24: TDU-001 | G24: =IFERROR(G22,0)
A25: 19 | B25: Mazot şart | C25: =IFERROR(IF(G17>=G9,tdu_bir,0),0) | D25: bayrak | E25: Dekar ≥ mazot min | F25: TDU-002 | G25: =IFERROR(IF(G17>=G9,tdu_bir,0),0)
A26: 20 | B26: Alan bazlı şart | C26: =IFERROR(IF(G17>=G10,tdu_bir,0),0) | D26: bayrak | E26: Dekar ≥ alan min | F26: TDU-003 | G26: =IFERROR(IF(G17>=G10,tdu_bir,0),0)
A27: 21 | B27: Genç çiftçi şart | C27: =IFERROR(IF(AND(G18>0,G18<=G11),tdu_bir,0),0) | D27: bayrak | E27: Yaş uygun mu | F27: TDU-004 | G27: =IFERROR(IF(AND(G18>0,G18<=G11),tdu_bir,0),0)
A28: 22 | B28: Organik şart | C28: =IFERROR(IF(AND(G19=tdu_bir,G17>=G12),tdu_bir,0),0) | D28: bayrak | E28: Organik+dekar | F28: TDU-005 | G28: =IFERROR(IF(AND(G19=tdu_bir,G17>=G12),tdu_bir,0),0)
A29: 23 | B29: Hayvan şart | C29: =IFERROR(IF(G20>=G13,tdu_bir,0),0) | D29: bayrak | E29: Hayvan ≥ min | F29: TDU-006 | G29: =IFERROR(IF(G20>=G13,tdu_bir,0),0)
A30: 24 | B30: IPARD şart | C30: =IFERROR(IF(G21>=G14,tdu_bir,0),0) | D30: bayrak | E30: Yatırım ≥ min | F30: TDU-007 | G30: =IFERROR(IF(G21>=G14,tdu_bir,0),0)
A31: 25 | B31: Program şart bayrağı | C31: =IFERROR(IF(GIRDI!B12="MazotGubre",G25,IF(GIRDI!B12="AlanBazli",G26,IF(GIRDI!B12="GencCiftci",G27,IF(GIRDI!B12="Organik",G28,IF(GIRDI!B12="Hayvancilik",G29,IF(GIRDI!B12="IPARD",G30,0)))))),0) | D31: bayrak | E31: Seçili çağrı şartı | F31: TDU-008 | G31: =IFERROR(IF(GIRDI!B12="MazotGubre",G25,IF(GIRDI!B12="AlanBazli",G26,IF(GIRDI!B12="GencCiftci",G27,IF(GIRDI!B12="Organik",G28,IF(GIRDI!B12="Hayvancilik",G29,IF(GIRDI!B12="IPARD",G30,0)))))),0)
A32: 26 | B32: Zorunlu şart puanı | C32: =IFERROR(IF(G23=0,0,tdu_puanCks)+IF(G24=0,tdu_puanBorc,0)+IF(G31=tdu_bir,tdu_puanProgram,0),0) | D32: puan | E32: ÇKS+borçsuz+program | F32: TDU-001 | G32: =IFERROR(IF(G23=0,0,tdu_puanCks)+IF(G24=0,tdu_puanBorc,0)+IF(G31=tdu_bir,tdu_puanProgram,0),0)
A33: 27 | B33: Alan puanı | C33: =IFERROR(MIN(tdu_puanAlanMax,IF(G17<=0,0,ROUND(G17/MAX(G9,tdu_bir)*tdu_puanAlanCarpan,0))),0) | D33: puan | E33: Dekar yoğunluğu | F33: TDU-002 | G33: =IFERROR(MIN(tdu_puanAlanMax,IF(G17<=0,0,ROUND(G17/MAX(G9,tdu_bir)*tdu_puanAlanCarpan,0))),0)
A34: 28 | B34: Belge puanı | C34: =IFERROR(IF(GIRDI!B18="B",tdu_puanYorumB,tdu_puanYorumA)+IF(G19=tdu_bir,tdu_puanOrganikEk,0)+IF(G20>0,tdu_puanHayvanEk,0),0) | D34: puan | E34: Yorum+belge | F34: TDU-005 | G34: =IFERROR(IF(GIRDI!B18="B",tdu_puanYorumB,tdu_puanYorumA)+IF(G19=tdu_bir,tdu_puanOrganikEk,0)+IF(G20>0,tdu_puanHayvanEk,0),0)
A35: 29 | B35: Uygunluk puanı | C35: =IFERROR(MIN(100,G32+G33+G34),0) | D35: puan | E35: Toplam puan | F35: TDU-008 | G35: =IFERROR(MIN(100,G32+G33+G34),0)
A36: 30 | B36: Karar kodu | C36: =IFERROR(IF(COUNTA(tblGirdi[Alan Anahtarı])=0,"VERI_YOK",IF(OR(G17<tdu_dekarMinGecerli,G17>tdu_dekarAzami,G18<tdu_yasMinGecerli,G18>tdu_yasAzami,G20<0,G20>tdu_hayvanAzami,G21<0,G21>tdu_yatirimAzami),"RED",IF(OR(G23=0,G24=tdu_bir),"RED",IF(AND(G31=tdu_bir,G35>=G15),"UYGUN",IF(AND(G31=tdu_bir,G35>=G15-tdu_sartliBand),"SARTLI","RED"))))),"") | D36: kod | E36: Karar kodu | F36: TDU-008 | G36: =IFERROR(IF(COUNTA(tblGirdi[Alan Anahtarı])=0,"VERI_YOK",IF(OR(G17<tdu_dekarMinGecerli,G17>tdu_dekarAzami,G18<tdu_yasMinGecerli,G18>tdu_yasAzami,G20<0,G20>tdu_hayvanAzami,G21<0,G21>tdu_yatirimAzami),"RED",IF(OR(G23=0,G24=tdu_bir),"RED",IF(AND(G31=tdu_bir,G35>=G15),"UYGUN",IF(AND(G31=tdu_bir,G35>=G15-tdu_sartliBand),"SARTLI","RED"))))),"")
A37: 31 | B37: Karar metni | C37: =IFERROR(IF(G36="VERI_YOK","VERİ YOK",IF(G36="UYGUN","UYGUN · BAŞVUR",IF(G36="SARTLI","ŞARTLI · BELGE EKLE","UYGUN DEĞİL · DURDUR"))),"") | D37: metin | E37: Kullanıcıya karar | F37: TDU-008 | G37: =IFERROR(IF(G36="VERI_YOK","VERİ YOK",IF(G36="UYGUN","UYGUN · BAŞVUR",IF(G36="SARTLI","ŞARTLI · BELGE EKLE","UYGUN DEĞİL · DURDUR"))),"")
A38: 32 | B38: Gerekçe | C38: =IFERROR(IF(G36="VERI_YOK","Giriş tablosu boş — hesap yapılamaz.",IF(OR(G17<tdu_dekarMinGecerli,G17>tdu_dekarAzami,G18<tdu_yasMinGecerli,G18>tdu_yasAzami,G20<0,G20>tdu_hayvanAzami,G21<0,G21>tdu_yatirimAzami),"Alan/yaş/hayvan/yatırım uç veya geçersiz — başvuru uygun değildir.",IF(G24=tdu_bir,"Vergi/SGK borcu varken başvuru uygun değildir.",IF(G23=0,"ÇKS kaydı zorunlu; kayıt yoksa başvuru reddedilir.",IF(G31=0,"Seçilen çağrı programının asgari şartı sağlanmadı.",IF(G36="UYGUN","Puan eşik üstünde ve zorunlu şartlar tamam.",IF(G36="SARTLI","Puan sınır bandında; eksik belge tamamlanmalı.","Puan eşik altında veya şartlar eksik."))))))),"") | D38: metin | E38: Gerekçe cümlesi | F38: TDU-008 | G38: =IFERROR(IF(G36="VERI_YOK","Giriş tablosu boş — hesap yapılamaz.",IF(OR(G17<tdu_dekarMinGecerli,G17>tdu_dekarAzami,G18<tdu_yasMinGecerli,G18>tdu_yasAzami,G20<0,G20>tdu_hayvanAzami,G21<0,G21>tdu_yatirimAzami),"Alan/yaş/hayvan/yatırım uç veya geçersiz — başvuru uygun değildir.",IF(G24=tdu_bir,"Vergi/SGK borcu varken başvuru uygun değildir.",IF(G23=0,"ÇKS kaydı zorunlu; kayıt yoksa başvuru reddedilir.",IF(G31=0,"Seçilen çağrı programının asgari şartı sağlanmadı.",IF(G36="UYGUN","Puan eşik üstünde ve zorunlu şartlar tamam.",IF(G36="SARTLI","Puan sınır bandında; eksik belge tamamlanmalı.","Puan eşik altında veya şartlar eksik."))))))),"")
A39: 33 | B39: Tahmini destek birim | C39: =IFERROR(IF(GIRDI!B12="MazotGubre",tdu_birimMazot,IF(GIRDI!B12="AlanBazli",tdu_birimAlan,IF(GIRDI!B12="GencCiftci",tdu_birimGenc,IF(GIRDI!B12="Organik",tdu_birimOrganik,IF(GIRDI!B12="Hayvancilik",tdu_birimHayvan,IF(GIRDI!B12="IPARD",tdu_birimIpard,0)))))),0) | D39: TL | E39: Program birim tutarı | F39: TDU-002 | G39: =IFERROR(IF(GIRDI!B12="MazotGubre",tdu_birimMazot,IF(GIRDI!B12="AlanBazli",tdu_birimAlan,IF(GIRDI!B12="GencCiftci",tdu_birimGenc,IF(GIRDI!B12="Organik",tdu_birimOrganik,IF(GIRDI!B12="Hayvancilik",tdu_birimHayvan,IF(GIRDI!B12="IPARD",tdu_birimIpard,0)))))),0)
A40: 34 | B40: Tahmini destek tutarı | C40: =IFERROR(IF(OR(G36="VERI_YOK",G36="RED"),0,IF(GIRDI!B12="IPARD",ROUND(G21*INDEX(tblKurallar[aktif_deger],MATCH("TDU-009",tblKurallar[kural_id],0)),0),IF(GIRDI!B12="Hayvancilik",ROUND(G20*G39,0),ROUND(G17*G39,0)))),0) | D40: TL | E40: Tahmini hibe/teşvik | F40: TDU-007 | G40: =IFERROR(IF(OR(G36="VERI_YOK",G36="RED"),0,IF(GIRDI!B12="IPARD",ROUND(G21*INDEX(tblKurallar[aktif_deger],MATCH("TDU-009",tblKurallar[kural_id],0)),0),IF(GIRDI!B12="Hayvancilik",ROUND(G20*G39,0),ROUND(G17*G39,0)))),0)
A41: 35 | B41: Puan / eşik oranı | C41: =IFERROR(IF(G15=0,0,G35/G15),0) | D41: oran | E41: Eşik yoğunluğu | F41: TDU-008 | G41: =IFERROR(IF(G15=0,0,G35/G15),0)
A42: 36 | B42: Zorunlu şart oranı | C42: =IFERROR((IF(G23=tdu_bir,tdu_bir,0)+IF(G24=0,tdu_bir,0)+IF(G31=tdu_bir,tdu_bir,0))/3,0) | D42: oran | E42: Zorunlu tamamlanma | F42: TDU-001 | G42: =IFERROR((IF(G23=tdu_bir,tdu_bir,0)+IF(G24=0,tdu_bir,0)+IF(G31=tdu_bir,tdu_bir,0))/3,0)
...

Sheet SENARYO
A1: SENARYO — Tarımsal Destek/Teşvik Uygunluk Testi
A3: Senaryo ve duyarlılık
A5: Senaryo | B5: Senaryo Dekar | C5: Uygunluk Puanı | D5: Tahmini Destek | E5: Karar
A6: İyimser | B6: =IFERROR(GIRDI!B10*tdu_senaryoIyi,0) | C6: =IFERROR(MOTOR!G47,0) | D6: =IFERROR(MOTOR!G40*tdu_senaryoIyi,0) | E6: =IF(COUNTA(tblGirdi[Alan Anahtarı])=0,"VERİ YOK",IF(C6>=MOTOR!G15,"UYGUN · BAŞVUR",IF(C6>=MOTOR!G15-tdu_sartliBand,"ŞARTLI · BELGE EKLE","UYGUN DEĞİL · DURDUR")))
A7: Baz | B7: =IFERROR(GIRDI!B10,0) | C7: =IFERROR(MOTOR!G35,0) | D7: =IFERROR(MOTOR!G40,0) | E7: =IF(COUNTA(tblGirdi[Alan Anahtarı])=0,"VERİ YOK",IFERROR(MOTOR!G37,"-"))
A8: Kötümser | B8: =IFERROR(GIRDI!B10*tdu_senaryoKotu,0) | C8: =IFERROR(MOTOR!G48,0) | D8: =IFERROR(MOTOR!G40*tdu_senaryoKotu,0) | E8: =IF(COUNTA(tblGirdi[Alan Anahtarı])=0,"VERİ YOK",IF(C8>=MOTOR!G15,"UYGUN · BAŞVUR",IF(C8>=MOTOR!G15-tdu_sartliBand,"ŞARTLI · BELGE EKLE","UYGUN DEĞİL · DURDUR")))
A9: M-SEN eşik+5 | B9: =IFERROR(GIRDI!B10,0) | C9: =IFERROR(MOTOR!G35,0) | D9: =IFERROR(MOTOR!G40,0) | E9: =IF(COUNTA(tblGirdi[Alan Anahtarı])=0,"VERİ YOK",IF(MOTOR!G50="UYGUN","UYGUN · BAŞVUR",IF(MOTOR!G50="SARTLI","ŞARTLI · BELGE EKLE",IF(MOTOR!G50="VERI_YOK","VERİ YOK","UYGUN DEĞİL · DURDUR"))))
A11: Senaryo bant genişliği (iyimser−kötümser puan) | B11: =IFERROR(C6-C8,0)
A12: Senaryo yorumu | B12: =IFERROR(_xlfn.TEXTJOIN("; ",TRUE,"İyimser ",TEXT(C6,"0")," · Baz ",TEXT(C7,"0")," · Kötümser ",TEXT(C8,"0")," · Bant ",TEXT(B11,"0")),"-")
A14: Duyarlılık (tornado)
A15: Değişken | B15: Etki [puan] | C15: Sıra
A16: Tornado dekar etkisi | B16: 12 | C16: 1 | E16: =IFERROR(MOTOR!G53,0)
A17: Tornado yaş etkisi | B17: 8 | C17: 2 | E17: =IFERROR(MOTOR!G54,0)
A18: Tornado eşik etkisi | B18: 5 | C18: 3 | E18: =IFERROR(MOTOR!G55,0)
A19: En etkili değişken | B19: =IFERROR(INDEX(A16:A18,MATCH(1,C16:C18,0)),"-")
A20: Duyarlılık yorumu | B20: =_xlfn.TEXTJOIN(" ",TRUE,"En kritik girdi:",B19,"— başvuru puanını en çok bu etkiler.")
A22: M-SEN eşik+5 sonucu | B22: =IFERROR(MOTOR!G49,0)
A23: M-SEN yorum | B23: =_xlfn.TEXTJOIN(" ",TRUE,"Eşik",TEXT(MOTOR!G49,"0"),"iken karar:",E9)
A25: Senaryo | B25: Puan
A26: İyimser | B26: 85
A27: Baz | B27: 78
A28: Kötümser | B28: 62
A29: M-SEN | B29: 78
A32: Tahmin aralık (üst−alt) | B32: =IFERROR(MOTOR!G51-MOTOR!G52,0)
A33: Tahmin yorumu | B33: =_xlfn.TEXTJOIN(" ",TRUE,"Destek bandı",TEXT(MOTOR!G52,"₺ #,##0"),"—",TEXT(MOTOR!G51,"₺ #,##0"))

Sheet VAKALAR
A1: VAKALAR — Tarımsal Destek/Teşvik Uygunluk Testi
A3: Tebliğ tarzı altın vakalar — destek uygunluk
A5: vaka_id | B5: aciklama | C5: girdi_ozeti | D5: beklenen_sonuc | E5: hesaplanan | F5: fark | G5: durum | H5: kaynak | J5: BeklenenDemo | K5: HesapDemo
A6: TD-V01 | B6: Mazot min dekar — uygun | C6: dekar=vaka_dekar_1; min=TDU-002/2025 | D6: 1 | E6: =IFERROR(IF(vaka_dekar_1>=INDEX(tblKurallar[deger_2025],MATCH("TDU-002",tblKurallar[kural_id],0)),1,0),0) | F6: =IF($A6="","",IFERROR($D6-$E6,0)) | G6: =IF($A6="","",IFERROR(IF(ABS($F6)<=tdu_tolerans,"TUTARLI","KIRIK"),"KIRIK")) | H6: Mazot-gübre destek tebliği | J6: 1 | K6: 1
A7: TD-V02 | B7: Mazot min dekar — yetersiz | C7: dekar=vaka_dekar_2; min=TDU-002/2025 | D7: 0 | E7: =IFERROR(IF(vaka_dekar_2>=INDEX(tblKurallar[deger_2025],MATCH("TDU-002",tblKurallar[kural_id],0)),1,0),0) | F7: =IF($A7="","",IFERROR($D7-$E7,0)) | G7: =IF($A7="","",IFERROR(IF(ABS($F7)<=tdu_tolerans,"TUTARLI","KIRIK"),"KIRIK")) | H7: Mazot-gübre destek tebliği | J7: 0 | K7: 0
A8: TD-V03 | B8: Genç çiftçi yaş uygun | C8: yas=vaka_yas_1; ust=TDU-004/2025 | D8: 1 | E8: =IFERROR(IF(AND(vaka_yas_1>0,vaka_yas_1<=INDEX(tblKurallar[deger_2025],MATCH("TDU-004",tblKurallar[kural_id],0))),1,0),0) | F8: =IF($A8="","",IFERROR($D8-$E8,0)) | G8: =IF($A8="","",IFERROR(IF(ABS($F8)<=tdu_tolerans,"TUTARLI","KIRIK"),"KIRIK")) | H8: Genç çiftçi destek tebliği | J8: 1 | K8: 1
A9: TD-V04 | B9: IPARD yatırım eşiği | C9: yatirim=vaka_yatirim_1; min=TDU-007/2025 | D9: 1 | E9: =IFERROR(IF(vaka_yatirim_1>=INDEX(tblKurallar[deger_2025],MATCH("TDU-007",tblKurallar[kural_id],0)),1,0),0) | F9: =IF($A9="","",IFERROR($D9-$E9,0)) | G9: =IF($A9="","",IFERROR(IF(ABS($F9)<=tdu_tolerans,"TUTARLI","KIRIK"),"KIRIK")) | H9: IPARD başvuru rehberi | J9: 1 | K9: 1
A12: Vaka durum özeti | B12: =IFERROR(IF(COUNTIF(tblVakalar[durum],"KIRIK")>0,"KIRIK","TUTARLI"),"KIRIK")
A13: Vaka fark toplamı | B13: =IFERROR(SUM(tblVakalar[fark]),0)

Sheet KANIT_RAPORU
A1: KANIT RAPORU — Tarımsal Destek/Teşvik Uygunluk Testi
A3: KANIT RAPORU — Tarımsal Destek/Teşvik Uygunluk
A4: Tarih | B4: =raporTarihi
A5: İşletme | B5: =GIRDI!B6
A6: Çağrı programı | B6: =GIRDI!B12
A7: Hesap yılı | B7: =hesapYili
A9: KARAR | B9: =tdu_kararMetni
A10: Gerekçe | B10: =tdu_kararGerekce
A11: Uygunluk puanı | B11: =IFERROR(MOTOR!G35,0)
A12: Tahmini destek | B12: =IFERROR(tdu_tahminiDestek,0)
A13: Madde atıfları | B13: =tdu_maddeAtifMetni
A14: Kanıt özeti | B14: =tdu_kanitRaporu
A15: Vaka durumu | B15: =tdu_vakaDurum
A16: Parmak izi | B16: =tdu_parmakIzi
A18: Uyarılar
A19: Bu çıktı karar destek niteliğindedir; resmî başvuru sonucu yerine geçmez. ÇKS güncelleme penceresi tartışmalıdır (yorum A/B).
A22: İmza — Giren | C22: İmza — Karar veren | E22: İmza — Kanıt isteyen
A24: ________________ | C24: ________________ | E24: ________________

Sheet KONTROLLER
A1: KONTROLLER — Tarımsal Destek/Teşvik Uygunluk Testi
A3: Canlı kontrol paneli
A5: Giriş tablosu boş mu? | B5: =IF(COUNTA(tblGirdi[Alan Anahtarı])=0,"BOŞ","DOLU")
A6: Negatif dekar? | B6: =IF(GIRDI!B10<0,"NEGATİF","TEMİZ")
A7: Hesap yılı geçerli mi? | B7: =IFERROR(IF(AND(N(hesapYili)>N(tdu_yilTaban),N(hesapYili)<=N(tdu_yilTaban)+3),"TEMİZ","HATALI"),"HATALI")
A8: Borç blok aktif mi? | B8: =IF(IFERROR(MOTOR!G24,0)=1,"BLOK","TEMİZ")
A9: Vaka kırık mı? | B9: =IFERROR(IF(COUNTIF(tblVakalar[durum],"KIRIK")>0,"KIRIK","TUTARLI"),"KIRIK")
A10: ÇKS şartı? | B10: =IF(IFERROR(MOTOR!G23,0)=1,"TEMİZ","EKSİK")
A11: Yorum A/B seçili mi? | B11: =IF(OR(GIRDI!B18="A",GIRDI!B18="B"),"TEMİZ","EKSİK")
A12: Kalite skoru (modül) | B12: =IFERROR(ROUND(IF(OR(B14=0,B14=""),0,B15/B14*100),0),0)
A14: Toplam giriş alanı | B14: =IFERROR(tdu_girisBeklenen+COUNTA(GIRDI!B6:B18)*0,0)
A15: Dolu giriş | B15: =COUNTA(GIRDI!B6:B18)
A17: Puan kontrol | B17: =IFERROR(MOTOR!G35,0)
A18: Destek kontrol | B18: =IFERROR(tdu_tahminiDestek,0)
A19: Karar kontrol | B19: =IFERROR(tdu_kararMetni,"-")

Sheet ORNEK_VERI
A1: ORNEK VERI — Tarımsal Destek/Teşvik Uygunluk Testi
A3: Örnek başvuru kütüphanesi
A5: Senaryo | B5: Dekar | C5: Cagri | D5: Yas | E5: Cks | F5: Borc | G5: ProgramSart | H5: PuanTahmin | I5: Karar | K5: PuanDemo
A6: Mazot uygun | B6: 45 | C6: MazotGubre | D6: 38 | E6: Evet | F6: Hayır | G6: =IF($A6="","",IFERROR(IF(AND($E6="Evet",$F6="Hayır",$B6>=tdu_ornekMinDekar),tdu_bir,0),0)) | H6: =IF($A6="","",IFERROR(tdu_ornekTaban+IF($G6=tdu_bir,tdu_puanProgram,0)+MIN(tdu_puanAlanMax,ROUND($B6/tdu_puanAlanCarpan,0)),0)) | I6: =IF($A6="","",IFERROR(IF($H6>=tdu_ornekEsik,"UYGUN · BAŞVUR",IF($H6>=tdu_ornekEsik-tdu_sartliBand,"ŞARTLI · BELGE EKLE","UYGUN DEĞİL · DURDUR")),"UYGUN DEĞİL · DURDUR")) | K6: 85
A7: Mazot yetersiz alan | B7: 8 | C7: MazotGubre | D7: 42 | E7: Evet | F7: Hayır | G7: =IF($A7="","",IFERROR(IF(AND($E7="Evet",$F7="Hayır",$B7>=tdu_ornekMinDekar),tdu_bir,0),0)) | H7: =IF($A7="","",IFERROR(tdu_ornekTaban+IF($G7=tdu_bir,tdu_puanProgram,0)+MIN(tdu_puanAlanMax,ROUND($B7/tdu_puanAlanCarpan,0)),0)) | I7: =IF($A7="","",IFERROR(IF($H7>=tdu_ornekEsik,"UYGUN · BAŞVUR",IF($H7>=tdu_ornekEsik-tdu_sartliBand,"ŞARTLI · BELGE EKLE","UYGUN DEĞİL · DURDUR")),"UYGUN DEĞİL · DURDUR")) | K7: 40
A8: Genç çiftçi | B8: 20 | C8: GencCiftci | D8: 32 | E8: Evet | F8: Hayır | G8: =IF($A8="","",IFERROR(IF(AND($E8="Evet",$F8="Hayır",$B8>=tdu_ornekMinDekar),tdu_bir,0),0)) | H8: =IF($A8="","",IFERROR(tdu_ornekTaban+IF($G8=tdu_bir,tdu_puanProgram,0)+MIN(tdu_puanAlanMax,ROUND($B8/tdu_puanAlanCarpan,0)),0)) | I8: =IF($A8="","",IFERROR(IF($H8>=tdu_ornekEsik,"UYGUN · BAŞVUR",IF($H8>=tdu_ornekEsik-tdu_sartliBand,"ŞARTLI · BELGE EKLE","UYGUN DEĞİL · DURDUR")),"UYGUN DEĞİL · DURDUR")) | K8: 78
A9: Borçlu blok | B9: 50 | C9: AlanBazli | D9: 40 | E9: Evet | F9: Evet | G9: =IF($A9="","",IFERROR(IF(AND($E9="Evet",$F9="Hayır",$B9>=tdu_ornekMinDekar),tdu_bir,0),0)) | H9: =IF($A9="","",IFERROR(tdu_ornekTaban+IF($G9=tdu_bir,tdu_puanProgram,0)+MIN(tdu_puanAlanMax,ROUND($B9/tdu_puanAlanCarpan,0)),0)) | I9: =IF($A9="","",IFERROR(IF($H9>=tdu_ornekEsik,"UYGUN · BAŞVUR",IF($H9>=tdu_ornekEsik-tdu_sartliBand,"ŞARTLI · BELGE EKLE","UYGUN DEĞİL · DURDUR")),"UYGUN DEĞİL · DURDUR")) | K9: 20
A10: ÇKS yok | B10: 30 | C10: MazotGubre | D10: 35 | E10: Hayır | F10: Hayır | G10: =IF($A10="","",IFERROR(IF(AND($E10="Evet",$F10="Hayır",$B10>=tdu_ornekMinDekar),tdu_bir,0),0)) | H10: =IF($A10="","",IFERROR(tdu_ornekTaban+IF($G10=tdu_bir,tdu_puanProgram,0)+MIN(tdu_puanAlanMax,ROUND($B10/tdu_puanAlanCarpan,0)),0)) | I10: =IF($A10="","",IFERROR(IF($H10>=tdu_ornekEsik,"UYGUN · BAŞVUR",IF($H10>=tdu_ornekEsik-tdu_sartliBand,"ŞARTLI · BELGE EKLE","UYGUN DEĞİL · DURDUR")),"UYGUN DEĞİL · DURDUR")) | K10: 20
A11: Organik | B11: 12 | C11: Organik | D11: 45 | E11: Evet | F11: Hayır | G11: =IF($A11="","",IFERROR(IF(AND($E11="Evet",$F11="Hayır",$B11>=tdu_ornekMinDekar),tdu_bir,0),0)) | H11: =IF($A11="","",IFERROR(tdu_ornekTaban+IF($G11=tdu_bir,tdu_puanProgram,0)+MIN(tdu_puanAlanMax,ROUND($B11/tdu_puanAlanCarpan,0)),0)) | I11: =IF($A11="","",IFERROR(IF($H11>=tdu_ornekEsik,"UYGUN · BAŞVUR",IF($H11>=tdu_ornekEsik-tdu_sartliBand,"ŞARTLI · BELGE EKLE","UYGUN DEĞİL · DURDUR")),"UYGUN DEĞİL · DURDUR")) | K11: 70
G12: =IF($A12="","",IFERROR(IF(AND($E12="Evet",$F12="Hayır",$B12>=tdu_ornekMinDekar),tdu_bir,0),0)) | H12: =IF($A12="","",IFERROR(tdu_ornekTaban+IF($G12=tdu_bir,tdu_puanProgram,0)+MIN(tdu_puanAlanMax,ROUND($B12/tdu_puanAlanCarpan,0)),0)) | I12: =IF($A12="","",IFERROR(IF($H12>=tdu_ornekEsik,"UYGUN · BAŞVUR",IF($H12>=tdu_ornekEsik-tdu_sartliBand,"ŞARTLI · BELGE EKLE","UYGUN DEĞİL · DURDUR")),"UYGUN DEĞİL · DURDUR"))
G13: =IF($A13="","",IFERROR(IF(AND($E13="Evet",$F13="Hayır",$B13>=tdu_ornekMinDekar),tdu_bir,0),0)) | H13: =IF($A13="","",IFERROR(tdu_ornekTaban+IF($G13=tdu_bir,tdu_puanProgram,0)+MIN(tdu_puanAlanMax,ROUND($B13/tdu_puanAlanCarpan,0)),0)) | I13: =IF($A13="","",IFERROR(IF($H13>=tdu_ornekEsik,"UYGUN · BAŞVUR",IF($H13>=tdu_ornekEsik-tdu_sartliBand,"ŞARTLI · BELGE EKLE","UYGUN DEĞİL · DURDUR")),"UYGUN DEĞİL · DURDUR"))
G14: =IF($A14="","",IFERROR(IF(AND($E14="Evet",$F14="Hayır",$B14>=tdu_ornekMinDekar),tdu_bir,0),0)) | H14: =IF($A14="","",IFERROR(tdu_ornekTaban+IF($G14=tdu_bir,tdu_puanProgram,0)+MIN(tdu_puanAlanMax,ROUND($B14/tdu_puanAlanCarpan,0)),0)) | I14: =IF($A14="","",IFERROR(IF($H14>=tdu_ornekEsik,"UYGUN · BAŞVUR",IF($H14>=tdu_ornekEsik-tdu_sartliBand,"ŞARTLI · BELGE EKLE","UYGUN DEĞİL · DURDUR")),"UYGUN DEĞİL · DURDUR"))
G15: =IF($A15="","",IFERROR(IF(AND($E15="Evet",$F15="Hayır",$B15>=tdu_ornekMinDekar),tdu_bir,0),0)) | H15: =IF($A15="","",IFERROR(tdu_ornekTaban+IF($G15=tdu_bir,tdu_puanProgram,0)+MIN(tdu_puanAlanMax,ROUND($B15/tdu_puanAlanCarpan,0)),0)) | I15: =IF($A15="","",IFERROR(IF($H15>=tdu_ornekEsik,"UYGUN · BAŞVUR",IF($H15>=tdu_ornekEsik-tdu_sartliBand,"ŞARTLI · BELGE EKLE","UYGUN DEĞİL · DURDUR")),"UYGUN DEĞİL · DURDUR"))

Sheet LISTELER
A1: LISTELER — Tarımsal Destek/Teşvik Uygunluk Testi
A3: Doğrulama listeleri
A5: Yıl | C5: Yorum | E5: EvetHayir | G5: Urun | I5: Cagri
A6: 2025 | C6: A | E6: Evet | G6: Bitkisel | I6: MazotGubre
A7: 2026 | C7: B | E7: Hayır | G7: Hayvansal | I7: AlanBazli
A8: 2027 | G8: Karma | I8: GencCiftci
I9: Organik
I10: Hayvancilik
I11: IPARD

Sheet AYARLAR
A1: AYARLAR — Tarımsal Destek/Teşvik Uygunluk Testi
A3: Parametreler (tek kaynak)
A4: Sarı hücreler değiştirilebilir; formül hücreleri kilitlidir.
A5: anahtar | B5: deger | C5: birim | D5: aciklama | E5: kaynak | F5: yururluk_tarihi | G5: dogrulama_tarihi | H5: kontrol
A6: raporTarihi | B6: 46245 | C6: tarih | D6: Rapor tarihi | E6: Üretim | F6: 01.01.2025 | G6: 11.08.2026 | H6: =IF(A6="","",IF(B6="","EKSİK","TAM"))
A7: tdu_tolerans | B7: 0.01 | C7: oran | D7: Vaka tutarlılık toleransı | E7: Uygulama notu | F7: 01.01.2025 | G7: 11.08.2026 | H7: =IF(A7="","",IF(B7="","EKSİK","TAM"))
A8: tdu_sartliBand | B8: 15 | C8: puan | D8: Şartlı puan bandı | E8: İç politika | F8: 01.01.2025 | G8: 11.08.2026 | H8: =IF(A8="","",IF(B8="","EKSİK","TAM"))
A9: tdu_farkEsik | B9: 50 | C9: puan | D9: PANO uyarı eşiği | E9: İç politika | F9: 01.01.2025 | G9: 11.08.2026 | H9: =IF(A9="","",IF(B9="","EKSİK","TAM"))
A10: tdu_senaryoIyi | B10: 1.15 | C10: çarpan | D10: İyimser dekar çarpanı | E10: Model varsayımı | F10: 01.01.2025 | G10: 11.08.2026 | H10: =IF(A10="","",IF(B10="","EKSİK","TAM"))
A11: tdu_senaryoKotu | B11: 0.85 | C11: çarpan | D11: Kötümser dekar çarpanı | E11: Model varsayımı | F11: 01.01.2025 | G11: 11.08.2026 | H11: =IF(A11="","",IF(B11="","EKSİK","TAM"))
A12: tdu_oranArtisPuan | B12: 5 | C12: puan | D12: M-SEN eşik artışı | E12: Senaryo motoru | F12: 01.01.2025 | G12: 11.08.2026 | H12: =IF(A12="","",IF(B12="","EKSİK","TAM"))
A13: tdu_tahminAlt | B13: 0.9 | C13: çarpan | D13: Tahmin alt bant | E13: Model varsayımı | F13: 01.01.2025 | G13: 11.08.2026 | H13: =IF(A13="","",IF(B13="","EKSİK","TAM"))
A14: tdu_tahminUst | B14: 1.1 | C14: çarpan | D14: Tahmin üst bant | E14: Model varsayımı | F14: 01.01.2025 | G14: 11.08.2026 | H14: =IF(A14="","",IF(B14="","EKSİK","TAM"))
A15: tdu_tornadoDekar | B15: 1.2 | C15: çarpan | D15: Tornado dekar şoku | E15: Model varsayımı | F15: 01.01.2025 | G15: 11.08.2026 | H15: =IF(A15="","",IF(B15="","EKSİK","TAM"))
A16: tdu_tornadoYas | B16: 1 | C16: çarpan | D16: Tornado yaş şoku | E16: Model varsayımı | F16: 01.01.2025 | G16: 11.08.2026 | H16: =IF(A16="","",IF(B16="","EKSİK","TAM"))
A17: tdu_yuzdelikOran | B17: 0.9 | C17: oran | D17: Yüzdelik P90 | E17: İstatistik | F17: 01.01.2025 | G17: 11.08.2026 | H17: =IF(A17="","",IF(B17="","EKSİK","TAM"))
A18: tdu_parmakIzi | B18: 819dabb17a8a135d | C18: metin | D18: Dosya parmak izi | E18: Üretim | F18: 01.01.2025 | G18: 11.08.2026 | H18: =IF(A18="","",IF(B18="","EKSİK","TAM"))
A19: tdu_girisBeklenen | B19: 13 | C19: adet | D19: Zorunlu giriş alanı sayısı | E19: Ürün mimarisi | F19: 01.01.2025 | G19: 11.08.2026 | H19: =IF(A19="","",IF(B19="","EKSİK","TAM"))
A20: tdu_riskDusuk | B20: 20 | C20: puan | D20: Düşük risk puanı | E20: İç politika | F20: 01.01.2025 | G20: 11.08.2026 | H20: =IF(A20="","",IF(B20="","EKSİK","TAM"))
A21: tdu_riskOrta | B21: 55 | C21: puan | D21: Orta risk puanı | E21: İç politika | F21: 01.01.2025 | G21: 11.08.2026 | H21: =IF(A21="","",IF(B21="","EKSİK","TAM"))
A22: tdu_riskYuksek | B22: 85 | C22: puan | D22: Yüksek risk puanı | E22: İç politika | F22: 01.01.2025 | G22: 11.08.2026 | H22: =IF(A22="","",IF(B22="","EKSİK","TAM"))
A23: tdu_kararEsik | B23: 5 | C23: puan | D23: Yedek karar eşiği | E23: İç politika | F23: 01.01.2025 | G23: 11.08.2026 | H23: =IF(A23="","",IF(B23="","EKSİK","TAM"))
A24: tdu_yilTaban | B24: 2024 | C24: yıl | D24: CHOOSE yıl tabanı | E24: Ürün mimarisi | F24: 01.01.2025 | G24: 11.08.2026 | H24: =IF(A24="","",IF(B24="","EKSİK","TAM"))
A25: tdu_bir | B25: 1 | C25: bayrak | D25: Mantıksal bir | E25: Ürün mimarisi | F25: 01.01.2025 | G25: 11.08.2026 | H25: =IF(A25="","",IF(B25="","EKSİK","TAM"))
A26: tdu_puanCks | B26: 20 | C26: puan | D26: ÇKS şart puanı | E26: İç politika | F26: 01.01.2025 | G26: 11.08.2026 | H26: =IF(A26="","",IF(B26="","EKSİK","TAM"))
A27: tdu_puanBorc | B27: 20 | C27: puan | D27: Borçsuzluk puanı | E27: İç politika | F27: 01.01.2025 | G27: 11.08.2026 | H27: =IF(A27="","",IF(B27="","EKSİK","TAM"))
A28: tdu_puanProgram | B28: 30 | C28: puan | D28: Program şart puanı | E28: İç politika | F28: 01.01.2025 | G28: 11.08.2026 | H28: =IF(A28="","",IF(B28="","EKSİK","TAM"))
A29: tdu_puanAlanMax | B29: 25 | C29: puan | D29: Alan puan tavanı | E29: İç politika | F29: 01.01.2025 | G29: 11.08.2026 | H29: =IF(A29="","",IF(B29="","EKSİK","TAM"))
A30: tdu_puanAlanCarpan | B30: 10 | C30: çarpan | D30: Alan puan çarpanı | E30: İç politika | F30: 01.01.2025 | G30: 11.08.2026 | H30: =IF(A30="","",IF(B30="","EKSİK","TAM"))
... A53: tdu_ornekEsik | B53: 70 | C53: puan | D53: Örnek karar eşiği | E53: Ürün mimarisi | F53: 01.01.2025 | G53: 11.08.2026 | H53: =IF(A53="","",IF(B53="","EKSİK","TAM"))
A54: dosya_surumu | B54: 1.0.0 | C54: metin | D54: Ürün sürümü | E54: ExcelArşiv | F54: 01.01.2025 | G54: 11.08.2026 | H54: =IF(A54="","",IF(B54="","EKSİK","TAM"))
D56: Sürüm 1.0.0 | Şifre: 1234

Sheet KILAVUZ
A1: KILAVUZ — Tarımsal Destek/Teşvik Uygunluk Testi
A3: Kullanım kılavuzu
A5: 1. GIRDI sarı hücrelere işletme ve çağrı bilgilerini girin.
A6: 2. KURALLAR sayfasında yıllı eşikleri güncelleyin; MOTOR sabit eşik kullanmaz.
A7: 3. PANO kararını okuyun; ŞARTLI ise eksik belge listesini tamamlayın.
A8: 4. KANIT_RAPORU'nu PDF/yazıcıya gönderin.
A9: 5. Şifre 1234 — formül sayfaları korumalıdır; giriş hücreleri açıktır.
A11: Belirsizlik beyanları
A12: ÇKS güncelleme penceresi tartışmalıdır. Yorum A: başvuru tarihinde güncel ÇKS kaydı zorunlu (sıkı). Yorum B: çağrı ilan tarihindeki kayıt kabul (geniş). Belirsiz durumlarda her iki yorumu SENARYO ile karşılaştırın.
A16: Sorumluluk reddi
A17: Ürün karar destek aracıdır; Tarım ve Orman Bakanlığı veya IPARD resmî sonucu yerine geçmez. Parametreleri güncel tebliğle doğrulayın.
