Workbook
Name raporTarihi: AYARLAR!$B$6
Name zincirTolerans: AYARLAR!$B$7
Name sdf_esikGecikmeGun: AYARLAR!$B$8
Name sdf_esikGeciken: AYARLAR!$B$9
Name sdf_kovaEsik1: AYARLAR!$B$10
Name sdf_kovaEsik2: AYARLAR!$B$11
Name sdf_kovaEsik3: AYARLAR!$B$12
Name sdf_hedefKapanis: AYARLAR!$B$13
Name sdf_sifir: AYARLAR!$B$14
Name sdf_kaliteTaban: AYARLAR!$B$15
Name sdf_kaliteCeza: AYARLAR!$B$16
Name sdf_senaryoTemkinli: AYARLAR!$B$17
Name sdf_senaryoBaz: AYARLAR!$B$18
Name sdf_senaryoIyimser: AYARLAR!$B$19
Name sdf_tornadoOran: AYARLAR!$B$20
Name sdf_yuzdelikOran: AYARLAR!$B$21
Name sdf_olcekHedef: AYARLAR!$B$22
Name sdf_azamiTutar: AYARLAR!$B$23
Name sdf_durumHaritasi: AYARLAR!$B$24
Name sdf_kuyrukOzeti_metin: AYARLAR!$B$25
Name sdf_kapaliDusum_metin: AYARLAR!$B$26
Name sdf_kanitRaporu_metin: AYARLAR!$B$27
Name sdf_dosyaSurumu: AYARLAR!$B$28
Name sdf_firmaUnvan: AYARLAR!$B$29
Name sdf_trendOcak: AYARLAR!$B$30
Name sdf_trendSubat: AYARLAR!$B$31
Name sdf_trendMart: AYARLAR!$B$32
Name sdf_trendNisan: AYARLAR!$B$33
Name sdf_trendMayis: AYARLAR!$B$34
Name sdf_trendHaziran: AYARLAR!$B$35
Name sdf_trendTemmuz: AYARLAR!$B$36
Name sdf_trendAgustos: AYARLAR!$B$37
Name sdf_trendEylul: AYARLAR!$B$38
Name sdf_trendEkim: AYARLAR!$B$39
Name sdf_trendKasim: AYARLAR!$B$40
Name sdf_trendAralik: AYARLAR!$B$41
Name sdf_acik8D: AYARLAR!$I$55
Name sdf_dfPlanToplam: AYARLAR!$I$56
Name sdf_gecikenAdet: AYARLAR!$I$57
Name sdf_dfGercekToplam: AYARLAR!$I$58
Name sdf_yetimKayit: AYARLAR!$I$59
Name sdf_gecersizGecis: AYARLAR!$I$60
Name sdf_zincirKirik: AYARLAR!$I$61
Name sdf_kapanisOrani: AYARLAR!$I$62
Name sdf_yasKova: AYARLAR!$I$63
Name sdf_tahsilatOrt: AYARLAR!$I$64
Name sdf_tahsilatSapma: AYARLAR!$I$65
Name sdf_tahminAralik: AYARLAR!$I$66
Name sdf_senaryoKarsilastirma: AYARLAR!$I$67
Name sdf_tornadoZirve: AYARLAR!$I$68
Name sdf_hhi: AYARLAR!$I$69
Name sdf_kaliteSkor: AYARLAR!$I$70
Name sdf_yuzdelikP90: AYARLAR!$I$71
Name sdf_senaryoMotor: AYARLAR!$I$72
Name sdf_kapaliDusum: AYARLAR!$I$73
Name sdf_kuyrukOzeti: AYARLAR!$I$74
Name sdf_kanitRaporu: AYARLAR!$I$75
Name sdf_sonrakiKimlik: AYARLAR!$I$76
Name sdf_kararKapi: AYARLAR!$I$77
Name sdf_modulT1: AYARLAR!$I$78

Sheet 00_BASLANGIC
A1: EXCELARŞİV KARAR SİSTEMİ v15.1 — ÜRETİM REFERANSI
A3: Konu | B3: Bağlayıcı Standart
A4: Amaç | B4: Kanıta dayalı, hatada kapalı çalışan Excel üretim ve denetim sistemi
A5: Öncelik | B5: Kullanıcının açık iş talebi ve gerçek kullanım senaryosu
A6: Ana akış | B6: Uygunluk → Yönetişim → Sözleşmeler → Üretim → Test → Kanıt → Kullanıcı Kabulü → Yayın
A7: Yayın ilkesi | B7: Üst aşamada hata varsa alt aşama GEÇTİ üretilemez
A8: Kullanıcı kabulü | B8: Excel masaüstü görünümü test edilmediyse DIŞ_KABUL_GEREKLİ
A9: Nihai yayın | B9: Yalnız uygulanabilir modüller GEÇTİ veya gerekçeli UYGULANMAZ
A10: Ticari ayrım | B10: Ekonomik olarak savunulabilir fiyat, gerçek pazar kabulü ile aynı değildir
A11: Karmaşıklık | B11: Karar değeri, eklenen karmaşıklığın maliyetinden büyük olmalıdır
A12: Excel sınırı | B12: Veritabanı, kurumsal yetkilendirme, değiştirilemez kayıt sistemi veya gerçek zamanlı olay platformu değildir
A13: Dil standardı | B13: Kullanıcıya görünen tüm sayfa, tablo, başlık, açıklama, uyarı ve karar metinleri saf Türkçe olmalıdır
A14: Muhasebe standardı | B14: Finansal ürünlerde Türkiye Tekdüzen Hesap Planı ve Türk muhasebe kullanım alışkanlıkları esas alınır
... A33: Muhasebe | B33: Türkiye Tekdüzen Hesap Planı ve Türk muhasebe/işletme düşünce yapısı esas alınır.

Sheet PANO
A1: ☰ PANO
B2: 8D / DÜZELTICI FAALIYET DOSYA SISTEMI | L2: Dönem: 2026 / Tam ▼ | M2: ★ DOĞRULANMIŞ
B3: Hedef Kullanıcı: Kalite müdürü, QA sorumlusu, müşteri şikâyet / 8D lideri, IATF denetim hazırlığı · 2026 Q3 Denetim Standardı
B5: AÇIK 8D ADEDI | D5: KONSOLİDE | E5: DF MALIYET TREND | G5: KONTROL | H5: NET OPERASYONEL MARJ | J5: GÜVENLİ | K5: SİSTEM GÜVEN SKORU | M5: DENETLENDİ
B7: =GİRDİLER!E17 | E7: =B7*0.22 | H7: =B7-E7 | K7: =IF(E7>0, ROUND(B7/E7, 2), 0)
B9: ↑ %14.2 konsolide canlı veri bağlantısı | E9: ● 8 Kalem nakit karşılığı: bloke | H9: ██████████░░░░░ %78.0 NET MARJ | K9: ✓ İDEAL karşılama rasyosu
B11: 8D / DÜZELTICI FAALIYET DOSYA SISTEMI — DÖNEMSEL İCRA VE PROJEKSİYON | F11: +%32 Verim | H11: KONSOLİDE OPERASYON VE KARAR MATRİSİ
B12: Kümülatif Hacim vs. Operasyonel Maliyet ve Net Kâr Eğilimi | H12: Anlık Hesaplama Sonuçları, Dinamik Formül Çıktıları ve Durum Puanlaması
B14: Dönem | C14: Aktif Hacim | D14: Maliyet/Yük | E14: Hedef | H14: PARAMETRE / KALEM | I14: ANA TUTAR | J14: FARK / MARJ | K14: VADE | L14: KONTROL DURUMU
B15: D1 | C15: 65 | D15: 45 | E15: 60 | H15: Dönemlik Kümülatif Bakiye | I15: =B7*0.45 | J15: =B7*0.05 | K15: 12 Ay | L15: ✓ DÜZENLİ
B16: D2 | C16: 78 | D16: 48 | E16: 70 | H16: Kritik Eşik Güvenlik Tamponu | I16: =B7*0.30 | J16: =B7*0.03 | K16: 24 Ay | L16: ★ AVANTAJ
B17: D3 | C17: 85 | D17: 55 | E17: 80 | H17: Operasyonel Net Fark | I17: =B7*0.15 | J17: =B7*0.02 | K17: 8 Ay | L17: ● YAKLAŞAN
B18: D4 | C18: 75 | D18: 42 | E18: 75 | H18: Rezerv ve Likit Dağılım | I18: =B7*0.10 | J18: =B7*0.01 | K18: 16 Ay | L18: ✓ TAM UYUM
B19: D5 | C19: 90 | D19: 40 | E19: 85 | H19: KONSOLİDE SİSTEM TOPLAMI | I19: =SUM(I15:I18) | J19: =SUM(J15:J18) | L19: TAM DOĞRULANDI (0 HATA)
B20: D6 | C20: 96 | D20: 32 | E20: 92
B22: KONSOLİDE PAY VE AĞIRLIK | F22: LİKİDİTE RİSKİ & ERKEN UYARI SİNYALLERİ | K22: KARAR MOTORU
B23: ■ Ana Segment (%42) | F23: Nakit Açığı Riski (30 Gün) | I23: 0.00 TL (Sıfır Risk) | K23: STRATEJİK VERİMLİLİK FIRSATI
B24: ■ İkincil Grup (%30) | F24: Tahsilat Gecikme Toleransı | I24: 48 Gün Güvenli Eşik | K24: Operasyonel süreç optimizasyonu ile kârlılık artış potansiyeli tespit edildi.
B25: ■ Destek Birimi (%15) | F25: ██████████████████████████████████████ Güvenli Bölge (%100)
B26: ■ Rezervler (%13) | F26: ✓ 90 GÜNLÜK PROJEKSİYONDA NAKİT SIKIŞIKLIĞI TESPİT EDİLMEDİ | K26: STRATEJİ REÇETESİNİ İNCELE >

Sheet GİRDİLER
A1: ☰ PANO
B3: 🔍 8D / DÜZELTICI FAALIYET DOSYA SISTEMI — Kayıt veya hesap ara... | G3: TOPLAM: 1.450 KAYIT | I3: HATALI HÜCRE: 0 ADET
B5: TARİH | C5: REFERANS NO | D5: İŞLEM AÇIKLAMASI VE DETAY | E5: BRÜT TUTAR (₺) | F5: KDV ORANI | G5: NET TUTAR (₺) | H5: HESAP / CARİ | I5: DURUM
B6: 12.10.2026 | C6: TR-0428-A | D6: Operasyonel ana kalem tahmini | E6: 845200 | F6: 0.2 | G6: =E6/(1+F6) | H6: Vadesiz Ticari | I6: ONAYLANDI
B7: 14.10.2026 | C7: TR-0429-B | D7: Operasyonel çıkış/maliyet tahmini | E7: 1240000 | F7: 0.2 | G7: =E7/(1+F7) | H7: Tedarikçi Havuzu | I7: BEKLEMEDE
B8: 18.10.2026 | C8: TR-0430-C | D8: Ödeme takvimi tahakkuku | E8: 620500 | F8: 0.1 | G8: =E8/(1+F8) | H8: Kısa Vade Tahakkuk | I8: ONAYLANDI
B9: 21.10.2026 | C9: TR-0431-D | D9: Müşteri işlem tahmini | E9: 415000 | F9: 0.2 | G9: =E9/(1+F9) | H9: Müşteri Alacağı | I9: ONAYLANDI
B10: 25.10.2026 | C10: TR-0432-E | D10: Ana operasyon tahmini | E10: 980400 | F10: 0.2 | G10: =E10/(1+F10) | H10: Vadesiz Ticari | I10: ONAYLANDI
B11: 28.10.2026 | C11: TR-0433-F | D11: Kredi/taksit karşılığı | E11: 1850000 | F11: 0.2 | G11: =E11/(1+F11) | H11: Finansman Havuzu | I11: BLOKE
B12: 02.11.2026 | C12: TR-0434-G | D12: Sabit gider ve yönetim notları | E12: 740000 | F12: 0.2 | G12: =E12/(1+F12) | H12: Genel Yönetim | I12: ONAYLANDI
B13: 05.11.2026 | C13: TR-0435-H | D13: Operasyonel ana kalem tahmini | E13: 520800 | F13: 0.2 | G13: =E13/(1+F13) | H13: Vadesiz Ticari | I13: ONAYLANDI
B14: 09.11.2026 | C14: TR-0436-I | D14: Müşteri işlem tahmini | E14: 1120000 | F14: 0.2 | G14: =E14/(1+F14) | H14: Müşteri Alacağı | I14: ONAYLANDI
B15: 12.11.2026 | C15: TR-0437-J | D15: Operasyonel çıkış tahmini | E15: 890000 | F15: 0.2 | G15: =E15/(1+F15) | H15: Tedarikçi Havuzu | I15: ONAYLANDI
B17: SAYFA TOPLAMI (10 / 1.450 KAYIT) | E17: =SUM(E6:E15)

Sheet YÖNETİM_RAPORU
A1: ☰ PANO
B2: 8D / DÜZELTICI FAALIYET DOSYA SISTEMI — NİHAİ KARAR VE DEĞERLEME
B3: Yönetim Kurulu ve İcra Komitesi için Otomatik Finansal Stres Testi Raporu · Kalite müdürü, QA sorumlusu, müşteri şikâyet / 8D lideri, IATF denetim hazırlığı
B4: DÖNEM: 2026 Q3 · DENETİM PROTOKOLÜ: ISO/VUK/IFRS UYUMLU · DURUM: ONAYLANDI
B6: SENARYO A: KÖTÜMSER (STRES TESTİ -%20) | H6: SENARYO B: BAZ MODEL (HEDEFLENEN)
B8: Ciro / Hacim Düşüşü: | E8: -%20.0 (Kriz Eşiği) | H8: Ciro / Hacim Gerçekleşmesi: | K8: %100.0 (Tam Bütçe)
B9: Beklenen Net Kâr / Getiri: | E9: =PANO!B7*0.8*0.22 | H9: Beklenen Net Kâr / Getiri: | K9: =PANO!H7
B10: Minimum Nakit Tamponu: | E10: =PANO!E7*0.75 | H10: Serbest Nakit Akımı: | K10: =PANO!H7*0.75
B11: Likidite Karşılama Oranı: | E11: =ROUND(PANO!B7*0.8/PANO!E7, 2) | H11: Yatırım Geri Dönüşü (ROI): | K11: %38.4 Yıllık
B14: STRES SENARYOSUNDA DAHİ İFLAS RİSKİ YOK | H14: OPTİMUM İCRA VE PLANLAMA REÇETESİ
B17: YÖNETİM KARAR MATRİSİ VE UYGULAMA REÇETESİ
B19: ● Öncelik 1: Acil Likidite ve Borç Servis Planlaması
B20: Sistemde hesaplanan vade günlerine sadık kalınarak nakit blokajı 3 gün önceden hazır edilmelidir.
B21: ● Öncelik 2: Formül Doğrulama ve Çapraz Sağlama
B22: Tüm hücreler kilitli formül korumasında olup girdi sayfalarında sıfır döngüsel başvuru (circular ref) garantilidir.
B23: ● Öncelik 3: Resmi Mevzuat ve Vergi Kalkanı Entegrasyonu
B24: 2026 güncel vergi dilimleri, amortisman ve SGK teşvik parametreleri tam otomatik yansıtılmaktadır.
B25: ● Öncelik 4: Yönetici İmzası ve Rapor Paylaşımı
B26: Tek tuşla PDF ve A4 çıktı formatına tam uyumlu sayfa yapısı kurgulanmıştır.

Sheet 01_YURUTME_CEKIRDEGI
A1: YÜRÜTME ÇEKİRDEĞİ — ZORUNLU ÜRETİM SIRASI
A3: Adım | B3: Modül | C3: Tetikleyici | D3: Zorunlu Kanıt | E3: GEÇTİ Kuralı | F3: Hata Durumu | G3: Sonraki Aşama
A4: 1 | B4: Excel Uygunluğu | C4: Her yeni model | D4: UYGUNLUK_KARARI | E4: Excel'in rolü açık | F4: HATA / BLOKE | G4: Yönetişim
A5: 2 | B5: Yönetişim | C5: Her model | D5: Risk seviyesi + etki girdileri | E5: Seviye hesaplandı | F5: BLOKE | G5: Sözleşmeler
A6: 3 | B6: Türk Muhasebe Eşlemesi | C6: Finansal model | D6: THP hesap eşleme tablosu | E6: Kritik satırlar THP ile uyumlu | F6: HATA | G6: Sözleşmeler
A7: 4 | B7: Veri ve Anlam Sözleşmeleri | C7: Girdi/KPI varsa | D7: Veri + KPI sözleşmeleri | E7: Kapsam %100 | F7: HATA | G7: Üretim
A8: 5 | B8: Üretim | C8: Sözleşmeler GEÇTİ | D8: Çalışan Excel | E8: Tek gerçek kaynak korunmuş | F8: HATA | G8: Testler
A9: 6 | B9: Görsel/Kullanım Katmanı | C9: Motor hazır | D9: Başlıklar + renk + grafik + yönlendirme | E9: Tüm kullanıcı sayfaları standarda uygun | F9: HATA | G9: Testler
A10: 7 | B10: Testler | C10: Üretim tamam | D10: Formül/OOXML/kimlik/oracle/golden/metamorfik | E10: Uygulanabilir hard gate'ler GEÇTİ | F10: HATA | G10: Kanıt
A11: 8 | B11: Hata-Kontrol Tutarlılığı | C11: Test sonucu var | D11: Hata taraması + kontrol sonuçları | E11: Formül hatası varken GEÇTİ yok | F11: HATA | G11: Kanıt
A12: 9 | B12: Kanıt | C12: Test sonucu var | D12: Makine okunur artefakt + özet | E12: Kanıt fiziksel ve tutarlı | F12: HATA | G12: Kullanıcı Kabulü
A13: 10 | B13: Kullanıcı Kabulü | C13: Kritik görevler | D13: Gerçek ekran davranışı | E13: Kritik görevler %100 | F13: DIŞ_KABUL_GEREKLİ | G13: Ticari
A14: 11 | B14: Ticari Değer | C14: Ürün satılacaksa | D14: ROI + demo + kanıt paketi | E14: Ekonomik değer kanıtlı | F14: UYARI / HATA | G14: Pazar Doğrulama
A15: 12 | B15: Pazar Doğrulama | C15: Pazar iddiası varsa | D15: Ücretli satış/pilot/fiyat kabul kanıtı | E15: Gerçek fiyat kabul kanıtı | F15: UYGULANMAZ / HATA | G15: Yayın

Sheet 02_KONTROL_LISTESI
A1: NİHAİ KONTROL LİSTESİ — KANITSIZ GEÇİŞ YOK
A3: Kontrol No | B3: Kontrol | C3: Beklenen | D3: Zorunlu Kapı? | E3: Sonuç
A4: K01 | B4: Kullanıcının açık talebi öncelikli mi? | C4: Evet | D4: EVET
A5: K02 | B5: Mevcut yapı, formüller ve tek gerçek kaynak korunuyor mu? | C5: Evet, değişiklik gerekçeli | D5: EVET
A6: K03 | B6: Üst aşama HATA ise alt aşama GEÇTİ engelleniyor mu? | C6: Evet | D6: EVET
A7: K04 | B7: Kanıt fiziksel çıktı ve içerik doğrulaması içeriyor mu? | C7: Evet | D7: EVET
A8: K05 | B8: Excel GUI erişimi olmadan kullanıcı görünümü GEÇTİ yazılıyor mu? | C8: Hayır | D8: EVET
A9: K06 | B9: NİHAİ yalnız GEÇTİ / gerekçeli UYGULANMAZ ile mi? | C9: Evet | D9: EVET
A10: K07 | B10: Ekonomik fiyat savunusu pazar doğrulamasından ayrılmış mı? | C10: Evet | D10: EVET
A11: K08 | B11: Prestij için gereksiz modül var mı? | C11: Hayır | D11: HAYIR
A12: K09 | B12: Excel sınırları açık mı? | C12: Evet | D12: EVET
A13: K10 | B13: Teknik kaynak korunuyor mu? | C13: Evet | D13: EVET
A14: K11 | B14: Kullanıcıya görünen tüm metinler Türkçe mi? | C14: Evet | D14: EVET
A15: K12 | B15: Her kullanıcı sayfasında üst başlık var mı? | C15: Evet | D15: EVET
... A34: K31 | B34: Premium vitrin, altyapı kadar güçlü ve satış fiyatını destekleyecek seviyede mi? | C34: Evet | D34: EVET

Sheet 03_GORSEL_TASARIM
A1: GÖRSEL TASARIM VE PREMIUM EXCEL STANDARDI
A3: Alan | B3: Zorunlu Kural | C3: Uygulama | D3: Yasak | E3: Kontrol | F3: Durum
A4: Sayfa başlığı | B4: Her kullanıcı sayfasının en üstünde tek ve açık sayfa başlığı | C4: A1'den başlayan koyu lacivert başlık bandı | D4: Başlıksız sayfa | E4: Başlık kapsama = %100 | F4: ZORUNLU
A5: Sekme renkleri | B5: Sayfalar işlevine göre renk kodlanır | C5: Girdi=mavi, hesap=gri, rapor=lacivert, kontrol=kırmızı, kılavuz=altın | D5: Rastgele renk | E5: Renk semantiği tutarlı | F5: ZORUNLU
A6: Kolon düzeni | B6: Veri blokları bitişik kolonlarda ilerler | C6: Gereksiz boş kolon bırakma; yalnız gerçek bölüm ayrımı varsa kontrollü boşluk | D6: A:C veri, D boş, E:F veri gibi parçalı yapı | E6: Boş kolon taraması | F6: ZORUNLU
A7: Girdi hücreleri | B7: Kullanıcının değiştireceği alan açıkça görünür | C7: Açık sarı dolgu + mavi yazı | D7: Formülle aynı görünüm | E7: Girdi/formül ayrımı | F7: ZORUNLU
A8: Formüller | B8: Hesap hücreleri kullanıcı girdisinden ayrılır | C8: Siyah yazı; sayfalar arası bağlantı yeşil yazı | D8: Hard-code gizleme | E8: Formül sınıfı kontrolü | F8: ZORUNLU
A9: Grafik sayısı | B9: Yönetici ekranında en fazla 3 ana karar grafiği | C9: Trend, karşılaştırma, köprü/dağılım; iş kararına bağlı | D9: Grafik kalabalığı | E9: Grafik başına karar sorusu | F9: ZORUNLU
A10: Grafik stili | B10: Kurumsal ve yüksek okunabilirlik | C10: Beyaz zemin, ince gridline, tek vurgu rengi, açık birim/başlık | D10: 3B, gölge, neon, gökkuşağı renkleri | E10: Görsel inceleme | F10: ZORUNLU
A11: Grafik başlığı | B11: Grafik 'neyi' değil 'ne anlama geldiğini' söyler | C11: Örn: 'Nakit 2028'de kritik eşiğin altına iniyor' | D11: 'Nakit Grafiği' gibi anlamsız başlık | E11: Başlık karar testi | F11: ZORUNLU
A12: Birimler | B12: Tüm finansal görsellerde birim açık | C12: TL, bin TL, milyon TL, %, gün, x | D12: Birim belirsizliği | E12: Birim kapsama %100 | F12: ZORUNLU
A13: Sıfır/negatif | B13: Finansal format standardı | C13: Sıfır='-', negatif kırmızı parantez | D13: -500 veya 0,00 kalabalığı | E13: Format kontrolü | F13: ZORUNLU
A14: Yazı tipi | B14: Tek aile | C14: Aptos veya Segoe UI | D14: Karışık font | E14: Tek font kontrolü | F14: ZORUNLU
... A22: Premium vitrin | B22: Görsel kalite ürün değerinin zorunlu parçasıdır | C22: Kaliteli grafik, gerçek KPI kartı, finansal hiyerarşi, tab rengi, fonksiyonel navigasyon | D22: Sadece doğru hesap yapıp çıplak/varsayılan Excel görünümü bırakmak | E22: Görsel release incelemesi | F22: ZORUNLU

Sheet 04_MUHASEBE_THP
A1: TÜRKİYE MUHASEBE VE TEKDÜZEN HESAP PLANI STANDARDI
A3: Konu | B3: Zorunlu Standart | C3: Örnek Türkçe Ad | D3: THP / Mantık | E3: Hata Riski | F3: Kontrol
A4: Dil | B4: Kullanıcıya görünen finansal terimler Türkçe | C4: Hasılat, Satışların Maliyeti, Brüt Kâr, Faaliyet Giderleri | D4: Türk işletme kullanımına uygun | E4: İngilizce jargon | F4: Terminoloji taraması
A5: Gelir Tablosu | B5: Türk sunum sırası kullanılır | C5: Net Satışlar → Satışların Maliyeti → Brüt Kâr → Faaliyet Giderleri → Faaliyet Kârı | D5: 600/610/611; 620-623; 63x | E5: Yanlış sınıflama | F5: Hesap eşleme
A6: Bilanço | B6: Dönen/Duran Varlık ve Kısa/Uzun Vadeli Yükümlülük ayrımı | C6: Hazır Değerler, Ticari Alacaklar, Stoklar, Mali Borçlar | D6: 1xx / 2xx / 3xx / 4xx / 5xx | E6: Vade sınıfı hatası | F6: Bilanço eşitliği
A7: Nakit Akışı | B7: İşletme/Yatırım/Finansman nakit akışları ayrılır | C7: Faaliyetlerden Nakit, Yatırım Harcamaları, Finansman Nakit Akışı | D7: Dolaylı/doğrudan yöntem açık seçilir | E7: Kâr = nakit sanılması | F7: Nakit devri
A8: Ticari Alacaklar | B8: Cari ve vade mantığı korunur | C8: 120 Alıcılar | D8: 120 | E8: Tahakkuk/nakit karışması | F8: Alacak devir kontrolü
A9: Ticari Borçlar | B9: Tedarikçi borcu ayrı izlenir | C9: 320 Satıcılar | D9: 320 | E9: Gider/ödeme karışması | F9: Borç devir kontrolü
A10: Kasa/Banka | B10: Hazır değerler ayrı izlenir | C10: 100 Kasa, 102 Bankalar | D10: 100 / 102 | E10: Virmanla toplam nakdin değişmesi | F10: Virman değişmezi
A11: Stok | B11: Dikeye uygun stok türü | C11: 150 İlk Madde ve Malzeme, 153 Ticari Mallar | D11: 15x | E11: Maliyet ve stok hareketinin kopması | F11: Stok devri
A12: Maddi Duran Varlık | B12: Yatırım harcaması ve amortisman bağlantılı | C12: 253 Tesis Makine Cihazlar, 255 Demirbaşlar, 257 Birikmiş Amortismanlar | D12: 25x | E12: Yatırım/gider karışması | F12: Net defter değeri devri
A13: Mali Borçlar | B13: Kısa/uzun vadeli borç ayrımı | C13: 300 Banka Kredileri / 400 Banka Kredileri | D13: 300 / 400 | E13: Vade sınıfı yanlış | F13: Borç devri
A14: Özkaynak | B14: Sermaye ve geçmiş yıl kârları ayrı | C14: 500 Sermaye, 570 Geçmiş Yıllar Kârları, 590 Dönem Net Kârı | D14: 5xx | E14: Net kâr bağının kopması | F14: Özkaynak devri
... A18: İstisna | B18: TFRS özel ürün varsa fark açık yazılır | C18: Tekdüzen raporlama ≠ TFRS finansal tablo sunumu | D18: Amaç belirtilir | E18: Standartları karıştırma | F18: Model amacı kontrolü

Sheet 05_KARAR_SATIS
A1: KARAR, GÜVEN VE SATIŞA HAZIRLIK STANDARDI
A3: Alan | B3: Müşteri Sorusu | C3: Zorunlu Ürün Davranışı | D3: Kanıt | E3: Başarısızlık Durumu | F3: Kapı
A4: 5 saniye | B4: Bu ürün neyi çözüyor? | C4: İlk ekranda hedef kullanıcı + pahalı problem + sonuç görünür | D4: Başlık + alt mesaj + gerçek ekran | E4: Ürün yalnız teknik isim | F4: HATA
A5: Acı | B5: Sorun bana neye mal oluyor? | C5: Mümkünse müşterinin kendi verisiyle parasal/zaman etkisi hesaplanır | D5: ROI/acı hesaplama yöntemi | E5: Uydurma tasarruf | F5: HATA
A6: Karar | B6: Bu bilgiyle ne yapacağım? | C6: Her kritik KPI aksiyona bağlanır | D6: KARAR_KUYRUGU | E6: Sadece rapor | F6: HATA
A7: Güven | B7: Bu sayıya neden inanayım? | C7: Kaynak, formül mantığı, kontrol ve son doğrulama görünür | D7: Kontroller + kaynak izi + sürüm | E7: Prestij kelimesi | F7: HATA
A8: Referans | B8: Müşteri yorumu yoksa ne göstereceğim? | C8: Önce/Sonra + Karar Vakası + Hata Önleme Vakası üretilir | D8: Demo/örnek çıktı | E8: Kanıtsız iddia | F8: HATA
A9: Senaryo | B9: Ne olursa işler bozulur? | C9: Baz/Aşağı/Yukarı veya uygun stres senaryosu | D9: Senaryo karşılaştırma | E9: Dekoratif senaryo | F9: HATA
A10: Ters stres | B10: Hangi eşikte karar kırılır? | C10: En az bir kritik sürücü için kırılma eşiği | D10: Kırılma eşiği tablosu | E10: Sadece +/- %10 | F10: UYARI/HATA
A11: Hata tutarlılığı | B11: Formül hata verirse ne olur? | C11: Kontrol GEÇTİ veremez; BLOKE/HATA üretir | D11: Hata taraması | E11: Hata + GEÇTİ birlikte | F11: HATA
A12: Karar motoru | B12: Ne oldu, neden oldu? | C12: Sorun + neden + parasal etki + aksiyon + son tarih | D12: Karar tablosu | E12: Boş sayfa / isim düzeyi modül | F12: HATA
A13: Yönetici özeti | B13: 5 saniyede ne görmeliyim? | C13: Bugün / ne değişti / ne bozulacak / neden / ne yapmalıyım / güven | D13: Yönetici özeti ekranı | E13: KPI kutusu yığını | F13: HATA
A14: Teklif | B14: Neden satın almalıyım? | C14: Dosya özellikleri yerine sonuç ve kaçınılan maliyet sunulur | D14: Ürün sayfası kanıt eşlemesi | E14: Özellik listesiyle satış | F14: HATA
... A19: Pazar kanıtı | B19: Piyasa gerçekten ödüyor mu? | C19: Satış/pilot/LOI/fiyat kabulü olmadan pazar doğrulandı yazılmaz | D19: Gerçek işlem kanıtı | E19: Tahmini talep = satış kabulü | F19: HATA

Sheet KAPAK
A1: KAPAK — 8D / Düzeltici Faaliyet Dosya Sistemi
A3: 8D / Düzeltici Faaliyet Dosya Sistemi
A4: Müşteri şikâyetinden 8D (D1–D8) kapanışına kadar dosyayı yönetir; kök neden ve DF plan/gerçek maliyet zincirini görünür kılar; müşteri/IATF kanıt raporu üretir.
A6: Bu ürün ne sağlar?
A7: • Makrosuz durum: D1 Ekip → D2 Problem → D3 Muhafaza → D4 Kök → D5 DF → D6 Uygula → D7 Önle → D8 Kapalı
A8: • Kök neden + DF plan/gerçek maliyet zinciri; ZİNCİR KIRIK bayrağı
A9: • Kapanış oranı ve kuyruk yaşlandırması (0-30 / 31-60 / 61-90 / 90+)
A10: • Yetim ekip ve geçersiz 8D geçiş uyarıları
A11: • KANIT_RAPORU — müşteri / IATF denetim dosyasına imzalı kanıt
A13: Kimler için?
A14: • 8D lideri / QA — şikâyet ve D1–D8 satırı girişi
A15: • Kalite müdürü — kapanış oranı ve DF maliyet kararı
... A21: Sürüm 1.0.0 | Lisans: Tek kullanıcı | ExcelArşiv

Sheet EKIP
A1: EKIP — 8D / Düzeltici Faaliyet Dosya Sistemi
A3: 8D ekip kartları — her üyenin tek kimliği vardır
A4: Sonraki Kimlik | B4: =sdf_sonrakiKimlik
A5: EkipId | B5: AdSoyad | C5: Bolum | D5: Rol | E5: HedefAcik8D | F5: VarsayşikâyetRisk | G5: Aktif | H5: BeklenenDfMaliyet | I5: Kapali8DAdet
A6: EKP-00001 | B6: Ayşe Yılmaz | C6: Kalite | D6: 8D Lider | E6: 3 | F6: 0.03 | G6: EVET | H6: =IF($A6="","",SUMIF(tblAkis[KaynakEkipId],$A6,tblAkis[Tutar])) | I6: =IF($A6="","",COUNTIFS(tblAkis[KaynakEkipId],$A6,tblAkis[Durum],"D8_KAPALI"))
A7: EKP-00002 | B7: Mehmet Kaya | C7: Üretim | D7: Proses | E7: 4 | F7: 0.02 | G7: EVET | H7: =IF($A7="","",SUMIF(tblAkis[KaynakEkipId],$A7,tblAkis[Tutar])) | I7: =IF($A7="","",COUNTIFS(tblAkis[KaynakEkipId],$A7,tblAkis[Durum],"D8_KAPALI"))
A8: EKP-00003 | B8: Zeynep Demir | C8: Kalite | D8: MSA | E8: 5 | F8: 0.03 | G8: EVET | H8: =IF($A8="","",SUMIF(tblAkis[KaynakEkipId],$A8,tblAkis[Tutar])) | I8: =IF($A8="","",COUNTIFS(tblAkis[KaynakEkipId],$A8,tblAkis[Durum],"D8_KAPALI"))
A9: EKP-00004 | B9: Can Öztürk | C9: Bakım | D9: Ekipman | E9: 6 | F9: 0.02 | G9: EVET | H9: =IF($A9="","",SUMIF(tblAkis[KaynakEkipId],$A9,tblAkis[Tutar])) | I9: =IF($A9="","",COUNTIFS(tblAkis[KaynakEkipId],$A9,tblAkis[Durum],"D8_KAPALI"))
A10: EKP-00005 | B10: Elif Şahin | C10: Satınalma | D10: Tedarikçi | E10: 7 | F10: 0.03 | G10: EVET | H10: =IF($A10="","",SUMIF(tblAkis[KaynakEkipId],$A10,tblAkis[Tutar])) | I10: =IF($A10="","",COUNTIFS(tblAkis[KaynakEkipId],$A10,tblAkis[Durum],"D8_KAPALI"))
A11: EKP-00006 | B11: Burak Çelik | C11: Üretim | D11: Operatör | E11: 8 | F11: 0.02 | G11: EVET | H11: =IF($A11="","",SUMIF(tblAkis[KaynakEkipId],$A11,tblAkis[Tutar])) | I11: =IF($A11="","",COUNTIFS(tblAkis[KaynakEkipId],$A11,tblAkis[Durum],"D8_KAPALI"))
A12: EKP-00007 | B12: Selin Arslan | C12: Kalite | D12: Müşteri | E12: 9 | F12: 0.03 | G12: EVET | H12: =IF($A12="","",SUMIF(tblAkis[KaynakEkipId],$A12,tblAkis[Tutar])) | I12: =IF($A12="","",COUNTIFS(tblAkis[KaynakEkipId],$A12,tblAkis[Durum],"D8_KAPALI"))
A13: EKP-00008 | B13: Emre Koç | C13: Mühendislik | D13: Tasarım | E13: 10 | F13: 0.02 | G13: EVET | H13: =IF($A13="","",SUMIF(tblAkis[KaynakEkipId],$A13,tblAkis[Tutar])) | I13: =IF($A13="","",COUNTIFS(tblAkis[KaynakEkipId],$A13,tblAkis[Durum],"D8_KAPALI"))
A14: EKP-00009 | B14: Deniz Acar | C14: Kalite | D14: 8D Lider | E14: 11 | F14: 0.03 | G14: EVET | H14: =IF($A14="","",SUMIF(tblAkis[KaynakEkipId],$A14,tblAkis[Tutar])) | I14: =IF($A14="","",COUNTIFS(tblAkis[KaynakEkipId],$A14,tblAkis[Durum],"D8_KAPALI"))
A15: EKP-00010 | B15: Burcu Polat | C15: Lojistik | D15: Sevkiyat | E15: 12 | F15: 0.02 | G15: EVET | H15: =IF($A15="","",SUMIF(tblAkis[KaynakEkipId],$A15,tblAkis[Tutar])) | I15: =IF($A15="","",COUNTIFS(tblAkis[KaynakEkipId],$A15,tblAkis[Durum],"D8_KAPALI"))
H16: =IF($A16="","",SUMIF(tblAkis[KaynakEkipId],$A16,tblAkis[Tutar])) | I16: =IF($A16="","",COUNTIFS(tblAkis[KaynakEkipId],$A16,tblAkis[Durum],"D8_KAPALI"))
H17: =IF($A17="","",SUMIF(tblAkis[KaynakEkipId],$A17,tblAkis[Tutar])) | I17: =IF($A17="","",COUNTIFS(tblAkis[KaynakEkipId],$A17,tblAkis[Durum],"D8_KAPALI"))
H18: =IF($A18="","",SUMIF(tblAkis[KaynakEkipId],$A18,tblAkis[Tutar])) | I18: =IF($A18="","",COUNTIFS(tblAkis[KaynakEkipId],$A18,tblAkis[Durum],"D8_KAPALI"))
H19: =IF($A19="","",SUMIF(tblAkis[KaynakEkipId],$A19,tblAkis[Tutar])) | I19: =IF($A19="","",COUNTIFS(tblAkis[KaynakEkipId],$A19,tblAkis[Durum],"D8_KAPALI"))
H20: =IF($A20="","",SUMIF(tblAkis[KaynakEkipId],$A20,tblAkis[Tutar])) | I20: =IF($A20="","",COUNTIFS(tblAkis[KaynakEkipId],$A20,tblAkis[Durum],"D8_KAPALI"))
H21: =IF($A21="","",SUMIF(tblAkis[KaynakEkipId],$A21,tblAkis[Tutar])) | I21: =IF($A21="","",COUNTIFS(tblAkis[KaynakEkipId],$A21,tblAkis[Durum],"D8_KAPALI"))
H22: =IF($A22="","",SUMIF(tblAkis[KaynakEkipId],$A22,tblAkis[Tutar])) | I22: =IF($A22="","",COUNTIFS(tblAkis[KaynakEkipId],$A22,tblAkis[Durum],"D8_KAPALI"))
H23: =IF($A23="","",SUMIF(tblAkis[KaynakEkipId],$A23,tblAkis[Tutar])) | I23: =IF($A23="","",COUNTIFS(tblAkis[KaynakEkipId],$A23,tblAkis[Durum],"D8_KAPALI"))
H24: =IF($A24="","",SUMIF(tblAkis[KaynakEkipId],$A24,tblAkis[Tutar])) | I24: =IF($A24="","",COUNTIFS(tblAkis[KaynakEkipId],$A24,tblAkis[Durum],"D8_KAPALI"))
H25: =IF($A25="","",SUMIF(tblAkis[KaynakEkipId],$A25,tblAkis[Tutar])) | I25: =IF($A25="","",COUNTIFS(tblAkis[KaynakEkipId],$A25,tblAkis[Durum],"D8_KAPALI"))
H26: =IF($A26="","",SUMIF(tblAkis[KaynakEkipId],$A26,tblAkis[Tutar])) | I26: =IF($A26="","",COUNTIFS(tblAkis[KaynakEkipId],$A26,tblAkis[Durum],"D8_KAPALI"))
H27: =IF($A27="","",SUMIF(tblAkis[KaynakEkipId],$A27,tblAkis[Tutar])) | I27: =IF($A27="","",COUNTIFS(tblAkis[KaynakEkipId],$A27,tblAkis[Durum],"D8_KAPALI"))
... H255: =IF($A255="","",SUMIF(tblAkis[KaynakEkipId],$A255,tblAkis[Tutar])) | I255: =IF($A255="","",COUNTIFS(tblAkis[KaynakEkipId],$A255,tblAkis[Durum],"D8_KAPALI"))

Sheet AKIS
A1: AKIS — 8D / Düzeltici Faaliyet Dosya Sistemi
A3: 8D dosya satırları — D1–D8 durum makinesi + yetim + geçersiz geçiş + DF maliyet zinciri
A5: IslemId | B5: KaynakEkipId | C5: SikayetNo | D5: BaslangicTarihi | E5: OncekiDurum | F5: Durum | G5: DfPlanMaliyet | H5: DfGercekMaliyet | I5: MusteriEtkiTl | J5: TekrarRisk | K5: DfDogrulamaTl | L5: Tutar | M5: KokNedenKod | N5: DfSinif | O5: ProblemOzet | P5: GecikmeGun | Q5: YasKova | R5: BeklenenDfMaliyet | S5: KapanisBayrak | T5: YetimBayrak | U5: GecisUyarisi | V5: ZincirBayrak | W5: KayitDolu
A6: 8D-00001 | B6: EKP-00001 | C6: SKY-2026-0001 | D6: 46240 | F6: D1_EKIP | G6: 17500 | H6: 16700 | J6: 0.15 | L6: 20125 | M6: Malzeme | N6: A | O6: Problem notu 1 | P6: =IF($D6="","",raporTarihi-$D6) | Q6: =IF($P6="","",IF($P6<=sdf_kovaEsik1,"0-30",IF($P6<=sdf_kovaEsik2,"31-60",IF($P6<=sdf_kovaEsik3,"61-90","90+")))) | R6: =IF($A6="","",IF($H6>0,$H6,$G6)) | S6: =IF($F6="D8_KAPALI","KAPANAN",IF($F6="IPTAL","IPTAL","ACIK")) | T6: =IF($B6="","YETİM",IF(COUNTIF(tblEkip[EkipId],$B6)=0,"YETİM","")) | U6: =IF(OR($E6&"|"&$F6="",COUNTIF(ListeIzinliGecis,$E6&"|"&$F6)>0),"","GEÇERSİZ GEÇİŞ") | V6: =IF(OR($F6="D8_KAPALI",$F6="D7_ONLE",$I6>0),IF(OR($H6="",$I6=""),"",IF(ABS($I6-$H6)>zincirTolerans,"ZİNCİR KIRIK","OK")),IF($H6>0,IF(OR($G6="",$H6=""),"",IF(ABS($H6-$G6)>zincirTolerans,"ZİNCİR KIRIK","OK")),"OK")) | W6: =IF($A6="","",1)
A7: 8D-00002 | B7: EKP-00002 | C7: SKY-2026-0002 | D7: 46235 | E7: D1_EKIP | F7: D2_PROBLEM | G7: 20000 | H7: 18400 | J7: 0.15 | L7: 23000 | M7: Makine | N7: B | O7: Problem notu 2 | P7: =IF($D7="","",raporTarihi-$D7) | Q7: =IF($P7="","",IF($P7<=sdf_kovaEsik1,"0-30",IF($P7<=sdf_kovaEsik2,"31-60",IF($P7<=sdf_kovaEsik3,"61-90","90+")))) | R7: =IF($A7="","",IF($H7>0,$H7,$G7)) | S7: =IF($F7="D8_KAPALI","KAPANAN",IF($F7="IPTAL","IPTAL","ACIK")) | T7: =IF($B7="","YETİM",IF(COUNTIF(tblEkip[EkipId],$B7)=0,"YETİM","")) | U7: =IF(OR($E7&"|"&$F7="",COUNTIF(ListeIzinliGecis,$E7&"|"&$F7)>0),"","GEÇERSİZ GEÇİŞ") | V7: =IF(OR($F7="D8_KAPALI",$F7="D7_ONLE",$I7>0),IF(OR($H7="",$I7=""),"",IF(ABS($I7-$H7)>zincirTolerans,"ZİNCİR KIRIK","OK")),IF($H7>0,IF(OR($G7="",$H7=""),"",IF(ABS($H7-$G7)>zincirTolerans,"ZİNCİR KIRIK","OK")),"OK")) | W7: =IF($A7="","",1)
A8: 8D-00003 | B8: EKP-00003 | C8: SKY-2026-0003 | D8: 46230 | E8: D2_PROBLEM | F8: D3_MUHAFAZA | G8: 22500 | H8: 20100 | J8: 0.1 | L8: 24750 | M8: Insan | N8: A | O8: Problem notu 3 | P8: =IF($D8="","",raporTarihi-$D8) | Q8: =IF($P8="","",IF($P8<=sdf_kovaEsik1,"0-30",IF($P8<=sdf_kovaEsik2,"31-60",IF($P8<=sdf_kovaEsik3,"61-90","90+")))) | R8: =IF($A8="","",IF($H8>0,$H8,$G8)) | S8: =IF($F8="D8_KAPALI","KAPANAN",IF($F8="IPTAL","IPTAL","ACIK")) | T8: =IF($B8="","YETİM",IF(COUNTIF(tblEkip[EkipId],$B8)=0,"YETİM","")) | U8: =IF(OR($E8&"|"&$F8="",COUNTIF(ListeIzinliGecis,$E8&"|"&$F8)>0),"","GEÇERSİZ GEÇİŞ") | V8: =IF(OR($F8="D8_KAPALI",$F8="D7_ONLE",$I8>0),IF(OR($H8="",$I8=""),"",IF(ABS($I8-$H8)>zincirTolerans,"ZİNCİR KIRIK","OK")),IF($H8>0,IF(OR($G8="",$H8=""),"",IF(ABS($H8-$G8)>zincirTolerans,"ZİNCİR KIRIK","OK")),"OK")) | W8: =IF($A8="","",1)
A9: 8D-00004 | B9: EKP-00004 | C9: SKY-2026-0004 | D9: 46225 | E9: D3_MUHAFAZA | F9: D4_KOK | G9: 25000 | H9: 25000 | J9: 0.15 | L9: 28750 | M9: Ortam | N9: B | O9: Problem notu 4 | P9: =IF($D9="","",raporTarihi-$D9) | Q9: =IF($P9="","",IF($P9<=sdf_kovaEsik1,"0-30",IF($P9<=sdf_kovaEsik2,"31-60",IF($P9<=sdf_kovaEsik3,"61-90","90+")))) | R9: =IF($A9="","",IF($H9>0,$H9,$G9)) | S9: =IF($F9="D8_KAPALI","KAPANAN",IF($F9="IPTAL","IPTAL","ACIK")) | T9: =IF($B9="","YETİM",IF(COUNTIF(tblEkip[EkipId],$B9)=0,"YETİM","")) | U9: =IF(OR($E9&"|"&$F9="",COUNTIF(ListeIzinliGecis,$E9&"|"&$F9)>0),"","GEÇERSİZ GEÇİŞ") | V9: =IF(OR($F9="D8_KAPALI",$F9="D7_ONLE",$I9>0),IF(OR($H9="",$I9=""),"",IF(ABS($I9-$H9)>zincirTolerans,"ZİNCİR KIRIK","OK")),IF($H9>0,IF(OR($G9="",$H9=""),"",IF(ABS($H9-$G9)>zincirTolerans,"ZİNCİR KIRIK","OK")),"OK")) | W9: =IF($A9="","",1)
A10: 8D-00005 | B10: EKP-00005 | C10: SKY-2026-0005 | D10: 46220 | E10: D4_KOK | F10: D5_DF | G10: 27500 | H10: 26700 | J10: 0.15 | L10: 31625 | M10: Yontem | N10: A | O10: Problem notu 5 | P10: =IF($D10="","",raporTarihi-$D10) | Q10: =IF($P10="","",IF($P10<=sdf_kovaEsik1,"0-30",IF($P10<=sdf_kovaEsik2,"31-60",IF($P10<=sdf_kovaEsik3,"61-90","90+")))) | R10: =IF($A10="","",IF($H10>0,$H10,$G10)) | S10: =IF($F10="D8_KAPALI","KAPANAN",IF($F10="IPTAL","IPTAL","ACIK")) | T10: =IF($B10="","YETİM",IF(COUNTIF(tblEkip[EkipId],$B10)=0,"YETİM","")) | U10: =IF(OR($E10&"|"&$F10="",COUNTIF(ListeIzinliGecis,$E10&"|"&$F10)>0),"","GEÇERSİZ GEÇİŞ") | V10: =IF(OR($F10="D8_KAPALI",$F10="D7_ONLE",$I10>0),IF(OR($H10="",$I10=""),"",IF(ABS($I10-$H10)>zincirTolerans,"ZİNCİR KIRIK","OK")),IF($H10>0,IF(OR($G10="",$H10=""),"",IF(ABS($H10-$G10)>zincirTolerans,"ZİNCİR KIRIK","OK")),"OK")) | W10: =IF($A10="","",1)
A11: 8D-00006 | B11: EKP-00006 | C11: SKY-2026-0006 | D11: 46215 | E11: D5_DF | F11: D6_UYGULA | G11: 30000 | H11: 28400 | J11: 0.1 | L11: 33000 | M11: Malzeme | N11: B | O11: Problem notu 6 | P11: =IF($D11="","",raporTarihi-$D11) | Q11: =IF($P11="","",IF($P11<=sdf_kovaEsik1,"0-30",IF($P11<=sdf_kovaEsik2,"31-60",IF($P11<=sdf_kovaEsik3,"61-90","90+")))) | R11: =IF($A11="","",IF($H11>0,$H11,$G11)) | S11: =IF($F11="D8_KAPALI","KAPANAN",IF($F11="IPTAL","IPTAL","ACIK")) | T11: =IF($B11="","YETİM",IF(COUNTIF(tblEkip[EkipId],$B11)=0,"YETİM","")) | U11: =IF(OR($E11&"|"&$F11="",COUNTIF(ListeIzinliGecis,$E11&"|"&$F11)>0),"","GEÇERSİZ GEÇİŞ") | V11: =IF(OR($F11="D8_KAPALI",$F11="D7_ONLE",$I11>0),IF(OR($H11="",$I11=""),"",IF(ABS($I11-$H11)>zincirTolerans,"ZİNCİR KIRIK","OK")),IF($H11>0,IF(OR($G11="",$H11=""),"",IF(ABS($H11-$G11)>zincirTolerans,"ZİNCİR KIRIK","OK")),"OK")) | W11: =IF($A11="","",1)
A12: 8D-00007 | B12: EKP-00007 | C12: SKY-2026-0007 | D12: 46210 | E12: D6_UYGULA | F12: D7_ONLE | G12: 32500 | H12: 30100 | I12: 65000 | J12: 0.15 | L12: 37375 | M12: Makine | N12: A | O12: Problem notu 7 | P12: =IF($D12="","",raporTarihi-$D12) | Q12: =IF($P12="","",IF($P12<=sdf_kovaEsik1,"0-30",IF($P12<=sdf_kovaEsik2,"31-60",IF($P12<=sdf_kovaEsik3,"61-90","90+")))) | R12: =IF($A12="","",IF($H12>0,$H12,$G12)) | S12: =IF($F12="D8_KAPALI","KAPANAN",IF($F12="IPTAL","IPTAL","ACIK")) | T12: =IF($B12="","YETİM",IF(COUNTIF(tblEkip[EkipId],$B12)=0,"YETİM","")) | U12: =IF(OR($E12&"|"&$F12="",COUNTIF(ListeIzinliGecis,$E12&"|"&$F12)>0),"","GEÇERSİZ GEÇİŞ") | V12: =IF(OR($F12="D8_KAPALI",$F12="D7_ONLE",$I12>0),IF(OR($H12="",$I12=""),"",IF(ABS($I12-$H12)>zincirTolerans,"ZİNCİR KIRIK","OK")),IF($H12>0,IF(OR($G12="",$H12=""),"",IF(ABS($H12-$G12)>zincirTolerans,"ZİNCİR KIRIK","OK")),"OK")) | W12: =IF($A12="","",1)
A13: 8D-00008 | B13: EKP-00008 | C13: SKY-2026-0008 | D13: 46205 | E13: D7_ONLE | F13: D8_KAPALI | G13: 35000 | H13: 35000 | I13: 70000 | J13: 0.15 | K13: 35000 | L13: 0 | M13: Insan | N13: B | O13: Problem notu 8 | P13: =IF($D13="","",raporTarihi-$D13) | Q13: =IF($P13="","",IF($P13<=sdf_kovaEsik1,"0-30",IF($P13<=sdf_kovaEsik2,"31-60",IF($P13<=sdf_kovaEsik3,"61-90","90+")))) | R13: =IF($A13="","",IF($H13>0,$H13,$G13)) | S13: =IF($F13="D8_KAPALI","KAPANAN",IF($F13="IPTAL","IPTAL","ACIK")) | T13: =IF($B13="","YETİM",IF(COUNTIF(tblEkip[EkipId],$B13)=0,"YETİM","")) | U13: =IF(OR($E13&"|"&$F13="",COUNTIF(ListeIzinliGecis,$E13&"|"&$F13)>0),"","GEÇERSİZ GEÇİŞ") | V13: =IF(OR($F13="D8_KAPALI",$F13="D7_ONLE",$I13>0),IF(OR($H13="",$I13=""),"",IF(ABS($I13-$H13)>zincirTolerans,"ZİNCİR KIRIK","OK")),IF($H13>0,IF(OR($G13="",$H13=""),"",IF(ABS($H13-$G13)>zincirTolerans,"ZİNCİR KIRIK","OK")),"OK")) | W13: =IF($A13="","",1)
A14: 8D-00009 | B14: EKP-00009 | C14: SKY-2026-0009 | D14: 46200 | E14: D5_DF | F14: IPTAL | G14: 37500 | H14: 36700 | J14: 0.1 | L14: 0 | M14: Ortam | N14: A | O14: Problem notu 9 | P14: =IF($D14="","",raporTarihi-$D14) | Q14: =IF($P14="","",IF($P14<=sdf_kovaEsik1,"0-30",IF($P14<=sdf_kovaEsik2,"31-60",IF($P14<=sdf_kovaEsik3,"61-90","90+")))) | R14: =IF($A14="","",IF($H14>0,$H14,$G14)) | S14: =IF($F14="D8_KAPALI","KAPANAN",IF($F14="IPTAL","IPTAL","ACIK")) | T14: =IF($B14="","YETİM",IF(COUNTIF(tblEkip[EkipId],$B14)=0,"YETİM","")) | U14: =IF(OR($E14&"|"&$F14="",COUNTIF(ListeIzinliGecis,$E14&"|"&$F14)>0),"","GEÇERSİZ GEÇİŞ") | V14: =IF(OR($F14="D8_KAPALI",$F14="D7_ONLE",$I14>0),IF(OR($H14="",$I14=""),"",IF(ABS($I14-$H14)>zincirTolerans,"ZİNCİR KIRIK","OK")),IF($H14>0,IF(OR($G14="",$H14=""),"",IF(ABS($H14-$G14)>zincirTolerans,"ZİNCİR KIRIK","OK")),"OK")) | W14: =IF($A14="","",1)
A15: 8D-00010 | B15: EKP-00010 | C15: SKY-2026-0010 | D15: 46195 | E15: D4_KOK | F15: D5_DF | G15: 40000 | H15: 38400 | J15: 0.15 | L15: 46000 | M15: Yontem | N15: B | O15: Problem notu 10 | P15: =IF($D15="","",raporTarihi-$D15) | Q15: =IF($P15="","",IF($P15<=sdf_kovaEsik1,"0-30",IF($P15<=sdf_kovaEsik2,"31-60",IF($P15<=sdf_kovaEsik3,"61-90","90+")))) | R15: =IF($A15="","",IF($H15>0,$H15,$G15)) | S15: =IF($F15="D8_KAPALI","KAPANAN",IF($F15="IPTAL","IPTAL","ACIK")) | T15: =IF($B15="","YETİM",IF(COUNTIF(tblEkip[EkipId],$B15)=0,"YETİM","")) | U15: =IF(OR($E15&"|"&$F15="",COUNTIF(ListeIzinliGecis,$E15&"|"&$F15)>0),"","GEÇERSİZ GEÇİŞ") | V15: =IF(OR($F15="D8_KAPALI",$F15="D7_ONLE",$I15>0),IF(OR($H15="",$I15=""),"",IF(ABS($I15-$H15)>zincirTolerans,"ZİNCİR KIRIK","OK")),IF($H15>0,IF(OR($G15="",$H15=""),"",IF(ABS($H15-$G15)>zincirTolerans,"ZİNCİR KIRIK","OK")),"OK")) | W15: =IF($A15="","",1)
A16: 8D-00011 | B16: EKP-00001 | C16: SKY-2026-0011 | D16: 46190 | F16: D1_EKIP | G16: 42500 | H16: 40100 | J16: 0.15 | L16: 48875 | M16: Malzeme | N16: A | O16: Problem notu 11 | P16: =IF($D16="","",raporTarihi-$D16) | Q16: =IF($P16="","",IF($P16<=sdf_kovaEsik1,"0-30",IF($P16<=sdf_kovaEsik2,"31-60",IF($P16<=sdf_kovaEsik3,"61-90","90+")))) | R16: =IF($A16="","",IF($H16>0,$H16,$G16)) | S16: =IF($F16="D8_KAPALI","KAPANAN",IF($F16="IPTAL","IPTAL","ACIK")) | T16: =IF($B16="","YETİM",IF(COUNTIF(tblEkip[EkipId],$B16)=0,"YETİM","")) | U16: =IF(OR($E16&"|"&$F16="",COUNTIF(ListeIzinliGecis,$E16&"|"&$F16)>0),"","GEÇERSİZ GEÇİŞ") | V16: =IF(OR($F16="D8_KAPALI",$F16="D7_ONLE",$I16>0),IF(OR($H16="",$I16=""),"",IF(ABS($I16-$H16)>zincirTolerans,"ZİNCİR KIRIK","OK")),IF($H16>0,IF(OR($G16="",$H16=""),"",IF(ABS($H16-$G16)>zincirTolerans,"ZİNCİR KIRIK","OK")),"OK")) | W16: =IF($A16="","",1)
A17: 8D-00012 | B17: EKP-00002 | C17: SKY-2026-0012 | D17: 46185 | E17: D1_EKIP | F17: D2_PROBLEM | G17: 45000 | H17: 67000 | J17: 0.1 | L17: 49500 | M17: Makine | N17: B | O17: Problem notu 12 | P17: =IF($D17="","",raporTarihi-$D17) | Q17: =IF($P17="","",IF($P17<=sdf_kovaEsik1,"0-30",IF($P17<=sdf_kovaEsik2,"31-60",IF($P17<=sdf_kovaEsik3,"61-90","90+")))) | R17: =IF($A17="","",IF($H17>0,$H17,$G17)) | S17: =IF($F17="D8_KAPALI","KAPANAN",IF($F17="IPTAL","IPTAL","ACIK")) | T17: =IF($B17="","YETİM",IF(COUNTIF(tblEkip[EkipId],$B17)=0,"YETİM","")) | U17: =IF(OR($E17&"|"&$F17="",COUNTIF(ListeIzinliGecis,$E17&"|"&$F17)>0),"","GEÇERSİZ GEÇİŞ") | V17: =IF(OR($F17="D8_KAPALI",$F17="D7_ONLE",$I17>0),IF(OR($H17="",$I17=""),"",IF(ABS($I17-$H17)>zincirTolerans,"ZİNCİR KIRIK","OK")),IF($H17>0,IF(OR($G17="",$H17=""),"",IF(ABS($H17-$G17)>zincirTolerans,"ZİNCİR KIRIK","OK")),"OK")) | W17: =IF($A17="","",1)
A18: 8D-00013 | B18: EKP-00003 | C18: SKY-2026-0013 | D18: 46180 | E18: D2_PROBLEM | F18: D3_MUHAFAZA | G18: 47500 | H18: 46700 | J18: 0.15 | L18: 54625 | M18: Insan | N18: A | O18: Problem notu 13 | P18: =IF($D18="","",raporTarihi-$D18) | Q18: =IF($P18="","",IF($P18<=sdf_kovaEsik1,"0-30",IF($P18<=sdf_kovaEsik2,"31-60",IF($P18<=sdf_kovaEsik3,"61-90","90+")))) | R18: =IF($A18="","",IF($H18>0,$H18,$G18)) | S18: =IF($F18="D8_KAPALI","KAPANAN",IF($F18="IPTAL","IPTAL","ACIK")) | T18: =IF($B18="","YETİM",IF(COUNTIF(tblEkip[EkipId],$B18)=0,"YETİM","")) | U18: =IF(OR($E18&"|"&$F18="",COUNTIF(ListeIzinliGecis,$E18&"|"&$F18)>0),"","GEÇERSİZ GEÇİŞ") | V18: =IF(OR($F18="D8_KAPALI",$F18="D7_ONLE",$I18>0),IF(OR($H18="",$I18=""),"",IF(ABS($I18-$H18)>zincirTolerans,"ZİNCİR KIRIK","OK")),IF($H18>0,IF(OR($G18="",$H18=""),"",IF(ABS($H18-$G18)>zincirTolerans,"ZİNCİR KIRIK","OK")),"OK")) | W18: =IF($A18="","",1)
A19: 8D-00014 | B19: EKP-00004 | C19: SKY-2026-0014 | D19: 46175 | E19: D3_MUHAFAZA | F19: D4_KOK | G19: 50000 | H19: 48400 | J19: 0.15 | L19: 57500 | M19: Ortam | N19: B | O19: Problem notu 14 | P19: =IF($D19="","",raporTarihi-$D19) | Q19: =IF($P19="","",IF($P19<=sdf_kovaEsik1,"0-30",IF($P19<=sdf_kovaEsik2,"31-60",IF($P19<=sdf_kovaEsik3,"61-90","90+")))) | R19: =IF($A19="","",IF($H19>0,$H19,$G19)) | S19: =IF($F19="D8_KAPALI","KAPANAN",IF($F19="IPTAL","IPTAL","ACIK")) | T19: =IF($B19="","YETİM",IF(COUNTIF(tblEkip[EkipId],$B19)=0,"YETİM","")) | U19: =IF(OR($E19&"|"&$F19="",COUNTIF(ListeIzinliGecis,$E19&"|"&$F19)>0),"","GEÇERSİZ GEÇİŞ") | V19: =IF(OR($F19="D8_KAPALI",$F19="D7_ONLE",$I19>0),IF(OR($H19="",$I19=""),"",IF(ABS($I19-$H19)>zincirTolerans,"ZİNCİR KIRIK","OK")),IF($H19>0,IF(OR($G19="",$H19=""),"",IF(ABS($H19-$G19)>zincirTolerans,"ZİNCİR KIRIK","OK")),"OK")) | W19: =IF($A19="","",1)
A20: 8D-00015 | B20: EKP-00005 | C20: SKY-2026-0015 | D20: 46170 | E20: D4_KOK | F20: D5_DF | G20: 52500 | H20: 50100 | J20: 0.1 | L20: 57750 | M20: Yontem | N20: A | O20: Problem notu 15 | P20: =IF($D20="","",raporTarihi-$D20) | Q20: =IF($P20="","",IF($P20<=sdf_kovaEsik1,"0-30",IF($P20<=sdf_kovaEsik2,"31-60",IF($P20<=sdf_kovaEsik3,"61-90","90+")))) | R20: =IF($A20="","",IF($H20>0,$H20,$G20)) | S20: =IF($F20="D8_KAPALI","KAPANAN",IF($F20="IPTAL","IPTAL","ACIK")) | T20: =IF($B20="","YETİM",IF(COUNTIF(tblEkip[EkipId],$B20)=0,"YETİM","")) | U20: =IF(OR($E20&"|"&$F20="",COUNTIF(ListeIzinliGecis,$E20&"|"&$F20)>0),"","GEÇERSİZ GEÇİŞ") | V20: =IF(OR($F20="D8_KAPALI",$F20="D7_ONLE",$I20>0),IF(OR($H20="",$I20=""),"",IF(ABS($I20-$H20)>zincirTolerans,"ZİNCİR KIRIK","OK")),IF($H20>0,IF(OR($G20="",$H20=""),"",IF(ABS($H20-$G20)>zincirTolerans,"ZİNCİR KIRIK","OK")),"OK")) | W20: =IF($A20="","",1)
A21: 8D-00016 | B21: EKP-00006 | C21: SKY-2026-0016 | D21: 46165 | E21: D5_DF | F21: D6_UYGULA | G21: 55000 | H21: 55000 | J21: 0.15 | L21: 63250 | M21: Malzeme | N21: B | O21: Problem notu 16 | P21: =IF($D21="","",raporTarihi-$D21) | Q21: =IF($P21="","",IF($P21<=sdf_kovaEsik1,"0-30",IF($P21<=sdf_kovaEsik2,"31-60",IF($P21<=sdf_kovaEsik3,"61-90","90+")))) | R21: =IF($A21="","",IF($H21>0,$H21,$G21)) | S21: =IF($F21="D8_KAPALI","KAPANAN",IF($F21="IPTAL","IPTAL","ACIK")) | T21: =IF($B21="","YETİM",IF(COUNTIF(tblEkip[EkipId],$B21)=0,"YETİM","")) | U21: =IF(OR($E21&"|"&$F21="",COUNTIF(ListeIzinliGecis,$E21&"|"&$F21)>0),"","GEÇERSİZ GEÇİŞ") | V21: =IF(OR($F21="D8_KAPALI",$F21="D7_ONLE",$I21>0),IF(OR($H21="",$I21=""),"",IF(ABS($I21-$H21)>zincirTolerans,"ZİNCİR KIRIK","OK")),IF($H21>0,IF(OR($G21="",$H21=""),"",IF(ABS($H21-$G21)>zincirTolerans,"ZİNCİR KIRIK","OK")),"OK")) | W21: =IF($A21="","",1)
A22: 8D-00017 | B22: EKP-00007 | C22: SKY-2026-0017 | D22: 46160 | E22: D6_UYGULA | F22: D7_ONLE | G22: 57500 | H22: 56700 | I22: 115000 | J22: 0.15 | L22: 66125 | M22: Makine | N22: A | O22: Problem notu 17 | P22: =IF($D22="","",raporTarihi-$D22) | Q22: =IF($P22="","",IF($P22<=sdf_kovaEsik1,"0-30",IF($P22<=sdf_kovaEsik2,"31-60",IF($P22<=sdf_kovaEsik3,"61-90","90+")))) | R22: =IF($A22="","",IF($H22>0,$H22,$G22)) | S22: =IF($F22="D8_KAPALI","KAPANAN",IF($F22="IPTAL","IPTAL","ACIK")) | T22: =IF($B22="","YETİM",IF(COUNTIF(tblEkip[EkipId],$B22)=0,"YETİM","")) | U22: =IF(OR($E22&"|"&$F22="",COUNTIF(ListeIzinliGecis,$E22&"|"&$F22)>0),"","GEÇERSİZ GEÇİŞ") | V22: =IF(OR($F22="D8_KAPALI",$F22="D7_ONLE",$I22>0),IF(OR($H22="",$I22=""),"",IF(ABS($I22-$H22)>zincirTolerans,"ZİNCİR KIRIK","OK")),IF($H22>0,IF(OR($G22="",$H22=""),"",IF(ABS($H22-$G22)>zincirTolerans,"ZİNCİR KIRIK","OK")),"OK")) | W22: =IF($A22="","",1)
A23: 8D-00018 | B23: EKP-00008 | C23: SKY-2026-0018 | D23: 46155 | E23: D1_EKIP | F23: D5_DF | G23: 60000 | H23: 58400 | J23: 0.1 | L23: 66000 | M23: Insan | N23: B | O23: Problem notu 18 | P23: =IF($D23="","",raporTarihi-$D23) | Q23: =IF($P23="","",IF($P23<=sdf_kovaEsik1,"0-30",IF($P23<=sdf_kovaEsik2,"31-60",IF($P23<=sdf_kovaEsik3,"61-90","90+")))) | R23: =IF($A23="","",IF($H23>0,$H23,$G23)) | S23: =IF($F23="D8_KAPALI","KAPANAN",IF($F23="IPTAL","IPTAL","ACIK")) | T23: =IF($B23="","YETİM",IF(COUNTIF(tblEkip[EkipId],$B23)=0,"YETİM","")) | U23: =IF(OR($E23&"|"&$F23="",COUNTIF(ListeIzinliGecis,$E23&"|"&$F23)>0),"","GEÇERSİZ GEÇİŞ") | V23: =IF(OR($F23="D8_KAPALI",$F23="D7_ONLE",$I23>0),IF(OR($H23="",$I23=""),"",IF(ABS($I23-$H23)>zincirTolerans,"ZİNCİR KIRIK","OK")),IF($H23>0,IF(OR($G23="",$H23=""),"",IF(ABS($H23-$G23)>zincirTolerans,"ZİNCİR KIRIK","OK")),"OK")) | W23: =IF($A23="","",1)
A24: 8D-00019 | B24: EKP-00009 | C24: SKY-2026-0019 | D24: 46150 | E24: D5_DF | F24: IPTAL | G24: 62500 | H24: 84500 | J24: 0.15 | L24: 0 | M24: Ortam | N24: A | O24: Problem notu 19 | P24: =IF($D24="","",raporTarihi-$D24) | Q24: =IF($P24="","",IF($P24<=sdf_kovaEsik1,"0-30",IF($P24<=sdf_kovaEsik2,"31-60",IF($P24<=sdf_kovaEsik3,"61-90","90+")))) | R24: =IF($A24="","",IF($H24>0,$H24,$G24)) | S24: =IF($F24="D8_KAPALI","KAPANAN",IF($F24="IPTAL","IPTAL","ACIK")) | T24: =IF($B24="","YETİM",IF(COUNTIF(tblEkip[EkipId],$B24)=0,"YETİM","")) | U24: =IF(OR($E24&"|"&$F24="",COUNTIF(ListeIzinliGecis,$E24&"|"&$F24)>0),"","GEÇERSİZ GEÇİŞ") | V24: =IF(OR($F24="D8_KAPALI",$F24="D7_ONLE",$I24>0),IF(OR($H24="",$I24=""),"",IF(ABS($I24-$H24)>zincirTolerans,"ZİNCİR KIRIK","OK")),IF($H24>0,IF(OR($G24="",$H24=""),"",IF(ABS($H24-$G24)>zincirTolerans,"ZİNCİR KIRIK","OK")),"OK")) | W24: =IF($A24="","",1)
A25: 8D-00020 | B25: EKP-00010 | C25: SKY-2026-0020 | D25: 46145 | E25: D6_UYGULA | F25: D2_PROBLEM | G25: 65000 | H25: 65000 | J25: 0.15 | L25: 74750 | M25: Yontem | N25: B | O25: Problem notu 20 | P25: =IF($D25="","",raporTarihi-$D25) | Q25: =IF($P25="","",IF($P25<=sdf_kovaEsik1,"0-30",IF($P25<=sdf_kovaEsik2,"31-60",IF($P25<=sdf_kovaEsik3,"61-90","90+")))) | R25: =IF($A25="","",IF($H25>0,$H25,$G25)) | S25: =IF($F25="D8_KAPALI","KAPANAN",IF($F25="IPTAL","IPTAL","ACIK")) | T25: =IF($B25="","YETİM",IF(COUNTIF(tblEkip[EkipId],$B25)=0,"YETİM","")) | U25: =IF(OR($E25&"|"&$F25="",COUNTIF(ListeIzinliGecis,$E25&"|"&$F25)>0),"","GEÇERSİZ GEÇİŞ") | V25: =IF(OR($F25="D8_KAPALI",$F25="D7_ONLE",$I25>0),IF(OR($H25="",$I25=""),"",IF(ABS($I25-$H25)>zincirTolerans,"ZİNCİR KIRIK","OK")),IF($H25>0,IF(OR($G25="",$H25=""),"",IF(ABS($H25-$G25)>zincirTolerans,"ZİNCİR KIRIK","OK")),"OK")) | W25: =IF($A25="","",1)
A26: 8D-00021 | B26: EKP-00001 | C26: SKY-2026-0021 | D26: 46140 | F26: D1_EKIP | G26: 67500 | H26: 66700 | J26: 0.1 | L26: 74250 | M26: Malzeme | N26: A | O26: Problem notu 21 | P26: =IF($D26="","",raporTarihi-$D26) | Q26: =IF($P26="","",IF($P26<=sdf_kovaEsik1,"0-30",IF($P26<=sdf_kovaEsik2,"31-60",IF($P26<=sdf_kovaEsik3,"61-90","90+")))) | R26: =IF($A26="","",IF($H26>0,$H26,$G26)) | S26: =IF($F26="D8_KAPALI","KAPANAN",IF($F26="IPTAL","IPTAL","ACIK")) | T26: =IF($B26="","YETİM",IF(COUNTIF(tblEkip[EkipId],$B26)=0,"YETİM","")) | U26: =IF(OR($E26&"|"&$F26="",COUNTIF(ListeIzinliGecis,$E26&"|"&$F26)>0),"","GEÇERSİZ GEÇİŞ") | V26: =IF(OR($F26="D8_KAPALI",$F26="D7_ONLE",$I26>0),IF(OR($H26="",$I26=""),"",IF(ABS($I26-$H26)>zincirTolerans,"ZİNCİR KIRIK","OK")),IF($H26>0,IF(OR($G26="",$H26=""),"",IF(ABS($H26-$G26)>zincirTolerans,"ZİNCİR KIRIK","OK")),"OK")) | W26: =IF($A26="","",1)
A27: 8D-00022 | C27: SKY-2026-0022 | D27: 46135 | E27: D1_EKIP | F27: D2_PROBLEM | G27: 70000 | H27: 68400 | J27: 0.15 | L27: 80500 | M27: Makine | N27: B | O27: Problem notu 22 | P27: =IF($D27="","",raporTarihi-$D27) | Q27: =IF($P27="","",IF($P27<=sdf_kovaEsik1,"0-30",IF($P27<=sdf_kovaEsik2,"31-60",IF($P27<=sdf_kovaEsik3,"61-90","90+")))) | R27: =IF($A27="","",IF($H27>0,$H27,$G27)) | S27: =IF($F27="D8_KAPALI","KAPANAN",IF($F27="IPTAL","IPTAL","ACIK")) | T27: =IF($B27="","YETİM",IF(COUNTIF(tblEkip[EkipId],$B27)=0,"YETİM","")) | U27: =IF(OR($E27&"|"&$F27="",COUNTIF(ListeIzinliGecis,$E27&"|"&$F27)>0),"","GEÇERSİZ GEÇİŞ") | V27: =IF(OR($F27="D8_KAPALI",$F27="D7_ONLE",$I27>0),IF(OR($H27="",$I27=""),"",IF(ABS($I27-$H27)>zincirTolerans,"ZİNCİR KIRIK","OK")),IF($H27>0,IF(OR($G27="",$H27=""),"",IF(ABS($H27-$G27)>zincirTolerans,"ZİNCİR KIRIK","OK")),"OK")) | W27: =IF($A27="","",1)
A28: 8D-00023 | B28: EKP-00003 | C28: SKY-2026-0023 | D28: 46130 | E28: D2_PROBLEM | F28: D3_MUHAFAZA | G28: 72500 | H28: 70100 | J28: 0.15 | L28: 83375 | M28: Insan | N28: A | O28: Problem notu 23 | P28: =IF($D28="","",raporTarihi-$D28) | Q28: =IF($P28="","",IF($P28<=sdf_kovaEsik1,"0-30",IF($P28<=sdf_kovaEsik2,"31-60",IF($P28<=sdf_kovaEsik3,"61-90","90+")))) | R28: =IF($A28="","",IF($H28>0,$H28,$G28)) | S28: =IF($F28="D8_KAPALI","KAPANAN",IF($F28="IPTAL","IPTAL","ACIK")) | T28: =IF($B28="","YETİM",IF(COUNTIF(tblEkip[EkipId],$B28)=0,"YETİM","")) | U28: =IF(OR($E28&"|"&$F28="",COUNTIF(ListeIzinliGecis,$E28&"|"&$F28)>0),"","GEÇERSİZ GEÇİŞ") | V28: =IF(OR($F28="D8_KAPALI",$F28="D7_ONLE",$I28>0),IF(OR($H28="",$I28=""),"",IF(ABS($I28-$H28)>zincirTolerans,"ZİNCİR KIRIK","OK")),IF($H28>0,IF(OR($G28="",$H28=""),"",IF(ABS($H28-$G28)>zincirTolerans,"ZİNCİR KIRIK","OK")),"OK")) | W28: =IF($A28="","",1)
A29: 8D-00024 | B29: EKP-00004 | C29: SKY-2026-0024 | D29: 46245 | E29: D3_MUHAFAZA | F29: D4_KOK | G29: 75000 | H29: 75000 | J29: 0.1 | L29: 82500 | M29: Ortam | N29: B | O29: Problem notu 24 | P29: =IF($D29="","",raporTarihi-$D29) | Q29: =IF($P29="","",IF($P29<=sdf_kovaEsik1,"0-30",IF($P29<=sdf_kovaEsik2,"31-60",IF($P29<=sdf_kovaEsik3,"61-90","90+")))) | R29: =IF($A29="","",IF($H29>0,$H29,$G29)) | S29: =IF($F29="D8_KAPALI","KAPANAN",IF($F29="IPTAL","IPTAL","ACIK")) | T29: =IF($B29="","YETİM",IF(COUNTIF(tblEkip[EkipId],$B29)=0,"YETİM","")) | U29: =IF(OR($E29&"|"&$F29="",COUNTIF(ListeIzinliGecis,$E29&"|"&$F29)>0),"","GEÇERSİZ GEÇİŞ") | V29: =IF(OR($F29="D8_KAPALI",$F29="D7_ONLE",$I29>0),IF(OR($H29="",$I29=""),"",IF(ABS($I29-$H29)>zincirTolerans,"ZİNCİR KIRIK","OK")),IF($H29>0,IF(OR($G29="",$H29=""),"",IF(ABS($H29-$G29)>zincirTolerans,"ZİNCİR KIRIK","OK")),"OK")) | W29: =IF($A29="","",1)
A30: 8D-00025 | B30: EKP-99999 | C30: SKY-2026-0025 | D30: 46240 | E30: D4_KOK | F30: D5_DF | G30: 77500 | H30: 76700 | J30: 0.15 | L30: 89125 | M30: Yontem | N30: A | O30: Problem notu 25 | P30: =IF($D30="","",raporTarihi-$D30) | Q30: =IF($P30="","",IF($P30<=sdf_kovaEsik1,"0-30",IF($P30<=sdf_kovaEsik2,"31-60",IF($P30<=sdf_kovaEsik3,"61-90","90+")))) | R30: =IF($A30="","",IF($H30>0,$H30,$G30)) | S30: =IF($F30="D8_KAPALI","KAPANAN",IF($F30="IPTAL","IPTAL","ACIK")) | T30: =IF($B30="","YETİM",IF(COUNTIF(tblEkip[EkipId],$B30)=0,"YETİM","")) | U30: =IF(OR($E30&"|"&$F30="",COUNTIF(ListeIzinliGecis,$E30&"|"&$F30)>0),"","GEÇERSİZ GEÇİŞ") | V30: =IF(OR($F30="D8_KAPALI",$F30="D7_ONLE",$I30>0),IF(OR($H30="",$I30=""),"",IF(ABS($I30-$H30)>zincirTolerans,"ZİNCİR KIRIK","OK")),IF($H30>0,IF(OR($G30="",$H30=""),"",IF(ABS($H30-$G30)>zincirTolerans,"ZİNCİR KIRIK","OK")),"OK")) | W30: =IF($A30="","",1)
A31: 8D-00026 | B31: EKP-00006 | C31: SKY-2026-0026 | D31: 46235 | E31: D5_DF | F31: D6_UYGULA | G31: 80000 | H31: 78400 | J31: 0.15 | L31: 92000 | M31: Malzeme | N31: B | O31: Problem notu 26 | P31: =IF($D31="","",raporTarihi-$D31) | Q31: =IF($P31="","",IF($P31<=sdf_kovaEsik1,"0-30",IF($P31<=sdf_kovaEsik2,"31-60",IF($P31<=sdf_kovaEsik3,"61-90","90+")))) | R31: =IF($A31="","",IF($H31>0,$H31,$G31)) | S31: =IF($F31="D8_KAPALI","KAPANAN",IF($F31="IPTAL","IPTAL","ACIK")) | T31: =IF($B31="","YETİM",IF(COUNTIF(tblEkip[EkipId],$B31)=0,"YETİM","")) | U31: =IF(OR($E31&"|"&$F31="",COUNTIF(ListeIzinliGecis,$E31&"|"&$F31)>0),"","GEÇERSİZ GEÇİŞ") | V31: =IF(OR($F31="D8_KAPALI",$F31="D7_ONLE",$I31>0),IF(OR($H31="",$I31=""),"",IF(ABS($I31-$H31)>zincirTolerans,"ZİNCİR KIRIK","OK")),IF($H31>0,IF(OR($G31="",$H31=""),"",IF(ABS($H31-$G31)>zincirTolerans,"ZİNCİR KIRIK","OK")),"OK")) | W31: =IF($A31="","",1)
A32: 8D-00027 | B32: EKP-00007 | C32: SKY-2026-0027 | D32: 46230 | E32: D6_UYGULA | F32: D7_ONLE | G32: 82500 | H32: 80100 | I32: 165000 | J32: 0.1 | L32: 90750 | M32: Makine | N32: A | O32: Problem notu 27 | P32: =IF($D32="","",raporTarihi-$D32) | Q32: =IF($P32="","",IF($P32<=sdf_kovaEsik1,"0-30",IF($P32<=sdf_kovaEsik2,"31-60",IF($P32<=sdf_kovaEsik3,"61-90","90+")))) | R32: =IF($A32="","",IF($H32>0,$H32,$G32)) | S32: =IF($F32="D8_KAPALI","KAPANAN",IF($F32="IPTAL","IPTAL","ACIK")) | T32: =IF($B32="","YETİM",IF(COUNTIF(tblEkip[EkipId],$B32)=0,"YETİM","")) | U32: =IF(OR($E32&"|"&$F32="",COUNTIF(ListeIzinliGecis,$E32&"|"&$F32)>0),"","GEÇERSİZ GEÇİŞ") | V32: =IF(OR($F32="D8_KAPALI",$F32="D7_ONLE",$I32>0),IF(OR($H32="",$I32=""),"",IF(ABS($I32-$H32)>zincirTolerans,"ZİNCİR KIRIK","OK")),IF($H32>0,IF(OR($G32="",$H32=""),"",IF(ABS($H32-$G32)>zincirTolerans,"ZİNCİR KIRIK","OK")),"OK")) | W32: =IF($A32="","",1)
A33: 8D-00028 | B33: EKP-00008 | C33: SKY-2026-0028 | D33: 46225 | E33: D7_ONLE | F33: D8_KAPALI | G33: 85000 | H33: 85000 | I33: 170000 | J33: 0.15 | K33: 85000 | L33: 0 | M33: Insan | N33: B | O33: Problem notu 28 | P33: =IF($D33="","",raporTarihi-$D33) | Q33: =IF($P33="","",IF($P33<=sdf_kovaEsik1,"0-30",IF($P33<=sdf_kovaEsik2,"31-60",IF($P33<=sdf_kovaEsik3,"61-90","90+")))) | R33: =IF($A33="","",IF($H33>0,$H33,$G33)) | S33: =IF($F33="D8_KAPALI","KAPANAN",IF($F33="IPTAL","IPTAL","ACIK")) | T33: =IF($B33="","YETİM",IF(COUNTIF(tblEkip[EkipId],$B33)=0,"YETİM","")) | U33: =IF(OR($E33&"|"&$F33="",COUNTIF(ListeIzinliGecis,$E33&"|"&$F33)>0),"","GEÇERSİZ GEÇİŞ") | V33: =IF(OR($F33="D8_KAPALI",$F33="D7_ONLE",$I33>0),IF(OR($H33="",$I33=""),"",IF(ABS($I33-$H33)>zincirTolerans,"ZİNCİR KIRIK","OK")),IF($H33>0,IF(OR($G33="",$H33=""),"",IF(ABS($H33-$G33)>zincirTolerans,"ZİNCİR KIRIK","OK")),"OK")) | W33: =IF($A33="","",1)
A34: 8D-00029 | B34: EKP-00009 | C34: SKY-2026-0029 | D34: 46220 | E34: D5_DF | F34: IPTAL | G34: 87500 | H34: 86700 | J34: 0.15 | L34: 0 | M34: Ortam | N34: A | O34: Problem notu 29 | P34: =IF($D34="","",raporTarihi-$D34) | Q34: =IF($P34="","",IF($P34<=sdf_kovaEsik1,"0-30",IF($P34<=sdf_kovaEsik2,"31-60",IF($P34<=sdf_kovaEsik3,"61-90","90+")))) | R34: =IF($A34="","",IF($H34>0,$H34,$G34)) | S34: =IF($F34="D8_KAPALI","KAPANAN",IF($F34="IPTAL","IPTAL","ACIK")) | T34: =IF($B34="","YETİM",IF(COUNTIF(tblEkip[EkipId],$B34)=0,"YETİM","")) | U34: =IF(OR($E34&"|"&$F34="",COUNTIF(ListeIzinliGecis,$E34&"|"&$F34)>0),"","GEÇERSİZ GEÇİŞ") | V34: =IF(OR($F34="D8_KAPALI",$F34="D7_ONLE",$I34>0),IF(OR($H34="",$I34=""),"",IF(ABS($I34-$H34)>zincirTolerans,"ZİNCİR KIRIK","OK")),IF($H34>0,IF(OR($G34="",$H34=""),"",IF(ABS($H34-$G34)>zincirTolerans,"ZİNCİR KIRIK","OK")),"OK")) | W34: =IF($A34="","",1)
A35: 8D-00030 | B35: EKP-00010 | C35: SKY-2026-0030 | D35: 46215 | E35: D4_KOK | F35: D5_DF | G35: 90000 | H35: 88400 | J35: 0.1 | L35: 99000 | M35: Yontem | N35: B | O35: Problem notu 30 | P35: =IF($D35="","",raporTarihi-$D35) | Q35: =IF($P35="","",IF($P35<=sdf_kovaEsik1,"0-30",IF($P35<=sdf_kovaEsik2,"31-60",IF($P35<=sdf_kovaEsik3,"61-90","90+")))) | R35: =IF($A35="","",IF($H35>0,$H35,$G35)) | S35: =IF($F35="D8_KAPALI","KAPANAN",IF($F35="IPTAL","IPTAL","ACIK")) | T35: =IF($B35="","YETİM",IF(COUNTIF(tblEkip[EkipId],$B35)=0,"YETİM","")) | U35: =IF(OR($E35&"|"&$F35="",COUNTIF(ListeIzinliGecis,$E35&"|"&$F35)>0),"","GEÇERSİZ GEÇİŞ") | V35: =IF(OR($F35="D8_KAPALI",$F35="D7_ONLE",$I35>0),IF(OR($H35="",$I35=""),"",IF(ABS($I35-$H35)>zincirTolerans,"ZİNCİR KIRIK","OK")),IF($H35>0,IF(OR($G35="",$H35=""),"",IF(ABS($H35-$G35)>zincirTolerans,"ZİNCİR KIRIK","OK")),"OK")) | W35: =IF($A35="","",1)
P36: =IF($D36="","",raporTarihi-$D36) | Q36: =IF($P36="","",IF($P36<=sdf_kovaEsik1,"0-30",IF($P36<=sdf_kovaEsik2,"31-60",IF($P36<=sdf_kovaEsik3,"61-90","90+")))) | R36: =IF($A36="","",IF($H36>0,$H36,$G36)) | S36: =IF($F36="D8_KAPALI","KAPANAN",IF($F36="IPTAL","IPTAL","ACIK")) | T36: =IF($B36="","YETİM",IF(COUNTIF(tblEkip[EkipId],$B36)=0,"YETİM","")) | U36: =IF(OR($E36&"|"&$F36="",COUNTIF(ListeIzinliGecis,$E36&"|"&$F36)>0),"","GEÇERSİZ GEÇİŞ") | V36: =IF(OR($F36="D8_KAPALI",$F36="D7_ONLE",$I36>0),IF(OR($H36="",$I36=""),"",IF(ABS($I36-$H36)>zincirTolerans,"ZİNCİR KIRIK","OK")),IF($H36>0,IF(OR($G36="",$H36=""),"",IF(ABS($H36-$G36)>zincirTolerans,"ZİNCİR KIRIK","OK")),"OK")) | W36: =IF($A36="","",1)
P37: =IF($D37="","",raporTarihi-$D37) | Q37: =IF($P37="","",IF($P37<=sdf_kovaEsik1,"0-30",IF($P37<=sdf_kovaEsik2,"31-60",IF($P37<=sdf_kovaEsik3,"61-90","90+")))) | R37: =IF($A37="","",IF($H37>0,$H37,$G37)) | S37: =IF($F37="D8_KAPALI","KAPANAN",IF($F37="IPTAL","IPTAL","ACIK")) | T37: =IF($B37="","YETİM",IF(COUNTIF(tblEkip[EkipId],$B37)=0,"YETİM","")) | U37: =IF(OR($E37&"|"&$F37="",COUNTIF(ListeIzinliGecis,$E37&"|"&$F37)>0),"","GEÇERSİZ GEÇİŞ") | V37: =IF(OR($F37="D8_KAPALI",$F37="D7_ONLE",$I37>0),IF(OR($H37="",$I37=""),"",IF(ABS($I37-$H37)>zincirTolerans,"ZİNCİR KIRIK","OK")),IF($H37>0,IF(OR($G37="",$H37=""),"",IF(ABS($H37-$G37)>zincirTolerans,"ZİNCİR KIRIK","OK")),"OK")) | W37: =IF($A37="","",1)
P38: =IF($D38="","",raporTarihi-$D38) | Q38: =IF($P38="","",IF($P38<=sdf_kovaEsik1,"0-30",IF($P38<=sdf_kovaEsik2,"31-60",IF($P38<=sdf_kovaEsik3,"61-90","90+")))) | R38: =IF($A38="","",IF($H38>0,$H38,$G38)) | S38: =IF($F38="D8_KAPALI","KAPANAN",IF($F38="IPTAL","IPTAL","ACIK")) | T38: =IF($B38="","YETİM",IF(COUNTIF(tblEkip[EkipId],$B38)=0,"YETİM","")) | U38: =IF(OR($E38&"|"&$F38="",COUNTIF(ListeIzinliGecis,$E38&"|"&$F38)>0),"","GEÇERSİZ GEÇİŞ") | V38: =IF(OR($F38="D8_KAPALI",$F38="D7_ONLE",$I38>0),IF(OR($H38="",$I38=""),"",IF(ABS($I38-$H38)>zincirTolerans,"ZİNCİR KIRIK","OK")),IF($H38>0,IF(OR($G38="",$H38=""),"",IF(ABS($H38-$G38)>zincirTolerans,"ZİNCİR KIRIK","OK")),"OK")) | W38: =IF($A38="","",1)
P39: =IF($D39="","",raporTarihi-$D39) | Q39: =IF($P39="","",IF($P39<=sdf_kovaEsik1,"0-30",IF($P39<=sdf_kovaEsik2,"31-60",IF($P39<=sdf_kovaEsik3,"61-90","90+")))) | R39: =IF($A39="","",IF($H39>0,$H39,$G39)) | S39: =IF($F39="D8_KAPALI","KAPANAN",IF($F39="IPTAL","IPTAL","ACIK")) | T39: =IF($B39="","YETİM",IF(COUNTIF(tblEkip[EkipId],$B39)=0,"YETİM","")) | U39: =IF(OR($E39&"|"&$F39="",COUNTIF(ListeIzinliGecis,$E39&"|"&$F39)>0),"","GEÇERSİZ GEÇİŞ") | V39: =IF(OR($F39="D8_KAPALI",$F39="D7_ONLE",$I39>0),IF(OR($H39="",$I39=""),"",IF(ABS($I39-$H39)>zincirTolerans,"ZİNCİR KIRIK","OK")),IF($H39>0,IF(OR($G39="",$H39=""),"",IF(ABS($H39-$G39)>zincirTolerans,"ZİNCİR KIRIK","OK")),"OK")) | W39: =IF($A39="","",1)
P40: =IF($D40="","",raporTarihi-$D40) | Q40: =IF($P40="","",IF($P40<=sdf_kovaEsik1,"0-30",IF($P40<=sdf_kovaEsik2,"31-60",IF($P40<=sdf_kovaEsik3,"61-90","90+")))) | R40: =IF($A40="","",IF($H40>0,$H40,$G40)) | S40: =IF($F40="D8_KAPALI","KAPANAN",IF($F40="IPTAL","IPTAL","ACIK")) | T40: =IF($B40="","YETİM",IF(COUNTIF(tblEkip[EkipId],$B40)=0,"YETİM","")) | U40: =IF(OR($E40&"|"&$F40="",COUNTIF(ListeIzinliGecis,$E40&"|"&$F40)>0),"","GEÇERSİZ GEÇİŞ") | V40: =IF(OR($F40="D8_KAPALI",$F40="D7_ONLE",$I40>0),IF(OR($H40="",$I40=""),"",IF(ABS($I40-$H40)>zincirTolerans,"ZİNCİR KIRIK","OK")),IF($H40>0,IF(OR($G40="",$H40=""),"",IF(ABS($H40-$G40)>zincirTolerans,"ZİNCİR KIRIK","OK")),"OK")) | W40: =IF($A40="","",1)
P41: =IF($D41="","",raporTarihi-$D41) | Q41: =IF($P41="","",IF($P41<=sdf_kovaEsik1,"0-30",IF($P41<=sdf_kovaEsik2,"31-60",IF($P41<=sdf_kovaEsik3,"61-90","90+")))) | R41: =IF($A41="","",IF($H41>0,$H41,$G41)) | S41: =IF($F41="D8_KAPALI","KAPANAN",IF($F41="IPTAL","IPTAL","ACIK")) | T41: =IF($B41="","YETİM",IF(COUNTIF(tblEkip[EkipId],$B41)=0,"YETİM","")) | U41: =IF(OR($E41&"|"&$F41="",COUNTIF(ListeIzinliGecis,$E41&"|"&$F41)>0),"","GEÇERSİZ GEÇİŞ") | V41: =IF(OR($F41="D8_KAPALI",$F41="D7_ONLE",$I41>0),IF(OR($H41="",$I41=""),"",IF(ABS($I41-$H41)>zincirTolerans,"ZİNCİR KIRIK","OK")),IF($H41>0,IF(OR($G41="",$H41=""),"",IF(ABS($H41-$G41)>zincirTolerans,"ZİNCİR KIRIK","OK")),"OK")) | W41: =IF($A41="","",1)
P42: =IF($D42="","",raporTarihi-$D42) | Q42: =IF($P42="","",IF($P42<=sdf_kovaEsik1,"0-30",IF($P42<=sdf_kovaEsik2,"31-60",IF($P42<=sdf_kovaEsik3,"61-90","90+")))) | R42: =IF($A42="","",IF($H42>0,$H42,$G42)) | S42: =IF($F42="D8_KAPALI","KAPANAN",IF($F42="IPTAL","IPTAL","ACIK")) | T42: =IF($B42="","YETİM",IF(COUNTIF(tblEkip[EkipId],$B42)=0,"YETİM","")) | U42: =IF(OR($E42&"|"&$F42="",COUNTIF(ListeIzinliGecis,$E42&"|"&$F42)>0),"","GEÇERSİZ GEÇİŞ") | V42: =IF(OR($F42="D8_KAPALI",$F42="D7_ONLE",$I42>0),IF(OR($H42="",$I42=""),"",IF(ABS($I42-$H42)>zincirTolerans,"ZİNCİR KIRIK","OK")),IF($H42>0,IF(OR($G42="",$H42=""),"",IF(ABS($H42-$G42)>zincirTolerans,"ZİNCİR KIRIK","OK")),"OK")) | W42: =IF($A42="","",1)
...

Sheet KUYRUKLAR
A1: KUYRUKLAR — 8D / Düzeltici Faaliyet Dosya Sistemi
A3: Durum bazlı canlı kuyruk — kapalı/iptal kayıtlar düşer
A5: Kuyruk | B5: Adet | C5: Tutar
A6: Kuyruk D1 Ekip | B6: =COUNTIFS(tblAkis[Durum],"D1_EKIP",tblAkis[Tutar],">0") | C6: =SUMIFS(tblAkis[Tutar],tblAkis[Durum],"D1_EKIP")
A7: Kuyruk D2 Problem | B7: =COUNTIFS(tblAkis[Durum],"D2_PROBLEM",tblAkis[Tutar],">0") | C7: =SUMIFS(tblAkis[Tutar],tblAkis[Durum],"D2_PROBLEM")
A8: Kuyruk D3 Muhafaza | B8: =COUNTIFS(tblAkis[Durum],"D3_MUHAFAZA",tblAkis[Tutar],">0") | C8: =SUMIFS(tblAkis[Tutar],tblAkis[Durum],"D3_MUHAFAZA")
A9: Kuyruk D4 Kök | B9: =COUNTIFS(tblAkis[Durum],"D4_KOK",tblAkis[Tutar],">0") | C9: =SUMIFS(tblAkis[Tutar],tblAkis[Durum],"D4_KOK")
A10: Kuyruk D5 DF | B10: =COUNTIFS(tblAkis[Durum],"D5_DF",tblAkis[Tutar],">0") | C10: =SUMIFS(tblAkis[Tutar],tblAkis[Durum],"D5_DF")
A11: Geciken (açık, yaş>eşik) | B11: =COUNTIFS(tblAkis[GecikmeGun],">"&sdf_esikGecikmeGun,tblAkis[Durum],"<>D8_KAPALI",tblAkis[Durum],"<>IPTAL",tblAkis[Tutar],">0") | C11: =SUMIFS(tblAkis[Tutar],tblAkis[GecikmeGun],">"&sdf_esikGecikmeGun,tblAkis[Durum],"<>D8_KAPALI",tblAkis[Durum],"<>IPTAL")
A12: Kuyruk D7 Önleme | B12: =COUNTIFS(tblAkis[Durum],"D7_ONLE",tblAkis[Tutar],">0") | C12: =SUMIFS(tblAkis[Tutar],tblAkis[Durum],"D7_ONLE")
A13: D8 Kapalı / İptal — kuyruktan düşer
A14: D8_KAPALI | B14: =COUNTIF(tblAkis[Durum],"D8_KAPALI") | C14: =SUMIF(tblAkis[Durum],"D8_KAPALI",tblAkis[DfDogrulamaTl])
A15: İptal | B15: =COUNTIF(tblAkis[Durum],"IPTAL") | C15: =SUMIF(tblAkis[Durum],"IPTAL",tblAkis[Tutar])
A17: Kuyruk Özeti | B17: =sdf_kuyrukOzeti
A19: Yaş Kova Dağılımı
A20: 0-30 | B20: =COUNTIF(tblAkis[YasKova],"0-30") | C20: =SUMIF(tblAkis[YasKova],"0-30",tblAkis[Tutar])
A21: 31-60 | B21: =COUNTIF(tblAkis[YasKova],"31-60") | C21: =SUMIF(tblAkis[YasKova],"31-60",tblAkis[Tutar])
A22: 61-90 | B22: =COUNTIF(tblAkis[YasKova],"61-90") | C22: =SUMIF(tblAkis[YasKova],"61-90",tblAkis[Tutar])
A23: 90+ | B23: =COUNTIF(tblAkis[YasKova],"90+") | C23: =SUMIF(tblAkis[YasKova],"90+",tblAkis[Tutar])

Sheet HESAP
A1: HESAP — 8D / Düzeltici Faaliyet Dosya Sistemi
