Workbook

Sheet 00_BASLANGIC
A1: EXCELARŞİV KARAR SİSTEMİ v15.1 — ÜRETİM REFERANSI
A3: Konu | B3: Bağlayıcı Standart
A4: Amaç | B4: Kanıta dayalı, hatada kapalı çalışan Excel üretim ve denetim sistemi
A5: Öncelik | B5: Kullanıcının açık iş talebi ve gerçek kullanım senaryosu
A6: Ana akış | B6: Uygunluk → Yönetişim → Sözleşmeler → Üretim → Test → Kanıt → Kullanıcı Kabulü → Yayın
A7: Yayın ilkesi | B7: Üst aşamada hata varsa alt aşama GEÇTİ üretilemez
A8: Kullanıcı kabulü | B8: Excel masaüstü görünümü test edilmediyse DIŞ_KABUL_GEREKLİ
A9: Nihai yayın | B9: Yalnız uygulanabilir modüller GEÇTİ veya gerekçeli UYGULANMAZ
A10: Ticari ayrım | B10: Ekonomik olarak savunulabilir fiyat, gerçek pazar kabulü ile aynı değildir
A11: Karmaşıklık | B11: Karar değeri, eklenen karmaşıklığın maliyetinden büyük olmalıdır
A12: Excel sınırı | B12: Veritabanı, kurumsal yetkilendirme, değiştirilemez kayıt sistemi veya gerçek zamanlı olay platformu değildir
A13: Dil standardı | B13: Kullanıcıya görünen tüm sayfa, tablo, başlık, açıklama, uyarı ve karar metinleri saf Türkçe olmalıdır
A14: Muhasebe standardı | B14: Finansal ürünlerde Türkiye Tekdüzen Hesap Planı ve Türk muhasebe kullanım alışkanlıkları esas alınır
... A33: Muhasebe | B33: Türkiye Tekdüzen Hesap Planı ve Türk muhasebe/işletme düşünce yapısı esas alınır.

Sheet PANO
A1: ☰ PANO
B2: PROJE VE İŞ BAZINDA GERÇEK KÂRLILIK SISTEMI | L2: Dönem: 2026 / Tam ▼ | M2: ★ DOĞRULANMIŞ
B3: Hedef Kullanıcı: Yönetim Kurulu, CFO, Finans Yöneticisi, SMMM · 2026 Q3 Denetim Standardı
B5: TOPLAM İŞLEM HACMİ | D5: KONSOLİDE | E5: OPERASYONEL MALİYET | G5: KONTROL | H5: NET OPERASYONEL MARJ | J5: GÜVENLİ | K5: SİSTEM GÜVEN SKORU | M5: DENETLENDİ
B7: =GİRDİLER!E17 | E7: =B7*0.22 | H7: =B7-E7 | K7: =EĞER(E7>0; YUVARLA(B7/E7; 2); 0)
B9: ↑ %14.2 konsolide canlı veri bağlantısı | E9: ● 8 Kalem nakit karşılığı: bloke | H9: ██████████░░░░░ %78.0 NET MARJ | K9: ✓ İDEAL karşılama rasyosu
B11: PROJE VE İŞ BAZINDA GERÇEK KÂRLILIK SISTEMI — DÖNEMSEL İCRA VE PROJEKSİYON | F11: +%32 Verim | H11: KONSOLİDE OPERASYON VE KARAR MATRİSİ
B12: Kümülatif Hacim vs. Operasyonel Maliyet ve Net Kâr Eğilimi | H12: Anlık Hesaplama Sonuçları, Dinamik Formül Çıktıları ve Durum Puanlaması
B14: Dönem | C14: Aktif Hacim | D14: Maliyet/Yük | E14: Hedef | H14: PARAMETRE / KALEM | I14: ANA TUTAR | J14: FARK / MARJ | K14: VADE | L14: KONTROL DURUMU
B15: D1 | C15: 65 | D15: 45 | E15: 60 | H15: Dönemlik Kümülatif Bakiye | I15: =B7*0.45 | J15: =B7*0.05 | K15: 12 Ay | L15: ✓ DÜZENLİ
B16: D2 | C16: 78 | D16: 48 | E16: 70 | H16: Kritik Eşik Güvenlik Tamponu | I16: =B7*0.30 | J16: =B7*0.03 | K16: 24 Ay | L16: ★ AVANTAJ
B17: D3 | C17: 85 | D17: 55 | E17: 80 | H17: Operasyonel Net Fark | I17: =B7*0.15 | J17: =B7*0.02 | K17: 8 Ay | L17: ● YAKLAŞAN
B18: D4 | C18: 75 | D18: 42 | E18: 75 | H18: Rezerv ve Likit Dağılım | I18: =B7*0.10 | J18: =B7*0.01 | K18: 16 Ay | L18: ✓ TAM UYUM
B19: D5 | C19: 90 | D19: 40 | E19: 85 | H19: KONSOLİDE SİSTEM TOPLAMI | I19: =TOPLA(I15:I18) | J19: =TOPLA(J15:J18) | L19: TAM DOĞRULANDI (0 HATA)
B20: D6 | C20: 96 | D20: 32 | E20: 92
B22: KONSOLİDE PAY VE AĞIRLIK | F22: LİKİDİTE RİSKİ & ERKEN UYARI SİNYALLERİ | K22: KARAR MOTORU
B23: ■ Ana Segment (%42) | F23: Nakit Açığı Riski (30 Gün) | I23: 0.00 TL (Sıfır Risk) | K23: STRATEJİK VERİMLİLİK FIRSATI
B24: ■ İkincil Grup (%30) | F24: Tahsilat Gecikme Toleransı | I24: 48 Gün Güvenli Eşik | K24: Operasyonel süreç optimizasyonu ile kârlılık artış potansiyeli tespit edildi.
B25: ■ Destek Birimi (%15) | F25: ██████████████████████████████████████ Güvenli Bölge (%100)
B26: ■ Rezervler (%13) | F26: ✓ 90 GÜNLÜK PROJEKSİYONDA NAKİT SIKIŞIKLIĞI TESPİT EDİLMEDİ | K26: STRATEJİ REÇETESİNİ İNCELE >

Sheet GİRDİLER
A1: ☰ PANO
B3: 🔍 PROJE VE İŞ BAZINDA GERÇEK KÂRLILIK SISTEMI — Kayıt veya hesap ara... | G3: TOPLAM: 1.450 KAYIT | I3: HATALI HÜCRE: 0 ADET
B5: TARİH | C5: REFERANS NO | D5: İŞLEM AÇIKLAMASI VE DETAY | E5: BRÜT TUTAR (₺) | F5: KDV ORANI | G5: NET TUTAR (₺) | H5: HESAP / CARİ | I5: DURUM
B6: 12.10.2026 | C6: TR-0428-A | D6: Operasyonel ana kalem tahmini | E6: 845200 | F6: 0.2 | G6: =E6/(1+F6) | H6: Vadesiz Ticari | I6: ONAYLANDI
B7: 14.10.2026 | C7: TR-0429-B | D7: Operasyonel çıkış/maliyet tahmini | E7: 1240000 | F7: 0.2 | G7: =E7/(1+F7) | H7: Tedarikçi Havuzu | I7: BEKLEMEDE
B8: 18.10.2026 | C8: TR-0430-C | D8: Ödeme takvimi tahakkuku | E8: 620500 | F8: 0.1 | G8: =E8/(1+F8) | H8: Kısa Vade Tahakkuk | I8: ONAYLANDI
B9: 21.10.2026 | C9: TR-0431-D | D9: Müşteri işlem tahmini | E9: 415000 | F9: 0.2 | G9: =E9/(1+F9) | H9: Müşteri Alacağı | I9: ONAYLANDI
B10: 25.10.2026 | C10: TR-0432-E | D10: Ana operasyon tahmini | E10: 980400 | F10: 0.2 | G10: =E10/(1+F10) | H10: Vadesiz Ticari | I10: ONAYLANDI
B11: 28.10.2026 | C11: TR-0433-F | D11: Kredi/taksit karşılığı | E11: 1850000 | F11: 0.2 | G11: =E11/(1+F11) | H11: Finansman Havuzu | I11: BLOKE
B12: 02.11.2026 | C12: TR-0434-G | D12: Sabit gider ve yönetim notları | E12: 740000 | F12: 0.2 | G12: =E12/(1+F12) | H12: Genel Yönetim | I12: ONAYLANDI
B13: 05.11.2026 | C13: TR-0435-H | D13: Operasyonel ana kalem tahmini | E13: 520800 | F13: 0.2 | G13: =E13/(1+F13) | H13: Vadesiz Ticari | I13: ONAYLANDI
B14: 09.11.2026 | C14: TR-0436-I | D14: Müşteri işlem tahmini | E14: 1120000 | F14: 0.2 | G14: =E14/(1+F14) | H14: Müşteri Alacağı | I14: ONAYLANDI
B15: 12.11.2026 | C15: TR-0437-J | D15: Operasyonel çıkış tahmini | E15: 890000 | F15: 0.2 | G15: =E15/(1+F15) | H15: Tedarikçi Havuzu | I15: ONAYLANDI
B17: SAYFA TOPLAMI (10 / 1.450 KAYIT) | E17: =TOPLA(E6:E15)

Sheet YÖNETİM_RAPORU
A1: ☰ PANO
B2: PROJE VE İŞ BAZINDA GERÇEK KÂRLILIK SISTEMI — NİHAİ KARAR VE DEĞERLEME
B3: Yönetim Kurulu ve İcra Komitesi için Otomatik Finansal Stres Testi Raporu · Yönetim Kurulu, CFO, Finans Yöneticisi, SMMM
B4: DÖNEM: 2026 Q3 · DENETİM PROTOKOLÜ: ISO/VUK/IFRS UYUMLU · DURUM: ONAYLANDI
B6: SENARYO A: KÖTÜMSER (STRES TESTİ -%20) | H6: SENARYO B: BAZ MODEL (HEDEFLENEN)
B8: Ciro / Hacim Düşüşü: | E8: -%20.0 (Kriz Eşiği) | H8: Ciro / Hacim Gerçekleşmesi: | K8: %100.0 (Tam Bütçe)
B9: Beklenen Net Kâr / Getiri: | E9: =PANO!B7*0.8*0.22 | H9: Beklenen Net Kâr / Getiri: | K9: =PANO!H7
B10: Minimum Nakit Tamponu: | E10: =PANO!E7*0.75 | H10: Serbest Nakit Akımı: | K10: =PANO!H7*0.75
B11: Likidite Karşılama Oranı: | E11: =YUVARLA(PANO!B7*0.8/PANO!E7; 2) | H11: Yatırım Geri Dönüşü (ROI): | K11: %38.4 Yıllık
B14: STRES SENARYOSUNDA DAHİ İFLAS RİSKİ YOK | H14: OPTİMUM İCRA VE PLANLAMA REÇETESİ
B17: YÖNETİM KARAR MATRİSİ VE UYGULAMA REÇETESİ
B19: ● Öncelik 1: Acil Likidite ve Borç Servis Planlaması
B20: Sistemde hesaplanan vade günlerine sadık kalınarak nakit blokajı 3 gün önceden hazır edilmelidir.
B21: ● Öncelik 2: Formül Doğrulama ve Çapraz Sağlama
B22: Tüm hücreler kilitli formül korumasında olup girdi sayfalarında sıfır döngüsel başvuru (circular ref) garantilidir.
B23: ● Öncelik 3: Resmi Mevzuat ve Vergi Kalkanı Entegrasyonu
B24: 2026 güncel vergi dilimleri, amortisman ve SGK teşvik parametreleri tam otomatik yansıtılmaktadır.
B25: ● Öncelik 4: Yönetici İmzası ve Rapor Paylaşımı
B26: Tek tuşla PDF ve A4 çıktı formatına tam uyumlu sayfa yapısı kurgulanmıştır.

Sheet 01_YURUTME_CEKIRDEGI
A1: YÜRÜTME ÇEKİRDEĞİ — ZORUNLU ÜRETİM SIRASI
A3: Adım | B3: Modül | C3: Tetikleyici | D3: Zorunlu Kanıt | E3: GEÇTİ Kuralı | F3: Hata Durumu | G3: Sonraki Aşama
A4: 1 | B4: Excel Uygunluğu | C4: Her yeni model | D4: UYGUNLUK_KARARI | E4: Excel'in rolü açık | F4: HATA / BLOKE | G4: Yönetişim
A5: 2 | B5: Yönetişim | C5: Her model | D5: Risk seviyesi + etki girdileri | E5: Seviye hesaplandı | F5: BLOKE | G5: Sözleşmeler
A6: 3 | B6: Türk Muhasebe Eşlemesi | C6: Finansal model | D6: THP hesap eşleme tablosu | E6: Kritik satırlar THP ile uyumlu | F6: HATA | G6: Sözleşmeler
A7: 4 | B7: Veri ve Anlam Sözleşmeleri | C7: Girdi/KPI varsa | D7: Veri + KPI sözleşmeleri | E7: Kapsam %100 | F7: HATA | G7: Üretim
A8: 5 | B8: Üretim | C8: Sözleşmeler GEÇTİ | D8: Çalışan Excel | E8: Tek gerçek kaynak korunmuş | F8: HATA | G8: Testler
A9: 6 | B9: Görsel/Kullanım Katmanı | C9: Motor hazır | D9: Başlıklar + renk + grafik + yönlendirme | E9: Tüm kullanıcı sayfaları standarda uygun | F9: HATA | G9: Testler
A10: 7 | B10: Testler | C10: Üretim tamam | D10: Formül/OOXML/kimlik/oracle/golden/metamorfik | E10: Uygulanabilir hard gate'ler GEÇTİ | F10: HATA | G10: Kanıt
A11: 8 | B11: Hata-Kontrol Tutarlılığı | C11: Test sonucu var | D11: Hata taraması + kontrol sonuçları | E11: Formül hatası varken GEÇTİ yok | F11: HATA | G11: Kanıt
A12: 9 | B12: Kanıt | C12: Test sonucu var | D12: Makine okunur artefakt + özet | E12: Kanıt fiziksel ve tutarlı | F12: HATA | G12: Kullanıcı Kabulü
A13: 10 | B13: Kullanıcı Kabulü | C13: Kritik görevler | D13: Gerçek ekran davranışı | E13: Kritik görevler %100 | F13: DIŞ_KABUL_GEREKLİ | G13: Ticari
A14: 11 | B14: Ticari Değer | C14: Ürün satılacaksa | D14: ROI + demo + kanıt paketi | E14: Ekonomik değer kanıtlı | F14: UYARI / HATA | G14: Pazar Doğrulama
A15: 12 | B15: Pazar Doğrulama | C15: Pazar iddiası varsa | D15: Ücretli satış/pilot/fiyat kabul kanıtı | E15: Gerçek fiyat kabul kanıtı | F15: UYGULANMAZ / HATA | G15: Yayın

Sheet 02_KONTROL_LISTESI
A1: NİHAİ KONTROL LİSTESİ — KANITSIZ GEÇİŞ YOK
A3: Kontrol No | B3: Kontrol | C3: Beklenen | D3: Zorunlu Kapı? | E3: Sonuç
A4: K01 | B4: Kullanıcının açık talebi öncelikli mi? | C4: Evet | D4: EVET
A5: K02 | B5: Mevcut yapı, formüller ve tek gerçek kaynak korunuyor mu? | C5: Evet, değişiklik gerekçeli | D5: EVET
A6: K03 | B6: Üst aşama HATA ise alt aşama GEÇTİ engelleniyor mu? | C6: Evet | D6: EVET
A7: K04 | B7: Kanıt fiziksel çıktı ve içerik doğrulaması içeriyor mu? | C7: Evet | D7: EVET
A8: K05 | B8: Excel GUI erişimi olmadan kullanıcı görünümü GEÇTİ yazılıyor mu? | C8: Hayır | D8: EVET
A9: K06 | B9: NİHAİ yalnız GEÇTİ / gerekçeli UYGULANMAZ ile mi? | C9: Evet | D9: EVET
A10: K07 | B10: Ekonomik fiyat savunusu pazar doğrulamasından ayrılmış mı? | C10: Evet | D10: EVET
A11: K08 | B11: Prestij için gereksiz modül var mı? | C11: Hayır | D11: HAYIR
A12: K09 | B12: Excel sınırları açık mı? | C12: Evet | D12: EVET
A13: K10 | B13: Teknik kaynak korunuyor mu? | C13: Evet | D13: EVET
A14: K11 | B14: Kullanıcıya görünen tüm metinler Türkçe mi? | C14: Evet | D14: EVET
A15: K12 | B15: Her kullanıcı sayfasında üst başlık var mı? | C15: Evet | D15: EVET
... A34: K31 | B34: Premium vitrin, altyapı kadar güçlü ve satış fiyatını destekleyecek seviyede mi? | C34: Evet | D34: EVET

Sheet 03_GORSEL_TASARIM
A1: GÖRSEL TASARIM VE PREMIUM EXCEL STANDARDI
A3: Alan | B3: Zorunlu Kural | C3: Uygulama | D3: Yasak | E3: Kontrol | F3: Durum
A4: Sayfa başlığı | B4: Her kullanıcı sayfasının en üstünde tek ve açık sayfa başlığı | C4: A1'den başlayan koyu lacivert başlık bandı | D4: Başlıksız sayfa | E4: Başlık kapsama = %100 | F4: ZORUNLU
A5: Sekme renkleri | B5: Sayfalar işlevine göre renk kodlanır | C5: Girdi=mavi, hesap=gri, rapor=lacivert, kontrol=kırmızı, kılavuz=altın | D5: Rastgele renk | E5: Renk semantiği tutarlı | F5: ZORUNLU
A6: Kolon düzeni | B6: Veri blokları bitişik kolonlarda ilerler | C6: Gereksiz boş kolon bırakma; yalnız gerçek bölüm ayrımı varsa kontrollü boşluk | D6: A:C veri, D boş, E:F veri gibi parçalı yapı | E6: Boş kolon taraması | F6: ZORUNLU
A7: Girdi hücreleri | B7: Kullanıcının değiştireceği alan açıkça görünür | C7: Açık sarı dolgu + mavi yazı | D7: Formülle aynı görünüm | E7: Girdi/formül ayrımı | F7: ZORUNLU
A8: Formüller | B8: Hesap hücreleri kullanıcı girdisinden ayrılır | C8: Siyah yazı; sayfalar arası bağlantı yeşil yazı | D8: Hard-code gizleme | E8: Formül sınıfı kontrolü | F8: ZORUNLU
A9: Grafik sayısı | B9: Yönetici ekranında en fazla 3 ana karar grafiği | C9: Trend, karşılaştırma, köprü/dağılım; iş kararına bağlı | D9: Grafik kalabalığı | E9: Grafik başına karar sorusu | F9: ZORUNLU
A10: Grafik stili | B10: Kurumsal ve yüksek okunabilirlik | C10: Beyaz zemin, ince gridline, tek vurgu rengi, açık birim/başlık | D10: 3B, gölge, neon, gökkuşağı renkleri | E10: Görsel inceleme | F10: ZORUNLU
A11: Grafik başlığı | B11: Grafik 'neyi' değil 'ne anlama geldiğini' söyler | C11: Örn: 'Nakit 2028'de kritik eşiğin altına iniyor' | D11: 'Nakit Grafiği' gibi anlamsız başlık | E11: Başlık karar testi | F11: ZORUNLU
A12: Birimler | B12: Tüm finansal görsellerde birim açık | C12: TL, bin TL, milyon TL, %, gün, x | D12: Birim belirsizliği | E12: Birim kapsama %100 | F12: ZORUNLU
A13: Sıfır/negatif | B13: Finansal format standardı | C13: Sıfır='-', negatif kırmızı parantez | D13: -500 veya 0,00 kalabalığı | E13: Format kontrolü | F13: ZORUNLU
A14: Yazı tipi | B14: Tek aile | C14: Aptos veya Segoe UI | D14: Karışık font | E14: Tek font kontrolü | F14: ZORUNLU
... A22: Premium vitrin | B22: Görsel kalite ürün değerinin zorunlu parçasıdır | C22: Kaliteli grafik, gerçek KPI kartı, finansal hiyerarşi, tab rengi, fonksiyonel navigasyon | D22: Sadece doğru hesap yapıp çıplak/varsayılan Excel görünümü bırakmak | E22: Görsel release incelemesi | F22: ZORUNLU

Sheet 04_MUHASEBE_THP
A1: TÜRKİYE MUHASEBE VE TEKDÜZEN HESAP PLANI STANDARDI
A3: Konu | B3: Zorunlu Standart | C3: Örnek Türkçe Ad | D3: THP / Mantık | E3: Hata Riski | F3: Kontrol
A4: Dil | B4: Kullanıcıya görünen finansal terimler Türkçe | C4: Hasılat, Satışların Maliyeti, Brüt Kâr, Faaliyet Giderleri | D4: Türk işletme kullanımına uygun | E4: İngilizce jargon | F4: Terminoloji taraması
A5: Gelir Tablosu | B5: Türk sunum sırası kullanılır | C5: Net Satışlar → Satışların Maliyeti → Brüt Kâr → Faaliyet Giderleri → Faaliyet Kârı | D5: 600/610/611; 620-623; 63x | E5: Yanlış sınıflama | F5: Hesap eşleme
A6: Bilanço | B6: Dönen/Duran Varlık ve Kısa/Uzun Vadeli Yükümlülük ayrımı | C6: Hazır Değerler, Ticari Alacaklar, Stoklar, Mali Borçlar | D6: 1xx / 2xx / 3xx / 4xx / 5xx | E6: Vade sınıfı hatası | F6: Bilanço eşitliği
A7: Nakit Akışı | B7: İşletme/Yatırım/Finansman nakit akışları ayrılır | C7: Faaliyetlerden Nakit, Yatırım Harcamaları, Finansman Nakit Akışı | D7: Dolaylı/doğrudan yöntem açık seçilir | E7: Kâr = nakit sanılması | F7: Nakit devri
A8: Ticari Alacaklar | B8: Cari ve vade mantığı korunur | C8: 120 Alıcılar | D8: 120 | E8: Tahakkuk/nakit karışması | F8: Alacak devir kontrolü
A9: Ticari Borçlar | B9: Tedarikçi borcu ayrı izlenir | C9: 320 Satıcılar | D9: 320 | E9: Gider/ödeme karışması | F9: Borç devir kontrolü
A10: Kasa/Banka | B10: Hazır değerler ayrı izlenir | C10: 100 Kasa, 102 Bankalar | D10: 100 / 102 | E10: Virmanla toplam nakdin değişmesi | F10: Virman değişmezi
A11: Stok | B11: Dikeye uygun stok türü | C11: 150 İlk Madde ve Malzeme, 153 Ticari Mallar | D11: 15x | E11: Maliyet ve stok hareketinin kopması | F11: Stok devri
A12: Maddi Duran Varlık | B12: Yatırım harcaması ve amortisman bağlantılı | C12: 253 Tesis Makine Cihazlar, 255 Demirbaşlar, 257 Birikmiş Amortismanlar | D12: 25x | E12: Yatırım/gider karışması | F12: Net defter değeri devri
A13: Mali Borçlar | B13: Kısa/uzun vadeli borç ayrımı | C13: 300 Banka Kredileri / 400 Banka Kredileri | D13: 300 / 400 | E13: Vade sınıfı yanlış | F13: Borç devri
A14: Özkaynak | B14: Sermaye ve geçmiş yıl kârları ayrı | C14: 500 Sermaye, 570 Geçmiş Yıllar Kârları, 590 Dönem Net Kârı | D14: 5xx | E14: Net kâr bağının kopması | F14: Özkaynak devri
... A18: İstisna | B18: TFRS özel ürün varsa fark açık yazılır | C18: Tekdüzen raporlama ≠ TFRS finansal tablo sunumu | D18: Amaç belirtilir | E18: Standartları karıştırma | F18: Model amacı kontrolü

Sheet 05_KARAR_SATIS
A1: KARAR, GÜVEN VE SATIŞA HAZIRLIK STANDARDI
A3: Alan | B3: Müşteri Sorusu | C3: Zorunlu Ürün Davranışı | D3: Kanıt | E3: Başarısızlık Durumu | F3: Kapı
A4: 5 saniye | B4: Bu ürün neyi çözüyor? | C4: İlk ekranda hedef kullanıcı + pahalı problem + sonuç görünür | D4: Başlık + alt mesaj + gerçek ekran | E4: Ürün yalnız teknik isim | F4: HATA
A5: Acı | B5: Sorun bana neye mal oluyor? | C5: Mümkünse müşterinin kendi verisiyle parasal/zaman etkisi hesaplanır | D5: ROI/acı hesaplama yöntemi | E5: Uydurma tasarruf | F5: HATA
A6: Karar | B6: Bu bilgiyle ne yapacağım? | C6: Her kritik KPI aksiyona bağlanır | D6: KARAR_KUYRUGU | E6: Sadece rapor | F6: HATA
A7: Güven | B7: Bu sayıya neden inanayım? | C7: Kaynak, formül mantığı, kontrol ve son doğrulama görünür | D7: Kontroller + kaynak izi + sürüm | E7: Prestij kelimesi | F7: HATA
A8: Referans | B8: Müşteri yorumu yoksa ne göstereceğim? | C8: Önce/Sonra + Karar Vakası + Hata Önleme Vakası üretilir | D8: Demo/örnek çıktı | E8: Kanıtsız iddia | F8: HATA
A9: Senaryo | B9: Ne olursa işler bozulur? | C9: Baz/Aşağı/Yukarı veya uygun stres senaryosu | D9: Senaryo karşılaştırma | E9: Dekoratif senaryo | F9: HATA
A10: Ters stres | B10: Hangi eşikte karar kırılır? | C10: En az bir kritik sürücü için kırılma eşiği | D10: Kırılma eşiği tablosu | E10: Sadece +/- %10 | F10: UYARI/HATA
A11: Hata tutarlılığı | B11: Formül hata verirse ne olur? | C11: Kontrol GEÇTİ veremez; BLOKE/HATA üretir | D11: Hata taraması | E11: Hata + GEÇTİ birlikte | F11: HATA
A12: Karar motoru | B12: Ne oldu, neden oldu? | C12: Sorun + neden + parasal etki + aksiyon + son tarih | D12: Karar tablosu | E12: Boş sayfa / isim düzeyi modül | F12: HATA
A13: Yönetici özeti | B13: 5 saniyede ne görmeliyim? | C13: Bugün / ne değişti / ne bozulacak / neden / ne yapmalıyım / güven | D13: Yönetici özeti ekranı | E13: KPI kutusu yığını | F13: HATA
A14: Teklif | B14: Neden satın almalıyım? | C14: Dosya özellikleri yerine sonuç ve kaçınılan maliyet sunulur | D14: Ürün sayfası kanıt eşlemesi | E14: Özellik listesiyle satış | F14: HATA
... A19: Pazar kanıtı | B19: Piyasa gerçekten ödüyor mu? | C19: Satış/pilot/LOI/fiyat kabulü olmadan pazar doğrulandı yazılmaz | D19: Gerçek işlem kanıtı | E19: Tahmini talep = satış kabulü | F19: HATA

Sheet KAPAK
A1: KAPAK — Proje ve İş Bazında Gerçek Kârlılık Sistemi
A3: Proje ve İş Bazında Gerçek Kârlılık Sistemi
A4: Her işin gelirini direkt giderlerle eşleştirin; iş bazında gerçek kâr ve marjı çıkarın, kaynakları kârlı işlere yönlendirin.
A6: Bu ürün ne sağlar?
A7: • İş bazında gelir ve direkt gider eşleştirmesi
A8: • Gerçek kâr ve marj hesabı ile günlük kâr karşılaştırması
A9: • Zarar eden iş uyarısı ve kaynak önceliklendirme
A10: • Senaryo ve duyarlılık analiziyle fiyat/maliyet yönetimi
A11: • Yönetici raporu ve karar kapısı (UYGUN/İNCELE/DURDUR)
A14: Kimler için?
A15: • Proje bazlı çalışan üreticiler
A16: • Hizmet işletmeleri
... A21: Sürüm 1.0.0 | 2026 | ExcelArşiv | Lisans: Tek kullanıcı

Sheet HIZLI_BASLANGIC
A1: HIZLI BASLANGIC — Proje ve İş Bazında Gerçek Kârlılık Sistemi
A3: Nasıl kullanılır?
A5: Adım 1 — İşleri girin | B5: IS_GIRILERI sayfasındaki sarı hücrelere iş numarası, iş adı, toplam gelir, direkt maliyet ve süre girin. Her satır bir iştir.
A6: Adım 2 — Sonuçları izleyin | B6: HESAP sayfası iş bazında kâr, marj ve günlük kârı hesaplar; PANO özeti gösterir.
A7: Adım 3 — Karar ve rapor | B7: KARAR sayfası UYGUN/İNCELE/DURDUR üretir; RAPOR yöneticiye sunulabilir.
A8: Adım 4 — Eşikleri ayarlayın | B8: Marj ve günlük kâr eşikleri AYARLAR sayfasından değiştirilir.
A11: Sık yapılan hatalar
A12: • Direkt giderlere genel giderleri de eklemek (maliyeti şişirir)
A13: • Süreyi gün yerine hafta girmek
A14: • İş numarasını boş bırakmak
A15: Bu dosya karar destek aracıdır; muhasebe kaydı veya vergi beyanı değildir.

Sheet IS_GIRILERI
A1: IS GIRILERI — Proje ve İş Bazında Gerçek Kârlılık Sistemi
A3: İş ve Gelir-Gider Girişleri
A4: Sarı hücrelere manuel veri girin. Her satır bir iştir; kâr, marj ve günlük kâr otomatik hesaplanır.
A5: İş Numarası | B5: İş Adı | C5: Toplam Gelir (₺) | D5: Direkt Maliyet (₺) | E5: Süre (Gün) | F5: Kâr (₺) | G5: Marj | H5: Günlük Kâr (₺) | I5: Durum | J5: Not
A6: IS-001 | B6: Web sitesi yenileme projesi | C6: 250000 | D6: 140000 | E6: 45 | F6: =$C6-$D6 | G6: =IF($C6=0,0,$F6/$C6) | H6: =IF($E6=0,0,$F6/$E6) | I6: =IF($B6="","",IF($F6<0,"ZARAR",IF($G6<IsMarjEsik,"RİSK","KÂRLI"))) | J6: Örnek: kârlı iş
A7: IS-002 | B7: Mobil uygulama geliştirme | C7: 180000 | D7: 120000 | E7: 60 | F7: =$C7-$D7 | G7: =IF($C7=0,0,$F7/$C7) | H7: =IF($E7=0,0,$F7/$E7) | I7: =IF($B7="","",IF($F7<0,"ZARAR",IF($G7<IsMarjEsik,"RİSK","KÂRLI"))) | J7: Örnek: orta marj
A8: IS-003 | B8: Kurumsal eğitim programı | C8: 95000 | D8: 61000 | E8: 20 | F8: =$C8-$D8 | G8: =IF($C8=0,0,$F8/$C8) | H8: =IF($E8=0,0,$F8/$E8) | I8: =IF($B8="","",IF($F8<0,"ZARAR",IF($G8<IsMarjEsik,"RİSK","KÂRLI"))) | J8: Örnek: kârlı iş
A9: IS-004 | B9: Logo ve kurumsal kimlik | C9: 42000 | D9: 31000 | E9: 15 | F9: =$C9-$D9 | G9: =IF($C9=0,0,$F9/$C9) | H9: =IF($E9=0,0,$F9/$E9) | I9: =IF($B9="","",IF($F9<0,"ZARAR",IF($G9<IsMarjEsik,"RİSK","KÂRLI"))) | J9: Örnek: dar marj
A10: IS-005 | B10: Sosyal medya yönetimi (3 ay) | C10: 75000 | D10: 45000 | E10: 90 | F10: =$C10-$D10 | G10: =IF($C10=0,0,$F10/$C10) | H10: =IF($E10=0,0,$F10/$E10) | I10: =IF($B10="","",IF($F10<0,"ZARAR",IF($G10<IsMarjEsik,"RİSK","KÂRLI"))) | J10: Örnek: sürekli gelir
A11: IS-006 | B11: Vitrin düzenleme işi | C11: 28000 | D11: 26000 | E11: 10 | F11: =$C11-$D11 | G11: =IF($C11=0,0,$F11/$C11) | H11: =IF($E11=0,0,$F11/$E11) | I11: =IF($B11="","",IF($F11<0,"ZARAR",IF($G11<IsMarjEsik,"RİSK","KÂRLI"))) | J11: Örnek: riskli iş
A12: IS-007 | B12: E-ticaret danışmanlığı | C12: 120000 | D12: 72000 | E12: 30 | F12: =$C12-$D12 | G12: =IF($C12=0,0,$F12/$C12) | H12: =IF($E12=0,0,$F12/$E12) | I12: =IF($B12="","",IF($F12<0,"ZARAR",IF($G12<IsMarjEsik,"RİSK","KÂRLI"))) | J12: Örnek: kârlı iş
A13: IS-008 | B13: Bakım ve destek sözleşmesi | C13: 90000 | D13: 50000 | E13: 365 | F13: =$C13-$D13 | G13: =IF($C13=0,0,$F13/$C13) | H13: =IF($E13=0,0,$F13/$E13) | I13: =IF($B13="","",IF($F13<0,"ZARAR",IF($G13<IsMarjEsik,"RİSK","KÂRLI"))) | J13: Örnek: yıllık sözleşme
A14: IS-009 | B14: Video prodüksiyon | C14: 66000 | D14: 48000 | E14: 25 | F14: =$C14-$D14 | G14: =IF($C14=0,0,$F14/$C14) | H14: =IF($E14=0,0,$F14/$E14) | I14: =IF($B14="","",IF($F14<0,"ZARAR",IF($G14<IsMarjEsik,"RİSK","KÂRLI"))) | J14: Örnek: dar marj
A15: IS-010 | B15: Veri raporlama paneli | C15: 145000 | D15: 88000 | E15: 50 | F15: =$C15-$D15 | G15: =IF($C15=0,0,$F15/$C15) | H15: =IF($E15=0,0,$F15/$E15) | I15: =IF($B15="","",IF($F15<0,"ZARAR",IF($G15<IsMarjEsik,"RİSK","KÂRLI"))) | J15: Örnek: kârlı iş
F16: =$C16-$D16 | G16: =IF($C16=0,0,$F16/$C16) | H16: =IF($E16=0,0,$F16/$E16) | I16: =IF($B16="","",IF($F16<0,"ZARAR",IF($G16<IsMarjEsik,"RİSK","KÂRLI")))
F17: =$C17-$D17 | G17: =IF($C17=0,0,$F17/$C17) | H17: =IF($E17=0,0,$F17/$E17) | I17: =IF($B17="","",IF($F17<0,"ZARAR",IF($G17<IsMarjEsik,"RİSK","KÂRLI")))
F18: =$C18-$D18 | G18: =IF($C18=0,0,$F18/$C18) | H18: =IF($E18=0,0,$F18/$E18) | I18: =IF($B18="","",IF($F18<0,"ZARAR",IF($G18<IsMarjEsik,"RİSK","KÂRLI")))
F19: =$C19-$D19 | G19: =IF($C19=0,0,$F19/$C19) | H19: =IF($E19=0,0,$F19/$E19) | I19: =IF($B19="","",IF($F19<0,"ZARAR",IF($G19<IsMarjEsik,"RİSK","KÂRLI")))
F20: =$C20-$D20 | G20: =IF($C20=0,0,$F20/$C20) | H20: =IF($E20=0,0,$F20/$E20) | I20: =IF($B20="","",IF($F20<0,"ZARAR",IF($G20<IsMarjEsik,"RİSK","KÂRLI")))
F21: =$C21-$D21 | G21: =IF($C21=0,0,$F21/$C21) | H21: =IF($E21=0,0,$F21/$E21) | I21: =IF($B21="","",IF($F21<0,"ZARAR",IF($G21<IsMarjEsik,"RİSK","KÂRLI")))
F22: =$C22-$D22 | G22: =IF($C22=0,0,$F22/$C22) | H22: =IF($E22=0,0,$F22/$E22) | I22: =IF($B22="","",IF($F22<0,"ZARAR",IF($G22<IsMarjEsik,"RİSK","KÂRLI")))
F23: =$C23-$D23 | G23: =IF($C23=0,0,$F23/$C23) | H23: =IF($E23=0,0,$F23/$E23) | I23: =IF($B23="","",IF($F23<0,"ZARAR",IF($G23<IsMarjEsik,"RİSK","KÂRLI")))
F24: =$C24-$D24 | G24: =IF($C24=0,0,$F24/$C24) | H24: =IF($E24=0,0,$F24/$E24) | I24: =IF($B24="","",IF($F24<0,"ZARAR",IF($G24<IsMarjEsik,"RİSK","KÂRLI")))
F25: =$C25-$D25 | G25: =IF($C25=0,0,$F25/$C25) | H25: =IF($E25=0,0,$F25/$E25) | I25: =IF($B25="","",IF($F25<0,"ZARAR",IF($G25<IsMarjEsik,"RİSK","KÂRLI")))
F26: =$C26-$D26 | G26: =IF($C26=0,0,$F26/$C26) | H26: =IF($E26=0,0,$F26/$E26) | I26: =IF($B26="","",IF($F26<0,"ZARAR",IF($G26<IsMarjEsik,"RİSK","KÂRLI")))
F27: =$C27-$D27 | G27: =IF($C27=0,0,$F27/$C27) | H27: =IF($E27=0,0,$F27/$E27) | I27: =IF($B27="","",IF($F27<0,"ZARAR",IF($G27<IsMarjEsik,"RİSK","KÂRLI")))
... F1004: =$C1004-$D1004 | G1004: =IF($C1004=0,0,$F1004/$C1004) | H1004: =IF($E1004=0,0,$F1004/$E1004) | I1004: =IF($B1004="","",IF($F1004<0,"ZARAR",IF($G1004<IsMarjEsik,"RİSK","KÂRLI")))
A1006: Sarı hücreler manuel giriştir; formül hücreleri kilitli ve korumalıdır.

Sheet HESAP
A1: HESAP — Proje ve İş Bazında Gerçek Kârlılık Sistemi
A3: İş Bazlı Kârlılık Özeti
A4: Aşağıdaki özet iş girişlerinden otomatik beslenir; elle değiştirilmez.
A6: Toplam İş Geliri | B6: =SUM(tblIs[Toplam Gelir (₺)])
A7: Toplam Direkt Maliyet | B7: =SUM(tblIs[Direkt Maliyet (₺)])
A8: Toplam Kâr | B8: =SUM(tblIs[Kâr (₺)])
A9: Ağırlıklı Marj | B9: =IF(B6=0,0,B8/B6)
A10: Ortalama Günlük Kâr | B10: =ROUND(IFERROR(AVERAGE(tblIs[Günlük Kâr (₺)]),0),0)
A11: Kârlı İş Sayısı | B11: =COUNTIF(tblIs[Durum],"KÂRLI")
A12: Riskli İş Sayısı | B12: =COUNTIF(tblIs[Durum],"RİSK")
A13: Zararlı İş Sayısı | B13: =COUNTIF(tblIs[Durum],"ZARAR")
A14: En Kârlı İş | B14: =IFERROR(INDEX(tblIs[İş Adı],MATCH(MAX(tblIs[Kâr (₺)]),tblIs[Kâr (₺)],0)),"YOK")
A15: En Yüksek Günlük Kârlı İş | B15: =IFERROR(INDEX(tblIs[İş Adı],MATCH(MAX(tblIs[Günlük Kâr (₺)]),tblIs[Günlük Kâr (₺)],0)),"YOK")
A16: En Düşük Günlük Kârlı İş | B16: =IFERROR(INDEX(tblIs[İş Adı],MATCH(MIN(tblIs[Günlük Kâr (₺)]),tblIs[Günlük Kâr (₺)],0)),"YOK")
A17: Süre Toplamı (Gün) | B17: =IFERROR(SUM(tblIs[Süre (Gün)]),0)
A18: Ortalama Süre (Gün) | B18: =ROUND(IFERROR(AVERAGE(tblIs[Süre (Gün)]),0),0)
A19: Gelir-Kâr Oranı | B19: =IF(B6=0,0,B8/B6)
A20: Kârlı İş Oranı | B20: =IFERROR(COUNTIF(tblIs[Durum],"KÂRLI")/COUNTA(tblIs[İş Adı]),0)
A21: Riskli İş Oranı | B21: =IFERROR(COUNTIF(tblIs[Durum],"RİSK")/COUNTA(tblIs[İş Adı]),0)
A22: Zararlı İş Oranı | B22: =IFERROR(COUNTIF(tblIs[Durum],"ZARAR")/COUNTA(tblIs[İş Adı]),0)
A23: Medyan İş Kârı | B23: =IFERROR(MEDIAN(tblIs[Kâr (₺)]),0)
A24: İş Kârı Yüzdelik P10 | B24: =_xlfn.PERCENTILE.INC(tblIs[Kâr (₺)],0.1)
A25: İş Kârı Yüzdelik P90 | B25: =_xlfn.PERCENTILE.INC(tblIs[Kâr (₺)],0.9)
A26: En Düşük İş Kârı | B26: =IFERROR(MIN(tblIs[Kâr (₺)]),0)
A27: En Yüksek İş Kârı | B27: =IFERROR(MAX(tblIs[Kâr (₺)]),0)
A28: Kâr Aralığı (Max-Min) | B28: =IFERROR(B27-B26,0)
A29: Medyan Günlük Kâr | B29: =IFERROR(MEDIAN(tblIs[Günlük Kâr (₺)]),0)
A30: En Düşük Marj | B30: =IFERROR(MIN(tblIs[Marj]),0)
A31: En Yüksek Marj | B31: =IFERROR(MAX(tblIs[Marj]),0)
A32: Ortalama Marj | B32: =IFERROR(AVERAGE(tblIs[Marj]),0)
A33: Marj Standart Sapması | B33: =IFERROR(stdev.p(tblIs[Marj]),0)
A34: Kâr Eğimi (Trend) | B34: =IFERROR(SLOPE(tblIs[Kâr (₺)],ROW(tblIs[Kâr (₺)])-ROW(tblIs[[#Headers],[Kâr (₺)]])),0)
A35: Kâr Kesişimi | B35: =IFERROR(INTERCEPT(tblIs[Kâr (₺)],ROW(tblIs[Kâr (₺)])-ROW(tblIs[[#Headers],[Kâr (₺)]])),0)
A36: Sonraki İş Kârı Tahmini | B36: =IFERROR(TREND(tblIs[Kâr (₺)],ROW(tblIs[Kâr (₺)])-ROW(tblIs[[#Headers],[Kâr (₺)]]),COUNTA(tblIs[İş Adı])+1),0)
A37: İlk Üç İş Kârı Toplamı | B37: =IFERROR(SUM(INDEX(tblIs[Kâr (₺)],1):INDEX(tblIs[Kâr (₺)],3)),0)
A38: Son Üç İş Kârı Toplamı | B38: =IFERROR(SUM(INDEX(tblIs[Kâr (₺)],COUNTA(tblIs[İş Adı])-2):INDEX(tblIs[Kâr (₺)],COUNTA(tblIs[İş Adı]))),0)
A39: İlk-Son Üç İş Farkı | B39: =IFERROR(B38-B37,0)
A40: Dönem Kâr Farkı (İlk-Son) | B40: =IFERROR(INDEX(tblIs[Kâr (₺)],COUNTA(tblIs[İş Adı]))-INDEX(tblIs[Kâr (₺)],1),0)
A41: Süre Başına Gelir (₺/Gün) | B41: =IF(B17=0,0,B6/B17)
A42: Süre Başına Kâr (₺/Gün) | B42: =IF(B17=0,0,B8/B17)
...

Sheet ANALITIK_MOTOR
A1: ANALITIK MOTOR — Proje ve İş Bazında Gerçek Kârlılık Sistemi
A3: ANALİTİK MOTOR — DERİNLİK KATMANI
A5: Kod | B5: Gösterge | C5: Değer | D5: Makine Yorumu
A6: T2 | B6: Ortalama İş Kârı | C6: =PANO!B29 | D6: =_xlfn.TEXTJOIN("; ",TRUE(),"Ortalama iş kârı ",TEXT(C6,"₺ #,##0")," TL — eğilim bu seviyede seyrediyor")
A7: T4 | B7: İlk-Son İş Kârı Farkı | C7: =IFERROR(INDEX(tblIs[Kâr (₺)],COUNTA(tblIs[İş Adı]))-INDEX(tblIs[Kâr (₺)],1),0) | D7: =_xlfn.TEXTJOIN("; ",TRUE(),"İlk ile son işin kâr farkı ",TEXT(C7,"₺ #,##0")," TL — artış kârlılık gücünü gösterir")
A8: O1 | B8: İş Kârı Sapması (STDEV) | C8: =PANO!B30 | D8: =_xlfn.TEXTJOIN("; ",TRUE(),"İş kârı sapması ",TEXT(C8,"₺ #,##0")," TL — sapma yüksekse kârlılık öngörülemezdir")
A9: O2 | B9: Tornado: En Büyük Etki | C9: =MAX(SENARYO_DUYARLILIK!B12:B13) | D9: =_xlfn.TEXTJOIN("; ",TRUE(),"Kârlılığı en çok etkileyen değişkenin etkisi ",TEXT(C9,"₺ #,##0")," TL — öncelik bu değişkenin izlenmesinde")
A10: O3 | B10: Senaryo Bant Genişliği | C10: =SENARYO_DUYARLILIK!C7-SENARYO_DUYARLILIK!C9 | D10: =_xlfn.TEXTJOIN("; ",TRUE(),"İyimser ile kötümser senaryo kâr farkı ",TEXT(C10,"₺ #,##0")," TL — belirsizlik aralığını gösterir")
A11: O8 | B11: Veri Kalite Skoru | C11: =KONTROLLER!B19 | D11: =_xlfn.TEXTJOIN("; ",TRUE(),"Veri kalite skoru ",TEXT(C11,"0")," puan — ",IF(C11>=IsKaliteIyi,"yüksek güven","veri girişi tamamlanmalı"))
A12: I1 | B12: Gelecek İş Kârı Tahmini | C12: =PANO!B28 | D12: =_xlfn.TEXTJOIN("; ",TRUE(),"Gelecek işin kâr tahmini ",TEXT(C12,"₺ #,##0")," TL — güven bandı için alt/üst sınır PANO sayfasındadır")
A13: I2 | B13: İş Kârı Yüzdelik P90 | C13: =_xlfn.PERCENTILE.INC(tblIs[Kâr (₺)],IsP90Oran) | D13: =_xlfn.TEXTJOIN("; ",TRUE(),"İş kârlarının %90 ı ",TEXT(C13,"₺ #,##0")," TL altında gerçekleşir — üst sınır portföy planı için kullanılabilir")

Sheet KONTROLLER
A1: KONTROLLER — Proje ve İş Bazında Gerçek Kârlılık Sistemi
A3: Giriş Kalite Kontrolleri
A4: Aşağıdaki kontroller canlı formüllerle çalışır; sorun varsa uyarı üretir.
A6: Boş iş adı var mı? | B6: =IF(COUNTBLANK(tblIs[İş Adı])=0,"TEMİZ","BOŞ VAR")
A7: Boş gelir var mı? | B7: =IF(COUNTBLANK(tblIs[Toplam Gelir (₺)])=0,"TEMİZ","BOŞ VAR")
A8: Negatif gelir var mı? | B8: =IF(COUNTIF(tblIs[Toplam Gelir (₺)],"<0")=0,"TEMİZ","NEGATİF VAR")
A9: Maliyeti geliri aşan iş var mı? | B9: =IF(COUNTIFS(tblIs[Direkt Maliyet (₺)],">0",tblIs[Toplam Gelir (₺)],"=0")=0,"TEMİZ","FARK VAR")
A10: Zararlı iş var mı? | B10: =IF(COUNTIF(tblIs[Durum],"ZARAR")=0,"YOK","VAR")
A11: Ağırlıklı marj eşiğin altında mı? | B11: =IF(HESAP!B9<IsMarjEsik,"AŞIYOR","NORMAL")
A12: Günlük kâr eşiği aşılıyor mu? | B12: =IF(HESAP!B10<IsGunlukKarEsik,"AŞIYOR","NORMAL")
A13: Riskli iş sayısı eşiği aşılıyor mu? | B13: =IF(HESAP!B13>IsRiskliAdetEsik,"AŞIYOR","NORMAL")
A15: Veri Kalitesi Skoru (0-100)
A16: Boş ve negatif girişlerin oranına göre üretilen kalite skoru.
A17: Toplam Giriş Hücresi | B17: =COUNTA(tblIs[İş Adı])*COUNTA(tblIs[#Headers])
A18: Dolu Giriş Hücresi | B18: =COUNTA(tblIs[İş Adı])+COUNTA(tblIs[Toplam Gelir (₺)])+COUNTA(tblIs[Direkt Maliyet (₺)])+COUNTA(tblIs[Süre (Gün)])+COUNTA(tblIs[Not])
A19: Kalite Skoru | B19: =ROUND(IF(IsToplamGiris=0,0,IsDoluGiris/IsToplamGiris*100),0)
A20: Kalite Seviyesi | B20: =IF(B19>=IsKaliteIyi,"YÜKSEK",IF(B19>=IsKaliteOrta,"ORTA","DÜŞÜK"))
A22: Kontroller yalnızca giriş verisini denetler; değerleri değiştirmez.

Sheet KARAR
A1: KARAR — Proje ve İş Bazında Gerçek Kârlılık Sistemi
A3: Karar Kapısı — İş Kârlılık Yeterliliği
A4: Ağırlıklı marj, zararlı iş ve günlük kâr eşiklerine göre üretilen karar.
A6: Toplam Kâr | B6: =HESAP!B8
A7: Ağırlıklı Marj | B7: =HESAP!B9
A8: Ortalama Günlük Kâr | B8: =HESAP!B10
A9: Zararlı İş Sayısı | B9: =HESAP!B13
A11: KARAR | B11: =IF(COUNTA(tblIs[İş Adı])=0,"VERİ YOK",IF(HESAP!B13>0,"DURDUR",IF(HESAP!B9<IsMarjEsik,"İNCELE",IF(HESAP!B10<IsGunlukKarEsik,"İNCELE","UYGUN"))))
A12: Gerekçe | B12: =IF(HESAP!B13>0,"Zararlı işler var; fiyatlama ve maliyet tahmini gözden geçirilmeli.",IF(HESAP!B9<IsMarjEsik,"Ağırlıklı marj hedefin altında; fiyat ve direkt maliyet dengesi revize edilmeli.",IF(HESAP!B10<IsGunlukKarEsik,"Günlük kâr eşiğin altında; kaynak tahsisi kârlı işlere kaydırılmalı.","Karar kapısı uygun: iş kârlılık göstergeleri hedef aralıkta.")))
A14: Önerilen Aksiyonlar
A15: Aksiyon 1 | B15: =IsAksiyon1_ACIKLAMA
A16: Aksiyon 2 | B16: =IsAksiyon2_ACIKLAMA
A17: Aksiyon 3 | B17: =IsAksiyon3_ACIKLAMA
A19: Karar yalnızca giriş verisi ve AYARLAR'daki eşiklerden türetilir; kesin finansal tavsiye değildir.

Sheet SENARYO_DUYARLILIK
A1: SENARYO DUYARLILIK — Proje ve İş Bazında Gerçek Kârlılık Sistemi
A3: Senaryo ve Duyarlılık Analizi
A4: İyimser, baz ve kötümser senaryolarda toplam kâr; ardından hangi değişkenin sonucu en çok etkilediğini gösteren tornado analizi.
A6: Senaryo | B6: Gelir Çarpanı | C6: Tahmini Toplam Kâr | D6: Tahmini Marj
A7: İYİMSER | B7: =IF(HESAP!B8=0,0,IsIyiSenaryo) | C7: =ROUND(HESAP!B6*IsIyiSenaryo-(HESAP!B6-HESAP!B8),0) | D7: =IF(HESAP!B6=0,0,C7/(HESAP!B6*IsIyiSenaryo))
A8: BAZ | B8: =IF(HESAP!B8=0,0,IsBazSenaryo) | C8: =ROUND(HESAP!B6*IsBazSenaryo-(HESAP!B6-HESAP!B8),0) | D8: =IF(HESAP!B6=0,0,C8/(HESAP!B6*IsBazSenaryo))
A9: KÖTÜMSER | B9: =IF(HESAP!B8=0,0,IsKotuSenaryo) | C9: =ROUND(HESAP!B6*IsKotuSenaryo-(HESAP!B6-HESAP!B8),0) | D9: =IF(HESAP!B6=0,0,C9/(HESAP!B6*IsKotuSenaryo))
A11: Tornado: Toplam Kâra Etki
A12: Gelir +%1 | B12: =ROUND(SUM(tblIs[Toplam Gelir (₺)])*IsTornadoGelir,0)
A13: Maliyet +%1 | B13: =ROUND(SUM(tblIs[Direkt Maliyet (₺)])*IsTornadoMaliyet,0)
A15: En Etkili Değişken | B15: =IF(B12>=B13,"Gelir","Maliyet")
A17: Tornado etkileri AYARLAR'daki çarpanlardan türetilir.

Sheet RAPOR
A1: PROJE VE İŞ BAZINDA GERÇEK KÂRLILIK SİSTEMİ — YÖNETİCİ ÖZETİ
A2: =_xlfn.CONCAT("Rapor Tarihi: ",TEXT(RaporTarihi,"dd.mm.yyyy")," | Hazırlayan: ",RaporHazirlayan," | Sürüm: ",DosyaSurumu)
A4: Karar | B4: =KARAR!B11
A6: Toplam İş Geliri | B6: =HESAP!B6
A7: Toplam Direkt Maliyet | B7: =HESAP!B7
A8: Toplam Kâr | B8: =HESAP!B8
A9: Ağırlıklı Marj | B9: =HESAP!B9
A10: Ortalama Günlük Kâr | B10: =HESAP!B10
A11: Kârlı İş Sayısı | B11: =HESAP!B11
A12: Riskli İş Sayısı | B12: =HESAP!B12
A13: Zararlı İş Sayısı | B13: =HESAP!B13
A14: En Kârlı İş | B14: =HESAP!B14
A15: Kalite Skoru | B15: =KONTROLLER!B19
A17: Varsayımlar ve Önemli Notlar
A18: • Bu yapı iş bazlı direkt giderleri esas alır; genel gider dağıtımı ayrı bir satır eklenerek yapılır.
A19: • Günlük kâr, işin toplam kârının süreye bölünmesiyle hesaplanır.
A20: • Eşikler ve senaryo çarpanları AYARLAR sayfasından alınır.
A21: • Bu dosya muhasebe kaydı değildir; kaynak tahsisi karar destek aracıdır.
A22: • Demo veriler gerçek müşteri verisi değildir; kullanımdan önce temizlenmelidir.
A24: Önerilen Aksiyonlar
A25: =IsAksiyon1_ACIKLAMA
A26: =IsAksiyon2_ACIKLAMA
A27: =IsAksiyon3_ACIKLAMA
A29: Bu rapor karar destek amaçlıdır; mali tavsiye niteliği taşımaz.

Sheet ORNEK_VERI
A1: ORNEK VERI — Proje ve İş Bazında Gerçek Kârlılık Sistemi
A3: Örnek Veri (Demo)
A4: Gerçek girişlere başlamadan önce demo veri ile ürünü deneyin. Bu satırlar örnektir; gerçek verilerle değiştirin.
A5: İş Numarası | B5: İş Adı | C5: Toplam Gelir (₺) | D5: Direkt Maliyet (₺) | E5: Süre (Gün) | F5: Kâr (₺) | G5: Not
A6: IS-001 | B6: Web sitesi projesi | C6: 250000 | D6: 140000 | E6: 30 | F6: =$C6-$D6 | G6: ="Örnek kayıt: "&$A6
A7: IS-002 | B7: Mobil uygulama | C7: 420000 | D7: 250000 | E7: 60 | F7: =$C7-$D7 | G7: ="Örnek kayıt: "&$A7
A8: IS-003 | B8: Danışmanlık | C8: 180000 | D8: 90000 | E8: 20 | F8: =$C8-$D8 | G8: ="Örnek kayıt: "&$A8
A9: IS-004 | B9: Eğitim programı | C9: 320000 | D9: 200000 | E9: 45 | F9: =$C9-$D9 | G9: ="Örnek kayıt: "&$A9
A10: IS-005 | B10: Bakım sözleşmesi | C10: 60000 | D10: 45000 | E10: 15 | F10: =$C10-$D10 | G10: ="Örnek kayıt: "&$A10
F11: =$C11-$D11 | G11: ="Örnek kayıt: "&$A11
F12: =$C12-$D12 | G12: ="Örnek kayıt: "&$A12
F13: =$C13-$D13 | G13: ="Örnek kayıt: "&$A13
F14: =$C14-$D14 | G14: ="Örnek kayıt: "&$A14
F15: =$C15-$D15 | G15: ="Örnek kayıt: "&$A15
F16: =$C16-$D16 | G16: ="Örnek kayıt: "&$A16
F17: =$C17-$D17 | G17: ="Örnek kayıt: "&$A17
F18: =$C18-$D18 | G18: ="Örnek kayıt: "&$A18
F19: =$C19-$D19 | G19: ="Örnek kayıt: "&$A19
F20: =$C20-$D20 | G20: ="Örnek kayıt: "&$A20
F21: =$C21-$D21 | G21: ="Örnek kayıt: "&$A21
F22: =$C22-$D22 | G22: ="Örnek kayıt: "&$A22
... F1004: =$C1004-$D1004 | G1004: ="Örnek kayıt: "&$A1004
A1006: Demo veriler rapor sonuçlarını örnekler; satın alma sonrası silinerek gerçek veriler girilir.

Sheet ANAHTAR
A1: ANAHTAR — ProjeVeIsBazindaGercekKarlilikSistemi
A3: ham_anahtar | B3: norm_anahtar | C3: duplike_sayisi | D3: not
A4: ORNEK-001 | B4: =UPPER(SUBSTITUTE(A4," ","")) | C4: =COUNTIF($A$4:$A$1000,A4) | D4: normalize + duplike izi
A5: ORNEK-002 | B5: =UPPER(SUBSTITUTE(A5," ","")) | C5: =COUNTIF($A$4:$A$1000,A5) | D5: kisa/uzun numara senaryosu

Sheet ESLESTIRME
A1: ESLESTIRME — ProjeVeIsBazindaGercekKarlilikSistemi
A3: kova | B3: aciklama | C3: tutar | D3: tolerans
A4: ESLESEN | B4: Tam eşleşen kayıtlar | C4: 0 | D4: 0
A5: TOLERANS | B5: Tolerans içi fark | C5: 0 | D5: 0.01
A6: TUTARSIZ | B6: Tutar uyuşmazlığı | C6: 0 | D6: 0
A7: ESLESMEYEN | B7: Eşleşmeyen kayıtlar | C7: 0 | D7: 0

Sheet KOK_NEDEN
A1: KOK_NEDEN — ProjeVeIsBazindaGercekKarlilikSistemi
A3: kova | B3: kok_neden | C3: aksiyon
A4: TANIMSIZ | B4: Sınıflandırılamayan kayıt — elle incele | C4: Manuel inceleme
A5: ESLESMEYEN | B5: Karşı tarafta yok | C5: Veri tamamlama
A6: TUTARSIZ | B6: Tutar farkı | C6: Mutabakat

Sheet DEGISIKLIK_KAYDI
A1: DEGISIKLIK KAYDI — Proje ve İş Bazında Gerçek Kârlılık Sistemi
A3: Değişiklik Kaydı
A4: Tarih | B4: Sürüm | C4: Değişiklik | D4: Neden | E4: Yapan
A5: 01.08.2026 | B5: 1.0.0 | C5: İlk üretim | D5: Ürünün yayına hazırlanması | E5: ExcelArşiv

Sheet LISTELER
A1: LISTELER — Proje ve İş Bazında Gerçek Kârlılık Sistemi
A3: Bağlı Listeler
A4: Bu sayfadaki listeler açılır menüleri besler; yeni seçenek eklemek için sarı hücrelere yazın.
A6: İş Durum Önerileri
A7: KÂRLI
A8: RİSK
A9: ZARAR

Sheet AYARLAR
A1: AYARLAR — Proje ve İş Bazında Gerçek Kârlılık Sistemi
A3: Sistem Ayarları ve Oranlar
A4: Tüm sabitler bu sayfadadır. Eşikleri ve çarpanları kendi işletmenize göre güncelleyin. Değişen her değer tüm hesaplamalara anında yansır.
A6: anahtar | B6: deger | C6: birim | D6: alt | E6: ust | F6: aciklama | G6: kaynak | H6: yururluk_tarihi | I6: dogrulama_tarihi
A7: FirmaUnvan | B7: Örnek Firma A.Ş. | C7: Metin | F7: Rapor ve kapakta görünen firma adı. | G7: Kullanıcı | H7: 46023 | I7: 46244
A8: RaporTarihi | B8: 46242 | C8: Tarih | F8: Tüm hesapların ve kararın alındığı tarih. | G8: Kullanıcı | H8: 46023 | I8: 46244
A9: RaporHazirlayan | B9: Finans Direktörü | C9: Metin | F9: Raporu hazırlayan kişi/rol. | G9: Kullanıcı | H9: 46023 | I9: 46244
A10: DosyaSurumu | B10: 1.0.0 | C10: Metin | F10: Ürün sürüm bilgisi; rapor alt bilgisinde görünür. | G10: Kullanıcı | H10: 46023 | I10: 46244
A11: IsMarjEsik | B11: 0.25 | C11: Oran | D11: 0 | E11: 1 | F11: Ağırlıklı marj bu eşiğin altındaysa karar İNCELE olur. | G11: Varsayım | H11: 46023 | I11: 46244
A12: IsGunlukKarEsik | B12: 3000 | C12: TL | D12: 0 | E12: 10000000 | F12: Ortalama günlük kâr bu eşiğin altındaysa karar İNCELE olur. | G12: Varsayım | H12: 46023 | I12: 46244
A13: IsRiskliAdetEsik | B13: 3 | C13: Skor | D13: 0 | E13: 1000 | F13: Riskli iş sayısı bu eşiği aşarsa kontrol uyarır. | G13: Varsayım | H13: 46023 | I13: 46244
A14: IsIyiSenaryo | B14: 1.05 | C14: Oran | D14: 0.5 | E14: 1.5 | F14: İyimser senaryoda toplam kâr bu çarpanla hesaplanır. | G14: Varsayım | H14: 46023 | I14: 46244
A15: IsBazSenaryo | B15: 1 | C15: Oran | D15: 0.5 | E15: 1.5 | F15: Baz senaryoda toplam kâr bu çarpanla hesaplanır. | G15: Varsayım | H15: 46023 | I15: 46244
A16: IsKotuSenaryo | B16: 0.95 | C16: Oran | D16: 0.5 | E16: 1.5 | F16: Kötümser senaryoda toplam kâr bu çarpanla hesaplanır. | G16: Varsayım | H16: 46023 | I16: 46244
A17: IsTornadoGelir | B17: 0.01 | C17: Oran | D17: 0 | E17: 0.2 | F17: Gelirin %1 artışının toplam kâra etkisi. | G17: Varsayım | H17: 46023 | I17: 46244
A18: IsTornadoMaliyet | B18: 0.01 | C18: Oran | D18: 0 | E18: 0.2 | F18: Maliyetin %1 artışının toplam kâra etkisi. | G18: Varsayım | H18: 46023 | I18: 46244
A19: IsTahminCarpan | B19: 1.645 | C19: Oran | D19: 0 | E19: 3 | F19: Tahmin bandı genişliği (standart sapma katı). | G19: Varsayım | H19: 46023 | I19: 46244
A20: IsKaliteIyi | B20: 90 | C20: Skor | D20: 0 | E20: 100 | F20: Kalite skoru bu eşiğin üzerindeyse YÜKSEK kalite. | G20: Varsayım | H20: 46023 | I20: 46244
A21: IsKaliteOrta | B21: 70 | C21: Skor | D21: 0 | E21: 100 | F21: Kalite skoru bu eşiğin üzerindeyse ORTA kalite. | G21: Varsayım | H21: 46023 | I21: 46244
A22: IsAksiyon1_ACIKLAMA | B22: Zararlı işlerde fiyatlama ve maliyet tahminini gözden geçirin. | C22: Metin | F22: DURDUR kararında gösterilen ilk öneri. | G22: Varsayım | H22: 46023 | I22: 46244
A23: IsAksiyon2_ACIKLAMA | B23: Marj düşükse kaynakları daha yüksek günlük kâr sağlayan işlere kaydırın. | C23: Metin | F23: İNCELE kararında gösterilen ikinci öneri. | G23: Varsayım | H23: 46023 | I23: 46244
A24: IsAksiyon3_ACIKLAMA | B24: Günlük kâr düşükse süre planlamasını ve verimlilik artışını birlikte inceleyin. | C24: Metin | F24: İNCELE kararında gösterilen üçüncü öneri. | G24: Varsayım | H24: 46023 | I24: 46244
A25: IsP90Oran | B25: 0.9 | C25: Oran | D25: 0.5 | E25: 1 | F25: İş kârı dağılımında üst yüzdelik dilimin oranı. | G25: Varsayım | H25: 46023 | I25: 46244
A26: IsPanelSatir1 | B26: 1 | C26: Satır | F26: PANO'daki iş grafiği serisinin tablodaki veri satırı (1. iş). | G26: Kullanıcı | H26: 46023 | I26: 46244
A27: IsPanelSatir2 | B27: 2 | C27: Satır | F27: PANO'daki iş grafiği serisinin tablodaki veri satırı (2. iş). | G27: Kullanıcı | H27: 46023 | I27: 46244
A28: IsPanelSatir3 | B28: 3 | C28: Satır | F28: PANO'daki iş grafiği serisinin tablodaki veri satırı (3. iş). | G28: Kullanıcı | H28: 46023 | I28: 46244
A29: IsPanelSatir4 | B29: 4 | C29: Satır | F29: PANO'daki iş grafiği serisinin tablodaki veri satırı (4. iş). | G29: Kullanıcı | H29: 46023 | I29: 46244
A30: IsPanelSatir5 | B30: 5 | C30: Satır | F30: PANO'daki iş grafiği serisinin tablodaki veri satırı (5. iş). | G30: Kullanıcı | H30: 46023 | I30: 46244
A31: IsPanelSatir6 | B31: 6 | C31: Satır | F31: PANO'daki iş grafiği serisinin tablodaki veri satırı (6. iş). | G31: Kullanıcı | H31: 46023 | I31: 46244
A32: IsPanelSatir7 | B32: 7 | C32: Satır | F32: PANO'daki iş grafiği serisinin tablodaki veri satırı (7. iş). | G32: Kullanıcı | H32: 46023 | I32: 46244
A33: IsPanelSatir8 | B33: 8 | C33: Satır | F33: PANO'daki iş grafiği serisinin tablodaki veri satırı (8. iş). | G33: Kullanıcı | H33: 46023 | I33: 46244
A34: IsPanelSatir9 | B34: 9 | C34: Satır | F34: PANO'daki iş grafiği serisinin tablodaki veri satırı (9. iş). | G34: Kullanıcı | H34: 46023 | I34: 46244
A35: IsPanelSatir10 | B35: 10 | C35: Satır | F35: PANO'daki iş grafiği serisinin tablodaki veri satırı (10. iş). | G35: Kullanıcı | H35: 46023 | I35: 46244
B45: VARSAYIM AÇIKLAMALARI
B46: Tüm eşikler ve çarpanlar kullanıcı tarafından değiştirilebilir varsayımlardır. Kaynak değeri 'Varsayım' olan parametreler KILAVUZ sayfasında toplu listelenir.

Sheet KILAVUZ
A1: KILAVUZ — Proje ve İş Bazında Gerçek Kârlılık Sistemi
A3: Kullanım Kılavuzu
A5: Veri girişi | B5: IS_GIRILERI sayfasında sarı hücrelere iş numarası, iş adı, toplam gelir, direkt maliyet ve süreyi girin. Kâr, marj, günlük kâr ve durum otomatik hesaplanır.
A6: Hesap katmanı | B6: HESAP sayfası iş bazında kâr, marj ve günlük kâr göstergelerini özetler.
A7: Karar ve rapor | B7: KARAR sayfası UYGUN/İNCELE/DURDUR kararını üretir; RAPOR yöneticiye sunulabilir.
A8: Ayarlar | B8: AYARLAR sayfasındaki eşikleri ve çarpanları mali müşavir veya kendi tecrübenize göre güncelleyin.
A9: Koruma | B9: Tüm sayfalar 1234 şifresiyle korunur; sarı hücreler serbesttir, formül hücreleri kilitlidir.
A11: Bu dosya karar destek aracıdır; muhasebe kaydı ve vergi beyanı niteliği taşımaz.
A13: Varsayım İşaretli Parametreler
A14: Aşağıdaki eşik ve çarpanlar AYARLAR sayfasında kaynak=Varsayım olarak işaretlidir; mevzuat zorunluluğu yoktur ve işletmeye göre güncellenmelidir.
A15: • Marj Risk Eşiği
A16: • Günlük Kâr Risk Eşiği
A17: • Riskli İş Adet Eşiği
A18: • İyimser, Baz ve Kötümser Senaryo Çarpanları
A19: • Tornado Gelir ve Maliyet Etkisi Oranları
A20: • Tahmin Çarpanı (standart sapma katı)
A21: • Kalite Skoru İyi ve Orta Eşikleri
A22: • P90 Yüzdelik Oranı
A23: • Aksiyon Önerisi Açıklamaları
A25: Bu dosya tamamen çevrimdışı çalışır; verileriniz cihazınızdan çıkmaz. Makro ve dış bağlantı yoktur.
