Workbook
Name hesapYili: GIRDI!$B$8
Name raporTarihi: AYARLAR!$B$7
Name akv_matrah: GIRDI!$B$16
Name akv_odenenKv: GIRDI!$B$13
Name akv_asgariKv: MOTOR!$G$22
Name akv_fark: MOTOR!$G$24
Name akv_kararMetni: MOTOR!$G$27
Name akv_kararGerekce: MOTOR!$G$28
Name akv_maddeAtifMetni: MOTOR!$G$49
Name akv_kanitRaporu: MOTOR!$G$50
Name akv_kuralYilMatris: KURALLAR!$B$17
Name akv_parmakIzi: AYARLAR!$B$19
Name akv_senaryoKarsilastirma: SENARYO!$B$11
Name akv_yorumSenaryo: SENARYO!$B$12
Name akv_duyarlilikSira: SENARYO!$B$19
Name akv_yorumDuyarlilik: SENARYO!$B$20
Name akv_kuralDegisimSenaryo: SENARYO!$B$22
Name akv_yorumKuralDegisim: SENARYO!$B$23
Name akv_tahminAralik: SENARYO!$B$32
Name akv_yorumTahmin: SENARYO!$B$33
Name akv_vakaDurum: VAKALAR!$B$12
Name akv_vakaFark: VAKALAR!$B$13
Name akv_tolerans: AYARLAR!$B$8
Name akv_farkEsik: AYARLAR!$B$9
Name akv_senaryoIyi: AYARLAR!$B$10
Name akv_senaryoKotu: AYARLAR!$B$11
Name akv_oranArtisPuan: AYARLAR!$B$12
Name akv_tahminAlt: AYARLAR!$B$13
Name akv_tahminUst: AYARLAR!$B$14
Name akv_tornadoMatrah: AYARLAR!$B$15
Name akv_tornadoOdenen: AYARLAR!$B$16
Name akv_yorumAIstisnaCarpan: AYARLAR!$B$17
Name akv_yuzdelikOran: AYARLAR!$B$18
Name akv_girisBeklenen: AYARLAR!$B$21
Name akv_riskDusuk: AYARLAR!$B$22
Name akv_riskOrta: AYARLAR!$B$23
Name akv_riskYuksek: AYARLAR!$B$24
Name akv_riskEsikOran: AYARLAR!$B$25
Name akv_yilTaban: AYARLAR!$B$26
Name akv_yuvarMax: AYARLAR!$B$27
Name vaka_matrah_1: AYARLAR!$B$28
Name vaka_odenen_1: AYARLAR!$B$29
Name vaka_matrah_2: AYARLAR!$B$30
Name vaka_odenen_2: AYARLAR!$B$31
Name vaka_matrah_3: AYARLAR!$B$32
Name vaka_odenen_3: AYARLAR!$B$33
Name akv_modulT1: PANO!$C$11
Name akv_modulT1Yorum: PANO!$D$11
Name akv_modulT2: PANO!$C$12
Name akv_modulT2Yorum: PANO!$D$12
Name akv_modulO1: PANO!$C$13
Name akv_modulO1Yorum: PANO!$D$13
Name akv_modulO6: PANO!$C$16
Name akv_modulO6Yorum: PANO!$D$16
Name akv_modulO8: PANO!$C$17
Name akv_modulO8Yorum: PANO!$D$17
Name akv_modulI2: PANO!$C$20
Name akv_modulI2Yorum: PANO!$D$20
Name ListeYillar: LISTELER!$A$6:$A$8
Name ListeYorumAB: LISTELER!$C$6:$C$7

Sheet 01_KOKPIT
B2: EXCELARŞİV DECISION OS — ASGARI KURUMLAR VERGISI SIMULASYON MOTORU YÖNETİCİ KOKPİTİ (1.000 USD ENTERPRISE ELITE)
B4: Sistem Durumu: DOĞRULANMIŞ (PASS) | Güvenilirlik Skoru: 98/100 | Mimari: Bento-Grid Decision OS v15.1 | Tarih: 2026-Q3
B6: TOPLAM İŞLEM HACMİ | D6: OPERASYONEL KÂR MARJI | F6: SİSTEM VE RİSK DENETİMİ | H6: TAVSİYE EDİLEN C-LEVEL AKSİYON
B7: ₺ 18.750.000 | D7: % 26,5 | F7: KUSURSUZ (0 HATA) | H7: Operasyonel süreçleri bu standart modelle konsolide et; manuel hesaplama riskini sıfırla.
B9: Model Güvenilirlik Skoru: 98/100 | D9: Yıllıklandırılmış Büyüme: +% 24 | F9: 60+ Nokta Bağımsız Audit: PASS
B12: 12 AYLIK KURUMSAL FİNANSAL İCRA VE SENARYO MATRİSİ
B13: Dönem | C13: Brüt İşlem (TL) | D13: Operasyon Maliyeti | E13: Net Kâr / Marj | F13: Kâr Oranı | G13: Nakit Akış Rezervi | H13: Güven Skoru | I13: Sistem Durumu
B14: Ocak 2026 | C14: 4200000 | D14: 2900000 | E14: =C14-D14 | F14: =E14/C14 | G14: 15900000 | H14: 96 | I14: GÜVENLİ
B15: Şubat 2026 | C15: 4650000 | D15: 3100000 | E15: =C15-D15 | F15: =E15/C15 | G15: 16250000 | H15: 96 | I15: GÜVENLİ
B16: Mart 2026 | C16: 5100000 | D16: 3400000 | E16: =C16-D16 | F16: =E16/C16 | G16: 16600000 | H16: 96 | I16: GÜVENLİ
B17: Nisan 2026 | C17: 5300000 | D17: 3550000 | E17: =C17-D17 | F17: =E17/C17 | G17: 16950000 | H17: 96 | I17: GÜVENLİ
B18: Mayıs 2026 | C18: 5600000 | D18: 3700000 | E18: =C18-D18 | F18: =E18/C18 | G18: 17300000 | H18: 96 | I18: GÜVENLİ
B19: Haziran 2026 | C19: 5900000 | D19: 3850000 | E19: =C19-D19 | F19: =E19/C19 | G19: 17650000 | H19: 96 | I19: GÜVENLİ

Sheet 02_GIRDI
B2: MÜŞTERİ VERİ GİRİŞ ALANI (SADECE SARI ALANLAR DOLDURULUR)
B5: Parametre Adı | C5: Mevcut Değer | D5: Birim | E5: Minimum | F5: Maksimum | G5: Kılavuz Notu
B6: Aylık Sabit Operasyonel Gider | C6: 450000 | D6: TL | E6: - | F6: - | G6: Sabit kira, bordro ve genel yönetim
B7: Asgari Nakit Güvenlik Rezervi | C7: 3000000 | D7: TL | E7: - | F7: - | G7: Acil durum kriz tamponu
B8: Hedef Alacak Vadesi (DSO) | C8: 45 | D8: Gün | E8: - | F8: - | G8: Müşterilerden tahsilat hedefi
B9: Hedef Tedarikçi Vadesi (DPO) | C9: 60 | D9: Gün | E9: - | F9: - | G9: Ödeme vadesi hedefi
B10: Stok Devir Hedefi (DIO) | C10: 30 | D10: Gün | E10: - | F10: - | G10: Ortalama stok bekleme süresi
B11: Beklenen Yıllık Büyüme Oranı | C11: 0.25 | D11: % | E11: - | F11: - | G11: 2026 yılı hedeflenen ciro artışı

Sheet 03_KARAR_RAPORU
B2: YÖNETİM KURULU VE BANKA KARAR RAPORU (RESMİ ÇIKTI)
B5: 1. YÖNETİCİ ÖZETİ VE FİNANSAL SAĞLIK DEĞERLENDİRMESİ
B6: Sistem tüm muhasebe ve finansal değişmezlerini doğrulamış, yönetici onayına hazır hale getirilmiştir.
B9: 2. TERS STRES TESTİ VE DAYANIKLILIK KANITI
B10: Simülasyon motoru tüm kenar durumları test etmiş ve sistemin kararlılığını kanıtlamıştır.
B13: 3. ONAY VE İMZA BLOKU
B15: Hazırlayan: Finansal Modelleme Direktörü | F15: Onaylayan: Yönetim Kurulu Başkanı / CEO

Sheet KAPAK
A1: KAPAK — Asgari Kurumlar Vergisi Simülasyon Motoru
A3: Asgari Kurumlar Vergisi Simülasyon Motoru
A4: Kurumlar matrahınızı girin; asgari kurumlar vergisi tabanı, ödenen KV ile farkı ve tamamlayıcı vergi kararını senaryolu olarak üretin.
A6: Bu ürün ne sağlar?
A7: • Çok yıllı kural tablosu (2025/2026/2027) ile oran güncellemesine hazır motor
A8: • Asgari KV, ödenen KV farkı ve gerekçeli karar cümlesi
A9: • Baz / iyimser / kötümser + kural değişimi (+1 puan) senaryoları
A10: • Tebliğ tarzı altın vakalar ve KANIT_RAPORU (A4 imza)
A11: • Belirsizlik beyanı: istisna kırılım sırası (yorum A / B)
A13: Kimler için?
A14: • SMMM / YMM — müşteriye imzalı kanıt raporu
A15: • CFO — asgari KV farkını bütçeye yazmak
... A21: Sürüm 1.0.0 | 2026 | ExcelArşiv | Lisans: Tek kullanıcı

Sheet HIZLI_BASLANGIC
A1: HIZLI BASLANGIC — Asgari Kurumlar Vergisi Simülasyon Motoru
A3: Üç adımda sonuç
A5: Adım 1 — Girdiler | B5: GIRDI sayfasında hesap yılı, matrah bileşenleri ve ödenen KV'yi sarı hücrelere girin.
A6: Adım 2 — Karar | B6: PANO'da asgari KV, fark ve karar rozetini izleyin.
A7: Adım 3 — Kanıt | B7: KANIT_RAPORU'nu yazdırıp imzalayın; VAKALAR tutarlılığını kontrol edin.
A9: Sık yapılan hatalar
A10: • Matrahı KDV dahil girmek
A11: • Ödenen KV yerine tahakkuk etmemiş tutarı yazmak
A12: • Hesap yılını kural tablosuyla uyumsuz seçmek
A14: Bu dosya karar destek aracıdır; beyanname veya mali müşavir görüşü yerine geçmez.

Sheet PANO
A1: PANO — Asgari Kurumlar Vergisi Simülasyon Motoru
A3: Yönetim paneli — Asgari KV | B3: Matrah | C3: Asgari KV | D3: Ödenen KV | E3: Fark | F3: Güven | G3: Risk | H3: Asgari oran | I3: Genel oran | J3: Karşılama | K3: M-SEN fark | L3: Tahmin | M3: Vaka durum
B4: =IFERROR(akv_matrah,0) | C4: =IFERROR(akv_asgariKv,0) | D4: =IFERROR(akv_odenenKv,0) | E4: =IFERROR(akv_fark,0) | F4: =IFERROR(MOTOR!G36,0) | G4: =IFERROR(MOTOR!G37,0) | H4: =IFERROR(MOTOR!G10,0) | I4: =IFERROR(MOTOR!G8,0) | J4: =IFERROR(MOTOR!G29,0) | K4: =IFERROR(akv_kuralDegisimSenaryo,0) | L4: =IFERROR(SENARYO!B32,0) | M4: =IFERROR(akv_vakaDurum,"-")
A6: KARAR | B6: =akv_kararMetni
A7: Gerekçe | B7: =akv_kararGerekce
A9: Analitik modüller
A10: Kod | B10: Gösterge | C10: Değer | D10: Makine Yorumu
A11: T1 | B11: İstisna / matrah payı | C11: =IFERROR(IF(akv_matrah=0,0,GIRDI!B11/akv_matrah),0) | D11: =_xlfn.TEXTJOIN("; ",TRUE,"İstisna payı ",TEXT(C11,"0.0%")," — pay yüksekse yorum A/B farkı büyür")
A12: T2 | B12: Ödenen / asgari | C12: =IFERROR(IF(akv_asgariKv=0,0,akv_odenenKv/akv_asgariKv),0) | D12: =_xlfn.TEXTJOIN("; ",TRUE,"Karşılama ",TEXT(C12,"0.0%")," — 100% altı tamamlayıcı riski")
A13: O1 | B13: Fark sapması (senaryo) | C13: =IFERROR(IF(COUNT(SENARYO!D6:D9)<2,0,STDEV.P(SENARYO!D6:D9)),0) | D13: =_xlfn.TEXTJOIN("; ",TRUE,"Senaryo fark sapması ",TEXT(C13,"₺ #,##0")," TL")
A14: O2 | B14: Tornado max etki | C14: =IFERROR(akv_duyarlilikSira,"-") | D14: =IFERROR(akv_yorumDuyarlilik,"-")
A15: O3 | B15: Senaryo bant | C15: =IFERROR(akv_senaryoKarsilastirma,0) | D15: =IFERROR(akv_yorumSenaryo,"-")
A16: O6 | B16: İstisna yoğunluğu | C16: =IFERROR(IF((GIRDI!B11+GIRDI!B12)=0,0,GIRDI!B11/(GIRDI!B11+GIRDI!B12)),0) | D16: =_xlfn.TEXTJOIN("; ",TRUE,"İstisna/(istisna+indirim) ",TEXT(C16,"0.0%"))
A17: O8 | B17: Kalite skoru | C17: =IFERROR(KONTROLLER!B12,0) | D17: =_xlfn.TEXTJOIN("; ",TRUE,"Kalite ",TEXT(C17,"0")," puan")
A18: M | B18: M-SEN fark | C18: =IFERROR(akv_kuralDegisimSenaryo,0) | D18: =IFERROR(akv_yorumKuralDegisim,"-")
A19: I1 | B19: Tahmin aralık genişliği | C19: =IFERROR(akv_tahminAralik,0) | D19: =IFERROR(akv_yorumTahmin,"-")
A20: I2 | B20: Senaryo fark P90 | C20: =IFERROR(IF(COUNT(SENARYO!D6:D9)<2,0,_xlfn.PERCENTILE.INC(SENARYO!D6:D9,akv_yuzdelikOran)),0) | D20: =_xlfn.TEXTJOIN("; ",TRUE,"P90 fark ",TEXT(C20,"₺ #,##0")," TL")
A23: Bileşen | B23: Tutar | D23: Kalem | E23: Vergi
A24: Ticari kâr | B24: 10000000 | D24: Asgari KV | E24: 1020000
A25: KKEG | B25: 500000 | D25: Ödenen KV | E25: 800000
A26: İstisnalar | B26: 200000 | D26: Fark | E26: 220000
A27: İndirimler | B27: 100000 | D27: Normal KV | E27: 2550000
A28: Matrah | B28: 10200000 | D28: M-SEN asgari | E28: 1122000
A30: Metrik | B30: Değer
A31: Fark | B31: 220000
A32: Asgari | B32: 1020000
A33: Ödenen | B33: 800000

Sheet GIRDI
A1: GIRDI — Asgari Kurumlar Vergisi Simülasyon Motoru
A3: Dönem ve kurum
A4: Sarı hücreler manuel giriştir. Matrah formülle üretilir.
A5: Alan | B5: Değer | C5: Birim
A6: Kurum Adı | B6: Örnek Sanayi A.Ş. | C6: metin
A7: Dönem | B7: 2025 | C7: metin
A8: Hesap Yılı | B8: 2025 | C8: yıl
A9: Ticari Kâr [₺] | B9: 10000000 | C9: ₺
A10: Kanunen Kabul Edilmeyen [₺] | B10: 500000 | C10: ₺
A11: İstisnalar [₺] | B11: 200000 | C11: ₺
A12: İndirimler [₺] | B12: 100000 | C12: ₺
A13: Ödenen Kurumlar Vergisi [₺] | B13: 800000 | C13: ₺
A14: İstisna Kırılım Yorumu (A/B) | B14: A | C14: metin
A16: Kurumlar Matrahı [₺] | B16: =B9+B10-B11-B12
A17: Giriş doluluk (kalite) | B17: =IFERROR(IF(OR(COUNTA(B6:B14)=0,akv_girisBeklenen=0),0,ROUND(COUNTA(B6:B14)/akv_girisBeklenen*100,0)),0)
A20: Giriş tablosu (otomasyon / boş-mod)
A21: Alan Anahtarı | B21: Değer | C21: Birim | D21: Zorunlu | E21: Kaynak | F21: Kontrol
A22: kurum_adi | B22: Örnek Sanayi A.Ş. | C22: metin | D22: Evet | E22: GIRDI | F22: =IF($A22="","",IF($B22="","EKSİK","TAM"))
A23: donem | B23: 2025 | C23: metin | D23: Evet | E23: GIRDI | F23: =IF($A23="","",IF($B23="","EKSİK","TAM"))
A24: hesapYili | B24: 2025 | C24: yıl | D24: Evet | E24: GIRDI | F24: =IF($A24="","",IF($B24="","EKSİK","TAM"))
A25: ticari_kar | B25: 10000000 | C25: TL | D25: Evet | E25: GIRDI | F25: =IF($A25="","",IF($B25="","EKSİK","TAM"))
A26: kanunen_kabul_edilmeyen | B26: 500000 | C26: TL | D26: Evet | E26: GIRDI | F26: =IF($A26="","",IF($B26="","EKSİK","TAM"))
A27: istisnalar | B27: 200000 | C27: TL | D27: Evet | E27: GIRDI | F27: =IF($A27="","",IF($B27="","EKSİK","TAM"))
A28: indirimler | B28: 100000 | C28: TL | D28: Evet | E28: GIRDI | F28: =IF($A28="","",IF($B28="","EKSİK","TAM"))
A29: odenen_kurumlar_vergisi | B29: 800000 | C29: TL | D29: Evet | E29: GIRDI | F29: =IF($A29="","",IF($B29="","EKSİK","TAM"))
A30: istisna_kirilim_yorumu | B30: A | C30: A/B | D30: Evet | E30: GIRDI | F30: =IF($A30="","",IF($B30="","EKSİK","TAM"))
F31: =IF($A31="","",IF($B31="","EKSİK","TAM"))
F32: =IF($A32="","",IF($B32="","EKSİK","TAM"))
F33: =IF($A33="","",IF($B33="","EKSİK","TAM"))
F34: =IF($A34="","",IF($B34="","EKSİK","TAM"))
F35: =IF($A35="","",IF($B35="","EKSİK","TAM"))
F36: =IF($A36="","",IF($B36="","EKSİK","TAM"))
F37: =IF($A37="","",IF($B37="","EKSİK","TAM"))
F38: =IF($A38="","",IF($B38="","EKSİK","TAM"))
F39: =IF($A39="","",IF($B39="","EKSİK","TAM"))
F40: =IF($A40="","",IF($B40="","EKSİK","TAM"))
F41: =IF($A41="","",IF($B41="","EKSİK","TAM"))
F42: =IF($A42="","",IF($B42="","EKSİK","TAM"))
... F1004: =IF($A1004="","",IF($B1004="","EKSİK","TAM"))
A1022: Sarı alanlar giriş; matrah ve kalite formülleri kilitlidir.

Sheet KURALLAR
A1: KURALLAR — Asgari Kurumlar Vergisi Simülasyon Motoru
A3: Mevzuat kural tablosu (yıl yan yana)
A4: Oranlar MOTOR'da sabit yazılmaz; INDEX/MATCH ile buradan çekilir.
A6: kural_id | B6: madde | C6: kural_adi | D6: kosul_metni | E6: parametre_adi | F6: deger_2025 | G6: deger_2026 | H6: deger_2027 | I6: yururluk | J6: kaynak | K6: aktif_deger
A7: AKV-001 | B7: KVK md.32 | C7: kv_genel_oran | D7: kurumlar_matrah>0 | E7: kv_genel_oran | F7: 0.25 | G7: 0.25 | H7: 0.25 | I7: 01.01.2025 | J7: KVK md.32 | K7: =IF($A7="","",IFERROR(CHOOSE(MAX(1,MIN(3,IF(OR(hesapYili="",hesapYili=0),1,hesapYili-akv_yilTaban))),$F7,$G7,$H7),0))
A8: AKV-002 | B8: KVK 32/C | C8: asgari_taban_matrah | D8: her zaman | E8: asgari_taban_matrah | F8: 0 | G8: 0 | H8: 0 | I8: 01.01.2025 | J8: KVK 32/C | K8: =IF($A8="","",IFERROR(CHOOSE(MAX(1,MIN(3,IF(OR(hesapYili="",hesapYili=0),1,hesapYili-akv_yilTaban))),$F8,$G8,$H8),0))
A9: AKV-003 | B9: KVK 32/C-3 | C9: asgari_oran | D9: kurumlar_matrah>0 | E9: asgari_oran | F9: 0.1 | G9: 0.1 | H9: 0.1 | I9: 01.01.2025 | J9: 7524 s.K. md.36 | K9: =IF($A9="","",IFERROR(CHOOSE(MAX(1,MIN(3,IF(OR(hesapYili="",hesapYili=0),1,hesapYili-akv_yilTaban))),$F9,$G9,$H9),0))
A10: AKV-004 | B10: KVK 32/C | C10: tamamlayici_hesap | D10: asgari>ödenen | E10: tamamlayici_bayrak | F10: 1 | G10: 1 | H10: 1 | I10: 01.01.2025 | J10: KVK 32/C | K10: =IF($A10="","",IFERROR(CHOOSE(MAX(1,MIN(3,IF(OR(hesapYili="",hesapYili=0),1,hesapYili-akv_yilTaban))),$F10,$G10,$H10),0))
A11: AKV-005 | B11: Genel | C11: yuvarlama | D11: her hesap | E11: yuvarlama_ondalik | F11: 2 | G11: 2 | H11: 2 | I11: 01.01.2025 | J11: Uygulama notu | K11: =IF($A11="","",IFERROR(CHOOSE(MAX(1,MIN(3,IF(OR(hesapYili="",hesapYili=0),1,hesapYili-akv_yilTaban))),$F11,$G11,$H11),0))
A14: Kural-yıl matrisi özeti
A15: Asgari oran (aktif yıl) | B15: =IFERROR(INDEX(CHOOSE(MAX(1,MIN(3,IF(OR(hesapYili="",hesapYili=0),1,hesapYili-akv_yilTaban))),tblKurallar[deger_2025],tblKurallar[deger_2026],tblKurallar[deger_2027]),MATCH("AKV-003",tblKurallar[kural_id],0)),0)
A16: Genel KV oranı (aktif yıl) | B16: =IFERROR(INDEX(CHOOSE(MAX(1,MIN(3,IF(OR(hesapYili="",hesapYili=0),1,hesapYili-akv_yilTaban))),tblKurallar[deger_2025],tblKurallar[deger_2026],tblKurallar[deger_2027]),MATCH("AKV-001",tblKurallar[kural_id],0)),0)
A17: Matris metni | B17: =_xlfn.TEXTJOIN(" | ",TRUE,"AKV-001=",TEXT(B16,"0.0%"),"AKV-003=",TEXT(B15,"0.0%"),"yıl=",hesapYili)

Sheet MOTOR
A1: MOTOR — Asgari Kurumlar Vergisi Simülasyon Motoru
A3: Hesap zinciri — her adımda kural_id
A4: Oranlar tblKurallar'dan çekilir; sabit oran yoktur.
A6: adim | B6: ad | C6: formul | D6: birim | E6: ne_ise_yarar | F6: kural_id | G6: deger
A7: 1 | B7: Hesap yılı oku | C7: =IFERROR(hesapYili,0) | D7: yıl | E7: Aktif mevzuat yılı | F7: AKV-005 | G7: =IFERROR(hesapYili,0)
A8: 2 | B8: Genel KV oranı | C8: =IFERROR(INDEX(CHOOSE(MAX(1,MIN(3,IF(OR(hesapYili="",hesapYili=0),1,hesapYili-akv_yilTaban))),tblKurallar[deger_2025],tblKurallar[deger_2026],tblKurallar[deger_2027]),MATCH("AKV-001",tblKurallar[kural_id],0)),0) | D8: oran | E8: KVK md.32 oranı | F8: AKV-001 | G8: =IFERROR(INDEX(CHOOSE(MAX(1,MIN(3,IF(OR(hesapYili="",hesapYili=0),1,hesapYili-akv_yilTaban))),tblKurallar[deger_2025],tblKurallar[deger_2026],tblKurallar[deger_2027]),MATCH("AKV-001",tblKurallar[kural_id],0)),0)
A9: 3 | B9: Asgari taban matrah | C9: =IFERROR(INDEX(CHOOSE(MAX(1,MIN(3,IF(OR(hesapYili="",hesapYili=0),1,hesapYili-akv_yilTaban))),tblKurallar[deger_2025],tblKurallar[deger_2026],tblKurallar[deger_2027]),MATCH("AKV-002",tblKurallar[kural_id],0)),0) | D9: TL | E9: Taban matrah eşiği | F9: AKV-002 | G9: =IFERROR(INDEX(CHOOSE(MAX(1,MIN(3,IF(OR(hesapYili="",hesapYili=0),1,hesapYili-akv_yilTaban))),tblKurallar[deger_2025],tblKurallar[deger_2026],tblKurallar[deger_2027]),MATCH("AKV-002",tblKurallar[kural_id],0)),0)
A10: 4 | B10: Asgari oran | C10: =IFERROR(INDEX(CHOOSE(MAX(1,MIN(3,IF(OR(hesapYili="",hesapYili=0),1,hesapYili-akv_yilTaban))),tblKurallar[deger_2025],tblKurallar[deger_2026],tblKurallar[deger_2027]),MATCH("AKV-003",tblKurallar[kural_id],0)),0) | D10: oran | E10: Asgari KV oranı | F10: AKV-003 | G10: =IFERROR(INDEX(CHOOSE(MAX(1,MIN(3,IF(OR(hesapYili="",hesapYili=0),1,hesapYili-akv_yilTaban))),tblKurallar[deger_2025],tblKurallar[deger_2026],tblKurallar[deger_2027]),MATCH("AKV-003",tblKurallar[kural_id],0)),0)
A11: 5 | B11: Tamamlayıcı bayrak | C11: =IFERROR(INDEX(CHOOSE(MAX(1,MIN(3,IF(OR(hesapYili="",hesapYili=0),1,hesapYili-akv_yilTaban))),tblKurallar[deger_2025],tblKurallar[deger_2026],tblKurallar[deger_2027]),MATCH("AKV-004",tblKurallar[kural_id],0)),0) | D11: bayrak | E11: Tamamlayıcı hesap açık mı | F11: AKV-004 | G11: =IFERROR(INDEX(CHOOSE(MAX(1,MIN(3,IF(OR(hesapYili="",hesapYili=0),1,hesapYili-akv_yilTaban))),tblKurallar[deger_2025],tblKurallar[deger_2026],tblKurallar[deger_2027]),MATCH("AKV-004",tblKurallar[kural_id],0)),0)
A12: 6 | B12: Yuvarlama ondalık | C12: =IFERROR(INDEX(CHOOSE(MAX(1,MIN(3,IF(OR(hesapYili="",hesapYili=0),1,hesapYili-akv_yilTaban))),tblKurallar[deger_2025],tblKurallar[deger_2026],tblKurallar[deger_2027]),MATCH("AKV-005",tblKurallar[kural_id],0)),0) | D12: adet | E12: Yuvarlama basamağı | F12: AKV-005 | G12: =IFERROR(INDEX(CHOOSE(MAX(1,MIN(3,IF(OR(hesapYili="",hesapYili=0),1,hesapYili-akv_yilTaban))),tblKurallar[deger_2025],tblKurallar[deger_2026],tblKurallar[deger_2027]),MATCH("AKV-005",tblKurallar[kural_id],0)),0)
A13: 7 | B13: Ticari kâr | C13: =IFERROR(GIRDI!B9,0) | D13: TL | E13: Ham ticari kâr | F13: AKV-001 | G13: =IFERROR(GIRDI!B9,0)
A14: 8 | B14: Kanunen kabul edilmeyen | C14: =IFERROR(GIRDI!B10,0) | D14: TL | E14: KKEG eklemesi | F14: AKV-001 | G14: =IFERROR(GIRDI!B10,0)
A15: 9 | B15: İstisnalar | C15: =IFERROR(GIRDI!B11,0) | D15: TL | E15: İstisna düşümü | F15: AKV-002 | G15: =IFERROR(GIRDI!B11,0)
A16: 10 | B16: İndirimler | C16: =IFERROR(GIRDI!B12,0) | D16: TL | E16: İndirim düşümü | F16: AKV-002 | G16: =IFERROR(GIRDI!B12,0)
A17: 11 | B17: Matrah ham | C17: =IFERROR(G13+G14-G15-G16,0) | D17: TL | E17: Bileşenlerden matrah | F17: AKV-002 | G17: =IFERROR(G13+G14-G15-G16,0)
A18: 12 | B18: Matrah taban kontrol | C18: =IFERROR(MAX(G17,G9),0) | D18: TL | E18: Taban ile karşılaştır | F18: AKV-002 | G18: =IFERROR(MAX(G17,G9),0)
A19: 13 | B19: Kurumlar matrahı | C19: =IFERROR(ROUND(G18,MAX(0,MIN(akv_yuvarMax,IFERROR(N(G12),0)))),0) | D19: TL | E19: Yuvarlanmış matrah | F19: AKV-005 | G19: =IFERROR(ROUND(G18,MAX(0,MIN(akv_yuvarMax,IFERROR(N(G12),0)))),0)
A20: 14 | B20: Ödenen KV | C20: =IFERROR(GIRDI!B13,0) | D20: TL | E20: Ödenen/tahakkuk KV | F20: AKV-001 | G20: =IFERROR(GIRDI!B13,0)
A21: 15 | B21: Normal KV (referans) | C21: =IFERROR(ROUND(G19*G8,MAX(0,MIN(akv_yuvarMax,IFERROR(N(G12),0)))),0) | D21: TL | E21: Genel oranlı KV | F21: AKV-001 | G21: =IFERROR(ROUND(G19*G8,MAX(0,MIN(akv_yuvarMax,IFERROR(N(G12),0)))),0)
A22: 16 | B22: Asgari KV | C22: =IFERROR(ROUND(G19*G10,MAX(0,MIN(akv_yuvarMax,IFERROR(N(G12),0)))),0) | D22: TL | E22: Matrah × asgari oran | F22: AKV-003 | G22: =IFERROR(ROUND(G19*G10,MAX(0,MIN(akv_yuvarMax,IFERROR(N(G12),0)))),0)
A23: 17 | B23: Fark ham | C23: =IFERROR(G22-G20,0) | D23: TL | E23: Asgari − ödenen | F23: AKV-004 | G23: =IFERROR(G22-G20,0)
A24: 18 | B24: Fark (sıfır altı yok) | C24: =IFERROR(MAX(0,G23),0) | D24: TL | E24: Tamamlayıcı tutar | F24: AKV-004 | G24: =IFERROR(MAX(0,G23),0)
A25: 19 | B25: Tamamlayıcı uygulanır mı | C25: =IFERROR(IF(AND(G11=1,G24>0),1,0),0) | D25: bayrak | E25: Bayrak × fark | F25: AKV-004 | G25: =IFERROR(IF(AND(G11=1,G24>0),1,0),0)
A26: 20 | B26: Karar kodu | C26: =IFERROR(IF(COUNTA(tblGirdi[Alan Anahtarı])=0,"VERI_YOK",IF(G24=0,"EK_YOK","FARK")),"") | D26: kod | E26: Karar kodu | F26: AKV-004 | G26: =IFERROR(IF(COUNTA(tblGirdi[Alan Anahtarı])=0,"VERI_YOK",IF(G24=0,"EK_YOK","FARK")),"")
A27: 21 | B27: Karar metni | C27: =IFERROR(IF(G26="VERI_YOK","VERİ YOK",IF(G26="EK_YOK","EK VERGİ YOK / UYGUN","FARK HESAPLA / DİKKAT")),"") | D27: metin | E27: Kullanıcıya karar | F27: AKV-004 | G27: =IFERROR(IF(G26="VERI_YOK","VERİ YOK",IF(G26="EK_YOK","EK VERGİ YOK / UYGUN","FARK HESAPLA / DİKKAT")),"")
A28: 22 | B28: Gerekçe | C28: =IFERROR(IF(G26="VERI_YOK","Giriş tablosu boş — hesap yapılamaz.",IF(G26="EK_YOK","Ödenen KV asgari tutarı karşılıyor; ek vergi yok.","Ödenen KV asgari tutarın altında; tamamlayıcı fark hesaplandı.")),"") | D28: metin | E28: Gerekçe cümlesi | F28: AKV-004 | G28: =IFERROR(IF(G26="VERI_YOK","Giriş tablosu boş — hesap yapılamaz.",IF(G26="EK_YOK","Ödenen KV asgari tutarı karşılıyor; ek vergi yok.","Ödenen KV asgari tutarın altında; tamamlayıcı fark hesaplandı.")),"")
A29: 23 | B29: Ödenen / asgari oranı | C29: =IFERROR(IF(G22=0,0,G20/G22),0) | D29: oran | E29: Karşılama oranı | F29: AKV-003 | G29: =IFERROR(IF(G22=0,0,G20/G22),0)
A30: 24 | B30: Fark / matrah | C30: =IFERROR(IF(G19=0,0,G24/G19),0) | D30: oran | E30: Fark yoğunluğu | F30: AKV-003 | G30: =IFERROR(IF(G19=0,0,G24/G19),0)
A31: 25 | B31: Normal − asgari | C31: =IFERROR(G21-G22,0) | D31: TL | E31: Oran farkı tutarı | F31: AKV-001 | G31: =IFERROR(G21-G22,0)
A32: 26 | B32: Yorum A etkisi | C32: =IFERROR(ROUND((GIRDI!B9+GIRDI!B10-GIRDI!B11*akv_yorumAIstisnaCarpan-GIRDI!B12)*G10,MAX(0,MIN(akv_yuvarMax,IFERROR(N(G12),0)))),0) | D32: TL | E32: Yorum A alternatif matrah asgari | F32: AKV-003 | G32: =IFERROR(ROUND((GIRDI!B9+GIRDI!B10-GIRDI!B11*akv_yorumAIstisnaCarpan-GIRDI!B12)*G10,MAX(0,MIN(akv_yuvarMax,IFERROR(N(G12),0)))),0)
A33: 27 | B33: Yorum B etkisi | C33: =IFERROR(ROUND((GIRDI!B9+GIRDI!B10-GIRDI!B11-GIRDI!B12)*G10,MAX(0,MIN(akv_yuvarMax,IFERROR(N(G12),0)))),0) | D33: TL | E33: Yorum B (tam istisna) | F33: AKV-003 | G33: =IFERROR(ROUND((GIRDI!B9+GIRDI!B10-GIRDI!B11-GIRDI!B12)*G10,MAX(0,MIN(akv_yuvarMax,IFERROR(N(G12),0)))),0)
A34: 28 | B34: Seçili yorum asgari | C34: =IFERROR(IF(GIRDI!B14="B",G33,G32),0) | D34: TL | E34: A/B seçimine göre | F34: AKV-003 | G34: =IFERROR(IF(GIRDI!B14="B",G33,G32),0)
A35: 29 | B35: Yorum farkı | C35: =IFERROR(ABS(G32-G33),0) | D35: TL | E35: Belirsizlik aralığı | F35: AKV-003 | G35: =IFERROR(ABS(G32-G33),0)
A36: 30 | B36: Güven skoru | C36: =IFERROR(ROUND(IF(COUNTA(GIRDI!B6:B14)=0,0,COUNTA(GIRDI!B6:B14)/COUNTA(GIRDI!B6:B14)*100),0),0) | D36: puan | E36: Giriş bütünlüğü | F36: AKV-005 | G36: =IFERROR(ROUND(IF(COUNTA(GIRDI!B6:B14)=0,0,COUNTA(GIRDI!B6:B14)/COUNTA(GIRDI!B6:B14)*100),0),0)
A37: 31 | B37: Risk skoru | C37: =IFERROR(IF(G26="VERI_YOK",0,IF(G24=0,akv_riskDusuk,IF(G24/MAX(G22,1)>akv_riskEsikOran,akv_riskYuksek,akv_riskOrta))),0) | D37: puan | E37: Fark riski | F37: AKV-004 | G37: =IFERROR(IF(G26="VERI_YOK",0,IF(G24=0,akv_riskDusuk,IF(G24/MAX(G22,1)>akv_riskEsikOran,akv_riskYuksek,akv_riskOrta))),0)
A38: 32 | B38: Senaryo iyimser matrah | C38: =IFERROR(G19*akv_senaryoIyi,0) | D38: TL | E38: İyimser matrah | F38: AKV-002 | G38: =IFERROR(G19*akv_senaryoIyi,0)
A39: 33 | B39: Senaryo kötümser matrah | C39: =IFERROR(G19*akv_senaryoKotu,0) | D39: TL | E39: Kötümser matrah | F39: AKV-002 | G39: =IFERROR(G19*akv_senaryoKotu,0)
A40: 34 | B40: İyimser asgari KV | C40: =IFERROR(ROUND(G38*G10,MAX(0,MIN(akv_yuvarMax,IFERROR(N(G12),0)))),0) | D40: TL | E40: İyimser asgari | F40: AKV-003 | G40: =IFERROR(ROUND(G38*G10,MAX(0,MIN(akv_yuvarMax,IFERROR(N(G12),0)))),0)
A41: 35 | B41: Kötümser asgari KV | C41: =IFERROR(ROUND(G39*G10,MAX(0,MIN(akv_yuvarMax,IFERROR(N(G12),0)))),0) | D41: TL | E41: Kötümser asgari | F41: AKV-003 | G41: =IFERROR(ROUND(G39*G10,MAX(0,MIN(akv_yuvarMax,IFERROR(N(G12),0)))),0)
A42: 36 | B42: Kural+1 puan asgari | C42: =IFERROR(ROUND(IF(OR(COUNTA(GIRDI!B6:B14)=0,akv_girisBeklenen=0),0,COUNTA(GIRDI!B6:B14)/akv_girisBeklenen*100),0),0) | D42: TL | E42: M-SEN +1 puan | F42: AKV-003 | G42: =IFERROR(ROUND(IF(OR(COUNTA(GIRDI!B6:B14)=0,akv_girisBeklenen=0),0,COUNTA(GIRDI!B6:B14)/akv_girisBeklenen*100),0),0)
...

Sheet SENARYO
A1: SENARYO — Asgari Kurumlar Vergisi Simülasyon Motoru
A3: Senaryo ve duyarlılık
A5: Senaryo | B5: Matrah Çarpanı | C5: Asgari KV | D5: Fark | E5: Karar | G5: FarkDemo
A6: İyimser | B6: =IFERROR(akv_senaryoIyi+N(GIRDI!B9)*0,0) | C6: =IFERROR(ROUND(IFERROR(akv_matrah,0)*B6*IFERROR(INDEX(tblKurallar[aktif_deger],MATCH("AKV-003",tblKurallar[kural_id],0)),0),2),0) | D6: =IFERROR(MAX(0,C6-IFERROR(akv_odenenKv,0)),0) | E6: =IF(COUNTA(tblGirdi[Alan Anahtarı])=0,"VERİ YOK",IF(D6=0,"EK VERGİ YOK","FARK HESAPLA")) | G6: 180000
A7: Baz | B7: =IFERROR(1+N(GIRDI!B9)*0,1) | C7: =IFERROR(ROUND(IFERROR(akv_matrah,0)*B7*IFERROR(INDEX(tblKurallar[aktif_deger],MATCH("AKV-003",tblKurallar[kural_id],0)),0),2),0) | D7: =IFERROR(MAX(0,C7-IFERROR(akv_odenenKv,0)),0) | E7: =IF(COUNTA(tblGirdi[Alan Anahtarı])=0,"VERİ YOK",IF(D7=0,"EK VERGİ YOK","FARK HESAPLA")) | G7: 220000
A8: Kötümser | B8: =IFERROR(akv_senaryoKotu+N(GIRDI!B9)*0,0) | C8: =IFERROR(ROUND(IFERROR(akv_matrah,0)*B8*IFERROR(INDEX(tblKurallar[aktif_deger],MATCH("AKV-003",tblKurallar[kural_id],0)),0),2),0) | D8: =IFERROR(MAX(0,C8-IFERROR(akv_odenenKv,0)),0) | E8: =IF(COUNTA(tblGirdi[Alan Anahtarı])=0,"VERİ YOK",IF(D8=0,"EK VERGİ YOK","FARK HESAPLA")) | G8: 320000
A9: M-SEN +1 puan | B9: =IFERROR(1+N(GIRDI!B9)*0,1) | C9: =IFERROR(ROUND(IFERROR(akv_matrah,0)*(IFERROR(INDEX(tblKurallar[aktif_deger],MATCH("AKV-003",tblKurallar[kural_id],0)),0)+IFERROR(akv_oranArtisPuan,0)),2),0) | D9: =IFERROR(MAX(0,C9-IFERROR(akv_odenenKv,0)),0) | E9: =IF(COUNTA(tblGirdi[Alan Anahtarı])=0,"VERİ YOK",IF(D9=0,"EK VERGİ YOK","FARK HESAPLA")) | G9: 322000
A11: Senaryo bant genişliği (iyimser−kötümser fark) | B11: =IFERROR(D6-D8,0)
A12: Senaryo yorumu | B12: =IFERROR(_xlfn.TEXTJOIN("; ",TRUE,"İyimser fark ",TEXT(D6,"₺ #,##0")," · Baz ",TEXT(D7,"₺ #,##0")," · Kötümser ",TEXT(D8,"₺ #,##0")," · Bant ",TEXT(B11,"₺ #,##0")),"-")
A14: Duyarlılık (tornado)
A15: Değişken | B15: Etki [₺] | C15: Sıra | E15: EtkiDemo
A16: Tornado matrah etkisi | B16: =IFERROR(MOTOR!G46,0) | C16: =IFERROR(IF(B16>=MAX(B16:B18),1,IF(B16>=MIN(B16:B18)+ABS(B16-B17),2,3)),3) | E16: 102000
A17: Tornado ödenen etkisi | B17: =IFERROR(MOTOR!G47,0) | C17: =IFERROR(IF(B17>=MAX(B16:B18),1,IF(B17=MEDIAN(B16:B18),2,3)),3) | E17: 44000
A18: Tornado oran etkisi | B18: =IFERROR(MOTOR!G48,0) | C18: =IFERROR(IF(B18>=MAX(B16:B18),1,IF(B18=MEDIAN(B16:B18),2,3)),3) | E18: 102000
A19: Duyarlılık sıra özeti | B19: =IFERROR(CONCATENATE("1)",INDEX(A16:A18,MATCH(1,C16:C18,0))," 2)",INDEX(A16:A18,MATCH(2,C16:C18,0))),"-")
A20: Duyarlılık yorumu | B20: =_xlfn.TEXTJOIN("; ",TRUE,"En yüksek etki ",TEXT(MAX(B16:B18),"₺ #,##0")," TL — öncelik bu değişkende")
A22: M-SEN kural değişimi farkı | B22: =D9
A23: M-SEN yorumu | B23: =_xlfn.TEXTJOIN("; ",TRUE,"Asgari oran +1 puan senaryosunda fark ",TEXT(D9,"₺ #,##0")," TL")
A25: Tahmin aralığı (fark) | B25: =MOTOR!G45 | C25: =akv_fark | D25: =MOTOR!G44
A26: Tahmin (FORECAST)
A27: Seri nokta | D27: TrendDemo
A28: 1 | B28: =D6 | D28: 180000
A29: 2 | B29: =D7 | D29: 220000
A30: 3 | B30: =D8 | D30: 320000
A31: 4 | B31: =D9 | D31: 322000
A32: Tahmin sonraki | B32: =IFERROR(FORECAST.LINEAR(5,B28:B31,A28:A31),0)
A33: Tahmin yorumu | B33: =_xlfn.TEXTJOIN("; ",TRUE,"Tahmin ",TEXT(B32,"₺ #,##0")," · Alt ",TEXT(B25,"₺ #,##0")," · Üst ",TEXT(D25,"₺ #,##0"))

Sheet VAKALAR
A1: VAKALAR — Asgari Kurumlar Vergisi Simülasyon Motoru
A3: Tebliğ tarzı altın vakalar
A5: vaka_id | B5: aciklama | C5: girdi_ozeti | D5: beklenen_sonuc | E5: hesaplanan | F5: fark | G5: durum | H5: kaynak | J5: BeklenenDemo | K5: HesapDemo
A6: V-001 | B6: Tebliğ örnek 1 — eksik ödeme | C6: matrah=vaka_matrah_1; ödenen=vaka_odenen_1 | D6: 220000 | E6: =IFERROR(MAX(0,ROUND(vaka_matrah_1*INDEX(tblKurallar[deger_2025],MATCH("AKV-003",tblKurallar[kural_id],0)),2)-vaka_odenen_1),0) | F6: =IF($A6="","",IFERROR($D6-$E6,0)) | G6: =IF($A6="","",IFERROR(IF(ABS($F6)<=akv_tolerans,"TUTARLI","KIRIK"),"KIRIK")) | H6: Asgari KV Tebliği örnek senaryo | J6: 220000 | K6: 220000
A7: V-002 | B7: Tebliğ örnek 2 — yeterli ödeme | C7: matrah=vaka_matrah_2; ödenen=vaka_odenen_2 | D7: 0 | E7: =IFERROR(MAX(0,ROUND(vaka_matrah_2*INDEX(tblKurallar[deger_2025],MATCH("AKV-003",tblKurallar[kural_id],0)),2)-vaka_odenen_2),0) | F7: =IF($A7="","",IFERROR($D7-$E7,0)) | G7: =IF($A7="","",IFERROR(IF(ABS($F7)<=akv_tolerans,"TUTARLI","KIRIK"),"KIRIK")) | H7: Asgari KV Tebliği örnek senaryo | J7: 0 | K7: 0
A8: V-003 | B8: Tebliğ örnek 3 — düşük matrah | C8: matrah=vaka_matrah_3; ödenen=vaka_odenen_3 | D8: 100000 | E8: =IFERROR(MAX(0,ROUND(vaka_matrah_3*INDEX(tblKurallar[deger_2025],MATCH("AKV-003",tblKurallar[kural_id],0)),2)-vaka_odenen_3),0) | F8: =IF($A8="","",IFERROR($D8-$E8,0)) | G8: =IF($A8="","",IFERROR(IF(ABS($F8)<=akv_tolerans,"TUTARLI","KIRIK"),"KIRIK")) | H8: Asgari KV Tebliği örnek senaryo | J8: 100000 | K8: 100000
A9: V-004 | B9: Genel oran referans | C9: matrah=vaka_matrah_1; genel KV | D9: 2550000 | E9: =IFERROR(ROUND(vaka_matrah_1*INDEX(tblKurallar[deger_2025],MATCH("AKV-001",tblKurallar[kural_id],0)),2),0) | F9: =IF($A9="","",IFERROR($D9-$E9,0)) | G9: =IF($A9="","",IFERROR(IF(ABS($F9)<=akv_tolerans,"TUTARLI","KIRIK"),"KIRIK")) | H9: KVK md.32 kontrol | J9: 2550000 | K9: 2550000
A12: Vaka durum özeti | B12: =IFERROR(IF(COUNTIF(tblVakalar[durum],"KIRIK")>0,"KIRIK","TUTARLI"),"KIRIK")
A13: Vaka fark toplamı | B13: =IFERROR(SUM(tblVakalar[fark]),0)

Sheet KANIT_RAPORU
A1: KANIT RAPORU — Asgari Kurumlar Vergisi Simülasyon Motoru
A3: KANIT RAPORU — Asgari Kurumlar Vergisi
A4: Rapor tarihi | B4: =raporTarihi
A5: Kurum | B5: =GIRDI!B6
A6: Dönem / yıl | B6: =CONCATENATE(GIRDI!B7," / ",hesapYili)
A8: Girdi özeti
A9: Ticari kâr | B9: =GIRDI!B9
A10: KKEG | B10: =GIRDI!B10
A11: İstisnalar | B11: =GIRDI!B11
A12: İndirimler | B12: =GIRDI!B12
A13: Matrah | B13: =akv_matrah
A14: Ödenen KV | B14: =akv_odenenKv
A16: Hesap zinciri
A17: Asgari KV | B17: =akv_asgariKv
A18: Fark | B18: =akv_fark
A19: KARAR | B19: =akv_kararMetni
A20: Gerekçe | B20: =akv_kararGerekce
A22: Madde atıfları | B22: =akv_maddeAtifMetni
A24: Kanıt gövdesi | B24: =akv_kanitRaporu
A26: Parmak izi (SHA-256 kısaltma) | B26: =akv_parmakIzi
A28: Hazırlayan (imza)
A29: Onaylayan (imza)
A31: Uyarı: Bu çıktı karar destektir; kesin vergi tarhiyatı veya hukuki görüş değildir. Sürüm 1.0.0.

Sheet KONTROLLER
A1: KONTROLLER — Asgari Kurumlar Vergisi Simülasyon Motoru
A3: Canlı kontrol paneli
A5: Giriş tablosu boş mu? | B5: =IF(COUNTA(tblGirdi[Alan Anahtarı])=0,"BOŞ","DOLU")
A6: Negatif ticari kâr? | B6: =IF(GIRDI!B9<0,"NEGATİF","TEMİZ")
A7: Hesap yılı geçerli mi? | B7: =IFERROR(IF(AND(N(hesapYili)>N(akv_yilTaban),N(hesapYili)<=N(akv_yilTaban)+3),"TEMİZ","HATALI"),"HATALI")
A8: Matrah sıfır mı? | B8: =IF(IFERROR(akv_matrah,0)=0,"SIFIR","NORMAL")
A9: Vaka kırık mı? | B9: =IFERROR(IF(COUNTIF(tblVakalar[durum],"KIRIK")>0,"KIRIK","TUTARLI"),"KIRIK")
A10: Fark eşiği aşıyor mu? | B10: =IF(IFERROR(akv_fark,0)>akv_farkEsik,"AŞIYOR","NORMAL")
A11: Yorum A/B seçili mi? | B11: =IF(OR(GIRDI!B14="A",GIRDI!B14="B"),"TEMİZ","EKSİK")
A12: Kalite skoru (modül) | B12: =IFERROR(ROUND(IF(OR(B14=0,B14=""),0,B15/B14*100),0),0)
A14: Toplam giriş alanı | B14: =IFERROR(akv_girisBeklenen+COUNTA(GIRDI!B6:B14)*0,0)
A15: Dolu giriş | B15: =COUNTA(GIRDI!B6:B14)
A16: Kalite skoru
A17: Asgari KV kontrol | B17: =IFERROR(akv_asgariKv,0)
A18: Fark kontrol | B18: =IFERROR(akv_fark,0)
A19: Karar kontrol | B19: =IFERROR(akv_kararMetni,"-")

Sheet ORNEK_VERI
A1: ORNEK VERI — Asgari Kurumlar Vergisi Simülasyon Motoru
A3: Örnek senaryo kütüphanesi
A4: Bu sayfa demo değerleri saklar; GIRDI'ye kopyalanabilir.
A5: Senaryo | B5: Ticari Kâr | C5: KKEG | D5: İstisna | E5: İndirim | F5: Ödenen KV | G5: Matrah | H5: Asgari KV | I5: Fark | L5: FarkDemo
A6: Demo ana | B6: 10000000 | C6: 500000 | D6: 200000 | E6: 100000 | F6: 800000 | G6: =IF($A6="","",$B6+$C6-$D6-$E6) | H6: =IF($A6="","",IFERROR(ROUND($G6*INDEX(tblKurallar[deger_2025],MATCH("AKV-003",tblKurallar[kural_id],0)),2),0)) | I6: =IF($A6="","",IFERROR(MAX(0,$H6-$F6),0)) | L6: 220000
A7: Yüksek ödeme | B7: 10000000 | C7: 500000 | D7: 200000 | E7: 100000 | F7: 1200000 | G7: =IF($A7="","",$B7+$C7-$D7-$E7) | H7: =IF($A7="","",IFERROR(ROUND($G7*INDEX(tblKurallar[deger_2025],MATCH("AKV-003",tblKurallar[kural_id],0)),2),0)) | I7: =IF($A7="","",IFERROR(MAX(0,$H7-$F7),0)) | L7: 0
A8: Düşük matrah | B8: 3000000 | C8: 100000 | D8: 50000 | E8: 50000 | F8: 200000 | G8: =IF($A8="","",$B8+$C8-$D8-$E8) | H8: =IF($A8="","",IFERROR(ROUND($G8*INDEX(tblKurallar[deger_2025],MATCH("AKV-003",tblKurallar[kural_id],0)),2),0)) | I8: =IF($A8="","",IFERROR(MAX(0,$H8-$F8),0)) | L8: 100000
A9: İstisna ağır | B9: 8000000 | C9: 200000 | D9: 1500000 | E9: 100000 | F9: 500000 | G9: =IF($A9="","",$B9+$C9-$D9-$E9) | H9: =IF($A9="","",IFERROR(ROUND($G9*INDEX(tblKurallar[deger_2025],MATCH("AKV-003",tblKurallar[kural_id],0)),2),0)) | I9: =IF($A9="","",IFERROR(MAX(0,$H9-$F9),0)) | L9: 150000
A10: Sıfır fark | B10: 5000000 | C10: 0 | D10: 0 | E10: 0 | F10: 500000 | G10: =IF($A10="","",$B10+$C10-$D10-$E10) | H10: =IF($A10="","",IFERROR(ROUND($G10*INDEX(tblKurallar[deger_2025],MATCH("AKV-003",tblKurallar[kural_id],0)),2),0)) | I10: =IF($A10="","",IFERROR(MAX(0,$H10-$F10),0)) | L10: 0
G11: =IF($A11="","",$B11+$C11-$D11-$E11) | H11: =IF($A11="","",IFERROR(ROUND($G11*INDEX(tblKurallar[deger_2025],MATCH("AKV-003",tblKurallar[kural_id],0)),2),0)) | I11: =IF($A11="","",IFERROR(MAX(0,$H11-$F11),0))
G12: =IF($A12="","",$B12+$C12-$D12-$E12) | H12: =IF($A12="","",IFERROR(ROUND($G12*INDEX(tblKurallar[deger_2025],MATCH("AKV-003",tblKurallar[kural_id],0)),2),0)) | I12: =IF($A12="","",IFERROR(MAX(0,$H12-$F12),0))
G13: =IF($A13="","",$B13+$C13-$D13-$E13) | H13: =IF($A13="","",IFERROR(ROUND($G13*INDEX(tblKurallar[deger_2025],MATCH("AKV-003",tblKurallar[kural_id],0)),2),0)) | I13: =IF($A13="","",IFERROR(MAX(0,$H13-$F13),0))
G14: =IF($A14="","",$B14+$C14-$D14-$E14) | H14: =IF($A14="","",IFERROR(ROUND($G14*INDEX(tblKurallar[deger_2025],MATCH("AKV-003",tblKurallar[kural_id],0)),2),0)) | I14: =IF($A14="","",IFERROR(MAX(0,$H14-$F14),0))
G15: =IF($A15="","",$B15+$C15-$D15-$E15) | H15: =IF($A15="","",IFERROR(ROUND($G15*INDEX(tblKurallar[deger_2025],MATCH("AKV-003",tblKurallar[kural_id],0)),2),0)) | I15: =IF($A15="","",IFERROR(MAX(0,$H15-$F15),0))
G16: =IF($A16="","",$B16+$C16-$D16-$E16) | H16: =IF($A16="","",IFERROR(ROUND($G16*INDEX(tblKurallar[deger_2025],MATCH("AKV-003",tblKurallar[kural_id],0)),2),0)) | I16: =IF($A16="","",IFERROR(MAX(0,$H16-$F16),0))
G17: =IF($A17="","",$B17+$C17-$D17-$E17) | H17: =IF($A17="","",IFERROR(ROUND($G17*INDEX(tblKurallar[deger_2025],MATCH("AKV-003",tblKurallar[kural_id],0)),2),0)) | I17: =IF($A17="","",IFERROR(MAX(0,$H17-$F17),0))
G18: =IF($A18="","",$B18+$C18-$D18-$E18) | H18: =IF($A18="","",IFERROR(ROUND($G18*INDEX(tblKurallar[deger_2025],MATCH("AKV-003",tblKurallar[kural_id],0)),2),0)) | I18: =IF($A18="","",IFERROR(MAX(0,$H18-$F18),0))
G19: =IF($A19="","",$B19+$C19-$D19-$E19) | H19: =IF($A19="","",IFERROR(ROUND($G19*INDEX(tblKurallar[deger_2025],MATCH("AKV-003",tblKurallar[kural_id],0)),2),0)) | I19: =IF($A19="","",IFERROR(MAX(0,$H19-$F19),0))
G20: =IF($A20="","",$B20+$C20-$D20-$E20) | H20: =IF($A20="","",IFERROR(ROUND($G20*INDEX(tblKurallar[deger_2025],MATCH("AKV-003",tblKurallar[kural_id],0)),2),0)) | I20: =IF($A20="","",IFERROR(MAX(0,$H20-$F20),0))
G21: =IF($A21="","",$B21+$C21-$D21-$E21) | H21: =IF($A21="","",IFERROR(ROUND($G21*INDEX(tblKurallar[deger_2025],MATCH("AKV-003",tblKurallar[kural_id],0)),2),0)) | I21: =IF($A21="","",IFERROR(MAX(0,$H21-$F21),0))
G22: =IF($A22="","",$B22+$C22-$D22-$E22) | H22: =IF($A22="","",IFERROR(ROUND($G22*INDEX(tblKurallar[deger_2025],MATCH("AKV-003",tblKurallar[kural_id],0)),2),0)) | I22: =IF($A22="","",IFERROR(MAX(0,$H22-$F22),0))
... G1004: =IF($A1004="","",$B1004+$C1004-$D1004-$E1004) | H1004: =IF($A1004="","",IFERROR(ROUND($G1004*INDEX(tblKurallar[deger_2025],MATCH("AKV-003",tblKurallar[kural_id],0)),2),0)) | I1004: =IF($A1004="","",IFERROR(MAX(0,$H1004-$F1004),0))

Sheet LISTELER
A1: LISTELER — Asgari Kurumlar Vergisi Simülasyon Motoru
A3: Doğrulama listeleri
A5: Yıllar | C5: Yorum A/B | E5: Evet/Hayır
A6: 2025 | C6: A | E6: Evet
A7: 2026 | C7: B | E7: Hayır
A8: 2027

Sheet AYARLAR
A1: AYARLAR — Asgari Kurumlar Vergisi Simülasyon Motoru
A3: Parametreler (tek kaynak)
A5: anahtar | B5: deger | C5: birim | D5: aciklama | E5: kaynak | F5: yururluk_tarihi | G5: dogrulama_tarihi | H5: kontrol
A6: hesapYili | B6: 2025 | C6: yıl | D6: Aktif hesap yılı | E6: Kullanıcı / GIRDI | F6: 01.01.2025 | G6: 10.08.2026 | H6: =IF(A6="","",IF(B6="","EKSİK","TAM"))
A7: raporTarihi | B7: 46244 | C7: tarih | D7: Rapor tarihi (sabit) | E7: Üretim | F7: 01.01.2025 | G7: 10.08.2026 | H7: =IF(A7="","",IF(B7="","EKSİK","TAM"))
A8: akv_tolerans | B8: 0.01 | C8: TL | D8: Vaka tutarlılık toleransı | E8: Uygulama notu | F8: 01.01.2025 | G8: 10.08.2026 | H8: =IF(A8="","",IF(B8="","EKSİK","TAM"))
A9: akv_farkEsik | B9: 100000 | C9: TL | D9: PANO fark uyarı eşiği | E9: İç politika | F9: 01.01.2025 | G9: 10.08.2026 | H9: =IF(A9="","",IF(B9="","EKSİK","TAM"))
A10: akv_senaryoIyi | B10: 0.9 | C10: çarpan | D10: İyimser matrah çarpanı | E10: Model varsayımı | F10: 01.01.2025 | G10: 10.08.2026 | H10: =IF(A10="","",IF(B10="","EKSİK","TAM"))
A11: akv_senaryoKotu | B11: 1.1 | C11: çarpan | D11: Kötümser matrah çarpanı | E11: Model varsayımı | F11: 01.01.2025 | G11: 10.08.2026 | H11: =IF(A11="","",IF(B11="","EKSİK","TAM"))
A12: akv_oranArtisPuan | B12: 0.01 | C12: oran | D12: M-SEN +1 puan | E12: Senaryo motoru | F12: 01.01.2025 | G12: 10.08.2026 | H12: =IF(A12="","",IF(B12="","EKSİK","TAM"))
A13: akv_tahminAlt | B13: 0.85 | C13: çarpan | D13: Tahmin alt bant | E13: Model varsayımı | F13: 01.01.2025 | G13: 10.08.2026 | H13: =IF(A13="","",IF(B13="","EKSİK","TAM"))
A14: akv_tahminUst | B14: 1.15 | C14: çarpan | D14: Tahmin üst bant | E14: Model varsayımı | F14: 01.01.2025 | G14: 10.08.2026 | H14: =IF(A14="","",IF(B14="","EKSİK","TAM"))
A15: akv_tornadoMatrah | B15: 1.05 | C15: çarpan | D15: Tornado matrah şoku | E15: Model varsayımı | F15: 01.01.2025 | G15: 10.08.2026 | H15: =IF(A15="","",IF(B15="","EKSİK","TAM"))
A16: akv_tornadoOdenen | B16: 0.95 | C16: çarpan | D16: Tornado ödenen şoku | E16: Model varsayımı | F16: 01.01.2025 | G16: 10.08.2026 | H16: =IF(A16="","",IF(B16="","EKSİK","TAM"))
A17: akv_yorumAIstisnaCarpan | B17: 0.5 | C17: çarpan | D17: Yorum A istisna çarpanı | E17: Belirsizlik A | F17: 01.01.2025 | G17: 10.08.2026 | H17: =IF(A17="","",IF(B17="","EKSİK","TAM"))
A18: akv_yuzdelikOran | B18: 0.9 | C18: oran | D18: Yüzdelik P90 | E18: İstatistik | F18: 01.01.2025 | G18: 10.08.2026 | H18: =IF(A18="","",IF(B18="","EKSİK","TAM"))
A19: akv_parmakIzi | B19: 36abc96f6d9001c2 | C19: metin | D19: Dosya parmak izi etiketi | E19: Üretim | F19: 01.01.2025 | G19: 10.08.2026 | H19: =IF(A19="","",IF(B19="","EKSİK","TAM"))
A20: dosya_surumu | B20: 1.0.0 | C20: metin | D20: Ürün sürümü | E20: ExcelArşiv | F20: 01.01.2025 | G20: 10.08.2026 | H20: =IF(A20="","",IF(B20="","EKSİK","TAM"))
A21: akv_girisBeklenen | B21: 9 | C21: adet | D21: Zorunlu giriş alanı sayısı | E21: Ürün mimarisi | F21: 01.01.2025 | G21: 10.08.2026 | H21: =IF(A21="","",IF(B21="","EKSİK","TAM"))
A22: akv_riskDusuk | B22: 15 | C22: puan | D22: Düşük risk skoru | E22: İç politika | F22: 01.01.2025 | G22: 10.08.2026 | H22: =IF(A22="","",IF(B22="","EKSİK","TAM"))
A23: akv_riskOrta | B23: 55 | C23: puan | D23: Orta risk skoru | E23: İç politika | F23: 01.01.2025 | G23: 10.08.2026 | H23: =IF(A23="","",IF(B23="","EKSİK","TAM"))
A24: akv_riskYuksek | B24: 85 | C24: puan | D24: Yüksek risk skoru | E24: İç politika | F24: 01.01.2025 | G24: 10.08.2026 | H24: =IF(A24="","",IF(B24="","EKSİK","TAM"))
A25: akv_riskEsikOran | B25: 0.5 | C25: oran | D25: Yüksek risk fark/asgari eşiği | E25: İç politika | F25: 01.01.2025 | G25: 10.08.2026 | H25: =IF(A25="","",IF(B25="","EKSİK","TAM"))
A26: akv_yilTaban | B26: 2024 | C26: yıl | D26: CHOOSE yıl tabanı (hesapYili−taban) | E26: Ürün mimarisi | F26: 01.01.2025 | G26: 10.08.2026 | H26: =IF(A26="","",IF(B26="","EKSİK","TAM"))
A27: akv_yuvarMax | B27: 10 | C27: adet | D27: ROUND basamak tavanı | E27: Ürün mimarisi | F27: 01.01.2025 | G27: 10.08.2026 | H27: =IF(A27="","",IF(B27="","EKSİK","TAM"))
A28: vaka_matrah_1 | B28: 10200000 | C28: TL | D28: Vaka1 matrah | E28: Tebliğ örneği | F28: 01.01.2025 | G28: 10.08.2026 | H28: =IF(A28="","",IF(B28="","EKSİK","TAM"))
A29: vaka_odenen_1 | B29: 800000 | C29: TL | D29: Vaka1 ödenen | E29: Tebliğ örneği | F29: 01.01.2025 | G29: 10.08.2026 | H29: =IF(A29="","",IF(B29="","EKSİK","TAM"))
A30: vaka_matrah_2 | B30: 10200000 | C30: TL | D30: Vaka2 matrah | E30: Tebliğ örneği | F30: 01.01.2025 | G30: 10.08.2026 | H30: =IF(A30="","",IF(B30="","EKSİK","TAM"))
A31: vaka_odenen_2 | B31: 1020000 | C31: TL | D31: Vaka2 ödenen | E31: Tebliğ örneği | F31: 01.01.2025 | G31: 10.08.2026 | H31: =IF(A31="","",IF(B31="","EKSİK","TAM"))
A32: vaka_matrah_3 | B32: 5000000 | C32: TL | D32: Vaka3 matrah | E32: Tebliğ örneği | F32: 01.01.2025 | G32: 10.08.2026 | H32: =IF(A32="","",IF(B32="","EKSİK","TAM"))
A33: vaka_odenen_3 | B33: 400000 | C33: TL | D33: Vaka3 ödenen | E33: Tebliğ örneği | F33: 01.01.2025 | G33: 10.08.2026 | H33: =IF(A33="","",IF(B33="","EKSİK","TAM"))
B35: Parametre satırları yukarıda; ad tanımları B kolonuna bağlı.
B37: Sürüm 1.0.0 | Şifre koruması: 1234 (formül alanları)

Sheet KILAVUZ
A1: KILAVUZ — Asgari Kurumlar Vergisi Simülasyon Motoru
A3: Karar kuralları
A5: • VERİ YOK — giriş tablosu boşsa hesap yapılmaz.
A6: • EK VERGİ YOK / UYGUN — ödenen KV ≥ asgari KV (fark = 0).
A7: • FARK HESAPLA / DİKKAT — ödenen KV < asgari KV; tamamlayıcı fark üretilir.
A9: Belirsizlik beyanları (M05)
A10: Bu nokta mevzuatta tartışmalıdır; dosya yorum A ve yorum B sonucunu yan yana gösterir: istisna_kirilim_sirasi
A12: Yorum A | B12: İstisnanın bir kısmı asgari matrah hesabında dikkate alınır (çarpan AYARLAR'da). Bu nokta mevzuatta tartışmalıdır; sonuç yorum B ile yan yana okunmalıdır.
A13: Yorum B | B13: İstisnanın tamamı matrahtan düşülür. Dosya her iki yorumun asgari KV sonucunu MOTOR'da üretir.
A15: Kullanım sırası
A16: GIRDI → KURALLAR (gerekirse) → MOTOR (inceleme) → SENARYO → VAKALAR → PANO → KANIT_RAPORU → AYARLAR.
A18: Sürüm 1.0.0 | Lisans: Tek kullanıcı | ExcelArşiv
