Workbook
Name raporTarihi: AYARLAR!$B$6
Name fam_yakitBirimFiyat: AYARLAR!$B$7
Name fam_amortismanTlKm: AYARLAR!$B$8
Name fam_sigortaYillik: AYARLAR!$B$9
Name fam_sigortaGunPay: AYARLAR!$B$10
Name fam_esikKmBasi: AYARLAR!$B$11
Name fam_esikBakimTl: AYARLAR!$B$12
Name fam_esikSaglik: AYARLAR!$B$13
Name fam_aylikCarpan: AYARLAR!$B$14
Name fam_senaryoTemkinli: AYARLAR!$B$15
Name fam_senaryoBaz: AYARLAR!$B$16
Name fam_senaryoIyimser: AYARLAR!$B$17
Name fam_tornadoOran: AYARLAR!$B$18
Name fam_yuzdelikOran: AYARLAR!$B$19
Name fam_percentileOran: AYARLAR!$B$20
Name fam_tahminCarpan: AYARLAR!$B$21
Name fam_olcekHedef: AYARLAR!$B$22
Name fam_kaliteTaban: AYARLAR!$B$23
Name fam_kaliteCeza: AYARLAR!$B$24
Name fam_kaliteSapma: AYARLAR!$B$25
Name fam_dosyaSurumu: AYARLAR!$B$26
Name fam_firmaUnvan: AYARLAR!$B$27
Name fam_alarmEsikMetin: AYARLAR!$B$28
Name fam_doluKayit: AYARLAR!$I$32
Name fam_toplamKm: AYARLAR!$I$33
Name fam_toplamMaliyet: AYARLAR!$I$34
Name fam_kmBasiMaliyet: AYARLAR!$I$35
Name fam_yakitToplam: AYARLAR!$I$36
Name fam_bakimToplam: AYARLAR!$I$37
Name fam_amortToplam: AYARLAR!$I$38
Name fam_sigortaToplam: AYARLAR!$I$39
Name fam_saglikSkor: AYARLAR!$I$40
Name fam_alarmAdet: AYARLAR!$I$41
Name fam_yetimAdet: AYARLAR!$I$42
Name fam_gunlukKmOrt: AYARLAR!$I$43
Name fam_aylikMaliyetTrend: AYARLAR!$I$44
Name fam_kmBasiSapma: AYARLAR!$I$45
Name fam_tornadoZirve: AYARLAR!$I$46
Name fam_senaryoKarsilastirma: AYARLAR!$I$47
Name fam_hhi: AYARLAR!$I$48
Name fam_kaliteSkor: AYARLAR!$I$49
Name fam_senaryoMotor: AYARLAR!$I$50
Name fam_tahminAralik: AYARLAR!$I$51
Name fam_yuzdelikP90: AYARLAR!$I$52
Name fam_sezonsalTrend: AYARLAR!$I$53
Name fam_alarmListesi: AYARLAR!$I$54
Name fam_kararKapi: AYARLAR!$I$55
Name fam_kararGerekce: AYARLAR!$I$56
Name fam_sonrakiKimlik: AYARLAR!$I$57
Name fam_yorumGunluk: AYARLAR!$I$60
Name fam_yorumAylik: AYARLAR!$I$61
Name fam_yorumSapma: AYARLAR!$I$62
Name fam_yorumTornado: AYARLAR!$I$63
Name fam_yorumSenaryo: AYARLAR!$I$64
Name fam_yorumHhi: AYARLAR!$I$65
Name fam_yorumKalite: AYARLAR!$I$66
Name fam_yorumSenMotor: AYARLAR!$I$67
Name fam_yorumTahmin: AYARLAR!$I$68
Name fam_yorumP90: AYARLAR!$I$69
Name ListeEvetHayir: LISTELER!$A$7:$A$8

Sheet 00_BASLANGIC
A1: EXCELARŞİV KARAR SİSTEMİ v15.1 — ÜRETİM REFERANSI
A3: Konu | B3: Bağlayıcı Standart
A4: Amaç | B4: Kanıta dayalı, hatada kapalı çalışan Excel üretim ve denetim sistemi
A5: Öncelik | B5: Kullanıcının açık iş talebi ve gerçek kullanım senaryosu
A6: Ana akış | B6: Uygunluk → Yönetişim → Sözleşmeler → Üretim → Test → Kanıt → Kullanıcı Kabulü → Yayın
A7: Yayın ilkesi | B7: Üst aşamada hata varsa alt aşama GEÇTİ üretilemez
A8: Kullanıcı kabulü | B8: Excel masaüstü görünümü test edilmediyse DIŞ_KABUL_GEREKLİ
A9: Nihai yayın | B9: Yalnız uygulanabilir modüller GEÇTİ veya gerekçeli UYGULANMAZ
A10: Ticari ayrım | B10: Ekonomik olarak savunulabilir fiyat, gerçek pazar kabulü ile aynı değildir
A11: Karmaşıklık | B11: Karar değeri, eklenen karmaşıklığın maliyetinden büyük olmalıdır
A12: Excel sınırı | B12: Veritabanı, kurumsal yetkilendirme, değiştirilemez kayıt sistemi veya gerçek zamanlı olay platformu değildir
A13: Dil standardı | B13: Kullanıcıya görünen tüm sayfa, tablo, başlık, açıklama, uyarı ve karar metinleri saf Türkçe olmalıdır
A14: Muhasebe standardı | B14: Finansal ürünlerde Türkiye Tekdüzen Hesap Planı ve Türk muhasebe kullanım alışkanlıkları esas alınır
... A33: Muhasebe | B33: Türkiye Tekdüzen Hesap Planı ve Türk muhasebe/işletme düşünce yapısı esas alınır.

Sheet PANO
A1: ☰ PANO
B2: FILO ARAÇ MALIYET KOMUTASI | L2: Dönem: 2026 / Tam ▼ | M2: ★ DOĞRULANMIŞ
B3: Hedef Kullanıcı: Filo yöneticisi, lojistik operasyon, saha şofi koordinatörü, CFO · 2026 Q3 Denetim Standardı
B5: GÜNLÜK KM ORTALAMASI | D5: KONSOLİDE | E5: AYLIK MALIYET TREND | G5: KONTROL | H5: NET OPERASYONEL MARJ | J5: GÜVENLİ | K5: SİSTEM GÜVEN SKORU | M5: DENETLENDİ
B7: =GİRDİLER!E17 | E7: =B7*0.22 | H7: =B7-E7 | K7: =EĞER(E7>0; YUVARLA(B7/E7; 2); 0)
B9: ↑ %14.2 konsolide canlı veri bağlantısı | E9: ● 8 Kalem nakit karşılığı: bloke | H9: ██████████░░░░░ %78.0 NET MARJ | K9: ✓ İDEAL karşılama rasyosu
B11: FILO ARAÇ MALIYET KOMUTASI — DÖNEMSEL İCRA VE PROJEKSİYON | F11: +%32 Verim | H11: KONSOLİDE OPERASYON VE KARAR MATRİSİ
B12: Kümülatif Hacim vs. Operasyonel Maliyet ve Net Kâr Eğilimi | H12: Anlık Hesaplama Sonuçları, Dinamik Formül Çıktıları ve Durum Puanlaması
B14: Dönem | C14: Aktif Hacim | D14: Maliyet/Yük | E14: Hedef | H14: PARAMETRE / KALEM | I14: ANA TUTAR | J14: FARK / MARJ | K14: VADE | L14: KONTROL DURUMU
B15: D1 | C15: 65 | D15: 45 | E15: 60 | H15: Dönemlik Kümülatif Bakiye | I15: =B7*0.45 | J15: =B7*0.05 | K15: 12 Ay | L15: ✓ DÜZENLİ
B16: D2 | C16: 78 | D16: 48 | E16: 70 | H16: Kritik Eşik Güvenlik Tamponu | I16: =B7*0.30 | J16: =B7*0.03 | K16: 24 Ay | L16: ★ AVANTAJ
B17: D3 | C17: 85 | D17: 55 | E17: 80 | H17: Operasyonel Net Fark | I17: =B7*0.15 | J17: =B7*0.02 | K17: 8 Ay | L17: ● YAKLAŞAN
B18: D4 | C18: 75 | D18: 42 | E18: 75 | H18: Rezerv ve Likit Dağılım | I18: =B7*0.10 | J18: =B7*0.01 | K18: 16 Ay | L18: ✓ TAM UYUM
B19: D5 | C19: 90 | D19: 40 | E19: 85 | H19: KONSOLİDE SİSTEM TOPLAMI | I19: =TOPLA(I15:I18) | J19: =TOPLA(J15:J18) | L19: TAM DOĞRULANDI (0 HATA)
B20: D6 | C20: 96 | D20: 32 | E20: 92
B22: KONSOLİDE PAY VE AĞIRLIK | F22: LİKİDİTE RİSKİ & ERKEN UYARI SİNYALLERİ | K22: KARAR MOTORU
B23: ■ Ana Segment (%42) | F23: Nakit Açığı Riski (30 Gün) | I23: 0.00 TL (Sıfır Risk) | K23: STRATEJİK VERİMLİLİK FIRSATI
B24: ■ İkincil Grup (%30) | F24: Tahsilat Gecikme Toleransı | I24: 48 Gün Güvenli Eşik | K24: Operasyonel süreç optimizasyonu ile kârlılık artış potansiyeli tespit edildi.
B25: ■ Destek Birimi (%15) | F25: ██████████████████████████████████████ Güvenli Bölge (%100)
B26: ■ Rezervler (%13) | F26: ✓ 90 GÜNLÜK PROJEKSİYONDA NAKİT SIKIŞIKLIĞI TESPİT EDİLMEDİ | K26: STRATEJİ REÇETESİNİ İNCELE >

Sheet GİRDİLER
A1: ☰ PANO
B3: 🔍 FILO ARAÇ MALIYET KOMUTASI — Kayıt veya hesap ara... | G3: TOPLAM: 1.450 KAYIT | I3: HATALI HÜCRE: 0 ADET
B5: TARİH | C5: REFERANS NO | D5: İŞLEM AÇIKLAMASI VE DETAY | E5: BRÜT TUTAR (₺) | F5: KDV ORANI | G5: NET TUTAR (₺) | H5: HESAP / CARİ | I5: DURUM
B6: 12.10.2026 | C6: TR-0428-A | D6: Operasyonel ana kalem tahmini | E6: 845200 | F6: 0.2 | G6: =E6/(1+F6) | H6: Vadesiz Ticari | I6: ONAYLANDI
B7: 14.10.2026 | C7: TR-0429-B | D7: Operasyonel çıkış/maliyet tahmini | E7: 1240000 | F7: 0.2 | G7: =E7/(1+F7) | H7: Tedarikçi Havuzu | I7: BEKLEMEDE
B8: 18.10.2026 | C8: TR-0430-C | D8: Ödeme takvimi tahakkuku | E8: 620500 | F8: 0.1 | G8: =E8/(1+F8) | H8: Kısa Vade Tahakkuk | I8: ONAYLANDI
B9: 21.10.2026 | C9: TR-0431-D | D9: Müşteri işlem tahmini | E9: 415000 | F9: 0.2 | G9: =E9/(1+F9) | H9: Müşteri Alacağı | I9: ONAYLANDI
B10: 25.10.2026 | C10: TR-0432-E | D10: Ana operasyon tahmini | E10: 980400 | F10: 0.2 | G10: =E10/(1+F10) | H10: Vadesiz Ticari | I10: ONAYLANDI
B11: 28.10.2026 | C11: TR-0433-F | D11: Kredi/taksit karşılığı | E11: 1850000 | F11: 0.2 | G11: =E11/(1+F11) | H11: Finansman Havuzu | I11: BLOKE
B12: 02.11.2026 | C12: TR-0434-G | D12: Sabit gider ve yönetim notları | E12: 740000 | F12: 0.2 | G12: =E12/(1+F12) | H12: Genel Yönetim | I12: ONAYLANDI
B13: 05.11.2026 | C13: TR-0435-H | D13: Operasyonel ana kalem tahmini | E13: 520800 | F13: 0.2 | G13: =E13/(1+F13) | H13: Vadesiz Ticari | I13: ONAYLANDI
B14: 09.11.2026 | C14: TR-0436-I | D14: Müşteri işlem tahmini | E14: 1120000 | F14: 0.2 | G14: =E14/(1+F14) | H14: Müşteri Alacağı | I14: ONAYLANDI
B15: 12.11.2026 | C15: TR-0437-J | D15: Operasyonel çıkış tahmini | E15: 890000 | F15: 0.2 | G15: =E15/(1+F15) | H15: Tedarikçi Havuzu | I15: ONAYLANDI
B17: SAYFA TOPLAMI (10 / 1.450 KAYIT) | E17: =TOPLA(E6:E15)

Sheet YÖNETİM_RAPORU
A1: ☰ PANO
B2: FILO ARAÇ MALIYET KOMUTASI — NİHAİ KARAR VE DEĞERLEME
B3: Yönetim Kurulu ve İcra Komitesi için Otomatik Finansal Stres Testi Raporu · Filo yöneticisi, lojistik operasyon, saha şofi koordinatörü, CFO
B4: DÖNEM: 2026 Q3 · DENETİM PROTOKOLÜ: ISO/VUK/IFRS UYUMLU · DURUM: ONAYLANDI
B6: SENARYO A: KÖTÜMSER (STRES TESTİ -%20) | H6: SENARYO B: BAZ MODEL (HEDEFLENEN)
B8: Ciro / Hacim Düşüşü: | E8: -%20.0 (Kriz Eşiği) | H8: Ciro / Hacim Gerçekleşmesi: | K8: %100.0 (Tam Bütçe)
B9: Beklenen Net Kâr / Getiri: | E9: =PANO!B7*0.8*0.22 | H9: Beklenen Net Kâr / Getiri: | K9: =PANO!H7
B10: Minimum Nakit Tamponu: | E10: =PANO!E7*0.75 | H10: Serbest Nakit Akımı: | K10: =PANO!H7*0.75
B11: Likidite Karşılama Oranı: | E11: =YUVARLA(PANO!B7*0.8/PANO!E7; 2) | H11: Yatırım Geri Dönüşü (ROI): | K11: %38.4 Yıllık
B14: STRES SENARYOSUNDA DAHİ İFLAS RİSKİ YOK | H14: OPTİMUM İCRA VE PLANLAMA REÇETESİ
B17: YÖNETİM KARAR MATRİSİ VE UYGULAMA REÇETESİ
B19: ● Öncelik 1: Acil Likidite ve Borç Servis Planlaması
B20: Sistemde hesaplanan vade günlerine sadık kalınarak nakit blokajı 3 gün önceden hazır edilmelidir.
B21: ● Öncelik 2: Formül Doğrulama ve Çapraz Sağlama
B22: Tüm hücreler kilitli formül korumasında olup girdi sayfalarında sıfır döngüsel başvuru (circular ref) garantilidir.
B23: ● Öncelik 3: Resmi Mevzuat ve Vergi Kalkanı Entegrasyonu
B24: 2026 güncel vergi dilimleri, amortisman ve SGK teşvik parametreleri tam otomatik yansıtılmaktadır.
B25: ● Öncelik 4: Yönetici İmzası ve Rapor Paylaşımı
B26: Tek tuşla PDF ve A4 çıktı formatına tam uyumlu sayfa yapısı kurgulanmıştır.

Sheet 01_YURUTME_CEKIRDEGI
A1: YÜRÜTME ÇEKİRDEĞİ — ZORUNLU ÜRETİM SIRASI
A3: Adım | B3: Modül | C3: Tetikleyici | D3: Zorunlu Kanıt | E3: GEÇTİ Kuralı | F3: Hata Durumu | G3: Sonraki Aşama
A4: 1 | B4: Excel Uygunluğu | C4: Her yeni model | D4: UYGUNLUK_KARARI | E4: Excel'in rolü açık | F4: HATA / BLOKE | G4: Yönetişim
A5: 2 | B5: Yönetişim | C5: Her model | D5: Risk seviyesi + etki girdileri | E5: Seviye hesaplandı | F5: BLOKE | G5: Sözleşmeler
A6: 3 | B6: Türk Muhasebe Eşlemesi | C6: Finansal model | D6: THP hesap eşleme tablosu | E6: Kritik satırlar THP ile uyumlu | F6: HATA | G6: Sözleşmeler
A7: 4 | B7: Veri ve Anlam Sözleşmeleri | C7: Girdi/KPI varsa | D7: Veri + KPI sözleşmeleri | E7: Kapsam %100 | F7: HATA | G7: Üretim
A8: 5 | B8: Üretim | C8: Sözleşmeler GEÇTİ | D8: Çalışan Excel | E8: Tek gerçek kaynak korunmuş | F8: HATA | G8: Testler
A9: 6 | B9: Görsel/Kullanım Katmanı | C9: Motor hazır | D9: Başlıklar + renk + grafik + yönlendirme | E9: Tüm kullanıcı sayfaları standarda uygun | F9: HATA | G9: Testler
A10: 7 | B10: Testler | C10: Üretim tamam | D10: Formül/OOXML/kimlik/oracle/golden/metamorfik | E10: Uygulanabilir hard gate'ler GEÇTİ | F10: HATA | G10: Kanıt
A11: 8 | B11: Hata-Kontrol Tutarlılığı | C11: Test sonucu var | D11: Hata taraması + kontrol sonuçları | E11: Formül hatası varken GEÇTİ yok | F11: HATA | G11: Kanıt
A12: 9 | B12: Kanıt | C12: Test sonucu var | D12: Makine okunur artefakt + özet | E12: Kanıt fiziksel ve tutarlı | F12: HATA | G12: Kullanıcı Kabulü
A13: 10 | B13: Kullanıcı Kabulü | C13: Kritik görevler | D13: Gerçek ekran davranışı | E13: Kritik görevler %100 | F13: DIŞ_KABUL_GEREKLİ | G13: Ticari
A14: 11 | B14: Ticari Değer | C14: Ürün satılacaksa | D14: ROI + demo + kanıt paketi | E14: Ekonomik değer kanıtlı | F14: UYARI / HATA | G14: Pazar Doğrulama
A15: 12 | B15: Pazar Doğrulama | C15: Pazar iddiası varsa | D15: Ücretli satış/pilot/fiyat kabul kanıtı | E15: Gerçek fiyat kabul kanıtı | F15: UYGULANMAZ / HATA | G15: Yayın

Sheet 02_KONTROL_LISTESI
A1: NİHAİ KONTROL LİSTESİ — KANITSIZ GEÇİŞ YOK
A3: Kontrol No | B3: Kontrol | C3: Beklenen | D3: Zorunlu Kapı? | E3: Sonuç
A4: K01 | B4: Kullanıcının açık talebi öncelikli mi? | C4: Evet | D4: EVET
A5: K02 | B5: Mevcut yapı, formüller ve tek gerçek kaynak korunuyor mu? | C5: Evet, değişiklik gerekçeli | D5: EVET
A6: K03 | B6: Üst aşama HATA ise alt aşama GEÇTİ engelleniyor mu? | C6: Evet | D6: EVET
A7: K04 | B7: Kanıt fiziksel çıktı ve içerik doğrulaması içeriyor mu? | C7: Evet | D7: EVET
A8: K05 | B8: Excel GUI erişimi olmadan kullanıcı görünümü GEÇTİ yazılıyor mu? | C8: Hayır | D8: EVET
A9: K06 | B9: NİHAİ yalnız GEÇTİ / gerekçeli UYGULANMAZ ile mi? | C9: Evet | D9: EVET
A10: K07 | B10: Ekonomik fiyat savunusu pazar doğrulamasından ayrılmış mı? | C10: Evet | D10: EVET
A11: K08 | B11: Prestij için gereksiz modül var mı? | C11: Hayır | D11: HAYIR
A12: K09 | B12: Excel sınırları açık mı? | C12: Evet | D12: EVET
A13: K10 | B13: Teknik kaynak korunuyor mu? | C13: Evet | D13: EVET
A14: K11 | B14: Kullanıcıya görünen tüm metinler Türkçe mi? | C14: Evet | D14: EVET
A15: K12 | B15: Her kullanıcı sayfasında üst başlık var mı? | C15: Evet | D15: EVET
... A34: K31 | B34: Premium vitrin, altyapı kadar güçlü ve satış fiyatını destekleyecek seviyede mi? | C34: Evet | D34: EVET

Sheet 03_GORSEL_TASARIM
A1: GÖRSEL TASARIM VE PREMIUM EXCEL STANDARDI
A3: Alan | B3: Zorunlu Kural | C3: Uygulama | D3: Yasak | E3: Kontrol | F3: Durum
A4: Sayfa başlığı | B4: Her kullanıcı sayfasının en üstünde tek ve açık sayfa başlığı | C4: A1'den başlayan koyu lacivert başlık bandı | D4: Başlıksız sayfa | E4: Başlık kapsama = %100 | F4: ZORUNLU
A5: Sekme renkleri | B5: Sayfalar işlevine göre renk kodlanır | C5: Girdi=mavi, hesap=gri, rapor=lacivert, kontrol=kırmızı, kılavuz=altın | D5: Rastgele renk | E5: Renk semantiği tutarlı | F5: ZORUNLU
A6: Kolon düzeni | B6: Veri blokları bitişik kolonlarda ilerler | C6: Gereksiz boş kolon bırakma; yalnız gerçek bölüm ayrımı varsa kontrollü boşluk | D6: A:C veri, D boş, E:F veri gibi parçalı yapı | E6: Boş kolon taraması | F6: ZORUNLU
A7: Girdi hücreleri | B7: Kullanıcının değiştireceği alan açıkça görünür | C7: Açık sarı dolgu + mavi yazı | D7: Formülle aynı görünüm | E7: Girdi/formül ayrımı | F7: ZORUNLU
A8: Formüller | B8: Hesap hücreleri kullanıcı girdisinden ayrılır | C8: Siyah yazı; sayfalar arası bağlantı yeşil yazı | D8: Hard-code gizleme | E8: Formül sınıfı kontrolü | F8: ZORUNLU
A9: Grafik sayısı | B9: Yönetici ekranında en fazla 3 ana karar grafiği | C9: Trend, karşılaştırma, köprü/dağılım; iş kararına bağlı | D9: Grafik kalabalığı | E9: Grafik başına karar sorusu | F9: ZORUNLU
A10: Grafik stili | B10: Kurumsal ve yüksek okunabilirlik | C10: Beyaz zemin, ince gridline, tek vurgu rengi, açık birim/başlık | D10: 3B, gölge, neon, gökkuşağı renkleri | E10: Görsel inceleme | F10: ZORUNLU
A11: Grafik başlığı | B11: Grafik 'neyi' değil 'ne anlama geldiğini' söyler | C11: Örn: 'Nakit 2028'de kritik eşiğin altına iniyor' | D11: 'Nakit Grafiği' gibi anlamsız başlık | E11: Başlık karar testi | F11: ZORUNLU
A12: Birimler | B12: Tüm finansal görsellerde birim açık | C12: TL, bin TL, milyon TL, %, gün, x | D12: Birim belirsizliği | E12: Birim kapsama %100 | F12: ZORUNLU
A13: Sıfır/negatif | B13: Finansal format standardı | C13: Sıfır='-', negatif kırmızı parantez | D13: -500 veya 0,00 kalabalığı | E13: Format kontrolü | F13: ZORUNLU
A14: Yazı tipi | B14: Tek aile | C14: Aptos veya Segoe UI | D14: Karışık font | E14: Tek font kontrolü | F14: ZORUNLU
... A22: Premium vitrin | B22: Görsel kalite ürün değerinin zorunlu parçasıdır | C22: Kaliteli grafik, gerçek KPI kartı, finansal hiyerarşi, tab rengi, fonksiyonel navigasyon | D22: Sadece doğru hesap yapıp çıplak/varsayılan Excel görünümü bırakmak | E22: Görsel release incelemesi | F22: ZORUNLU

Sheet 04_MUHASEBE_THP
A1: TÜRKİYE MUHASEBE VE TEKDÜZEN HESAP PLANI STANDARDI
A3: Konu | B3: Zorunlu Standart | C3: Örnek Türkçe Ad | D3: THP / Mantık | E3: Hata Riski | F3: Kontrol
A4: Dil | B4: Kullanıcıya görünen finansal terimler Türkçe | C4: Hasılat, Satışların Maliyeti, Brüt Kâr, Faaliyet Giderleri | D4: Türk işletme kullanımına uygun | E4: İngilizce jargon | F4: Terminoloji taraması
A5: Gelir Tablosu | B5: Türk sunum sırası kullanılır | C5: Net Satışlar → Satışların Maliyeti → Brüt Kâr → Faaliyet Giderleri → Faaliyet Kârı | D5: 600/610/611; 620-623; 63x | E5: Yanlış sınıflama | F5: Hesap eşleme
A6: Bilanço | B6: Dönen/Duran Varlık ve Kısa/Uzun Vadeli Yükümlülük ayrımı | C6: Hazır Değerler, Ticari Alacaklar, Stoklar, Mali Borçlar | D6: 1xx / 2xx / 3xx / 4xx / 5xx | E6: Vade sınıfı hatası | F6: Bilanço eşitliği
A7: Nakit Akışı | B7: İşletme/Yatırım/Finansman nakit akışları ayrılır | C7: Faaliyetlerden Nakit, Yatırım Harcamaları, Finansman Nakit Akışı | D7: Dolaylı/doğrudan yöntem açık seçilir | E7: Kâr = nakit sanılması | F7: Nakit devri
A8: Ticari Alacaklar | B8: Cari ve vade mantığı korunur | C8: 120 Alıcılar | D8: 120 | E8: Tahakkuk/nakit karışması | F8: Alacak devir kontrolü
A9: Ticari Borçlar | B9: Tedarikçi borcu ayrı izlenir | C9: 320 Satıcılar | D9: 320 | E9: Gider/ödeme karışması | F9: Borç devir kontrolü
A10: Kasa/Banka | B10: Hazır değerler ayrı izlenir | C10: 100 Kasa, 102 Bankalar | D10: 100 / 102 | E10: Virmanla toplam nakdin değişmesi | F10: Virman değişmezi
A11: Stok | B11: Dikeye uygun stok türü | C11: 150 İlk Madde ve Malzeme, 153 Ticari Mallar | D11: 15x | E11: Maliyet ve stok hareketinin kopması | F11: Stok devri
A12: Maddi Duran Varlık | B12: Yatırım harcaması ve amortisman bağlantılı | C12: 253 Tesis Makine Cihazlar, 255 Demirbaşlar, 257 Birikmiş Amortismanlar | D12: 25x | E12: Yatırım/gider karışması | F12: Net defter değeri devri
A13: Mali Borçlar | B13: Kısa/uzun vadeli borç ayrımı | C13: 300 Banka Kredileri / 400 Banka Kredileri | D13: 300 / 400 | E13: Vade sınıfı yanlış | F13: Borç devri
A14: Özkaynak | B14: Sermaye ve geçmiş yıl kârları ayrı | C14: 500 Sermaye, 570 Geçmiş Yıllar Kârları, 590 Dönem Net Kârı | D14: 5xx | E14: Net kâr bağının kopması | F14: Özkaynak devri
... A18: İstisna | B18: TFRS özel ürün varsa fark açık yazılır | C18: Tekdüzen raporlama ≠ TFRS finansal tablo sunumu | D18: Amaç belirtilir | E18: Standartları karıştırma | F18: Model amacı kontrolü

Sheet 05_KARAR_SATIS
A1: KARAR, GÜVEN VE SATIŞA HAZIRLIK STANDARDI
A3: Alan | B3: Müşteri Sorusu | C3: Zorunlu Ürün Davranışı | D3: Kanıt | E3: Başarısızlık Durumu | F3: Kapı
A4: 5 saniye | B4: Bu ürün neyi çözüyor? | C4: İlk ekranda hedef kullanıcı + pahalı problem + sonuç görünür | D4: Başlık + alt mesaj + gerçek ekran | E4: Ürün yalnız teknik isim | F4: HATA
A5: Acı | B5: Sorun bana neye mal oluyor? | C5: Mümkünse müşterinin kendi verisiyle parasal/zaman etkisi hesaplanır | D5: ROI/acı hesaplama yöntemi | E5: Uydurma tasarruf | F5: HATA
A6: Karar | B6: Bu bilgiyle ne yapacağım? | C6: Her kritik KPI aksiyona bağlanır | D6: KARAR_KUYRUGU | E6: Sadece rapor | F6: HATA
A7: Güven | B7: Bu sayıya neden inanayım? | C7: Kaynak, formül mantığı, kontrol ve son doğrulama görünür | D7: Kontroller + kaynak izi + sürüm | E7: Prestij kelimesi | F7: HATA
A8: Referans | B8: Müşteri yorumu yoksa ne göstereceğim? | C8: Önce/Sonra + Karar Vakası + Hata Önleme Vakası üretilir | D8: Demo/örnek çıktı | E8: Kanıtsız iddia | F8: HATA
A9: Senaryo | B9: Ne olursa işler bozulur? | C9: Baz/Aşağı/Yukarı veya uygun stres senaryosu | D9: Senaryo karşılaştırma | E9: Dekoratif senaryo | F9: HATA
A10: Ters stres | B10: Hangi eşikte karar kırılır? | C10: En az bir kritik sürücü için kırılma eşiği | D10: Kırılma eşiği tablosu | E10: Sadece +/- %10 | F10: UYARI/HATA
A11: Hata tutarlılığı | B11: Formül hata verirse ne olur? | C11: Kontrol GEÇTİ veremez; BLOKE/HATA üretir | D11: Hata taraması | E11: Hata + GEÇTİ birlikte | F11: HATA
A12: Karar motoru | B12: Ne oldu, neden oldu? | C12: Sorun + neden + parasal etki + aksiyon + son tarih | D12: Karar tablosu | E12: Boş sayfa / isim düzeyi modül | F12: HATA
A13: Yönetici özeti | B13: 5 saniyede ne görmeliyim? | C13: Bugün / ne değişti / ne bozulacak / neden / ne yapmalıyım / güven | D13: Yönetici özeti ekranı | E13: KPI kutusu yığını | F13: HATA
A14: Teklif | B14: Neden satın almalıyım? | C14: Dosya özellikleri yerine sonuç ve kaçınılan maliyet sunulur | D14: Ürün sayfası kanıt eşlemesi | E14: Özellik listesiyle satış | F14: HATA
... A19: Pazar kanıtı | B19: Piyasa gerçekten ödüyor mu? | C19: Satış/pilot/LOI/fiyat kabulü olmadan pazar doğrulandı yazılmaz | D19: Gerçek işlem kanıtı | E19: Tahmini talep = satış kabulü | F19: HATA

Sheet KAPAK
A1: KAPAK — Filo Araç Maliyet Komutası
A3: Filo Araç Maliyet Komutası
A4: Araç filosunda km başı gerçek maliyeti yakıt + bakım + amortisman + sigorta kalemleriyle hesaplar; saha günlük girişi ≤6 alan; varlık sağlık skoru ve alarm kuyruğu üretir; UYGUN / DİKKAT / KRİTİK / VERİ YOK kararı verir.
A6: Bu ürün ne sağlar?
A7: • Km başı gerçek maliyet: yakıt + bakım + amortisman + sigorta
A8: • Günlük saha girişi en fazla 6 alan — 30 saniye hedefi
A9: • Varlık sağlık skoru formülle veriden türer (sabit skor yok)
A10: • 12 aylık sezonsal maliyet zinciri ve alarm eşiği kuyruğu
A11: • Makrosuz, çevrimdışı; telematik bağı yok
A13: Kimler için?
A14: • Saha / şoför koordinatörü — günlük km-yakıt-bakım satırı
A15: • Filo yöneticisi — km başı maliyet ve karar panosu
... A21: Sürüm 1.0.0 | Kod: FAM-PRO | Lisans: Tek kullanıcı | ExcelArşiv

Sheet VARLIKLAR
A1: VARLIKLAR — Filo Araç Maliyet Komutası
A3: Araç kartları — her varlığın tek kimliği vardır
A4: Sonraki Kimlik | B4: =fam_sonrakiKimlik
A5: VarlikId | B5: PlakaAd | C5: Tip | D5: YakitTuru | E5: TuketimLt100km | F5: AmortismanTlKm | G5: SigortaYillikTl | H5: Aktif | I5: ToplamKm | J5: ToplamMaliyet | K5: OrtKmBasi | L5: SaglikSkor
A6: ARC-00001 | B6: Ford Transit 350 | C6: Panelvan | D6: Dizel | E6: 9.5 | F6: 1.85 | G6: 42000 | H6: EVET | I6: =IF($A6="","",SUMIF(tblGunluk[VarlikId],$A6,tblGunluk[Km_km])) | J6: =IF($A6="","",SUMIF(tblGunluk[VarlikId],$A6,tblGunluk[FormulToplamTl])) | K6: =IF($A6="","",IFERROR(SUMIF(tblGunluk[VarlikId],$A6,tblGunluk[FormulToplamTl])/SUMIF(tblGunluk[VarlikId],$A6,tblGunluk[Km_km]),0)) | L6: =IF($A6="","",MAX(0,MIN(100,fam_kaliteTaban-IF($K6>fam_esikKmBasi,fam_kaliteCeza,0)-COUNTIFS(tblGunluk[VarlikId],$A6,tblGunluk[AlarmBayrak],"ALARM")*fam_kaliteSapma-IF($H6="HAYIR",fam_kaliteCeza,0))))
A7: ARC-00002 | B7: Mercedes Sprinter | C7: Panelvan | D7: Dizel | E7: 10.2 | F7: 2.1 | G7: 48000 | H7: EVET | I7: =IF($A7="","",SUMIF(tblGunluk[VarlikId],$A7,tblGunluk[Km_km])) | J7: =IF($A7="","",SUMIF(tblGunluk[VarlikId],$A7,tblGunluk[FormulToplamTl])) | K7: =IF($A7="","",IFERROR(SUMIF(tblGunluk[VarlikId],$A7,tblGunluk[FormulToplamTl])/SUMIF(tblGunluk[VarlikId],$A7,tblGunluk[Km_km]),0)) | L7: =IF($A7="","",MAX(0,MIN(100,fam_kaliteTaban-IF($K7>fam_esikKmBasi,fam_kaliteCeza,0)-COUNTIFS(tblGunluk[VarlikId],$A7,tblGunluk[AlarmBayrak],"ALARM")*fam_kaliteSapma-IF($H7="HAYIR",fam_kaliteCeza,0))))
A8: ARC-00003 | B8: Fiat Ducato | C8: Kamyonet | D8: Dizel | E8: 11 | F8: 1.7 | G8: 36000 | H8: EVET | I8: =IF($A8="","",SUMIF(tblGunluk[VarlikId],$A8,tblGunluk[Km_km])) | J8: =IF($A8="","",SUMIF(tblGunluk[VarlikId],$A8,tblGunluk[FormulToplamTl])) | K8: =IF($A8="","",IFERROR(SUMIF(tblGunluk[VarlikId],$A8,tblGunluk[FormulToplamTl])/SUMIF(tblGunluk[VarlikId],$A8,tblGunluk[Km_km]),0)) | L8: =IF($A8="","",MAX(0,MIN(100,fam_kaliteTaban-IF($K8>fam_esikKmBasi,fam_kaliteCeza,0)-COUNTIFS(tblGunluk[VarlikId],$A8,tblGunluk[AlarmBayrak],"ALARM")*fam_kaliteSapma-IF($H8="HAYIR",fam_kaliteCeza,0))))
A9: ARC-00004 | B9: VW Crafter | C9: Panelvan | D9: Dizel | E9: 9.8 | F9: 2 | G9: 45000 | H9: EVET | I9: =IF($A9="","",SUMIF(tblGunluk[VarlikId],$A9,tblGunluk[Km_km])) | J9: =IF($A9="","",SUMIF(tblGunluk[VarlikId],$A9,tblGunluk[FormulToplamTl])) | K9: =IF($A9="","",IFERROR(SUMIF(tblGunluk[VarlikId],$A9,tblGunluk[FormulToplamTl])/SUMIF(tblGunluk[VarlikId],$A9,tblGunluk[Km_km]),0)) | L9: =IF($A9="","",MAX(0,MIN(100,fam_kaliteTaban-IF($K9>fam_esikKmBasi,fam_kaliteCeza,0)-COUNTIFS(tblGunluk[VarlikId],$A9,tblGunluk[AlarmBayrak],"ALARM")*fam_kaliteSapma-IF($H9="HAYIR",fam_kaliteCeza,0))))
A10: ARC-00005 | B10: Isuzu NPR | C10: Kamyon | D10: Dizel | E10: 14.5 | F10: 2.4 | G10: 55000 | H10: EVET | I10: =IF($A10="","",SUMIF(tblGunluk[VarlikId],$A10,tblGunluk[Km_km])) | J10: =IF($A10="","",SUMIF(tblGunluk[VarlikId],$A10,tblGunluk[FormulToplamTl])) | K10: =IF($A10="","",IFERROR(SUMIF(tblGunluk[VarlikId],$A10,tblGunluk[FormulToplamTl])/SUMIF(tblGunluk[VarlikId],$A10,tblGunluk[Km_km]),0)) | L10: =IF($A10="","",MAX(0,MIN(100,fam_kaliteTaban-IF($K10>fam_esikKmBasi,fam_kaliteCeza,0)-COUNTIFS(tblGunluk[VarlikId],$A10,tblGunluk[AlarmBayrak],"ALARM")*fam_kaliteSapma-IF($H10="HAYIR",fam_kaliteCeza,0))))
A11: ARC-00006 | B11: Renault Master | C11: Panelvan | D11: Dizel | E11: 10 | F11: 1.9 | G11: 40000 | H11: EVET | I11: =IF($A11="","",SUMIF(tblGunluk[VarlikId],$A11,tblGunluk[Km_km])) | J11: =IF($A11="","",SUMIF(tblGunluk[VarlikId],$A11,tblGunluk[FormulToplamTl])) | K11: =IF($A11="","",IFERROR(SUMIF(tblGunluk[VarlikId],$A11,tblGunluk[FormulToplamTl])/SUMIF(tblGunluk[VarlikId],$A11,tblGunluk[Km_km]),0)) | L11: =IF($A11="","",MAX(0,MIN(100,fam_kaliteTaban-IF($K11>fam_esikKmBasi,fam_kaliteCeza,0)-COUNTIFS(tblGunluk[VarlikId],$A11,tblGunluk[AlarmBayrak],"ALARM")*fam_kaliteSapma-IF($H11="HAYIR",fam_kaliteCeza,0))))
A12: ARC-00007 | B12: Toyota Hilux | C12: Kamyonet | D12: Dizel | E12: 8.5 | F12: 1.6 | G12: 32000 | H12: EVET | I12: =IF($A12="","",SUMIF(tblGunluk[VarlikId],$A12,tblGunluk[Km_km])) | J12: =IF($A12="","",SUMIF(tblGunluk[VarlikId],$A12,tblGunluk[FormulToplamTl])) | K12: =IF($A12="","",IFERROR(SUMIF(tblGunluk[VarlikId],$A12,tblGunluk[FormulToplamTl])/SUMIF(tblGunluk[VarlikId],$A12,tblGunluk[Km_km]),0)) | L12: =IF($A12="","",MAX(0,MIN(100,fam_kaliteTaban-IF($K12>fam_esikKmBasi,fam_kaliteCeza,0)-COUNTIFS(tblGunluk[VarlikId],$A12,tblGunluk[AlarmBayrak],"ALARM")*fam_kaliteSapma-IF($H12="HAYIR",fam_kaliteCeza,0))))
A13: ARC-00008 | B13: MAN TGL | C13: Kamyon | D13: Dizel | E13: 16 | F13: 2.8 | G13: 62000 | H13: EVET | I13: =IF($A13="","",SUMIF(tblGunluk[VarlikId],$A13,tblGunluk[Km_km])) | J13: =IF($A13="","",SUMIF(tblGunluk[VarlikId],$A13,tblGunluk[FormulToplamTl])) | K13: =IF($A13="","",IFERROR(SUMIF(tblGunluk[VarlikId],$A13,tblGunluk[FormulToplamTl])/SUMIF(tblGunluk[VarlikId],$A13,tblGunluk[Km_km]),0)) | L13: =IF($A13="","",MAX(0,MIN(100,fam_kaliteTaban-IF($K13>fam_esikKmBasi,fam_kaliteCeza,0)-COUNTIFS(tblGunluk[VarlikId],$A13,tblGunluk[AlarmBayrak],"ALARM")*fam_kaliteSapma-IF($H13="HAYIR",fam_kaliteCeza,0))))
I14: =IF($A14="","",SUMIF(tblGunluk[VarlikId],$A14,tblGunluk[Km_km])) | J14: =IF($A14="","",SUMIF(tblGunluk[VarlikId],$A14,tblGunluk[FormulToplamTl])) | K14: =IF($A14="","",IFERROR(SUMIF(tblGunluk[VarlikId],$A14,tblGunluk[FormulToplamTl])/SUMIF(tblGunluk[VarlikId],$A14,tblGunluk[Km_km]),0)) | L14: =IF($A14="","",MAX(0,MIN(100,fam_kaliteTaban-IF($K14>fam_esikKmBasi,fam_kaliteCeza,0)-COUNTIFS(tblGunluk[VarlikId],$A14,tblGunluk[AlarmBayrak],"ALARM")*fam_kaliteSapma-IF($H14="HAYIR",fam_kaliteCeza,0))))
I15: =IF($A15="","",SUMIF(tblGunluk[VarlikId],$A15,tblGunluk[Km_km])) | J15: =IF($A15="","",SUMIF(tblGunluk[VarlikId],$A15,tblGunluk[FormulToplamTl])) | K15: =IF($A15="","",IFERROR(SUMIF(tblGunluk[VarlikId],$A15,tblGunluk[FormulToplamTl])/SUMIF(tblGunluk[VarlikId],$A15,tblGunluk[Km_km]),0)) | L15: =IF($A15="","",MAX(0,MIN(100,fam_kaliteTaban-IF($K15>fam_esikKmBasi,fam_kaliteCeza,0)-COUNTIFS(tblGunluk[VarlikId],$A15,tblGunluk[AlarmBayrak],"ALARM")*fam_kaliteSapma-IF($H15="HAYIR",fam_kaliteCeza,0))))
I16: =IF($A16="","",SUMIF(tblGunluk[VarlikId],$A16,tblGunluk[Km_km])) | J16: =IF($A16="","",SUMIF(tblGunluk[VarlikId],$A16,tblGunluk[FormulToplamTl])) | K16: =IF($A16="","",IFERROR(SUMIF(tblGunluk[VarlikId],$A16,tblGunluk[FormulToplamTl])/SUMIF(tblGunluk[VarlikId],$A16,tblGunluk[Km_km]),0)) | L16: =IF($A16="","",MAX(0,MIN(100,fam_kaliteTaban-IF($K16>fam_esikKmBasi,fam_kaliteCeza,0)-COUNTIFS(tblGunluk[VarlikId],$A16,tblGunluk[AlarmBayrak],"ALARM")*fam_kaliteSapma-IF($H16="HAYIR",fam_kaliteCeza,0))))
I17: =IF($A17="","",SUMIF(tblGunluk[VarlikId],$A17,tblGunluk[Km_km])) | J17: =IF($A17="","",SUMIF(tblGunluk[VarlikId],$A17,tblGunluk[FormulToplamTl])) | K17: =IF($A17="","",IFERROR(SUMIF(tblGunluk[VarlikId],$A17,tblGunluk[FormulToplamTl])/SUMIF(tblGunluk[VarlikId],$A17,tblGunluk[Km_km]),0)) | L17: =IF($A17="","",MAX(0,MIN(100,fam_kaliteTaban-IF($K17>fam_esikKmBasi,fam_kaliteCeza,0)-COUNTIFS(tblGunluk[VarlikId],$A17,tblGunluk[AlarmBayrak],"ALARM")*fam_kaliteSapma-IF($H17="HAYIR",fam_kaliteCeza,0))))
I18: =IF($A18="","",SUMIF(tblGunluk[VarlikId],$A18,tblGunluk[Km_km])) | J18: =IF($A18="","",SUMIF(tblGunluk[VarlikId],$A18,tblGunluk[FormulToplamTl])) | K18: =IF($A18="","",IFERROR(SUMIF(tblGunluk[VarlikId],$A18,tblGunluk[FormulToplamTl])/SUMIF(tblGunluk[VarlikId],$A18,tblGunluk[Km_km]),0)) | L18: =IF($A18="","",MAX(0,MIN(100,fam_kaliteTaban-IF($K18>fam_esikKmBasi,fam_kaliteCeza,0)-COUNTIFS(tblGunluk[VarlikId],$A18,tblGunluk[AlarmBayrak],"ALARM")*fam_kaliteSapma-IF($H18="HAYIR",fam_kaliteCeza,0))))
I19: =IF($A19="","",SUMIF(tblGunluk[VarlikId],$A19,tblGunluk[Km_km])) | J19: =IF($A19="","",SUMIF(tblGunluk[VarlikId],$A19,tblGunluk[FormulToplamTl])) | K19: =IF($A19="","",IFERROR(SUMIF(tblGunluk[VarlikId],$A19,tblGunluk[FormulToplamTl])/SUMIF(tblGunluk[VarlikId],$A19,tblGunluk[Km_km]),0)) | L19: =IF($A19="","",MAX(0,MIN(100,fam_kaliteTaban-IF($K19>fam_esikKmBasi,fam_kaliteCeza,0)-COUNTIFS(tblGunluk[VarlikId],$A19,tblGunluk[AlarmBayrak],"ALARM")*fam_kaliteSapma-IF($H19="HAYIR",fam_kaliteCeza,0))))
I20: =IF($A20="","",SUMIF(tblGunluk[VarlikId],$A20,tblGunluk[Km_km])) | J20: =IF($A20="","",SUMIF(tblGunluk[VarlikId],$A20,tblGunluk[FormulToplamTl])) | K20: =IF($A20="","",IFERROR(SUMIF(tblGunluk[VarlikId],$A20,tblGunluk[FormulToplamTl])/SUMIF(tblGunluk[VarlikId],$A20,tblGunluk[Km_km]),0)) | L20: =IF($A20="","",MAX(0,MIN(100,fam_kaliteTaban-IF($K20>fam_esikKmBasi,fam_kaliteCeza,0)-COUNTIFS(tblGunluk[VarlikId],$A20,tblGunluk[AlarmBayrak],"ALARM")*fam_kaliteSapma-IF($H20="HAYIR",fam_kaliteCeza,0))))
I21: =IF($A21="","",SUMIF(tblGunluk[VarlikId],$A21,tblGunluk[Km_km])) | J21: =IF($A21="","",SUMIF(tblGunluk[VarlikId],$A21,tblGunluk[FormulToplamTl])) | K21: =IF($A21="","",IFERROR(SUMIF(tblGunluk[VarlikId],$A21,tblGunluk[FormulToplamTl])/SUMIF(tblGunluk[VarlikId],$A21,tblGunluk[Km_km]),0)) | L21: =IF($A21="","",MAX(0,MIN(100,fam_kaliteTaban-IF($K21>fam_esikKmBasi,fam_kaliteCeza,0)-COUNTIFS(tblGunluk[VarlikId],$A21,tblGunluk[AlarmBayrak],"ALARM")*fam_kaliteSapma-IF($H21="HAYIR",fam_kaliteCeza,0))))
I22: =IF($A22="","",SUMIF(tblGunluk[VarlikId],$A22,tblGunluk[Km_km])) | J22: =IF($A22="","",SUMIF(tblGunluk[VarlikId],$A22,tblGunluk[FormulToplamTl])) | K22: =IF($A22="","",IFERROR(SUMIF(tblGunluk[VarlikId],$A22,tblGunluk[FormulToplamTl])/SUMIF(tblGunluk[VarlikId],$A22,tblGunluk[Km_km]),0)) | L22: =IF($A22="","",MAX(0,MIN(100,fam_kaliteTaban-IF($K22>fam_esikKmBasi,fam_kaliteCeza,0)-COUNTIFS(tblGunluk[VarlikId],$A22,tblGunluk[AlarmBayrak],"ALARM")*fam_kaliteSapma-IF($H22="HAYIR",fam_kaliteCeza,0))))
I23: =IF($A23="","",SUMIF(tblGunluk[VarlikId],$A23,tblGunluk[Km_km])) | J23: =IF($A23="","",SUMIF(tblGunluk[VarlikId],$A23,tblGunluk[FormulToplamTl])) | K23: =IF($A23="","",IFERROR(SUMIF(tblGunluk[VarlikId],$A23,tblGunluk[FormulToplamTl])/SUMIF(tblGunluk[VarlikId],$A23,tblGunluk[Km_km]),0)) | L23: =IF($A23="","",MAX(0,MIN(100,fam_kaliteTaban-IF($K23>fam_esikKmBasi,fam_kaliteCeza,0)-COUNTIFS(tblGunluk[VarlikId],$A23,tblGunluk[AlarmBayrak],"ALARM")*fam_kaliteSapma-IF($H23="HAYIR",fam_kaliteCeza,0))))
I24: =IF($A24="","",SUMIF(tblGunluk[VarlikId],$A24,tblGunluk[Km_km])) | J24: =IF($A24="","",SUMIF(tblGunluk[VarlikId],$A24,tblGunluk[FormulToplamTl])) | K24: =IF($A24="","",IFERROR(SUMIF(tblGunluk[VarlikId],$A24,tblGunluk[FormulToplamTl])/SUMIF(tblGunluk[VarlikId],$A24,tblGunluk[Km_km]),0)) | L24: =IF($A24="","",MAX(0,MIN(100,fam_kaliteTaban-IF($K24>fam_esikKmBasi,fam_kaliteCeza,0)-COUNTIFS(tblGunluk[VarlikId],$A24,tblGunluk[AlarmBayrak],"ALARM")*fam_kaliteSapma-IF($H24="HAYIR",fam_kaliteCeza,0))))
I25: =IF($A25="","",SUMIF(tblGunluk[VarlikId],$A25,tblGunluk[Km_km])) | J25: =IF($A25="","",SUMIF(tblGunluk[VarlikId],$A25,tblGunluk[FormulToplamTl])) | K25: =IF($A25="","",IFERROR(SUMIF(tblGunluk[VarlikId],$A25,tblGunluk[FormulToplamTl])/SUMIF(tblGunluk[VarlikId],$A25,tblGunluk[Km_km]),0)) | L25: =IF($A25="","",MAX(0,MIN(100,fam_kaliteTaban-IF($K25>fam_esikKmBasi,fam_kaliteCeza,0)-COUNTIFS(tblGunluk[VarlikId],$A25,tblGunluk[AlarmBayrak],"ALARM")*fam_kaliteSapma-IF($H25="HAYIR",fam_kaliteCeza,0))))
... I255: =IF($A255="","",SUMIF(tblGunluk[VarlikId],$A255,tblGunluk[Km_km])) | J255: =IF($A255="","",SUMIF(tblGunluk[VarlikId],$A255,tblGunluk[FormulToplamTl])) | K255: =IF($A255="","",IFERROR(SUMIF(tblGunluk[VarlikId],$A255,tblGunluk[FormulToplamTl])/SUMIF(tblGunluk[VarlikId],$A255,tblGunluk[Km_km]),0)) | L255: =IF($A255="","",MAX(0,MIN(100,fam_kaliteTaban-IF($K255>fam_esikKmBasi,fam_kaliteCeza,0)-COUNTIFS(tblGunluk[VarlikId],$A255,tblGunluk[AlarmBayrak],"ALARM")*fam_kaliteSapma-IF($H255="HAYIR",fam_kaliteCeza,0))))

Sheet GUNLUK_GIRIS
A1: GUNLUK GIRIS — Filo Araç Maliyet Komutası
A3: GÜNLÜK saha girişi — satır başına en fazla 6 manuel alan (S02)
A5: SatirId | B5: VarlikId | C5: Tarih | D5: Km_km | E5: YakitLt_lt | F5: BakimTl_tl | G5: OlayTuru | H5: FormulYakitTl | I5: FormulAmortTl | J5: FormulSigortaTl | K5: FormulToplamTl | L5: FormulKmBasi | M5: SaglikSkorSatir | N5: AlarmBayrak | O5: FormulKayitDolu | P5: FormulYetim
A6: GLG-00001 | B6: ARC-00001 | C6: 46242 | D6: 135 | E6: 12.8 | F6: 0 | G6: BAKIM | H6: =IF($A6="","",$E6*fam_yakitBirimFiyat) | I6: =IF($A6="","",$D6*IFERROR(SUMIF(tblVarliklar[VarlikId],$B6,tblVarliklar[AmortismanTlKm]),fam_amortismanTlKm)) | J6: =IF($A6="","",IFERROR(SUMIF(tblVarliklar[VarlikId],$B6,tblVarliklar[SigortaYillikTl]),fam_sigortaYillik)/365*fam_sigortaGunPay) | K6: =IF($A6="","",$H6+$F6+$I6+$J6) | L6: =IF(OR($A6="",$D6=0),"",$K6/$D6) | M6: =IF($A6="","",MAX(0,MIN(100,fam_kaliteTaban-IF($L6>fam_esikKmBasi,fam_kaliteCeza,0)-IF($F6>fam_esikBakimTl,fam_kaliteSapma,0)-IF($P6="YETIM",fam_kaliteCeza,0)))) | N6: =IF($A6="","",IF(OR($L6>fam_esikKmBasi,$F6>fam_esikBakimTl,$M6<fam_esikSaglik),"ALARM","UYGUN")) | O6: =IF($A6="","",1) | P6: =IF($A6="","",IF(OR($B6="",COUNTIF(tblVarliklar[VarlikId],$B6)=0),"YETIM","TAMAM"))
A7: GLG-00002 | B7: ARC-00002 | C7: 46239 | D7: 190 | E7: 19.4 | F7: 0 | G7: YAKIT | H7: =IF($A7="","",$E7*fam_yakitBirimFiyat) | I7: =IF($A7="","",$D7*IFERROR(SUMIF(tblVarliklar[VarlikId],$B7,tblVarliklar[AmortismanTlKm]),fam_amortismanTlKm)) | J7: =IF($A7="","",IFERROR(SUMIF(tblVarliklar[VarlikId],$B7,tblVarliklar[SigortaYillikTl]),fam_sigortaYillik)/365*fam_sigortaGunPay) | K7: =IF($A7="","",$H7+$F7+$I7+$J7) | L7: =IF(OR($A7="",$D7=0),"",$K7/$D7) | M7: =IF($A7="","",MAX(0,MIN(100,fam_kaliteTaban-IF($L7>fam_esikKmBasi,fam_kaliteCeza,0)-IF($F7>fam_esikBakimTl,fam_kaliteSapma,0)-IF($P7="YETIM",fam_kaliteCeza,0)))) | N7: =IF($A7="","",IF(OR($L7>fam_esikKmBasi,$F7>fam_esikBakimTl,$M7<fam_esikSaglik),"ALARM","UYGUN")) | O7: =IF($A7="","",1) | P7: =IF($A7="","",IF(OR($B7="",COUNTIF(tblVarliklar[VarlikId],$B7)=0),"YETIM","TAMAM"))
A8: GLG-00003 | B8: ARC-00003 | C8: 46236 | D8: 185 | E8: 20.4 | F8: 0 | G8: MUAYENE | H8: =IF($A8="","",$E8*fam_yakitBirimFiyat) | I8: =IF($A8="","",$D8*IFERROR(SUMIF(tblVarliklar[VarlikId],$B8,tblVarliklar[AmortismanTlKm]),fam_amortismanTlKm)) | J8: =IF($A8="","",IFERROR(SUMIF(tblVarliklar[VarlikId],$B8,tblVarliklar[SigortaYillikTl]),fam_sigortaYillik)/365*fam_sigortaGunPay) | K8: =IF($A8="","",$H8+$F8+$I8+$J8) | L8: =IF(OR($A8="",$D8=0),"",$K8/$D8) | M8: =IF($A8="","",MAX(0,MIN(100,fam_kaliteTaban-IF($L8>fam_esikKmBasi,fam_kaliteCeza,0)-IF($F8>fam_esikBakimTl,fam_kaliteSapma,0)-IF($P8="YETIM",fam_kaliteCeza,0)))) | N8: =IF($A8="","",IF(OR($L8>fam_esikKmBasi,$F8>fam_esikBakimTl,$M8<fam_esikSaglik),"ALARM","UYGUN")) | O8: =IF($A8="","",1) | P8: =IF($A8="","",IF(OR($B8="",COUNTIF(tblVarliklar[VarlikId],$B8)=0),"YETIM","TAMAM"))
A9: GLG-00004 | B9: ARC-00004 | C9: 46233 | D9: 240 | E9: 23.5 | F9: 0 | G9: ARIZA | H9: =IF($A9="","",$E9*fam_yakitBirimFiyat) | I9: =IF($A9="","",$D9*IFERROR(SUMIF(tblVarliklar[VarlikId],$B9,tblVarliklar[AmortismanTlKm]),fam_amortismanTlKm)) | J9: =IF($A9="","",IFERROR(SUMIF(tblVarliklar[VarlikId],$B9,tblVarliklar[SigortaYillikTl]),fam_sigortaYillik)/365*fam_sigortaGunPay) | K9: =IF($A9="","",$H9+$F9+$I9+$J9) | L9: =IF(OR($A9="",$D9=0),"",$K9/$D9) | M9: =IF($A9="","",MAX(0,MIN(100,fam_kaliteTaban-IF($L9>fam_esikKmBasi,fam_kaliteCeza,0)-IF($F9>fam_esikBakimTl,fam_kaliteSapma,0)-IF($P9="YETIM",fam_kaliteCeza,0)))) | N9: =IF($A9="","",IF(OR($L9>fam_esikKmBasi,$F9>fam_esikBakimTl,$M9<fam_esikSaglik),"ALARM","UYGUN")) | O9: =IF($A9="","",1) | P9: =IF($A9="","",IF(OR($B9="",COUNTIF(tblVarliklar[VarlikId],$B9)=0),"YETIM","TAMAM"))
A10: GLG-00005 | B10: ARC-00005 | C10: 46230 | D10: 295 | E10: 42.8 | F10: 570 | G10: DIGER | H10: =IF($A10="","",$E10*fam_yakitBirimFiyat) | I10: =IF($A10="","",$D10*IFERROR(SUMIF(tblVarliklar[VarlikId],$B10,tblVarliklar[AmortismanTlKm]),fam_amortismanTlKm)) | J10: =IF($A10="","",IFERROR(SUMIF(tblVarliklar[VarlikId],$B10,tblVarliklar[SigortaYillikTl]),fam_sigortaYillik)/365*fam_sigortaGunPay) | K10: =IF($A10="","",$H10+$F10+$I10+$J10) | L10: =IF(OR($A10="",$D10=0),"",$K10/$D10) | M10: =IF($A10="","",MAX(0,MIN(100,fam_kaliteTaban-IF($L10>fam_esikKmBasi,fam_kaliteCeza,0)-IF($F10>fam_esikBakimTl,fam_kaliteSapma,0)-IF($P10="YETIM",fam_kaliteCeza,0)))) | N10: =IF($A10="","",IF(OR($L10>fam_esikKmBasi,$F10>fam_esikBakimTl,$M10<fam_esikSaglik),"ALARM","UYGUN")) | O10: =IF($A10="","",1) | P10: =IF($A10="","",IF(OR($B10="",COUNTIF(tblVarliklar[VarlikId],$B10)=0),"YETIM","TAMAM"))
A11: GLG-00006 | B11: ARC-00006 | C11: 46227 | D11: 290 | E11: 29 | F11: 0 | G11: SEFER | H11: =IF($A11="","",$E11*fam_yakitBirimFiyat) | I11: =IF($A11="","",$D11*IFERROR(SUMIF(tblVarliklar[VarlikId],$B11,tblVarliklar[AmortismanTlKm]),fam_amortismanTlKm)) | J11: =IF($A11="","",IFERROR(SUMIF(tblVarliklar[VarlikId],$B11,tblVarliklar[SigortaYillikTl]),fam_sigortaYillik)/365*fam_sigortaGunPay) | K11: =IF($A11="","",$H11+$F11+$I11+$J11) | L11: =IF(OR($A11="",$D11=0),"",$K11/$D11) | M11: =IF($A11="","",MAX(0,MIN(100,fam_kaliteTaban-IF($L11>fam_esikKmBasi,fam_kaliteCeza,0)-IF($F11>fam_esikBakimTl,fam_kaliteSapma,0)-IF($P11="YETIM",fam_kaliteCeza,0)))) | N11: =IF($A11="","",IF(OR($L11>fam_esikKmBasi,$F11>fam_esikBakimTl,$M11<fam_esikSaglik),"ALARM","UYGUN")) | O11: =IF($A11="","",1) | P11: =IF($A11="","",IF(OR($B11="",COUNTIF(tblVarliklar[VarlikId],$B11)=0),"YETIM","TAMAM"))
A12: GLG-00007 | B12: ARC-00007 | C12: 46224 | D12: 100 | E12: 8.5 | F12: 0 | G12: BAKIM | H12: =IF($A12="","",$E12*fam_yakitBirimFiyat) | I12: =IF($A12="","",$D12*IFERROR(SUMIF(tblVarliklar[VarlikId],$B12,tblVarliklar[AmortismanTlKm]),fam_amortismanTlKm)) | J12: =IF($A12="","",IFERROR(SUMIF(tblVarliklar[VarlikId],$B12,tblVarliklar[SigortaYillikTl]),fam_sigortaYillik)/365*fam_sigortaGunPay) | K12: =IF($A12="","",$H12+$F12+$I12+$J12) | L12: =IF(OR($A12="",$D12=0),"",$K12/$D12) | M12: =IF($A12="","",MAX(0,MIN(100,fam_kaliteTaban-IF($L12>fam_esikKmBasi,fam_kaliteCeza,0)-IF($F12>fam_esikBakimTl,fam_kaliteSapma,0)-IF($P12="YETIM",fam_kaliteCeza,0)))) | N12: =IF($A12="","",IF(OR($L12>fam_esikKmBasi,$F12>fam_esikBakimTl,$M12<fam_esikSaglik),"ALARM","UYGUN")) | O12: =IF($A12="","",1) | P12: =IF($A12="","",IF(OR($B12="",COUNTIF(tblVarliklar[VarlikId],$B12)=0),"YETIM","TAMAM"))
A13: GLG-00008 | B13: ARC-00008 | C13: 46221 | D13: 155 | E13: 24.8 | F13: 0 | G13: YAKIT | H13: =IF($A13="","",$E13*fam_yakitBirimFiyat) | I13: =IF($A13="","",$D13*IFERROR(SUMIF(tblVarliklar[VarlikId],$B13,tblVarliklar[AmortismanTlKm]),fam_amortismanTlKm)) | J13: =IF($A13="","",IFERROR(SUMIF(tblVarliklar[VarlikId],$B13,tblVarliklar[SigortaYillikTl]),fam_sigortaYillik)/365*fam_sigortaGunPay) | K13: =IF($A13="","",$H13+$F13+$I13+$J13) | L13: =IF(OR($A13="",$D13=0),"",$K13/$D13) | M13: =IF($A13="","",MAX(0,MIN(100,fam_kaliteTaban-IF($L13>fam_esikKmBasi,fam_kaliteCeza,0)-IF($F13>fam_esikBakimTl,fam_kaliteSapma,0)-IF($P13="YETIM",fam_kaliteCeza,0)))) | N13: =IF($A13="","",IF(OR($L13>fam_esikKmBasi,$F13>fam_esikBakimTl,$M13<fam_esikSaglik),"ALARM","UYGUN")) | O13: =IF($A13="","",1) | P13: =IF($A13="","",IF(OR($B13="",COUNTIF(tblVarliklar[VarlikId],$B13)=0),"YETIM","TAMAM"))
A14: GLG-00009 | B14: ARC-00001 | C14: 46218 | D14: 150 | E14: 14.2 | F14: 0 | G14: MUAYENE | H14: =IF($A14="","",$E14*fam_yakitBirimFiyat) | I14: =IF($A14="","",$D14*IFERROR(SUMIF(tblVarliklar[VarlikId],$B14,tblVarliklar[AmortismanTlKm]),fam_amortismanTlKm)) | J14: =IF($A14="","",IFERROR(SUMIF(tblVarliklar[VarlikId],$B14,tblVarliklar[SigortaYillikTl]),fam_sigortaYillik)/365*fam_sigortaGunPay) | K14: =IF($A14="","",$H14+$F14+$I14+$J14) | L14: =IF(OR($A14="",$D14=0),"",$K14/$D14) | M14: =IF($A14="","",MAX(0,MIN(100,fam_kaliteTaban-IF($L14>fam_esikKmBasi,fam_kaliteCeza,0)-IF($F14>fam_esikBakimTl,fam_kaliteSapma,0)-IF($P14="YETIM",fam_kaliteCeza,0)))) | N14: =IF($A14="","",IF(OR($L14>fam_esikKmBasi,$F14>fam_esikBakimTl,$M14<fam_esikSaglik),"ALARM","UYGUN")) | O14: =IF($A14="","",1) | P14: =IF($A14="","",IF(OR($B14="",COUNTIF(tblVarliklar[VarlikId],$B14)=0),"YETIM","TAMAM"))
A15: GLG-00010 | B15: ARC-00002 | C15: 46215 | D15: 205 | E15: 20.9 | F15: 690 | G15: ARIZA | H15: =IF($A15="","",$E15*fam_yakitBirimFiyat) | I15: =IF($A15="","",$D15*IFERROR(SUMIF(tblVarliklar[VarlikId],$B15,tblVarliklar[AmortismanTlKm]),fam_amortismanTlKm)) | J15: =IF($A15="","",IFERROR(SUMIF(tblVarliklar[VarlikId],$B15,tblVarliklar[SigortaYillikTl]),fam_sigortaYillik)/365*fam_sigortaGunPay) | K15: =IF($A15="","",$H15+$F15+$I15+$J15) | L15: =IF(OR($A15="",$D15=0),"",$K15/$D15) | M15: =IF($A15="","",MAX(0,MIN(100,fam_kaliteTaban-IF($L15>fam_esikKmBasi,fam_kaliteCeza,0)-IF($F15>fam_esikBakimTl,fam_kaliteSapma,0)-IF($P15="YETIM",fam_kaliteCeza,0)))) | N15: =IF($A15="","",IF(OR($L15>fam_esikKmBasi,$F15>fam_esikBakimTl,$M15<fam_esikSaglik),"ALARM","UYGUN")) | O15: =IF($A15="","",1) | P15: =IF($A15="","",IF(OR($B15="",COUNTIF(tblVarliklar[VarlikId],$B15)=0),"YETIM","TAMAM"))
A16: GLG-00011 | B16: ARC-00003 | C16: 46212 | D16: 260 | E16: 28.6 | F16: 0 | G16: DIGER | H16: =IF($A16="","",$E16*fam_yakitBirimFiyat) | I16: =IF($A16="","",$D16*IFERROR(SUMIF(tblVarliklar[VarlikId],$B16,tblVarliklar[AmortismanTlKm]),fam_amortismanTlKm)) | J16: =IF($A16="","",IFERROR(SUMIF(tblVarliklar[VarlikId],$B16,tblVarliklar[SigortaYillikTl]),fam_sigortaYillik)/365*fam_sigortaGunPay) | K16: =IF($A16="","",$H16+$F16+$I16+$J16) | L16: =IF(OR($A16="",$D16=0),"",$K16/$D16) | M16: =IF($A16="","",MAX(0,MIN(100,fam_kaliteTaban-IF($L16>fam_esikKmBasi,fam_kaliteCeza,0)-IF($F16>fam_esikBakimTl,fam_kaliteSapma,0)-IF($P16="YETIM",fam_kaliteCeza,0)))) | N16: =IF($A16="","",IF(OR($L16>fam_esikKmBasi,$F16>fam_esikBakimTl,$M16<fam_esikSaglik),"ALARM","UYGUN")) | O16: =IF($A16="","",1) | P16: =IF($A16="","",IF(OR($B16="",COUNTIF(tblVarliklar[VarlikId],$B16)=0),"YETIM","TAMAM"))
A17: GLG-00012 | B17: ARC-00004 | C17: 46209 | D17: 255 | E17: 25 | F17: 2200 | G17: SEFER | H17: =IF($A17="","",$E17*fam_yakitBirimFiyat) | I17: =IF($A17="","",$D17*IFERROR(SUMIF(tblVarliklar[VarlikId],$B17,tblVarliklar[AmortismanTlKm]),fam_amortismanTlKm)) | J17: =IF($A17="","",IFERROR(SUMIF(tblVarliklar[VarlikId],$B17,tblVarliklar[SigortaYillikTl]),fam_sigortaYillik)/365*fam_sigortaGunPay) | K17: =IF($A17="","",$H17+$F17+$I17+$J17) | L17: =IF(OR($A17="",$D17=0),"",$K17/$D17) | M17: =IF($A17="","",MAX(0,MIN(100,fam_kaliteTaban-IF($L17>fam_esikKmBasi,fam_kaliteCeza,0)-IF($F17>fam_esikBakimTl,fam_kaliteSapma,0)-IF($P17="YETIM",fam_kaliteCeza,0)))) | N17: =IF($A17="","",IF(OR($L17>fam_esikKmBasi,$F17>fam_esikBakimTl,$M17<fam_esikSaglik),"ALARM","UYGUN")) | O17: =IF($A17="","",1) | P17: =IF($A17="","",IF(OR($B17="",COUNTIF(tblVarliklar[VarlikId],$B17)=0),"YETIM","TAMAM"))
... A34: GLG-00029 | B34: ARC-00005 | C34: 46158 | D34: 155 | E34: 22.5 | F34: 0 | G34: DIGER | H34: =IF($A34="","",$E34*fam_yakitBirimFiyat) | I34: =IF($A34="","",$D34*IFERROR(SUMIF(tblVarliklar[VarlikId],$B34,tblVarliklar[AmortismanTlKm]),fam_amortismanTlKm)) | J34: =IF($A34="","",IFERROR(SUMIF(tblVarliklar[VarlikId],$B34,tblVarliklar[SigortaYillikTl]),fam_sigortaYillik)/365*fam_sigortaGunPay) | K34: =IF($A34="","",$H34+$F34+$I34+$J34) | L34: =IF(OR($A34="",$D34=0),"",$K34/$D34) | M34: =IF($A34="","",MAX(0,MIN(100,fam_kaliteTaban-IF($L34>fam_esikKmBasi,fam_kaliteCeza,0)-IF($F34>fam_esikBakimTl,fam_kaliteSapma,0)-IF($P34="YETIM",fam_kaliteCeza,0)))) | N34: =IF($A34="","",IF(OR($L34>fam_esikKmBasi,$F34>fam_esikBakimTl,$M34<fam_esikSaglik),"ALARM","UYGUN")) | O34: =IF($A34="","",1) | P34: =IF($A34="","",IF(OR($B34="",COUNTIF(tblVarliklar[VarlikId],$B34)=0),"YETIM","TAMAM"))
A35: GLG-00030 | C35: 46155 | D35: 150 | E35: 15 | F35: 690 | G35: SEFER | H35: =IF($A35="","",$E35*fam_yakitBirimFiyat) | I35: =IF($A35="","",$D35*IFERROR(SUMIF(tblVarliklar[VarlikId],$B35,tblVarliklar[AmortismanTlKm]),fam_amortismanTlKm)) | J35: =IF($A35="","",IFERROR(SUMIF(tblVarliklar[VarlikId],$B35,tblVarliklar[SigortaYillikTl]),fam_sigortaYillik)/365*fam_sigortaGunPay) | K35: =IF($A35="","",$H35+$F35+$I35+$J35) | L35: =IF(OR($A35="",$D35=0),"",$K35/$D35) | M35: =IF($A35="","",MAX(0,MIN(100,fam_kaliteTaban-IF($L35>fam_esikKmBasi,fam_kaliteCeza,0)-IF($F35>fam_esikBakimTl,fam_kaliteSapma,0)-IF($P35="YETIM",fam_kaliteCeza,0)))) | N35: =IF($A35="","",IF(OR($L35>fam_esikKmBasi,$F35>fam_esikBakimTl,$M35<fam_esikSaglik),"ALARM","UYGUN")) | O35: =IF($A35="","",1) | P35: =IF($A35="","",IF(OR($B35="",COUNTIF(tblVarliklar[VarlikId],$B35)=0),"YETIM","TAMAM"))
A36: GLG-00031 | B36: ARC-00007 | C36: 46152 | D36: 205 | E36: 17.4 | F36: 0 | G36: BAKIM | H36: =IF($A36="","",$E36*fam_yakitBirimFiyat) | I36: =IF($A36="","",$D36*IFERROR(SUMIF(tblVarliklar[VarlikId],$B36,tblVarliklar[AmortismanTlKm]),fam_amortismanTlKm)) | J36: =IF($A36="","",IFERROR(SUMIF(tblVarliklar[VarlikId],$B36,tblVarliklar[SigortaYillikTl]),fam_sigortaYillik)/365*fam_sigortaGunPay) | K36: =IF($A36="","",$H36+$F36+$I36+$J36) | L36: =IF(OR($A36="",$D36=0),"",$K36/$D36) | M36: =IF($A36="","",MAX(0,MIN(100,fam_kaliteTaban-IF($L36>fam_esikKmBasi,fam_kaliteCeza,0)-IF($F36>fam_esikBakimTl,fam_kaliteSapma,0)-IF($P36="YETIM",fam_kaliteCeza,0)))) | N36: =IF($A36="","",IF(OR($L36>fam_esikKmBasi,$F36>fam_esikBakimTl,$M36<fam_esikSaglik),"ALARM","UYGUN")) | O36: =IF($A36="","",1) | P36: =IF($A36="","",IF(OR($B36="",COUNTIF(tblVarliklar[VarlikId],$B36)=0),"YETIM","TAMAM"))
A37: GLG-00032 | B37: ARC-00008 | C37: 46149 | D37: 260 | E37: 41.6 | F37: 0 | G37: YAKIT | H37: =IF($A37="","",$E37*fam_yakitBirimFiyat) | I37: =IF($A37="","",$D37*IFERROR(SUMIF(tblVarliklar[VarlikId],$B37,tblVarliklar[AmortismanTlKm]),fam_amortismanTlKm)) | J37: =IF($A37="","",IFERROR(SUMIF(tblVarliklar[VarlikId],$B37,tblVarliklar[SigortaYillikTl]),fam_sigortaYillik)/365*fam_sigortaGunPay) | K37: =IF($A37="","",$H37+$F37+$I37+$J37) | L37: =IF(OR($A37="",$D37=0),"",$K37/$D37) | M37: =IF($A37="","",MAX(0,MIN(100,fam_kaliteTaban-IF($L37>fam_esikKmBasi,fam_kaliteCeza,0)-IF($F37>fam_esikBakimTl,fam_kaliteSapma,0)-IF($P37="YETIM",fam_kaliteCeza,0)))) | N37: =IF($A37="","",IF(OR($L37>fam_esikKmBasi,$F37>fam_esikBakimTl,$M37<fam_esikSaglik),"ALARM","UYGUN")) | O37: =IF($A37="","",1) | P37: =IF($A37="","",IF(OR($B37="",COUNTIF(tblVarliklar[VarlikId],$B37)=0),"YETIM","TAMAM"))
A38: GLG-00033 | B38: ARC-99999 | C38: 46146 | D38: 255 | E38: 24.2 | F38: 0 | G38: MUAYENE | H38: =IF($A38="","",$E38*fam_yakitBirimFiyat) | I38: =IF($A38="","",$D38*IFERROR(SUMIF(tblVarliklar[VarlikId],$B38,tblVarliklar[AmortismanTlKm]),fam_amortismanTlKm)) | J38: =IF($A38="","",IFERROR(SUMIF(tblVarliklar[VarlikId],$B38,tblVarliklar[SigortaYillikTl]),fam_sigortaYillik)/365*fam_sigortaGunPay) | K38: =IF($A38="","",$H38+$F38+$I38+$J38) | L38: =IF(OR($A38="",$D38=0),"",$K38/$D38) | M38: =IF($A38="","",MAX(0,MIN(100,fam_kaliteTaban-IF($L38>fam_esikKmBasi,fam_kaliteCeza,0)-IF($F38>fam_esikBakimTl,fam_kaliteSapma,0)-IF($P38="YETIM",fam_kaliteCeza,0)))) | N38: =IF($A38="","",IF(OR($L38>fam_esikKmBasi,$F38>fam_esikBakimTl,$M38<fam_esikSaglik),"ALARM","UYGUN")) | O38: =IF($A38="","",1) | P38: =IF($A38="","",IF(OR($B38="",COUNTIF(tblVarliklar[VarlikId],$B38)=0),"YETIM","TAMAM"))
A39: GLG-00034 | B39: ARC-00002 | C39: 46143 | D39: 310 | E39: 31.6 | F39: 0 | G39: ARIZA | H39: =IF($A39="","",$E39*fam_yakitBirimFiyat) | I39: =IF($A39="","",$D39*IFERROR(SUMIF(tblVarliklar[VarlikId],$B39,tblVarliklar[AmortismanTlKm]),fam_amortismanTlKm)) | J39: =IF($A39="","",IFERROR(SUMIF(tblVarliklar[VarlikId],$B39,tblVarliklar[SigortaYillikTl]),fam_sigortaYillik)/365*fam_sigortaGunPay) | K39: =IF($A39="","",$H39+$F39+$I39+$J39) | L39: =IF(OR($A39="",$D39=0),"",$K39/$D39) | M39: =IF($A39="","",MAX(0,MIN(100,fam_kaliteTaban-IF($L39>fam_esikKmBasi,fam_kaliteCeza,0)-IF($F39>fam_esikBakimTl,fam_kaliteSapma,0)-IF($P39="YETIM",fam_kaliteCeza,0)))) | N39: =IF($A39="","",IF(OR($L39>fam_esikKmBasi,$F39>fam_esikBakimTl,$M39<fam_esikSaglik),"ALARM","UYGUN")) | O39: =IF($A39="","",1) | P39: =IF($A39="","",IF(OR($B39="",COUNTIF(tblVarliklar[VarlikId],$B39)=0),"YETIM","TAMAM"))
A40: GLG-00035 | B40: ARC-00003 | C40: 46140 | D40: 120 | E40: 13.2 | F40: 810 | G40: DIGER | H40: =IF($A40="","",$E40*fam_yakitBirimFiyat) | I40: =IF($A40="","",$D40*IFERROR(SUMIF(tblVarliklar[VarlikId],$B40,tblVarliklar[AmortismanTlKm]),fam_amortismanTlKm)) | J40: =IF($A40="","",IFERROR(SUMIF(tblVarliklar[VarlikId],$B40,tblVarliklar[SigortaYillikTl]),fam_sigortaYillik)/365*fam_sigortaGunPay) | K40: =IF($A40="","",$H40+$F40+$I40+$J40) | L40: =IF(OR($A40="",$D40=0),"",$K40/$D40) | M40: =IF($A40="","",MAX(0,MIN(100,fam_kaliteTaban-IF($L40>fam_esikKmBasi,fam_kaliteCeza,0)-IF($F40>fam_esikBakimTl,fam_kaliteSapma,0)-IF($P40="YETIM",fam_kaliteCeza,0)))) | N40: =IF($A40="","",IF(OR($L40>fam_esikKmBasi,$F40>fam_esikBakimTl,$M40<fam_esikSaglik),"ALARM","UYGUN")) | O40: =IF($A40="","",1) | P40: =IF($A40="","",IF(OR($B40="",COUNTIF(tblVarliklar[VarlikId],$B40)=0),"YETIM","TAMAM"))
A41: GLG-00036 | B41: ARC-00004 | C41: 46137 | D41: 115 | E41: 11.3 | F41: 0 | G41: SEFER | H41: =IF($A41="","",$E41*fam_yakitBirimFiyat) | I41: =IF($A41="","",$D41*IFERROR(SUMIF(tblVarliklar[VarlikId],$B41,tblVarliklar[AmortismanTlKm]),fam_amortismanTlKm)) | J41: =IF($A41="","",IFERROR(SUMIF(tblVarliklar[VarlikId],$B41,tblVarliklar[SigortaYillikTl]),fam_sigortaYillik)/365*fam_sigortaGunPay) | K41: =IF($A41="","",$H41+$F41+$I41+$J41) | L41: =IF(OR($A41="",$D41=0),"",$K41/$D41) | M41: =IF($A41="","",MAX(0,MIN(100,fam_kaliteTaban-IF($L41>fam_esikKmBasi,fam_kaliteCeza,0)-IF($F41>fam_esikBakimTl,fam_kaliteSapma,0)-IF($P41="YETIM",fam_kaliteCeza,0)))) | N41: =IF($A41="","",IF(OR($L41>fam_esikKmBasi,$F41>fam_esikBakimTl,$M41<fam_esikSaglik),"ALARM","UYGUN")) | O41: =IF($A41="","",1) | P41: =IF($A41="","",IF(OR($B41="",COUNTIF(tblVarliklar[VarlikId],$B41)=0),"YETIM","TAMAM"))
H42: =IF($A42="","",$E42*fam_yakitBirimFiyat) | I42: =IF($A42="","",$D42*IFERROR(SUMIF(tblVarliklar[VarlikId],$B42,tblVarliklar[AmortismanTlKm]),fam_amortismanTlKm)) | J42: =IF($A42="","",IFERROR(SUMIF(tblVarliklar[VarlikId],$B42,tblVarliklar[SigortaYillikTl]),fam_sigortaYillik)/365*fam_sigortaGunPay) | K42: =IF($A42="","",$H42+$F42+$I42+$J42) | L42: =IF(OR($A42="",$D42=0),"",$K42/$D42) | M42: =IF($A42="","",MAX(0,MIN(100,fam_kaliteTaban-IF($L42>fam_esikKmBasi,fam_kaliteCeza,0)-IF($F42>fam_esikBakimTl,fam_kaliteSapma,0)-IF($P42="YETIM",fam_kaliteCeza,0)))) | N42: =IF($A42="","",IF(OR($L42>fam_esikKmBasi,$F42>fam_esikBakimTl,$M42<fam_esikSaglik),"ALARM","UYGUN")) | O42: =IF($A42="","",1) | P42: =IF($A42="","",IF(OR($B42="",COUNTIF(tblVarliklar[VarlikId],$B42)=0),"YETIM","TAMAM"))
H43: =IF($A43="","",$E43*fam_yakitBirimFiyat) | I43: =IF($A43="","",$D43*IFERROR(SUMIF(tblVarliklar[VarlikId],$B43,tblVarliklar[AmortismanTlKm]),fam_amortismanTlKm)) | J43: =IF($A43="","",IFERROR(SUMIF(tblVarliklar[VarlikId],$B43,tblVarliklar[SigortaYillikTl]),fam_sigortaYillik)/365*fam_sigortaGunPay) | K43: =IF($A43="","",$H43+$F43+$I43+$J43) | L43: =IF(OR($A43="",$D43=0),"",$K43/$D43) | M43: =IF($A43="","",MAX(0,MIN(100,fam_kaliteTaban-IF($L43>fam_esikKmBasi,fam_kaliteCeza,0)-IF($F43>fam_esikBakimTl,fam_kaliteSapma,0)-IF($P43="YETIM",fam_kaliteCeza,0)))) | N43: =IF($A43="","",IF(OR($L43>fam_esikKmBasi,$F43>fam_esikBakimTl,$M43<fam_esikSaglik),"ALARM","UYGUN")) | O43: =IF($A43="","",1) | P43: =IF($A43="","",IF(OR($B43="",COUNTIF(tblVarliklar[VarlikId],$B43)=0),"YETIM","TAMAM"))
H44: =IF($A44="","",$E44*fam_yakitBirimFiyat) | I44: =IF($A44="","",$D44*IFERROR(SUMIF(tblVarliklar[VarlikId],$B44,tblVarliklar[AmortismanTlKm]),fam_amortismanTlKm)) | J44: =IF($A44="","",IFERROR(SUMIF(tblVarliklar[VarlikId],$B44,tblVarliklar[SigortaYillikTl]),fam_sigortaYillik)/365*fam_sigortaGunPay) | K44: =IF($A44="","",$H44+$F44+$I44+$J44) | L44: =IF(OR($A44="",$D44=0),"",$K44/$D44) | M44: =IF($A44="","",MAX(0,MIN(100,fam_kaliteTaban-IF($L44>fam_esikKmBasi,fam_kaliteCeza,0)-IF($F44>fam_esikBakimTl,fam_kaliteSapma,0)-IF($P44="YETIM",fam_kaliteCeza,0)))) | N44: =IF($A44="","",IF(OR($L44>fam_esikKmBasi,$F44>fam_esikBakimTl,$M44<fam_esikSaglik),"ALARM","UYGUN")) | O44: =IF($A44="","",1) | P44: =IF($A44="","",IF(OR($B44="",COUNTIF(tblVarliklar[VarlikId],$B44)=0),"YETIM","TAMAM"))
H45: =IF($A45="","",$E45*fam_yakitBirimFiyat) | I45: =IF($A45="","",$D45*IFERROR(SUMIF(tblVarliklar[VarlikId],$B45,tblVarliklar[AmortismanTlKm]),fam_amortismanTlKm)) | J45: =IF($A45="","",IFERROR(SUMIF(tblVarliklar[VarlikId],$B45,tblVarliklar[SigortaYillikTl]),fam_sigortaYillik)/365*fam_sigortaGunPay) | K45: =IF($A45="","",$H45+$F45+$I45+$J45) | L45: =IF(OR($A45="",$D45=0),"",$K45/$D45) | M45: =IF($A45="","",MAX(0,MIN(100,fam_kaliteTaban-IF($L45>fam_esikKmBasi,fam_kaliteCeza,0)-IF($F45>fam_esikBakimTl,fam_kaliteSapma,0)-IF($P45="YETIM",fam_kaliteCeza,0)))) | N45: =IF($A45="","",IF(OR($L45>fam_esikKmBasi,$F45>fam_esikBakimTl,$M45<fam_esikSaglik),"ALARM","UYGUN")) | O45: =IF($A45="","",1) | P45: =IF($A45="","",IF(OR($B45="",COUNTIF(tblVarliklar[VarlikId],$B45)=0),"YETIM","TAMAM"))
H46: =IF($A46="","",$E46*fam_yakitBirimFiyat) | I46: =IF($A46="","",$D46*IFERROR(SUMIF(tblVarliklar[VarlikId],$B46,tblVarliklar[AmortismanTlKm]),fam_amortismanTlKm)) | J46: =IF($A46="","",IFERROR(SUMIF(tblVarliklar[VarlikId],$B46,tblVarliklar[SigortaYillikTl]),fam_sigortaYillik)/365*fam_sigortaGunPay) | K46: =IF($A46="","",$H46+$F46+$I46+$J46) | L46: =IF(OR($A46="",$D46=0),"",$K46/$D46) | M46: =IF($A46="","",MAX(0,MIN(100,fam_kaliteTaban-IF($L46>fam_esikKmBasi,fam_kaliteCeza,0)-IF($F46>fam_esikBakimTl,fam_kaliteSapma,0)-IF($P46="YETIM",fam_kaliteCeza,0)))) | N46: =IF($A46="","",IF(OR($L46>fam_esikKmBasi,$F46>fam_esikBakimTl,$M46<fam_esikSaglik),"ALARM","UYGUN")) | O46: =IF($A46="","",1) | P46: =IF($A46="","",IF(OR($B46="",COUNTIF(tblVarliklar[VarlikId],$B46)=0),"YETIM","TAMAM"))
H47: =IF($A47="","",$E47*fam_yakitBirimFiyat) | I47: =IF($A47="","",$D47*IFERROR(SUMIF(tblVarliklar[VarlikId],$B47,tblVarliklar[AmortismanTlKm]),fam_amortismanTlKm)) | J47: =IF($A47="","",IFERROR(SUMIF(tblVarliklar[VarlikId],$B47,tblVarliklar[SigortaYillikTl]),fam_sigortaYillik)/365*fam_sigortaGunPay) | K47: =IF($A47="","",$H47+$F47+$I47+$J47) | L47: =IF(OR($A47="",$D47=0),"",$K47/$D47) | M47: =IF($A47="","",MAX(0,MIN(100,fam_kaliteTaban-IF($L47>fam_esikKmBasi,fam_kaliteCeza,0)-IF($F47>fam_esikBakimTl,fam_kaliteSapma,0)-IF($P47="YETIM",fam_kaliteCeza,0)))) | N47: =IF($A47="","",IF(OR($L47>fam_esikKmBasi,$F47>fam_esikBakimTl,$M47<fam_esikSaglik),"ALARM","UYGUN")) | O47: =IF($A47="","",1) | P47: =IF($A47="","",IF(OR($B47="",COUNTIF(tblVarliklar[VarlikId],$B47)=0),"YETIM","TAMAM"))
H48: =IF($A48="","",$E48*fam_yakitBirimFiyat) | I48: =IF($A48="","",$D48*IFERROR(SUMIF(tblVarliklar[VarlikId],$B48,tblVarliklar[AmortismanTlKm]),fam_amortismanTlKm)) | J48: =IF($A48="","",IFERROR(SUMIF(tblVarliklar[VarlikId],$B48,tblVarliklar[SigortaYillikTl]),fam_sigortaYillik)/365*fam_sigortaGunPay) | K48: =IF($A48="","",$H48+$F48+$I48+$J48) | L48: =IF(OR($A48="",$D48=0),"",$K48/$D48) | M48: =IF($A48="","",MAX(0,MIN(100,fam_kaliteTaban-IF($L48>fam_esikKmBasi,fam_kaliteCeza,0)-IF($F48>fam_esikBakimTl,fam_kaliteSapma,0)-IF($P48="YETIM",fam_kaliteCeza,0)))) | N48: =IF($A48="","",IF(OR($L48>fam_esikKmBasi,$F48>fam_esikBakimTl,$M48<fam_esikSaglik),"ALARM","UYGUN")) | O48: =IF($A48="","",1) | P48: =IF($A48="","",IF(OR($B48="",COUNTIF(tblVarliklar[VarlikId],$B48)=0),"YETIM","TAMAM"))
H49: =IF($A49="","",$E49*fam_yakitBirimFiyat) | I49: =IF($A49="","",$D49*IFERROR(SUMIF(tblVarliklar[VarlikId],$B49,tblVarliklar[AmortismanTlKm]),fam_amortismanTlKm)) | J49: =IF($A49="","",IFERROR(SUMIF(tblVarliklar[VarlikId],$B49,tblVarliklar[SigortaYillikTl]),fam_sigortaYillik)/365*fam_sigortaGunPay) | K49: =IF($A49="","",$H49+$F49+$I49+$J49) | L49: =IF(OR($A49="",$D49=0),"",$K49/$D49) | M49: =IF($A49="","",MAX(0,MIN(100,fam_kaliteTaban-IF($L49>fam_esikKmBasi,fam_kaliteCeza,0)-IF($F49>fam_esikBakimTl,fam_kaliteSapma,0)-IF($P49="YETIM",fam_kaliteCeza,0)))) | N49: =IF($A49="","",IF(OR($L49>fam_esikKmBasi,$F49>fam_esikBakimTl,$M49<fam_esikSaglik),"ALARM","UYGUN")) | O49: =IF($A49="","",1) | P49: =IF($A49="","",IF(OR($B49="",COUNTIF(tblVarliklar[VarlikId],$B49)=0),"YETIM","TAMAM"))
H50: =IF($A50="","",$E50*fam_yakitBirimFiyat) | I50: =IF($A50="","",$D50*IFERROR(SUMIF(tblVarliklar[VarlikId],$B50,tblVarliklar[AmortismanTlKm]),fam_amortismanTlKm)) | J50: =IF($A50="","",IFERROR(SUMIF(tblVarliklar[VarlikId],$B50,tblVarliklar[SigortaYillikTl]),fam_sigortaYillik)/365*fam_sigortaGunPay) | K50: =IF($A50="","",$H50+$F50+$I50+$J50) | L50: =IF(OR($A50="",$D50=0),"",$K50/$D50) | M50: =IF($A50="","",MAX(0,MIN(100,fam_kaliteTaban-IF($L50>fam_esikKmBasi,fam_kaliteCeza,0)-IF($F50>fam_esikBakimTl,fam_kaliteSapma,0)-IF($P50="YETIM",fam_kaliteCeza,0)))) | N50: =IF($A50="","",IF(OR($L50>fam_esikKmBasi,$F50>fam_esikBakimTl,$M50<fam_esikSaglik),"ALARM","UYGUN")) | O50: =IF($A50="","",1) | P50: =IF($A50="","",IF(OR($B50="",COUNTIF(tblVarliklar[VarlikId],$B50)=0),"YETIM","TAMAM"))
H51: =IF($A51="","",$E51*fam_yakitBirimFiyat) | I51: =IF($A51="","",$D51*IFERROR(SUMIF(tblVarliklar[VarlikId],$B51,tblVarliklar[AmortismanTlKm]),fam_amortismanTlKm)) | J51: =IF($A51="","",IFERROR(SUMIF(tblVarliklar[VarlikId],$B51,tblVarliklar[SigortaYillikTl]),fam_sigortaYillik)/365*fam_sigortaGunPay) | K51: =IF($A51="","",$H51+$F51+$I51+$J51) | L51: =IF(OR($A51="",$D51=0),"",$K51/$D51) | M51: =IF($A51="","",MAX(0,MIN(100,fam_kaliteTaban-IF($L51>fam_esikKmBasi,fam_kaliteCeza,0)-IF($F51>fam_esikBakimTl,fam_kaliteSapma,0)-IF($P51="YETIM",fam_kaliteCeza,0)))) | N51: =IF($A51="","",IF(OR($L51>fam_esikKmBasi,$F51>fam_esikBakimTl,$M51<fam_esikSaglik),"ALARM","UYGUN")) | O51: =IF($A51="","",1) | P51: =IF($A51="","",IF(OR($B51="",COUNTIF(tblVarliklar[VarlikId],$B51)=0),"YETIM","TAMAM"))
H52: =IF($A52="","",$E52*fam_yakitBirimFiyat) | I52: =IF($A52="","",$D52*IFERROR(SUMIF(tblVarliklar[VarlikId],$B52,tblVarliklar[AmortismanTlKm]),fam_amortismanTlKm)) | J52: =IF($A52="","",IFERROR(SUMIF(tblVarliklar[VarlikId],$B52,tblVarliklar[SigortaYillikTl]),fam_sigortaYillik)/365*fam_sigortaGunPay) | K52: =IF($A52="","",$H52+$F52+$I52+$J52) | L52: =IF(OR($A52="",$D52=0),"",$K52/$D52) | M52: =IF($A52="","",MAX(0,MIN(100,fam_kaliteTaban-IF($L52>fam_esikKmBasi,fam_kaliteCeza,0)-IF($F52>fam_esikBakimTl,fam_kaliteSapma,0)-IF($P52="YETIM",fam_kaliteCeza,0)))) | N52: =IF($A52="","",IF(OR($L52>fam_esikKmBasi,$F52>fam_esikBakimTl,$M52<fam_esikSaglik),"ALARM","UYGUN")) | O52: =IF($A52="","",1) | P52: =IF($A52="","",IF(OR($B52="",COUNTIF(tblVarliklar[VarlikId],$B52)=0),"YETIM","TAMAM"))
H53: =IF($A53="","",$E53*fam_yakitBirimFiyat) | I53: =IF($A53="","",$D53*IFERROR(SUMIF(tblVarliklar[VarlikId],$B53,tblVarliklar[AmortismanTlKm]),fam_amortismanTlKm)) | J53: =IF($A53="","",IFERROR(SUMIF(tblVarliklar[VarlikId],$B53,tblVarliklar[SigortaYillikTl]),fam_sigortaYillik)/365*fam_sigortaGunPay) | K53: =IF($A53="","",$H53+$F53+$I53+$J53) | L53: =IF(OR($A53="",$D53=0),"",$K53/$D53) | M53: =IF($A53="","",MAX(0,MIN(100,fam_kaliteTaban-IF($L53>fam_esikKmBasi,fam_kaliteCeza,0)-IF($F53>fam_esikBakimTl,fam_kaliteSapma,0)-IF($P53="YETIM",fam_kaliteCeza,0)))) | N53: =IF($A53="","",IF(OR($L53>fam_esikKmBasi,$F53>fam_esikBakimTl,$M53<fam_esikSaglik),"ALARM","UYGUN")) | O53: =IF($A53="","",1) | P53: =IF($A53="","",IF(OR($B53="",COUNTIF(tblVarliklar[VarlikId],$B53)=0),"YETIM","TAMAM"))
