Workbook
Name toleransKurus: AYARLAR!$B$6
Name raporTarihi: AYARLAR!$B$7
Name cbb_esikEslesme: AYARLAR!$B$8
Name cbb_esikFark: AYARLAR!$B$9
Name cbb_azamiTutar: AYARLAR!$B$10
Name cbb_ikincilUzunluk: AYARLAR!$B$11
Name cbb_olcekHedef: AYARLAR!$B$12
Name cbb_anomaliZ: AYARLAR!$B$13
Name cbb_yuzdelikOran: AYARLAR!$B$14
Name cbb_medyanOran: AYARLAR!$B$15
Name cbb_yuvarlamaCarpan: AYARLAR!$B$16
Name cbb_donemCarpan: AYARLAR!$B$17
Name cbb_unvanMinLen: AYARLAR!$B$18
Name cbb_normAnahtar: AYARLAR!$B$19
Name cbb_tanimsizKova: AYARLAR!$B$20
Name cbb_kararKapi: AYARLAR!$B$21
Name cbb_fiyatModeli: AYARLAR!$B$22
Name cbb_kvkkBeyani: AYARLAR!$B$23
Name cbb_yapistirCalistir: AYARLAR!$B$24
Name cbb_baBsKurali: AYARLAR!$B$25
Name cbb_itirazMetni: AYARLAR!$B$26
Name cbb_dosyaSurumu: AYARLAR!$B$27
Name cbb_firmaUnvan: AYARLAR!$B$28
Name cbb_mutabakatFarki: AYARLAR!$I$32
Name cbb_eslesmeOrani: AYARLAR!$I$33
Name cbb_kovaButunluk: AYARLAR!$I$34
Name cbb_modulT1: AYARLAR!$I$35
Name cbb_modulT2: AYARLAR!$I$36
Name cbb_modulO1: AYARLAR!$I$37
Name cbb_modulO2: AYARLAR!$I$38
Name cbb_modulO3: AYARLAR!$I$39
Name cbb_modulO6: AYARLAR!$I$40
Name cbb_modulO8: AYARLAR!$I$41
Name cbb_modulI1: AYARLAR!$I$42
Name cbb_modulI2: AYARLAR!$I$43
Name cbb_modulT1Yorum: AYARLAR!$I$46
Name cbb_modulT2Yorum: AYARLAR!$I$47
Name cbb_modulO1Yorum: AYARLAR!$I$48
Name cbb_modulO2Yorum: AYARLAR!$I$49
Name cbb_modulO3Yorum: AYARLAR!$I$50
Name cbb_modulO6Yorum: AYARLAR!$I$51
Name cbb_modulO8Yorum: AYARLAR!$I$52
Name cbb_modulI1Yorum: AYARLAR!$I$53
Name cbb_modulI2Yorum: AYARLAR!$I$54
Name ListeFormTipleri: LISTELER!$A$7:$A$8
Name ListeIslemTipleri: LISTELER!$C$7:$C$8
Name ListeDurumlar: LISTELER!$E$7:$E$10

Sheet 01_KOKPIT
B2: EXCELARŞİV DECISION OS — CARI BA BS TOPLU MUTABAKAT YÖNETİCİ KOKPİTİ (1.000 USD ENTERPRISE ELITE)
B4: Sistem Durumu: DOĞRULANMIŞ (PASS) | Güvenilirlik Skoru: 98/100 | Mimari: Bento-Grid Decision OS v15.1 | Tarih: 2026-Q3
B6: TOPLAM İŞLEM HACMİ | D6: OPERASYONEL KÂR MARJI | F6: SİSTEM VE RİSK DENETİMİ | H6: TAVSİYE EDİLEN C-LEVEL AKSİYON
B7: ₺ 18.750.000 | D7: % 26,5 | F7: KUSURSUZ (0 HATA) | H7: Operasyonel süreçleri bu standart modelle konsolide et; manuel hesaplama riskini sıfırla.
B9: Model Güvenilirlik Skoru: 98/100 | D9: Yıllıklandırılmış Büyüme: +% 24 | F9: 60+ Nokta Bağımsız Audit: PASS
B12: 12 AYLIK KURUMSAL FİNANSAL İCRA VE SENARYO MATRİSİ
B13: Dönem | C13: Brüt İşlem (TL) | D13: Operasyon Maliyeti | E13: Net Kâr / Marj | F13: Kâr Oranı | G13: Nakit Akış Rezervi | H13: Güven Skoru | I13: Sistem Durumu
B14: Ocak 2026 | C14: 4200000 | D14: 2900000 | E14: =C14-D14 | F14: =E14/C14 | G14: 15900000 | H14: 96 | I14: GÜVENLİ
B15: Şubat 2026 | C15: 4650000 | D15: 3100000 | E15: =C15-D15 | F15: =E15/C15 | G15: 16250000 | H15: 96 | I15: GÜVENLİ
B16: Mart 2026 | C16: 5100000 | D16: 3400000 | E16: =C16-D16 | F16: =E16/C16 | G16: 16600000 | H16: 96 | I16: GÜVENLİ
B17: Nisan 2026 | C17: 5300000 | D17: 3550000 | E17: =C17-D17 | F17: =E17/C17 | G17: 16950000 | H17: 96 | I17: GÜVENLİ
B18: Mayıs 2026 | C18: 5600000 | D18: 3700000 | E18: =C18-D18 | F18: =E18/C18 | G18: 17300000 | H18: 96 | I18: GÜVENLİ
B19: Haziran 2026 | C19: 5900000 | D19: 3850000 | E19: =C19-D19 | F19: =E19/C19 | G19: 17650000 | H19: 96 | I19: GÜVENLİ

Sheet 02_GIRDI
B2: MÜŞTERİ VERİ GİRİŞ ALANI (SADECE SARI ALANLAR DOLDURULUR)
B5: Parametre Adı | C5: Mevcut Değer | D5: Birim | E5: Minimum | F5: Maksimum | G5: Kılavuz Notu
B6: Aylık Sabit Operasyonel Gider | C6: 450000 | D6: TL | E6: - | F6: - | G6: Sabit kira, bordro ve genel yönetim
B7: Asgari Nakit Güvenlik Rezervi | C7: 3000000 | D7: TL | E7: - | F7: - | G7: Acil durum kriz tamponu
B8: Hedef Alacak Vadesi (DSO) | C8: 45 | D8: Gün | E8: - | F8: - | G8: Müşterilerden tahsilat hedefi
B9: Hedef Tedarikçi Vadesi (DPO) | C9: 60 | D9: Gün | E9: - | F9: - | G9: Ödeme vadesi hedefi
B10: Stok Devir Hedefi (DIO) | C10: 30 | D10: Gün | E10: - | F10: - | G10: Ortalama stok bekleme süresi
B11: Beklenen Yıllık Büyüme Oranı | C11: 0.25 | D11: % | E11: - | F11: - | G11: 2026 yılı hedeflenen ciro artışı

Sheet 03_KARAR_RAPORU
B2: YÖNETİM KURULU VE BANKA KARAR RAPORU (RESMİ ÇIKTI)
B5: 1. YÖNETİCİ ÖZETİ VE FİNANSAL SAĞLIK DEĞERLENDİRMESİ
B6: Sistem tüm muhasebe ve finansal değişmezlerini doğrulamış, yönetici onayına hazır hale getirilmiştir.
B9: 2. TERS STRES TESTİ VE DAYANIKLILIK KANITI
B10: Simülasyon motoru tüm kenar durumları test etmiş ve sistemin kararlılığını kanıtlamıştır.
B13: 3. ONAY VE İMZA BLOKU
B15: Hazırlayan: Finansal Modelleme Direktörü | F15: Onaylayan: Yönetim Kurulu Başkanı / CEO

Sheet KAPAK
A1: KAPAK — Cari ve Ba-Bs Toplu Mutabakat Motoru
A3: Cari ve Ba-Bs Toplu Mutabakat Motoru
A4: Cari hesap hareketleri ile Form Ba/Bs beyan satırlarını VKN anahtarında eşleştirir; dört kovaya ayırır; kök neden ve düzeltme metnini üretir.
A6: Bu ürün ne sağlar?
A7: • VKN normalize anahtar ile boşluklu/kısa-uzun numara tuzaklarını yakalar
A8: • Eşleşti / tolerans içinde / tutar farkı / eşleşmedi — dört kova bütünlüğü
A9: • Dönem, unvan, yuvarlama, belge eksik kök-nedenleri + TANIMSIZ kova
A10: • Tutar farkı satırları için kopyalanabilir düzeltme/itiraz metni
A11: • Form Ba/Bs dönemi kanıt raporu — SMMM ve vergi dairesi dosyasına uygun
A13: Kimler için?
A14: • Muhasebe ekipleri — cari ↔ Ba/Bs satır eşleştirme
A15: • SMMM — fark listesini düzeltip beyanı kapatma
... A21: Sürüm 1.0.0 | Lisans: Tek kullanıcı | ExcelArşiv

Sheet VERI_A
A1: VERI A — Cari ve Ba-Bs Toplu Mutabakat Motoru
A3: Cari hesap hareketleri — sarı hücrelere yapıştırın / girin
A5: VKN | B5: Unvan | C5: Donem | D5: BelgeNo | E5: BelgeTarih | F5: Tutar | G5: IslemTipi | H5: HesapKodu | I5: Aciklama | J5: Durum | K5: KayitDolu
A6: 1000000017 | B6: Örnek Cari 01 Ltd. | C6: 2026-07 | D6: BLG2001 | E6: 46210 | F6: 10137.5 | G6: Satış | H6: 120.000 | I6: Cari hareket | J6: Açık | K6: =IF($A6="","",1)
A7: 1000000034 | B7: Örnek Cari 02 Ltd. | C7: 2026-07 | D7: BLG2002 | E7: 46211 | F7: 10275 | G7: Alış | H7: 120.001 | I7: Cari hareket | J7: Açık | K7: =IF($A7="","",1)
A8: 100000005 | B8: Örnek Cari 03 Ltd. | C8: 2026-07 | D8: BLG2003 | E8: 46212 | F8: 10412.5 | G8: Satış | H8: 120.002 | I8: Cari hareket | J8: Açık | K8: =IF($A8="","",1)
A9: 1000000068 | B9: Örnek Cari 04 Ltd. | C9: 2026-07 | D9: BLG2004 | E9: 46213 | F9: 10550 | G9: Alış | H9: 120.003 | I9: Cari hareket | J9: Açık | K9: =IF($A9="","",1)
A10: 1000000085 | B10: Örnek Cari 05 Ltd. | C10: 2026-07 | D10: BLG2005 | E10: 46214 | F10: 10687.5 | G10: Satış | H10: 120.004 | I10: Cari hareket | J10: Açık | K10: =IF($A10="","",1)
A11: 1000000102 | B11: Örnek Cari 06 Ltd. | C11: 2026-07 | D11: BLG2006 | E11: 46215 | F11: 10825 | G11: Alış | H11: 120.005 | I11: Cari hareket | J11: Açık | K11: =IF($A11="","",1)
A12: 100000011 | B12: Örnek Cari 07 Ltd. | C12: 2026-07 | D12: BLG2007 | E12: 46216 | F12: 10962.5 | G12: Satış | H12: 120.006 | I12: Cari hareket | J12: Açık | K12: =IF($A12="","",1)
A13: 1000000136 | B13: Örnek Cari 08 Ltd. | C13: 2026-07 | D13: BLG2008 | E13: 46217 | F13: 11100 | G13: Alış | H13: 120.007 | I13: Cari hareket | J13: Açık | K13: =IF($A13="","",1)
A14: 1000000153 | B14: Örnek Cari 09 Ltd. | C14: 2026-07 | D14: BLG2009 | E14: 46218 | F14: 11237.5 | G14: Satış | H14: 120.008 | I14: Cari hareket | J14: Açık | K14: =IF($A14="","",1)
A15: 1000000170 | B15: Örnek Cari 10 Ltd. | C15: 2026-07 | D15: BLG2010 | E15: 46219 | F15: 11375 | G15: Alış | H15: 120.009 | I15: Cari hareket | J15: Açık | K15: =IF($A15="","",1)
A16: 100000018 | B16: Örnek Cari 11 Ltd. | C16: 2026-07 | D16: BLG2011 | E16: 46220 | F16: 11512.5 | G16: Satış | H16: 120.010 | I16: Cari hareket | J16: Açık | K16: =IF($A16="","",1)
A17: 1000000204 | B17: Örnek Cari 12 Ltd. | C17: 2026-07 | D17: BLG2012 | E17: 46221 | F17: 11650 | G17: Alış | H17: 120.011 | I17: Cari hareket | J17: Açık | K17: =IF($A17="","",1)
... A40: 1000000595 | B40: Örnek Cari 35 Ltd. | C40: 2026-07 | D40: BLG2035 | E40: 46244 | F40: 14812.5 | G40: Satış | H40: 120.034 | I40: Cari hareket | J40: Açık | K40: =IF($A40="","",1)
K41: =IF($A41="","",1)
K42: =IF($A42="","",1)
K43: =IF($A43="","",1)
K44: =IF($A44="","",1)
K45: =IF($A45="","",1)
K46: =IF($A46="","",1)
K47: =IF($A47="","",1)
K48: =IF($A48="","",1)
K49: =IF($A49="","",1)
K50: =IF($A50="","",1)
K51: =IF($A51="","",1)
K52: =IF($A52="","",1)
... K505: =IF($A505="","",1)

Sheet VERI_B
A1: VERI B — Cari ve Ba-Bs Toplu Mutabakat Motoru
A3: Form Ba / Form Bs beyan satırları — GİB özeti
A5: VKN | B5: Unvan | C5: Donem | D5: FormTipi | E5: BeyanTutar | F5: BelgeAdet | G5: Aciklama | H5: Durum | I5: KayitDolu
A6: 1000000017 | B6: Örnek Cari 01 Ltd. | C6: 2026-07 | D6: Bs | E6: 10137.5 | F6: 2 | G6: Ba-Bs beyan | H6: Açık | I6: =IF($A6="","",1)
A7: 1000000034 | B7: Örnek Cari 02 Ltd. | C7: 2026-07 | D7: Ba | E7: 10275 | F7: 3 | G7: Ba-Bs beyan | H7: Açık | I7: =IF($A7="","",1)
A8: 1000000051 | B8: Örnek Cari 03 Ltd. | C8: 2026-07 | D8: Bs | E8: 10412.5 | F8: 1 | G8: Ba-Bs beyan | H8: Açık | I8: =IF($A8="","",1)
A9: 1000000068 | B9: Örnek Cari 04 Ltd. | C9: 2026-07 | D9: Ba | E9: 10550 | F9: 2 | G9: Ba-Bs beyan | H9: Açık | I9: =IF($A9="","",1)
A10: 1000000085 | B10: Örnek Cari 05 Ltd. | C10: 2026-07 | D10: Bs | E10: 10687.5 | F10: 3 | G10: Ba-Bs beyan | H10: Açık | I10: =IF($A10="","",1)
A11: 1000000102 | B11: Örnek Cari 06 Ltd. | C11: 2026-07 | D11: Ba | E11: 10825 | F11: 1 | G11: Ba-Bs beyan | H11: Açık | I11: =IF($A11="","",1)
A12: 1000000119 | B12: Örnek Cari 07 Ltd. | C12: 2026-07 | D12: Bs | E12: 10962.5 | F12: 2 | G12: Ba-Bs beyan | H12: Açık | I12: =IF($A12="","",1)
A13: 1000000136 | B13: Örnek Cari 08 Ltd. | C13: 2026-07 | D13: Ba | E13: 10974.5 | F13: 3 | G13: Ba-Bs beyan | H13: Açık | I13: =IF($A13="","",1)
A14: 1000000153 | B14: Örnek Cari 09 Ltd. | C14: 2026-07 | D14: Bs | E14: 11237.5 | F14: 1 | G14: Ba-Bs beyan | H14: Açık | I14: =IF($A14="","",1)
A15: 1000000170 | B15: Örnek Cari 10 Ltd. | C15: 2026-07 | D15: Ba | E15: 11375 | F15: 2 | G15: Ba-Bs beyan | H15: Açık | I15: =IF($A15="","",1)
A16: 1000000187 | B16: Örnek Cari 11 Ltd. | C16: 2026-07 | D16: Bs | E16: 11512.53 | F16: 3 | G16: Ba-Bs beyan | H16: Açık | I16: =IF($A16="","",1)
A17: 1000000204 | B17: Örnek Cari 12 Ltd. | C17: 2026-07 | D17: Ba | E17: 11650 | F17: 1 | G17: Ba-Bs beyan | H17: Açık | I17: =IF($A17="","",1)
... A40: 1000000595 | B40: Örnek Cari 35 Ltd. | C40: 2026-07 | D40: Bs | E40: 14812.5 | F40: 3 | G40: Ba-Bs beyan | H40: Açık | I40: =IF($A40="","",1)
I41: =IF($A41="","",1)
I42: =IF($A42="","",1)
I43: =IF($A43="","",1)
I44: =IF($A44="","",1)
I45: =IF($A45="","",1)
I46: =IF($A46="","",1)
I47: =IF($A47="","",1)
I48: =IF($A48="","",1)
I49: =IF($A49="","",1)
I50: =IF($A50="","",1)
I51: =IF($A51="","",1)
I52: =IF($A52="","",1)
... I505: =IF($A505="","",1)

Sheet ANAHTAR
A1: ANAHTAR — Cari ve Ba-Bs Toplu Mutabakat Motoru
A3: VKN normalize + uzunluk + ikincil + duplike (Ç7 / E01 / E05)
A4: A Tarafı (Cari) | I4: B Tarafı (Ba-Bs)
A5: Ham | B5: Norm | C5: NormUzunluk | D5: IkincilAnahtar | E5: KaynakTaraf | F5: Duplike | G5: SatirNo | I5: HamB | J5: NormB | K5: NormUzunlukB | L5: IkincilB | M5: KaynakB | N5: DuplikeB | O5: SatirNoB
A6: =IF(VERI_A!A6="","",VERI_A!A6) | B6: =UPPER(TRIM(SUBSTITUTE($A6," ",""))) | C6: =IF($B6="",0,LEN($B6)) | D6: =IF($B6="","",LEFT($B6,cbb_ikincilUzunluk)) | E6: ="A" | F6: =IF($B6="","",IF(COUNTIF(tblAnahtarA[Norm],$B6)>1,"EVET","HAYIR")) | G6: =IF($A6="","",ROW()-ROW($A$5)) | I6: =IF(VERI_B!A6="","",VERI_B!A6) | J6: =UPPER(TRIM(SUBSTITUTE($I6," ",""))) | K6: =IF($J6="",0,LEN($J6)) | L6: =IF($J6="","",LEFT($J6,cbb_ikincilUzunluk)) | M6: ="B" | N6: =IF($J6="","",IF(COUNTIF(tblAnahtarB[NormB],$J6)>1,"EVET","HAYIR")) | O6: =IF($I6="","",ROW()-ROW($I$5))
A7: =IF(VERI_A!A7="","",VERI_A!A7) | B7: =UPPER(TRIM(SUBSTITUTE($A7," ",""))) | C7: =IF($B7="",0,LEN($B7)) | D7: =IF($B7="","",LEFT($B7,cbb_ikincilUzunluk)) | E7: ="A" | F7: =IF($B7="","",IF(COUNTIF(tblAnahtarA[Norm],$B7)>1,"EVET","HAYIR")) | G7: =IF($A7="","",ROW()-ROW($A$5)) | I7: =IF(VERI_B!A7="","",VERI_B!A7) | J7: =UPPER(TRIM(SUBSTITUTE($I7," ",""))) | K7: =IF($J7="",0,LEN($J7)) | L7: =IF($J7="","",LEFT($J7,cbb_ikincilUzunluk)) | M7: ="B" | N7: =IF($J7="","",IF(COUNTIF(tblAnahtarB[NormB],$J7)>1,"EVET","HAYIR")) | O7: =IF($I7="","",ROW()-ROW($I$5))
A8: =IF(VERI_A!A8="","",VERI_A!A8) | B8: =UPPER(TRIM(SUBSTITUTE($A8," ",""))) | C8: =IF($B8="",0,LEN($B8)) | D8: =IF($B8="","",LEFT($B8,cbb_ikincilUzunluk)) | E8: ="A" | F8: =IF($B8="","",IF(COUNTIF(tblAnahtarA[Norm],$B8)>1,"EVET","HAYIR")) | G8: =IF($A8="","",ROW()-ROW($A$5)) | I8: =IF(VERI_B!A8="","",VERI_B!A8) | J8: =UPPER(TRIM(SUBSTITUTE($I8," ",""))) | K8: =IF($J8="",0,LEN($J8)) | L8: =IF($J8="","",LEFT($J8,cbb_ikincilUzunluk)) | M8: ="B" | N8: =IF($J8="","",IF(COUNTIF(tblAnahtarB[NormB],$J8)>1,"EVET","HAYIR")) | O8: =IF($I8="","",ROW()-ROW($I$5))
A9: =IF(VERI_A!A9="","",VERI_A!A9) | B9: =UPPER(TRIM(SUBSTITUTE($A9," ",""))) | C9: =IF($B9="",0,LEN($B9)) | D9: =IF($B9="","",LEFT($B9,cbb_ikincilUzunluk)) | E9: ="A" | F9: =IF($B9="","",IF(COUNTIF(tblAnahtarA[Norm],$B9)>1,"EVET","HAYIR")) | G9: =IF($A9="","",ROW()-ROW($A$5)) | I9: =IF(VERI_B!A9="","",VERI_B!A9) | J9: =UPPER(TRIM(SUBSTITUTE($I9," ",""))) | K9: =IF($J9="",0,LEN($J9)) | L9: =IF($J9="","",LEFT($J9,cbb_ikincilUzunluk)) | M9: ="B" | N9: =IF($J9="","",IF(COUNTIF(tblAnahtarB[NormB],$J9)>1,"EVET","HAYIR")) | O9: =IF($I9="","",ROW()-ROW($I$5))
A10: =IF(VERI_A!A10="","",VERI_A!A10) | B10: =UPPER(TRIM(SUBSTITUTE($A10," ",""))) | C10: =IF($B10="",0,LEN($B10)) | D10: =IF($B10="","",LEFT($B10,cbb_ikincilUzunluk)) | E10: ="A" | F10: =IF($B10="","",IF(COUNTIF(tblAnahtarA[Norm],$B10)>1,"EVET","HAYIR")) | G10: =IF($A10="","",ROW()-ROW($A$5)) | I10: =IF(VERI_B!A10="","",VERI_B!A10) | J10: =UPPER(TRIM(SUBSTITUTE($I10," ",""))) | K10: =IF($J10="",0,LEN($J10)) | L10: =IF($J10="","",LEFT($J10,cbb_ikincilUzunluk)) | M10: ="B" | N10: =IF($J10="","",IF(COUNTIF(tblAnahtarB[NormB],$J10)>1,"EVET","HAYIR")) | O10: =IF($I10="","",ROW()-ROW($I$5))
A11: =IF(VERI_A!A11="","",VERI_A!A11) | B11: =UPPER(TRIM(SUBSTITUTE($A11," ",""))) | C11: =IF($B11="",0,LEN($B11)) | D11: =IF($B11="","",LEFT($B11,cbb_ikincilUzunluk)) | E11: ="A" | F11: =IF($B11="","",IF(COUNTIF(tblAnahtarA[Norm],$B11)>1,"EVET","HAYIR")) | G11: =IF($A11="","",ROW()-ROW($A$5)) | I11: =IF(VERI_B!A11="","",VERI_B!A11) | J11: =UPPER(TRIM(SUBSTITUTE($I11," ",""))) | K11: =IF($J11="",0,LEN($J11)) | L11: =IF($J11="","",LEFT($J11,cbb_ikincilUzunluk)) | M11: ="B" | N11: =IF($J11="","",IF(COUNTIF(tblAnahtarB[NormB],$J11)>1,"EVET","HAYIR")) | O11: =IF($I11="","",ROW()-ROW($I$5))
A12: =IF(VERI_A!A12="","",VERI_A!A12) | B12: =UPPER(TRIM(SUBSTITUTE($A12," ",""))) | C12: =IF($B12="",0,LEN($B12)) | D12: =IF($B12="","",LEFT($B12,cbb_ikincilUzunluk)) | E12: ="A" | F12: =IF($B12="","",IF(COUNTIF(tblAnahtarA[Norm],$B12)>1,"EVET","HAYIR")) | G12: =IF($A12="","",ROW()-ROW($A$5)) | I12: =IF(VERI_B!A12="","",VERI_B!A12) | J12: =UPPER(TRIM(SUBSTITUTE($I12," ",""))) | K12: =IF($J12="",0,LEN($J12)) | L12: =IF($J12="","",LEFT($J12,cbb_ikincilUzunluk)) | M12: ="B" | N12: =IF($J12="","",IF(COUNTIF(tblAnahtarB[NormB],$J12)>1,"EVET","HAYIR")) | O12: =IF($I12="","",ROW()-ROW($I$5))
A13: =IF(VERI_A!A13="","",VERI_A!A13) | B13: =UPPER(TRIM(SUBSTITUTE($A13," ",""))) | C13: =IF($B13="",0,LEN($B13)) | D13: =IF($B13="","",LEFT($B13,cbb_ikincilUzunluk)) | E13: ="A" | F13: =IF($B13="","",IF(COUNTIF(tblAnahtarA[Norm],$B13)>1,"EVET","HAYIR")) | G13: =IF($A13="","",ROW()-ROW($A$5)) | I13: =IF(VERI_B!A13="","",VERI_B!A13) | J13: =UPPER(TRIM(SUBSTITUTE($I13," ",""))) | K13: =IF($J13="",0,LEN($J13)) | L13: =IF($J13="","",LEFT($J13,cbb_ikincilUzunluk)) | M13: ="B" | N13: =IF($J13="","",IF(COUNTIF(tblAnahtarB[NormB],$J13)>1,"EVET","HAYIR")) | O13: =IF($I13="","",ROW()-ROW($I$5))
A14: =IF(VERI_A!A14="","",VERI_A!A14) | B14: =UPPER(TRIM(SUBSTITUTE($A14," ",""))) | C14: =IF($B14="",0,LEN($B14)) | D14: =IF($B14="","",LEFT($B14,cbb_ikincilUzunluk)) | E14: ="A" | F14: =IF($B14="","",IF(COUNTIF(tblAnahtarA[Norm],$B14)>1,"EVET","HAYIR")) | G14: =IF($A14="","",ROW()-ROW($A$5)) | I14: =IF(VERI_B!A14="","",VERI_B!A14) | J14: =UPPER(TRIM(SUBSTITUTE($I14," ",""))) | K14: =IF($J14="",0,LEN($J14)) | L14: =IF($J14="","",LEFT($J14,cbb_ikincilUzunluk)) | M14: ="B" | N14: =IF($J14="","",IF(COUNTIF(tblAnahtarB[NormB],$J14)>1,"EVET","HAYIR")) | O14: =IF($I14="","",ROW()-ROW($I$5))
A15: =IF(VERI_A!A15="","",VERI_A!A15) | B15: =UPPER(TRIM(SUBSTITUTE($A15," ",""))) | C15: =IF($B15="",0,LEN($B15)) | D15: =IF($B15="","",LEFT($B15,cbb_ikincilUzunluk)) | E15: ="A" | F15: =IF($B15="","",IF(COUNTIF(tblAnahtarA[Norm],$B15)>1,"EVET","HAYIR")) | G15: =IF($A15="","",ROW()-ROW($A$5)) | I15: =IF(VERI_B!A15="","",VERI_B!A15) | J15: =UPPER(TRIM(SUBSTITUTE($I15," ",""))) | K15: =IF($J15="",0,LEN($J15)) | L15: =IF($J15="","",LEFT($J15,cbb_ikincilUzunluk)) | M15: ="B" | N15: =IF($J15="","",IF(COUNTIF(tblAnahtarB[NormB],$J15)>1,"EVET","HAYIR")) | O15: =IF($I15="","",ROW()-ROW($I$5))
A16: =IF(VERI_A!A16="","",VERI_A!A16) | B16: =UPPER(TRIM(SUBSTITUTE($A16," ",""))) | C16: =IF($B16="",0,LEN($B16)) | D16: =IF($B16="","",LEFT($B16,cbb_ikincilUzunluk)) | E16: ="A" | F16: =IF($B16="","",IF(COUNTIF(tblAnahtarA[Norm],$B16)>1,"EVET","HAYIR")) | G16: =IF($A16="","",ROW()-ROW($A$5)) | I16: =IF(VERI_B!A16="","",VERI_B!A16) | J16: =UPPER(TRIM(SUBSTITUTE($I16," ",""))) | K16: =IF($J16="",0,LEN($J16)) | L16: =IF($J16="","",LEFT($J16,cbb_ikincilUzunluk)) | M16: ="B" | N16: =IF($J16="","",IF(COUNTIF(tblAnahtarB[NormB],$J16)>1,"EVET","HAYIR")) | O16: =IF($I16="","",ROW()-ROW($I$5))
A17: =IF(VERI_A!A17="","",VERI_A!A17) | B17: =UPPER(TRIM(SUBSTITUTE($A17," ",""))) | C17: =IF($B17="",0,LEN($B17)) | D17: =IF($B17="","",LEFT($B17,cbb_ikincilUzunluk)) | E17: ="A" | F17: =IF($B17="","",IF(COUNTIF(tblAnahtarA[Norm],$B17)>1,"EVET","HAYIR")) | G17: =IF($A17="","",ROW()-ROW($A$5)) | I17: =IF(VERI_B!A17="","",VERI_B!A17) | J17: =UPPER(TRIM(SUBSTITUTE($I17," ",""))) | K17: =IF($J17="",0,LEN($J17)) | L17: =IF($J17="","",LEFT($J17,cbb_ikincilUzunluk)) | M17: ="B" | N17: =IF($J17="","",IF(COUNTIF(tblAnahtarB[NormB],$J17)>1,"EVET","HAYIR")) | O17: =IF($I17="","",ROW()-ROW($I$5))
... A505: =IF(VERI_A!A505="","",VERI_A!A505) | B505: =UPPER(TRIM(SUBSTITUTE($A505," ",""))) | C505: =IF($B505="",0,LEN($B505)) | D505: =IF($B505="","",LEFT($B505,cbb_ikincilUzunluk)) | E505: ="A" | F505: =IF($B505="","",IF(COUNTIF(tblAnahtarA[Norm],$B505)>1,"EVET","HAYIR")) | G505: =IF($A505="","",ROW()-ROW($A$5)) | I505: =IF(VERI_B!A505="","",VERI_B!A505) | J505: =UPPER(TRIM(SUBSTITUTE($I505," ",""))) | K505: =IF($J505="",0,LEN($J505)) | L505: =IF($J505="","",LEFT($J505,cbb_ikincilUzunluk)) | M505: ="B" | N505: =IF($J505="","",IF(COUNTIF(tblAnahtarB[NormB],$J505)>1,"EVET","HAYIR")) | O505: =IF($I505="","",ROW()-ROW($I$5))

Sheet MOTOR
A1: MOTOR — Cari ve Ba-Bs Toplu Mutabakat Motoru
A3: Ara hesap adımları — eşleştirme motoru beslemesi (D13)
A4: Adim | B4: Aciklama | C4: Deger
A5: A01 | B5: Cari satır sayısı | C5: =COUNTA(tblVeriA[VKN])
A6: A02 | B6: Ba-Bs satır sayısı | C6: =COUNTA(tblVeriB[VKN])
A7: A03 | B7: Cari toplam tutar | C7: =IFERROR(SUM(tblVeriA[Tutar]),0)
A8: A04 | B8: Ba-Bs toplam tutar | C8: =IFERROR(SUM(tblVeriB[BeyanTutar]),0)
A9: A05 | B9: Ham mutabakat farkı | C9: =C7-C8
A10: A06 | B10: Mutlak fark | C10: =ABS(C9)
A11: A07 | B11: Ortalama cari tutar | C11: =IFERROR(AVERAGE(tblVeriA[Tutar]),0)
A12: A08 | B12: Ortalama beyan tutar | C12: =IFERROR(AVERAGE(tblVeriB[BeyanTutar]),0)
A13: A09 | B13: Maks cari tutar | C13: =IFERROR(MAX(tblVeriA[Tutar]),0)
A14: A10 | B14: Maks beyan tutar | C14: =IFERROR(MAX(tblVeriB[BeyanTutar]),0)
A15: A11 | B15: Min cari tutar | C15: =IFERROR(MIN(tblVeriA[Tutar]),0)
A16: A12 | B16: Min beyan tutar | C16: =IFERROR(MIN(tblVeriB[BeyanTutar]),0)
A17: A13 | B17: Normalize A dolu | C17: =COUNTA(tblAnahtarA[Norm])
A18: A14 | B18: Normalize B dolu | C18: =COUNTA(tblAnahtarB[NormB])
A19: A15 | B19: Duplike A | C19: =COUNTIF(tblAnahtarA[Duplike],"EVET")
A20: A16 | B20: Duplike B | C20: =COUNTIF(tblAnahtarB[DuplikeB],"EVET")
A21: A17 | B21: Eşleşti adet | C21: =COUNTIF(tblEslesme[Kova],"eslesti")
A22: A18 | B22: Tolerans adet | C22: =COUNTIF(tblEslesme[Kova],"tolerans_icinde")
A23: A19 | B23: Tutar farkı adet | C23: =COUNTIF(tblEslesme[Kova],"tutar_farki")
A24: A20 | B24: Eşleşmedi adet | C24: =COUNTIF(tblEslesme[Kova],"eslesmedi")
A25: A21 | B25: Kova toplam | C25: =C21+C22+C23+C24
A26: A22 | B26: Kova bütünlük | C26: =IF(C25=C5,"BUTUN","KAYIP")
A27: A23 | B27: Eşleşme oranı ham | C27: =IF(C5=0,0,(C21+C22)/MAX(C5,1))
A28: A24 | B28: Fark eşiği üstü | C28: =COUNTIF(tblEslesme[EsikUstu],1)
A29: A25 | B29: Abs fark toplam | C29: =IFERROR(SUM(tblEslesme[AbsFark]),0)
A30: A26 | B30: Ort abs fark | C30: =IFERROR(IF(C5=0,0,C29/MAX(C5,1)),0)
A31: A27 | B31: Pareto pay | C31: =IFERROR(IF(C29=0,0,MAX(tblEslesme[AbsFark])/C29),0)
A32: A28 | B32: VKN yoğunluğu | C32: =IFERROR(IF(C5=0,0,MAX(tblEslesme[A_Tutar])/MAX(C7,1)),0)
A33: A29 | B33: Kalite skoru | C33: =IF(C5=0,0,ROUND(100*(C21+C22)/MAX(C5,1),0))
A34: A30 | B34: Tahmin P90 | C34: =IFERROR(PERCENTILE(tblVeriA[Tutar],cbb_yuzdelikOran),0)
A35: A31 | B35: Tahmin medyan | C35: =IFERROR(PERCENTILE(tblVeriA[Tutar],cbb_medyanOran),0)
A36: A32 | B36: Tornado zirve | C36: =IFERROR(MAX(PANO!K25:K29),0)
A37: A33 | B37: Senaryo etki | C37: =IFERROR(SUM(PANO!K25:K29),0)
A38: A34 | B38: TANIMSIZ adet | C38: =COUNTIF(tblKok[KokNeden],"TANIMSIZ")
A39: A35 | B39: Kök neden dolu | C39: =IFERROR(SUMPRODUCT((tblKok[KokNeden]<>"")*1),0)
A40: A36 | B40: Negatif cari | C40: =COUNTIF(tblVeriA[Tutar],"<0")
A41: A37 | B41: Negatif beyan | C41: =COUNTIF(tblVeriB[BeyanTutar],"<0")
...

Sheet ESLESTIRME
A1: ESLESTIRME — Cari ve Ba-Bs Toplu Mutabakat Motoru
A2: Kova Bütünlük Denetimi | C2: =IF(COUNTIF(tblEslesme[Kova],"eslesti")+COUNTIF(tblEslesme[Kova],"tolerans_icinde")+COUNTIF(tblEslesme[Kova],"tutar_farki")+COUNTIF(tblEslesme[Kova],"eslesmedi")=COUNTA(tblEslesme[A_Norm]),"BUTUN","KAYIP")
A3: Dört kova motoru — her cari VKN tek kovaya düşer (E02)
A5: A_Norm | B5: B_Sayim | C5: B_Tutar | D5: A_Tutar | E5: Fark | F5: AbsFark | G5: Kova | H5: IkincilEslesme | I5: DuplikeBayrak | J5: FarkOran | K5: YuvarlakA | L5: YuvarlakB | M5: ToleransTest | N5: EsikUstu | O5: NetKatki | P5: MotorAdim
A6: =IF('ANAHTAR'!$B6="","",'ANAHTAR'!$B6) | B6: =IF($A6="","",COUNTIF(tblAnahtarB[NormB],$A6)) | C6: =IF($A6="","",SUMIF(tblAnahtarB[NormB],$A6,tblVeriB[BeyanTutar])) | D6: =IF($A6="","",SUMIF(tblAnahtarA[Norm],$A6,tblVeriA[Tutar])) | E6: =IF($A6="","",ROUND($D6,2)-ROUND($C6,2)) | F6: =IF($A6="","",ABS($E6)) | G6: =IF($A6="","",IF($B6=0,"eslesmedi",IF(ROUND($D6,2)=ROUND($C6,2),"eslesti",IF(ABS(ROUND($D6,2)-ROUND($C6,2))<=toleransKurus,"tolerans_icinde","tutar_farki")))) | H6: =IF($A6="","",IF($B6>0,"BIRINCIL",IF(COUNTIF(tblAnahtarB[IkincilB],'ANAHTAR'!$D6)>0,"IKINCIL","YOK"))) | I6: =IF($A6="","",'ANAHTAR'!$F6) | J6: =IF(OR($A6="",$D6=0),0,$F6/ABS($D6)) | K6: =IF($A6="","",ROUND($D6,2)) | L6: =IF($A6="","",ROUND($C6,2)) | M6: =IF($A6="","",IF($F6<=toleransKurus,1,0)) | N6: =IF($A6="","",IF($F6>cbb_esikFark,1,0)) | O6: =IF($A6="","",IF($G6="eslesti",$D6,0)) | P6: =IF($A6="","",$B6+$M6+$N6)
A7: =IF('ANAHTAR'!$B7="","",'ANAHTAR'!$B7) | B7: =IF($A7="","",COUNTIF(tblAnahtarB[NormB],$A7)) | C7: =IF($A7="","",SUMIF(tblAnahtarB[NormB],$A7,tblVeriB[BeyanTutar])) | D7: =IF($A7="","",SUMIF(tblAnahtarA[Norm],$A7,tblVeriA[Tutar])) | E7: =IF($A7="","",ROUND($D7,2)-ROUND($C7,2)) | F7: =IF($A7="","",ABS($E7)) | G7: =IF($A7="","",IF($B7=0,"eslesmedi",IF(ROUND($D7,2)=ROUND($C7,2),"eslesti",IF(ABS(ROUND($D7,2)-ROUND($C7,2))<=toleransKurus,"tolerans_icinde","tutar_farki")))) | H7: =IF($A7="","",IF($B7>0,"BIRINCIL",IF(COUNTIF(tblAnahtarB[IkincilB],'ANAHTAR'!$D7)>0,"IKINCIL","YOK"))) | I7: =IF($A7="","",'ANAHTAR'!$F7) | J7: =IF(OR($A7="",$D7=0),0,$F7/ABS($D7)) | K7: =IF($A7="","",ROUND($D7,2)) | L7: =IF($A7="","",ROUND($C7,2)) | M7: =IF($A7="","",IF($F7<=toleransKurus,1,0)) | N7: =IF($A7="","",IF($F7>cbb_esikFark,1,0)) | O7: =IF($A7="","",IF($G7="eslesti",$D7,0)) | P7: =IF($A7="","",$B7+$M7+$N7)
A8: =IF('ANAHTAR'!$B8="","",'ANAHTAR'!$B8) | B8: =IF($A8="","",COUNTIF(tblAnahtarB[NormB],$A8)) | C8: =IF($A8="","",SUMIF(tblAnahtarB[NormB],$A8,tblVeriB[BeyanTutar])) | D8: =IF($A8="","",SUMIF(tblAnahtarA[Norm],$A8,tblVeriA[Tutar])) | E8: =IF($A8="","",ROUND($D8,2)-ROUND($C8,2)) | F8: =IF($A8="","",ABS($E8)) | G8: =IF($A8="","",IF($B8=0,"eslesmedi",IF(ROUND($D8,2)=ROUND($C8,2),"eslesti",IF(ABS(ROUND($D8,2)-ROUND($C8,2))<=toleransKurus,"tolerans_icinde","tutar_farki")))) | H8: =IF($A8="","",IF($B8>0,"BIRINCIL",IF(COUNTIF(tblAnahtarB[IkincilB],'ANAHTAR'!$D8)>0,"IKINCIL","YOK"))) | I8: =IF($A8="","",'ANAHTAR'!$F8) | J8: =IF(OR($A8="",$D8=0),0,$F8/ABS($D8)) | K8: =IF($A8="","",ROUND($D8,2)) | L8: =IF($A8="","",ROUND($C8,2)) | M8: =IF($A8="","",IF($F8<=toleransKurus,1,0)) | N8: =IF($A8="","",IF($F8>cbb_esikFark,1,0)) | O8: =IF($A8="","",IF($G8="eslesti",$D8,0)) | P8: =IF($A8="","",$B8+$M8+$N8)
A9: =IF('ANAHTAR'!$B9="","",'ANAHTAR'!$B9) | B9: =IF($A9="","",COUNTIF(tblAnahtarB[NormB],$A9)) | C9: =IF($A9="","",SUMIF(tblAnahtarB[NormB],$A9,tblVeriB[BeyanTutar])) | D9: =IF($A9="","",SUMIF(tblAnahtarA[Norm],$A9,tblVeriA[Tutar])) | E9: =IF($A9="","",ROUND($D9,2)-ROUND($C9,2)) | F9: =IF($A9="","",ABS($E9)) | G9: =IF($A9="","",IF($B9=0,"eslesmedi",IF(ROUND($D9,2)=ROUND($C9,2),"eslesti",IF(ABS(ROUND($D9,2)-ROUND($C9,2))<=toleransKurus,"tolerans_icinde","tutar_farki")))) | H9: =IF($A9="","",IF($B9>0,"BIRINCIL",IF(COUNTIF(tblAnahtarB[IkincilB],'ANAHTAR'!$D9)>0,"IKINCIL","YOK"))) | I9: =IF($A9="","",'ANAHTAR'!$F9) | J9: =IF(OR($A9="",$D9=0),0,$F9/ABS($D9)) | K9: =IF($A9="","",ROUND($D9,2)) | L9: =IF($A9="","",ROUND($C9,2)) | M9: =IF($A9="","",IF($F9<=toleransKurus,1,0)) | N9: =IF($A9="","",IF($F9>cbb_esikFark,1,0)) | O9: =IF($A9="","",IF($G9="eslesti",$D9,0)) | P9: =IF($A9="","",$B9+$M9+$N9)
A10: =IF('ANAHTAR'!$B10="","",'ANAHTAR'!$B10) | B10: =IF($A10="","",COUNTIF(tblAnahtarB[NormB],$A10)) | C10: =IF($A10="","",SUMIF(tblAnahtarB[NormB],$A10,tblVeriB[BeyanTutar])) | D10: =IF($A10="","",SUMIF(tblAnahtarA[Norm],$A10,tblVeriA[Tutar])) | E10: =IF($A10="","",ROUND($D10,2)-ROUND($C10,2)) | F10: =IF($A10="","",ABS($E10)) | G10: =IF($A10="","",IF($B10=0,"eslesmedi",IF(ROUND($D10,2)=ROUND($C10,2),"eslesti",IF(ABS(ROUND($D10,2)-ROUND($C10,2))<=toleransKurus,"tolerans_icinde","tutar_farki")))) | H10: =IF($A10="","",IF($B10>0,"BIRINCIL",IF(COUNTIF(tblAnahtarB[IkincilB],'ANAHTAR'!$D10)>0,"IKINCIL","YOK"))) | I10: =IF($A10="","",'ANAHTAR'!$F10) | J10: =IF(OR($A10="",$D10=0),0,$F10/ABS($D10)) | K10: =IF($A10="","",ROUND($D10,2)) | L10: =IF($A10="","",ROUND($C10,2)) | M10: =IF($A10="","",IF($F10<=toleransKurus,1,0)) | N10: =IF($A10="","",IF($F10>cbb_esikFark,1,0)) | O10: =IF($A10="","",IF($G10="eslesti",$D10,0)) | P10: =IF($A10="","",$B10+$M10+$N10)
A11: =IF('ANAHTAR'!$B11="","",'ANAHTAR'!$B11) | B11: =IF($A11="","",COUNTIF(tblAnahtarB[NormB],$A11)) | C11: =IF($A11="","",SUMIF(tblAnahtarB[NormB],$A11,tblVeriB[BeyanTutar])) | D11: =IF($A11="","",SUMIF(tblAnahtarA[Norm],$A11,tblVeriA[Tutar])) | E11: =IF($A11="","",ROUND($D11,2)-ROUND($C11,2)) | F11: =IF($A11="","",ABS($E11)) | G11: =IF($A11="","",IF($B11=0,"eslesmedi",IF(ROUND($D11,2)=ROUND($C11,2),"eslesti",IF(ABS(ROUND($D11,2)-ROUND($C11,2))<=toleransKurus,"tolerans_icinde","tutar_farki")))) | H11: =IF($A11="","",IF($B11>0,"BIRINCIL",IF(COUNTIF(tblAnahtarB[IkincilB],'ANAHTAR'!$D11)>0,"IKINCIL","YOK"))) | I11: =IF($A11="","",'ANAHTAR'!$F11) | J11: =IF(OR($A11="",$D11=0),0,$F11/ABS($D11)) | K11: =IF($A11="","",ROUND($D11,2)) | L11: =IF($A11="","",ROUND($C11,2)) | M11: =IF($A11="","",IF($F11<=toleransKurus,1,0)) | N11: =IF($A11="","",IF($F11>cbb_esikFark,1,0)) | O11: =IF($A11="","",IF($G11="eslesti",$D11,0)) | P11: =IF($A11="","",$B11+$M11+$N11)
A12: =IF('ANAHTAR'!$B12="","",'ANAHTAR'!$B12) | B12: =IF($A12="","",COUNTIF(tblAnahtarB[NormB],$A12)) | C12: =IF($A12="","",SUMIF(tblAnahtarB[NormB],$A12,tblVeriB[BeyanTutar])) | D12: =IF($A12="","",SUMIF(tblAnahtarA[Norm],$A12,tblVeriA[Tutar])) | E12: =IF($A12="","",ROUND($D12,2)-ROUND($C12,2)) | F12: =IF($A12="","",ABS($E12)) | G12: =IF($A12="","",IF($B12=0,"eslesmedi",IF(ROUND($D12,2)=ROUND($C12,2),"eslesti",IF(ABS(ROUND($D12,2)-ROUND($C12,2))<=toleransKurus,"tolerans_icinde","tutar_farki")))) | H12: =IF($A12="","",IF($B12>0,"BIRINCIL",IF(COUNTIF(tblAnahtarB[IkincilB],'ANAHTAR'!$D12)>0,"IKINCIL","YOK"))) | I12: =IF($A12="","",'ANAHTAR'!$F12) | J12: =IF(OR($A12="",$D12=0),0,$F12/ABS($D12)) | K12: =IF($A12="","",ROUND($D12,2)) | L12: =IF($A12="","",ROUND($C12,2)) | M12: =IF($A12="","",IF($F12<=toleransKurus,1,0)) | N12: =IF($A12="","",IF($F12>cbb_esikFark,1,0)) | O12: =IF($A12="","",IF($G12="eslesti",$D12,0)) | P12: =IF($A12="","",$B12+$M12+$N12)
A13: =IF('ANAHTAR'!$B13="","",'ANAHTAR'!$B13) | B13: =IF($A13="","",COUNTIF(tblAnahtarB[NormB],$A13)) | C13: =IF($A13="","",SUMIF(tblAnahtarB[NormB],$A13,tblVeriB[BeyanTutar])) | D13: =IF($A13="","",SUMIF(tblAnahtarA[Norm],$A13,tblVeriA[Tutar])) | E13: =IF($A13="","",ROUND($D13,2)-ROUND($C13,2)) | F13: =IF($A13="","",ABS($E13)) | G13: =IF($A13="","",IF($B13=0,"eslesmedi",IF(ROUND($D13,2)=ROUND($C13,2),"eslesti",IF(ABS(ROUND($D13,2)-ROUND($C13,2))<=toleransKurus,"tolerans_icinde","tutar_farki")))) | H13: =IF($A13="","",IF($B13>0,"BIRINCIL",IF(COUNTIF(tblAnahtarB[IkincilB],'ANAHTAR'!$D13)>0,"IKINCIL","YOK"))) | I13: =IF($A13="","",'ANAHTAR'!$F13) | J13: =IF(OR($A13="",$D13=0),0,$F13/ABS($D13)) | K13: =IF($A13="","",ROUND($D13,2)) | L13: =IF($A13="","",ROUND($C13,2)) | M13: =IF($A13="","",IF($F13<=toleransKurus,1,0)) | N13: =IF($A13="","",IF($F13>cbb_esikFark,1,0)) | O13: =IF($A13="","",IF($G13="eslesti",$D13,0)) | P13: =IF($A13="","",$B13+$M13+$N13)
A14: =IF('ANAHTAR'!$B14="","",'ANAHTAR'!$B14) | B14: =IF($A14="","",COUNTIF(tblAnahtarB[NormB],$A14)) | C14: =IF($A14="","",SUMIF(tblAnahtarB[NormB],$A14,tblVeriB[BeyanTutar])) | D14: =IF($A14="","",SUMIF(tblAnahtarA[Norm],$A14,tblVeriA[Tutar])) | E14: =IF($A14="","",ROUND($D14,2)-ROUND($C14,2)) | F14: =IF($A14="","",ABS($E14)) | G14: =IF($A14="","",IF($B14=0,"eslesmedi",IF(ROUND($D14,2)=ROUND($C14,2),"eslesti",IF(ABS(ROUND($D14,2)-ROUND($C14,2))<=toleransKurus,"tolerans_icinde","tutar_farki")))) | H14: =IF($A14="","",IF($B14>0,"BIRINCIL",IF(COUNTIF(tblAnahtarB[IkincilB],'ANAHTAR'!$D14)>0,"IKINCIL","YOK"))) | I14: =IF($A14="","",'ANAHTAR'!$F14) | J14: =IF(OR($A14="",$D14=0),0,$F14/ABS($D14)) | K14: =IF($A14="","",ROUND($D14,2)) | L14: =IF($A14="","",ROUND($C14,2)) | M14: =IF($A14="","",IF($F14<=toleransKurus,1,0)) | N14: =IF($A14="","",IF($F14>cbb_esikFark,1,0)) | O14: =IF($A14="","",IF($G14="eslesti",$D14,0)) | P14: =IF($A14="","",$B14+$M14+$N14)
A15: =IF('ANAHTAR'!$B15="","",'ANAHTAR'!$B15) | B15: =IF($A15="","",COUNTIF(tblAnahtarB[NormB],$A15)) | C15: =IF($A15="","",SUMIF(tblAnahtarB[NormB],$A15,tblVeriB[BeyanTutar])) | D15: =IF($A15="","",SUMIF(tblAnahtarA[Norm],$A15,tblVeriA[Tutar])) | E15: =IF($A15="","",ROUND($D15,2)-ROUND($C15,2)) | F15: =IF($A15="","",ABS($E15)) | G15: =IF($A15="","",IF($B15=0,"eslesmedi",IF(ROUND($D15,2)=ROUND($C15,2),"eslesti",IF(ABS(ROUND($D15,2)-ROUND($C15,2))<=toleransKurus,"tolerans_icinde","tutar_farki")))) | H15: =IF($A15="","",IF($B15>0,"BIRINCIL",IF(COUNTIF(tblAnahtarB[IkincilB],'ANAHTAR'!$D15)>0,"IKINCIL","YOK"))) | I15: =IF($A15="","",'ANAHTAR'!$F15) | J15: =IF(OR($A15="",$D15=0),0,$F15/ABS($D15)) | K15: =IF($A15="","",ROUND($D15,2)) | L15: =IF($A15="","",ROUND($C15,2)) | M15: =IF($A15="","",IF($F15<=toleransKurus,1,0)) | N15: =IF($A15="","",IF($F15>cbb_esikFark,1,0)) | O15: =IF($A15="","",IF($G15="eslesti",$D15,0)) | P15: =IF($A15="","",$B15+$M15+$N15)
A16: =IF('ANAHTAR'!$B16="","",'ANAHTAR'!$B16) | B16: =IF($A16="","",COUNTIF(tblAnahtarB[NormB],$A16)) | C16: =IF($A16="","",SUMIF(tblAnahtarB[NormB],$A16,tblVeriB[BeyanTutar])) | D16: =IF($A16="","",SUMIF(tblAnahtarA[Norm],$A16,tblVeriA[Tutar])) | E16: =IF($A16="","",ROUND($D16,2)-ROUND($C16,2)) | F16: =IF($A16="","",ABS($E16)) | G16: =IF($A16="","",IF($B16=0,"eslesmedi",IF(ROUND($D16,2)=ROUND($C16,2),"eslesti",IF(ABS(ROUND($D16,2)-ROUND($C16,2))<=toleransKurus,"tolerans_icinde","tutar_farki")))) | H16: =IF($A16="","",IF($B16>0,"BIRINCIL",IF(COUNTIF(tblAnahtarB[IkincilB],'ANAHTAR'!$D16)>0,"IKINCIL","YOK"))) | I16: =IF($A16="","",'ANAHTAR'!$F16) | J16: =IF(OR($A16="",$D16=0),0,$F16/ABS($D16)) | K16: =IF($A16="","",ROUND($D16,2)) | L16: =IF($A16="","",ROUND($C16,2)) | M16: =IF($A16="","",IF($F16<=toleransKurus,1,0)) | N16: =IF($A16="","",IF($F16>cbb_esikFark,1,0)) | O16: =IF($A16="","",IF($G16="eslesti",$D16,0)) | P16: =IF($A16="","",$B16+$M16+$N16)
A17: =IF('ANAHTAR'!$B17="","",'ANAHTAR'!$B17) | B17: =IF($A17="","",COUNTIF(tblAnahtarB[NormB],$A17)) | C17: =IF($A17="","",SUMIF(tblAnahtarB[NormB],$A17,tblVeriB[BeyanTutar])) | D17: =IF($A17="","",SUMIF(tblAnahtarA[Norm],$A17,tblVeriA[Tutar])) | E17: =IF($A17="","",ROUND($D17,2)-ROUND($C17,2)) | F17: =IF($A17="","",ABS($E17)) | G17: =IF($A17="","",IF($B17=0,"eslesmedi",IF(ROUND($D17,2)=ROUND($C17,2),"eslesti",IF(ABS(ROUND($D17,2)-ROUND($C17,2))<=toleransKurus,"tolerans_icinde","tutar_farki")))) | H17: =IF($A17="","",IF($B17>0,"BIRINCIL",IF(COUNTIF(tblAnahtarB[IkincilB],'ANAHTAR'!$D17)>0,"IKINCIL","YOK"))) | I17: =IF($A17="","",'ANAHTAR'!$F17) | J17: =IF(OR($A17="",$D17=0),0,$F17/ABS($D17)) | K17: =IF($A17="","",ROUND($D17,2)) | L17: =IF($A17="","",ROUND($C17,2)) | M17: =IF($A17="","",IF($F17<=toleransKurus,1,0)) | N17: =IF($A17="","",IF($F17>cbb_esikFark,1,0)) | O17: =IF($A17="","",IF($G17="eslesti",$D17,0)) | P17: =IF($A17="","",$B17+$M17+$N17)
... A505: =IF('ANAHTAR'!$B505="","",'ANAHTAR'!$B505) | B505: =IF($A505="","",COUNTIF(tblAnahtarB[NormB],$A505)) | C505: =IF($A505="","",SUMIF(tblAnahtarB[NormB],$A505,tblVeriB[BeyanTutar])) | D505: =IF($A505="","",SUMIF(tblAnahtarA[Norm],$A505,tblVeriA[Tutar])) | E505: =IF($A505="","",ROUND($D505,2)-ROUND($C505,2)) | F505: =IF($A505="","",ABS($E505)) | G505: =IF($A505="","",IF($B505=0,"eslesmedi",IF(ROUND($D505,2)=ROUND($C505,2),"eslesti",IF(ABS(ROUND($D505,2)-ROUND($C505,2))<=toleransKurus,"tolerans_icinde","tutar_farki")))) | H505: =IF($A505="","",IF($B505>0,"BIRINCIL",IF(COUNTIF(tblAnahtarB[IkincilB],'ANAHTAR'!$D505)>0,"IKINCIL","YOK"))) | I505: =IF($A505="","",'ANAHTAR'!$F505) | J505: =IF(OR($A505="",$D505=0),0,$F505/ABS($D505)) | K505: =IF($A505="","",ROUND($D505,2)) | L505: =IF($A505="","",ROUND($C505,2)) | M505: =IF($A505="","",IF($F505<=toleransKurus,1,0)) | N505: =IF($A505="","",IF($F505>cbb_esikFark,1,0)) | O505: =IF($A505="","",IF($G505="eslesti",$D505,0)) | P505: =IF($A505="","",$B505+$M505+$N505)

Sheet KOK_NEDEN
A1: KOK NEDEN — Cari ve Ba-Bs Toplu Mutabakat Motoru
A3: Öncelik kurallı kök neden — eşleşmeyen fark TANIMSIZ (E04)
A4: Kural Önceliği
A5: Sira | B5: NedenKodu | C5: Test | D5: Aciklama
A6: 1 | B6: DONEM | C6: donem_a<>donem_b | D6: Dönem uyuşmazlığı şüphesi
A7: 2 | B7: UNVAN | C7: unvan_norm_a<>unvan_norm_b | D7: Unvan normalize farkı
A8: 3 | B8: YUVARLAMA | C8: ABS(fark)<=toleransKurus*10 | D8: Kuruş/yuvarlama sapması
A9: 4 | B9: BELGE_EKSIK | C9: belge_adet=0 | D9: Belge adedi eksik/sıfır
A10: 5 | B10: TIP_KARISIK | C10: form_tipi_uyumsuz | D10: Ba/Bs tipi ile alış-satış uyumsuz
A11: 6 | B11: TANIMSIZ | C11: TRUE | D11: Hiçbir kurala girmedi — elle incele
A13: TANIMSIZ kovası görünür tutulur — zorla sınıflandırma yok. Elle inceleyin.
A14: Satır Sınıflandırması
A15: A_Norm | B15: Kova | C15: AbsFark | D15: UnvanNorm | E15: BelgeAdet | F15: FormTipi | G15: Donem | H15: KokNeden
A16: =IF('ESLESTIRME'!$A16="","",'ESLESTIRME'!$A16) | B16: =IF($A16="","",IFERROR(INDEX(tblEslesme[Kova],MATCH($A16,tblEslesme[A_Norm],0)),"")) | C16: =IF($A16="","",IFERROR(INDEX(tblEslesme[AbsFark],MATCH($A16,tblEslesme[A_Norm],0)),0)) | D16: =IF($A16="","",IFERROR(INDEX(tblVeriA[Unvan],MATCH($A16,tblAnahtarA[Norm],0)),"")) | E16: =IF($A16="","",IFERROR(SUMIF(tblAnahtarB[NormB],$A16,tblVeriB[BelgeAdet]),0)) | F16: =IF($A16="","",IFERROR(INDEX(tblVeriB[FormTipi],MATCH($A16,tblAnahtarB[NormB],0)),"")) | G16: =IF($A16="","",IFERROR(INDEX(tblVeriA[Donem],MATCH($A16,tblAnahtarA[Norm],0)),"")) | H16: =IF(OR($A16="",$B16<>"tutar_farki"),"",IF($E16=0,"BELGE_EKSIK",IF($C16<=toleransKurus*cbb_yuvarlamaCarpan,"YUVARLAMA",IF(AND($F16<>"Ba",$F16<>"Bs"),"TIP_KARISIK",IF($C16>cbb_esikFark*cbb_donemCarpan,"DONEM",IF(LEN($D16)<cbb_unvanMinLen,"UNVAN","TANIMSIZ"))))))
A17: =IF('ESLESTIRME'!$A17="","",'ESLESTIRME'!$A17) | B17: =IF($A17="","",IFERROR(INDEX(tblEslesme[Kova],MATCH($A17,tblEslesme[A_Norm],0)),"")) | C17: =IF($A17="","",IFERROR(INDEX(tblEslesme[AbsFark],MATCH($A17,tblEslesme[A_Norm],0)),0)) | D17: =IF($A17="","",IFERROR(INDEX(tblVeriA[Unvan],MATCH($A17,tblAnahtarA[Norm],0)),"")) | E17: =IF($A17="","",IFERROR(SUMIF(tblAnahtarB[NormB],$A17,tblVeriB[BelgeAdet]),0)) | F17: =IF($A17="","",IFERROR(INDEX(tblVeriB[FormTipi],MATCH($A17,tblAnahtarB[NormB],0)),"")) | G17: =IF($A17="","",IFERROR(INDEX(tblVeriA[Donem],MATCH($A17,tblAnahtarA[Norm],0)),"")) | H17: =IF(OR($A17="",$B17<>"tutar_farki"),"",IF($E17=0,"BELGE_EKSIK",IF($C17<=toleransKurus*cbb_yuvarlamaCarpan,"YUVARLAMA",IF(AND($F17<>"Ba",$F17<>"Bs"),"TIP_KARISIK",IF($C17>cbb_esikFark*cbb_donemCarpan,"DONEM",IF(LEN($D17)<cbb_unvanMinLen,"UNVAN","TANIMSIZ"))))))
A18: =IF('ESLESTIRME'!$A18="","",'ESLESTIRME'!$A18) | B18: =IF($A18="","",IFERROR(INDEX(tblEslesme[Kova],MATCH($A18,tblEslesme[A_Norm],0)),"")) | C18: =IF($A18="","",IFERROR(INDEX(tblEslesme[AbsFark],MATCH($A18,tblEslesme[A_Norm],0)),0)) | D18: =IF($A18="","",IFERROR(INDEX(tblVeriA[Unvan],MATCH($A18,tblAnahtarA[Norm],0)),"")) | E18: =IF($A18="","",IFERROR(SUMIF(tblAnahtarB[NormB],$A18,tblVeriB[BelgeAdet]),0)) | F18: =IF($A18="","",IFERROR(INDEX(tblVeriB[FormTipi],MATCH($A18,tblAnahtarB[NormB],0)),"")) | G18: =IF($A18="","",IFERROR(INDEX(tblVeriA[Donem],MATCH($A18,tblAnahtarA[Norm],0)),"")) | H18: =IF(OR($A18="",$B18<>"tutar_farki"),"",IF($E18=0,"BELGE_EKSIK",IF($C18<=toleransKurus*cbb_yuvarlamaCarpan,"YUVARLAMA",IF(AND($F18<>"Ba",$F18<>"Bs"),"TIP_KARISIK",IF($C18>cbb_esikFark*cbb_donemCarpan,"DONEM",IF(LEN($D18)<cbb_unvanMinLen,"UNVAN","TANIMSIZ"))))))
A19: =IF('ESLESTIRME'!$A19="","",'ESLESTIRME'!$A19) | B19: =IF($A19="","",IFERROR(INDEX(tblEslesme[Kova],MATCH($A19,tblEslesme[A_Norm],0)),"")) | C19: =IF($A19="","",IFERROR(INDEX(tblEslesme[AbsFark],MATCH($A19,tblEslesme[A_Norm],0)),0)) | D19: =IF($A19="","",IFERROR(INDEX(tblVeriA[Unvan],MATCH($A19,tblAnahtarA[Norm],0)),"")) | E19: =IF($A19="","",IFERROR(SUMIF(tblAnahtarB[NormB],$A19,tblVeriB[BelgeAdet]),0)) | F19: =IF($A19="","",IFERROR(INDEX(tblVeriB[FormTipi],MATCH($A19,tblAnahtarB[NormB],0)),"")) | G19: =IF($A19="","",IFERROR(INDEX(tblVeriA[Donem],MATCH($A19,tblAnahtarA[Norm],0)),"")) | H19: =IF(OR($A19="",$B19<>"tutar_farki"),"",IF($E19=0,"BELGE_EKSIK",IF($C19<=toleransKurus*cbb_yuvarlamaCarpan,"YUVARLAMA",IF(AND($F19<>"Ba",$F19<>"Bs"),"TIP_KARISIK",IF($C19>cbb_esikFark*cbb_donemCarpan,"DONEM",IF(LEN($D19)<cbb_unvanMinLen,"UNVAN","TANIMSIZ"))))))
A20: =IF('ESLESTIRME'!$A20="","",'ESLESTIRME'!$A20) | B20: =IF($A20="","",IFERROR(INDEX(tblEslesme[Kova],MATCH($A20,tblEslesme[A_Norm],0)),"")) | C20: =IF($A20="","",IFERROR(INDEX(tblEslesme[AbsFark],MATCH($A20,tblEslesme[A_Norm],0)),0)) | D20: =IF($A20="","",IFERROR(INDEX(tblVeriA[Unvan],MATCH($A20,tblAnahtarA[Norm],0)),"")) | E20: =IF($A20="","",IFERROR(SUMIF(tblAnahtarB[NormB],$A20,tblVeriB[BelgeAdet]),0)) | F20: =IF($A20="","",IFERROR(INDEX(tblVeriB[FormTipi],MATCH($A20,tblAnahtarB[NormB],0)),"")) | G20: =IF($A20="","",IFERROR(INDEX(tblVeriA[Donem],MATCH($A20,tblAnahtarA[Norm],0)),"")) | H20: =IF(OR($A20="",$B20<>"tutar_farki"),"",IF($E20=0,"BELGE_EKSIK",IF($C20<=toleransKurus*cbb_yuvarlamaCarpan,"YUVARLAMA",IF(AND($F20<>"Ba",$F20<>"Bs"),"TIP_KARISIK",IF($C20>cbb_esikFark*cbb_donemCarpan,"DONEM",IF(LEN($D20)<cbb_unvanMinLen,"UNVAN","TANIMSIZ"))))))
A21: =IF('ESLESTIRME'!$A21="","",'ESLESTIRME'!$A21) | B21: =IF($A21="","",IFERROR(INDEX(tblEslesme[Kova],MATCH($A21,tblEslesme[A_Norm],0)),"")) | C21: =IF($A21="","",IFERROR(INDEX(tblEslesme[AbsFark],MATCH($A21,tblEslesme[A_Norm],0)),0)) | D21: =IF($A21="","",IFERROR(INDEX(tblVeriA[Unvan],MATCH($A21,tblAnahtarA[Norm],0)),"")) | E21: =IF($A21="","",IFERROR(SUMIF(tblAnahtarB[NormB],$A21,tblVeriB[BelgeAdet]),0)) | F21: =IF($A21="","",IFERROR(INDEX(tblVeriB[FormTipi],MATCH($A21,tblAnahtarB[NormB],0)),"")) | G21: =IF($A21="","",IFERROR(INDEX(tblVeriA[Donem],MATCH($A21,tblAnahtarA[Norm],0)),"")) | H21: =IF(OR($A21="",$B21<>"tutar_farki"),"",IF($E21=0,"BELGE_EKSIK",IF($C21<=toleransKurus*cbb_yuvarlamaCarpan,"YUVARLAMA",IF(AND($F21<>"Ba",$F21<>"Bs"),"TIP_KARISIK",IF($C21>cbb_esikFark*cbb_donemCarpan,"DONEM",IF(LEN($D21)<cbb_unvanMinLen,"UNVAN","TANIMSIZ"))))))
A22: =IF('ESLESTIRME'!$A22="","",'ESLESTIRME'!$A22) | B22: =IF($A22="","",IFERROR(INDEX(tblEslesme[Kova],MATCH($A22,tblEslesme[A_Norm],0)),"")) | C22: =IF($A22="","",IFERROR(INDEX(tblEslesme[AbsFark],MATCH($A22,tblEslesme[A_Norm],0)),0)) | D22: =IF($A22="","",IFERROR(INDEX(tblVeriA[Unvan],MATCH($A22,tblAnahtarA[Norm],0)),"")) | E22: =IF($A22="","",IFERROR(SUMIF(tblAnahtarB[NormB],$A22,tblVeriB[BelgeAdet]),0)) | F22: =IF($A22="","",IFERROR(INDEX(tblVeriB[FormTipi],MATCH($A22,tblAnahtarB[NormB],0)),"")) | G22: =IF($A22="","",IFERROR(INDEX(tblVeriA[Donem],MATCH($A22,tblAnahtarA[Norm],0)),"")) | H22: =IF(OR($A22="",$B22<>"tutar_farki"),"",IF($E22=0,"BELGE_EKSIK",IF($C22<=toleransKurus*cbb_yuvarlamaCarpan,"YUVARLAMA",IF(AND($F22<>"Ba",$F22<>"Bs"),"TIP_KARISIK",IF($C22>cbb_esikFark*cbb_donemCarpan,"DONEM",IF(LEN($D22)<cbb_unvanMinLen,"UNVAN","TANIMSIZ"))))))
A23: =IF('ESLESTIRME'!$A23="","",'ESLESTIRME'!$A23) | B23: =IF($A23="","",IFERROR(INDEX(tblEslesme[Kova],MATCH($A23,tblEslesme[A_Norm],0)),"")) | C23: =IF($A23="","",IFERROR(INDEX(tblEslesme[AbsFark],MATCH($A23,tblEslesme[A_Norm],0)),0)) | D23: =IF($A23="","",IFERROR(INDEX(tblVeriA[Unvan],MATCH($A23,tblAnahtarA[Norm],0)),"")) | E23: =IF($A23="","",IFERROR(SUMIF(tblAnahtarB[NormB],$A23,tblVeriB[BelgeAdet]),0)) | F23: =IF($A23="","",IFERROR(INDEX(tblVeriB[FormTipi],MATCH($A23,tblAnahtarB[NormB],0)),"")) | G23: =IF($A23="","",IFERROR(INDEX(tblVeriA[Donem],MATCH($A23,tblAnahtarA[Norm],0)),"")) | H23: =IF(OR($A23="",$B23<>"tutar_farki"),"",IF($E23=0,"BELGE_EKSIK",IF($C23<=toleransKurus*cbb_yuvarlamaCarpan,"YUVARLAMA",IF(AND($F23<>"Ba",$F23<>"Bs"),"TIP_KARISIK",IF($C23>cbb_esikFark*cbb_donemCarpan,"DONEM",IF(LEN($D23)<cbb_unvanMinLen,"UNVAN","TANIMSIZ"))))))
A24: =IF('ESLESTIRME'!$A24="","",'ESLESTIRME'!$A24) | B24: =IF($A24="","",IFERROR(INDEX(tblEslesme[Kova],MATCH($A24,tblEslesme[A_Norm],0)),"")) | C24: =IF($A24="","",IFERROR(INDEX(tblEslesme[AbsFark],MATCH($A24,tblEslesme[A_Norm],0)),0)) | D24: =IF($A24="","",IFERROR(INDEX(tblVeriA[Unvan],MATCH($A24,tblAnahtarA[Norm],0)),"")) | E24: =IF($A24="","",IFERROR(SUMIF(tblAnahtarB[NormB],$A24,tblVeriB[BelgeAdet]),0)) | F24: =IF($A24="","",IFERROR(INDEX(tblVeriB[FormTipi],MATCH($A24,tblAnahtarB[NormB],0)),"")) | G24: =IF($A24="","",IFERROR(INDEX(tblVeriA[Donem],MATCH($A24,tblAnahtarA[Norm],0)),"")) | H24: =IF(OR($A24="",$B24<>"tutar_farki"),"",IF($E24=0,"BELGE_EKSIK",IF($C24<=toleransKurus*cbb_yuvarlamaCarpan,"YUVARLAMA",IF(AND($F24<>"Ba",$F24<>"Bs"),"TIP_KARISIK",IF($C24>cbb_esikFark*cbb_donemCarpan,"DONEM",IF(LEN($D24)<cbb_unvanMinLen,"UNVAN","TANIMSIZ"))))))
A25: =IF('ESLESTIRME'!$A25="","",'ESLESTIRME'!$A25) | B25: =IF($A25="","",IFERROR(INDEX(tblEslesme[Kova],MATCH($A25,tblEslesme[A_Norm],0)),"")) | C25: =IF($A25="","",IFERROR(INDEX(tblEslesme[AbsFark],MATCH($A25,tblEslesme[A_Norm],0)),0)) | D25: =IF($A25="","",IFERROR(INDEX(tblVeriA[Unvan],MATCH($A25,tblAnahtarA[Norm],0)),"")) | E25: =IF($A25="","",IFERROR(SUMIF(tblAnahtarB[NormB],$A25,tblVeriB[BelgeAdet]),0)) | F25: =IF($A25="","",IFERROR(INDEX(tblVeriB[FormTipi],MATCH($A25,tblAnahtarB[NormB],0)),"")) | G25: =IF($A25="","",IFERROR(INDEX(tblVeriA[Donem],MATCH($A25,tblAnahtarA[Norm],0)),"")) | H25: =IF(OR($A25="",$B25<>"tutar_farki"),"",IF($E25=0,"BELGE_EKSIK",IF($C25<=toleransKurus*cbb_yuvarlamaCarpan,"YUVARLAMA",IF(AND($F25<>"Ba",$F25<>"Bs"),"TIP_KARISIK",IF($C25>cbb_esikFark*cbb_donemCarpan,"DONEM",IF(LEN($D25)<cbb_unvanMinLen,"UNVAN","TANIMSIZ"))))))
A26: =IF('ESLESTIRME'!$A26="","",'ESLESTIRME'!$A26) | B26: =IF($A26="","",IFERROR(INDEX(tblEslesme[Kova],MATCH($A26,tblEslesme[A_Norm],0)),"")) | C26: =IF($A26="","",IFERROR(INDEX(tblEslesme[AbsFark],MATCH($A26,tblEslesme[A_Norm],0)),0)) | D26: =IF($A26="","",IFERROR(INDEX(tblVeriA[Unvan],MATCH($A26,tblAnahtarA[Norm],0)),"")) | E26: =IF($A26="","",IFERROR(SUMIF(tblAnahtarB[NormB],$A26,tblVeriB[BelgeAdet]),0)) | F26: =IF($A26="","",IFERROR(INDEX(tblVeriB[FormTipi],MATCH($A26,tblAnahtarB[NormB],0)),"")) | G26: =IF($A26="","",IFERROR(INDEX(tblVeriA[Donem],MATCH($A26,tblAnahtarA[Norm],0)),"")) | H26: =IF(OR($A26="",$B26<>"tutar_farki"),"",IF($E26=0,"BELGE_EKSIK",IF($C26<=toleransKurus*cbb_yuvarlamaCarpan,"YUVARLAMA",IF(AND($F26<>"Ba",$F26<>"Bs"),"TIP_KARISIK",IF($C26>cbb_esikFark*cbb_donemCarpan,"DONEM",IF(LEN($D26)<cbb_unvanMinLen,"UNVAN","TANIMSIZ"))))))
A27: =IF('ESLESTIRME'!$A27="","",'ESLESTIRME'!$A27) | B27: =IF($A27="","",IFERROR(INDEX(tblEslesme[Kova],MATCH($A27,tblEslesme[A_Norm],0)),"")) | C27: =IF($A27="","",IFERROR(INDEX(tblEslesme[AbsFark],MATCH($A27,tblEslesme[A_Norm],0)),0)) | D27: =IF($A27="","",IFERROR(INDEX(tblVeriA[Unvan],MATCH($A27,tblAnahtarA[Norm],0)),"")) | E27: =IF($A27="","",IFERROR(SUMIF(tblAnahtarB[NormB],$A27,tblVeriB[BelgeAdet]),0)) | F27: =IF($A27="","",IFERROR(INDEX(tblVeriB[FormTipi],MATCH($A27,tblAnahtarB[NormB],0)),"")) | G27: =IF($A27="","",IFERROR(INDEX(tblVeriA[Donem],MATCH($A27,tblAnahtarA[Norm],0)),"")) | H27: =IF(OR($A27="",$B27<>"tutar_farki"),"",IF($E27=0,"BELGE_EKSIK",IF($C27<=toleransKurus*cbb_yuvarlamaCarpan,"YUVARLAMA",IF(AND($F27<>"Ba",$F27<>"Bs"),"TIP_KARISIK",IF($C27>cbb_esikFark*cbb_donemCarpan,"DONEM",IF(LEN($D27)<cbb_unvanMinLen,"UNVAN","TANIMSIZ"))))))
... A515: =IF('ESLESTIRME'!$A515="","",'ESLESTIRME'!$A515) | B515: =IF($A515="","",IFERROR(INDEX(tblEslesme[Kova],MATCH($A515,tblEslesme[A_Norm],0)),"")) | C515: =IF($A515="","",IFERROR(INDEX(tblEslesme[AbsFark],MATCH($A515,tblEslesme[A_Norm],0)),0)) | D515: =IF($A515="","",IFERROR(INDEX(tblVeriA[Unvan],MATCH($A515,tblAnahtarA[Norm],0)),"")) | E515: =IF($A515="","",IFERROR(SUMIF(tblAnahtarB[NormB],$A515,tblVeriB[BelgeAdet]),0)) | F515: =IF($A515="","",IFERROR(INDEX(tblVeriB[FormTipi],MATCH($A515,tblAnahtarB[NormB],0)),"")) | G515: =IF($A515="","",IFERROR(INDEX(tblVeriA[Donem],MATCH($A515,tblAnahtarA[Norm],0)),"")) | H515: =IF(OR($A515="",$B515<>"tutar_farki"),"",IF($E515=0,"BELGE_EKSIK",IF($C515<=toleransKurus*cbb_yuvarlamaCarpan,"YUVARLAMA",IF(AND($F515<>"Ba",$F515<>"Bs"),"TIP_KARISIK",IF($C515>cbb_esikFark*cbb_donemCarpan,"DONEM",IF(LEN($D515)<cbb_unvanMinLen,"UNVAN","TANIMSIZ"))))))

Sheet PANO
A1: PANO — Cari ve Ba-Bs Toplu Mutabakat Motoru
A3: Karar Destek Paneli — Form Ba/Bs | C3: Rapor Tarihi | D3: =raporTarihi
A4: KARAR | B4: =IF(COUNTA(tblVeriA[VKN])=0,"VERİ YOK",IF(OR(COUNTIF(tblVeriA[Tutar],"<0")>0,COUNTIF(tblVeriB[BeyanTutar],"<0")>0),"İNCELE",IF(OR(COUNTIF(tblVeriA[Tutar],">"&cbb_azamiTutar)>0,COUNTIF(tblVeriB[BeyanTutar],">"&cbb_azamiTutar)>0),"İNCELE",IF(cbb_eslesmeOrani<cbb_esikEslesme,"DURDUR",IF(ABS(cbb_mutabakatFarki)>cbb_esikFark,"İNCELE","UYGUN")))))
A6: Eşleşme Oranı | B6: =IFERROR(cbb_modulT1,0) | D6: Modül Yorumları
A7: Cari Toplam (A) | B7: =IFERROR(SUM(tblVeriA[Tutar]),0) | D7: =cbb_modulT1Yorum
A8: Ba-Bs Toplam (B) | B8: =IFERROR(SUM(tblVeriB[BeyanTutar]),0) | D8: =cbb_modulT2Yorum
A9: Mutabakat Farkı | B9: =IFERROR(cbb_mutabakatFarki,0) | D9: =cbb_modulO1Yorum
A10: Eşleşti Adet | B10: =COUNTIF(tblEslesme[Kova],"eslesti") | D10: =cbb_modulO2Yorum
A11: Tolerans İçinde | B11: =COUNTIF(tblEslesme[Kova],"tolerans_icinde") | D11: =cbb_modulO3Yorum
A12: Tutar Farkı Adet | B12: =COUNTIF(tblEslesme[Kova],"tutar_farki") | D12: =cbb_modulO6Yorum
A13: Eşleşmedi Adet | B13: =COUNTIF(tblEslesme[Kova],"eslesmedi") | D13: =cbb_modulO8Yorum
A14: Kova Bütünlük | B14: =cbb_kovaButunluk | D14: =cbb_modulI1Yorum
A15: Anomali Sayısı | B15: =cbb_modulO1 | D15: =cbb_modulI2Yorum
A16: Ort. Abs Fark | B16: =cbb_modulT2
A17: VKN Yoğunlaşma | B17: =cbb_modulO6
A18: Kalite Skoru | B18: =cbb_modulO8
A19: Tahmin / P90 | B19: =cbb_modulI2
A20: Tornado Zirve | B20: =cbb_modulO2
A21: Senaryo Etki | B21: =cbb_modulO3
A22: Duplike Uyarı | B22: =COUNTIF(tblAnahtarA[Duplike],"EVET")
A23: Grafik Kaynağı
A24: Kova | B24: Adet | D24: Neden | E24: Adet | G24: Gün | H24: Fark | J24: Senaryo | K24: Etki
A25: Eşleşti | B25: 24 | D25: Dönem | E25: 2 | G25: 1 | H25: 120 | J25: Tolerans sıkı | K25: 380
A26: Tolerans | B26: 3 | D26: Unvan | E26: 1 | G26: 2 | H26: 138.5 | J26: VKN normalize | K26: 260
A27: Tutar farkı | B27: 5 | D27: Yuvarlama | E27: 1 | G27: 3 | H27: 157 | J27: Dönem düzelt | K27: 190
A28: Eşleşmedi | B28: 3 | D28: Belge | E28: 1 | G28: 4 | H28: 175.5 | J28: Unvan temizle | K28: 110
D29: Tip | E29: 0 | G29: 5 | H29: 194 | J29: Belge tamamla | K29: 75
D30: Tanımsız | E30: 3 | G30: 6 | H30: 212.5
G31: 7 | H31: 231

Sheet AKSIYON
A1: AKSIYON — Cari ve Ba-Bs Toplu Mutabakat Motoru
I2: Şablon | J2: 'IF(kova<>"tutar_farki","","Sipariş "&siparisNo&" için fark "&TEXT(fark,"0.00")&" TL. Dayanak: "&kokNeden&". İtiraz dosyası üretildi.")
A3: Tutar farkı satırları için düzeltme metni — tek yön (yazmaz, üretir)
A5: A_Norm | B5: Kova | C5: Fark | D5: KokNeden | E5: Oncelik | F5: ItirazMetni | G5: Durum
A6: =IF('KOK_NEDEN'!$A6="","",'KOK_NEDEN'!$A6) | B6: =IF($A6="","",IFERROR(INDEX(tblKok[Kova],MATCH($A6,tblKok[A_Norm],0)),"")) | C6: =IF($A6="","",IFERROR(INDEX(tblEslesme[Fark],MATCH($A6,tblEslesme[A_Norm],0)),0)) | D6: =IF($A6="","",IFERROR(INDEX(tblKok[KokNeden],MATCH($A6,tblKok[A_Norm],0)),"")) | E6: =IF($B6<>"tutar_farki","",IF(ABS($C6)>cbb_esikFark,"YUKSEK","NORMAL")) | F6: =IF($B6<>"tutar_farki","","VKN "&$A6&" için cari↔Ba/Bs fark "&TEXT($C6,"0.00")&" TL. Dayanak: "&$D6&". Düzeltme dosyası üretildi.") | G6: =IF($B6<>"tutar_farki","","Beklemede")
A7: =IF('KOK_NEDEN'!$A7="","",'KOK_NEDEN'!$A7) | B7: =IF($A7="","",IFERROR(INDEX(tblKok[Kova],MATCH($A7,tblKok[A_Norm],0)),"")) | C7: =IF($A7="","",IFERROR(INDEX(tblEslesme[Fark],MATCH($A7,tblEslesme[A_Norm],0)),0)) | D7: =IF($A7="","",IFERROR(INDEX(tblKok[KokNeden],MATCH($A7,tblKok[A_Norm],0)),"")) | E7: =IF($B7<>"tutar_farki","",IF(ABS($C7)>cbb_esikFark,"YUKSEK","NORMAL")) | F7: =IF($B7<>"tutar_farki","","VKN "&$A7&" için cari↔Ba/Bs fark "&TEXT($C7,"0.00")&" TL. Dayanak: "&$D7&". Düzeltme dosyası üretildi.") | G7: =IF($B7<>"tutar_farki","","Beklemede")
A8: =IF('KOK_NEDEN'!$A8="","",'KOK_NEDEN'!$A8) | B8: =IF($A8="","",IFERROR(INDEX(tblKok[Kova],MATCH($A8,tblKok[A_Norm],0)),"")) | C8: =IF($A8="","",IFERROR(INDEX(tblEslesme[Fark],MATCH($A8,tblEslesme[A_Norm],0)),0)) | D8: =IF($A8="","",IFERROR(INDEX(tblKok[KokNeden],MATCH($A8,tblKok[A_Norm],0)),"")) | E8: =IF($B8<>"tutar_farki","",IF(ABS($C8)>cbb_esikFark,"YUKSEK","NORMAL")) | F8: =IF($B8<>"tutar_farki","","VKN "&$A8&" için cari↔Ba/Bs fark "&TEXT($C8,"0.00")&" TL. Dayanak: "&$D8&". Düzeltme dosyası üretildi.") | G8: =IF($B8<>"tutar_farki","","Beklemede")
A9: =IF('KOK_NEDEN'!$A9="","",'KOK_NEDEN'!$A9) | B9: =IF($A9="","",IFERROR(INDEX(tblKok[Kova],MATCH($A9,tblKok[A_Norm],0)),"")) | C9: =IF($A9="","",IFERROR(INDEX(tblEslesme[Fark],MATCH($A9,tblEslesme[A_Norm],0)),0)) | D9: =IF($A9="","",IFERROR(INDEX(tblKok[KokNeden],MATCH($A9,tblKok[A_Norm],0)),"")) | E9: =IF($B9<>"tutar_farki","",IF(ABS($C9)>cbb_esikFark,"YUKSEK","NORMAL")) | F9: =IF($B9<>"tutar_farki","","VKN "&$A9&" için cari↔Ba/Bs fark "&TEXT($C9,"0.00")&" TL. Dayanak: "&$D9&". Düzeltme dosyası üretildi.") | G9: =IF($B9<>"tutar_farki","","Beklemede")
A10: =IF('KOK_NEDEN'!$A10="","",'KOK_NEDEN'!$A10) | B10: =IF($A10="","",IFERROR(INDEX(tblKok[Kova],MATCH($A10,tblKok[A_Norm],0)),"")) | C10: =IF($A10="","",IFERROR(INDEX(tblEslesme[Fark],MATCH($A10,tblEslesme[A_Norm],0)),0)) | D10: =IF($A10="","",IFERROR(INDEX(tblKok[KokNeden],MATCH($A10,tblKok[A_Norm],0)),"")) | E10: =IF($B10<>"tutar_farki","",IF(ABS($C10)>cbb_esikFark,"YUKSEK","NORMAL")) | F10: =IF($B10<>"tutar_farki","","VKN "&$A10&" için cari↔Ba/Bs fark "&TEXT($C10,"0.00")&" TL. Dayanak: "&$D10&". Düzeltme dosyası üretildi.") | G10: =IF($B10<>"tutar_farki","","Beklemede")
A11: =IF('KOK_NEDEN'!$A11="","",'KOK_NEDEN'!$A11) | B11: =IF($A11="","",IFERROR(INDEX(tblKok[Kova],MATCH($A11,tblKok[A_Norm],0)),"")) | C11: =IF($A11="","",IFERROR(INDEX(tblEslesme[Fark],MATCH($A11,tblEslesme[A_Norm],0)),0)) | D11: =IF($A11="","",IFERROR(INDEX(tblKok[KokNeden],MATCH($A11,tblKok[A_Norm],0)),"")) | E11: =IF($B11<>"tutar_farki","",IF(ABS($C11)>cbb_esikFark,"YUKSEK","NORMAL")) | F11: =IF($B11<>"tutar_farki","","VKN "&$A11&" için cari↔Ba/Bs fark "&TEXT($C11,"0.00")&" TL. Dayanak: "&$D11&". Düzeltme dosyası üretildi.") | G11: =IF($B11<>"tutar_farki","","Beklemede")
A12: =IF('KOK_NEDEN'!$A12="","",'KOK_NEDEN'!$A12) | B12: =IF($A12="","",IFERROR(INDEX(tblKok[Kova],MATCH($A12,tblKok[A_Norm],0)),"")) | C12: =IF($A12="","",IFERROR(INDEX(tblEslesme[Fark],MATCH($A12,tblEslesme[A_Norm],0)),0)) | D12: =IF($A12="","",IFERROR(INDEX(tblKok[KokNeden],MATCH($A12,tblKok[A_Norm],0)),"")) | E12: =IF($B12<>"tutar_farki","",IF(ABS($C12)>cbb_esikFark,"YUKSEK","NORMAL")) | F12: =IF($B12<>"tutar_farki","","VKN "&$A12&" için cari↔Ba/Bs fark "&TEXT($C12,"0.00")&" TL. Dayanak: "&$D12&". Düzeltme dosyası üretildi.") | G12: =IF($B12<>"tutar_farki","","Beklemede")
A13: =IF('KOK_NEDEN'!$A13="","",'KOK_NEDEN'!$A13) | B13: =IF($A13="","",IFERROR(INDEX(tblKok[Kova],MATCH($A13,tblKok[A_Norm],0)),"")) | C13: =IF($A13="","",IFERROR(INDEX(tblEslesme[Fark],MATCH($A13,tblEslesme[A_Norm],0)),0)) | D13: =IF($A13="","",IFERROR(INDEX(tblKok[KokNeden],MATCH($A13,tblKok[A_Norm],0)),"")) | E13: =IF($B13<>"tutar_farki","",IF(ABS($C13)>cbb_esikFark,"YUKSEK","NORMAL")) | F13: =IF($B13<>"tutar_farki","","VKN "&$A13&" için cari↔Ba/Bs fark "&TEXT($C13,"0.00")&" TL. Dayanak: "&$D13&". Düzeltme dosyası üretildi.") | G13: =IF($B13<>"tutar_farki","","Beklemede")
A14: =IF('KOK_NEDEN'!$A14="","",'KOK_NEDEN'!$A14) | B14: =IF($A14="","",IFERROR(INDEX(tblKok[Kova],MATCH($A14,tblKok[A_Norm],0)),"")) | C14: =IF($A14="","",IFERROR(INDEX(tblEslesme[Fark],MATCH($A14,tblEslesme[A_Norm],0)),0)) | D14: =IF($A14="","",IFERROR(INDEX(tblKok[KokNeden],MATCH($A14,tblKok[A_Norm],0)),"")) | E14: =IF($B14<>"tutar_farki","",IF(ABS($C14)>cbb_esikFark,"YUKSEK","NORMAL")) | F14: =IF($B14<>"tutar_farki","","VKN "&$A14&" için cari↔Ba/Bs fark "&TEXT($C14,"0.00")&" TL. Dayanak: "&$D14&". Düzeltme dosyası üretildi.") | G14: =IF($B14<>"tutar_farki","","Beklemede")
A15: =IF('KOK_NEDEN'!$A15="","",'KOK_NEDEN'!$A15) | B15: =IF($A15="","",IFERROR(INDEX(tblKok[Kova],MATCH($A15,tblKok[A_Norm],0)),"")) | C15: =IF($A15="","",IFERROR(INDEX(tblEslesme[Fark],MATCH($A15,tblEslesme[A_Norm],0)),0)) | D15: =IF($A15="","",IFERROR(INDEX(tblKok[KokNeden],MATCH($A15,tblKok[A_Norm],0)),"")) | E15: =IF($B15<>"tutar_farki","",IF(ABS($C15)>cbb_esikFark,"YUKSEK","NORMAL")) | F15: =IF($B15<>"tutar_farki","","VKN "&$A15&" için cari↔Ba/Bs fark "&TEXT($C15,"0.00")&" TL. Dayanak: "&$D15&". Düzeltme dosyası üretildi.") | G15: =IF($B15<>"tutar_farki","","Beklemede")
A16: =IF('KOK_NEDEN'!$A16="","",'KOK_NEDEN'!$A16) | B16: =IF($A16="","",IFERROR(INDEX(tblKok[Kova],MATCH($A16,tblKok[A_Norm],0)),"")) | C16: =IF($A16="","",IFERROR(INDEX(tblEslesme[Fark],MATCH($A16,tblEslesme[A_Norm],0)),0)) | D16: =IF($A16="","",IFERROR(INDEX(tblKok[KokNeden],MATCH($A16,tblKok[A_Norm],0)),"")) | E16: =IF($B16<>"tutar_farki","",IF(ABS($C16)>cbb_esikFark,"YUKSEK","NORMAL")) | F16: =IF($B16<>"tutar_farki","","VKN "&$A16&" için cari↔Ba/Bs fark "&TEXT($C16,"0.00")&" TL. Dayanak: "&$D16&". Düzeltme dosyası üretildi.") | G16: =IF($B16<>"tutar_farki","","Beklemede")
A17: =IF('KOK_NEDEN'!$A17="","",'KOK_NEDEN'!$A17) | B17: =IF($A17="","",IFERROR(INDEX(tblKok[Kova],MATCH($A17,tblKok[A_Norm],0)),"")) | C17: =IF($A17="","",IFERROR(INDEX(tblEslesme[Fark],MATCH($A17,tblEslesme[A_Norm],0)),0)) | D17: =IF($A17="","",IFERROR(INDEX(tblKok[KokNeden],MATCH($A17,tblKok[A_Norm],0)),"")) | E17: =IF($B17<>"tutar_farki","",IF(ABS($C17)>cbb_esikFark,"YUKSEK","NORMAL")) | F17: =IF($B17<>"tutar_farki","","VKN "&$A17&" için cari↔Ba/Bs fark "&TEXT($C17,"0.00")&" TL. Dayanak: "&$D17&". Düzeltme dosyası üretildi.") | G17: =IF($B17<>"tutar_farki","","Beklemede")
... A505: =IF('KOK_NEDEN'!$A505="","",'KOK_NEDEN'!$A505) | B505: =IF($A505="","",IFERROR(INDEX(tblKok[Kova],MATCH($A505,tblKok[A_Norm],0)),"")) | C505: =IF($A505="","",IFERROR(INDEX(tblEslesme[Fark],MATCH($A505,tblEslesme[A_Norm],0)),0)) | D505: =IF($A505="","",IFERROR(INDEX(tblKok[KokNeden],MATCH($A505,tblKok[A_Norm],0)),"")) | E505: =IF($B505<>"tutar_farki","",IF(ABS($C505)>cbb_esikFark,"YUKSEK","NORMAL")) | F505: =IF($B505<>"tutar_farki","","VKN "&$A505&" için cari↔Ba/Bs fark "&TEXT($C505,"0.00")&" TL. Dayanak: "&$D505&". Düzeltme dosyası üretildi.") | G505: =IF($B505<>"tutar_farki","","Beklemede")

Sheet KANIT_RAPORU
A1: KANIT RAPORU — Cari ve Ba-Bs Toplu Mutabakat Motoru
A3: Form Ba/Bs Dönem Mutabakat Kanıt Raporu
A4: Rapor Tarihi | B4: =raporTarihi
A5: Sürüm | B5: 1.0.0 | D5: Lisans | E5: Tek kullanıcı
A7: KARAR | B7: =PANO!B4
A9: Eşleşme Oranı | B9: =cbb_eslesmeOrani
A10: Cari Toplam | B10: =SUM(tblVeriA[Tutar])
A11: Mutabakat Farkı | B11: =cbb_mutabakatFarki
A12: Eşleşti | B12: =COUNTIF(tblEslesme[Kova],"eslesti")
A13: Tutar Farkı | B13: =COUNTIF(tblEslesme[Kova],"tutar_farki")
A14: Eşleşmedi | B14: =COUNTIF(tblEslesme[Kova],"eslesmedi")
A15: Kova Bütünlük | B15: =cbb_kovaButunluk
A17: Varsayımlar
A18: Tolerans kuruşu AYARLAR'dan gelir. VKN UPPER/TRIM/SUBSTITUTE ile normalize edilir. Bu çıktı karar destektir; kesin mali/hukuki görüş yerine geçmez.
A20: Önerilen Aksiyonlar
A21: 1. Tutar farkı satırlarında AKSIYON düzeltme metnini kullanın.
A22: 2. TANIMSIZ kök nedenleri elle inceleyin.
A23: 3. Duplike VKN'leri temizleyip yeniden eşleştirin.

Sheet KONTROLLER
A1: KONTROLLER — Cari ve Ba-Bs Toplu Mutabakat Motoru
A3: Canlı Kontrol Paneli
A5: A satır sayısı | B5: =COUNTA(tblVeriA[VKN])
A6: B satır sayısı | B6: =COUNTA(tblVeriB[VKN])
A7: Eşleşti | B7: =COUNTIF(tblEslesme[Kova],"eslesti")
A8: Tolerans | B8: =COUNTIF(tblEslesme[Kova],"tolerans_icinde")
A9: Tutar farkı | B9: =COUNTIF(tblEslesme[Kova],"tutar_farki")
A10: Eşleşmedi | B10: =COUNTIF(tblEslesme[Kova],"eslesmedi")
A11: Kova toplam | B11: =B7+B8+B9+B10
A12: Bütünlük | B12: =IF(B11=B5,"BUTUN","KAYIP")
A13: Duplike A | B13: =COUNTIF(tblAnahtarA[Duplike],"EVET")
A14: TANIMSIZ | B14: =COUNTIF(tblKok[KokNeden],"TANIMSIZ")
A15: Boş karar yolu | B15: =IF(B5=0,"VERİ YOK","VERİ VAR")
A16: Kalite skoru | B16: =IF(B5=0,0,ROUND(100*(B7+B8)/MAX(B5,1),0))
A17: Net A | B17: =SUM(tblVeriA[Tutar])
A18: Net B | B18: =SUM(tblVeriB[BeyanTutar])
A19: Fark kontrol | B19: =B17-B18

Sheet ORNEK_VERI
A1: ORNEK VERI — Cari ve Ba-Bs Toplu Mutabakat Motoru
A3: Örnek Senaryo Açıklaması
A4: Dosyada 35 satır örnek Ba/Bs mutabakat vardır: eşleşen, tolerans içi, tutar farkı ve eşleşmeyen kovalar kasıtlı üretilmiştir. Kısa/uzun VKN senaryosu satır 3, 7, 11'dedir. VERI_A (cari) ve VERI_B (Ba/Bs) temizleyip kendi dökümünüzü yapıştırın.
A6: Örnek özet (bilgi)
A7: Beklenen eşleşen ~24 | tolerans ~3 | tutar farkı ~5 | eşleşmedi ~3
A9: Ölçek sözleşmesi | B9: 50000

Sheet LISTELER
A1: LISTELER — Cari ve Ba-Bs Toplu Mutabakat Motoru
A3: Form Tipi | C3: İşlem Tipi | E3: Durum Listesi | G3: EvetHayir
A6: FormTipi | C6: IslemTipi | E6: Durum | G6: Secim
A7: Ba | C7: Alış | E7: Açık | G7: EVET
A8: Bs | C8: Satış | E8: Kapalı | G8: HAYIR
E9: İncele
E10: Beklemede

Sheet AYARLAR
A1: AYARLAR — Cari ve Ba-Bs Toplu Mutabakat Motoru
A3: Tek kaynak parametreler — kaynak ve yürürlük zorunlu (D10)
A5: anahtar | B5: deger | C5: birim | D5: kaynak | E5: yururluk_tarihi | F5: aciklama
A6: toleransKurus | B6: 0.05 | C6: TL | D6: İş kuralı — kuruş toleransı | E6: 01.01.2026 | F6: Eşleşme toleransı
A7: raporTarihi | B7: 46244 | C7: tarih | D7: Kullanıcı / dönem kapanışı | E7: 01.01.2026 | F7: Rapor tarihi (TODAY yok)
