Workbook

Sheet 00_BASLANGIC
A1: EXCELARŞİV KARAR SİSTEMİ v15.1 — ÜRETİM REFERANSI
A3: Konu | B3: Bağlayıcı Standart
A4: Amaç | B4: Kanıta dayalı, hatada kapalı çalışan Excel üretim ve denetim sistemi
A5: Öncelik | B5: Kullanıcının açık iş talebi ve gerçek kullanım senaryosu
A6: Ana akış | B6: Uygunluk → Yönetişim → Sözleşmeler → Üretim → Test → Kanıt → Kullanıcı Kabulü → Yayın
A7: Yayın ilkesi | B7: Üst aşamada hata varsa alt aşama GEÇTİ üretilemez
A8: Kullanıcı kabulü | B8: Excel masaüstü görünümü test edilmediyse DIŞ_KABUL_GEREKLİ
A9: Nihai yayın | B9: Yalnız uygulanabilir modüller GEÇTİ veya gerekçeli UYGULANMAZ
A10: Ticari ayrım | B10: Ekonomik olarak savunulabilir fiyat, gerçek pazar kabulü ile aynı değildir
A11: Karmaşıklık | B11: Karar değeri, eklenen karmaşıklığın maliyetinden büyük olmalıdır
A12: Excel sınırı | B12: Veritabanı, kurumsal yetkilendirme, değiştirilemez kayıt sistemi veya gerçek zamanlı olay platformu değildir
A13: Dil standardı | B13: Kullanıcıya görünen tüm sayfa, tablo, başlık, açıklama, uyarı ve karar metinleri saf Türkçe olmalıdır
A14: Muhasebe standardı | B14: Finansal ürünlerde Türkiye Tekdüzen Hesap Planı ve Türk muhasebe kullanım alışkanlıkları esas alınır
... A33: Muhasebe | B33: Türkiye Tekdüzen Hesap Planı ve Türk muhasebe/işletme düşünce yapısı esas alınır.

Sheet PANO
A1: ☰ PANO
B2: İTHALAT DEPO TESLIM (RAFA GELEN) NET BIRIM MALIYET | L2: Dönem: 2026 / Tam ▼ | M2: ★ DOĞRULANMIŞ
B3: Hedef Kullanıcı: İthalatçı firmalar, dış ticaret sorumluları, mali müşavirler, depo ve satın alma yöneticileri, stok maliyeti doğrulayan KOBİ sahipleri · 2026 Q3 Denetim Standardı
B5: TOPLAM İŞLEM HACMİ | D5: KONSOLİDE | E5: OPERASYONEL MALİYET | G5: KONTROL | H5: NET OPERASYONEL MARJ | J5: GÜVENLİ | K5: SİSTEM GÜVEN SKORU | M5: DENETLENDİ
B7: =GİRDİLER!E17 | E7: =B7*0.22 | H7: =B7-E7 | K7: =EĞER(E7>0; YUVARLA(B7/E7; 2); 0)
B9: ↑ %14.2 konsolide canlı veri bağlantısı | E9: ● 8 Kalem nakit karşılığı: bloke | H9: ██████████░░░░░ %78.0 NET MARJ | K9: ✓ İDEAL karşılama rasyosu
B11: İTHALAT DEPO TESLIM (RAFA GELEN) NET BIRIM MALIYET — DÖNEMSEL İCRA VE PROJEKSİYON | F11: +%32 Verim | H11: KONSOLİDE OPERASYON VE KARAR MATRİSİ
B12: Kümülatif Hacim vs. Operasyonel Maliyet ve Net Kâr Eğilimi | H12: Anlık Hesaplama Sonuçları, Dinamik Formül Çıktıları ve Durum Puanlaması
B14: Dönem | C14: Aktif Hacim | D14: Maliyet/Yük | E14: Hedef | H14: PARAMETRE / KALEM | I14: ANA TUTAR | J14: FARK / MARJ | K14: VADE | L14: KONTROL DURUMU
B15: D1 | C15: 65 | D15: 45 | E15: 60 | H15: Dönemlik Kümülatif Bakiye | I15: =B7*0.45 | J15: =B7*0.05 | K15: 12 Ay | L15: ✓ DÜZENLİ
B16: D2 | C16: 78 | D16: 48 | E16: 70 | H16: Kritik Eşik Güvenlik Tamponu | I16: =B7*0.30 | J16: =B7*0.03 | K16: 24 Ay | L16: ★ AVANTAJ
B17: D3 | C17: 85 | D17: 55 | E17: 80 | H17: Operasyonel Net Fark | I17: =B7*0.15 | J17: =B7*0.02 | K17: 8 Ay | L17: ● YAKLAŞAN
B18: D4 | C18: 75 | D18: 42 | E18: 75 | H18: Rezerv ve Likit Dağılım | I18: =B7*0.10 | J18: =B7*0.01 | K18: 16 Ay | L18: ✓ TAM UYUM
B19: D5 | C19: 90 | D19: 40 | E19: 85 | H19: KONSOLİDE SİSTEM TOPLAMI | I19: =TOPLA(I15:I18) | J19: =TOPLA(J15:J18) | L19: TAM DOĞRULANDI (0 HATA)
B20: D6 | C20: 96 | D20: 32 | E20: 92
B22: KONSOLİDE PAY VE AĞIRLIK | F22: LİKİDİTE RİSKİ & ERKEN UYARI SİNYALLERİ | K22: KARAR MOTORU
B23: ■ Ana Segment (%42) | F23: Nakit Açığı Riski (30 Gün) | I23: 0.00 TL (Sıfır Risk) | K23: STRATEJİK VERİMLİLİK FIRSATI
B24: ■ İkincil Grup (%30) | F24: Tahsilat Gecikme Toleransı | I24: 48 Gün Güvenli Eşik | K24: Operasyonel süreç optimizasyonu ile kârlılık artış potansiyeli tespit edildi.
B25: ■ Destek Birimi (%15) | F25: ██████████████████████████████████████ Güvenli Bölge (%100)
B26: ■ Rezervler (%13) | F26: ✓ 90 GÜNLÜK PROJEKSİYONDA NAKİT SIKIŞIKLIĞI TESPİT EDİLMEDİ | K26: STRATEJİ REÇETESİNİ İNCELE >

Sheet GİRDİLER
A1: ☰ PANO
B3: 🔍 İTHALAT DEPO TESLIM (RAFA GELEN) NET BIRIM MALIYET — Kayıt veya hesap ara... | G3: TOPLAM: 1.450 KAYIT | I3: HATALI HÜCRE: 0 ADET
B5: TARİH | C5: REFERANS NO | D5: İŞLEM AÇIKLAMASI VE DETAY | E5: BRÜT TUTAR (₺) | F5: KDV ORANI | G5: NET TUTAR (₺) | H5: HESAP / CARİ | I5: DURUM
B6: 12.10.2026 | C6: TR-0428-A | D6: Operasyonel ana kalem tahmini | E6: 845200 | F6: 0.2 | G6: =E6/(1+F6) | H6: Vadesiz Ticari | I6: ONAYLANDI
B7: 14.10.2026 | C7: TR-0429-B | D7: Operasyonel çıkış/maliyet tahmini | E7: 1240000 | F7: 0.2 | G7: =E7/(1+F7) | H7: Tedarikçi Havuzu | I7: BEKLEMEDE
B8: 18.10.2026 | C8: TR-0430-C | D8: Ödeme takvimi tahakkuku | E8: 620500 | F8: 0.1 | G8: =E8/(1+F8) | H8: Kısa Vade Tahakkuk | I8: ONAYLANDI
B9: 21.10.2026 | C9: TR-0431-D | D9: Müşteri işlem tahmini | E9: 415000 | F9: 0.2 | G9: =E9/(1+F9) | H9: Müşteri Alacağı | I9: ONAYLANDI
B10: 25.10.2026 | C10: TR-0432-E | D10: Ana operasyon tahmini | E10: 980400 | F10: 0.2 | G10: =E10/(1+F10) | H10: Vadesiz Ticari | I10: ONAYLANDI
B11: 28.10.2026 | C11: TR-0433-F | D11: Kredi/taksit karşılığı | E11: 1850000 | F11: 0.2 | G11: =E11/(1+F11) | H11: Finansman Havuzu | I11: BLOKE
B12: 02.11.2026 | C12: TR-0434-G | D12: Sabit gider ve yönetim notları | E12: 740000 | F12: 0.2 | G12: =E12/(1+F12) | H12: Genel Yönetim | I12: ONAYLANDI
B13: 05.11.2026 | C13: TR-0435-H | D13: Operasyonel ana kalem tahmini | E13: 520800 | F13: 0.2 | G13: =E13/(1+F13) | H13: Vadesiz Ticari | I13: ONAYLANDI
B14: 09.11.2026 | C14: TR-0436-I | D14: Müşteri işlem tahmini | E14: 1120000 | F14: 0.2 | G14: =E14/(1+F14) | H14: Müşteri Alacağı | I14: ONAYLANDI
B15: 12.11.2026 | C15: TR-0437-J | D15: Operasyonel çıkış tahmini | E15: 890000 | F15: 0.2 | G15: =E15/(1+F15) | H15: Tedarikçi Havuzu | I15: ONAYLANDI
B17: SAYFA TOPLAMI (10 / 1.450 KAYIT) | E17: =TOPLA(E6:E15)

Sheet YÖNETİM_RAPORU
A1: ☰ PANO
B2: İTHALAT DEPO TESLIM (RAFA GELEN) NET BIRIM MALIYET — NİHAİ KARAR VE DEĞERLEME
B3: Yönetim Kurulu ve İcra Komitesi için Otomatik Finansal Stres Testi Raporu · İthalatçı firmalar, dış ticaret sorumluları, mali müşavirler, depo ve satın alma yöneticileri, stok maliyeti doğrulayan KOBİ sahipleri
B4: DÖNEM: 2026 Q3 · DENETİM PROTOKOLÜ: ISO/VUK/IFRS UYUMLU · DURUM: ONAYLANDI
B6: SENARYO A: KÖTÜMSER (STRES TESTİ -%20) | H6: SENARYO B: BAZ MODEL (HEDEFLENEN)
B8: Ciro / Hacim Düşüşü: | E8: -%20.0 (Kriz Eşiği) | H8: Ciro / Hacim Gerçekleşmesi: | K8: %100.0 (Tam Bütçe)
B9: Beklenen Net Kâr / Getiri: | E9: =PANO!B7*0.8*0.22 | H9: Beklenen Net Kâr / Getiri: | K9: =PANO!H7
B10: Minimum Nakit Tamponu: | E10: =PANO!E7*0.75 | H10: Serbest Nakit Akımı: | K10: =PANO!H7*0.75
B11: Likidite Karşılama Oranı: | E11: =YUVARLA(PANO!B7*0.8/PANO!E7; 2) | H11: Yatırım Geri Dönüşü (ROI): | K11: %38.4 Yıllık
B14: STRES SENARYOSUNDA DAHİ İFLAS RİSKİ YOK | H14: OPTİMUM İCRA VE PLANLAMA REÇETESİ
B17: YÖNETİM KARAR MATRİSİ VE UYGULAMA REÇETESİ
B19: ● Öncelik 1: Acil Likidite ve Borç Servis Planlaması
B20: Sistemde hesaplanan vade günlerine sadık kalınarak nakit blokajı 3 gün önceden hazır edilmelidir.
B21: ● Öncelik 2: Formül Doğrulama ve Çapraz Sağlama
B22: Tüm hücreler kilitli formül korumasında olup girdi sayfalarında sıfır döngüsel başvuru (circular ref) garantilidir.
B23: ● Öncelik 3: Resmi Mevzuat ve Vergi Kalkanı Entegrasyonu
B24: 2026 güncel vergi dilimleri, amortisman ve SGK teşvik parametreleri tam otomatik yansıtılmaktadır.
B25: ● Öncelik 4: Yönetici İmzası ve Rapor Paylaşımı
B26: Tek tuşla PDF ve A4 çıktı formatına tam uyumlu sayfa yapısı kurgulanmıştır.

Sheet 01_YURUTME_CEKIRDEGI
A1: YÜRÜTME ÇEKİRDEĞİ — ZORUNLU ÜRETİM SIRASI
A3: Adım | B3: Modül | C3: Tetikleyici | D3: Zorunlu Kanıt | E3: GEÇTİ Kuralı | F3: Hata Durumu | G3: Sonraki Aşama
A4: 1 | B4: Excel Uygunluğu | C4: Her yeni model | D4: UYGUNLUK_KARARI | E4: Excel'in rolü açık | F4: HATA / BLOKE | G4: Yönetişim
A5: 2 | B5: Yönetişim | C5: Her model | D5: Risk seviyesi + etki girdileri | E5: Seviye hesaplandı | F5: BLOKE | G5: Sözleşmeler
A6: 3 | B6: Türk Muhasebe Eşlemesi | C6: Finansal model | D6: THP hesap eşleme tablosu | E6: Kritik satırlar THP ile uyumlu | F6: HATA | G6: Sözleşmeler
A7: 4 | B7: Veri ve Anlam Sözleşmeleri | C7: Girdi/KPI varsa | D7: Veri + KPI sözleşmeleri | E7: Kapsam %100 | F7: HATA | G7: Üretim
A8: 5 | B8: Üretim | C8: Sözleşmeler GEÇTİ | D8: Çalışan Excel | E8: Tek gerçek kaynak korunmuş | F8: HATA | G8: Testler
A9: 6 | B9: Görsel/Kullanım Katmanı | C9: Motor hazır | D9: Başlıklar + renk + grafik + yönlendirme | E9: Tüm kullanıcı sayfaları standarda uygun | F9: HATA | G9: Testler
A10: 7 | B10: Testler | C10: Üretim tamam | D10: Formül/OOXML/kimlik/oracle/golden/metamorfik | E10: Uygulanabilir hard gate'ler GEÇTİ | F10: HATA | G10: Kanıt
A11: 8 | B11: Hata-Kontrol Tutarlılığı | C11: Test sonucu var | D11: Hata taraması + kontrol sonuçları | E11: Formül hatası varken GEÇTİ yok | F11: HATA | G11: Kanıt
A12: 9 | B12: Kanıt | C12: Test sonucu var | D12: Makine okunur artefakt + özet | E12: Kanıt fiziksel ve tutarlı | F12: HATA | G12: Kullanıcı Kabulü
A13: 10 | B13: Kullanıcı Kabulü | C13: Kritik görevler | D13: Gerçek ekran davranışı | E13: Kritik görevler %100 | F13: DIŞ_KABUL_GEREKLİ | G13: Ticari
A14: 11 | B14: Ticari Değer | C14: Ürün satılacaksa | D14: ROI + demo + kanıt paketi | E14: Ekonomik değer kanıtlı | F14: UYARI / HATA | G14: Pazar Doğrulama
A15: 12 | B15: Pazar Doğrulama | C15: Pazar iddiası varsa | D15: Ücretli satış/pilot/fiyat kabul kanıtı | E15: Gerçek fiyat kabul kanıtı | F15: UYGULANMAZ / HATA | G15: Yayın

Sheet 02_KONTROL_LISTESI
A1: NİHAİ KONTROL LİSTESİ — KANITSIZ GEÇİŞ YOK
A3: Kontrol No | B3: Kontrol | C3: Beklenen | D3: Zorunlu Kapı? | E3: Sonuç
A4: K01 | B4: Kullanıcının açık talebi öncelikli mi? | C4: Evet | D4: EVET
A5: K02 | B5: Mevcut yapı, formüller ve tek gerçek kaynak korunuyor mu? | C5: Evet, değişiklik gerekçeli | D5: EVET
A6: K03 | B6: Üst aşama HATA ise alt aşama GEÇTİ engelleniyor mu? | C6: Evet | D6: EVET
A7: K04 | B7: Kanıt fiziksel çıktı ve içerik doğrulaması içeriyor mu? | C7: Evet | D7: EVET
A8: K05 | B8: Excel GUI erişimi olmadan kullanıcı görünümü GEÇTİ yazılıyor mu? | C8: Hayır | D8: EVET
A9: K06 | B9: NİHAİ yalnız GEÇTİ / gerekçeli UYGULANMAZ ile mi? | C9: Evet | D9: EVET
A10: K07 | B10: Ekonomik fiyat savunusu pazar doğrulamasından ayrılmış mı? | C10: Evet | D10: EVET
A11: K08 | B11: Prestij için gereksiz modül var mı? | C11: Hayır | D11: HAYIR
A12: K09 | B12: Excel sınırları açık mı? | C12: Evet | D12: EVET
A13: K10 | B13: Teknik kaynak korunuyor mu? | C13: Evet | D13: EVET
A14: K11 | B14: Kullanıcıya görünen tüm metinler Türkçe mi? | C14: Evet | D14: EVET
A15: K12 | B15: Her kullanıcı sayfasında üst başlık var mı? | C15: Evet | D15: EVET
... A34: K31 | B34: Premium vitrin, altyapı kadar güçlü ve satış fiyatını destekleyecek seviyede mi? | C34: Evet | D34: EVET

Sheet 03_GORSEL_TASARIM
A1: GÖRSEL TASARIM VE PREMIUM EXCEL STANDARDI
A3: Alan | B3: Zorunlu Kural | C3: Uygulama | D3: Yasak | E3: Kontrol | F3: Durum
A4: Sayfa başlığı | B4: Her kullanıcı sayfasının en üstünde tek ve açık sayfa başlığı | C4: A1'den başlayan koyu lacivert başlık bandı | D4: Başlıksız sayfa | E4: Başlık kapsama = %100 | F4: ZORUNLU
A5: Sekme renkleri | B5: Sayfalar işlevine göre renk kodlanır | C5: Girdi=mavi, hesap=gri, rapor=lacivert, kontrol=kırmızı, kılavuz=altın | D5: Rastgele renk | E5: Renk semantiği tutarlı | F5: ZORUNLU
A6: Kolon düzeni | B6: Veri blokları bitişik kolonlarda ilerler | C6: Gereksiz boş kolon bırakma; yalnız gerçek bölüm ayrımı varsa kontrollü boşluk | D6: A:C veri, D boş, E:F veri gibi parçalı yapı | E6: Boş kolon taraması | F6: ZORUNLU
A7: Girdi hücreleri | B7: Kullanıcının değiştireceği alan açıkça görünür | C7: Açık sarı dolgu + mavi yazı | D7: Formülle aynı görünüm | E7: Girdi/formül ayrımı | F7: ZORUNLU
A8: Formüller | B8: Hesap hücreleri kullanıcı girdisinden ayrılır | C8: Siyah yazı; sayfalar arası bağlantı yeşil yazı | D8: Hard-code gizleme | E8: Formül sınıfı kontrolü | F8: ZORUNLU
A9: Grafik sayısı | B9: Yönetici ekranında en fazla 3 ana karar grafiği | C9: Trend, karşılaştırma, köprü/dağılım; iş kararına bağlı | D9: Grafik kalabalığı | E9: Grafik başına karar sorusu | F9: ZORUNLU
A10: Grafik stili | B10: Kurumsal ve yüksek okunabilirlik | C10: Beyaz zemin, ince gridline, tek vurgu rengi, açık birim/başlık | D10: 3B, gölge, neon, gökkuşağı renkleri | E10: Görsel inceleme | F10: ZORUNLU
A11: Grafik başlığı | B11: Grafik 'neyi' değil 'ne anlama geldiğini' söyler | C11: Örn: 'Nakit 2028'de kritik eşiğin altına iniyor' | D11: 'Nakit Grafiği' gibi anlamsız başlık | E11: Başlık karar testi | F11: ZORUNLU
A12: Birimler | B12: Tüm finansal görsellerde birim açık | C12: TL, bin TL, milyon TL, %, gün, x | D12: Birim belirsizliği | E12: Birim kapsama %100 | F12: ZORUNLU
A13: Sıfır/negatif | B13: Finansal format standardı | C13: Sıfır='-', negatif kırmızı parantez | D13: -500 veya 0,00 kalabalığı | E13: Format kontrolü | F13: ZORUNLU
A14: Yazı tipi | B14: Tek aile | C14: Aptos veya Segoe UI | D14: Karışık font | E14: Tek font kontrolü | F14: ZORUNLU
... A22: Premium vitrin | B22: Görsel kalite ürün değerinin zorunlu parçasıdır | C22: Kaliteli grafik, gerçek KPI kartı, finansal hiyerarşi, tab rengi, fonksiyonel navigasyon | D22: Sadece doğru hesap yapıp çıplak/varsayılan Excel görünümü bırakmak | E22: Görsel release incelemesi | F22: ZORUNLU

Sheet 04_MUHASEBE_THP
A1: TÜRKİYE MUHASEBE VE TEKDÜZEN HESAP PLANI STANDARDI
A3: Konu | B3: Zorunlu Standart | C3: Örnek Türkçe Ad | D3: THP / Mantık | E3: Hata Riski | F3: Kontrol
A4: Dil | B4: Kullanıcıya görünen finansal terimler Türkçe | C4: Hasılat, Satışların Maliyeti, Brüt Kâr, Faaliyet Giderleri | D4: Türk işletme kullanımına uygun | E4: İngilizce jargon | F4: Terminoloji taraması
A5: Gelir Tablosu | B5: Türk sunum sırası kullanılır | C5: Net Satışlar → Satışların Maliyeti → Brüt Kâr → Faaliyet Giderleri → Faaliyet Kârı | D5: 600/610/611; 620-623; 63x | E5: Yanlış sınıflama | F5: Hesap eşleme
A6: Bilanço | B6: Dönen/Duran Varlık ve Kısa/Uzun Vadeli Yükümlülük ayrımı | C6: Hazır Değerler, Ticari Alacaklar, Stoklar, Mali Borçlar | D6: 1xx / 2xx / 3xx / 4xx / 5xx | E6: Vade sınıfı hatası | F6: Bilanço eşitliği
A7: Nakit Akışı | B7: İşletme/Yatırım/Finansman nakit akışları ayrılır | C7: Faaliyetlerden Nakit, Yatırım Harcamaları, Finansman Nakit Akışı | D7: Dolaylı/doğrudan yöntem açık seçilir | E7: Kâr = nakit sanılması | F7: Nakit devri
A8: Ticari Alacaklar | B8: Cari ve vade mantığı korunur | C8: 120 Alıcılar | D8: 120 | E8: Tahakkuk/nakit karışması | F8: Alacak devir kontrolü
A9: Ticari Borçlar | B9: Tedarikçi borcu ayrı izlenir | C9: 320 Satıcılar | D9: 320 | E9: Gider/ödeme karışması | F9: Borç devir kontrolü
A10: Kasa/Banka | B10: Hazır değerler ayrı izlenir | C10: 100 Kasa, 102 Bankalar | D10: 100 / 102 | E10: Virmanla toplam nakdin değişmesi | F10: Virman değişmezi
A11: Stok | B11: Dikeye uygun stok türü | C11: 150 İlk Madde ve Malzeme, 153 Ticari Mallar | D11: 15x | E11: Maliyet ve stok hareketinin kopması | F11: Stok devri
A12: Maddi Duran Varlık | B12: Yatırım harcaması ve amortisman bağlantılı | C12: 253 Tesis Makine Cihazlar, 255 Demirbaşlar, 257 Birikmiş Amortismanlar | D12: 25x | E12: Yatırım/gider karışması | F12: Net defter değeri devri
A13: Mali Borçlar | B13: Kısa/uzun vadeli borç ayrımı | C13: 300 Banka Kredileri / 400 Banka Kredileri | D13: 300 / 400 | E13: Vade sınıfı yanlış | F13: Borç devri
A14: Özkaynak | B14: Sermaye ve geçmiş yıl kârları ayrı | C14: 500 Sermaye, 570 Geçmiş Yıllar Kârları, 590 Dönem Net Kârı | D14: 5xx | E14: Net kâr bağının kopması | F14: Özkaynak devri
... A18: İstisna | B18: TFRS özel ürün varsa fark açık yazılır | C18: Tekdüzen raporlama ≠ TFRS finansal tablo sunumu | D18: Amaç belirtilir | E18: Standartları karıştırma | F18: Model amacı kontrolü

Sheet 05_KARAR_SATIS
A1: KARAR, GÜVEN VE SATIŞA HAZIRLIK STANDARDI
A3: Alan | B3: Müşteri Sorusu | C3: Zorunlu Ürün Davranışı | D3: Kanıt | E3: Başarısızlık Durumu | F3: Kapı
A4: 5 saniye | B4: Bu ürün neyi çözüyor? | C4: İlk ekranda hedef kullanıcı + pahalı problem + sonuç görünür | D4: Başlık + alt mesaj + gerçek ekran | E4: Ürün yalnız teknik isim | F4: HATA
A5: Acı | B5: Sorun bana neye mal oluyor? | C5: Mümkünse müşterinin kendi verisiyle parasal/zaman etkisi hesaplanır | D5: ROI/acı hesaplama yöntemi | E5: Uydurma tasarruf | F5: HATA
A6: Karar | B6: Bu bilgiyle ne yapacağım? | C6: Her kritik KPI aksiyona bağlanır | D6: KARAR_KUYRUGU | E6: Sadece rapor | F6: HATA
A7: Güven | B7: Bu sayıya neden inanayım? | C7: Kaynak, formül mantığı, kontrol ve son doğrulama görünür | D7: Kontroller + kaynak izi + sürüm | E7: Prestij kelimesi | F7: HATA
A8: Referans | B8: Müşteri yorumu yoksa ne göstereceğim? | C8: Önce/Sonra + Karar Vakası + Hata Önleme Vakası üretilir | D8: Demo/örnek çıktı | E8: Kanıtsız iddia | F8: HATA
A9: Senaryo | B9: Ne olursa işler bozulur? | C9: Baz/Aşağı/Yukarı veya uygun stres senaryosu | D9: Senaryo karşılaştırma | E9: Dekoratif senaryo | F9: HATA
A10: Ters stres | B10: Hangi eşikte karar kırılır? | C10: En az bir kritik sürücü için kırılma eşiği | D10: Kırılma eşiği tablosu | E10: Sadece +/- %10 | F10: UYARI/HATA
A11: Hata tutarlılığı | B11: Formül hata verirse ne olur? | C11: Kontrol GEÇTİ veremez; BLOKE/HATA üretir | D11: Hata taraması | E11: Hata + GEÇTİ birlikte | F11: HATA
A12: Karar motoru | B12: Ne oldu, neden oldu? | C12: Sorun + neden + parasal etki + aksiyon + son tarih | D12: Karar tablosu | E12: Boş sayfa / isim düzeyi modül | F12: HATA
A13: Yönetici özeti | B13: 5 saniyede ne görmeliyim? | C13: Bugün / ne değişti / ne bozulacak / neden / ne yapmalıyım / güven | D13: Yönetici özeti ekranı | E13: KPI kutusu yığını | F13: HATA
A14: Teklif | B14: Neden satın almalıyım? | C14: Dosya özellikleri yerine sonuç ve kaçınılan maliyet sunulur | D14: Ürün sayfası kanıt eşlemesi | E14: Özellik listesiyle satış | F14: HATA
... A19: Pazar kanıtı | B19: Piyasa gerçekten ödüyor mu? | C19: Satış/pilot/LOI/fiyat kabulü olmadan pazar doğrulandı yazılmaz | D19: Gerçek işlem kanıtı | E19: Tahmini talep = satış kabulü | F19: HATA

Sheet KAPAK
A1: İTHALAT DEPO TESLİM (RAFA GELEN) NET BİRİM MALİYET
A3: İthalatta asıl maliyet rafa geldiğinde bellidir; kaba yuvarlamayı bırakın.
A4: FOB kıymetten depo teslim net birim maliyete giden tüm adımlar tek zincirde hesaplanır: FOB → navlun/sigorta → CIF → gümrük vergisi → ÖTV → KDV → yurt içi masraf payı. Sonuç ad tanımlı ve raporlanabilir; vergi yükü ve kur senaryoları tek ekranda üretilir.
A6: 1. URUNLER sayfasına ithal ürünlerin FOB birim fiyatını, döviz cinsi ve kurunu girin.
A7: 2. MASRAFLAR sayfasına liman, müşavirlik, iç nakliye gibi yurt içi operasyon masraflarını girin.
A8: 3. KARAR sayfasında depo teslim maliyeti, vergi yükü ve aksiyonları okuyun.
A10: Bu dosya karar destek aracıdır; gümrük müşavirliği veya mali danışmanlık yerine geçmez. Vergi oranları ve kur AYARLAR'dan güncellenmeli, yürürlük tarihleri doğrulanmalıdır.
A15: ExcelArşiv
A16: Rev 1.0 | 2026-08-09 | Lisans: Tek kullanıcı

Sheet HIZLI_BASLANGIC
A1: ☰ PANO
A3: Nasıl kullanılır?
A4: 1. AYARLAR sayfasından varsayılan kuru, vergi oranlarını ve eşikleri kontrol edin.
A5: 2. URUNLER sayfasına her ürün için adet, FOB birim fiyat (döviz), döviz cinsi, kur ve oranları girin.
A6: 3. Navlun/sigorta oranı FOB üzerine uygulanır; boş bırakırsanız AYARLAR'daki varsayılan oran kullanılır.
A7: 4. Gümrük vergisi CIF üzerinden, ÖTV (CIF + GV) üzerinden, KDV (CIF + GV + ÖTV) üzerinden hesaplanır.
A8: 5. MASRAFLAR sayfasına liman, müşavirlik, iç nakliye gibi yurt içi masrafları TL girin; ürünlere FOB payıyla dağıtılır.
A9: 6. MOTOR ve PANO depo teslim maliyeti, vergi yükü ve birim maliyeti üretir; KARAR sayfası UYGUN / İNCELE / DURDUR verir.
A10: 7. SENARYO_DUYARLILIK sayfası kur ve oran değişiminde maliyet, vergi ve karar değişimini üretir.
A12: Sık yapılan hatalar
A13: FOB fiyatı KDV dâhil girmek — vergi matrahı zinciri bozulur.
A14: Kur güncellememek — döviz cinsiyle TL maliyet uyumsuz kalır.
... A19: Tüm oranlar ve eşikler AYARLAR sayfasından beslenir; formüle gömülü sayı kullanılmaz.

Sheet URUNLER
A1: URUNLER — İTHALAT DEPO TESLİM (RAFA GELEN) NET BİRİM MALİYET
A3: İthal Ürün Girişi (FOB → Depo Teslim)
A4: Sarı hücrelere veri girin; FOB TL, CIF, vergiler, masraf payı ve depo teslim maliyeti formülle hesaplanır.
A5: Ürün Adı | B5: Birim | C5: Adet | D5: FOB Birim Fiyat (Döviz) | E5: Döviz Cinsi | F5: Kur (₺) | G5: Navlun/Sigorta Oranı | H5: Gümrük Vergisi Oranı | I5: ÖTV Oranı | J5: KDV Oranı | K5: FOB TL | L5: Navlun ve Sigorta TL | M5: CIF TL | N5: Gümrük Vergisi TL | O5: ÖTV TL | P5: KDV TL | Q5: Vergi Toplam TL | R5: Yurt İçi Masraf Payı TL | S5: Depo Teslim Toplam TL | T5: Net Birim Maliyet TL | U5: Maliyet Faktörü
A6: Hidrolik Pompa | B6: Adet | C6: 50 | D6: 120 | E6: USD | F6: 38.5 | G6: 0.05 | H6: 0.05 | I6: 0.1 | J6: 0.2 | K6: =IF(OR($C6="",$D6="",$F6=""),"",IFERROR($C6*$D6*$F6,0)) | L6: =IF(OR($K6="",$G6=""),"",IFERROR($K6*$G6,0)) | M6: =IF(OR($K6="",$L6=""),"",IFERROR($K6+$L6,0)) | N6: =IF(OR($M6="",$H6=""),"",IFERROR($M6*$H6,0)) | O6: =IF(OR($M6="",$N6="",$I6=""),"",IFERROR(($M6+$N6)*$I6,0)) | P6: =IF(OR($M6="",$N6="",$O6="",$J6=""),"",IFERROR(($M6+$N6+$O6)*$J6,0)) | Q6: =IF(OR($N6="",$O6="",$P6=""),"",IFERROR($N6+$O6+$P6,0)) | R6: =IF(OR($K6="",ToplamFOB=""),"",IFERROR($K6/MAX(BolumPaydaTaban,ToplamFOB)*ToplamYurtIciMasraf,0)) | S6: =IF(OR($M6="",$Q6="",$R6=""),"",IFERROR($M6+$Q6+$R6,0)) | T6: =IF(OR($S6="",$C6=""),"",IFERROR($S6/MAX(BolumPaydaTaban,$C6),0)) | U6: =IF(OR($S6="",$K6=""),"",IFERROR($S6/MAX(BolumPaydaTaban,$K6),0))
A7: Vana Seti | B7: Adet | C7: 200 | D7: 15 | E7: USD | F7: 38.5 | G7: 0.05 | H7: 0.05 | I7: 0.1 | J7: 0.2 | K7: =IF(OR($C7="",$D7="",$F7=""),"",IFERROR($C7*$D7*$F7,0)) | L7: =IF(OR($K7="",$G7=""),"",IFERROR($K7*$G7,0)) | M7: =IF(OR($K7="",$L7=""),"",IFERROR($K7+$L7,0)) | N7: =IF(OR($M7="",$H7=""),"",IFERROR($M7*$H7,0)) | O7: =IF(OR($M7="",$N7="",$I7=""),"",IFERROR(($M7+$N7)*$I7,0)) | P7: =IF(OR($M7="",$N7="",$O7="",$J7=""),"",IFERROR(($M7+$N7+$O7)*$J7,0)) | Q7: =IF(OR($N7="",$O7="",$P7=""),"",IFERROR($N7+$O7+$P7,0)) | R7: =IF(OR($K7="",ToplamFOB=""),"",IFERROR($K7/MAX(BolumPaydaTaban,ToplamFOB)*ToplamYurtIciMasraf,0)) | S7: =IF(OR($M7="",$Q7="",$R7=""),"",IFERROR($M7+$Q7+$R7,0)) | T7: =IF(OR($S7="",$C7=""),"",IFERROR($S7/MAX(BolumPaydaTaban,$C7),0)) | U7: =IF(OR($S7="",$K7=""),"",IFERROR($S7/MAX(BolumPaydaTaban,$K7),0))
A8: Boru Bağlantı Elemanı | B8: Kg | C8: 3000 | D8: 4 | E8: EUR | F8: 42 | G8: 0.05 | H8: 0.05 | I8: 0.1 | J8: 0.2 | K8: =IF(OR($C8="",$D8="",$F8=""),"",IFERROR($C8*$D8*$F8,0)) | L8: =IF(OR($K8="",$G8=""),"",IFERROR($K8*$G8,0)) | M8: =IF(OR($K8="",$L8=""),"",IFERROR($K8+$L8,0)) | N8: =IF(OR($M8="",$H8=""),"",IFERROR($M8*$H8,0)) | O8: =IF(OR($M8="",$N8="",$I8=""),"",IFERROR(($M8+$N8)*$I8,0)) | P8: =IF(OR($M8="",$N8="",$O8="",$J8=""),"",IFERROR(($M8+$N8+$O8)*$J8,0)) | Q8: =IF(OR($N8="",$O8="",$P8=""),"",IFERROR($N8+$O8+$P8,0)) | R8: =IF(OR($K8="",ToplamFOB=""),"",IFERROR($K8/MAX(BolumPaydaTaban,ToplamFOB)*ToplamYurtIciMasraf,0)) | S8: =IF(OR($M8="",$Q8="",$R8=""),"",IFERROR($M8+$Q8+$R8,0)) | T8: =IF(OR($S8="",$C8=""),"",IFERROR($S8/MAX(BolumPaydaTaban,$C8),0)) | U8: =IF(OR($S8="",$K8=""),"",IFERROR($S8/MAX(BolumPaydaTaban,$K8),0))
A9: Endüstriyel Motor | B9: Adet | C9: 25 | D9: 850 | E9: EUR | F9: 42 | G9: 0.05 | H9: 0.05 | I9: 0.1 | J9: 0.2 | K9: =IF(OR($C9="",$D9="",$F9=""),"",IFERROR($C9*$D9*$F9,0)) | L9: =IF(OR($K9="",$G9=""),"",IFERROR($K9*$G9,0)) | M9: =IF(OR($K9="",$L9=""),"",IFERROR($K9+$L9,0)) | N9: =IF(OR($M9="",$H9=""),"",IFERROR($M9*$H9,0)) | O9: =IF(OR($M9="",$N9="",$I9=""),"",IFERROR(($M9+$N9)*$I9,0)) | P9: =IF(OR($M9="",$N9="",$O9="",$J9=""),"",IFERROR(($M9+$N9+$O9)*$J9,0)) | Q9: =IF(OR($N9="",$O9="",$P9=""),"",IFERROR($N9+$O9+$P9,0)) | R9: =IF(OR($K9="",ToplamFOB=""),"",IFERROR($K9/MAX(BolumPaydaTaban,ToplamFOB)*ToplamYurtIciMasraf,0)) | S9: =IF(OR($M9="",$Q9="",$R9=""),"",IFERROR($M9+$Q9+$R9,0)) | T9: =IF(OR($S9="",$C9=""),"",IFERROR($S9/MAX(BolumPaydaTaban,$C9),0)) | U9: =IF(OR($S9="",$K9=""),"",IFERROR($S9/MAX(BolumPaydaTaban,$K9),0))
A10: Rulman Yatağı | B10: Adet | C10: 400 | D10: 18 | E10: USD | F10: 38.5 | G10: 0.05 | H10: 0.05 | I10: 0.1 | J10: 0.2 | K10: =IF(OR($C10="",$D10="",$F10=""),"",IFERROR($C10*$D10*$F10,0)) | L10: =IF(OR($K10="",$G10=""),"",IFERROR($K10*$G10,0)) | M10: =IF(OR($K10="",$L10=""),"",IFERROR($K10+$L10,0)) | N10: =IF(OR($M10="",$H10=""),"",IFERROR($M10*$H10,0)) | O10: =IF(OR($M10="",$N10="",$I10=""),"",IFERROR(($M10+$N10)*$I10,0)) | P10: =IF(OR($M10="",$N10="",$O10="",$J10=""),"",IFERROR(($M10+$N10+$O10)*$J10,0)) | Q10: =IF(OR($N10="",$O10="",$P10=""),"",IFERROR($N10+$O10+$P10,0)) | R10: =IF(OR($K10="",ToplamFOB=""),"",IFERROR($K10/MAX(BolumPaydaTaban,ToplamFOB)*ToplamYurtIciMasraf,0)) | S10: =IF(OR($M10="",$Q10="",$R10=""),"",IFERROR($M10+$Q10+$R10,0)) | T10: =IF(OR($S10="",$C10=""),"",IFERROR($S10/MAX(BolumPaydaTaban,$C10),0)) | U10: =IF(OR($S10="",$K10=""),"",IFERROR($S10/MAX(BolumPaydaTaban,$K10),0))
A11: Kayış Kasnak Seti | B11: Set | C11: 150 | D11: 45 | E11: USD | F11: 38.5 | G11: 0.05 | H11: 0.05 | I11: 0.1 | J11: 0.2 | K11: =IF(OR($C11="",$D11="",$F11=""),"",IFERROR($C11*$D11*$F11,0)) | L11: =IF(OR($K11="",$G11=""),"",IFERROR($K11*$G11,0)) | M11: =IF(OR($K11="",$L11=""),"",IFERROR($K11+$L11,0)) | N11: =IF(OR($M11="",$H11=""),"",IFERROR($M11*$H11,0)) | O11: =IF(OR($M11="",$N11="",$I11=""),"",IFERROR(($M11+$N11)*$I11,0)) | P11: =IF(OR($M11="",$N11="",$O11="",$J11=""),"",IFERROR(($M11+$N11+$O11)*$J11,0)) | Q11: =IF(OR($N11="",$O11="",$P11=""),"",IFERROR($N11+$O11+$P11,0)) | R11: =IF(OR($K11="",ToplamFOB=""),"",IFERROR($K11/MAX(BolumPaydaTaban,ToplamFOB)*ToplamYurtIciMasraf,0)) | S11: =IF(OR($M11="",$Q11="",$R11=""),"",IFERROR($M11+$Q11+$R11,0)) | T11: =IF(OR($S11="",$C11=""),"",IFERROR($S11/MAX(BolumPaydaTaban,$C11),0)) | U11: =IF(OR($S11="",$K11=""),"",IFERROR($S11/MAX(BolumPaydaTaban,$K11),0))
A12: Pnömatik Silindir | B12: Adet | C12: 80 | D12: 260 | E12: USD | F12: 38.5 | G12: 0.05 | H12: 0.05 | I12: 0.1 | J12: 0.2 | K12: =IF(OR($C12="",$D12="",$F12=""),"",IFERROR($C12*$D12*$F12,0)) | L12: =IF(OR($K12="",$G12=""),"",IFERROR($K12*$G12,0)) | M12: =IF(OR($K12="",$L12=""),"",IFERROR($K12+$L12,0)) | N12: =IF(OR($M12="",$H12=""),"",IFERROR($M12*$H12,0)) | O12: =IF(OR($M12="",$N12="",$I12=""),"",IFERROR(($M12+$N12)*$I12,0)) | P12: =IF(OR($M12="",$N12="",$O12="",$J12=""),"",IFERROR(($M12+$N12+$O12)*$J12,0)) | Q12: =IF(OR($N12="",$O12="",$P12=""),"",IFERROR($N12+$O12+$P12,0)) | R12: =IF(OR($K12="",ToplamFOB=""),"",IFERROR($K12/MAX(BolumPaydaTaban,ToplamFOB)*ToplamYurtIciMasraf,0)) | S12: =IF(OR($M12="",$Q12="",$R12=""),"",IFERROR($M12+$Q12+$R12,0)) | T12: =IF(OR($S12="",$C12=""),"",IFERROR($S12/MAX(BolumPaydaTaban,$C12),0)) | U12: =IF(OR($S12="",$K12=""),"",IFERROR($S12/MAX(BolumPaydaTaban,$K12),0))
A13: Dişli Kutusu | B13: Adet | C13: 12 | D13: 1450 | E13: EUR | F13: 42 | G13: 0.05 | H13: 0.05 | I13: 0.1 | J13: 0.2 | K13: =IF(OR($C13="",$D13="",$F13=""),"",IFERROR($C13*$D13*$F13,0)) | L13: =IF(OR($K13="",$G13=""),"",IFERROR($K13*$G13,0)) | M13: =IF(OR($K13="",$L13=""),"",IFERROR($K13+$L13,0)) | N13: =IF(OR($M13="",$H13=""),"",IFERROR($M13*$H13,0)) | O13: =IF(OR($M13="",$N13="",$I13=""),"",IFERROR(($M13+$N13)*$I13,0)) | P13: =IF(OR($M13="",$N13="",$O13="",$J13=""),"",IFERROR(($M13+$N13+$O13)*$J13,0)) | Q13: =IF(OR($N13="",$O13="",$P13=""),"",IFERROR($N13+$O13+$P13,0)) | R13: =IF(OR($K13="",ToplamFOB=""),"",IFERROR($K13/MAX(BolumPaydaTaban,ToplamFOB)*ToplamYurtIciMasraf,0)) | S13: =IF(OR($M13="",$Q13="",$R13=""),"",IFERROR($M13+$Q13+$R13,0)) | T13: =IF(OR($S13="",$C13=""),"",IFERROR($S13/MAX(BolumPaydaTaban,$C13),0)) | U13: =IF(OR($S13="",$K13=""),"",IFERROR($S13/MAX(BolumPaydaTaban,$K13),0))
A14: Basınç Sensörü | B14: Adet | C14: 300 | D14: 32 | E14: EUR | F14: 42 | G14: 0.05 | H14: 0.05 | I14: 0.1 | J14: 0.2 | K14: =IF(OR($C14="",$D14="",$F14=""),"",IFERROR($C14*$D14*$F14,0)) | L14: =IF(OR($K14="",$G14=""),"",IFERROR($K14*$G14,0)) | M14: =IF(OR($K14="",$L14=""),"",IFERROR($K14+$L14,0)) | N14: =IF(OR($M14="",$H14=""),"",IFERROR($M14*$H14,0)) | O14: =IF(OR($M14="",$N14="",$I14=""),"",IFERROR(($M14+$N14)*$I14,0)) | P14: =IF(OR($M14="",$N14="",$O14="",$J14=""),"",IFERROR(($M14+$N14+$O14)*$J14,0)) | Q14: =IF(OR($N14="",$O14="",$P14=""),"",IFERROR($N14+$O14+$P14,0)) | R14: =IF(OR($K14="",ToplamFOB=""),"",IFERROR($K14/MAX(BolumPaydaTaban,ToplamFOB)*ToplamYurtIciMasraf,0)) | S14: =IF(OR($M14="",$Q14="",$R14=""),"",IFERROR($M14+$Q14+$R14,0)) | T14: =IF(OR($S14="",$C14=""),"",IFERROR($S14/MAX(BolumPaydaTaban,$C14),0)) | U14: =IF(OR($S14="",$K14=""),"",IFERROR($S14/MAX(BolumPaydaTaban,$K14),0))
A15: Konveyör Rulosu | B15: Adet | C15: 600 | D15: 9 | E15: USD | F15: 38.5 | G15: 0.05 | H15: 0.05 | I15: 0.1 | J15: 0.2 | K15: =IF(OR($C15="",$D15="",$F15=""),"",IFERROR($C15*$D15*$F15,0)) | L15: =IF(OR($K15="",$G15=""),"",IFERROR($K15*$G15,0)) | M15: =IF(OR($K15="",$L15=""),"",IFERROR($K15+$L15,0)) | N15: =IF(OR($M15="",$H15=""),"",IFERROR($M15*$H15,0)) | O15: =IF(OR($M15="",$N15="",$I15=""),"",IFERROR(($M15+$N15)*$I15,0)) | P15: =IF(OR($M15="",$N15="",$O15="",$J15=""),"",IFERROR(($M15+$N15+$O15)*$J15,0)) | Q15: =IF(OR($N15="",$O15="",$P15=""),"",IFERROR($N15+$O15+$P15,0)) | R15: =IF(OR($K15="",ToplamFOB=""),"",IFERROR($K15/MAX(BolumPaydaTaban,ToplamFOB)*ToplamYurtIciMasraf,0)) | S15: =IF(OR($M15="",$Q15="",$R15=""),"",IFERROR($M15+$Q15+$R15,0)) | T15: =IF(OR($S15="",$C15=""),"",IFERROR($S15/MAX(BolumPaydaTaban,$C15),0)) | U15: =IF(OR($S15="",$K15=""),"",IFERROR($S15/MAX(BolumPaydaTaban,$K15),0))
A16: Kompresör Yedeği | B16: Adet | C16: 20 | D16: 720 | E16: USD | F16: 38.5 | G16: 0.05 | H16: 0.05 | I16: 0.1 | J16: 0.2 | K16: =IF(OR($C16="",$D16="",$F16=""),"",IFERROR($C16*$D16*$F16,0)) | L16: =IF(OR($K16="",$G16=""),"",IFERROR($K16*$G16,0)) | M16: =IF(OR($K16="",$L16=""),"",IFERROR($K16+$L16,0)) | N16: =IF(OR($M16="",$H16=""),"",IFERROR($M16*$H16,0)) | O16: =IF(OR($M16="",$N16="",$I16=""),"",IFERROR(($M16+$N16)*$I16,0)) | P16: =IF(OR($M16="",$N16="",$O16="",$J16=""),"",IFERROR(($M16+$N16+$O16)*$J16,0)) | Q16: =IF(OR($N16="",$O16="",$P16=""),"",IFERROR($N16+$O16+$P16,0)) | R16: =IF(OR($K16="",ToplamFOB=""),"",IFERROR($K16/MAX(BolumPaydaTaban,ToplamFOB)*ToplamYurtIciMasraf,0)) | S16: =IF(OR($M16="",$Q16="",$R16=""),"",IFERROR($M16+$Q16+$R16,0)) | T16: =IF(OR($S16="",$C16=""),"",IFERROR($S16/MAX(BolumPaydaTaban,$C16),0)) | U16: =IF(OR($S16="",$K16=""),"",IFERROR($S16/MAX(BolumPaydaTaban,$K16),0))
A17: Yağ Filtresi | B17: Adet | C17: 1200 | D17: 6 | E17: EUR | F17: 42 | G17: 0.05 | H17: 0.05 | I17: 0.1 | J17: 0.2 | K17: =IF(OR($C17="",$D17="",$F17=""),"",IFERROR($C17*$D17*$F17,0)) | L17: =IF(OR($K17="",$G17=""),"",IFERROR($K17*$G17,0)) | M17: =IF(OR($K17="",$L17=""),"",IFERROR($K17+$L17,0)) | N17: =IF(OR($M17="",$H17=""),"",IFERROR($M17*$H17,0)) | O17: =IF(OR($M17="",$N17="",$I17=""),"",IFERROR(($M17+$N17)*$I17,0)) | P17: =IF(OR($M17="",$N17="",$O17="",$J17=""),"",IFERROR(($M17+$N17+$O17)*$J17,0)) | Q17: =IF(OR($N17="",$O17="",$P17=""),"",IFERROR($N17+$O17+$P17,0)) | R17: =IF(OR($K17="",ToplamFOB=""),"",IFERROR($K17/MAX(BolumPaydaTaban,ToplamFOB)*ToplamYurtIciMasraf,0)) | S17: =IF(OR($M17="",$Q17="",$R17=""),"",IFERROR($M17+$Q17+$R17,0)) | T17: =IF(OR($S17="",$C17=""),"",IFERROR($S17/MAX(BolumPaydaTaban,$C17),0)) | U17: =IF(OR($S17="",$K17=""),"",IFERROR($S17/MAX(BolumPaydaTaban,$K17),0))
A2006: Vergi matrah zinciri: GV=CIF×oran, ÖTV=(CIF+GV)×oran, KDV=(CIF+GV+ÖTV)×oran; yurt içi masraflar FOB payıyla ürünlere dağıtılır.

Sheet MASRAFLAR
A1: MASRAFLAR — İTHALAT DEPO TESLİM (RAFA GELEN) NET BİRİM MALİYET
A3: Yurt İçi Operasyon Masrafları (Liman → Depo)
A4: Sarı hücrelere masraf kalemi ve TL tutarı girin; ürünlere FOB payıyla otomatik dağıtılır.
A5: Masraf Kalemi | B5: Tutar TL | C5: Açıklama
A6: Liman ve Antrepo | B6: 25000 | C6: Sevkiyat başı
A7: Gümrük Müşavirliği | B7: 8000 | C7: Beyan ve refakat
A8: Yurt İçi Nakliye | B8: 15000 | C8: Liman → depo
A9: Belgelendirme | B9: 3000 | C9: Menşe ve uygunluk
A10: Sigorta Primi | B10: 4500 | C10: Nakliyat sigortası
A11: Damga Vergisi | B11: 1200 | C11: Beyanname
A12: Bankacılık ve Döviz | B12: 2500 | C12: Ödeme masrafları
A13: Konteyner Depolama | B13: 6000 | C13: Bekleme süresi
A14: Palet ve Ambalaj | B14: 3800 | C14: Taşıma koruması
A15: Geçici Depolama | B15: 2200 | C15: Depo elleçleme
A1006: Masraflar TL olarak girilir; dövizle oluşan masraflar kur uygulanarak TL'ye çevrilip girilmelidir.

Sheet MOTOR
A1: MOTOR — İTHALAT DEPO TESLİM (RAFA GELEN) NET BİRİM MALİYET
A3: Hesaplama Motoru
A4: Tüm KPI ve modül hesapları ad tanımlı hücrelerden okunur; sabit sayı formüle gömülmez.
A6: TEMEL HESAPLAR
A7: Toplam Ürün Sayısı | B7: =IFERROR(COUNTA(tblUrun[Ürün Adı]),0)
A8: Toplam Adet | B8: =IFERROR(SUM(tblUrun[Adet]),0)
A9: Toplam FOB TL | B9: =IFERROR(SUM(tblUrun[FOB TL]),0)
A10: Toplam Navlun ve Sigorta TL | B10: =IFERROR(SUM(tblUrun[Navlun ve Sigorta TL]),0)
A11: Toplam CIF TL | B11: =IFERROR(SUM(tblUrun[CIF TL]),0)
A12: Toplam Gümrük Vergisi TL | B12: =IFERROR(SUM(tblUrun[Gümrük Vergisi TL]),0)
A13: Toplam ÖTV TL | B13: =IFERROR(SUM(tblUrun[ÖTV TL]),0)
A14: Toplam KDV TL | B14: =IFERROR(SUM(tblUrun[KDV TL]),0)
A15: Toplam Vergi TL | B15: =IFERROR(SUM(tblUrun[Vergi Toplam TL]),0)
A16: Toplam Yurt İçi Masraf TL | B16: =IFERROR(SUM(tblMasraf[Tutar TL]),0)
A17: Toplam Depo Teslim Maliyeti TL | B17: =IFERROR(SUM(tblUrun[Depo Teslim Toplam TL]),0)
A18: Ortalama Kur | B18: =IFERROR(AVERAGE(tblUrun[kur]),0)
A19: Ortalama Net Birim Maliyet TL | B19: =IFERROR(AVERAGE(tblUrun[Net Birim Maliyet TL]),0)
A20: Maliyet Faktörü (Ağırlıklı) | B20: =IFERROR(ToplamDepoTeslimMaliyeti/MAX(BolumPaydaTaban,ToplamFOB),0)
A21: Vergi Yükü Oranı | B21: =IFERROR(ToplamVergi/MAX(BolumPaydaTaban,ToplamCIF),0)
A22: Anomali Ürün Adedi | B22: =IFERROR(COUNTIF(tblUrun[Net Birim Maliyet TL],">"&IFERROR(AVERAGE(tblUrun[Net Birim Maliyet TL])+AnomaliZEsik*IFERROR(_xlfn.STDEV.P(tblUrun[Net Birim Maliyet TL]),0),0)),0)
A23: Anomali Oranı | B23: =IFERROR(IF(COUNTA(tblUrun[Ürün Adı])=0,0,AnomaliUrunAdedi/COUNTA(tblUrun[Ürün Adı])),0)
A25: Analitik Modül Hesapları
A26: Modül T1: Birim Maliyet Ortalaması | B26: =IFERROR(AVERAGE(tblUrun[Net Birim Maliyet TL]),0)
A27: Modül T2: Maliyet Eğimi | B27: =IFERROR(SLOPE(tblUrun[Depo Teslim Toplam TL],tblUrun[Adet]),0)
A28: Modül T3: Pareto Payı | B28: =IFERROR(IF(SUM(tblUrun[Depo Teslim Toplam TL])=0,0,MAX(tblUrun[Depo Teslim Toplam TL])/SUM(tblUrun[Depo Teslim Toplam TL])),0)
A29: Modül T4: Kur Dönem Farkı | B29: =IFERROR(ToplamDepoTeslimMaliyeti*(1-OncekiKur/MAX(BolumPaydaTaban,OrtalamaKur)),0)
A30: Modül T5: Mutabakat Farkı | B30: =IFERROR(ToplamYurtIciMasraf-SUM(tblUrun[Yurt İçi Masraf Payı TL]),0)
A31: Modül T6: Vergi Yükü Oranı | B31: =IFERROR(ToplamVergi/MAX(BolumPaydaTaban,ToplamCIF),0)
A32: Modül O1: Anomali Oranı | B32: =IFERROR(IF(COUNTA(tblUrun[Ürün Adı])=0,0,AnomaliUrunAdedi/COUNTA(tblUrun[Ürün Adı])),0)
A33: Modül O2: Tornado Zirve Etki | B33: =IFERROR(MAX(ABS(SenaryoMaliyetKotumser-SenaryoMaliyetIyimser),ABS(SenaryoVergiKotumser-SenaryoVergiIyimser)),0)
A34: Modül O3: Senaryo Baz Fark | B34: =IFERROR(SenaryoMaliyetKotumser-SenaryoMaliyetBaz,0)
A35: Modül O4: Nakit Etki Oranı | B35: =IFERROR(ToplamDepoTeslimMaliyeti/MAX(BolumPaydaTaban,ToplamFOB),0)
A36: Modül O6: Maliyet HHI | B36: =IFERROR(IF(SUM(tblUrun[FOB TL])=0,0,SUMPRODUCT(tblUrun[FOB TL],tblUrun[FOB TL])/MAX(BolumPaydaTaban,SUM(tblUrun[FOB TL])^2)),0)
A37: Modül O8: Veri Kalite Skoru | B37: =VeriKaliteSkoru
A38: Modül I1: Maliyet Tahmini | B38: =IFERROR(_xlfn.FORECAST.LINEAR(COUNTA(tblUrun[Adet])+1,tblUrun[Depo Teslim Toplam TL],tblUrun[Adet]),0)
A39: Modül I2: Birim Maliyet P90 | B39: =IFERROR(_xlfn.PERCENTILE.INC(tblUrun[Net Birim Maliyet TL],P90Kuantil),0)
A40: Modül I3: Maliyet NPV | B40: =IFERROR(NPV(IskontoOrani,ToplamDepoTeslimMaliyeti),0)
A41: Modül I7: Nakit Açığı Köprüsü | B41: =IFERROR(MAX(0,ToplamVergi-PesinOdemeTutari),0)
A42: Modül Makine Yorumları
A43: T1 Birim Maliyet Ortalaması | B43: =modulT1BirimMaliyetOrt | C43: =_xlfn.TEXTJOIN(" | ",TRUE(),"T1: Ortalama birim maliyet "&TEXT(modulT1BirimMaliyetOrt,"#,##0")&" ₺",IF(modulT1BirimMaliyetOrt>OrtalamaNetBirimMaliyet,"birim maliyet ortalamanın üzerinde","birim maliyet dağılımı normal"))
...

Sheet KONTROL
A1: KONTROL — İTHALAT DEPO TESLİM (RAFA GELEN) NET BİRİM MALİYET
A3: Veri Kalite Kontrolleri
A5: Ürün tablosunda dolu satır | B5: =IFERROR(COUNTA(tblUrun[Ürün Adı]),0)
A6: Masraf tablosunda dolu satır | B6: =IFERROR(COUNTA(tblMasraf[Masraf Kalemi]),0)
A7: Negatif adet kontrolü | B7: =IF(COUNTIF(tblUrun[Adet],"<0")>0,"FAIL","PASS")
A8: Negatif FOB kontrolü | B8: =IF(COUNTIF(tblUrun[FOB Birim Fiyat (Döviz)],"<0")>0,"FAIL","PASS")
A9: Sıfır kur kontrolü | B9: =IF(COUNTIF(tblUrun[Kur (₺)],"=0")>0,"FAIL","PASS")
A10: Boş kur kontrolü | B10: =IF(COUNTIF(tblUrun[Kur (₺)],"")>0,"FAIL","PASS")
A11: Oran aralık kontrolü | B11: =IF(SUMPRODUCT(--(tblUrun[Gümrük Vergisi Oranı]>1))+SUMPRODUCT(--(tblUrun[Gümrük Vergisi Oranı]<0))>0,"FAIL","PASS")
A12: Negatif masraf kontrolü | B12: =IF(COUNTIF(tblMasraf[Tutar TL],"<0")>0,"FAIL","PASS")
A15: SKORLAMA
A16: PASS Sayısı | B16: =COUNTIF(B5:B12,"PASS")
A17: FAIL Sayısı | B17: =COUNTIF(B5:B12,"FAIL")
A18: WARN Sayısı | B18: =COUNTIF(B5:B12,"WARN")
A19: Veri Kalite Skoru | B19: =IFERROR(IF(DoluGirisHucre=0,0,MAX(0,VeriKaliteTaban-FAIL_Sayisi*VeriKaliteFailCeza-WARN_Sayisi*VeriKaliteUyariCeza)),0)
A20: Veri Kalite Seviyesi | B20: =IF(VeriKaliteSkoru>=VeriKaliteIyiEsik,"İYİ",IF(VeriKaliteSkoru>=VeriKaliteOrtaEsik,"ORTA","DÜŞÜK"))
A21: Dolu Girdi Hücresi | B21: =IFERROR(COUNTA(tblUrun[Ürün Adı])+COUNTA(tblMasraf[Masraf Kalemi]),0)
A22: Toplam Girdi Kapasitesi | B22: =IFERROR(ROWS(tblUrun)+ROWS(tblMasraf),0)
A23: Doluluk Oranı | B23: =IFERROR(DoluGirisHucre/KayitKapasite,0)
A24: Durum | B24: =IF(FAIL_Sayisi=0,"SAĞLIKLI","İNCELE")
A26: Skor ve sağlık durumu formülle üretilir; sahte veri yoktur.

Sheet KARAR
A1: KARAR — İTHALAT DEPO TESLİM (RAFA GELEN) NET BİRİM MALİYET
A3: Karar Motoru
A5: DEPO TESLİM MALİYET ÖZETİ
A6: Toplam Depo Teslim Maliyeti | B6: =ToplamDepoTeslimMaliyeti
A7: Maliyet Faktörü (Ağırlıklı) | B7: =MaliyetFaktoru
A8: Vergi Yükü Oranı | B8: =VergiYukOrani
A9: Mutabakat Farkı | B9: =modulT5MutabakatFark
A11: KARAR | B11: =IF(VeriKaliteSkoru=0,"VERİ YOK",IF(OR(MaliyetFaktoru<1,ToplamFOB<0),"DURDUR",IF(OR(VergiYukOrani>VergiYukEsik,MaliyetFaktoru>MaliyetFaktorEsik),"DURDUR",IF(OR(ABS(modulT5MutabakatFark)>ToplamYurtIciMasraf*MutabakatEsikOran,AnomaliUrunAdedi>0,modulI7NakitAcik>0),"İNCELE","UYGUN"))))
A12: GEREKÇE | B12: =IF(VeriKaliteSkoru=0,"Girdi eksik; lütfen sarı hücreleri doldurun.",IF(MaliyetFaktoru<1,"Maliyet faktörü 1 altında: FOB ve kur girişlerini kontrol edin.",IF(VergiYukOrani>VergiYukEsik,"Vergi yükü oranı %"&TEXT(VergiYukOrani,"0.0%")&" eşiği aşıyor; vergi matrahı ve oranları gözden geçirin.",IF(MaliyetFaktoru>MaliyetFaktorEsik,"Maliyet faktörü "&TEXT(MaliyetFaktoru,"0.00")&" eşiği aşıyor; yüksek kaldıraçlı ithalat.",IF(ABS(modulT5MutabakatFark)>ToplamYurtIciMasraf*MutabakatEsikOran,"Yurt içi masraf dağıtımı ile masraf tablosu farklı; dağıtımı denetleyin.","Depo teslim maliyeti eşikler içinde; maliyet ürünlere dağıtıldı.")))))
A14: AKSİYONLAR
A15: =IF(OR(KararSonuc="VERİ YOK",KararSonuc="DURDUR"),"Ürün ve masraf girişlerini tamamlayın; vergi matrahı ve kur değerlerini gözden geçirin",IF(VergiYukOrani>VergiYukEsik,"Vergi yükü eşik üstünde; tedarikçi/rota değerlendirmesi yapın","Depo teslim maliyet hedefini sürdürün"))
A16: =IF(ABS(modulT5MutabakatFark)>ToplamYurtIciMasraf*MutabakatEsikOran,"Masraf dağıtımı ile tablo farkı "&TEXT(modulT5MutabakatFark,"#,##0")&" ₺; dağıtımı denetleyin","Masraf mutabakatı tutarlı")
A17: =IF(AnomaliUrunAdedi>0,"Uç birim maliyetli ürünlerin FOB ve oran girişlerini inceleyin","Birim maliyet dağılımı tutarlı")
A18: =IF(modulI7NakitAcik>0,"Peşin ödenen ithal vergileri nakit açığı "&TEXT(modulI7NakitAcik,"#,##0")&" ₺; kısa vadeli nakit planı yapın","İthal vergileri nakit yükü karşılanıyor")
A21: Karar, gerekçe ve aksiyonlar makine tarafından üretilir; yalnızca sarı hücreler değiştirilebilir.

Sheet SENARYO_DUYARLILIK
A1: SENARYO DUYARLILIK — İTHALAT DEPO TESLİM (RAFA GELEN) NET BİRİM MALİYET
A3: Senaryo ve Duyarlılık Analizi
A6: Değişken | B6: Kötümser | C6: Baz | D6: İyimser
A7: Depo Teslim Maliyeti (₺) | B7: =IFERROR(ToplamDepoTeslimMaliyeti*(1+SenaryoKotumserKat),0) | C7: =ToplamDepoTeslimMaliyeti | D7: =IFERROR(ToplamDepoTeslimMaliyeti*(1-SenaryoIyimserKat),0)
A8: Vergi Yükü Oranı (Kötümser Senaryo) | B8: =IFERROR(VergiYukOrani*(1+SenaryoKotumserKat),0) | C8: =VergiYukOrani | D8: =IFERROR(VergiYukOrani*(1-SenaryoIyimserKat),0)
A9: Maliyet Faktörü (Kötümser Senaryo) | B9: =IFERROR(MaliyetFaktoru*(1+SenaryoKotumserKat),0) | C9: =MaliyetFaktoru | D9: =IFERROR(MaliyetFaktoru*(1-SenaryoIyimserKat),0)
A10: Nakit Açığı (Kötümser Senaryo) | B10: =IFERROR(MAX(0,ToplamVergi*(1+SenaryoKotumserKat)-PesinOdemeTutari),0) | C10: =IFERROR(MAX(0,ToplamVergi-PesinOdemeTutari),0) | D10: =IFERROR(MAX(0,ToplamVergi*(1-SenaryoIyimserKat)-PesinOdemeTutari),0)
A11: Karar | B11: =IF(VeriKaliteSkoru=0,"VERİ YOK",IF(B8>VergiYukEsik,"DURDUR",IF(OR(B10>0,B9>MaliyetFaktorEsik),"İNCELE","UYGUN"))) | C11: =IF(VeriKaliteSkoru=0,"VERİ YOK",IF(C8>VergiYukEsik,"DURDUR",IF(OR(C10>0,C9>MaliyetFaktorEsik),"İNCELE","UYGUN"))) | D11: =IF(VeriKaliteSkoru=0,"VERİ YOK",IF(D8>VergiYukEsik,"DURDUR",IF(OR(D10>0,D9>MaliyetFaktorEsik),"İNCELE","UYGUN")))
A13: Tornado Duyarlılık
A14: Kur Değişimi | B14: =IFERROR(OrtalamaKur*(1-DuyarliDegisim),0) | C14: =OrtalamaKur | D14: =IFERROR(OrtalamaKur*(1+DuyarliDegisim),0)
A15: Maliyet Etkisi (₺) | B15: =IFERROR(MAX(0,ToplamFOB*(1+DuyarliDegisim)*MaliyetFaktoru-ToplamDepoTeslimMaliyeti),0) | C15: =IFERROR(MAX(0,ToplamFOB*MaliyetFaktoru-ToplamDepoTeslimMaliyeti),0) | D15: =IFERROR(MAX(0,ToplamFOB*(1-DuyarliDegisim)*MaliyetFaktoru-ToplamDepoTeslimMaliyeti),0)
A17: Karar değişimi duyarlılığı | B17: =IF(VeriKaliteSkoru=0,"VERİ YOK",IF(MAX(B10,C10,D10)>0,"NAKİT AÇIĞI VAR","NAKİT DENGELİ"))
A19: Senaryo çarpanları AYARLAR'dan beslenir; kötümser/baz/iyimser aralıkta karar tek ekranda üretilir.

Sheet RAPOR
A1: RAPOR — İTHALAT DEPO TESLİM (RAFA GELEN) NET BİRİM MALİYET
A2: İTHALAT DEPO TESLİM (RAFA GELEN) NET BİRİM MALİYET
A3: Yönetici Raporu
A4: Firma: | B4: =firmaUnvani
A5: Rapor Tarihi: | B5: =raporTarihi
A6: KARAR: | B6: =KararSonuc
A8: ÖZET TABLOSU
A9: Toplam Depo Teslim Maliyeti (₺) | B9: =ToplamDepoTeslimMaliyeti
A10: Maliyet Faktörü (Ağırlıklı) | B10: =MaliyetFaktoru
A11: Vergi Yükü Oranı | B11: =VergiYukOrani
A12: Toplam FOB (₺) | B12: =ToplamFOB
A13: Toplam Vergi (₺) | B13: =ToplamVergi
A14: Yurt İçi Masraflar (₺) | B14: =ToplamYurtIciMasraf
A15: Veri Kalite Skoru | B15: =VeriKaliteSkoru
A16: Toplam Adet | B16: =ToplamAdet
A18: =KararGerekce
A20: VARSAYIMLAR
A21: Gümrük vergisi, ÖTV ve KDV oranları AYARLAR'dan okunur; GTİP ve mevzuat değişikliğinde güncellenmelidir.
A22: Döviz kurları AYARLAR'dan okunur; kullanıcı güncel kuru girmelidir.
A23: Yurt içi masraflar FOB payıyla ürünlere dağıtılır; dağıtım anahtarı değiştirilebilir.
A25: UYARILAR
A26: Vergi yükü eşiği aşılırsa depo teslim maliyeti rekabetçi olmayabilir.
A27: Kur yüksekliği maliyet faktörünü artırır; tedarikçi/rota değerlendirmesi gerekebilir.
A28: Masraf mutabakat farkı varsa dağıtım anahtarı veya masraf girişleri yanlış olabilir.
A30: ÖNERİLEN AKSİYONLAR
A31: Vergi yükü eşik üstünde ise tedarikçi, teslim şekli ve gümrük rejimini değerlendirin.
A32: Nakit açığı varsa ithal vergilerinin ödeme zamanlamasını ve finansmanını planlayın.
A33: Veri kalite skoru düşükse ürün ve masraf girişlerini tamamlayıp raporu yeniden oluşturun.
... A37: Verileriniz cihazınızdan çıkmaz; dosya tamamen çevrimdışı çalışır.

Sheet ORNEK_VERI
A1: ORNEK VERI — İTHALAT DEPO TESLİM (RAFA GELEN) NET BİRİM MALİYET
A3: Örnek Veri (URUNLER)
A5: Ürün Adı | B5: Birim | C5: Adet | D5: FOB Birim Fiyat (Döviz) | E5: Döviz Cinsi | F5: Kur (₺) | G5: Navlun/Sigorta Oranı | H5: Gümrük Vergisi Oranı | I5: ÖTV Oranı | J5: KDV Oranı
A6: Hidrolik Pompa | B6: Adet | C6: 50 | D6: 120 | E6: USD | F6: 38.5 | G6: 0.05 | H6: 0.05 | I6: 0.1 | J6: 0.2
A7: Vana Seti | B7: Adet | C7: 200 | D7: 15 | E7: USD | F7: 38.5 | G7: 0.05 | H7: 0.05 | I7: 0.1 | J7: 0.2
A8: Boru Bağlantı Elemanı | B8: Kg | C8: 3000 | D8: 4 | E8: EUR | F8: 42 | G8: 0.05 | H8: 0.05 | I8: 0.1 | J8: 0.2
A9: Endüstriyel Motor | B9: Adet | C9: 25 | D9: 850 | E9: EUR | F9: 42 | G9: 0.05 | H9: 0.05 | I9: 0.1 | J9: 0.2
A13: Örnek Veri (MASRAFLAR)
A15: Masraf Kalemi | B15: Tutar TL | C15: Açıklama
A16: Liman ve Antrepo | B16: 25000 | C16: Sevkiyat başı
A17: Gümrük Müşavirliği | B17: 8000 | C17: Beyan ve refakat
A18: Yurt İçi Nakliye | B18: 15000 | C18: Liman → depo
A19: Belgelendirme | B19: 3000 | C19: Menşe ve uygunluk
A21: Örnek veri yalnızca gösterim içindir; üretim dosyasına kopyalanabilir.

Sheet ANAHTAR
A1: ANAHTAR — IthalatDepoTeslimNetBirimMaliyet
A3: ham_anahtar | B3: norm_anahtar | C3: duplike_sayisi | D3: not
A4: ORNEK-001 | B4: =UPPER(SUBSTITUTE(A4," ","")) | C4: =COUNTIF($A$4:$A$1000,A4) | D4: normalize + duplike izi
A5: ORNEK-002 | B5: =UPPER(SUBSTITUTE(A5," ","")) | C5: =COUNTIF($A$4:$A$1000,A5) | D5: kisa/uzun numara senaryosu

Sheet ESLESTIRME
A1: ESLESTIRME — IthalatDepoTeslimNetBirimMaliyet
A3: kova | B3: aciklama | C3: tutar | D3: tolerans
A4: ESLESEN | B4: Tam eşleşen kayıtlar | C4: 0 | D4: 0
A5: TOLERANS | B5: Tolerans içi fark | C5: 0 | D5: 0.01
A6: TUTARSIZ | B6: Tutar uyuşmazlığı | C6: 0 | D6: 0
A7: ESLESMEYEN | B7: Eşleşmeyen kayıtlar | C7: 0 | D7: 0

Sheet KOK_NEDEN
A1: KOK_NEDEN — IthalatDepoTeslimNetBirimMaliyet
A3: kova | B3: kok_neden | C3: aksiyon
A4: TANIMSIZ | B4: Sınıflandırılamayan kayıt — elle incele | C4: Manuel inceleme
A5: ESLESMEYEN | B5: Karşı tarafta yok | C5: Veri tamamlama
A6: TUTARSIZ | B6: Tutar farkı | C6: Mutabakat

Sheet DEGISIKLIK_KAYDI
A1: DEGISIKLIK KAYDI — İTHALAT DEPO TESLİM (RAFA GELEN) NET BİRİM MALİYET
A3: Değişiklik Kaydı
A5: Sürüm | B5: Tarih | C5: Açıklama
A6: 1.0.0 | B6: 09.08.2026 | C6: İlk sürüm: FOB→CIF→vergi zinciri, depo teslim net birim maliyet, karar motoru ve 16 analitik modül.

Sheet LISTELER
A1: LISTELER — İTHALAT DEPO TESLİM (RAFA GELEN) NET BİRİM MALİYET
A3: Açılır Liste Kaynakları
A4: Döviz Cinsleri | B4: Birimler
A6: USD | B6: Adet
A7: EUR | B7: Kg
A8: GBP | B8: Ton
B9: Palet
B10: Metre
A13: Listeler AYARLAR sayfasındaki ayarlarla birlikte doğrulama aralıklarını besler.

Sheet AYARLAR
A1: AYARLAR — İTHALAT DEPO TESLİM (RAFA GELEN) NET BİRİM MALİYET
A3: Ayarlar ve Eşikler (Formüle Sabit Sayı Girilmez)
A4: Tüm katsayı ve eşikler bu sayfadadır. Mevzuat değişikliklerinde AYARLAR'dan güncellenir; formüller değişmez. Kaynağı Varsayım işaretli değerler kullanıcı tarafından doğrulanmalıdır.
A5: Grup | B5: Anahtar | C5: Değer | D5: Birim | E5: Açıklama | F5: kaynak | G5: yururluk_tarihi | H5: dogrulama_tarihi
A6: Genel | B6: firmaUnvani | C6: Örnek Şirket A.Ş. | D6: metin | E6: Rapor başlığında görünen firma adı | F6: Kullanıcı | G6: 09.08.2026 | H6: 09.08.2026
A7: Genel | B7: raporTarihi | C7: =TODAY() | D7: tarih | E7: Dosyadaki tek tarih kaynağı; tüm rapor tarihleri buradan okunur. | F7: Kullanıcı | G7: 09.08.2026 | H7: 09.08.2026
A8: Kur | B8: VarsayilanKur | C8: 38.5 | D8: ₺/USD | E8: Döviz cinsi dolu ama kur boş bırakılırsa kullanılan varsayılan kur. | F8: TCMB gösterge kuru; kullanıcı doğrulamalı | G8: 09.08.2026 | H8: 09.08.2026
A9: Kur | B9: OncekiKur | C9: 35 | D9: ₺/USD | E9: Önceki dönem kuru; kur dönem farkı analizinin tabanı. | F9: TCMB gösterge kuru; kullanıcı doğrulamalı | G9: 09.08.2026 | H9: 09.08.2026
A10: Vergi | B10: GumrukOranVarsayilan | C10: 0.05 | D10: oran | E10: Ürün satırında oran boşsa kullanılan varsayılan gümrük vergisi oranı. | F10: İthalat Rejimi Kararı; GTİP bazlı | G10: 09.08.2026 | H10: 09.08.2026
A11: Vergi | B11: OtvOranVarsayilan | C11: 0.1 | D11: oran | E11: Ürün satırında oran boşsa kullanılan varsayılan ÖTV oranı. | F11: 4760 s. ÖTV Kanunu Liste; GTİP bazlı | G11: 09.08.2026 | H11: 09.08.2026
A12: Vergi | B12: KdvOranVarsayilan | C12: 0.2 | D12: oran | E12: Ürün satırında oran boşsa kullanılan varsayılan KDV oranı (genel oran). | F12: 3065 s. KDV Kanunu md.21 | G12: 09.08.2026 | H12: 09.08.2026
A13: Vergi | B13: NavlunSigortaOranVarsayilan | C13: 0.05 | D13: oran | E13: Ürün satırında oran boşsa kullanılan varsayılan navlun/sigorta oranı. | F13: İthalat Rejimi; götürü sigorta uygulaması | G13: 09.08.2026 | H13: 09.08.2026
A14: Genel | B14: BolumPaydaTaban | C14: 1e-07 | D14: katsayı | E14: Bölme işlemlerinde sıfır payda koruması için kullanılan taban değer. | F14: Varsayım | G14: 09.08.2026 | H14: 09.08.2026
A15: Risk | B15: VergiYukEsik | C15: 0.25 | D15: oran | E15: Toplam verginin CIF'e oranı uyarı eşiği. | F15: Varsayım | G15: 09.08.2026 | H15: 09.08.2026
A16: Risk | B16: MaliyetFaktorEsik | C16: 1.8 | D16: katsayı | E16: Depo teslim maliyetin FOB'a oranı yüksek kabul eşiği. | F16: Varsayım | G16: 09.08.2026 | H16: 09.08.2026
A17: Risk | B17: AnomaliZEsik | C17: 2 | D17: oran | E17: Birim maliyet anomali |Z| eşiği. | F17: Varsayım | G17: 09.08.2026 | H17: 09.08.2026
A18: Risk | B18: MutabakatEsikOran | C18: 0.05 | D18: oran | E18: Masraf mutabakat farkı kabul eşiği (masraf tablosuna oranla). | F18: Varsayım | G18: 09.08.2026 | H18: 09.08.2026
A19: Eşik | B19: VeriKaliteIyiEsik | C19: 90 | D19: puan | E19: Kalite skoru iyi eşiği. | F19: Varsayım | G19: 09.08.2026 | H19: 09.08.2026
... A34: Risk | B34: NpvEsikOran | C34: 0.5 | D34: oran | E34: Maliyet NPV değerinin toplam maliyete oranı yüksek kabul eşiği. | F34: Varsayım | G34: 09.08.2026 | H34: 09.08.2026
A36: Sarı değer hücreleri kullanıcı tarafından değiştirilebilir; formül hücreleri kilitlidir.

Sheet KILAVUZ
A1: KILAVUZ — İTHALAT DEPO TESLİM (RAFA GELEN) NET BİRİM MALİYET
A3: Kullanım Kılavuzu
A5: Bu dosya, ithal ürünlerin depo teslim (rafa gelen) net birim maliyetini hesaplayan bir karar destek aracıdır.
A6: 1. AYARLAR: Varsayılan kur, vergi oranları, eşikler ve rapor tarihi bu sayfadadır.
A7: 2. URUNLER: İthal ürünlerin FOB birim fiyatı, adedi, döviz cinsi ve kuru girin; CIF ve vergiler otomatik hesaplanır.
A8: 3. MASRAFLAR: Liman, müşavirlik, iç nakliye gibi yurt içi masrafları TL girin; FOB payıyla ürünlere dağıtılır.
A9: 4. MOTOR: Tüm hesaplar ad tanımlı hücrelerde; denetlenebilir ve değiştirilebilir.
A10: 5. KARAR: UYGUN / İNCELE / DURDUR kararı, gerekçe ve aksiyonlar makine tarafından üretilir.
A11: 6. PANO ve RAPOR: Yönetici özeti ve yazdırılabilir rapor.
A12: 7. SENARYO_DUYARLILIK: Kur ve oran değişiminde maliyet, vergi ve karar değişimi görülür.
A13: Veri girişi yalnızca sarı hücreleredir. Beyaz/yeşil formül hücreleri 1234 şifresiyle korumalıdır.
A14: Güvenlik: Dosyada makro, dış bağlantı ve telemetri yoktur. Verileriniz cihazınızdan çıkmaz.
... A18: Hata görürseniz önce AYARLAR'ı, sonra veri girişlerini kontrol edin; KONTROL sayfası kaliteyi gösterir.
