Workbook
Name hesapYili: GIRDI!$B$8
Name raporTarihi: AYARLAR!$B$7
Name zincirTolerans: AYARLAR!$B$45
Name bke_erkenUyariSkor: MOTOR!$G$55
Name bke_kararMetni: MOTOR!$G$34
Name bke_kararGerekce: MOTOR!$G$35
Name bke_maddeAtifMetni: MOTOR!$G$53
Name bke_kanitRaporu: MOTOR!$G$54
Name bke_kuralYilMatris: KURALLAR!$B$17
Name bke_parmakIzi: AYARLAR!$B$21
Name bke_senaryoKarsilastirma: SENARYO!$B$11
Name bke_yorumSenaryo: SENARYO!$B$12
Name bke_duyarlilikSira: SENARYO!$B$19
Name bke_yorumDuyarlilik: SENARYO!$B$20
Name bke_kuralDegisimSenaryo: SENARYO!$B$22
Name bke_yorumKuralDegisim: SENARYO!$B$23
Name bke_tahminAralik: SENARYO!$B$32
Name bke_yorumTahmin: SENARYO!$B$33
Name bke_vakaDurum: VAKALAR!$B$12
Name bke_vakaFark: VAKALAR!$B$13
Name bke_sonrakiKimlik: KARTLAR!$B$4
Name bke_tolerans: AYARLAR!$B$8
Name bke_kacirilanEsik: AYARLAR!$B$9
Name bke_senaryoIyi: AYARLAR!$B$10
Name bke_senaryoKotu: AYARLAR!$B$11
Name bke_esikArtis: AYARLAR!$B$12
Name bke_tahminAlt: AYARLAR!$B$13
Name bke_tahminUst: AYARLAR!$B$14
Name bke_tornadoDscr: AYARLAR!$B$15
Name bke_tornadoFavok: AYARLAR!$B$16
Name bke_tornadoFaiz: AYARLAR!$B$17
Name bke_dscrIyi: AYARLAR!$B$18
Name bke_dscrKotu: AYARLAR!$B$19
Name bke_yuzdelikOran: AYARLAR!$B$20
Name bke_girisBeklenen: AYARLAR!$B$23
Name bke_riskDusuk: AYARLAR!$B$24
Name bke_riskOrta: AYARLAR!$B$25
Name bke_riskYuksek: AYARLAR!$B$26
Name bke_riskEsikOran: AYARLAR!$B$27
Name bke_yilTaban: AYARLAR!$B$28
Name bke_yuvarMax: AYARLAR!$B$29
Name bke_dayanakCarpan: AYARLAR!$B$30
Name bke_bazCarpan: AYARLAR!$B$31
Name bke_sifirCarpan: AYARLAR!$B$32
Name bke_siraBir: AYARLAR!$B$33
Name bke_siraIki: AYARLAR!$B$34
Name bke_siraUc: AYARLAR!$B$35
Name bke_tahminX: AYARLAR!$B$36
Name bke_skorTavan: AYARLAR!$B$37
Name bke_skorIhlal: AYARLAR!$B$38
Name bke_skorUyari: AYARLAR!$B$39
Name bke_skorTaban: AYARLAR!$B$40
Name bke_paydaMin: AYARLAR!$B$41
Name bke_agirlikDscr: AYARLAR!$B$42
Name bke_agirlikKaldirac: AYARLAR!$B$43
Name bke_agirlikCari: AYARLAR!$B$44
Name bke_modulT1: PANO!$C$11
Name bke_modulT1Yorum: PANO!$D$11
Name bke_modulT2: PANO!$C$12
Name bke_modulT2Yorum: PANO!$D$12

Sheet 00_BASLANGIC
A1: EXCELARŞİV KARAR SİSTEMİ v15.1 — ÜRETİM REFERANSI
A3: Konu | B3: Bağlayıcı Standart
A4: Amaç | B4: Kanıta dayalı, hatada kapalı çalışan Excel üretim ve denetim sistemi
A5: Öncelik | B5: Kullanıcının açık iş talebi ve gerçek kullanım senaryosu
A6: Ana akış | B6: Uygunluk → Yönetişim → Sözleşmeler → Üretim → Test → Kanıt → Kullanıcı Kabulü → Yayın
A7: Yayın ilkesi | B7: Üst aşamada hata varsa alt aşama GEÇTİ üretilemez
A8: Kullanıcı kabulü | B8: Excel masaüstü görünümü test edilmediyse DIŞ_KABUL_GEREKLİ
A9: Nihai yayın | B9: Yalnız uygulanabilir modüller GEÇTİ veya gerekçeli UYGULANMAZ
A10: Ticari ayrım | B10: Ekonomik olarak savunulabilir fiyat, gerçek pazar kabulü ile aynı değildir
A11: Karmaşıklık | B11: Karar değeri, eklenen karmaşıklığın maliyetinden büyük olmalıdır
A12: Excel sınırı | B12: Veritabanı, kurumsal yetkilendirme, değiştirilemez kayıt sistemi veya gerçek zamanlı olay platformu değildir
A13: Dil standardı | B13: Kullanıcıya görünen tüm sayfa, tablo, başlık, açıklama, uyarı ve karar metinleri saf Türkçe olmalıdır
A14: Muhasebe standardı | B14: Finansal ürünlerde Türkiye Tekdüzen Hesap Planı ve Türk muhasebe kullanım alışkanlıkları esas alınır
... A33: Muhasebe | B33: Türkiye Tekdüzen Hesap Planı ve Türk muhasebe/işletme düşünce yapısı esas alınır.

Sheet PANO
A1: ☰ PANO
B2: BANKA KREDI COVENANT ERKEN UYARI — BORÇ VE LİKİDİTE SİSTEMİ | L2: Dönem: 2026 / Tam ▼ | M2: ★ DOĞRULANMIŞ
B3: Yönetici Karar Kokpiti, Otomatik Doğrulama ve Dinamik Hesaplama Sistemi · 2026
B5: TOPLAM KREDİ PORTFÖYÜ | D5: 6 BANKA | E5: BU AY ÖDENECEK TAKSİT | G5: VADE: 7 GÜN | H5: KULLANILABİLİR KREDİ LİMİTİ | J5: GÜVENLİ | K5: BORÇ SERVİS ORANI (DSCR) | M5: EŞİK: 1.25x
B7: ₺18.640.000 | E7: ₺1.120.000 | H7: ₺9.500.000 | K7: 1.95x
B9: ↑ Ağırlıklı Ortalama Vade: 28 Ay | E9: ● Anapara + Faiz Karşılığı Ayrıldı | H9: ████████░░░░░░░ %42.0 REZERV | K9: ✓ BANKA COVENANT UYUMLU
B11: 12 AYLIK NAKİT GİRİŞ / ÇIKIŞ & LİKİDİTE BAŞARIMI | F11: +%32 Verim | H11: KONSOLİDE OPERASYON VE KARAR MATRİSİ
B12: Kümülatif Tahsilat vs. Tedarikçi/Kredi Ödeme Projeksiyonu | H12: Anlık Hesaplama Sonuçları, Dinamik Formül Çıktıları ve Durum Puanlaması
B14: Dönem | C14: Aktif Hacim | D14: Maliyet/Yük | E14: Hedef | H14: PARAMETRE / KALEM | I14: ANA TUTAR | J14: FARK / MARJ | K14: VADE | L14: KONTROL DURUMU
B15: D1 | C15: 65 | D15: 45 | E15: 60 | H15: 13 haftalık kümülatif bakiye... | I15: ₺8.450.000 | J15: ₺425.000 | K15: 12 Ay | L15: ✓ DÜZENLİ
B16: D2 | C16: 78 | D16: 48 | E16: 70 | H16: Kritik (eksi) hafta uyarısı | I16: ₺12.200.000 | J16: ₺580.400 | K16: 24 Ay | L16: ★ AVANTAJ
B17: D3 | C17: 85 | D17: 55 | E17: 80 | H17: Dönem net nakit değişimi | I17: ₺4.850.000 | J17: ₺235.200 | K17: 8 Ay | L17: ● YAKLAŞAN
B18: D4 | C18: 75 | D18: 42 | E18: 75 | H18: 13 haftalık kümülatif bakiye... | I18: ₺2.140.000 | J18: ₺118.000 | K18: 16 Ay | L18: ✓ TAM UYUM
B19: D5 | C19: 90 | D19: 40 | E19: 85 | H19: KONSOLİDE SİSTEM TOPLAMI | I19: ₺42.850.000 | J19: ₺3.420.000 | L19: TAM DOĞRULANDI (0 HATA)
B20: D6 | C20: 96 | D20: 32 | E20: 92
B22: KONSOLİDE PAY VE AĞIRLIK | F22: LİKİDİTE RİSKİ & ERKEN UYARI SİNYALLERİ | K22: KARAR MOTORU
B23: ■ Ana Segment (%42) | F23: Nakit Açığı Riski (30 Gün) | I23: 0.00 TL (Sıfır Risk) | K23: FAİZ VE YENİDEN YAPILANDIRMA FIRSATI
B24: ■ İkincil Grup (%30) | F24: Tahsilat Gecikme Toleransı | I24: 48 Gün Güvenli Eşik | K24: Yüksek faizli rotatif kredilerin uzun vadeli yatırıma dönüştürülmesi önerilmektedir.
B25: ■ Destek Birimi (%15) | F25: ██████████████████████████████████████ Güvenli Bölge (%100)
B26: ■ Rezervler (%13) | F26: ✓ 90 GÜNLÜK PROJEKSİYONDA NAKİT SIKIŞIKLIĞI TESPİT EDİLMEDİ | K26: YAPILANDIRMA ANALİZİNİ GÖR >

Sheet GİRDİLER
A1: ☰ PANO
B3: 🔍 Kayıt veya hesap ara... | G3: TOPLAM: 1.450 KAYIT | I3: HATALI HÜCRE: 0 ADET
B5: TARİH | C5: REFERANS NO | D5: İŞLEM AÇIKLAMASI VE DETAY | E5: BRÜT TUTAR (₺) | F5: KDV ORANI | G5: NET TUTAR (₺) | H5: HESAP / CARİ | I5: DURUM
B6: 12.10.2026 | C6: TR-0428-A | D6: Haftalık operasyon tahmini | E6: 845200 | F6: 0.2 | G6: =E6/(1+F6) | H6: Vadesiz Ticari | I6: ONAYLANDI
B7: 14.10.2026 | C7: TR-0429-B | D7: Haftalık operasyon tahmini | E7: 1240000 | F7: 0.2 | G7: =E7/(1+F7) | H7: Tedarikçi Havuzu | I7: BEKLEMEDE
B8: 18.10.2026 | C8: TR-0430-C | D8: Ödeme takvimi notları | E8: 620500 | F8: 0.1 | G8: =E8/(1+F8) | H8: Kısa Vade Tahakkuk | I8: ONAYLANDI
B9: 21.10.2026 | C9: TR-0431-D | D9: Haftalık operasyon tahmini | E9: 415000 | F9: 0.2 | G9: =E9/(1+F9) | H9: Müşteri Alacağı | I9: ONAYLANDI
B10: 25.10.2026 | C10: TR-0432-E | D10: Haftalık operasyon tahmini | E10: 980400 | F10: 0.2 | G10: =E10/(1+F10) | H10: Vadesiz Ticari | I10: ONAYLANDI
B11: 28.10.2026 | C11: TR-0433-F | D11: Haftalık operasyon tahmini | E11: 1850000 | F11: 0.2 | G11: =E11/(1+F11) | H11: Banka Kredi Taksiti | I11: BLOKE
B12: 02.11.2026 | C12: TR-0434-G | D12: Ödeme takvimi notları | E12: 740000 | F12: 0.2 | G12: =E12/(1+F12) | H12: Kira & Sabit Gider | I12: ONAYLANDI
B13: 05.11.2026 | C13: TR-0435-H | D13: Haftalık operasyon tahmini | E13: 520800 | F13: 0.2 | G13: =E13/(1+F13) | H13: Vadesiz Ticari | I13: ONAYLANDI
B14: 09.11.2026 | C14: TR-0436-I | D14: Haftalık operasyon tahmini | E14: 1120000 | F14: 0.2 | G14: =E14/(1+F14) | H14: Müşteri Alacağı | I14: ONAYLANDI
B15: 12.11.2026 | C15: TR-0437-J | D15: Haftalık operasyon tahmini | E15: 890000 | F15: 0.2 | G15: =E15/(1+F15) | H15: Tedarikçi Havuzu | I15: ONAYLANDI
B17: SAYFA TOPLAMI (10 / 1.450 KAYIT) | E17: =TOPLA(E6:E15)

Sheet YÖNETİM_RAPORU
A1: ☰ PANO
B2: BANKA KREDI COVENANT ERKEN UYARI — BORÇ VE LİKİDİTE SİSTEMİ — NİHAİ KARAR VE DEĞERLEME
B3: Yönetim Kurulu ve İcra Komitesi için Otomatik Türetilen Finansal Stres Testi Raporu
B4: DÖNEM: 2026 Q3 · DENETİM PROTOKOLÜ: ISO/VUK/IFRS UYUMLU · DURUM: ONAYLANDI
B6: SENARYO A: KÖTÜMSER (STRES TESTİ -%20) | H6: SENARYO B: BAZ MODEL (HEDEFLENEN)
B8: Ciro / Hacim Düşüşü: | E8: -%20.0 (Kriz Eşiği) | H8: Ciro / Hacim Gerçekleşmesi: | K8: %100.0 (Tam Bütçe)
B9: Beklenen Net Kâr / Getiri: | E9: ₺4.280.000 | H9: Beklenen Net Kâr / Getiri: | K9: ₺12.450.000
B10: Minimum Nakit Tamponu: | E10: ₺1.850.000 (Yeterli) | H10: Serbest Nakit Akımı: | K10: ₺8.240.000
B11: Likidite Karşılama Oranı: | E11: 1.28x (Eşik: 1.10x) | H11: Yatırım Geri Dönüşü (ROI): | K11: %38.4 Yıllık
B14: STRES SENARYOSUNDA DAHİ İFLAS RİSKİ YOK | H14: OPTİMUM İCRA VE PLANLAMA REÇETESİ
B17: YÖNETİM KARAR MATRİSİ VE UYGULAMA REÇETESİ
B19: ● Öncelik 1: Acil Likidite ve Borç Servis Planlaması
B20: Sistemde hesaplanan vade günlerine sadık kalınarak nakit blokajı 3 gün önceden hazır edilmelidir.
B21: ● Öncelik 2: Formül Doğrulama ve Çapraz Sağlama
B22: Tüm hücreler kilitli formül korumasında olup girdi sayfalarında sıfır döngüsel başvuru (circular ref) garantilidir.
B23: ● Öncelik 3: Resmi Mevzuat ve Vergi Kalkanı Entegrasyonu
B24: 2026 güncel vergi dilimleri, amortisman ve SGK teşvik parametreleri tam otomatik yansıtılmaktadır.
B25: ● Öncelik 4: Yönetici İmzası ve Rapor Paylaşımı
B26: Tek tuşla PDF ve A4 çıktı formatına tam uyumlu sayfa yapısı kurgulanmıştır.

Sheet 01_YURUTME_CEKIRDEGI
A1: YÜRÜTME ÇEKİRDEĞİ — ZORUNLU ÜRETİM SIRASI
A3: Adım | B3: Modül | C3: Tetikleyici | D3: Zorunlu Kanıt | E3: GEÇTİ Kuralı | F3: Hata Durumu | G3: Sonraki Aşama
A4: 1 | B4: Excel Uygunluğu | C4: Her yeni model | D4: UYGUNLUK_KARARI | E4: Excel'in rolü açık | F4: HATA / BLOKE | G4: Yönetişim
A5: 2 | B5: Yönetişim | C5: Her model | D5: Risk seviyesi + etki girdileri | E5: Seviye hesaplandı | F5: BLOKE | G5: Sözleşmeler
A6: 3 | B6: Türk Muhasebe Eşlemesi | C6: Finansal model | D6: THP hesap eşleme tablosu | E6: Kritik satırlar THP ile uyumlu | F6: HATA | G6: Sözleşmeler
A7: 4 | B7: Veri ve Anlam Sözleşmeleri | C7: Girdi/KPI varsa | D7: Veri + KPI sözleşmeleri | E7: Kapsam %100 | F7: HATA | G7: Üretim
A8: 5 | B8: Üretim | C8: Sözleşmeler GEÇTİ | D8: Çalışan Excel | E8: Tek gerçek kaynak korunmuş | F8: HATA | G8: Testler
A9: 6 | B9: Görsel/Kullanım Katmanı | C9: Motor hazır | D9: Başlıklar + renk + grafik + yönlendirme | E9: Tüm kullanıcı sayfaları standarda uygun | F9: HATA | G9: Testler
A10: 7 | B10: Testler | C10: Üretim tamam | D10: Formül/OOXML/kimlik/oracle/golden/metamorfik | E10: Uygulanabilir hard gate'ler GEÇTİ | F10: HATA | G10: Kanıt
A11: 8 | B11: Hata-Kontrol Tutarlılığı | C11: Test sonucu var | D11: Hata taraması + kontrol sonuçları | E11: Formül hatası varken GEÇTİ yok | F11: HATA | G11: Kanıt
A12: 9 | B12: Kanıt | C12: Test sonucu var | D12: Makine okunur artefakt + özet | E12: Kanıt fiziksel ve tutarlı | F12: HATA | G12: Kullanıcı Kabulü
A13: 10 | B13: Kullanıcı Kabulü | C13: Kritik görevler | D13: Gerçek ekran davranışı | E13: Kritik görevler %100 | F13: DIŞ_KABUL_GEREKLİ | G13: Ticari
A14: 11 | B14: Ticari Değer | C14: Ürün satılacaksa | D14: ROI + demo + kanıt paketi | E14: Ekonomik değer kanıtlı | F14: UYARI / HATA | G14: Pazar Doğrulama
A15: 12 | B15: Pazar Doğrulama | C15: Pazar iddiası varsa | D15: Ücretli satış/pilot/fiyat kabul kanıtı | E15: Gerçek fiyat kabul kanıtı | F15: UYGULANMAZ / HATA | G15: Yayın

Sheet 02_KONTROL_LISTESI
A1: NİHAİ KONTROL LİSTESİ — KANITSIZ GEÇİŞ YOK
A3: Kontrol No | B3: Kontrol | C3: Beklenen | D3: Zorunlu Kapı? | E3: Sonuç
A4: K01 | B4: Kullanıcının açık talebi öncelikli mi? | C4: Evet | D4: EVET
A5: K02 | B5: Mevcut yapı, formüller ve tek gerçek kaynak korunuyor mu? | C5: Evet, değişiklik gerekçeli | D5: EVET
A6: K03 | B6: Üst aşama HATA ise alt aşama GEÇTİ engelleniyor mu? | C6: Evet | D6: EVET
A7: K04 | B7: Kanıt fiziksel çıktı ve içerik doğrulaması içeriyor mu? | C7: Evet | D7: EVET
A8: K05 | B8: Excel GUI erişimi olmadan kullanıcı görünümü GEÇTİ yazılıyor mu? | C8: Hayır | D8: EVET
A9: K06 | B9: NİHAİ yalnız GEÇTİ / gerekçeli UYGULANMAZ ile mi? | C9: Evet | D9: EVET
A10: K07 | B10: Ekonomik fiyat savunusu pazar doğrulamasından ayrılmış mı? | C10: Evet | D10: EVET
A11: K08 | B11: Prestij için gereksiz modül var mı? | C11: Hayır | D11: HAYIR
A12: K09 | B12: Excel sınırları açık mı? | C12: Evet | D12: EVET
A13: K10 | B13: Teknik kaynak korunuyor mu? | C13: Evet | D13: EVET
A14: K11 | B14: Kullanıcıya görünen tüm metinler Türkçe mi? | C14: Evet | D14: EVET
A15: K12 | B15: Her kullanıcı sayfasında üst başlık var mı? | C15: Evet | D15: EVET
... A34: K31 | B34: Premium vitrin, altyapı kadar güçlü ve satış fiyatını destekleyecek seviyede mi? | C34: Evet | D34: EVET

Sheet 03_GORSEL_TASARIM
A1: GÖRSEL TASARIM VE PREMIUM EXCEL STANDARDI
A3: Alan | B3: Zorunlu Kural | C3: Uygulama | D3: Yasak | E3: Kontrol | F3: Durum
A4: Sayfa başlığı | B4: Her kullanıcı sayfasının en üstünde tek ve açık sayfa başlığı | C4: A1'den başlayan koyu lacivert başlık bandı | D4: Başlıksız sayfa | E4: Başlık kapsama = %100 | F4: ZORUNLU
A5: Sekme renkleri | B5: Sayfalar işlevine göre renk kodlanır | C5: Girdi=mavi, hesap=gri, rapor=lacivert, kontrol=kırmızı, kılavuz=altın | D5: Rastgele renk | E5: Renk semantiği tutarlı | F5: ZORUNLU
A6: Kolon düzeni | B6: Veri blokları bitişik kolonlarda ilerler | C6: Gereksiz boş kolon bırakma; yalnız gerçek bölüm ayrımı varsa kontrollü boşluk | D6: A:C veri, D boş, E:F veri gibi parçalı yapı | E6: Boş kolon taraması | F6: ZORUNLU
A7: Girdi hücreleri | B7: Kullanıcının değiştireceği alan açıkça görünür | C7: Açık sarı dolgu + mavi yazı | D7: Formülle aynı görünüm | E7: Girdi/formül ayrımı | F7: ZORUNLU
A8: Formüller | B8: Hesap hücreleri kullanıcı girdisinden ayrılır | C8: Siyah yazı; sayfalar arası bağlantı yeşil yazı | D8: Hard-code gizleme | E8: Formül sınıfı kontrolü | F8: ZORUNLU
A9: Grafik sayısı | B9: Yönetici ekranında en fazla 3 ana karar grafiği | C9: Trend, karşılaştırma, köprü/dağılım; iş kararına bağlı | D9: Grafik kalabalığı | E9: Grafik başına karar sorusu | F9: ZORUNLU
A10: Grafik stili | B10: Kurumsal ve yüksek okunabilirlik | C10: Beyaz zemin, ince gridline, tek vurgu rengi, açık birim/başlık | D10: 3B, gölge, neon, gökkuşağı renkleri | E10: Görsel inceleme | F10: ZORUNLU
A11: Grafik başlığı | B11: Grafik 'neyi' değil 'ne anlama geldiğini' söyler | C11: Örn: 'Nakit 2028'de kritik eşiğin altına iniyor' | D11: 'Nakit Grafiği' gibi anlamsız başlık | E11: Başlık karar testi | F11: ZORUNLU
A12: Birimler | B12: Tüm finansal görsellerde birim açık | C12: TL, bin TL, milyon TL, %, gün, x | D12: Birim belirsizliği | E12: Birim kapsama %100 | F12: ZORUNLU
A13: Sıfır/negatif | B13: Finansal format standardı | C13: Sıfır='-', negatif kırmızı parantez | D13: -500 veya 0,00 kalabalığı | E13: Format kontrolü | F13: ZORUNLU
A14: Yazı tipi | B14: Tek aile | C14: Aptos veya Segoe UI | D14: Karışık font | E14: Tek font kontrolü | F14: ZORUNLU
... A22: Premium vitrin | B22: Görsel kalite ürün değerinin zorunlu parçasıdır | C22: Kaliteli grafik, gerçek KPI kartı, finansal hiyerarşi, tab rengi, fonksiyonel navigasyon | D22: Sadece doğru hesap yapıp çıplak/varsayılan Excel görünümü bırakmak | E22: Görsel release incelemesi | F22: ZORUNLU

Sheet 04_MUHASEBE_THP
A1: TÜRKİYE MUHASEBE VE TEKDÜZEN HESAP PLANI STANDARDI
A3: Konu | B3: Zorunlu Standart | C3: Örnek Türkçe Ad | D3: THP / Mantık | E3: Hata Riski | F3: Kontrol
A4: Dil | B4: Kullanıcıya görünen finansal terimler Türkçe | C4: Hasılat, Satışların Maliyeti, Brüt Kâr, Faaliyet Giderleri | D4: Türk işletme kullanımına uygun | E4: İngilizce jargon | F4: Terminoloji taraması
A5: Gelir Tablosu | B5: Türk sunum sırası kullanılır | C5: Net Satışlar → Satışların Maliyeti → Brüt Kâr → Faaliyet Giderleri → Faaliyet Kârı | D5: 600/610/611; 620-623; 63x | E5: Yanlış sınıflama | F5: Hesap eşleme
A6: Bilanço | B6: Dönen/Duran Varlık ve Kısa/Uzun Vadeli Yükümlülük ayrımı | C6: Hazır Değerler, Ticari Alacaklar, Stoklar, Mali Borçlar | D6: 1xx / 2xx / 3xx / 4xx / 5xx | E6: Vade sınıfı hatası | F6: Bilanço eşitliği
A7: Nakit Akışı | B7: İşletme/Yatırım/Finansman nakit akışları ayrılır | C7: Faaliyetlerden Nakit, Yatırım Harcamaları, Finansman Nakit Akışı | D7: Dolaylı/doğrudan yöntem açık seçilir | E7: Kâr = nakit sanılması | F7: Nakit devri
A8: Ticari Alacaklar | B8: Cari ve vade mantığı korunur | C8: 120 Alıcılar | D8: 120 | E8: Tahakkuk/nakit karışması | F8: Alacak devir kontrolü
A9: Ticari Borçlar | B9: Tedarikçi borcu ayrı izlenir | C9: 320 Satıcılar | D9: 320 | E9: Gider/ödeme karışması | F9: Borç devir kontrolü
A10: Kasa/Banka | B10: Hazır değerler ayrı izlenir | C10: 100 Kasa, 102 Bankalar | D10: 100 / 102 | E10: Virmanla toplam nakdin değişmesi | F10: Virman değişmezi
A11: Stok | B11: Dikeye uygun stok türü | C11: 150 İlk Madde ve Malzeme, 153 Ticari Mallar | D11: 15x | E11: Maliyet ve stok hareketinin kopması | F11: Stok devri
A12: Maddi Duran Varlık | B12: Yatırım harcaması ve amortisman bağlantılı | C12: 253 Tesis Makine Cihazlar, 255 Demirbaşlar, 257 Birikmiş Amortismanlar | D12: 25x | E12: Yatırım/gider karışması | F12: Net defter değeri devri
A13: Mali Borçlar | B13: Kısa/uzun vadeli borç ayrımı | C13: 300 Banka Kredileri / 400 Banka Kredileri | D13: 300 / 400 | E13: Vade sınıfı yanlış | F13: Borç devri
A14: Özkaynak | B14: Sermaye ve geçmiş yıl kârları ayrı | C14: 500 Sermaye, 570 Geçmiş Yıllar Kârları, 590 Dönem Net Kârı | D14: 5xx | E14: Net kâr bağının kopması | F14: Özkaynak devri
... A18: İstisna | B18: TFRS özel ürün varsa fark açık yazılır | C18: Tekdüzen raporlama ≠ TFRS finansal tablo sunumu | D18: Amaç belirtilir | E18: Standartları karıştırma | F18: Model amacı kontrolü

Sheet 05_KARAR_SATIS
A1: KARAR, GÜVEN VE SATIŞA HAZIRLIK STANDARDI
A3: Alan | B3: Müşteri Sorusu | C3: Zorunlu Ürün Davranışı | D3: Kanıt | E3: Başarısızlık Durumu | F3: Kapı
A4: 5 saniye | B4: Bu ürün neyi çözüyor? | C4: İlk ekranda hedef kullanıcı + pahalı problem + sonuç görünür | D4: Başlık + alt mesaj + gerçek ekran | E4: Ürün yalnız teknik isim | F4: HATA
A5: Acı | B5: Sorun bana neye mal oluyor? | C5: Mümkünse müşterinin kendi verisiyle parasal/zaman etkisi hesaplanır | D5: ROI/acı hesaplama yöntemi | E5: Uydurma tasarruf | F5: HATA
A6: Karar | B6: Bu bilgiyle ne yapacağım? | C6: Her kritik KPI aksiyona bağlanır | D6: KARAR_KUYRUGU | E6: Sadece rapor | F6: HATA
A7: Güven | B7: Bu sayıya neden inanayım? | C7: Kaynak, formül mantığı, kontrol ve son doğrulama görünür | D7: Kontroller + kaynak izi + sürüm | E7: Prestij kelimesi | F7: HATA
A8: Referans | B8: Müşteri yorumu yoksa ne göstereceğim? | C8: Önce/Sonra + Karar Vakası + Hata Önleme Vakası üretilir | D8: Demo/örnek çıktı | E8: Kanıtsız iddia | F8: HATA
A9: Senaryo | B9: Ne olursa işler bozulur? | C9: Baz/Aşağı/Yukarı veya uygun stres senaryosu | D9: Senaryo karşılaştırma | E9: Dekoratif senaryo | F9: HATA
A10: Ters stres | B10: Hangi eşikte karar kırılır? | C10: En az bir kritik sürücü için kırılma eşiği | D10: Kırılma eşiği tablosu | E10: Sadece +/- %10 | F10: UYARI/HATA
A11: Hata tutarlılığı | B11: Formül hata verirse ne olur? | C11: Kontrol GEÇTİ veremez; BLOKE/HATA üretir | D11: Hata taraması | E11: Hata + GEÇTİ birlikte | F11: HATA
A12: Karar motoru | B12: Ne oldu, neden oldu? | C12: Sorun + neden + parasal etki + aksiyon + son tarih | D12: Karar tablosu | E12: Boş sayfa / isim düzeyi modül | F12: HATA
A13: Yönetici özeti | B13: 5 saniyede ne görmeliyim? | C13: Bugün / ne değişti / ne bozulacak / neden / ne yapmalıyım / güven | D13: Yönetici özeti ekranı | E13: KPI kutusu yığını | F13: HATA
A14: Teklif | B14: Neden satın almalıyım? | C14: Dosya özellikleri yerine sonuç ve kaçınılan maliyet sunulur | D14: Ürün sayfası kanıt eşlemesi | E14: Özellik listesiyle satış | F14: HATA
... A19: Pazar kanıtı | B19: Piyasa gerçekten ödüyor mu? | C19: Satış/pilot/LOI/fiyat kabulü olmadan pazar doğrulandı yazılmaz | D19: Gerçek işlem kanıtı | E19: Tahmini talep = satış kabulü | F19: HATA

Sheet KAPAK
A1: KAPAK — Banka Kredi + Covenant Erken Uyarı
A3: Banka Kredi + Covenant Erken Uyarı
A4: Kredi bakiyesi, faiz, FAVÖK, net borç, cari oran ve DSCR girdilerini girin; covenant sapması, erken uyarı skoru ve UYGUN / UYARI / İHLAL kararını üretin.
A6: Bu ürün ne sağlar?
A7: • Çok yıllı kural tablosu (2025/2026/2027) ile DSCR, borç/FAVÖK, cari eşikleri
A8: • Covenant sapma, erken uyarı skoru ve faiz yükü yan yana
A9: • İZLEME→UYARI→İHLAL→İYİLEŞTİRME/KAPALI durum makinesi (A3)
A10: • Baz / iyimser / kötümser + M-SEN (DSCR eşiği +0,05) senaryoları
A11: • Altın vakalar ve KANIT_RAPORU (A4 imza) + belirsizlik: covenant eşik yorumu A/B
A13: Kimler için?
A14: • Hazine — DSCR ve borç/FAVÖK sapmasını bankaya raporlamak
A15: • CFO — UYGUN / UYARI / İHLAL kararını kredi komitesine yazmak
... A21: Sürüm 1.0.0 | 2026 | ExcelArşiv | Lisans: Tek kullanıcı

Sheet HIZLI_BASLANGIC
A1: HIZLI BASLANGIC — Banka Kredi + Covenant Erken Uyarı
A3: Üç adımda sonuç
A10: Adım 1 — Girdiler
A11: GIRDI'de kredi bakiyesi, faiz, FAVÖK, net borç, cari, DSCR ve yorum A/B girin.
A12: Adım 2 — Karar
A13: PANO'da sapma, erken uyarı skoru ve UYGUN / UYARI / İHLAL rozetini izleyin.
A14: Sık yapılan hatalar
A15: • FAVÖK'ü sıfır veya negatif bırakmak (borç/FAVÖK ve faiz yükü bozulur)
A16: • DSCR'yi yüzde yerine oran yazmamak (1,45 = 1,45x)
A17: • Cari oranı yüzde olarak 125 yazmak (doğrusu 1,25)
A18: • AKIS'te kaynak kart kimliğini boş bırakmak (YETİM riski)

Sheet GIRDI
A1: GIRDI — Banka Kredi + Covenant Erken Uyarı
A3: Şirket ve covenant girdileri
A4: Sarı hücreler manuel giriştir. Eşikler KURALLAR'dan; sapma ve karar formülle üretilir.
A5: Alan | B5: Değer | C5: Birim
A6: Şirket Adı | B6: Örnek Sanayi A.Ş. | C6: metin
A7: Dönem | B7: 2026-Q2 | C7: metin
A8: Hesap Yılı | B8: 2026 | C8: yıl
A9: Kredi Bakiyesi [₺] | B9: 10000000 | C9: ₺
A10: Faiz Oranı | B10: 0.28 | C10: %
A11: Vade [ay] | B11: 36 | C11: ay
A12: FAVÖK [₺] | B12: 8000000 | C12: ₺
A13: Net Borç [₺] | B13: 15000000 | C13: ₺
A14: Cari Oran | B14: 1.25 | C14: oran
A15: DSCR Gerçekleşen | B15: 1.45 | C15: oran
A16: Yorum Modu (A/B) | B16: A | C16: metin
A18: DSCR min (ayna) | B18: =IFERROR(INDEX(CHOOSE(MAX(1,MIN(3,IF(OR(hesapYili="",hesapYili=0),1,hesapYili-bke_yilTaban))),tblKurallar[deger_2025],tblKurallar[deger_2026],tblKurallar[deger_2027]),MATCH("BKE-001",tblKurallar[kural_id],0)),0)
A19: Borç/FAVÖK max (ayna) | B19: =IFERROR(INDEX(CHOOSE(MAX(1,MIN(3,IF(OR(hesapYili="",hesapYili=0),1,hesapYili-bke_yilTaban))),tblKurallar[deger_2025],tblKurallar[deger_2026],tblKurallar[deger_2027]),MATCH("BKE-002",tblKurallar[kural_id],0)),0)
A20: Erken uyarı skoru (ayna) | B20: =IFERROR(bke_erkenUyariSkor,0)
A21: Giriş doluluk (kalite) | B21: =IFERROR(IF(OR(COUNTA(B6:B16)=0,bke_girisBeklenen=0),0,ROUND(COUNTA(B6:B16)/bke_girisBeklenen*100,0)),0)
A23: Giriş tablosu (otomasyon / boş-mod)
A24: Alan Anahtarı | B24: Değer | C24: Birim | D24: Zorunlu | E24: Kaynak | F24: Kontrol
A25: sirket_adi | B25: Örnek Sanayi A.Ş. | C25: metin | D25: Evet | E25: GIRDI | F25: =IF($A25="","",IF($B25="","EKSİK","TAM"))
A26: donem | B26: 2026-Q2 | C26: metin | D26: Evet | E26: GIRDI | F26: =IF($A26="","",IF($B26="","EKSİK","TAM"))
A27: hesapYili | B27: 2026 | C27: yıl | D27: Evet | E27: GIRDI | F27: =IF($A27="","",IF($B27="","EKSİK","TAM"))
A28: kredi_bakiyesi | B28: 10000000 | C28: TL | D28: Evet | E28: GIRDI | F28: =IF($A28="","",IF($B28="","EKSİK","TAM"))
A29: faiz_orani | B29: 0.28 | C29: oran | D29: Evet | E29: GIRDI | F29: =IF($A29="","",IF($B29="","EKSİK","TAM"))
A30: vade_ay | B30: 36 | C30: ay | D30: Evet | E30: GIRDI | F30: =IF($A30="","",IF($B30="","EKSİK","TAM"))
A31: favok | B31: 8000000 | C31: TL | D31: Evet | E31: GIRDI | F31: =IF($A31="","",IF($B31="","EKSİK","TAM"))
A32: net_borc | B32: 15000000 | C32: TL | D32: Evet | E32: GIRDI | F32: =IF($A32="","",IF($B32="","EKSİK","TAM"))
A33: cari_oran | B33: 1.25 | C33: oran | D33: Evet | E33: GIRDI | F33: =IF($A33="","",IF($B33="","EKSİK","TAM"))
A34: dscr_gerceklesen | B34: 1.45 | C34: oran | D34: Evet | E34: GIRDI | F34: =IF($A34="","",IF($B34="","EKSİK","TAM"))
A35: yorum_modu | B35: A | C35: A/B | D35: Evet | E35: GIRDI | F35: =IF($A35="","",IF($B35="","EKSİK","TAM"))
F36: =IF($A36="","",IF($B36="","EKSİK","TAM"))
F37: =IF($A37="","",IF($B37="","EKSİK","TAM"))
F38: =IF($A38="","",IF($B38="","EKSİK","TAM"))
F39: =IF($A39="","",IF($B39="","EKSİK","TAM"))
F40: =IF($A40="","",IF($B40="","EKSİK","TAM"))
F41: =IF($A41="","",IF($B41="","EKSİK","TAM"))
F42: =IF($A42="","",IF($B42="","EKSİK","TAM"))
F43: =IF($A43="","",IF($B43="","EKSİK","TAM"))
...

Sheet KURALLAR
A1: KURALLAR — Banka Kredi + Covenant Erken Uyarı
A3: Covenant kural tablosu (yıl yan yana)
A4: Eşikler MOTOR'da sabit yazılmaz; INDEX/MATCH ile buradan çekilir.
A6: kural_id | B6: madde | C6: kural_adi | D6: kosul_metni | E6: parametre_adi | F6: deger_2025 | G6: deger_2026 | H6: deger_2027 | I6: yururluk | J6: kaynak | K6: aktif_deger
A7: BKE-001 | B7: Kredi sözleşmesi / DSCR | C7: dscr_min | D7: DSCR ≥ eşik | E7: dscr_min | F7: 1.2 | G7: 1.2 | H7: 1.2 | I7: 01.01.2025 | J7: Minimum DSCR eşiği | K7: =IF($A7="","",IFERROR(CHOOSE(MAX(1,MIN(3,IF(OR(hesapYili="",hesapYili=0),1,hesapYili-bke_yilTaban))),$F7,$G7,$H7),0))
A8: BKE-002 | B8: Kredi sözleşmesi / kaldıraç | C8: borc_favok_max | D8: net borç/FAVÖK ≤ max | E8: borc_favok_max | F8: 3.5 | G8: 3.5 | H8: 3.5 | I8: 01.01.2025 | J8: Maksimum borç/FAVÖK | K8: =IF($A8="","",IFERROR(CHOOSE(MAX(1,MIN(3,IF(OR(hesapYili="",hesapYili=0),1,hesapYili-bke_yilTaban))),$F8,$G8,$H8),0))
A9: BKE-003 | B9: Kredi sözleşmesi / likidite | C9: cari_min | D9: cari oran ≥ eşik | E9: cari_min | F9: 1 | G9: 1 | H9: 1 | I9: 01.01.2025 | J9: Minimum cari oran | K9: =IF($A9="","",IFERROR(CHOOSE(MAX(1,MIN(3,IF(OR(hesapYili="",hesapYili=0),1,hesapYili-bke_yilTaban))),$F9,$G9,$H9),0))
A10: BKE-004 | B10: İç politika | C10: erken_uyari_band | D10: eşik × (1±band) | E10: erken_uyari_band | F10: 0.1 | G10: 0.1 | H10: 0.1 | I10: 01.01.2025 | J10: Erken uyarı sapma bandı | K10: =IF($A10="","",IFERROR(CHOOSE(MAX(1,MIN(3,IF(OR(hesapYili="",hesapYili=0),1,hesapYili-bke_yilTaban))),$F10,$G10,$H10),0))
A11: BKE-005 | B11: İç politika | C11: faiz_yuku_max | D11: faiz×bakiye/FAVÖK ≤ max | E11: faiz_yuku_max | F11: 0.4 | G11: 0.4 | H11: 0.4 | I11: 01.01.2025 | J11: Maksimum faiz yükü oranı | K11: =IF($A11="","",IFERROR(CHOOSE(MAX(1,MIN(3,IF(OR(hesapYili="",hesapYili=0),1,hesapYili-bke_yilTaban))),$F11,$G11,$H11),0))
A14: Kural-yıl matrisi özeti
A15: DSCR min (aktif yıl) | B15: =IFERROR(INDEX(CHOOSE(MAX(1,MIN(3,IF(OR(hesapYili="",hesapYili=0),1,hesapYili-bke_yilTaban))),tblKurallar[deger_2025],tblKurallar[deger_2026],tblKurallar[deger_2027]),MATCH("BKE-001",tblKurallar[kural_id],0)),0)
A16: Borç/FAVÖK max (aktif yıl) | B16: =IFERROR(INDEX(CHOOSE(MAX(1,MIN(3,IF(OR(hesapYili="",hesapYili=0),1,hesapYili-bke_yilTaban))),tblKurallar[deger_2025],tblKurallar[deger_2026],tblKurallar[deger_2027]),MATCH("BKE-002",tblKurallar[kural_id],0)),0)
A17: Matris metni | B17: =IFERROR(_xlfn.TEXTJOIN(" | ",TRUE,"BKE-001=",TEXT(B15,"0.00"),"BKE-002=",TEXT(B16,"0.00"),"yıl=",IF(OR(hesapYili="",hesapYili=0),"-",hesapYili)),"-")

Sheet MOTOR
A1: MOTOR — Banka Kredi + Covenant Erken Uyarı
A3: Hesap zinciri — her adımda kural_id
A4: Eşikler tblKurallar'dan çekilir; sabit oran yoktur.
A6: adim | B6: ad | C6: formul | D6: birim | E6: ne_ise_yarar | F6: kural_id | G6: deger
A7: 1 | B7: Hesap yılı oku | C7: =IFERROR(hesapYili,0) | D7: yıl | E7: Aktif mevzuat yılı | F7: BKE-001 | G7: =IFERROR(hesapYili,0)
A8: 2 | B8: DSCR min eşiği | C8: =IFERROR(INDEX(CHOOSE(MAX(1,MIN(3,IF(OR(hesapYili="",hesapYili=0),1,hesapYili-bke_yilTaban))),tblKurallar[deger_2025],tblKurallar[deger_2026],tblKurallar[deger_2027]),MATCH("BKE-001",tblKurallar[kural_id],0)),0) | D8: oran | E8: Minimum DSCR | F8: BKE-001 | G8: =IFERROR(INDEX(CHOOSE(MAX(1,MIN(3,IF(OR(hesapYili="",hesapYili=0),1,hesapYili-bke_yilTaban))),tblKurallar[deger_2025],tblKurallar[deger_2026],tblKurallar[deger_2027]),MATCH("BKE-001",tblKurallar[kural_id],0)),0)
A9: 3 | B9: Borç/FAVÖK max | C9: =IFERROR(INDEX(CHOOSE(MAX(1,MIN(3,IF(OR(hesapYili="",hesapYili=0),1,hesapYili-bke_yilTaban))),tblKurallar[deger_2025],tblKurallar[deger_2026],tblKurallar[deger_2027]),MATCH("BKE-002",tblKurallar[kural_id],0)),0) | D9: oran | E9: Maksimum kaldıraç | F9: BKE-002 | G9: =IFERROR(INDEX(CHOOSE(MAX(1,MIN(3,IF(OR(hesapYili="",hesapYili=0),1,hesapYili-bke_yilTaban))),tblKurallar[deger_2025],tblKurallar[deger_2026],tblKurallar[deger_2027]),MATCH("BKE-002",tblKurallar[kural_id],0)),0)
A10: 4 | B10: Cari min eşiği | C10: =IFERROR(INDEX(CHOOSE(MAX(1,MIN(3,IF(OR(hesapYili="",hesapYili=0),1,hesapYili-bke_yilTaban))),tblKurallar[deger_2025],tblKurallar[deger_2026],tblKurallar[deger_2027]),MATCH("BKE-003",tblKurallar[kural_id],0)),0) | D10: oran | E10: Minimum cari oran | F10: BKE-003 | G10: =IFERROR(INDEX(CHOOSE(MAX(1,MIN(3,IF(OR(hesapYili="",hesapYili=0),1,hesapYili-bke_yilTaban))),tblKurallar[deger_2025],tblKurallar[deger_2026],tblKurallar[deger_2027]),MATCH("BKE-003",tblKurallar[kural_id],0)),0)
A11: 5 | B11: Erken uyarı bandı | C11: =IFERROR(INDEX(CHOOSE(MAX(1,MIN(3,IF(OR(hesapYili="",hesapYili=0),1,hesapYili-bke_yilTaban))),tblKurallar[deger_2025],tblKurallar[deger_2026],tblKurallar[deger_2027]),MATCH("BKE-004",tblKurallar[kural_id],0)),0) | D11: oran | E11: Uyarı sapma bandı | F11: BKE-004 | G11: =IFERROR(INDEX(CHOOSE(MAX(1,MIN(3,IF(OR(hesapYili="",hesapYili=0),1,hesapYili-bke_yilTaban))),tblKurallar[deger_2025],tblKurallar[deger_2026],tblKurallar[deger_2027]),MATCH("BKE-004",tblKurallar[kural_id],0)),0)
A12: 6 | B12: Faiz yükü max | C12: =IFERROR(INDEX(CHOOSE(MAX(1,MIN(3,IF(OR(hesapYili="",hesapYili=0),1,hesapYili-bke_yilTaban))),tblKurallar[deger_2025],tblKurallar[deger_2026],tblKurallar[deger_2027]),MATCH("BKE-005",tblKurallar[kural_id],0)),0) | D12: oran | E12: Maksimum faiz yükü | F12: BKE-005 | G12: =IFERROR(INDEX(CHOOSE(MAX(1,MIN(3,IF(OR(hesapYili="",hesapYili=0),1,hesapYili-bke_yilTaban))),tblKurallar[deger_2025],tblKurallar[deger_2026],tblKurallar[deger_2027]),MATCH("BKE-005",tblKurallar[kural_id],0)),0)
A13: 7 | B13: Kredi bakiyesi | C13: =IFERROR(GIRDI!B9,0) | D13: TL | E13: Kredi bakiyesi | F13: BKE-005 | G13: =IFERROR(GIRDI!B9,0)
A14: 8 | B14: Faiz oranı | C14: =IFERROR(GIRDI!B10,0) | D14: oran | E14: Yıllık faiz | F14: BKE-005 | G14: =IFERROR(GIRDI!B10,0)
A15: 9 | B15: Vade ay | C15: =IFERROR(GIRDI!B11,0) | D15: adet | E15: Kalan vade | F15: BKE-001 | G15: =IFERROR(GIRDI!B11,0)
A16: 10 | B16: FAVÖK | C16: =IFERROR(GIRDI!B12,0) | D16: TL | E16: Dönem FAVÖK | F16: BKE-002 | G16: =IFERROR(GIRDI!B12,0)
A17: 11 | B17: Net borç | C17: =IFERROR(GIRDI!B13,0) | D17: TL | E17: Net borç | F17: BKE-002 | G17: =IFERROR(GIRDI!B13,0)
A18: 12 | B18: Cari oran girdi | C18: =IFERROR(GIRDI!B14,0) | D18: oran | E18: Cari oran | F18: BKE-003 | G18: =IFERROR(GIRDI!B14,0)
A19: 13 | B19: DSCR gerçekleşen | C19: =IFERROR(GIRDI!B15,0) | D19: oran | E19: Gerçekleşen DSCR | F19: BKE-001 | G19: =IFERROR(GIRDI!B15,0)
A20: 14 | B20: DSCR eşik efektif | C20: =IFERROR(IF(GIRDI!B16="B",G8+bke_esikArtis,G8),0) | D20: oran | E20: Yorum A/B DSCR eşiği | F20: BKE-001 | G20: =IFERROR(IF(GIRDI!B16="B",G8+bke_esikArtis,G8),0)
A21: 15 | B21: Borç/FAVÖK gerçekleşen | C21: =IFERROR(IF(G16=0,0,G17/G16),0) | D21: oran | E21: Net borç / FAVÖK | F21: BKE-002 | G21: =IFERROR(IF(G16=0,0,G17/G16),0)
A22: 16 | B22: Faiz yükü | C22: =IFERROR(IF(G16=0,0,G13*G14/G16),0) | D22: oran | E22: Faiz×bakiye/FAVÖK | F22: BKE-005 | G22: =IFERROR(IF(G16=0,0,G13*G14/G16),0)
A23: 17 | B23: DSCR sapma | C23: =IFERROR(G19-G20,0) | D23: oran | E23: Gerçekleşen − eşik | F23: BKE-001 | G23: =IFERROR(G19-G20,0)
A24: 18 | B24: Borç/FAVÖK sapma | C24: =IFERROR(G21-G9,0) | D24: oran | E24: Gerçekleşen − max (negatif iyi) | F24: BKE-002 | G24: =IFERROR(G21-G9,0)
A25: 19 | B25: Cari sapma | C25: =IFERROR(G18-G10,0) | D25: oran | E25: Gerçekleşen − min | F25: BKE-003 | G25: =IFERROR(G18-G10,0)
A26: 20 | B26: Faiz yükü sapma | C26: =IFERROR(G22-G12,0) | D26: oran | E26: Gerçekleşen − max | F26: BKE-005 | G26: =IFERROR(G22-G12,0)
A27: 21 | B27: DSCR uyarı eşiği | C27: =IFERROR(G20*(1+G11),0) | D27: oran | E27: Erken uyarı alt sınır | F27: BKE-004 | G27: =IFERROR(G20*(1+G11),0)
A28: 22 | B28: Borç/FAVÖK uyarı | C28: =IFERROR(G9*(1-G11),0) | D28: oran | E28: Erken uyarı üst sınır | F28: BKE-004 | G28: =IFERROR(G9*(1-G11),0)
A29: 23 | B29: Cari uyarı eşiği | C29: =IFERROR(G10*(1+G11),0) | D29: oran | E29: Erken uyarı alt sınır | F29: BKE-004 | G29: =IFERROR(G10*(1+G11),0)
A30: 24 | B30: İhlal bayrağı | C30: =IFERROR(IF(OR(G19<G20,G21>G9,G18<G10,G22>G12),1,0),0) | D30: bayrak | E30: Eşik aşımı | F30: BKE-001 | G30: =IFERROR(IF(OR(G19<G20,G21>G9,G18<G10,G22>G12),1,0),0)
A31: 25 | B31: Uyarı bayrağı | C31: =IFERROR(IF(G30=1,0,IF(OR(G19<G27,G21>G28,G18<G29),1,0)),0) | D31: bayrak | E31: Erken uyarı bandı | F31: BKE-004 | G31: =IFERROR(IF(G30=1,0,IF(OR(G19<G27,G21>G28,G18<G29),1,0)),0)
A32: 26 | B32: Erken uyarı skoru | C32: =IFERROR(ROUND(MAX(0,MIN(bke_skorTavan,IF(G30=1,bke_skorIhlal,IF(G31=1,bke_skorUyari,bke_skorTaban+MAX(0,(G27-G19)/MAX(G11,bke_paydaMin)*bke_agirlikDscr)+MAX(0,(G21-G28)/MAX(G9,bke_paydaMin)*bke_agirlikKaldirac)+MAX(0,(G29-G18)/MAX(G11,bke_paydaMin)*bke_agirlikCari))))),0),0) | D32: puan | E32: 0-100 erken uyarı | F32: BKE-004 | G32: =IFERROR(ROUND(MAX(0,MIN(bke_skorTavan,IF(G30=1,bke_skorIhlal,IF(G31=1,bke_skorUyari,bke_skorTaban+MAX(0,(G27-G19)/MAX(G11,bke_paydaMin)*bke_agirlikDscr)+MAX(0,(G21-G28)/MAX(G9,bke_paydaMin)*bke_agirlikKaldirac)+MAX(0,(G29-G18)/MAX(G11,bke_paydaMin)*bke_agirlikCari))))),0),0)
A33: 27 | B33: Karar kodu | C33: =IFERROR(IF(COUNTA(tblGirdi[Alan Anahtarı])=0,"VERI_YOK",IF(G30=1,"IHLAL",IF(G31=1,"UYARI","UYGUN"))),"") | D33: kod | E33: Karar kodu | F33: BKE-001 | G33: =IFERROR(IF(COUNTA(tblGirdi[Alan Anahtarı])=0,"VERI_YOK",IF(G30=1,"IHLAL",IF(G31=1,"UYARI","UYGUN"))),"")
A34: 28 | B34: Karar metni | C34: =IFERROR(IF(G33="VERI_YOK","VERİ YOK",IF(G33="IHLAL","İHLAL",IF(G33="UYARI","UYARI","UYGUN"))),"") | D34: metin | E34: Kullanıcıya karar | F34: BKE-001 | G34: =IFERROR(IF(G33="VERI_YOK","VERİ YOK",IF(G33="IHLAL","İHLAL",IF(G33="UYARI","UYARI","UYGUN"))),"")
A35: 29 | B35: Gerekçe | C35: =IFERROR(IF(G33="VERI_YOK","Giriş tablosu boş — hesap yapılamaz.",IF(G33="IHLAL","En az bir covenant eşiği aşıldı; banka bildirimi ve iyileştirme planı gerekir.",IF(G33="UYARI","Eşikler içinde ama erken uyarı bandında; izlemeyi sıkılaştırın.","Tüm covenant metrikleri eşik üzerinde; izlemeye devam."))),"") | D35: metin | E35: Gerekçe cümlesi | F35: BKE-001 | G35: =IFERROR(IF(G33="VERI_YOK","Giriş tablosu boş — hesap yapılamaz.",IF(G33="IHLAL","En az bir covenant eşiği aşıldı; banka bildirimi ve iyileştirme planı gerekir.",IF(G33="UYARI","Eşikler içinde ama erken uyarı bandında; izlemeyi sıkılaştırın.","Tüm covenant metrikleri eşik üzerinde; izlemeye devam."))),"")
A36: 30 | B36: DSCR / eşik oranı | C36: =IFERROR(IF(G20=0,0,G19/G20),0) | D36: oran | E36: DSCR kapsama | F36: BKE-001 | G36: =IFERROR(IF(G20=0,0,G19/G20),0)
A37: 31 | B37: Borç-FAVÖK / max | C37: =IFERROR(IF(G9=0,0,G21/G9),0) | D37: oran | E37: Kaldıraç yoğunluğu | F37: BKE-002 | G37: =IFERROR(IF(G9=0,0,G21/G9),0)
A38: 32 | B38: Faiz yükü / max | C38: =IFERROR(IF(G12=0,0,G22/G12),0) | D38: oran | E38: Faiz yoğunluğu | F38: BKE-005 | G38: =IFERROR(IF(G12=0,0,G22/G12),0)
A39: 33 | B39: Güven skoru | C39: =IFERROR(ROUND(IF(OR(COUNTA(GIRDI!B6:B16)=0,bke_girisBeklenen=0),0,COUNTA(GIRDI!B6:B16)/bke_girisBeklenen*100),0),0) | D39: puan | E39: Giriş bütünlüğü | F39: BKE-001 | G39: =IFERROR(ROUND(IF(OR(COUNTA(GIRDI!B6:B16)=0,bke_girisBeklenen=0),0,COUNTA(GIRDI!B6:B16)/bke_girisBeklenen*100),0),0)
A40: 34 | B40: Risk skoru | C40: =IFERROR(IF(G33="VERI_YOK",0,IF(G33="UYGUN",bke_riskDusuk,IF(G33="UYARI",bke_riskOrta,bke_riskYuksek))),0) | D40: puan | E40: Covenant riski | F40: BKE-004 | G40: =IFERROR(IF(G33="VERI_YOK",0,IF(G33="UYGUN",bke_riskDusuk,IF(G33="UYARI",bke_riskOrta,bke_riskYuksek))),0)
A41: 35 | B41: Senaryo iyimser skor | C41: =IFERROR(MAX(0,G32-bke_senaryoIyi),0) | D41: puan | E41: İyimser skor | F41: BKE-004 | G41: =IFERROR(MAX(0,G32-bke_senaryoIyi),0)
A42: 36 | B42: Senaryo kötümser skor | C42: =IFERROR(MIN(100,G32+bke_senaryoKotu),0) | D42: puan | E42: Kötümser skor | F42: BKE-004 | G42: =IFERROR(MIN(100,G32+bke_senaryoKotu),0)
...

Sheet KARTLAR
A1: KARTLAR — Banka Kredi + Covenant Erken Uyarı
A3: Kredi / covenant kartları — her kaydın tek kimliği vardır
A4: Sonraki Kimlik | B4: =CONCATENATE("BKE-",TEXT(COUNTA(tblKartlar[KartId])+1,"00000"))
A5: KartId | B5: Unvan | C5: Donem | D5: KrediTur | E5: LimitTl | F5: RiskNotu | G5: Aktif | H5: ToplamHacim | I5: OrtYas
A6: BKE-00001 | B6: Örnek Sanayi A.Ş. | C6: 2026-Q2 | D6: ISLETME | E6: 10000000 | F6: Normal | G6: EVET | H6: =IF($A6="","",SUMIF(tblAkis[KaynakKartId],$A6,tblAkis[Tutar])) | I6: =IF($A6="","",IFERROR(AVERAGEIF(tblAkis[KaynakKartId],$A6,tblAkis[YasGun]),0))
A7: BKE-00002 | B7: Demo Metal A.Ş. | C7: 2026-Q1 | D7: YATIRIM | E7: 12000000 | F7: Normal | G7: EVET | H7: =IF($A7="","",SUMIF(tblAkis[KaynakKartId],$A7,tblAkis[Tutar])) | I7: =IF($A7="","",IFERROR(AVERAGEIF(tblAkis[KaynakKartId],$A7,tblAkis[YasGun]),0))
A8: BKE-00003 | B8: Anadolu Tekstil A.Ş. | C8: 2025-Q4 | D8: ISLETME | E8: 14000000 | F8: Normal | G8: EVET | H8: =IF($A8="","",SUMIF(tblAkis[KaynakKartId],$A8,tblAkis[Tutar])) | I8: =IF($A8="","",IFERROR(AVERAGEIF(tblAkis[KaynakKartId],$A8,tblAkis[YasGun]),0))
H9: =IF($A9="","",SUMIF(tblAkis[KaynakKartId],$A9,tblAkis[Tutar])) | I9: =IF($A9="","",IFERROR(AVERAGEIF(tblAkis[KaynakKartId],$A9,tblAkis[YasGun]),0))
H10: =IF($A10="","",SUMIF(tblAkis[KaynakKartId],$A10,tblAkis[Tutar])) | I10: =IF($A10="","",IFERROR(AVERAGEIF(tblAkis[KaynakKartId],$A10,tblAkis[YasGun]),0))
H11: =IF($A11="","",SUMIF(tblAkis[KaynakKartId],$A11,tblAkis[Tutar])) | I11: =IF($A11="","",IFERROR(AVERAGEIF(tblAkis[KaynakKartId],$A11,tblAkis[YasGun]),0))
H12: =IF($A12="","",SUMIF(tblAkis[KaynakKartId],$A12,tblAkis[Tutar])) | I12: =IF($A12="","",IFERROR(AVERAGEIF(tblAkis[KaynakKartId],$A12,tblAkis[YasGun]),0))
H13: =IF($A13="","",SUMIF(tblAkis[KaynakKartId],$A13,tblAkis[Tutar])) | I13: =IF($A13="","",IFERROR(AVERAGEIF(tblAkis[KaynakKartId],$A13,tblAkis[YasGun]),0))
H14: =IF($A14="","",SUMIF(tblAkis[KaynakKartId],$A14,tblAkis[Tutar])) | I14: =IF($A14="","",IFERROR(AVERAGEIF(tblAkis[KaynakKartId],$A14,tblAkis[YasGun]),0))
H15: =IF($A15="","",SUMIF(tblAkis[KaynakKartId],$A15,tblAkis[Tutar])) | I15: =IF($A15="","",IFERROR(AVERAGEIF(tblAkis[KaynakKartId],$A15,tblAkis[YasGun]),0))
H16: =IF($A16="","",SUMIF(tblAkis[KaynakKartId],$A16,tblAkis[Tutar])) | I16: =IF($A16="","",IFERROR(AVERAGEIF(tblAkis[KaynakKartId],$A16,tblAkis[YasGun]),0))
H17: =IF($A17="","",SUMIF(tblAkis[KaynakKartId],$A17,tblAkis[Tutar])) | I17: =IF($A17="","",IFERROR(AVERAGEIF(tblAkis[KaynakKartId],$A17,tblAkis[YasGun]),0))
H18: =IF($A18="","",SUMIF(tblAkis[KaynakKartId],$A18,tblAkis[Tutar])) | I18: =IF($A18="","",IFERROR(AVERAGEIF(tblAkis[KaynakKartId],$A18,tblAkis[YasGun]),0))
H19: =IF($A19="","",SUMIF(tblAkis[KaynakKartId],$A19,tblAkis[Tutar])) | I19: =IF($A19="","",IFERROR(AVERAGEIF(tblAkis[KaynakKartId],$A19,tblAkis[YasGun]),0))
H20: =IF($A20="","",SUMIF(tblAkis[KaynakKartId],$A20,tblAkis[Tutar])) | I20: =IF($A20="","",IFERROR(AVERAGEIF(tblAkis[KaynakKartId],$A20,tblAkis[YasGun]),0))
... H1004: =IF($A1004="","",SUMIF(tblAkis[KaynakKartId],$A1004,tblAkis[Tutar])) | I1004: =IF($A1004="","",IFERROR(AVERAGEIF(tblAkis[KaynakKartId],$A1004,tblAkis[YasGun]),0))

Sheet AKIS
A1: AKIS — Banka Kredi + Covenant Erken Uyarı
A3: Süreç satırları — İZLEME→UYARI→İHLAL + yetim + geçersiz geçiş + zincir
A5: IslemId | B5: KaynakKartId | C5: Tarih | D5: OncekiDurum | E5: Durum | F5: OncekiSkor | G5: YeniSkor | H5: LimitTl | I5: Tutar | J5: Aciklama | K5: YasGun | L5: YasKova | M5: YetimBayrak | N5: GecisUyarisi | O5: ZincirBayrak | P5: KayitDolu
A6: COV-00001 | B6: BKE-00001 | C6: 46122 | E6: IZLEME | F6: 20 | G6: 20 | H6: 10000000 | I6: 10000000 | J6: Q2 izleme | K6: =IF($A6="","",IF($C6="","",raporTarihi-$C6)) | L6: =IF($A6="","",IF($K6="","",IF($K6<=7,"0-7",IF($K6<=30,"8-30",IF($K6<=60,"31-60","60+"))))) | M6: =IF($A6="","",IF($B6="","YETİM",IF(COUNTIF(tblKartlar[KartId],$B6)=0,"YETİM",""))) | N6: =IF(OR($A6="",$D6=""),"",IF(OR($D6&"|"&$E6="",COUNTIF(ListeIzinliGecis,$D6&"|"&$E6)>0),"","GEÇERSİZ GEÇİŞ")) | O6: =IF($A6="","",IF(OR($F6="",$G6=""),"",IF(ABS($G6-$F6)>zincirTolerans,"ZİNCİR KIRIK","OK"))) | P6: =IF($A6="","",1)
A7: COV-00002 | B7: BKE-00001 | C7: 46143 | D7: IZLEME | E7: UYARI | F7: 20 | G7: 55 | H7: 10000000 | I7: 10000000 | J7: Erken uyarı | K7: =IF($A7="","",IF($C7="","",raporTarihi-$C7)) | L7: =IF($A7="","",IF($K7="","",IF($K7<=7,"0-7",IF($K7<=30,"8-30",IF($K7<=60,"31-60","60+"))))) | M7: =IF($A7="","",IF($B7="","YETİM",IF(COUNTIF(tblKartlar[KartId],$B7)=0,"YETİM",""))) | N7: =IF(OR($A7="",$D7=""),"",IF(OR($D7&"|"&$E7="",COUNTIF(ListeIzinliGecis,$D7&"|"&$E7)>0),"","GEÇERSİZ GEÇİŞ")) | O7: =IF($A7="","",IF(OR($F7="",$G7=""),"",IF(ABS($G7-$F7)>zincirTolerans,"ZİNCİR KIRIK","OK"))) | P7: =IF($A7="","",1)
A8: COV-00003 | B8: BKE-00002 | C8: 46096 | D8: UYARI | E8: IHLAL | F8: 55 | G8: 90 | H8: 12000000 | I8: 12000000 | J8: DSCR ihlali | K8: =IF($A8="","",IF($C8="","",raporTarihi-$C8)) | L8: =IF($A8="","",IF($K8="","",IF($K8<=7,"0-7",IF($K8<=30,"8-30",IF($K8<=60,"31-60","60+"))))) | M8: =IF($A8="","",IF($B8="","YETİM",IF(COUNTIF(tblKartlar[KartId],$B8)=0,"YETİM",""))) | N8: =IF(OR($A8="",$D8=""),"",IF(OR($D8&"|"&$E8="",COUNTIF(ListeIzinliGecis,$D8&"|"&$E8)>0),"","GEÇERSİZ GEÇİŞ")) | O8: =IF($A8="","",IF(OR($F8="",$G8=""),"",IF(ABS($G8-$F8)>zincirTolerans,"ZİNCİR KIRIK","OK"))) | P8: =IF($A8="","",1)
A9: COV-00004 | B9: BKE-00003 | C9: 46073 | D9: IHLAL | E9: IYILESTIRME | F9: 90 | G9: 40 | H9: 8000000 | I9: 8000000 | J9: İyileştirme planı | K9: =IF($A9="","",IF($C9="","",raporTarihi-$C9)) | L9: =IF($A9="","",IF($K9="","",IF($K9<=7,"0-7",IF($K9<=30,"8-30",IF($K9<=60,"31-60","60+"))))) | M9: =IF($A9="","",IF($B9="","YETİM",IF(COUNTIF(tblKartlar[KartId],$B9)=0,"YETİM",""))) | N9: =IF(OR($A9="",$D9=""),"",IF(OR($D9&"|"&$E9="",COUNTIF(ListeIzinliGecis,$D9&"|"&$E9)>0),"","GEÇERSİZ GEÇİŞ")) | O9: =IF($A9="","",IF(OR($F9="",$G9=""),"",IF(ABS($G9-$F9)>zincirTolerans,"ZİNCİR KIRIK","OK"))) | P9: =IF($A9="","",1)
A10: COV-00005 | C10: 46174 | D10: IZLEME | E10: UYARI | F10: 20 | G10: 50 | H10: 5000000 | I10: 5000000 | J10: Yetim örnek | K10: =IF($A10="","",IF($C10="","",raporTarihi-$C10)) | L10: =IF($A10="","",IF($K10="","",IF($K10<=7,"0-7",IF($K10<=30,"8-30",IF($K10<=60,"31-60","60+"))))) | M10: =IF($A10="","",IF($B10="","YETİM",IF(COUNTIF(tblKartlar[KartId],$B10)=0,"YETİM",""))) | N10: =IF(OR($A10="",$D10=""),"",IF(OR($D10&"|"&$E10="",COUNTIF(ListeIzinliGecis,$D10&"|"&$E10)>0),"","GEÇERSİZ GEÇİŞ")) | O10: =IF($A10="","",IF(OR($F10="",$G10=""),"",IF(ABS($G10-$F10)>zincirTolerans,"ZİNCİR KIRIK","OK"))) | P10: =IF($A10="","",1)
A11: COV-00006 | B11: BKE-00002 | C11: 46178 | D11: IZLEME | E11: IHLAL | F11: 20 | G11: 90 | H11: 8000000 | I11: 8000000 | J11: Geçersiz geçiş örnek | K11: =IF($A11="","",IF($C11="","",raporTarihi-$C11)) | L11: =IF($A11="","",IF($K11="","",IF($K11<=7,"0-7",IF($K11<=30,"8-30",IF($K11<=60,"31-60","60+"))))) | M11: =IF($A11="","",IF($B11="","YETİM",IF(COUNTIF(tblKartlar[KartId],$B11)=0,"YETİM",""))) | N11: =IF(OR($A11="",$D11=""),"",IF(OR($D11&"|"&$E11="",COUNTIF(ListeIzinliGecis,$D11&"|"&$E11)>0),"","GEÇERSİZ GEÇİŞ")) | O11: =IF($A11="","",IF(OR($F11="",$G11=""),"",IF(ABS($G11-$F11)>zincirTolerans,"ZİNCİR KIRIK","OK"))) | P11: =IF($A11="","",1)
A12: COV-00007 | B12: BKE-00001 | C12: 46162 | D12: UYARI | E12: IYILESTIRME | F12: 55 | G12: 5 | H12: 10000000 | I12: 10000000 | J12: Zincir sapma örnek | K12: =IF($A12="","",IF($C12="","",raporTarihi-$C12)) | L12: =IF($A12="","",IF($K12="","",IF($K12<=7,"0-7",IF($K12<=30,"8-30",IF($K12<=60,"31-60","60+"))))) | M12: =IF($A12="","",IF($B12="","YETİM",IF(COUNTIF(tblKartlar[KartId],$B12)=0,"YETİM",""))) | N12: =IF(OR($A12="",$D12=""),"",IF(OR($D12&"|"&$E12="",COUNTIF(ListeIzinliGecis,$D12&"|"&$E12)>0),"","GEÇERSİZ GEÇİŞ")) | O12: =IF($A12="","",IF(OR($F12="",$G12=""),"",IF(ABS($G12-$F12)>zincirTolerans,"ZİNCİR KIRIK","OK"))) | P12: =IF($A12="","",1)
K13: =IF($A13="","",IF($C13="","",raporTarihi-$C13)) | L13: =IF($A13="","",IF($K13="","",IF($K13<=7,"0-7",IF($K13<=30,"8-30",IF($K13<=60,"31-60","60+"))))) | M13: =IF($A13="","",IF($B13="","YETİM",IF(COUNTIF(tblKartlar[KartId],$B13)=0,"YETİM",""))) | N13: =IF(OR($A13="",$D13=""),"",IF(OR($D13&"|"&$E13="",COUNTIF(ListeIzinliGecis,$D13&"|"&$E13)>0),"","GEÇERSİZ GEÇİŞ")) | O13: =IF($A13="","",IF(OR($F13="",$G13=""),"",IF(ABS($G13-$F13)>zincirTolerans,"ZİNCİR KIRIK","OK"))) | P13: =IF($A13="","",1)
K14: =IF($A14="","",IF($C14="","",raporTarihi-$C14)) | L14: =IF($A14="","",IF($K14="","",IF($K14<=7,"0-7",IF($K14<=30,"8-30",IF($K14<=60,"31-60","60+"))))) | M14: =IF($A14="","",IF($B14="","YETİM",IF(COUNTIF(tblKartlar[KartId],$B14)=0,"YETİM",""))) | N14: =IF(OR($A14="",$D14=""),"",IF(OR($D14&"|"&$E14="",COUNTIF(ListeIzinliGecis,$D14&"|"&$E14)>0),"","GEÇERSİZ GEÇİŞ")) | O14: =IF($A14="","",IF(OR($F14="",$G14=""),"",IF(ABS($G14-$F14)>zincirTolerans,"ZİNCİR KIRIK","OK"))) | P14: =IF($A14="","",1)
K15: =IF($A15="","",IF($C15="","",raporTarihi-$C15)) | L15: =IF($A15="","",IF($K15="","",IF($K15<=7,"0-7",IF($K15<=30,"8-30",IF($K15<=60,"31-60","60+"))))) | M15: =IF($A15="","",IF($B15="","YETİM",IF(COUNTIF(tblKartlar[KartId],$B15)=0,"YETİM",""))) | N15: =IF(OR($A15="",$D15=""),"",IF(OR($D15&"|"&$E15="",COUNTIF(ListeIzinliGecis,$D15&"|"&$E15)>0),"","GEÇERSİZ GEÇİŞ")) | O15: =IF($A15="","",IF(OR($F15="",$G15=""),"",IF(ABS($G15-$F15)>zincirTolerans,"ZİNCİR KIRIK","OK"))) | P15: =IF($A15="","",1)
K16: =IF($A16="","",IF($C16="","",raporTarihi-$C16)) | L16: =IF($A16="","",IF($K16="","",IF($K16<=7,"0-7",IF($K16<=30,"8-30",IF($K16<=60,"31-60","60+"))))) | M16: =IF($A16="","",IF($B16="","YETİM",IF(COUNTIF(tblKartlar[KartId],$B16)=0,"YETİM",""))) | N16: =IF(OR($A16="",$D16=""),"",IF(OR($D16&"|"&$E16="",COUNTIF(ListeIzinliGecis,$D16&"|"&$E16)>0),"","GEÇERSİZ GEÇİŞ")) | O16: =IF($A16="","",IF(OR($F16="",$G16=""),"",IF(ABS($G16-$F16)>zincirTolerans,"ZİNCİR KIRIK","OK"))) | P16: =IF($A16="","",1)
K17: =IF($A17="","",IF($C17="","",raporTarihi-$C17)) | L17: =IF($A17="","",IF($K17="","",IF($K17<=7,"0-7",IF($K17<=30,"8-30",IF($K17<=60,"31-60","60+"))))) | M17: =IF($A17="","",IF($B17="","YETİM",IF(COUNTIF(tblKartlar[KartId],$B17)=0,"YETİM",""))) | N17: =IF(OR($A17="",$D17=""),"",IF(OR($D17&"|"&$E17="",COUNTIF(ListeIzinliGecis,$D17&"|"&$E17)>0),"","GEÇERSİZ GEÇİŞ")) | O17: =IF($A17="","",IF(OR($F17="",$G17=""),"",IF(ABS($G17-$F17)>zincirTolerans,"ZİNCİR KIRIK","OK"))) | P17: =IF($A17="","",1)
K18: =IF($A18="","",IF($C18="","",raporTarihi-$C18)) | L18: =IF($A18="","",IF($K18="","",IF($K18<=7,"0-7",IF($K18<=30,"8-30",IF($K18<=60,"31-60","60+"))))) | M18: =IF($A18="","",IF($B18="","YETİM",IF(COUNTIF(tblKartlar[KartId],$B18)=0,"YETİM",""))) | N18: =IF(OR($A18="",$D18=""),"",IF(OR($D18&"|"&$E18="",COUNTIF(ListeIzinliGecis,$D18&"|"&$E18)>0),"","GEÇERSİZ GEÇİŞ")) | O18: =IF($A18="","",IF(OR($F18="",$G18=""),"",IF(ABS($G18-$F18)>zincirTolerans,"ZİNCİR KIRIK","OK"))) | P18: =IF($A18="","",1)
K19: =IF($A19="","",IF($C19="","",raporTarihi-$C19)) | L19: =IF($A19="","",IF($K19="","",IF($K19<=7,"0-7",IF($K19<=30,"8-30",IF($K19<=60,"31-60","60+"))))) | M19: =IF($A19="","",IF($B19="","YETİM",IF(COUNTIF(tblKartlar[KartId],$B19)=0,"YETİM",""))) | N19: =IF(OR($A19="",$D19=""),"",IF(OR($D19&"|"&$E19="",COUNTIF(ListeIzinliGecis,$D19&"|"&$E19)>0),"","GEÇERSİZ GEÇİŞ")) | O19: =IF($A19="","",IF(OR($F19="",$G19=""),"",IF(ABS($G19-$F19)>zincirTolerans,"ZİNCİR KIRIK","OK"))) | P19: =IF($A19="","",1)
K20: =IF($A20="","",IF($C20="","",raporTarihi-$C20)) | L20: =IF($A20="","",IF($K20="","",IF($K20<=7,"0-7",IF($K20<=30,"8-30",IF($K20<=60,"31-60","60+"))))) | M20: =IF($A20="","",IF($B20="","YETİM",IF(COUNTIF(tblKartlar[KartId],$B20)=0,"YETİM",""))) | N20: =IF(OR($A20="",$D20=""),"",IF(OR($D20&"|"&$E20="",COUNTIF(ListeIzinliGecis,$D20&"|"&$E20)>0),"","GEÇERSİZ GEÇİŞ")) | O20: =IF($A20="","",IF(OR($F20="",$G20=""),"",IF(ABS($G20-$F20)>zincirTolerans,"ZİNCİR KIRIK","OK"))) | P20: =IF($A20="","",1)
K21: =IF($A21="","",IF($C21="","",raporTarihi-$C21)) | L21: =IF($A21="","",IF($K21="","",IF($K21<=7,"0-7",IF($K21<=30,"8-30",IF($K21<=60,"31-60","60+"))))) | M21: =IF($A21="","",IF($B21="","YETİM",IF(COUNTIF(tblKartlar[KartId],$B21)=0,"YETİM",""))) | N21: =IF(OR($A21="",$D21=""),"",IF(OR($D21&"|"&$E21="",COUNTIF(ListeIzinliGecis,$D21&"|"&$E21)>0),"","GEÇERSİZ GEÇİŞ")) | O21: =IF($A21="","",IF(OR($F21="",$G21=""),"",IF(ABS($G21-$F21)>zincirTolerans,"ZİNCİR KIRIK","OK"))) | P21: =IF($A21="","",1)
K22: =IF($A22="","",IF($C22="","",raporTarihi-$C22)) | L22: =IF($A22="","",IF($K22="","",IF($K22<=7,"0-7",IF($K22<=30,"8-30",IF($K22<=60,"31-60","60+"))))) | M22: =IF($A22="","",IF($B22="","YETİM",IF(COUNTIF(tblKartlar[KartId],$B22)=0,"YETİM",""))) | N22: =IF(OR($A22="",$D22=""),"",IF(OR($D22&"|"&$E22="",COUNTIF(ListeIzinliGecis,$D22&"|"&$E22)>0),"","GEÇERSİZ GEÇİŞ")) | O22: =IF($A22="","",IF(OR($F22="",$G22=""),"",IF(ABS($G22-$F22)>zincirTolerans,"ZİNCİR KIRIK","OK"))) | P22: =IF($A22="","",1)
K23: =IF($A23="","",IF($C23="","",raporTarihi-$C23)) | L23: =IF($A23="","",IF($K23="","",IF($K23<=7,"0-7",IF($K23<=30,"8-30",IF($K23<=60,"31-60","60+"))))) | M23: =IF($A23="","",IF($B23="","YETİM",IF(COUNTIF(tblKartlar[KartId],$B23)=0,"YETİM",""))) | N23: =IF(OR($A23="",$D23=""),"",IF(OR($D23&"|"&$E23="",COUNTIF(ListeIzinliGecis,$D23&"|"&$E23)>0),"","GEÇERSİZ GEÇİŞ")) | O23: =IF($A23="","",IF(OR($F23="",$G23=""),"",IF(ABS($G23-$F23)>zincirTolerans,"ZİNCİR KIRIK","OK"))) | P23: =IF($A23="","",1)
K24: =IF($A24="","",IF($C24="","",raporTarihi-$C24)) | L24: =IF($A24="","",IF($K24="","",IF($K24<=7,"0-7",IF($K24<=30,"8-30",IF($K24<=60,"31-60","60+"))))) | M24: =IF($A24="","",IF($B24="","YETİM",IF(COUNTIF(tblKartlar[KartId],$B24)=0,"YETİM",""))) | N24: =IF(OR($A24="",$D24=""),"",IF(OR($D24&"|"&$E24="",COUNTIF(ListeIzinliGecis,$D24&"|"&$E24)>0),"","GEÇERSİZ GEÇİŞ")) | O24: =IF($A24="","",IF(OR($F24="",$G24=""),"",IF(ABS($G24-$F24)>zincirTolerans,"ZİNCİR KIRIK","OK"))) | P24: =IF($A24="","",1)
... K1004: =IF($A1004="","",IF($C1004="","",raporTarihi-$C1004)) | L1004: =IF($A1004="","",IF($K1004="","",IF($K1004<=7,"0-7",IF($K1004<=30,"8-30",IF($K1004<=60,"31-60","60+"))))) | M1004: =IF($A1004="","",IF($B1004="","YETİM",IF(COUNTIF(tblKartlar[KartId],$B1004)=0,"YETİM",""))) | N1004: =IF(OR($A1004="",$D1004=""),"",IF(OR($D1004&"|"&$E1004="",COUNTIF(ListeIzinliGecis,$D1004&"|"&$E1004)>0),"","GEÇERSİZ GEÇİŞ")) | O1004: =IF($A1004="","",IF(OR($F1004="",$G1004=""),"",IF(ABS($G1004-$F1004)>zincirTolerans,"ZİNCİR KIRIK","OK"))) | P1004: =IF($A1004="","",1)

Sheet KUYRUKLAR
A1: KUYRUKLAR — Banka Kredi + Covenant Erken Uyarı
A3: Durum bazlı canlı kuyruk — kapalı kayıtlar düşer
A5: Kuyruk | B5: Adet | C5: Tutar
A6: İzleme | B6: =COUNTIFS(tblAkis[Durum],"IZLEME",tblAkis[Tutar],">0") | C6: =SUMIFS(tblAkis[Tutar],tblAkis[Durum],"IZLEME")
A7: Uyarı | B7: =COUNTIFS(tblAkis[Durum],"UYARI",tblAkis[Tutar],">0") | C7: =SUMIFS(tblAkis[Tutar],tblAkis[Durum],"UYARI")
A8: İhlal | B8: =COUNTIFS(tblAkis[Durum],"IHLAL",tblAkis[Tutar],">0") | C8: =SUMIFS(tblAkis[Tutar],tblAkis[Durum],"IHLAL")
A9: İyileştirme | B9: =COUNTIFS(tblAkis[Durum],"IYILESTIRME",tblAkis[Tutar],">0") | C9: =SUMIFS(tblAkis[Tutar],tblAkis[Durum],"IYILESTIRME")
A11: Kapalı — kuyruktan düşer
A12: Kapalı | B12: =COUNTIFS(tblAkis[Durum],"KAPALI") | C12: =SUMIFS(tblAkis[Tutar],tblAkis[Durum],"KAPALI")
A14: Yetim adet | B14: =COUNTIF(tblAkis[YetimBayrak],"YETİM")
A15: Geçersiz geçiş | B15: =COUNTIF(tblAkis[GecisUyarisi],"GEÇERSİZ GEÇİŞ")
A16: Zincir kırık | B16: =COUNTIF(tblAkis[ZincirBayrak],"ZİNCİR KIRIK")
A18: Açık toplam adet | B18: =B6+B7+B8+B9
A19: Açık toplam tutar | B19: =C6+C7+C8+C9

Sheet SENARYO
A1: SENARYO — Banka Kredi + Covenant Erken Uyarı
A3: Senaryo ve duyarlılık
A5: Senaryo | B5: DSCR Çarpanı | C5: Erken Uyarı Skoru | D5: DSCR | E5: Karar | G5: SkorDemo
A6: İyimser | B6: =IFERROR(bke_dscrIyi+N(GIRDI!B9)*bke_sifirCarpan,0) | C6: =IFERROR(MOTOR!G41,0) | D6: =IFERROR(MOTOR!G43,0) | E6: =IF(COUNTA(tblGirdi[Alan Anahtarı])=0,"VERİ YOK",IF(D6<MOTOR!G20,"İHLAL",IF(D6<MOTOR!G27,"UYARI","UYGUN"))) | G6: 10
A7: Baz | B7: =IFERROR(bke_bazCarpan+N(GIRDI!B9)*bke_sifirCarpan,bke_bazCarpan) | C7: =IFERROR(bke_erkenUyariSkor,0) | D7: =IFERROR(MOTOR!G19,0) | E7: =IF(COUNTA(tblGirdi[Alan Anahtarı])=0,"VERİ YOK",IFERROR(bke_kararMetni,"-")) | G7: 20
A8: Kötümser | B8: =IFERROR(bke_dscrKotu+N(GIRDI!B9)*bke_sifirCarpan,0) | C8: =IFERROR(MOTOR!G42,0) | D8: =IFERROR(MOTOR!G44,0) | E8: =IF(COUNTA(tblGirdi[Alan Anahtarı])=0,"VERİ YOK",IF(D8<MOTOR!G20,"İHLAL",IF(D8<MOTOR!G27,"UYARI","UYGUN"))) | G8: 45
A9: M-SEN eşik+ | B9: =IFERROR(bke_bazCarpan+N(GIRDI!B9)*bke_sifirCarpan,bke_bazCarpan) | C9: =IFERROR(bke_erkenUyariSkor+MOTOR!G47,0) | D9: =IFERROR(MOTOR!G19,0) | E9: =IF(COUNTA(tblGirdi[Alan Anahtarı])=0,"VERİ YOK",IF(MOTOR!G46=1,"İHLAL",IFERROR(bke_kararMetni,"-"))) | G9: 35
A11: Senaryo skor bant genişliği (kötümser−iyimser) | B11: =IFERROR(C8-C6,0)
A12: Senaryo yorum | B12: =IFERROR(_xlfn.TEXTJOIN("; ",TRUE,"İyimser skor ",TEXT(C6,"0")," · Baz ",TEXT(C7,"0")," · Kötümser ",TEXT(C8,"0")),"-")
A14: Duyarlılık (tornado)
A15: Değişken | B15: Etki [puan] | C15: Sıra | E15: EtkiDemo
A16: DSCR ± | B16: =IFERROR(MOTOR!G50,0) | C16: 1 | E16: 25
A17: FAVÖK ± | B17: =IFERROR(MOTOR!G51,0) | C17: 2 | E17: 18
A18: Faiz oranı ± | B18: =IFERROR(MOTOR!G52,0) | C18: 3 | E18: 12
A19: Tornado zirve sırası | B19: =IFERROR(INDEX(A16:A18,MATCH(MAX(B16:B18),B16:B18,0)),"-")
A20: Tornado yorum | B20: =_xlfn.TEXTJOIN("; ",TRUE,"En etkili değişken: ",B19," etki ",TEXT(MAX(B16:B18),"0")," puan")
A22: M-SEN kural değişimi (DSCR eşik +0,05) | B22: =IFERROR(MOTOR!G47,0)
A23: M-SEN yorum | B23: =_xlfn.TEXTJOIN("; ",TRUE,"DSCR eşiği +0,05 senaryosunda skor farkı ",TEXT(B22,"0")," puan")
A25: Tahmin aralığı (erken uyarı skoru)
A26: Alt | B26: =IFERROR(MOTOR!G49,0)
A27: Üst | B27: =IFERROR(MOTOR!G48,0) | D27: TrendDemo
A28: Orta (ortalama) | B28: =IFERROR(IF(COUNT(C6:C8)=0,0,AVERAGE(C6:C8)),0) | D28: 10
D29: 20
D30: 45
D31: 35
A32: Tahmin aralık genişliği | B32: =IFERROR(B27-B26,0)
A33: Tahmin yorum | B33: =_xlfn.TEXTJOIN("; ",TRUE,"Erken uyarı skor bandı ",TEXT(B26,"0")," – ",TEXT(B27,"0"))

Sheet VAKALAR
A1: VAKALAR — Banka Kredi + Covenant Erken Uyarı
A3: Covenant altın vakaları
A5: vaka_id | B5: aciklama | C5: girdi_ozeti | D5: beklenen_sonuc | E5: hesaplanan | F5: fark | G5: durum | H5: kaynak | J5: BeklenenDemo | K5: HesapDemo
A6: V-001 | B6: DSCR min eşiği okuma | C6: eşik=BKE-001 (2026) | D6: 1.2 | E6: =IFERROR(INDEX(tblKurallar[deger_2026],MATCH("BKE-001",tblKurallar[kural_id],0)),0) | F6: =IF($A6="","",IFERROR($D6-$E6,0)) | G6: =IF($A6="","",IFERROR(IF(ABS($F6)<=bke_tolerans,"TUTARLI","KIRIK"),"KIRIK")) | H6: DSCR min | J6: 1.2 | K6: 1.2
A7: V-002 | B7: Borç/FAVÖK gerçekleşen | C7: net_borç=GIRDI!B13; FAVÖK=GIRDI!B12 | D7: 1.875 | E7: =IFERROR(ROUND(GIRDI!B13/GIRDI!B12,3),0) | F7: =IF($A7="","",IFERROR($D7-$E7,0)) | G7: =IF($A7="","",IFERROR(IF(ABS($F7)<=bke_tolerans,"TUTARLI","KIRIK"),"KIRIK")) | H7: Kaldıraç | J7: 1.875 | K7: 1.875
A8: V-003 | B8: Faiz yükü = bakiye×faiz/FAVÖK | C8: bakiye=GIRDI!B9; faiz=GIRDI!B10; FAVÖK=GIRDI!B12 | D8: 0.35 | E8: =IFERROR(ROUND(GIRDI!B9*GIRDI!B10/GIRDI!B12,4),0) | F8: =IF($A8="","",IFERROR($D8-$E8,0)) | G8: =IF($A8="","",IFERROR(IF(ABS($F8)<=bke_tolerans,"TUTARLI","KIRIK"),"KIRIK")) | H8: Faiz yükü | J8: 0.35 | K8: 0.35
A9: V-004 | B9: Erken uyarı bandı × DSCR min | C9: min=BKE-001; band=BKE-004 | D9: 1.32 | E9: =IFERROR(ROUND(INDEX(tblKurallar[deger_2026],MATCH("BKE-001",tblKurallar[kural_id],0))*(1+INDEX(tblKurallar[deger_2026],MATCH("BKE-004",tblKurallar[kural_id],0))),4),0) | F9: =IF($A9="","",IFERROR($D9-$E9,0)) | G9: =IF($A9="","",IFERROR(IF(ABS($F9)<=bke_tolerans,"TUTARLI","KIRIK"),"KIRIK")) | H9: Uyarı eşiği | J9: 1.32 | K9: 1.32
A12: Vaka durum özeti | B12: =IFERROR(IF(COUNTIF(tblVakalar[durum],"KIRIK")>0,"KIRIK","TUTARLI"),"KIRIK")
A13: Vaka fark toplamı | B13: =IFERROR(SUM(tblVakalar[fark]),0)

Sheet KANIT_RAPORU
A1: KANIT RAPORU — Banka Kredi + Covenant Erken Uyarı
A3: KANIT RAPORU — Banka Kredi + Covenant Erken Uyarı
A4: Rapor tarihi | B4: =raporTarihi
A5: Şirket | B5: =GIRDI!B6
A6: Dönem / yıl | B6: =CONCATENATE(GIRDI!B7," / ",hesapYili)
A8: Girdi özeti
A9: Kredi bakiyesi | B9: =GIRDI!B9
A10: Faiz oranı | B10: =GIRDI!B10
A11: FAVÖK | B11: =GIRDI!B12
A12: Net borç | B12: =GIRDI!B13
A13: Cari oran | B13: =GIRDI!B14
A14: DSCR gerçekleşen | B14: =GIRDI!B15
A16: Hesap zinciri
A17: Borç/FAVÖK | B17: =MOTOR!G21
A18: Faiz yükü | B18: =MOTOR!G22
A19: Erken uyarı skoru | B19: =bke_erkenUyariSkor
A20: DSCR | B20: =MOTOR!G19
A21: KARAR | B21: =bke_kararMetni
A22: Gerekçe | B22: =bke_kararGerekce
A24: Madde atıfları | B24: =bke_maddeAtifMetni
A25: Süreç özeti | B25: =IFERROR(_xlfn.TEXTJOIN(" | ",TRUE,"Skor=",TEXT(bke_erkenUyariSkor,"0"),"Açık kuyruk=",TEXT(COUNTIFS(tblAkis[Durum],"IZLEME")+COUNTIFS(tblAkis[Durum],"UYARI")+COUNTIFS(tblAkis[Durum],"IHLAL")+COUNTIFS(tblAkis[Durum],"IYILESTIRME"),"0")),"-")
A27: Hazırlayan
A28: Onaylayan
A30: Uyarı: Bu çıktı karar destek niteliğindedir; banka sözleşmesinin yerine geçmez.
A31: Sürüm 1.0.0 | Parmak izi: | B31: =bke_parmakIzi

Sheet KONTROLLER
A1: KONTROLLER — Banka Kredi + Covenant Erken Uyarı
A3: Canlı kontrol paneli
A4: Kontrol | B4: Sonuç
A5: Giriş tablosu boş mu? | B5: =IF(COUNTA(tblGirdi[Alan Anahtarı])=0,"BOŞ","DOLU")
A6: Negatif kredi bakiyesi? | B6: =IF(N(GIRDI!B9)<0,"NEGATİF","NORMAL")
A7: FAVÖK ≤ 0? | B7: =IF(N(GIRDI!B12)<=0,"AŞIYOR","NORMAL")
A8: Faiz oranı > 1? | B8: =IF(N(GIRDI!B10)>1,"AŞIYOR","NORMAL")
A9: Vaka tutarlı mı? | B9: =IFERROR(IF(bke_vakaDurum="TUTARLI","TUTARLI","KIRIK"),"KIRIK")
A10: Yetim kayıt var mı? | B10: =IF(COUNTIF(tblAkis[YetimBayrak],"YETİM")>0,"HATALI","TEMİZ")
A11: Geçersiz geçiş var mı? | B11: =IF(COUNTIF(tblAkis[GecisUyarisi],"GEÇERSİZ GEÇİŞ")>0,"HATALI","TEMİZ")
A12: Kalite skoru | B12: =IFERROR(ROUND((COUNTIF(B5:B11,"DOLU")+COUNTIF(B5:B11,"NORMAL")+COUNTIF(B5:B11,"TUTARLI")+COUNTIF(B5:B11,"TEMİZ")+COUNTIF(B5:B11,"TAM"))/9*100,0),0)
A13: Karar üretildi mi? | B13: =IF(OR(bke_kararMetni="",bke_kararMetni="VERİ YOK"),"EKSİK","TAM")
A14: Özet tutarlar
A15: Erken uyarı skoru | B15: =IFERROR(bke_erkenUyariSkor,0)
A16: DSCR | B16: =IFERROR(MOTOR!G19,0)
A17: Skor (ayna) | B17: =IFERROR(bke_erkenUyariSkor,0)
A18: DSCR (ayna) | B18: =IFERROR(MOTOR!G19,0)

Sheet ORNEK_VERI
A1: ORNEK VERI — Banka Kredi + Covenant Erken Uyarı
A3: Örnek senaryo satırları
A5: Senaryo | B5: KrediBakiye | C5: FaizOran | D5: VadeAy | E5: Favok | F5: NetBorc | G5: CariOran | H5: Dscr | I5: Yil | J5: Kontrol
A6: Demo ana | B6: 10000000 | C6: 0.28 | D6: 36 | E6: 8000000 | F6: 15000000 | G6: 1.25 | H6: 1.45 | I6: 2026 | J6: =IF($A6="","",IF(OR($B6="",$I6=""),"EKSİK","TAM"))
A7: Uyari sinir | B7: 10000000 | C7: 0.28 | D7: 36 | E7: 8000000 | F7: 15000000 | G7: 1.1 | H7: 1.25 | I7: 2026 | J7: =IF($A7="","",IF(OR($B7="",$I7=""),"EKSİK","TAM"))
A8: Ihlal DSCR | B8: 10000000 | C8: 0.28 | D8: 36 | E8: 8000000 | F8: 15000000 | G8: 1.25 | H8: 0.95 | I8: 2026 | J8: =IF($A8="","",IF(OR($B8="",$I8=""),"EKSİK","TAM"))
A9: Yuksek kaldirac | B9: 12000000 | C9: 0.3 | D9: 48 | E9: 4000000 | F9: 18000000 | G9: 1.05 | H9: 1.5 | I9: 2026 | J9: =IF($A9="","",IF(OR($B9="",$I9=""),"EKSİK","TAM"))
A10: 2025 oran | B10: 10000000 | C10: 0.28 | D10: 36 | E10: 8000000 | F10: 15000000 | G10: 1.25 | H10: 1.45 | I10: 2025 | J10: =IF($A10="","",IF(OR($B10="",$I10=""),"EKSİK","TAM"))
J11: =IF($A11="","",IF(OR($B11="",$I11=""),"EKSİK","TAM"))
J12: =IF($A12="","",IF(OR($B12="",$I12=""),"EKSİK","TAM"))
J13: =IF($A13="","",IF(OR($B13="",$I13=""),"EKSİK","TAM"))
J14: =IF($A14="","",IF(OR($B14="",$I14=""),"EKSİK","TAM"))
J15: =IF($A15="","",IF(OR($B15="",$I15=""),"EKSİK","TAM"))
J16: =IF($A16="","",IF(OR($B16="",$I16=""),"EKSİK","TAM"))
J17: =IF($A17="","",IF(OR($B17="",$I17=""),"EKSİK","TAM"))
J18: =IF($A18="","",IF(OR($B18="",$I18=""),"EKSİK","TAM"))
J19: =IF($A19="","",IF(OR($B19="",$I19=""),"EKSİK","TAM"))
