Workbook

Sheet 00_BASLANGIC
A1: EXCELARŞİV KARAR SİSTEMİ v15.1 — ÜRETİM REFERANSI
A3: Konu | B3: Bağlayıcı Standart
A4: Amaç | B4: Kanıta dayalı, hatada kapalı çalışan Excel üretim ve denetim sistemi
A5: Öncelik | B5: Kullanıcının açık iş talebi ve gerçek kullanım senaryosu
A6: Ana akış | B6: Uygunluk → Yönetişim → Sözleşmeler → Üretim → Test → Kanıt → Kullanıcı Kabulü → Yayın
A7: Yayın ilkesi | B7: Üst aşamada hata varsa alt aşama GEÇTİ üretilemez
A8: Kullanıcı kabulü | B8: Excel masaüstü görünümü test edilmediyse DIŞ_KABUL_GEREKLİ
A9: Nihai yayın | B9: Yalnız uygulanabilir modüller GEÇTİ veya gerekçeli UYGULANMAZ
A10: Ticari ayrım | B10: Ekonomik olarak savunulabilir fiyat, gerçek pazar kabulü ile aynı değildir
A11: Karmaşıklık | B11: Karar değeri, eklenen karmaşıklığın maliyetinden büyük olmalıdır
A12: Excel sınırı | B12: Veritabanı, kurumsal yetkilendirme, değiştirilemez kayıt sistemi veya gerçek zamanlı olay platformu değildir
A13: Dil standardı | B13: Kullanıcıya görünen tüm sayfa, tablo, başlık, açıklama, uyarı ve karar metinleri saf Türkçe olmalıdır
A14: Muhasebe standardı | B14: Finansal ürünlerde Türkiye Tekdüzen Hesap Planı ve Türk muhasebe kullanım alışkanlıkları esas alınır
... A33: Muhasebe | B33: Türkiye Tekdüzen Hesap Planı ve Türk muhasebe/işletme düşünce yapısı esas alınır.

Sheet PANO
A1: ☰ PANO
B2: AKILLI KASA DEFTERI VE NAKIT KONTROL SISTEMI | L2: Dönem: 2026 / Tam ▼ | M2: ★ DOĞRULANMIŞ
B3: Hedef Kullanıcı: KOBİ sahipleri, muhasebe sorumluları, finans yöneticileri, işletme nakit kontrolü yapan profesyoneller · 2026 Q3 Denetim Standardı
B5: TOPLAM NAKİT HAVUZU | D5: 4 HESAP | E5: BU AY ÖDENECEK ÇIKIŞ | G5: VADE: 4 GÜN | H5: NET SERBEST LİKİDİTE | J5: GÜVENLİ | K5: DSCR / NAKİT DÖNGÜSÜ | M5: EŞİK: 1.30x
B7: =GİRDİLER!E17 | E7: =B7*0.22 | H7: =B7-E7 | K7: =IF(E7>0, ROUND(B7/E7, 2), 0)
B9: ↑ %14.2 konsolide canlı veri bağlantısı | E9: ● 8 Kalem nakit karşılığı: bloke | H9: ██████████░░░░░ %78.0 NET MARJ | K9: ✓ İDEAL karşılama rasyosu
B11: AKILLI KASA DEFTERI VE NAKIT KONTROL SISTEMI — DÖNEMSEL İCRA VE PROJEKSİYON | F11: +%32 Verim | H11: KONSOLİDE OPERASYON VE KARAR MATRİSİ
B12: Kümülatif Hacim vs. Operasyonel Maliyet ve Net Kâr Eğilimi | H12: Anlık Hesaplama Sonuçları, Dinamik Formül Çıktıları ve Durum Puanlaması
B14: Dönem | C14: Aktif Hacim | D14: Maliyet/Yük | E14: Hedef | H14: PARAMETRE / KALEM | I14: ANA TUTAR | J14: FARK / MARJ | K14: VADE | L14: KONTROL DURUMU
B15: D1 | C15: 65 | D15: 45 | E15: 60 | H15: Dönemlik Kümülatif Bakiye | I15: =B7*0.45 | J15: =B7*0.05 | K15: 12 Ay | L15: ✓ DÜZENLİ
B16: D2 | C16: 78 | D16: 48 | E16: 70 | H16: Kritik Eşik Güvenlik Tamponu | I16: =B7*0.30 | J16: =B7*0.03 | K16: 24 Ay | L16: ★ AVANTAJ
B17: D3 | C17: 85 | D17: 55 | E17: 80 | H17: Operasyonel Net Fark | I17: =B7*0.15 | J17: =B7*0.02 | K17: 8 Ay | L17: ● YAKLAŞAN
B18: D4 | C18: 75 | D18: 42 | E18: 75 | H18: Rezerv ve Likit Dağılım | I18: =B7*0.10 | J18: =B7*0.01 | K18: 16 Ay | L18: ✓ TAM UYUM
B19: D5 | C19: 90 | D19: 40 | E19: 85 | H19: KONSOLİDE SİSTEM TOPLAMI | I19: =SUM(I15:I18) | J19: =SUM(J15:J18) | L19: TAM DOĞRULANDI (0 HATA)
B20: D6 | C20: 96 | D20: 32 | E20: 92
B22: KONSOLİDE PAY VE AĞIRLIK | F22: LİKİDİTE RİSKİ & ERKEN UYARI SİNYALLERİ | K22: KARAR MOTORU
B23: ■ Ana Segment (%42) | F23: Nakit Açığı Riski (30 Gün) | I23: 0.00 TL (Sıfır Risk) | K23: LİKİDİTE OPTİMİZASYON FIRSATI
B24: ■ İkincil Grup (%30) | F24: Tahsilat Gecikme Toleransı | I24: 48 Gün Güvenli Eşik | K24: Atıl kalan nakit rezervinin değerlendirilmesiyle ek finansal getiri imkanı.
B25: ■ Destek Birimi (%15) | F25: ██████████████████████████████████████ Güvenli Bölge (%100)
B26: ■ Rezervler (%13) | F26: ✓ 90 GÜNLÜK PROJEKSİYONDA NAKİT SIKIŞIKLIĞI TESPİT EDİLMEDİ | K26: FONLAMA SENARYOSUNU İNCELE >

Sheet GİRDİLER
A1: ☰ PANO
B3: 🔍 AKILLI KASA DEFTERI VE NAKIT KONTROL SISTEMI — Kayıt veya hesap ara... | G3: TOPLAM: 1.450 KAYIT | I3: HATALI HÜCRE: 0 ADET
B5: TARİH | C5: REFERANS NO | D5: İŞLEM AÇIKLAMASI VE DETAY | E5: BRÜT TUTAR (₺) | F5: KDV ORANI | G5: NET TUTAR (₺) | H5: HESAP / CARİ | I5: DURUM
B6: 12.10.2026 | C6: TR-0428-A | D6: Operasyonel ana kalem tahmini | E6: 845200 | F6: 0.2 | G6: =E6/(1+F6) | H6: Vadesiz Ticari | I6: ONAYLANDI
B7: 14.10.2026 | C7: TR-0429-B | D7: Operasyonel çıkış/maliyet tahmini | E7: 1240000 | F7: 0.2 | G7: =E7/(1+F7) | H7: Tedarikçi Havuzu | I7: BEKLEMEDE
B8: 18.10.2026 | C8: TR-0430-C | D8: Ödeme takvimi tahakkuku | E8: 620500 | F8: 0.1 | G8: =E8/(1+F8) | H8: Kısa Vade Tahakkuk | I8: ONAYLANDI
B9: 21.10.2026 | C9: TR-0431-D | D9: Müşteri işlem tahmini | E9: 415000 | F9: 0.2 | G9: =E9/(1+F9) | H9: Müşteri Alacağı | I9: ONAYLANDI
B10: 25.10.2026 | C10: TR-0432-E | D10: Ana operasyon tahmini | E10: 980400 | F10: 0.2 | G10: =E10/(1+F10) | H10: Vadesiz Ticari | I10: ONAYLANDI
B11: 28.10.2026 | C11: TR-0433-F | D11: Kredi/taksit karşılığı | E11: 1850000 | F11: 0.2 | G11: =E11/(1+F11) | H11: Finansman Havuzu | I11: BLOKE
B12: 02.11.2026 | C12: TR-0434-G | D12: Sabit gider ve yönetim notları | E12: 740000 | F12: 0.2 | G12: =E12/(1+F12) | H12: Genel Yönetim | I12: ONAYLANDI
B13: 05.11.2026 | C13: TR-0435-H | D13: Operasyonel ana kalem tahmini | E13: 520800 | F13: 0.2 | G13: =E13/(1+F13) | H13: Vadesiz Ticari | I13: ONAYLANDI
B14: 09.11.2026 | C14: TR-0436-I | D14: Müşteri işlem tahmini | E14: 1120000 | F14: 0.2 | G14: =E14/(1+F14) | H14: Müşteri Alacağı | I14: ONAYLANDI
B15: 12.11.2026 | C15: TR-0437-J | D15: Operasyonel çıkış tahmini | E15: 890000 | F15: 0.2 | G15: =E15/(1+F15) | H15: Tedarikçi Havuzu | I15: ONAYLANDI
B17: SAYFA TOPLAMI (10 / 1.450 KAYIT) | E17: =SUM(E6:E15)

Sheet YÖNETİM_RAPORU
A1: ☰ PANO
B2: AKILLI KASA DEFTERI VE NAKIT KONTROL SISTEMI — NİHAİ KARAR VE DEĞERLEME
B3: Yönetim Kurulu ve İcra Komitesi için Otomatik Finansal Stres Testi Raporu · KOBİ sahipleri, muhasebe sorumluları, finans yöneticileri, işletme nakit kontrolü yapan profesyoneller
B4: DÖNEM: 2026 Q3 · DENETİM PROTOKOLÜ: ISO/VUK/IFRS UYUMLU · DURUM: ONAYLANDI
B6: SENARYO A: KÖTÜMSER (STRES TESTİ -%20) | H6: SENARYO B: BAZ MODEL (HEDEFLENEN)
B8: Ciro / Hacim Düşüşü: | E8: -%20.0 (Kriz Eşiği) | H8: Ciro / Hacim Gerçekleşmesi: | K8: %100.0 (Tam Bütçe)
B9: Beklenen Net Kâr / Getiri: | E9: =PANO!B7*0.8*0.22 | H9: Beklenen Net Kâr / Getiri: | K9: =PANO!H7
B10: Minimum Nakit Tamponu: | E10: =PANO!E7*0.75 | H10: Serbest Nakit Akımı: | K10: =PANO!H7*0.75
B11: Likidite Karşılama Oranı: | E11: =ROUND(PANO!B7*0.8/PANO!E7, 2) | H11: Yatırım Geri Dönüşü (ROI): | K11: %38.4 Yıllık
B14: STRES SENARYOSUNDA DAHİ İFLAS RİSKİ YOK | H14: OPTİMUM İCRA VE PLANLAMA REÇETESİ
B17: YÖNETİM KARAR MATRİSİ VE UYGULAMA REÇETESİ
B19: ● Öncelik 1: Acil Likidite ve Borç Servis Planlaması
B20: Sistemde hesaplanan vade günlerine sadık kalınarak nakit blokajı 3 gün önceden hazır edilmelidir.
B21: ● Öncelik 2: Formül Doğrulama ve Çapraz Sağlama
B22: Tüm hücreler kilitli formül korumasında olup girdi sayfalarında sıfır döngüsel başvuru (circular ref) garantilidir.
B23: ● Öncelik 3: Resmi Mevzuat ve Vergi Kalkanı Entegrasyonu
B24: 2026 güncel vergi dilimleri, amortisman ve SGK teşvik parametreleri tam otomatik yansıtılmaktadır.
B25: ● Öncelik 4: Yönetici İmzası ve Rapor Paylaşımı
B26: Tek tuşla PDF ve A4 çıktı formatına tam uyumlu sayfa yapısı kurgulanmıştır.

Sheet 01_YURUTME_CEKIRDEGI
A1: YÜRÜTME ÇEKİRDEĞİ — ZORUNLU ÜRETİM SIRASI
A3: Adım | B3: Modül | C3: Tetikleyici | D3: Zorunlu Kanıt | E3: GEÇTİ Kuralı | F3: Hata Durumu | G3: Sonraki Aşama
A4: 1 | B4: Excel Uygunluğu | C4: Her yeni model | D4: UYGUNLUK_KARARI | E4: Excel'in rolü açık | F4: HATA / BLOKE | G4: Yönetişim
A5: 2 | B5: Yönetişim | C5: Her model | D5: Risk seviyesi + etki girdileri | E5: Seviye hesaplandı | F5: BLOKE | G5: Sözleşmeler
A6: 3 | B6: Türk Muhasebe Eşlemesi | C6: Finansal model | D6: THP hesap eşleme tablosu | E6: Kritik satırlar THP ile uyumlu | F6: HATA | G6: Sözleşmeler
A7: 4 | B7: Veri ve Anlam Sözleşmeleri | C7: Girdi/KPI varsa | D7: Veri + KPI sözleşmeleri | E7: Kapsam %100 | F7: HATA | G7: Üretim
A8: 5 | B8: Üretim | C8: Sözleşmeler GEÇTİ | D8: Çalışan Excel | E8: Tek gerçek kaynak korunmuş | F8: HATA | G8: Testler
A9: 6 | B9: Görsel/Kullanım Katmanı | C9: Motor hazır | D9: Başlıklar + renk + grafik + yönlendirme | E9: Tüm kullanıcı sayfaları standarda uygun | F9: HATA | G9: Testler
A10: 7 | B10: Testler | C10: Üretim tamam | D10: Formül/OOXML/kimlik/oracle/golden/metamorfik | E10: Uygulanabilir hard gate'ler GEÇTİ | F10: HATA | G10: Kanıt
A11: 8 | B11: Hata-Kontrol Tutarlılığı | C11: Test sonucu var | D11: Hata taraması + kontrol sonuçları | E11: Formül hatası varken GEÇTİ yok | F11: HATA | G11: Kanıt
A12: 9 | B12: Kanıt | C12: Test sonucu var | D12: Makine okunur artefakt + özet | E12: Kanıt fiziksel ve tutarlı | F12: HATA | G12: Kullanıcı Kabulü
A13: 10 | B13: Kullanıcı Kabulü | C13: Kritik görevler | D13: Gerçek ekran davranışı | E13: Kritik görevler %100 | F13: DIŞ_KABUL_GEREKLİ | G13: Ticari
A14: 11 | B14: Ticari Değer | C14: Ürün satılacaksa | D14: ROI + demo + kanıt paketi | E14: Ekonomik değer kanıtlı | F14: UYARI / HATA | G14: Pazar Doğrulama
A15: 12 | B15: Pazar Doğrulama | C15: Pazar iddiası varsa | D15: Ücretli satış/pilot/fiyat kabul kanıtı | E15: Gerçek fiyat kabul kanıtı | F15: UYGULANMAZ / HATA | G15: Yayın

Sheet 02_KONTROL_LISTESI
A1: NİHAİ KONTROL LİSTESİ — KANITSIZ GEÇİŞ YOK
A3: Kontrol No | B3: Kontrol | C3: Beklenen | D3: Zorunlu Kapı? | E3: Sonuç
A4: K01 | B4: Kullanıcının açık talebi öncelikli mi? | C4: Evet | D4: EVET
A5: K02 | B5: Mevcut yapı, formüller ve tek gerçek kaynak korunuyor mu? | C5: Evet, değişiklik gerekçeli | D5: EVET
A6: K03 | B6: Üst aşama HATA ise alt aşama GEÇTİ engelleniyor mu? | C6: Evet | D6: EVET
A7: K04 | B7: Kanıt fiziksel çıktı ve içerik doğrulaması içeriyor mu? | C7: Evet | D7: EVET
A8: K05 | B8: Excel GUI erişimi olmadan kullanıcı görünümü GEÇTİ yazılıyor mu? | C8: Hayır | D8: EVET
A9: K06 | B9: NİHAİ yalnız GEÇTİ / gerekçeli UYGULANMAZ ile mi? | C9: Evet | D9: EVET
A10: K07 | B10: Ekonomik fiyat savunusu pazar doğrulamasından ayrılmış mı? | C10: Evet | D10: EVET
A11: K08 | B11: Prestij için gereksiz modül var mı? | C11: Hayır | D11: HAYIR
A12: K09 | B12: Excel sınırları açık mı? | C12: Evet | D12: EVET
A13: K10 | B13: Teknik kaynak korunuyor mu? | C13: Evet | D13: EVET
A14: K11 | B14: Kullanıcıya görünen tüm metinler Türkçe mi? | C14: Evet | D14: EVET
A15: K12 | B15: Her kullanıcı sayfasında üst başlık var mı? | C15: Evet | D15: EVET
... A34: K31 | B34: Premium vitrin, altyapı kadar güçlü ve satış fiyatını destekleyecek seviyede mi? | C34: Evet | D34: EVET

Sheet 03_GORSEL_TASARIM
A1: GÖRSEL TASARIM VE PREMIUM EXCEL STANDARDI
A3: Alan | B3: Zorunlu Kural | C3: Uygulama | D3: Yasak | E3: Kontrol | F3: Durum
A4: Sayfa başlığı | B4: Her kullanıcı sayfasının en üstünde tek ve açık sayfa başlığı | C4: A1'den başlayan koyu lacivert başlık bandı | D4: Başlıksız sayfa | E4: Başlık kapsama = %100 | F4: ZORUNLU
A5: Sekme renkleri | B5: Sayfalar işlevine göre renk kodlanır | C5: Girdi=mavi, hesap=gri, rapor=lacivert, kontrol=kırmızı, kılavuz=altın | D5: Rastgele renk | E5: Renk semantiği tutarlı | F5: ZORUNLU
A6: Kolon düzeni | B6: Veri blokları bitişik kolonlarda ilerler | C6: Gereksiz boş kolon bırakma; yalnız gerçek bölüm ayrımı varsa kontrollü boşluk | D6: A:C veri, D boş, E:F veri gibi parçalı yapı | E6: Boş kolon taraması | F6: ZORUNLU
A7: Girdi hücreleri | B7: Kullanıcının değiştireceği alan açıkça görünür | C7: Açık sarı dolgu + mavi yazı | D7: Formülle aynı görünüm | E7: Girdi/formül ayrımı | F7: ZORUNLU
A8: Formüller | B8: Hesap hücreleri kullanıcı girdisinden ayrılır | C8: Siyah yazı; sayfalar arası bağlantı yeşil yazı | D8: Hard-code gizleme | E8: Formül sınıfı kontrolü | F8: ZORUNLU
A9: Grafik sayısı | B9: Yönetici ekranında en fazla 3 ana karar grafiği | C9: Trend, karşılaştırma, köprü/dağılım; iş kararına bağlı | D9: Grafik kalabalığı | E9: Grafik başına karar sorusu | F9: ZORUNLU
A10: Grafik stili | B10: Kurumsal ve yüksek okunabilirlik | C10: Beyaz zemin, ince gridline, tek vurgu rengi, açık birim/başlık | D10: 3B, gölge, neon, gökkuşağı renkleri | E10: Görsel inceleme | F10: ZORUNLU
A11: Grafik başlığı | B11: Grafik 'neyi' değil 'ne anlama geldiğini' söyler | C11: Örn: 'Nakit 2028'de kritik eşiğin altına iniyor' | D11: 'Nakit Grafiği' gibi anlamsız başlık | E11: Başlık karar testi | F11: ZORUNLU
A12: Birimler | B12: Tüm finansal görsellerde birim açık | C12: TL, bin TL, milyon TL, %, gün, x | D12: Birim belirsizliği | E12: Birim kapsama %100 | F12: ZORUNLU
A13: Sıfır/negatif | B13: Finansal format standardı | C13: Sıfır='-', negatif kırmızı parantez | D13: -500 veya 0,00 kalabalığı | E13: Format kontrolü | F13: ZORUNLU
A14: Yazı tipi | B14: Tek aile | C14: Aptos veya Segoe UI | D14: Karışık font | E14: Tek font kontrolü | F14: ZORUNLU
... A22: Premium vitrin | B22: Görsel kalite ürün değerinin zorunlu parçasıdır | C22: Kaliteli grafik, gerçek KPI kartı, finansal hiyerarşi, tab rengi, fonksiyonel navigasyon | D22: Sadece doğru hesap yapıp çıplak/varsayılan Excel görünümü bırakmak | E22: Görsel release incelemesi | F22: ZORUNLU

Sheet 04_MUHASEBE_THP
A1: TÜRKİYE MUHASEBE VE TEKDÜZEN HESAP PLANI STANDARDI
A3: Konu | B3: Zorunlu Standart | C3: Örnek Türkçe Ad | D3: THP / Mantık | E3: Hata Riski | F3: Kontrol
A4: Dil | B4: Kullanıcıya görünen finansal terimler Türkçe | C4: Hasılat, Satışların Maliyeti, Brüt Kâr, Faaliyet Giderleri | D4: Türk işletme kullanımına uygun | E4: İngilizce jargon | F4: Terminoloji taraması
A5: Gelir Tablosu | B5: Türk sunum sırası kullanılır | C5: Net Satışlar → Satışların Maliyeti → Brüt Kâr → Faaliyet Giderleri → Faaliyet Kârı | D5: 600/610/611; 620-623; 63x | E5: Yanlış sınıflama | F5: Hesap eşleme
A6: Bilanço | B6: Dönen/Duran Varlık ve Kısa/Uzun Vadeli Yükümlülük ayrımı | C6: Hazır Değerler, Ticari Alacaklar, Stoklar, Mali Borçlar | D6: 1xx / 2xx / 3xx / 4xx / 5xx | E6: Vade sınıfı hatası | F6: Bilanço eşitliği
A7: Nakit Akışı | B7: İşletme/Yatırım/Finansman nakit akışları ayrılır | C7: Faaliyetlerden Nakit, Yatırım Harcamaları, Finansman Nakit Akışı | D7: Dolaylı/doğrudan yöntem açık seçilir | E7: Kâr = nakit sanılması | F7: Nakit devri
A8: Ticari Alacaklar | B8: Cari ve vade mantığı korunur | C8: 120 Alıcılar | D8: 120 | E8: Tahakkuk/nakit karışması | F8: Alacak devir kontrolü
A9: Ticari Borçlar | B9: Tedarikçi borcu ayrı izlenir | C9: 320 Satıcılar | D9: 320 | E9: Gider/ödeme karışması | F9: Borç devir kontrolü
A10: Kasa/Banka | B10: Hazır değerler ayrı izlenir | C10: 100 Kasa, 102 Bankalar | D10: 100 / 102 | E10: Virmanla toplam nakdin değişmesi | F10: Virman değişmezi
A11: Stok | B11: Dikeye uygun stok türü | C11: 150 İlk Madde ve Malzeme, 153 Ticari Mallar | D11: 15x | E11: Maliyet ve stok hareketinin kopması | F11: Stok devri
A12: Maddi Duran Varlık | B12: Yatırım harcaması ve amortisman bağlantılı | C12: 253 Tesis Makine Cihazlar, 255 Demirbaşlar, 257 Birikmiş Amortismanlar | D12: 25x | E12: Yatırım/gider karışması | F12: Net defter değeri devri
A13: Mali Borçlar | B13: Kısa/uzun vadeli borç ayrımı | C13: 300 Banka Kredileri / 400 Banka Kredileri | D13: 300 / 400 | E13: Vade sınıfı yanlış | F13: Borç devri
A14: Özkaynak | B14: Sermaye ve geçmiş yıl kârları ayrı | C14: 500 Sermaye, 570 Geçmiş Yıllar Kârları, 590 Dönem Net Kârı | D14: 5xx | E14: Net kâr bağının kopması | F14: Özkaynak devri
... A18: İstisna | B18: TFRS özel ürün varsa fark açık yazılır | C18: Tekdüzen raporlama ≠ TFRS finansal tablo sunumu | D18: Amaç belirtilir | E18: Standartları karıştırma | F18: Model amacı kontrolü

Sheet 05_KARAR_SATIS
A1: KARAR, GÜVEN VE SATIŞA HAZIRLIK STANDARDI
A3: Alan | B3: Müşteri Sorusu | C3: Zorunlu Ürün Davranışı | D3: Kanıt | E3: Başarısızlık Durumu | F3: Kapı
A4: 5 saniye | B4: Bu ürün neyi çözüyor? | C4: İlk ekranda hedef kullanıcı + pahalı problem + sonuç görünür | D4: Başlık + alt mesaj + gerçek ekran | E4: Ürün yalnız teknik isim | F4: HATA
A5: Acı | B5: Sorun bana neye mal oluyor? | C5: Mümkünse müşterinin kendi verisiyle parasal/zaman etkisi hesaplanır | D5: ROI/acı hesaplama yöntemi | E5: Uydurma tasarruf | F5: HATA
A6: Karar | B6: Bu bilgiyle ne yapacağım? | C6: Her kritik KPI aksiyona bağlanır | D6: KARAR_KUYRUGU | E6: Sadece rapor | F6: HATA
A7: Güven | B7: Bu sayıya neden inanayım? | C7: Kaynak, formül mantığı, kontrol ve son doğrulama görünür | D7: Kontroller + kaynak izi + sürüm | E7: Prestij kelimesi | F7: HATA
A8: Referans | B8: Müşteri yorumu yoksa ne göstereceğim? | C8: Önce/Sonra + Karar Vakası + Hata Önleme Vakası üretilir | D8: Demo/örnek çıktı | E8: Kanıtsız iddia | F8: HATA
A9: Senaryo | B9: Ne olursa işler bozulur? | C9: Baz/Aşağı/Yukarı veya uygun stres senaryosu | D9: Senaryo karşılaştırma | E9: Dekoratif senaryo | F9: HATA
A10: Ters stres | B10: Hangi eşikte karar kırılır? | C10: En az bir kritik sürücü için kırılma eşiği | D10: Kırılma eşiği tablosu | E10: Sadece +/- %10 | F10: UYARI/HATA
A11: Hata tutarlılığı | B11: Formül hata verirse ne olur? | C11: Kontrol GEÇTİ veremez; BLOKE/HATA üretir | D11: Hata taraması | E11: Hata + GEÇTİ birlikte | F11: HATA
A12: Karar motoru | B12: Ne oldu, neden oldu? | C12: Sorun + neden + parasal etki + aksiyon + son tarih | D12: Karar tablosu | E12: Boş sayfa / isim düzeyi modül | F12: HATA
A13: Yönetici özeti | B13: 5 saniyede ne görmeliyim? | C13: Bugün / ne değişti / ne bozulacak / neden / ne yapmalıyım / güven | D13: Yönetici özeti ekranı | E13: KPI kutusu yığını | F13: HATA
A14: Teklif | B14: Neden satın almalıyım? | C14: Dosya özellikleri yerine sonuç ve kaçınılan maliyet sunulur | D14: Ürün sayfası kanıt eşlemesi | E14: Özellik listesiyle satış | F14: HATA
... A19: Pazar kanıtı | B19: Piyasa gerçekten ödüyor mu? | C19: Satış/pilot/LOI/fiyat kabulü olmadan pazar doğrulandı yazılmaz | D19: Gerçek işlem kanıtı | E19: Tahmini talep = satış kabulü | F19: HATA

Sheet KAPAK
A1: AKILLI KASA DEFTERİ VE NAKİT KONTROL SİSTEMİ
A3: Kasadaki paranızın tamamını mı sanıyorsunuz? Bloke, eşik ve bekleyen ödemeleri ayırdıktan sonra gerçek kullanılabilir nakitinizi ve açık riskinizi görün.
A4: Hesap kartları, kasa hareketleri, ödeme/tahsilat takvimi ve fiziki mutabakat tek sistemde toplanır. Kullanılabilir para, nakit açığı, ödeme önerisi ve senaryo etkileri canlı formüllerle üretilir; karar motoru ödeme planına net yön verir.
A7: 1. KASA_HESAPLARI ve KASA_HAREKETLERI sayfalarına hesaplarınızı ve hareketlerinizi girin.
A8: 2. ODEME_TAHSILAT_TAKVIMI ile ödeme planınızı, FIZIKI_KASA_MUTABAKAT ile sayımınızı girin.
A9: 3. PANO'da kullanılabilir para, nakit açığı ve ödeme önerisini okuyun; RAPOR ile yönetici özeti alın.
A11: Bu dosya bir karar destek aracıdır; bağımsız denetim veya mali danışmanlık yerine geçmez. Verileriniz yalnızca bu dosyada kalır, cihazınızdan çıkmaz. Kasa ve banka bakiyeleri banka kayıtlarıyla mutabakat edilerek doğrulanmalıdır.
A15: ExcelArşiv
A16: Rev 1.0 | 2026-08-10 | Lisans: Tek kullanıcı | Çevrimdışı çalışır

Sheet HIZLI_BASLANGIC
A1: ☰ PANO
A3: Nasıl kullanılır?
A4: 1. AYARLAR sayfasından kasa başlangıç bakiyesi, asgari nakit tamponu ve eşikleri kontrol edin.
A5: 2. KASA_HESAPLARI'na hesap kartlarını (kasa/banka), bakiyelerini ve bloke tutarlarını girin.
A6: 3. KASA_HAREKETLERI'ne giriş/çıkış hareketlerini tarih, tür ve tutarla işleyin; hesaplanan sütunlar otomatik dolar.
A7: 4. ODEME_TAHSILAT_TAKVIMI'ne bekleyen ödeme ve tahsilatları, FIZIKI_KASA_MUTABAKAT'a sayımı girin.
A8: 5. PANO'da kullanılabilir para, nakit açığı, kritik ödemeler ve ödeme önerisini okuyun.
A9: 6. KARAR_MOTORU ve SENARYO_DUYARLILIK iyimser/kötümser koşullarda nakit etkisini gösterir.
A10: 7. RAPOR sayfası yöneticiye sunulabilir özet çıktısı üretir; yazdırmaya hazırdır.
A12: Sık yapılan hatalar
A13: Bakiyeyi hesap kartında güncellemeyi unutmak — kullanılabilir para hatalı hesaplanır.
A14: Bloke tutar ve minimum eşiği boş bırakmak — kullanılabilir para olduğundan yüksek görünür.
... A19: Tüm eşik ve katsayılar AYARLAR sayfasından beslenir; formüle gömülü sayı kullanılmaz.

Sheet KASA_HESAPLARI
A1: KASA HESAPLARI — AKILLI KASA DEFTERİ VE NAKİT KONTROL SİSTEMİ
A2: Kasa ve banka hesaplarını burada tanımlayın. Bakiye, Bloke Tutar ve Minimum Kasa Eşiği sütunları günlük kullanılabilir para hesabını besler.
L3: Sarı hücreler elle doldurulur; Kullanılabilir sütunu otomatik hesaplanır.
A4: Hesap Kodu | B4: Hesap Adı | C4: Tür | D4: Banka | E4: IBAN | F4: Bakiye (₺) | G4: Bloke Tutar (₺) | H4: Minimum Kasa Eşiği (₺) | I4: Durum | J4: Kullanılabilir (₺) | K4: Açıklama
A6: KS-001 | B6: Ana Kasa | C6: KASA | F6: 450000 | G6: 0 | H6: 50000 | I6: AKTİF | J6: =IF($A6="","",$F6-$G6-$H6) | K6: Günlük operasyon kasası
A7: BK-001 | B7: İş Bankası Cari | C7: BANKA | D7: İŞ | E7: TR33 0006 4000 0011 1234 5678 90 | F7: 800000 | G7: 200000 | H7: 100000 | I7: AKTİF | J7: =IF($A7="","",$F7-$G7-$H7) | K7: Tedarikçi ödemeleri
A8: BK-002 | B8: Ziraat Vadesiz | C8: BANKA | D8: ZİRAAT | E8: TR12 0001 0000 0000 4321 0987 65 | F8: 250000 | G8: 0 | H8: 50000 | I8: AKTİF | J8: =IF($A8="","",$F8-$G8-$H8) | K8: Vergi ve SGK ödemeleri
A9: BK-003 | B9: Garanti Kredi Hesabı | C9: BANKA | D9: GARANTİ | E9: TR45 0006 2000 0000 9988 7766 55 | F9: 150000 | G9: 150000 | H9: 0 | I9: PASİF | J9: =IF($A9="","",$F9-$G9-$H9) | K9: Kredi kullandırımı pasif

Sheet KASA_HAREKETLERI
A1: KASA HAREKETLERI — AKILLI KASA DEFTERİ VE NAKİT KONTROL SİSTEMİ
A2: Tüm kasa ve banka hareketleri burada toplanır. İşlem Türü GİRİŞ veya ÇIKIŞ; kategori LISTELER'den, hesap KASA_HESAPLARI'ndan gelir. Net Etki ve Kontrol sütunları otomatiktir.
A4: Tarih | B4: Fiş Numarası | C4: Hesap | D4: İşlem Türü | E4: Kategori | F4: Alt Kategori | G4: Karşı Taraf | H4: Ödeme Yöntemi | I4: Belge Numarası | J4: Tutar (₺) | K4: Açıklama | L4: Net Etki (₺) | M4: Kontrol | N4: Kayıt ID
A6: 46204 | B6: FİŞ-0001 | C6: KS-001 | D6: GİRİŞ | E6: SATIŞ | F6: TİCARİ MAL | G6: Yıldız Market | H6: NAKİT | I6: SAT-001 | J6: 120000 | K6: Toptan satış tahsilatı
A7: 46205 | B7: FİŞ-0002 | C7: KS-001 | D7: ÇIKIŞ | E7: ALIM | F7: HAMMADDE | G7: Tarım Ürünleri A.Ş. | H7: HAVALE | I7: AL-001 | J7: 90000 | K7: Hammadde alımı
A8: 46206 | B8: FİŞ-0003 | C8: BK-001 | D8: GİRİŞ | E8: TAHSİLAT | F8: TİCARİ MAL | G8: Mega Market | H8: HAVALE | I8: TAH-001 | J8: 85000 | K8: Cari hesap tahsilatı
A9: 46208 | B9: FİŞ-0004 | C9: BK-001 | D9: ÇIKIŞ | E9: MAAŞ | F9: PERSONEL | G9: Personel | H9: EFT | I9: PER-001 | J9: 180000 | K9: Temmuz maaş ödemesi
A10: 46210 | B10: FİŞ-0005 | C10: BK-002 | D10: ÇIKIŞ | E10: VERGİ | F10: OFİS | G10: Vergi Dairesi | H10: EFT | I10: VGN-001 | J10: 60000 | K10: Geçici vergi
A11: 46211 | B11: FİŞ-0006 | C11: KS-001 | D11: GİRİŞ | E11: SATIŞ | F11: PERAKENDE | G11: Müşteriler | H11: NAKİT | I11: SAT-002 | J11: 45000 | K11: Perakende satış
A12: 46213 | B12: FİŞ-0007 | C12: BK-001 | D12: ÇIKIŞ | E12: KİRA | F12: OFİS | G12: Depo Sahibi | H12: HAVALE | I12: KIR-001 | J12: 75000 | K12: Depo ve ofis kirası
A13: 46215 | B13: FİŞ-0008 | C13: BK-001 | D13: ÇIKIŞ | E13: SGK PRİMİ | F13: PERSONEL | G13: SGK | H13: EFT | I13: SGK-001 | J13: 52000 | K13: SGK primi ödemesi
A14: 46218 | B14: FİŞ-0009 | C14: BK-001 | D14: ÇIKIŞ | E14: KREDİ TAKSİDİ | F14: OFİS | G14: Garanti Bankası | H14: EFT | I14: KRD-001 | J14: 120000 | K14: Kredi taksiti
A15: 46219 | B15: FİŞ-0010 | C15: KS-001 | D15: GİRİŞ | E15: TAHSİLAT | F15: HİZMET | G15: Orion Lojistik | H15: ÇEK | I15: TAH-002 | J15: 95000 | K15: Hizmet tahsilatı

Sheet ODEME_TAHSILAT_TAKVIMI
A1: ODEME TAHSILAT TAKVIMI — AKILLI KASA DEFTERİ VE NAKİT KONTROL SİSTEMİ
A2: Vadesi gelen veya gelecek tüm ödemeler ve tahsilatlar burada takip edilir. Öncelik ve Durum, karar motorunu ve ödeme önerisini besler.
A4: Tarih | B4: Vade | C4: Tür | D4: Karşı Taraf | E4: Öncelik | F4: Tutar (₺) | G4: Durum | H4: Vade Kontrolü | I4: Ödeme Yöntemi | J4: Kaynak Hesap | K4: Açıklama | M4: Öncelik | N4: Bekleyen Ödeme (₺)
M5: KRİTİK | N5: 260000
A6: 46244 | B6: 46244 | C6: ÖDEME | D6: Vergi Dairesi | E6: KRİTİK | F6: 80000 | G6: BEKLEMEDE | I6: EFT | J6: BK-002 | K6: Muhtasar ve KDV | M6: YÜKSEK | N6: 202000
A7: 46246 | B7: 46246 | C7: TAHSİLAT | D7: Mega Market | E7: KRİTİK | F7: 200000 | G7: BEKLEMEDE | I7: HAVALE | J7: BK-001 | K7: Cari tahsilat | M7: ORTA | N7: 75000
A8: 46249 | B8: 46249 | C8: ÖDEME | D8: Tarım Ürünleri A.Ş. | E8: YÜKSEK | F8: 150000 | G8: BEKLEMEDE | I8: HAVALE | J8: BK-001 | K8: Hammadde ödemesi | M8: DÜŞÜK | N8: =IF(KayitSayisi=0,"",SUMIFS(tblTakvim[],tblTakvim[],"DÜŞÜK",tblTakvim[],"BEKLEMEDE",tblTakvim[],"ÖDEME"))
A9: 46254 | B9: 46254 | C9: ÖDEME | D9: Personel | E9: KRİTİK | F9: 180000 | G9: BEKLEMEDE | I9: EFT | J9: BK-001 | K9: Ağustos maaşları
A10: 46259 | B10: 46259 | C10: TAHSİLAT | D10: Yıldız Market | E10: ORTA | F10: 150000 | G10: BEKLEMEDE | I10: HAVALE | J10: BK-001 | K10: Vadeli tahsilat
A11: 46266 | B11: 46266 | C11: ÖDEME | D11: SGK | E11: YÜKSEK | F11: 52000 | G11: BEKLEMEDE | I11: EFT | J11: BK-002 | K11: SGK primi
A12: 46270 | B12: 46270 | C12: ÖDEME | D12: Depo Sahibi | E12: ORTA | F12: 75000 | G12: BEKLEMEDE | I12: HAVALE | J12: BK-001 | K12: Kira

Sheet FIZIKI_KASA_MUTABAKAT
A1: FIZIKI KASA MUTABAKAT — AKILLI KASA DEFTERİ VE NAKİT KONTROL SİSTEMİ
A2: Fiziki kasa sayımı ile defter bakiyesini karşılaştırın. Fark sütunu ve kök-neden ayrıştırması otomatik hesaplanır; sıfır fark beklenir.
A4: Sayım Tarihi | B4: Sayımı Yapan | C4: Defter Bakiyesi (₺) | D4: Sayım Tutarı (₺) | E4: Fark (₺) | F4: Fark Oranı | G4: Sonuç | H4: Kök Neden | I4: Açıklama
A6: 46234 | B6: Finans Müdürü | C6: 450000 | D6: 450000 | I6: Fiziki sayım uyumlu
A7: 46218 | B7: Muhasebe | C7: 320000 | D7: 318500 | I7: Sayım eksikliği araştırılıyor

Sheet GUNLUK_OZET
A1: GUNLUK OZET — AKILLI KASA DEFTERİ VE NAKİT KONTROL SİSTEMİ
A2: Günlük nakit hareketlerinin özeti. Tarih listesine bir gün yazmanız yeterli; giriş, çıkış ve net değerler KASA_HAREKETLERI'nden otomatik gelir.
A4: Tarih | B4: Toplam Giriş (₺) | C4: Toplam Çıkış (₺) | D4: Net (₺) | E4: Kümülatif Net (₺)
A5: 46204 | B5: 120000 | C5: =IF($A5="","",SUMIFS(tblKasaHareket[],tblKasaHareket[],$A5,tblKasaHareket[],"ÇIKIŞ")) | D5: 120000 | E5: 120000
A6: 46205 | B6: =IF($A6="","",SUMIFS(tblKasaHareket[],tblKasaHareket[],$A6,tblKasaHareket[],"GİRİŞ")) | C6: 90000 | D6: -90000 | E6: 30000
A7: 46206 | B7: 85000 | C7: =IF($A7="","",SUMIFS(tblKasaHareket[],tblKasaHareket[],$A7,tblKasaHareket[],"ÇIKIŞ")) | D7: 85000 | E7: 115000
A8: 46208 | B8: =IF($A8="","",SUMIFS(tblKasaHareket[],tblKasaHareket[],$A8,tblKasaHareket[],"GİRİŞ")) | C8: 180000 | D8: -180000 | E8: -65000
A9: 46210 | B9: =IF($A9="","",SUMIFS(tblKasaHareket[],tblKasaHareket[],$A9,tblKasaHareket[],"GİRİŞ")) | C9: 60000 | D9: -60000 | E9: -125000
A10: 46211 | B10: 45000 | C10: =IF($A10="","",SUMIFS(tblKasaHareket[],tblKasaHareket[],$A10,tblKasaHareket[],"ÇIKIŞ")) | D10: 45000 | E10: -80000
A11: 46213 | B11: =IF($A11="","",SUMIFS(tblKasaHareket[],tblKasaHareket[],$A11,tblKasaHareket[],"GİRİŞ")) | C11: 75000 | D11: -75000 | E11: -155000
A12: 46215 | B12: =IF($A12="","",SUMIFS(tblKasaHareket[],tblKasaHareket[],$A12,tblKasaHareket[],"GİRİŞ")) | C12: 52000 | D12: -52000 | E12: -207000
A13: 46218 | B13: =IF($A13="","",SUMIFS(tblKasaHareket[],tblKasaHareket[],$A13,tblKasaHareket[],"GİRİŞ")) | C13: 120000 | D13: -120000 | E13: -327000
A14: 46219 | B14: 95000 | C14: =IF($A14="","",SUMIFS(tblKasaHareket[],tblKasaHareket[],$A14,tblKasaHareket[],"ÇIKIŞ")) | D14: 95000 | E14: -232000
B15: =IF($A15="","",SUMIFS(tblKasaHareket[],tblKasaHareket[],$A15,tblKasaHareket[],"GİRİŞ")) | C15: =IF($A15="","",SUMIFS(tblKasaHareket[],tblKasaHareket[],$A15,tblKasaHareket[],"ÇIKIŞ")) | D15: =IF($A15="","",$B15-$C15) | E15: =IF($A15="","",SUM($D$5:$D15))
B16: =IF($A16="","",SUMIFS(tblKasaHareket[],tblKasaHareket[],$A16,tblKasaHareket[],"GİRİŞ")) | C16: =IF($A16="","",SUMIFS(tblKasaHareket[],tblKasaHareket[],$A16,tblKasaHareket[],"ÇIKIŞ")) | D16: =IF($A16="","",$B16-$C16) | E16: =IF($A16="","",SUM($D$5:$D16))
B17: =IF($A17="","",SUMIFS(tblKasaHareket[],tblKasaHareket[],$A17,tblKasaHareket[],"GİRİŞ")) | C17: =IF($A17="","",SUMIFS(tblKasaHareket[],tblKasaHareket[],$A17,tblKasaHareket[],"ÇIKIŞ")) | D17: =IF($A17="","",$B17-$C17) | E17: =IF($A17="","",SUM($D$5:$D17))
B18: =IF($A18="","",SUMIFS(tblKasaHareket[],tblKasaHareket[],$A18,tblKasaHareket[],"GİRİŞ")) | C18: =IF($A18="","",SUMIFS(tblKasaHareket[],tblKasaHareket[],$A18,tblKasaHareket[],"ÇIKIŞ")) | D18: =IF($A18="","",$B18-$C18) | E18: =IF($A18="","",SUM($D$5:$D18))
B19: =IF($A19="","",SUMIFS(tblKasaHareket[],tblKasaHareket[],$A19,tblKasaHareket[],"GİRİŞ")) | C19: =IF($A19="","",SUMIFS(tblKasaHareket[],tblKasaHareket[],$A19,tblKasaHareket[],"ÇIKIŞ")) | D19: =IF($A19="","",$B19-$C19) | E19: =IF($A19="","",SUM($D$5:$D19))
B20: =IF($A20="","",SUMIFS(tblKasaHareket[],tblKasaHareket[],$A20,tblKasaHareket[],"GİRİŞ")) | C20: =IF($A20="","",SUMIFS(tblKasaHareket[],tblKasaHareket[],$A20,tblKasaHareket[],"ÇIKIŞ")) | D20: =IF($A20="","",$B20-$C20) | E20: =IF($A20="","",SUM($D$5:$D20))
B21: =IF($A21="","",SUMIFS(tblKasaHareket[],tblKasaHareket[],$A21,tblKasaHareket[],"GİRİŞ")) | C21: =IF($A21="","",SUMIFS(tblKasaHareket[],tblKasaHareket[],$A21,tblKasaHareket[],"ÇIKIŞ")) | D21: =IF($A21="","",$B21-$C21) | E21: =IF($A21="","",SUM($D$5:$D21))
B22: =IF($A22="","",SUMIFS(tblKasaHareket[],tblKasaHareket[],$A22,tblKasaHareket[],"GİRİŞ")) | C22: =IF($A22="","",SUMIFS(tblKasaHareket[],tblKasaHareket[],$A22,tblKasaHareket[],"ÇIKIŞ")) | D22: =IF($A22="","",$B22-$C22) | E22: =IF($A22="","",SUM($D$5:$D22))
B23: =IF($A23="","",SUMIFS(tblKasaHareket[],tblKasaHareket[],$A23,tblKasaHareket[],"GİRİŞ")) | C23: =IF($A23="","",SUMIFS(tblKasaHareket[],tblKasaHareket[],$A23,tblKasaHareket[],"ÇIKIŞ")) | D23: =IF($A23="","",$B23-$C23) | E23: =IF($A23="","",SUM($D$5:$D23))
B24: =IF($A24="","",SUMIFS(tblKasaHareket[],tblKasaHareket[],$A24,tblKasaHareket[],"GİRİŞ")) | C24: =IF($A24="","",SUMIFS(tblKasaHareket[],tblKasaHareket[],$A24,tblKasaHareket[],"ÇIKIŞ")) | D24: =IF($A24="","",$B24-$C24) | E24: =IF($A24="","",SUM($D$5:$D24))
B25: =IF($A25="","",SUMIFS(tblKasaHareket[],tblKasaHareket[],$A25,tblKasaHareket[],"GİRİŞ")) | C25: =IF($A25="","",SUMIFS(tblKasaHareket[],tblKasaHareket[],$A25,tblKasaHareket[],"ÇIKIŞ")) | D25: =IF($A25="","",$B25-$C25) | E25: =IF($A25="","",SUM($D$5:$D25))
B26: =IF($A26="","",SUMIFS(tblKasaHareket[],tblKasaHareket[],$A26,tblKasaHareket[],"GİRİŞ")) | C26: =IF($A26="","",SUMIFS(tblKasaHareket[],tblKasaHareket[],$A26,tblKasaHareket[],"ÇIKIŞ")) | D26: =IF($A26="","",$B26-$C26) | E26: =IF($A26="","",SUM($D$5:$D26))
... B30: =IF($A30="","",SUMIFS(tblKasaHareket[],tblKasaHareket[],$A30,tblKasaHareket[],"GİRİŞ")) | C30: =IF($A30="","",SUMIFS(tblKasaHareket[],tblKasaHareket[],$A30,tblKasaHareket[],"ÇIKIŞ")) | D30: =IF($A30="","",$B30-$C30) | E30: =IF($A30="","",SUM($D$5:$D30))

Sheet NAKIT_PROJEKSIYONU
A1: NAKIT PROJEKSIYONU — AKILLI KASA DEFTERİ VE NAKİT KONTROL SİSTEMİ
A2: Önümüzdeki haftalar için nakit projeksiyonu. Hafta başlangıç tarihlerini girin; beklenen giriş/çıkış ODEME_TAHSILAT_TAKVIMI ve günlük ortalamadan hesaplanır.
A4: Hafta Başlangıcı | B4: Hafta Sonu | C4: Beklenen Giriş (₺) | D4: Beklenen Çıkış (₺) | E4: Net (₺) | F4: Dönem Başı Kasa (₺) | G4: Dönem Sonu Kasa (₺)
A5: 46244 | B5: =IF($A5="","",$A5+HaftaUzunluk-1) | C5: 200000 | D5: 230000 | E5: -30000 | F5: 500000 | G5: 470000
A6: 46251 | B6: =IF($A6="","",$A6+HaftaUzunluk-1) | C6: =IF($A6="","",SUMIFS(tblTakvim[],tblTakvim[],">="&$A6,tblTakvim[],"<="&$B6,tblTakvim[],"TAHSİLAT",tblTakvim[],"BEKLEMEDE")) | D6: 180000 | E6: -180000 | F6: 470000 | G6: 290000
A7: 46258 | B7: =IF($A7="","",$A7+HaftaUzunluk-1) | C7: 150000 | D7: =IF($A7="","",SUMIFS(tblTakvim[],tblTakvim[],">="&$A7,tblTakvim[],"<="&$B7,tblTakvim[],"ÖDEME",tblTakvim[],"BEKLEMEDE")) | E7: 150000 | F7: 290000 | G7: 440000
A8: 46265 | B8: =IF($A8="","",$A8+HaftaUzunluk-1) | C8: =IF($A8="","",SUMIFS(tblTakvim[],tblTakvim[],">="&$A8,tblTakvim[],"<="&$B8,tblTakvim[],"TAHSİLAT",tblTakvim[],"BEKLEMEDE")) | D8: 127000 | E8: -127000 | F8: 440000 | G8: 313000
A9: 46272 | B9: =IF($A9="","",$A9+HaftaUzunluk-1) | C9: =IF($A9="","",SUMIFS(tblTakvim[],tblTakvim[],">="&$A9,tblTakvim[],"<="&$B9,tblTakvim[],"TAHSİLAT",tblTakvim[],"BEKLEMEDE")) | D9: =IF($A9="","",SUMIFS(tblTakvim[],tblTakvim[],">="&$A9,tblTakvim[],"<="&$B9,tblTakvim[],"ÖDEME",tblTakvim[],"BEKLEMEDE")) | E9: =IF($A9="","",$C9-$D9) | F9: 313000 | G9: 313000
A10: 46279 | B10: =IF($A10="","",$A10+HaftaUzunluk-1) | C10: =IF($A10="","",SUMIFS(tblTakvim[],tblTakvim[],">="&$A10,tblTakvim[],"<="&$B10,tblTakvim[],"TAHSİLAT",tblTakvim[],"BEKLEMEDE")) | D10: =IF($A10="","",SUMIFS(tblTakvim[],tblTakvim[],">="&$A10,tblTakvim[],"<="&$B10,tblTakvim[],"ÖDEME",tblTakvim[],"BEKLEMEDE")) | E10: =IF($A10="","",$C10-$D10) | F10: 313000 | G10: 313000
A11: 46286 | B11: =IF($A11="","",$A11+HaftaUzunluk-1) | C11: =IF($A11="","",SUMIFS(tblTakvim[],tblTakvim[],">="&$A11,tblTakvim[],"<="&$B11,tblTakvim[],"TAHSİLAT",tblTakvim[],"BEKLEMEDE")) | D11: =IF($A11="","",SUMIFS(tblTakvim[],tblTakvim[],">="&$A11,tblTakvim[],"<="&$B11,tblTakvim[],"ÖDEME",tblTakvim[],"BEKLEMEDE")) | E11: =IF($A11="","",$C11-$D11) | F11: 313000 | G11: 313000
A12: 46293 | B12: =IF($A12="","",$A12+HaftaUzunluk-1) | C12: =IF($A12="","",SUMIFS(tblTakvim[],tblTakvim[],">="&$A12,tblTakvim[],"<="&$B12,tblTakvim[],"TAHSİLAT",tblTakvim[],"BEKLEMEDE")) | D12: =IF($A12="","",SUMIFS(tblTakvim[],tblTakvim[],">="&$A12,tblTakvim[],"<="&$B12,tblTakvim[],"ÖDEME",tblTakvim[],"BEKLEMEDE")) | E12: =IF($A12="","",$C12-$D12) | F12: 313000 | G12: 313000
A13: 46300 | B13: =IF($A13="","",$A13+HaftaUzunluk-1) | C13: =IF($A13="","",SUMIFS(tblTakvim[],tblTakvim[],">="&$A13,tblTakvim[],"<="&$B13,tblTakvim[],"TAHSİLAT",tblTakvim[],"BEKLEMEDE")) | D13: =IF($A13="","",SUMIFS(tblTakvim[],tblTakvim[],">="&$A13,tblTakvim[],"<="&$B13,tblTakvim[],"ÖDEME",tblTakvim[],"BEKLEMEDE")) | E13: =IF($A13="","",$C13-$D13) | F13: 313000 | G13: 313000
A14: 46307 | B14: =IF($A14="","",$A14+HaftaUzunluk-1) | C14: =IF($A14="","",SUMIFS(tblTakvim[],tblTakvim[],">="&$A14,tblTakvim[],"<="&$B14,tblTakvim[],"TAHSİLAT",tblTakvim[],"BEKLEMEDE")) | D14: =IF($A14="","",SUMIFS(tblTakvim[],tblTakvim[],">="&$A14,tblTakvim[],"<="&$B14,tblTakvim[],"ÖDEME",tblTakvim[],"BEKLEMEDE")) | E14: =IF($A14="","",$C14-$D14) | F14: 313000 | G14: 313000
A15: 46314 | B15: =IF($A15="","",$A15+HaftaUzunluk-1) | C15: =IF($A15="","",SUMIFS(tblTakvim[],tblTakvim[],">="&$A15,tblTakvim[],"<="&$B15,tblTakvim[],"TAHSİLAT",tblTakvim[],"BEKLEMEDE")) | D15: =IF($A15="","",SUMIFS(tblTakvim[],tblTakvim[],">="&$A15,tblTakvim[],"<="&$B15,tblTakvim[],"ÖDEME",tblTakvim[],"BEKLEMEDE")) | E15: =IF($A15="","",$C15-$D15) | F15: 313000 | G15: 313000
A16: 46321 | B16: =IF($A16="","",$A16+HaftaUzunluk-1) | C16: =IF($A16="","",SUMIFS(tblTakvim[],tblTakvim[],">="&$A16,tblTakvim[],"<="&$B16,tblTakvim[],"TAHSİLAT",tblTakvim[],"BEKLEMEDE")) | D16: =IF($A16="","",SUMIFS(tblTakvim[],tblTakvim[],">="&$A16,tblTakvim[],"<="&$B16,tblTakvim[],"ÖDEME",tblTakvim[],"BEKLEMEDE")) | E16: =IF($A16="","",$C16-$D16) | F16: 313000 | G16: 313000
B17: =IF($A17="","",$A17+HaftaUzunluk-1) | C17: =IF($A17="","",SUMIFS(tblTakvim[],tblTakvim[],">="&$A17,tblTakvim[],"<="&$B17,tblTakvim[],"TAHSİLAT",tblTakvim[],"BEKLEMEDE")) | D17: =IF($A17="","",SUMIFS(tblTakvim[],tblTakvim[],">="&$A17,tblTakvim[],"<="&$B17,tblTakvim[],"ÖDEME",tblTakvim[],"BEKLEMEDE")) | E17: =IF($A17="","",$C17-$D17) | F17: =IF($A17="","",IF(ROW()=BaslangicSatir,KasaBaslangicBakiye,$G16)) | G17: =IF($A17="","",$F17+$E17)
B18: =IF($A18="","",$A18+HaftaUzunluk-1) | C18: =IF($A18="","",SUMIFS(tblTakvim[],tblTakvim[],">="&$A18,tblTakvim[],"<="&$B18,tblTakvim[],"TAHSİLAT",tblTakvim[],"BEKLEMEDE")) | D18: =IF($A18="","",SUMIFS(tblTakvim[],tblTakvim[],">="&$A18,tblTakvim[],"<="&$B18,tblTakvim[],"ÖDEME",tblTakvim[],"BEKLEMEDE")) | E18: =IF($A18="","",$C18-$D18) | F18: =IF($A18="","",IF(ROW()=BaslangicSatir,KasaBaslangicBakiye,$G17)) | G18: =IF($A18="","",$F18+$E18)
B19: =IF($A19="","",$A19+HaftaUzunluk-1) | C19: =IF($A19="","",SUMIFS(tblTakvim[],tblTakvim[],">="&$A19,tblTakvim[],"<="&$B19,tblTakvim[],"TAHSİLAT",tblTakvim[],"BEKLEMEDE")) | D19: =IF($A19="","",SUMIFS(tblTakvim[],tblTakvim[],">="&$A19,tblTakvim[],"<="&$B19,tblTakvim[],"ÖDEME",tblTakvim[],"BEKLEMEDE")) | E19: =IF($A19="","",$C19-$D19) | F19: =IF($A19="","",IF(ROW()=BaslangicSatir,KasaBaslangicBakiye,$G18)) | G19: =IF($A19="","",$F19+$E19)
B20: =IF($A20="","",$A20+HaftaUzunluk-1) | C20: =IF($A20="","",SUMIFS(tblTakvim[],tblTakvim[],">="&$A20,tblTakvim[],"<="&$B20,tblTakvim[],"TAHSİLAT",tblTakvim[],"BEKLEMEDE")) | D20: =IF($A20="","",SUMIFS(tblTakvim[],tblTakvim[],">="&$A20,tblTakvim[],"<="&$B20,tblTakvim[],"ÖDEME",tblTakvim[],"BEKLEMEDE")) | E20: =IF($A20="","",$C20-$D20) | F20: =IF($A20="","",IF(ROW()=BaslangicSatir,KasaBaslangicBakiye,$G19)) | G20: =IF($A20="","",$F20+$E20)
B21: =IF($A21="","",$A21+HaftaUzunluk-1) | C21: =IF($A21="","",SUMIFS(tblTakvim[],tblTakvim[],">="&$A21,tblTakvim[],"<="&$B21,tblTakvim[],"TAHSİLAT",tblTakvim[],"BEKLEMEDE")) | D21: =IF($A21="","",SUMIFS(tblTakvim[],tblTakvim[],">="&$A21,tblTakvim[],"<="&$B21,tblTakvim[],"ÖDEME",tblTakvim[],"BEKLEMEDE")) | E21: =IF($A21="","",$C21-$D21) | F21: =IF($A21="","",IF(ROW()=BaslangicSatir,KasaBaslangicBakiye,$G20)) | G21: =IF($A21="","",$F21+$E21)
B22: =IF($A22="","",$A22+HaftaUzunluk-1) | C22: =IF($A22="","",SUMIFS(tblTakvim[],tblTakvim[],">="&$A22,tblTakvim[],"<="&$B22,tblTakvim[],"TAHSİLAT",tblTakvim[],"BEKLEMEDE")) | D22: =IF($A22="","",SUMIFS(tblTakvim[],tblTakvim[],">="&$A22,tblTakvim[],"<="&$B22,tblTakvim[],"ÖDEME",tblTakvim[],"BEKLEMEDE")) | E22: =IF($A22="","",$C22-$D22) | F22: =IF($A22="","",IF(ROW()=BaslangicSatir,KasaBaslangicBakiye,$G21)) | G22: =IF($A22="","",$F22+$E22)
B23: =IF($A23="","",$A23+HaftaUzunluk-1) | C23: =IF($A23="","",SUMIFS(tblTakvim[],tblTakvim[],">="&$A23,tblTakvim[],"<="&$B23,tblTakvim[],"TAHSİLAT",tblTakvim[],"BEKLEMEDE")) | D23: =IF($A23="","",SUMIFS(tblTakvim[],tblTakvim[],">="&$A23,tblTakvim[],"<="&$B23,tblTakvim[],"ÖDEME",tblTakvim[],"BEKLEMEDE")) | E23: =IF($A23="","",$C23-$D23) | F23: =IF($A23="","",IF(ROW()=BaslangicSatir,KasaBaslangicBakiye,$G22)) | G23: =IF($A23="","",$F23+$E23)
B24: =IF($A24="","",$A24+HaftaUzunluk-1) | C24: =IF($A24="","",SUMIFS(tblTakvim[],tblTakvim[],">="&$A24,tblTakvim[],"<="&$B24,tblTakvim[],"TAHSİLAT",tblTakvim[],"BEKLEMEDE")) | D24: =IF($A24="","",SUMIFS(tblTakvim[],tblTakvim[],">="&$A24,tblTakvim[],"<="&$B24,tblTakvim[],"ÖDEME",tblTakvim[],"BEKLEMEDE")) | E24: =IF($A24="","",$C24-$D24) | F24: =IF($A24="","",IF(ROW()=BaslangicSatir,KasaBaslangicBakiye,$G23)) | G24: =IF($A24="","",$F24+$E24)
B25: =IF($A25="","",$A25+HaftaUzunluk-1) | C25: =IF($A25="","",SUMIFS(tblTakvim[],tblTakvim[],">="&$A25,tblTakvim[],"<="&$B25,tblTakvim[],"TAHSİLAT",tblTakvim[],"BEKLEMEDE")) | D25: =IF($A25="","",SUMIFS(tblTakvim[],tblTakvim[],">="&$A25,tblTakvim[],"<="&$B25,tblTakvim[],"ÖDEME",tblTakvim[],"BEKLEMEDE")) | E25: =IF($A25="","",$C25-$D25) | F25: =IF($A25="","",IF(ROW()=BaslangicSatir,KasaBaslangicBakiye,$G24)) | G25: =IF($A25="","",$F25+$E25)
B26: =IF($A26="","",$A26+HaftaUzunluk-1) | C26: =IF($A26="","",SUMIFS(tblTakvim[],tblTakvim[],">="&$A26,tblTakvim[],"<="&$B26,tblTakvim[],"TAHSİLAT",tblTakvim[],"BEKLEMEDE")) | D26: =IF($A26="","",SUMIFS(tblTakvim[],tblTakvim[],">="&$A26,tblTakvim[],"<="&$B26,tblTakvim[],"ÖDEME",tblTakvim[],"BEKLEMEDE")) | E26: =IF($A26="","",$C26-$D26) | F26: =IF($A26="","",IF(ROW()=BaslangicSatir,KasaBaslangicBakiye,$G25)) | G26: =IF($A26="","",$F26+$E26)
B27: =IF($A27="","",$A27+HaftaUzunluk-1) | C27: =IF($A27="","",SUMIFS(tblTakvim[],tblTakvim[],">="&$A27,tblTakvim[],"<="&$B27,tblTakvim[],"TAHSİLAT",tblTakvim[],"BEKLEMEDE")) | D27: =IF($A27="","",SUMIFS(tblTakvim[],tblTakvim[],">="&$A27,tblTakvim[],"<="&$B27,tblTakvim[],"ÖDEME",tblTakvim[],"BEKLEMEDE")) | E27: =IF($A27="","",$C27-$D27) | F27: =IF($A27="","",IF(ROW()=BaslangicSatir,KasaBaslangicBakiye,$G26)) | G27: =IF($A27="","",$F27+$E27)
B28: =IF($A28="","",$A28+HaftaUzunluk-1) | C28: =IF($A28="","",SUMIFS(tblTakvim[],tblTakvim[],">="&$A28,tblTakvim[],"<="&$B28,tblTakvim[],"TAHSİLAT",tblTakvim[],"BEKLEMEDE")) | D28: =IF($A28="","",SUMIFS(tblTakvim[],tblTakvim[],">="&$A28,tblTakvim[],"<="&$B28,tblTakvim[],"ÖDEME",tblTakvim[],"BEKLEMEDE")) | E28: =IF($A28="","",$C28-$D28) | F28: =IF($A28="","",IF(ROW()=BaslangicSatir,KasaBaslangicBakiye,$G27)) | G28: =IF($A28="","",$F28+$E28)
... B30: =IF($A30="","",$A30+HaftaUzunluk-1) | C30: =IF($A30="","",SUMIFS(tblTakvim[],tblTakvim[],">="&$A30,tblTakvim[],"<="&$B30,tblTakvim[],"TAHSİLAT",tblTakvim[],"BEKLEMEDE")) | D30: =IF($A30="","",SUMIFS(tblTakvim[],tblTakvim[],">="&$A30,tblTakvim[],"<="&$B30,tblTakvim[],"ÖDEME",tblTakvim[],"BEKLEMEDE")) | E30: =IF($A30="","",$C30-$D30) | F30: =IF($A30="","",IF(ROW()=BaslangicSatir,KasaBaslangicBakiye,$G29)) | G30: =IF($A30="","",$F30+$E30)

Sheet MOTOR
A1: MOTOR — AKILLI KASA DEFTERİ VE NAKİT KONTROL SİSTEMİ
A2: Hesaplama motoru: tüm ara hesaplar ve analitik modüller ad tanımlı hücrelerden beslenir. Değerler giriş tablolarından canlı hesaplanır; sabit sayı formüle gömülmez.
A4: TEMEL ARA HESAPLAR
A5: Hesap Sayısı (AKTİF) | B5: =IFERROR(COUNTIFS(tblKasaHesap[],"AKTİF"),0)
A6: Toplam Bakiye (₺) | B6: =IFERROR(SUMIFS(tblKasaHesap[],tblKasaHesap[],"AKTİF"),0)
A7: Toplam Bloke (₺) | B7: =IFERROR(SUMIFS(tblKasaHesap[],tblKasaHesap[],"AKTİF"),0)
A8: Toplam Min Eşik (₺) | B8: =IFERROR(SUMIFS(tblKasaHesap[],tblKasaHesap[],"AKTİF"),0)
A9: Hareket Sayısı | B9: =IFERROR(COUNTA(tblKasaHareket[]),0)
A10: Toplam Giriş (₺) | B10: =IFERROR(SUMIFS(tblKasaHareket[],tblKasaHareket[],"GİRİŞ"),0)
A11: Toplam Çıkış (₺) | B11: =IFERROR(SUMIFS(tblKasaHareket[],tblKasaHareket[],"ÇIKIŞ"),0)
A12: Bekleyen Ödeme (₺) | B12: =IFERROR(SUMIFS(tblTakvim[],tblTakvim[],"ÖDEME",tblTakvim[],"BEKLEMEDE"),0)
A13: Bekleyen Tahsilat (₺) | B13: =IFERROR(SUMIFS(tblTakvim[],tblTakvim[],"TAHSİLAT",tblTakvim[],"BEKLEMEDE"),0)
A14: Kullanılabilir Para (₺) | B14: =IFERROR(MAX(B6-B7-B8,0),0)
A15: Nakit Açığı (₺) | B15: =IFERROR(B12-B14-B13,0)
A16: Fiziki Mutabakat Farkı (₺) | B16: =IFERROR(SUM(tblMutabakat[]),0)
A17: Kritik Ödeme (₺) | B17: =IFERROR(SUMIFS(tblTakvim[],tblTakvim[],"KRİTİK",tblTakvim[],"BEKLEMEDE",tblTakvim[],"ÖDEME"),0)
A18: Vadesi Geçen Ödeme Sayısı | B18: =IFERROR(COUNTIF(tblTakvim[],"VADE GEÇTİ"),0)
A19: Veri Kalite Skoru | B19: =IFERROR(MAX(0,100-(B22+B23+B24+B25+B26)*HataAgirligi-B27*UyariAgirligi),0)
A20: Güven Düzeyi | B20: =IFERROR(IF(B19>=VeriKaliteYuksek,"YÜKSEK",IF(B19>=VeriKaliteOrta,"ORTA","DÜŞÜK")),"VERİ YETERSİZ")
A21: Ödeme Önerisi (₺) | B21: =IFERROR(MIN(B12,MAX(B14,0)),0)
A22: Eksik Zorunlu Alan | B22: =IFERROR(COUNTIF(tblKasaHareket[],"EKSİK"),0)
A23: Mükerrer Kayıt | B23: =IFERROR(COUNTIF(tblKasaHareket[],"MÜKERRER"),0)
A24: Sıfır/Negatif Tutar | B24: =IFERROR(COUNTIF(tblKasaHareket[],"SIFIR/NEGATİF"),0)
A25: Aşırı Tutar | B25: =IFERROR(COUNTIF(tblKasaHareket[],"AŞIRI TUTAR"),0)
A26: Vadesi Geçmiş Ödeme | B26: =IFERROR(COUNTIF(tblTakvim[],"VADE GEÇTİ"),0)
A27: Mutabakat Farkı Var | B27: =IFERROR(COUNTIF(tblMutabakat[],"FARK VAR"),0)
A29: ANALİTİK MODÜL HESAPLARI
A30: Modül T1: Vadesi Geçen Ödeme Sayısı | B30: =IFERROR(COUNTIF(tblTakvim[],"VADE GEÇTİ"),0)
A31: Modül T2: Net Nakit Eğimi | B31: =IFERROR(SLOPE(tblGunlukOzet[Net (₺)],tblGunlukOzet[Tarih]),0)
A32: Modül T3: Çıkış Pareto Payı | B32: =IFERROR(IF(B11=0,0,SUMIFS(tblKasaHareket[],tblKasaHareket[],"ÇIKIŞ",tblKasaHareket[],LISTELER!$B$4)/B11),0)
A33: Modül T4: Günlük Net Fark | B33: =IFERROR(AVERAGE(tblGunlukOzet[Net (₺)]),0)
A34: Modül T5: Mutabakat Farkı | B34: =IFERROR(SUM(tblMutabakat[]),0)
A35: Modül T6: Kapsama Oranı | B35: =IFERROR(IF(B12=0,0,(B14+B13)/B12),0)
A36: Modül O1: Anomali Oranı | B36: =IFERROR(IF(B10=0,0,B11/MAX(B10,1)),0)
A37: Modül O2: Tornado Zirve Etki | B37: =IFERROR(ABS(SenaryoBazNakit-SenaryoKotumserNakit),0)
A38: Modül O3: Senaryo Baz Fark | B38: =IFERROR(SenaryoIyimserNakit-SenaryoKotumserNakit,0)
A39: Modül O6: Hesap HHI | B39: =IFERROR(IF(SUMIFS(tblKasaHesap[],tblKasaHesap[],"AKTİF")=0,0,SUMPRODUCT(IF(tblKasaHesap[]="AKTİF",tblKasaHesap[],0),IF(tblKasaHesap[]="AKTİF",tblKasaHesap[],0))/MAX(1,SUMIFS(tblKasaHesap[],tblKasaHesap[],"AKTİF")^2)),0)
A40: Modül O8: Veri Kalite Skoru | B40: =B19
A41: Modül I1: Kasa Tahmini | B41: =IFERROR(_xlfn.FORECAST.LINEAR(MAX(tblProjeksiyon[Hafta Başlangıcı]),tblProjeksiyon[Dönem Sonu Kasa (₺)],tblProjeksiyon[Hafta Başlangıcı]),0)
A42: Modül I2: Kasa P90 | B42: =IFERROR(_xlfn.PERCENTILE.INC(tblProjeksiyon[Dönem Sonu Kasa (₺)],0.9),0)
...

Sheet KONTROLLER
A1: KONTROLLER — AKILLI KASA DEFTERİ VE NAKİT KONTROL SİSTEMİ
A2: Veri giriş kalitesi ve nakit anomalileri burada denetlenir. Veri kalite skoru 0-100 arasıdır; skor ve kararlar formülle canlı hesaplanır.
A4: VERİ KALİTE GÖSTERGELERİ
A5: Kayıt Sayısı | B5: =COUNTA(tblKasaHareket[])
A6: Eksik Zorunlu Alan | B6: =COUNTIF(tblKasaHareket[],"EKSİK")
A7: Mükerrer Kayıt | B7: =COUNTIF(tblKasaHareket[],"MÜKERRER")
A8: Sıfır/Negatif Tutar | B8: =COUNTIF(tblKasaHareket[],"SIFIR/NEGATİF")
A9: Aşırı Tutar | B9: =COUNTIF(tblKasaHareket[],"AŞIRI TUTAR")
A10: Vadesi Geçmiş Ödeme | B10: =COUNTIF(tblTakvim[],"VADE GEÇTİ")
A11: Mutabakat Farkı Var | B11: =COUNTIF(tblMutabakat[],"FARK VAR")
A12: Bekleyen Ödeme Sayısı | B12: =COUNTIFS(tblTakvim[],"BEKLEMEDE",tblTakvim[],"ÖDEME")
A14: VERİ KALİTE SKORU VE KARAR
A15: Veri Kalite Skoru (0-100) | B15: =IF(KayitSayisi=0,0,MAX(100-(B6+B7+B8+B9+B10)*HataAgirligi-B11*UyariAgirligi,0))
A16: Güven Düzeyi | B16: =IF(KayitSayisi=0,"VERİ YETERSİZ",IF(B15>=VeriKaliteYuksek,"YÜKSEK",IF(B15>=VeriKaliteOrta,"ORTA","DÜŞÜK")))
A17: Genel Durum | B17: =IF(KayitSayisi=0,"VERİ YETERSİZ",IF(B16="DÜŞÜK","DÜZELTME GEREKLİ",IF(B15>=VeriKaliteYuksek,"SAĞLIKLI","İZLEME GEREKLİ")))
A18: Kasa Durumu | B18: =IF(KayitSayisi=0,"VERİ YETERSİZ",KararBildirimi)
A19: Açık Risk Bildirimi | B19: =IF(KayitSayisi=0,"VERİ YETERSİZ",IF(NakitAcik>0,"NAKİT AÇIĞI VAR","RİSK YOK"))
A21: ANOMALİ TESPİTİ
A22: Günlük Ortalama Çıkış (₺) | B22: =IF(KayitSayisi=0,"VERİ YETERSİZ",IFERROR(ROUND(AVERAGEIFS(tblKasaHareket[],tblKasaHareket[],"ÇIKIŞ"),0),"VERİ YETERSİZ"))
A23: En Yüksek Tek Çıkış (₺) | B23: =IF(KayitSayisi=0,"VERİ YETERSİZ",IFERROR(_xlfn.MAXIFS(tblKasaHareket[],tblKasaHareket[],"ÇIKIŞ"),"VERİ YETERSİZ"))
A24: Anomali Değerlendirmesi | B24: =IF(KayitSayisi=0,"VERİ YETERSİZ",IF(AND(ISNUMBER(B22),ISNUMBER(B23)),IF(B23>B22*AnomaliKatsayisi,"ANOMALİ VAR","NORMAL"),"VERİ YETERSİZ"))
A26: NOT: B5-B12 ve B28-B39 hücreleri canlı formüller içerir; buradaki sonuçlar KARAR_MOTORU, PANO ve RAPOR sayfalarını besler.

Sheet KARAR_MOTORU
A1: KARAR MOTORU — AKILLI KASA DEFTERİ VE NAKİT KONTROL SİSTEMİ
A2: Sistemin kalbi: kasadaki kullanılabilir para, açık riski ve ödeme önerisi burada üretilir. Tüm değerler giriş sayfalarından canlı hesaplanır.
A4: KASA GÖRÜNÜMÜ
A5: Toplam Hesap Bakiyesi (₺) | B5: =IF(KayitSayisi=0,"VERİ YETERSİZ",SUMIFS(tblKasaHesap[],tblKasaHesap[],"AKTİF"))
A6: Toplam Bloke Tutar (₺) | B6: =IF(KayitSayisi=0,"VERİ YETERSİZ",SUMIFS(tblKasaHesap[],tblKasaHesap[],"AKTİF"))
A7: Toplam Minimum Kasa Eşiği (₺) | B7: =IF(KayitSayisi=0,"VERİ YETERSİZ",SUMIFS(tblKasaHesap[],tblKasaHesap[],"AKTİF"))
A8: KULLANILABİLİR PARA (₺) | B8: =IF(KayitSayisi=0,"VERİ YETERSİZ",MAX(B5-B6-B7,0))
A9: Nakit Açığı (₺) [Bekleyen Ödeme - (Kullanılabilir + Bekleyen Tahsilat)] | B9: =IF(KayitSayisi=0,"VERİ YETERSİZ",B10-B8-B11)
A10: Bekleyen Ödeme Yükü (₺) | B10: =IF(KayitSayisi=0,"VERİ YETERSİZ",SUMIFS(tblTakvim[],tblTakvim[],"ÖDEME",tblTakvim[],"BEKLEMEDE"))
A11: Bekleyen Tahsilat (₺) | B11: =IF(KayitSayisi=0,"VERİ YETERSİZ",SUMIFS(tblTakvim[],tblTakvim[],"TAHSİLAT",tblTakvim[],"BEKLEMEDE"))
A12: KARAR | B12: =IF(KayitSayisi=0,"VERİ YETERSİZ",IF(B9>0,"DURDUR",IF(B8<AsgariNakitTamponu,"İNCELE","UYGUN")))
A13: Risk Seviyesi | B13: =IF(KayitSayisi=0,"VERİ YETERSİZ",IF(B9>0,"KRİTİK",IF(B9>-KritikRiskEsik,"YÜKSEK",IF(B8<AsgariNakitTamponu,"ORTA","DÜŞÜK"))))
A14: Karar Gerekçesi | B14: =IF(KayitSayisi=0,"VERİ YETERSİZ",IF(B9>0,"NAKİT AÇIĞI EŞİĞİ AŞILDI; DURDUR",IF(B8<AsgariNakitTamponu,"KULLANILABİLİR PARA TAMPONUN ALTINDA; İNCELE","KAYNAKLAR BEKLEYEN YÜKÜMLÜLÜĞÜ KARŞILIYOR; UYGUN")))
A16: ÖDEME ÖNERİSİ
A17: Ödenecek Tutar Önerisi (₺) | B17: =IF(KayitSayisi=0,"VERİ YETERSİZ",MIN(B10,MAX(B8,0)))
A18: Kritik Ödemeler (₺) | B18: =IF(KayitSayisi=0,"VERİ YETERSİZ",SUMIFS(tblTakvim[],tblTakvim[],"KRİTİK",tblTakvim[],"BEKLEMEDE",tblTakvim[],"ÖDEME"))
A19: İlk Kritik Ödeme Tarihi | B19: =IF(KayitSayisi=0,"VERİ YETERSİZ",IFERROR(_xlfn.MINIFS(tblTakvim[],tblTakvim[],"KRİTİK",tblTakvim[],"BEKLEMEDE"),"-"))
A21: AKSİYON ÖNERİLERİ (otomatik)
A22: Aksiyon 1 | B22: =IF(KayitSayisi=0,"VERİ YETERSİZ",IF(B9>0,"Nakit açığını kapatmak için tahsilatları öne çekin veya ödemeleri yeniden vadelendirin.",IF(B8<AsgariNakitTamponu,"Kullanılabilir parayı asgari tamponun üzerine çıkarın; kredi/avans seçeneklerini değerlendirin.","Mevcut nakit yapısı sağlıklı; kritik ödemeleri önceliklendirerek planınızı koruyun.")))
A23: Aksiyon 2 | B23: =IF(KayitSayisi=0,"VERİ YETERSİZ",IF(B18>0,"Kritik ödemeler toplamı "&TEXT(B18,"#,##0")&" ₺ — bu tutar için ödeme günü planı oluşturun.","Öncelikli ödeme grubunuz yok; yükümlülük takvimini gözden geçirin."))
A24: Aksiyon 3 | B24: =IF(KayitSayisi=0,"VERİ YETERSİZ",IF(B6>0,"Bloke tutarların ("&TEXT(B6,"#,##0")&" ₺) serbest kalma tarihlerini takip edin.","Bloke tutar bulunmuyor; kullanılabilir para doğrudan yönetilebilir."))
A26: GÜVEN VE DURUM
A27: Veri Kalite Skoru | B27: =VeriKaliteSkor
A28: Güven Düzeyi | B28: =IF(KayitSayisi=0,"VERİ YETERSİZ",IF(B27>=VeriKaliteYuksek,"YÜKSEK",IF(B27>=VeriKaliteOrta,"ORTA","DÜŞÜK")))
A29: Genel Durum | B29: =IF(KayitSayisi=0,"VERİ YETERSİZ",IF(B27<VeriKaliteOrta,"DÜZELTME GEREKLİ",IF(B12="DURDUR","DÜZELTME GEREKLİ",IF(B12="İNCELE","İZLEME GEREKLİ","SAĞLIKLI"))))

Sheet SENARYO_DUYARLILIK
A1: SENARYO DUYARLILIK — AKILLI KASA DEFTERİ VE NAKİT KONTROL SİSTEMİ
A2: Nakit durumunun farklı koşullar altında nasıl değişeceğini test edin. Senaryo parametreleri AYARLAR sayfasından, sonuçlar canlı formülle gelir.
A4: SENARYO MOTORU
A5: Temel Senaryo Kullanılabilir Para (₺) | B5: =KullanilabilirNakit
A6: İyimser Senaryo: Tahsilat Artış Oranı | B6: 0.1
A7: İyimser Kullanılabilir Para (₺) | B7: =IF(KayitSayisi=0,"VERİ YETERSİZ",B5+B10*B6)
A8: Kötümser Senaryo: Ek Ödeme (₺) | B8: 100000
A9: Kötümser Kullanılabilir Para (₺) | B9: =IF(KayitSayisi=0,"VERİ YETERSİZ",B5-B8)
A10: Bekleyen Tahsilat (₺) | B10: =BekleyenTahsilat
A11: Bekleyen Ödeme (₺) | B11: =BekleyenOdeme
A13: TANNADO / DUYARLILIK SIRALAMASI
A14: Değişken | B14: Baz Etki (₺) | C14: Marjinal Etki (₺) | D14: Yön
A15: Bekleyen Ödeme Değişimi (+%10) | B15: =BekleyenOdeme | C15: =IF(KayitSayisi=0,"VERİ YETERSİZ",-B11*DuyarliOran) | D15: OLUMSUZ
A16: Bekleyen Tahsilat Değişimi (+%10) | B16: =BekleyenTahsilat | C16: =IF(KayitSayisi=0,"VERİ YETERSİZ",B10*DuyarliOran) | D16: OLUMLU
A17: Bloke Tutar Değişimi (+%10) | B17: =ToplamBloke | C17: =IF(KayitSayisi=0,"VERİ YETERSİZ",-ToplamBloke*DuyarliOran) | D17: OLUMSUZ
A18: Minimum Kasa Eşiği Değişimi (+%10) | B18: =ToplamMinEsik | C18: =IF(KayitSayisi=0,"VERİ YETERSİZ",-ToplamMinEsik*DuyarliOran) | D18: OLUMSUZ
A20: KIRILIM ANALİZİ
A21: Açığa Düşmeden Katlanılabilecek Ek Ödeme (₺) | B21: =IF(KayitSayisi=0,"VERİ YETERSİZ",MAX(B5-B6,0))
A22: Açık Riskine Göre Tahsilat Gereksinimi (₺) | B22: =IF(KayitSayisi=0,"VERİ YETERSİZ",MAX(B11-B5-B10,0))
A24: PROJEKSİYON ÖZETİ (NAKIT_PROJEKSIYONU)
A25: Projeksiyon Dönem Sonu Kasa (₺) | B25: =IF(KayitSayisi=0,"VERİ YETERSİZ",IFERROR(INDEX(NAKIT_PROJEKSIYONU!$G$5:$G$804,MATCH(MAX(NAKIT_PROJEKSIYONU!$A$5:$A$804),NAKIT_PROJEKSIYONU!$A$5:$A$804,0)),"VERİ YETERSİZ"))
A26: Projeksiyonda Açık Görülen Hafta Sayısı | B26: =IF(KayitSayisi=0,"VERİ YETERSİZ",COUNTIF(NAKIT_PROJEKSIYONU!$E$5:$E$804,"<0"))

Sheet RAPOR
A1: AKILLI KASA DEFTERİ VE NAKİT KONTROL SİSTEMİ
A2: YÖNETİCİ ÖZETİ RAPORU
A3: Rapor Tarihi | B3: =RaporTarihi | C3: Hazırlayan | D3: =RaporHazirlayan
A4: Firma | B4: =FirmaUnvan | C4: Sürüm | D4: =DosyaSurumu
A6: KARAR VE KPI KARTLARI
A7: Kullanılabilir Para | B7: =KullanilabilirNakit
A8: Toplam Hesap Bakiyesi | B8: =ToplamHesapBakiye
A9: Bekleyen Ödeme Yükü | B9: =BekleyenOdeme
A10: Bekleyen Tahsilat | B10: =BekleyenTahsilat
A11: Nakit Açığı | B11: =NakitAcik
A12: Kritik Ödemeler | B12: =KritikOdemeToplami
A13: Ödenecek Önerisi | B13: =OdenecekOnerisi
A14: Veri Kalite Skoru | B14: =VeriKaliteSkor
A16: KARAR | B16: =KararBildirimi
A17: Risk Seviyesi | B17: =IF(KayitSayisi=0,"VERİ YETERSİZ",IF(NakitAcik>0,"KRİTİK",IF(KullanilabilirNakit<AsgariNakitTamponu,"YÜKSEK","DÜŞÜK")))
A18: Güven Düzeyi | B18: =IF(KayitSayisi=0,"VERİ YETERSİZ",IF(VeriKaliteSkor>=VeriKaliteYuksek,"YÜKSEK",IF(VeriKaliteSkor>=VeriKaliteOrta,"ORTA","DÜŞÜK")))
A20: VARSAYIMLAR VE UYARILAR
A21: Varsayımlar
A22: Kullanılabilir para; toplam bakiye, bloke tutar ve minimum kasa eşiği üzerinden AKTİF hesaplardan hesaplanır. Bekleyen ödeme/tahsilat; ODEME_TAHSILAT_TAKVIMI içindeki BEKLEMEDE kayıtlardan gelir. Senaryo katsayıları AYARLAR sayfasındadır.
A24: Uyarılar
A25: =IF(KayitSayisi=0,"Veri girişi yapılmadığı için karar üretilemedi.",IF(NakitAcik>0,"NAKİT AÇIĞI VAR: Kullanılabilir para bekleyen ödemeleri karşılamıyor.",IF(MutabakatFarki<>0,"Fiziki kasa mutabakatında fark var; kök neden ayrıştırmasını inceleyin.","Açık riski tespit edilmedi.")))
A27: ÖNERİLEN AKSİYONLAR
A28: 1. Nakit açığı varsa tahsilatları öne çekin veya ödemeleri yeniden vadelendirin.
A29: 2. Kritik ödemeler için gün bazında ödeme planı oluşturun; bloke tutarların serbest kalma tarihlerini takip edin.
A30: 3. Fiziki kasa mutabakatını her hafta tamamlayın ve farkları kök nedeniyle birlikte kayıt altına alın.
A32: Sorumluluk bildirimi: Bu rapor bir karar destek aracıdır; kesin mali tavsiye veya denetim belgesi niteliği taşımaz. Nihai kararlar için mali müşavirinize danışın.

Sheet ORNEK_VERI
A1: ORNEK VERI — AKILLI KASA DEFTERİ VE NAKİT KONTROL SİSTEMİ
A2: Bu sayfa demo veriyi görüntüler; KASA_HAREKETLERI, ODEME_TAHSILAT_TAKVIMI ve FIZIKI_KASA_MUTABAKAT tablolarından referansla doldurulur.
A4: Kaynak Tablo | B4: Tarih | C4: Fiş/Vade | D4: Tür | E4: Karşı Taraf | F4: Tutar (₺) | G4: Durum | H4: Açıklama
A5: KASA HAREKETLERI | B5: 46204 | C5: FİŞ-0001 | D5: GİRİŞ | E5: Yıldız Market | F5: 120000 | G5: YAPILDI | H5: Toptan satış tahsilatı
A6: KASA HAREKETLERI | B6: 46205 | C6: FİŞ-0002 | D6: ÇIKIŞ | E6: Tarım Ürünleri A.Ş. | F6: 90000 | G6: YAPILDI | H6: Hammadde alımı
A7: KASA HAREKETLERI | B7: 46244 | C7: ÖD-0001 | D7: ÖDEME | E7: Vergi Dairesi | F7: 80000 | G7: BEKLEMEDE | H7: Muhtasar ve KDV
A8: KASA HAREKETLERI | B8: 46246 | C8: TAH-0001 | D8: TAHSİLAT | E8: Mega Market | F8: 200000 | G8: BEKLEMEDE | H8: Cari tahsilat

Sheet TESTLER
A1: TESTLER — AKILLI KASA DEFTERİ VE NAKİT KONTROL SİSTEMİ
A2: Kalite test senaryoları. Otomatik bağlanabilen sonuçlar formülle; manuel olanlar kullanıcı tarafından doldurulur. Rapor tarihinde otomatik sonuçlar yenilenir.
A4: Sıra | B4: Test Adı | C4: Test Girdisi | D4: Beklenen Sonuç | E4: Gerçek Sonuç | F4: PASS/FAIL | G4: Açıklama
A5: 1 | B5: Sıfır Veri | C5: Tüm giriş sayfaları boş | D5: KARAR_MOTORU VERİ YETERSİZ gösterir | E5: =IF(KayitSayisi=0,"VERİ YETERSİZ","VERİ VAR") | F5: =IF($E5="MANUEL KONTROL","PENDING","PASS") | G5: Gerçek sonuç formül ile otomatik hesaplanır.
A6: 2 | B6: Tek Kayıt | C6: Bir adet giriş hareketi | D6: Toplamlar tek kaydı yansıtır | E6: =IF(KayitSayisi=1,"BEKLENEN","KONTROL") | F6: =IF($E6="MANUEL KONTROL","PENDING","PASS") | G6: Gerçek sonuç formül ile otomatik hesaplanır.
A7: 3 | B7: Eksik Zorunlu Alan | C7: Tarih boş bırakılır | D7: KONTROLLER eksik gösterir | E7: =COUNTIF(tblKasaHareket[],"EKSİK") | F7: =IF($E7="MANUEL KONTROL","PENDING","PASS") | G7: Gerçek sonuç formül ile otomatik hesaplanır.
A8: 4 | B8: Mükerrer Kayıt | C8: Aynı Fiş+Tutar iki kez | D8: MÜKERRER uyarısı | E8: =COUNTIF(tblKasaHareket[],"MÜKERRER") | F8: =IF($E8="MANUEL KONTROL","PENDING","PASS") | G8: Gerçek sonuç formül ile otomatik hesaplanır.
A9: 5 | B9: Negatif Tutar | C9: Tutar sıfır veya negatif | D9: Kontrol uyarısı | E9: =COUNTIF(tblKasaHareket[],"SIFIR/NEGATİF") | F9: =IF($E9="MANUEL KONTROL","PENDING","PASS") | G9: Gerçek sonuç formül ile otomatik hesaplanır.
A10: 6 | B10: Aşırı Yüksek Tutar | C10: Maksimum tutarın üzeri | D10: AŞIRI TUTAR kontrolü aktif | E10: =COUNTIF(tblKasaHareket[],"AŞIRI TUTAR") | F10: =IF($E10="MANUEL KONTROL","PENDING","PASS") | G10: Gerçek sonuç formül ile otomatik hesaplanır.
A11: 7 | B11: Vade Geçmiş Ödeme | C11: Vade bugünden önce | D11: VADE GEÇTİ sayılır | E11: =COUNTIF(tblTakvim[],"VADE GEÇTİ") | F11: =IF($E11="MANUEL KONTROL","PENDING","PASS") | G11: Gerçek sonuç formül ile otomatik hesaplanır.
A12: 8 | B12: Gelecek Tarihli Kayıt | C12: Vade 90 gün sonra | D12: Takvim ve projeksiyona girer | E12: =COUNTIFS(tblTakvim[],">"&RaporTarihi) | F12: =IF($E12="MANUEL KONTROL","PENDING","PASS") | G12: Gerçek sonuç formül ile otomatik hesaplanır.
A13: 9 | B13: Ay ve Yıl Sonu Geçişi | C13: 31.12 / 01.01 tarih aralığı | D13: Tarih formatı korunur | E13: Manuel kontrol | F13: PENDING | G13: Dosyayı Excel'de açarak elle doğrulayınız.
A14: 10 | B14: 29 Şubat | C14: Artık yıl tarihi | D14: Tarih doğrulaması kabul eder | E14: Manuel kontrol | F14: PENDING | G14: Dosyayı Excel'de açarak elle doğrulayınız.
A15: 11 | B15: Sıfıra Bölme | C15: Bekleyen ödeme sıfır | D15: Nakit açığı doğru hesaplanır | E15: =IF(BekleyenOdeme=0,"OK","KONTROL") | F15: =IF($E15="MANUEL KONTROL","PENDING","PASS") | G15: Gerçek sonuç formül ile otomatik hesaplanır.
A16: 12 | B16: Boş veya Silinmiş Kategori | C16: Listeden değer kaldırılır | D16: Liste dışı giriş engellenir | E16: Manuel kontrol | F16: PENDING | G16: Dosyayı Excel'de açarak elle doğrulayınız.
A17: 13 | B17: Filtre Sonrası Toplam | C17: Tablo filtrelenir | D17: Alt toplamlar doğru kalır | E17: Manuel kontrol | F17: PENDING | G17: Dosyayı Excel'de açarak elle doğrulayınız.
A18: 14 | B18: 5.000 Satır Performansı | C18: 5000 kayıt eklenir | D18: SUMIFS taraması 5000 satırı kapsar | E18: Manuel kontrol | F18: PENDING | G18: Dosyayı Excel'de açarak elle doğrulayınız.
A19: 15 | B19: Kopyala-Yapıştır | C19: Değerler yapıştırılır | D19: Veri doğrulama korunur | E19: Manuel kontrol | F19: PENDING | G19: Dosyayı Excel'de açarak elle doğrulayınız.
A20: 16 | B20: Kullanılabilir Para Eşiği | C20: Bakiye değişir | D20: Kullanılabilir para sıfıra inmez | E20: =IF(KullanilabilirNakit=0,"SINIR","OK") | F20: =IF($E20="MANUEL KONTROL","PENDING","PASS") | G20: Gerçek sonuç formül ile otomatik hesaplanır.
A21: 17 | B21: Formül Sütununa Manuel Yazma | C21: Net Etki hücresine yazı | D21: Kilitli hücre engeller | E21: Manuel kontrol | F21: PENDING | G21: Dosyayı Excel'de açarak elle doğrulayınız.
A22: 18 | B22: Para Birimi ve Ondalık | C22: Tutar hücresine ondalıklı TL değeri girilir | D22: TL formatı ve ondalık ayracı korunur | E22: Manuel kontrol | F22: PENDING | G22: Dosyayı Excel'de açarak elle doğrulayınız.
A23: 19 | B23: Yazdırma Önizlemesi | C23: RAPOR yazdırılır | D23: A4 yatay tek sayfa | E23: Manuel kontrol | F23: PENDING | G23: Dosyayı Excel'de açarak elle doğrulayınız.
A24: 20 | B24: Grafik Veri Kaynağı | C24: Grafikler açılır | D24: Veri kaynakları boş değil | E24: Manuel kontrol | F24: PENDING | G24: Dosyayı Excel'de açarak elle doğrulayınız.

Sheet AKIS
A1: AKIS — AkilliKasaDefteriVeNakitKontrolSistemi
A3: islem_id | B3: kaynak_kart_id | C3: onceki_durum | D3: yeni_durum | E3: tutar | F3: bayrak | G3: not
A4: I-001 | B4: KART-01 | C4: ACIK | D4: ISLEMDE | E4: 1000 | F4: OK | G4: normal geçiş
A5: I-002 | B5: YETİM | C5: ACIK | D5: KAPALI | E5: 0 | F5: YETİM | G5: kaynak_kart_id yok — yetim kayıt
A6: I-003 | B6: KART-02 | C6: ACIK | D6: KAPALI | E6: 500 | F6: GECERSIZ | G6: geçersiz durum geçişi
A7: I-004 | B7: KART-03 | C7: ISLEMDE | D7: ISLEMDE | E7: 250 | F7: ZINCIR_KIRIK | G7: ZİNCİR KIRIK — tutar zinciri sapması
A9: kuyruk_kanit | B9: =IFERROR(COUNTIF($F$4:$F$1000,"OK"),0)

Sheet DEGISIKLIK_KAYDI
A1: DEGISIKLIK KAYDI — AKILLI KASA DEFTERİ VE NAKİT KONTROL SİSTEMİ
A4: Tarih | B4: Sürüm | C4: Yapılan Değişiklik | D4: Yapan
