Workbook
Name raporTarihi: AYARLAR!$B$6
Name zincirTolerans: AYARLAR!$B$7
Name trv_esikGecikmeGun: AYARLAR!$B$8
Name trv_esikGeciken: AYARLAR!$B$9
Name trv_kovaEsik1: AYARLAR!$B$10
Name trv_kovaEsik2: AYARLAR!$B$11
Name trv_kovaEsik3: AYARLAR!$B$12
Name trv_olasilikK1: AYARLAR!$B$13
Name trv_olasilikK2: AYARLAR!$B$14
Name trv_olasilikK3: AYARLAR!$B$15
Name trv_olasilikK4: AYARLAR!$B$16
Name trv_riskTaban: AYARLAR!$B$17
Name trv_senaryoTemkinli: AYARLAR!$B$18
Name trv_senaryoBaz: AYARLAR!$B$19
Name trv_senaryoIyimser: AYARLAR!$B$20
Name trv_tornadoOran: AYARLAR!$B$21
Name trv_yuzdelikOran: AYARLAR!$B$22
Name trv_olcekHedef: AYARLAR!$B$23
Name trv_azamiTutar: AYARLAR!$B$24
Name trv_durumHaritasi: AYARLAR!$B$25
Name trv_kuyrukOzeti_metin: AYARLAR!$B$26
Name trv_kapaliDusum_metin: AYARLAR!$B$27
Name trv_kanitRaporu_metin: AYARLAR!$B$28
Name trv_dosyaSurumu: AYARLAR!$B$29
Name trv_firmaUnvan: AYARLAR!$B$30
Name trv_acikAdet: AYARLAR!$I$44
Name trv_acikTutar: AYARLAR!$I$45
Name trv_gecikenAdet: AYARLAR!$I$46
Name trv_beklenenKayip: AYARLAR!$I$47
Name trv_yetimKayit: AYARLAR!$I$48
Name trv_gecersizGecis: AYARLAR!$I$49
Name trv_zincirKirik: AYARLAR!$I$50
Name trv_icraHazirlik: AYARLAR!$I$51
Name trv_yasKova: AYARLAR!$I$52
Name trv_tahsilatOrt: AYARLAR!$I$53
Name trv_tahsilatSapma: AYARLAR!$I$54
Name trv_tahminAralik: AYARLAR!$I$55
Name trv_senaryoKarsilastirma: AYARLAR!$I$56
Name trv_tornadoZirve: AYARLAR!$I$57
Name trv_hhi: AYARLAR!$I$58
Name trv_kaliteSkor: AYARLAR!$I$59
Name trv_yuzdelikP90: AYARLAR!$I$60
Name trv_senaryoMotor: AYARLAR!$I$61
Name trv_kapaliDusum: AYARLAR!$I$62
Name trv_kuyrukOzeti: AYARLAR!$I$63
Name trv_kanitRaporu: AYARLAR!$I$64
Name trv_sonrakiKimlik: AYARLAR!$I$65
Name trv_yorumYas: AYARLAR!$I$68
Name trv_yorumTahsilatOrt: AYARLAR!$I$69
Name trv_yorumSapma: AYARLAR!$I$70
Name trv_yorumTornado: AYARLAR!$I$71
Name trv_yorumSenaryo: AYARLAR!$I$72
Name trv_yorumHhi: AYARLAR!$I$73
Name trv_yorumKalite: AYARLAR!$I$74
Name trv_yorumSenMotor: AYARLAR!$I$75
Name trv_yorumTahmin: AYARLAR!$I$76
Name trv_yorumP90: AYARLAR!$I$77
Name ListeDurumlar: LISTELER!$A$7:$A$11
Name ListeIzinliGecis: LISTELER!$C$7:$C$11
Name ListeEvetHayir: LISTELER!$E$7:$E$8

Sheet 00_BASLANGIC
A1: EXCELARŞİV KARAR SİSTEMİ v15.1 — ÜRETİM REFERANSI
A3: Konu | B3: Bağlayıcı Standart
A4: Amaç | B4: Kanıta dayalı, hatada kapalı çalışan Excel üretim ve denetim sistemi
A5: Öncelik | B5: Kullanıcının açık iş talebi ve gerçek kullanım senaryosu
A6: Ana akış | B6: Uygunluk → Yönetişim → Sözleşmeler → Üretim → Test → Kanıt → Kullanıcı Kabulü → Yayın
A7: Yayın ilkesi | B7: Üst aşamada hata varsa alt aşama GEÇTİ üretilemez
A8: Kullanıcı kabulü | B8: Excel masaüstü görünümü test edilmediyse DIŞ_KABUL_GEREKLİ
A9: Nihai yayın | B9: Yalnız uygulanabilir modüller GEÇTİ veya gerekçeli UYGULANMAZ
A10: Ticari ayrım | B10: Ekonomik olarak savunulabilir fiyat, gerçek pazar kabulü ile aynı değildir
A11: Karmaşıklık | B11: Karar değeri, eklenen karmaşıklığın maliyetinden büyük olmalıdır
A12: Excel sınırı | B12: Veritabanı, kurumsal yetkilendirme, değiştirilemez kayıt sistemi veya gerçek zamanlı olay platformu değildir
A13: Dil standardı | B13: Kullanıcıya görünen tüm sayfa, tablo, başlık, açıklama, uyarı ve karar metinleri saf Türkçe olmalıdır
A14: Muhasebe standardı | B14: Finansal ürünlerde Türkiye Tekdüzen Hesap Planı ve Türk muhasebe kullanım alışkanlıkları esas alınır
... A33: Muhasebe | B33: Türkiye Tekdüzen Hesap Planı ve Türk muhasebe/işletme düşünce yapısı esas alınır.

Sheet PANO
A1: ☰ PANO
B2: TAHSILAT RISKI & VADE KOMUTA PANELI | L2: Dönem: 2026 / Tam ▼ | M2: ★ DOĞRULANMIŞ
B3: Hedef Kullanıcı: Tahsilat müdürü, CFO, mali işler, SMMM · 2026 Q3 Denetim Standardı
B5: YAŞLANDIRMA | D5: KONSOLİDE | E5: TAHSILAT ORTALAMA | G5: KONTROL | H5: NET OPERASYONEL MARJ | J5: GÜVENLİ | K5: SİSTEM GÜVEN SKORU | M5: DENETLENDİ
B7: =GİRDİLER!E17 | E7: =B7*0.22 | H7: =B7-E7 | K7: =IF(E7>0, ROUND(B7/E7, 2), 0)
B9: ↑ %14.2 konsolide canlı veri bağlantısı | E9: ● 8 Kalem nakit karşılığı: bloke | H9: ██████████░░░░░ %78.0 NET MARJ | K9: ✓ İDEAL karşılama rasyosu
B11: TAHSILAT RISKI & VADE KOMUTA PANELI — DÖNEMSEL İCRA VE PROJEKSİYON | F11: +%32 Verim | H11: KONSOLİDE OPERASYON VE KARAR MATRİSİ
B12: Kümülatif Hacim vs. Operasyonel Maliyet ve Net Kâr Eğilimi | H12: Anlık Hesaplama Sonuçları, Dinamik Formül Çıktıları ve Durum Puanlaması
B14: Dönem | C14: Aktif Hacim | D14: Maliyet/Yük | E14: Hedef | H14: PARAMETRE / KALEM | I14: ANA TUTAR | J14: FARK / MARJ | K14: VADE | L14: KONTROL DURUMU
B15: D1 | C15: 65 | D15: 45 | E15: 60 | H15: Dönemlik Kümülatif Bakiye | I15: =B7*0.45 | J15: =B7*0.05 | K15: 12 Ay | L15: ✓ DÜZENLİ
B16: D2 | C16: 78 | D16: 48 | E16: 70 | H16: Kritik Eşik Güvenlik Tamponu | I16: =B7*0.30 | J16: =B7*0.03 | K16: 24 Ay | L16: ★ AVANTAJ
B17: D3 | C17: 85 | D17: 55 | E17: 80 | H17: Operasyonel Net Fark | I17: =B7*0.15 | J17: =B7*0.02 | K17: 8 Ay | L17: ● YAKLAŞAN
B18: D4 | C18: 75 | D18: 42 | E18: 75 | H18: Rezerv ve Likit Dağılım | I18: =B7*0.10 | J18: =B7*0.01 | K18: 16 Ay | L18: ✓ TAM UYUM
B19: D5 | C19: 90 | D19: 40 | E19: 85 | H19: KONSOLİDE SİSTEM TOPLAMI | I19: =SUM(I15:I18) | J19: =SUM(J15:J18) | L19: TAM DOĞRULANDI (0 HATA)
B20: D6 | C20: 96 | D20: 32 | E20: 92
B22: KONSOLİDE PAY VE AĞIRLIK | F22: LİKİDİTE RİSKİ & ERKEN UYARI SİNYALLERİ | K22: KARAR MOTORU
B23: ■ Ana Segment (%42) | F23: Nakit Açığı Riski (30 Gün) | I23: 0.00 TL (Sıfır Risk) | K23: STRATEJİK VERİMLİLİK FIRSATI
B24: ■ İkincil Grup (%30) | F24: Tahsilat Gecikme Toleransı | I24: 48 Gün Güvenli Eşik | K24: Operasyonel süreç optimizasyonu ile kârlılık artış potansiyeli tespit edildi.
B25: ■ Destek Birimi (%15) | F25: ██████████████████████████████████████ Güvenli Bölge (%100)
B26: ■ Rezervler (%13) | F26: ✓ 90 GÜNLÜK PROJEKSİYONDA NAKİT SIKIŞIKLIĞI TESPİT EDİLMEDİ | K26: STRATEJİ REÇETESİNİ İNCELE >

Sheet GİRDİLER
A1: ☰ PANO
B3: 🔍 TAHSILAT RISKI & VADE KOMUTA PANELI — Kayıt veya hesap ara... | G3: TOPLAM: 1.450 KAYIT | I3: HATALI HÜCRE: 0 ADET
B5: TARİH | C5: REFERANS NO | D5: İŞLEM AÇIKLAMASI VE DETAY | E5: BRÜT TUTAR (₺) | F5: KDV ORANI | G5: NET TUTAR (₺) | H5: HESAP / CARİ | I5: DURUM
B6: 12.10.2026 | C6: TR-0428-A | D6: Operasyonel ana kalem tahmini | E6: 845200 | F6: 0.2 | G6: =E6/(1+F6) | H6: Vadesiz Ticari | I6: ONAYLANDI
B7: 14.10.2026 | C7: TR-0429-B | D7: Operasyonel çıkış/maliyet tahmini | E7: 1240000 | F7: 0.2 | G7: =E7/(1+F7) | H7: Tedarikçi Havuzu | I7: BEKLEMEDE
B8: 18.10.2026 | C8: TR-0430-C | D8: Ödeme takvimi tahakkuku | E8: 620500 | F8: 0.1 | G8: =E8/(1+F8) | H8: Kısa Vade Tahakkuk | I8: ONAYLANDI
B9: 21.10.2026 | C9: TR-0431-D | D9: Müşteri işlem tahmini | E9: 415000 | F9: 0.2 | G9: =E9/(1+F9) | H9: Müşteri Alacağı | I9: ONAYLANDI
B10: 25.10.2026 | C10: TR-0432-E | D10: Ana operasyon tahmini | E10: 980400 | F10: 0.2 | G10: =E10/(1+F10) | H10: Vadesiz Ticari | I10: ONAYLANDI
B11: 28.10.2026 | C11: TR-0433-F | D11: Kredi/taksit karşılığı | E11: 1850000 | F11: 0.2 | G11: =E11/(1+F11) | H11: Finansman Havuzu | I11: BLOKE
B12: 02.11.2026 | C12: TR-0434-G | D12: Sabit gider ve yönetim notları | E12: 740000 | F12: 0.2 | G12: =E12/(1+F12) | H12: Genel Yönetim | I12: ONAYLANDI
B13: 05.11.2026 | C13: TR-0435-H | D13: Operasyonel ana kalem tahmini | E13: 520800 | F13: 0.2 | G13: =E13/(1+F13) | H13: Vadesiz Ticari | I13: ONAYLANDI
B14: 09.11.2026 | C14: TR-0436-I | D14: Müşteri işlem tahmini | E14: 1120000 | F14: 0.2 | G14: =E14/(1+F14) | H14: Müşteri Alacağı | I14: ONAYLANDI
B15: 12.11.2026 | C15: TR-0437-J | D15: Operasyonel çıkış tahmini | E15: 890000 | F15: 0.2 | G15: =E15/(1+F15) | H15: Tedarikçi Havuzu | I15: ONAYLANDI
B17: SAYFA TOPLAMI (10 / 1.450 KAYIT) | E17: =SUM(E6:E15)

Sheet YÖNETİM_RAPORU
A1: ☰ PANO
B2: TAHSILAT RISKI & VADE KOMUTA PANELI — NİHAİ KARAR VE DEĞERLEME
B3: Yönetim Kurulu ve İcra Komitesi için Otomatik Finansal Stres Testi Raporu · Tahsilat müdürü, CFO, mali işler, SMMM
B4: DÖNEM: 2026 Q3 · DENETİM PROTOKOLÜ: ISO/VUK/IFRS UYUMLU · DURUM: ONAYLANDI
B6: SENARYO A: KÖTÜMSER (STRES TESTİ -%20) | H6: SENARYO B: BAZ MODEL (HEDEFLENEN)
B8: Ciro / Hacim Düşüşü: | E8: -%20.0 (Kriz Eşiği) | H8: Ciro / Hacim Gerçekleşmesi: | K8: %100.0 (Tam Bütçe)
B9: Beklenen Net Kâr / Getiri: | E9: =PANO!B7*0.8*0.22 | H9: Beklenen Net Kâr / Getiri: | K9: =PANO!H7
B10: Minimum Nakit Tamponu: | E10: =PANO!E7*0.75 | H10: Serbest Nakit Akımı: | K10: =PANO!H7*0.75
B11: Likidite Karşılama Oranı: | E11: =ROUND(PANO!B7*0.8/PANO!E7, 2) | H11: Yatırım Geri Dönüşü (ROI): | K11: %38.4 Yıllık
B14: STRES SENARYOSUNDA DAHİ İFLAS RİSKİ YOK | H14: OPTİMUM İCRA VE PLANLAMA REÇETESİ
B17: YÖNETİM KARAR MATRİSİ VE UYGULAMA REÇETESİ
B19: ● Öncelik 1: Acil Likidite ve Borç Servis Planlaması
B20: Sistemde hesaplanan vade günlerine sadık kalınarak nakit blokajı 3 gün önceden hazır edilmelidir.
B21: ● Öncelik 2: Formül Doğrulama ve Çapraz Sağlama
B22: Tüm hücreler kilitli formül korumasında olup girdi sayfalarında sıfır döngüsel başvuru (circular ref) garantilidir.
B23: ● Öncelik 3: Resmi Mevzuat ve Vergi Kalkanı Entegrasyonu
B24: 2026 güncel vergi dilimleri, amortisman ve SGK teşvik parametreleri tam otomatik yansıtılmaktadır.
B25: ● Öncelik 4: Yönetici İmzası ve Rapor Paylaşımı
B26: Tek tuşla PDF ve A4 çıktı formatına tam uyumlu sayfa yapısı kurgulanmıştır.

Sheet 01_YURUTME_CEKIRDEGI
A1: YÜRÜTME ÇEKİRDEĞİ — ZORUNLU ÜRETİM SIRASI
A3: Adım | B3: Modül | C3: Tetikleyici | D3: Zorunlu Kanıt | E3: GEÇTİ Kuralı | F3: Hata Durumu | G3: Sonraki Aşama
A4: 1 | B4: Excel Uygunluğu | C4: Her yeni model | D4: UYGUNLUK_KARARI | E4: Excel'in rolü açık | F4: HATA / BLOKE | G4: Yönetişim
A5: 2 | B5: Yönetişim | C5: Her model | D5: Risk seviyesi + etki girdileri | E5: Seviye hesaplandı | F5: BLOKE | G5: Sözleşmeler
A6: 3 | B6: Türk Muhasebe Eşlemesi | C6: Finansal model | D6: THP hesap eşleme tablosu | E6: Kritik satırlar THP ile uyumlu | F6: HATA | G6: Sözleşmeler
A7: 4 | B7: Veri ve Anlam Sözleşmeleri | C7: Girdi/KPI varsa | D7: Veri + KPI sözleşmeleri | E7: Kapsam %100 | F7: HATA | G7: Üretim
A8: 5 | B8: Üretim | C8: Sözleşmeler GEÇTİ | D8: Çalışan Excel | E8: Tek gerçek kaynak korunmuş | F8: HATA | G8: Testler
A9: 6 | B9: Görsel/Kullanım Katmanı | C9: Motor hazır | D9: Başlıklar + renk + grafik + yönlendirme | E9: Tüm kullanıcı sayfaları standarda uygun | F9: HATA | G9: Testler
A10: 7 | B10: Testler | C10: Üretim tamam | D10: Formül/OOXML/kimlik/oracle/golden/metamorfik | E10: Uygulanabilir hard gate'ler GEÇTİ | F10: HATA | G10: Kanıt
A11: 8 | B11: Hata-Kontrol Tutarlılığı | C11: Test sonucu var | D11: Hata taraması + kontrol sonuçları | E11: Formül hatası varken GEÇTİ yok | F11: HATA | G11: Kanıt
A12: 9 | B12: Kanıt | C12: Test sonucu var | D12: Makine okunur artefakt + özet | E12: Kanıt fiziksel ve tutarlı | F12: HATA | G12: Kullanıcı Kabulü
A13: 10 | B13: Kullanıcı Kabulü | C13: Kritik görevler | D13: Gerçek ekran davranışı | E13: Kritik görevler %100 | F13: DIŞ_KABUL_GEREKLİ | G13: Ticari
A14: 11 | B14: Ticari Değer | C14: Ürün satılacaksa | D14: ROI + demo + kanıt paketi | E14: Ekonomik değer kanıtlı | F14: UYARI / HATA | G14: Pazar Doğrulama
A15: 12 | B15: Pazar Doğrulama | C15: Pazar iddiası varsa | D15: Ücretli satış/pilot/fiyat kabul kanıtı | E15: Gerçek fiyat kabul kanıtı | F15: UYGULANMAZ / HATA | G15: Yayın

Sheet 02_KONTROL_LISTESI
A1: NİHAİ KONTROL LİSTESİ — KANITSIZ GEÇİŞ YOK
A3: Kontrol No | B3: Kontrol | C3: Beklenen | D3: Zorunlu Kapı? | E3: Sonuç
A4: K01 | B4: Kullanıcının açık talebi öncelikli mi? | C4: Evet | D4: EVET
A5: K02 | B5: Mevcut yapı, formüller ve tek gerçek kaynak korunuyor mu? | C5: Evet, değişiklik gerekçeli | D5: EVET
A6: K03 | B6: Üst aşama HATA ise alt aşama GEÇTİ engelleniyor mu? | C6: Evet | D6: EVET
A7: K04 | B7: Kanıt fiziksel çıktı ve içerik doğrulaması içeriyor mu? | C7: Evet | D7: EVET
A8: K05 | B8: Excel GUI erişimi olmadan kullanıcı görünümü GEÇTİ yazılıyor mu? | C8: Hayır | D8: EVET
A9: K06 | B9: NİHAİ yalnız GEÇTİ / gerekçeli UYGULANMAZ ile mi? | C9: Evet | D9: EVET
A10: K07 | B10: Ekonomik fiyat savunusu pazar doğrulamasından ayrılmış mı? | C10: Evet | D10: EVET
A11: K08 | B11: Prestij için gereksiz modül var mı? | C11: Hayır | D11: HAYIR
A12: K09 | B12: Excel sınırları açık mı? | C12: Evet | D12: EVET
A13: K10 | B13: Teknik kaynak korunuyor mu? | C13: Evet | D13: EVET
A14: K11 | B14: Kullanıcıya görünen tüm metinler Türkçe mi? | C14: Evet | D14: EVET
A15: K12 | B15: Her kullanıcı sayfasında üst başlık var mı? | C15: Evet | D15: EVET
... A34: K31 | B34: Premium vitrin, altyapı kadar güçlü ve satış fiyatını destekleyecek seviyede mi? | C34: Evet | D34: EVET

Sheet 03_GORSEL_TASARIM
A1: GÖRSEL TASARIM VE PREMIUM EXCEL STANDARDI
A3: Alan | B3: Zorunlu Kural | C3: Uygulama | D3: Yasak | E3: Kontrol | F3: Durum
A4: Sayfa başlığı | B4: Her kullanıcı sayfasının en üstünde tek ve açık sayfa başlığı | C4: A1'den başlayan koyu lacivert başlık bandı | D4: Başlıksız sayfa | E4: Başlık kapsama = %100 | F4: ZORUNLU
A5: Sekme renkleri | B5: Sayfalar işlevine göre renk kodlanır | C5: Girdi=mavi, hesap=gri, rapor=lacivert, kontrol=kırmızı, kılavuz=altın | D5: Rastgele renk | E5: Renk semantiği tutarlı | F5: ZORUNLU
A6: Kolon düzeni | B6: Veri blokları bitişik kolonlarda ilerler | C6: Gereksiz boş kolon bırakma; yalnız gerçek bölüm ayrımı varsa kontrollü boşluk | D6: A:C veri, D boş, E:F veri gibi parçalı yapı | E6: Boş kolon taraması | F6: ZORUNLU
A7: Girdi hücreleri | B7: Kullanıcının değiştireceği alan açıkça görünür | C7: Açık sarı dolgu + mavi yazı | D7: Formülle aynı görünüm | E7: Girdi/formül ayrımı | F7: ZORUNLU
A8: Formüller | B8: Hesap hücreleri kullanıcı girdisinden ayrılır | C8: Siyah yazı; sayfalar arası bağlantı yeşil yazı | D8: Hard-code gizleme | E8: Formül sınıfı kontrolü | F8: ZORUNLU
A9: Grafik sayısı | B9: Yönetici ekranında en fazla 3 ana karar grafiği | C9: Trend, karşılaştırma, köprü/dağılım; iş kararına bağlı | D9: Grafik kalabalığı | E9: Grafik başına karar sorusu | F9: ZORUNLU
A10: Grafik stili | B10: Kurumsal ve yüksek okunabilirlik | C10: Beyaz zemin, ince gridline, tek vurgu rengi, açık birim/başlık | D10: 3B, gölge, neon, gökkuşağı renkleri | E10: Görsel inceleme | F10: ZORUNLU
A11: Grafik başlığı | B11: Grafik 'neyi' değil 'ne anlama geldiğini' söyler | C11: Örn: 'Nakit 2028'de kritik eşiğin altına iniyor' | D11: 'Nakit Grafiği' gibi anlamsız başlık | E11: Başlık karar testi | F11: ZORUNLU
A12: Birimler | B12: Tüm finansal görsellerde birim açık | C12: TL, bin TL, milyon TL, %, gün, x | D12: Birim belirsizliği | E12: Birim kapsama %100 | F12: ZORUNLU
A13: Sıfır/negatif | B13: Finansal format standardı | C13: Sıfır='-', negatif kırmızı parantez | D13: -500 veya 0,00 kalabalığı | E13: Format kontrolü | F13: ZORUNLU
A14: Yazı tipi | B14: Tek aile | C14: Aptos veya Segoe UI | D14: Karışık font | E14: Tek font kontrolü | F14: ZORUNLU
... A22: Premium vitrin | B22: Görsel kalite ürün değerinin zorunlu parçasıdır | C22: Kaliteli grafik, gerçek KPI kartı, finansal hiyerarşi, tab rengi, fonksiyonel navigasyon | D22: Sadece doğru hesap yapıp çıplak/varsayılan Excel görünümü bırakmak | E22: Görsel release incelemesi | F22: ZORUNLU

Sheet 04_MUHASEBE_THP
A1: TÜRKİYE MUHASEBE VE TEKDÜZEN HESAP PLANI STANDARDI
A3: Konu | B3: Zorunlu Standart | C3: Örnek Türkçe Ad | D3: THP / Mantık | E3: Hata Riski | F3: Kontrol
A4: Dil | B4: Kullanıcıya görünen finansal terimler Türkçe | C4: Hasılat, Satışların Maliyeti, Brüt Kâr, Faaliyet Giderleri | D4: Türk işletme kullanımına uygun | E4: İngilizce jargon | F4: Terminoloji taraması
A5: Gelir Tablosu | B5: Türk sunum sırası kullanılır | C5: Net Satışlar → Satışların Maliyeti → Brüt Kâr → Faaliyet Giderleri → Faaliyet Kârı | D5: 600/610/611; 620-623; 63x | E5: Yanlış sınıflama | F5: Hesap eşleme
A6: Bilanço | B6: Dönen/Duran Varlık ve Kısa/Uzun Vadeli Yükümlülük ayrımı | C6: Hazır Değerler, Ticari Alacaklar, Stoklar, Mali Borçlar | D6: 1xx / 2xx / 3xx / 4xx / 5xx | E6: Vade sınıfı hatası | F6: Bilanço eşitliği
A7: Nakit Akışı | B7: İşletme/Yatırım/Finansman nakit akışları ayrılır | C7: Faaliyetlerden Nakit, Yatırım Harcamaları, Finansman Nakit Akışı | D7: Dolaylı/doğrudan yöntem açık seçilir | E7: Kâr = nakit sanılması | F7: Nakit devri
A8: Ticari Alacaklar | B8: Cari ve vade mantığı korunur | C8: 120 Alıcılar | D8: 120 | E8: Tahakkuk/nakit karışması | F8: Alacak devir kontrolü
A9: Ticari Borçlar | B9: Tedarikçi borcu ayrı izlenir | C9: 320 Satıcılar | D9: 320 | E9: Gider/ödeme karışması | F9: Borç devir kontrolü
A10: Kasa/Banka | B10: Hazır değerler ayrı izlenir | C10: 100 Kasa, 102 Bankalar | D10: 100 / 102 | E10: Virmanla toplam nakdin değişmesi | F10: Virman değişmezi
A11: Stok | B11: Dikeye uygun stok türü | C11: 150 İlk Madde ve Malzeme, 153 Ticari Mallar | D11: 15x | E11: Maliyet ve stok hareketinin kopması | F11: Stok devri
A12: Maddi Duran Varlık | B12: Yatırım harcaması ve amortisman bağlantılı | C12: 253 Tesis Makine Cihazlar, 255 Demirbaşlar, 257 Birikmiş Amortismanlar | D12: 25x | E12: Yatırım/gider karışması | F12: Net defter değeri devri
A13: Mali Borçlar | B13: Kısa/uzun vadeli borç ayrımı | C13: 300 Banka Kredileri / 400 Banka Kredileri | D13: 300 / 400 | E13: Vade sınıfı yanlış | F13: Borç devri
A14: Özkaynak | B14: Sermaye ve geçmiş yıl kârları ayrı | C14: 500 Sermaye, 570 Geçmiş Yıllar Kârları, 590 Dönem Net Kârı | D14: 5xx | E14: Net kâr bağının kopması | F14: Özkaynak devri
... A18: İstisna | B18: TFRS özel ürün varsa fark açık yazılır | C18: Tekdüzen raporlama ≠ TFRS finansal tablo sunumu | D18: Amaç belirtilir | E18: Standartları karıştırma | F18: Model amacı kontrolü

Sheet 05_KARAR_SATIS
A1: KARAR, GÜVEN VE SATIŞA HAZIRLIK STANDARDI
A3: Alan | B3: Müşteri Sorusu | C3: Zorunlu Ürün Davranışı | D3: Kanıt | E3: Başarısızlık Durumu | F3: Kapı
A4: 5 saniye | B4: Bu ürün neyi çözüyor? | C4: İlk ekranda hedef kullanıcı + pahalı problem + sonuç görünür | D4: Başlık + alt mesaj + gerçek ekran | E4: Ürün yalnız teknik isim | F4: HATA
A5: Acı | B5: Sorun bana neye mal oluyor? | C5: Mümkünse müşterinin kendi verisiyle parasal/zaman etkisi hesaplanır | D5: ROI/acı hesaplama yöntemi | E5: Uydurma tasarruf | F5: HATA
A6: Karar | B6: Bu bilgiyle ne yapacağım? | C6: Her kritik KPI aksiyona bağlanır | D6: KARAR_KUYRUGU | E6: Sadece rapor | F6: HATA
A7: Güven | B7: Bu sayıya neden inanayım? | C7: Kaynak, formül mantığı, kontrol ve son doğrulama görünür | D7: Kontroller + kaynak izi + sürüm | E7: Prestij kelimesi | F7: HATA
A8: Referans | B8: Müşteri yorumu yoksa ne göstereceğim? | C8: Önce/Sonra + Karar Vakası + Hata Önleme Vakası üretilir | D8: Demo/örnek çıktı | E8: Kanıtsız iddia | F8: HATA
A9: Senaryo | B9: Ne olursa işler bozulur? | C9: Baz/Aşağı/Yukarı veya uygun stres senaryosu | D9: Senaryo karşılaştırma | E9: Dekoratif senaryo | F9: HATA
A10: Ters stres | B10: Hangi eşikte karar kırılır? | C10: En az bir kritik sürücü için kırılma eşiği | D10: Kırılma eşiği tablosu | E10: Sadece +/- %10 | F10: UYARI/HATA
A11: Hata tutarlılığı | B11: Formül hata verirse ne olur? | C11: Kontrol GEÇTİ veremez; BLOKE/HATA üretir | D11: Hata taraması | E11: Hata + GEÇTİ birlikte | F11: HATA
A12: Karar motoru | B12: Ne oldu, neden oldu? | C12: Sorun + neden + parasal etki + aksiyon + son tarih | D12: Karar tablosu | E12: Boş sayfa / isim düzeyi modül | F12: HATA
A13: Yönetici özeti | B13: 5 saniyede ne görmeliyim? | C13: Bugün / ne değişti / ne bozulacak / neden / ne yapmalıyım / güven | D13: Yönetici özeti ekranı | E13: KPI kutusu yığını | F13: HATA
A14: Teklif | B14: Neden satın almalıyım? | C14: Dosya özellikleri yerine sonuç ve kaçınılan maliyet sunulur | D14: Ürün sayfası kanıt eşlemesi | E14: Özellik listesiyle satış | F14: HATA
... A19: Pazar kanıtı | B19: Piyasa gerçekten ödüyor mu? | C19: Satış/pilot/LOI/fiyat kabulü olmadan pazar doğrulandı yazılmaz | D19: Gerçek işlem kanıtı | E19: Tahmini talep = satış kabulü | F19: HATA

Sheet KAPAK
A1: KAPAK — Tahsilat Riski & Vade Komuta Paneli
A3: Tahsilat Riski & Vade Komuta Paneli
A4: Müşteri faturalarını vade yaşlandırması, tahsilat olasılığı ve durum makinesi ile yönetir; beklenen kaybı görünür kılar; ARA / İCRA HAZIRLIĞI / İZLE kararı üretir.
A6: Bu ürün ne sağlar?
A7: • Makrosuz durum makinesi: Açık → Hatırlatma → İhtar → Tahsil / Kapalı
A8: • Yaşlandırma kovaları (0-30 / 31-60 / 61-90 / 90+)
A9: • Tahsilat olasılığı + beklenen kayıp motoru
A10: • Geçersiz geçiş ve yetim müşteri uyarıları
A11: • Dönemsel tahsilat kanıt raporu — yönetici/SMMM dosyasına uygun
A13: Kimler için?
A14: • Tahsilat müdürü — günün kuyruğu ve icra hazırlığı
A15: • CFO / mali işler — beklenen kayıp ve yaşlandırma
... A21: Sürüm 1.0.0 | Lisans: Tek kullanıcı | ExcelArşiv

Sheet KARTLAR
A1: KARTLAR — Tahsilat Riski & Vade Komuta Paneli
A3: Müşteri kartları — her kaydın tek kimliği vardır
A4: Sonraki Kimlik | B4: =trv_sonrakiKimlik
A5: KartId | B5: Unvan | C5: Sektor | D5: Sehir | E5: LimitTl | F5: RiskNotu | G5: Aktif | H5: ToplamAcik | I5: OrtGecikme
A6: MUS-00001 | B6: Atlas Ticaret Ltd. | C6: Toptan | D6: İstanbul | E6: 1500000 | F6: Normal | G6: EVET | H6: =IF($A6="","",SUMIF(tblAkis[KaynakKartId],$A6,tblAkis[Tutar])) | I6: =IF($A6="","",IFERROR(AVERAGEIF(tblAkis[KaynakKartId],$A6,tblAkis[GecikmeGun]),0))
A7: MUS-00002 | B7: Demir Market A.Ş. | C7: Perakende | D7: Ankara | E7: 1620000 | F7: Normal | G7: EVET | H7: =IF($A7="","",SUMIF(tblAkis[KaynakKartId],$A7,tblAkis[Tutar])) | I7: =IF($A7="","",IFERROR(AVERAGEIF(tblAkis[KaynakKartId],$A7,tblAkis[GecikmeGun]),0))
A8: MUS-00003 | B8: Nova Gıda | C8: Gıda | D8: İzmir | E8: 1740000 | F8: Normal | G8: EVET | H8: =IF($A8="","",SUMIF(tblAkis[KaynakKartId],$A8,tblAkis[Tutar])) | I8: =IF($A8="","",IFERROR(AVERAGEIF(tblAkis[KaynakKartId],$A8,tblAkis[GecikmeGun]),0))
A9: MUS-00004 | B9: Proje Lojistik | C9: Lojistik | D9: Bursa | E9: 1860000 | F9: Normal | G9: EVET | H9: =IF($A9="","",SUMIF(tblAkis[KaynakKartId],$A9,tblAkis[Tutar])) | I9: =IF($A9="","",IFERROR(AVERAGEIF(tblAkis[KaynakKartId],$A9,tblAkis[GecikmeGun]),0))
A10: MUS-00005 | B10: Su Enerji Pro | C10: Enerji | D10: Antalya | E10: 1980000 | F10: Normal | G10: EVET | H10: =IF($A10="","",SUMIF(tblAkis[KaynakKartId],$A10,tblAkis[Tutar])) | I10: =IF($A10="","",IFERROR(AVERAGEIF(tblAkis[KaynakKartId],$A10,tblAkis[GecikmeGun]),0))
A11: MUS-00006 | B11: Cephe Yapı | C11: İnşaat | D11: Kocaeli | E11: 2100000 | F11: Normal | G11: EVET | H11: =IF($A11="","",SUMIF(tblAkis[KaynakKartId],$A11,tblAkis[Tutar])) | I11: =IF($A11="","",IFERROR(AVERAGEIF(tblAkis[KaynakKartId],$A11,tblAkis[GecikmeGun]),0))
A12: MUS-00007 | B12: Zemin Tarım | C12: Tarım | D12: Adana | E12: 2220000 | F12: Normal | G12: EVET | H12: =IF($A12="","",SUMIF(tblAkis[KaynakKartId],$A12,tblAkis[Tutar])) | I12: =IF($A12="","",IFERROR(AVERAGEIF(tblAkis[KaynakKartId],$A12,tblAkis[GecikmeGun]),0))
A13: MUS-00008 | B13: İskele Medikal | C13: Sağlık | D13: Gaziantep | E13: 2340000 | F13: Normal | G13: EVET | H13: =IF($A13="","",SUMIF(tblAkis[KaynakKartId],$A13,tblAkis[Tutar])) | I13: =IF($A13="","",IFERROR(AVERAGEIF(tblAkis[KaynakKartId],$A13,tblAkis[GecikmeGun]),0))
H14: =IF($A14="","",SUMIF(tblAkis[KaynakKartId],$A14,tblAkis[Tutar])) | I14: =IF($A14="","",IFERROR(AVERAGEIF(tblAkis[KaynakKartId],$A14,tblAkis[GecikmeGun]),0))
H15: =IF($A15="","",SUMIF(tblAkis[KaynakKartId],$A15,tblAkis[Tutar])) | I15: =IF($A15="","",IFERROR(AVERAGEIF(tblAkis[KaynakKartId],$A15,tblAkis[GecikmeGun]),0))
H16: =IF($A16="","",SUMIF(tblAkis[KaynakKartId],$A16,tblAkis[Tutar])) | I16: =IF($A16="","",IFERROR(AVERAGEIF(tblAkis[KaynakKartId],$A16,tblAkis[GecikmeGun]),0))
H17: =IF($A17="","",SUMIF(tblAkis[KaynakKartId],$A17,tblAkis[Tutar])) | I17: =IF($A17="","",IFERROR(AVERAGEIF(tblAkis[KaynakKartId],$A17,tblAkis[GecikmeGun]),0))
H18: =IF($A18="","",SUMIF(tblAkis[KaynakKartId],$A18,tblAkis[Tutar])) | I18: =IF($A18="","",IFERROR(AVERAGEIF(tblAkis[KaynakKartId],$A18,tblAkis[GecikmeGun]),0))
H19: =IF($A19="","",SUMIF(tblAkis[KaynakKartId],$A19,tblAkis[Tutar])) | I19: =IF($A19="","",IFERROR(AVERAGEIF(tblAkis[KaynakKartId],$A19,tblAkis[GecikmeGun]),0))
H20: =IF($A20="","",SUMIF(tblAkis[KaynakKartId],$A20,tblAkis[Tutar])) | I20: =IF($A20="","",IFERROR(AVERAGEIF(tblAkis[KaynakKartId],$A20,tblAkis[GecikmeGun]),0))
H21: =IF($A21="","",SUMIF(tblAkis[KaynakKartId],$A21,tblAkis[Tutar])) | I21: =IF($A21="","",IFERROR(AVERAGEIF(tblAkis[KaynakKartId],$A21,tblAkis[GecikmeGun]),0))
H22: =IF($A22="","",SUMIF(tblAkis[KaynakKartId],$A22,tblAkis[Tutar])) | I22: =IF($A22="","",IFERROR(AVERAGEIF(tblAkis[KaynakKartId],$A22,tblAkis[GecikmeGun]),0))
H23: =IF($A23="","",SUMIF(tblAkis[KaynakKartId],$A23,tblAkis[Tutar])) | I23: =IF($A23="","",IFERROR(AVERAGEIF(tblAkis[KaynakKartId],$A23,tblAkis[GecikmeGun]),0))
H24: =IF($A24="","",SUMIF(tblAkis[KaynakKartId],$A24,tblAkis[Tutar])) | I24: =IF($A24="","",IFERROR(AVERAGEIF(tblAkis[KaynakKartId],$A24,tblAkis[GecikmeGun]),0))
H25: =IF($A25="","",SUMIF(tblAkis[KaynakKartId],$A25,tblAkis[Tutar])) | I25: =IF($A25="","",IFERROR(AVERAGEIF(tblAkis[KaynakKartId],$A25,tblAkis[GecikmeGun]),0))
... H255: =IF($A255="","",SUMIF(tblAkis[KaynakKartId],$A255,tblAkis[Tutar])) | I255: =IF($A255="","",IFERROR(AVERAGEIF(tblAkis[KaynakKartId],$A255,tblAkis[GecikmeGun]),0))

Sheet AKIS
A1: AKIS — Tahsilat Riski & Vade Komuta Paneli
A3: Fatura/vade satırları — durum makinesi + yetim + geçersiz geçiş + zincir
A5: IslemId | B5: KaynakKartId | C5: FaturaNo | D5: VadeTarihi | E5: OdemeTarihi | F5: OncekiDurum | G5: Durum | H5: FaturaTutari | I5: OdemeTutari | J5: Tutar | K5: RiskSkoru | L5: Sektor | M5: YorumA | N5: YorumB | O5: GecikmeGun | P5: YasKova | Q5: TahsilatOlasilik | R5: BeklenenKayip | S5: YetimBayrak | T5: GecisUyarisi | U5: ZincirBayrak | V5: KayitDolu
A6: FAT-00001 | B6: MUS-00001 | C6: FR-2026-0001 | D6: 46241 | G6: ACIK | H6: 89500 | I6: 0 | J6: 89500 | K6: 23 | L6: Toptan | M6: A | N6: Takip notu 1 | O6: =IF($A6="","",IF(OR($G6="TAHSIL",$G6="KAPALI"),0,IF($D6="","",raporTarihi-$D6))) | P6: =IF($A6="","",IF($O6="","",IF($O6<=trv_kovaEsik1,"0-30",IF($O6<=trv_kovaEsik2,"31-60",IF($O6<=trv_kovaEsik3,"61-90","90+"))))) | Q6: =IF(OR($A6="",$G6="TAHSIL",$G6="KAPALI"),"",IF($P6="0-30",trv_olasilikK1,IF($P6="31-60",trv_olasilikK2,IF($P6="61-90",trv_olasilikK3,trv_olasilikK4)))) | R6: =IF(OR($A6="",$Q6=""),"",$J6*(1-$Q6)*MAX(trv_riskTaban,$K6/100)) | S6: =IF($A6="","",IF($B6="","YETİM",IF(COUNTIF(tblKartlar[KartId],$B6)=0,"YETİM",""))) | T6: =IF(OR($A6="",$F6=""),"",IF(OR($F6&"|"&$G6="",COUNTIF(ListeIzinliGecis,$F6&"|"&$G6)>0),"","GEÇERSİZ GEÇİŞ")) | U6: =IF($A6="","",IF(OR($G6="TAHSIL",$I6>0),IF(OR($H6="",$I6=""),"",IF(ABS($I6-$H6)>zincirTolerans,"ZİNCİR KIRIK","OK")),"OK")) | V6: =IF($A6="","",1)
A7: FAT-00002 | B7: MUS-00002 | C7: FR-2026-0002 | D7: 46237 | F7: ACIK | G7: HATIRLATMA | H7: 99000 | I7: 0 | J7: 99000 | K7: 26 | L7: Perakende | M7: B | N7: Takip notu 2 | O7: =IF($A7="","",IF(OR($G7="TAHSIL",$G7="KAPALI"),0,IF($D7="","",raporTarihi-$D7))) | P7: =IF($A7="","",IF($O7="","",IF($O7<=trv_kovaEsik1,"0-30",IF($O7<=trv_kovaEsik2,"31-60",IF($O7<=trv_kovaEsik3,"61-90","90+"))))) | Q7: =IF(OR($A7="",$G7="TAHSIL",$G7="KAPALI"),"",IF($P7="0-30",trv_olasilikK1,IF($P7="31-60",trv_olasilikK2,IF($P7="61-90",trv_olasilikK3,trv_olasilikK4)))) | R7: =IF(OR($A7="",$Q7=""),"",$J7*(1-$Q7)*MAX(trv_riskTaban,$K7/100)) | S7: =IF($A7="","",IF($B7="","YETİM",IF(COUNTIF(tblKartlar[KartId],$B7)=0,"YETİM",""))) | T7: =IF(OR($A7="",$F7=""),"",IF(OR($F7&"|"&$G7="",COUNTIF(ListeIzinliGecis,$F7&"|"&$G7)>0),"","GEÇERSİZ GEÇİŞ")) | U7: =IF($A7="","",IF(OR($G7="TAHSIL",$I7>0),IF(OR($H7="",$I7=""),"",IF(ABS($I7-$H7)>zincirTolerans,"ZİNCİR KIRIK","OK")),"OK")) | V7: =IF($A7="","",1)
A8: FAT-00003 | B8: MUS-00003 | C8: FR-2026-0003 | D8: 46233 | F8: HATIRLATMA | G8: IHTAR | H8: 108500 | I8: 0 | J8: 108500 | K8: 29 | L8: Gıda | M8: A | N8: Takip notu 3 | O8: =IF($A8="","",IF(OR($G8="TAHSIL",$G8="KAPALI"),0,IF($D8="","",raporTarihi-$D8))) | P8: =IF($A8="","",IF($O8="","",IF($O8<=trv_kovaEsik1,"0-30",IF($O8<=trv_kovaEsik2,"31-60",IF($O8<=trv_kovaEsik3,"61-90","90+"))))) | Q8: =IF(OR($A8="",$G8="TAHSIL",$G8="KAPALI"),"",IF($P8="0-30",trv_olasilikK1,IF($P8="31-60",trv_olasilikK2,IF($P8="61-90",trv_olasilikK3,trv_olasilikK4)))) | R8: =IF(OR($A8="",$Q8=""),"",$J8*(1-$Q8)*MAX(trv_riskTaban,$K8/100)) | S8: =IF($A8="","",IF($B8="","YETİM",IF(COUNTIF(tblKartlar[KartId],$B8)=0,"YETİM",""))) | T8: =IF(OR($A8="",$F8=""),"",IF(OR($F8&"|"&$G8="",COUNTIF(ListeIzinliGecis,$F8&"|"&$G8)>0),"","GEÇERSİZ GEÇİŞ")) | U8: =IF($A8="","",IF(OR($G8="TAHSIL",$I8>0),IF(OR($H8="",$I8=""),"",IF(ABS($I8-$H8)>zincirTolerans,"ZİNCİR KIRIK","OK")),"OK")) | V8: =IF($A8="","",1)
A9: FAT-00004 | B9: MUS-00004 | C9: FR-2026-0004 | D9: 46229 | E9: 46243 | F9: IHTAR | G9: TAHSIL | H9: 118000 | I9: 118000 | J9: 0 | K9: 32 | L9: Lojistik | M9: B | N9: Takip notu 4 | O9: =IF($A9="","",IF(OR($G9="TAHSIL",$G9="KAPALI"),0,IF($D9="","",raporTarihi-$D9))) | P9: =IF($A9="","",IF($O9="","",IF($O9<=trv_kovaEsik1,"0-30",IF($O9<=trv_kovaEsik2,"31-60",IF($O9<=trv_kovaEsik3,"61-90","90+"))))) | Q9: =IF(OR($A9="",$G9="TAHSIL",$G9="KAPALI"),"",IF($P9="0-30",trv_olasilikK1,IF($P9="31-60",trv_olasilikK2,IF($P9="61-90",trv_olasilikK3,trv_olasilikK4)))) | R9: =IF(OR($A9="",$Q9=""),"",$J9*(1-$Q9)*MAX(trv_riskTaban,$K9/100)) | S9: =IF($A9="","",IF($B9="","YETİM",IF(COUNTIF(tblKartlar[KartId],$B9)=0,"YETİM",""))) | T9: =IF(OR($A9="",$F9=""),"",IF(OR($F9&"|"&$G9="",COUNTIF(ListeIzinliGecis,$F9&"|"&$G9)>0),"","GEÇERSİZ GEÇİŞ")) | U9: =IF($A9="","",IF(OR($G9="TAHSIL",$I9>0),IF(OR($H9="",$I9=""),"",IF(ABS($I9-$H9)>zincirTolerans,"ZİNCİR KIRIK","OK")),"OK")) | V9: =IF($A9="","",1)
A10: FAT-00005 | B10: MUS-00005 | C10: FR-2026-0005 | D10: 46225 | F10: IHTAR | G10: KAPALI | H10: 127500 | I10: 0 | J10: 0 | K10: 35 | L10: Enerji | M10: A | N10: Takip notu 5 | O10: =IF($A10="","",IF(OR($G10="TAHSIL",$G10="KAPALI"),0,IF($D10="","",raporTarihi-$D10))) | P10: =IF($A10="","",IF($O10="","",IF($O10<=trv_kovaEsik1,"0-30",IF($O10<=trv_kovaEsik2,"31-60",IF($O10<=trv_kovaEsik3,"61-90","90+"))))) | Q10: =IF(OR($A10="",$G10="TAHSIL",$G10="KAPALI"),"",IF($P10="0-30",trv_olasilikK1,IF($P10="31-60",trv_olasilikK2,IF($P10="61-90",trv_olasilikK3,trv_olasilikK4)))) | R10: =IF(OR($A10="",$Q10=""),"",$J10*(1-$Q10)*MAX(trv_riskTaban,$K10/100)) | S10: =IF($A10="","",IF($B10="","YETİM",IF(COUNTIF(tblKartlar[KartId],$B10)=0,"YETİM",""))) | T10: =IF(OR($A10="",$F10=""),"",IF(OR($F10&"|"&$G10="",COUNTIF(ListeIzinliGecis,$F10&"|"&$G10)>0),"","GEÇERSİZ GEÇİŞ")) | U10: =IF($A10="","",IF(OR($G10="TAHSIL",$I10>0),IF(OR($H10="",$I10=""),"",IF(ABS($I10-$H10)>zincirTolerans,"ZİNCİR KIRIK","OK")),"OK")) | V10: =IF($A10="","",1)
A11: FAT-00006 | B11: MUS-00006 | C11: FR-2026-0006 | D11: 46221 | F11: ACIK | G11: HATIRLATMA | H11: 137000 | I11: 0 | J11: 137000 | K11: 38 | L11: İnşaat | M11: B | N11: Takip notu 6 | O11: =IF($A11="","",IF(OR($G11="TAHSIL",$G11="KAPALI"),0,IF($D11="","",raporTarihi-$D11))) | P11: =IF($A11="","",IF($O11="","",IF($O11<=trv_kovaEsik1,"0-30",IF($O11<=trv_kovaEsik2,"31-60",IF($O11<=trv_kovaEsik3,"61-90","90+"))))) | Q11: =IF(OR($A11="",$G11="TAHSIL",$G11="KAPALI"),"",IF($P11="0-30",trv_olasilikK1,IF($P11="31-60",trv_olasilikK2,IF($P11="61-90",trv_olasilikK3,trv_olasilikK4)))) | R11: =IF(OR($A11="",$Q11=""),"",$J11*(1-$Q11)*MAX(trv_riskTaban,$K11/100)) | S11: =IF($A11="","",IF($B11="","YETİM",IF(COUNTIF(tblKartlar[KartId],$B11)=0,"YETİM",""))) | T11: =IF(OR($A11="",$F11=""),"",IF(OR($F11&"|"&$G11="",COUNTIF(ListeIzinliGecis,$F11&"|"&$G11)>0),"","GEÇERSİZ GEÇİŞ")) | U11: =IF($A11="","",IF(OR($G11="TAHSIL",$I11>0),IF(OR($H11="",$I11=""),"",IF(ABS($I11-$H11)>zincirTolerans,"ZİNCİR KIRIK","OK")),"OK")) | V11: =IF($A11="","",1)
A12: FAT-00007 | B12: MUS-00007 | C12: FR-2026-0007 | D12: 46217 | F12: HATIRLATMA | G12: IHTAR | H12: 146500 | I12: 0 | J12: 146500 | K12: 41 | L12: Tarım | M12: A | N12: Takip notu 7 | O12: =IF($A12="","",IF(OR($G12="TAHSIL",$G12="KAPALI"),0,IF($D12="","",raporTarihi-$D12))) | P12: =IF($A12="","",IF($O12="","",IF($O12<=trv_kovaEsik1,"0-30",IF($O12<=trv_kovaEsik2,"31-60",IF($O12<=trv_kovaEsik3,"61-90","90+"))))) | Q12: =IF(OR($A12="",$G12="TAHSIL",$G12="KAPALI"),"",IF($P12="0-30",trv_olasilikK1,IF($P12="31-60",trv_olasilikK2,IF($P12="61-90",trv_olasilikK3,trv_olasilikK4)))) | R12: =IF(OR($A12="",$Q12=""),"",$J12*(1-$Q12)*MAX(trv_riskTaban,$K12/100)) | S12: =IF($A12="","",IF($B12="","YETİM",IF(COUNTIF(tblKartlar[KartId],$B12)=0,"YETİM",""))) | T12: =IF(OR($A12="",$F12=""),"",IF(OR($F12&"|"&$G12="",COUNTIF(ListeIzinliGecis,$F12&"|"&$G12)>0),"","GEÇERSİZ GEÇİŞ")) | U12: =IF($A12="","",IF(OR($G12="TAHSIL",$I12>0),IF(OR($H12="",$I12=""),"",IF(ABS($I12-$H12)>zincirTolerans,"ZİNCİR KIRIK","OK")),"OK")) | V12: =IF($A12="","",1)
A13: FAT-00008 | B13: MUS-00008 | C13: FR-2026-0008 | D13: 46213 | F13: ACIK | G13: ACIK | H13: 156000 | I13: 0 | J13: 156000 | K13: 44 | L13: Sağlık | M13: B | N13: Takip notu 8 | O13: =IF($A13="","",IF(OR($G13="TAHSIL",$G13="KAPALI"),0,IF($D13="","",raporTarihi-$D13))) | P13: =IF($A13="","",IF($O13="","",IF($O13<=trv_kovaEsik1,"0-30",IF($O13<=trv_kovaEsik2,"31-60",IF($O13<=trv_kovaEsik3,"61-90","90+"))))) | Q13: =IF(OR($A13="",$G13="TAHSIL",$G13="KAPALI"),"",IF($P13="0-30",trv_olasilikK1,IF($P13="31-60",trv_olasilikK2,IF($P13="61-90",trv_olasilikK3,trv_olasilikK4)))) | R13: =IF(OR($A13="",$Q13=""),"",$J13*(1-$Q13)*MAX(trv_riskTaban,$K13/100)) | S13: =IF($A13="","",IF($B13="","YETİM",IF(COUNTIF(tblKartlar[KartId],$B13)=0,"YETİM",""))) | T13: =IF(OR($A13="",$F13=""),"",IF(OR($F13&"|"&$G13="",COUNTIF(ListeIzinliGecis,$F13&"|"&$G13)>0),"","GEÇERSİZ GEÇİŞ")) | U13: =IF($A13="","",IF(OR($G13="TAHSIL",$I13>0),IF(OR($H13="",$I13=""),"",IF(ABS($I13-$H13)>zincirTolerans,"ZİNCİR KIRIK","OK")),"OK")) | V13: =IF($A13="","",1)
A14: FAT-00009 | B14: MUS-00001 | C14: FR-2026-0009 | D14: 46209 | G14: ACIK | H14: 165500 | I14: 0 | J14: 165500 | K14: 47 | L14: Toptan | M14: A | N14: Takip notu 9 | O14: =IF($A14="","",IF(OR($G14="TAHSIL",$G14="KAPALI"),0,IF($D14="","",raporTarihi-$D14))) | P14: =IF($A14="","",IF($O14="","",IF($O14<=trv_kovaEsik1,"0-30",IF($O14<=trv_kovaEsik2,"31-60",IF($O14<=trv_kovaEsik3,"61-90","90+"))))) | Q14: =IF(OR($A14="",$G14="TAHSIL",$G14="KAPALI"),"",IF($P14="0-30",trv_olasilikK1,IF($P14="31-60",trv_olasilikK2,IF($P14="61-90",trv_olasilikK3,trv_olasilikK4)))) | R14: =IF(OR($A14="",$Q14=""),"",$J14*(1-$Q14)*MAX(trv_riskTaban,$K14/100)) | S14: =IF($A14="","",IF($B14="","YETİM",IF(COUNTIF(tblKartlar[KartId],$B14)=0,"YETİM",""))) | T14: =IF(OR($A14="",$F14=""),"",IF(OR($F14&"|"&$G14="",COUNTIF(ListeIzinliGecis,$F14&"|"&$G14)>0),"","GEÇERSİZ GEÇİŞ")) | U14: =IF($A14="","",IF(OR($G14="TAHSIL",$I14>0),IF(OR($H14="",$I14=""),"",IF(ABS($I14-$H14)>zincirTolerans,"ZİNCİR KIRIK","OK")),"OK")) | V14: =IF($A14="","",1)
A15: FAT-00010 | B15: MUS-00002 | C15: FR-2026-0010 | D15: 46205 | F15: ACIK | G15: HATIRLATMA | H15: 175000 | I15: 0 | J15: 175000 | K15: 50 | L15: Perakende | M15: B | N15: Takip notu 10 | O15: =IF($A15="","",IF(OR($G15="TAHSIL",$G15="KAPALI"),0,IF($D15="","",raporTarihi-$D15))) | P15: =IF($A15="","",IF($O15="","",IF($O15<=trv_kovaEsik1,"0-30",IF($O15<=trv_kovaEsik2,"31-60",IF($O15<=trv_kovaEsik3,"61-90","90+"))))) | Q15: =IF(OR($A15="",$G15="TAHSIL",$G15="KAPALI"),"",IF($P15="0-30",trv_olasilikK1,IF($P15="31-60",trv_olasilikK2,IF($P15="61-90",trv_olasilikK3,trv_olasilikK4)))) | R15: =IF(OR($A15="",$Q15=""),"",$J15*(1-$Q15)*MAX(trv_riskTaban,$K15/100)) | S15: =IF($A15="","",IF($B15="","YETİM",IF(COUNTIF(tblKartlar[KartId],$B15)=0,"YETİM",""))) | T15: =IF(OR($A15="",$F15=""),"",IF(OR($F15&"|"&$G15="",COUNTIF(ListeIzinliGecis,$F15&"|"&$G15)>0),"","GEÇERSİZ GEÇİŞ")) | U15: =IF($A15="","",IF(OR($G15="TAHSIL",$I15>0),IF(OR($H15="",$I15=""),"",IF(ABS($I15-$H15)>zincirTolerans,"ZİNCİR KIRIK","OK")),"OK")) | V15: =IF($A15="","",1)
A16: FAT-00011 | B16: MUS-00003 | C16: FR-2026-0011 | D16: 46201 | F16: HATIRLATMA | G16: IHTAR | H16: 184500 | I16: 0 | J16: 184500 | K16: 53 | L16: Gıda | M16: A | N16: Takip notu 11 | O16: =IF($A16="","",IF(OR($G16="TAHSIL",$G16="KAPALI"),0,IF($D16="","",raporTarihi-$D16))) | P16: =IF($A16="","",IF($O16="","",IF($O16<=trv_kovaEsik1,"0-30",IF($O16<=trv_kovaEsik2,"31-60",IF($O16<=trv_kovaEsik3,"61-90","90+"))))) | Q16: =IF(OR($A16="",$G16="TAHSIL",$G16="KAPALI"),"",IF($P16="0-30",trv_olasilikK1,IF($P16="31-60",trv_olasilikK2,IF($P16="61-90",trv_olasilikK3,trv_olasilikK4)))) | R16: =IF(OR($A16="",$Q16=""),"",$J16*(1-$Q16)*MAX(trv_riskTaban,$K16/100)) | S16: =IF($A16="","",IF($B16="","YETİM",IF(COUNTIF(tblKartlar[KartId],$B16)=0,"YETİM",""))) | T16: =IF(OR($A16="",$F16=""),"",IF(OR($F16&"|"&$G16="",COUNTIF(ListeIzinliGecis,$F16&"|"&$G16)>0),"","GEÇERSİZ GEÇİŞ")) | U16: =IF($A16="","",IF(OR($G16="TAHSIL",$I16>0),IF(OR($H16="",$I16=""),"",IF(ABS($I16-$H16)>zincirTolerans,"ZİNCİR KIRIK","OK")),"OK")) | V16: =IF($A16="","",1)
A17: FAT-00012 | B17: MUS-00004 | C17: FR-2026-0012 | D17: 46197 | E17: 46243 | F17: IHTAR | G17: TAHSIL | H17: 194000 | I17: 182000 | J17: 0 | K17: 56 | L17: Lojistik | M17: B | N17: Takip notu 12 | O17: =IF($A17="","",IF(OR($G17="TAHSIL",$G17="KAPALI"),0,IF($D17="","",raporTarihi-$D17))) | P17: =IF($A17="","",IF($O17="","",IF($O17<=trv_kovaEsik1,"0-30",IF($O17<=trv_kovaEsik2,"31-60",IF($O17<=trv_kovaEsik3,"61-90","90+"))))) | Q17: =IF(OR($A17="",$G17="TAHSIL",$G17="KAPALI"),"",IF($P17="0-30",trv_olasilikK1,IF($P17="31-60",trv_olasilikK2,IF($P17="61-90",trv_olasilikK3,trv_olasilikK4)))) | R17: =IF(OR($A17="",$Q17=""),"",$J17*(1-$Q17)*MAX(trv_riskTaban,$K17/100)) | S17: =IF($A17="","",IF($B17="","YETİM",IF(COUNTIF(tblKartlar[KartId],$B17)=0,"YETİM",""))) | T17: =IF(OR($A17="",$F17=""),"",IF(OR($F17&"|"&$G17="",COUNTIF(ListeIzinliGecis,$F17&"|"&$G17)>0),"","GEÇERSİZ GEÇİŞ")) | U17: =IF($A17="","",IF(OR($G17="TAHSIL",$I17>0),IF(OR($H17="",$I17=""),"",IF(ABS($I17-$H17)>zincirTolerans,"ZİNCİR KIRIK","OK")),"OK")) | V17: =IF($A17="","",1)
A18: FAT-00013 | B18: MUS-00005 | C18: FR-2026-0013 | D18: 46193 | F18: IHTAR | G18: KAPALI | H18: 203500 | I18: 0 | J18: 0 | K18: 59 | L18: Enerji | M18: A | N18: Takip notu 13 | O18: =IF($A18="","",IF(OR($G18="TAHSIL",$G18="KAPALI"),0,IF($D18="","",raporTarihi-$D18))) | P18: =IF($A18="","",IF($O18="","",IF($O18<=trv_kovaEsik1,"0-30",IF($O18<=trv_kovaEsik2,"31-60",IF($O18<=trv_kovaEsik3,"61-90","90+"))))) | Q18: =IF(OR($A18="",$G18="TAHSIL",$G18="KAPALI"),"",IF($P18="0-30",trv_olasilikK1,IF($P18="31-60",trv_olasilikK2,IF($P18="61-90",trv_olasilikK3,trv_olasilikK4)))) | R18: =IF(OR($A18="",$Q18=""),"",$J18*(1-$Q18)*MAX(trv_riskTaban,$K18/100)) | S18: =IF($A18="","",IF($B18="","YETİM",IF(COUNTIF(tblKartlar[KartId],$B18)=0,"YETİM",""))) | T18: =IF(OR($A18="",$F18=""),"",IF(OR($F18&"|"&$G18="",COUNTIF(ListeIzinliGecis,$F18&"|"&$G18)>0),"","GEÇERSİZ GEÇİŞ")) | U18: =IF($A18="","",IF(OR($G18="TAHSIL",$I18>0),IF(OR($H18="",$I18=""),"",IF(ABS($I18-$H18)>zincirTolerans,"ZİNCİR KIRIK","OK")),"OK")) | V18: =IF($A18="","",1)
A19: FAT-00014 | B19: MUS-00006 | C19: FR-2026-0014 | D19: 46189 | F19: ACIK | G19: HATIRLATMA | H19: 213000 | I19: 0 | J19: 213000 | K19: 62 | L19: İnşaat | M19: B | N19: Takip notu 14 | O19: =IF($A19="","",IF(OR($G19="TAHSIL",$G19="KAPALI"),0,IF($D19="","",raporTarihi-$D19))) | P19: =IF($A19="","",IF($O19="","",IF($O19<=trv_kovaEsik1,"0-30",IF($O19<=trv_kovaEsik2,"31-60",IF($O19<=trv_kovaEsik3,"61-90","90+"))))) | Q19: =IF(OR($A19="",$G19="TAHSIL",$G19="KAPALI"),"",IF($P19="0-30",trv_olasilikK1,IF($P19="31-60",trv_olasilikK2,IF($P19="61-90",trv_olasilikK3,trv_olasilikK4)))) | R19: =IF(OR($A19="",$Q19=""),"",$J19*(1-$Q19)*MAX(trv_riskTaban,$K19/100)) | S19: =IF($A19="","",IF($B19="","YETİM",IF(COUNTIF(tblKartlar[KartId],$B19)=0,"YETİM",""))) | T19: =IF(OR($A19="",$F19=""),"",IF(OR($F19&"|"&$G19="",COUNTIF(ListeIzinliGecis,$F19&"|"&$G19)>0),"","GEÇERSİZ GEÇİŞ")) | U19: =IF($A19="","",IF(OR($G19="TAHSIL",$I19>0),IF(OR($H19="",$I19=""),"",IF(ABS($I19-$H19)>zincirTolerans,"ZİNCİR KIRIK","OK")),"OK")) | V19: =IF($A19="","",1)
A20: FAT-00015 | B20: MUS-00007 | C20: FR-2026-0015 | D20: 46185 | F20: HATIRLATMA | G20: IHTAR | H20: 222500 | I20: 0 | J20: 222500 | K20: 65 | L20: Tarım | M20: A | N20: Takip notu 15 | O20: =IF($A20="","",IF(OR($G20="TAHSIL",$G20="KAPALI"),0,IF($D20="","",raporTarihi-$D20))) | P20: =IF($A20="","",IF($O20="","",IF($O20<=trv_kovaEsik1,"0-30",IF($O20<=trv_kovaEsik2,"31-60",IF($O20<=trv_kovaEsik3,"61-90","90+"))))) | Q20: =IF(OR($A20="",$G20="TAHSIL",$G20="KAPALI"),"",IF($P20="0-30",trv_olasilikK1,IF($P20="31-60",trv_olasilikK2,IF($P20="61-90",trv_olasilikK3,trv_olasilikK4)))) | R20: =IF(OR($A20="",$Q20=""),"",$J20*(1-$Q20)*MAX(trv_riskTaban,$K20/100)) | S20: =IF($A20="","",IF($B20="","YETİM",IF(COUNTIF(tblKartlar[KartId],$B20)=0,"YETİM",""))) | T20: =IF(OR($A20="",$F20=""),"",IF(OR($F20&"|"&$G20="",COUNTIF(ListeIzinliGecis,$F20&"|"&$G20)>0),"","GEÇERSİZ GEÇİŞ")) | U20: =IF($A20="","",IF(OR($G20="TAHSIL",$I20>0),IF(OR($H20="",$I20=""),"",IF(ABS($I20-$H20)>zincirTolerans,"ZİNCİR KIRIK","OK")),"OK")) | V20: =IF($A20="","",1)
A21: FAT-00016 | B21: MUS-00008 | C21: FR-2026-0016 | D21: 46181 | F21: ACIK | G21: ACIK | H21: 232000 | I21: 0 | J21: 232000 | K21: 68 | L21: Sağlık | M21: B | N21: Takip notu 16 | O21: =IF($A21="","",IF(OR($G21="TAHSIL",$G21="KAPALI"),0,IF($D21="","",raporTarihi-$D21))) | P21: =IF($A21="","",IF($O21="","",IF($O21<=trv_kovaEsik1,"0-30",IF($O21<=trv_kovaEsik2,"31-60",IF($O21<=trv_kovaEsik3,"61-90","90+"))))) | Q21: =IF(OR($A21="",$G21="TAHSIL",$G21="KAPALI"),"",IF($P21="0-30",trv_olasilikK1,IF($P21="31-60",trv_olasilikK2,IF($P21="61-90",trv_olasilikK3,trv_olasilikK4)))) | R21: =IF(OR($A21="",$Q21=""),"",$J21*(1-$Q21)*MAX(trv_riskTaban,$K21/100)) | S21: =IF($A21="","",IF($B21="","YETİM",IF(COUNTIF(tblKartlar[KartId],$B21)=0,"YETİM",""))) | T21: =IF(OR($A21="",$F21=""),"",IF(OR($F21&"|"&$G21="",COUNTIF(ListeIzinliGecis,$F21&"|"&$G21)>0),"","GEÇERSİZ GEÇİŞ")) | U21: =IF($A21="","",IF(OR($G21="TAHSIL",$I21>0),IF(OR($H21="",$I21=""),"",IF(ABS($I21-$H21)>zincirTolerans,"ZİNCİR KIRIK","OK")),"OK")) | V21: =IF($A21="","",1)
A22: FAT-00017 | B22: MUS-00001 | C22: FR-2026-0017 | D22: 46177 | G22: ACIK | H22: 241500 | I22: 0 | J22: 241500 | K22: 71 | L22: Toptan | M22: A | N22: Takip notu 17 | O22: =IF($A22="","",IF(OR($G22="TAHSIL",$G22="KAPALI"),0,IF($D22="","",raporTarihi-$D22))) | P22: =IF($A22="","",IF($O22="","",IF($O22<=trv_kovaEsik1,"0-30",IF($O22<=trv_kovaEsik2,"31-60",IF($O22<=trv_kovaEsik3,"61-90","90+"))))) | Q22: =IF(OR($A22="",$G22="TAHSIL",$G22="KAPALI"),"",IF($P22="0-30",trv_olasilikK1,IF($P22="31-60",trv_olasilikK2,IF($P22="61-90",trv_olasilikK3,trv_olasilikK4)))) | R22: =IF(OR($A22="",$Q22=""),"",$J22*(1-$Q22)*MAX(trv_riskTaban,$K22/100)) | S22: =IF($A22="","",IF($B22="","YETİM",IF(COUNTIF(tblKartlar[KartId],$B22)=0,"YETİM",""))) | T22: =IF(OR($A22="",$F22=""),"",IF(OR($F22&"|"&$G22="",COUNTIF(ListeIzinliGecis,$F22&"|"&$G22)>0),"","GEÇERSİZ GEÇİŞ")) | U22: =IF($A22="","",IF(OR($G22="TAHSIL",$I22>0),IF(OR($H22="",$I22=""),"",IF(ABS($I22-$H22)>zincirTolerans,"ZİNCİR KIRIK","OK")),"OK")) | V22: =IF($A22="","",1)
A23: FAT-00018 | B23: MUS-00002 | C23: FR-2026-0018 | D23: 46173 | F23: ACIK | G23: IHTAR | H23: 251000 | I23: 0 | J23: 251000 | K23: 74 | L23: Perakende | M23: B | N23: Takip notu 18 | O23: =IF($A23="","",IF(OR($G23="TAHSIL",$G23="KAPALI"),0,IF($D23="","",raporTarihi-$D23))) | P23: =IF($A23="","",IF($O23="","",IF($O23<=trv_kovaEsik1,"0-30",IF($O23<=trv_kovaEsik2,"31-60",IF($O23<=trv_kovaEsik3,"61-90","90+"))))) | Q23: =IF(OR($A23="",$G23="TAHSIL",$G23="KAPALI"),"",IF($P23="0-30",trv_olasilikK1,IF($P23="31-60",trv_olasilikK2,IF($P23="61-90",trv_olasilikK3,trv_olasilikK4)))) | R23: =IF(OR($A23="",$Q23=""),"",$J23*(1-$Q23)*MAX(trv_riskTaban,$K23/100)) | S23: =IF($A23="","",IF($B23="","YETİM",IF(COUNTIF(tblKartlar[KartId],$B23)=0,"YETİM",""))) | T23: =IF(OR($A23="",$F23=""),"",IF(OR($F23&"|"&$G23="",COUNTIF(ListeIzinliGecis,$F23&"|"&$G23)>0),"","GEÇERSİZ GEÇİŞ")) | U23: =IF($A23="","",IF(OR($G23="TAHSIL",$I23>0),IF(OR($H23="",$I23=""),"",IF(ABS($I23-$H23)>zincirTolerans,"ZİNCİR KIRIK","OK")),"OK")) | V23: =IF($A23="","",1)
A24: FAT-00019 | B24: MUS-00003 | C24: FR-2026-0019 | D24: 46169 | F24: HATIRLATMA | G24: IHTAR | H24: 260500 | I24: 305500 | J24: 260500 | K24: 77 | L24: Gıda | M24: A | N24: Takip notu 19 | O24: =IF($A24="","",IF(OR($G24="TAHSIL",$G24="KAPALI"),0,IF($D24="","",raporTarihi-$D24))) | P24: =IF($A24="","",IF($O24="","",IF($O24<=trv_kovaEsik1,"0-30",IF($O24<=trv_kovaEsik2,"31-60",IF($O24<=trv_kovaEsik3,"61-90","90+"))))) | Q24: =IF(OR($A24="",$G24="TAHSIL",$G24="KAPALI"),"",IF($P24="0-30",trv_olasilikK1,IF($P24="31-60",trv_olasilikK2,IF($P24="61-90",trv_olasilikK3,trv_olasilikK4)))) | R24: =IF(OR($A24="",$Q24=""),"",$J24*(1-$Q24)*MAX(trv_riskTaban,$K24/100)) | S24: =IF($A24="","",IF($B24="","YETİM",IF(COUNTIF(tblKartlar[KartId],$B24)=0,"YETİM",""))) | T24: =IF(OR($A24="",$F24=""),"",IF(OR($F24&"|"&$G24="",COUNTIF(ListeIzinliGecis,$F24&"|"&$G24)>0),"","GEÇERSİZ GEÇİŞ")) | U24: =IF($A24="","",IF(OR($G24="TAHSIL",$I24>0),IF(OR($H24="",$I24=""),"",IF(ABS($I24-$H24)>zincirTolerans,"ZİNCİR KIRIK","OK")),"OK")) | V24: =IF($A24="","",1)
A25: FAT-00020 | B25: MUS-00004 | C25: FR-2026-0020 | D25: 46165 | F25: IHTAR | G25: HATIRLATMA | H25: 270000 | I25: 0 | J25: 270000 | K25: 80 | L25: Lojistik | M25: B | N25: Takip notu 20 | O25: =IF($A25="","",IF(OR($G25="TAHSIL",$G25="KAPALI"),0,IF($D25="","",raporTarihi-$D25))) | P25: =IF($A25="","",IF($O25="","",IF($O25<=trv_kovaEsik1,"0-30",IF($O25<=trv_kovaEsik2,"31-60",IF($O25<=trv_kovaEsik3,"61-90","90+"))))) | Q25: =IF(OR($A25="",$G25="TAHSIL",$G25="KAPALI"),"",IF($P25="0-30",trv_olasilikK1,IF($P25="31-60",trv_olasilikK2,IF($P25="61-90",trv_olasilikK3,trv_olasilikK4)))) | R25: =IF(OR($A25="",$Q25=""),"",$J25*(1-$Q25)*MAX(trv_riskTaban,$K25/100)) | S25: =IF($A25="","",IF($B25="","YETİM",IF(COUNTIF(tblKartlar[KartId],$B25)=0,"YETİM",""))) | T25: =IF(OR($A25="",$F25=""),"",IF(OR($F25&"|"&$G25="",COUNTIF(ListeIzinliGecis,$F25&"|"&$G25)>0),"","GEÇERSİZ GEÇİŞ")) | U25: =IF($A25="","",IF(OR($G25="TAHSIL",$I25>0),IF(OR($H25="",$I25=""),"",IF(ABS($I25-$H25)>zincirTolerans,"ZİNCİR KIRIK","OK")),"OK")) | V25: =IF($A25="","",1)
A26: FAT-00021 | B26: MUS-00005 | C26: FR-2026-0021 | D26: 46161 | F26: IHTAR | G26: KAPALI | H26: 279500 | I26: 0 | J26: 0 | K26: 83 | L26: Enerji | M26: A | N26: Takip notu 21 | O26: =IF($A26="","",IF(OR($G26="TAHSIL",$G26="KAPALI"),0,IF($D26="","",raporTarihi-$D26))) | P26: =IF($A26="","",IF($O26="","",IF($O26<=trv_kovaEsik1,"0-30",IF($O26<=trv_kovaEsik2,"31-60",IF($O26<=trv_kovaEsik3,"61-90","90+"))))) | Q26: =IF(OR($A26="",$G26="TAHSIL",$G26="KAPALI"),"",IF($P26="0-30",trv_olasilikK1,IF($P26="31-60",trv_olasilikK2,IF($P26="61-90",trv_olasilikK3,trv_olasilikK4)))) | R26: =IF(OR($A26="",$Q26=""),"",$J26*(1-$Q26)*MAX(trv_riskTaban,$K26/100)) | S26: =IF($A26="","",IF($B26="","YETİM",IF(COUNTIF(tblKartlar[KartId],$B26)=0,"YETİM",""))) | T26: =IF(OR($A26="",$F26=""),"",IF(OR($F26&"|"&$G26="",COUNTIF(ListeIzinliGecis,$F26&"|"&$G26)>0),"","GEÇERSİZ GEÇİŞ")) | U26: =IF($A26="","",IF(OR($G26="TAHSIL",$I26>0),IF(OR($H26="",$I26=""),"",IF(ABS($I26-$H26)>zincirTolerans,"ZİNCİR KIRIK","OK")),"OK")) | V26: =IF($A26="","",1)
A27: FAT-00022 | C27: FR-2026-0022 | D27: 46157 | F27: ACIK | G27: HATIRLATMA | H27: 289000 | I27: 0 | J27: 289000 | K27: 86 | L27: İnşaat | M27: B | N27: Takip notu 22 | O27: =IF($A27="","",IF(OR($G27="TAHSIL",$G27="KAPALI"),0,IF($D27="","",raporTarihi-$D27))) | P27: =IF($A27="","",IF($O27="","",IF($O27<=trv_kovaEsik1,"0-30",IF($O27<=trv_kovaEsik2,"31-60",IF($O27<=trv_kovaEsik3,"61-90","90+"))))) | Q27: =IF(OR($A27="",$G27="TAHSIL",$G27="KAPALI"),"",IF($P27="0-30",trv_olasilikK1,IF($P27="31-60",trv_olasilikK2,IF($P27="61-90",trv_olasilikK3,trv_olasilikK4)))) | R27: =IF(OR($A27="",$Q27=""),"",$J27*(1-$Q27)*MAX(trv_riskTaban,$K27/100)) | S27: =IF($A27="","",IF($B27="","YETİM",IF(COUNTIF(tblKartlar[KartId],$B27)=0,"YETİM",""))) | T27: =IF(OR($A27="",$F27=""),"",IF(OR($F27&"|"&$G27="",COUNTIF(ListeIzinliGecis,$F27&"|"&$G27)>0),"","GEÇERSİZ GEÇİŞ")) | U27: =IF($A27="","",IF(OR($G27="TAHSIL",$I27>0),IF(OR($H27="",$I27=""),"",IF(ABS($I27-$H27)>zincirTolerans,"ZİNCİR KIRIK","OK")),"OK")) | V27: =IF($A27="","",1)
A28: FAT-00023 | B28: MUS-00007 | C28: FR-2026-0023 | D28: 46153 | F28: HATIRLATMA | G28: IHTAR | H28: 298500 | I28: 0 | J28: 298500 | K28: 89 | L28: Tarım | M28: A | N28: Takip notu 23 | O28: =IF($A28="","",IF(OR($G28="TAHSIL",$G28="KAPALI"),0,IF($D28="","",raporTarihi-$D28))) | P28: =IF($A28="","",IF($O28="","",IF($O28<=trv_kovaEsik1,"0-30",IF($O28<=trv_kovaEsik2,"31-60",IF($O28<=trv_kovaEsik3,"61-90","90+"))))) | Q28: =IF(OR($A28="",$G28="TAHSIL",$G28="KAPALI"),"",IF($P28="0-30",trv_olasilikK1,IF($P28="31-60",trv_olasilikK2,IF($P28="61-90",trv_olasilikK3,trv_olasilikK4)))) | R28: =IF(OR($A28="",$Q28=""),"",$J28*(1-$Q28)*MAX(trv_riskTaban,$K28/100)) | S28: =IF($A28="","",IF($B28="","YETİM",IF(COUNTIF(tblKartlar[KartId],$B28)=0,"YETİM",""))) | T28: =IF(OR($A28="",$F28=""),"",IF(OR($F28&"|"&$G28="",COUNTIF(ListeIzinliGecis,$F28&"|"&$G28)>0),"","GEÇERSİZ GEÇİŞ")) | U28: =IF($A28="","",IF(OR($G28="TAHSIL",$I28>0),IF(OR($H28="",$I28=""),"",IF(ABS($I28-$H28)>zincirTolerans,"ZİNCİR KIRIK","OK")),"OK")) | V28: =IF($A28="","",1)
A29: FAT-00024 | B29: MUS-00008 | C29: FR-2026-0024 | D29: 46149 | F29: ACIK | G29: ACIK | H29: 308000 | I29: 0 | J29: 308000 | K29: 22 | L29: Sağlık | M29: B | N29: Takip notu 24 | O29: =IF($A29="","",IF(OR($G29="TAHSIL",$G29="KAPALI"),0,IF($D29="","",raporTarihi-$D29))) | P29: =IF($A29="","",IF($O29="","",IF($O29<=trv_kovaEsik1,"0-30",IF($O29<=trv_kovaEsik2,"31-60",IF($O29<=trv_kovaEsik3,"61-90","90+"))))) | Q29: =IF(OR($A29="",$G29="TAHSIL",$G29="KAPALI"),"",IF($P29="0-30",trv_olasilikK1,IF($P29="31-60",trv_olasilikK2,IF($P29="61-90",trv_olasilikK3,trv_olasilikK4)))) | R29: =IF(OR($A29="",$Q29=""),"",$J29*(1-$Q29)*MAX(trv_riskTaban,$K29/100)) | S29: =IF($A29="","",IF($B29="","YETİM",IF(COUNTIF(tblKartlar[KartId],$B29)=0,"YETİM",""))) | T29: =IF(OR($A29="",$F29=""),"",IF(OR($F29&"|"&$G29="",COUNTIF(ListeIzinliGecis,$F29&"|"&$G29)>0),"","GEÇERSİZ GEÇİŞ")) | U29: =IF($A29="","",IF(OR($G29="TAHSIL",$I29>0),IF(OR($H29="",$I29=""),"",IF(ABS($I29-$H29)>zincirTolerans,"ZİNCİR KIRIK","OK")),"OK")) | V29: =IF($A29="","",1)
A30: FAT-00025 | B30: MUS-99999 | C30: FR-2026-0025 | D30: 46145 | G30: ACIK | H30: 317500 | I30: 0 | J30: 317500 | K30: 25 | L30: Toptan | M30: A | N30: Takip notu 25 | O30: =IF($A30="","",IF(OR($G30="TAHSIL",$G30="KAPALI"),0,IF($D30="","",raporTarihi-$D30))) | P30: =IF($A30="","",IF($O30="","",IF($O30<=trv_kovaEsik1,"0-30",IF($O30<=trv_kovaEsik2,"31-60",IF($O30<=trv_kovaEsik3,"61-90","90+"))))) | Q30: =IF(OR($A30="",$G30="TAHSIL",$G30="KAPALI"),"",IF($P30="0-30",trv_olasilikK1,IF($P30="31-60",trv_olasilikK2,IF($P30="61-90",trv_olasilikK3,trv_olasilikK4)))) | R30: =IF(OR($A30="",$Q30=""),"",$J30*(1-$Q30)*MAX(trv_riskTaban,$K30/100)) | S30: =IF($A30="","",IF($B30="","YETİM",IF(COUNTIF(tblKartlar[KartId],$B30)=0,"YETİM",""))) | T30: =IF(OR($A30="",$F30=""),"",IF(OR($F30&"|"&$G30="",COUNTIF(ListeIzinliGecis,$F30&"|"&$G30)>0),"","GEÇERSİZ GEÇİŞ")) | U30: =IF($A30="","",IF(OR($G30="TAHSIL",$I30>0),IF(OR($H30="",$I30=""),"",IF(ABS($I30-$H30)>zincirTolerans,"ZİNCİR KIRIK","OK")),"OK")) | V30: =IF($A30="","",1)
A31: FAT-00026 | B31: MUS-00002 | C31: FR-2026-0026 | D31: 46141 | F31: ACIK | G31: HATIRLATMA | H31: 327000 | I31: 0 | J31: 327000 | K31: 28 | L31: Perakende | M31: B | N31: Takip notu 26 | O31: =IF($A31="","",IF(OR($G31="TAHSIL",$G31="KAPALI"),0,IF($D31="","",raporTarihi-$D31))) | P31: =IF($A31="","",IF($O31="","",IF($O31<=trv_kovaEsik1,"0-30",IF($O31<=trv_kovaEsik2,"31-60",IF($O31<=trv_kovaEsik3,"61-90","90+"))))) | Q31: =IF(OR($A31="",$G31="TAHSIL",$G31="KAPALI"),"",IF($P31="0-30",trv_olasilikK1,IF($P31="31-60",trv_olasilikK2,IF($P31="61-90",trv_olasilikK3,trv_olasilikK4)))) | R31: =IF(OR($A31="",$Q31=""),"",$J31*(1-$Q31)*MAX(trv_riskTaban,$K31/100)) | S31: =IF($A31="","",IF($B31="","YETİM",IF(COUNTIF(tblKartlar[KartId],$B31)=0,"YETİM",""))) | T31: =IF(OR($A31="",$F31=""),"",IF(OR($F31&"|"&$G31="",COUNTIF(ListeIzinliGecis,$F31&"|"&$G31)>0),"","GEÇERSİZ GEÇİŞ")) | U31: =IF($A31="","",IF(OR($G31="TAHSIL",$I31>0),IF(OR($H31="",$I31=""),"",IF(ABS($I31-$H31)>zincirTolerans,"ZİNCİR KIRIK","OK")),"OK")) | V31: =IF($A31="","",1)
A32: FAT-00027 | B32: MUS-00003 | C32: FR-2026-0027 | D32: 46137 | F32: HATIRLATMA | G32: IHTAR | H32: 336500 | I32: 0 | J32: 336500 | K32: 31 | L32: Gıda | M32: A | N32: Takip notu 27 | O32: =IF($A32="","",IF(OR($G32="TAHSIL",$G32="KAPALI"),0,IF($D32="","",raporTarihi-$D32))) | P32: =IF($A32="","",IF($O32="","",IF($O32<=trv_kovaEsik1,"0-30",IF($O32<=trv_kovaEsik2,"31-60",IF($O32<=trv_kovaEsik3,"61-90","90+"))))) | Q32: =IF(OR($A32="",$G32="TAHSIL",$G32="KAPALI"),"",IF($P32="0-30",trv_olasilikK1,IF($P32="31-60",trv_olasilikK2,IF($P32="61-90",trv_olasilikK3,trv_olasilikK4)))) | R32: =IF(OR($A32="",$Q32=""),"",$J32*(1-$Q32)*MAX(trv_riskTaban,$K32/100)) | S32: =IF($A32="","",IF($B32="","YETİM",IF(COUNTIF(tblKartlar[KartId],$B32)=0,"YETİM",""))) | T32: =IF(OR($A32="",$F32=""),"",IF(OR($F32&"|"&$G32="",COUNTIF(ListeIzinliGecis,$F32&"|"&$G32)>0),"","GEÇERSİZ GEÇİŞ")) | U32: =IF($A32="","",IF(OR($G32="TAHSIL",$I32>0),IF(OR($H32="",$I32=""),"",IF(ABS($I32-$H32)>zincirTolerans,"ZİNCİR KIRIK","OK")),"OK")) | V32: =IF($A32="","",1)
A33: FAT-00028 | B33: MUS-00004 | C33: FR-2026-0028 | D33: 46243 | E33: 46243 | F33: IHTAR | G33: TAHSIL | H33: 346000 | I33: 346000 | J33: 0 | K33: 34 | L33: Lojistik | M33: B | N33: Takip notu 28 | O33: =IF($A33="","",IF(OR($G33="TAHSIL",$G33="KAPALI"),0,IF($D33="","",raporTarihi-$D33))) | P33: =IF($A33="","",IF($O33="","",IF($O33<=trv_kovaEsik1,"0-30",IF($O33<=trv_kovaEsik2,"31-60",IF($O33<=trv_kovaEsik3,"61-90","90+"))))) | Q33: =IF(OR($A33="",$G33="TAHSIL",$G33="KAPALI"),"",IF($P33="0-30",trv_olasilikK1,IF($P33="31-60",trv_olasilikK2,IF($P33="61-90",trv_olasilikK3,trv_olasilikK4)))) | R33: =IF(OR($A33="",$Q33=""),"",$J33*(1-$Q33)*MAX(trv_riskTaban,$K33/100)) | S33: =IF($A33="","",IF($B33="","YETİM",IF(COUNTIF(tblKartlar[KartId],$B33)=0,"YETİM",""))) | T33: =IF(OR($A33="",$F33=""),"",IF(OR($F33&"|"&$G33="",COUNTIF(ListeIzinliGecis,$F33&"|"&$G33)>0),"","GEÇERSİZ GEÇİŞ")) | U33: =IF($A33="","",IF(OR($G33="TAHSIL",$I33>0),IF(OR($H33="",$I33=""),"",IF(ABS($I33-$H33)>zincirTolerans,"ZİNCİR KIRIK","OK")),"OK")) | V33: =IF($A33="","",1)
O34: =IF($A34="","",IF(OR($G34="TAHSIL",$G34="KAPALI"),0,IF($D34="","",raporTarihi-$D34))) | P34: =IF($A34="","",IF($O34="","",IF($O34<=trv_kovaEsik1,"0-30",IF($O34<=trv_kovaEsik2,"31-60",IF($O34<=trv_kovaEsik3,"61-90","90+"))))) | Q34: =IF(OR($A34="",$G34="TAHSIL",$G34="KAPALI"),"",IF($P34="0-30",trv_olasilikK1,IF($P34="31-60",trv_olasilikK2,IF($P34="61-90",trv_olasilikK3,trv_olasilikK4)))) | R34: =IF(OR($A34="",$Q34=""),"",$J34*(1-$Q34)*MAX(trv_riskTaban,$K34/100)) | S34: =IF($A34="","",IF($B34="","YETİM",IF(COUNTIF(tblKartlar[KartId],$B34)=0,"YETİM",""))) | T34: =IF(OR($A34="",$F34=""),"",IF(OR($F34&"|"&$G34="",COUNTIF(ListeIzinliGecis,$F34&"|"&$G34)>0),"","GEÇERSİZ GEÇİŞ")) | U34: =IF($A34="","",IF(OR($G34="TAHSIL",$I34>0),IF(OR($H34="",$I34=""),"",IF(ABS($I34-$H34)>zincirTolerans,"ZİNCİR KIRIK","OK")),"OK")) | V34: =IF($A34="","",1)
O35: =IF($A35="","",IF(OR($G35="TAHSIL",$G35="KAPALI"),0,IF($D35="","",raporTarihi-$D35))) | P35: =IF($A35="","",IF($O35="","",IF($O35<=trv_kovaEsik1,"0-30",IF($O35<=trv_kovaEsik2,"31-60",IF($O35<=trv_kovaEsik3,"61-90","90+"))))) | Q35: =IF(OR($A35="",$G35="TAHSIL",$G35="KAPALI"),"",IF($P35="0-30",trv_olasilikK1,IF($P35="31-60",trv_olasilikK2,IF($P35="61-90",trv_olasilikK3,trv_olasilikK4)))) | R35: =IF(OR($A35="",$Q35=""),"",$J35*(1-$Q35)*MAX(trv_riskTaban,$K35/100)) | S35: =IF($A35="","",IF($B35="","YETİM",IF(COUNTIF(tblKartlar[KartId],$B35)=0,"YETİM",""))) | T35: =IF(OR($A35="",$F35=""),"",IF(OR($F35&"|"&$G35="",COUNTIF(ListeIzinliGecis,$F35&"|"&$G35)>0),"","GEÇERSİZ GEÇİŞ")) | U35: =IF($A35="","",IF(OR($G35="TAHSIL",$I35>0),IF(OR($H35="",$I35=""),"",IF(ABS($I35-$H35)>zincirTolerans,"ZİNCİR KIRIK","OK")),"OK")) | V35: =IF($A35="","",1)
O36: =IF($A36="","",IF(OR($G36="TAHSIL",$G36="KAPALI"),0,IF($D36="","",raporTarihi-$D36))) | P36: =IF($A36="","",IF($O36="","",IF($O36<=trv_kovaEsik1,"0-30",IF($O36<=trv_kovaEsik2,"31-60",IF($O36<=trv_kovaEsik3,"61-90","90+"))))) | Q36: =IF(OR($A36="",$G36="TAHSIL",$G36="KAPALI"),"",IF($P36="0-30",trv_olasilikK1,IF($P36="31-60",trv_olasilikK2,IF($P36="61-90",trv_olasilikK3,trv_olasilikK4)))) | R36: =IF(OR($A36="",$Q36=""),"",$J36*(1-$Q36)*MAX(trv_riskTaban,$K36/100)) | S36: =IF($A36="","",IF($B36="","YETİM",IF(COUNTIF(tblKartlar[KartId],$B36)=0,"YETİM",""))) | T36: =IF(OR($A36="",$F36=""),"",IF(OR($F36&"|"&$G36="",COUNTIF(ListeIzinliGecis,$F36&"|"&$G36)>0),"","GEÇERSİZ GEÇİŞ")) | U36: =IF($A36="","",IF(OR($G36="TAHSIL",$I36>0),IF(OR($H36="",$I36=""),"",IF(ABS($I36-$H36)>zincirTolerans,"ZİNCİR KIRIK","OK")),"OK")) | V36: =IF($A36="","",1)
O37: =IF($A37="","",IF(OR($G37="TAHSIL",$G37="KAPALI"),0,IF($D37="","",raporTarihi-$D37))) | P37: =IF($A37="","",IF($O37="","",IF($O37<=trv_kovaEsik1,"0-30",IF($O37<=trv_kovaEsik2,"31-60",IF($O37<=trv_kovaEsik3,"61-90","90+"))))) | Q37: =IF(OR($A37="",$G37="TAHSIL",$G37="KAPALI"),"",IF($P37="0-30",trv_olasilikK1,IF($P37="31-60",trv_olasilikK2,IF($P37="61-90",trv_olasilikK3,trv_olasilikK4)))) | R37: =IF(OR($A37="",$Q37=""),"",$J37*(1-$Q37)*MAX(trv_riskTaban,$K37/100)) | S37: =IF($A37="","",IF($B37="","YETİM",IF(COUNTIF(tblKartlar[KartId],$B37)=0,"YETİM",""))) | T37: =IF(OR($A37="",$F37=""),"",IF(OR($F37&"|"&$G37="",COUNTIF(ListeIzinliGecis,$F37&"|"&$G37)>0),"","GEÇERSİZ GEÇİŞ")) | U37: =IF($A37="","",IF(OR($G37="TAHSIL",$I37>0),IF(OR($H37="",$I37=""),"",IF(ABS($I37-$H37)>zincirTolerans,"ZİNCİR KIRIK","OK")),"OK")) | V37: =IF($A37="","",1)
O38: =IF($A38="","",IF(OR($G38="TAHSIL",$G38="KAPALI"),0,IF($D38="","",raporTarihi-$D38))) | P38: =IF($A38="","",IF($O38="","",IF($O38<=trv_kovaEsik1,"0-30",IF($O38<=trv_kovaEsik2,"31-60",IF($O38<=trv_kovaEsik3,"61-90","90+"))))) | Q38: =IF(OR($A38="",$G38="TAHSIL",$G38="KAPALI"),"",IF($P38="0-30",trv_olasilikK1,IF($P38="31-60",trv_olasilikK2,IF($P38="61-90",trv_olasilikK3,trv_olasilikK4)))) | R38: =IF(OR($A38="",$Q38=""),"",$J38*(1-$Q38)*MAX(trv_riskTaban,$K38/100)) | S38: =IF($A38="","",IF($B38="","YETİM",IF(COUNTIF(tblKartlar[KartId],$B38)=0,"YETİM",""))) | T38: =IF(OR($A38="",$F38=""),"",IF(OR($F38&"|"&$G38="",COUNTIF(ListeIzinliGecis,$F38&"|"&$G38)>0),"","GEÇERSİZ GEÇİŞ")) | U38: =IF($A38="","",IF(OR($G38="TAHSIL",$I38>0),IF(OR($H38="",$I38=""),"",IF(ABS($I38-$H38)>zincirTolerans,"ZİNCİR KIRIK","OK")),"OK")) | V38: =IF($A38="","",1)
O39: =IF($A39="","",IF(OR($G39="TAHSIL",$G39="KAPALI"),0,IF($D39="","",raporTarihi-$D39))) | P39: =IF($A39="","",IF($O39="","",IF($O39<=trv_kovaEsik1,"0-30",IF($O39<=trv_kovaEsik2,"31-60",IF($O39<=trv_kovaEsik3,"61-90","90+"))))) | Q39: =IF(OR($A39="",$G39="TAHSIL",$G39="KAPALI"),"",IF($P39="0-30",trv_olasilikK1,IF($P39="31-60",trv_olasilikK2,IF($P39="61-90",trv_olasilikK3,trv_olasilikK4)))) | R39: =IF(OR($A39="",$Q39=""),"",$J39*(1-$Q39)*MAX(trv_riskTaban,$K39/100)) | S39: =IF($A39="","",IF($B39="","YETİM",IF(COUNTIF(tblKartlar[KartId],$B39)=0,"YETİM",""))) | T39: =IF(OR($A39="",$F39=""),"",IF(OR($F39&"|"&$G39="",COUNTIF(ListeIzinliGecis,$F39&"|"&$G39)>0),"","GEÇERSİZ GEÇİŞ")) | U39: =IF($A39="","",IF(OR($G39="TAHSIL",$I39>0),IF(OR($H39="",$I39=""),"",IF(ABS($I39-$H39)>zincirTolerans,"ZİNCİR KIRIK","OK")),"OK")) | V39: =IF($A39="","",1)
