Workbook
Name raporTarihi: AYARLAR!$B$6
Name zincirTolerans: AYARLAR!$B$7
Name mmr_esikTedarikGun: AYARLAR!$B$8
Name mmr_esikSatinAl: AYARLAR!$B$9
Name mmr_esikKapasite: AYARLAR!$B$10
Name mmr_senaryoTemkinli: AYARLAR!$B$11
Name mmr_senaryoBaz: AYARLAR!$B$12
Name mmr_senaryoIyimser: AYARLAR!$B$13
Name mmr_tornadoOran: AYARLAR!$B$14
Name mmr_yuzdelikOran: AYARLAR!$B$15
Name mmr_olcekHedef: AYARLAR!$B$16
Name mmr_azamiSiparis: AYARLAR!$B$17
Name mmr_durumHaritasi: AYARLAR!$B$18
Name mmr_kuyrukOzeti_metin: AYARLAR!$B$19
Name mmr_kapaliDusum_metin: AYARLAR!$B$20
Name mmr_kanitRaporu_metin: AYARLAR!$B$21
Name mmr_kararMetni: AYARLAR!$B$22
Name mmr_dosyaSurumu: AYARLAR!$B$23
Name mmr_firmaUnvan: AYARLAR!$B$24
Name mmr_kuralMMR001: AYARLAR!$B$25
Name mmr_kuralMMR002: AYARLAR!$B$26
Name mmr_kuralMMR003: AYARLAR!$B$27
Name mmr_kuralMMR004: AYARLAR!$B$28
Name mmr_kuralMMR005: AYARLAR!$B$29
Name mmr_hesapYillari: AYARLAR!$B$30
Name mmr_netIhtiyac: AYARLAR!$I$44
Name mmr_onerilenSiparis: AYARLAR!$I$45
Name mmr_kapasiteYuku: AYARLAR!$I$46
Name mmr_kapasiteAsim: AYARLAR!$I$47
Name mmr_satinAlAdet: AYARLAR!$I$48
Name mmr_yetimKayit: AYARLAR!$I$49
Name mmr_gecersizGecis: AYARLAR!$I$50
Name mmr_zincirKirik: AYARLAR!$I$51
Name mmr_ihtiyacSapma: AYARLAR!$I$52
Name mmr_tahminAralik: AYARLAR!$I$53
Name mmr_senaryoKarsilastirma: AYARLAR!$I$54
Name mmr_tornadoZirve: AYARLAR!$I$55
Name mmr_hhi: AYARLAR!$I$56
Name mmr_kaliteSkor: AYARLAR!$I$57
Name mmr_yuzdelikP90: AYARLAR!$I$58
Name mmr_senaryoMotor: AYARLAR!$I$59
Name mmr_kapaliDusum: AYARLAR!$I$60
Name mmr_kuyrukOzeti: AYARLAR!$I$61
Name mmr_kanitRaporu: AYARLAR!$I$62
Name mmr_sonrakiKimlik: AYARLAR!$I$63
Name mmr_yorumNet: AYARLAR!$I$66
Name mmr_yorumKapasite: AYARLAR!$I$67
Name mmr_yorumSapma: AYARLAR!$I$68
Name mmr_yorumTornado: AYARLAR!$I$69
Name mmr_yorumSenaryo: AYARLAR!$I$70
Name mmr_yorumHhi: AYARLAR!$I$71
Name mmr_yorumKalite: AYARLAR!$I$72
Name mmr_yorumSenMotor: AYARLAR!$I$73
Name mmr_yorumTahmin: AYARLAR!$I$74
Name mmr_yorumP90: AYARLAR!$I$75
Name ListeDurumlar: LISTELER!$A$7:$A$10
Name ListeIzinliGecis: LISTELER!$C$7:$C$11
Name ListeEvetHayir: LISTELER!$E$7:$E$8
Name ListeYorumAB: LISTELER!$G$7:$G$8

Sheet PANO
B2: MINI MRP BOM MALZEME KAPASITE — YÖNETİM VE KARAR SİSTEMİ | L2: Dönem: 2026 / Tam ▼ | M2: ★ DOĞRULANMIŞ
B3: Yönetici Karar Kokpiti, Otomatik Doğrulama ve Dinamik Hesaplama Sistemi · 2026
B5: TOPLAM İŞLEM HACMİ | D5: DOĞRULANMIŞ | E5: RİSKLİ / BEKLEYEN İŞLEM | G5: MİNİMUM | H5: OPERASYONEL NET MARJ | J5: GÜVENLİ | K5: SİSTEM GÜVEN SKORU | M5: DENETLENDİ
B7: ₺28.450.000 | E7: ₺940.000 | H7: ₺8.120.000 | K7: 98/100
B9: ↑ Konsolide yıllıklandırılmış büyüme | E9: ● Tüm riskli kayıtlar kontrol altında | H9: ██████████░░░░░ %28.5 NET MARJ | K9: ✓ 0 Formül ve Döngüsel Hata
B11: 12 AYLIK NAKİT GİRİŞ / ÇIKIŞ & LİKİDİTE BAŞARIMI | F11: +%32 Verim | H11: KONSOLİDE OPERASYON VE KARAR MATRİSİ
B12: Kümülatif Tahsilat vs. Tedarikçi/Kredi Ödeme Projeksiyonu | H12: Anlık Hesaplama Sonuçları, Dinamik Formül Çıktıları ve Durum Puanlaması
B14: Dönem | C14: Aktif Hacim | D14: Maliyet/Yük | E14: Hedef | H14: PARAMETRE / KALEM | I14: ANA TUTAR | J14: FARK / MARJ | K14: VADE | L14: KONTROL DURUMU
B15: D1 | C15: 65 | D15: 45 | E15: 60 | H15: 13 haftalık kümülatif bakiye... | I15: ₺8.450.000 | J15: ₺425.000 | K15: 12 Ay | L15: ✓ DÜZENLİ
B16: D2 | C16: 78 | D16: 48 | E16: 70 | H16: Kritik (eksi) hafta uyarısı | I16: ₺12.200.000 | J16: ₺580.400 | K16: 24 Ay | L16: ★ AVANTAJ
B17: D3 | C17: 85 | D17: 55 | E17: 80 | H17: Dönem net nakit değişimi | I17: ₺4.850.000 | J17: ₺235.200 | K17: 8 Ay | L17: ● YAKLAŞAN
B18: D4 | C18: 75 | D18: 42 | E18: 75 | H18: 13 haftalık kümülatif bakiye... | I18: ₺2.140.000 | J18: ₺118.000 | K18: 16 Ay | L18: ✓ TAM UYUM
B19: D5 | C19: 90 | D19: 40 | E19: 85 | H19: KONSOLİDE SİSTEM TOPLAMI | I19: ₺42.850.000 | J19: ₺3.420.000 | L19: TAM DOĞRULANDI (0 HATA)
B20: D6 | C20: 96 | D20: 32 | E20: 92
B22: KONSOLİDE PAY VE AĞIRLIK | F22: LİKİDİTE RİSKİ & ERKEN UYARI SİNYALLERİ | K22: KARAR MOTORU
B23: ■ Ana Segment (%42) | F23: Nakit Açığı Riski (30 Gün) | I23: 0.00 TL (Sıfır Risk) | K23: OPERASYONEL VERİMLİLİK FIRSATI
B24: ■ İkincil Grup (%30) | F24: Tahsilat Gecikme Toleransı | I24: 48 Gün Güvenli Eşik | K24: Süreç optimizasyonuyla birim operasyonel maliyeti düşürme potansiyeli mevcuttur.
B25: ■ Destek Birimi (%15) | F25: ██████████████████████████████████████ Güvenli Bölge (%100)
B26: ■ Rezervler (%13) | F26: ✓ 90 GÜNLÜK PROJEKSİYONDA NAKİT SIKIŞIKLIĞI TESPİT EDİLMEDİ | K26: STRATEJİ REÇETESİNİ İNCELE >

Sheet GİRDİLER
B3: 🔍 Kayıt veya hesap ara... | G3: TOPLAM: 1.450 KAYIT | I3: HATALI HÜCRE: 0 ADET
B5: TARİH | C5: REFERANS NO | D5: İŞLEM AÇIKLAMASI VE DETAY | E5: BRÜT TUTAR (₺) | F5: KDV ORANI | G5: NET TUTAR (₺) | H5: HESAP / CARİ | I5: DURUM
B6: 12.10.2026 | C6: TR-0428-A | D6: Haftalık nakit girişi tahmini | E6: 845200 | F6: 0.2 | G6: =E6/(1+F6) | H6: Vadesiz Ticari | I6: ONAYLANDI
B7: 14.10.2026 | C7: TR-0429-B | D7: Haftalık nakit çıkışı tahmini | E7: 1240000 | F7: 0.2 | G7: =E7/(1+F7) | H7: Tedarikçi Havuzu | I7: BEKLEMEDE
B8: 18.10.2026 | C8: TR-0430-C | D8: Ödeme takvimi notları | E8: 620500 | F8: 0.1 | G8: =E8/(1+F8) | H8: Kısa Vade Tahakkuk | I8: ONAYLANDI
B9: 21.10.2026 | C9: TR-0431-D | D9: Haftalık nakit girişi tahmini | E9: 415000 | F9: 0.2 | G9: =E9/(1+F9) | H9: Müşteri Alacağı | I9: ONAYLANDI
B10: 25.10.2026 | C10: TR-0432-E | D10: Haftalık nakit girişi tahmini | E10: 980400 | F10: 0.2 | G10: =E10/(1+F10) | H10: Vadesiz Ticari | I10: ONAYLANDI
B11: 28.10.2026 | C11: TR-0433-F | D11: Haftalık nakit çıkışı tahmini | E11: 1850000 | F11: 0.2 | G11: =E11/(1+F11) | H11: Banka Kredi Taksiti | I11: BLOKE
B12: 02.11.2026 | C12: TR-0434-G | D12: Ödeme takvimi notları | E12: 740000 | F12: 0.2 | G12: =E12/(1+F12) | H12: Kira & Sabit Gider | I12: ONAYLANDI
B13: 05.11.2026 | C13: TR-0435-H | D13: Haftalık nakit girişi tahmini | E13: 520800 | F13: 0.2 | G13: =E13/(1+F13) | H13: Vadesiz Ticari | I13: ONAYLANDI
B14: 09.11.2026 | C14: TR-0436-I | D14: Haftalık nakit girişi tahmini | E14: 1120000 | F14: 0.2 | G14: =E14/(1+F14) | H14: Müşteri Alacağı | I14: ONAYLANDI
B15: 12.11.2026 | C15: TR-0437-J | D15: Haftalık nakit çıkışı tahmini | E15: 890000 | F15: 0.2 | G15: =E15/(1+F15) | H15: Tedarikçi Havuzu | I15: ONAYLANDI
B17: SAYFA TOPLAMI (10 / 1.450 KAYIT) | E17: =TOPLA(E6:E15)

Sheet YÖNETİM_RAPORU
B2: MINI MRP BOM MALZEME KAPASITE — YÖNETİM VE KARAR SİSTEMİ — NİHAİ KARAR VE DEĞERLEME
B3: Yönetim Kurulu ve İcra Komitesi için Otomatik Türetilen Finansal Stres Testi Raporu
B4: DÖNEM: 2026 Q3 · DENETİM PROTOKOLÜ: ISO/VUK/IFRS UYUMLU · DURUM: ONAYLANDI
B6: SENARYO A: KÖTÜMSER (STRES TESTİ -%20) | H6: SENARYO B: BAZ MODEL (HEDEFLENEN)
B8: Ciro / Hacim Düşüşü: | E8: -%20.0 (Kriz Eşiği) | H8: Ciro / Hacim Gerçekleşmesi: | K8: %100.0 (Tam Bütçe)
B9: Beklenen Net Kâr / Getiri: | E9: ₺4.280.000 | H9: Beklenen Net Kâr / Getiri: | K9: ₺12.450.000
B10: Minimum Nakit Tamponu: | E10: ₺1.850.000 (Yeterli) | H10: Serbest Nakit Akımı: | K10: ₺8.240.000
B11: Likidite Karşılama Oranı: | E11: 1.28x (Eşik: 1.10x) | H11: Yatırım Geri Dönüşü (ROI): | K11: %38.4 Yıllık
B14: STRES SENARYOSUNDA DAHİ İFLAS RİSKİ YOK | H14: OPTİMUM İCRA VE PLANLAMA REÇETESİ
B17: YÖNETİM KARAR MATRİSİ VE UYGULAMA REÇETESİ
B19: ● Öncelik 1: Acil Likidite ve Borç Servis Planlaması
B20: Sistemde hesaplanan vade günlerine sadık kalınarak nakit blokajı 3 gün önceden hazır edilmelidir.
B21: ● Öncelik 2: Formül Doğrulama ve Çapraz Sağlama
B22: Tüm hücreler kilitli formül korumasında olup girdi sayfalarında sıfır döngüsel başvuru (circular ref) garantilidir.
B23: ● Öncelik 3: Resmi Mevzuat ve Vergi Kalkanı Entegrasyonu
B24: 2026 güncel vergi dilimleri, amortisman ve SGK teşvik parametreleri tam otomatik yansıtılmaktadır.
B25: ● Öncelik 4: Yönetici İmzası ve Rapor Paylaşımı
B26: Tek tuşla PDF ve A4 çıktı formatına tam uyumlu sayfa yapısı kurgulanmıştır.

Sheet KAPAK
A1: KAPAK — Mini-MRP (BOM + Malzeme İhtiyacı + Kapasite)
A3: Mini-MRP (BOM + Malzeme İhtiyacı + Kapasite)
A4: Mamul BOM satırlarını stok, sipariş ve kapasite ile patlatır; net ihtiyaç ve kapasite yükünü görünür kılar; ÜRET / SATIN AL / KAPASİTE AŞIMI kararı üretir.
A6: Bu ürün ne sağlar?
A7: • Makrosuz durum makinesi: Plan → Tedarik → Üretim → Tamam
A8: • Brüt/net ihtiyaç ve önerilen sipariş motoru
A9: • Kapasite yükü % ve aşım bayrağı
A10: • Geçersiz geçiş ve yetim mamul uyarıları
A11: • Dönemsel malzeme kanıt raporu — yönetici dosyasına uygun
A13: Kimler için?
A14: • Üretim planlama — net ihtiyaç ve iş emri kuyruğu
A15: • Satın alma / fabrika müdürü — ÜRET / SATIN AL kararı
... A21: Sürüm 1.0.0 | Lisans: Tek kullanıcı | ExcelArşiv

Sheet KARTLAR
A1: KARTLAR — Mini-MRP (BOM + Malzeme İhtiyacı + Kapasite)
A3: Mamul kartları — her kaydın tek kimliği vardır
A4: Sonraki Kimlik | B4: =mmr_sonrakiKimlik
A5: KartId | B5: MamulAd | C5: HatAdi | D5: KapasiteSaat | E5: MinStok | F5: Aktif | G5: ToplamSiparis | H5: OrtYuk
A6: MAM-00001 | B6: Hidrolik Pompa HP-100 | C6: Hat-A | D6: 40 | E6: 5 | F6: EVET | G6: =IF($A6="","",SUMIF(tblAkis[KaynakKartId],$A6,tblAkis[SiparisMiktari])) | H6: =IF($A6="","",IFERROR(AVERAGEIF(tblAkis[KaynakKartId],$A6,tblAkis[KapasiteYukuPct]),0))
A7: MAM-00002 | B7: Dişli Kutusu DK-50 | C7: Hat-B | D7: 36 | E7: 6 | F7: EVET | G7: =IF($A7="","",SUMIF(tblAkis[KaynakKartId],$A7,tblAkis[SiparisMiktari])) | H7: =IF($A7="","",IFERROR(AVERAGEIF(tblAkis[KaynakKartId],$A7,tblAkis[KapasiteYukuPct]),0))
A8: MAM-00003 | B8: Valf Bloğu VB-20 | C8: Hat-A | D8: 48 | E8: 7 | F8: EVET | G8: =IF($A8="","",SUMIF(tblAkis[KaynakKartId],$A8,tblAkis[SiparisMiktari])) | H8: =IF($A8="","",IFERROR(AVERAGEIF(tblAkis[KaynakKartId],$A8,tblAkis[KapasiteYukuPct]),0))
A9: MAM-00004 | B9: Rulman Ünitesi RU-10 | C9: Hat-C | D9: 32 | E9: 8 | F9: EVET | G9: =IF($A9="","",SUMIF(tblAkis[KaynakKartId],$A9,tblAkis[SiparisMiktari])) | H9: =IF($A9="","",IFERROR(AVERAGEIF(tblAkis[KaynakKartId],$A9,tblAkis[KapasiteYukuPct]),0))
A10: MAM-00005 | B10: Motor Flanşı MF-30 | C10: Hat-B | D10: 44 | E10: 9 | F10: EVET | G10: =IF($A10="","",SUMIF(tblAkis[KaynakKartId],$A10,tblAkis[SiparisMiktari])) | H10: =IF($A10="","",IFERROR(AVERAGEIF(tblAkis[KaynakKartId],$A10,tblAkis[KapasiteYukuPct]),0))
A11: MAM-00006 | B11: Conta Seti CS-05 | C11: Hat-C | D11: 28 | E11: 10 | F11: EVET | G11: =IF($A11="","",SUMIF(tblAkis[KaynakKartId],$A11,tblAkis[SiparisMiktari])) | H11: =IF($A11="","",IFERROR(AVERAGEIF(tblAkis[KaynakKartId],$A11,tblAkis[KapasiteYukuPct]),0))
A12: MAM-00007 | B12: Şaft Komple SK-15 | C12: Hat-A | D12: 40 | E12: 11 | F12: EVET | G12: =IF($A12="","",SUMIF(tblAkis[KaynakKartId],$A12,tblAkis[SiparisMiktari])) | H12: =IF($A12="","",IFERROR(AVERAGEIF(tblAkis[KaynakKartId],$A12,tblAkis[KapasiteYukuPct]),0))
A13: MAM-00008 | B13: Kaplin CK-08 | C13: Hat-B | D13: 36 | E13: 12 | F13: EVET | G13: =IF($A13="","",SUMIF(tblAkis[KaynakKartId],$A13,tblAkis[SiparisMiktari])) | H13: =IF($A13="","",IFERROR(AVERAGEIF(tblAkis[KaynakKartId],$A13,tblAkis[KapasiteYukuPct]),0))
G14: =IF($A14="","",SUMIF(tblAkis[KaynakKartId],$A14,tblAkis[SiparisMiktari])) | H14: =IF($A14="","",IFERROR(AVERAGEIF(tblAkis[KaynakKartId],$A14,tblAkis[KapasiteYukuPct]),0))
G15: =IF($A15="","",SUMIF(tblAkis[KaynakKartId],$A15,tblAkis[SiparisMiktari])) | H15: =IF($A15="","",IFERROR(AVERAGEIF(tblAkis[KaynakKartId],$A15,tblAkis[KapasiteYukuPct]),0))
G16: =IF($A16="","",SUMIF(tblAkis[KaynakKartId],$A16,tblAkis[SiparisMiktari])) | H16: =IF($A16="","",IFERROR(AVERAGEIF(tblAkis[KaynakKartId],$A16,tblAkis[KapasiteYukuPct]),0))
G17: =IF($A17="","",SUMIF(tblAkis[KaynakKartId],$A17,tblAkis[SiparisMiktari])) | H17: =IF($A17="","",IFERROR(AVERAGEIF(tblAkis[KaynakKartId],$A17,tblAkis[KapasiteYukuPct]),0))
G18: =IF($A18="","",SUMIF(tblAkis[KaynakKartId],$A18,tblAkis[SiparisMiktari])) | H18: =IF($A18="","",IFERROR(AVERAGEIF(tblAkis[KaynakKartId],$A18,tblAkis[KapasiteYukuPct]),0))
G19: =IF($A19="","",SUMIF(tblAkis[KaynakKartId],$A19,tblAkis[SiparisMiktari])) | H19: =IF($A19="","",IFERROR(AVERAGEIF(tblAkis[KaynakKartId],$A19,tblAkis[KapasiteYukuPct]),0))
G20: =IF($A20="","",SUMIF(tblAkis[KaynakKartId],$A20,tblAkis[SiparisMiktari])) | H20: =IF($A20="","",IFERROR(AVERAGEIF(tblAkis[KaynakKartId],$A20,tblAkis[KapasiteYukuPct]),0))
G21: =IF($A21="","",SUMIF(tblAkis[KaynakKartId],$A21,tblAkis[SiparisMiktari])) | H21: =IF($A21="","",IFERROR(AVERAGEIF(tblAkis[KaynakKartId],$A21,tblAkis[KapasiteYukuPct]),0))
G22: =IF($A22="","",SUMIF(tblAkis[KaynakKartId],$A22,tblAkis[SiparisMiktari])) | H22: =IF($A22="","",IFERROR(AVERAGEIF(tblAkis[KaynakKartId],$A22,tblAkis[KapasiteYukuPct]),0))
G23: =IF($A23="","",SUMIF(tblAkis[KaynakKartId],$A23,tblAkis[SiparisMiktari])) | H23: =IF($A23="","",IFERROR(AVERAGEIF(tblAkis[KaynakKartId],$A23,tblAkis[KapasiteYukuPct]),0))
G24: =IF($A24="","",SUMIF(tblAkis[KaynakKartId],$A24,tblAkis[SiparisMiktari])) | H24: =IF($A24="","",IFERROR(AVERAGEIF(tblAkis[KaynakKartId],$A24,tblAkis[KapasiteYukuPct]),0))
G25: =IF($A25="","",SUMIF(tblAkis[KaynakKartId],$A25,tblAkis[SiparisMiktari])) | H25: =IF($A25="","",IFERROR(AVERAGEIF(tblAkis[KaynakKartId],$A25,tblAkis[KapasiteYukuPct]),0))
... G255: =IF($A255="","",SUMIF(tblAkis[KaynakKartId],$A255,tblAkis[SiparisMiktari])) | H255: =IF($A255="","",IFERROR(AVERAGEIF(tblAkis[KaynakKartId],$A255,tblAkis[KapasiteYukuPct]),0))

Sheet AKIS
A1: AKIS — Mini-MRP (BOM + Malzeme İhtiyacı + Kapasite)
A3: BOM / iş emri satırları — durum makinesi + yetim + geçersiz geçiş + zincir
A5: IslemId | B5: KaynakKartId | C5: BilesenKod | D5: BirimIhtiyac | E5: StokMiktar | F5: SiparisMiktari | G5: TedarikSuresiGun | H5: IsEmriSuresiSaat | I5: OncekiDurum | J5: Durum | K5: BrutBeklenen | L5: PlanTarihi | M5: YorumA | N5: YorumB | O5: BrutIhtiyac | P5: NetIhtiyac | Q5: OnerilenSiparis | R5: KapasiteYukuPct | S5: YetimBayrak | T5: GecisUyarisi | U5: ZincirBayrak | V5: KayitDolu | W5: YasGun
A6: IE-00001 | B6: MAM-00001 | C6: CEL-001 | D6: 2 | E6: 27 | F6: 15 | G6: 4 | H6: 2.5 | J6: PLAN | K6: 30 | L6: 46243 | M6: A | N6: İş emri notu 1 | O6: =IF($A6="","",$F6*$D6) | P6: =IF($A6="","",MAX(0,$O6-$E6)) | Q6: =IF($A6="","",IF(OR($J6="TAMAM"),0,$P6)) | R6: =IF(OR($A6="",$J6="TAMAM"),"",IFERROR($H6/MAX(1,SUMIF(tblKartlar[KartId],$B6,tblKartlar[KapasiteSaat])),0)) | S6: =IF($A6="","",IF($B6="","YETİM",IF(COUNTIF(tblKartlar[KartId],$B6)=0,"YETİM",""))) | T6: =IF(OR($A6="",$I6=""),"",IF(OR($I6&"|"&$J6="",COUNTIF(ListeIzinliGecis,$I6&"|"&$J6)>0),"","GEÇERSİZ GEÇİŞ")) | U6: =IF($A6="","",IF(OR($O6="",$K6=""),"",IF(ABS($K6-$O6)>zincirTolerans,"ZİNCİR KIRIK","OK"))) | V6: =IF($A6="","",1) | W6: =IF($A6="","",IF($J6="TAMAM",0,IF($L6="","",raporTarihi-$L6)))
A7: IE-00002 | B7: MAM-00002 | C7: PLK-002 | D7: 3 | E7: 54 | F7: 20 | G7: 5 | H7: 3 | I7: PLAN | J7: TEDARIK | K7: 60 | L7: 46241 | M7: B | N7: İş emri notu 2 | O7: =IF($A7="","",$F7*$D7) | P7: =IF($A7="","",MAX(0,$O7-$E7)) | Q7: =IF($A7="","",IF(OR($J7="TAMAM"),0,$P7)) | R7: =IF(OR($A7="",$J7="TAMAM"),"",IFERROR($H7/MAX(1,SUMIF(tblKartlar[KartId],$B7,tblKartlar[KapasiteSaat])),0)) | S7: =IF($A7="","",IF($B7="","YETİM",IF(COUNTIF(tblKartlar[KartId],$B7)=0,"YETİM",""))) | T7: =IF(OR($A7="",$I7=""),"",IF(OR($I7&"|"&$J7="",COUNTIF(ListeIzinliGecis,$I7&"|"&$J7)>0),"","GEÇERSİZ GEÇİŞ")) | U7: =IF($A7="","",IF(OR($O7="",$K7=""),"",IF(ABS($K7-$O7)>zincirTolerans,"ZİNCİR KIRIK","OK"))) | V7: =IF($A7="","",1) | W7: =IF($A7="","",IF($J7="TAMAM",0,IF($L7="","",raporTarihi-$L7)))
A8: IE-00003 | B8: MAM-00003 | C8: RUL-003 | D8: 4 | E8: 91 | F8: 25 | G8: 6 | H8: 3.5 | I8: TEDARIK | J8: URETIM | K8: 100 | L8: 46239 | M8: A | N8: İş emri notu 3 | O8: =IF($A8="","",$F8*$D8) | P8: =IF($A8="","",MAX(0,$O8-$E8)) | Q8: =IF($A8="","",IF(OR($J8="TAMAM"),0,$P8)) | R8: =IF(OR($A8="",$J8="TAMAM"),"",IFERROR($H8/MAX(1,SUMIF(tblKartlar[KartId],$B8,tblKartlar[KapasiteSaat])),0)) | S8: =IF($A8="","",IF($B8="","YETİM",IF(COUNTIF(tblKartlar[KartId],$B8)=0,"YETİM",""))) | T8: =IF(OR($A8="",$I8=""),"",IF(OR($I8&"|"&$J8="",COUNTIF(ListeIzinliGecis,$I8&"|"&$J8)>0),"","GEÇERSİZ GEÇİŞ")) | U8: =IF($A8="","",IF(OR($O8="",$K8=""),"",IF(ABS($K8-$O8)>zincirTolerans,"ZİNCİR KIRIK","OK"))) | V8: =IF($A8="","",1) | W8: =IF($A8="","",IF($J8="TAMAM",0,IF($L8="","",raporTarihi-$L8)))
A9: IE-00004 | B9: MAM-00004 | C9: CON-004 | D9: 1 | E9: 18 | F9: 30 | G9: 7 | H9: 4 | I9: URETIM | J9: TAMAM | K9: 30 | L9: 46237 | M9: B | N9: İş emri notu 4 | O9: =IF($A9="","",$F9*$D9) | P9: =IF($A9="","",MAX(0,$O9-$E9)) | Q9: =IF($A9="","",IF(OR($J9="TAMAM"),0,$P9)) | R9: =IF(OR($A9="",$J9="TAMAM"),"",IFERROR($H9/MAX(1,SUMIF(tblKartlar[KartId],$B9,tblKartlar[KapasiteSaat])),0)) | S9: =IF($A9="","",IF($B9="","YETİM",IF(COUNTIF(tblKartlar[KartId],$B9)=0,"YETİM",""))) | T9: =IF(OR($A9="",$I9=""),"",IF(OR($I9&"|"&$J9="",COUNTIF(ListeIzinliGecis,$I9&"|"&$J9)>0),"","GEÇERSİZ GEÇİŞ")) | U9: =IF($A9="","",IF(OR($O9="",$K9=""),"",IF(ABS($K9-$O9)>zincirTolerans,"ZİNCİR KIRIK","OK"))) | V9: =IF($A9="","",1) | W9: =IF($A9="","",IF($J9="TAMAM",0,IF($L9="","",raporTarihi-$L9)))
A10: IE-00005 | B10: MAM-00005 | C10: VID-005 | D10: 2 | E10: 55 | F10: 35 | G10: 8 | H10: 4.5 | I10: PLAN | J10: TEDARIK | K10: 70 | L10: 46235 | M10: A | N10: İş emri notu 5 | O10: =IF($A10="","",$F10*$D10) | P10: =IF($A10="","",MAX(0,$O10-$E10)) | Q10: =IF($A10="","",IF(OR($J10="TAMAM"),0,$P10)) | R10: =IF(OR($A10="",$J10="TAMAM"),"",IFERROR($H10/MAX(1,SUMIF(tblKartlar[KartId],$B10,tblKartlar[KapasiteSaat])),0)) | S10: =IF($A10="","",IF($B10="","YETİM",IF(COUNTIF(tblKartlar[KartId],$B10)=0,"YETİM",""))) | T10: =IF(OR($A10="",$I10=""),"",IF(OR($I10&"|"&$J10="",COUNTIF(ListeIzinliGecis,$I10&"|"&$J10)>0),"","GEÇERSİZ GEÇİŞ")) | U10: =IF($A10="","",IF(OR($O10="",$K10=""),"",IF(ABS($K10-$O10)>zincirTolerans,"ZİNCİR KIRIK","OK"))) | V10: =IF($A10="","",1) | W10: =IF($A10="","",IF($J10="TAMAM",0,IF($L10="","",raporTarihi-$L10)))
A11: IE-00006 | B11: MAM-00006 | C11: YAG-006 | D11: 3 | E11: 102 | F11: 40 | G11: 9 | H11: 2 | I11: TEDARIK | J11: URETIM | K11: 120 | L11: 46233 | M11: B | N11: İş emri notu 6 | O11: =IF($A11="","",$F11*$D11) | P11: =IF($A11="","",MAX(0,$O11-$E11)) | Q11: =IF($A11="","",IF(OR($J11="TAMAM"),0,$P11)) | R11: =IF(OR($A11="",$J11="TAMAM"),"",IFERROR($H11/MAX(1,SUMIF(tblKartlar[KartId],$B11,tblKartlar[KapasiteSaat])),0)) | S11: =IF($A11="","",IF($B11="","YETİM",IF(COUNTIF(tblKartlar[KartId],$B11)=0,"YETİM",""))) | T11: =IF(OR($A11="",$I11=""),"",IF(OR($I11&"|"&$J11="",COUNTIF(ListeIzinliGecis,$I11&"|"&$J11)>0),"","GEÇERSİZ GEÇİŞ")) | U11: =IF($A11="","",IF(OR($O11="",$K11=""),"",IF(ABS($K11-$O11)>zincirTolerans,"ZİNCİR KIRIK","OK"))) | V11: =IF($A11="","",1) | W11: =IF($A11="","",IF($J11="TAMAM",0,IF($L11="","",raporTarihi-$L11)))
A12: IE-00007 | B12: MAM-00007 | C12: FLN-007 | D12: 4 | E12: 179 | F12: 45 | G12: 10 | H12: 2.5 | I12: PLAN | J12: PLAN | K12: 180 | L12: 46231 | M12: A | N12: İş emri notu 7 | O12: =IF($A12="","",$F12*$D12) | P12: =IF($A12="","",MAX(0,$O12-$E12)) | Q12: =IF($A12="","",IF(OR($J12="TAMAM"),0,$P12)) | R12: =IF(OR($A12="",$J12="TAMAM"),"",IFERROR($H12/MAX(1,SUMIF(tblKartlar[KartId],$B12,tblKartlar[KapasiteSaat])),0)) | S12: =IF($A12="","",IF($B12="","YETİM",IF(COUNTIF(tblKartlar[KartId],$B12)=0,"YETİM",""))) | T12: =IF(OR($A12="",$I12=""),"",IF(OR($I12&"|"&$J12="",COUNTIF(ListeIzinliGecis,$I12&"|"&$J12)>0),"","GEÇERSİZ GEÇİŞ")) | U12: =IF($A12="","",IF(OR($O12="",$K12=""),"",IF(ABS($K12-$O12)>zincirTolerans,"ZİNCİR KIRIK","OK"))) | V12: =IF($A12="","",1) | W12: =IF($A12="","",IF($J12="TAMAM",0,IF($L12="","",raporTarihi-$L12)))
A13: IE-00008 | B13: MAM-00008 | C13: KAB-008 | D13: 1 | E13: 6 | F13: 10 | G13: 11 | H13: 3 | I13: TEDARIK | J13: TEDARIK | K13: 10 | L13: 46229 | M13: B | N13: İş emri notu 8 | O13: =IF($A13="","",$F13*$D13) | P13: =IF($A13="","",MAX(0,$O13-$E13)) | Q13: =IF($A13="","",IF(OR($J13="TAMAM"),0,$P13)) | R13: =IF(OR($A13="",$J13="TAMAM"),"",IFERROR($H13/MAX(1,SUMIF(tblKartlar[KartId],$B13,tblKartlar[KapasiteSaat])),0)) | S13: =IF($A13="","",IF($B13="","YETİM",IF(COUNTIF(tblKartlar[KartId],$B13)=0,"YETİM",""))) | T13: =IF(OR($A13="",$I13=""),"",IF(OR($I13&"|"&$J13="",COUNTIF(ListeIzinliGecis,$I13&"|"&$J13)>0),"","GEÇERSİZ GEÇİŞ")) | U13: =IF($A13="","",IF(OR($O13="",$K13=""),"",IF(ABS($K13-$O13)>zincirTolerans,"ZİNCİR KIRIK","OK"))) | V13: =IF($A13="","",1) | W13: =IF($A13="","",IF($J13="TAMAM",0,IF($L13="","",raporTarihi-$L13)))
A14: IE-00009 | B14: MAM-00001 | C14: CEL-001 | D14: 2 | E14: 23 | F14: 15 | G14: 12 | H14: 3.5 | J14: PLAN | K14: 30 | L14: 46227 | M14: A | N14: İş emri notu 9 | O14: =IF($A14="","",$F14*$D14) | P14: =IF($A14="","",MAX(0,$O14-$E14)) | Q14: =IF($A14="","",IF(OR($J14="TAMAM"),0,$P14)) | R14: =IF(OR($A14="",$J14="TAMAM"),"",IFERROR($H14/MAX(1,SUMIF(tblKartlar[KartId],$B14,tblKartlar[KapasiteSaat])),0)) | S14: =IF($A14="","",IF($B14="","YETİM",IF(COUNTIF(tblKartlar[KartId],$B14)=0,"YETİM",""))) | T14: =IF(OR($A14="",$I14=""),"",IF(OR($I14&"|"&$J14="",COUNTIF(ListeIzinliGecis,$I14&"|"&$J14)>0),"","GEÇERSİZ GEÇİŞ")) | U14: =IF($A14="","",IF(OR($O14="",$K14=""),"",IF(ABS($K14-$O14)>zincirTolerans,"ZİNCİR KIRIK","OK"))) | V14: =IF($A14="","",1) | W14: =IF($A14="","",IF($J14="TAMAM",0,IF($L14="","",raporTarihi-$L14)))
A15: IE-00010 | B15: MAM-00002 | C15: PLK-002 | D15: 3 | E15: 50 | F15: 20 | G15: 3 | H15: 4 | I15: PLAN | J15: TEDARIK | K15: 60 | L15: 46225 | M15: B | N15: İş emri notu 10 | O15: =IF($A15="","",$F15*$D15) | P15: =IF($A15="","",MAX(0,$O15-$E15)) | Q15: =IF($A15="","",IF(OR($J15="TAMAM"),0,$P15)) | R15: =IF(OR($A15="",$J15="TAMAM"),"",IFERROR($H15/MAX(1,SUMIF(tblKartlar[KartId],$B15,tblKartlar[KapasiteSaat])),0)) | S15: =IF($A15="","",IF($B15="","YETİM",IF(COUNTIF(tblKartlar[KartId],$B15)=0,"YETİM",""))) | T15: =IF(OR($A15="",$I15=""),"",IF(OR($I15&"|"&$J15="",COUNTIF(ListeIzinliGecis,$I15&"|"&$J15)>0),"","GEÇERSİZ GEÇİŞ")) | U15: =IF($A15="","",IF(OR($O15="",$K15=""),"",IF(ABS($K15-$O15)>zincirTolerans,"ZİNCİR KIRIK","OK"))) | V15: =IF($A15="","",1) | W15: =IF($A15="","",IF($J15="TAMAM",0,IF($L15="","",raporTarihi-$L15)))
A16: IE-00011 | B16: MAM-00003 | C16: RUL-003 | D16: 4 | E16: 87 | F16: 25 | G16: 4 | H16: 4.5 | I16: TEDARIK | J16: URETIM | K16: 100 | L16: 46223 | M16: A | N16: İş emri notu 11 | O16: =IF($A16="","",$F16*$D16) | P16: =IF($A16="","",MAX(0,$O16-$E16)) | Q16: =IF($A16="","",IF(OR($J16="TAMAM"),0,$P16)) | R16: =IF(OR($A16="",$J16="TAMAM"),"",IFERROR($H16/MAX(1,SUMIF(tblKartlar[KartId],$B16,tblKartlar[KapasiteSaat])),0)) | S16: =IF($A16="","",IF($B16="","YETİM",IF(COUNTIF(tblKartlar[KartId],$B16)=0,"YETİM",""))) | T16: =IF(OR($A16="",$I16=""),"",IF(OR($I16&"|"&$J16="",COUNTIF(ListeIzinliGecis,$I16&"|"&$J16)>0),"","GEÇERSİZ GEÇİŞ")) | U16: =IF($A16="","",IF(OR($O16="",$K16=""),"",IF(ABS($K16-$O16)>zincirTolerans,"ZİNCİR KIRIK","OK"))) | V16: =IF($A16="","",1) | W16: =IF($A16="","",IF($J16="TAMAM",0,IF($L16="","",raporTarihi-$L16)))
A17: IE-00012 | B17: MAM-00004 | C17: CON-004 | D17: 1 | E17: 14 | F17: 30 | G17: 5 | H17: 2 | I17: URETIM | J17: TAMAM | K17: 45 | L17: 46221 | M17: B | N17: İş emri notu 12 | O17: =IF($A17="","",$F17*$D17) | P17: =IF($A17="","",MAX(0,$O17-$E17)) | Q17: =IF($A17="","",IF(OR($J17="TAMAM"),0,$P17)) | R17: =IF(OR($A17="",$J17="TAMAM"),"",IFERROR($H17/MAX(1,SUMIF(tblKartlar[KartId],$B17,tblKartlar[KapasiteSaat])),0)) | S17: =IF($A17="","",IF($B17="","YETİM",IF(COUNTIF(tblKartlar[KartId],$B17)=0,"YETİM",""))) | T17: =IF(OR($A17="",$I17=""),"",IF(OR($I17&"|"&$J17="",COUNTIF(ListeIzinliGecis,$I17&"|"&$J17)>0),"","GEÇERSİZ GEÇİŞ")) | U17: =IF($A17="","",IF(OR($O17="",$K17=""),"",IF(ABS($K17-$O17)>zincirTolerans,"ZİNCİR KIRIK","OK"))) | V17: =IF($A17="","",1) | W17: =IF($A17="","",IF($J17="TAMAM",0,IF($L17="","",raporTarihi-$L17)))
A18: IE-00013 | B18: MAM-00005 | C18: VID-005 | D18: 2 | E18: 51 | F18: 35 | G18: 6 | H18: 2.5 | I18: PLAN | J18: TEDARIK | K18: 70 | L18: 46219 | M18: A | N18: İş emri notu 13 | O18: =IF($A18="","",$F18*$D18) | P18: =IF($A18="","",MAX(0,$O18-$E18)) | Q18: =IF($A18="","",IF(OR($J18="TAMAM"),0,$P18)) | R18: =IF(OR($A18="",$J18="TAMAM"),"",IFERROR($H18/MAX(1,SUMIF(tblKartlar[KartId],$B18,tblKartlar[KapasiteSaat])),0)) | S18: =IF($A18="","",IF($B18="","YETİM",IF(COUNTIF(tblKartlar[KartId],$B18)=0,"YETİM",""))) | T18: =IF(OR($A18="",$I18=""),"",IF(OR($I18&"|"&$J18="",COUNTIF(ListeIzinliGecis,$I18&"|"&$J18)>0),"","GEÇERSİZ GEÇİŞ")) | U18: =IF($A18="","",IF(OR($O18="",$K18=""),"",IF(ABS($K18-$O18)>zincirTolerans,"ZİNCİR KIRIK","OK"))) | V18: =IF($A18="","",1) | W18: =IF($A18="","",IF($J18="TAMAM",0,IF($L18="","",raporTarihi-$L18)))
A19: IE-00014 | B19: MAM-00006 | C19: YAG-006 | D19: 3 | E19: 118 | F19: 40 | G19: 7 | H19: 3 | I19: TEDARIK | J19: URETIM | K19: 120 | L19: 46217 | M19: B | N19: İş emri notu 14 | O19: =IF($A19="","",$F19*$D19) | P19: =IF($A19="","",MAX(0,$O19-$E19)) | Q19: =IF($A19="","",IF(OR($J19="TAMAM"),0,$P19)) | R19: =IF(OR($A19="",$J19="TAMAM"),"",IFERROR($H19/MAX(1,SUMIF(tblKartlar[KartId],$B19,tblKartlar[KapasiteSaat])),0)) | S19: =IF($A19="","",IF($B19="","YETİM",IF(COUNTIF(tblKartlar[KartId],$B19)=0,"YETİM",""))) | T19: =IF(OR($A19="",$I19=""),"",IF(OR($I19&"|"&$J19="",COUNTIF(ListeIzinliGecis,$I19&"|"&$J19)>0),"","GEÇERSİZ GEÇİŞ")) | U19: =IF($A19="","",IF(OR($O19="",$K19=""),"",IF(ABS($K19-$O19)>zincirTolerans,"ZİNCİR KIRIK","OK"))) | V19: =IF($A19="","",1) | W19: =IF($A19="","",IF($J19="TAMAM",0,IF($L19="","",raporTarihi-$L19)))
A20: IE-00015 | B20: MAM-00007 | C20: FLN-007 | D20: 4 | E20: 175 | F20: 45 | G20: 8 | H20: 3.5 | I20: PLAN | J20: PLAN | K20: 180 | L20: 46215 | M20: A | N20: İş emri notu 15 | O20: =IF($A20="","",$F20*$D20) | P20: =IF($A20="","",MAX(0,$O20-$E20)) | Q20: =IF($A20="","",IF(OR($J20="TAMAM"),0,$P20)) | R20: =IF(OR($A20="",$J20="TAMAM"),"",IFERROR($H20/MAX(1,SUMIF(tblKartlar[KartId],$B20,tblKartlar[KapasiteSaat])),0)) | S20: =IF($A20="","",IF($B20="","YETİM",IF(COUNTIF(tblKartlar[KartId],$B20)=0,"YETİM",""))) | T20: =IF(OR($A20="",$I20=""),"",IF(OR($I20&"|"&$J20="",COUNTIF(ListeIzinliGecis,$I20&"|"&$J20)>0),"","GEÇERSİZ GEÇİŞ")) | U20: =IF($A20="","",IF(OR($O20="",$K20=""),"",IF(ABS($K20-$O20)>zincirTolerans,"ZİNCİR KIRIK","OK"))) | V20: =IF($A20="","",1) | W20: =IF($A20="","",IF($J20="TAMAM",0,IF($L20="","",raporTarihi-$L20)))
A21: IE-00016 | B21: MAM-00008 | C21: KAB-008 | D21: 1 | E21: 2 | F21: 10 | G21: 9 | H21: 4 | I21: TEDARIK | J21: TEDARIK | K21: 10 | L21: 46213 | M21: B | N21: İş emri notu 16 | O21: =IF($A21="","",$F21*$D21) | P21: =IF($A21="","",MAX(0,$O21-$E21)) | Q21: =IF($A21="","",IF(OR($J21="TAMAM"),0,$P21)) | R21: =IF(OR($A21="",$J21="TAMAM"),"",IFERROR($H21/MAX(1,SUMIF(tblKartlar[KartId],$B21,tblKartlar[KapasiteSaat])),0)) | S21: =IF($A21="","",IF($B21="","YETİM",IF(COUNTIF(tblKartlar[KartId],$B21)=0,"YETİM",""))) | T21: =IF(OR($A21="",$I21=""),"",IF(OR($I21&"|"&$J21="",COUNTIF(ListeIzinliGecis,$I21&"|"&$J21)>0),"","GEÇERSİZ GEÇİŞ")) | U21: =IF($A21="","",IF(OR($O21="",$K21=""),"",IF(ABS($K21-$O21)>zincirTolerans,"ZİNCİR KIRIK","OK"))) | V21: =IF($A21="","",1) | W21: =IF($A21="","",IF($J21="TAMAM",0,IF($L21="","",raporTarihi-$L21)))
A22: IE-00017 | B22: MAM-00001 | C22: CEL-001 | D22: 2 | E22: 19 | F22: 15 | G22: 10 | H22: 4.5 | J22: PLAN | K22: 30 | L22: 46211 | M22: A | N22: İş emri notu 17 | O22: =IF($A22="","",$F22*$D22) | P22: =IF($A22="","",MAX(0,$O22-$E22)) | Q22: =IF($A22="","",IF(OR($J22="TAMAM"),0,$P22)) | R22: =IF(OR($A22="",$J22="TAMAM"),"",IFERROR($H22/MAX(1,SUMIF(tblKartlar[KartId],$B22,tblKartlar[KapasiteSaat])),0)) | S22: =IF($A22="","",IF($B22="","YETİM",IF(COUNTIF(tblKartlar[KartId],$B22)=0,"YETİM",""))) | T22: =IF(OR($A22="",$I22=""),"",IF(OR($I22&"|"&$J22="",COUNTIF(ListeIzinliGecis,$I22&"|"&$J22)>0),"","GEÇERSİZ GEÇİŞ")) | U22: =IF($A22="","",IF(OR($O22="",$K22=""),"",IF(ABS($K22-$O22)>zincirTolerans,"ZİNCİR KIRIK","OK"))) | V22: =IF($A22="","",1) | W22: =IF($A22="","",IF($J22="TAMAM",0,IF($L22="","",raporTarihi-$L22)))
A23: IE-00018 | B23: MAM-00002 | C23: PLK-002 | D23: 3 | E23: 46 | F23: 20 | G23: 11 | H23: 2 | I23: PLAN | J23: URETIM | K23: 60 | L23: 46209 | M23: B | N23: İş emri notu 18 | O23: =IF($A23="","",$F23*$D23) | P23: =IF($A23="","",MAX(0,$O23-$E23)) | Q23: =IF($A23="","",IF(OR($J23="TAMAM"),0,$P23)) | R23: =IF(OR($A23="",$J23="TAMAM"),"",IFERROR($H23/MAX(1,SUMIF(tblKartlar[KartId],$B23,tblKartlar[KapasiteSaat])),0)) | S23: =IF($A23="","",IF($B23="","YETİM",IF(COUNTIF(tblKartlar[KartId],$B23)=0,"YETİM",""))) | T23: =IF(OR($A23="",$I23=""),"",IF(OR($I23&"|"&$J23="",COUNTIF(ListeIzinliGecis,$I23&"|"&$J23)>0),"","GEÇERSİZ GEÇİŞ")) | U23: =IF($A23="","",IF(OR($O23="",$K23=""),"",IF(ABS($K23-$O23)>zincirTolerans,"ZİNCİR KIRIK","OK"))) | V23: =IF($A23="","",1) | W23: =IF($A23="","",IF($J23="TAMAM",0,IF($L23="","",raporTarihi-$L23)))
A24: IE-00019 | B24: MAM-00003 | C24: RUL-003 | D24: 4 | E24: 83 | F24: 25 | G24: 12 | H24: 2.5 | I24: TEDARIK | J24: URETIM | K24: 115 | L24: 46207 | M24: A | N24: İş emri notu 19 | O24: =IF($A24="","",$F24*$D24) | P24: =IF($A24="","",MAX(0,$O24-$E24)) | Q24: =IF($A24="","",IF(OR($J24="TAMAM"),0,$P24)) | R24: =IF(OR($A24="",$J24="TAMAM"),"",IFERROR($H24/MAX(1,SUMIF(tblKartlar[KartId],$B24,tblKartlar[KapasiteSaat])),0)) | S24: =IF($A24="","",IF($B24="","YETİM",IF(COUNTIF(tblKartlar[KartId],$B24)=0,"YETİM",""))) | T24: =IF(OR($A24="",$I24=""),"",IF(OR($I24&"|"&$J24="",COUNTIF(ListeIzinliGecis,$I24&"|"&$J24)>0),"","GEÇERSİZ GEÇİŞ")) | U24: =IF($A24="","",IF(OR($O24="",$K24=""),"",IF(ABS($K24-$O24)>zincirTolerans,"ZİNCİR KIRIK","OK"))) | V24: =IF($A24="","",1) | W24: =IF($A24="","",IF($J24="TAMAM",0,IF($L24="","",raporTarihi-$L24)))
A25: IE-00020 | B25: MAM-00004 | C25: CON-004 | D25: 1 | E25: 30 | F25: 30 | G25: 3 | H25: 3 | I25: URETIM | J25: PLAN | K25: 30 | L25: 46245 | M25: B | N25: İş emri notu 20 | O25: =IF($A25="","",$F25*$D25) | P25: =IF($A25="","",MAX(0,$O25-$E25)) | Q25: =IF($A25="","",IF(OR($J25="TAMAM"),0,$P25)) | R25: =IF(OR($A25="",$J25="TAMAM"),"",IFERROR($H25/MAX(1,SUMIF(tblKartlar[KartId],$B25,tblKartlar[KapasiteSaat])),0)) | S25: =IF($A25="","",IF($B25="","YETİM",IF(COUNTIF(tblKartlar[KartId],$B25)=0,"YETİM",""))) | T25: =IF(OR($A25="",$I25=""),"",IF(OR($I25&"|"&$J25="",COUNTIF(ListeIzinliGecis,$I25&"|"&$J25)>0),"","GEÇERSİZ GEÇİŞ")) | U25: =IF($A25="","",IF(OR($O25="",$K25=""),"",IF(ABS($K25-$O25)>zincirTolerans,"ZİNCİR KIRIK","OK"))) | V25: =IF($A25="","",1) | W25: =IF($A25="","",IF($J25="TAMAM",0,IF($L25="","",raporTarihi-$L25)))
A26: IE-00021 | B26: MAM-00005 | C26: VID-005 | D26: 2 | E26: 67 | F26: 35 | G26: 4 | H26: 3.5 | I26: PLAN | J26: TEDARIK | K26: 70 | L26: 46243 | M26: A | N26: İş emri notu 21 | O26: =IF($A26="","",$F26*$D26) | P26: =IF($A26="","",MAX(0,$O26-$E26)) | Q26: =IF($A26="","",IF(OR($J26="TAMAM"),0,$P26)) | R26: =IF(OR($A26="",$J26="TAMAM"),"",IFERROR($H26/MAX(1,SUMIF(tblKartlar[KartId],$B26,tblKartlar[KapasiteSaat])),0)) | S26: =IF($A26="","",IF($B26="","YETİM",IF(COUNTIF(tblKartlar[KartId],$B26)=0,"YETİM",""))) | T26: =IF(OR($A26="",$I26=""),"",IF(OR($I26&"|"&$J26="",COUNTIF(ListeIzinliGecis,$I26&"|"&$J26)>0),"","GEÇERSİZ GEÇİŞ")) | U26: =IF($A26="","",IF(OR($O26="",$K26=""),"",IF(ABS($K26-$O26)>zincirTolerans,"ZİNCİR KIRIK","OK"))) | V26: =IF($A26="","",1) | W26: =IF($A26="","",IF($J26="TAMAM",0,IF($L26="","",raporTarihi-$L26)))
A27: IE-00022 | C27: YAG-006 | D27: 3 | E27: 114 | F27: 40 | G27: 5 | H27: 4 | I27: TEDARIK | J27: URETIM | K27: 120 | L27: 46241 | M27: B | N27: İş emri notu 22 | O27: =IF($A27="","",$F27*$D27) | P27: =IF($A27="","",MAX(0,$O27-$E27)) | Q27: =IF($A27="","",IF(OR($J27="TAMAM"),0,$P27)) | R27: =IF(OR($A27="",$J27="TAMAM"),"",IFERROR($H27/MAX(1,SUMIF(tblKartlar[KartId],$B27,tblKartlar[KapasiteSaat])),0)) | S27: =IF($A27="","",IF($B27="","YETİM",IF(COUNTIF(tblKartlar[KartId],$B27)=0,"YETİM",""))) | T27: =IF(OR($A27="",$I27=""),"",IF(OR($I27&"|"&$J27="",COUNTIF(ListeIzinliGecis,$I27&"|"&$J27)>0),"","GEÇERSİZ GEÇİŞ")) | U27: =IF($A27="","",IF(OR($O27="",$K27=""),"",IF(ABS($K27-$O27)>zincirTolerans,"ZİNCİR KIRIK","OK"))) | V27: =IF($A27="","",1) | W27: =IF($A27="","",IF($J27="TAMAM",0,IF($L27="","",raporTarihi-$L27)))
A28: IE-00023 | B28: MAM-00007 | C28: FLN-007 | D28: 4 | E28: 171 | F28: 45 | G28: 6 | H28: 4.5 | I28: PLAN | J28: PLAN | K28: 180 | L28: 46239 | M28: A | N28: İş emri notu 23 | O28: =IF($A28="","",$F28*$D28) | P28: =IF($A28="","",MAX(0,$O28-$E28)) | Q28: =IF($A28="","",IF(OR($J28="TAMAM"),0,$P28)) | R28: =IF(OR($A28="",$J28="TAMAM"),"",IFERROR($H28/MAX(1,SUMIF(tblKartlar[KartId],$B28,tblKartlar[KapasiteSaat])),0)) | S28: =IF($A28="","",IF($B28="","YETİM",IF(COUNTIF(tblKartlar[KartId],$B28)=0,"YETİM",""))) | T28: =IF(OR($A28="",$I28=""),"",IF(OR($I28&"|"&$J28="",COUNTIF(ListeIzinliGecis,$I28&"|"&$J28)>0),"","GEÇERSİZ GEÇİŞ")) | U28: =IF($A28="","",IF(OR($O28="",$K28=""),"",IF(ABS($K28-$O28)>zincirTolerans,"ZİNCİR KIRIK","OK"))) | V28: =IF($A28="","",1) | W28: =IF($A28="","",IF($J28="TAMAM",0,IF($L28="","",raporTarihi-$L28)))
A29: IE-00024 | B29: MAM-00008 | C29: KAB-008 | D29: 1 | E29: 0 | F29: 10 | G29: 7 | H29: 2 | I29: TEDARIK | J29: TEDARIK | K29: 10 | L29: 46237 | M29: B | N29: İş emri notu 24 | O29: =IF($A29="","",$F29*$D29) | P29: =IF($A29="","",MAX(0,$O29-$E29)) | Q29: =IF($A29="","",IF(OR($J29="TAMAM"),0,$P29)) | R29: =IF(OR($A29="",$J29="TAMAM"),"",IFERROR($H29/MAX(1,SUMIF(tblKartlar[KartId],$B29,tblKartlar[KapasiteSaat])),0)) | S29: =IF($A29="","",IF($B29="","YETİM",IF(COUNTIF(tblKartlar[KartId],$B29)=0,"YETİM",""))) | T29: =IF(OR($A29="",$I29=""),"",IF(OR($I29&"|"&$J29="",COUNTIF(ListeIzinliGecis,$I29&"|"&$J29)>0),"","GEÇERSİZ GEÇİŞ")) | U29: =IF($A29="","",IF(OR($O29="",$K29=""),"",IF(ABS($K29-$O29)>zincirTolerans,"ZİNCİR KIRIK","OK"))) | V29: =IF($A29="","",1) | W29: =IF($A29="","",IF($J29="TAMAM",0,IF($L29="","",raporTarihi-$L29)))
A30: IE-00025 | B30: MAM-99999 | C30: CEL-001 | D30: 2 | E30: 15 | F30: 15 | G30: 8 | H30: 2.5 | J30: PLAN | K30: 30 | L30: 46235 | M30: A | N30: İş emri notu 25 | O30: =IF($A30="","",$F30*$D30) | P30: =IF($A30="","",MAX(0,$O30-$E30)) | Q30: =IF($A30="","",IF(OR($J30="TAMAM"),0,$P30)) | R30: =IF(OR($A30="",$J30="TAMAM"),"",IFERROR($H30/MAX(1,SUMIF(tblKartlar[KartId],$B30,tblKartlar[KapasiteSaat])),0)) | S30: =IF($A30="","",IF($B30="","YETİM",IF(COUNTIF(tblKartlar[KartId],$B30)=0,"YETİM",""))) | T30: =IF(OR($A30="",$I30=""),"",IF(OR($I30&"|"&$J30="",COUNTIF(ListeIzinliGecis,$I30&"|"&$J30)>0),"","GEÇERSİZ GEÇİŞ")) | U30: =IF($A30="","",IF(OR($O30="",$K30=""),"",IF(ABS($K30-$O30)>zincirTolerans,"ZİNCİR KIRIK","OK"))) | V30: =IF($A30="","",1) | W30: =IF($A30="","",IF($J30="TAMAM",0,IF($L30="","",raporTarihi-$L30)))
A31: IE-00026 | B31: MAM-00002 | C31: PLK-002 | D31: 3 | E31: 42 | F31: 20 | G31: 9 | H31: 3 | I31: PLAN | J31: TEDARIK | K31: 60 | L31: 46233 | M31: B | N31: İş emri notu 26 | O31: =IF($A31="","",$F31*$D31) | P31: =IF($A31="","",MAX(0,$O31-$E31)) | Q31: =IF($A31="","",IF(OR($J31="TAMAM"),0,$P31)) | R31: =IF(OR($A31="",$J31="TAMAM"),"",IFERROR($H31/MAX(1,SUMIF(tblKartlar[KartId],$B31,tblKartlar[KapasiteSaat])),0)) | S31: =IF($A31="","",IF($B31="","YETİM",IF(COUNTIF(tblKartlar[KartId],$B31)=0,"YETİM",""))) | T31: =IF(OR($A31="",$I31=""),"",IF(OR($I31&"|"&$J31="",COUNTIF(ListeIzinliGecis,$I31&"|"&$J31)>0),"","GEÇERSİZ GEÇİŞ")) | U31: =IF($A31="","",IF(OR($O31="",$K31=""),"",IF(ABS($K31-$O31)>zincirTolerans,"ZİNCİR KIRIK","OK"))) | V31: =IF($A31="","",1) | W31: =IF($A31="","",IF($J31="TAMAM",0,IF($L31="","",raporTarihi-$L31)))
A32: IE-00027 | B32: MAM-00003 | C32: RUL-003 | D32: 4 | E32: 99 | F32: 25 | G32: 10 | H32: 3.5 | I32: TEDARIK | J32: URETIM | K32: 100 | L32: 46231 | M32: A | N32: İş emri notu 27 | O32: =IF($A32="","",$F32*$D32) | P32: =IF($A32="","",MAX(0,$O32-$E32)) | Q32: =IF($A32="","",IF(OR($J32="TAMAM"),0,$P32)) | R32: =IF(OR($A32="",$J32="TAMAM"),"",IFERROR($H32/MAX(1,SUMIF(tblKartlar[KartId],$B32,tblKartlar[KapasiteSaat])),0)) | S32: =IF($A32="","",IF($B32="","YETİM",IF(COUNTIF(tblKartlar[KartId],$B32)=0,"YETİM",""))) | T32: =IF(OR($A32="",$I32=""),"",IF(OR($I32&"|"&$J32="",COUNTIF(ListeIzinliGecis,$I32&"|"&$J32)>0),"","GEÇERSİZ GEÇİŞ")) | U32: =IF($A32="","",IF(OR($O32="",$K32=""),"",IF(ABS($K32-$O32)>zincirTolerans,"ZİNCİR KIRIK","OK"))) | V32: =IF($A32="","",1) | W32: =IF($A32="","",IF($J32="TAMAM",0,IF($L32="","",raporTarihi-$L32)))
A33: IE-00028 | B33: MAM-00004 | C33: CON-004 | D33: 1 | E33: 26 | F33: 30 | G33: 11 | H33: 4 | I33: URETIM | J33: TAMAM | K33: 30 | L33: 46229 | M33: B | N33: İş emri notu 28 | O33: =IF($A33="","",$F33*$D33) | P33: =IF($A33="","",MAX(0,$O33-$E33)) | Q33: =IF($A33="","",IF(OR($J33="TAMAM"),0,$P33)) | R33: =IF(OR($A33="",$J33="TAMAM"),"",IFERROR($H33/MAX(1,SUMIF(tblKartlar[KartId],$B33,tblKartlar[KapasiteSaat])),0)) | S33: =IF($A33="","",IF($B33="","YETİM",IF(COUNTIF(tblKartlar[KartId],$B33)=0,"YETİM",""))) | T33: =IF(OR($A33="",$I33=""),"",IF(OR($I33&"|"&$J33="",COUNTIF(ListeIzinliGecis,$I33&"|"&$J33)>0),"","GEÇERSİZ GEÇİŞ")) | U33: =IF($A33="","",IF(OR($O33="",$K33=""),"",IF(ABS($K33-$O33)>zincirTolerans,"ZİNCİR KIRIK","OK"))) | V33: =IF($A33="","",1) | W33: =IF($A33="","",IF($J33="TAMAM",0,IF($L33="","",raporTarihi-$L33)))
O34: =IF($A34="","",$F34*$D34) | P34: =IF($A34="","",MAX(0,$O34-$E34)) | Q34: =IF($A34="","",IF(OR($J34="TAMAM"),0,$P34)) | R34: =IF(OR($A34="",$J34="TAMAM"),"",IFERROR($H34/MAX(1,SUMIF(tblKartlar[KartId],$B34,tblKartlar[KapasiteSaat])),0)) | S34: =IF($A34="","",IF($B34="","YETİM",IF(COUNTIF(tblKartlar[KartId],$B34)=0,"YETİM",""))) | T34: =IF(OR($A34="",$I34=""),"",IF(OR($I34&"|"&$J34="",COUNTIF(ListeIzinliGecis,$I34&"|"&$J34)>0),"","GEÇERSİZ GEÇİŞ")) | U34: =IF($A34="","",IF(OR($O34="",$K34=""),"",IF(ABS($K34-$O34)>zincirTolerans,"ZİNCİR KIRIK","OK"))) | V34: =IF($A34="","",1) | W34: =IF($A34="","",IF($J34="TAMAM",0,IF($L34="","",raporTarihi-$L34)))
O35: =IF($A35="","",$F35*$D35) | P35: =IF($A35="","",MAX(0,$O35-$E35)) | Q35: =IF($A35="","",IF(OR($J35="TAMAM"),0,$P35)) | R35: =IF(OR($A35="",$J35="TAMAM"),"",IFERROR($H35/MAX(1,SUMIF(tblKartlar[KartId],$B35,tblKartlar[KapasiteSaat])),0)) | S35: =IF($A35="","",IF($B35="","YETİM",IF(COUNTIF(tblKartlar[KartId],$B35)=0,"YETİM",""))) | T35: =IF(OR($A35="",$I35=""),"",IF(OR($I35&"|"&$J35="",COUNTIF(ListeIzinliGecis,$I35&"|"&$J35)>0),"","GEÇERSİZ GEÇİŞ")) | U35: =IF($A35="","",IF(OR($O35="",$K35=""),"",IF(ABS($K35-$O35)>zincirTolerans,"ZİNCİR KIRIK","OK"))) | V35: =IF($A35="","",1) | W35: =IF($A35="","",IF($J35="TAMAM",0,IF($L35="","",raporTarihi-$L35)))
O36: =IF($A36="","",$F36*$D36) | P36: =IF($A36="","",MAX(0,$O36-$E36)) | Q36: =IF($A36="","",IF(OR($J36="TAMAM"),0,$P36)) | R36: =IF(OR($A36="",$J36="TAMAM"),"",IFERROR($H36/MAX(1,SUMIF(tblKartlar[KartId],$B36,tblKartlar[KapasiteSaat])),0)) | S36: =IF($A36="","",IF($B36="","YETİM",IF(COUNTIF(tblKartlar[KartId],$B36)=0,"YETİM",""))) | T36: =IF(OR($A36="",$I36=""),"",IF(OR($I36&"|"&$J36="",COUNTIF(ListeIzinliGecis,$I36&"|"&$J36)>0),"","GEÇERSİZ GEÇİŞ")) | U36: =IF($A36="","",IF(OR($O36="",$K36=""),"",IF(ABS($K36-$O36)>zincirTolerans,"ZİNCİR KIRIK","OK"))) | V36: =IF($A36="","",1) | W36: =IF($A36="","",IF($J36="TAMAM",0,IF($L36="","",raporTarihi-$L36)))
O37: =IF($A37="","",$F37*$D37) | P37: =IF($A37="","",MAX(0,$O37-$E37)) | Q37: =IF($A37="","",IF(OR($J37="TAMAM"),0,$P37)) | R37: =IF(OR($A37="",$J37="TAMAM"),"",IFERROR($H37/MAX(1,SUMIF(tblKartlar[KartId],$B37,tblKartlar[KapasiteSaat])),0)) | S37: =IF($A37="","",IF($B37="","YETİM",IF(COUNTIF(tblKartlar[KartId],$B37)=0,"YETİM",""))) | T37: =IF(OR($A37="",$I37=""),"",IF(OR($I37&"|"&$J37="",COUNTIF(ListeIzinliGecis,$I37&"|"&$J37)>0),"","GEÇERSİZ GEÇİŞ")) | U37: =IF($A37="","",IF(OR($O37="",$K37=""),"",IF(ABS($K37-$O37)>zincirTolerans,"ZİNCİR KIRIK","OK"))) | V37: =IF($A37="","",1) | W37: =IF($A37="","",IF($J37="TAMAM",0,IF($L37="","",raporTarihi-$L37)))
O38: =IF($A38="","",$F38*$D38) | P38: =IF($A38="","",MAX(0,$O38-$E38)) | Q38: =IF($A38="","",IF(OR($J38="TAMAM"),0,$P38)) | R38: =IF(OR($A38="",$J38="TAMAM"),"",IFERROR($H38/MAX(1,SUMIF(tblKartlar[KartId],$B38,tblKartlar[KapasiteSaat])),0)) | S38: =IF($A38="","",IF($B38="","YETİM",IF(COUNTIF(tblKartlar[KartId],$B38)=0,"YETİM",""))) | T38: =IF(OR($A38="",$I38=""),"",IF(OR($I38&"|"&$J38="",COUNTIF(ListeIzinliGecis,$I38&"|"&$J38)>0),"","GEÇERSİZ GEÇİŞ")) | U38: =IF($A38="","",IF(OR($O38="",$K38=""),"",IF(ABS($K38-$O38)>zincirTolerans,"ZİNCİR KIRIK","OK"))) | V38: =IF($A38="","",1) | W38: =IF($A38="","",IF($J38="TAMAM",0,IF($L38="","",raporTarihi-$L38)))
O39: =IF($A39="","",$F39*$D39) | P39: =IF($A39="","",MAX(0,$O39-$E39)) | Q39: =IF($A39="","",IF(OR($J39="TAMAM"),0,$P39)) | R39: =IF(OR($A39="",$J39="TAMAM"),"",IFERROR($H39/MAX(1,SUMIF(tblKartlar[KartId],$B39,tblKartlar[KapasiteSaat])),0)) | S39: =IF($A39="","",IF($B39="","YETİM",IF(COUNTIF(tblKartlar[KartId],$B39)=0,"YETİM",""))) | T39: =IF(OR($A39="",$I39=""),"",IF(OR($I39&"|"&$J39="",COUNTIF(ListeIzinliGecis,$I39&"|"&$J39)>0),"","GEÇERSİZ GEÇİŞ")) | U39: =IF($A39="","",IF(OR($O39="",$K39=""),"",IF(ABS($K39-$O39)>zincirTolerans,"ZİNCİR KIRIK","OK"))) | V39: =IF($A39="","",1) | W39: =IF($A39="","",IF($J39="TAMAM",0,IF($L39="","",raporTarihi-$L39)))
O40: =IF($A40="","",$F40*$D40) | P40: =IF($A40="","",MAX(0,$O40-$E40)) | Q40: =IF($A40="","",IF(OR($J40="TAMAM"),0,$P40)) | R40: =IF(OR($A40="",$J40="TAMAM"),"",IFERROR($H40/MAX(1,SUMIF(tblKartlar[KartId],$B40,tblKartlar[KapasiteSaat])),0)) | S40: =IF($A40="","",IF($B40="","YETİM",IF(COUNTIF(tblKartlar[KartId],$B40)=0,"YETİM",""))) | T40: =IF(OR($A40="",$I40=""),"",IF(OR($I40&"|"&$J40="",COUNTIF(ListeIzinliGecis,$I40&"|"&$J40)>0),"","GEÇERSİZ GEÇİŞ")) | U40: =IF($A40="","",IF(OR($O40="",$K40=""),"",IF(ABS($K40-$O40)>zincirTolerans,"ZİNCİR KIRIK","OK"))) | V40: =IF($A40="","",1) | W40: =IF($A40="","",IF($J40="TAMAM",0,IF($L40="","",raporTarihi-$L40)))
O41: =IF($A41="","",$F41*$D41) | P41: =IF($A41="","",MAX(0,$O41-$E41)) | Q41: =IF($A41="","",IF(OR($J41="TAMAM"),0,$P41)) | R41: =IF(OR($A41="",$J41="TAMAM"),"",IFERROR($H41/MAX(1,SUMIF(tblKartlar[KartId],$B41,tblKartlar[KapasiteSaat])),0)) | S41: =IF($A41="","",IF($B41="","YETİM",IF(COUNTIF(tblKartlar[KartId],$B41)=0,"YETİM",""))) | T41: =IF(OR($A41="",$I41=""),"",IF(OR($I41&"|"&$J41="",COUNTIF(ListeIzinliGecis,$I41&"|"&$J41)>0),"","GEÇERSİZ GEÇİŞ")) | U41: =IF($A41="","",IF(OR($O41="",$K41=""),"",IF(ABS($K41-$O41)>zincirTolerans,"ZİNCİR KIRIK","OK"))) | V41: =IF($A41="","",1) | W41: =IF($A41="","",IF($J41="TAMAM",0,IF($L41="","",raporTarihi-$L41)))
O42: =IF($A42="","",$F42*$D42) | P42: =IF($A42="","",MAX(0,$O42-$E42)) | Q42: =IF($A42="","",IF(OR($J42="TAMAM"),0,$P42)) | R42: =IF(OR($A42="",$J42="TAMAM"),"",IFERROR($H42/MAX(1,SUMIF(tblKartlar[KartId],$B42,tblKartlar[KapasiteSaat])),0)) | S42: =IF($A42="","",IF($B42="","YETİM",IF(COUNTIF(tblKartlar[KartId],$B42)=0,"YETİM",""))) | T42: =IF(OR($A42="",$I42=""),"",IF(OR($I42&"|"&$J42="",COUNTIF(ListeIzinliGecis,$I42&"|"&$J42)>0),"","GEÇERSİZ GEÇİŞ")) | U42: =IF($A42="","",IF(OR($O42="",$K42=""),"",IF(ABS($K42-$O42)>zincirTolerans,"ZİNCİR KIRIK","OK"))) | V42: =IF($A42="","",1) | W42: =IF($A42="","",IF($J42="TAMAM",0,IF($L42="","",raporTarihi-$L42)))
...

Sheet KUYRUKLAR
A1: KUYRUKLAR — Mini-MRP (BOM + Malzeme İhtiyacı + Kapasite)
A3: Durum bazlı canlı kuyruk — kapalı kayıtlar düşer
A5: Kuyruk | B5: Adet | C5: Net İhtiyaç
A6: Kuyruk Plan | B6: =COUNTIFS(tblAkis[Durum],"PLAN",tblAkis[KayitDolu],1) | C6: =SUMIF(tblAkis[Durum],"PLAN",tblAkis[NetIhtiyac])
A7: Kuyruk Tedarik | B7: =COUNTIFS(tblAkis[Durum],"TEDARIK",tblAkis[KayitDolu],1) | C7: =SUMIF(tblAkis[Durum],"TEDARIK",tblAkis[NetIhtiyac])
A8: Kuyruk Üretim | B8: =COUNTIFS(tblAkis[Durum],"URETIM",tblAkis[KayitDolu],1) | C8: =SUMIF(tblAkis[Durum],"URETIM",tblAkis[NetIhtiyac])
A9: Satın Al (net>0 ve tedarik≥eşik) | B9: =COUNTIFS(tblAkis[NetIhtiyac],">0",tblAkis[TedarikSuresiGun],">="&mmr_esikTedarikGun,tblAkis[Durum],"<>TAMAM") | C9: =SUMIFS(tblAkis[NetIhtiyac],tblAkis[NetIhtiyac],">0",tblAkis[TedarikSuresiGun],">="&mmr_esikTedarikGun,tblAkis[Durum],"<>TAMAM")
A11: Kapalı (Tamam) — kuyruktan düşer
A12: Tamam | B12: =COUNTIF(tblAkis[Durum],"TAMAM") | C12: =SUMIF(tblAkis[Durum],"TAMAM",tblAkis[NetIhtiyac])
A15: Kuyruk Özeti | B15: =mmr_kuyrukOzeti
A17: Kapasite Yük Bandı
A18: ≤%70 | B18: =COUNTIFS(tblAkis[KapasiteYukuPct],"<="&0.7,tblAkis[KayitDolu],1)
A19: %70-100 | B19: =COUNTIFS(tblAkis[KapasiteYukuPct],">0.7",tblAkis[KapasiteYukuPct],"<=1",tblAkis[KayitDolu],1)
A20: >%100 | B20: =COUNTIFS(tblAkis[KapasiteYukuPct],">1",tblAkis[KayitDolu],1)
A21: Boş/Tamam | B21: =COUNTBLANK(tblAkis[KapasiteYukuPct])

Sheet HESAP
A1: HESAP — Mini-MRP (BOM + Malzeme İhtiyacı + Kapasite)
A3: Hesap motoru — ≥40 adım; sabitler AYARLAR'dan
A5: Adım | B5: Açıklama | C5: Değer
A6: H01 | B6: Toplam işlem | C6: =COUNTA(tblAkis[IslemId])
A7: H02 | B7: Dolu kayıt | C7: =SUM(tblAkis[KayitDolu])
A8: H03 | B8: Brüt ihtiyaç toplam | C8: =SUM(tblAkis[BrutIhtiyac])
A9: H04 | B9: Stok toplam | C9: =SUM(tblAkis[StokMiktar])
A10: H05 | B10: Sipariş toplam | C10: =SUM(tblAkis[SiparisMiktari])
A11: H06 | B11: Plan adet | C11: =COUNTIF(tblAkis[Durum],"PLAN")
A12: H07 | B12: Tedarik adet | C12: =COUNTIF(tblAkis[Durum],"TEDARIK")
A13: H08 | B13: Üretim adet | C13: =COUNTIF(tblAkis[Durum],"URETIM")
A14: H09 | B14: Tamam adet | C14: =COUNTIF(tblAkis[Durum],"TAMAM")
A15: H10 | B15: Açık kuyruk adet | C15: =C11+C12+C13
A16: H11 | B16: Kapalı düşüm adet | C16: =C14
A17: H12 | B17: Net ihtiyaç toplam | C17: =SUM(tblAkis[NetIhtiyac])
A18: H13 | B18: Önerilen sipariş | C18: =SUM(tblAkis[OnerilenSiparis])
A19: H14 | B19: Yetim adet | C19: =COUNTIF(tblAkis[YetimBayrak],"YETİM")
A20: H15 | B20: Geçersiz geçiş | C20: =COUNTIF(tblAkis[GecisUyarisi],"GEÇERSİZ GEÇİŞ")
A21: H16 | B21: Zincir kırık | C21: =COUNTIF(tblAkis[ZincirBayrak],"ZİNCİR KIRIK")
A22: H17 | B22: Zincir OK | C22: =COUNTIF(tblAkis[ZincirBayrak],"OK")
A23: H18 | B23: Kapasite aşım adet | C23: =COUNTIFS(tblAkis[KapasiteYukuPct],">"&mmr_esikKapasite,tblAkis[KayitDolu],1)
A24: H19 | B24: Ort kapasite yükü | C24: =IFERROR(AVERAGEIF(tblAkis[KayitDolu],1,tblAkis[KapasiteYukuPct]),0)
A25: H20 | B25: Satın al adet | C25: =COUNTIFS(tblAkis[NetIhtiyac],">0",tblAkis[TedarikSuresiGun],">="&mmr_esikTedarikGun,tblAkis[Durum],"<>TAMAM")
A26: H21 | B26: Ort tedarik gün | C26: =IFERROR(AVERAGEIF(tblAkis[KayitDolu],1,tblAkis[TedarikSuresiGun]),0)
A27: H22 | B27: Ort iş emri saat | C27: =IFERROR(AVERAGEIF(tblAkis[KayitDolu],1,tblAkis[IsEmriSuresiSaat]),0)
A28: H23 | B28: İhtiyaç sapma | C28: =C8-C9
A29: H24 | B29: Brüt-beklenen fark | C29: =SUM(tblAkis[BrutIhtiyac])-SUM(tblAkis[BrutBeklenen])
A30: H25 | B30: Temkinli senaryo | C30: =C17*mmr_senaryoTemkinli
A31: H26 | B31: Baz senaryo | C31: =C17*mmr_senaryoBaz
A32: H27 | B32: İyimser senaryo | C32: =C17*mmr_senaryoIyimser
A33: H28 | B33: Senaryo farkı | C33: =C32-C30
A34: H29 | B34: Tornado (oran×net) | C34: =C17*mmr_tornadoOran
A35: H30 | B35: HHI proxy | C35: =IFERROR((MAX(C11,C12,C13)/MAX(C15,1))^2,0)
A36: H31 | B36: Kalite skoru | C36: =IF(C6=0,0,MAX(0,100-C19*10-C20*10-C21*10-C23*5))
A37: H32 | B37: Tahmin PERCENTILE | C37: =IFERROR(_xlfn.PERCENTILE.INC(tblAkis[NetIhtiyac],mmr_yuzdelikOran),0)
A38: H33 | B38: Tahmin FORECAST | C38: =IFERROR(FORECAST(COUNTA(tblAkis[IslemId])+1,tblAkis[NetIhtiyac],tblAkis[KayitDolu]),C37)
A39: H34 | B39: Tahmin aralık | C39: =IFERROR((C37+C38)/2,0)
A40: H35 | B40: P90 yüzdelik | C40: =IFERROR(_xlfn.PERCENTILE.INC(tblAkis[BrutIhtiyac],mmr_yuzdelikOran),0)
A41: H36 | B41: Kart sayısı | C41: =COUNTA(tblKartlar[KartId])
A42: H37 | B42: Kapasite saat toplam | C42: =SUM(tblKartlar[KapasiteSaat])
...

Sheet RAPOR
A1: RAPOR — Mini-MRP (BOM + Malzeme İhtiyacı + Kapasite)
A3: Dönemsel Malzeme / Kapasite Kanıt Raporu
A4: Rapor Tarihi | B4: =raporTarihi
A5: Sürüm | B5: 1.0.0 | D5: Lisans | E5: Tek kullanıcı
A7: KARAR | B7: =PANO!B4
A9: Net İhtiyaç | B9: =mmr_netIhtiyac
A10: Önerilen Sipariş | B10: =mmr_onerilenSiparis
A11: Kapasite Yükü | B11: =mmr_kapasiteYuku
A12: Yetim | B12: =mmr_yetimKayit
A13: Geçersiz Geçiş | B13: =mmr_gecersizGecis
A14: Zincir Kırık | B14: =mmr_zincirKirik
A15: Tahmin Aralık | B15: =mmr_tahminAralik
A16: Kanıt Özeti | B16: =mmr_kanitRaporu
A18: Varsayımlar
A19: Durum haritası AYARLAR'dadır. Geçersiz geçiş engellenmez, görünür kılınır. Net ihtiyaç = MAX(0, brüt − stok). Kapasite yükü = iş emri süresi / hat kapasitesi. Kurallar MMR-001..005 (2025-2027). Bu çıktı karar destektir; kesin üretim emri değildir.
A21: Önerilen Aksiyonlar
A22: 1. Yetim kayıtları KARTLAR'a bağlayın veya satırı düzeltin.
A23: 2. Kapasite aşımı olan hatlarda iş emrini kaydırın veya fasona alın.
A24: 3. Zincir kırık satırlarda brüt ihtiyaç ↔ beklenen farkını açıklayın.
A26: Sürüm 1.0.0 | Bu dosya karar destek aracıdır.

Sheet KONTROLLER
A1: KONTROLLER — Mini-MRP (BOM + Malzeme İhtiyacı + Kapasite)
A3: Canlı Kontrol Paneli
A5: İşlem sayısı | B5: =COUNTA(tblAkis[IslemId])
A6: Kart sayısı | B6: =COUNTA(tblKartlar[KartId])
A7: Plan | B7: =COUNTIF(tblAkis[Durum],"PLAN")
A8: Tedarik | B8: =COUNTIF(tblAkis[Durum],"TEDARIK")
A9: Üretim | B9: =COUNTIF(tblAkis[Durum],"URETIM")
A10: Tamam | B10: =COUNTIF(tblAkis[Durum],"TAMAM")
A11: Açık toplam | B11: =B7+B8+B9
A12: Yetim | B12: =mmr_yetimKayit
A13: Geçersiz | B13: =mmr_gecersizGecis
A14: Zincir kırık | B14: =mmr_zincirKirik
A15: Kapasite aşım | B15: =mmr_kapasiteAsim
A16: Boş karar yolu | B16: =IF(B5=0,"VERİ YOK","VERİ VAR")
A17: Kalite skoru | B17: =mmr_kaliteSkor
A18: Net ihtiyaç | B18: =mmr_netIhtiyac
A19: Önerilen sipariş | B19: =mmr_onerilenSiparis
A20: Kapalı düşüm | B20: =mmr_kapaliDusum

Sheet ORNEK_VERI
A1: ORNEK VERI — Mini-MRP (BOM + Malzeme İhtiyacı + Kapasite)
A3: Örnek Senaryo Açıklaması
A4: Dosyada 8 mamul kartı ve 28 BOM/iş emri satırı vardır. Yetim (22, 25), geçersiz geçiş (18, 20) ve zincir kırık (12, 19) kasıtlıdır. KARTLAR ve AKIS'i temizleyip kendi verinizi girebilirsiniz.
A6: Örnek özet (bilgi)
A7: Durumlar: Plan/Tedarik/Üretim/Tamam — kapalılar kuyruktan düşer
A8: Kurallar: MMR-001..005 | Hesap yılları: 2025-2027
A9: Ölçek sözleşmesi | B9: 20000

Sheet LISTELER
A1: LISTELER — Mini-MRP (BOM + Malzeme İhtiyacı + Kapasite)
A3: Durum Listesi | C3: İzinli Geçişler | E3: Evet / Hayır | G3: Yorum A/B | I3: Bileşen
A6: DurumId | C6: Gecis | E6: Secim | G6: Yorum | I6: Bilesen
A7: PLAN | C7: PLAN|TEDARIK | E7: EVET | G7: A | I7: CEL-001
A8: TEDARIK | C8: TEDARIK|URETIM | E8: HAYIR | G8: B | I8: PLK-002
A9: URETIM | C9: TEDARIK|PLAN | I9: RUL-003
A10: TAMAM | C10: URETIM|TAMAM | I10: CON-004
C11: URETIM|TEDARIK | I11: VID-005
I12: YAG-006
I13: FLN-007
I14: KAB-008

Sheet AYARLAR
A1: AYARLAR — Mini-MRP (BOM + Malzeme İhtiyacı + Kapasite)
A3: Tek kaynak parametreler + durum haritası (A01/A06)
A5: anahtar | B5: deger | C5: birim | D5: kaynak | E5: yururluk_tarihi | F5: aciklama
A6: raporTarihi | B6: 46245 | C6: tarih | D6: Kullanıcı / dönem kapanışı | E6: 01.01.2026 | F6: Rapor tarihi (TODAY yok)
A7: zincirTolerans | B7: 5 | C7: adet | D7: İş kuralı — brüt/beklenen sapma | E7: 01.01.2026 | F7: ZİNCİR KIRIK eşiği
A8: mmr_esikTedarikGun | B8: 7 | C8: gün | D8: İç politika | E8: 01.01.2026 | F8: Satın al tedarik eşiği
A9: mmr_esikSatinAl | B9: 3 | C9: adet | D9: İç politika | E9: 01.01.2026 | F9: Karar eşiği satın al
A10: mmr_esikKapasite | B10: 1 | C10: oran | D10: Kapasite politikası | E10: 01.01.2026 | F10: Aşım eşiği %100
A11: mmr_senaryoTemkinli | B11: 0.85 | C11: oran | D11: Senaryo motoru | E11: 01.01.2026 | F11: Temkinli çarpan
A12: mmr_senaryoBaz | B12: 1 | C12: oran | D12: Senaryo motoru | E12: 01.01.2026 | F12: Baz çarpan
A13: mmr_senaryoIyimser | B13: 1.15 | C13: oran | D13: Senaryo motoru | E13: 01.01.2026 | F13: İyimser çarpan
A14: mmr_tornadoOran | B14: 0.08 | C14: oran | D14: Duyarlılık | E14: 01.01.2026 | F14: Tornado etki oranı
A15: mmr_yuzdelikOran | B15: 0.9 | C15: oran | D15: İstatistik kuralı | E15: 01.01.2026 | F15: PERCENTILE oranı
A16: mmr_olcekHedef | B16: 20000 | C16: satir | D16: Manda A3 Ö1 | E16: 01.01.2026 | F16: Ölçek sözleşmesi
A17: mmr_azamiSiparis | B17: 100000 | C17: adet | D17: İç politika — uç değer | E17: 01.01.2026 | F17: Azami makul
A18: mmr_durumHaritasi | B18: AYARLAR durum tablosu | C18: metin | D18: SPEC akis.durum_haritasi | E18: 01.01.2026 | F18: Durum makinesi kaynağı
A19: mmr_kuyrukOzeti_metin | B19: KUYRUKLAR canlı özet | C19: metin | D19: A05 kuyruk | E19: 01.01.2026 | F19: Kuyruk görünümü
A20: mmr_kapaliDusum_metin | B20: kapali kategori kuyruktan düşer | C20: metin | D20: A06 | E20: 01.01.2026 | F20: Kapalı düşüm kuralı
A21: mmr_kanitRaporu_metin | B21: RAPOR kanıt çıktısı | C21: metin | D21: Dönemsel rapor | E21: 01.01.2026 | F21: Kanıt raporu
A22: mmr_kararMetni | B22: PANO karar hücresi | C22: metin | D22: Karar motoru | E22: 01.01.2026 | F22: ÜRET/SATIN AL/AŞIM/VERİ YOK
A23: mmr_dosyaSurumu | B23: 1.0.0 | C23: metin | D23: Sürüm yönetimi | E23: 01.01.2026 | F23: Ürün sürümü
A24: mmr_firmaUnvan | B24: Örnek Üretim A.Ş. | C24: metin | D24: Kullanıcı girişi | E24: 01.01.2026 | F24: Firma
A25: mmr_kuralMMR001 | B25: Net ihtiyaç ≥ 0 | C25: metin | D25: MMR-001 | E25: 01.01.2025 | F25: Net ihtiyaç negatif olamaz
A26: mmr_kuralMMR002 | B26: Kapasite yükü bayrağı | C26: metin | D26: MMR-002 | E26: 01.01.2025 | F26: Yük > eşik → aşım
A27: mmr_kuralMMR003 | B27: Brüt↔beklenen zincir | C27: metin | D27: MMR-003 | E27: 01.01.2026 | F27: Zincir kırık görünür
A28: mmr_kuralMMR004 | B28: Yetim mamul tespiti | C28: metin | D28: MMR-004 | E28: 01.01.2026 | F28: Kart bağlanmalı
A29: mmr_kuralMMR005 | B29: Karar yolu dört durum | C29: metin | D29: MMR-005 | E29: 01.01.2027 | F29: ÜRET/SATIN AL/AŞIM/VERİ YOK
A30: mmr_hesapYillari | B30: 2025-2027 | C30: metin | D30: SPEC mevzuat | E30: 01.01.2025 | F30: Hesap yılları
H33: Durum Haritası
H34: durum_id | I34: durum_adi | J34: sira | K34: izinli_sonraki_durumlar | L34: kategori
H35: PLAN | I35: Plan | J35: 1 | K35: TEDARIK | L35: acik
H36: TEDARIK | I36: Tedarik | J36: 2 | K36: URETIM|PLAN | L36: acik
H37: URETIM | I37: Üretim | J37: 3 | K37: TAMAM|TEDARIK | L37: acik
H38: TAMAM | I38: Tamam | J38: 4 | L38: kapali
H42: Motor Çıktıları
H43: anahtar | I43: deger
H44: mmr_netIhtiyac | I44: =HESAP!C17
H45: mmr_onerilenSiparis | I45: =HESAP!C18
H46: mmr_kapasiteYuku | I46: =HESAP!C24
H47: mmr_kapasiteAsim | I47: =HESAP!C23
...

Sheet KILAVUZ
A1: KILAVUZ — Mini-MRP (BOM + Malzeme İhtiyacı + Kapasite)
A3: Kullanım Kılavuzu
A5: 1. KARTLAR sayfasına mamul kartı ekleyin; sonraki kimliği kullanın.
A6: 2. AKIS sayfasına her BOM/iş emri satırını yazın; durum kolonunu listeden seçin.
A7: 3. Önceki durum boş bırakılırsa geçiş uyarısı çalışmaz; bilinçli geçişte doldurun.
A8: 4. Geçersiz geçiş engellenmez — kırmızı uyarı üretir (makrosuz kural).
A9: 5. Kapalı durum (Tamam) açık kuyruklardan düşer.
A10: 6. raporTarihi AYARLAR'dadır; TODAY kullanılmaz. Yaşlandırma plan tarihine göredir.
A11: 7. Koruma şifresi: 1234 — formül hücreleri kilitli, sarı hücreler açıktır.
A12: 8. RAPOR sayfasını PDF olarak yazdırabilirsiniz.
A13: 9. Sürüm 1.0.0 | Lisans: Tek kullanıcı | ExcelArşiv
