Workbook
Name raporTarihi: AYARLAR!$B$6
Name spy_d2: AYARLAR!$B$7
Name spy_A2: AYARLAR!$B$8
Name spy_ucSigma: AYARLAR!$B$9
Name spy_altiSigma: AYARLAR!$B$10
Name spy_esikCpk: AYARLAR!$B$11
Name spy_esikCp: AYARLAR!$B$12
Name spy_esikSaglik: AYARLAR!$B$13
Name spy_aylikCarpan: AYARLAR!$B$14
Name spy_senaryoTemkinli: AYARLAR!$B$15
Name spy_senaryoBaz: AYARLAR!$B$16
Name spy_senaryoIyimser: AYARLAR!$B$17
Name spy_tornadoOran: AYARLAR!$B$18
Name spy_yuzdelikOran: AYARLAR!$B$19
Name spy_percentileOran: AYARLAR!$B$20
Name spy_tahminCarpan: AYARLAR!$B$21
Name spy_olcekHedef: AYARLAR!$B$22
Name spy_kaliteTaban: AYARLAR!$B$23
Name spy_kaliteCeza: AYARLAR!$B$24
Name spy_kaliteSapma: AYARLAR!$B$25
Name spy_dosyaSurumu: AYARLAR!$B$26
Name spy_firmaUnvan: AYARLAR!$B$27
Name spy_alarmEsikMetin: AYARLAR!$B$28
Name spy_doluKayit: AYARLAR!$I$32
Name spy_xbarOrt: AYARLAR!$I$33
Name spy_sigmaOrt: AYARLAR!$I$34
Name spy_cpOrt: AYARLAR!$I$35
Name spy_cpkOrt: AYARLAR!$I$36
Name spy_cpkMin: AYARLAR!$I$37
Name spy_aktifProses: AYARLAR!$I$38
Name spy_rToplam: AYARLAR!$I$39
Name spy_saglikSkor: AYARLAR!$I$40
Name spy_alarmAdet: AYARLAR!$I$41
Name spy_yetimAdet: AYARLAR!$I$42
Name spy_gunlukXbarOrt: AYARLAR!$I$43
Name spy_aylikCpkTrend: AYARLAR!$I$44
Name spy_cpkSapma: AYARLAR!$I$45
Name spy_tornadoZirve: AYARLAR!$I$46
Name spy_senaryoKarsilastirma: AYARLAR!$I$47
Name spy_hhi: AYARLAR!$I$48
Name spy_kaliteSkor: AYARLAR!$I$49
Name spy_senaryoMotor: AYARLAR!$I$50
Name spy_tahminAralik: AYARLAR!$I$51
Name spy_yuzdelikP90: AYARLAR!$I$52
Name spy_sezonsalTrend: AYARLAR!$I$53
Name spy_alarmListesi: AYARLAR!$I$54
Name spy_kararKapi: AYARLAR!$I$55
Name spy_kararGerekce: AYARLAR!$I$56
Name spy_sonrakiKimlik: AYARLAR!$I$57
Name spy_yorumGunluk: AYARLAR!$I$60
Name spy_yorumAylik: AYARLAR!$I$61
Name spy_yorumSapma: AYARLAR!$I$62
Name spy_yorumTornado: AYARLAR!$I$63
Name spy_yorumSenaryo: AYARLAR!$I$64
Name spy_yorumHhi: AYARLAR!$I$65
Name spy_yorumKalite: AYARLAR!$I$66
Name spy_yorumSenMotor: AYARLAR!$I$67
Name spy_yorumTahmin: AYARLAR!$I$68
Name spy_yorumP90: AYARLAR!$I$69
Name ListeEvetHayir: LISTELER!$A$7:$A$8

Sheet KAPAK
A1: KAPAK — SPC Proses Yetenek Analizi
A3: SPC Proses Yetenek Analizi
A4: Proses yetenek (Cp/Cpk), X̄-R kontrol kartı ve Western Electric alarmlarını tek dosyada üretir; saha günlük girişi ≤6 alan; varlık sağlık skoru ve alarm kuyruğu; UYGUN / DİKKAT / KRİTİK / VERİ YOK kararı verir.
A6: Bu ürün ne sağlar?
A7: • Cp ve Cpk: USL/LSL ve σ (R̄/d2) zinciriyle canlı hesap
A8: • Günlük X̄-R girişi en fazla 6 alan — 30 saniye hedefi
A9: • Varlık sağlık skoru formülle veriden türer (sabit skor yok)
A10: • 12 aylık sezonsal yetenek zinciri ve kontrol limiti alarm kuyruğu
A11: • Makrosuz, çevrimdışı; dış istatistik API bağı yok
A13: Kimler için?
A14: • Saha / ölçüm operatörü — günlük X̄-R satırı
A15: • Kalite müdürü / süreç mühendisi — Cp/Cpk ve karar panosu
... A21: Sürüm 1.0.0 | Kod: SPY-PRO | Lisans: Tek kullanıcı | ExcelArşiv

Sheet VARLIKLAR
A1: VARLIKLAR — SPC Proses Yetenek Analizi
A3: Proses / özellik kartları — her varlığın tek kimliği vardır
A4: Sonraki Kimlik | B4: =spy_sonrakiKimlik
A5: VarlikId | B5: ProsesAd | C5: Tip | D5: Birim | E5: LSL_birim | F5: USL_birim | G5: Hedef_birim | H5: AltgrupN_adet | I5: Aktif | J5: OlcumAdet | K5: OrtCpk | L5: SaglikSkor
A6: PRS-00001 | B6: Mil Cap Olcum | C6: Torna | D6: mm | E6: 9.9 | F6: 10.1 | G6: 10 | H6: 5 | I6: EVET | J6: =IF($A6="","",COUNTIF(tblOlcum[VarlikId],$A6)) | K6: =IF($A6="","",IFERROR(AVERAGEIF(tblOlcum[VarlikId],$A6,tblOlcum[FormulCpk]),0)) | L6: =IF($A6="","",MAX(0,MIN(100,spy_kaliteTaban-IF($K6<spy_esikCpk,spy_kaliteCeza,0)-COUNTIFS(tblOlcum[VarlikId],$A6,tblOlcum[AlarmBayrak],"ALARM")*spy_kaliteSapma-IF($I6="HAYIR",spy_kaliteCeza,0))))
A7: PRS-00002 | B7: Delik Cap | C7: Freze | D7: mm | E7: 5.95 | F7: 6.05 | G7: 6 | H7: 5 | I7: EVET | J7: =IF($A7="","",COUNTIF(tblOlcum[VarlikId],$A7)) | K7: =IF($A7="","",IFERROR(AVERAGEIF(tblOlcum[VarlikId],$A7,tblOlcum[FormulCpk]),0)) | L7: =IF($A7="","",MAX(0,MIN(100,spy_kaliteTaban-IF($K7<spy_esikCpk,spy_kaliteCeza,0)-COUNTIFS(tblOlcum[VarlikId],$A7,tblOlcum[AlarmBayrak],"ALARM")*spy_kaliteSapma-IF($I7="HAYIR",spy_kaliteCeza,0))))
A8: PRS-00003 | B8: Yuzey Puruzluluk | C8: Taslama | D8: um | E8: 0.4 | F8: 1.6 | G8: 0.8 | H8: 5 | I8: EVET | J8: =IF($A8="","",COUNTIF(tblOlcum[VarlikId],$A8)) | K8: =IF($A8="","",IFERROR(AVERAGEIF(tblOlcum[VarlikId],$A8,tblOlcum[FormulCpk]),0)) | L8: =IF($A8="","",MAX(0,MIN(100,spy_kaliteTaban-IF($K8<spy_esikCpk,spy_kaliteCeza,0)-COUNTIFS(tblOlcum[VarlikId],$A8,tblOlcum[AlarmBayrak],"ALARM")*spy_kaliteSapma-IF($I8="HAYIR",spy_kaliteCeza,0))))
A9: PRS-00004 | B9: Sac Kalinlik | C9: Pres | D9: mm | E9: 1.95 | F9: 2.05 | G9: 2 | H9: 5 | I9: EVET | J9: =IF($A9="","",COUNTIF(tblOlcum[VarlikId],$A9)) | K9: =IF($A9="","",IFERROR(AVERAGEIF(tblOlcum[VarlikId],$A9,tblOlcum[FormulCpk]),0)) | L9: =IF($A9="","",MAX(0,MIN(100,spy_kaliteTaban-IF($K9<spy_esikCpk,spy_kaliteCeza,0)-COUNTIFS(tblOlcum[VarlikId],$A9,tblOlcum[AlarmBayrak],"ALARM")*spy_kaliteSapma-IF($I9="HAYIR",spy_kaliteCeza,0))))
A10: PRS-00005 | B10: Kaynak Boyu | C10: Kaynak | D10: mm | E10: 19.5 | F10: 20.5 | G10: 20 | H10: 5 | I10: EVET | J10: =IF($A10="","",COUNTIF(tblOlcum[VarlikId],$A10)) | K10: =IF($A10="","",IFERROR(AVERAGEIF(tblOlcum[VarlikId],$A10,tblOlcum[FormulCpk]),0)) | L10: =IF($A10="","",MAX(0,MIN(100,spy_kaliteTaban-IF($K10<spy_esikCpk,spy_kaliteCeza,0)-COUNTIFS(tblOlcum[VarlikId],$A10,tblOlcum[AlarmBayrak],"ALARM")*spy_kaliteSapma-IF($I10="HAYIR",spy_kaliteCeza,0))))
A11: PRS-00006 | B11: Montaj Bosluk | C11: Montaj | D11: mm | E11: 0.05 | F11: 0.25 | G11: 0.15 | H11: 5 | I11: EVET | J11: =IF($A11="","",COUNTIF(tblOlcum[VarlikId],$A11)) | K11: =IF($A11="","",IFERROR(AVERAGEIF(tblOlcum[VarlikId],$A11,tblOlcum[FormulCpk]),0)) | L11: =IF($A11="","",MAX(0,MIN(100,spy_kaliteTaban-IF($K11<spy_esikCpk,spy_kaliteCeza,0)-COUNTIFS(tblOlcum[VarlikId],$A11,tblOlcum[AlarmBayrak],"ALARM")*spy_kaliteSapma-IF($I11="HAYIR",spy_kaliteCeza,0))))
A12: PRS-00007 | B12: Sicaklik Kontrol | C12: Firin | D12: C | E12: 175 | F12: 185 | G12: 180 | H12: 5 | I12: EVET | J12: =IF($A12="","",COUNTIF(tblOlcum[VarlikId],$A12)) | K12: =IF($A12="","",IFERROR(AVERAGEIF(tblOlcum[VarlikId],$A12,tblOlcum[FormulCpk]),0)) | L12: =IF($A12="","",MAX(0,MIN(100,spy_kaliteTaban-IF($K12<spy_esikCpk,spy_kaliteCeza,0)-COUNTIFS(tblOlcum[VarlikId],$A12,tblOlcum[AlarmBayrak],"ALARM")*spy_kaliteSapma-IF($I12="HAYIR",spy_kaliteCeza,0))))
A13: PRS-00008 | B13: Tork Sikiştirma | C13: Montaj | D13: Nm | E13: 18 | F13: 22 | G13: 20 | H13: 5 | I13: EVET | J13: =IF($A13="","",COUNTIF(tblOlcum[VarlikId],$A13)) | K13: =IF($A13="","",IFERROR(AVERAGEIF(tblOlcum[VarlikId],$A13,tblOlcum[FormulCpk]),0)) | L13: =IF($A13="","",MAX(0,MIN(100,spy_kaliteTaban-IF($K13<spy_esikCpk,spy_kaliteCeza,0)-COUNTIFS(tblOlcum[VarlikId],$A13,tblOlcum[AlarmBayrak],"ALARM")*spy_kaliteSapma-IF($I13="HAYIR",spy_kaliteCeza,0))))
J14: =IF($A14="","",COUNTIF(tblOlcum[VarlikId],$A14)) | K14: =IF($A14="","",IFERROR(AVERAGEIF(tblOlcum[VarlikId],$A14,tblOlcum[FormulCpk]),0)) | L14: =IF($A14="","",MAX(0,MIN(100,spy_kaliteTaban-IF($K14<spy_esikCpk,spy_kaliteCeza,0)-COUNTIFS(tblOlcum[VarlikId],$A14,tblOlcum[AlarmBayrak],"ALARM")*spy_kaliteSapma-IF($I14="HAYIR",spy_kaliteCeza,0))))
J15: =IF($A15="","",COUNTIF(tblOlcum[VarlikId],$A15)) | K15: =IF($A15="","",IFERROR(AVERAGEIF(tblOlcum[VarlikId],$A15,tblOlcum[FormulCpk]),0)) | L15: =IF($A15="","",MAX(0,MIN(100,spy_kaliteTaban-IF($K15<spy_esikCpk,spy_kaliteCeza,0)-COUNTIFS(tblOlcum[VarlikId],$A15,tblOlcum[AlarmBayrak],"ALARM")*spy_kaliteSapma-IF($I15="HAYIR",spy_kaliteCeza,0))))
J16: =IF($A16="","",COUNTIF(tblOlcum[VarlikId],$A16)) | K16: =IF($A16="","",IFERROR(AVERAGEIF(tblOlcum[VarlikId],$A16,tblOlcum[FormulCpk]),0)) | L16: =IF($A16="","",MAX(0,MIN(100,spy_kaliteTaban-IF($K16<spy_esikCpk,spy_kaliteCeza,0)-COUNTIFS(tblOlcum[VarlikId],$A16,tblOlcum[AlarmBayrak],"ALARM")*spy_kaliteSapma-IF($I16="HAYIR",spy_kaliteCeza,0))))
J17: =IF($A17="","",COUNTIF(tblOlcum[VarlikId],$A17)) | K17: =IF($A17="","",IFERROR(AVERAGEIF(tblOlcum[VarlikId],$A17,tblOlcum[FormulCpk]),0)) | L17: =IF($A17="","",MAX(0,MIN(100,spy_kaliteTaban-IF($K17<spy_esikCpk,spy_kaliteCeza,0)-COUNTIFS(tblOlcum[VarlikId],$A17,tblOlcum[AlarmBayrak],"ALARM")*spy_kaliteSapma-IF($I17="HAYIR",spy_kaliteCeza,0))))
J18: =IF($A18="","",COUNTIF(tblOlcum[VarlikId],$A18)) | K18: =IF($A18="","",IFERROR(AVERAGEIF(tblOlcum[VarlikId],$A18,tblOlcum[FormulCpk]),0)) | L18: =IF($A18="","",MAX(0,MIN(100,spy_kaliteTaban-IF($K18<spy_esikCpk,spy_kaliteCeza,0)-COUNTIFS(tblOlcum[VarlikId],$A18,tblOlcum[AlarmBayrak],"ALARM")*spy_kaliteSapma-IF($I18="HAYIR",spy_kaliteCeza,0))))
J19: =IF($A19="","",COUNTIF(tblOlcum[VarlikId],$A19)) | K19: =IF($A19="","",IFERROR(AVERAGEIF(tblOlcum[VarlikId],$A19,tblOlcum[FormulCpk]),0)) | L19: =IF($A19="","",MAX(0,MIN(100,spy_kaliteTaban-IF($K19<spy_esikCpk,spy_kaliteCeza,0)-COUNTIFS(tblOlcum[VarlikId],$A19,tblOlcum[AlarmBayrak],"ALARM")*spy_kaliteSapma-IF($I19="HAYIR",spy_kaliteCeza,0))))
J20: =IF($A20="","",COUNTIF(tblOlcum[VarlikId],$A20)) | K20: =IF($A20="","",IFERROR(AVERAGEIF(tblOlcum[VarlikId],$A20,tblOlcum[FormulCpk]),0)) | L20: =IF($A20="","",MAX(0,MIN(100,spy_kaliteTaban-IF($K20<spy_esikCpk,spy_kaliteCeza,0)-COUNTIFS(tblOlcum[VarlikId],$A20,tblOlcum[AlarmBayrak],"ALARM")*spy_kaliteSapma-IF($I20="HAYIR",spy_kaliteCeza,0))))
J21: =IF($A21="","",COUNTIF(tblOlcum[VarlikId],$A21)) | K21: =IF($A21="","",IFERROR(AVERAGEIF(tblOlcum[VarlikId],$A21,tblOlcum[FormulCpk]),0)) | L21: =IF($A21="","",MAX(0,MIN(100,spy_kaliteTaban-IF($K21<spy_esikCpk,spy_kaliteCeza,0)-COUNTIFS(tblOlcum[VarlikId],$A21,tblOlcum[AlarmBayrak],"ALARM")*spy_kaliteSapma-IF($I21="HAYIR",spy_kaliteCeza,0))))
J22: =IF($A22="","",COUNTIF(tblOlcum[VarlikId],$A22)) | K22: =IF($A22="","",IFERROR(AVERAGEIF(tblOlcum[VarlikId],$A22,tblOlcum[FormulCpk]),0)) | L22: =IF($A22="","",MAX(0,MIN(100,spy_kaliteTaban-IF($K22<spy_esikCpk,spy_kaliteCeza,0)-COUNTIFS(tblOlcum[VarlikId],$A22,tblOlcum[AlarmBayrak],"ALARM")*spy_kaliteSapma-IF($I22="HAYIR",spy_kaliteCeza,0))))
J23: =IF($A23="","",COUNTIF(tblOlcum[VarlikId],$A23)) | K23: =IF($A23="","",IFERROR(AVERAGEIF(tblOlcum[VarlikId],$A23,tblOlcum[FormulCpk]),0)) | L23: =IF($A23="","",MAX(0,MIN(100,spy_kaliteTaban-IF($K23<spy_esikCpk,spy_kaliteCeza,0)-COUNTIFS(tblOlcum[VarlikId],$A23,tblOlcum[AlarmBayrak],"ALARM")*spy_kaliteSapma-IF($I23="HAYIR",spy_kaliteCeza,0))))
J24: =IF($A24="","",COUNTIF(tblOlcum[VarlikId],$A24)) | K24: =IF($A24="","",IFERROR(AVERAGEIF(tblOlcum[VarlikId],$A24,tblOlcum[FormulCpk]),0)) | L24: =IF($A24="","",MAX(0,MIN(100,spy_kaliteTaban-IF($K24<spy_esikCpk,spy_kaliteCeza,0)-COUNTIFS(tblOlcum[VarlikId],$A24,tblOlcum[AlarmBayrak],"ALARM")*spy_kaliteSapma-IF($I24="HAYIR",spy_kaliteCeza,0))))
J25: =IF($A25="","",COUNTIF(tblOlcum[VarlikId],$A25)) | K25: =IF($A25="","",IFERROR(AVERAGEIF(tblOlcum[VarlikId],$A25,tblOlcum[FormulCpk]),0)) | L25: =IF($A25="","",MAX(0,MIN(100,spy_kaliteTaban-IF($K25<spy_esikCpk,spy_kaliteCeza,0)-COUNTIFS(tblOlcum[VarlikId],$A25,tblOlcum[AlarmBayrak],"ALARM")*spy_kaliteSapma-IF($I25="HAYIR",spy_kaliteCeza,0))))
... J255: =IF($A255="","",COUNTIF(tblOlcum[VarlikId],$A255)) | K255: =IF($A255="","",IFERROR(AVERAGEIF(tblOlcum[VarlikId],$A255,tblOlcum[FormulCpk]),0)) | L255: =IF($A255="","",MAX(0,MIN(100,spy_kaliteTaban-IF($K255<spy_esikCpk,spy_kaliteCeza,0)-COUNTIFS(tblOlcum[VarlikId],$A255,tblOlcum[AlarmBayrak],"ALARM")*spy_kaliteSapma-IF($I255="HAYIR",spy_kaliteCeza,0))))

Sheet GUNLUK_GIRIS
A1: GUNLUK GIRIS — SPC Proses Yetenek Analizi
A3: GÜNLÜK ölçüm girişi — satır başına en fazla 6 manuel alan (S02)
A5: SatirId | B5: VarlikId | C5: Tarih | D5: Xbar_birim | E5: R_birim | F5: AltgrupN_adet | G5: Vardiya | H5: FormulSigma | I5: FormulCp | J5: FormulCpk | K5: FormulUclX | L5: FormulLclX | M5: SaglikSkorSatir | N5: AlarmBayrak | O5: FormulKayitDolu | P5: FormulYetim
A6: OLC-00001 | B6: PRS-00001 | C6: 46242 | D6: 9.984 | E6: 0.0512 | F6: 5 | G6: GECE | H6: =IF(OR($A6="",$E6=0),"",$E6/spy_d2) | I6: =IF(OR($A6="",$H6=0),"",IFERROR((SUMIF(tblProsesler[VarlikId],$B6,tblProsesler[USL_birim])-SUMIF(tblProsesler[VarlikId],$B6,tblProsesler[LSL_birim]))/(spy_altiSigma*$H6),0)) | J6: =IF(OR($A6="",$H6=0),"",IFERROR(MIN((SUMIF(tblProsesler[VarlikId],$B6,tblProsesler[USL_birim])-$D6)/(spy_ucSigma*$H6),($D6-SUMIF(tblProsesler[VarlikId],$B6,tblProsesler[LSL_birim]))/(spy_ucSigma*$H6)),0)) | K6: =IF($A6="","",IFERROR(AVERAGEIF(tblOlcum[VarlikId],$B6,tblOlcum[Xbar_birim])+spy_A2*$E6,0)) | L6: =IF($A6="","",IFERROR(AVERAGEIF(tblOlcum[VarlikId],$B6,tblOlcum[Xbar_birim])-spy_A2*$E6,0)) | M6: =IF($A6="","",MAX(0,MIN(100,spy_kaliteTaban-IF($J6<spy_esikCpk,spy_kaliteCeza,0)-IF(OR($D6>$K6,$D6<$L6),spy_kaliteSapma,0)-IF($P6="YETIM",spy_kaliteCeza,0)))) | N6: =IF($A6="","",IF(OR($J6<spy_esikCpk,$D6>$K6,$D6<$L6,$M6<spy_esikSaglik),"ALARM","UYGUN")) | O6: =IF($A6="","",1) | P6: =IF($A6="","",IF(OR($B6="",COUNTIF(tblProsesler[VarlikId],$B6)=0),"YETIM","TAMAM"))
A7: OLC-00002 | B7: PRS-00002 | C7: 46239 | D7: 5.996 | E7: 0.0168 | F7: 5 | G7: HAFTASONU | H7: =IF(OR($A7="",$E7=0),"",$E7/spy_d2) | I7: =IF(OR($A7="",$H7=0),"",IFERROR((SUMIF(tblProsesler[VarlikId],$B7,tblProsesler[USL_birim])-SUMIF(tblProsesler[VarlikId],$B7,tblProsesler[LSL_birim]))/(spy_altiSigma*$H7),0)) | J7: =IF(OR($A7="",$H7=0),"",IFERROR(MIN((SUMIF(tblProsesler[VarlikId],$B7,tblProsesler[USL_birim])-$D7)/(spy_ucSigma*$H7),($D7-SUMIF(tblProsesler[VarlikId],$B7,tblProsesler[LSL_birim]))/(spy_ucSigma*$H7)),0)) | K7: =IF($A7="","",IFERROR(AVERAGEIF(tblOlcum[VarlikId],$B7,tblOlcum[Xbar_birim])+spy_A2*$E7,0)) | L7: =IF($A7="","",IFERROR(AVERAGEIF(tblOlcum[VarlikId],$B7,tblOlcum[Xbar_birim])-spy_A2*$E7,0)) | M7: =IF($A7="","",MAX(0,MIN(100,spy_kaliteTaban-IF($J7<spy_esikCpk,spy_kaliteCeza,0)-IF(OR($D7>$K7,$D7<$L7),spy_kaliteSapma,0)-IF($P7="YETIM",spy_kaliteCeza,0)))) | N7: =IF($A7="","",IF(OR($J7<spy_esikCpk,$D7>$K7,$D7<$L7,$M7<spy_esikSaglik),"ALARM","UYGUN")) | O7: =IF($A7="","",1) | P7: =IF($A7="","",IF(OR($B7="",COUNTIF(tblProsesler[VarlikId],$B7)=0),"YETIM","TAMAM"))
A8: OLC-00003 | B8: PRS-00003 | C8: 46236 | D8: 0.8 | E8: 0.096 | F8: 5 | G8: FAZLA_MESAI | H8: =IF(OR($A8="",$E8=0),"",$E8/spy_d2) | I8: =IF(OR($A8="",$H8=0),"",IFERROR((SUMIF(tblProsesler[VarlikId],$B8,tblProsesler[USL_birim])-SUMIF(tblProsesler[VarlikId],$B8,tblProsesler[LSL_birim]))/(spy_altiSigma*$H8),0)) | J8: =IF(OR($A8="",$H8=0),"",IFERROR(MIN((SUMIF(tblProsesler[VarlikId],$B8,tblProsesler[USL_birim])-$D8)/(spy_ucSigma*$H8),($D8-SUMIF(tblProsesler[VarlikId],$B8,tblProsesler[LSL_birim]))/(spy_ucSigma*$H8)),0)) | K8: =IF($A8="","",IFERROR(AVERAGEIF(tblOlcum[VarlikId],$B8,tblOlcum[Xbar_birim])+spy_A2*$E8,0)) | L8: =IF($A8="","",IFERROR(AVERAGEIF(tblOlcum[VarlikId],$B8,tblOlcum[Xbar_birim])-spy_A2*$E8,0)) | M8: =IF($A8="","",MAX(0,MIN(100,spy_kaliteTaban-IF($J8<spy_esikCpk,spy_kaliteCeza,0)-IF(OR($D8>$K8,$D8<$L8),spy_kaliteSapma,0)-IF($P8="YETIM",spy_kaliteCeza,0)))) | N8: =IF($A8="","",IF(OR($J8<spy_esikCpk,$D8>$K8,$D8<$L8,$M8<spy_esikSaglik),"ALARM","UYGUN")) | O8: =IF($A8="","",1) | P8: =IF($A8="","",IF(OR($B8="",COUNTIF(tblProsesler[VarlikId],$B8)=0),"YETIM","TAMAM"))
A9: OLC-00004 | B9: PRS-00004 | C9: 46233 | D9: 2.004 | E9: 0.0168 | F9: 5 | G9: NUMUNE | H9: =IF(OR($A9="",$E9=0),"",$E9/spy_d2) | I9: =IF(OR($A9="",$H9=0),"",IFERROR((SUMIF(tblProsesler[VarlikId],$B9,tblProsesler[USL_birim])-SUMIF(tblProsesler[VarlikId],$B9,tblProsesler[LSL_birim]))/(spy_altiSigma*$H9),0)) | J9: =IF(OR($A9="",$H9=0),"",IFERROR(MIN((SUMIF(tblProsesler[VarlikId],$B9,tblProsesler[USL_birim])-$D9)/(spy_ucSigma*$H9),($D9-SUMIF(tblProsesler[VarlikId],$B9,tblProsesler[LSL_birim]))/(spy_ucSigma*$H9)),0)) | K9: =IF($A9="","",IFERROR(AVERAGEIF(tblOlcum[VarlikId],$B9,tblOlcum[Xbar_birim])+spy_A2*$E9,0)) | L9: =IF($A9="","",IFERROR(AVERAGEIF(tblOlcum[VarlikId],$B9,tblOlcum[Xbar_birim])-spy_A2*$E9,0)) | M9: =IF($A9="","",MAX(0,MIN(100,spy_kaliteTaban-IF($J9<spy_esikCpk,spy_kaliteCeza,0)-IF(OR($D9>$K9,$D9<$L9),spy_kaliteSapma,0)-IF($P9="YETIM",spy_kaliteCeza,0)))) | N9: =IF($A9="","",IF(OR($J9<spy_esikCpk,$D9>$K9,$D9<$L9,$M9<spy_esikSaglik),"ALARM","UYGUN")) | O9: =IF($A9="","",1) | P9: =IF($A9="","",IF(OR($B9="",COUNTIF(tblProsesler[VarlikId],$B9)=0),"YETIM","TAMAM"))
A10: OLC-00005 | B10: PRS-00005 | C10: 46230 | D10: 20.08 | E10: 0.256 | F10: 5 | G10: DIGER | H10: =IF(OR($A10="",$E10=0),"",$E10/spy_d2) | I10: =IF(OR($A10="",$H10=0),"",IFERROR((SUMIF(tblProsesler[VarlikId],$B10,tblProsesler[USL_birim])-SUMIF(tblProsesler[VarlikId],$B10,tblProsesler[LSL_birim]))/(spy_altiSigma*$H10),0)) | J10: =IF(OR($A10="",$H10=0),"",IFERROR(MIN((SUMIF(tblProsesler[VarlikId],$B10,tblProsesler[USL_birim])-$D10)/(spy_ucSigma*$H10),($D10-SUMIF(tblProsesler[VarlikId],$B10,tblProsesler[LSL_birim]))/(spy_ucSigma*$H10)),0)) | K10: =IF($A10="","",IFERROR(AVERAGEIF(tblOlcum[VarlikId],$B10,tblOlcum[Xbar_birim])+spy_A2*$E10,0)) | L10: =IF($A10="","",IFERROR(AVERAGEIF(tblOlcum[VarlikId],$B10,tblOlcum[Xbar_birim])-spy_A2*$E10,0)) | M10: =IF($A10="","",MAX(0,MIN(100,spy_kaliteTaban-IF($J10<spy_esikCpk,spy_kaliteCeza,0)-IF(OR($D10>$K10,$D10<$L10),spy_kaliteSapma,0)-IF($P10="YETIM",spy_kaliteCeza,0)))) | N10: =IF($A10="","",IF(OR($J10<spy_esikCpk,$D10>$K10,$D10<$L10,$M10<spy_esikSaglik),"ALARM","UYGUN")) | O10: =IF($A10="","",1) | P10: =IF($A10="","",IF(OR($B10="",COUNTIF(tblProsesler[VarlikId],$B10)=0),"YETIM","TAMAM"))
A11: OLC-00006 | B11: PRS-00006 | C11: 46227 | D11: 0.174 | E11: 0.0688 | F11: 5 | G11: GUNDUZ | H11: =IF(OR($A11="",$E11=0),"",$E11/spy_d2) | I11: =IF(OR($A11="",$H11=0),"",IFERROR((SUMIF(tblProsesler[VarlikId],$B11,tblProsesler[USL_birim])-SUMIF(tblProsesler[VarlikId],$B11,tblProsesler[LSL_birim]))/(spy_altiSigma*$H11),0)) | J11: =IF(OR($A11="",$H11=0),"",IFERROR(MIN((SUMIF(tblProsesler[VarlikId],$B11,tblProsesler[USL_birim])-$D11)/(spy_ucSigma*$H11),($D11-SUMIF(tblProsesler[VarlikId],$B11,tblProsesler[LSL_birim]))/(spy_ucSigma*$H11)),0)) | K11: =IF($A11="","",IFERROR(AVERAGEIF(tblOlcum[VarlikId],$B11,tblOlcum[Xbar_birim])+spy_A2*$E11,0)) | L11: =IF($A11="","",IFERROR(AVERAGEIF(tblOlcum[VarlikId],$B11,tblOlcum[Xbar_birim])-spy_A2*$E11,0)) | M11: =IF($A11="","",MAX(0,MIN(100,spy_kaliteTaban-IF($J11<spy_esikCpk,spy_kaliteCeza,0)-IF(OR($D11>$K11,$D11<$L11),spy_kaliteSapma,0)-IF($P11="YETIM",spy_kaliteCeza,0)))) | N11: =IF($A11="","",IF(OR($J11<spy_esikCpk,$D11>$K11,$D11<$L11,$M11<spy_esikSaglik),"ALARM","UYGUN")) | O11: =IF($A11="","",1) | P11: =IF($A11="","",IF(OR($B11="",COUNTIF(tblProsesler[VarlikId],$B11)=0),"YETIM","TAMAM"))
A12: OLC-00007 | B12: PRS-00007 | C12: 46224 | D12: 178.8 | E12: 3.44 | F12: 5 | G12: GECE | H12: =IF(OR($A12="",$E12=0),"",$E12/spy_d2) | I12: =IF(OR($A12="",$H12=0),"",IFERROR((SUMIF(tblProsesler[VarlikId],$B12,tblProsesler[USL_birim])-SUMIF(tblProsesler[VarlikId],$B12,tblProsesler[LSL_birim]))/(spy_altiSigma*$H12),0)) | J12: =IF(OR($A12="",$H12=0),"",IFERROR(MIN((SUMIF(tblProsesler[VarlikId],$B12,tblProsesler[USL_birim])-$D12)/(spy_ucSigma*$H12),($D12-SUMIF(tblProsesler[VarlikId],$B12,tblProsesler[LSL_birim]))/(spy_ucSigma*$H12)),0)) | K12: =IF($A12="","",IFERROR(AVERAGEIF(tblOlcum[VarlikId],$B12,tblOlcum[Xbar_birim])+spy_A2*$E12,0)) | L12: =IF($A12="","",IFERROR(AVERAGEIF(tblOlcum[VarlikId],$B12,tblOlcum[Xbar_birim])-spy_A2*$E12,0)) | M12: =IF($A12="","",MAX(0,MIN(100,spy_kaliteTaban-IF($J12<spy_esikCpk,spy_kaliteCeza,0)-IF(OR($D12>$K12,$D12<$L12),spy_kaliteSapma,0)-IF($P12="YETIM",spy_kaliteCeza,0)))) | N12: =IF($A12="","",IF(OR($J12<spy_esikCpk,$D12>$K12,$D12<$L12,$M12<spy_esikSaglik),"ALARM","UYGUN")) | O12: =IF($A12="","",1) | P12: =IF($A12="","",IF(OR($B12="",COUNTIF(tblProsesler[VarlikId],$B12)=0),"YETIM","TAMAM"))
A13: OLC-00008 | B13: PRS-00008 | C13: 46221 | D13: 19.68 | E13: 1.024 | F13: 5 | G13: HAFTASONU | H13: =IF(OR($A13="",$E13=0),"",$E13/spy_d2) | I13: =IF(OR($A13="",$H13=0),"",IFERROR((SUMIF(tblProsesler[VarlikId],$B13,tblProsesler[USL_birim])-SUMIF(tblProsesler[VarlikId],$B13,tblProsesler[LSL_birim]))/(spy_altiSigma*$H13),0)) | J13: =IF(OR($A13="",$H13=0),"",IFERROR(MIN((SUMIF(tblProsesler[VarlikId],$B13,tblProsesler[USL_birim])-$D13)/(spy_ucSigma*$H13),($D13-SUMIF(tblProsesler[VarlikId],$B13,tblProsesler[LSL_birim]))/(spy_ucSigma*$H13)),0)) | K13: =IF($A13="","",IFERROR(AVERAGEIF(tblOlcum[VarlikId],$B13,tblOlcum[Xbar_birim])+spy_A2*$E13,0)) | L13: =IF($A13="","",IFERROR(AVERAGEIF(tblOlcum[VarlikId],$B13,tblOlcum[Xbar_birim])-spy_A2*$E13,0)) | M13: =IF($A13="","",MAX(0,MIN(100,spy_kaliteTaban-IF($J13<spy_esikCpk,spy_kaliteCeza,0)-IF(OR($D13>$K13,$D13<$L13),spy_kaliteSapma,0)-IF($P13="YETIM",spy_kaliteCeza,0)))) | N13: =IF($A13="","",IF(OR($J13<spy_esikCpk,$D13>$K13,$D13<$L13,$M13<spy_esikSaglik),"ALARM","UYGUN")) | O13: =IF($A13="","",1) | P13: =IF($A13="","",IF(OR($B13="",COUNTIF(tblProsesler[VarlikId],$B13)=0),"YETIM","TAMAM"))
A14: OLC-00009 | B14: PRS-00001 | C14: 46218 | D14: 9.992 | E14: 0.0336 | F14: 5 | G14: FAZLA_MESAI | H14: =IF(OR($A14="",$E14=0),"",$E14/spy_d2) | I14: =IF(OR($A14="",$H14=0),"",IFERROR((SUMIF(tblProsesler[VarlikId],$B14,tblProsesler[USL_birim])-SUMIF(tblProsesler[VarlikId],$B14,tblProsesler[LSL_birim]))/(spy_altiSigma*$H14),0)) | J14: =IF(OR($A14="",$H14=0),"",IFERROR(MIN((SUMIF(tblProsesler[VarlikId],$B14,tblProsesler[USL_birim])-$D14)/(spy_ucSigma*$H14),($D14-SUMIF(tblProsesler[VarlikId],$B14,tblProsesler[LSL_birim]))/(spy_ucSigma*$H14)),0)) | K14: =IF($A14="","",IFERROR(AVERAGEIF(tblOlcum[VarlikId],$B14,tblOlcum[Xbar_birim])+spy_A2*$E14,0)) | L14: =IF($A14="","",IFERROR(AVERAGEIF(tblOlcum[VarlikId],$B14,tblOlcum[Xbar_birim])-spy_A2*$E14,0)) | M14: =IF($A14="","",MAX(0,MIN(100,spy_kaliteTaban-IF($J14<spy_esikCpk,spy_kaliteCeza,0)-IF(OR($D14>$K14,$D14<$L14),spy_kaliteSapma,0)-IF($P14="YETIM",spy_kaliteCeza,0)))) | N14: =IF($A14="","",IF(OR($J14<spy_esikCpk,$D14>$K14,$D14<$L14,$M14<spy_esikSaglik),"ALARM","UYGUN")) | O14: =IF($A14="","",1) | P14: =IF($A14="","",IF(OR($B14="",COUNTIF(tblProsesler[VarlikId],$B14)=0),"YETIM","TAMAM"))
A15: OLC-00010 | B15: PRS-00002 | C15: 46215 | D15: 6 | E15: 0.008 | F15: 5 | G15: NUMUNE | H15: =IF(OR($A15="",$E15=0),"",$E15/spy_d2) | I15: =IF(OR($A15="",$H15=0),"",IFERROR((SUMIF(tblProsesler[VarlikId],$B15,tblProsesler[USL_birim])-SUMIF(tblProsesler[VarlikId],$B15,tblProsesler[LSL_birim]))/(spy_altiSigma*$H15),0)) | J15: =IF(OR($A15="",$H15=0),"",IFERROR(MIN((SUMIF(tblProsesler[VarlikId],$B15,tblProsesler[USL_birim])-$D15)/(spy_ucSigma*$H15),($D15-SUMIF(tblProsesler[VarlikId],$B15,tblProsesler[LSL_birim]))/(spy_ucSigma*$H15)),0)) | K15: =IF($A15="","",IFERROR(AVERAGEIF(tblOlcum[VarlikId],$B15,tblOlcum[Xbar_birim])+spy_A2*$E15,0)) | L15: =IF($A15="","",IFERROR(AVERAGEIF(tblOlcum[VarlikId],$B15,tblOlcum[Xbar_birim])-spy_A2*$E15,0)) | M15: =IF($A15="","",MAX(0,MIN(100,spy_kaliteTaban-IF($J15<spy_esikCpk,spy_kaliteCeza,0)-IF(OR($D15>$K15,$D15<$L15),spy_kaliteSapma,0)-IF($P15="YETIM",spy_kaliteCeza,0)))) | N15: =IF($A15="","",IF(OR($J15<spy_esikCpk,$D15>$K15,$D15<$L15,$M15<spy_esikSaglik),"ALARM","UYGUN")) | O15: =IF($A15="","",1) | P15: =IF($A15="","",IF(OR($B15="",COUNTIF(tblProsesler[VarlikId],$B15)=0),"YETIM","TAMAM"))
A16: OLC-00011 | B16: PRS-00003 | C16: 46212 | D16: 0.848 | E16: 0.2016 | F16: 5 | G16: DIGER | H16: =IF(OR($A16="",$E16=0),"",$E16/spy_d2) | I16: =IF(OR($A16="",$H16=0),"",IFERROR((SUMIF(tblProsesler[VarlikId],$B16,tblProsesler[USL_birim])-SUMIF(tblProsesler[VarlikId],$B16,tblProsesler[LSL_birim]))/(spy_altiSigma*$H16),0)) | J16: =IF(OR($A16="",$H16=0),"",IFERROR(MIN((SUMIF(tblProsesler[VarlikId],$B16,tblProsesler[USL_birim])-$D16)/(spy_ucSigma*$H16),($D16-SUMIF(tblProsesler[VarlikId],$B16,tblProsesler[LSL_birim]))/(spy_ucSigma*$H16)),0)) | K16: =IF($A16="","",IFERROR(AVERAGEIF(tblOlcum[VarlikId],$B16,tblOlcum[Xbar_birim])+spy_A2*$E16,0)) | L16: =IF($A16="","",IFERROR(AVERAGEIF(tblOlcum[VarlikId],$B16,tblOlcum[Xbar_birim])-spy_A2*$E16,0)) | M16: =IF($A16="","",MAX(0,MIN(100,spy_kaliteTaban-IF($J16<spy_esikCpk,spy_kaliteCeza,0)-IF(OR($D16>$K16,$D16<$L16),spy_kaliteSapma,0)-IF($P16="YETIM",spy_kaliteCeza,0)))) | N16: =IF($A16="","",IF(OR($J16<spy_esikCpk,$D16>$K16,$D16<$L16,$M16<spy_esikSaglik),"ALARM","UYGUN")) | O16: =IF($A16="","",1) | P16: =IF($A16="","",IF(OR($B16="",COUNTIF(tblProsesler[VarlikId],$B16)=0),"YETIM","TAMAM"))
A17: OLC-00012 | B17: PRS-00004 | C17: 46209 | D17: 2.065 | E17: 0.055 | F17: 5 | G17: GUNDUZ | H17: =IF(OR($A17="",$E17=0),"",$E17/spy_d2) | I17: =IF(OR($A17="",$H17=0),"",IFERROR((SUMIF(tblProsesler[VarlikId],$B17,tblProsesler[USL_birim])-SUMIF(tblProsesler[VarlikId],$B17,tblProsesler[LSL_birim]))/(spy_altiSigma*$H17),0)) | J17: =IF(OR($A17="",$H17=0),"",IFERROR(MIN((SUMIF(tblProsesler[VarlikId],$B17,tblProsesler[USL_birim])-$D17)/(spy_ucSigma*$H17),($D17-SUMIF(tblProsesler[VarlikId],$B17,tblProsesler[LSL_birim]))/(spy_ucSigma*$H17)),0)) | K17: =IF($A17="","",IFERROR(AVERAGEIF(tblOlcum[VarlikId],$B17,tblOlcum[Xbar_birim])+spy_A2*$E17,0)) | L17: =IF($A17="","",IFERROR(AVERAGEIF(tblOlcum[VarlikId],$B17,tblOlcum[Xbar_birim])-spy_A2*$E17,0)) | M17: =IF($A17="","",MAX(0,MIN(100,spy_kaliteTaban-IF($J17<spy_esikCpk,spy_kaliteCeza,0)-IF(OR($D17>$K17,$D17<$L17),spy_kaliteSapma,0)-IF($P17="YETIM",spy_kaliteCeza,0)))) | N17: =IF($A17="","",IF(OR($J17<spy_esikCpk,$D17>$K17,$D17<$L17,$M17<spy_esikSaglik),"ALARM","UYGUN")) | O17: =IF($A17="","",1) | P17: =IF($A17="","",IF(OR($B17="",COUNTIF(tblProsesler[VarlikId],$B17)=0),"YETIM","TAMAM"))
... A34: OLC-00029 | B34: PRS-00005 | C34: 46158 | D34: 19.92 | E34: 0.256 | F34: 5 | G34: DIGER | H34: =IF(OR($A34="",$E34=0),"",$E34/spy_d2) | I34: =IF(OR($A34="",$H34=0),"",IFERROR((SUMIF(tblProsesler[VarlikId],$B34,tblProsesler[USL_birim])-SUMIF(tblProsesler[VarlikId],$B34,tblProsesler[LSL_birim]))/(spy_altiSigma*$H34),0)) | J34: =IF(OR($A34="",$H34=0),"",IFERROR(MIN((SUMIF(tblProsesler[VarlikId],$B34,tblProsesler[USL_birim])-$D34)/(spy_ucSigma*$H34),($D34-SUMIF(tblProsesler[VarlikId],$B34,tblProsesler[LSL_birim]))/(spy_ucSigma*$H34)),0)) | K34: =IF($A34="","",IFERROR(AVERAGEIF(tblOlcum[VarlikId],$B34,tblOlcum[Xbar_birim])+spy_A2*$E34,0)) | L34: =IF($A34="","",IFERROR(AVERAGEIF(tblOlcum[VarlikId],$B34,tblOlcum[Xbar_birim])-spy_A2*$E34,0)) | M34: =IF($A34="","",MAX(0,MIN(100,spy_kaliteTaban-IF($J34<spy_esikCpk,spy_kaliteCeza,0)-IF(OR($D34>$K34,$D34<$L34),spy_kaliteSapma,0)-IF($P34="YETIM",spy_kaliteCeza,0)))) | N34: =IF($A34="","",IF(OR($J34<spy_esikCpk,$D34>$K34,$D34<$L34,$M34<spy_esikSaglik),"ALARM","UYGUN")) | O34: =IF($A34="","",1) | P34: =IF($A34="","",IF(OR($B34="",COUNTIF(tblProsesler[VarlikId],$B34)=0),"YETIM","TAMAM"))
A35: OLC-00030 | C35: 46155 | D35: 0.28 | E35: 0.11 | F35: 5 | G35: GUNDUZ | H35: =IF(OR($A35="",$E35=0),"",$E35/spy_d2) | I35: =IF(OR($A35="",$H35=0),"",IFERROR((SUMIF(tblProsesler[VarlikId],$B35,tblProsesler[USL_birim])-SUMIF(tblProsesler[VarlikId],$B35,tblProsesler[LSL_birim]))/(spy_altiSigma*$H35),0)) | J35: =IF(OR($A35="",$H35=0),"",IFERROR(MIN((SUMIF(tblProsesler[VarlikId],$B35,tblProsesler[USL_birim])-$D35)/(spy_ucSigma*$H35),($D35-SUMIF(tblProsesler[VarlikId],$B35,tblProsesler[LSL_birim]))/(spy_ucSigma*$H35)),0)) | K35: =IF($A35="","",IFERROR(AVERAGEIF(tblOlcum[VarlikId],$B35,tblOlcum[Xbar_birim])+spy_A2*$E35,0)) | L35: =IF($A35="","",IFERROR(AVERAGEIF(tblOlcum[VarlikId],$B35,tblOlcum[Xbar_birim])-spy_A2*$E35,0)) | M35: =IF($A35="","",MAX(0,MIN(100,spy_kaliteTaban-IF($J35<spy_esikCpk,spy_kaliteCeza,0)-IF(OR($D35>$K35,$D35<$L35),spy_kaliteSapma,0)-IF($P35="YETIM",spy_kaliteCeza,0)))) | N35: =IF($A35="","",IF(OR($J35<spy_esikCpk,$D35>$K35,$D35<$L35,$M35<spy_esikSaglik),"ALARM","UYGUN")) | O35: =IF($A35="","",1) | P35: =IF($A35="","",IF(OR($B35="",COUNTIF(tblProsesler[VarlikId],$B35)=0),"YETIM","TAMAM"))
A36: OLC-00031 | B36: PRS-00007 | C36: 46152 | D36: 180 | E36: 0.8 | F36: 5 | G36: GECE | H36: =IF(OR($A36="",$E36=0),"",$E36/spy_d2) | I36: =IF(OR($A36="",$H36=0),"",IFERROR((SUMIF(tblProsesler[VarlikId],$B36,tblProsesler[USL_birim])-SUMIF(tblProsesler[VarlikId],$B36,tblProsesler[LSL_birim]))/(spy_altiSigma*$H36),0)) | J36: =IF(OR($A36="",$H36=0),"",IFERROR(MIN((SUMIF(tblProsesler[VarlikId],$B36,tblProsesler[USL_birim])-$D36)/(spy_ucSigma*$H36),($D36-SUMIF(tblProsesler[VarlikId],$B36,tblProsesler[LSL_birim]))/(spy_ucSigma*$H36)),0)) | K36: =IF($A36="","",IFERROR(AVERAGEIF(tblOlcum[VarlikId],$B36,tblOlcum[Xbar_birim])+spy_A2*$E36,0)) | L36: =IF($A36="","",IFERROR(AVERAGEIF(tblOlcum[VarlikId],$B36,tblOlcum[Xbar_birim])-spy_A2*$E36,0)) | M36: =IF($A36="","",MAX(0,MIN(100,spy_kaliteTaban-IF($J36<spy_esikCpk,spy_kaliteCeza,0)-IF(OR($D36>$K36,$D36<$L36),spy_kaliteSapma,0)-IF($P36="YETIM",spy_kaliteCeza,0)))) | N36: =IF($A36="","",IF(OR($J36<spy_esikCpk,$D36>$K36,$D36<$L36,$M36<spy_esikSaglik),"ALARM","UYGUN")) | O36: =IF($A36="","",1) | P36: =IF($A36="","",IF(OR($B36="",COUNTIF(tblProsesler[VarlikId],$B36)=0),"YETIM","TAMAM"))
A37: OLC-00032 | B37: PRS-00008 | C37: 46149 | D37: 20.16 | E37: 0.672 | F37: 5 | G37: HAFTASONU | H37: =IF(OR($A37="",$E37=0),"",$E37/spy_d2) | I37: =IF(OR($A37="",$H37=0),"",IFERROR((SUMIF(tblProsesler[VarlikId],$B37,tblProsesler[USL_birim])-SUMIF(tblProsesler[VarlikId],$B37,tblProsesler[LSL_birim]))/(spy_altiSigma*$H37),0)) | J37: =IF(OR($A37="",$H37=0),"",IFERROR(MIN((SUMIF(tblProsesler[VarlikId],$B37,tblProsesler[USL_birim])-$D37)/(spy_ucSigma*$H37),($D37-SUMIF(tblProsesler[VarlikId],$B37,tblProsesler[LSL_birim]))/(spy_ucSigma*$H37)),0)) | K37: =IF($A37="","",IFERROR(AVERAGEIF(tblOlcum[VarlikId],$B37,tblOlcum[Xbar_birim])+spy_A2*$E37,0)) | L37: =IF($A37="","",IFERROR(AVERAGEIF(tblOlcum[VarlikId],$B37,tblOlcum[Xbar_birim])-spy_A2*$E37,0)) | M37: =IF($A37="","",MAX(0,MIN(100,spy_kaliteTaban-IF($J37<spy_esikCpk,spy_kaliteCeza,0)-IF(OR($D37>$K37,$D37<$L37),spy_kaliteSapma,0)-IF($P37="YETIM",spy_kaliteCeza,0)))) | N37: =IF($A37="","",IF(OR($J37<spy_esikCpk,$D37>$K37,$D37<$L37,$M37<spy_esikSaglik),"ALARM","UYGUN")) | O37: =IF($A37="","",1) | P37: =IF($A37="","",IF(OR($B37="",COUNTIF(tblProsesler[VarlikId],$B37)=0),"YETIM","TAMAM"))
A38: OLC-00033 | B38: PRS-99999 | C38: 46146 | D38: 10.016 | E38: 0.0512 | F38: 5 | G38: FAZLA_MESAI | H38: =IF(OR($A38="",$E38=0),"",$E38/spy_d2) | I38: =IF(OR($A38="",$H38=0),"",IFERROR((SUMIF(tblProsesler[VarlikId],$B38,tblProsesler[USL_birim])-SUMIF(tblProsesler[VarlikId],$B38,tblProsesler[LSL_birim]))/(spy_altiSigma*$H38),0)) | J38: =IF(OR($A38="",$H38=0),"",IFERROR(MIN((SUMIF(tblProsesler[VarlikId],$B38,tblProsesler[USL_birim])-$D38)/(spy_ucSigma*$H38),($D38-SUMIF(tblProsesler[VarlikId],$B38,tblProsesler[LSL_birim]))/(spy_ucSigma*$H38)),0)) | K38: =IF($A38="","",IFERROR(AVERAGEIF(tblOlcum[VarlikId],$B38,tblOlcum[Xbar_birim])+spy_A2*$E38,0)) | L38: =IF($A38="","",IFERROR(AVERAGEIF(tblOlcum[VarlikId],$B38,tblOlcum[Xbar_birim])-spy_A2*$E38,0)) | M38: =IF($A38="","",MAX(0,MIN(100,spy_kaliteTaban-IF($J38<spy_esikCpk,spy_kaliteCeza,0)-IF(OR($D38>$K38,$D38<$L38),spy_kaliteSapma,0)-IF($P38="YETIM",spy_kaliteCeza,0)))) | N38: =IF($A38="","",IF(OR($J38<spy_esikCpk,$D38>$K38,$D38<$L38,$M38<spy_esikSaglik),"ALARM","UYGUN")) | O38: =IF($A38="","",1) | P38: =IF($A38="","",IF(OR($B38="",COUNTIF(tblProsesler[VarlikId],$B38)=0),"YETIM","TAMAM"))
A39: OLC-00034 | B39: PRS-00002 | C39: 46143 | D39: 6.012 | E39: 0.0344 | F39: 5 | G39: NUMUNE | H39: =IF(OR($A39="",$E39=0),"",$E39/spy_d2) | I39: =IF(OR($A39="",$H39=0),"",IFERROR((SUMIF(tblProsesler[VarlikId],$B39,tblProsesler[USL_birim])-SUMIF(tblProsesler[VarlikId],$B39,tblProsesler[LSL_birim]))/(spy_altiSigma*$H39),0)) | J39: =IF(OR($A39="",$H39=0),"",IFERROR(MIN((SUMIF(tblProsesler[VarlikId],$B39,tblProsesler[USL_birim])-$D39)/(spy_ucSigma*$H39),($D39-SUMIF(tblProsesler[VarlikId],$B39,tblProsesler[LSL_birim]))/(spy_ucSigma*$H39)),0)) | K39: =IF($A39="","",IFERROR(AVERAGEIF(tblOlcum[VarlikId],$B39,tblOlcum[Xbar_birim])+spy_A2*$E39,0)) | L39: =IF($A39="","",IFERROR(AVERAGEIF(tblOlcum[VarlikId],$B39,tblOlcum[Xbar_birim])-spy_A2*$E39,0)) | M39: =IF($A39="","",MAX(0,MIN(100,spy_kaliteTaban-IF($J39<spy_esikCpk,spy_kaliteCeza,0)-IF(OR($D39>$K39,$D39<$L39),spy_kaliteSapma,0)-IF($P39="YETIM",spy_kaliteCeza,0)))) | N39: =IF($A39="","",IF(OR($J39<spy_esikCpk,$D39>$K39,$D39<$L39,$M39<spy_esikSaglik),"ALARM","UYGUN")) | O39: =IF($A39="","",1) | P39: =IF($A39="","",IF(OR($B39="",COUNTIF(tblProsesler[VarlikId],$B39)=0),"YETIM","TAMAM"))
A40: OLC-00035 | B40: PRS-00003 | C40: 46140 | D40: 0.656 | E40: 0.4128 | F40: 5 | G40: DIGER | H40: =IF(OR($A40="",$E40=0),"",$E40/spy_d2) | I40: =IF(OR($A40="",$H40=0),"",IFERROR((SUMIF(tblProsesler[VarlikId],$B40,tblProsesler[USL_birim])-SUMIF(tblProsesler[VarlikId],$B40,tblProsesler[LSL_birim]))/(spy_altiSigma*$H40),0)) | J40: =IF(OR($A40="",$H40=0),"",IFERROR(MIN((SUMIF(tblProsesler[VarlikId],$B40,tblProsesler[USL_birim])-$D40)/(spy_ucSigma*$H40),($D40-SUMIF(tblProsesler[VarlikId],$B40,tblProsesler[LSL_birim]))/(spy_ucSigma*$H40)),0)) | K40: =IF($A40="","",IFERROR(AVERAGEIF(tblOlcum[VarlikId],$B40,tblOlcum[Xbar_birim])+spy_A2*$E40,0)) | L40: =IF($A40="","",IFERROR(AVERAGEIF(tblOlcum[VarlikId],$B40,tblOlcum[Xbar_birim])-spy_A2*$E40,0)) | M40: =IF($A40="","",MAX(0,MIN(100,spy_kaliteTaban-IF($J40<spy_esikCpk,spy_kaliteCeza,0)-IF(OR($D40>$K40,$D40<$L40),spy_kaliteSapma,0)-IF($P40="YETIM",spy_kaliteCeza,0)))) | N40: =IF($A40="","",IF(OR($J40<spy_esikCpk,$D40>$K40,$D40<$L40,$M40<spy_esikSaglik),"ALARM","UYGUN")) | O40: =IF($A40="","",1) | P40: =IF($A40="","",IF(OR($B40="",COUNTIF(tblProsesler[VarlikId],$B40)=0),"YETIM","TAMAM"))
A41: OLC-00036 | B41: PRS-00004 | C41: 46137 | D41: 1.992 | E41: 0.0256 | F41: 5 | G41: GUNDUZ | H41: =IF(OR($A41="",$E41=0),"",$E41/spy_d2) | I41: =IF(OR($A41="",$H41=0),"",IFERROR((SUMIF(tblProsesler[VarlikId],$B41,tblProsesler[USL_birim])-SUMIF(tblProsesler[VarlikId],$B41,tblProsesler[LSL_birim]))/(spy_altiSigma*$H41),0)) | J41: =IF(OR($A41="",$H41=0),"",IFERROR(MIN((SUMIF(tblProsesler[VarlikId],$B41,tblProsesler[USL_birim])-$D41)/(spy_ucSigma*$H41),($D41-SUMIF(tblProsesler[VarlikId],$B41,tblProsesler[LSL_birim]))/(spy_ucSigma*$H41)),0)) | K41: =IF($A41="","",IFERROR(AVERAGEIF(tblOlcum[VarlikId],$B41,tblOlcum[Xbar_birim])+spy_A2*$E41,0)) | L41: =IF($A41="","",IFERROR(AVERAGEIF(tblOlcum[VarlikId],$B41,tblOlcum[Xbar_birim])-spy_A2*$E41,0)) | M41: =IF($A41="","",MAX(0,MIN(100,spy_kaliteTaban-IF($J41<spy_esikCpk,spy_kaliteCeza,0)-IF(OR($D41>$K41,$D41<$L41),spy_kaliteSapma,0)-IF($P41="YETIM",spy_kaliteCeza,0)))) | N41: =IF($A41="","",IF(OR($J41<spy_esikCpk,$D41>$K41,$D41<$L41,$M41<spy_esikSaglik),"ALARM","UYGUN")) | O41: =IF($A41="","",1) | P41: =IF($A41="","",IF(OR($B41="",COUNTIF(tblProsesler[VarlikId],$B41)=0),"YETIM","TAMAM"))
H42: =IF(OR($A42="",$E42=0),"",$E42/spy_d2) | I42: =IF(OR($A42="",$H42=0),"",IFERROR((SUMIF(tblProsesler[VarlikId],$B42,tblProsesler[USL_birim])-SUMIF(tblProsesler[VarlikId],$B42,tblProsesler[LSL_birim]))/(spy_altiSigma*$H42),0)) | J42: =IF(OR($A42="",$H42=0),"",IFERROR(MIN((SUMIF(tblProsesler[VarlikId],$B42,tblProsesler[USL_birim])-$D42)/(spy_ucSigma*$H42),($D42-SUMIF(tblProsesler[VarlikId],$B42,tblProsesler[LSL_birim]))/(spy_ucSigma*$H42)),0)) | K42: =IF($A42="","",IFERROR(AVERAGEIF(tblOlcum[VarlikId],$B42,tblOlcum[Xbar_birim])+spy_A2*$E42,0)) | L42: =IF($A42="","",IFERROR(AVERAGEIF(tblOlcum[VarlikId],$B42,tblOlcum[Xbar_birim])-spy_A2*$E42,0)) | M42: =IF($A42="","",MAX(0,MIN(100,spy_kaliteTaban-IF($J42<spy_esikCpk,spy_kaliteCeza,0)-IF(OR($D42>$K42,$D42<$L42),spy_kaliteSapma,0)-IF($P42="YETIM",spy_kaliteCeza,0)))) | N42: =IF($A42="","",IF(OR($J42<spy_esikCpk,$D42>$K42,$D42<$L42,$M42<spy_esikSaglik),"ALARM","UYGUN")) | O42: =IF($A42="","",1) | P42: =IF($A42="","",IF(OR($B42="",COUNTIF(tblProsesler[VarlikId],$B42)=0),"YETIM","TAMAM"))
H43: =IF(OR($A43="",$E43=0),"",$E43/spy_d2) | I43: =IF(OR($A43="",$H43=0),"",IFERROR((SUMIF(tblProsesler[VarlikId],$B43,tblProsesler[USL_birim])-SUMIF(tblProsesler[VarlikId],$B43,tblProsesler[LSL_birim]))/(spy_altiSigma*$H43),0)) | J43: =IF(OR($A43="",$H43=0),"",IFERROR(MIN((SUMIF(tblProsesler[VarlikId],$B43,tblProsesler[USL_birim])-$D43)/(spy_ucSigma*$H43),($D43-SUMIF(tblProsesler[VarlikId],$B43,tblProsesler[LSL_birim]))/(spy_ucSigma*$H43)),0)) | K43: =IF($A43="","",IFERROR(AVERAGEIF(tblOlcum[VarlikId],$B43,tblOlcum[Xbar_birim])+spy_A2*$E43,0)) | L43: =IF($A43="","",IFERROR(AVERAGEIF(tblOlcum[VarlikId],$B43,tblOlcum[Xbar_birim])-spy_A2*$E43,0)) | M43: =IF($A43="","",MAX(0,MIN(100,spy_kaliteTaban-IF($J43<spy_esikCpk,spy_kaliteCeza,0)-IF(OR($D43>$K43,$D43<$L43),spy_kaliteSapma,0)-IF($P43="YETIM",spy_kaliteCeza,0)))) | N43: =IF($A43="","",IF(OR($J43<spy_esikCpk,$D43>$K43,$D43<$L43,$M43<spy_esikSaglik),"ALARM","UYGUN")) | O43: =IF($A43="","",1) | P43: =IF($A43="","",IF(OR($B43="",COUNTIF(tblProsesler[VarlikId],$B43)=0),"YETIM","TAMAM"))
H44: =IF(OR($A44="",$E44=0),"",$E44/spy_d2) | I44: =IF(OR($A44="",$H44=0),"",IFERROR((SUMIF(tblProsesler[VarlikId],$B44,tblProsesler[USL_birim])-SUMIF(tblProsesler[VarlikId],$B44,tblProsesler[LSL_birim]))/(spy_altiSigma*$H44),0)) | J44: =IF(OR($A44="",$H44=0),"",IFERROR(MIN((SUMIF(tblProsesler[VarlikId],$B44,tblProsesler[USL_birim])-$D44)/(spy_ucSigma*$H44),($D44-SUMIF(tblProsesler[VarlikId],$B44,tblProsesler[LSL_birim]))/(spy_ucSigma*$H44)),0)) | K44: =IF($A44="","",IFERROR(AVERAGEIF(tblOlcum[VarlikId],$B44,tblOlcum[Xbar_birim])+spy_A2*$E44,0)) | L44: =IF($A44="","",IFERROR(AVERAGEIF(tblOlcum[VarlikId],$B44,tblOlcum[Xbar_birim])-spy_A2*$E44,0)) | M44: =IF($A44="","",MAX(0,MIN(100,spy_kaliteTaban-IF($J44<spy_esikCpk,spy_kaliteCeza,0)-IF(OR($D44>$K44,$D44<$L44),spy_kaliteSapma,0)-IF($P44="YETIM",spy_kaliteCeza,0)))) | N44: =IF($A44="","",IF(OR($J44<spy_esikCpk,$D44>$K44,$D44<$L44,$M44<spy_esikSaglik),"ALARM","UYGUN")) | O44: =IF($A44="","",1) | P44: =IF($A44="","",IF(OR($B44="",COUNTIF(tblProsesler[VarlikId],$B44)=0),"YETIM","TAMAM"))
H45: =IF(OR($A45="",$E45=0),"",$E45/spy_d2) | I45: =IF(OR($A45="",$H45=0),"",IFERROR((SUMIF(tblProsesler[VarlikId],$B45,tblProsesler[USL_birim])-SUMIF(tblProsesler[VarlikId],$B45,tblProsesler[LSL_birim]))/(spy_altiSigma*$H45),0)) | J45: =IF(OR($A45="",$H45=0),"",IFERROR(MIN((SUMIF(tblProsesler[VarlikId],$B45,tblProsesler[USL_birim])-$D45)/(spy_ucSigma*$H45),($D45-SUMIF(tblProsesler[VarlikId],$B45,tblProsesler[LSL_birim]))/(spy_ucSigma*$H45)),0)) | K45: =IF($A45="","",IFERROR(AVERAGEIF(tblOlcum[VarlikId],$B45,tblOlcum[Xbar_birim])+spy_A2*$E45,0)) | L45: =IF($A45="","",IFERROR(AVERAGEIF(tblOlcum[VarlikId],$B45,tblOlcum[Xbar_birim])-spy_A2*$E45,0)) | M45: =IF($A45="","",MAX(0,MIN(100,spy_kaliteTaban-IF($J45<spy_esikCpk,spy_kaliteCeza,0)-IF(OR($D45>$K45,$D45<$L45),spy_kaliteSapma,0)-IF($P45="YETIM",spy_kaliteCeza,0)))) | N45: =IF($A45="","",IF(OR($J45<spy_esikCpk,$D45>$K45,$D45<$L45,$M45<spy_esikSaglik),"ALARM","UYGUN")) | O45: =IF($A45="","",1) | P45: =IF($A45="","",IF(OR($B45="",COUNTIF(tblProsesler[VarlikId],$B45)=0),"YETIM","TAMAM"))
H46: =IF(OR($A46="",$E46=0),"",$E46/spy_d2) | I46: =IF(OR($A46="",$H46=0),"",IFERROR((SUMIF(tblProsesler[VarlikId],$B46,tblProsesler[USL_birim])-SUMIF(tblProsesler[VarlikId],$B46,tblProsesler[LSL_birim]))/(spy_altiSigma*$H46),0)) | J46: =IF(OR($A46="",$H46=0),"",IFERROR(MIN((SUMIF(tblProsesler[VarlikId],$B46,tblProsesler[USL_birim])-$D46)/(spy_ucSigma*$H46),($D46-SUMIF(tblProsesler[VarlikId],$B46,tblProsesler[LSL_birim]))/(spy_ucSigma*$H46)),0)) | K46: =IF($A46="","",IFERROR(AVERAGEIF(tblOlcum[VarlikId],$B46,tblOlcum[Xbar_birim])+spy_A2*$E46,0)) | L46: =IF($A46="","",IFERROR(AVERAGEIF(tblOlcum[VarlikId],$B46,tblOlcum[Xbar_birim])-spy_A2*$E46,0)) | M46: =IF($A46="","",MAX(0,MIN(100,spy_kaliteTaban-IF($J46<spy_esikCpk,spy_kaliteCeza,0)-IF(OR($D46>$K46,$D46<$L46),spy_kaliteSapma,0)-IF($P46="YETIM",spy_kaliteCeza,0)))) | N46: =IF($A46="","",IF(OR($J46<spy_esikCpk,$D46>$K46,$D46<$L46,$M46<spy_esikSaglik),"ALARM","UYGUN")) | O46: =IF($A46="","",1) | P46: =IF($A46="","",IF(OR($B46="",COUNTIF(tblProsesler[VarlikId],$B46)=0),"YETIM","TAMAM"))
H47: =IF(OR($A47="",$E47=0),"",$E47/spy_d2) | I47: =IF(OR($A47="",$H47=0),"",IFERROR((SUMIF(tblProsesler[VarlikId],$B47,tblProsesler[USL_birim])-SUMIF(tblProsesler[VarlikId],$B47,tblProsesler[LSL_birim]))/(spy_altiSigma*$H47),0)) | J47: =IF(OR($A47="",$H47=0),"",IFERROR(MIN((SUMIF(tblProsesler[VarlikId],$B47,tblProsesler[USL_birim])-$D47)/(spy_ucSigma*$H47),($D47-SUMIF(tblProsesler[VarlikId],$B47,tblProsesler[LSL_birim]))/(spy_ucSigma*$H47)),0)) | K47: =IF($A47="","",IFERROR(AVERAGEIF(tblOlcum[VarlikId],$B47,tblOlcum[Xbar_birim])+spy_A2*$E47,0)) | L47: =IF($A47="","",IFERROR(AVERAGEIF(tblOlcum[VarlikId],$B47,tblOlcum[Xbar_birim])-spy_A2*$E47,0)) | M47: =IF($A47="","",MAX(0,MIN(100,spy_kaliteTaban-IF($J47<spy_esikCpk,spy_kaliteCeza,0)-IF(OR($D47>$K47,$D47<$L47),spy_kaliteSapma,0)-IF($P47="YETIM",spy_kaliteCeza,0)))) | N47: =IF($A47="","",IF(OR($J47<spy_esikCpk,$D47>$K47,$D47<$L47,$M47<spy_esikSaglik),"ALARM","UYGUN")) | O47: =IF($A47="","",1) | P47: =IF($A47="","",IF(OR($B47="",COUNTIF(tblProsesler[VarlikId],$B47)=0),"YETIM","TAMAM"))
H48: =IF(OR($A48="",$E48=0),"",$E48/spy_d2) | I48: =IF(OR($A48="",$H48=0),"",IFERROR((SUMIF(tblProsesler[VarlikId],$B48,tblProsesler[USL_birim])-SUMIF(tblProsesler[VarlikId],$B48,tblProsesler[LSL_birim]))/(spy_altiSigma*$H48),0)) | J48: =IF(OR($A48="",$H48=0),"",IFERROR(MIN((SUMIF(tblProsesler[VarlikId],$B48,tblProsesler[USL_birim])-$D48)/(spy_ucSigma*$H48),($D48-SUMIF(tblProsesler[VarlikId],$B48,tblProsesler[LSL_birim]))/(spy_ucSigma*$H48)),0)) | K48: =IF($A48="","",IFERROR(AVERAGEIF(tblOlcum[VarlikId],$B48,tblOlcum[Xbar_birim])+spy_A2*$E48,0)) | L48: =IF($A48="","",IFERROR(AVERAGEIF(tblOlcum[VarlikId],$B48,tblOlcum[Xbar_birim])-spy_A2*$E48,0)) | M48: =IF($A48="","",MAX(0,MIN(100,spy_kaliteTaban-IF($J48<spy_esikCpk,spy_kaliteCeza,0)-IF(OR($D48>$K48,$D48<$L48),spy_kaliteSapma,0)-IF($P48="YETIM",spy_kaliteCeza,0)))) | N48: =IF($A48="","",IF(OR($J48<spy_esikCpk,$D48>$K48,$D48<$L48,$M48<spy_esikSaglik),"ALARM","UYGUN")) | O48: =IF($A48="","",1) | P48: =IF($A48="","",IF(OR($B48="",COUNTIF(tblProsesler[VarlikId],$B48)=0),"YETIM","TAMAM"))
H49: =IF(OR($A49="",$E49=0),"",$E49/spy_d2) | I49: =IF(OR($A49="",$H49=0),"",IFERROR((SUMIF(tblProsesler[VarlikId],$B49,tblProsesler[USL_birim])-SUMIF(tblProsesler[VarlikId],$B49,tblProsesler[LSL_birim]))/(spy_altiSigma*$H49),0)) | J49: =IF(OR($A49="",$H49=0),"",IFERROR(MIN((SUMIF(tblProsesler[VarlikId],$B49,tblProsesler[USL_birim])-$D49)/(spy_ucSigma*$H49),($D49-SUMIF(tblProsesler[VarlikId],$B49,tblProsesler[LSL_birim]))/(spy_ucSigma*$H49)),0)) | K49: =IF($A49="","",IFERROR(AVERAGEIF(tblOlcum[VarlikId],$B49,tblOlcum[Xbar_birim])+spy_A2*$E49,0)) | L49: =IF($A49="","",IFERROR(AVERAGEIF(tblOlcum[VarlikId],$B49,tblOlcum[Xbar_birim])-spy_A2*$E49,0)) | M49: =IF($A49="","",MAX(0,MIN(100,spy_kaliteTaban-IF($J49<spy_esikCpk,spy_kaliteCeza,0)-IF(OR($D49>$K49,$D49<$L49),spy_kaliteSapma,0)-IF($P49="YETIM",spy_kaliteCeza,0)))) | N49: =IF($A49="","",IF(OR($J49<spy_esikCpk,$D49>$K49,$D49<$L49,$M49<spy_esikSaglik),"ALARM","UYGUN")) | O49: =IF($A49="","",1) | P49: =IF($A49="","",IF(OR($B49="",COUNTIF(tblProsesler[VarlikId],$B49)=0),"YETIM","TAMAM"))
H50: =IF(OR($A50="",$E50=0),"",$E50/spy_d2) | I50: =IF(OR($A50="",$H50=0),"",IFERROR((SUMIF(tblProsesler[VarlikId],$B50,tblProsesler[USL_birim])-SUMIF(tblProsesler[VarlikId],$B50,tblProsesler[LSL_birim]))/(spy_altiSigma*$H50),0)) | J50: =IF(OR($A50="",$H50=0),"",IFERROR(MIN((SUMIF(tblProsesler[VarlikId],$B50,tblProsesler[USL_birim])-$D50)/(spy_ucSigma*$H50),($D50-SUMIF(tblProsesler[VarlikId],$B50,tblProsesler[LSL_birim]))/(spy_ucSigma*$H50)),0)) | K50: =IF($A50="","",IFERROR(AVERAGEIF(tblOlcum[VarlikId],$B50,tblOlcum[Xbar_birim])+spy_A2*$E50,0)) | L50: =IF($A50="","",IFERROR(AVERAGEIF(tblOlcum[VarlikId],$B50,tblOlcum[Xbar_birim])-spy_A2*$E50,0)) | M50: =IF($A50="","",MAX(0,MIN(100,spy_kaliteTaban-IF($J50<spy_esikCpk,spy_kaliteCeza,0)-IF(OR($D50>$K50,$D50<$L50),spy_kaliteSapma,0)-IF($P50="YETIM",spy_kaliteCeza,0)))) | N50: =IF($A50="","",IF(OR($J50<spy_esikCpk,$D50>$K50,$D50<$L50,$M50<spy_esikSaglik),"ALARM","UYGUN")) | O50: =IF($A50="","",1) | P50: =IF($A50="","",IF(OR($B50="",COUNTIF(tblProsesler[VarlikId],$B50)=0),"YETIM","TAMAM"))
H51: =IF(OR($A51="",$E51=0),"",$E51/spy_d2) | I51: =IF(OR($A51="",$H51=0),"",IFERROR((SUMIF(tblProsesler[VarlikId],$B51,tblProsesler[USL_birim])-SUMIF(tblProsesler[VarlikId],$B51,tblProsesler[LSL_birim]))/(spy_altiSigma*$H51),0)) | J51: =IF(OR($A51="",$H51=0),"",IFERROR(MIN((SUMIF(tblProsesler[VarlikId],$B51,tblProsesler[USL_birim])-$D51)/(spy_ucSigma*$H51),($D51-SUMIF(tblProsesler[VarlikId],$B51,tblProsesler[LSL_birim]))/(spy_ucSigma*$H51)),0)) | K51: =IF($A51="","",IFERROR(AVERAGEIF(tblOlcum[VarlikId],$B51,tblOlcum[Xbar_birim])+spy_A2*$E51,0)) | L51: =IF($A51="","",IFERROR(AVERAGEIF(tblOlcum[VarlikId],$B51,tblOlcum[Xbar_birim])-spy_A2*$E51,0)) | M51: =IF($A51="","",MAX(0,MIN(100,spy_kaliteTaban-IF($J51<spy_esikCpk,spy_kaliteCeza,0)-IF(OR($D51>$K51,$D51<$L51),spy_kaliteSapma,0)-IF($P51="YETIM",spy_kaliteCeza,0)))) | N51: =IF($A51="","",IF(OR($J51<spy_esikCpk,$D51>$K51,$D51<$L51,$M51<spy_esikSaglik),"ALARM","UYGUN")) | O51: =IF($A51="","",1) | P51: =IF($A51="","",IF(OR($B51="",COUNTIF(tblProsesler[VarlikId],$B51)=0),"YETIM","TAMAM"))
H52: =IF(OR($A52="",$E52=0),"",$E52/spy_d2) | I52: =IF(OR($A52="",$H52=0),"",IFERROR((SUMIF(tblProsesler[VarlikId],$B52,tblProsesler[USL_birim])-SUMIF(tblProsesler[VarlikId],$B52,tblProsesler[LSL_birim]))/(spy_altiSigma*$H52),0)) | J52: =IF(OR($A52="",$H52=0),"",IFERROR(MIN((SUMIF(tblProsesler[VarlikId],$B52,tblProsesler[USL_birim])-$D52)/(spy_ucSigma*$H52),($D52-SUMIF(tblProsesler[VarlikId],$B52,tblProsesler[LSL_birim]))/(spy_ucSigma*$H52)),0)) | K52: =IF($A52="","",IFERROR(AVERAGEIF(tblOlcum[VarlikId],$B52,tblOlcum[Xbar_birim])+spy_A2*$E52,0)) | L52: =IF($A52="","",IFERROR(AVERAGEIF(tblOlcum[VarlikId],$B52,tblOlcum[Xbar_birim])-spy_A2*$E52,0)) | M52: =IF($A52="","",MAX(0,MIN(100,spy_kaliteTaban-IF($J52<spy_esikCpk,spy_kaliteCeza,0)-IF(OR($D52>$K52,$D52<$L52),spy_kaliteSapma,0)-IF($P52="YETIM",spy_kaliteCeza,0)))) | N52: =IF($A52="","",IF(OR($J52<spy_esikCpk,$D52>$K52,$D52<$L52,$M52<spy_esikSaglik),"ALARM","UYGUN")) | O52: =IF($A52="","",1) | P52: =IF($A52="","",IF(OR($B52="",COUNTIF(tblProsesler[VarlikId],$B52)=0),"YETIM","TAMAM"))
H53: =IF(OR($A53="",$E53=0),"",$E53/spy_d2) | I53: =IF(OR($A53="",$H53=0),"",IFERROR((SUMIF(tblProsesler[VarlikId],$B53,tblProsesler[USL_birim])-SUMIF(tblProsesler[VarlikId],$B53,tblProsesler[LSL_birim]))/(spy_altiSigma*$H53),0)) | J53: =IF(OR($A53="",$H53=0),"",IFERROR(MIN((SUMIF(tblProsesler[VarlikId],$B53,tblProsesler[USL_birim])-$D53)/(spy_ucSigma*$H53),($D53-SUMIF(tblProsesler[VarlikId],$B53,tblProsesler[LSL_birim]))/(spy_ucSigma*$H53)),0)) | K53: =IF($A53="","",IFERROR(AVERAGEIF(tblOlcum[VarlikId],$B53,tblOlcum[Xbar_birim])+spy_A2*$E53,0)) | L53: =IF($A53="","",IFERROR(AVERAGEIF(tblOlcum[VarlikId],$B53,tblOlcum[Xbar_birim])-spy_A2*$E53,0)) | M53: =IF($A53="","",MAX(0,MIN(100,spy_kaliteTaban-IF($J53<spy_esikCpk,spy_kaliteCeza,0)-IF(OR($D53>$K53,$D53<$L53),spy_kaliteSapma,0)-IF($P53="YETIM",spy_kaliteCeza,0)))) | N53: =IF($A53="","",IF(OR($J53<spy_esikCpk,$D53>$K53,$D53<$L53,$M53<spy_esikSaglik),"ALARM","UYGUN")) | O53: =IF($A53="","",1) | P53: =IF($A53="","",IF(OR($B53="",COUNTIF(tblProsesler[VarlikId],$B53)=0),"YETIM","TAMAM"))
... H255: =IF(OR($A255="",$E255=0),"",$E255/spy_d2) | I255: =IF(OR($A255="",$H255=0),"",IFERROR((SUMIF(tblProsesler[VarlikId],$B255,tblProsesler[USL_birim])-SUMIF(tblProsesler[VarlikId],$B255,tblProsesler[LSL_birim]))/(spy_altiSigma*$H255),0)) | J255: =IF(OR($A255="",$H255=0),"",IFERROR(MIN((SUMIF(tblProsesler[VarlikId],$B255,tblProsesler[USL_birim])-$D255)/(spy_ucSigma*$H255),($D255-SUMIF(tblProsesler[VarlikId],$B255,tblProsesler[LSL_birim]))/(spy_ucSigma*$H255)),0)) | K255: =IF($A255="","",IFERROR(AVERAGEIF(tblOlcum[VarlikId],$B255,tblOlcum[Xbar_birim])+spy_A2*$E255,0)) | L255: =IF($A255="","",IFERROR(AVERAGEIF(tblOlcum[VarlikId],$B255,tblOlcum[Xbar_birim])-spy_A2*$E255,0)) | M255: =IF($A255="","",MAX(0,MIN(100,spy_kaliteTaban-IF($J255<spy_esikCpk,spy_kaliteCeza,0)-IF(OR($D255>$K255,$D255<$L255),spy_kaliteSapma,0)-IF($P255="YETIM",spy_kaliteCeza,0)))) | N255: =IF($A255="","",IF(OR($J255<spy_esikCpk,$D255>$K255,$D255<$L255,$M255<spy_esikSaglik),"ALARM","UYGUN")) | O255: =IF($A255="","",1) | P255: =IF($A255="","",IF(OR($B255="",COUNTIF(tblProsesler[VarlikId],$B255)=0),"YETIM","TAMAM"))

Sheet DONEM_ANALIZ
A1: DONEM ANALIZ — SPC Proses Yetenek Analizi
A3: 12 aylık sezonsallık — Cp/Cpk zinciri (S03)
A5: Ay | B5: Ay_Anahtari | C5: Olcum Adet | D5: Ort Cpk | E5: Ort Cp | F5: Sezonsal Etiket
A6: Ocak | B6: Ay_1 | C6: 28 | D6: 1.22 | E6: 1.35 | F6: 12_AY_SEZONSAL
A7: Subat | B7: Ay_2 | C7: 30 | D7: 1.18 | E7: 1.3 | F7: 12_AY_SEZONSAL
A8: Mart | B8: Ay_3 | C8: 32 | D8: 1.25 | E8: 1.38 | F8: 12_AY_SEZONSAL
A9: Nisan | B9: Ay_4 | C9: 35 | D9: 1.3 | E9: 1.42 | F9: 12_AY_SEZONSAL
A10: Mayis | B10: Ay_5 | C10: 38 | D10: 1.28 | E10: 1.4 | F10: 12_AY_SEZONSAL
A11: Haziran | B11: Ay_6 | C11: 40 | D11: 1.35 | E11: 1.48 | F11: 12_AY_SEZONSAL
A12: Temmuz | B12: Ay_7 | C12: 42 | D12: 1.4 | E12: 1.52 | F12: 12_AY_SEZONSAL
A13: Agustos | B13: Ay_8 | C13: 41 | D13: 1.33 | E13: 1.45 | F13: 12_AY_SEZONSAL
A14: Eylul | B14: Ay_9 | C14: 36 | D14: 1.27 | E14: 1.38 | F14: 12_AY_SEZONSAL
A15: Ekim | B15: Ay_10 | C15: 33 | D15: 1.2 | E15: 1.32 | F15: 12_AY_SEZONSAL
A16: Kasim | B16: Ay_11 | C16: 30 | D16: 1.16 | E16: 1.28 | F16: 12_AY_SEZONSAL
A17: Aralik | B17: Ay_12 | C17: 29 | D17: 1.19 | E17: 1.31 | F17: 12_AY_SEZONSAL
A20: Sezonsal Trend Özeti | B20: =spy_sezonsalTrend
A22: 12 Ay Toplam Ölçüm | B22: =SUM(C6:C17)
A23: 12 Ay Ort Cpk | B23: =IFERROR(AVERAGE(D6:D17),0)
A24: 12 Ay Ort Cp | B24: =IFERROR(AVERAGE(E6:E17),0)
A25: Canlı dönem ölçüm | B25: =spy_doluKayit
A26: Canlı dönem Cpk | B26: =spy_cpkOrt

Sheet HESAP
A1: HESAP — SPC Proses Yetenek Analizi
A3: Hesap motoru — ≥40 adım; Cp/Cpk sabitleri AYARLAR'dan
A5: Adım | B5: Açıklama | C5: Değer
A6: H01 | B6: Toplam ölçüm kayıt | C6: =COUNTA(tblOlcum[SatirId])
A7: H02 | B7: Dolu kayıt | C7: =SUM(tblOlcum[FormulKayitDolu])
A8: H03 | B8: X̄ toplam | C8: =SUM(tblOlcum[Xbar_birim])
A9: H04 | B9: R toplam | C9: =SUM(tblOlcum[R_birim])
A10: H05 | B10: Sigma ortalama | C10: =IFERROR(AVERAGEIF(tblOlcum[FormulSigma],">0"),0)
A11: H06 | B11: Cp ortalama | C11: =IFERROR(AVERAGEIF(tblOlcum[FormulCp],">0"),0)
A12: H07 | B12: Cpk ortalama | C12: =IFERROR(AVERAGEIF(tblOlcum[FormulCpk],">0"),0)
A13: H08 | B13: Min Cpk | C13: =IFERROR(MIN(tblOlcum[FormulCpk]),0)
A14: H09 | B14: Max Cpk | C14: =IFERROR(MAX(tblOlcum[FormulCpk]),0)
A15: H10 | B15: X̄ ortalama | C15: =IFERROR(AVERAGEIF(tblOlcum[Xbar_birim],">0"),0)
A16: H11 | B16: Aktif proses adet | C16: =COUNTIF(tblProsesler[Aktif],"EVET")
A17: H12 | B17: Toplam proses kart | C17: =COUNTA(tblProsesler[VarlikId])
A18: H13 | B18: Alarm adet | C18: =COUNTIF(tblOlcum[AlarmBayrak],"ALARM")
A19: H14 | B19: Yetim kayıt | C19: =COUNTIF(tblOlcum[FormulYetim],"YETIM")
A20: H15 | B20: Ortalama sağlık skor | C20: =IFERROR(AVERAGEIF(tblOlcum[SaglikSkorSatir],">0"),0)
A21: H16 | B21: Min sağlık skor | C21: =IFERROR(MIN(tblOlcum[SaglikSkorSatir]),0)
A22: H17 | B22: Cpk eşik aşımı | C22: =COUNTIFS(tblOlcum[FormulCpk],"<"&spy_esikCpk,tblOlcum[FormulKayitDolu],">0")
A23: H18 | B23: WE kontrol limiti aşımı | C23: =COUNTIFS(tblOlcum[AlarmBayrak],"ALARM",tblOlcum[FormulKayitDolu],">0")
A24: H19 | B24: Düşük sağlık adet | C24: =COUNTIFS(tblOlcum[SaglikSkorSatir],"<"&spy_esikSaglik,tblOlcum[FormulKayitDolu],">0")
A25: H20 | B25: Günlük X̄ ort | C25: =IFERROR(C15/MAX(C7,1),0)
A26: H21 | B26: Aylık Cpk proxy | C26: =C12*spy_aylikCarpan
A27: H22 | B27: Cpk sapma | C27: =IFERROR(ABS(C12-spy_esikCpk),0)
A28: H23 | B28: Cp payı proxy | C28: =IFERROR(C11/MAX(C12,0.001),0)
A29: H24 | B29: Sigma payı | C29: =IFERROR(C10/MAX(C15,0.001),0)
A30: H25 | B30: R payı | C30: =IFERROR(C9/MAX(C8,0.001),0)
A31: H26 | B31: Alarm oranı | C31: =IFERROR(C18/MAX(C7,1),0)
A32: H27 | B32: Temkinli senaryo Cpk | C32: =C12*spy_senaryoTemkinli
A33: H28 | B33: Baz senaryo Cpk | C33: =C12*spy_senaryoBaz
A34: H29 | B34: İyimser senaryo Cpk | C34: =C12*spy_senaryoIyimser
A35: H30 | B35: Senaryo farkı | C35: =C34-C32
A36: H31 | B36: Tornado LSL etki | C36: =C12*spy_tornadoOran
A37: H32 | B37: Tornado USL etki | C37: =C11*spy_tornadoOran
A38: H33 | B38: Tornado sigma etki | C38: =C10*spy_tornadoOran
A39: H34 | B39: Tornado zirve | C39: =MAX(C36,C37,C38)
A40: H35 | B40: HHI proxy | C40: =IFERROR((C11/MAX(C11+C12,0.001))^2+(C12/MAX(C11+C12,0.001))^2+(C18/MAX(C7,1))^2+(C19/MAX(C7,1))^2,0)
A41: H36 | B41: Kalite skor | C41: =MAX(0,spy_kaliteTaban-C22*spy_kaliteCeza-C23*spy_kaliteSapma-C24*spy_kaliteSapma)
A42: H37 | B42: Tahmin aralık | C42: =C33*spy_tahminCarpan
...

Sheet PANO
A1: ☰ PANO
B2: STRATEJİK YÖNETİCİ KOKPİTİ | L2: Dönem: 2026 / Tam ▼ | M2: ★ DOĞRULANMIŞ
A3: Karar panosu — Cp/Cpk + alarm + trend | B3: Yönetici Karar Kokpiti, Otomatik Doğrulama ve Dinamik Hesaplama Sistemi · 2026
A5: KARAR | B5: =spy_kararKapi
A6: Gösterge | B6: Değer
A7: Dolu Kayıt | B7: =spy_doluKayit | D7: Gerekçe | E7: =spy_kararGerekce
A8: Ort Cp | B8: =spy_cpOrt
A9: Ort Cpk | B9: =spy_cpkOrt
A10: Min Cpk | B10: =spy_cpkMin | D10: Öneri 1 | E10: =_xlfn.TEXTJOIN(" ",TRUE,"Cpk",TEXT(spy_cpkOrt,"0.000"),"— eşik",TEXT(spy_esikCpk,"0.000"))
A11: Sigma Ort | B11: =spy_sigmaOrt | D11: Öneri 2 | E11: =_xlfn.TEXTJOIN(" ",TRUE,"WE alarm",spy_alarmAdet,"adet — sağlık",TEXT(spy_saglikSkor,"0")) | F11: +%32 Verim | H11: KONSOLİDE OPERASYON VE KARAR MATRİSİ
A12: X̄ Ort | B12: =spy_xbarOrt | D12: Öneri 3 | E12: =_xlfn.TEXTJOIN(" ",TRUE,"Tornado zirve",TEXT(spy_tornadoZirve,"0.000"),"etki") | H12: Anlık Hesaplama Sonuçları ve Durum Puanlaması
A13: Aktif Proses | B13: =spy_aktifProses
A14: WE Alarm Adet | B14: =spy_alarmAdet
A15: Sağlık Skor Ort | B15: =spy_saglikSkor
A16: Yetim Kayıt | B16: =spy_yetimAdet
A17: Kalite Skor | B17: =spy_kaliteSkor
A18: Tornado Zirve | B18: =spy_tornadoZirve
A19: P90 Cpk | B19: =spy_yuzdelikP90
A20: Cpk Sapma | B20: =spy_cpkSapma
A22: Kalem | B22: Deger | D22: Senaryo | E22: Cpk | F22: LİKİDİTE RİSKİ & ERKEN UYARI SİNYALLERİ | G22: Hafta | H22: Cpk | J22: Vardiya | K22: KARAR MOTORU
A23: Cp | B23: 1.38 | D23: Temkinli | E23: 1.12 | F23: Nakit Açığı Riski (30 Gün) | G23: H1 | H23: 1.18 | I23: 0.00 TL (Sıfır Risk) | J23: GUNDUZ | K23: LİKİDİTE OPTİMİZASYON FIRSATI
A24: Cpk | B24: 1.25 | D24: Baz | E24: 1.25 | F24: Tahsilat Gecikme Toleransı | G24: H2 | H24: 1.21 | I24: 48 Gün Güvenli Eşik | J24: GECE | K24: Atıl kalan nakit rezervinin gecelik repoda
A25: Sigma | B25: 0.042 | D25: Iyimser | E25: 1.38 | F25: ██████████████████████████████ Güvenli Bölge (%100) | G25: H3 | H25: 1.24 | J25: HAFTASONU | K25: değerlendirilmesiyle ek getiri imkanı.
A26: Alarm | B26: 3 | F26: ✓ 90 GÜNLÜK PROJEKSİYONDA NAKİT SIKIŞIKLIĞI TESPİT EDİLMEDİ | G26: H4 | H26: 1.27 | J26: NUMUNE | K26: FONLAMA SENARYOSUNU İNCELE ›
G27: H5 | H27: 1.3
G28: H6 | H28: 1.33
G29: H7 | H29: 1.36
G30: H8 | H30: 1.39

Sheet ALARMLAR
A1: ALARMLAR — SPC Proses Yetenek Analizi
A3: Alarm listesi — varlık + eşik + süre (S05)
A5: Varlık | B5: Alarm | C5: Eşik | D5: Süre / Tarih | E5: Ort Cpk | F5: Sağlık Skor
A6: PRS-00001 | B6: =IF(OR(COUNTIFS(tblOlcum[VarlikId],A6,tblOlcum[AlarmBayrak],"ALARM")>0,IFERROR(SUMIF(tblProsesler[VarlikId],A6,tblProsesler[SaglikSkor]),100)<spy_esikSaglik),"ALARM","YOK") | C6: =IFERROR(ABS(E6-spy_esikCpk),0) | D6: =raporTarihi | E6: =IFERROR(SUMIF(tblProsesler[VarlikId],A6,tblProsesler[OrtCpk]),0) | F6: =IFERROR(SUMIF(tblProsesler[VarlikId],A6,tblProsesler[SaglikSkor]),0)
A7: PRS-00002 | B7: =IF(OR(COUNTIFS(tblOlcum[VarlikId],A7,tblOlcum[AlarmBayrak],"ALARM")>0,IFERROR(SUMIF(tblProsesler[VarlikId],A7,tblProsesler[SaglikSkor]),100)<spy_esikSaglik),"ALARM","YOK") | C7: =IFERROR(ABS(E7-spy_esikCpk),0) | D7: =raporTarihi | E7: =IFERROR(SUMIF(tblProsesler[VarlikId],A7,tblProsesler[OrtCpk]),0) | F7: =IFERROR(SUMIF(tblProsesler[VarlikId],A7,tblProsesler[SaglikSkor]),0)
A8: PRS-00003 | B8: =IF(OR(COUNTIFS(tblOlcum[VarlikId],A8,tblOlcum[AlarmBayrak],"ALARM")>0,IFERROR(SUMIF(tblProsesler[VarlikId],A8,tblProsesler[SaglikSkor]),100)<spy_esikSaglik),"ALARM","YOK") | C8: =IFERROR(ABS(E8-spy_esikCpk),0) | D8: =raporTarihi | E8: =IFERROR(SUMIF(tblProsesler[VarlikId],A8,tblProsesler[OrtCpk]),0) | F8: =IFERROR(SUMIF(tblProsesler[VarlikId],A8,tblProsesler[SaglikSkor]),0)
A9: PRS-00004 | B9: =IF(OR(COUNTIFS(tblOlcum[VarlikId],A9,tblOlcum[AlarmBayrak],"ALARM")>0,IFERROR(SUMIF(tblProsesler[VarlikId],A9,tblProsesler[SaglikSkor]),100)<spy_esikSaglik),"ALARM","YOK") | C9: =IFERROR(ABS(E9-spy_esikCpk),0) | D9: =raporTarihi | E9: =IFERROR(SUMIF(tblProsesler[VarlikId],A9,tblProsesler[OrtCpk]),0) | F9: =IFERROR(SUMIF(tblProsesler[VarlikId],A9,tblProsesler[SaglikSkor]),0)
A10: PRS-00005 | B10: =IF(OR(COUNTIFS(tblOlcum[VarlikId],A10,tblOlcum[AlarmBayrak],"ALARM")>0,IFERROR(SUMIF(tblProsesler[VarlikId],A10,tblProsesler[SaglikSkor]),100)<spy_esikSaglik),"ALARM","YOK") | C10: =IFERROR(ABS(E10-spy_esikCpk),0) | D10: =raporTarihi | E10: =IFERROR(SUMIF(tblProsesler[VarlikId],A10,tblProsesler[OrtCpk]),0) | F10: =IFERROR(SUMIF(tblProsesler[VarlikId],A10,tblProsesler[SaglikSkor]),0)
A11: PRS-00006 | B11: =IF(OR(COUNTIFS(tblOlcum[VarlikId],A11,tblOlcum[AlarmBayrak],"ALARM")>0,IFERROR(SUMIF(tblProsesler[VarlikId],A11,tblProsesler[SaglikSkor]),100)<spy_esikSaglik),"ALARM","YOK") | C11: =IFERROR(ABS(E11-spy_esikCpk),0) | D11: =raporTarihi | E11: =IFERROR(SUMIF(tblProsesler[VarlikId],A11,tblProsesler[OrtCpk]),0) | F11: =IFERROR(SUMIF(tblProsesler[VarlikId],A11,tblProsesler[SaglikSkor]),0)
A12: PRS-00007 | B12: =IF(OR(COUNTIFS(tblOlcum[VarlikId],A12,tblOlcum[AlarmBayrak],"ALARM")>0,IFERROR(SUMIF(tblProsesler[VarlikId],A12,tblProsesler[SaglikSkor]),100)<spy_esikSaglik),"ALARM","YOK") | C12: =IFERROR(ABS(E12-spy_esikCpk),0) | D12: =raporTarihi | E12: =IFERROR(SUMIF(tblProsesler[VarlikId],A12,tblProsesler[OrtCpk]),0) | F12: =IFERROR(SUMIF(tblProsesler[VarlikId],A12,tblProsesler[SaglikSkor]),0)
A13: PRS-00008 | B13: =IF(OR(COUNTIFS(tblOlcum[VarlikId],A13,tblOlcum[AlarmBayrak],"ALARM")>0,IFERROR(SUMIF(tblProsesler[VarlikId],A13,tblProsesler[SaglikSkor]),100)<spy_esikSaglik),"ALARM","YOK") | C13: =IFERROR(ABS(E13-spy_esikCpk),0) | D13: =raporTarihi | E13: =IFERROR(SUMIF(tblProsesler[VarlikId],A13,tblProsesler[OrtCpk]),0) | F13: =IFERROR(SUMIF(tblProsesler[VarlikId],A13,tblProsesler[SaglikSkor]),0)
A16: Alarm Özeti | B16: =spy_alarmListesi
A18: Toplam Alarm Satır | B18: =COUNTIF(B6:B13,"ALARM")

Sheet RAPOR
A1: RAPOR — SPC Proses Yetenek Analizi
A3: Dönemsel yönetim raporu — IATF/müşteri kanıt paketi
A5: Ürün | B5: SPC Proses Yetenek Analizi
A6: Sürüm | B6: 1.0.0
A7: Rapor Tarihi | B7: =raporTarihi
A8: Firma | B8: =spy_firmaUnvan
A10: KARAR | B10: =spy_kararKapi
A11: Ort Cpk | B11: =spy_cpkOrt
A12: Ort Cp | B12: =spy_cpOrt
A13: Min Cpk | B13: =spy_cpkMin
A14: Sağlık Skor | B14: =spy_saglikSkor
A15: WE Alarm Adet | B15: =spy_alarmAdet
A17: Gösterge | B17: Değer
A18: Sigma Ort | B18: =spy_sigmaOrt
A19: X̄ Ort | B19: =spy_xbarOrt
A20: Kalite Skor | B20: =spy_kaliteSkor
A21: P90 Cpk | B21: =spy_yuzdelikP90
A24: Varsayımlar
A25: d2, A2, 3σ/6σ çarpanları ve Cp/Cpk eşikleri AYARLAR'da kaynak + yürürlük tarihli. Karar destek çıktısıdır; sertifikasyon / kalite tavsiyesi değildir.
A28: İmza — Kalite Müdürü | C28: ________________
A29: İmza — Denetçi / Müşteri | C29: ________________
A31: SHA notu: sevk paketinde SHA-256 yer alır | 1.0.0

Sheet KONTROLLER
A1: KONTROLLER — SPC Proses Yetenek Analizi
A3: Canlı sağlık kontrolleri — formülle
A5: Kontrol | B5: Sonuç | C5: Değer
A6: Dolu kayıt > 0 | B6: =IF(spy_doluKayit>0,"GEÇTİ","KALDI") | C6: =spy_doluKayit
A7: Yetim kayıt = 0 | B7: =IF(spy_yetimAdet=0,"GEÇTİ","UYARI") | C7: =spy_yetimAdet
A8: Cpk hesaplı | B8: =IF(spy_cpkOrt>=0,"GEÇTİ","KALDI") | C8: =spy_cpkOrt
A9: Sağlık skor formül | B9: =IF(spy_saglikSkor>=0,"GEÇTİ","KALDI") | C9: =spy_saglikSkor
A10: Alarm listesi | B10: =IF(spy_alarmAdet>=0,"GEÇTİ","KALDI") | C10: =spy_alarmAdet
