Workbook
Name raporTarihi: AYARLAR!$B$6
Name zincirTolerans: AYARLAR!$B$7
Name isg_matrisTipi: AYARLAR!$B$8
Name isg_esikGecikmeGun: AYARLAR!$B$9
Name isg_esikGeciken: AYARLAR!$B$10
Name isg_esikKritik: AYARLAR!$B$11
Name isg_esikKritikSeviye: AYARLAR!$B$12
Name isg_esikYuksek: AYARLAR!$B$13
Name isg_esikOrta: AYARLAR!$B$14
Name isg_esikAnomali: AYARLAR!$B$15
Name isg_gecikmeOranGun: AYARLAR!$B$16
Name isg_senaryoTemkinli: AYARLAR!$B$17
Name isg_senaryoBaz: AYARLAR!$B$18
Name isg_senaryoIyimser: AYARLAR!$B$19
Name isg_tornadoOran: AYARLAR!$B$20
Name isg_yuzdelikOran: AYARLAR!$B$21
Name isg_yenilemeTarihi: AYARLAR!$B$22
Name isg_olcekHedef: AYARLAR!$B$23
Name isg_azamiSkor: AYARLAR!$B$24
Name isg_dosyaSurumu: AYARLAR!$B$25
Name isg_firmaUnvan: AYARLAR!$B$26
Name isg_puanlamaMatrisi: AYARLAR!$B$27
Name isg_eylemDurum: AYARLAR!$B$28
Name isg_kvkkBeyani: AYARLAR!$B$29
Name isg_tehlikeAdet: AYARLAR!$I$43
Name isg_kritikAdet: AYARLAR!$I$44
Name isg_ortalamaSkor: AYARLAR!$I$45
Name isg_uyumOrani: AYARLAR!$I$46
Name isg_acikAdet: AYARLAR!$I$47
Name isg_gecikenAdet: AYARLAR!$I$48
Name isg_yetimKayit: AYARLAR!$I$49
Name isg_gecersizGecis: AYARLAR!$I$50
Name isg_zincirKirik: AYARLAR!$I$51
Name isg_eylemYas: AYARLAR!$I$52
Name isg_tahminAralik: AYARLAR!$I$53
Name isg_senaryoKarsilastirma: AYARLAR!$I$54
Name isg_tornadoZirve: AYARLAR!$I$55
Name isg_eylemOncelik: AYARLAR!$I$56
Name isg_paretoKritik: AYARLAR!$I$57
Name isg_gecikmeMaliyeti: AYARLAR!$I$58
Name isg_anomaliSayisi: AYARLAR!$I$59
Name isg_skorDagilim: AYARLAR!$I$60
Name isg_kapaliDusum: AYARLAR!$I$61
Name isg_kuyrukOzeti: AYARLAR!$I$62
Name isg_maddeAtif: AYARLAR!$I$63
Name isg_yenilemeTakvim: AYARLAR!$I$64
Name isg_revizyonGecmisi: AYARLAR!$I$65
Name isg_kanitRaporu: AYARLAR!$I$66
Name isg_sonrakiKimlik: AYARLAR!$I$67
Name isg_yorumEylemYas: AYARLAR!$I$70
Name isg_yorumGecikme: AYARLAR!$I$71
Name isg_yorumTahmin: AYARLAR!$I$72
Name isg_yorumSenaryo: AYARLAR!$I$73
Name isg_yorumTornado: AYARLAR!$I$74
Name isg_yorumOncelik: AYARLAR!$I$75
Name isg_yorumPareto: AYARLAR!$I$76
Name isg_yorumAnomali: AYARLAR!$I$77
Name ListeDurumlar: LISTELER!$A$7:$A$11
Name ListeIzinliGecis: LISTELER!$C$7:$C$14
Name ListeEvetHayir: LISTELER!$E$7:$E$8

Sheet 00_BASLANGIC
A1: EXCELARŞİV KARAR SİSTEMİ v15.1 — ÜRETİM REFERANSI
A3: Konu | B3: Bağlayıcı Standart
A4: Amaç | B4: Kanıta dayalı, hatada kapalı çalışan Excel üretim ve denetim sistemi
A5: Öncelik | B5: Kullanıcının açık iş talebi ve gerçek kullanım senaryosu
A6: Ana akış | B6: Uygunluk → Yönetişim → Sözleşmeler → Üretim → Test → Kanıt → Kullanıcı Kabulü → Yayın
A7: Yayın ilkesi | B7: Üst aşamada hata varsa alt aşama GEÇTİ üretilemez
A8: Kullanıcı kabulü | B8: Excel masaüstü görünümü test edilmediyse DIŞ_KABUL_GEREKLİ
A9: Nihai yayın | B9: Yalnız uygulanabilir modüller GEÇTİ veya gerekçeli UYGULANMAZ
A10: Ticari ayrım | B10: Ekonomik olarak savunulabilir fiyat, gerçek pazar kabulü ile aynı değildir
A11: Karmaşıklık | B11: Karar değeri, eklenen karmaşıklığın maliyetinden büyük olmalıdır
A12: Excel sınırı | B12: Veritabanı, kurumsal yetkilendirme, değiştirilemez kayıt sistemi veya gerçek zamanlı olay platformu değildir
A13: Dil standardı | B13: Kullanıcıya görünen tüm sayfa, tablo, başlık, açıklama, uyarı ve karar metinleri saf Türkçe olmalıdır
A14: Muhasebe standardı | B14: Finansal ürünlerde Türkiye Tekdüzen Hesap Planı ve Türk muhasebe kullanım alışkanlıkları esas alınır
... A33: Muhasebe | B33: Türkiye Tekdüzen Hesap Planı ve Türk muhasebe/işletme düşünce yapısı esas alınır.

Sheet PANO
A1: ☰ PANO
B2: İSG RISK DEĞERLENDIRME PRO (6331) | L2: Dönem: 2026 / Tam ▼ | M2: ★ DOĞRULANMIŞ
B3: Hedef Kullanıcı: İSG uzmanı, işveren vekili, denetim hazırlığı · 2026 Q3 Denetim Standardı
B5: SENARYO | D5: KONSOLİDE | E5: EYLEM YAŞLANDIRMA | G5: KONTROL | H5: NET OPERASYONEL MARJ | J5: GÜVENLİ | K5: SİSTEM GÜVEN SKORU | M5: DENETLENDİ
B7: =GİRDİLER!E17 | E7: =B7*0.22 | H7: =B7-E7 | K7: =IF(E7>0, ROUND(B7/E7, 2), 0)
B9: ↑ %14.2 konsolide canlı veri bağlantısı | E9: ● 8 Kalem nakit karşılığı: bloke | H9: ██████████░░░░░ %78.0 NET MARJ | K9: ✓ İDEAL karşılama rasyosu
B11: İSG RISK DEĞERLENDIRME PRO (6331) — DÖNEMSEL İCRA VE PROJEKSİYON | F11: +%32 Verim | H11: KONSOLİDE OPERASYON VE KARAR MATRİSİ
B12: Kümülatif Hacim vs. Operasyonel Maliyet ve Net Kâr Eğilimi | H12: Anlık Hesaplama Sonuçları, Dinamik Formül Çıktıları ve Durum Puanlaması
B14: Dönem | C14: Aktif Hacim | D14: Maliyet/Yük | E14: Hedef | H14: PARAMETRE / KALEM | I14: ANA TUTAR | J14: FARK / MARJ | K14: VADE | L14: KONTROL DURUMU
B15: D1 | C15: 65 | D15: 45 | E15: 60 | H15: Dönemlik Kümülatif Bakiye | I15: =B7*0.45 | J15: =B7*0.05 | K15: 12 Ay | L15: ✓ DÜZENLİ
B16: D2 | C16: 78 | D16: 48 | E16: 70 | H16: Kritik Eşik Güvenlik Tamponu | I16: =B7*0.30 | J16: =B7*0.03 | K16: 24 Ay | L16: ★ AVANTAJ
B17: D3 | C17: 85 | D17: 55 | E17: 80 | H17: Operasyonel Net Fark | I17: =B7*0.15 | J17: =B7*0.02 | K17: 8 Ay | L17: ● YAKLAŞAN
B18: D4 | C18: 75 | D18: 42 | E18: 75 | H18: Rezerv ve Likit Dağılım | I18: =B7*0.10 | J18: =B7*0.01 | K18: 16 Ay | L18: ✓ TAM UYUM
B19: D5 | C19: 90 | D19: 40 | E19: 85 | H19: KONSOLİDE SİSTEM TOPLAMI | I19: =SUM(I15:I18) | J19: =SUM(J15:J18) | L19: TAM DOĞRULANDI (0 HATA)
B20: D6 | C20: 96 | D20: 32 | E20: 92
B22: KONSOLİDE PAY VE AĞIRLIK | F22: LİKİDİTE RİSKİ & ERKEN UYARI SİNYALLERİ | K22: KARAR MOTORU
B23: ■ Ana Segment (%42) | F23: Nakit Açığı Riski (30 Gün) | I23: 0.00 TL (Sıfır Risk) | K23: STRATEJİK VERİMLİLİK FIRSATI
B24: ■ İkincil Grup (%30) | F24: Tahsilat Gecikme Toleransı | I24: 48 Gün Güvenli Eşik | K24: Operasyonel süreç optimizasyonu ile kârlılık artış potansiyeli tespit edildi.
B25: ■ Destek Birimi (%15) | F25: ██████████████████████████████████████ Güvenli Bölge (%100)
B26: ■ Rezervler (%13) | F26: ✓ 90 GÜNLÜK PROJEKSİYONDA NAKİT SIKIŞIKLIĞI TESPİT EDİLMEDİ | K26: STRATEJİ REÇETESİNİ İNCELE >

Sheet GİRDİLER
A1: ☰ PANO
B3: 🔍 İSG RISK DEĞERLENDIRME PRO (6331) — Kayıt veya hesap ara... | G3: TOPLAM: 1.450 KAYIT | I3: HATALI HÜCRE: 0 ADET
B5: TARİH | C5: REFERANS NO | D5: İŞLEM AÇIKLAMASI VE DETAY | E5: BRÜT TUTAR (₺) | F5: KDV ORANI | G5: NET TUTAR (₺) | H5: HESAP / CARİ | I5: DURUM
B6: 12.10.2026 | C6: TR-0428-A | D6: Operasyonel ana kalem tahmini | E6: 845200 | F6: 0.2 | G6: =E6/(1+F6) | H6: Vadesiz Ticari | I6: ONAYLANDI
B7: 14.10.2026 | C7: TR-0429-B | D7: Operasyonel çıkış/maliyet tahmini | E7: 1240000 | F7: 0.2 | G7: =E7/(1+F7) | H7: Tedarikçi Havuzu | I7: BEKLEMEDE
B8: 18.10.2026 | C8: TR-0430-C | D8: Ödeme takvimi tahakkuku | E8: 620500 | F8: 0.1 | G8: =E8/(1+F8) | H8: Kısa Vade Tahakkuk | I8: ONAYLANDI
B9: 21.10.2026 | C9: TR-0431-D | D9: Müşteri işlem tahmini | E9: 415000 | F9: 0.2 | G9: =E9/(1+F9) | H9: Müşteri Alacağı | I9: ONAYLANDI
B10: 25.10.2026 | C10: TR-0432-E | D10: Ana operasyon tahmini | E10: 980400 | F10: 0.2 | G10: =E10/(1+F10) | H10: Vadesiz Ticari | I10: ONAYLANDI
B11: 28.10.2026 | C11: TR-0433-F | D11: Kredi/taksit karşılığı | E11: 1850000 | F11: 0.2 | G11: =E11/(1+F11) | H11: Finansman Havuzu | I11: BLOKE
B12: 02.11.2026 | C12: TR-0434-G | D12: Sabit gider ve yönetim notları | E12: 740000 | F12: 0.2 | G12: =E12/(1+F12) | H12: Genel Yönetim | I12: ONAYLANDI
B13: 05.11.2026 | C13: TR-0435-H | D13: Operasyonel ana kalem tahmini | E13: 520800 | F13: 0.2 | G13: =E13/(1+F13) | H13: Vadesiz Ticari | I13: ONAYLANDI
B14: 09.11.2026 | C14: TR-0436-I | D14: Müşteri işlem tahmini | E14: 1120000 | F14: 0.2 | G14: =E14/(1+F14) | H14: Müşteri Alacağı | I14: ONAYLANDI
B15: 12.11.2026 | C15: TR-0437-J | D15: Operasyonel çıkış tahmini | E15: 890000 | F15: 0.2 | G15: =E15/(1+F15) | H15: Tedarikçi Havuzu | I15: ONAYLANDI
B17: SAYFA TOPLAMI (10 / 1.450 KAYIT) | E17: =SUM(E6:E15)

Sheet YÖNETİM_RAPORU
A1: ☰ PANO
B2: İSG RISK DEĞERLENDIRME PRO (6331) — NİHAİ KARAR VE DEĞERLEME
B3: Yönetim Kurulu ve İcra Komitesi için Otomatik Finansal Stres Testi Raporu · İSG uzmanı, işveren vekili, denetim hazırlığı
B4: DÖNEM: 2026 Q3 · DENETİM PROTOKOLÜ: ISO/VUK/IFRS UYUMLU · DURUM: ONAYLANDI
B6: SENARYO A: KÖTÜMSER (STRES TESTİ -%20) | H6: SENARYO B: BAZ MODEL (HEDEFLENEN)
B8: Ciro / Hacim Düşüşü: | E8: -%20.0 (Kriz Eşiği) | H8: Ciro / Hacim Gerçekleşmesi: | K8: %100.0 (Tam Bütçe)
B9: Beklenen Net Kâr / Getiri: | E9: =PANO!B7*0.8*0.22 | H9: Beklenen Net Kâr / Getiri: | K9: =PANO!H7
B10: Minimum Nakit Tamponu: | E10: =PANO!E7*0.75 | H10: Serbest Nakit Akımı: | K10: =PANO!H7*0.75
B11: Likidite Karşılama Oranı: | E11: =ROUND(PANO!B7*0.8/PANO!E7, 2) | H11: Yatırım Geri Dönüşü (ROI): | K11: %38.4 Yıllık
B14: STRES SENARYOSUNDA DAHİ İFLAS RİSKİ YOK | H14: OPTİMUM İCRA VE PLANLAMA REÇETESİ
B17: YÖNETİM KARAR MATRİSİ VE UYGULAMA REÇETESİ
B19: ● Öncelik 1: Acil Likidite ve Borç Servis Planlaması
B20: Sistemde hesaplanan vade günlerine sadık kalınarak nakit blokajı 3 gün önceden hazır edilmelidir.
B21: ● Öncelik 2: Formül Doğrulama ve Çapraz Sağlama
B22: Tüm hücreler kilitli formül korumasında olup girdi sayfalarında sıfır döngüsel başvuru (circular ref) garantilidir.
B23: ● Öncelik 3: Resmi Mevzuat ve Vergi Kalkanı Entegrasyonu
B24: 2026 güncel vergi dilimleri, amortisman ve SGK teşvik parametreleri tam otomatik yansıtılmaktadır.
B25: ● Öncelik 4: Yönetici İmzası ve Rapor Paylaşımı
B26: Tek tuşla PDF ve A4 çıktı formatına tam uyumlu sayfa yapısı kurgulanmıştır.

Sheet 01_YURUTME_CEKIRDEGI
A1: YÜRÜTME ÇEKİRDEĞİ — ZORUNLU ÜRETİM SIRASI
A3: Adım | B3: Modül | C3: Tetikleyici | D3: Zorunlu Kanıt | E3: GEÇTİ Kuralı | F3: Hata Durumu | G3: Sonraki Aşama
A4: 1 | B4: Excel Uygunluğu | C4: Her yeni model | D4: UYGUNLUK_KARARI | E4: Excel'in rolü açık | F4: HATA / BLOKE | G4: Yönetişim
A5: 2 | B5: Yönetişim | C5: Her model | D5: Risk seviyesi + etki girdileri | E5: Seviye hesaplandı | F5: BLOKE | G5: Sözleşmeler
A6: 3 | B6: Türk Muhasebe Eşlemesi | C6: Finansal model | D6: THP hesap eşleme tablosu | E6: Kritik satırlar THP ile uyumlu | F6: HATA | G6: Sözleşmeler
A7: 4 | B7: Veri ve Anlam Sözleşmeleri | C7: Girdi/KPI varsa | D7: Veri + KPI sözleşmeleri | E7: Kapsam %100 | F7: HATA | G7: Üretim
A8: 5 | B8: Üretim | C8: Sözleşmeler GEÇTİ | D8: Çalışan Excel | E8: Tek gerçek kaynak korunmuş | F8: HATA | G8: Testler
A9: 6 | B9: Görsel/Kullanım Katmanı | C9: Motor hazır | D9: Başlıklar + renk + grafik + yönlendirme | E9: Tüm kullanıcı sayfaları standarda uygun | F9: HATA | G9: Testler
A10: 7 | B10: Testler | C10: Üretim tamam | D10: Formül/OOXML/kimlik/oracle/golden/metamorfik | E10: Uygulanabilir hard gate'ler GEÇTİ | F10: HATA | G10: Kanıt
A11: 8 | B11: Hata-Kontrol Tutarlılığı | C11: Test sonucu var | D11: Hata taraması + kontrol sonuçları | E11: Formül hatası varken GEÇTİ yok | F11: HATA | G11: Kanıt
A12: 9 | B12: Kanıt | C12: Test sonucu var | D12: Makine okunur artefakt + özet | E12: Kanıt fiziksel ve tutarlı | F12: HATA | G12: Kullanıcı Kabulü
A13: 10 | B13: Kullanıcı Kabulü | C13: Kritik görevler | D13: Gerçek ekran davranışı | E13: Kritik görevler %100 | F13: DIŞ_KABUL_GEREKLİ | G13: Ticari
A14: 11 | B14: Ticari Değer | C14: Ürün satılacaksa | D14: ROI + demo + kanıt paketi | E14: Ekonomik değer kanıtlı | F14: UYARI / HATA | G14: Pazar Doğrulama
A15: 12 | B15: Pazar Doğrulama | C15: Pazar iddiası varsa | D15: Ücretli satış/pilot/fiyat kabul kanıtı | E15: Gerçek fiyat kabul kanıtı | F15: UYGULANMAZ / HATA | G15: Yayın

Sheet 02_KONTROL_LISTESI
A1: NİHAİ KONTROL LİSTESİ — KANITSIZ GEÇİŞ YOK
A3: Kontrol No | B3: Kontrol | C3: Beklenen | D3: Zorunlu Kapı? | E3: Sonuç
A4: K01 | B4: Kullanıcının açık talebi öncelikli mi? | C4: Evet | D4: EVET
A5: K02 | B5: Mevcut yapı, formüller ve tek gerçek kaynak korunuyor mu? | C5: Evet, değişiklik gerekçeli | D5: EVET
A6: K03 | B6: Üst aşama HATA ise alt aşama GEÇTİ engelleniyor mu? | C6: Evet | D6: EVET
A7: K04 | B7: Kanıt fiziksel çıktı ve içerik doğrulaması içeriyor mu? | C7: Evet | D7: EVET
A8: K05 | B8: Excel GUI erişimi olmadan kullanıcı görünümü GEÇTİ yazılıyor mu? | C8: Hayır | D8: EVET
A9: K06 | B9: NİHAİ yalnız GEÇTİ / gerekçeli UYGULANMAZ ile mi? | C9: Evet | D9: EVET
A10: K07 | B10: Ekonomik fiyat savunusu pazar doğrulamasından ayrılmış mı? | C10: Evet | D10: EVET
A11: K08 | B11: Prestij için gereksiz modül var mı? | C11: Hayır | D11: HAYIR
A12: K09 | B12: Excel sınırları açık mı? | C12: Evet | D12: EVET
A13: K10 | B13: Teknik kaynak korunuyor mu? | C13: Evet | D13: EVET
A14: K11 | B14: Kullanıcıya görünen tüm metinler Türkçe mi? | C14: Evet | D14: EVET
A15: K12 | B15: Her kullanıcı sayfasında üst başlık var mı? | C15: Evet | D15: EVET
... A34: K31 | B34: Premium vitrin, altyapı kadar güçlü ve satış fiyatını destekleyecek seviyede mi? | C34: Evet | D34: EVET

Sheet 03_GORSEL_TASARIM
A1: GÖRSEL TASARIM VE PREMIUM EXCEL STANDARDI
A3: Alan | B3: Zorunlu Kural | C3: Uygulama | D3: Yasak | E3: Kontrol | F3: Durum
A4: Sayfa başlığı | B4: Her kullanıcı sayfasının en üstünde tek ve açık sayfa başlığı | C4: A1'den başlayan koyu lacivert başlık bandı | D4: Başlıksız sayfa | E4: Başlık kapsama = %100 | F4: ZORUNLU
A5: Sekme renkleri | B5: Sayfalar işlevine göre renk kodlanır | C5: Girdi=mavi, hesap=gri, rapor=lacivert, kontrol=kırmızı, kılavuz=altın | D5: Rastgele renk | E5: Renk semantiği tutarlı | F5: ZORUNLU
A6: Kolon düzeni | B6: Veri blokları bitişik kolonlarda ilerler | C6: Gereksiz boş kolon bırakma; yalnız gerçek bölüm ayrımı varsa kontrollü boşluk | D6: A:C veri, D boş, E:F veri gibi parçalı yapı | E6: Boş kolon taraması | F6: ZORUNLU
A7: Girdi hücreleri | B7: Kullanıcının değiştireceği alan açıkça görünür | C7: Açık sarı dolgu + mavi yazı | D7: Formülle aynı görünüm | E7: Girdi/formül ayrımı | F7: ZORUNLU
A8: Formüller | B8: Hesap hücreleri kullanıcı girdisinden ayrılır | C8: Siyah yazı; sayfalar arası bağlantı yeşil yazı | D8: Hard-code gizleme | E8: Formül sınıfı kontrolü | F8: ZORUNLU
A9: Grafik sayısı | B9: Yönetici ekranında en fazla 3 ana karar grafiği | C9: Trend, karşılaştırma, köprü/dağılım; iş kararına bağlı | D9: Grafik kalabalığı | E9: Grafik başına karar sorusu | F9: ZORUNLU
A10: Grafik stili | B10: Kurumsal ve yüksek okunabilirlik | C10: Beyaz zemin, ince gridline, tek vurgu rengi, açık birim/başlık | D10: 3B, gölge, neon, gökkuşağı renkleri | E10: Görsel inceleme | F10: ZORUNLU
A11: Grafik başlığı | B11: Grafik 'neyi' değil 'ne anlama geldiğini' söyler | C11: Örn: 'Nakit 2028'de kritik eşiğin altına iniyor' | D11: 'Nakit Grafiği' gibi anlamsız başlık | E11: Başlık karar testi | F11: ZORUNLU
A12: Birimler | B12: Tüm finansal görsellerde birim açık | C12: TL, bin TL, milyon TL, %, gün, x | D12: Birim belirsizliği | E12: Birim kapsama %100 | F12: ZORUNLU
A13: Sıfır/negatif | B13: Finansal format standardı | C13: Sıfır='-', negatif kırmızı parantez | D13: -500 veya 0,00 kalabalığı | E13: Format kontrolü | F13: ZORUNLU
A14: Yazı tipi | B14: Tek aile | C14: Aptos veya Segoe UI | D14: Karışık font | E14: Tek font kontrolü | F14: ZORUNLU
... A22: Premium vitrin | B22: Görsel kalite ürün değerinin zorunlu parçasıdır | C22: Kaliteli grafik, gerçek KPI kartı, finansal hiyerarşi, tab rengi, fonksiyonel navigasyon | D22: Sadece doğru hesap yapıp çıplak/varsayılan Excel görünümü bırakmak | E22: Görsel release incelemesi | F22: ZORUNLU

Sheet 04_MUHASEBE_THP
A1: TÜRKİYE MUHASEBE VE TEKDÜZEN HESAP PLANI STANDARDI
A3: Konu | B3: Zorunlu Standart | C3: Örnek Türkçe Ad | D3: THP / Mantık | E3: Hata Riski | F3: Kontrol
A4: Dil | B4: Kullanıcıya görünen finansal terimler Türkçe | C4: Hasılat, Satışların Maliyeti, Brüt Kâr, Faaliyet Giderleri | D4: Türk işletme kullanımına uygun | E4: İngilizce jargon | F4: Terminoloji taraması
A5: Gelir Tablosu | B5: Türk sunum sırası kullanılır | C5: Net Satışlar → Satışların Maliyeti → Brüt Kâr → Faaliyet Giderleri → Faaliyet Kârı | D5: 600/610/611; 620-623; 63x | E5: Yanlış sınıflama | F5: Hesap eşleme
A6: Bilanço | B6: Dönen/Duran Varlık ve Kısa/Uzun Vadeli Yükümlülük ayrımı | C6: Hazır Değerler, Ticari Alacaklar, Stoklar, Mali Borçlar | D6: 1xx / 2xx / 3xx / 4xx / 5xx | E6: Vade sınıfı hatası | F6: Bilanço eşitliği
A7: Nakit Akışı | B7: İşletme/Yatırım/Finansman nakit akışları ayrılır | C7: Faaliyetlerden Nakit, Yatırım Harcamaları, Finansman Nakit Akışı | D7: Dolaylı/doğrudan yöntem açık seçilir | E7: Kâr = nakit sanılması | F7: Nakit devri
A8: Ticari Alacaklar | B8: Cari ve vade mantığı korunur | C8: 120 Alıcılar | D8: 120 | E8: Tahakkuk/nakit karışması | F8: Alacak devir kontrolü
A9: Ticari Borçlar | B9: Tedarikçi borcu ayrı izlenir | C9: 320 Satıcılar | D9: 320 | E9: Gider/ödeme karışması | F9: Borç devir kontrolü
A10: Kasa/Banka | B10: Hazır değerler ayrı izlenir | C10: 100 Kasa, 102 Bankalar | D10: 100 / 102 | E10: Virmanla toplam nakdin değişmesi | F10: Virman değişmezi
A11: Stok | B11: Dikeye uygun stok türü | C11: 150 İlk Madde ve Malzeme, 153 Ticari Mallar | D11: 15x | E11: Maliyet ve stok hareketinin kopması | F11: Stok devri
A12: Maddi Duran Varlık | B12: Yatırım harcaması ve amortisman bağlantılı | C12: 253 Tesis Makine Cihazlar, 255 Demirbaşlar, 257 Birikmiş Amortismanlar | D12: 25x | E12: Yatırım/gider karışması | F12: Net defter değeri devri
A13: Mali Borçlar | B13: Kısa/uzun vadeli borç ayrımı | C13: 300 Banka Kredileri / 400 Banka Kredileri | D13: 300 / 400 | E13: Vade sınıfı yanlış | F13: Borç devri
A14: Özkaynak | B14: Sermaye ve geçmiş yıl kârları ayrı | C14: 500 Sermaye, 570 Geçmiş Yıllar Kârları, 590 Dönem Net Kârı | D14: 5xx | E14: Net kâr bağının kopması | F14: Özkaynak devri
... A18: İstisna | B18: TFRS özel ürün varsa fark açık yazılır | C18: Tekdüzen raporlama ≠ TFRS finansal tablo sunumu | D18: Amaç belirtilir | E18: Standartları karıştırma | F18: Model amacı kontrolü

Sheet 05_KARAR_SATIS
A1: KARAR, GÜVEN VE SATIŞA HAZIRLIK STANDARDI
A3: Alan | B3: Müşteri Sorusu | C3: Zorunlu Ürün Davranışı | D3: Kanıt | E3: Başarısızlık Durumu | F3: Kapı
A4: 5 saniye | B4: Bu ürün neyi çözüyor? | C4: İlk ekranda hedef kullanıcı + pahalı problem + sonuç görünür | D4: Başlık + alt mesaj + gerçek ekran | E4: Ürün yalnız teknik isim | F4: HATA
A5: Acı | B5: Sorun bana neye mal oluyor? | C5: Mümkünse müşterinin kendi verisiyle parasal/zaman etkisi hesaplanır | D5: ROI/acı hesaplama yöntemi | E5: Uydurma tasarruf | F5: HATA
A6: Karar | B6: Bu bilgiyle ne yapacağım? | C6: Her kritik KPI aksiyona bağlanır | D6: KARAR_KUYRUGU | E6: Sadece rapor | F6: HATA
A7: Güven | B7: Bu sayıya neden inanayım? | C7: Kaynak, formül mantığı, kontrol ve son doğrulama görünür | D7: Kontroller + kaynak izi + sürüm | E7: Prestij kelimesi | F7: HATA
A8: Referans | B8: Müşteri yorumu yoksa ne göstereceğim? | C8: Önce/Sonra + Karar Vakası + Hata Önleme Vakası üretilir | D8: Demo/örnek çıktı | E8: Kanıtsız iddia | F8: HATA
A9: Senaryo | B9: Ne olursa işler bozulur? | C9: Baz/Aşağı/Yukarı veya uygun stres senaryosu | D9: Senaryo karşılaştırma | E9: Dekoratif senaryo | F9: HATA
A10: Ters stres | B10: Hangi eşikte karar kırılır? | C10: En az bir kritik sürücü için kırılma eşiği | D10: Kırılma eşiği tablosu | E10: Sadece +/- %10 | F10: UYARI/HATA
A11: Hata tutarlılığı | B11: Formül hata verirse ne olur? | C11: Kontrol GEÇTİ veremez; BLOKE/HATA üretir | D11: Hata taraması | E11: Hata + GEÇTİ birlikte | F11: HATA
A12: Karar motoru | B12: Ne oldu, neden oldu? | C12: Sorun + neden + parasal etki + aksiyon + son tarih | D12: Karar tablosu | E12: Boş sayfa / isim düzeyi modül | F12: HATA
A13: Yönetici özeti | B13: 5 saniyede ne görmeliyim? | C13: Bugün / ne değişti / ne bozulacak / neden / ne yapmalıyım / güven | D13: Yönetici özeti ekranı | E13: KPI kutusu yığını | F13: HATA
A14: Teklif | B14: Neden satın almalıyım? | C14: Dosya özellikleri yerine sonuç ve kaçınılan maliyet sunulur | D14: Ürün sayfası kanıt eşlemesi | E14: Özellik listesiyle satış | F14: HATA
... A19: Pazar kanıtı | B19: Piyasa gerçekten ödüyor mu? | C19: Satış/pilot/LOI/fiyat kabulü olmadan pazar doğrulandı yazılmaz | D19: Gerçek işlem kanıtı | E19: Tahmini talep = satış kabulü | F19: HATA

Sheet KAPAK
A1: KAPAK — İSG Risk Değerlendirme Pro (6331)
A3: İSG Risk Değerlendirme Pro (6331)
A4: 6331 sayılı Kanun çerçevesinde tehlike envanteri, L-matris / Fine-Kinney puanlama, eylem durum makinesi ve denetime sunulabilir kanıt raporu üretir.
A6: Bu ürün ne sağlar?
A7: • Makrosuz eylem durum makinesi: Planlandı → Devam → Bekliyor → Tamamlandı / İptal
A8: • L-matris veya Fine-Kinney seçimli puanlama (AYARLAR)
A9: • Eylem yaşlandırma kovaları ve geçersiz geçiş uyarısı
A10: • Skor dağılımı, uyum oranı, yenileme takvimi
A11: • KANIT_RAPORU — madde atfı, revizyon, imza alanı
A13: Kimler için?
A14: • İSG uzmanı — envanter ve skorlama
A15: • İşveren vekili — eylem onayı
... A21: Sürüm 1.0.0 | Lisans: Tek kullanıcı | ExcelArşiv

Sheet ENVANTER
A1: ENVANTER — İSG Risk Değerlendirme Pro (6331)
A3: Tehlike envanteri — her kaydın tek kimliği vardır (ID disiplini)
A4: Sonraki Kimlik | B4: =isg_sonrakiKimlik
A5: TehlikeId | B5: Bolum | C5: TehlikeAdi | D5: MaddeAtif | E5: Olasilik | F5: Siddet | G5: Frekans | H5: MevcutKontrol | I5: Aktif | J5: HamSkor | K5: RiskSeviye | L5: KayitDolu
A6: TEH-00001 | B6: Üretim | C6: Makine koruyucu eksik | D6: ISG-001 | E6: 4 | F6: 5 | G6: 3 | H6: Kısmi koruyucu | I6: EVET | J6: =IF($A6="","",IF(isg_matrisTipi="FK",$E6*$G6*$F6,$E6*$F6)) | K6: =IF($A6="","",IF($J6>=isg_esikKritikSeviye,"Kritik",IF($J6>=isg_esikYuksek,"Yüksek",IF($J6>=isg_esikOrta,"Orta","Düşük")))) | L6: =IF($A6="","",1)
A7: TEH-00002 | B7: Üretim | C7: Gürültü eşiği aşımı | D7: ISG-002 | E7: 3 | F7: 4 | G7: 4 | H7: Kulaklık | I7: EVET | J7: =IF($A7="","",IF(isg_matrisTipi="FK",$E7*$G7*$F7,$E7*$F7)) | K7: =IF($A7="","",IF($J7>=isg_esikKritikSeviye,"Kritik",IF($J7>=isg_esikYuksek,"Yüksek",IF($J7>=isg_esikOrta,"Orta","Düşük")))) | L7: =IF($A7="","",1)
A8: TEH-00003 | B8: Depo | C8: Yüksekte istifleme | D8: ISG-001 | E8: 3 | F8: 5 | G8: 2 | H8: Emniyet kemeri | I8: EVET | J8: =IF($A8="","",IF(isg_matrisTipi="FK",$E8*$G8*$F8,$E8*$F8)) | K8: =IF($A8="","",IF($J8>=isg_esikKritikSeviye,"Kritik",IF($J8>=isg_esikYuksek,"Yüksek",IF($J8>=isg_esikOrta,"Orta","Düşük")))) | L8: =IF($A8="","",1)
A9: TEH-00004 | B9: Depo | C9: Forklift çarpışma riski | D9: ISG-001 | E9: 4 | F9: 5 | G9: 3 | H9: Yaya yolu | I9: EVET | J9: =IF($A9="","",IF(isg_matrisTipi="FK",$E9*$G9*$F9,$E9*$F9)) | K9: =IF($A9="","",IF($J9>=isg_esikKritikSeviye,"Kritik",IF($J9>=isg_esikYuksek,"Yüksek",IF($J9>=isg_esikOrta,"Orta","Düşük")))) | L9: =IF($A9="","",1)
A10: TEH-00005 | B10: Ofis | C10: Ergonomi / VDU | D10: ISG-003 | E10: 2 | F10: 3 | G10: 5 | H10: Ayarlı masa | I10: EVET | J10: =IF($A10="","",IF(isg_matrisTipi="FK",$E10*$G10*$F10,$E10*$F10)) | K10: =IF($A10="","",IF($J10>=isg_esikKritikSeviye,"Kritik",IF($J10>=isg_esikYuksek,"Yüksek",IF($J10>=isg_esikOrta,"Orta","Düşük")))) | L10: =IF($A10="","",1)
A11: TEH-00006 | B11: Ofis | C11: Elektrik kablosu dağınıklığı | D11: ISG-001 | E11: 2 | F11: 4 | G11: 2 | H11: Kabinet | I11: EVET | J11: =IF($A11="","",IF(isg_matrisTipi="FK",$E11*$G11*$F11,$E11*$F11)) | K11: =IF($A11="","",IF($J11>=isg_esikKritikSeviye,"Kritik",IF($J11>=isg_esikYuksek,"Yüksek",IF($J11>=isg_esikOrta,"Orta","Düşük")))) | L11: =IF($A11="","",1)
A12: TEH-00007 | B12: Saha | C12: Kaygan zemin | D12: ISG-001 | E12: 3 | F12: 4 | G12: 3 | H12: Uyarı levhası | I12: EVET | J12: =IF($A12="","",IF(isg_matrisTipi="FK",$E12*$G12*$F12,$E12*$F12)) | K12: =IF($A12="","",IF($J12>=isg_esikKritikSeviye,"Kritik",IF($J12>=isg_esikYuksek,"Yüksek",IF($J12>=isg_esikOrta,"Orta","Düşük")))) | L12: =IF($A12="","",1)
A13: TEH-00008 | B13: Saha | C13: Kimyasal dökülme | D13: ISG-002 | E13: 3 | F13: 5 | G13: 2 | H13: Spill kiti | I13: EVET | J13: =IF($A13="","",IF(isg_matrisTipi="FK",$E13*$G13*$F13,$E13*$F13)) | K13: =IF($A13="","",IF($J13>=isg_esikKritikSeviye,"Kritik",IF($J13>=isg_esikYuksek,"Yüksek",IF($J13>=isg_esikOrta,"Orta","Düşük")))) | L13: =IF($A13="","",1)
A14: TEH-00009 | B14: Üretim | C14: Toz maruziyeti | D14: ISG-002 | E14: 4 | F14: 4 | G14: 4 | H14: Maske | I14: EVET | J14: =IF($A14="","",IF(isg_matrisTipi="FK",$E14*$G14*$F14,$E14*$F14)) | K14: =IF($A14="","",IF($J14>=isg_esikKritikSeviye,"Kritik",IF($J14>=isg_esikYuksek,"Yüksek",IF($J14>=isg_esikOrta,"Orta","Düşük")))) | L14: =IF($A14="","",1)
A15: TEH-00010 | B15: Üretim | C15: Sıcak yüzey teması | D15: ISG-001 | E15: 3 | F15: 4 | G15: 3 | H15: Eldiven | I15: EVET | J15: =IF($A15="","",IF(isg_matrisTipi="FK",$E15*$G15*$F15,$E15*$F15)) | K15: =IF($A15="","",IF($J15>=isg_esikKritikSeviye,"Kritik",IF($J15>=isg_esikYuksek,"Yüksek",IF($J15>=isg_esikOrta,"Orta","Düşük")))) | L15: =IF($A15="","",1)
A16: TEH-00011 | B16: Bakım | C16: Enerji kesilmeden müdahale | D16: ISG-001 | E16: 5 | F16: 5 | G16: 2 | H16: LOTO kısmi | I16: EVET | J16: =IF($A16="","",IF(isg_matrisTipi="FK",$E16*$G16*$F16,$E16*$F16)) | K16: =IF($A16="","",IF($J16>=isg_esikKritikSeviye,"Kritik",IF($J16>=isg_esikYuksek,"Yüksek",IF($J16>=isg_esikOrta,"Orta","Düşük")))) | L16: =IF($A16="","",1)
A17: TEH-00012 | B17: Bakım | C17: İskele stabilite | D17: ISG-001 | E17: 3 | F17: 5 | G17: 2 | H17: Kontrol formu | I17: EVET | J17: =IF($A17="","",IF(isg_matrisTipi="FK",$E17*$G17*$F17,$E17*$F17)) | K17: =IF($A17="","",IF($J17>=isg_esikKritikSeviye,"Kritik",IF($J17>=isg_esikYuksek,"Yüksek",IF($J17>=isg_esikOrta,"Orta","Düşük")))) | L17: =IF($A17="","",1)
... A29: TEH-00024 | B29: Saha | C29: Gece aydınlatma yetersiz | D29: ISG-001 | E29: 3 | F29: 3 | G29: 2 | H29: Projektör | I29: EVET | J29: =IF($A29="","",IF(isg_matrisTipi="FK",$E29*$G29*$F29,$E29*$F29)) | K29: =IF($A29="","",IF($J29>=isg_esikKritikSeviye,"Kritik",IF($J29>=isg_esikYuksek,"Yüksek",IF($J29>=isg_esikOrta,"Orta","Düşük")))) | L29: =IF($A29="","",1)
J30: =IF($A30="","",IF(isg_matrisTipi="FK",$E30*$G30*$F30,$E30*$F30)) | K30: =IF($A30="","",IF($J30>=isg_esikKritikSeviye,"Kritik",IF($J30>=isg_esikYuksek,"Yüksek",IF($J30>=isg_esikOrta,"Orta","Düşük")))) | L30: =IF($A30="","",1)
J31: =IF($A31="","",IF(isg_matrisTipi="FK",$E31*$G31*$F31,$E31*$F31)) | K31: =IF($A31="","",IF($J31>=isg_esikKritikSeviye,"Kritik",IF($J31>=isg_esikYuksek,"Yüksek",IF($J31>=isg_esikOrta,"Orta","Düşük")))) | L31: =IF($A31="","",1)
J32: =IF($A32="","",IF(isg_matrisTipi="FK",$E32*$G32*$F32,$E32*$F32)) | K32: =IF($A32="","",IF($J32>=isg_esikKritikSeviye,"Kritik",IF($J32>=isg_esikYuksek,"Yüksek",IF($J32>=isg_esikOrta,"Orta","Düşük")))) | L32: =IF($A32="","",1)
J33: =IF($A33="","",IF(isg_matrisTipi="FK",$E33*$G33*$F33,$E33*$F33)) | K33: =IF($A33="","",IF($J33>=isg_esikKritikSeviye,"Kritik",IF($J33>=isg_esikYuksek,"Yüksek",IF($J33>=isg_esikOrta,"Orta","Düşük")))) | L33: =IF($A33="","",1)
J34: =IF($A34="","",IF(isg_matrisTipi="FK",$E34*$G34*$F34,$E34*$F34)) | K34: =IF($A34="","",IF($J34>=isg_esikKritikSeviye,"Kritik",IF($J34>=isg_esikYuksek,"Yüksek",IF($J34>=isg_esikOrta,"Orta","Düşük")))) | L34: =IF($A34="","",1)
J35: =IF($A35="","",IF(isg_matrisTipi="FK",$E35*$G35*$F35,$E35*$F35)) | K35: =IF($A35="","",IF($J35>=isg_esikKritikSeviye,"Kritik",IF($J35>=isg_esikYuksek,"Yüksek",IF($J35>=isg_esikOrta,"Orta","Düşük")))) | L35: =IF($A35="","",1)
J36: =IF($A36="","",IF(isg_matrisTipi="FK",$E36*$G36*$F36,$E36*$F36)) | K36: =IF($A36="","",IF($J36>=isg_esikKritikSeviye,"Kritik",IF($J36>=isg_esikYuksek,"Yüksek",IF($J36>=isg_esikOrta,"Orta","Düşük")))) | L36: =IF($A36="","",1)
J37: =IF($A37="","",IF(isg_matrisTipi="FK",$E37*$G37*$F37,$E37*$F37)) | K37: =IF($A37="","",IF($J37>=isg_esikKritikSeviye,"Kritik",IF($J37>=isg_esikYuksek,"Yüksek",IF($J37>=isg_esikOrta,"Orta","Düşük")))) | L37: =IF($A37="","",1)
J38: =IF($A38="","",IF(isg_matrisTipi="FK",$E38*$G38*$F38,$E38*$F38)) | K38: =IF($A38="","",IF($J38>=isg_esikKritikSeviye,"Kritik",IF($J38>=isg_esikYuksek,"Yüksek",IF($J38>=isg_esikOrta,"Orta","Düşük")))) | L38: =IF($A38="","",1)
J39: =IF($A39="","",IF(isg_matrisTipi="FK",$E39*$G39*$F39,$E39*$F39)) | K39: =IF($A39="","",IF($J39>=isg_esikKritikSeviye,"Kritik",IF($J39>=isg_esikYuksek,"Yüksek",IF($J39>=isg_esikOrta,"Orta","Düşük")))) | L39: =IF($A39="","",1)
J40: =IF($A40="","",IF(isg_matrisTipi="FK",$E40*$G40*$F40,$E40*$F40)) | K40: =IF($A40="","",IF($J40>=isg_esikKritikSeviye,"Kritik",IF($J40>=isg_esikYuksek,"Yüksek",IF($J40>=isg_esikOrta,"Orta","Düşük")))) | L40: =IF($A40="","",1)
J41: =IF($A41="","",IF(isg_matrisTipi="FK",$E41*$G41*$F41,$E41*$F41)) | K41: =IF($A41="","",IF($J41>=isg_esikKritikSeviye,"Kritik",IF($J41>=isg_esikYuksek,"Yüksek",IF($J41>=isg_esikOrta,"Orta","Düşük")))) | L41: =IF($A41="","",1)
... J205: =IF($A205="","",IF(isg_matrisTipi="FK",$E205*$G205*$F205,$E205*$F205)) | K205: =IF($A205="","",IF($J205>=isg_esikKritikSeviye,"Kritik",IF($J205>=isg_esikYuksek,"Yüksek",IF($J205>=isg_esikOrta,"Orta","Düşük")))) | L205: =IF($A205="","",1)

Sheet DEGERLENDIRME
A1: DEGERLENDIRME — İSG Risk Değerlendirme Pro (6331)
A3: Hesap motoru — ≥40 adım; puanlama matrisi AYARLAR'dan
A5: Adım | B5: Açıklama | C5: Değer
A6: H01 | B6: Tehlike toplam | C6: =COUNTA(tblEnvanter[TehlikeId])
A7: H02 | B7: Dolu kayıt | C7: =SUM(tblEnvanter[KayitDolu])
A8: H03 | B8: Aktif tehlike | C8: =COUNTIF(tblEnvanter[Aktif],"EVET")
A9: H04 | B9: Skor toplam | C9: =SUM(tblEnvanter[HamSkor])
A10: H05 | B10: Ortalama skor | C10: =IFERROR(AVERAGE(tblEnvanter[HamSkor]),0)
A11: H06 | B11: Maks skor | C11: =IFERROR(MAX(tblEnvanter[HamSkor]),0)
A12: H07 | B12: Min skor | C12: =IFERROR(MIN(tblEnvanter[HamSkor]),0)
A13: H08 | B13: Düşük adet | C13: =COUNTIF(tblEnvanter[RiskSeviye],"Düşük")
A14: H09 | B14: Orta adet | C14: =COUNTIF(tblEnvanter[RiskSeviye],"Orta")
A15: H10 | B15: Yüksek adet | C15: =COUNTIF(tblEnvanter[RiskSeviye],"Yüksek")
A16: H11 | B16: Kritik adet | C16: =COUNTIF(tblEnvanter[RiskSeviye],"Kritik")
A17: H12 | B17: ISG-001 atıf | C17: =COUNTIF(tblEnvanter[MaddeAtif],"ISG-001")
A18: H13 | B18: ISG-002 atıf | C18: =COUNTIF(tblEnvanter[MaddeAtif],"ISG-002")
A19: H14 | B19: ISG-003 atıf | C19: =COUNTIF(tblEnvanter[MaddeAtif],"ISG-003")
A20: H15 | B20: Eylem toplam | C20: =COUNTA(tblEylem[EylemId])
A21: H16 | B21: Planlandı | C21: =COUNTIF(tblEylem[Durum],"PLANLANDI")
A22: H17 | B22: Devam | C22: =COUNTIF(tblEylem[Durum],"DEVAM")
A23: H18 | B23: Bekliyor | C23: =COUNTIF(tblEylem[Durum],"BEKLIYOR")
A24: H19 | B24: Tamamlandı | C24: =COUNTIF(tblEylem[Durum],"TAMAMLANDI")
A25: H20 | B25: İptal | C25: =COUNTIF(tblEylem[Durum],"IPTAL")
A26: H21 | B26: Açık adet | C26: =C21+C22+C23
A27: H22 | B27: Kapalı adet | C27: =C24+C25
A28: H23 | B28: Açık tutar | C28: =SUMIF(tblEylem[Durum],"PLANLANDI",tblEylem[Tutar])+SUMIF(tblEylem[Durum],"DEVAM",tblEylem[Tutar])+SUMIF(tblEylem[Durum],"BEKLIYOR",tblEylem[Tutar])
A29: H24 | B29: Yetim adet | C29: =COUNTIF(tblEylem[YetimBayrak],"YETİM")
A30: H25 | B30: Geçersiz geçiş | C30: =COUNTIF(tblEylem[GecisUyarisi],"GEÇERSİZ GEÇİŞ")
A31: H26 | B31: Zincir kırık | C31: =COUNTIF(tblEylem[ZincirBayrak],"ZİNCİR KIRIK")
A32: H27 | B32: Zincir OK | C32: =COUNTIF(tblEylem[ZincirBayrak],"OK")
A33: H28 | B33: Yaş 0-7 | C33: =COUNTIF(tblEylem[YasKova],"0-7")
A34: H29 | B34: Yaş 8-30 | C34: =COUNTIF(tblEylem[YasKova],"8-30")
A35: H30 | B35: Yaş 31-60 | C35: =COUNTIF(tblEylem[YasKova],"31-60")
A36: H31 | B36: Yaş 60+ | C36: =COUNTIF(tblEylem[YasKova],"60+")
A37: H32 | B37: Ort yaş gün | C37: =IFERROR(AVERAGE(tblEylem[YasGun]),0)
A38: H33 | B38: Geciken adet | C38: =COUNTIFS(tblEylem[YasGun],">"&isg_esikGecikmeGun,tblEylem[Durum],"<>TAMAMLANDI",tblEylem[Durum],"<>IPTAL",tblEylem[Tutar],">0")
A39: H34 | B39: Geciken tutar | C39: =SUMIFS(tblEylem[Tutar],tblEylem[YasGun],">"&isg_esikGecikmeGun,tblEylem[Durum],"<>TAMAMLANDI",tblEylem[Durum],"<>IPTAL")
A40: H35 | B40: Gecikme maliyeti | C40: =C39*isg_gecikmeOranGun
A41: H36 | B41: Temkinli senaryo | C41: =C9*isg_senaryoTemkinli
A42: H37 | B42: Baz senaryo | C42: =C9*isg_senaryoBaz
...

Sheet EYLEM_PLANI
A1: EYLEM PLANI — İSG Risk Değerlendirme Pro (6331)
A3: Eylem satırları — durum makinesi + yetim + geçersiz geçiş + zincir bayrakları
A5: EylemId | B5: KaynakTehlikeId | C5: Tarih | D5: Termin | E5: OncekiDurum | F5: Durum | G5: Sorumlu | H5: Aciklama | I5: IlkSkor | J5: HedefSkor | K5: Tutar | L5: YasGun | M5: YasKova | N5: YetimBayrak | O5: GecisUyarisi | P5: ZincirBayrak | Q5: KayitDolu
A6: EYL-00001 | B6: TEH-00001 | C6: 46240 | D6: 46235 | F6: PLANLANDI | G6: Sorumlu 2 | H6: Kontrol eylemi 1 | I6: 20 | J6: 18 | K6: 5000 | L6: =IF($A6="","",IF($C6="","",raporTarihi-$C6)) | M6: =IF($A6="","",IF($L6="","",IF($L6<=7,"0-7",IF($L6<=30,"8-30",IF($L6<=60,"31-60","60+"))))) | N6: =IF($A6="","",IF($B6="","YETİM",IF(COUNTIF(tblEnvanter[TehlikeId],$B6)=0,"YETİM",""))) | O6: =IF(OR($A6="",$E6=""),"",IF(OR($E6&"|"&$F6="",COUNTIF(ListeIzinliGecis,$E6&"|"&$F6)>0),"","GEÇERSİZ GEÇİŞ")) | P6: =IF($A6="","",IF(OR($I6="",$J6=""),"",IF(ABS($J6-$I6)>zincirTolerans,"ZİNCİR KIRIK","OK"))) | Q6: =IF($A6="","",1)
A7: EYL-00002 | B7: TEH-00002 | C7: 46236 | D7: 46236 | E7: PLANLANDI | F7: DEVAM | G7: Sorumlu 3 | H7: Kontrol eylemi 2 | I7: 12 | J7: 8 | K7: 3000 | L7: =IF($A7="","",IF($C7="","",raporTarihi-$C7)) | M7: =IF($A7="","",IF($L7="","",IF($L7<=7,"0-7",IF($L7<=30,"8-30",IF($L7<=60,"31-60","60+"))))) | N7: =IF($A7="","",IF($B7="","YETİM",IF(COUNTIF(tblEnvanter[TehlikeId],$B7)=0,"YETİM",""))) | O7: =IF(OR($A7="",$E7=""),"",IF(OR($E7&"|"&$F7="",COUNTIF(ListeIzinliGecis,$E7&"|"&$F7)>0),"","GEÇERSİZ GEÇİŞ")) | P7: =IF($A7="","",IF(OR($I7="",$J7=""),"",IF(ABS($J7-$I7)>zincirTolerans,"ZİNCİR KIRIK","OK"))) | Q7: =IF($A7="","",1)
A8: EYL-00003 | B8: TEH-00003 | C8: 46232 | D8: 46237 | E8: DEVAM | F8: BEKLIYOR | G8: Sorumlu 4 | H8: Kontrol eylemi 3 | I8: 15 | J8: 9 | K8: 3750 | L8: =IF($A8="","",IF($C8="","",raporTarihi-$C8)) | M8: =IF($A8="","",IF($L8="","",IF($L8<=7,"0-7",IF($L8<=30,"8-30",IF($L8<=60,"31-60","60+"))))) | N8: =IF($A8="","",IF($B8="","YETİM",IF(COUNTIF(tblEnvanter[TehlikeId],$B8)=0,"YETİM",""))) | O8: =IF(OR($A8="",$E8=""),"",IF(OR($E8&"|"&$F8="",COUNTIF(ListeIzinliGecis,$E8&"|"&$F8)>0),"","GEÇERSİZ GEÇİŞ")) | P8: =IF($A8="","",IF(OR($I8="",$J8=""),"",IF(ABS($J8-$I8)>zincirTolerans,"ZİNCİR KIRIK","OK"))) | Q8: =IF($A8="","",1)
A9: EYL-00004 | B9: TEH-00004 | C9: 46228 | D9: 46238 | E9: BEKLIYOR | F9: TAMAMLANDI | G9: Sorumlu 5 | H9: Kontrol eylemi 4 | I9: 20 | J9: 12 | K9: 5000 | L9: =IF($A9="","",IF($C9="","",raporTarihi-$C9)) | M9: =IF($A9="","",IF($L9="","",IF($L9<=7,"0-7",IF($L9<=30,"8-30",IF($L9<=60,"31-60","60+"))))) | N9: =IF($A9="","",IF($B9="","YETİM",IF(COUNTIF(tblEnvanter[TehlikeId],$B9)=0,"YETİM",""))) | O9: =IF(OR($A9="",$E9=""),"",IF(OR($E9&"|"&$F9="",COUNTIF(ListeIzinliGecis,$E9&"|"&$F9)>0),"","GEÇERSİZ GEÇİŞ")) | P9: =IF($A9="","",IF(OR($I9="",$J9=""),"",IF(ABS($J9-$I9)>zincirTolerans,"ZİNCİR KIRIK","OK"))) | Q9: =IF($A9="","",1)
A10: EYL-00005 | B10: TEH-00005 | C10: 46224 | D10: 46239 | E10: DEVAM | F10: IPTAL | G10: Sorumlu 6 | H10: Kontrol eylemi 5 | I10: 6 | J10: 6 | K10: 1500 | L10: =IF($A10="","",IF($C10="","",raporTarihi-$C10)) | M10: =IF($A10="","",IF($L10="","",IF($L10<=7,"0-7",IF($L10<=30,"8-30",IF($L10<=60,"31-60","60+"))))) | N10: =IF($A10="","",IF($B10="","YETİM",IF(COUNTIF(tblEnvanter[TehlikeId],$B10)=0,"YETİM",""))) | O10: =IF(OR($A10="",$E10=""),"",IF(OR($E10&"|"&$F10="",COUNTIF(ListeIzinliGecis,$E10&"|"&$F10)>0),"","GEÇERSİZ GEÇİŞ")) | P10: =IF($A10="","",IF(OR($I10="",$J10=""),"",IF(ABS($J10-$I10)>zincirTolerans,"ZİNCİR KIRIK","OK"))) | Q10: =IF($A10="","",1)
A11: EYL-00006 | B11: TEH-00006 | C11: 46220 | D11: 46240 | E11: PLANLANDI | F11: DEVAM | G11: Sorumlu 1 | H11: Kontrol eylemi 6 | I11: 8 | J11: 6 | K11: 2000 | L11: =IF($A11="","",IF($C11="","",raporTarihi-$C11)) | M11: =IF($A11="","",IF($L11="","",IF($L11<=7,"0-7",IF($L11<=30,"8-30",IF($L11<=60,"31-60","60+"))))) | N11: =IF($A11="","",IF($B11="","YETİM",IF(COUNTIF(tblEnvanter[TehlikeId],$B11)=0,"YETİM",""))) | O11: =IF(OR($A11="",$E11=""),"",IF(OR($E11&"|"&$F11="",COUNTIF(ListeIzinliGecis,$E11&"|"&$F11)>0),"","GEÇERSİZ GEÇİŞ")) | P11: =IF($A11="","",IF(OR($I11="",$J11=""),"",IF(ABS($J11-$I11)>zincirTolerans,"ZİNCİR KIRIK","OK"))) | Q11: =IF($A11="","",1)
A12: EYL-00007 | B12: TEH-00007 | C12: 46216 | D12: 46241 | E12: DEVAM | F12: BEKLIYOR | G12: Sorumlu 2 | H12: Kontrol eylemi 7 | I12: 12 | J12: 8 | K12: 3000 | L12: =IF($A12="","",IF($C12="","",raporTarihi-$C12)) | M12: =IF($A12="","",IF($L12="","",IF($L12<=7,"0-7",IF($L12<=30,"8-30",IF($L12<=60,"31-60","60+"))))) | N12: =IF($A12="","",IF($B12="","YETİM",IF(COUNTIF(tblEnvanter[TehlikeId],$B12)=0,"YETİM",""))) | O12: =IF(OR($A12="",$E12=""),"",IF(OR($E12&"|"&$F12="",COUNTIF(ListeIzinliGecis,$E12&"|"&$F12)>0),"","GEÇERSİZ GEÇİŞ")) | P12: =IF($A12="","",IF(OR($I12="",$J12=""),"",IF(ABS($J12-$I12)>zincirTolerans,"ZİNCİR KIRIK","OK"))) | Q12: =IF($A12="","",1)
A13: EYL-00008 | B13: TEH-00008 | C13: 46212 | D13: 46242 | E13: PLANLANDI | F13: PLANLANDI | G13: Sorumlu 3 | H13: Kontrol eylemi 8 | I13: 15 | J13: 9 | K13: 3750 | L13: =IF($A13="","",IF($C13="","",raporTarihi-$C13)) | M13: =IF($A13="","",IF($L13="","",IF($L13<=7,"0-7",IF($L13<=30,"8-30",IF($L13<=60,"31-60","60+"))))) | N13: =IF($A13="","",IF($B13="","YETİM",IF(COUNTIF(tblEnvanter[TehlikeId],$B13)=0,"YETİM",""))) | O13: =IF(OR($A13="",$E13=""),"",IF(OR($E13&"|"&$F13="",COUNTIF(ListeIzinliGecis,$E13&"|"&$F13)>0),"","GEÇERSİZ GEÇİŞ")) | P13: =IF($A13="","",IF(OR($I13="",$J13=""),"",IF(ABS($J13-$I13)>zincirTolerans,"ZİNCİR KIRIK","OK"))) | Q13: =IF($A13="","",1)
A14: EYL-00009 | B14: TEH-00009 | C14: 46208 | D14: 46243 | F14: PLANLANDI | G14: Sorumlu 4 | H14: Kontrol eylemi 9 | I14: 16 | J14: 8 | K14: 4000 | L14: =IF($A14="","",IF($C14="","",raporTarihi-$C14)) | M14: =IF($A14="","",IF($L14="","",IF($L14<=7,"0-7",IF($L14<=30,"8-30",IF($L14<=60,"31-60","60+"))))) | N14: =IF($A14="","",IF($B14="","YETİM",IF(COUNTIF(tblEnvanter[TehlikeId],$B14)=0,"YETİM",""))) | O14: =IF(OR($A14="",$E14=""),"",IF(OR($E14&"|"&$F14="",COUNTIF(ListeIzinliGecis,$E14&"|"&$F14)>0),"","GEÇERSİZ GEÇİŞ")) | P14: =IF($A14="","",IF(OR($I14="",$J14=""),"",IF(ABS($J14-$I14)>zincirTolerans,"ZİNCİR KIRIK","OK"))) | Q14: =IF($A14="","",1)
A15: EYL-00010 | B15: TEH-00010 | C15: 46204 | D15: 46244 | E15: PLANLANDI | F15: DEVAM | G15: Sorumlu 5 | H15: Kontrol eylemi 10 | I15: 12 | J15: 12 | K15: 3000 | L15: =IF($A15="","",IF($C15="","",raporTarihi-$C15)) | M15: =IF($A15="","",IF($L15="","",IF($L15<=7,"0-7",IF($L15<=30,"8-30",IF($L15<=60,"31-60","60+"))))) | N15: =IF($A15="","",IF($B15="","YETİM",IF(COUNTIF(tblEnvanter[TehlikeId],$B15)=0,"YETİM",""))) | O15: =IF(OR($A15="",$E15=""),"",IF(OR($E15&"|"&$F15="",COUNTIF(ListeIzinliGecis,$E15&"|"&$F15)>0),"","GEÇERSİZ GEÇİŞ")) | P15: =IF($A15="","",IF(OR($I15="",$J15=""),"",IF(ABS($J15-$I15)>zincirTolerans,"ZİNCİR KIRIK","OK"))) | Q15: =IF($A15="","",1)
A16: EYL-00011 | B16: TEH-00011 | C16: 46200 | D16: 46245 | E16: DEVAM | F16: BEKLIYOR | G16: Sorumlu 6 | H16: Kontrol eylemi 11 | I16: 25 | J16: 23 | K16: 6250 | L16: =IF($A16="","",IF($C16="","",raporTarihi-$C16)) | M16: =IF($A16="","",IF($L16="","",IF($L16<=7,"0-7",IF($L16<=30,"8-30",IF($L16<=60,"31-60","60+"))))) | N16: =IF($A16="","",IF($B16="","YETİM",IF(COUNTIF(tblEnvanter[TehlikeId],$B16)=0,"YETİM",""))) | O16: =IF(OR($A16="",$E16=""),"",IF(OR($E16&"|"&$F16="",COUNTIF(ListeIzinliGecis,$E16&"|"&$F16)>0),"","GEÇERSİZ GEÇİŞ")) | P16: =IF($A16="","",IF(OR($I16="",$J16=""),"",IF(ABS($J16-$I16)>zincirTolerans,"ZİNCİR KIRIK","OK"))) | Q16: =IF($A16="","",1)
A17: EYL-00012 | B17: TEH-00012 | C17: 46196 | D17: 46246 | E17: BEKLIYOR | F17: TAMAMLANDI | G17: Sorumlu 1 | H17: Kontrol eylemi 12 | I17: 15 | J17: 55 | K17: 3750 | L17: =IF($A17="","",IF($C17="","",raporTarihi-$C17)) | M17: =IF($A17="","",IF($L17="","",IF($L17<=7,"0-7",IF($L17<=30,"8-30",IF($L17<=60,"31-60","60+"))))) | N17: =IF($A17="","",IF($B17="","YETİM",IF(COUNTIF(tblEnvanter[TehlikeId],$B17)=0,"YETİM",""))) | O17: =IF(OR($A17="",$E17=""),"",IF(OR($E17&"|"&$F17="",COUNTIF(ListeIzinliGecis,$E17&"|"&$F17)>0),"","GEÇERSİZ GEÇİŞ")) | P17: =IF($A17="","",IF(OR($I17="",$J17=""),"",IF(ABS($J17-$I17)>zincirTolerans,"ZİNCİR KIRIK","OK"))) | Q17: =IF($A17="","",1)
A18: EYL-00013 | B18: TEH-00013 | C18: 46192 | D18: 46247 | E18: DEVAM | F18: IPTAL | G18: Sorumlu 2 | H18: Kontrol eylemi 13 | I18: 9 | J18: 3 | K18: 2250 | L18: =IF($A18="","",IF($C18="","",raporTarihi-$C18)) | M18: =IF($A18="","",IF($L18="","",IF($L18<=7,"0-7",IF($L18<=30,"8-30",IF($L18<=60,"31-60","60+"))))) | N18: =IF($A18="","",IF($B18="","YETİM",IF(COUNTIF(tblEnvanter[TehlikeId],$B18)=0,"YETİM",""))) | O18: =IF(OR($A18="",$E18=""),"",IF(OR($E18&"|"&$F18="",COUNTIF(ListeIzinliGecis,$E18&"|"&$F18)>0),"","GEÇERSİZ GEÇİŞ")) | P18: =IF($A18="","",IF(OR($I18="",$J18=""),"",IF(ABS($J18-$I18)>zincirTolerans,"ZİNCİR KIRIK","OK"))) | Q18: =IF($A18="","",1)
A19: EYL-00014 | B19: TEH-00014 | C19: 46188 | D19: 46248 | E19: PLANLANDI | F19: DEVAM | G19: Sorumlu 3 | H19: Kontrol eylemi 14 | I19: 16 | J19: 8 | K19: 4000 | L19: =IF($A19="","",IF($C19="","",raporTarihi-$C19)) | M19: =IF($A19="","",IF($L19="","",IF($L19<=7,"0-7",IF($L19<=30,"8-30",IF($L19<=60,"31-60","60+"))))) | N19: =IF($A19="","",IF($B19="","YETİM",IF(COUNTIF(tblEnvanter[TehlikeId],$B19)=0,"YETİM",""))) | O19: =IF(OR($A19="",$E19=""),"",IF(OR($E19&"|"&$F19="",COUNTIF(ListeIzinliGecis,$E19&"|"&$F19)>0),"","GEÇERSİZ GEÇİŞ")) | P19: =IF($A19="","",IF(OR($I19="",$J19=""),"",IF(ABS($J19-$I19)>zincirTolerans,"ZİNCİR KIRIK","OK"))) | Q19: =IF($A19="","",1)
A20: EYL-00015 | B20: TEH-00015 | C20: 46184 | D20: 46249 | E20: DEVAM | F20: BEKLIYOR | G20: Sorumlu 4 | H20: Kontrol eylemi 15 | I20: 10 | J20: 10 | K20: 2500 | L20: =IF($A20="","",IF($C20="","",raporTarihi-$C20)) | M20: =IF($A20="","",IF($L20="","",IF($L20<=7,"0-7",IF($L20<=30,"8-30",IF($L20<=60,"31-60","60+"))))) | N20: =IF($A20="","",IF($B20="","YETİM",IF(COUNTIF(tblEnvanter[TehlikeId],$B20)=0,"YETİM",""))) | O20: =IF(OR($A20="",$E20=""),"",IF(OR($E20&"|"&$F20="",COUNTIF(ListeIzinliGecis,$E20&"|"&$F20)>0),"","GEÇERSİZ GEÇİŞ")) | P20: =IF($A20="","",IF(OR($I20="",$J20=""),"",IF(ABS($J20-$I20)>zincirTolerans,"ZİNCİR KIRIK","OK"))) | Q20: =IF($A20="","",1)
A21: EYL-00016 | B21: TEH-00016 | C21: 46180 | D21: 46250 | E21: PLANLANDI | F21: PLANLANDI | G21: Sorumlu 5 | H21: Kontrol eylemi 16 | I21: 9 | J21: 7 | K21: 2250 | L21: =IF($A21="","",IF($C21="","",raporTarihi-$C21)) | M21: =IF($A21="","",IF($L21="","",IF($L21<=7,"0-7",IF($L21<=30,"8-30",IF($L21<=60,"31-60","60+"))))) | N21: =IF($A21="","",IF($B21="","YETİM",IF(COUNTIF(tblEnvanter[TehlikeId],$B21)=0,"YETİM",""))) | O21: =IF(OR($A21="",$E21=""),"",IF(OR($E21&"|"&$F21="",COUNTIF(ListeIzinliGecis,$E21&"|"&$F21)>0),"","GEÇERSİZ GEÇİŞ")) | P21: =IF($A21="","",IF(OR($I21="",$J21=""),"",IF(ABS($J21-$I21)>zincirTolerans,"ZİNCİR KIRIK","OK"))) | Q21: =IF($A21="","",1)
A22: EYL-00017 | B22: TEH-00017 | C22: 46176 | D22: 46251 | F22: PLANLANDI | G22: Sorumlu 6 | H22: Kontrol eylemi 17 | I22: 12 | J22: 8 | K22: 3000 | L22: =IF($A22="","",IF($C22="","",raporTarihi-$C22)) | M22: =IF($A22="","",IF($L22="","",IF($L22<=7,"0-7",IF($L22<=30,"8-30",IF($L22<=60,"31-60","60+"))))) | N22: =IF($A22="","",IF($B22="","YETİM",IF(COUNTIF(tblEnvanter[TehlikeId],$B22)=0,"YETİM",""))) | O22: =IF(OR($A22="",$E22=""),"",IF(OR($E22&"|"&$F22="",COUNTIF(ListeIzinliGecis,$E22&"|"&$F22)>0),"","GEÇERSİZ GEÇİŞ")) | P22: =IF($A22="","",IF(OR($I22="",$J22=""),"",IF(ABS($J22-$I22)>zincirTolerans,"ZİNCİR KIRIK","OK"))) | Q22: =IF($A22="","",1)
A23: EYL-00018 | B23: TEH-00018 | C23: 46172 | D23: 46252 | E23: PLANLANDI | F23: TAMAMLANDI | G23: Sorumlu 1 | H23: Kontrol eylemi 18 | I23: 6 | J23: 1 | K23: 1500 | L23: =IF($A23="","",IF($C23="","",raporTarihi-$C23)) | M23: =IF($A23="","",IF($L23="","",IF($L23<=7,"0-7",IF($L23<=30,"8-30",IF($L23<=60,"31-60","60+"))))) | N23: =IF($A23="","",IF($B23="","YETİM",IF(COUNTIF(tblEnvanter[TehlikeId],$B23)=0,"YETİM",""))) | O23: =IF(OR($A23="",$E23=""),"",IF(OR($E23&"|"&$F23="",COUNTIF(ListeIzinliGecis,$E23&"|"&$F23)>0),"","GEÇERSİZ GEÇİŞ")) | P23: =IF($A23="","",IF(OR($I23="",$J23=""),"",IF(ABS($J23-$I23)>zincirTolerans,"ZİNCİR KIRIK","OK"))) | Q23: =IF($A23="","",1)
A24: EYL-00019 | B24: TEH-00019 | C24: 46168 | D24: 46253 | E24: DEVAM | F24: BEKLIYOR | G24: Sorumlu 2 | H24: Kontrol eylemi 19 | I24: 20 | J24: 60 | K24: 5000 | L24: =IF($A24="","",IF($C24="","",raporTarihi-$C24)) | M24: =IF($A24="","",IF($L24="","",IF($L24<=7,"0-7",IF($L24<=30,"8-30",IF($L24<=60,"31-60","60+"))))) | N24: =IF($A24="","",IF($B24="","YETİM",IF(COUNTIF(tblEnvanter[TehlikeId],$B24)=0,"YETİM",""))) | O24: =IF(OR($A24="",$E24=""),"",IF(OR($E24&"|"&$F24="",COUNTIF(ListeIzinliGecis,$E24&"|"&$F24)>0),"","GEÇERSİZ GEÇİŞ")) | P24: =IF($A24="","",IF(OR($I24="",$J24=""),"",IF(ABS($J24-$I24)>zincirTolerans,"ZİNCİR KIRIK","OK"))) | Q24: =IF($A24="","",1)
A25: EYL-00020 | B25: TEH-00020 | C25: 46164 | D25: 46234 | E25: TAMAMLANDI | F25: DEVAM | G25: Sorumlu 3 | H25: Kontrol eylemi 20 | I25: 15 | J25: 15 | K25: 3750 | L25: =IF($A25="","",IF($C25="","",raporTarihi-$C25)) | M25: =IF($A25="","",IF($L25="","",IF($L25<=7,"0-7",IF($L25<=30,"8-30",IF($L25<=60,"31-60","60+"))))) | N25: =IF($A25="","",IF($B25="","YETİM",IF(COUNTIF(tblEnvanter[TehlikeId],$B25)=0,"YETİM",""))) | O25: =IF(OR($A25="",$E25=""),"",IF(OR($E25&"|"&$F25="",COUNTIF(ListeIzinliGecis,$E25&"|"&$F25)>0),"","GEÇERSİZ GEÇİŞ")) | P25: =IF($A25="","",IF(OR($I25="",$J25=""),"",IF(ABS($J25-$I25)>zincirTolerans,"ZİNCİR KIRIK","OK"))) | Q25: =IF($A25="","",1)
A26: EYL-00021 | B26: TEH-00021 | C26: 46160 | D26: 46235 | E26: DEVAM | F26: IPTAL | G26: Sorumlu 4 | H26: Kontrol eylemi 21 | I26: 10 | J26: 8 | K26: 2500 | L26: =IF($A26="","",IF($C26="","",raporTarihi-$C26)) | M26: =IF($A26="","",IF($L26="","",IF($L26<=7,"0-7",IF($L26<=30,"8-30",IF($L26<=60,"31-60","60+"))))) | N26: =IF($A26="","",IF($B26="","YETİM",IF(COUNTIF(tblEnvanter[TehlikeId],$B26)=0,"YETİM",""))) | O26: =IF(OR($A26="",$E26=""),"",IF(OR($E26&"|"&$F26="",COUNTIF(ListeIzinliGecis,$E26&"|"&$F26)>0),"","GEÇERSİZ GEÇİŞ")) | P26: =IF($A26="","",IF(OR($I26="",$J26=""),"",IF(ABS($J26-$I26)>zincirTolerans,"ZİNCİR KIRIK","OK"))) | Q26: =IF($A26="","",1)
A27: EYL-00022 | C27: 46156 | D27: 46236 | E27: PLANLANDI | F27: DEVAM | G27: Sorumlu 5 | H27: Kontrol eylemi 22 | I27: 8 | J27: 4 | K27: 2000 | L27: =IF($A27="","",IF($C27="","",raporTarihi-$C27)) | M27: =IF($A27="","",IF($L27="","",IF($L27<=7,"0-7",IF($L27<=30,"8-30",IF($L27<=60,"31-60","60+"))))) | N27: =IF($A27="","",IF($B27="","YETİM",IF(COUNTIF(tblEnvanter[TehlikeId],$B27)=0,"YETİM",""))) | O27: =IF(OR($A27="",$E27=""),"",IF(OR($E27&"|"&$F27="",COUNTIF(ListeIzinliGecis,$E27&"|"&$F27)>0),"","GEÇERSİZ GEÇİŞ")) | P27: =IF($A27="","",IF(OR($I27="",$J27=""),"",IF(ABS($J27-$I27)>zincirTolerans,"ZİNCİR KIRIK","OK"))) | Q27: =IF($A27="","",1)
A28: EYL-00023 | B28: TEH-00023 | C28: 46242 | D28: 46237 | E28: DEVAM | F28: BEKLIYOR | G28: Sorumlu 6 | H28: Kontrol eylemi 23 | I28: 9 | J28: 3 | K28: 2250 | L28: =IF($A28="","",IF($C28="","",raporTarihi-$C28)) | M28: =IF($A28="","",IF($L28="","",IF($L28<=7,"0-7",IF($L28<=30,"8-30",IF($L28<=60,"31-60","60+"))))) | N28: =IF($A28="","",IF($B28="","YETİM",IF(COUNTIF(tblEnvanter[TehlikeId],$B28)=0,"YETİM",""))) | O28: =IF(OR($A28="",$E28=""),"",IF(OR($E28&"|"&$F28="",COUNTIF(ListeIzinliGecis,$E28&"|"&$F28)>0),"","GEÇERSİZ GEÇİŞ")) | P28: =IF($A28="","",IF(OR($I28="",$J28=""),"",IF(ABS($J28-$I28)>zincirTolerans,"ZİNCİR KIRIK","OK"))) | Q28: =IF($A28="","",1)
A29: EYL-00024 | B29: TEH-00024 | C29: 46238 | D29: 46238 | E29: PLANLANDI | F29: PLANLANDI | G29: Sorumlu 1 | H29: Kontrol eylemi 24 | I29: 9 | J29: 1 | K29: 2250 | L29: =IF($A29="","",IF($C29="","",raporTarihi-$C29)) | M29: =IF($A29="","",IF($L29="","",IF($L29<=7,"0-7",IF($L29<=30,"8-30",IF($L29<=60,"31-60","60+"))))) | N29: =IF($A29="","",IF($B29="","YETİM",IF(COUNTIF(tblEnvanter[TehlikeId],$B29)=0,"YETİM",""))) | O29: =IF(OR($A29="",$E29=""),"",IF(OR($E29&"|"&$F29="",COUNTIF(ListeIzinliGecis,$E29&"|"&$F29)>0),"","GEÇERSİZ GEÇİŞ")) | P29: =IF($A29="","",IF(OR($I29="",$J29=""),"",IF(ABS($J29-$I29)>zincirTolerans,"ZİNCİR KIRIK","OK"))) | Q29: =IF($A29="","",1)
A30: EYL-00025 | B30: TEH-99999 | C30: 46234 | D30: 46239 | F30: PLANLANDI | G30: Sorumlu 2 | H30: Kontrol eylemi 25 | I30: 20 | J30: 20 | K30: 5000 | L30: =IF($A30="","",IF($C30="","",raporTarihi-$C30)) | M30: =IF($A30="","",IF($L30="","",IF($L30<=7,"0-7",IF($L30<=30,"8-30",IF($L30<=60,"31-60","60+"))))) | N30: =IF($A30="","",IF($B30="","YETİM",IF(COUNTIF(tblEnvanter[TehlikeId],$B30)=0,"YETİM",""))) | O30: =IF(OR($A30="",$E30=""),"",IF(OR($E30&"|"&$F30="",COUNTIF(ListeIzinliGecis,$E30&"|"&$F30)>0),"","GEÇERSİZ GEÇİŞ")) | P30: =IF($A30="","",IF(OR($I30="",$J30=""),"",IF(ABS($J30-$I30)>zincirTolerans,"ZİNCİR KIRIK","OK"))) | Q30: =IF($A30="","",1)
A31: EYL-00026 | B31: TEH-00002 | C31: 46230 | D31: 46240 | E31: PLANLANDI | F31: DEVAM | G31: Sorumlu 3 | H31: Kontrol eylemi 26 | I31: 12 | J31: 10 | K31: 3000 | L31: =IF($A31="","",IF($C31="","",raporTarihi-$C31)) | M31: =IF($A31="","",IF($L31="","",IF($L31<=7,"0-7",IF($L31<=30,"8-30",IF($L31<=60,"31-60","60+"))))) | N31: =IF($A31="","",IF($B31="","YETİM",IF(COUNTIF(tblEnvanter[TehlikeId],$B31)=0,"YETİM",""))) | O31: =IF(OR($A31="",$E31=""),"",IF(OR($E31&"|"&$F31="",COUNTIF(ListeIzinliGecis,$E31&"|"&$F31)>0),"","GEÇERSİZ GEÇİŞ")) | P31: =IF($A31="","",IF(OR($I31="",$J31=""),"",IF(ABS($J31-$I31)>zincirTolerans,"ZİNCİR KIRIK","OK"))) | Q31: =IF($A31="","",1)
A32: EYL-00027 | B32: TEH-00003 | C32: 46226 | D32: 46241 | E32: DEVAM | F32: BEKLIYOR | G32: Sorumlu 4 | H32: Kontrol eylemi 27 | I32: 15 | J32: 11 | K32: 3750 | L32: =IF($A32="","",IF($C32="","",raporTarihi-$C32)) | M32: =IF($A32="","",IF($L32="","",IF($L32<=7,"0-7",IF($L32<=30,"8-30",IF($L32<=60,"31-60","60+"))))) | N32: =IF($A32="","",IF($B32="","YETİM",IF(COUNTIF(tblEnvanter[TehlikeId],$B32)=0,"YETİM",""))) | O32: =IF(OR($A32="",$E32=""),"",IF(OR($E32&"|"&$F32="",COUNTIF(ListeIzinliGecis,$E32&"|"&$F32)>0),"","GEÇERSİZ GEÇİŞ")) | P32: =IF($A32="","",IF(OR($I32="",$J32=""),"",IF(ABS($J32-$I32)>zincirTolerans,"ZİNCİR KIRIK","OK"))) | Q32: =IF($A32="","",1)
A33: EYL-00028 | B33: TEH-00004 | C33: 46222 | D33: 46242 | E33: BEKLIYOR | F33: TAMAMLANDI | G33: Sorumlu 5 | H33: Kontrol eylemi 28 | I33: 20 | J33: 14 | K33: 5000 | L33: =IF($A33="","",IF($C33="","",raporTarihi-$C33)) | M33: =IF($A33="","",IF($L33="","",IF($L33<=7,"0-7",IF($L33<=30,"8-30",IF($L33<=60,"31-60","60+"))))) | N33: =IF($A33="","",IF($B33="","YETİM",IF(COUNTIF(tblEnvanter[TehlikeId],$B33)=0,"YETİM",""))) | O33: =IF(OR($A33="",$E33=""),"",IF(OR($E33&"|"&$F33="",COUNTIF(ListeIzinliGecis,$E33&"|"&$F33)>0),"","GEÇERSİZ GEÇİŞ")) | P33: =IF($A33="","",IF(OR($I33="",$J33=""),"",IF(ABS($J33-$I33)>zincirTolerans,"ZİNCİR KIRIK","OK"))) | Q33: =IF($A33="","",1)
L34: =IF($A34="","",IF($C34="","",raporTarihi-$C34)) | M34: =IF($A34="","",IF($L34="","",IF($L34<=7,"0-7",IF($L34<=30,"8-30",IF($L34<=60,"31-60","60+"))))) | N34: =IF($A34="","",IF($B34="","YETİM",IF(COUNTIF(tblEnvanter[TehlikeId],$B34)=0,"YETİM",""))) | O34: =IF(OR($A34="",$E34=""),"",IF(OR($E34&"|"&$F34="",COUNTIF(ListeIzinliGecis,$E34&"|"&$F34)>0),"","GEÇERSİZ GEÇİŞ")) | P34: =IF($A34="","",IF(OR($I34="",$J34=""),"",IF(ABS($J34-$I34)>zincirTolerans,"ZİNCİR KIRIK","OK"))) | Q34: =IF($A34="","",1)
L35: =IF($A35="","",IF($C35="","",raporTarihi-$C35)) | M35: =IF($A35="","",IF($L35="","",IF($L35<=7,"0-7",IF($L35<=30,"8-30",IF($L35<=60,"31-60","60+"))))) | N35: =IF($A35="","",IF($B35="","YETİM",IF(COUNTIF(tblEnvanter[TehlikeId],$B35)=0,"YETİM",""))) | O35: =IF(OR($A35="",$E35=""),"",IF(OR($E35&"|"&$F35="",COUNTIF(ListeIzinliGecis,$E35&"|"&$F35)>0),"","GEÇERSİZ GEÇİŞ")) | P35: =IF($A35="","",IF(OR($I35="",$J35=""),"",IF(ABS($J35-$I35)>zincirTolerans,"ZİNCİR KIRIK","OK"))) | Q35: =IF($A35="","",1)
L36: =IF($A36="","",IF($C36="","",raporTarihi-$C36)) | M36: =IF($A36="","",IF($L36="","",IF($L36<=7,"0-7",IF($L36<=30,"8-30",IF($L36<=60,"31-60","60+"))))) | N36: =IF($A36="","",IF($B36="","YETİM",IF(COUNTIF(tblEnvanter[TehlikeId],$B36)=0,"YETİM",""))) | O36: =IF(OR($A36="",$E36=""),"",IF(OR($E36&"|"&$F36="",COUNTIF(ListeIzinliGecis,$E36&"|"&$F36)>0),"","GEÇERSİZ GEÇİŞ")) | P36: =IF($A36="","",IF(OR($I36="",$J36=""),"",IF(ABS($J36-$I36)>zincirTolerans,"ZİNCİR KIRIK","OK"))) | Q36: =IF($A36="","",1)
L37: =IF($A37="","",IF($C37="","",raporTarihi-$C37)) | M37: =IF($A37="","",IF($L37="","",IF($L37<=7,"0-7",IF($L37<=30,"8-30",IF($L37<=60,"31-60","60+"))))) | N37: =IF($A37="","",IF($B37="","YETİM",IF(COUNTIF(tblEnvanter[TehlikeId],$B37)=0,"YETİM",""))) | O37: =IF(OR($A37="",$E37=""),"",IF(OR($E37&"|"&$F37="",COUNTIF(ListeIzinliGecis,$E37&"|"&$F37)>0),"","GEÇERSİZ GEÇİŞ")) | P37: =IF($A37="","",IF(OR($I37="",$J37=""),"",IF(ABS($J37-$I37)>zincirTolerans,"ZİNCİR KIRIK","OK"))) | Q37: =IF($A37="","",1)
L38: =IF($A38="","",IF($C38="","",raporTarihi-$C38)) | M38: =IF($A38="","",IF($L38="","",IF($L38<=7,"0-7",IF($L38<=30,"8-30",IF($L38<=60,"31-60","60+"))))) | N38: =IF($A38="","",IF($B38="","YETİM",IF(COUNTIF(tblEnvanter[TehlikeId],$B38)=0,"YETİM",""))) | O38: =IF(OR($A38="",$E38=""),"",IF(OR($E38&"|"&$F38="",COUNTIF(ListeIzinliGecis,$E38&"|"&$F38)>0),"","GEÇERSİZ GEÇİŞ")) | P38: =IF($A38="","",IF(OR($I38="",$J38=""),"",IF(ABS($J38-$I38)>zincirTolerans,"ZİNCİR KIRIK","OK"))) | Q38: =IF($A38="","",1)
L39: =IF($A39="","",IF($C39="","",raporTarihi-$C39)) | M39: =IF($A39="","",IF($L39="","",IF($L39<=7,"0-7",IF($L39<=30,"8-30",IF($L39<=60,"31-60","60+"))))) | N39: =IF($A39="","",IF($B39="","YETİM",IF(COUNTIF(tblEnvanter[TehlikeId],$B39)=0,"YETİM",""))) | O39: =IF(OR($A39="",$E39=""),"",IF(OR($E39&"|"&$F39="",COUNTIF(ListeIzinliGecis,$E39&"|"&$F39)>0),"","GEÇERSİZ GEÇİŞ")) | P39: =IF($A39="","",IF(OR($I39="",$J39=""),"",IF(ABS($J39-$I39)>zincirTolerans,"ZİNCİR KIRIK","OK"))) | Q39: =IF($A39="","",1)
L40: =IF($A40="","",IF($C40="","",raporTarihi-$C40)) | M40: =IF($A40="","",IF($L40="","",IF($L40<=7,"0-7",IF($L40<=30,"8-30",IF($L40<=60,"31-60","60+"))))) | N40: =IF($A40="","",IF($B40="","YETİM",IF(COUNTIF(tblEnvanter[TehlikeId],$B40)=0,"YETİM",""))) | O40: =IF(OR($A40="",$E40=""),"",IF(OR($E40&"|"&$F40="",COUNTIF(ListeIzinliGecis,$E40&"|"&$F40)>0),"","GEÇERSİZ GEÇİŞ")) | P40: =IF($A40="","",IF(OR($I40="",$J40=""),"",IF(ABS($J40-$I40)>zincirTolerans,"ZİNCİR KIRIK","OK"))) | Q40: =IF($A40="","",1)
L41: =IF($A41="","",IF($C41="","",raporTarihi-$C41)) | M41: =IF($A41="","",IF($L41="","",IF($L41<=7,"0-7",IF($L41<=30,"8-30",IF($L41<=60,"31-60","60+"))))) | N41: =IF($A41="","",IF($B41="","YETİM",IF(COUNTIF(tblEnvanter[TehlikeId],$B41)=0,"YETİM",""))) | O41: =IF(OR($A41="",$E41=""),"",IF(OR($E41&"|"&$F41="",COUNTIF(ListeIzinliGecis,$E41&"|"&$F41)>0),"","GEÇERSİZ GEÇİŞ")) | P41: =IF($A41="","",IF(OR($I41="",$J41=""),"",IF(ABS($J41-$I41)>zincirTolerans,"ZİNCİR KIRIK","OK"))) | Q41: =IF($A41="","",1)
L42: =IF($A42="","",IF($C42="","",raporTarihi-$C42)) | M42: =IF($A42="","",IF($L42="","",IF($L42<=7,"0-7",IF($L42<=30,"8-30",IF($L42<=60,"31-60","60+"))))) | N42: =IF($A42="","",IF($B42="","YETİM",IF(COUNTIF(tblEnvanter[TehlikeId],$B42)=0,"YETİM",""))) | O42: =IF(OR($A42="",$E42=""),"",IF(OR($E42&"|"&$F42="",COUNTIF(ListeIzinliGecis,$E42&"|"&$F42)>0),"","GEÇERSİZ GEÇİŞ")) | P42: =IF($A42="","",IF(OR($I42="",$J42=""),"",IF(ABS($J42-$I42)>zincirTolerans,"ZİNCİR KIRIK","OK"))) | Q42: =IF($A42="","",1)
...

Sheet AKIS
A1: AKIS — İSG Risk Değerlendirme Pro (6331)
A3: Eylem akış özeti — KAYNAK_KART_ID / yetim / kuyruk (EYLEM_PLANI ile bağlı)
A5: KAYNAK_KART_ID kontrolü
A6: Yetim (YETİM) adet | B6: =COUNTIF(tblEylem[YetimBayrak],"YETİM")
A7: Geçersiz geçiş | B7: =COUNTIF(tblEylem[GecisUyarisi],"GEÇERSİZ GEÇİŞ")
A8: Zincir kırık | B8: =COUNTIF(tblEylem[ZincirBayrak],"ZİNCİR KIRIK")
A10: Kuyruk | B10: Adet | C10: Tutar
A11: Planlandı | B11: =COUNTIFS(tblEylem[durum],"PLANLANDI",tblEylem[tutar],">0") | C11: =SUMIFS(tblEylem[tutar],tblEylem[durum],"PLANLANDI")
A12: Devam | B12: =COUNTIFS(tblEylem[durum],"DEVAM",tblEylem[tutar],">0") | C12: =SUMIFS(tblEylem[tutar],tblEylem[durum],"DEVAM")
A13: Bekliyor | B13: =COUNTIFS(tblEylem[durum],"BEKLIYOR",tblEylem[tutar],">0") | C13: =SUMIFS(tblEylem[tutar],tblEylem[durum],"BEKLIYOR")
A15: Kapalı (Tamamlandı+İptal) kuyruktan düşer
A16: Tamamlandı | B16: =COUNTIFS(tblEylem[durum],"TAMAMLANDI",tblEylem[tutar],">0")
A17: İptal | B17: =COUNTIFS(tblEylem[durum],"IPTAL",tblEylem[tutar],">0")

Sheet KANIT_RAPORU
A1: KANIT RAPORU — İSG Risk Değerlendirme Pro (6331)
A3: Denetim Kanıt Raporu — 6331 Risk Değerlendirme
A4: Ürün | B4: İSG Risk Değerlendirme Pro (6331)
A5: Sürüm | B5: 1.0.0
A6: Rapor türü | B6: Kanıt çıktısı — müşteriye/imza için
A7: Ortam | B7: Çevrimdışı · makro yok · telemetri yok
A8: Rapor Tarihi | B8: =raporTarihi
A9: KARAR | B9: =PANO!B4
A11: Tehlike Adet | B11: =isg_tehlikeAdet
A12: Kritik Adet | B12: =isg_kritikAdet
A13: Uyum Oranı | B13: =isg_uyumOrani
A14: Yetim | B14: =isg_yetimKayit
A15: Geçersiz Geçiş | B15: =isg_gecersizGecis
A16: Zincir Kırık | B16: =isg_zincirKirik
A17: Madde Atıf | B17: =isg_maddeAtif
A18: Kanıt Özeti | B18: =isg_kanitRaporu
A19: Skor Dağılım | B19: =isg_skorDagilim
A20: Yenileme Takvim | B20: =isg_yenilemeTakvim
A21: Revizyon Geçmişi | B21: =isg_revizyonGecmisi
A23: Hesap Zinciri
A24: Olasılık × Şiddet (L) veya Olasılık × Frekans × Şiddet (FK) → HamSkor → RiskSeviye → Eylem durum makinesi → PANO kararı.
A26: Varsayımlar ve Belirsizlik
A27: Matris seçimi (L-matris / Fine-Kinney) kullanıcı tercihidir; aynı girdiler farklı skor üretebilir. Bu çıktı karar destektir; kesin hukuki/iş güvenliği görüşü yerine geçmez. KVKK: kişisel veri toplanmaz, çevrimdışı çalışır.
A28: =isg_kvkkBeyani
A30: İmza / Onay
A31: Hazırlayan
A32: Kontrol eden
A33: Tarih | B33: =raporTarihi
A34: Kaşe / imza
A36: SHA-256 sevk anında KANIT/SEVK_KARARI.md ve denetim raporlarına yazılır; alıcı indirdiği dosyayı parmak iziyle doğrular.
A38: Sürüm 1.0.0 | Bu dosya karar destek aracıdır.

Sheet KONTROLLER
A1: KONTROLLER — İSG Risk Değerlendirme Pro (6331)
A3: Canlı Kontrol Paneli
A5: Tehlike sayısı | B5: =COUNTA(tblEnvanter[TehlikeId])
A6: Eylem sayısı | B6: =COUNTA(tblEylem[EylemId])
A7: Kritik | B7: =isg_kritikAdet
A8: Planlandı | B8: =COUNTIF(tblEylem[Durum],"PLANLANDI")
A9: Devam | B9: =COUNTIF(tblEylem[Durum],"DEVAM")
A10: Bekliyor | B10: =COUNTIF(tblEylem[Durum],"BEKLIYOR")
A11: Tamamlandı | B11: =COUNTIF(tblEylem[Durum],"TAMAMLANDI")
A12: Yetim | B12: =isg_yetimKayit
A13: Geçersiz | B13: =isg_gecersizGecis
A14: Zincir kırık | B14: =isg_zincirKirik
A15: Boş karar yolu | B15: =IF(B5=0,"VERİ YOK","VERİ VAR")
A16: Kalite skoru | B16: =DEGERLENDIRME!C56
A17: Uyum oranı | B17: =isg_uyumOrani
A18: Gecikme maliyeti | B18: =isg_gecikmeMaliyeti
A19: Kapalı düşüm | B19: =isg_kapaliDusum

Sheet ORNEK_VERI
A1: ORNEK VERI — İSG Risk Değerlendirme Pro (6331)
A3: Örnek Senaryo Açıklaması
A4: Dosyada 24 tehlike ve 28 eylem satırı vardır. Yetim (22, 25), geçersiz geçiş (18, 20) ve zincir kırık (12, 19) kasıtlıdır. ENVANTER ve EYLEM_PLANI'nı temizleyip kendi verinizi girebilirsiniz.
A6: Örnek özet (bilgi)
A7: Durumlar: Planlandı/Devam/Bekliyor/Tamamlandı/İptal — kapalılar kuyruktan düşer
A9: Ölçek sözleşmesi | B9: 5000

Sheet LISTELER
A1: LISTELER — İSG Risk Değerlendirme Pro (6331)
A3: Durum Listesi | C3: İzinli Geçişler | E3: Evet / Hayır | G3: Madde Atıf | I3: Matris Tipi
A6: DurumId | C6: Gecis | E6: Secim | G6: Madde | I6: Tip
A7: PLANLANDI | C7: PLANLANDI|DEVAM | E7: EVET | G7: ISG-001 | I7: L
A8: DEVAM | C8: PLANLANDI|IPTAL | E8: HAYIR | G8: ISG-002 | I8: FK
A9: BEKLIYOR | C9: DEVAM|BEKLIYOR | G9: ISG-003
A10: TAMAMLANDI | C10: DEVAM|TAMAMLANDI
A11: IPTAL | C11: DEVAM|IPTAL
C12: BEKLIYOR|DEVAM
C13: BEKLIYOR|TAMAMLANDI
C14: BEKLIYOR|IPTAL

Sheet AYARLAR
A1: AYARLAR — İSG Risk Değerlendirme Pro (6331)
A3: Tek kaynak parametreler + durum haritası + puanlama matrisi
A5: anahtar | B5: deger | C5: birim | D5: kaynak | E5: yururluk_tarihi | F5: aciklama
A6: raporTarihi | B6: 46244 | C6: tarih | D6: Kullanıcı / dönem kapanışı | E6: 01.01.2026 | F6: Rapor tarihi (TODAY yok)
A7: zincirTolerans | B7: 15 | C7: skor | D7: İş kuralı — skor sapma | E7: 01.01.2026 | F7: ZİNCİR KIRIK eşiği (ilk-hedef)
A8: isg_matrisTipi | B8: L | C8: metin | D8: Kullanıcı seçimi L/FK | E8: 01.01.2026 | F8: L-matris veya Fine-Kinney
A9: isg_esikGecikmeGun | B9: 30 | C9: gün | D9: İç politika | E9: 01.01.2026 | F9: Gecikme eşiği
