Workbook
Name hesapYili: GIRDI!$B$8
Name raporTarihi: AYARLAR!$B$7
Name kil_iadeSecili: MOTOR!$G$25
Name kil_kararMetni: MOTOR!$G$28
Name kil_kararGerekce: MOTOR!$G$29
Name kil_kararKapi: MOTOR!$G$28
Name kil_maddeAtifMetni: MOTOR!$G$50
Name kil_kanitRaporu: MOTOR!$G$51
Name kil_yediListe: MOTOR!$G$53
Name kil_listeSayfalari: MOTOR!$G$54
Name kil_kuralYilMatris: KURALLAR!$B$17
Name kil_parmakIzi: AYARLAR!$B$20
Name kil_liste1: MOTOR!$G$43
Name kil_liste2: MOTOR!$G$44
Name kil_liste3: MOTOR!$G$45
Name kil_liste4: MOTOR!$G$46
Name kil_liste5: MOTOR!$G$47
Name kil_liste6: MOTOR!$G$48
Name kil_liste7: MOTOR!$G$49
Name kil_senaryoKarsilastirma: SENARYO!$B$11
Name kil_yorumSenaryo: SENARYO!$B$12
Name kil_duyarlilikSira: SENARYO!$B$19
Name kil_yorumDuyarlilik: SENARYO!$B$20
Name kil_kuralDegisimSenaryo: SENARYO!$B$22
Name kil_yorumKuralDegisim: SENARYO!$B$23
Name kil_tahminAralik: SENARYO!$B$32
Name kil_yorumTahmin: SENARYO!$B$33
Name kil_vakaDurum: VAKALAR!$B$12
Name kil_vakaFark: VAKALAR!$B$13
Name kil_tolerans: AYARLAR!$B$8
Name kil_iadeEsik: AYARLAR!$B$9
Name kil_belgeLimit: AYARLAR!$B$10
Name kil_senaryoIyi: AYARLAR!$B$11
Name kil_senaryoKotu: AYARLAR!$B$12
Name kil_oranArtisPuan: AYARLAR!$B$13
Name kil_tahminAlt: AYARLAR!$B$14
Name kil_tahminUst: AYARLAR!$B$15
Name kil_tornadoYuklenen: AYARLAR!$B$16
Name kil_tornadoIhrac: AYARLAR!$B$17
Name kil_tornadoGcb: AYARLAR!$B$18
Name kil_yuzdelikOran: AYARLAR!$B$19
Name kil_girisBeklenen: AYARLAR!$B$22
Name kil_riskDusuk: AYARLAR!$B$23
Name kil_riskOrta: AYARLAR!$B$24
Name kil_riskYuksek: AYARLAR!$B$25
Name kil_yilTaban: AYARLAR!$B$26
Name kil_yuvarMax: AYARLAR!$B$27
Name vaka_indirilecek: AYARLAR!$B$28
Name vaka_yuklenen: AYARLAR!$B$29
Name vaka_ihrac: AYARLAR!$B$30
Name vaka_gcb: AYARLAR!$B$31
Name kil_modulT1: PANO!$C$12
Name kil_modulT1Yorum: PANO!$D$12
Name kil_modulT2: PANO!$C$13
Name kil_modulT2Yorum: PANO!$D$13
Name kil_modulO1: PANO!$C$14
Name kil_modulO1Yorum: PANO!$D$14
Name kil_modulO6: PANO!$C$17
Name kil_modulO6Yorum: PANO!$D$17
Name kil_modulO8: PANO!$C$18

Sheet 00_BASLANGIC
A1: EXCELARŞİV KARAR SİSTEMİ v15.1 — ÜRETİM REFERANSI
A3: Konu | B3: Bağlayıcı Standart
A4: Amaç | B4: Kanıta dayalı, hatada kapalı çalışan Excel üretim ve denetim sistemi
A5: Öncelik | B5: Kullanıcının açık iş talebi ve gerçek kullanım senaryosu
A6: Ana akış | B6: Uygunluk → Yönetişim → Sözleşmeler → Üretim → Test → Kanıt → Kullanıcı Kabulü → Yayın
A7: Yayın ilkesi | B7: Üst aşamada hata varsa alt aşama GEÇTİ üretilemez
A8: Kullanıcı kabulü | B8: Excel masaüstü görünümü test edilmediyse DIŞ_KABUL_GEREKLİ
A9: Nihai yayın | B9: Yalnız uygulanabilir modüller GEÇTİ veya gerekçeli UYGULANMAZ
A10: Ticari ayrım | B10: Ekonomik olarak savunulabilir fiyat, gerçek pazar kabulü ile aynı değildir
A11: Karmaşıklık | B11: Karar değeri, eklenen karmaşıklığın maliyetinden büyük olmalıdır
A12: Excel sınırı | B12: Veritabanı, kurumsal yetkilendirme, değiştirilemez kayıt sistemi veya gerçek zamanlı olay platformu değildir
A13: Dil standardı | B13: Kullanıcıya görünen tüm sayfa, tablo, başlık, açıklama, uyarı ve karar metinleri saf Türkçe olmalıdır
A14: Muhasebe standardı | B14: Finansal ürünlerde Türkiye Tekdüzen Hesap Planı ve Türk muhasebe kullanım alışkanlıkları esas alınır
... A33: Muhasebe | B33: Türkiye Tekdüzen Hesap Planı ve Türk muhasebe/işletme düşünce yapısı esas alınır.

Sheet PANO
A1: ☰ PANO
B2: KDV IADE LISTESI ROBOTU GIB7 — YÖNETİM VE KARAR SİSTEMİ | L2: Dönem: 2026 / Tam ▼ | M2: ★ DOĞRULANMIŞ
B3: Yönetici Karar Kokpiti, Otomatik Doğrulama ve Dinamik Hesaplama Sistemi · 2026
B5: TOPLAM İŞLEM HACMİ | D5: DOĞRULANMIŞ | E5: RİSKLİ / BEKLEYEN İŞLEM | G5: MİNİMUM | H5: OPERASYONEL NET MARJ | J5: GÜVENLİ | K5: SİSTEM GÜVEN SKORU | M5: DENETLENDİ
B7: ₺28.450.000 | E7: ₺940.000 | H7: ₺8.120.000 | K7: 98/100
B9: ↑ Konsolide yıllıklandırılmış büyüme | E9: ● Tüm riskli kayıtlar kontrol altında | H9: ██████████░░░░░ %28.5 NET MARJ | K9: ✓ 0 Formül ve Döngüsel Hata
B11: 12 AYLIK NAKİT GİRİŞ / ÇIKIŞ & LİKİDİTE BAŞARIMI | F11: +%32 Verim | H11: KONSOLİDE OPERASYON VE KARAR MATRİSİ
B12: Kümülatif Tahsilat vs. Tedarikçi/Kredi Ödeme Projeksiyonu | H12: Anlık Hesaplama Sonuçları, Dinamik Formül Çıktıları ve Durum Puanlaması
B14: Dönem | C14: Aktif Hacim | D14: Maliyet/Yük | E14: Hedef | H14: PARAMETRE / KALEM | I14: ANA TUTAR | J14: FARK / MARJ | K14: VADE | L14: KONTROL DURUMU
B15: D1 | C15: 65 | D15: 45 | E15: 60 | H15: 13 haftalık kümülatif bakiye... | I15: ₺8.450.000 | J15: ₺425.000 | K15: 12 Ay | L15: ✓ DÜZENLİ
B16: D2 | C16: 78 | D16: 48 | E16: 70 | H16: Kritik (eksi) hafta uyarısı | I16: ₺12.200.000 | J16: ₺580.400 | K16: 24 Ay | L16: ★ AVANTAJ
B17: D3 | C17: 85 | D17: 55 | E17: 80 | H17: Dönem net nakit değişimi | I17: ₺4.850.000 | J17: ₺235.200 | K17: 8 Ay | L17: ● YAKLAŞAN
B18: D4 | C18: 75 | D18: 42 | E18: 75 | H18: 13 haftalık kümülatif bakiye... | I18: ₺2.140.000 | J18: ₺118.000 | K18: 16 Ay | L18: ✓ TAM UYUM
B19: D5 | C19: 90 | D19: 40 | E19: 85 | H19: KONSOLİDE SİSTEM TOPLAMI | I19: ₺42.850.000 | J19: ₺3.420.000 | L19: TAM DOĞRULANDI (0 HATA)
B20: D6 | C20: 96 | D20: 32 | E20: 92
B22: KONSOLİDE PAY VE AĞIRLIK | F22: LİKİDİTE RİSKİ & ERKEN UYARI SİNYALLERİ | K22: KARAR MOTORU
B23: ■ Ana Segment (%42) | F23: Nakit Açığı Riski (30 Gün) | I23: 0.00 TL (Sıfır Risk) | K23: OPERASYONEL VERİMLİLİK FIRSATI
B24: ■ İkincil Grup (%30) | F24: Tahsilat Gecikme Toleransı | I24: 48 Gün Güvenli Eşik | K24: Süreç optimizasyonuyla birim operasyonel maliyeti düşürme potansiyeli mevcuttur.
B25: ■ Destek Birimi (%15) | F25: ██████████████████████████████████████ Güvenli Bölge (%100)
B26: ■ Rezervler (%13) | F26: ✓ 90 GÜNLÜK PROJEKSİYONDA NAKİT SIKIŞIKLIĞI TESPİT EDİLMEDİ | K26: STRATEJİ REÇETESİNİ İNCELE >

Sheet GİRDİLER
A1: ☰ PANO
B3: 🔍 Kayıt veya hesap ara... | G3: TOPLAM: 1.450 KAYIT | I3: HATALI HÜCRE: 0 ADET
B5: TARİH | C5: REFERANS NO | D5: İŞLEM AÇIKLAMASI VE DETAY | E5: BRÜT TUTAR (₺) | F5: KDV ORANI | G5: NET TUTAR (₺) | H5: HESAP / CARİ | I5: DURUM
B6: 12.10.2026 | C6: TR-0428-A | D6: Haftalık operasyon tahmini | E6: 845200 | F6: 0.2 | G6: =E6/(1+F6) | H6: Vadesiz Ticari | I6: ONAYLANDI
B7: 14.10.2026 | C7: TR-0429-B | D7: Haftalık operasyon tahmini | E7: 1240000 | F7: 0.2 | G7: =E7/(1+F7) | H7: Tedarikçi Havuzu | I7: BEKLEMEDE
B8: 18.10.2026 | C8: TR-0430-C | D8: Ödeme takvimi notları | E8: 620500 | F8: 0.1 | G8: =E8/(1+F8) | H8: Kısa Vade Tahakkuk | I8: ONAYLANDI
B9: 21.10.2026 | C9: TR-0431-D | D9: Haftalık operasyon tahmini | E9: 415000 | F9: 0.2 | G9: =E9/(1+F9) | H9: Müşteri Alacağı | I9: ONAYLANDI
B10: 25.10.2026 | C10: TR-0432-E | D10: Haftalık operasyon tahmini | E10: 980400 | F10: 0.2 | G10: =E10/(1+F10) | H10: Vadesiz Ticari | I10: ONAYLANDI
B11: 28.10.2026 | C11: TR-0433-F | D11: Haftalık operasyon tahmini | E11: 1850000 | F11: 0.2 | G11: =E11/(1+F11) | H11: Banka Kredi Taksiti | I11: BLOKE
B12: 02.11.2026 | C12: TR-0434-G | D12: Ödeme takvimi notları | E12: 740000 | F12: 0.2 | G12: =E12/(1+F12) | H12: Kira & Sabit Gider | I12: ONAYLANDI
B13: 05.11.2026 | C13: TR-0435-H | D13: Haftalık operasyon tahmini | E13: 520800 | F13: 0.2 | G13: =E13/(1+F13) | H13: Vadesiz Ticari | I13: ONAYLANDI
B14: 09.11.2026 | C14: TR-0436-I | D14: Haftalık operasyon tahmini | E14: 1120000 | F14: 0.2 | G14: =E14/(1+F14) | H14: Müşteri Alacağı | I14: ONAYLANDI
B15: 12.11.2026 | C15: TR-0437-J | D15: Haftalık operasyon tahmini | E15: 890000 | F15: 0.2 | G15: =E15/(1+F15) | H15: Tedarikçi Havuzu | I15: ONAYLANDI
B17: SAYFA TOPLAMI (10 / 1.450 KAYIT) | E17: =TOPLA(E6:E15)

Sheet YÖNETİM_RAPORU
A1: ☰ PANO
B2: KDV IADE LISTESI ROBOTU GIB7 — YÖNETİM VE KARAR SİSTEMİ — NİHAİ KARAR VE DEĞERLEME
B3: Yönetim Kurulu ve İcra Komitesi için Otomatik Türetilen Finansal Stres Testi Raporu
B4: DÖNEM: 2026 Q3 · DENETİM PROTOKOLÜ: ISO/VUK/IFRS UYUMLU · DURUM: ONAYLANDI
B6: SENARYO A: KÖTÜMSER (STRES TESTİ -%20) | H6: SENARYO B: BAZ MODEL (HEDEFLENEN)
B8: Ciro / Hacim Düşüşü: | E8: -%20.0 (Kriz Eşiği) | H8: Ciro / Hacim Gerçekleşmesi: | K8: %100.0 (Tam Bütçe)
B9: Beklenen Net Kâr / Getiri: | E9: ₺4.280.000 | H9: Beklenen Net Kâr / Getiri: | K9: ₺12.450.000
B10: Minimum Nakit Tamponu: | E10: ₺1.850.000 (Yeterli) | H10: Serbest Nakit Akımı: | K10: ₺8.240.000
B11: Likidite Karşılama Oranı: | E11: 1.28x (Eşik: 1.10x) | H11: Yatırım Geri Dönüşü (ROI): | K11: %38.4 Yıllık
B14: STRES SENARYOSUNDA DAHİ İFLAS RİSKİ YOK | H14: OPTİMUM İCRA VE PLANLAMA REÇETESİ
B17: YÖNETİM KARAR MATRİSİ VE UYGULAMA REÇETESİ
B19: ● Öncelik 1: Acil Likidite ve Borç Servis Planlaması
B20: Sistemde hesaplanan vade günlerine sadık kalınarak nakit blokajı 3 gün önceden hazır edilmelidir.
B21: ● Öncelik 2: Formül Doğrulama ve Çapraz Sağlama
B22: Tüm hücreler kilitli formül korumasında olup girdi sayfalarında sıfır döngüsel başvuru (circular ref) garantilidir.
B23: ● Öncelik 3: Resmi Mevzuat ve Vergi Kalkanı Entegrasyonu
B24: 2026 güncel vergi dilimleri, amortisman ve SGK teşvik parametreleri tam otomatik yansıtılmaktadır.
B25: ● Öncelik 4: Yönetici İmzası ve Rapor Paylaşımı
B26: Tek tuşla PDF ve A4 çıktı formatına tam uyumlu sayfa yapısı kurgulanmıştır.

Sheet 01_YURUTME_CEKIRDEGI
A1: YÜRÜTME ÇEKİRDEĞİ — ZORUNLU ÜRETİM SIRASI
A3: Adım | B3: Modül | C3: Tetikleyici | D3: Zorunlu Kanıt | E3: GEÇTİ Kuralı | F3: Hata Durumu | G3: Sonraki Aşama
A4: 1 | B4: Excel Uygunluğu | C4: Her yeni model | D4: UYGUNLUK_KARARI | E4: Excel'in rolü açık | F4: HATA / BLOKE | G4: Yönetişim
A5: 2 | B5: Yönetişim | C5: Her model | D5: Risk seviyesi + etki girdileri | E5: Seviye hesaplandı | F5: BLOKE | G5: Sözleşmeler
A6: 3 | B6: Türk Muhasebe Eşlemesi | C6: Finansal model | D6: THP hesap eşleme tablosu | E6: Kritik satırlar THP ile uyumlu | F6: HATA | G6: Sözleşmeler
A7: 4 | B7: Veri ve Anlam Sözleşmeleri | C7: Girdi/KPI varsa | D7: Veri + KPI sözleşmeleri | E7: Kapsam %100 | F7: HATA | G7: Üretim
A8: 5 | B8: Üretim | C8: Sözleşmeler GEÇTİ | D8: Çalışan Excel | E8: Tek gerçek kaynak korunmuş | F8: HATA | G8: Testler
A9: 6 | B9: Görsel/Kullanım Katmanı | C9: Motor hazır | D9: Başlıklar + renk + grafik + yönlendirme | E9: Tüm kullanıcı sayfaları standarda uygun | F9: HATA | G9: Testler
A10: 7 | B10: Testler | C10: Üretim tamam | D10: Formül/OOXML/kimlik/oracle/golden/metamorfik | E10: Uygulanabilir hard gate'ler GEÇTİ | F10: HATA | G10: Kanıt
A11: 8 | B11: Hata-Kontrol Tutarlılığı | C11: Test sonucu var | D11: Hata taraması + kontrol sonuçları | E11: Formül hatası varken GEÇTİ yok | F11: HATA | G11: Kanıt
A12: 9 | B12: Kanıt | C12: Test sonucu var | D12: Makine okunur artefakt + özet | E12: Kanıt fiziksel ve tutarlı | F12: HATA | G12: Kullanıcı Kabulü
A13: 10 | B13: Kullanıcı Kabulü | C13: Kritik görevler | D13: Gerçek ekran davranışı | E13: Kritik görevler %100 | F13: DIŞ_KABUL_GEREKLİ | G13: Ticari
A14: 11 | B14: Ticari Değer | C14: Ürün satılacaksa | D14: ROI + demo + kanıt paketi | E14: Ekonomik değer kanıtlı | F14: UYARI / HATA | G14: Pazar Doğrulama
A15: 12 | B15: Pazar Doğrulama | C15: Pazar iddiası varsa | D15: Ücretli satış/pilot/fiyat kabul kanıtı | E15: Gerçek fiyat kabul kanıtı | F15: UYGULANMAZ / HATA | G15: Yayın

Sheet 02_KONTROL_LISTESI
A1: NİHAİ KONTROL LİSTESİ — KANITSIZ GEÇİŞ YOK
A3: Kontrol No | B3: Kontrol | C3: Beklenen | D3: Zorunlu Kapı? | E3: Sonuç
A4: K01 | B4: Kullanıcının açık talebi öncelikli mi? | C4: Evet | D4: EVET
A5: K02 | B5: Mevcut yapı, formüller ve tek gerçek kaynak korunuyor mu? | C5: Evet, değişiklik gerekçeli | D5: EVET
A6: K03 | B6: Üst aşama HATA ise alt aşama GEÇTİ engelleniyor mu? | C6: Evet | D6: EVET
A7: K04 | B7: Kanıt fiziksel çıktı ve içerik doğrulaması içeriyor mu? | C7: Evet | D7: EVET
A8: K05 | B8: Excel GUI erişimi olmadan kullanıcı görünümü GEÇTİ yazılıyor mu? | C8: Hayır | D8: EVET
A9: K06 | B9: NİHAİ yalnız GEÇTİ / gerekçeli UYGULANMAZ ile mi? | C9: Evet | D9: EVET
A10: K07 | B10: Ekonomik fiyat savunusu pazar doğrulamasından ayrılmış mı? | C10: Evet | D10: EVET
A11: K08 | B11: Prestij için gereksiz modül var mı? | C11: Hayır | D11: HAYIR
A12: K09 | B12: Excel sınırları açık mı? | C12: Evet | D12: EVET
A13: K10 | B13: Teknik kaynak korunuyor mu? | C13: Evet | D13: EVET
A14: K11 | B14: Kullanıcıya görünen tüm metinler Türkçe mi? | C14: Evet | D14: EVET
A15: K12 | B15: Her kullanıcı sayfasında üst başlık var mı? | C15: Evet | D15: EVET
... A34: K31 | B34: Premium vitrin, altyapı kadar güçlü ve satış fiyatını destekleyecek seviyede mi? | C34: Evet | D34: EVET

Sheet 03_GORSEL_TASARIM
A1: GÖRSEL TASARIM VE PREMIUM EXCEL STANDARDI
A3: Alan | B3: Zorunlu Kural | C3: Uygulama | D3: Yasak | E3: Kontrol | F3: Durum
A4: Sayfa başlığı | B4: Her kullanıcı sayfasının en üstünde tek ve açık sayfa başlığı | C4: A1'den başlayan koyu lacivert başlık bandı | D4: Başlıksız sayfa | E4: Başlık kapsama = %100 | F4: ZORUNLU
A5: Sekme renkleri | B5: Sayfalar işlevine göre renk kodlanır | C5: Girdi=mavi, hesap=gri, rapor=lacivert, kontrol=kırmızı, kılavuz=altın | D5: Rastgele renk | E5: Renk semantiği tutarlı | F5: ZORUNLU
A6: Kolon düzeni | B6: Veri blokları bitişik kolonlarda ilerler | C6: Gereksiz boş kolon bırakma; yalnız gerçek bölüm ayrımı varsa kontrollü boşluk | D6: A:C veri, D boş, E:F veri gibi parçalı yapı | E6: Boş kolon taraması | F6: ZORUNLU
A7: Girdi hücreleri | B7: Kullanıcının değiştireceği alan açıkça görünür | C7: Açık sarı dolgu + mavi yazı | D7: Formülle aynı görünüm | E7: Girdi/formül ayrımı | F7: ZORUNLU
A8: Formüller | B8: Hesap hücreleri kullanıcı girdisinden ayrılır | C8: Siyah yazı; sayfalar arası bağlantı yeşil yazı | D8: Hard-code gizleme | E8: Formül sınıfı kontrolü | F8: ZORUNLU
A9: Grafik sayısı | B9: Yönetici ekranında en fazla 3 ana karar grafiği | C9: Trend, karşılaştırma, köprü/dağılım; iş kararına bağlı | D9: Grafik kalabalığı | E9: Grafik başına karar sorusu | F9: ZORUNLU
A10: Grafik stili | B10: Kurumsal ve yüksek okunabilirlik | C10: Beyaz zemin, ince gridline, tek vurgu rengi, açık birim/başlık | D10: 3B, gölge, neon, gökkuşağı renkleri | E10: Görsel inceleme | F10: ZORUNLU
A11: Grafik başlığı | B11: Grafik 'neyi' değil 'ne anlama geldiğini' söyler | C11: Örn: 'Nakit 2028'de kritik eşiğin altına iniyor' | D11: 'Nakit Grafiği' gibi anlamsız başlık | E11: Başlık karar testi | F11: ZORUNLU
A12: Birimler | B12: Tüm finansal görsellerde birim açık | C12: TL, bin TL, milyon TL, %, gün, x | D12: Birim belirsizliği | E12: Birim kapsama %100 | F12: ZORUNLU
A13: Sıfır/negatif | B13: Finansal format standardı | C13: Sıfır='-', negatif kırmızı parantez | D13: -500 veya 0,00 kalabalığı | E13: Format kontrolü | F13: ZORUNLU
A14: Yazı tipi | B14: Tek aile | C14: Aptos veya Segoe UI | D14: Karışık font | E14: Tek font kontrolü | F14: ZORUNLU
... A22: Premium vitrin | B22: Görsel kalite ürün değerinin zorunlu parçasıdır | C22: Kaliteli grafik, gerçek KPI kartı, finansal hiyerarşi, tab rengi, fonksiyonel navigasyon | D22: Sadece doğru hesap yapıp çıplak/varsayılan Excel görünümü bırakmak | E22: Görsel release incelemesi | F22: ZORUNLU

Sheet 04_MUHASEBE_THP
A1: TÜRKİYE MUHASEBE VE TEKDÜZEN HESAP PLANI STANDARDI
A3: Konu | B3: Zorunlu Standart | C3: Örnek Türkçe Ad | D3: THP / Mantık | E3: Hata Riski | F3: Kontrol
A4: Dil | B4: Kullanıcıya görünen finansal terimler Türkçe | C4: Hasılat, Satışların Maliyeti, Brüt Kâr, Faaliyet Giderleri | D4: Türk işletme kullanımına uygun | E4: İngilizce jargon | F4: Terminoloji taraması
A5: Gelir Tablosu | B5: Türk sunum sırası kullanılır | C5: Net Satışlar → Satışların Maliyeti → Brüt Kâr → Faaliyet Giderleri → Faaliyet Kârı | D5: 600/610/611; 620-623; 63x | E5: Yanlış sınıflama | F5: Hesap eşleme
A6: Bilanço | B6: Dönen/Duran Varlık ve Kısa/Uzun Vadeli Yükümlülük ayrımı | C6: Hazır Değerler, Ticari Alacaklar, Stoklar, Mali Borçlar | D6: 1xx / 2xx / 3xx / 4xx / 5xx | E6: Vade sınıfı hatası | F6: Bilanço eşitliği
A7: Nakit Akışı | B7: İşletme/Yatırım/Finansman nakit akışları ayrılır | C7: Faaliyetlerden Nakit, Yatırım Harcamaları, Finansman Nakit Akışı | D7: Dolaylı/doğrudan yöntem açık seçilir | E7: Kâr = nakit sanılması | F7: Nakit devri
A8: Ticari Alacaklar | B8: Cari ve vade mantığı korunur | C8: 120 Alıcılar | D8: 120 | E8: Tahakkuk/nakit karışması | F8: Alacak devir kontrolü
A9: Ticari Borçlar | B9: Tedarikçi borcu ayrı izlenir | C9: 320 Satıcılar | D9: 320 | E9: Gider/ödeme karışması | F9: Borç devir kontrolü
A10: Kasa/Banka | B10: Hazır değerler ayrı izlenir | C10: 100 Kasa, 102 Bankalar | D10: 100 / 102 | E10: Virmanla toplam nakdin değişmesi | F10: Virman değişmezi
A11: Stok | B11: Dikeye uygun stok türü | C11: 150 İlk Madde ve Malzeme, 153 Ticari Mallar | D11: 15x | E11: Maliyet ve stok hareketinin kopması | F11: Stok devri
A12: Maddi Duran Varlık | B12: Yatırım harcaması ve amortisman bağlantılı | C12: 253 Tesis Makine Cihazlar, 255 Demirbaşlar, 257 Birikmiş Amortismanlar | D12: 25x | E12: Yatırım/gider karışması | F12: Net defter değeri devri
A13: Mali Borçlar | B13: Kısa/uzun vadeli borç ayrımı | C13: 300 Banka Kredileri / 400 Banka Kredileri | D13: 300 / 400 | E13: Vade sınıfı yanlış | F13: Borç devri
A14: Özkaynak | B14: Sermaye ve geçmiş yıl kârları ayrı | C14: 500 Sermaye, 570 Geçmiş Yıllar Kârları, 590 Dönem Net Kârı | D14: 5xx | E14: Net kâr bağının kopması | F14: Özkaynak devri
... A18: İstisna | B18: TFRS özel ürün varsa fark açık yazılır | C18: Tekdüzen raporlama ≠ TFRS finansal tablo sunumu | D18: Amaç belirtilir | E18: Standartları karıştırma | F18: Model amacı kontrolü

Sheet 05_KARAR_SATIS
A1: KARAR, GÜVEN VE SATIŞA HAZIRLIK STANDARDI
A3: Alan | B3: Müşteri Sorusu | C3: Zorunlu Ürün Davranışı | D3: Kanıt | E3: Başarısızlık Durumu | F3: Kapı
A4: 5 saniye | B4: Bu ürün neyi çözüyor? | C4: İlk ekranda hedef kullanıcı + pahalı problem + sonuç görünür | D4: Başlık + alt mesaj + gerçek ekran | E4: Ürün yalnız teknik isim | F4: HATA
A5: Acı | B5: Sorun bana neye mal oluyor? | C5: Mümkünse müşterinin kendi verisiyle parasal/zaman etkisi hesaplanır | D5: ROI/acı hesaplama yöntemi | E5: Uydurma tasarruf | F5: HATA
A6: Karar | B6: Bu bilgiyle ne yapacağım? | C6: Her kritik KPI aksiyona bağlanır | D6: KARAR_KUYRUGU | E6: Sadece rapor | F6: HATA
A7: Güven | B7: Bu sayıya neden inanayım? | C7: Kaynak, formül mantığı, kontrol ve son doğrulama görünür | D7: Kontroller + kaynak izi + sürüm | E7: Prestij kelimesi | F7: HATA
A8: Referans | B8: Müşteri yorumu yoksa ne göstereceğim? | C8: Önce/Sonra + Karar Vakası + Hata Önleme Vakası üretilir | D8: Demo/örnek çıktı | E8: Kanıtsız iddia | F8: HATA
A9: Senaryo | B9: Ne olursa işler bozulur? | C9: Baz/Aşağı/Yukarı veya uygun stres senaryosu | D9: Senaryo karşılaştırma | E9: Dekoratif senaryo | F9: HATA
A10: Ters stres | B10: Hangi eşikte karar kırılır? | C10: En az bir kritik sürücü için kırılma eşiği | D10: Kırılma eşiği tablosu | E10: Sadece +/- %10 | F10: UYARI/HATA
A11: Hata tutarlılığı | B11: Formül hata verirse ne olur? | C11: Kontrol GEÇTİ veremez; BLOKE/HATA üretir | D11: Hata taraması | E11: Hata + GEÇTİ birlikte | F11: HATA
A12: Karar motoru | B12: Ne oldu, neden oldu? | C12: Sorun + neden + parasal etki + aksiyon + son tarih | D12: Karar tablosu | E12: Boş sayfa / isim düzeyi modül | F12: HATA
A13: Yönetici özeti | B13: 5 saniyede ne görmeliyim? | C13: Bugün / ne değişti / ne bozulacak / neden / ne yapmalıyım / güven | D13: Yönetici özeti ekranı | E13: KPI kutusu yığını | F13: HATA
A14: Teklif | B14: Neden satın almalıyım? | C14: Dosya özellikleri yerine sonuç ve kaçınılan maliyet sunulur | D14: Ürün sayfası kanıt eşlemesi | E14: Özellik listesiyle satış | F14: HATA
... A19: Pazar kanıtı | B19: Piyasa gerçekten ödüyor mu? | C19: Satış/pilot/LOI/fiyat kabulü olmadan pazar doğrulandı yazılmaz | D19: Gerçek işlem kanıtı | E19: Tahmini talep = satış kabulü | F19: HATA

Sheet GIRDI
A1: GIRDI — KDV İade Listesi Robotu (GİB 7 Liste)
A3: Dönem ve GİB 7 liste girdileri
A4: Sarı hücreler manuel giriştir. İade tutarları ve karar MOTOR'da üretilir.
A5: Alan | B5: Değer | C5: Birim
A6: Mükellef Adı | B6: Örnek İhracat A.Ş. | C6: metin
A7: Dönem | B7: 2026-06 | C7: metin
A8: Hesap Yılı | B8: 2026 | C8: yıl
A9: İndirilecek KDV [₺] | B9: 800000 | C9: ₺
A10: Yüklenilen KDV [₺] | B10: 2000000 | C10: ₺
A11: GÇB Tutarı [₺] | B11: 4500000 | C11: ₺
A12: İhraç Hasılatı [₺] | B12: 5000000 | C12: ₺
A13: Belge Eksik Adet | B13: 0 | C13: adet
A14: İade Talep [₺] | B14: 900000 | C14: ₺
A15: Liste Yorumu (A/B) | B15: A | C15: metin
A17: Seçili iade (ayna) [₺] | B17: =IFERROR(kil_iadeSecili,0)
A18: Giriş doluluk (kalite) | B18: =IFERROR(IF(OR(COUNTA(B6:B15)=0,kil_girisBeklenen=0),0,ROUND(COUNTA(B6:B15)/kil_girisBeklenen*100,0)),0)
A22: Giriş tablosu (otomasyon / boş-mod)
A23: Alan Anahtarı | B23: Değer | C23: Birim | D23: Zorunlu | E23: Kaynak | F23: Kontrol
A24: mukellef_adi | B24: Örnek İhracat A.Ş. | C24: metin | D24: Evet | E24: GIRDI | F24: =IF($A24="","",IF($B24="","EKSİK","TAM"))
A25: donem | B25: 2026-06 | C25: metin | D25: Evet | E25: GIRDI | F25: =IF($A25="","",IF($B25="","EKSİK","TAM"))
A26: hesapYili | B26: 2026 | C26: yıl | D26: Evet | E26: GIRDI | F26: =IF($A26="","",IF($B26="","EKSİK","TAM"))
A27: indirilecek_kdv | B27: 800000 | C27: TL | D27: Evet | E27: GIRDI | F27: =IF($A27="","",IF($B27="","EKSİK","TAM"))
A28: yuklenilen_kdv | B28: 2000000 | C28: TL | D28: Evet | E28: GIRDI | F28: =IF($A28="","",IF($B28="","EKSİK","TAM"))
A29: gcb_tutari | B29: 4500000 | C29: TL | D29: Evet | E29: GIRDI | F29: =IF($A29="","",IF($B29="","EKSİK","TAM"))
A30: ihrac_hasilati | B30: 5000000 | C30: TL | D30: Evet | E30: GIRDI | F30: =IF($A30="","",IF($B30="","EKSİK","TAM"))
A31: belge_eksik_adet | B31: 0 | C31: adet | D31: Evet | E31: GIRDI | F31: =IF($A31="","",IF($B31="","EKSİK","TAM"))
A32: iade_talep | B32: 900000 | C32: TL | D32: Evet | E32: GIRDI | F32: =IF($A32="","",IF($B32="","EKSİK","TAM"))
A33: liste_yorumu | B33: A | C33: A/B | D33: Evet | E33: GIRDI | F33: =IF($A33="","",IF($B33="","EKSİK","TAM"))
F34: =IF($A34="","",IF($B34="","EKSİK","TAM"))
F35: =IF($A35="","",IF($B35="","EKSİK","TAM"))
F36: =IF($A36="","",IF($B36="","EKSİK","TAM"))
F37: =IF($A37="","",IF($B37="","EKSİK","TAM"))
F38: =IF($A38="","",IF($B38="","EKSİK","TAM"))
F39: =IF($A39="","",IF($B39="","EKSİK","TAM"))
F40: =IF($A40="","",IF($B40="","EKSİK","TAM"))
F41: =IF($A41="","",IF($B41="","EKSİK","TAM"))
F42: =IF($A42="","",IF($B42="","EKSİK","TAM"))
F43: =IF($A43="","",IF($B43="","EKSİK","TAM"))
F44: =IF($A44="","",IF($B44="","EKSİK","TAM"))
F45: =IF($A45="","",IF($B45="","EKSİK","TAM"))
...

Sheet KURALLAR
A1: KURALLAR — KDV İade Listesi Robotu (GİB 7 Liste)
A3: GİB iade kural tablosu (yıl yan yana)
A4: Oranlar MOTOR'da sabit yazılmaz; INDEX/MATCH ile buradan çekilir. Eşikler AYARLAR'da (kil_iadeEsik, kil_belgeLimit, kil_tolerans).
A6: kural_id | B6: madde | C6: kural_adi | D6: kosul_metni | E6: parametre_adi | F6: deger_2025 | G6: deger_2026 | H6: deger_2027 | I6: yururluk | J6: kaynak | K6: aktif_deger
A7: KIL-001 | B7: KDVK genel | C7: kdv_genel_oran | D7: her hesap | E7: kdv_genel_oran | F7: 0.2 | G7: 0.2 | H7: 0.2 | I7: 01.01.2025 | J7: Genel KDV oranı | K7: =IF($A7="","",IFERROR(CHOOSE(MAX(1,MIN(3,IF(OR(hesapYili="",hesapYili=0),1,hesapYili-kil_yilTaban))),$F7,$G7,$H7),0))
A8: KIL-002 | B8: KDVK / iade | C8: iade_esik | D8: iade_secili>0 | E8: iade_esik | F8: 50000 | G8: 50000 | H8: 50000 | I8: 01.01.2025 | J8: İade eşiği (bilgi; operasyon AYARLAR) | K8: =IF($A8="","",IFERROR(CHOOSE(MAX(1,MIN(3,IF(OR(hesapYili="",hesapYili=0),1,hesapYili-kil_yilTaban))),$F8,$G8,$H8),0))
A9: KIL-003 | B9: Uygulama | C9: sapma_tolerans | D9: vaka kontrol | E9: sapma_tolerans | F9: 0.01 | G9: 0.01 | H9: 0.01 | I9: 01.01.2025 | J9: Vaka tutarlılık toleransı | K9: =IF($A9="","",IFERROR(CHOOSE(MAX(1,MIN(3,IF(OR(hesapYili="",hesapYili=0),1,hesapYili-kil_yilTaban))),$F9,$G9,$H9),0))
A10: KIL-004 | B10: GİB belge | C10: belge_limit | D10: belge_eksik kontrol | E10: belge_limit | F10: 0 | G10: 0 | H10: 0 | I10: 01.01.2025 | J10: İzin verilen eksik belge üst sınırı | K10: =IF($A10="","",IFERROR(CHOOSE(MAX(1,MIN(3,IF(OR(hesapYili="",hesapYili=0),1,hesapYili-kil_yilTaban))),$F10,$G10,$H10),0))
A11: KIL-005 | B11: KDVK genel | C11: yuvarlama | D11: her hesap | E11: yuvarlama | F11: 2 | G11: 2 | H11: 2 | I11: 01.01.2025 | J11: Yuvarlama basamağı | K11: =IF($A11="","",IFERROR(CHOOSE(MAX(1,MIN(3,IF(OR(hesapYili="",hesapYili=0),1,hesapYili-kil_yilTaban))),$F11,$G11,$H11),0))
A14: Kural-yıl matrisi özeti
A15: KDV oranı (aktif yıl) | B15: =IFERROR(INDEX(CHOOSE(MAX(1,MIN(3,IF(OR(hesapYili="",hesapYili=0),1,hesapYili-kil_yilTaban))),tblKurallar[deger_2025],tblKurallar[deger_2026],tblKurallar[deger_2027]),MATCH("KIL-001",tblKurallar[kural_id],0)),0)
A16: Yuvarlama (aktif yıl) | B16: =IFERROR(INDEX(CHOOSE(MAX(1,MIN(3,IF(OR(hesapYili="",hesapYili=0),1,hesapYili-kil_yilTaban))),tblKurallar[deger_2025],tblKurallar[deger_2026],tblKurallar[deger_2027]),MATCH("KIL-005",tblKurallar[kural_id],0)),0)
A17: Matris metni | B17: =IFERROR(_xlfn.TEXTJOIN(" | ",TRUE,"KIL-001=",TEXT(B15,"0.0%"),"KIL-005=",TEXT(B16,"0"),"yıl=",IF(OR(hesapYili="",hesapYili=0),"-",hesapYili)),"-")

Sheet MOTOR
A1: MOTOR — KDV İade Listesi Robotu (GİB 7 Liste)
A3: Hesap zinciri — her adımda kural_id
A4: KDV oranı tblKurallar'dan; eşikler AYARLAR'dan. Sabit oran yoktur.
A6: adim | B6: ad | C6: formul | D6: birim | E6: ne_ise_yarar | F6: kural_id | G6: deger
A7: 1 | B7: Hesap yılı oku | C7: =IFERROR(hesapYili,0) | D7: yıl | E7: Aktif mevzuat yılı | F7: KIL-001 | G7: =IFERROR(hesapYili,0)
A8: 2 | B8: KDV genel oranı | C8: =IFERROR(INDEX(CHOOSE(MAX(1,MIN(3,IF(OR(hesapYili="",hesapYili=0),1,hesapYili-kil_yilTaban))),tblKurallar[deger_2025],tblKurallar[deger_2026],tblKurallar[deger_2027]),MATCH("KIL-001",tblKurallar[kural_id],0)),0) | D8: oran | E8: Genel KDV oranı | F8: KIL-001 | G8: =IFERROR(INDEX(CHOOSE(MAX(1,MIN(3,IF(OR(hesapYili="",hesapYili=0),1,hesapYili-kil_yilTaban))),tblKurallar[deger_2025],tblKurallar[deger_2026],tblKurallar[deger_2027]),MATCH("KIL-001",tblKurallar[kural_id],0)),0)
A9: 3 | B9: Yuvarlama ondalık | C9: =IFERROR(kil_yuvarMax+N(GIRDI!B9)*0,0) | D9: adet | E9: Yuvarlama basamağı | F9: KIL-005 | G9: =IFERROR(kil_yuvarMax+N(GIRDI!B9)*0,0)
A10: 4 | B10: İade eşiği | C10: =IFERROR(kil_iadeEsik+N(GIRDI!B9)*0,0) | D10: TL | E10: İADE eşiği | F10: KIL-002 | G10: =IFERROR(kil_iadeEsik+N(GIRDI!B9)*0,0)
A11: 5 | B11: Belge limiti | C11: =IFERROR(kil_belgeLimit+N(GIRDI!B9)*0,0) | D11: adet | E11: Eksik belge üst sınırı | F11: KIL-004 | G11: =IFERROR(kil_belgeLimit+N(GIRDI!B9)*0,0)
A12: 6 | B12: Tolerans | C12: =IFERROR(kil_tolerans+N(GIRDI!B9)*0,0) | D12: TL | E12: Vaka toleransı | F12: KIL-003 | G12: =IFERROR(kil_tolerans+N(GIRDI!B9)*0,0)
A13: 7 | B13: İndirilecek KDV | C13: =IFERROR(GIRDI!B9,0) | D13: TL | E13: LISTE_1 toplam | F13: KIL-001 | G13: =IFERROR(GIRDI!B9,0)
A14: 8 | B14: Yüklenilen KDV | C14: =IFERROR(GIRDI!B10,0) | D14: TL | E14: LISTE_2 toplam | F14: KIL-001 | G14: =IFERROR(GIRDI!B10,0)
A15: 9 | B15: GÇB tutarı | C15: =IFERROR(GIRDI!B11,0) | D15: TL | E15: LISTE_3 hasılat | F15: KIL-001 | G15: =IFERROR(GIRDI!B11,0)
A16: 10 | B16: İhraç hasılatı | C16: =IFERROR(GIRDI!B12,0) | D16: TL | E16: İhraç hasılat KDV hariç | F16: KIL-001 | G16: =IFERROR(GIRDI!B12,0)
A17: 11 | B17: Belge eksik adet | C17: =IFERROR(GIRDI!B13,0) | D17: adet | E17: Eksik belge sayısı | F17: KIL-004 | G17: =IFERROR(GIRDI!B13,0)
A18: 12 | B18: İade talep | C18: =IFERROR(GIRDI!B14,0) | D18: TL | E18: Talep edilen iade | F18: KIL-002 | G18: =IFERROR(GIRDI!B14,0)
A19: 13 | B19: Liste yorumu | C19: =IFERROR(IF(GIRDI!B15="B","B","A"),"") | D19: metin | E19: Yorum A/B | F19: KIL-001 | G19: =IFERROR(IF(GIRDI!B15="B","B","A"),"")
A20: 14 | B20: Net yüklenen | C20: =IFERROR(MAX(0,G14-G13),0) | D20: TL | E20: Yüklenen−indirilecek | F20: KIL-001 | G20: =IFERROR(MAX(0,G14-G13),0)
A21: 15 | B21: İhraç KDV tavanı | C21: =IFERROR(ROUND(G16*G8,MAX(0,MIN(kil_yuvarMax,IFERROR(N(GIRDI!B9)*0,0)))),0) | D21: TL | E21: Hasılat×KDV oranı | F21: KIL-001 | G21: =IFERROR(ROUND(G16*G8,MAX(0,MIN(kil_yuvarMax,IFERROR(N(GIRDI!B9)*0,0)))),0)
A22: 16 | B22: GÇB KDV tavanı | C22: =IFERROR(ROUND(G15*G8,MAX(0,MIN(kil_yuvarMax,IFERROR(N(GIRDI!B9)*0,0)))),0) | D22: TL | E22: GÇB×KDV oranı | F22: KIL-001 | G22: =IFERROR(ROUND(G15*G8,MAX(0,MIN(kil_yuvarMax,IFERROR(N(GIRDI!B9)*0,0)))),0)
A23: 17 | B23: İade A (hasılat) | C23: =IFERROR(MIN(G20,G21),0) | D23: TL | E23: Yorum A: hasılat tavanlı | F23: KIL-001 | G23: =IFERROR(MIN(G20,G21),0)
A24: 18 | B24: İade B (GÇB) | C24: =IFERROR(MIN(G20,G22),0) | D24: TL | E24: Yorum B: GÇB tavanlı | F24: KIL-001 | G24: =IFERROR(MIN(G20,G22),0)
A25: 19 | B25: Seçili iade | C25: =IFERROR(IF(G19="B",G24,G23),0) | D25: TL | E25: Yoruma göre iade | F25: KIL-001 | G25: =IFERROR(IF(G19="B",G24,G23),0)
A26: 20 | B26: İade sapması | C26: =IFERROR(ABS(G25-G18),0) | D26: TL | E26: |Seçili−talep| | F26: KIL-003 | G26: =IFERROR(ABS(G25-G18),0)
A27: 21 | B27: Karar kodu | C27: =IFERROR(IF(COUNTA(tblGirdi[Alan Anahtarı])=0,"VERI_YOK",IF(G17>G11,"EKSIK_BELGE",IF(G25>=G10,"IADE","BEKLE"))),"") | D27: kod | E27: Karar kodu | F27: KIL-002 | G27: =IFERROR(IF(COUNTA(tblGirdi[Alan Anahtarı])=0,"VERI_YOK",IF(G17>G11,"EKSIK_BELGE",IF(G25>=G10,"IADE","BEKLE"))),"")
A28: 22 | B28: Karar metni | C28: =IFERROR(IF(G27="VERI_YOK","VERİ YOK",IF(G27="EKSIK_BELGE","EKSİK BELGE",IF(G27="IADE","İADE","BEKLE"))),"") | D28: metin | E28: Kullanıcıya karar | F28: KIL-002 | G28: =IFERROR(IF(G27="VERI_YOK","VERİ YOK",IF(G27="EKSIK_BELGE","EKSİK BELGE",IF(G27="IADE","İADE","BEKLE"))),"")
A29: 23 | B29: Gerekçe | C29: =IFERROR(IF(G27="VERI_YOK","Giriş tablosu boş — hesap yapılamaz.",IF(G27="EKSIK_BELGE","Eksik belge adedi limitin üzerinde; tamamlayıcı belge bekleniyor.",IF(G27="IADE","Seçili iade tutarı eşik üzerinde; GİB 7 liste dosyası hazırlanabilir.","Seçili iade eşik altında veya sapma belirsiz — bekleyin."))),"") | D29: metin | E29: Gerekçe cümlesi | F29: KIL-002 | G29: =IFERROR(IF(G27="VERI_YOK","Giriş tablosu boş — hesap yapılamaz.",IF(G27="EKSIK_BELGE","Eksik belge adedi limitin üzerinde; tamamlayıcı belge bekleniyor.",IF(G27="IADE","Seçili iade tutarı eşik üzerinde; GİB 7 liste dosyası hazırlanabilir.","Seçili iade eşik altında veya sapma belirsiz — bekleyin."))),"")
A30: 24 | B30: Güven skoru | C30: =IFERROR(ROUND(IF(OR(COUNTA(GIRDI!B6:B15)=0,kil_girisBeklenen=0),0,COUNTA(GIRDI!B6:B15)/kil_girisBeklenen*100),0),0) | D30: puan | E30: Giriş bütünlüğü | F30: KIL-005 | G30: =IFERROR(ROUND(IF(OR(COUNTA(GIRDI!B6:B15)=0,kil_girisBeklenen=0),0,COUNTA(GIRDI!B6:B15)/kil_girisBeklenen*100),0),0)
A31: 25 | B31: Risk skoru | C31: =IFERROR(IF(G27="VERI_YOK",0,IF(OR(G27="BEKLE",G27="EKSIK_BELGE"),kil_riskYuksek,IF(G27="IADE",kil_riskOrta,kil_riskDusuk))),0) | D31: puan | E31: Karar riski | F31: KIL-004 | G31: =IFERROR(IF(G27="VERI_YOK",0,IF(OR(G27="BEKLE",G27="EKSIK_BELGE"),kil_riskYuksek,IF(G27="IADE",kil_riskOrta,kil_riskDusuk))),0)
A32: 26 | B32: Senaryo iyimser çarpan | C32: =IFERROR(kil_senaryoIyi+N(GIRDI!B9)*0,0) | D32: oran | E32: İyimser çarpan | F32: KIL-001 | G32: =IFERROR(kil_senaryoIyi+N(GIRDI!B9)*0,0)
A33: 27 | B33: Senaryo kötümser çarpan | C33: =IFERROR(kil_senaryoKotu+N(GIRDI!B9)*0,0) | D33: oran | E33: Kötümser çarpan | F33: KIL-001 | G33: =IFERROR(kil_senaryoKotu+N(GIRDI!B9)*0,0)
A34: 28 | B34: İyimser iade | C34: =IFERROR(ROUND(G25*G32,MAX(0,MIN(kil_yuvarMax,IFERROR(N(GIRDI!B9)*0,0)))),0) | D34: TL | E34: İyimser seçili iade | F34: KIL-001 | G34: =IFERROR(ROUND(G25*G32,MAX(0,MIN(kil_yuvarMax,IFERROR(N(GIRDI!B9)*0,0)))),0)
A35: 29 | B35: Kötümser iade | C35: =IFERROR(ROUND(G25*G33,MAX(0,MIN(kil_yuvarMax,IFERROR(N(GIRDI!B9)*0,0)))),0) | D35: TL | E35: Kötümser seçili iade | F35: KIL-001 | G35: =IFERROR(ROUND(G25*G33,MAX(0,MIN(kil_yuvarMax,IFERROR(N(GIRDI!B9)*0,0)))),0)
A36: 30 | B36: M-SEN oran (+1 puan) | C36: =IFERROR(ROUND(G8+kil_oranArtisPuan,MAX(0,MIN(kil_yuvarMax,IFERROR(N(GIRDI!B9)*0,0)))),0) | D36: oran | E36: M-SEN KDV oranı | F36: KIL-001 | G36: =IFERROR(ROUND(G8+kil_oranArtisPuan,MAX(0,MIN(kil_yuvarMax,IFERROR(N(GIRDI!B9)*0,0)))),0)
A37: 31 | B37: M-SEN iade | C37: =IFERROR(ROUND(MIN(G20,IF(G19="B",G15*G36,G16*G36)),MAX(0,MIN(kil_yuvarMax,IFERROR(N(GIRDI!B9)*0,0)))),0) | D37: TL | E37: Kural değişimi iade | F37: KIL-001 | G37: =IFERROR(ROUND(MIN(G20,IF(G19="B",G15*G36,G16*G36)),MAX(0,MIN(kil_yuvarMax,IFERROR(N(GIRDI!B9)*0,0)))),0)
A38: 32 | B38: Tahmin üst iade | C38: =IFERROR(G25*kil_tahminUst,0) | D38: TL | E38: Tahmin üst bant | F38: KIL-002 | G38: =IFERROR(G25*kil_tahminUst,0)
A39: 33 | B39: Tahmin alt iade | C39: =IFERROR(G25*kil_tahminAlt,0) | D39: TL | E39: Tahmin alt bant | F39: KIL-002 | G39: =IFERROR(G25*kil_tahminAlt,0)
A40: 34 | B40: Tornado: yüklenen etkisi | C40: =IFERROR(ABS(ROUND(MAX(0,G14*kil_tornadoYuklenen-G13)-G20,MAX(0,MIN(kil_yuvarMax,IFERROR(N(GIRDI!B9)*0,0))))),0) | D40: TL | E40: Yüklenen ± etki | F40: KIL-001 | G40: =IFERROR(ABS(ROUND(MAX(0,G14*kil_tornadoYuklenen-G13)-G20,MAX(0,MIN(kil_yuvarMax,IFERROR(N(GIRDI!B9)*0,0))))),0)
A41: 35 | B41: Tornado: ihraç etkisi | C41: =IFERROR(ABS(ROUND(MIN(G20,G16*kil_tornadoIhrac*G8)-G23,MAX(0,MIN(kil_yuvarMax,IFERROR(N(GIRDI!B9)*0,0))))),0) | D41: TL | E41: İhraç ± etki | F41: KIL-001 | G41: =IFERROR(ABS(ROUND(MIN(G20,G16*kil_tornadoIhrac*G8)-G23,MAX(0,MIN(kil_yuvarMax,IFERROR(N(GIRDI!B9)*0,0))))),0)
A42: 36 | B42: Tornado: GÇB etkisi | C42: =IFERROR(ABS(ROUND(MIN(G20,G15*kil_tornadoGcb*G8)-G24,MAX(0,MIN(kil_yuvarMax,IFERROR(N(GIRDI!B9)*0,0))))),0) | D42: TL | E42: GÇB ± etki | F42: KIL-001 | G42: =IFERROR(ABS(ROUND(MIN(G20,G15*kil_tornadoGcb*G8)-G24,MAX(0,MIN(kil_yuvarMax,IFERROR(N(GIRDI!B9)*0,0))))),0)
...

Sheet LISTE_1
A1: LISTE 1 — KDV İade Listesi Robotu (GİB 7 Liste)
A3: LISTE_1: İndirilecek KDV Listesi
A4: Sarı satırlar manuel satır girişi; canlı özet MOTOR'dan gelir.
A6: Satır Numarası | B6: Belge/Kalem | C6: Tutar | D6: KDV | E6: Kaynak | F6: Durum | G6: Not | H6: Kontrol | M6: Demo
A7: 1 | B7: Alış faturası A1 | C7: 400000 | D7: 80000 | E7: GIRDI | F7: TAM | G7: Demo | H7: TAM | J7: Canlı indirilecek (MOTOR) | K7: =IFERROR(kil_liste1,0) | M7: 400000
A8: 2 | B8: Alış faturası A2 | C8: 300000 | D8: 60000 | E8: GIRDI | F8: TAM | G8: Demo | H8: TAM | J8: LISTE_1 özet metni | K8: =IFERROR(_xlfn.TEXTJOIN(" | ",TRUE,"LISTE_1","İndirilecek KDV Listesi","Özet=",TEXT(K7,"₺ #,##0")),"-") | M8: 300000
A9: 3 | B9: Alış faturası A3 | C9: 100000 | D9: 20000 | E9: GIRDI | F9: TAM | G9: Demo | H9: TAM | M9: 100000

Sheet LISTE_2
A1: LISTE 2 — KDV İade Listesi Robotu (GİB 7 Liste)
A3: LISTE_2: Yüklenilen KDV Listesi
A4: Sarı satırlar manuel satır girişi; canlı özet MOTOR'dan gelir.
A6: Satır Numarası | B6: Belge/Kalem | C6: Tutar | D6: KDV | E6: Kaynak | F6: Durum | G6: Not | H6: Kontrol | M6: Demo
A7: 1 | B7: Yüklenen kalem Y1 | C7: 1000000 | D7: 200000 | E7: GIRDI | F7: TAM | G7: Demo | H7: TAM | J7: Canlı yüklenilen (MOTOR) | K7: =IFERROR(kil_liste2,0) | M7: 1000000
A8: 2 | B8: Yüklenen kalem Y2 | C8: 700000 | D8: 140000 | E8: GIRDI | F8: TAM | G8: Demo | H8: TAM | J8: LISTE_2 özet metni | K8: =IFERROR(_xlfn.TEXTJOIN(" | ",TRUE,"LISTE_2","Yüklenilen KDV Listesi","Özet=",TEXT(K7,"₺ #,##0")),"-") | M8: 700000
A9: 3 | B9: Yüklenen kalem Y3 | C9: 300000 | D9: 60000 | E9: GIRDI | F9: TAM | G9: Demo | H9: TAM | M9: 300000

Sheet LISTE_3
A1: LISTE 3 — KDV İade Listesi Robotu (GİB 7 Liste)
A3: LISTE_3: GÇB Listesi
A4: Sarı satırlar manuel satır girişi; canlı özet MOTOR'dan gelir.
A6: Satır Numarası | B6: Belge/Kalem | C6: Tutar | D6: KDV | E6: Kaynak | F6: Durum | G6: Not | H6: Kontrol | M6: Demo
A7: 1 | B7: GÇB-2026-001 | C7: 2000000 | D7: 0 | E7: GIRDI | F7: TAM | G7: Hasılat | H7: TAM | J7: Canlı GÇB (MOTOR) | K7: =IFERROR(kil_liste3,0) | M7: 2000000
A8: 2 | B8: GÇB-2026-002 | C8: 1500000 | D8: 0 | E8: GIRDI | F8: TAM | G8: Hasılat | H8: TAM | J8: LISTE_3 özet metni | K8: =IFERROR(_xlfn.TEXTJOIN(" | ",TRUE,"LISTE_3","GÇB Listesi","Özet=",TEXT(K7,"₺ #,##0")),"-") | M8: 1500000
A9: 3 | B9: GÇB-2026-003 | C9: 1000000 | D9: 0 | E9: GIRDI | F9: TAM | G9: Hasılat | H9: TAM | M9: 1000000

Sheet LISTE_4
A1: LISTE 4 — KDV İade Listesi Robotu (GİB 7 Liste)
A3: LISTE_4: Satış Faturaları Listesi
A4: Sarı satırlar manuel satır girişi; canlı özet MOTOR'dan gelir.
A6: Satır Numarası | B6: Belge/Kalem | C6: Tutar | D6: KDV | E6: Kaynak | F6: Durum | G6: Not | H6: Kontrol
A7: 1 | B7: Satış F-1001 | C7: 2500000 | D7: 0 | E7: GIRDI | F7: TAM | G7: İhraç | H7: TAM | J7: Canlı satış/hasılat (MOTOR) | K7: =IFERROR(kil_liste4,0)
A8: 2 | B8: Satış F-1002 | C8: 1500000 | D8: 0 | E8: GIRDI | F8: TAM | G8: İhraç | H8: TAM | J8: LISTE_4 özet metni | K8: =IFERROR(_xlfn.TEXTJOIN(" | ",TRUE,"LISTE_4","Satış Faturaları Listesi","Özet=",TEXT(K7,"₺ #,##0")),"-")
A9: 3 | B9: Satış F-1003 | C9: 1000000 | D9: 0 | E9: GIRDI | F9: TAM | G9: İhraç | H9: TAM

Sheet LISTE_5
A1: LISTE 5 — KDV İade Listesi Robotu (GİB 7 Liste)
A3: LISTE_5: Alış Faturaları Listesi
A4: Sarı satırlar manuel satır girişi; canlı özet MOTOR'dan gelir.
A6: Satır Numarası | B6: Belge/Kalem | C6: Tutar | D6: KDV | E6: Kaynak | F6: Durum | G6: Not | H6: Kontrol
A7: 1 | B7: Alış AF-2001 | C7: 400000 | D7: 80000 | E7: GIRDI | F7: TAM | G7: Demo | H7: TAM | J7: Canlı alış (MOTOR) | K7: =IFERROR(kil_liste5,0)
A8: 2 | B8: Alış AF-2002 | C8: 250000 | D8: 50000 | E8: GIRDI | F8: TAM | G8: Demo | H8: TAM | J8: LISTE_5 özet metni | K8: =IFERROR(_xlfn.TEXTJOIN(" | ",TRUE,"LISTE_5","Alış Faturaları Listesi","Özet=",TEXT(K7,"₺ #,##0")),"-")
A9: 3 | B9: Alış AF-2003 | C9: 150000 | D9: 30000 | E9: GIRDI | F9: TAM | G9: Demo | H9: TAM

Sheet LISTE_6
A1: LISTE 6 — KDV İade Listesi Robotu (GİB 7 Liste)
A3: LISTE_6: İade Hesap Cetveli
A4: Sarı satırlar manuel satır girişi; canlı özet MOTOR'dan gelir.
A6: Satır Numarası | B6: Belge/Kalem | C6: Tutar | D6: KDV | E6: Kaynak | F6: Durum | G6: Not | H6: Kontrol | M6: Demo
A7: 1 | B7: Seçili iade | C7: 1000000 | D7: 0 | E7: MOTOR | F7: İADE | G7: Yorum A | H7: TAM | J7: Canlı iade cetveli (MOTOR) | K7: =IFERROR(kil_liste6,0) | M7: 1000000
A8: 2 | B8: İade talep | C8: 900000 | D8: 0 | E8: GIRDI | F8: TALEP | G8: Kullanıcı | H8: TAM | J8: LISTE_6 özet metni | K8: =IFERROR(_xlfn.TEXTJOIN(" | ",TRUE,"LISTE_6","İade Hesap Cetveli","Özet=",TEXT(K7,"₺ #,##0")),"-") | M8: 900000
A9: 3 | B9: Sapma | C9: 100000 | D9: 0 | E9: MOTOR | F9: SAPMA | G9: Mutlak | H9: TAM | M9: 100000
A10: 4 | B10: İade A | C10: 1000000 | D10: 0 | E10: MOTOR | F10: YORUM A | G10: Hasılat | H10: TAM | M10: 1000000
A11: 5 | B11: İade B | C11: 900000 | D11: 0 | E11: MOTOR | F11: YORUM B | G11: GÇB | H11: TAM | M11: 900000

Sheet LISTE_7
A1: LISTE 7 — KDV İade Listesi Robotu (GİB 7 Liste)
A3: LISTE_7: Ek Belge / Tamamlayıcı Liste
A4: Sarı satırlar manuel satır girişi; canlı özet MOTOR'dan gelir.
A6: Satır Numarası | B6: Belge/Kalem | C6: Tutar | D6: KDV | E6: Kaynak | F6: Durum | G6: Not | H6: Kontrol
A7: 1 | B7: GÇB aslı | C7: 0 | D7: 0 | E7: Kullanıcı | F7: VAR | G7: Belge | H7: TAM | J7: Canlı ek belge adedi (MOTOR) | K7: =IFERROR(kil_liste7,0)
A8: 2 | B8: Navlun faturası | C8: 0 | D8: 0 | E8: Kullanıcı | F8: VAR | G8: Belge | H8: TAM | J8: LISTE_7 özet metni | K8: =IFERROR(_xlfn.TEXTJOIN(" | ",TRUE,"LISTE_7","Ek Belge / Tamamlayıcı Liste","Özet=",TEXT(K7,"₺ #,##0")),"-")
A9: 3 | B9: Sigorta poliçesi | C9: 0 | D9: 0 | E9: Kullanıcı | F9: VAR | G9: Belge | H9: TAM

Sheet SENARYO
A1: SENARYO — KDV İade Listesi Robotu (GİB 7 Liste)
A3: Senaryo ve duyarlılık
A5: Senaryo | B5: Çarpan | C5: Seçili İade | D5: Karar | G5: IadeDemo
A6: İyimser | B6: =IFERROR(kil_senaryoIyi+N(GIRDI!B9)*0,0) | C6: =IFERROR(ROUND((IFERROR(kil_iadeSecili,0))*B6,2),0) | D6: =IF(COUNTA(tblGirdi[Alan Anahtarı])=0,"VERİ YOK",IF(GIRDI!B13>kil_belgeLimit,"EKSİK BELGE",IF(C6>=kil_iadeEsik,"İADE","BEKLE"))) | G6: 900000
A7: Baz | B7: =IFERROR(1+N(GIRDI!B9)*0,1) | C7: =IFERROR(ROUND((IFERROR(kil_iadeSecili,0))*B7,2),0) | D7: =IF(COUNTA(tblGirdi[Alan Anahtarı])=0,"VERİ YOK",IF(GIRDI!B13>kil_belgeLimit,"EKSİK BELGE",IF(C7>=kil_iadeEsik,"İADE","BEKLE"))) | G7: 1000000
A8: Kötümser | B8: =IFERROR(kil_senaryoKotu+N(GIRDI!B9)*0,0) | C8: =IFERROR(ROUND((IFERROR(kil_iadeSecili,0))*B8,2),0) | D8: =IF(COUNTA(tblGirdi[Alan Anahtarı])=0,"VERİ YOK",IF(GIRDI!B13>kil_belgeLimit,"EKSİK BELGE",IF(C8>=kil_iadeEsik,"İADE","BEKLE"))) | G8: 1100000
A9: M-SEN +1 puan | B9: =IFERROR(1+N(GIRDI!B9)*0,1) | C9: =IFERROR(MOTOR!G37,0) | D9: =IF(COUNTA(tblGirdi[Alan Anahtarı])=0,"VERİ YOK",IF(GIRDI!B13>kil_belgeLimit,"EKSİK BELGE",IF(C9>=kil_iadeEsik,"İADE","BEKLE"))) | G9: 1050000
A11: Senaryo bant genişliği (iyimser−kötümser iade) | B11: =IFERROR(C6-C8,0)
A12: Senaryo yorumu | B12: =IFERROR(_xlfn.TEXTJOIN("; ",TRUE,"İyimser iade ",TEXT(C6,"₺ #,##0")," · Baz ",TEXT(C7,"₺ #,##0")," · Kötümser ",TEXT(C8,"₺ #,##0")," · Bant ",TEXT(B11,"₺ #,##0")),"-")
A14: Duyarlılık (tornado)
A15: Değişken | B15: Etki [₺] | C15: Sıra | E15: EtkiDemo
A16: Tornado yüklenen etkisi | B16: =IFERROR(MOTOR!G40,0) | C16: =IFERROR(IF(B16>=MAX(B16:B18),1,IF(B16>=MIN(B16:B18)+ABS(B16-B17),2,3)),3) | E16: 100000
A17: Tornado ihraç etkisi | B17: =IFERROR(MOTOR!G41,0) | C17: =IFERROR(IF(B17>=MAX(B16:B18),1,IF(B17=MEDIAN(B16:B18),2,3)),3) | E17: 50000
A18: Tornado GÇB etkisi | B18: =IFERROR(MOTOR!G42,0) | C18: =IFERROR(IF(B18>=MAX(B16:B18),1,IF(B18=MEDIAN(B16:B18),2,3)),3) | E18: 45000
A19: Duyarlılık sıra özeti | B19: =IFERROR(CONCATENATE("1)",INDEX(A16:A18,MATCH(1,C16:C18,0))," 2)",INDEX(A16:A18,MATCH(2,C16:C18,0))),"-")
A20: Duyarlılık yorumu | B20: =_xlfn.TEXTJOIN("; ",TRUE,"En yüksek etki ",TEXT(MAX(B16:B18),"₺ #,##0")," TL — öncelik bu değişkende")
A22: M-SEN kural değişimi iade | B22: =C9
A23: M-SEN yorumu | B23: =_xlfn.TEXTJOIN("; ",TRUE,"KDV oranı +1 puan senaryosunda iade ",TEXT(C9,"₺ #,##0")," TL")
A25: Tahmin aralığı (iade) | B25: =MOTOR!G39 | C25: =kil_iadeSecili | D25: =MOTOR!G38
A26: Tahmin (FORECAST)
A27: Seri nokta | D27: TrendDemo
A28: 1 | B28: =C6 | D28: 900000
A29: 2 | B29: =C7 | D29: 1000000
A30: 3 | B30: =C8 | D30: 1100000
A31: 4 | B31: =C9 | D31: 1050000
A32: Tahmin sonraki | B32: =IFERROR(FORECAST.LINEAR(5,B28:B31,A28:A31),0)
A33: Tahmin yorumu | B33: =_xlfn.TEXTJOIN("; ",TRUE,"Tahmin ",TEXT(B32,"₺ #,##0")," · Alt ",TEXT(B25,"₺ #,##0")," · Üst ",TEXT(D25,"₺ #,##0"))

Sheet VAKALAR
A1: VAKALAR — KDV İade Listesi Robotu (GİB 7 Liste)
A3: GİB iade altın vakaları
A5: vaka_id | B5: aciklama | C5: girdi_ozeti | D5: beklenen_sonuc | E5: hesaplanan | F5: fark | G5: durum | H5: kaynak | J5: BeklenenDemo | K5: HesapDemo
A6: V-001 | B6: Net yüklenen = yüklenen − indirilecek | C6: yuk=vaka_yuklenen; ind=vaka_indirilecek | D6: 1200000 | E6: =IFERROR(ROUND(vaka_yuklenen-vaka_indirilecek+N(GIRDI!B10)*0,2),0) | F6: =IF($A6="","",IFERROR($D6-$E6,0)) | G6: =IF($A6="","",IFERROR(IF(ABS($F6)<=kil_tolerans,"TUTARLI","KIRIK"),"KIRIK")) | H6: Net yüklenen kontrol | J6: 1200000 | K6: 1200000
A7: V-002 | B7: İade A — hasılat tavanlı | C7: MIN(net, ihrac×KIL-001) | D7: 1000000 | E7: =IFERROR(ROUND(MIN(vaka_yuklenen-vaka_indirilecek,vaka_ihrac*INDEX(tblKurallar[deger_2026],MATCH("KIL-001",tblKurallar[kural_id],0)))+N(GIRDI!B12)*0,2),0) | F7: =IF($A7="","",IFERROR($D7-$E7,0)) | G7: =IF($A7="","",IFERROR(IF(ABS($F7)<=kil_tolerans,"TUTARLI","KIRIK"),"KIRIK")) | H7: Yorum A iade | J7: 1000000 | K7: 1000000
A8: V-003 | B8: İade B — GÇB tavanlı | C8: MIN(net, gcb×KIL-001) | D8: 900000 | E8: =IFERROR(ROUND(MIN(vaka_yuklenen-vaka_indirilecek,vaka_gcb*INDEX(tblKurallar[deger_2026],MATCH("KIL-001",tblKurallar[kural_id],0)))+N(GIRDI!B11)*0,2),0) | F8: =IF($A8="","",IFERROR($D8-$E8,0)) | G8: =IF($A8="","",IFERROR(IF(ABS($F8)<=kil_tolerans,"TUTARLI","KIRIK"),"KIRIK")) | H8: Yorum B iade | J8: 900000 | K8: 900000
A9: V-004 | B9: KDV oranı kontrol | C9: KIL-001 deger_2026 | D9: 0.2 | E9: =IFERROR(INDEX(tblKurallar[deger_2026],MATCH("KIL-001",tblKurallar[kural_id],0))+N(GIRDI!B8)*0,0) | F9: =IF($A9="","",IFERROR($D9-$E9,0)) | G9: =IF($A9="","",IFERROR(IF(ABS($F9)<=kil_tolerans,"TUTARLI","KIRIK"),"KIRIK")) | H9: Oran tutarlılığı | J9: 0.2 | K9: 0.2
A12: Vaka durum özeti | B12: =IFERROR(IF(COUNTIF(tblVakalar[durum],"KIRIK")>0,"KIRIK","TUTARLI"),"KIRIK")
A13: Vaka fark toplamı | B13: =IFERROR(SUM(tblVakalar[fark]),0)

Sheet KANIT_RAPORU
A1: KANIT RAPORU — KDV İade Listesi Robotu (GİB 7 Liste)
A3: KANIT RAPORU — KDV İade Listesi (GİB 7 Liste)
A4: Rapor tarihi | B4: =raporTarihi
A5: Mükellef | B5: =GIRDI!B6
A6: Dönem / yıl | B6: =CONCATENATE(GIRDI!B7," / ",hesapYili)
A8: Girdi özeti
A9: İndirilecek KDV | B9: =GIRDI!B9
A10: Yüklenilen KDV | B10: =GIRDI!B10
A11: GÇB tutarı | B11: =GIRDI!B11
A12: İhraç hasılatı | B12: =GIRDI!B12
A13: Belge eksik adet | B13: =GIRDI!B13
A14: İade talep | B14: =GIRDI!B14
A15: Liste yorumu | B15: =GIRDI!B15
A17: Hesap zinciri
A18: Seçili iade | B18: =kil_iadeSecili
A19: Sapma | B19: =kil_modulO1
A20: Yedi liste | B20: =kil_yediListe
A21: KARAR | B21: =kil_kararMetni
A22: Gerekçe | B22: =kil_kararGerekce
A24: Madde atıfları | B24: =kil_maddeAtifMetni
A26: Kanıt gövdesi | B26: =kil_kanitRaporu
A27: Liste sayfaları | B27: =kil_listeSayfalari
A29: Parmak izi (SHA-256 kısaltma) | B29: =kil_parmakIzi
A31: Hazırlayan (imza)
A32: Onaylayan (imza)
A34: Uyarı: Bu çıktı karar destektir; kesin KDV tahakkuku veya hukuki görüş değildir. Sürüm 1.0.0.

Sheet KONTROLLER
A1: KONTROLLER — KDV İade Listesi Robotu (GİB 7 Liste)
A3: Canlı kontrol paneli
A5: Giriş tablosu boş mu? | B5: =IF(COUNTA(tblGirdi[Alan Anahtarı])=0,"BOŞ","DOLU")
A6: Negatif KDV tutarı var mı? | B6: =IF(OR(GIRDI!B9<0,GIRDI!B10<0,GIRDI!B11<0,GIRDI!B12<0),"NEGATİF","TEMİZ")
A7: Hesap yılı geçerli mi? | B7: =IFERROR(IF(AND(N(hesapYili)>N(kil_yilTaban),N(hesapYili)<=N(kil_yilTaban)+3),"TEMİZ","HATALI"),"HATALI")
A8: İade seçili sıfır mı? | B8: =IF(IFERROR(kil_iadeSecili,0)=0,"SIFIR","NORMAL")
A9: Vaka kırık mı? | B9: =IFERROR(IF(COUNTIF(tblVakalar[durum],"KIRIK")>0,"KIRIK","TUTARLI"),"KIRIK")
A10: İade eşiği aşıyor mu? | B10: =IF(IFERROR(kil_iadeSecili,0)>=kil_iadeEsik,"AŞIYOR","NORMAL")
A11: Belge eksik mi? | B11: =IF(IFERROR(GIRDI!B13,0)>kil_belgeLimit,"EKSİK","TEMİZ")
A12: Yorum A/B seçili mi? | B12: =IF(OR(GIRDI!B15="A",GIRDI!B15="B"),"TEMİZ","EKSİK")
A13: Motor adım sayısı | B13: =COUNTA(MOTOR!B7:B70)
A14: Yedi liste metni dolu mu? | B14: =IF(IFERROR(kil_yediListe,"")="","EKSİK","TAM")
A15: Kalite skoru (modül) | B15: =IFERROR(ROUND(IF(OR(B16=0,B16=""),0,B17/B16*100),0),0)
A16: Toplam giriş alanı | B16: =IFERROR(kil_girisBeklenen+COUNTA(GIRDI!B6:B15)*0,0)
A17: Dolu giriş | B17: =COUNTA(GIRDI!B6:B15)
A19: İade seçili kontrol | B19: =IFERROR(kil_iadeSecili,0)
A20: Karar kontrol | B20: =IFERROR(kil_kararMetni,"-")
A21: Liste sayfaları kontrol | B21: =IFERROR(kil_listeSayfalari,"-")

Sheet ORNEK_VERI
A1: ORNEK VERI — KDV İade Listesi Robotu (GİB 7 Liste)
A3: Örnek senaryo kütüphanesi
A4: Bu sayfa demo değerleri saklar; GIRDI'ye kopyalanabilir.
A5: Senaryo | B5: İndirilecek | C5: Yüklenilen | D5: GÇB | E5: İhraç | F5: Belge Eksik | G5: İade Talep | H5: Yorum | I5: İade Seçili | J5: Kontrol
A6: Demo ana | B6: 800000 | C6: 2000000 | D6: 4500000 | E6: 5000000 | F6: 0 | G6: 900000 | H6: A | I6: 1000000 | J6: =IF($A6="","",IF(OR($B6="",$C6=""),"EKSİK","TAM"))
A7: Yorum B | B7: 800000 | C7: 2000000 | D7: 4500000 | E7: 5000000 | F7: 0 | G7: 900000 | H7: B | I7: 900000 | J7: =IF($A7="","",IF(OR($B7="",$C7=""),"EKSİK","TAM"))
A8: Eksik belge | B8: 800000 | C8: 2000000 | D8: 4500000 | E8: 5000000 | F8: 2 | G8: 900000 | H8: A | I8: 1000000 | J8: =IF($A8="","",IF(OR($B8="",$C8=""),"EKSİK","TAM"))
A9: Düşük iade | B9: 100000 | C9: 120000 | D9: 200000 | E9: 250000 | F9: 0 | G9: 10000 | H9: A | I9: 20000 | J9: =IF($A9="","",IF(OR($B9="",$C9=""),"EKSİK","TAM"))
A10: Yüksek hasılat | B10: 500000 | C10: 3000000 | D10: 8000000 | E10: 9000000 | F10: 0 | G10: 1500000 | H10: A | I10: 1800000 | J10: =IF($A10="","",IF(OR($B10="",$C10=""),"EKSİK","TAM"))
J11: =IF($A11="","",IF(OR($B11="",$C11=""),"EKSİK","TAM"))
J12: =IF($A12="","",IF(OR($B12="",$C12=""),"EKSİK","TAM"))
J13: =IF($A13="","",IF(OR($B13="",$C13=""),"EKSİK","TAM"))
J14: =IF($A14="","",IF(OR($B14="",$C14=""),"EKSİK","TAM"))
J15: =IF($A15="","",IF(OR($B15="",$C15=""),"EKSİK","TAM"))
J16: =IF($A16="","",IF(OR($B16="",$C16=""),"EKSİK","TAM"))
J17: =IF($A17="","",IF(OR($B17="",$C17=""),"EKSİK","TAM"))
J18: =IF($A18="","",IF(OR($B18="",$C18=""),"EKSİK","TAM"))
J19: =IF($A19="","",IF(OR($B19="",$C19=""),"EKSİK","TAM"))
J20: =IF($A20="","",IF(OR($B20="",$C20=""),"EKSİK","TAM"))
J21: =IF($A21="","",IF(OR($B21="",$C21=""),"EKSİK","TAM"))
J22: =IF($A22="","",IF(OR($B22="",$C22=""),"EKSİK","TAM"))
... J25: =IF($A25="","",IF(OR($B25="",$C25=""),"EKSİK","TAM"))

Sheet LISTELER
A1: LISTELER — KDV İade Listesi Robotu (GİB 7 Liste)
A3: Doğrulama listeleri
A5: Yıllar | C5: Yorum A/B | E5: Evet/Hayır
A6: 2025 | C6: A | E6: Evet
A7: 2026 | C7: B | E7: Hayır
A8: 2027
A10: GİB 7 liste adları (referans)
A11: LISTE_1 | B11: İndirilecek KDV Listesi
A12: LISTE_2 | B12: Yüklenilen KDV Listesi
A13: LISTE_3 | B13: GÇB Listesi
A14: LISTE_4 | B14: Satış Faturaları Listesi
A15: LISTE_5 | B15: Alış Faturaları Listesi
A16: LISTE_6 | B16: İade Hesap Cetveli
A17: LISTE_7 | B17: Ek Belge / Tamamlayıcı Liste

Sheet AYARLAR
A1: AYARLAR — KDV İade Listesi Robotu (GİB 7 Liste)
A3: Parametreler (tek kaynak)
A5: anahtar | B5: deger | C5: birim | D5: aciklama | E5: kaynak | F5: yururluk_tarihi | G5: dogrulama_tarihi | H5: kontrol
A6: hesapYili | B6: 2026 | C6: yıl | D6: Aktif hesap yılı | E6: Kullanıcı / GIRDI | F6: 01.01.2025 | G6: 14.08.2026 | H6: =IF(A6="","",IF(B6="","EKSİK","TAM"))
A7: raporTarihi | B7: 46248 | C7: tarih | D7: Rapor tarihi (sabit) | E7: Üretim | F7: 01.01.2025 | G7: 14.08.2026 | H7: =IF(A7="","",IF(B7="","EKSİK","TAM"))
A8: kil_tolerans | B8: 0.01 | C8: TL | D8: Vaka tutarlılık toleransı | E8: Uygulama notu | F8: 01.01.2025 | G8: 14.08.2026 | H8: =IF(A8="","",IF(B8="","EKSİK","TAM"))
A9: kil_iadeEsik | B9: 50000 | C9: TL | D9: İADE karar eşiği | E9: İç politika | F9: 01.01.2025 | G9: 14.08.2026 | H9: =IF(A9="","",IF(B9="","EKSİK","TAM"))
A10: kil_belgeLimit | B10: 0 | C10: adet | D10: İzin verilen eksik belge üst sınırı | E10: GİB belge | F10: 01.01.2025 | G10: 14.08.2026 | H10: =IF(A10="","",IF(B10="","EKSİK","TAM"))
A11: kil_senaryoIyi | B11: 0.9 | C11: çarpan | D11: İyimser iade çarpanı | E11: Model varsayımı | F11: 01.01.2025 | G11: 14.08.2026 | H11: =IF(A11="","",IF(B11="","EKSİK","TAM"))
A12: kil_senaryoKotu | B12: 1.1 | C12: çarpan | D12: Kötümser iade çarpanı | E12: Model varsayımı | F12: 01.01.2025 | G12: 14.08.2026 | H12: =IF(A12="","",IF(B12="","EKSİK","TAM"))
A13: kil_oranArtisPuan | B13: 0.01 | C13: oran | D13: M-SEN +1 puan | E13: Senaryo motoru | F13: 01.01.2025 | G13: 14.08.2026 | H13: =IF(A13="","",IF(B13="","EKSİK","TAM"))
A14: kil_tahminAlt | B14: 0.85 | C14: çarpan | D14: Tahmin alt bant | E14: Model varsayımı | F14: 01.01.2025 | G14: 14.08.2026 | H14: =IF(A14="","",IF(B14="","EKSİK","TAM"))
A15: kil_tahminUst | B15: 1.15 | C15: çarpan | D15: Tahmin üst bant | E15: Model varsayımı | F15: 01.01.2025 | G15: 14.08.2026 | H15: =IF(A15="","",IF(B15="","EKSİK","TAM"))
A16: kil_tornadoYuklenen | B16: 1.05 | C16: çarpan | D16: Tornado yüklenen şoku | E16: Model varsayımı | F16: 01.01.2025 | G16: 14.08.2026 | H16: =IF(A16="","",IF(B16="","EKSİK","TAM"))
A17: kil_tornadoIhrac | B17: 1.05 | C17: çarpan | D17: Tornado ihraç şoku | E17: Model varsayımı | F17: 01.01.2025 | G17: 14.08.2026 | H17: =IF(A17="","",IF(B17="","EKSİK","TAM"))
... A19: kil_yuzdelikOran | B19: 0.9 | C19: oran | D19: Yüzdelik P90 | E19: İstatistik | F19: 01.01.2025 | G19: 14.08.2026 | H19: =IF(A19="","",IF(B19="","EKSİK","TAM"))
A20: kil_parmakIzi | B20: d628bcbe2cac2b1c | C20: metin | D20: Dosya parmak izi etiketi | E20: Üretim | F20: 01.01.2025 | G20: 14.08.2026 | H20: =IF(A20="","",IF(B20="","EKSİK","TAM"))
A21: dosya_surumu | B21: 1.0.0 | C21: metin | D21: Ürün sürümü | E21: ExcelArşiv | F21: 01.01.2025 | G21: 14.08.2026 | H21: =IF(A21="","",IF(B21="","EKSİK","TAM"))
A22: kil_girisBeklenen | B22: 10 | C22: adet | D22: Zorunlu giriş alanı sayısı | E22: Ürün mimarisi | F22: 01.01.2025 | G22: 14.08.2026 | H22: =IF(A22="","",IF(B22="","EKSİK","TAM"))
A23: kil_riskDusuk | B23: 15 | C23: puan | D23: Düşük risk skoru | E23: İç politika | F23: 01.01.2025 | G23: 14.08.2026 | H23: =IF(A23="","",IF(B23="","EKSİK","TAM"))
A24: kil_riskOrta | B24: 55 | C24: puan | D24: Orta risk skoru | E24: İç politika | F24: 01.01.2025 | G24: 14.08.2026 | H24: =IF(A24="","",IF(B24="","EKSİK","TAM"))
A25: kil_riskYuksek | B25: 85 | C25: puan | D25: Yüksek risk skoru | E25: İç politika | F25: 01.01.2025 | G25: 14.08.2026 | H25: =IF(A25="","",IF(B25="","EKSİK","TAM"))
A26: kil_yilTaban | B26: 2024 | C26: yıl | D26: CHOOSE yıl tabanı (hesapYili−taban) | E26: Ürün mimarisi | F26: 01.01.2025 | G26: 14.08.2026 | H26: =IF(A26="","",IF(B26="","EKSİK","TAM"))
A27: kil_yuvarMax | B27: 2 | C27: adet | D27: ROUND basamak tavanı | E27: Ürün mimarisi | F27: 01.01.2025 | G27: 14.08.2026 | H27: =IF(A27="","",IF(B27="","EKSİK","TAM"))
A28: vaka_indirilecek | B28: 800000 | C28: TL | D28: Vaka indirilecek KDV | E28: Demo vaka | F28: 01.01.2025 | G28: 14.08.2026 | H28: =IF(A28="","",IF(B28="","EKSİK","TAM"))
A29: vaka_yuklenen | B29: 2000000 | C29: TL | D29: Vaka yüklenen KDV | E29: Demo vaka | F29: 01.01.2025 | G29: 14.08.2026 | H29: =IF(A29="","",IF(B29="","EKSİK","TAM"))
A30: vaka_ihrac | B30: 5000000 | C30: TL | D30: Vaka ihraç hasılat | E30: Demo vaka | F30: 01.01.2025 | G30: 14.08.2026 | H30: =IF(A30="","",IF(B30="","EKSİK","TAM"))
A31: vaka_gcb | B31: 4500000 | C31: TL | D31: Vaka GÇB tutarı | E31: Demo vaka | F31: 01.01.2025 | G31: 14.08.2026 | H31: =IF(A31="","",IF(B31="","EKSİK","TAM"))
B33: Parametre satırları yukarıda; ad tanımları B kolonuna bağlı.
B35: Sürüm 1.0.0 | Şifre koruması: 1234 (formül alanları)

Sheet KILAVUZ
A1: KILAVUZ — KDV İade Listesi Robotu (GİB 7 Liste)
A3: Karar kuralları
A5: • VERİ YOK — giriş tablosu boşsa hesap yapılmaz.
A6: • İADE — seçili iade tutarı eşik üzerinde ve belge limiti aşılmamış.
A7: • EKSİK BELGE — belge eksik adedi kil_belgeLimit üstünde.
A8: • BEKLE — seçili iade eşik altında veya sapma belirsiz.
A10: GİB 7 liste adları
A11: LISTE_1: İndirilecek KDV Listesi
A12: LISTE_2: Yüklenilen KDV Listesi
A13: LISTE_3: GÇB Listesi
A14: LISTE_4: Satış Faturaları Listesi
A15: LISTE_5: Alış Faturaları Listesi
... A20: Bu nokta mevzuatta tartışmalıdır; dosya yorum A ve yorum B sonucunu yan yana gösterir: liste_sirasi
A22: Yorum A | B22: İade tavanı ihraç hasılatı × KDV oranı ile sınırlanır (LISTE_4 / hasılat). Bu nokta mevzuatta tartışmalıdır; sonuç yorum B ile yan yana okunmalıdır.
A23: Yorum B | B23: İade tavanı GÇB tutarı × KDV oranı ile sınırlanır (LISTE_3). Dosya her iki yorumun sonucunu MOTOR'da üretir.
A25: Kullanım sırası
A26: GIRDI → KURALLAR → MOTOR → LISTE_1..LISTE_7 → SENARYO → VAKALAR → PANO → KANIT_RAPORU → AYARLAR → KILAVUZ.
A28: Sürüm 1.0.0 | Lisans: Tek kullanıcı | ExcelArşiv
