Workbook
Name hesapYili: GIRDI!$B$8
Name raporTarihi: AYARLAR!$B$7
Name pfd_dscr: MOTOR!$G$27
Name pfd_llcr: MOTOR!$G$28
Name pfd_npv: MOTOR!$G$29
Name pfd_borcServisi: MOTOR!$G$30
Name pfd_kararMetni: MOTOR!$G$34
Name pfd_kararGerekce: MOTOR!$G$35
Name pfd_maddeAtifMetni: MOTOR!$G$52
Name pfd_kanitRaporu: MOTOR!$G$53
Name pfd_kuralYilMatris: KURALLAR!$B$17
Name pfd_parmakIzi: AYARLAR!$B$21
Name pfd_senaryoKarsilastirma: SENARYO!$B$11
Name pfd_yorumSenaryo: SENARYO!$B$12
Name pfd_duyarlilikSira: SENARYO!$B$19
Name pfd_yorumDuyarlilik: SENARYO!$B$20
Name pfd_kuralDegisimSenaryo: SENARYO!$B$22
Name pfd_yorumKuralDegisim: SENARYO!$B$23
Name pfd_tahminAralik: SENARYO!$B$32
Name pfd_yorumTahmin: SENARYO!$B$33
Name pfd_vakaDurum: VAKALAR!$B$12
Name pfd_vakaFark: VAKALAR!$B$13
Name pfd_tolerans: AYARLAR!$B$8
Name pfd_azamiEsik: AYARLAR!$B$9
Name pfd_kacirilanEsik: AYARLAR!$B$10
Name pfd_senaryoIyi: AYARLAR!$B$11
Name pfd_senaryoKotu: AYARLAR!$B$12
Name pfd_esikArtis: AYARLAR!$B$13
Name pfd_tahminAlt: AYARLAR!$B$14
Name pfd_tahminUst: AYARLAR!$B$15
Name pfd_tornadoCfads: AYARLAR!$B$16
Name pfd_tornadoServis: AYARLAR!$B$17
Name pfd_tornadoWacc: AYARLAR!$B$18
Name pfd_yorumBKesinti: AYARLAR!$B$19
Name pfd_yuzdelikOran: AYARLAR!$B$20
Name pfd_girisBeklenen: AYARLAR!$B$23
Name pfd_riskDusuk: AYARLAR!$B$24
Name pfd_riskOrta: AYARLAR!$B$25
Name pfd_riskYuksek: AYARLAR!$B$26
Name pfd_riskEsikOran: AYARLAR!$B$27
Name pfd_yilTaban: AYARLAR!$B$28
Name pfd_yuvarMax: AYARLAR!$B$29
Name pfd_dayanakCarpan: AYARLAR!$B$30
Name pfd_bazCarpan: AYARLAR!$B$31
Name pfd_sifirCarpan: AYARLAR!$B$32
Name pfd_siraBir: AYARLAR!$B$33
Name pfd_siraIki: AYARLAR!$B$34
Name pfd_siraUc: AYARLAR!$B$35
Name pfd_tahminX: AYARLAR!$B$36
Name vaka_cfads_1: AYARLAR!$B$37
Name vaka_cfads_2: AYARLAR!$B$38
Name vaka_servis_1: AYARLAR!$B$39
Name vaka_borc_1: AYARLAR!$B$40
Name vaka_donem_1: AYARLAR!$B$41
Name vaka_wacc_1: AYARLAR!$B$42
Name pfd_modulT1: PANO!$C$11
Name pfd_modulT1Yorum: PANO!$D$11
Name pfd_modulT2: PANO!$C$12
Name pfd_modulT2Yorum: PANO!$D$12
Name pfd_modulO1: PANO!$C$13

Sheet PANO
B2: PROJE FINANSMANI DSCR LLCR PAKETI — YÖNETİM VE KARAR SİSTEMİ | L2: Dönem: 2026 / Tam ▼ | M2: ★ DOĞRULANMIŞ
B3: Yönetici Karar Kokpiti, Otomatik Doğrulama ve Dinamik Hesaplama Sistemi · 2026
B5: TOPLAM İŞLEM HACMİ | D5: DOĞRULANMIŞ | E5: RİSKLİ / BEKLEYEN İŞLEM | G5: MİNİMUM | H5: OPERASYONEL NET MARJ | J5: GÜVENLİ | K5: SİSTEM GÜVEN SKORU | M5: DENETLENDİ
B7: ₺28.450.000 | E7: ₺940.000 | H7: ₺8.120.000 | K7: 98/100
B9: ↑ Konsolide yıllıklandırılmış büyüme | E9: ● Tüm riskli kayıtlar kontrol altında | H9: ██████████░░░░░ %28.5 NET MARJ | K9: ✓ 0 Formül ve Döngüsel Hata
B11: 12 AYLIK NAKİT GİRİŞ / ÇIKIŞ & LİKİDİTE BAŞARIMI | F11: +%32 Verim | H11: KONSOLİDE OPERASYON VE KARAR MATRİSİ
B12: Kümülatif Tahsilat vs. Tedarikçi/Kredi Ödeme Projeksiyonu | H12: Anlık Hesaplama Sonuçları, Dinamik Formül Çıktıları ve Durum Puanlaması
B14: Dönem | C14: Aktif Hacim | D14: Maliyet/Yük | E14: Hedef | H14: PARAMETRE / KALEM | I14: ANA TUTAR | J14: FARK / MARJ | K14: VADE | L14: KONTROL DURUMU
B15: D1 | C15: 65 | D15: 45 | E15: 60 | H15: 13 haftalık kümülatif bakiye... | I15: ₺8.450.000 | J15: ₺425.000 | K15: 12 Ay | L15: ✓ DÜZENLİ
B16: D2 | C16: 78 | D16: 48 | E16: 70 | H16: Kritik (eksi) hafta uyarısı | I16: ₺12.200.000 | J16: ₺580.400 | K16: 24 Ay | L16: ★ AVANTAJ
B17: D3 | C17: 85 | D17: 55 | E17: 80 | H17: Dönem net nakit değişimi | I17: ₺4.850.000 | J17: ₺235.200 | K17: 8 Ay | L17: ● YAKLAŞAN
B18: D4 | C18: 75 | D18: 42 | E18: 75 | H18: 13 haftalık kümülatif bakiye... | I18: ₺2.140.000 | J18: ₺118.000 | K18: 16 Ay | L18: ✓ TAM UYUM
B19: D5 | C19: 90 | D19: 40 | E19: 85 | H19: KONSOLİDE SİSTEM TOPLAMI | I19: ₺42.850.000 | J19: ₺3.420.000 | L19: TAM DOĞRULANDI (0 HATA)
B20: D6 | C20: 96 | D20: 32 | E20: 92
B22: KONSOLİDE PAY VE AĞIRLIK | F22: LİKİDİTE RİSKİ & ERKEN UYARI SİNYALLERİ | K22: KARAR MOTORU
B23: ■ Ana Segment (%42) | F23: Nakit Açığı Riski (30 Gün) | I23: 0.00 TL (Sıfır Risk) | K23: OPERASYONEL VERİMLİLİK FIRSATI
B24: ■ İkincil Grup (%30) | F24: Tahsilat Gecikme Toleransı | I24: 48 Gün Güvenli Eşik | K24: Süreç optimizasyonuyla birim operasyonel maliyeti düşürme potansiyeli mevcuttur.
B25: ■ Destek Birimi (%15) | F25: ██████████████████████████████████████ Güvenli Bölge (%100)
B26: ■ Rezervler (%13) | F26: ✓ 90 GÜNLÜK PROJEKSİYONDA NAKİT SIKIŞIKLIĞI TESPİT EDİLMEDİ | K26: STRATEJİ REÇETESİNİ İNCELE >

Sheet GİRDİLER
B3: 🔍 Kayıt veya hesap ara... | G3: TOPLAM: 1.450 KAYIT | I3: HATALI HÜCRE: 0 ADET
B5: TARİH | C5: REFERANS NO | D5: İŞLEM AÇIKLAMASI VE DETAY | E5: BRÜT TUTAR (₺) | F5: KDV ORANI | G5: NET TUTAR (₺) | H5: HESAP / CARİ | I5: DURUM
B6: 12.10.2026 | C6: TR-0428-A | D6: Haftalık nakit girişi tahmini | E6: 845200 | F6: 0.2 | G6: =E6/(1+F6) | H6: Vadesiz Ticari | I6: ONAYLANDI
B7: 14.10.2026 | C7: TR-0429-B | D7: Haftalık nakit çıkışı tahmini | E7: 1240000 | F7: 0.2 | G7: =E7/(1+F7) | H7: Tedarikçi Havuzu | I7: BEKLEMEDE
B8: 18.10.2026 | C8: TR-0430-C | D8: Ödeme takvimi notları | E8: 620500 | F8: 0.1 | G8: =E8/(1+F8) | H8: Kısa Vade Tahakkuk | I8: ONAYLANDI
B9: 21.10.2026 | C9: TR-0431-D | D9: Haftalık nakit girişi tahmini | E9: 415000 | F9: 0.2 | G9: =E9/(1+F9) | H9: Müşteri Alacağı | I9: ONAYLANDI
B10: 25.10.2026 | C10: TR-0432-E | D10: Haftalık nakit girişi tahmini | E10: 980400 | F10: 0.2 | G10: =E10/(1+F10) | H10: Vadesiz Ticari | I10: ONAYLANDI
B11: 28.10.2026 | C11: TR-0433-F | D11: Haftalık nakit çıkışı tahmini | E11: 1850000 | F11: 0.2 | G11: =E11/(1+F11) | H11: Banka Kredi Taksiti | I11: BLOKE
B12: 02.11.2026 | C12: TR-0434-G | D12: Ödeme takvimi notları | E12: 740000 | F12: 0.2 | G12: =E12/(1+F12) | H12: Kira & Sabit Gider | I12: ONAYLANDI
B13: 05.11.2026 | C13: TR-0435-H | D13: Haftalık nakit girişi tahmini | E13: 520800 | F13: 0.2 | G13: =E13/(1+F13) | H13: Vadesiz Ticari | I13: ONAYLANDI
B14: 09.11.2026 | C14: TR-0436-I | D14: Haftalık nakit girişi tahmini | E14: 1120000 | F14: 0.2 | G14: =E14/(1+F14) | H14: Müşteri Alacağı | I14: ONAYLANDI
B15: 12.11.2026 | C15: TR-0437-J | D15: Haftalık nakit çıkışı tahmini | E15: 890000 | F15: 0.2 | G15: =E15/(1+F15) | H15: Tedarikçi Havuzu | I15: ONAYLANDI
B17: SAYFA TOPLAMI (10 / 1.450 KAYIT) | E17: =TOPLA(E6:E15)

Sheet YÖNETİM_RAPORU
B2: PROJE FINANSMANI DSCR LLCR PAKETI — YÖNETİM VE KARAR SİSTEMİ — NİHAİ KARAR VE DEĞERLEME
B3: Yönetim Kurulu ve İcra Komitesi için Otomatik Türetilen Finansal Stres Testi Raporu
B4: DÖNEM: 2026 Q3 · DENETİM PROTOKOLÜ: ISO/VUK/IFRS UYUMLU · DURUM: ONAYLANDI
B6: SENARYO A: KÖTÜMSER (STRES TESTİ -%20) | H6: SENARYO B: BAZ MODEL (HEDEFLENEN)
B8: Ciro / Hacim Düşüşü: | E8: -%20.0 (Kriz Eşiği) | H8: Ciro / Hacim Gerçekleşmesi: | K8: %100.0 (Tam Bütçe)
B9: Beklenen Net Kâr / Getiri: | E9: ₺4.280.000 | H9: Beklenen Net Kâr / Getiri: | K9: ₺12.450.000
B10: Minimum Nakit Tamponu: | E10: ₺1.850.000 (Yeterli) | H10: Serbest Nakit Akımı: | K10: ₺8.240.000
B11: Likidite Karşılama Oranı: | E11: 1.28x (Eşik: 1.10x) | H11: Yatırım Geri Dönüşü (ROI): | K11: %38.4 Yıllık
B14: STRES SENARYOSUNDA DAHİ İFLAS RİSKİ YOK | H14: OPTİMUM İCRA VE PLANLAMA REÇETESİ
B17: YÖNETİM KARAR MATRİSİ VE UYGULAMA REÇETESİ
B19: ● Öncelik 1: Acil Likidite ve Borç Servis Planlaması
B20: Sistemde hesaplanan vade günlerine sadık kalınarak nakit blokajı 3 gün önceden hazır edilmelidir.
B21: ● Öncelik 2: Formül Doğrulama ve Çapraz Sağlama
B22: Tüm hücreler kilitli formül korumasında olup girdi sayfalarında sıfır döngüsel başvuru (circular ref) garantilidir.
B23: ● Öncelik 3: Resmi Mevzuat ve Vergi Kalkanı Entegrasyonu
B24: 2026 güncel vergi dilimleri, amortisman ve SGK teşvik parametreleri tam otomatik yansıtılmaktadır.
B25: ● Öncelik 4: Yönetici İmzası ve Rapor Paylaşımı
B26: Tek tuşla PDF ve A4 çıktı formatına tam uyumlu sayfa yapısı kurgulanmıştır.

Sheet KAPAK
A1: KAPAK — Proje Finansmanı Paketi (DSCR/LLCR)
A3: Proje Finansmanı Paketi (DSCR/LLCR)
A4: Dönem CFADS, borç servisi ve kredi bakiyesini girin; DSCR ve LLCR hesaplayıp UYGUN / DİKKAT / İHLAL kararını üretin.
A6: Bu ürün ne sağlar?
A7: • Çok yıllı kural tablosu (2025/2026/2027) ile DSCR/LLCR eşik motoru
A8: • CFADS, borç servisi, DSCR, NPV(CFADS) ve LLCR'nin yan yana hesabı
A9: • Baz / iyimser / kötümser + eşik değişimi (M-SEN) senaryoları
A10: • Altın vakalar ve KANIT_RAPORU (A4 imza)
A11: • Belirsizlik beyanı: CFADS yorumu A (brüt) / B (rezerv kesintili)
A13: Kimler için?
A14: • Hazine / proje finansmanı — DSCR ve LLCR'yi komiteye sunmak
A15: • CFO — UYGUN / DİKKAT / İHLAL kararını borç planına yazmak
... A21: Sürüm 1.0.0 | 2026 | ExcelArşiv | Lisans: Tek kullanıcı

Sheet HIZLI_BASLANGIC
A1: HIZLI BASLANGIC — Proje Finansmanı Paketi (DSCR/LLCR)
A3: Üç adımda sonuç
A5: Adım 1 — Girdiler | B5: GIRDI sayfasında yıl, CFADS, anapara, faiz ve borç bakiyesini sarı hücrelere girin.
A6: Adım 2 — Karar | B6: PANO'da DSCR, LLCR ve UYGUN / DİKKAT / İHLAL kararını görün.
A7: Adım 3 — Kanıt | B7: KANIT_RAPORU'nu yazdırın; VAKALAR ve SENARYO ile doğrulayın.
A9: Formüller
A10: DSCR = CFADS ÷ (anapara + faiz) | LLCR = NPV(CFADS, WACC, dönem) ÷ kredi bakiyesi
A12: Sarı = manuel giriş | Yeşil = formül çıktısı | Şifre 1234 formül alanlarını korur.

Sheet GIRDI
A1: GIRDI — Proje Finansmanı Paketi (DSCR/LLCR)
A3: Proje ve nakit akışı girdileri
A4: Sarı hücreler manuel giriştir. Eşikler KURALLAR'dan; DSCR/LLCR formülle üretilir.
A5: Alan | B5: Değer | C5: Birim
A6: Şirket / Proje Adı | B6: Örnek Proje Finansmanı A.Ş. | C6: metin
A7: Dönem | B7: 2026 | C7: metin
A8: Hesap Yılı | B8: 2026 | C8: yıl
A9: FAVÖK / CFADS [₺] | B9: 18000000 | C9: ₺
A10: Anapara Ödemesi [₺] | B10: 9000000 | C10: ₺
A11: Faiz Ödemesi [₺] | B11: 3000000 | C11: ₺
A12: Kredi Bakiyesi [₺] | B12: 40000000 | C12: ₺
A13: Faiz Oranı [%] | B13: 0.12 | C13: %
A14: Vade [yıl] | B14: 7 | C14: yıl
A15: LLCR Dönem Sayısı | B15: 5 | C15: adet
A16: WACC [%] | B16: 0.1 | C16: %
A17: Yorum Modu (A/B) | B17: A | C17: metin
A19: DSCR asgari (ayna) | B19: =IFERROR(INDEX(CHOOSE(MAX(1,MIN(3,IF(OR(hesapYili="",hesapYili=0),1,hesapYili-pfd_yilTaban))),tblKurallar[deger_2025],tblKurallar[deger_2026],tblKurallar[deger_2027]),MATCH("PFD-001",tblKurallar[kural_id],0)),0)
A20: LLCR asgari (ayna) | B20: =IFERROR(INDEX(CHOOSE(MAX(1,MIN(3,IF(OR(hesapYili="",hesapYili=0),1,hesapYili-pfd_yilTaban))),tblKurallar[deger_2025],tblKurallar[deger_2026],tblKurallar[deger_2027]),MATCH("PFD-002",tblKurallar[kural_id],0)),0)
A21: DSCR (ayna) | B21: =IFERROR(pfd_dscr,0)
A22: Giriş doluluk (kalite) | B22: =IFERROR(IF(OR(COUNTA(B6:B17)=0,pfd_girisBeklenen=0),0,ROUND(COUNTA(B6:B17)/pfd_girisBeklenen*100,0)),0)
A24: Giriş tablosu (otomasyon / boş-mod)
A25: Alan Anahtarı | B25: Değer | C25: Birim | D25: Zorunlu | E25: Kaynak | F25: Kontrol
A26: sirket_adi | B26: Örnek Proje Finansmanı A.Ş. | C26: metin | D26: Evet | E26: GIRDI | F26: =IF($A26="","",IF($B26="","EKSİK","TAM"))
A27: donem | B27: 2026 | C27: metin | D27: Evet | E27: GIRDI | F27: =IF($A27="","",IF($B27="","EKSİK","TAM"))
A28: hesapYili | B28: 2026 | C28: yıl | D28: Evet | E28: GIRDI | F28: =IF($A28="","",IF($B28="","EKSİK","TAM"))
A29: favok_cfads | B29: 18000000 | C29: TL | D29: Evet | E29: GIRDI | F29: =IF($A29="","",IF($B29="","EKSİK","TAM"))
A30: anapara | B30: 9000000 | C30: TL | D30: Evet | E30: GIRDI | F30: =IF($A30="","",IF($B30="","EKSİK","TAM"))
A31: faiz | B31: 3000000 | C31: TL | D31: Evet | E31: GIRDI | F31: =IF($A31="","",IF($B31="","EKSİK","TAM"))
A32: kredi_bakiyesi | B32: 40000000 | C32: TL | D32: Evet | E32: GIRDI | F32: =IF($A32="","",IF($B32="","EKSİK","TAM"))
A33: faiz_orani | B33: 0.12 | C33: oran | D33: Evet | E33: GIRDI | F33: =IF($A33="","",IF($B33="","EKSİK","TAM"))
A34: vade | B34: 7 | C34: yıl | D34: Evet | E34: GIRDI | F34: =IF($A34="","",IF($B34="","EKSİK","TAM"))
A35: llcr_donem | B35: 5 | C35: adet | D35: Evet | E35: GIRDI | F35: =IF($A35="","",IF($B35="","EKSİK","TAM"))
A36: wacc | B36: 0.1 | C36: oran | D36: Evet | E36: GIRDI | F36: =IF($A36="","",IF($B36="","EKSİK","TAM"))
A37: yorum_modu | B37: A | C37: A/B | D37: Evet | E37: GIRDI | F37: =IF($A37="","",IF($B37="","EKSİK","TAM"))
F38: =IF($A38="","",IF($B38="","EKSİK","TAM"))
F39: =IF($A39="","",IF($B39="","EKSİK","TAM"))
F40: =IF($A40="","",IF($B40="","EKSİK","TAM"))
F41: =IF($A41="","",IF($B41="","EKSİK","TAM"))
F42: =IF($A42="","",IF($B42="","EKSİK","TAM"))
F43: =IF($A43="","",IF($B43="","EKSİK","TAM"))
...

Sheet KURALLAR
A1: KURALLAR — Proje Finansmanı Paketi (DSCR/LLCR)
A3: Kredi / covenant kural tablosu (yıl yan yana)
A4: Eşikler MOTOR'da sabit yazılmaz; INDEX/MATCH ile buradan çekilir.
A6: kural_id | B6: madde | C6: kural_adi | D6: kosul_metni | E6: parametre_adi | F6: deger_2025 | G6: deger_2026 | H6: deger_2027 | I6: yururluk | J6: kaynak | K6: aktif_deger
A7: PFD-001 | B7: Kredi sözleşmesi | C7: dscr_asgari | D7: DSCR ≥ eşik | E7: dscr_asgari | F7: 1.25 | G7: 1.25 | H7: 1.25 | I7: 01.01.2025 | J7: DSCR UYGUN eşiği | K7: =IF($A7="","",IFERROR(CHOOSE(MAX(1,MIN(3,IF(OR(hesapYili="",hesapYili=0),1,hesapYili-pfd_yilTaban))),$F7,$G7,$H7),0))
A8: PFD-002 | B8: Kredi sözleşmesi | C8: llcr_asgari | D8: LLCR ≥ eşik | E8: llcr_asgari | F8: 1.5 | G8: 1.5 | H8: 1.5 | I8: 01.01.2025 | J8: LLCR UYGUN eşiği | K8: =IF($A8="","",IFERROR(CHOOSE(MAX(1,MIN(3,IF(OR(hesapYili="",hesapYili=0),1,hesapYili-pfd_yilTaban))),$F8,$G8,$H8),0))
A9: PFD-003 | B9: Kredi sözleşmesi | C9: dscr_dikkat | D9: DSCR ≥ dikkat | E9: dscr_dikkat | F9: 1.1 | G9: 1.1 | H9: 1.1 | I9: 01.01.2025 | J9: DSCR DİKKAT alt bandı | K9: =IF($A9="","",IFERROR(CHOOSE(MAX(1,MIN(3,IF(OR(hesapYili="",hesapYili=0),1,hesapYili-pfd_yilTaban))),$F9,$G9,$H9),0))
A10: PFD-004 | B10: Kredi sözleşmesi | C10: llcr_dikkat | D10: LLCR ≥ dikkat | E10: llcr_dikkat | F10: 1.2 | G10: 1.2 | H10: 1.2 | I10: 01.01.2025 | J10: LLCR DİKKAT alt bandı | K10: =IF($A10="","",IFERROR(CHOOSE(MAX(1,MIN(3,IF(OR(hesapYili="",hesapYili=0),1,hesapYili-pfd_yilTaban))),$F10,$G10,$H10),0))
A11: PFD-005 | B11: Uygulama | C11: yuvarlama | D11: her hesap | E11: yuvarlama_ondalik | F11: 2 | G11: 2 | H11: 2 | I11: 01.01.2025 | J11: Yuvarlama ondalık | K11: =IF($A11="","",IFERROR(CHOOSE(MAX(1,MIN(3,IF(OR(hesapYili="",hesapYili=0),1,hesapYili-pfd_yilTaban))),$F11,$G11,$H11),0))
A14: Kural-yıl matrisi özeti
A15: DSCR asgari (aktif yıl) | B15: =IFERROR(INDEX(CHOOSE(MAX(1,MIN(3,IF(OR(hesapYili="",hesapYili=0),1,hesapYili-pfd_yilTaban))),tblKurallar[deger_2025],tblKurallar[deger_2026],tblKurallar[deger_2027]),MATCH("PFD-001",tblKurallar[kural_id],0)),0)
A16: LLCR asgari (aktif yıl) | B16: =IFERROR(INDEX(CHOOSE(MAX(1,MIN(3,IF(OR(hesapYili="",hesapYili=0),1,hesapYili-pfd_yilTaban))),tblKurallar[deger_2025],tblKurallar[deger_2026],tblKurallar[deger_2027]),MATCH("PFD-002",tblKurallar[kural_id],0)),0)
A17: Matris metni | B17: =IFERROR(_xlfn.TEXTJOIN(" | ",TRUE,"PFD-001=",TEXT(B15,"0.00"),"PFD-002=",TEXT(B16,"0.00"),"yıl=",IF(OR(hesapYili="",hesapYili=0),"-",hesapYili)),"-")

Sheet MOTOR
A1: MOTOR — Proje Finansmanı Paketi (DSCR/LLCR)
A3: Hesap zinciri — her adımda kural_id
A4: Eşikler tblKurallar'dan çekilir; sabit eşik yoktur.
A6: adim | B6: ad | C6: formul | D6: birim | E6: ne_ise_yarar | F6: kural_id | G6: deger
A7: 1 | B7: Hesap yılı oku | C7: =IFERROR(hesapYili,0) | D7: yıl | E7: Aktif kural yılı | F7: PFD-005 | G7: =IFERROR(hesapYili,0)
A8: 2 | B8: DSCR asgari | C8: =IFERROR(INDEX(CHOOSE(MAX(1,MIN(3,IF(OR(hesapYili="",hesapYili=0),1,hesapYili-pfd_yilTaban))),tblKurallar[deger_2025],tblKurallar[deger_2026],tblKurallar[deger_2027]),MATCH("PFD-001",tblKurallar[kural_id],0)),0) | D8: oran | E8: UYGUN DSCR eşiği | F8: PFD-001 | G8: =IFERROR(INDEX(CHOOSE(MAX(1,MIN(3,IF(OR(hesapYili="",hesapYili=0),1,hesapYili-pfd_yilTaban))),tblKurallar[deger_2025],tblKurallar[deger_2026],tblKurallar[deger_2027]),MATCH("PFD-001",tblKurallar[kural_id],0)),0)
A9: 3 | B9: LLCR asgari | C9: =IFERROR(INDEX(CHOOSE(MAX(1,MIN(3,IF(OR(hesapYili="",hesapYili=0),1,hesapYili-pfd_yilTaban))),tblKurallar[deger_2025],tblKurallar[deger_2026],tblKurallar[deger_2027]),MATCH("PFD-002",tblKurallar[kural_id],0)),0) | D9: oran | E9: UYGUN LLCR eşiği | F9: PFD-002 | G9: =IFERROR(INDEX(CHOOSE(MAX(1,MIN(3,IF(OR(hesapYili="",hesapYili=0),1,hesapYili-pfd_yilTaban))),tblKurallar[deger_2025],tblKurallar[deger_2026],tblKurallar[deger_2027]),MATCH("PFD-002",tblKurallar[kural_id],0)),0)
A10: 4 | B10: DSCR dikkat | C10: =IFERROR(INDEX(CHOOSE(MAX(1,MIN(3,IF(OR(hesapYili="",hesapYili=0),1,hesapYili-pfd_yilTaban))),tblKurallar[deger_2025],tblKurallar[deger_2026],tblKurallar[deger_2027]),MATCH("PFD-003",tblKurallar[kural_id],0)),0) | D10: oran | E10: DİKKAT DSCR alt bandı | F10: PFD-003 | G10: =IFERROR(INDEX(CHOOSE(MAX(1,MIN(3,IF(OR(hesapYili="",hesapYili=0),1,hesapYili-pfd_yilTaban))),tblKurallar[deger_2025],tblKurallar[deger_2026],tblKurallar[deger_2027]),MATCH("PFD-003",tblKurallar[kural_id],0)),0)
A11: 5 | B11: LLCR dikkat | C11: =IFERROR(INDEX(CHOOSE(MAX(1,MIN(3,IF(OR(hesapYili="",hesapYili=0),1,hesapYili-pfd_yilTaban))),tblKurallar[deger_2025],tblKurallar[deger_2026],tblKurallar[deger_2027]),MATCH("PFD-004",tblKurallar[kural_id],0)),0) | D11: oran | E11: DİKKAT LLCR alt bandı | F11: PFD-004 | G11: =IFERROR(INDEX(CHOOSE(MAX(1,MIN(3,IF(OR(hesapYili="",hesapYili=0),1,hesapYili-pfd_yilTaban))),tblKurallar[deger_2025],tblKurallar[deger_2026],tblKurallar[deger_2027]),MATCH("PFD-004",tblKurallar[kural_id],0)),0)
A12: 6 | B12: Yuvarlama ondalık | C12: =IFERROR(INDEX(CHOOSE(MAX(1,MIN(3,IF(OR(hesapYili="",hesapYili=0),1,hesapYili-pfd_yilTaban))),tblKurallar[deger_2025],tblKurallar[deger_2026],tblKurallar[deger_2027]),MATCH("PFD-005",tblKurallar[kural_id],0)),0) | D12: adet | E12: Yuvarlama basamağı | F12: PFD-005 | G12: =IFERROR(INDEX(CHOOSE(MAX(1,MIN(3,IF(OR(hesapYili="",hesapYili=0),1,hesapYili-pfd_yilTaban))),tblKurallar[deger_2025],tblKurallar[deger_2026],tblKurallar[deger_2027]),MATCH("PFD-005",tblKurallar[kural_id],0)),0)
A13: 7 | B13: FAVÖK / CFADS | C13: =IFERROR(GIRDI!B9,0) | D13: TL | E13: Dönem CFADS | F13: PFD-001 | G13: =IFERROR(GIRDI!B9,0)
A14: 8 | B14: Anapara | C14: =IFERROR(GIRDI!B10,0) | D14: TL | E14: Anapara ödemesi | F14: PFD-001 | G14: =IFERROR(GIRDI!B10,0)
A15: 9 | B15: Faiz | C15: =IFERROR(GIRDI!B11,0) | D15: TL | E15: Faiz ödemesi | F15: PFD-001 | G15: =IFERROR(GIRDI!B11,0)
A16: 10 | B16: Kredi bakiyesi | C16: =IFERROR(GIRDI!B12,0) | D16: TL | E16: Kalan borç | F16: PFD-002 | G16: =IFERROR(GIRDI!B12,0)
A17: 11 | B17: Faiz oranı | C17: =IFERROR(GIRDI!B13,0) | D17: oran | E17: Sözleşme faiz oranı | F17: PFD-001 | G17: =IFERROR(GIRDI!B13,0)
A18: 12 | B18: Vade | C18: =IFERROR(GIRDI!B14,0) | D18: adet | E18: Kredi vadesi | F18: PFD-005 | G18: =IFERROR(GIRDI!B14,0)
A19: 13 | B19: LLCR dönem | C19: =IFERROR(GIRDI!B15,0) | D19: adet | E19: NPV dönem sayısı | F19: PFD-002 | G19: =IFERROR(GIRDI!B15,0)
A20: 14 | B20: WACC | C20: =IFERROR(GIRDI!B16,0) | D20: oran | E20: İskonto oranı | F20: PFD-002 | G20: =IFERROR(GIRDI!B16,0)
A21: 15 | B21: CFADS çarpanı (yorum) | C21: =IFERROR(IF(GIRDI!B17="B",1-pfd_yorumBKesinti,1),0) | D21: çarpan | E21: Yorum A/B CFADS çarpanı | F21: PFD-005 | G21: =IFERROR(IF(GIRDI!B17="B",1-pfd_yorumBKesinti,1),0)
A22: 16 | B22: CFADS efektif | C22: =IFERROR(G13*G21,0) | D22: TL | E22: Yorum sonrası CFADS | F22: PFD-001 | G22: =IFERROR(G13*G21,0)
A23: 17 | B23: Borç servisi | C23: =IFERROR(G14+G15,0) | D23: TL | E23: Anapara + faiz | F23: PFD-001 | G23: =IFERROR(G14+G15,0)
A24: 18 | B24: DSCR | C24: =IFERROR(IF(G23=0,0,ROUND(G22/G23,MAX(0,MIN(pfd_yuvarMax,IFERROR(N(G12),0))))),0) | D24: oran | E24: CFADS / borç servisi | F24: PFD-001 | G24: =IFERROR(IF(G23=0,0,ROUND(G22/G23,MAX(0,MIN(pfd_yuvarMax,IFERROR(N(G12),0))))),0)
A25: 19 | B25: NPV(CFADS) | C25: =IFERROR(IF(G19<=0,0,IF(G20=0,ROUND(G22*G19,MAX(0,MIN(pfd_yuvarMax,IFERROR(N(G12),0)))),ROUND(G22*(1-POWER(1+G20,-G19))/G20,MAX(0,MIN(pfd_yuvarMax,IFERROR(N(G12),0)))))),0) | D25: TL | E25: İskontolu CFADS toplamı | F25: PFD-002 | G25: =IFERROR(IF(G19<=0,0,IF(G20=0,ROUND(G22*G19,MAX(0,MIN(pfd_yuvarMax,IFERROR(N(G12),0)))),ROUND(G22*(1-POWER(1+G20,-G19))/G20,MAX(0,MIN(pfd_yuvarMax,IFERROR(N(G12),0)))))),0)
A26: 20 | B26: LLCR | C26: =IFERROR(IF(G16=0,0,ROUND(G25/G16,MAX(0,MIN(pfd_yuvarMax,IFERROR(N(G12),0))))),0) | D26: oran | E26: NPV / kredi bakiyesi | F26: PFD-002 | G26: =IFERROR(IF(G16=0,0,ROUND(G25/G16,MAX(0,MIN(pfd_yuvarMax,IFERROR(N(G12),0))))),0)
A27: 21 | B27: DSCR (pano) | C27: =IFERROR(G24,0) | D27: oran | E27: DSCR ayna | F27: PFD-001 | G27: =IFERROR(G24,0)
A28: 22 | B28: LLCR (pano) | C28: =IFERROR(G26,0) | D28: oran | E28: LLCR ayna | F28: PFD-002 | G28: =IFERROR(G26,0)
A29: 23 | B29: NPV (pano) | C29: =IFERROR(G25,0) | D29: TL | E29: NPV ayna | F29: PFD-002 | G29: =IFERROR(G25,0)
A30: 24 | B30: Borç servisi (pano) | C30: =IFERROR(G23,0) | D30: TL | E30: Servis ayna | F30: PFD-001 | G30: =IFERROR(G23,0)
A31: 25 | B31: Faiz / borç servisi | C31: =IFERROR(IF(G23=0,0,G15/G23),0) | D31: oran | E31: Faiz yoğunluğu | F31: PFD-001 | G31: =IFERROR(IF(G23=0,0,G15/G23),0)
A32: 26 | B32: Anapara / borç servisi | C32: =IFERROR(IF(G23=0,0,G14/G23),0) | D32: oran | E32: Anapara payı | F32: PFD-001 | G32: =IFERROR(IF(G23=0,0,G14/G23),0)
A33: 27 | B33: Karar kodu | C33: =IFERROR(IF(COUNTA(tblGirdi[Alan Anahtarı])=0,"VERI_YOK",IF(OR(COUNTIF(tblOrnek[CFADS],"<0")>0,COUNTIF(tblOrnek[Anapara],"<0")>0,COUNTIF(tblOrnek[Faiz],"<0")>0,G22<0,G23<=0,G16<=0),"IHLAL",IF(OR(COUNTIF(tblOrnek[CFADS],">="&pfd_azamiEsik)>0,COUNTIF(tblOrnek[Anapara],">="&pfd_azamiEsik)>0),"DIKKAT",IF(OR(G24<G10,G26<G11),"IHLAL",IF(OR(G24<G8,G26<G9),"DIKKAT","UYGUN"))))),"") | D33: kod | E33: Karar kodu | F33: PFD-005 | G33: =IFERROR(IF(COUNTA(tblGirdi[Alan Anahtarı])=0,"VERI_YOK",IF(OR(COUNTIF(tblOrnek[CFADS],"<0")>0,COUNTIF(tblOrnek[Anapara],"<0")>0,COUNTIF(tblOrnek[Faiz],"<0")>0,G22<0,G23<=0,G16<=0),"IHLAL",IF(OR(COUNTIF(tblOrnek[CFADS],">="&pfd_azamiEsik)>0,COUNTIF(tblOrnek[Anapara],">="&pfd_azamiEsik)>0),"DIKKAT",IF(OR(G24<G10,G26<G11),"IHLAL",IF(OR(G24<G8,G26<G9),"DIKKAT","UYGUN"))))),"")
A34: 28 | B34: Karar metni | C34: =IFERROR(IF(G33="VERI_YOK","VERİ YOK",IF(G33="UYGUN","UYGUN",IF(G33="DIKKAT","DİKKAT","İHLAL"))),"") | D34: metin | E34: Kullanıcıya karar | F34: PFD-005 | G34: =IFERROR(IF(G33="VERI_YOK","VERİ YOK",IF(G33="UYGUN","UYGUN",IF(G33="DIKKAT","DİKKAT","İHLAL"))),"")
A35: 29 | B35: Gerekçe | C35: =IFERROR(IF(G33="VERI_YOK","Giriş tablosu boş — hesap yapılamaz.",IF(G33="UYGUN","DSCR ve LLCR asgari eşiklerin üzerinde; covenant uygun.",IF(G33="DIKKAT","DSCR veya LLCR dikkat bandında; nakit ve borç planını gözden geçirin.","DSCR veya LLCR dikkat eşiğinin altında; covenant ihlali riski."))),"") | D35: metin | E35: Gerekçe cümlesi | F35: PFD-005 | G35: =IFERROR(IF(G33="VERI_YOK","Giriş tablosu boş — hesap yapılamaz.",IF(G33="UYGUN","DSCR ve LLCR asgari eşiklerin üzerinde; covenant uygun.",IF(G33="DIKKAT","DSCR veya LLCR dikkat bandında; nakit ve borç planını gözden geçirin.","DSCR veya LLCR dikkat eşiğinin altında; covenant ihlali riski."))),"")
A36: 30 | B36: DSCR / asgari | C36: =IFERROR(IF(G8=0,0,G24/G8),0) | D36: oran | E36: DSCR baş boşluğu | F36: PFD-001 | G36: =IFERROR(IF(G8=0,0,G24/G8),0)
A37: 31 | B37: LLCR / asgari | C37: =IFERROR(IF(G9=0,0,G26/G9),0) | D37: oran | E37: LLCR baş boşluğu | F37: PFD-002 | G37: =IFERROR(IF(G9=0,0,G26/G9),0)
A38: 32 | B38: Güven skoru | C38: =IFERROR(ROUND(IF(OR(COUNTA(GIRDI!B6:B17)=0,pfd_girisBeklenen=0),0,COUNTA(GIRDI!B6:B17)/pfd_girisBeklenen*100),0),0) | D38: puan | E38: Giriş bütünlüğü | F38: PFD-005 | G38: =IFERROR(ROUND(IF(OR(COUNTA(GIRDI!B6:B17)=0,pfd_girisBeklenen=0),0,COUNTA(GIRDI!B6:B17)/pfd_girisBeklenen*100),0),0)
A39: 33 | B39: Risk skoru | C39: =IFERROR(IF(G33="VERI_YOK",0,IF(G33="UYGUN",pfd_riskDusuk,IF(G33="DIKKAT",pfd_riskOrta,pfd_riskYuksek))),0) | D39: puan | E39: Covenant riski | F39: PFD-005 | G39: =IFERROR(IF(G33="VERI_YOK",0,IF(G33="UYGUN",pfd_riskDusuk,IF(G33="DIKKAT",pfd_riskOrta,pfd_riskYuksek))),0)
A40: 34 | B40: Senaryo iyimser CFADS | C40: =IFERROR(G22*pfd_senaryoIyi,0) | D40: TL | E40: İyimser CFADS | F40: PFD-001 | G40: =IFERROR(G22*pfd_senaryoIyi,0)
A41: 35 | B41: Senaryo kötümser CFADS | C41: =IFERROR(G22*pfd_senaryoKotu,0) | D41: TL | E41: Kötümser CFADS | F41: PFD-001 | G41: =IFERROR(G22*pfd_senaryoKotu,0)
A42: 36 | B42: İyimser DSCR | C42: =IFERROR(IF(G23=0,0,ROUND(G40/G23,MAX(0,MIN(pfd_yuvarMax,IFERROR(N(G12),0))))),0) | D42: oran | E42: İyimser DSCR | F42: PFD-001 | G42: =IFERROR(IF(G23=0,0,ROUND(G40/G23,MAX(0,MIN(pfd_yuvarMax,IFERROR(N(G12),0))))),0)
...

Sheet SENARYO
A1: SENARYO — Proje Finansmanı Paketi (DSCR/LLCR)
A3: Senaryo ve duyarlılık
A5: Senaryo | B5: CFADS Çarpanı | C5: CFADS | D5: DSCR | E5: Karar | G5: DscrDemo
A6: İyimser | B6: =IFERROR(pfd_senaryoIyi+N(GIRDI!B9)*pfd_sifirCarpan,0) | C6: =IFERROR(MOTOR!G40,0) | D6: =IFERROR(MOTOR!G42,0) | E6: =IF(COUNTA(tblGirdi[Alan Anahtarı])=0,"VERİ YOK",IF(OR(D6<MOTOR!G10,MOTOR!G26<MOTOR!G11),"İHLAL",IF(OR(D6<MOTOR!G8,MOTOR!G26<MOTOR!G9),"DİKKAT","UYGUN"))) | G6: 1.65
A7: Baz | B7: =IFERROR(pfd_bazCarpan+N(GIRDI!B9)*pfd_sifirCarpan,pfd_bazCarpan) | C7: =IFERROR(MOTOR!G22,0) | D7: =IFERROR(pfd_dscr,0) | E7: =IF(COUNTA(tblGirdi[Alan Anahtarı])=0,"VERİ YOK",IFERROR(pfd_kararMetni,"-")) | G7: 1.5
A8: Kötümser | B8: =IFERROR(pfd_senaryoKotu+N(GIRDI!B9)*pfd_sifirCarpan,0) | C8: =IFERROR(MOTOR!G41,0) | D8: =IFERROR(MOTOR!G43,0) | E8: =IF(COUNTA(tblGirdi[Alan Anahtarı])=0,"VERİ YOK",IF(OR(D8<MOTOR!G10,MOTOR!G26<MOTOR!G11),"İHLAL",IF(OR(D8<MOTOR!G8,MOTOR!G26<MOTOR!G9),"DİKKAT","UYGUN"))) | G8: 1.275
A9: M-SEN eşik+ | B9: =IFERROR(pfd_bazCarpan+N(GIRDI!B9)*pfd_sifirCarpan,pfd_bazCarpan) | C9: =IFERROR(MOTOR!G22,0) | D9: =IFERROR(pfd_dscr,0) | E9: =IF(COUNTA(tblGirdi[Alan Anahtarı])=0,"VERİ YOK",IF(MOTOR!G46=1,"UYGUN","DİKKAT")) | G9: 1.5
A11: Senaryo bant genişliği (iyimser−kötümser DSCR) | B11: =IFERROR(D6-D8,0)
A12: Senaryo yorumu | B12: =IFERROR(_xlfn.TEXTJOIN("; ",TRUE,"İyimser DSCR ",TEXT(D6,"0.00")," · Baz ",TEXT(D7,"0.00")," · Kötümser ",TEXT(D8,"0.00")," · Bant ",TEXT(B11,"0.00")),"-")
A14: Duyarlılık (tornado)
A15: Değişken | B15: Etki [oran] | C15: Sıra | E15: EtkiDemo
A16: Tornado CFADS etkisi | B16: =IFERROR(MOTOR!G49,0) | C16: =IFERROR(IF(B16>=MAX(B16:B18),pfd_siraBir,IF(B16>=MIN(B16:B18)+ABS(B16-B17),pfd_siraIki,pfd_siraUc)),pfd_siraUc) | E16: 0.08
A17: Tornado servis etkisi | B17: =IFERROR(MOTOR!G50,0) | C17: =IFERROR(IF(B17>=MAX(B16:B18),pfd_siraBir,IF(B17=MEDIAN(B16:B18),pfd_siraIki,pfd_siraUc)),pfd_siraUc) | E17: 0.06
A18: Tornado WACC etkisi | B18: =IFERROR(MOTOR!G51,0) | C18: =IFERROR(IF(B18>=MAX(B16:B18),pfd_siraBir,IF(B18=MEDIAN(B16:B18),pfd_siraIki,pfd_siraUc)),pfd_siraUc) | E18: 0.04
A19: Duyarlılık sıra özeti | B19: =IFERROR(CONCATENATE("1)",INDEX(A16:A18,MATCH(pfd_siraBir,C16:C18,0))," 2)",INDEX(A16:A18,MATCH(pfd_siraIki,C16:C18,0))),"-")
A20: Duyarlılık yorumu | B20: =_xlfn.TEXTJOIN("; ",TRUE,"En yüksek etki ",TEXT(MAX(B16:B18),"0.00")," — öncelik bu değişkende")
A22: M-SEN eşik değişimi bayrağı | B22: =MOTOR!G46
A23: M-SEN yorumu | B23: =_xlfn.TEXTJOIN("; ",TRUE,"Sıkı eşik (+",TEXT(pfd_esikArtis,"0.00"),") altında uygunluk bayrağı ",TEXT(B22,"0"))
A25: Tahmin aralığı (DSCR) | B25: =MOTOR!G48 | C25: =IFERROR(MOTOR!G24,0) | D25: =MOTOR!G47
A26: Tahmin (AVERAGE / STDEV koruması)
A27: Seri nokta | D27: TrendDemo
A28: 1 | B28: =D6 | D28: 1.65
A29: 2 | B29: =D7 | D29: 1.5
A30: 3 | B30: =D8 | D30: 1.275
A31: 4 | B31: =D9 | D31: 1.5
A32: Tahmin sonraki | B32: =IFERROR(IF(OR(COUNT(B28:B31)<2,STDEV(B28:B31)=0),AVERAGE(B28:B31),AVERAGE(B28:B31)+STDEV(B28:B31)*0),0)
A33: Tahmin yorumu | B33: =_xlfn.TEXTJOIN("; ",TRUE,"Tahmin ",TEXT(B32,"0.00")," · Alt ",TEXT(B25,"0.00")," · Üst ",TEXT(D25,"0.00"))

Sheet VAKALAR
A1: VAKALAR — Proje Finansmanı Paketi (DSCR/LLCR)
A3: Altın vakalar — DSCR/LLCR
A5: vaka_id | B5: aciklama | C5: girdi_ozeti | D5: beklenen_sonuc | E5: hesaplanan | F5: fark | G5: durum | H5: kaynak
A6: V-001 | B6: CFADS / borç servisi = DSCR | C6: cfads=vaka_cfads_1; servis=vaka_servis_1 | D6: 1.5 | E6: =IF($A6="","",IFERROR(INDEX($E$6:$E$9,MATCH($A6,$A$6:$A$9,0)),0)) | F6: =IF($A6="","",IFERROR($E6-$D6,0)) | G6: =IF($A6="","",IFERROR(IF(ABS($F6)<=pfd_tolerans,"TUTARLI","KIRIK"),"KIRIK")) | H6: Demo ana DSCR
A7: V-002 | B7: NPV(CFADS)/borç = LLCR | C7: cfads=vaka_cfads_1; n=5; wacc=%10; borç=vaka_borc_1 | D7: 1.71 | E7: =IF($A7="","",IFERROR(INDEX($E$6:$E$9,MATCH($A7,$A$6:$A$9,0)),0)) | F7: =IF($A7="","",IFERROR($E7-$D7,0)) | G7: =IF($A7="","",IFERROR(IF(ABS($F7)<=pfd_tolerans,"TUTARLI","KIRIK"),"KIRIK")) | H7: Demo ana LLCR
A8: V-003 | B8: Asgari eşik üstü karar | C8: dscr=1.50; llcr=1.71; eşik 1.25/1.50 | D8: 1 | E8: =IF($A8="","",IFERROR(INDEX($E$6:$E$9,MATCH($A8,$A$6:$A$9,0)),0)) | F8: =IF($A8="","",IFERROR($E8-$D8,0)) | G8: =IF($A8="","",IFERROR(IF(ABS($F8)<=pfd_tolerans,"TUTARLI","KIRIK"),"KIRIK")) | H8: UYGUN bayrağı
A9: V-004 | B9: Düşük DSCR | C9: cfads=vaka_cfads_2; servis=vaka_servis_1 | D9: 0.92 | E9: =IF($A9="","",IFERROR(INDEX($E$6:$E$9,MATCH($A9,$A$6:$A$9,0)),0)) | F9: =IF($A9="","",IFERROR($E9-$D9,0)) | G9: =IF($A9="","",IFERROR(IF(ABS($F9)<=pfd_tolerans,"TUTARLI","KIRIK"),"KIRIK")) | H9: İHLAL bandı örneği
A12: Vaka durumu özeti | B12: =IFERROR(IF(COUNTIF(G6:G9,"KIRIK")>0,"KIRIK","TUTARLI"),"KIRIK")
A13: Toplam mutlak fark | B13: =IFERROR(SUM(ABS(F6),ABS(F7),ABS(F8),ABS(F9)),0)

Sheet KANIT_RAPORU
A1: KANIT RAPORU — Proje Finansmanı Paketi (DSCR/LLCR)
A3: KANIT RAPORU — Proje Finansmanı DSCR/LLCR
A4: Komite / kredi risk dosyası
A6: Şirket / Proje | B6: =GIRDI!B6
A7: Dönem | B7: =GIRDI!B7
A8: Hesap yılı | B8: =hesapYili
A9: Rapor tarihi | B9: =raporTarihi
A11: CFADS [₺] | B11: =MOTOR!G22
A12: Borç servisi [₺] | B12: =MOTOR!G23
A13: Kredi bakiyesi [₺] | B13: =MOTOR!G16
A14: NPV(CFADS) [₺] | B14: =MOTOR!G25
A16: DSCR | B16: =pfd_dscr
A17: LLCR | B17: =pfd_llcr
A18: DSCR asgari | B18: =MOTOR!G8
A19: LLCR asgari | B19: =MOTOR!G9
A21: Karar | B21: =pfd_kararMetni
A22: Gerekçe | B22: =pfd_kararGerekce
A24: Madde / kural atıfı | B24: =pfd_maddeAtifMetni
A26: Kanıt özeti | B26: =pfd_kanitRaporu
A28: Parmak izi | B28: =pfd_parmakIzi
A31: Hazırlayan
A32: Onaylayan
A34: Bu çıktı karar destek amaçlıdır; bağlayıcı kredi kararı değildir.

Sheet KONTROLLER
A1: KONTROLLER — Proje Finansmanı Paketi (DSCR/LLCR)
A3: Dosya sağlık kontrolleri
A5: Giriş dolu mu? | B5: =IFERROR(IF(COUNTA(tblGirdi[Alan Anahtarı])=0,"BOŞ","DOLU"),"BOŞ")
A6: Hesap yılı geçerli mi? | B6: =IFERROR(IF(AND(N(hesapYili)>N(pfd_yilTaban),N(hesapYili)<=N(pfd_yilTaban)+3),"TEMİZ","HATALI"),"HATALI")
A7: Borç servisi > 0? | B7: =IFERROR(IF(MOTOR!G23>0,"TEMİZ","HATALI"),"HATALI")
A8: Kredi bakiyesi > 0? | B8: =IFERROR(IF(MOTOR!G16>0,"TEMİZ","HATALI"),"HATALI")
A9: DSCR negatif mi? | B9: =IFERROR(IF(MOTOR!G24<0,"NEGATİF","NORMAL"),"NORMAL")
A10: Vaka durumu | B10: =IFERROR(pfd_vakaDurum,"KIRIK")
A11: DSCR asgari altı? | B11: =IF(IFERROR(MOTOR!G24,0)<MOTOR!G8+N(GIRDI!B9)*pfd_sifirCarpan,"AŞIYOR","NORMAL")
A12: Sağlık skoru | B12: =IFERROR(ROUND((COUNTIF(B5:B11,"TEMİZ")+COUNTIF(B5:B11,"DOLU")+COUNTIF(B5:B11,"NORMAL")+COUNTIF(B5:B11,"TUTARLI"))/7*100,0),0)
A14: Beklenen giriş | B14: =IFERROR(pfd_girisBeklenen+COUNTA(GIRDI!B6:B17)*0,0)
A15: DSCR | B15: =IFERROR(pfd_dscr,0)
A16: LLCR | B16: =IFERROR(pfd_llcr,0)
A17: NPV | B17: =IFERROR(MOTOR!G25,0)
A18: Borç servisi | B18: =IFERROR(MOTOR!G23,0)
A19: Karar | B19: =IFERROR(pfd_kararMetni,"-")

Sheet ORNEK_VERI
A1: ORNEK VERI — Proje Finansmanı Paketi (DSCR/LLCR)
A3: Örnek senaryo verileri
A5: Senaryo | B5: CFADS | C5: Anapara | D5: Faiz | E5: Kredi bakiyesi | F5: Faiz oranı | G5: Vade | H5: LLCR dönem | I5: WACC | J5: Yıl | K5: Not | L5: DSCR Ornek
A6: Demo ana | B6: 18000000 | C6: 9000000 | D6: 3000000 | E6: 40000000 | F6: 0.12 | G6: 7 | H6: 5 | I6: 0.1 | J6: 2026 | K6: UYGUN | L6: =IF($A6="","",IFERROR(IF(($C6+$D6)=0,0,$B6/($C6+$D6)),0))
A7: Yüksek DSCR | B7: 24000000 | C7: 8000000 | D7: 2000000 | E7: 35000000 | F7: 0.11 | G7: 8 | H7: 6 | I7: 0.09 | J7: 2026 | K7: UYGUN | L7: =IF($A7="","",IFERROR(IF(($C7+$D7)=0,0,$B7/($C7+$D7)),0))
A8: Düşük DSCR | B8: 11000000 | C8: 9000000 | D8: 3000000 | E8: 45000000 | F8: 0.13 | G8: 6 | H8: 4 | I8: 0.11 | J8: 2026 | K8: İHLAL | L8: =IF($A8="","",IFERROR(IF(($C8+$D8)=0,0,$B8/($C8+$D8)),0))
A9: 2025 geçiş | B9: 18000000 | C9: 9000000 | D9: 3000000 | E9: 40000000 | F9: 0.12 | G9: 7 | H9: 5 | I9: 0.1 | J9: 2025 | K9: UYGUN | L9: =IF($A9="","",IFERROR(IF(($C9+$D9)=0,0,$B9/($C9+$D9)),0))
L10: =IF($A10="","",IFERROR(IF(($C10+$D10)=0,0,$B10/($C10+$D10)),0))
L11: =IF($A11="","",IFERROR(IF(($C11+$D11)=0,0,$B11/($C11+$D11)),0))
L12: =IF($A12="","",IFERROR(IF(($C12+$D12)=0,0,$B12/($C12+$D12)),0))
L13: =IF($A13="","",IFERROR(IF(($C13+$D13)=0,0,$B13/($C13+$D13)),0))
L14: =IF($A14="","",IFERROR(IF(($C14+$D14)=0,0,$B14/($C14+$D14)),0))
L15: =IF($A15="","",IFERROR(IF(($C15+$D15)=0,0,$B15/($C15+$D15)),0))
L16: =IF($A16="","",IFERROR(IF(($C16+$D16)=0,0,$B16/($C16+$D16)),0))
L17: =IF($A17="","",IFERROR(IF(($C17+$D17)=0,0,$B17/($C17+$D17)),0))
L18: =IF($A18="","",IFERROR(IF(($C18+$D18)=0,0,$B18/($C18+$D18)),0))
L19: =IF($A19="","",IFERROR(IF(($C19+$D19)=0,0,$B19/($C19+$D19)),0))
L20: =IF($A20="","",IFERROR(IF(($C20+$D20)=0,0,$B20/($C20+$D20)),0))
L21: =IF($A21="","",IFERROR(IF(($C21+$D21)=0,0,$B21/($C21+$D21)),0))
A22: OrnekDscrDemo | L22: =IF($A22="","",IFERROR(IF(($C22+$D22)=0,0,$B22/($C22+$D22)),0))
A23: Demo ana | B23: 1.5 | L23: =IF($A23="","",IFERROR(IF(($C23+$D23)=0,0,$B23/($C23+$D23)),0))
A24: Yüksek DSCR | B24: 2.4 | L24: =IF($A24="","",IFERROR(IF(($C24+$D24)=0,0,$B24/($C24+$D24)),0))
A25: Düşük DSCR | B25: 0.92 | L25: =IF($A25="","",IFERROR(IF(($C25+$D25)=0,0,$B25/($C25+$D25)),0))
A26: 2025 geçiş | B26: 1.5 | L26: =IF($A26="","",IFERROR(IF(($C26+$D26)=0,0,$B26/($C26+$D26)),0))
L27: =IF($A27="","",IFERROR(IF(($C27+$D27)=0,0,$B27/($C27+$D27)),0))
L28: =IF($A28="","",IFERROR(IF(($C28+$D28)=0,0,$B28/($C28+$D28)),0))
L29: =IF($A29="","",IFERROR(IF(($C29+$D29)=0,0,$B29/($C29+$D29)),0))
L30: =IF($A30="","",IFERROR(IF(($C30+$D30)=0,0,$B30/($C30+$D30)),0))
L31: =IF($A31="","",IFERROR(IF(($C31+$D31)=0,0,$B31/($C31+$D31)),0))
L32: =IF($A32="","",IFERROR(IF(($C32+$D32)=0,0,$B32/($C32+$D32)),0))
L33: =IF($A33="","",IFERROR(IF(($C33+$D33)=0,0,$B33/($C33+$D33)),0))
L34: =IF($A34="","",IFERROR(IF(($C34+$D34)=0,0,$B34/($C34+$D34)),0))
L35: =IF($A35="","",IFERROR(IF(($C35+$D35)=0,0,$B35/($C35+$D35)),0))
L36: =IF($A36="","",IFERROR(IF(($C36+$D36)=0,0,$B36/($C36+$D36)),0))
L37: =IF($A37="","",IFERROR(IF(($C37+$D37)=0,0,$B37/($C37+$D37)),0))
L38: =IF($A38="","",IFERROR(IF(($C38+$D38)=0,0,$B38/($C38+$D38)),0))
... L1004: =IF($A1004="","",IFERROR(IF(($C1004+$D1004)=0,0,$B1004/($C1004+$D1004)),0))

Sheet LISTELER
A1: LISTELER — Proje Finansmanı Paketi (DSCR/LLCR)
A3: Doğrulama listeleri
A5: Yıl | C5: Yorum | E5: EvetHayır
A6: 2025 | C6: A | E6: Evet
A7: 2026 | C7: B | E7: Hayır
A8: 2027

Sheet AYARLAR
A1: AYARLAR — Proje Finansmanı Paketi (DSCR/LLCR)
A3: Parametreler (tek kaynak)
A5: anahtar | B5: deger | C5: birim | D5: aciklama | E5: kaynak | F5: yururluk_tarihi | G5: dogrulama_tarihi | H5: kontrol
A6: hesapYili | B6: 2026 | C6: yıl | D6: Aktif hesap yılı | E6: Kullanıcı / GIRDI | F6: 01.01.2025 | G6: 11.08.2026 | H6: =IF(A6="","",IF(B6="","EKSİK","TAM"))
A7: raporTarihi | B7: 46245 | C7: tarih | D7: Rapor tarihi (sabit) | E7: Üretim | F7: 01.01.2025 | G7: 11.08.2026 | H7: =IF(A7="","",IF(B7="","EKSİK","TAM"))
A8: pfd_tolerans | B8: 0.02 | C8: oran | D8: Vaka tutarlılık toleransı | E8: Uygulama notu | F8: 01.01.2025 | G8: 11.08.2026 | H8: =IF(A8="","",IF(B8="","EKSİK","TAM"))
A9: pfd_azamiEsik | B9: 100000000000 | C9: TL | D9: Uç değer / azami giriş eşiği | E9: İç politika | F9: 01.01.2025 | G9: 11.08.2026 | H9: =IF(A9="","",IF(B9="","EKSİK","TAM"))
A10: pfd_kacirilanEsik | B10: 1.25 | C10: oran | D10: PANO DSCR uyarı eşiği | E10: İç politika | F10: 01.01.2025 | G10: 11.08.2026 | H10: =IF(A10="","",IF(B10="","EKSİK","TAM"))
A11: pfd_senaryoIyi | B11: 1.1 | C11: çarpan | D11: İyimser CFADS çarpanı | E11: Model varsayımı | F11: 01.01.2025 | G11: 11.08.2026 | H11: =IF(A11="","",IF(B11="","EKSİK","TAM"))
A12: pfd_senaryoKotu | B12: 0.85 | C12: çarpan | D12: Kötümser CFADS çarpanı | E12: Model varsayımı | F12: 01.01.2025 | G12: 11.08.2026 | H12: =IF(A12="","",IF(B12="","EKSİK","TAM"))
A13: pfd_esikArtis | B13: 0.05 | C13: oran | D13: M-SEN eşik + delta | E13: Senaryo motoru | F13: 01.01.2025 | G13: 11.08.2026 | H13: =IF(A13="","",IF(B13="","EKSİK","TAM"))
A14: pfd_tahminAlt | B14: 0.85 | C14: çarpan | D14: Tahmin alt bant | E14: Model varsayımı | F14: 01.01.2025 | G14: 11.08.2026 | H14: =IF(A14="","",IF(B14="","EKSİK","TAM"))
A15: pfd_tahminUst | B15: 1.15 | C15: çarpan | D15: Tahmin üst bant | E15: Model varsayımı | F15: 01.01.2025 | G15: 11.08.2026 | H15: =IF(A15="","",IF(B15="","EKSİK","TAM"))
A16: pfd_tornadoCfads | B16: 1.05 | C16: çarpan | D16: Tornado CFADS şoku | E16: Model varsayımı | F16: 01.01.2025 | G16: 11.08.2026 | H16: =IF(A16="","",IF(B16="","EKSİK","TAM"))
A17: pfd_tornadoServis | B17: 1.05 | C17: çarpan | D17: Tornado servis şoku | E17: Model varsayımı | F17: 01.01.2025 | G17: 11.08.2026 | H17: =IF(A17="","",IF(B17="","EKSİK","TAM"))
... A20: pfd_yuzdelikOran | B20: 0.9 | C20: oran | D20: Yüzdelik P90 | E20: İstatistik | F20: 01.01.2025 | G20: 11.08.2026 | H20: =IF(A20="","",IF(B20="","EKSİK","TAM"))
A21: pfd_parmakIzi | B21: 2f04db5b772ba8e9 | C21: metin | D21: Dosya parmak izi etiketi | E21: Üretim | F21: 01.01.2025 | G21: 11.08.2026 | H21: =IF(A21="","",IF(B21="","EKSİK","TAM"))
A22: dosya_surumu | B22: 1.0.0 | C22: metin | D22: Ürün sürümü | E22: ExcelArşiv | F22: 01.01.2025 | G22: 11.08.2026 | H22: =IF(A22="","",IF(B22="","EKSİK","TAM"))
A23: pfd_girisBeklenen | B23: 12 | C23: adet | D23: Zorunlu giriş alanı sayısı | E23: Ürün mimarisi | F23: 01.01.2025 | G23: 11.08.2026 | H23: =IF(A23="","",IF(B23="","EKSİK","TAM"))
A24: pfd_riskDusuk | B24: 15 | C24: puan | D24: UYGUN risk skoru | E24: İç politika | F24: 01.01.2025 | G24: 11.08.2026 | H24: =IF(A24="","",IF(B24="","EKSİK","TAM"))
A25: pfd_riskOrta | B25: 55 | C25: puan | D25: DİKKAT risk skoru | E25: İç politika | F25: 01.01.2025 | G25: 11.08.2026 | H25: =IF(A25="","",IF(B25="","EKSİK","TAM"))
A26: pfd_riskYuksek | B26: 85 | C26: puan | D26: İHLAL risk skoru | E26: İç politika | F26: 01.01.2025 | G26: 11.08.2026 | H26: =IF(A26="","",IF(B26="","EKSİK","TAM"))
A27: pfd_riskEsikOran | B27: 0.5 | C27: oran | D27: Yedek risk oranı | E27: İç politika | F27: 01.01.2025 | G27: 11.08.2026 | H27: =IF(A27="","",IF(B27="","EKSİK","TAM"))
A28: pfd_yilTaban | B28: 2024 | C28: yıl | D28: CHOOSE yıl tabanı | E28: Ürün mimarisi | F28: 01.01.2025 | G28: 11.08.2026 | H28: =IF(A28="","",IF(B28="","EKSİK","TAM"))
A29: pfd_yuvarMax | B29: 10 | C29: adet | D29: ROUND basamak tavanı | E29: Ürün mimarisi | F29: 01.01.2025 | G29: 11.08.2026 | H29: =IF(A29="","",IF(B29="","EKSİK","TAM"))
A30: pfd_dayanakCarpan | B30: 10 | C30: adet | D30: Yedek çarpan | E30: Ürün mimarisi | F30: 01.01.2025 | G30: 11.08.2026 | H30: =IF(A30="","",IF(B30="","EKSİK","TAM"))
A31: pfd_bazCarpan | B31: 1 | C31: çarpan | D31: Baz senaryo çarpanı | E31: Model varsayımı | F31: 01.01.2025 | G31: 11.08.2026 | H31: =IF(A31="","",IF(B31="","EKSİK","TAM"))
A32: pfd_sifirCarpan | B32: 0 | C32: çarpan | D32: Nötr çarpan (sıfır) | E32: Model varsayımı | F32: 01.01.2025 | G32: 11.08.2026 | H32: =IF(A32="","",IF(B32="","EKSİK","TAM"))
A33: pfd_siraBir | B33: 1 | C33: adet | D33: Tornado sıra 1 | E33: Ürün mimarisi | F33: 01.01.2025 | G33: 11.08.2026 | H33: =IF(A33="","",IF(B33="","EKSİK","TAM"))
A34: pfd_siraIki | B34: 2 | C34: adet | D34: Tornado sıra 2 | E34: Ürün mimarisi | F34: 01.01.2025 | G34: 11.08.2026 | H34: =IF(A34="","",IF(B34="","EKSİK","TAM"))
... A42: vaka_wacc_1 | B42: 0.1 | C42: oran | D42: Vaka WACC | E42: Altın vaka | F42: 01.01.2025 | G42: 11.08.2026 | H42: =IF(A42="","",IF(B42="","EKSİK","TAM"))
B44: Parametre satırları yukarıda; ad tanımları B kolonuna bağlı.
B46: Sürüm 1.0.0 | Şifre koruması: 1234 (formül alanları)

Sheet KILAVUZ
A1: KILAVUZ — Proje Finansmanı Paketi (DSCR/LLCR)
A3: Karar kuralları
A5: • VERİ YOK — giriş tablosu boşsa hesap yapılmaz.
A6: • UYGUN — DSCR ≥ asgari ve LLCR ≥ asgari; covenant uygun.
A7: • DİKKAT — DSCR veya LLCR dikkat bandında; plan gözden geçirilmeli.
A8: • İHLAL — DSCR veya LLCR dikkat eşiğinin altında; ihlal riski.
A10: Belirsizlik beyanları (M05)
A11: Bu nokta mevzuatta tartışmalıdır; dosya yorum A ve yorum B sonucunu yan yana gösterir: cfads_yorumu
A13: Yorum A | B13: CFADS brüt girilir; borç servisi = anapara + faiz. DSCR = CFADS ÷ borç servisi. LLCR = NPV(CFADS, WACC, dönem) ÷ kredi bakiyesi.
A14: Yorum B | B14: Yorum B, CFADS üzerinden rezerv kesintisi uygular (daha düşük CFADS → daha düşük DSCR/LLCR). Dosya her iki yorumun sonucunu MOTOR'da üretir.
A16: Kullanım sırası
A17: GIRDI → KURALLAR (gerekirse) → MOTOR (inceleme) → SENARYO → VAKALAR → PANO → KANIT_RAPORU → AYARLAR.
A19: Sürüm 1.0.0 | Lisans: Tek kullanıcı | ExcelArşiv
