Workbook
Name hesapYili: GIRDI!$B$8
Name raporTarihi: AYARLAR!$B$7
Name ayd_maliyet: GIRDI!$B$9
Name ayd_netDefter: GIRDI!$B$15
Name ayd_fark: MOTOR!$G$20
Name ayd_fonGec32: MOTOR!$G$21
Name ayd_ozKaynak298: MOTOR!$G$23
Name ayd_kararMetni: MOTOR!$G$31
Name ayd_kararGerekce: MOTOR!$G$32
Name ayd_kararKapi: MOTOR!$G$31
Name ayd_amortismanCetvel: AMORTISMAN!$K$12
Name ayd_maddeAtifMetni: MOTOR!$G$52
Name ayd_kanitRaporu: MOTOR!$G$53
Name ayd_kuralYilMatris: KURALLAR!$B$17
Name ayd_parmakIzi: AYARLAR!$B$19
Name ayd_senaryoKarsilastirma: SENARYO!$B$11
Name ayd_yorumSenaryo: SENARYO!$B$12
Name ayd_duyarlilikSira: SENARYO!$B$19
Name ayd_yorumDuyarlilik: SENARYO!$B$20
Name ayd_kuralDegisimSenaryo: SENARYO!$B$22
Name ayd_yorumKuralDegisim: SENARYO!$B$23
Name ayd_tahminAralik: SENARYO!$B$32
Name ayd_yorumTahmin: SENARYO!$B$33
Name ayd_vakaDurum: VAKALAR!$B$12
Name ayd_vakaFark: VAKALAR!$B$13
Name ayd_tolerans: AYARLAR!$B$8
Name ayd_farkEsik: AYARLAR!$B$9
Name ayd_senaryoIyi: AYARLAR!$B$10
Name ayd_senaryoKotu: AYARLAR!$B$11
Name ayd_oranArtisPuan: AYARLAR!$B$12
Name ayd_tahminAlt: AYARLAR!$B$13
Name ayd_tahminUst: AYARLAR!$B$14
Name ayd_tornadoMaliyet: AYARLAR!$B$15
Name ayd_tornadoEndeks: AYARLAR!$B$16
Name ayd_tasarrufCarpan: AYARLAR!$B$17
Name ayd_yuzdelikOran: AYARLAR!$B$18
Name ayd_girisBeklenen: AYARLAR!$B$21
Name ayd_riskDusuk: AYARLAR!$B$22
Name ayd_riskOrta: AYARLAR!$B$23
Name ayd_riskYuksek: AYARLAR!$B$24
Name ayd_kararEsik: AYARLAR!$B$25
Name ayd_yilTaban: AYARLAR!$B$26
Name ayd_yuvarMax: AYARLAR!$B$27
Name vaka_maliyet_1: AYARLAR!$B$28
Name vaka_endeks_1: AYARLAR!$B$29
Name vaka_maliyet_2: AYARLAR!$B$30
Name vaka_endeks_2: AYARLAR!$B$31
Name vaka_maliyet_3: AYARLAR!$B$32
Name vaka_endeks_3: AYARLAR!$B$33
Name ayd_modulT1: PANO!$C$11
Name ayd_modulT1Yorum: PANO!$D$11
Name ayd_modulT2: PANO!$C$12
Name ayd_modulT2Yorum: PANO!$D$12
Name ayd_modulO1: PANO!$C$13
Name ayd_modulO1Yorum: PANO!$D$13
Name ayd_modulO6: PANO!$C$16
Name ayd_modulO6Yorum: PANO!$D$16
Name ayd_modulO8: PANO!$C$17
Name ayd_modulO8Yorum: PANO!$D$17
Name ayd_modulI2: PANO!$C$20

Sheet 00_BASLANGIC
A1: EXCELARŞİV KARAR SİSTEMİ v15.1 — ÜRETİM REFERANSI
A3: Konu | B3: Bağlayıcı Standart
A4: Amaç | B4: Kanıta dayalı, hatada kapalı çalışan Excel üretim ve denetim sistemi
A5: Öncelik | B5: Kullanıcının açık iş talebi ve gerçek kullanım senaryosu
A6: Ana akış | B6: Uygunluk → Yönetişim → Sözleşmeler → Üretim → Test → Kanıt → Kullanıcı Kabulü → Yayın
A7: Yayın ilkesi | B7: Üst aşamada hata varsa alt aşama GEÇTİ üretilemez
A8: Kullanıcı kabulü | B8: Excel masaüstü görünümü test edilmediyse DIŞ_KABUL_GEREKLİ
A9: Nihai yayın | B9: Yalnız uygulanabilir modüller GEÇTİ veya gerekçeli UYGULANMAZ
A10: Ticari ayrım | B10: Ekonomik olarak savunulabilir fiyat, gerçek pazar kabulü ile aynı değildir
A11: Karmaşıklık | B11: Karar değeri, eklenen karmaşıklığın maliyetinden büyük olmalıdır
A12: Excel sınırı | B12: Veritabanı, kurumsal yetkilendirme, değiştirilemez kayıt sistemi veya gerçek zamanlı olay platformu değildir
A13: Dil standardı | B13: Kullanıcıya görünen tüm sayfa, tablo, başlık, açıklama, uyarı ve karar metinleri saf Türkçe olmalıdır
A14: Muhasebe standardı | B14: Finansal ürünlerde Türkiye Tekdüzen Hesap Planı ve Türk muhasebe kullanım alışkanlıkları esas alınır
... A33: Muhasebe | B33: Türkiye Tekdüzen Hesap Planı ve Türk muhasebe/işletme düşünce yapısı esas alınır.

Sheet PANO
A1: ☰ PANO
B2: AMORTISMAN + 2026 YENIDEN DEĞERLEME | L2: Dönem: 2026 / Tam ▼ | M2: ★ DOĞRULANMIŞ
B3: Hedef Kullanıcı: SMMM, mali işler · 2026 Q3 Denetim Standardı
B5: AMORTISMAN TOPLAM | D5: KONSOLİDE | E5: YD FARK | G5: KONTROL | H5: NET OPERASYONEL MARJ | J5: GÜVENLİ | K5: SİSTEM GÜVEN SKORU | M5: DENETLENDİ
B7: =GİRDİLER!E17 | E7: =B7*0.22 | H7: =B7-E7 | K7: =IF(E7>0, ROUND(B7/E7, 2), 0)
B9: ↑ %14.2 konsolide canlı veri bağlantısı | E9: ● 8 Kalem nakit karşılığı: bloke | H9: ██████████░░░░░ %78.0 NET MARJ | K9: ✓ İDEAL karşılama rasyosu
B11: AMORTISMAN + 2026 YENIDEN DEĞERLEME — DÖNEMSEL İCRA VE PROJEKSİYON | F11: +%32 Verim | H11: KONSOLİDE OPERASYON VE KARAR MATRİSİ
B12: Kümülatif Hacim vs. Operasyonel Maliyet ve Net Kâr Eğilimi | H12: Anlık Hesaplama Sonuçları, Dinamik Formül Çıktıları ve Durum Puanlaması
B14: Dönem | C14: Aktif Hacim | D14: Maliyet/Yük | E14: Hedef | H14: PARAMETRE / KALEM | I14: ANA TUTAR | J14: FARK / MARJ | K14: VADE | L14: KONTROL DURUMU
B15: D1 | C15: 65 | D15: 45 | E15: 60 | H15: Dönemlik Kümülatif Bakiye | I15: =B7*0.45 | J15: =B7*0.05 | K15: 12 Ay | L15: ✓ DÜZENLİ
B16: D2 | C16: 78 | D16: 48 | E16: 70 | H16: Kritik Eşik Güvenlik Tamponu | I16: =B7*0.30 | J16: =B7*0.03 | K16: 24 Ay | L16: ★ AVANTAJ
B17: D3 | C17: 85 | D17: 55 | E17: 80 | H17: Operasyonel Net Fark | I17: =B7*0.15 | J17: =B7*0.02 | K17: 8 Ay | L17: ● YAKLAŞAN
B18: D4 | C18: 75 | D18: 42 | E18: 75 | H18: Rezerv ve Likit Dağılım | I18: =B7*0.10 | J18: =B7*0.01 | K18: 16 Ay | L18: ✓ TAM UYUM
B19: D5 | C19: 90 | D19: 40 | E19: 85 | H19: KONSOLİDE SİSTEM TOPLAMI | I19: =SUM(I15:I18) | J19: =SUM(J15:J18) | L19: TAM DOĞRULANDI (0 HATA)
B20: D6 | C20: 96 | D20: 32 | E20: 92
B22: KONSOLİDE PAY VE AĞIRLIK | F22: LİKİDİTE RİSKİ & ERKEN UYARI SİNYALLERİ | K22: KARAR MOTORU
B23: ■ Ana Segment (%42) | F23: Nakit Açığı Riski (30 Gün) | I23: 0.00 TL (Sıfır Risk) | K23: LİKİDİTE OPTİMİZASYON FIRSATI
B24: ■ İkincil Grup (%30) | F24: Tahsilat Gecikme Toleransı | I24: 48 Gün Güvenli Eşik | K24: Atıl kalan nakit rezervinin gecelik repoda
B25: ■ Destek Birimi (%15) | F25: ██████████████████████████████████████ Güvenli Bölge (%100)
B26: ■ Rezervler (%13) | F26: ✓ 90 GÜNLÜK PROJEKSİYONDA NAKİT SIKIŞIKLIĞI TESPİT EDİLMEDİ | K26: FONLAMA SENARYOSUNU İNCELE ›

Sheet GİRDİLER
A1: ☰ PANO
B3: 🔍 AMORTISMAN + 2026 YENIDEN DEĞERLEME — Kayıt veya hesap ara... | G3: TOPLAM: 1.450 KAYIT | I3: HATALI HÜCRE: 0 ADET
B5: TARİH | C5: REFERANS NO | D5: İŞLEM AÇIKLAMASI VE DETAY | E5: BRÜT TUTAR (₺) | F5: KDV ORANI | G5: NET TUTAR (₺) | H5: HESAP / CARİ | I5: DURUM
B6: 12.10.2026 | C6: TR-0428-A | D6: Operasyonel ana kalem tahmini | E6: 845200 | F6: 0.2 | G6: =E6/(1+F6) | H6: Vadesiz Ticari | I6: ONAYLANDI
B7: 14.10.2026 | C7: TR-0429-B | D7: Operasyonel çıkış/maliyet tahmini | E7: 1240000 | F7: 0.2 | G7: =E7/(1+F7) | H7: Tedarikçi Havuzu | I7: BEKLEMEDE
B8: 18.10.2026 | C8: TR-0430-C | D8: Ödeme takvimi tahakkuku | E8: 620500 | F8: 0.1 | G8: =E8/(1+F8) | H8: Kısa Vade Tahakkuk | I8: ONAYLANDI
B9: 21.10.2026 | C9: TR-0431-D | D9: Müşteri işlem tahmini | E9: 415000 | F9: 0.2 | G9: =E9/(1+F9) | H9: Müşteri Alacağı | I9: ONAYLANDI
B10: 25.10.2026 | C10: TR-0432-E | D10: Ana operasyon tahmini | E10: 980400 | F10: 0.2 | G10: =E10/(1+F10) | H10: Vadesiz Ticari | I10: ONAYLANDI
B11: 28.10.2026 | C11: TR-0433-F | D11: Kredi/taksit karşılığı | E11: 1850000 | F11: 0.2 | G11: =E11/(1+F11) | H11: Finansman Havuzu | I11: BLOKE
B12: 02.11.2026 | C12: TR-0434-G | D12: Sabit gider ve yönetim notları | E12: 740000 | F12: 0.2 | G12: =E12/(1+F12) | H12: Genel Yönetim | I12: ONAYLANDI
B13: 05.11.2026 | C13: TR-0435-H | D13: Operasyonel ana kalem tahmini | E13: 520800 | F13: 0.2 | G13: =E13/(1+F13) | H13: Vadesiz Ticari | I13: ONAYLANDI
B14: 09.11.2026 | C14: TR-0436-I | D14: Müşteri işlem tahmini | E14: 1120000 | F14: 0.2 | G14: =E14/(1+F14) | H14: Müşteri Alacağı | I14: ONAYLANDI
B15: 12.11.2026 | C15: TR-0437-J | D15: Operasyonel çıkış tahmini | E15: 890000 | F15: 0.2 | G15: =E15/(1+F15) | H15: Tedarikçi Havuzu | I15: ONAYLANDI
B17: SAYFA TOPLAMI (10 / 1.450 KAYIT) | E17: =SUM(E6:E15)

Sheet YÖNETİM_RAPORU
A1: ☰ PANO
B2: AMORTISMAN + 2026 YENIDEN DEĞERLEME — NİHAİ KARAR VE DEĞERLEME
B3: Yönetim Kurulu ve İcra Komitesi için Otomatik Finansal Stres Testi Raporu · SMMM, mali işler
B4: DÖNEM: 2026 Q3 · DENETİM PROTOKOLÜ: ISO/VUK/IFRS UYUMLU · DURUM: ONAYLANDI
B6: SENARYO A: KÖTÜMSER (STRES TESTİ -%20) | H6: SENARYO B: BAZ MODEL (HEDEFLENEN)
B8: Ciro / Hacim Düşüşü: | E8: -%20.0 (Kriz Eşiği) | H8: Ciro / Hacim Gerçekleşmesi: | K8: %100.0 (Tam Bütçe)
B9: Beklenen Net Kâr / Getiri: | E9: =PANO!B7*0.8*0.22 | H9: Beklenen Net Kâr / Getiri: | K9: =PANO!H7
B10: Minimum Nakit Tamponu: | E10: =PANO!E7*0.75 | H10: Serbest Nakit Akımı: | K10: =PANO!H7*0.75
B11: Likidite Karşılama Oranı: | E11: =ROUND(PANO!B7*0.8/PANO!E7, 2) | H11: Yatırım Geri Dönüşü (ROI): | K11: %38.4 Yıllık
B14: STRES SENARYOSUNDA DAHİ İFLAS RİSKİ YOK | H14: OPTİMUM İCRA VE PLANLAMA REÇETESİ
B17: YÖNETİM KARAR MATRİSİ VE UYGULAMA REÇETESİ
B19: ● Öncelik 1: Acil Likidite ve Borç Servis Planlaması
B20: Sistemde hesaplanan vade günlerine sadık kalınarak nakit blokajı 3 gün önceden hazır edilmelidir.
B21: ● Öncelik 2: Formül Doğrulama ve Çapraz Sağlama
B22: Tüm hücreler kilitli formül korumasında olup girdi sayfalarında sıfır döngüsel başvuru (circular ref) garantilidir.
B23: ● Öncelik 3: Resmi Mevzuat ve Vergi Kalkanı Entegrasyonu
B24: 2026 güncel vergi dilimleri, amortisman ve SGK teşvik parametreleri tam otomatik yansıtılmaktadır.
B25: ● Öncelik 4: Yönetici İmzası ve Rapor Paylaşımı
B26: Tek tuşla PDF ve A4 çıktı formatına tam uyumlu sayfa yapısı kurgulanmıştır.

Sheet 01_YURUTME_CEKIRDEGI
A1: YÜRÜTME ÇEKİRDEĞİ — ZORUNLU ÜRETİM SIRASI
A3: Adım | B3: Modül | C3: Tetikleyici | D3: Zorunlu Kanıt | E3: GEÇTİ Kuralı | F3: Hata Durumu | G3: Sonraki Aşama
A4: 1 | B4: Excel Uygunluğu | C4: Her yeni model | D4: UYGUNLUK_KARARI | E4: Excel'in rolü açık | F4: HATA / BLOKE | G4: Yönetişim
A5: 2 | B5: Yönetişim | C5: Her model | D5: Risk seviyesi + etki girdileri | E5: Seviye hesaplandı | F5: BLOKE | G5: Sözleşmeler
A6: 3 | B6: Türk Muhasebe Eşlemesi | C6: Finansal model | D6: THP hesap eşleme tablosu | E6: Kritik satırlar THP ile uyumlu | F6: HATA | G6: Sözleşmeler
A7: 4 | B7: Veri ve Anlam Sözleşmeleri | C7: Girdi/KPI varsa | D7: Veri + KPI sözleşmeleri | E7: Kapsam %100 | F7: HATA | G7: Üretim
A8: 5 | B8: Üretim | C8: Sözleşmeler GEÇTİ | D8: Çalışan Excel | E8: Tek gerçek kaynak korunmuş | F8: HATA | G8: Testler
A9: 6 | B9: Görsel/Kullanım Katmanı | C9: Motor hazır | D9: Başlıklar + renk + grafik + yönlendirme | E9: Tüm kullanıcı sayfaları standarda uygun | F9: HATA | G9: Testler
A10: 7 | B10: Testler | C10: Üretim tamam | D10: Formül/OOXML/kimlik/oracle/golden/metamorfik | E10: Uygulanabilir hard gate'ler GEÇTİ | F10: HATA | G10: Kanıt
A11: 8 | B11: Hata-Kontrol Tutarlılığı | C11: Test sonucu var | D11: Hata taraması + kontrol sonuçları | E11: Formül hatası varken GEÇTİ yok | F11: HATA | G11: Kanıt
A12: 9 | B12: Kanıt | C12: Test sonucu var | D12: Makine okunur artefakt + özet | E12: Kanıt fiziksel ve tutarlı | F12: HATA | G12: Kullanıcı Kabulü
A13: 10 | B13: Kullanıcı Kabulü | C13: Kritik görevler | D13: Gerçek ekran davranışı | E13: Kritik görevler %100 | F13: DIŞ_KABUL_GEREKLİ | G13: Ticari
A14: 11 | B14: Ticari Değer | C14: Ürün satılacaksa | D14: ROI + demo + kanıt paketi | E14: Ekonomik değer kanıtlı | F14: UYARI / HATA | G14: Pazar Doğrulama
A15: 12 | B15: Pazar Doğrulama | C15: Pazar iddiası varsa | D15: Ücretli satış/pilot/fiyat kabul kanıtı | E15: Gerçek fiyat kabul kanıtı | F15: UYGULANMAZ / HATA | G15: Yayın

Sheet 02_KONTROL_LISTESI
A1: NİHAİ KONTROL LİSTESİ — KANITSIZ GEÇİŞ YOK
A3: Kontrol No | B3: Kontrol | C3: Beklenen | D3: Zorunlu Kapı? | E3: Sonuç
A4: K01 | B4: Kullanıcının açık talebi öncelikli mi? | C4: Evet | D4: EVET
A5: K02 | B5: Mevcut yapı, formüller ve tek gerçek kaynak korunuyor mu? | C5: Evet, değişiklik gerekçeli | D5: EVET
A6: K03 | B6: Üst aşama HATA ise alt aşama GEÇTİ engelleniyor mu? | C6: Evet | D6: EVET
A7: K04 | B7: Kanıt fiziksel çıktı ve içerik doğrulaması içeriyor mu? | C7: Evet | D7: EVET
A8: K05 | B8: Excel GUI erişimi olmadan kullanıcı görünümü GEÇTİ yazılıyor mu? | C8: Hayır | D8: EVET
A9: K06 | B9: NİHAİ yalnız GEÇTİ / gerekçeli UYGULANMAZ ile mi? | C9: Evet | D9: EVET
A10: K07 | B10: Ekonomik fiyat savunusu pazar doğrulamasından ayrılmış mı? | C10: Evet | D10: EVET
A11: K08 | B11: Prestij için gereksiz modül var mı? | C11: Hayır | D11: HAYIR
A12: K09 | B12: Excel sınırları açık mı? | C12: Evet | D12: EVET
A13: K10 | B13: Teknik kaynak korunuyor mu? | C13: Evet | D13: EVET
A14: K11 | B14: Kullanıcıya görünen tüm metinler Türkçe mi? | C14: Evet | D14: EVET
A15: K12 | B15: Her kullanıcı sayfasında üst başlık var mı? | C15: Evet | D15: EVET
... A34: K31 | B34: Premium vitrin, altyapı kadar güçlü ve satış fiyatını destekleyecek seviyede mi? | C34: Evet | D34: EVET

Sheet 03_GORSEL_TASARIM
A1: GÖRSEL TASARIM VE PREMIUM EXCEL STANDARDI
A3: Alan | B3: Zorunlu Kural | C3: Uygulama | D3: Yasak | E3: Kontrol | F3: Durum
A4: Sayfa başlığı | B4: Her kullanıcı sayfasının en üstünde tek ve açık sayfa başlığı | C4: A1'den başlayan koyu lacivert başlık bandı | D4: Başlıksız sayfa | E4: Başlık kapsama = %100 | F4: ZORUNLU
A5: Sekme renkleri | B5: Sayfalar işlevine göre renk kodlanır | C5: Girdi=mavi, hesap=gri, rapor=lacivert, kontrol=kırmızı, kılavuz=altın | D5: Rastgele renk | E5: Renk semantiği tutarlı | F5: ZORUNLU
A6: Kolon düzeni | B6: Veri blokları bitişik kolonlarda ilerler | C6: Gereksiz boş kolon bırakma; yalnız gerçek bölüm ayrımı varsa kontrollü boşluk | D6: A:C veri, D boş, E:F veri gibi parçalı yapı | E6: Boş kolon taraması | F6: ZORUNLU
A7: Girdi hücreleri | B7: Kullanıcının değiştireceği alan açıkça görünür | C7: Açık sarı dolgu + mavi yazı | D7: Formülle aynı görünüm | E7: Girdi/formül ayrımı | F7: ZORUNLU
A8: Formüller | B8: Hesap hücreleri kullanıcı girdisinden ayrılır | C8: Siyah yazı; sayfalar arası bağlantı yeşil yazı | D8: Hard-code gizleme | E8: Formül sınıfı kontrolü | F8: ZORUNLU
A9: Grafik sayısı | B9: Yönetici ekranında en fazla 3 ana karar grafiği | C9: Trend, karşılaştırma, köprü/dağılım; iş kararına bağlı | D9: Grafik kalabalığı | E9: Grafik başına karar sorusu | F9: ZORUNLU
A10: Grafik stili | B10: Kurumsal ve yüksek okunabilirlik | C10: Beyaz zemin, ince gridline, tek vurgu rengi, açık birim/başlık | D10: 3B, gölge, neon, gökkuşağı renkleri | E10: Görsel inceleme | F10: ZORUNLU
A11: Grafik başlığı | B11: Grafik 'neyi' değil 'ne anlama geldiğini' söyler | C11: Örn: 'Nakit 2028'de kritik eşiğin altına iniyor' | D11: 'Nakit Grafiği' gibi anlamsız başlık | E11: Başlık karar testi | F11: ZORUNLU
A12: Birimler | B12: Tüm finansal görsellerde birim açık | C12: TL, bin TL, milyon TL, %, gün, x | D12: Birim belirsizliği | E12: Birim kapsama %100 | F12: ZORUNLU
A13: Sıfır/negatif | B13: Finansal format standardı | C13: Sıfır='-', negatif kırmızı parantez | D13: -500 veya 0,00 kalabalığı | E13: Format kontrolü | F13: ZORUNLU
A14: Yazı tipi | B14: Tek aile | C14: Aptos veya Segoe UI | D14: Karışık font | E14: Tek font kontrolü | F14: ZORUNLU
... A22: Premium vitrin | B22: Görsel kalite ürün değerinin zorunlu parçasıdır | C22: Kaliteli grafik, gerçek KPI kartı, finansal hiyerarşi, tab rengi, fonksiyonel navigasyon | D22: Sadece doğru hesap yapıp çıplak/varsayılan Excel görünümü bırakmak | E22: Görsel release incelemesi | F22: ZORUNLU

Sheet 04_MUHASEBE_THP
A1: TÜRKİYE MUHASEBE VE TEKDÜZEN HESAP PLANI STANDARDI
A3: Konu | B3: Zorunlu Standart | C3: Örnek Türkçe Ad | D3: THP / Mantık | E3: Hata Riski | F3: Kontrol
A4: Dil | B4: Kullanıcıya görünen finansal terimler Türkçe | C4: Hasılat, Satışların Maliyeti, Brüt Kâr, Faaliyet Giderleri | D4: Türk işletme kullanımına uygun | E4: İngilizce jargon | F4: Terminoloji taraması
A5: Gelir Tablosu | B5: Türk sunum sırası kullanılır | C5: Net Satışlar → Satışların Maliyeti → Brüt Kâr → Faaliyet Giderleri → Faaliyet Kârı | D5: 600/610/611; 620-623; 63x | E5: Yanlış sınıflama | F5: Hesap eşleme
A6: Bilanço | B6: Dönen/Duran Varlık ve Kısa/Uzun Vadeli Yükümlülük ayrımı | C6: Hazır Değerler, Ticari Alacaklar, Stoklar, Mali Borçlar | D6: 1xx / 2xx / 3xx / 4xx / 5xx | E6: Vade sınıfı hatası | F6: Bilanço eşitliği
A7: Nakit Akışı | B7: İşletme/Yatırım/Finansman nakit akışları ayrılır | C7: Faaliyetlerden Nakit, Yatırım Harcamaları, Finansman Nakit Akışı | D7: Dolaylı/doğrudan yöntem açık seçilir | E7: Kâr = nakit sanılması | F7: Nakit devri
A8: Ticari Alacaklar | B8: Cari ve vade mantığı korunur | C8: 120 Alıcılar | D8: 120 | E8: Tahakkuk/nakit karışması | F8: Alacak devir kontrolü
A9: Ticari Borçlar | B9: Tedarikçi borcu ayrı izlenir | C9: 320 Satıcılar | D9: 320 | E9: Gider/ödeme karışması | F9: Borç devir kontrolü
A10: Kasa/Banka | B10: Hazır değerler ayrı izlenir | C10: 100 Kasa, 102 Bankalar | D10: 100 / 102 | E10: Virmanla toplam nakdin değişmesi | F10: Virman değişmezi
A11: Stok | B11: Dikeye uygun stok türü | C11: 150 İlk Madde ve Malzeme, 153 Ticari Mallar | D11: 15x | E11: Maliyet ve stok hareketinin kopması | F11: Stok devri
A12: Maddi Duran Varlık | B12: Yatırım harcaması ve amortisman bağlantılı | C12: 253 Tesis Makine Cihazlar, 255 Demirbaşlar, 257 Birikmiş Amortismanlar | D12: 25x | E12: Yatırım/gider karışması | F12: Net defter değeri devri
A13: Mali Borçlar | B13: Kısa/uzun vadeli borç ayrımı | C13: 300 Banka Kredileri / 400 Banka Kredileri | D13: 300 / 400 | E13: Vade sınıfı yanlış | F13: Borç devri
A14: Özkaynak | B14: Sermaye ve geçmiş yıl kârları ayrı | C14: 500 Sermaye, 570 Geçmiş Yıllar Kârları, 590 Dönem Net Kârı | D14: 5xx | E14: Net kâr bağının kopması | F14: Özkaynak devri
... A18: İstisna | B18: TFRS özel ürün varsa fark açık yazılır | C18: Tekdüzen raporlama ≠ TFRS finansal tablo sunumu | D18: Amaç belirtilir | E18: Standartları karıştırma | F18: Model amacı kontrolü

Sheet 05_KARAR_SATIS
A1: KARAR, GÜVEN VE SATIŞA HAZIRLIK STANDARDI
A3: Alan | B3: Müşteri Sorusu | C3: Zorunlu Ürün Davranışı | D3: Kanıt | E3: Başarısızlık Durumu | F3: Kapı
A4: 5 saniye | B4: Bu ürün neyi çözüyor? | C4: İlk ekranda hedef kullanıcı + pahalı problem + sonuç görünür | D4: Başlık + alt mesaj + gerçek ekran | E4: Ürün yalnız teknik isim | F4: HATA
A5: Acı | B5: Sorun bana neye mal oluyor? | C5: Mümkünse müşterinin kendi verisiyle parasal/zaman etkisi hesaplanır | D5: ROI/acı hesaplama yöntemi | E5: Uydurma tasarruf | F5: HATA
A6: Karar | B6: Bu bilgiyle ne yapacağım? | C6: Her kritik KPI aksiyona bağlanır | D6: KARAR_KUYRUGU | E6: Sadece rapor | F6: HATA
A7: Güven | B7: Bu sayıya neden inanayım? | C7: Kaynak, formül mantığı, kontrol ve son doğrulama görünür | D7: Kontroller + kaynak izi + sürüm | E7: Prestij kelimesi | F7: HATA
A8: Referans | B8: Müşteri yorumu yoksa ne göstereceğim? | C8: Önce/Sonra + Karar Vakası + Hata Önleme Vakası üretilir | D8: Demo/örnek çıktı | E8: Kanıtsız iddia | F8: HATA
A9: Senaryo | B9: Ne olursa işler bozulur? | C9: Baz/Aşağı/Yukarı veya uygun stres senaryosu | D9: Senaryo karşılaştırma | E9: Dekoratif senaryo | F9: HATA
A10: Ters stres | B10: Hangi eşikte karar kırılır? | C10: En az bir kritik sürücü için kırılma eşiği | D10: Kırılma eşiği tablosu | E10: Sadece +/- %10 | F10: UYARI/HATA
A11: Hata tutarlılığı | B11: Formül hata verirse ne olur? | C11: Kontrol GEÇTİ veremez; BLOKE/HATA üretir | D11: Hata taraması | E11: Hata + GEÇTİ birlikte | F11: HATA
A12: Karar motoru | B12: Ne oldu, neden oldu? | C12: Sorun + neden + parasal etki + aksiyon + son tarih | D12: Karar tablosu | E12: Boş sayfa / isim düzeyi modül | F12: HATA
A13: Yönetici özeti | B13: 5 saniyede ne görmeliyim? | C13: Bugün / ne değişti / ne bozulacak / neden / ne yapmalıyım / güven | D13: Yönetici özeti ekranı | E13: KPI kutusu yığını | F13: HATA
A14: Teklif | B14: Neden satın almalıyım? | C14: Dosya özellikleri yerine sonuç ve kaçınılan maliyet sunulur | D14: Ürün sayfası kanıt eşlemesi | E14: Özellik listesiyle satış | F14: HATA
... A19: Pazar kanıtı | B19: Piyasa gerçekten ödüyor mu? | C19: Satış/pilot/LOI/fiyat kabulü olmadan pazar doğrulandı yazılmaz | D19: Gerçek işlem kanıtı | E19: Tahmini talep = satış kabulü | F19: HATA

Sheet GIRDI
A1: GIRDI — Amortisman + 2026 Yeniden Değerleme
A3: Dönem ve kıymet
A4: Sarı hücreler manuel giriştir. Fark ve karar formülle üretilir.
A5: Alan | B5: Değer | C5: Birim
A6: Kurum Adı | B6: Örnek Sanayi A.Ş. | C6: metin
A7: Dönem | B7: 2025 | C7: metin
A8: Hesap Yılı | B8: 2025 | C8: yıl
A9: Maliyet (iktisap) [₺] | B9: 1000000 | C9: ₺
A10: Birikmiş Amortisman [₺] | B10: 200000 | C10: ₺
A11: Endeks Oranı [çarpan] | B11: 1.45 | C11: çarpan
A12: Kalan Ömür [yıl] | B12: 10 | C12: yıl
A13: Öncelik Yorumu (A/B) | B13: A | C13: A/B
A15: Net Defter Değeri [₺] | B15: =MAX(0,B9-B10)
A16: Değer Artış Farkı [₺] | B16: =IFERROR(ROUND(MAX(0,B9*(B11-1)),2),0)
A17: Giriş doluluk (kalite) | B17: =IFERROR(IF(OR(COUNTA(B6:B13)=0,ayd_girisBeklenen=0),0,ROUND(COUNTA(B6:B13)/ayd_girisBeklenen*100,0)),0)
A20: Giriş tablosu (otomasyon / boş-mod)
A21: Alan Anahtarı | B21: Değer | C21: Birim | D21: Zorunlu | E21: Kaynak | F21: Kontrol
A22: kurum_adi | B22: Örnek Sanayi A.Ş. | C22: metin | D22: Evet | E22: GIRDI | F22: =IF($A22="","",IF($B22="","EKSİK","TAM"))
A23: donem | B23: 2025 | C23: metin | D23: Evet | E23: GIRDI | F23: =IF($A23="","",IF($B23="","EKSİK","TAM"))
A24: hesapYili | B24: 2025 | C24: yıl | D24: Evet | E24: GIRDI | F24: =IF($A24="","",IF($B24="","EKSİK","TAM"))
A25: maliyet | B25: 1000000 | C25: TL | D25: Evet | E25: GIRDI | F25: =IF($A25="","",IF($B25="","EKSİK","TAM"))
A26: birikmis_amortisman | B26: 200000 | C26: TL | D26: Evet | E26: GIRDI | F26: =IF($A26="","",IF($B26="","EKSİK","TAM"))
A27: endeks_orani | B27: 1.45 | C27: çarpan | D27: Evet | E27: GIRDI | F27: =IF($A27="","",IF($B27="","EKSİK","TAM"))
A28: kalan_omur_yil | B28: 10 | C28: yıl | D28: Evet | E28: GIRDI | F28: =IF($A28="","",IF($B28="","EKSİK","TAM"))
A29: oncelik_yorumu | B29: A | C29: A/B | D29: Evet | E29: GIRDI | F29: =IF($A29="","",IF($B29="","EKSİK","TAM"))
F30: =IF($A30="","",IF($B30="","EKSİK","TAM"))
F31: =IF($A31="","",IF($B31="","EKSİK","TAM"))
F32: =IF($A32="","",IF($B32="","EKSİK","TAM"))
F33: =IF($A33="","",IF($B33="","EKSİK","TAM"))
F34: =IF($A34="","",IF($B34="","EKSİK","TAM"))
F35: =IF($A35="","",IF($B35="","EKSİK","TAM"))
F36: =IF($A36="","",IF($B36="","EKSİK","TAM"))
F37: =IF($A37="","",IF($B37="","EKSİK","TAM"))
F38: =IF($A38="","",IF($B38="","EKSİK","TAM"))
F39: =IF($A39="","",IF($B39="","EKSİK","TAM"))
F40: =IF($A40="","",IF($B40="","EKSİK","TAM"))
F41: =IF($A41="","",IF($B41="","EKSİK","TAM"))
... F1004: =IF($A1004="","",IF($B1004="","EKSİK","TAM"))
A1022: Sarı alanlar giriş; fark ve kalite formülleri kilitlidir.

Sheet AMORTISMAN
A1: AMORTISMAN — Amortisman + 2026 Yeniden Değerleme
A3: Amortisman cetveli — yeniden değerleme öncesi / sonrası
A4: Cetvel, GIRDI maliyet/birikmiş/endeks/kalan ömür ve MOTOR farkından üretilir. 298/Ç ile Geç.32 kararı PANO'da; burada yıllık amortisman etkisi görülür.
A6: Özet
A7: Net defter (önce) [₺] | B7: =IFERROR(ayd_netDefter,0)
A8: Değer artış farkı [₺] | B8: =IFERROR(ayd_fark,0)
A9: Yıllık amortisman önce [₺] | B9: =IFERROR(IF(OR(GIRDI!B12="",GIRDI!B12=0),0,ayd_netDefter/GIRDI!B12),0)
A10: Yıllık amortisman sonra [₺] | B10: =IFERROR(IF(OR(GIRDI!B12="",GIRDI!B12=0),0,(ayd_netDefter+ayd_fark)/GIRDI!B12),0)
A11: Yıllık amortisman farkı [₺] | B11: =IFERROR(B10-B9,0)
A12: Cetvel özeti (kanıt) | K12: =_xlfn.TEXTJOIN(" · ",TRUE,"Önce=",TEXT(B9,"₺ #,##0"),"Sonra=",TEXT(B10,"₺ #,##0"),"Fark=",TEXT(B11,"₺ #,##0"),"Yıl=",TEXT(IFERROR(GIRDI!B12,0),"0"))
A14: Yıllık amortisman cetveli
A15: Yil | B15: AmortOnce | C15: AmortSonra | D15: AmortFark | E15: KumulatifOnce | F15: KumulatifSonra | G15: KalanNDDOnce | H15: KalanNDDSonra | I15: Durum | K15: OnceDemo | L15: SonraDemo
A16: 1 | B16: =IF(OR($A16="",$A16>IFERROR(GIRDI!B12,0)),"",IFERROR(IF(OR(GIRDI!B12="",GIRDI!B12=0),0,ayd_netDefter/GIRDI!B12),0)) | C16: =IF(OR($A16="",$A16>IFERROR(GIRDI!B12,0)),"",IFERROR(IF(OR(GIRDI!B12="",GIRDI!B12=0),0,(ayd_netDefter+ayd_fark)/GIRDI!B12),0)) | D16: =IF($B16="","",IFERROR($C16-$B16,0)) | E16: =IF($B16="","",IFERROR($A16*$B16,0)) | F16: =IF($C16="","",IFERROR($A16*$C16,0)) | G16: =IF($B16="","",IFERROR(MAX(0,ayd_netDefter-$E16),0)) | H16: =IF($C16="","",IFERROR(MAX(0,ayd_netDefter+ayd_fark-$F16),0)) | I16: =IF($A16="","",IF($A16>IFERROR(GIRDI!B12,0),"DIŞI","AKTİF")) | K16: 80000 | L16: 125000
A17: 2 | B17: =IF(OR($A17="",$A17>IFERROR(GIRDI!B12,0)),"",IFERROR(IF(OR(GIRDI!B12="",GIRDI!B12=0),0,ayd_netDefter/GIRDI!B12),0)) | C17: =IF(OR($A17="",$A17>IFERROR(GIRDI!B12,0)),"",IFERROR(IF(OR(GIRDI!B12="",GIRDI!B12=0),0,(ayd_netDefter+ayd_fark)/GIRDI!B12),0)) | D17: =IF($B17="","",IFERROR($C17-$B17,0)) | E17: =IF($B17="","",IFERROR($A17*$B17,0)) | F17: =IF($C17="","",IFERROR($A17*$C17,0)) | G17: =IF($B17="","",IFERROR(MAX(0,ayd_netDefter-$E17),0)) | H17: =IF($C17="","",IFERROR(MAX(0,ayd_netDefter+ayd_fark-$F17),0)) | I17: =IF($A17="","",IF($A17>IFERROR(GIRDI!B12,0),"DIŞI","AKTİF")) | K17: 80000 | L17: 125000
A18: 3 | B18: =IF(OR($A18="",$A18>IFERROR(GIRDI!B12,0)),"",IFERROR(IF(OR(GIRDI!B12="",GIRDI!B12=0),0,ayd_netDefter/GIRDI!B12),0)) | C18: =IF(OR($A18="",$A18>IFERROR(GIRDI!B12,0)),"",IFERROR(IF(OR(GIRDI!B12="",GIRDI!B12=0),0,(ayd_netDefter+ayd_fark)/GIRDI!B12),0)) | D18: =IF($B18="","",IFERROR($C18-$B18,0)) | E18: =IF($B18="","",IFERROR($A18*$B18,0)) | F18: =IF($C18="","",IFERROR($A18*$C18,0)) | G18: =IF($B18="","",IFERROR(MAX(0,ayd_netDefter-$E18),0)) | H18: =IF($C18="","",IFERROR(MAX(0,ayd_netDefter+ayd_fark-$F18),0)) | I18: =IF($A18="","",IF($A18>IFERROR(GIRDI!B12,0),"DIŞI","AKTİF")) | K18: 80000 | L18: 125000
A19: 4 | B19: =IF(OR($A19="",$A19>IFERROR(GIRDI!B12,0)),"",IFERROR(IF(OR(GIRDI!B12="",GIRDI!B12=0),0,ayd_netDefter/GIRDI!B12),0)) | C19: =IF(OR($A19="",$A19>IFERROR(GIRDI!B12,0)),"",IFERROR(IF(OR(GIRDI!B12="",GIRDI!B12=0),0,(ayd_netDefter+ayd_fark)/GIRDI!B12),0)) | D19: =IF($B19="","",IFERROR($C19-$B19,0)) | E19: =IF($B19="","",IFERROR($A19*$B19,0)) | F19: =IF($C19="","",IFERROR($A19*$C19,0)) | G19: =IF($B19="","",IFERROR(MAX(0,ayd_netDefter-$E19),0)) | H19: =IF($C19="","",IFERROR(MAX(0,ayd_netDefter+ayd_fark-$F19),0)) | I19: =IF($A19="","",IF($A19>IFERROR(GIRDI!B12,0),"DIŞI","AKTİF")) | K19: 80000 | L19: 125000
A20: 5 | B20: =IF(OR($A20="",$A20>IFERROR(GIRDI!B12,0)),"",IFERROR(IF(OR(GIRDI!B12="",GIRDI!B12=0),0,ayd_netDefter/GIRDI!B12),0)) | C20: =IF(OR($A20="",$A20>IFERROR(GIRDI!B12,0)),"",IFERROR(IF(OR(GIRDI!B12="",GIRDI!B12=0),0,(ayd_netDefter+ayd_fark)/GIRDI!B12),0)) | D20: =IF($B20="","",IFERROR($C20-$B20,0)) | E20: =IF($B20="","",IFERROR($A20*$B20,0)) | F20: =IF($C20="","",IFERROR($A20*$C20,0)) | G20: =IF($B20="","",IFERROR(MAX(0,ayd_netDefter-$E20),0)) | H20: =IF($C20="","",IFERROR(MAX(0,ayd_netDefter+ayd_fark-$F20),0)) | I20: =IF($A20="","",IF($A20>IFERROR(GIRDI!B12,0),"DIŞI","AKTİF")) | K20: 80000 | L20: 125000
A21: 6 | B21: =IF(OR($A21="",$A21>IFERROR(GIRDI!B12,0)),"",IFERROR(IF(OR(GIRDI!B12="",GIRDI!B12=0),0,ayd_netDefter/GIRDI!B12),0)) | C21: =IF(OR($A21="",$A21>IFERROR(GIRDI!B12,0)),"",IFERROR(IF(OR(GIRDI!B12="",GIRDI!B12=0),0,(ayd_netDefter+ayd_fark)/GIRDI!B12),0)) | D21: =IF($B21="","",IFERROR($C21-$B21,0)) | E21: =IF($B21="","",IFERROR($A21*$B21,0)) | F21: =IF($C21="","",IFERROR($A21*$C21,0)) | G21: =IF($B21="","",IFERROR(MAX(0,ayd_netDefter-$E21),0)) | H21: =IF($C21="","",IFERROR(MAX(0,ayd_netDefter+ayd_fark-$F21),0)) | I21: =IF($A21="","",IF($A21>IFERROR(GIRDI!B12,0),"DIŞI","AKTİF")) | K21: 80000 | L21: 125000
A22: 7 | B22: =IF(OR($A22="",$A22>IFERROR(GIRDI!B12,0)),"",IFERROR(IF(OR(GIRDI!B12="",GIRDI!B12=0),0,ayd_netDefter/GIRDI!B12),0)) | C22: =IF(OR($A22="",$A22>IFERROR(GIRDI!B12,0)),"",IFERROR(IF(OR(GIRDI!B12="",GIRDI!B12=0),0,(ayd_netDefter+ayd_fark)/GIRDI!B12),0)) | D22: =IF($B22="","",IFERROR($C22-$B22,0)) | E22: =IF($B22="","",IFERROR($A22*$B22,0)) | F22: =IF($C22="","",IFERROR($A22*$C22,0)) | G22: =IF($B22="","",IFERROR(MAX(0,ayd_netDefter-$E22),0)) | H22: =IF($C22="","",IFERROR(MAX(0,ayd_netDefter+ayd_fark-$F22),0)) | I22: =IF($A22="","",IF($A22>IFERROR(GIRDI!B12,0),"DIŞI","AKTİF")) | K22: 80000 | L22: 125000
A23: 8 | B23: =IF(OR($A23="",$A23>IFERROR(GIRDI!B12,0)),"",IFERROR(IF(OR(GIRDI!B12="",GIRDI!B12=0),0,ayd_netDefter/GIRDI!B12),0)) | C23: =IF(OR($A23="",$A23>IFERROR(GIRDI!B12,0)),"",IFERROR(IF(OR(GIRDI!B12="",GIRDI!B12=0),0,(ayd_netDefter+ayd_fark)/GIRDI!B12),0)) | D23: =IF($B23="","",IFERROR($C23-$B23,0)) | E23: =IF($B23="","",IFERROR($A23*$B23,0)) | F23: =IF($C23="","",IFERROR($A23*$C23,0)) | G23: =IF($B23="","",IFERROR(MAX(0,ayd_netDefter-$E23),0)) | H23: =IF($C23="","",IFERROR(MAX(0,ayd_netDefter+ayd_fark-$F23),0)) | I23: =IF($A23="","",IF($A23>IFERROR(GIRDI!B12,0),"DIŞI","AKTİF")) | K23: 80000 | L23: 125000
A24: 9 | B24: =IF(OR($A24="",$A24>IFERROR(GIRDI!B12,0)),"",IFERROR(IF(OR(GIRDI!B12="",GIRDI!B12=0),0,ayd_netDefter/GIRDI!B12),0)) | C24: =IF(OR($A24="",$A24>IFERROR(GIRDI!B12,0)),"",IFERROR(IF(OR(GIRDI!B12="",GIRDI!B12=0),0,(ayd_netDefter+ayd_fark)/GIRDI!B12),0)) | D24: =IF($B24="","",IFERROR($C24-$B24,0)) | E24: =IF($B24="","",IFERROR($A24*$B24,0)) | F24: =IF($C24="","",IFERROR($A24*$C24,0)) | G24: =IF($B24="","",IFERROR(MAX(0,ayd_netDefter-$E24),0)) | H24: =IF($C24="","",IFERROR(MAX(0,ayd_netDefter+ayd_fark-$F24),0)) | I24: =IF($A24="","",IF($A24>IFERROR(GIRDI!B12,0),"DIŞI","AKTİF")) | K24: 80000 | L24: 125000
A25: 10 | B25: =IF(OR($A25="",$A25>IFERROR(GIRDI!B12,0)),"",IFERROR(IF(OR(GIRDI!B12="",GIRDI!B12=0),0,ayd_netDefter/GIRDI!B12),0)) | C25: =IF(OR($A25="",$A25>IFERROR(GIRDI!B12,0)),"",IFERROR(IF(OR(GIRDI!B12="",GIRDI!B12=0),0,(ayd_netDefter+ayd_fark)/GIRDI!B12),0)) | D25: =IF($B25="","",IFERROR($C25-$B25,0)) | E25: =IF($B25="","",IFERROR($A25*$B25,0)) | F25: =IF($C25="","",IFERROR($A25*$C25,0)) | G25: =IF($B25="","",IFERROR(MAX(0,ayd_netDefter-$E25),0)) | H25: =IF($C25="","",IFERROR(MAX(0,ayd_netDefter+ayd_fark-$F25),0)) | I25: =IF($A25="","",IF($A25>IFERROR(GIRDI!B12,0),"DIŞI","AKTİF")) | K25: 80000 | L25: 125000
A26: 11 | B26: =IF(OR($A26="",$A26>IFERROR(GIRDI!B12,0)),"",IFERROR(IF(OR(GIRDI!B12="",GIRDI!B12=0),0,ayd_netDefter/GIRDI!B12),0)) | C26: =IF(OR($A26="",$A26>IFERROR(GIRDI!B12,0)),"",IFERROR(IF(OR(GIRDI!B12="",GIRDI!B12=0),0,(ayd_netDefter+ayd_fark)/GIRDI!B12),0)) | D26: =IF($B26="","",IFERROR($C26-$B26,0)) | E26: =IF($B26="","",IFERROR($A26*$B26,0)) | F26: =IF($C26="","",IFERROR($A26*$C26,0)) | G26: =IF($B26="","",IFERROR(MAX(0,ayd_netDefter-$E26),0)) | H26: =IF($C26="","",IFERROR(MAX(0,ayd_netDefter+ayd_fark-$F26),0)) | I26: =IF($A26="","",IF($A26>IFERROR(GIRDI!B12,0),"DIŞI","AKTİF"))
A27: 12 | B27: =IF(OR($A27="",$A27>IFERROR(GIRDI!B12,0)),"",IFERROR(IF(OR(GIRDI!B12="",GIRDI!B12=0),0,ayd_netDefter/GIRDI!B12),0)) | C27: =IF(OR($A27="",$A27>IFERROR(GIRDI!B12,0)),"",IFERROR(IF(OR(GIRDI!B12="",GIRDI!B12=0),0,(ayd_netDefter+ayd_fark)/GIRDI!B12),0)) | D27: =IF($B27="","",IFERROR($C27-$B27,0)) | E27: =IF($B27="","",IFERROR($A27*$B27,0)) | F27: =IF($C27="","",IFERROR($A27*$C27,0)) | G27: =IF($B27="","",IFERROR(MAX(0,ayd_netDefter-$E27),0)) | H27: =IF($C27="","",IFERROR(MAX(0,ayd_netDefter+ayd_fark-$F27),0)) | I27: =IF($A27="","",IF($A27>IFERROR(GIRDI!B12,0),"DIŞI","AKTİF"))
A28: 13 | B28: =IF(OR($A28="",$A28>IFERROR(GIRDI!B12,0)),"",IFERROR(IF(OR(GIRDI!B12="",GIRDI!B12=0),0,ayd_netDefter/GIRDI!B12),0)) | C28: =IF(OR($A28="",$A28>IFERROR(GIRDI!B12,0)),"",IFERROR(IF(OR(GIRDI!B12="",GIRDI!B12=0),0,(ayd_netDefter+ayd_fark)/GIRDI!B12),0)) | D28: =IF($B28="","",IFERROR($C28-$B28,0)) | E28: =IF($B28="","",IFERROR($A28*$B28,0)) | F28: =IF($C28="","",IFERROR($A28*$C28,0)) | G28: =IF($B28="","",IFERROR(MAX(0,ayd_netDefter-$E28),0)) | H28: =IF($C28="","",IFERROR(MAX(0,ayd_netDefter+ayd_fark-$F28),0)) | I28: =IF($A28="","",IF($A28>IFERROR(GIRDI!B12,0),"DIŞI","AKTİF"))
A29: 14 | B29: =IF(OR($A29="",$A29>IFERROR(GIRDI!B12,0)),"",IFERROR(IF(OR(GIRDI!B12="",GIRDI!B12=0),0,ayd_netDefter/GIRDI!B12),0)) | C29: =IF(OR($A29="",$A29>IFERROR(GIRDI!B12,0)),"",IFERROR(IF(OR(GIRDI!B12="",GIRDI!B12=0),0,(ayd_netDefter+ayd_fark)/GIRDI!B12),0)) | D29: =IF($B29="","",IFERROR($C29-$B29,0)) | E29: =IF($B29="","",IFERROR($A29*$B29,0)) | F29: =IF($C29="","",IFERROR($A29*$C29,0)) | G29: =IF($B29="","",IFERROR(MAX(0,ayd_netDefter-$E29),0)) | H29: =IF($C29="","",IFERROR(MAX(0,ayd_netDefter+ayd_fark-$F29),0)) | I29: =IF($A29="","",IF($A29>IFERROR(GIRDI!B12,0),"DIŞI","AKTİF"))
A30: 15 | B30: =IF(OR($A30="",$A30>IFERROR(GIRDI!B12,0)),"",IFERROR(IF(OR(GIRDI!B12="",GIRDI!B12=0),0,ayd_netDefter/GIRDI!B12),0)) | C30: =IF(OR($A30="",$A30>IFERROR(GIRDI!B12,0)),"",IFERROR(IF(OR(GIRDI!B12="",GIRDI!B12=0),0,(ayd_netDefter+ayd_fark)/GIRDI!B12),0)) | D30: =IF($B30="","",IFERROR($C30-$B30,0)) | E30: =IF($B30="","",IFERROR($A30*$B30,0)) | F30: =IF($C30="","",IFERROR($A30*$C30,0)) | G30: =IF($B30="","",IFERROR(MAX(0,ayd_netDefter-$E30),0)) | H30: =IF($C30="","",IFERROR(MAX(0,ayd_netDefter+ayd_fark-$F30),0)) | I30: =IF($A30="","",IF($A30>IFERROR(GIRDI!B12,0),"DIŞI","AKTİF"))
A31: 16 | B31: =IF(OR($A31="",$A31>IFERROR(GIRDI!B12,0)),"",IFERROR(IF(OR(GIRDI!B12="",GIRDI!B12=0),0,ayd_netDefter/GIRDI!B12),0)) | C31: =IF(OR($A31="",$A31>IFERROR(GIRDI!B12,0)),"",IFERROR(IF(OR(GIRDI!B12="",GIRDI!B12=0),0,(ayd_netDefter+ayd_fark)/GIRDI!B12),0)) | D31: =IF($B31="","",IFERROR($C31-$B31,0)) | E31: =IF($B31="","",IFERROR($A31*$B31,0)) | F31: =IF($C31="","",IFERROR($A31*$C31,0)) | G31: =IF($B31="","",IFERROR(MAX(0,ayd_netDefter-$E31),0)) | H31: =IF($C31="","",IFERROR(MAX(0,ayd_netDefter+ayd_fark-$F31),0)) | I31: =IF($A31="","",IF($A31>IFERROR(GIRDI!B12,0),"DIŞI","AKTİF"))
A32: 17 | B32: =IF(OR($A32="",$A32>IFERROR(GIRDI!B12,0)),"",IFERROR(IF(OR(GIRDI!B12="",GIRDI!B12=0),0,ayd_netDefter/GIRDI!B12),0)) | C32: =IF(OR($A32="",$A32>IFERROR(GIRDI!B12,0)),"",IFERROR(IF(OR(GIRDI!B12="",GIRDI!B12=0),0,(ayd_netDefter+ayd_fark)/GIRDI!B12),0)) | D32: =IF($B32="","",IFERROR($C32-$B32,0)) | E32: =IF($B32="","",IFERROR($A32*$B32,0)) | F32: =IF($C32="","",IFERROR($A32*$C32,0)) | G32: =IF($B32="","",IFERROR(MAX(0,ayd_netDefter-$E32),0)) | H32: =IF($C32="","",IFERROR(MAX(0,ayd_netDefter+ayd_fark-$F32),0)) | I32: =IF($A32="","",IF($A32>IFERROR(GIRDI!B12,0),"DIŞI","AKTİF"))
A33: 18 | B33: =IF(OR($A33="",$A33>IFERROR(GIRDI!B12,0)),"",IFERROR(IF(OR(GIRDI!B12="",GIRDI!B12=0),0,ayd_netDefter/GIRDI!B12),0)) | C33: =IF(OR($A33="",$A33>IFERROR(GIRDI!B12,0)),"",IFERROR(IF(OR(GIRDI!B12="",GIRDI!B12=0),0,(ayd_netDefter+ayd_fark)/GIRDI!B12),0)) | D33: =IF($B33="","",IFERROR($C33-$B33,0)) | E33: =IF($B33="","",IFERROR($A33*$B33,0)) | F33: =IF($C33="","",IFERROR($A33*$C33,0)) | G33: =IF($B33="","",IFERROR(MAX(0,ayd_netDefter-$E33),0)) | H33: =IF($C33="","",IFERROR(MAX(0,ayd_netDefter+ayd_fark-$F33),0)) | I33: =IF($A33="","",IF($A33>IFERROR(GIRDI!B12,0),"DIŞI","AKTİF"))
A34: 19 | B34: =IF(OR($A34="",$A34>IFERROR(GIRDI!B12,0)),"",IFERROR(IF(OR(GIRDI!B12="",GIRDI!B12=0),0,ayd_netDefter/GIRDI!B12),0)) | C34: =IF(OR($A34="",$A34>IFERROR(GIRDI!B12,0)),"",IFERROR(IF(OR(GIRDI!B12="",GIRDI!B12=0),0,(ayd_netDefter+ayd_fark)/GIRDI!B12),0)) | D34: =IF($B34="","",IFERROR($C34-$B34,0)) | E34: =IF($B34="","",IFERROR($A34*$B34,0)) | F34: =IF($C34="","",IFERROR($A34*$C34,0)) | G34: =IF($B34="","",IFERROR(MAX(0,ayd_netDefter-$E34),0)) | H34: =IF($C34="","",IFERROR(MAX(0,ayd_netDefter+ayd_fark-$F34),0)) | I34: =IF($A34="","",IF($A34>IFERROR(GIRDI!B12,0),"DIŞI","AKTİF"))
A35: 20 | B35: =IF(OR($A35="",$A35>IFERROR(GIRDI!B12,0)),"",IFERROR(IF(OR(GIRDI!B12="",GIRDI!B12=0),0,ayd_netDefter/GIRDI!B12),0)) | C35: =IF(OR($A35="",$A35>IFERROR(GIRDI!B12,0)),"",IFERROR(IF(OR(GIRDI!B12="",GIRDI!B12=0),0,(ayd_netDefter+ayd_fark)/GIRDI!B12),0)) | D35: =IF($B35="","",IFERROR($C35-$B35,0)) | E35: =IF($B35="","",IFERROR($A35*$B35,0)) | F35: =IF($C35="","",IFERROR($A35*$C35,0)) | G35: =IF($B35="","",IFERROR(MAX(0,ayd_netDefter-$E35),0)) | H35: =IF($C35="","",IFERROR(MAX(0,ayd_netDefter+ayd_fark-$F35),0)) | I35: =IF($A35="","",IF($A35>IFERROR(GIRDI!B12,0),"DIŞI","AKTİF"))
A36: 21 | B36: =IF(OR($A36="",$A36>IFERROR(GIRDI!B12,0)),"",IFERROR(IF(OR(GIRDI!B12="",GIRDI!B12=0),0,ayd_netDefter/GIRDI!B12),0)) | C36: =IF(OR($A36="",$A36>IFERROR(GIRDI!B12,0)),"",IFERROR(IF(OR(GIRDI!B12="",GIRDI!B12=0),0,(ayd_netDefter+ayd_fark)/GIRDI!B12),0)) | D36: =IF($B36="","",IFERROR($C36-$B36,0)) | E36: =IF($B36="","",IFERROR($A36*$B36,0)) | F36: =IF($C36="","",IFERROR($A36*$C36,0)) | G36: =IF($B36="","",IFERROR(MAX(0,ayd_netDefter-$E36),0)) | H36: =IF($C36="","",IFERROR(MAX(0,ayd_netDefter+ayd_fark-$F36),0)) | I36: =IF($A36="","",IF($A36>IFERROR(GIRDI!B12,0),"DIŞI","AKTİF"))
A37: 22 | B37: =IF(OR($A37="",$A37>IFERROR(GIRDI!B12,0)),"",IFERROR(IF(OR(GIRDI!B12="",GIRDI!B12=0),0,ayd_netDefter/GIRDI!B12),0)) | C37: =IF(OR($A37="",$A37>IFERROR(GIRDI!B12,0)),"",IFERROR(IF(OR(GIRDI!B12="",GIRDI!B12=0),0,(ayd_netDefter+ayd_fark)/GIRDI!B12),0)) | D37: =IF($B37="","",IFERROR($C37-$B37,0)) | E37: =IF($B37="","",IFERROR($A37*$B37,0)) | F37: =IF($C37="","",IFERROR($A37*$C37,0)) | G37: =IF($B37="","",IFERROR(MAX(0,ayd_netDefter-$E37),0)) | H37: =IF($C37="","",IFERROR(MAX(0,ayd_netDefter+ayd_fark-$F37),0)) | I37: =IF($A37="","",IF($A37>IFERROR(GIRDI!B12,0),"DIŞI","AKTİF"))
A38: 23 | B38: =IF(OR($A38="",$A38>IFERROR(GIRDI!B12,0)),"",IFERROR(IF(OR(GIRDI!B12="",GIRDI!B12=0),0,ayd_netDefter/GIRDI!B12),0)) | C38: =IF(OR($A38="",$A38>IFERROR(GIRDI!B12,0)),"",IFERROR(IF(OR(GIRDI!B12="",GIRDI!B12=0),0,(ayd_netDefter+ayd_fark)/GIRDI!B12),0)) | D38: =IF($B38="","",IFERROR($C38-$B38,0)) | E38: =IF($B38="","",IFERROR($A38*$B38,0)) | F38: =IF($C38="","",IFERROR($A38*$C38,0)) | G38: =IF($B38="","",IFERROR(MAX(0,ayd_netDefter-$E38),0)) | H38: =IF($C38="","",IFERROR(MAX(0,ayd_netDefter+ayd_fark-$F38),0)) | I38: =IF($A38="","",IF($A38>IFERROR(GIRDI!B12,0),"DIŞI","AKTİF"))
A39: 24 | B39: =IF(OR($A39="",$A39>IFERROR(GIRDI!B12,0)),"",IFERROR(IF(OR(GIRDI!B12="",GIRDI!B12=0),0,ayd_netDefter/GIRDI!B12),0)) | C39: =IF(OR($A39="",$A39>IFERROR(GIRDI!B12,0)),"",IFERROR(IF(OR(GIRDI!B12="",GIRDI!B12=0),0,(ayd_netDefter+ayd_fark)/GIRDI!B12),0)) | D39: =IF($B39="","",IFERROR($C39-$B39,0)) | E39: =IF($B39="","",IFERROR($A39*$B39,0)) | F39: =IF($C39="","",IFERROR($A39*$C39,0)) | G39: =IF($B39="","",IFERROR(MAX(0,ayd_netDefter-$E39),0)) | H39: =IF($C39="","",IFERROR(MAX(0,ayd_netDefter+ayd_fark-$F39),0)) | I39: =IF($A39="","",IF($A39>IFERROR(GIRDI!B12,0),"DIŞI","AKTİF"))
A40: 25 | B40: =IF(OR($A40="",$A40>IFERROR(GIRDI!B12,0)),"",IFERROR(IF(OR(GIRDI!B12="",GIRDI!B12=0),0,ayd_netDefter/GIRDI!B12),0)) | C40: =IF(OR($A40="",$A40>IFERROR(GIRDI!B12,0)),"",IFERROR(IF(OR(GIRDI!B12="",GIRDI!B12=0),0,(ayd_netDefter+ayd_fark)/GIRDI!B12),0)) | D40: =IF($B40="","",IFERROR($C40-$B40,0)) | E40: =IF($B40="","",IFERROR($A40*$B40,0)) | F40: =IF($C40="","",IFERROR($A40*$C40,0)) | G40: =IF($B40="","",IFERROR(MAX(0,ayd_netDefter-$E40),0)) | H40: =IF($C40="","",IFERROR(MAX(0,ayd_netDefter+ayd_fark-$F40),0)) | I40: =IF($A40="","",IF($A40>IFERROR(GIRDI!B12,0),"DIŞI","AKTİF"))
A41: 26 | B41: =IF(OR($A41="",$A41>IFERROR(GIRDI!B12,0)),"",IFERROR(IF(OR(GIRDI!B12="",GIRDI!B12=0),0,ayd_netDefter/GIRDI!B12),0)) | C41: =IF(OR($A41="",$A41>IFERROR(GIRDI!B12,0)),"",IFERROR(IF(OR(GIRDI!B12="",GIRDI!B12=0),0,(ayd_netDefter+ayd_fark)/GIRDI!B12),0)) | D41: =IF($B41="","",IFERROR($C41-$B41,0)) | E41: =IF($B41="","",IFERROR($A41*$B41,0)) | F41: =IF($C41="","",IFERROR($A41*$C41,0)) | G41: =IF($B41="","",IFERROR(MAX(0,ayd_netDefter-$E41),0)) | H41: =IF($C41="","",IFERROR(MAX(0,ayd_netDefter+ayd_fark-$F41),0)) | I41: =IF($A41="","",IF($A41>IFERROR(GIRDI!B12,0),"DIŞI","AKTİF"))
A42: 27 | B42: =IF(OR($A42="",$A42>IFERROR(GIRDI!B12,0)),"",IFERROR(IF(OR(GIRDI!B12="",GIRDI!B12=0),0,ayd_netDefter/GIRDI!B12),0)) | C42: =IF(OR($A42="",$A42>IFERROR(GIRDI!B12,0)),"",IFERROR(IF(OR(GIRDI!B12="",GIRDI!B12=0),0,(ayd_netDefter+ayd_fark)/GIRDI!B12),0)) | D42: =IF($B42="","",IFERROR($C42-$B42,0)) | E42: =IF($B42="","",IFERROR($A42*$B42,0)) | F42: =IF($C42="","",IFERROR($A42*$C42,0)) | G42: =IF($B42="","",IFERROR(MAX(0,ayd_netDefter-$E42),0)) | H42: =IF($C42="","",IFERROR(MAX(0,ayd_netDefter+ayd_fark-$F42),0)) | I42: =IF($A42="","",IF($A42>IFERROR(GIRDI!B12,0),"DIŞI","AKTİF"))
A43: 28 | B43: =IF(OR($A43="",$A43>IFERROR(GIRDI!B12,0)),"",IFERROR(IF(OR(GIRDI!B12="",GIRDI!B12=0),0,ayd_netDefter/GIRDI!B12),0)) | C43: =IF(OR($A43="",$A43>IFERROR(GIRDI!B12,0)),"",IFERROR(IF(OR(GIRDI!B12="",GIRDI!B12=0),0,(ayd_netDefter+ayd_fark)/GIRDI!B12),0)) | D43: =IF($B43="","",IFERROR($C43-$B43,0)) | E43: =IF($B43="","",IFERROR($A43*$B43,0)) | F43: =IF($C43="","",IFERROR($A43*$C43,0)) | G43: =IF($B43="","",IFERROR(MAX(0,ayd_netDefter-$E43),0)) | H43: =IF($C43="","",IFERROR(MAX(0,ayd_netDefter+ayd_fark-$F43),0)) | I43: =IF($A43="","",IF($A43>IFERROR(GIRDI!B12,0),"DIŞI","AKTİF"))
...

Sheet KURALLAR
A1: KURALLAR — Amortisman + 2026 Yeniden Değerleme
A3: Mevzuat kural tablosu (yıl yan yana)
A4: Oranlar MOTOR'da sabit yazılmaz; INDEX/MATCH ile buradan çekilir.
A6: kural_id | B6: madde | C6: kural_adi | D6: kosul_metni | E6: parametre_adi | F6: deger_2025 | G6: deger_2026 | H6: deger_2027 | I6: yururluk | J6: kaynak | K6: aktif_deger
A7: AYD-001 | B7: VUK 298/Ç | C7: endeks_taban | D7: endeks>=taban | E7: endeks_taban | F7: 1 | G7: 1 | H7: 1 | I7: 01.01.2025 | J7: VUK md.298/Ç | K7: =IF($A7="","",IFERROR(CHOOSE(MAX(1,MIN(3,IF(OR(hesapYili="",hesapYili=0),1,hesapYili-ayd_yilTaban))),$F7,$G7,$H7),0))
A8: AYD-002 | B8: Geçici 32 | C8: gec32_fon_orani | D8: fark>0 | E8: gec32_fon_orani | F8: 0.02 | G8: 0.02 | H8: 0.02 | I8: 01.01.2025 | J8: VUK Geçici md.32 | K8: =IF($A8="","",IFERROR(CHOOSE(MAX(1,MIN(3,IF(OR(hesapYili="",hesapYili=0),1,hesapYili-ayd_yilTaban))),$F8,$G8,$H8),0))
A9: AYD-003 | B9: KVK md.32 | C9: kv_oran | D9: vergi etkisi | E9: kv_oran | F9: 0.25 | G9: 0.25 | H9: 0.25 | I9: 01.01.2025 | J9: KVK md.32 | K9: =IF($A9="","",IFERROR(CHOOSE(MAX(1,MIN(3,IF(OR(hesapYili="",hesapYili=0),1,hesapYili-ayd_yilTaban))),$F9,$G9,$H9),0))
A10: AYD-004 | B10: VUK 298/Ç | C10: c298_fon_orani | D10: 298 yolu | E10: c298_fon_orani | F10: 0 | G10: 0 | H10: 0 | I10: 01.01.2025 | J10: VUK md.298/Ç | K10: =IF($A10="","",IFERROR(CHOOSE(MAX(1,MIN(3,IF(OR(hesapYili="",hesapYili=0),1,hesapYili-ayd_yilTaban))),$F10,$G10,$H10),0))
A11: AYD-005 | B11: Genel | C11: yuvarlama | D11: her hesap | E11: yuvarlama_ondalik | F11: 2 | G11: 2 | H11: 2 | I11: 01.01.2025 | J11: Uygulama notu | K11: =IF($A11="","",IFERROR(CHOOSE(MAX(1,MIN(3,IF(OR(hesapYili="",hesapYili=0),1,hesapYili-ayd_yilTaban))),$F11,$G11,$H11),0))
A14: Kural-yıl matrisi özeti
A15: Geç.32 fon oranı (aktif yıl) | B15: =IFERROR(INDEX(CHOOSE(MAX(1,MIN(3,IF(OR(hesapYili="",hesapYili=0),1,hesapYili-ayd_yilTaban))),tblKurallar[deger_2025],tblKurallar[deger_2026],tblKurallar[deger_2027]),MATCH("AYD-002",tblKurallar[kural_id],0)),0)
A16: KV oranı (aktif yıl) | B16: =IFERROR(INDEX(CHOOSE(MAX(1,MIN(3,IF(OR(hesapYili="",hesapYili=0),1,hesapYili-ayd_yilTaban))),tblKurallar[deger_2025],tblKurallar[deger_2026],tblKurallar[deger_2027]),MATCH("AYD-003",tblKurallar[kural_id],0)),0)
A17: Matris metni | B17: =_xlfn.TEXTJOIN(" | ",TRUE,"AYD-002=",TEXT(B15,"0.0%"),"AYD-003=",TEXT(B16,"0.0%"),"yıl=",hesapYili)

Sheet MOTOR
A1: MOTOR — Amortisman + 2026 Yeniden Değerleme
A3: Hesap zinciri — her adımda kural_id
A4: Oranlar tblKurallar'dan çekilir; sabit oran yoktur.
A6: adim | B6: ad | C6: formul | D6: birim | E6: ne_ise_yarar | F6: kural_id | G6: deger
A7: 1 | B7: Hesap yılı oku | C7: =IFERROR(hesapYili,0) | D7: yıl | E7: Aktif mevzuat yılı | F7: AYD-005 | G7: =IFERROR(hesapYili,0)
A8: 2 | B8: Endeks taban | C8: =IFERROR(INDEX(CHOOSE(MAX(1,MIN(3,IF(OR(hesapYili="",hesapYili=0),1,hesapYili-ayd_yilTaban))),tblKurallar[deger_2025],tblKurallar[deger_2026],tblKurallar[deger_2027]),MATCH("AYD-001",tblKurallar[kural_id],0)),0) | D8: çarpan | E8: Minimum endeks | F8: AYD-001 | G8: =IFERROR(INDEX(CHOOSE(MAX(1,MIN(3,IF(OR(hesapYili="",hesapYili=0),1,hesapYili-ayd_yilTaban))),tblKurallar[deger_2025],tblKurallar[deger_2026],tblKurallar[deger_2027]),MATCH("AYD-001",tblKurallar[kural_id],0)),0)
A9: 3 | B9: Geç.32 fon oranı | C9: =IFERROR(INDEX(CHOOSE(MAX(1,MIN(3,IF(OR(hesapYili="",hesapYili=0),1,hesapYili-ayd_yilTaban))),tblKurallar[deger_2025],tblKurallar[deger_2026],tblKurallar[deger_2027]),MATCH("AYD-002",tblKurallar[kural_id],0)),0) | D9: oran | E9: Fon vergi oranı | F9: AYD-002 | G9: =IFERROR(INDEX(CHOOSE(MAX(1,MIN(3,IF(OR(hesapYili="",hesapYili=0),1,hesapYili-ayd_yilTaban))),tblKurallar[deger_2025],tblKurallar[deger_2026],tblKurallar[deger_2027]),MATCH("AYD-002",tblKurallar[kural_id],0)),0)
A10: 4 | B10: KV oranı | C10: =IFERROR(INDEX(CHOOSE(MAX(1,MIN(3,IF(OR(hesapYili="",hesapYili=0),1,hesapYili-ayd_yilTaban))),tblKurallar[deger_2025],tblKurallar[deger_2026],tblKurallar[deger_2027]),MATCH("AYD-003",tblKurallar[kural_id],0)),0) | D10: oran | E10: Kurumlar vergisi oranı | F10: AYD-003 | G10: =IFERROR(INDEX(CHOOSE(MAX(1,MIN(3,IF(OR(hesapYili="",hesapYili=0),1,hesapYili-ayd_yilTaban))),tblKurallar[deger_2025],tblKurallar[deger_2026],tblKurallar[deger_2027]),MATCH("AYD-003",tblKurallar[kural_id],0)),0)
A11: 5 | B11: 298/Ç fon oranı | C11: =IFERROR(INDEX(CHOOSE(MAX(1,MIN(3,IF(OR(hesapYili="",hesapYili=0),1,hesapYili-ayd_yilTaban))),tblKurallar[deger_2025],tblKurallar[deger_2026],tblKurallar[deger_2027]),MATCH("AYD-004",tblKurallar[kural_id],0)),0) | D11: oran | E11: 298 yolu fon | F11: AYD-004 | G11: =IFERROR(INDEX(CHOOSE(MAX(1,MIN(3,IF(OR(hesapYili="",hesapYili=0),1,hesapYili-ayd_yilTaban))),tblKurallar[deger_2025],tblKurallar[deger_2026],tblKurallar[deger_2027]),MATCH("AYD-004",tblKurallar[kural_id],0)),0)
A12: 6 | B12: Yuvarlama ondalık | C12: =IFERROR(INDEX(CHOOSE(MAX(1,MIN(3,IF(OR(hesapYili="",hesapYili=0),1,hesapYili-ayd_yilTaban))),tblKurallar[deger_2025],tblKurallar[deger_2026],tblKurallar[deger_2027]),MATCH("AYD-005",tblKurallar[kural_id],0)),0) | D12: adet | E12: Yuvarlama basamağı | F12: AYD-005 | G12: =IFERROR(INDEX(CHOOSE(MAX(1,MIN(3,IF(OR(hesapYili="",hesapYili=0),1,hesapYili-ayd_yilTaban))),tblKurallar[deger_2025],tblKurallar[deger_2026],tblKurallar[deger_2027]),MATCH("AYD-005",tblKurallar[kural_id],0)),0)
A13: 7 | B13: Maliyet | C13: =IFERROR(GIRDI!B9,0) | D13: TL | E13: İktisap maliyeti | F13: AYD-001 | G13: =IFERROR(GIRDI!B9,0)
A14: 8 | B14: Birikmiş amortisman | C14: =IFERROR(GIRDI!B10,0) | D14: TL | E14: Birikmiş amortisman | F14: AYD-001 | G14: =IFERROR(GIRDI!B10,0)
A15: 9 | B15: Endeks oranı | C15: =IFERROR(GIRDI!B11,0) | D15: çarpan | E15: Kullanıcı endeksi | F15: AYD-001 | G15: =IFERROR(GIRDI!B11,0)
A16: 10 | B16: Kalan ömür | C16: =IFERROR(GIRDI!B12,0) | D16: yıl | E16: Kalan ekonomik ömür | F16: AYD-003 | G16: =IFERROR(GIRDI!B12,0)
A17: 11 | B17: Net defter değeri | C17: =IFERROR(MAX(0,G13-G14),0) | D17: TL | E17: Maliyet − birikmiş | F17: AYD-001 | G17: =IFERROR(MAX(0,G13-G14),0)
A18: 12 | B18: Endeks düzeltilmiş | C18: =IFERROR(MAX(G15,G8),0) | D18: çarpan | E18: Taban ile max | F18: AYD-001 | G18: =IFERROR(MAX(G15,G8),0)
A19: 13 | B19: Yeniden değerlenmiş maliyet | C19: =IFERROR(ROUND(G13*G18,MAX(0,MIN(ayd_yuvarMax,IFERROR(N(G12),0)))),0) | D19: TL | E19: Maliyet × endeks | F19: AYD-001 | G19: =IFERROR(ROUND(G13*G18,MAX(0,MIN(ayd_yuvarMax,IFERROR(N(G12),0)))),0)
A20: 14 | B20: Değer artış farkı | C20: =IFERROR(ROUND(MAX(0,G13*(G18-1)),MAX(0,MIN(ayd_yuvarMax,IFERROR(N(G12),0)))),0) | D20: TL | E20: Maliyet×(endeks−1) | F20: AYD-001 | G20: =IFERROR(ROUND(MAX(0,G13*(G18-1)),MAX(0,MIN(ayd_yuvarMax,IFERROR(N(G12),0)))),0)
A21: 15 | B21: Geç.32 fon vergisi | C21: =IFERROR(ROUND(G20*G9,MAX(0,MIN(ayd_yuvarMax,IFERROR(N(G12),0)))),0) | D21: TL | E21: Fark × fon oranı | F21: AYD-002 | G21: =IFERROR(ROUND(G20*G9,MAX(0,MIN(ayd_yuvarMax,IFERROR(N(G12),0)))),0)
A22: 16 | B22: 298/Ç fon vergisi | C22: =IFERROR(ROUND(G20*G11,MAX(0,MIN(ayd_yuvarMax,IFERROR(N(G12),0)))),0) | D22: TL | E22: Fark × 298 fon | F22: AYD-004 | G22: =IFERROR(ROUND(G20*G11,MAX(0,MIN(ayd_yuvarMax,IFERROR(N(G12),0)))),0)
A23: 17 | B23: Özkaynak 298/Ç | C23: =IFERROR(G20-G22,0) | D23: TL | E23: Fark − 298 fon | F23: AYD-004 | G23: =IFERROR(G20-G22,0)
A24: 18 | B24: Özkaynak Geç.32 | C24: =IFERROR(G20-G21,0) | D24: TL | E24: Fark − Geç.32 fon | F24: AYD-002 | G24: =IFERROR(G20-G21,0)
A25: 19 | B25: Ek amortisman yıllık | C25: =IFERROR(IF(G16=0,0,G20/G16),0) | D25: TL | E25: Fark / kalan ömür | F25: AYD-003 | G25: =IFERROR(IF(G16=0,0,G20/G16),0)
A26: 20 | B26: Vergi tasarrufu brüt | C26: =IFERROR(ROUND(G20*G10,MAX(0,MIN(ayd_yuvarMax,IFERROR(N(G12),0)))),0) | D26: TL | E26: Fark × KV oranı | F26: AYD-003 | G26: =IFERROR(ROUND(G20*G10,MAX(0,MIN(ayd_yuvarMax,IFERROR(N(G12),0)))),0)
A27: 21 | B27: Net fayda 298/Ç | C27: =IFERROR(G23,0) | D27: TL | E27: 298 özkaynak net | F27: AYD-004 | G27: =IFERROR(G23,0)
A28: 22 | B28: Net fayda Geç.32 | C28: =IFERROR(G24+G26*ayd_tasarrufCarpan,0) | D28: TL | E28: Özkaynak+vergi faydası | F28: AYD-002 | G28: =IFERROR(G24+G26*ayd_tasarrufCarpan,0)
A29: 23 | B29: Fayda farkı (298−Geç32) | C29: =IFERROR(G27-G28,0) | D29: TL | E29: Yol karşılaştırması | F29: AYD-001 | G29: =IFERROR(G27-G28,0)
A30: 24 | B30: Karar kodu | C30: =IFERROR(IF(COUNTA(tblGirdi[Alan Anahtarı])=0,"VERI_YOK",IF(G20<=0,"YAPMA",IF(ABS(G29)<=ayd_kararEsik,"BEKLE","YAP"))),"") | D30: kod | E30: Karar kodu | F30: AYD-001 | G30: =IFERROR(IF(COUNTA(tblGirdi[Alan Anahtarı])=0,"VERI_YOK",IF(G20<=0,"YAPMA",IF(ABS(G29)<=ayd_kararEsik,"BEKLE","YAP"))),"")
A31: 25 | B31: Karar metni | C31: =IFERROR(IF(G30="VERI_YOK","VERİ YOK",IF(G30="YAPMA","YAPMA",IF(G30="BEKLE","BEKLE","YAP"))),"") | D31: metin | E31: Kullanıcıya karar | F31: AYD-001 | G31: =IFERROR(IF(G30="VERI_YOK","VERİ YOK",IF(G30="YAPMA","YAPMA",IF(G30="BEKLE","BEKLE","YAP"))),"")
A32: 26 | B32: Gerekçe | C32: =IFERROR(IF(G30="VERI_YOK","Giriş tablosu boş — amortisman AND yeniden değerleme hesaplanamaz.",IF(G30="YAPMA","Endeks artışı yok veya fark sıfır; yeniden değerleme yapılmamalı.",IF(G30="BEKLE","298/Ç AND Geç.32 net faydaları eşik içinde; öncelik yorumunu AND amortisman cetvelini gözden geçirin.",IF(G29>0,"YAP · 298/Ç net faydası önde; amortisman cetveli AND fon yükü uygun.","YAP · Geç.32 net faydası (özkaynak+vergi) önde; amortisman cetveli ile birlikte uygulayın.")))),"") | D32: metin | E32: Gerekçe cümlesi | F32: AYD-001 | G32: =IFERROR(IF(G30="VERI_YOK","Giriş tablosu boş — amortisman AND yeniden değerleme hesaplanamaz.",IF(G30="YAPMA","Endeks artışı yok veya fark sıfır; yeniden değerleme yapılmamalı.",IF(G30="BEKLE","298/Ç AND Geç.32 net faydaları eşik içinde; öncelik yorumunu AND amortisman cetvelini gözden geçirin.",IF(G29>0,"YAP · 298/Ç net faydası önde; amortisman cetveli AND fon yükü uygun.","YAP · Geç.32 net faydası (özkaynak+vergi) önde; amortisman cetveli ile birlikte uygulayın.")))),"")
A33: 27 | B33: Fark / maliyet | C33: =IFERROR(IF(G13=0,0,G20/G13),0) | D33: oran | E33: Artış yoğunluğu | F33: AYD-001 | G33: =IFERROR(IF(G13=0,0,G20/G13),0)
A34: 28 | B34: Fon / fark | C34: =IFERROR(IF(G20=0,0,G21/G20),0) | D34: oran | E34: Fon yük oranı | F34: AYD-002 | G34: =IFERROR(IF(G20=0,0,G21/G20),0)
A35: 29 | B35: Yorum A net (298 öncelik) | C35: =IFERROR(G27,0) | D35: TL | E35: A yolu net | F35: AYD-004 | G35: =IFERROR(G27,0)
A36: 30 | B36: Yorum B net (Geç.32 öncelik) | C36: =IFERROR(G28,0) | D36: TL | E36: B yolu net | F36: AYD-002 | G36: =IFERROR(G28,0)
A37: 31 | B37: Seçili yorum net | C37: =IFERROR(IF(GIRDI!B13="B",G36,G35),0) | D37: TL | E37: A/B seçimine göre | F37: AYD-001 | G37: =IFERROR(IF(GIRDI!B13="B",G36,G35),0)
A38: 32 | B38: Yorum farkı | C38: =IFERROR(ABS(G35-G36),0) | D38: TL | E38: Belirsizlik aralığı | F38: AYD-001 | G38: =IFERROR(ABS(G35-G36),0)
A39: 33 | B39: Güven skoru | C39: =IFERROR(ROUND(IF(OR(COUNTA(GIRDI!B6:B13)=0,ayd_girisBeklenen=0),0,COUNTA(GIRDI!B6:B13)/ayd_girisBeklenen*100),0),0) | D39: puan | E39: Giriş bütünlüğü | F39: AYD-005 | G39: =IFERROR(ROUND(IF(OR(COUNTA(GIRDI!B6:B13)=0,ayd_girisBeklenen=0),0,COUNTA(GIRDI!B6:B13)/ayd_girisBeklenen*100),0),0)
A40: 34 | B40: Risk skoru | C40: =IFERROR(IF(G30="VERI_YOK",0,IF(G30="YAPMA",ayd_riskDusuk,IF(G30="BEKLE",ayd_riskOrta,ayd_riskYuksek))),0) | D40: puan | E40: Karar riski | F40: AYD-001 | G40: =IFERROR(IF(G30="VERI_YOK",0,IF(G30="YAPMA",ayd_riskDusuk,IF(G30="BEKLE",ayd_riskOrta,ayd_riskYuksek))),0)
A41: 35 | B41: Senaryo iyimser maliyet | C41: =IFERROR(G13*ayd_senaryoIyi,0) | D41: TL | E41: İyimser maliyet | F41: AYD-001 | G41: =IFERROR(G13*ayd_senaryoIyi,0)
A42: 36 | B42: Senaryo kötümser maliyet | C42: =IFERROR(G13*ayd_senaryoKotu,0) | D42: TL | E42: Kötümser maliyet | F42: AYD-001 | G42: =IFERROR(G13*ayd_senaryoKotu,0)
...

Sheet SENARYO
A1: SENARYO — Amortisman + 2026 Yeniden Değerleme
A3: Senaryo ve duyarlılık
A5: Senaryo | B5: Maliyet Çarpanı | C5: Değer Farkı | D5: Geç.32 Fon | E5: Karar | G5: FarkDemo
A6: İyimser | B6: =IFERROR(ayd_senaryoIyi+N(GIRDI!B9)*0,0) | C6: =IFERROR(ROUND(MAX(0,IFERROR(ayd_maliyet,0)*B6*(IFERROR(GIRDI!B11,1)-1)),2),0) | D6: =IFERROR(ROUND(C6*IFERROR(INDEX(tblKurallar[aktif_deger],MATCH("AYD-002",tblKurallar[kural_id],0)),0),2),0) | E6: =IF(COUNTA(tblGirdi[Alan Anahtarı])=0,"VERİ YOK",IF(C6=0,"YAPMA","YAP")) | G6: 405000
A7: Baz | B7: =IFERROR(1+N(GIRDI!B9)*0,1) | C7: =IFERROR(ROUND(MAX(0,IFERROR(ayd_maliyet,0)*B7*(IFERROR(GIRDI!B11,1)-1)),2),0) | D7: =IFERROR(ROUND(C7*IFERROR(INDEX(tblKurallar[aktif_deger],MATCH("AYD-002",tblKurallar[kural_id],0)),0),2),0) | E7: =IF(COUNTA(tblGirdi[Alan Anahtarı])=0,"VERİ YOK",IF(C7=0,"YAPMA","YAP")) | G7: 450000
A8: Kötümser | B8: =IFERROR(ayd_senaryoKotu+N(GIRDI!B9)*0,0) | C8: =IFERROR(ROUND(MAX(0,IFERROR(ayd_maliyet,0)*B8*(IFERROR(GIRDI!B11,1)-1)),2),0) | D8: =IFERROR(ROUND(C8*IFERROR(INDEX(tblKurallar[aktif_deger],MATCH("AYD-002",tblKurallar[kural_id],0)),0),2),0) | E8: =IF(COUNTA(tblGirdi[Alan Anahtarı])=0,"VERİ YOK",IF(C8=0,"YAPMA","YAP")) | G8: 495000
A9: M-SEN fon+1 puan | B9: =IFERROR(1+N(GIRDI!B9)*0,1) | C9: =IFERROR(ayd_fark,0) | D9: =IFERROR(MOTOR!G45,0) | E9: =IF(COUNTA(tblGirdi[Alan Anahtarı])=0,"VERİ YOK",IF(C9=0,"YAPMA",IF(ABS(D9-MOTOR!G21)>ayd_kararEsik,"BEKLE","YAP"))) | G9: 459000
A11: Senaryo bant genişliği (iyimser−kötümser fark) | B11: =IFERROR(C6-C8,0)
A12: Senaryo yorumu | B12: =IFERROR(_xlfn.TEXTJOIN("; ",TRUE,"İyimser fark ",TEXT(C6,"₺ #,##0")," · Baz ",TEXT(C7,"₺ #,##0")," · Kötümser ",TEXT(C8,"₺ #,##0")," · Bant ",TEXT(B11,"₺ #,##0")),"-")
A14: Duyarlılık (tornado)
A15: Değişken | B15: Etki [₺] | C15: Sıra | E15: EtkiDemo
A16: Tornado maliyet etkisi | B16: =IFERROR(MOTOR!G49,0) | C16: =IFERROR(IF(B16>=MAX(B16:B18),1,IF(B16>=MIN(B16:B18)+ABS(B16-B17),2,3)),3) | E16: 22500
A17: Tornado endeks etkisi | B17: =IFERROR(MOTOR!G50,0) | C17: =IFERROR(IF(B17>=MAX(B16:B18),1,IF(B17=MEDIAN(B16:B18),2,3)),3) | E17: 45000
A18: Tornado fon etkisi | B18: =IFERROR(MOTOR!G51,0) | C18: =IFERROR(IF(B18>=MAX(B16:B18),1,IF(B18=MEDIAN(B16:B18),2,3)),3) | E18: 4500
A19: Duyarlılık sıra özeti | B19: =IFERROR(CONCATENATE("1)",INDEX(A16:A18,MATCH(1,C16:C18,0))," 2)",INDEX(A16:A18,MATCH(2,C16:C18,0))),"-")
A20: Duyarlılık yorumu | B20: =_xlfn.TEXTJOIN("; ",TRUE,"En yüksek etki ",TEXT(MAX(B16:B18),"₺ #,##0")," TL — öncelik bu değişkende")
A22: M-SEN kural değişimi fon | B22: =D9
A23: M-SEN yorumu | B23: =_xlfn.TEXTJOIN("; ",TRUE,"Fon oranı +1 puan senaryosunda fon ",TEXT(D9,"₺ #,##0")," TL")
A25: Tahmin aralığı (fark) | B25: =MOTOR!G48 | C25: =ayd_fark | D25: =MOTOR!G47
A26: Tahmin (FORECAST)
A27: Seri nokta | D27: TrendDemo
A28: 1 | B28: =C6 | D28: 405000
A29: 2 | B29: =C7 | D29: 450000
A30: 3 | B30: =C8 | D30: 495000
A31: 4 | B31: =C9 | D31: 459000
A32: Tahmin sonraki | B32: =IFERROR(FORECAST.LINEAR(5,B28:B31,A28:A31),0)
A33: Tahmin yorumu | B33: =_xlfn.TEXTJOIN("; ",TRUE,"Tahmin ",TEXT(B32,"₺ #,##0")," · Alt ",TEXT(B25,"₺ #,##0")," · Üst ",TEXT(D25,"₺ #,##0"))

Sheet VAKALAR
A1: VAKALAR — Amortisman + 2026 Yeniden Değerleme
A3: Tebliğ tarzı altın vakalar
A5: vaka_id | B5: aciklama | C5: girdi_ozeti | D5: beklenen_sonuc | E5: hesaplanan | F5: fark | G5: durum | H5: kaynak | J5: BeklenenDemo | K5: HesapDemo
A6: YD-V01 | B6: Tebliğ örnek 1 — pozitif fark | C6: maliyet=vaka_maliyet_1; endeks=vaka_endeks_1 | D6: 450000 | E6: =IFERROR(ROUND(MAX(0,vaka_maliyet_1*(vaka_endeks_1-INDEX(tblKurallar[deger_2025],MATCH("AYD-001",tblKurallar[kural_id],0)))),2),0) | F6: =IF($A6="","",IFERROR($D6-$E6,0)) | G6: =IF($A6="","",IFERROR(IF(ABS($F6)<=ayd_tolerans,"TUTARLI","KIRIK"),"KIRIK")) | H6: VUK 298/Ç · Geçici 32 hesap örneği | J6: 450000 | K6: 450000
A7: YD-V02 | B7: Tebliğ örnek 2 — orta endeks | C7: maliyet=vaka_maliyet_2; endeks=vaka_endeks_2 | D7: 400000 | E7: =IFERROR(ROUND(MAX(0,vaka_maliyet_2*(vaka_endeks_2-INDEX(tblKurallar[deger_2025],MATCH("AYD-001",tblKurallar[kural_id],0)))),2),0) | F7: =IF($A7="","",IFERROR($D7-$E7,0)) | G7: =IF($A7="","",IFERROR(IF(ABS($F7)<=ayd_tolerans,"TUTARLI","KIRIK"),"KIRIK")) | H7: VUK 298/Ç hesap örneği | J7: 400000 | K7: 400000
A8: YD-V03 | B8: Tebliğ örnek 3 — düşük endeks | C8: maliyet=vaka_maliyet_3; endeks=vaka_endeks_3 | D8: 50000 | E8: =IFERROR(ROUND(MAX(0,vaka_maliyet_3*(vaka_endeks_3-INDEX(tblKurallar[deger_2025],MATCH("AYD-001",tblKurallar[kural_id],0)))),2),0) | F8: =IF($A8="","",IFERROR($D8-$E8,0)) | G8: =IF($A8="","",IFERROR(IF(ABS($F8)<=ayd_tolerans,"TUTARLI","KIRIK"),"KIRIK")) | H8: VUK 298/Ç hesap örneği | J8: 50000 | K8: 50000
A9: YD-V04 | B9: Geç.32 fon kontrolü | C9: fark=vaka_maliyet_1*(vaka_endeks_1-1); fon oranı AYD-002 | D9: 9000 | E9: =IFERROR(ROUND(MAX(0,vaka_maliyet_1*(vaka_endeks_1-1))*INDEX(tblKurallar[deger_2025],MATCH("AYD-002",tblKurallar[kural_id],0)),2),0) | F9: =IF($A9="","",IFERROR($D9-$E9,0)) | G9: =IF($A9="","",IFERROR(IF(ABS($F9)<=ayd_tolerans,"TUTARLI","KIRIK"),"KIRIK")) | H9: VUK Geçici md.32 | J9: 9000 | K9: 9000
A12: Vaka durum özeti | B12: =IFERROR(IF(COUNTIF(tblVakalar[durum],"KIRIK")>0,"KIRIK","TUTARLI"),"KIRIK")
A13: Vaka fark toplamı | B13: =IFERROR(SUM(tblVakalar[fark]),0)

Sheet KANIT_RAPORU
A1: KANIT RAPORU — Amortisman + 2026 Yeniden Değerleme
A3: KANIT RAPORU — Amortisman + 2026 Yeniden Değerleme
A4: Rapor tarihi | B4: =raporTarihi
A5: Kurum | B5: =GIRDI!B6
A6: Dönem / yıl | B6: =CONCATENATE(GIRDI!B7," / ",hesapYili)
A8: Girdi özeti
A9: Maliyet | B9: =GIRDI!B9
A10: Birikmiş amortisman | B10: =GIRDI!B10
A11: Endeks oranı | B11: =GIRDI!B11
A12: Kalan ömür | B12: =GIRDI!B12
A13: Değer artış farkı | B13: =ayd_fark
A14: Net defter | B14: =ayd_netDefter
A16: Hesap zinciri
A17: Geç.32 fon | B17: =ayd_fonGec32
A18: Özkaynak 298/Ç | B18: =ayd_ozKaynak298
A19: KARAR | B19: =ayd_kararMetni
A20: Gerekçe | B20: =ayd_kararGerekce
A22: Madde atıfları | B22: =ayd_maddeAtifMetni
A24: Kanıt gövdesi | B24: =ayd_kanitRaporu
A26: Parmak izi (SHA-256 kısaltma) | B26: =ayd_parmakIzi
A28: Hazırlayan (imza)
A29: Onaylayan (imza)
A31: Uyarı: Bu çıktı karar destektir; kesin vergi tarhiyatı veya hukuki görüş değildir. Sürüm 1.0.0.

Sheet KONTROLLER
A1: KONTROLLER — Amortisman + 2026 Yeniden Değerleme
A3: Canlı kontrol paneli
A5: Giriş tablosu boş mu? | B5: =IF(COUNTA(tblGirdi[Alan Anahtarı])=0,"BOŞ","DOLU")
A6: Negatif maliyet? | B6: =IF(GIRDI!B9<0,"NEGATİF","TEMİZ")
A7: Hesap yılı geçerli mi? | B7: =IFERROR(IF(AND(N(hesapYili)>N(ayd_yilTaban),N(hesapYili)<=N(ayd_yilTaban)+3),"TEMİZ","HATALI"),"HATALI")
A8: Fark sıfır mı? | B8: =IF(IFERROR(ayd_fark,0)=0,"SIFIR","NORMAL")
A9: Vaka kırık mı? | B9: =IFERROR(IF(COUNTIF(tblVakalar[durum],"KIRIK")>0,"KIRIK","TUTARLI"),"KIRIK")
A10: Fark eşiği aşıyor mu? | B10: =IF(IFERROR(ayd_fark,0)>ayd_farkEsik,"AŞIYOR","NORMAL")
A11: Öncelik A/B seçili mi? | B11: =IF(OR(GIRDI!B13="A",GIRDI!B13="B"),"TEMİZ","EKSİK")
A12: Kalite skoru (modül) | B12: =IFERROR(ROUND(IF(OR(B14=0,B14=""),0,B15/B14*100),0),0)
A14: Toplam giriş alanı | B14: =IFERROR(ayd_girisBeklenen+COUNTA(GIRDI!B6:B13)*0,0)
A15: Dolu giriş | B15: =COUNTA(GIRDI!B6:B13)
A17: Fark kontrol | B17: =IFERROR(ayd_fark,0)
A18: Fon kontrol | B18: =IFERROR(ayd_fonGec32,0)
A19: Karar kontrol | B19: =IFERROR(ayd_kararMetni,"-")

Sheet ORNEK_VERI
A1: ORNEK VERI — Amortisman + 2026 Yeniden Değerleme
A3: Örnek senaryo kütüphanesi
A4: Bu sayfa demo değerleri saklar; GIRDI'ye kopyalanabilir.
A5: Senaryo | B5: Maliyet | C5: Birikmiş | D5: Endeks | E5: Kalan Ömür | F5: Öncelik | G5: Fark | H5: Fon Geç.32 | I5: Özkaynak 298 | L5: FarkDemo
A6: Demo ana | B6: 1000000 | C6: 200000 | D6: 1.45 | E6: 10 | F6: A | G6: =IF($A6="","",IFERROR(ROUND(MAX(0,$B6*($D6-1)),2),0)) | H6: =IF($A6="","",IFERROR(ROUND($G6*INDEX(tblKurallar[deger_2025],MATCH("AYD-002",tblKurallar[kural_id],0)),2),0)) | I6: =IF($A6="","",IFERROR($G6-$G6*INDEX(tblKurallar[deger_2025],MATCH("AYD-004",tblKurallar[kural_id],0)),0)) | L6: 450000
