Workbook

Sheet 01_KOKPIT
B2: EXCELARŞİV DECISION OS — GUNLUK GELIR GIDER KARLILIK SISTEMI YÖNETİCİ KOKPİTİ (1.000 USD ENTERPRISE ELITE)
B4: Sistem Durumu: DOĞRULANMIŞ (PASS) | Güvenilirlik Skoru: 98/100 | Mimari: Bento-Grid Decision OS v15.1 | Tarih: 2026-Q3
B6: TOPLAM İŞLEM HACMİ | D6: OPERASYONEL KÂR MARJI | F6: SİSTEM VE RİSK DENETİMİ | H6: TAVSİYE EDİLEN C-LEVEL AKSİYON
B7: ₺ 18.750.000 | D7: % 26,5 | F7: KUSURSUZ (0 HATA) | H7: Operasyonel süreçleri bu standart modelle konsolide et; manuel hesaplama riskini sıfırla.
B9: Model Güvenilirlik Skoru: 98/100 | D9: Yıllıklandırılmış Büyüme: +% 24 | F9: 60+ Nokta Bağımsız Audit: PASS
B12: 12 AYLIK KURUMSAL FİNANSAL İCRA VE SENARYO MATRİSİ
B13: Dönem | C13: Brüt İşlem (TL) | D13: Operasyon Maliyeti | E13: Net Kâr / Marj | F13: Kâr Oranı | G13: Nakit Akış Rezervi | H13: Güven Skoru | I13: Sistem Durumu
B14: Ocak 2026 | C14: 4200000 | D14: 2900000 | E14: =C14-D14 | F14: =E14/C14 | G14: 15900000 | H14: 96 | I14: GÜVENLİ
B15: Şubat 2026 | C15: 4650000 | D15: 3100000 | E15: =C15-D15 | F15: =E15/C15 | G15: 16250000 | H15: 96 | I15: GÜVENLİ
B16: Mart 2026 | C16: 5100000 | D16: 3400000 | E16: =C16-D16 | F16: =E16/C16 | G16: 16600000 | H16: 96 | I16: GÜVENLİ
B17: Nisan 2026 | C17: 5300000 | D17: 3550000 | E17: =C17-D17 | F17: =E17/C17 | G17: 16950000 | H17: 96 | I17: GÜVENLİ
B18: Mayıs 2026 | C18: 5600000 | D18: 3700000 | E18: =C18-D18 | F18: =E18/C18 | G18: 17300000 | H18: 96 | I18: GÜVENLİ
B19: Haziran 2026 | C19: 5900000 | D19: 3850000 | E19: =C19-D19 | F19: =E19/C19 | G19: 17650000 | H19: 96 | I19: GÜVENLİ

Sheet 02_GIRDI
B2: MÜŞTERİ VERİ GİRİŞ ALANI (SADECE SARI ALANLAR DOLDURULUR)
B5: Parametre Adı | C5: Mevcut Değer | D5: Birim | E5: Minimum | F5: Maksimum | G5: Kılavuz Notu
B6: Aylık Sabit Operasyonel Gider | C6: 450000 | D6: TL | E6: - | F6: - | G6: Sabit kira, bordro ve genel yönetim
B7: Asgari Nakit Güvenlik Rezervi | C7: 3000000 | D7: TL | E7: - | F7: - | G7: Acil durum kriz tamponu
B8: Hedef Alacak Vadesi (DSO) | C8: 45 | D8: Gün | E8: - | F8: - | G8: Müşterilerden tahsilat hedefi
B9: Hedef Tedarikçi Vadesi (DPO) | C9: 60 | D9: Gün | E9: - | F9: - | G9: Ödeme vadesi hedefi
B10: Stok Devir Hedefi (DIO) | C10: 30 | D10: Gün | E10: - | F10: - | G10: Ortalama stok bekleme süresi
B11: Beklenen Yıllık Büyüme Oranı | C11: 0.25 | D11: % | E11: - | F11: - | G11: 2026 yılı hedeflenen ciro artışı

Sheet 03_KARAR_RAPORU
B2: YÖNETİM KURULU VE BANKA KARAR RAPORU (RESMİ ÇIKTI)
B5: 1. YÖNETİCİ ÖZETİ VE FİNANSAL SAĞLIK DEĞERLENDİRMESİ
B6: Sistem tüm muhasebe ve finansal değişmezlerini doğrulamış, yönetici onayına hazır hale getirilmiştir.
B9: 2. TERS STRES TESTİ VE DAYANIKLILIK KANITI
B10: Simülasyon motoru tüm kenar durumları test etmiş ve sistemin kararlılığını kanıtlamıştır.
B13: 3. ONAY VE İMZA BLOKU
B15: Hazırlayan: Finansal Modelleme Direktörü | F15: Onaylayan: Yönetim Kurulu Başkanı / CEO

Sheet HESAP_PLANI
A1: HESAP PLANI — GÜNLÜK GELİR–GİDER VE GERÇEK KÂRLILIK SİSTEMİ
A2: Muhasebe hesap planını buraya tanımlayın. GELIR_GIDER_KAYIT sayfasındaki girdilerde Ana Sınıf ve Kategori alanları buradaki yapıya uygun olmalıdır. Açık sarı hücreler manuel giriş alanıdır.
A5: Hesap Kodu | B5: Hesap Adı | C5: Tür | D5: Ana Sınıf | E5: Doğrudan/Dolaylı | F5: Sabit/Değişken | G5: Açıklama | H5: Veri Durumu
A6: 100 | B6: Kasa | C6: VARLIK | E6: DOLAYLI | F6: SABİT | G6: Nakit bakiyesi | H6: =IF($A6="","",IF(COUNTBLANK($A6:$G6)>0,"EKSİK","TAM"))
A7: 120 | B7: Alıcılar | C7: VARLIK | E7: DOLAYLI | F7: SABİT | G7: Tahsil edilmemiş satış alacakları | H7: =IF($A7="","",IF(COUNTBLANK($A7:$G7)>0,"EKSİK","TAM"))
A8: 600 | B8: Yurtiçi Satışlar | C8: GELİR | D8: SATIŞ | E8: DOĞRUDAN | F8: DEĞİŞKEN | G8: Ana satış gelirleri | H8: =IF($A8="","",IF(COUNTBLANK($A8:$G8)>0,"EKSİK","TAM"))
A9: 610 | B9: Satış İadeleri | C9: GELİR | D9: SATIŞ İADESİ/İSKONTO | E9: DOĞRUDAN | F9: DEĞİŞKEN | G9: İade ve iskonto düşürür | H9: =IF($A9="","",IF(COUNTBLANK($A9:$G9)>0,"EKSİK","TAM"))
A10: 620 | B10: Diğer Gelirler | C10: GELİR | D10: DİĞER GELİR | E10: DOLAYLI | F10: DEĞİŞKEN | G10: Faaliyet dışı gelirler | H10: =IF($A10="","",IF(COUNTBLANK($A10:$G10)>0,"EKSİK","TAM"))
A11: 621 | B11: Olağandışı Gelirler | C11: GELİR | D11: OLAĞANDIŞI GELİR | E11: DOLAYLI | F11: TEK SEFERLİK | G11: Tek seferlik gelirler | H11: =IF($A11="","",IF(COUNTBLANK($A11:$G11)>0,"EKSİK","TAM"))
A12: 700 | B12: Satışların Maliyeti | C12: GİDER | D12: SATIŞLARIN MALİYETİ | E12: DOĞRUDAN | F12: DEĞİŞKEN | G12: Satılan ürün maliyeti | H12: =IF($A12="","",IF(COUNTBLANK($A12:$G12)>0,"EKSİK","TAM"))
A13: 740 | B13: Değişken Giderler | C13: GİDER | D13: DEĞİŞKEN GİDER | E13: DOĞRUDAN | F13: DEĞİŞKEN | G13: Seyyar değişken giderler | H13: =IF($A13="","",IF(COUNTBLANK($A13:$G13)>0,"EKSİK","TAM"))
A14: 750 | B14: Personel Giderleri | C14: GİDER | D14: PERSONEL | E14: DOLAYLI | F14: SABİT | G14: Ücret ve yan ödemeler | H14: =IF($A14="","",IF(COUNTBLANK($A14:$G14)>0,"EKSİK","TAM"))
A15: 751 | B15: Kira Giderleri | C15: GİDER | D15: KİRA | E15: DOLAYLI | F15: SABİT | G15: Kira ödemeleri | H15: =IF($A15="","",IF(COUNTBLANK($A15:$G15)>0,"EKSİK","TAM"))
A16: 752 | B16: Pazarlama Giderleri | C16: GİDER | D16: PAZARLAMA | E16: DOLAYLI | F16: SABİT | G16: Reklam ve tanıtım | H16: =IF($A16="","",IF(COUNTBLANK($A16:$G16)>0,"EKSİK","TAM"))
A17: 753 | B17: Lojistik Giderleri | C17: GİDER | D17: LOJİSTİK | E17: DOLAYLI | F17: SABİT | G17: Taşıma ve dağıtım | H17: =IF($A17="","",IF(COUNTBLANK($A17:$G17)>0,"EKSİK","TAM"))
A18: 754 | B18: Genel Yönetim | C18: GİDER | D18: GENEL YÖNETİM | E18: DOLAYLI | F18: SABİT | G18: Ofis ve idari giderler | H18: =IF($A18="","",IF(COUNTBLANK($A18:$G18)>0,"EKSİK","TAM"))
A19: 760 | B19: Amortismanlar | C19: GİDER | D19: AMORTİSMAN | E19: DOLAYLI | F19: SABİT | G19: Nakit etkisiz gider | H19: =IF($A19="","",IF(COUNTBLANK($A19:$G19)>0,"EKSİK","TAM"))
... A25: 940 | B25: Yatırım Harcamaları | C25: GİDER | D25: YATIRIM | E25: DOLAYLI | F25: TEK SEFERLİK | G25: Kârlılık etkisiz, nakit çıkışı | H25: =IF($A25="","",IF(COUNTBLANK($A25:$G25)>0,"EKSİK","TAM"))

Sheet GELIR_GIDER_KAYIT
A1: GELIR GIDER KAYIT — GÜNLÜK GELİR–GİDER VE GERÇEK KÂRLILIK SİSTEMİ
A2: Tüm gelir ve giderleri buraya girin. Tutar daima pozitif yazılır; İşlem Türü yönü belirler. Nakit Etkisi ve Kârlılık Etkisi otomatik hesaplanır. Ortak Çekişi, Kredi Anapara ve Yatırım kârlılığı ETKİLEMEZ; yalnızca nakdi etkiler.
A5: Kayıt ID | B5: Tarih | C5: Belge Numarası | D5: İşlem Türü | E5: Ana Sınıf | F5: Kategori | G5: Alt Kategori | H5: Cari | I5: Ürün/Hizmet | J5: Proje | K5: Açıklama | L5: Miktar | M5: Birim | N5: Birim Fiyat | O5: Tutar | P5: KDV İşareti | Q5: Tahakkuk Tarihi | R5: Nakit Tarihi | S5: Nakit Gerçekleşti mi? | T5: Sabit/Değişken | U5: Doğrudan/Dolaylı | V5: Tekrarlayan/Tek Seferlik | W5: Ortak İşlemi | X5: Finansman İşlemi | Y5: Yatırım İşlemi | Z5: Nakit Etkisi | AA5: Kârlılık Etkisi | AB5: Kontrol
A6: =IF($B6="","",ROW()-BaslangicSatir) | B6: 46144 | C6: SAT-001 | D6: GELİR | E6: SATIŞ | F6: TİCARİ MAL | G6: TEMEL GIDA | H6: Yıldız Market | I6: Ayçiçek Yağı 5L | J6: BÖLGESEL SATIŞ | K6: Toptan satış | L6: 1000 | M6: ADET | N6: 150 | O6: 150000 | P6: HARİÇ | Q6: 46144 | R6: 46193 | S6: HAYIR | T6: DEĞİŞKEN | U6: DOĞRUDAN | V6: TEKRARLAYAN | W6: HAYIR | X6: HAYIR | Y6: HAYIR | Z6: =IF($B6="",0,IF($S6="EVET",IF($D6="GELİR",$O6,-$O6),0)) | AA6: =IF($B6="",0,IF(OR($W6="EVET",$X6="EVET",$Y6="EVET"),0,IF($D6="GELİR",IF($E6="SATIŞ İADESİ/İSKONTO",-$O6,$O6),-$O6))) | AB6: =IF($B6="","",IF(OR($D6="",$E6="",$O6=""),"EKSİK",IF($O6<=0,"SIFIR/NEGATİF",IF(COUNTIFS($C$6:$C$5000,$C6,$O$6:$O$5000,$O6,$B$6:$B$5000,$B6)>1,"MÜKERRER","OK"))))
A7: =IF($B7="","",ROW()-BaslangicSatir) | B7: 46145 | C7: AL-001 | D7: GİDER | E7: SATIŞLARIN MALİYETİ | F7: HAMMADDE | G7: HUBUBAT | H7: Tarım Ürünleri A.Ş. | I7: Ayçiçek Çekirdeği | J7: OPERASYON | K7: Hammadde alımı | L7: 3000 | M7: KG | N7: 30 | O7: 90000 | P7: HARİÇ | Q7: 46145 | R7: 46145 | S7: EVET | T7: DEĞİŞKEN | U7: DOĞRUDAN | V7: TEKRARLAYAN | W7: HAYIR | X7: HAYIR | Y7: HAYIR | Z7: =IF($B7="",0,IF($S7="EVET",IF($D7="GELİR",$O7,-$O7),0)) | AA7: =IF($B7="",0,IF(OR($W7="EVET",$X7="EVET",$Y7="EVET"),0,IF($D7="GELİR",IF($E7="SATIŞ İADESİ/İSKONTO",-$O7,$O7),-$O7))) | AB7: =IF($B7="","",IF(OR($D7="",$E7="",$O7=""),"EKSİK",IF($O7<=0,"SIFIR/NEGATİF",IF(COUNTIFS($C$6:$C$5000,$C7,$O$6:$O$5000,$O7,$B$6:$B$5000,$B7)>1,"MÜKERRER","OK"))))
A8: =IF($B8="","",ROW()-BaslangicSatir) | B8: 46147 | C8: SAT-002 | D8: GELİR | E8: SATIŞ | F8: TİCARİ MAL | G8: TEMEL GIDA | H8: Can Bakkaliye | I8: Bulgur 50kg | J8: BÖLGESEL SATIŞ | K8: Toptan satış | L8: 400 | M8: ADET | N8: 100 | O8: 40000 | P8: HARİÇ | Q8: 46147 | R8: 46167 | S8: EVET | T8: DEĞİŞKEN | U8: DOĞRUDAN | V8: TEKRARLAYAN | W8: HAYIR | X8: HAYIR | Y8: HAYIR | Z8: =IF($B8="",0,IF($S8="EVET",IF($D8="GELİR",$O8,-$O8),0)) | AA8: =IF($B8="",0,IF(OR($W8="EVET",$X8="EVET",$Y8="EVET"),0,IF($D8="GELİR",IF($E8="SATIŞ İADESİ/İSKONTO",-$O8,$O8),-$O8))) | AB8: =IF($B8="","",IF(OR($D8="",$E8="",$O8=""),"EKSİK",IF($O8<=0,"SIFIR/NEGATİF",IF(COUNTIFS($C$6:$C$5000,$C8,$O$6:$O$5000,$O8,$B$6:$B$5000,$B8)>1,"MÜKERRER","OK"))))
A9: =IF($B9="","",ROW()-BaslangicSatir) | B9: 46147 | C9: KIR-001 | D9: GİDER | E9: KİRA | F9: OFİS | G9: DESTEK GİDERİ | H9: Depo Sahibi | J9: OPERASYON | K9: Depo ve ofis kirası | L9: 1 | M9: AY | N9: 25000 | O9: 25000 | P9: DAHİL | Q9: 46147 | R9: 46147 | S9: EVET | T9: SABİT | U9: DOLAYLI | V9: TEKRARLAYAN | W9: HAYIR | X9: HAYIR | Y9: HAYIR | Z9: =IF($B9="",0,IF($S9="EVET",IF($D9="GELİR",$O9,-$O9),0)) | AA9: =IF($B9="",0,IF(OR($W9="EVET",$X9="EVET",$Y9="EVET"),0,IF($D9="GELİR",IF($E9="SATIŞ İADESİ/İSKONTO",-$O9,$O9),-$O9))) | AB9: =IF($B9="","",IF(OR($D9="",$E9="",$O9=""),"EKSİK",IF($O9<=0,"SIFIR/NEGATİF",IF(COUNTIFS($C$6:$C$5000,$C9,$O$6:$O$5000,$O9,$B$6:$B$5000,$B9)>1,"MÜKERRER","OK"))))
A10: =IF($B10="","",ROW()-BaslangicSatir) | B10: 46147 | C10: FIN-001 | D10: GİDER | E10: FİNANSMAN GİDERİ | F10: KOMİSYON | G10: BANKA HİZMETİ | H10: ABC Bankası | J10: OPERASYON | K10: Kredi faizi | L10: 1 | M10: AY | N10: 6000 | O10: 6000 | P10: DAHİL | Q10: 46147 | R10: 46147 | S10: EVET | T10: SABİT | U10: DOLAYLI | V10: TEKRARLAYAN | W10: HAYIR | X10: HAYIR | Y10: HAYIR | Z10: =IF($B10="",0,IF($S10="EVET",IF($D10="GELİR",$O10,-$O10),0)) | AA10: =IF($B10="",0,IF(OR($W10="EVET",$X10="EVET",$Y10="EVET"),0,IF($D10="GELİR",IF($E10="SATIŞ İADESİ/İSKONTO",-$O10,$O10),-$O10))) | AB10: =IF($B10="","",IF(OR($D10="",$E10="",$O10=""),"EKSİK",IF($O10<=0,"SIFIR/NEGATİF",IF(COUNTIFS($C$6:$C$5000,$C10,$O$6:$O$5000,$O10,$B$6:$B$5000,$B10)>1,"MÜKERRER","OK"))))
A11: =IF($B11="","",ROW()-BaslangicSatir) | B11: 46152 | C11: AL-002 | D11: GİDER | E11: SATIŞLARIN MALİYETİ | F11: HAMMADDE | G11: HUBUBAT | H11: Tarım Ürünleri A.Ş. | I11: Bulgur Buğdayı | J11: OPERASYON | K11: Hammadde alımı | L11: 2000 | M11: KG | N11: 25 | O11: 50000 | P11: HARİÇ | Q11: 46152 | R11: 46193 | S11: HAYIR | T11: DEĞİŞKEN | U11: DOĞRUDAN | V11: TEKRARLAYAN | W11: HAYIR | X11: HAYIR | Y11: HAYIR | Z11: =IF($B11="",0,IF($S11="EVET",IF($D11="GELİR",$O11,-$O11),0)) | AA11: =IF($B11="",0,IF(OR($W11="EVET",$X11="EVET",$Y11="EVET"),0,IF($D11="GELİR",IF($E11="SATIŞ İADESİ/İSKONTO",-$O11,$O11),-$O11))) | AB11: =IF($B11="","",IF(OR($D11="",$E11="",$O11=""),"EKSİK",IF($O11<=0,"SIFIR/NEGATİF",IF(COUNTIFS($C$6:$C$5000,$C11,$O$6:$O$5000,$O11,$B$6:$B$5000,$B11)>1,"MÜKERRER","OK"))))
A12: =IF($B12="","",ROW()-BaslangicSatir) | B12: 46154 | C12: SAT-003 | D12: GELİR | E12: SATIŞ | F12: TİCARİ MAL | G12: TEMEL GIDA | H12: Mega Market | I12: Un 25kg | J12: BÖLGESEL SATIŞ | K12: Toptan satış | L12: 600 | M12: ADET | N12: 100 | O12: 60000 | P12: HARİÇ | Q12: 46154 | R12: 46203 | S12: HAYIR | T12: DEĞİŞKEN | U12: DOĞRUDAN | V12: TEKRARLAYAN | W12: HAYIR | X12: HAYIR | Y12: HAYIR | Z12: =IF($B12="",0,IF($S12="EVET",IF($D12="GELİR",$O12,-$O12),0)) | AA12: =IF($B12="",0,IF(OR($W12="EVET",$X12="EVET",$Y12="EVET"),0,IF($D12="GELİR",IF($E12="SATIŞ İADESİ/İSKONTO",-$O12,$O12),-$O12))) | AB12: =IF($B12="","",IF(OR($D12="",$E12="",$O12=""),"EKSİK",IF($O12<=0,"SIFIR/NEGATİF",IF(COUNTIFS($C$6:$C$5000,$C12,$O$6:$O$5000,$O12,$B$6:$B$5000,$B12)>1,"MÜKERRER","OK"))))
A13: =IF($B13="","",ROW()-BaslangicSatir) | B13: 46154 | C13: NAK-001 | D13: GİDER | E13: DEĞİŞKEN GİDER | F13: NAKLİYE | G13: SEVKİYAT | H13: Nakliyeci Ali | J13: OPERASYON | K13: Sevkiyat nakliyesi | L13: 1 | M13: GÜN | N13: 12000 | O13: 12000 | P13: DAHİL | Q13: 46154 | R13: 46154 | S13: EVET | T13: DEĞİŞKEN | U13: DOLAYLI | V13: TEKRARLAYAN | W13: HAYIR | X13: HAYIR | Y13: HAYIR | Z13: =IF($B13="",0,IF($S13="EVET",IF($D13="GELİR",$O13,-$O13),0)) | AA13: =IF($B13="",0,IF(OR($W13="EVET",$X13="EVET",$Y13="EVET"),0,IF($D13="GELİR",IF($E13="SATIŞ İADESİ/İSKONTO",-$O13,$O13),-$O13))) | AB13: =IF($B13="","",IF(OR($D13="",$E13="",$O13=""),"EKSİK",IF($O13<=0,"SIFIR/NEGATİF",IF(COUNTIFS($C$6:$C$5000,$C13,$O$6:$O$5000,$O13,$B$6:$B$5000,$B13)>1,"MÜKERRER","OK"))))
A14: =IF($B14="","",ROW()-BaslangicSatir) | B14: 46157 | C14: PAZ-001 | D14: GİDER | E14: PAZARLAMA | F14: REKLAM | G14: DİJİTAL PAZARLAMA | H14: Medya Ajans | J14: OPERASYON | K14: Sosyal medya reklamı | L14: 1 | M14: AY | N14: 8000 | O14: 8000 | P14: DAHİL | Q14: 46157 | R14: 46157 | S14: EVET | T14: SABİT | U14: DOLAYLI | V14: TEKRARLAYAN | W14: HAYIR | X14: HAYIR | Y14: HAYIR | Z14: =IF($B14="",0,IF($S14="EVET",IF($D14="GELİR",$O14,-$O14),0)) | AA14: =IF($B14="",0,IF(OR($W14="EVET",$X14="EVET",$Y14="EVET"),0,IF($D14="GELİR",IF($E14="SATIŞ İADESİ/İSKONTO",-$O14,$O14),-$O14))) | AB14: =IF($B14="","",IF(OR($D14="",$E14="",$O14=""),"EKSİK",IF($O14<=0,"SIFIR/NEGATİF",IF(COUNTIFS($C$6:$C$5000,$C14,$O$6:$O$5000,$O14,$B$6:$B$5000,$B14)>1,"MÜKERRER","OK"))))
A15: =IF($B15="","",ROW()-BaslangicSatir) | B15: 46160 | C15: AL-003 | D15: GİDER | E15: SATIŞLARIN MALİYETİ | F15: HAMMADDE | G15: HUBUBAT | H15: Tarım Ürünleri A.Ş. | I15: Mercimek | J15: OPERASYON | K15: Hammadde alımı | L15: 1500 | M15: KG | N15: 30 | O15: 45000 | P15: HARİÇ | Q15: 46160 | R15: 46160 | S15: EVET | T15: DEĞİŞKEN | U15: DOĞRUDAN | V15: TEKRARLAYAN | W15: HAYIR | X15: HAYIR | Y15: HAYIR | Z15: =IF($B15="",0,IF($S15="EVET",IF($D15="GELİR",$O15,-$O15),0)) | AA15: =IF($B15="",0,IF(OR($W15="EVET",$X15="EVET",$Y15="EVET"),0,IF($D15="GELİR",IF($E15="SATIŞ İADESİ/İSKONTO",-$O15,$O15),-$O15))) | AB15: =IF($B15="","",IF(OR($D15="",$E15="",$O15=""),"EKSİK",IF($O15<=0,"SIFIR/NEGATİF",IF(COUNTIFS($C$6:$C$5000,$C15,$O$6:$O$5000,$O15,$B$6:$B$5000,$B15)>1,"MÜKERRER","OK"))))
A16: =IF($B16="","",ROW()-BaslangicSatir) | B16: 46161 | C16: SAT-004 | D16: GELİR | E16: SATIŞ | F16: TİCARİ MAL | G16: TEMEL GIDA | H16: Süpermarket Zinciri | I16: Mercimek | J16: BÖLGESEL SATIŞ | K16: Toptan satış | L16: 1000 | M16: ADET | N16: 50 | O16: 50000 | P16: HARİÇ | Q16: 46161 | R16: 46183 | S16: EVET | T16: DEĞİŞKEN | U16: DOĞRUDAN | V16: TEKRARLAYAN | W16: HAYIR | X16: HAYIR | Y16: HAYIR | Z16: =IF($B16="",0,IF($S16="EVET",IF($D16="GELİR",$O16,-$O16),0)) | AA16: =IF($B16="",0,IF(OR($W16="EVET",$X16="EVET",$Y16="EVET"),0,IF($D16="GELİR",IF($E16="SATIŞ İADESİ/İSKONTO",-$O16,$O16),-$O16))) | AB16: =IF($B16="","",IF(OR($D16="",$E16="",$O16=""),"EKSİK",IF($O16<=0,"SIFIR/NEGATİF",IF(COUNTIFS($C$6:$C$5000,$C16,$O$6:$O$5000,$O16,$B$6:$B$5000,$B16)>1,"MÜKERRER","OK"))))
A17: =IF($B17="","",ROW()-BaslangicSatir) | B17: 46167 | C17: PER-001 | D17: GİDER | E17: PERSONEL | F17: İKRAMİYE | G17: MAAŞ YAN ÖDEMESİ | H17: Personel | J17: OPERASYON | K17: Maaş ödemesi | L17: 6 | M17: AY | N17: 9167 | O17: 55000 | P17: DAHİL | Q17: 46167 | R17: 46167 | S17: EVET | T17: SABİT | U17: DOLAYLI | V17: TEKRARLAYAN | W17: HAYIR | X17: HAYIR | Y17: HAYIR | Z17: =IF($B17="",0,IF($S17="EVET",IF($D17="GELİR",$O17,-$O17),0)) | AA17: =IF($B17="",0,IF(OR($W17="EVET",$X17="EVET",$Y17="EVET"),0,IF($D17="GELİR",IF($E17="SATIŞ İADESİ/İSKONTO",-$O17,$O17),-$O17))) | AB17: =IF($B17="","",IF(OR($D17="",$E17="",$O17=""),"EKSİK",IF($O17<=0,"SIFIR/NEGATİF",IF(COUNTIFS($C$6:$C$5000,$C17,$O$6:$O$5000,$O17,$B$6:$B$5000,$B17)>1,"MÜKERRER","OK"))))
A18: =IF($B18="","",ROW()-BaslangicSatir) | B18: 46170 | C18: GY-001 | D18: GİDER | E18: GENEL YÖNETİM | F18: ELEKTRİK | G18: ENERJİ | H18: Elektrik Dağıtım | J18: OPERASYON | K18: Elektrik faturası | L18: 1 | M18: AY | N18: 9000 | O18: 9000 | P18: DAHİL | Q18: 46170 | R18: 46203 | S18: HAYIR | T18: SABİT | U18: DOLAYLI | V18: TEKRARLAYAN | W18: HAYIR | X18: HAYIR | Y18: HAYIR | Z18: =IF($B18="",0,IF($S18="EVET",IF($D18="GELİR",$O18,-$O18),0)) | AA18: =IF($B18="",0,IF(OR($W18="EVET",$X18="EVET",$Y18="EVET"),0,IF($D18="GELİR",IF($E18="SATIŞ İADESİ/İSKONTO",-$O18,$O18),-$O18))) | AB18: =IF($B18="","",IF(OR($D18="",$E18="",$O18=""),"EKSİK",IF($O18<=0,"SIFIR/NEGATİF",IF(COUNTIFS($C$6:$C$5000,$C18,$O$6:$O$5000,$O18,$B$6:$B$5000,$B18)>1,"MÜKERRER","OK"))))
A19: =IF($B19="","",ROW()-BaslangicSatir) | B19: 46173 | C19: AMR-001 | D19: GİDER | E19: AMORTİSMAN | F19: OFİS | G19: DESTEK GİDERİ | H19: - | J19: OPERASYON | K19: Demirbaş amortismanı | L19: 1 | M19: AY | N19: 3000 | O19: 3000 | P19: HARİÇ | Q19: 46173 | S19: HAYIR | T19: SABİT | U19: DOLAYLI | V19: TEKRARLAYAN | W19: HAYIR | X19: HAYIR | Y19: HAYIR | Z19: =IF($B19="",0,IF($S19="EVET",IF($D19="GELİR",$O19,-$O19),0)) | AA19: =IF($B19="",0,IF(OR($W19="EVET",$X19="EVET",$Y19="EVET"),0,IF($D19="GELİR",IF($E19="SATIŞ İADESİ/İSKONTO",-$O19,$O19),-$O19))) | AB19: =IF($B19="","",IF(OR($D19="",$E19="",$O19=""),"EKSİK",IF($O19<=0,"SIFIR/NEGATİF",IF(COUNTIFS($C$6:$C$5000,$C19,$O$6:$O$5000,$O19,$B$6:$B$5000,$B19)>1,"MÜKERRER","OK"))))
A20: =IF($B20="","",ROW()-BaslangicSatir) | B20: 46173 | C20: VRG-001 | D20: GİDER | E20: VERGİ | F20: SİGORTA | G20: YASAL YÜKÜMLÜLÜK | H20: Vergi Dairesi | J20: OPERASYON | K20: Muhtasar/KDV vergisi | L20: 1 | M20: AY | N20: 4000 | O20: 4000 | P20: DAHİL | Q20: 46173 | R20: 46203 | S20: HAYIR | T20: SABİT | U20: DOLAYLI | V20: TEKRARLAYAN | W20: HAYIR | X20: HAYIR | Y20: HAYIR | Z20: =IF($B20="",0,IF($S20="EVET",IF($D20="GELİR",$O20,-$O20),0)) | AA20: =IF($B20="",0,IF(OR($W20="EVET",$X20="EVET",$Y20="EVET"),0,IF($D20="GELİR",IF($E20="SATIŞ İADESİ/İSKONTO",-$O20,$O20),-$O20))) | AB20: =IF($B20="","",IF(OR($D20="",$E20="",$O20=""),"EKSİK",IF($O20<=0,"SIFIR/NEGATİF",IF(COUNTIFS($C$6:$C$5000,$C20,$O$6:$O$5000,$O20,$B$6:$B$5000,$B20)>1,"MÜKERRER","OK"))))
A21: =IF($B21="","",ROW()-BaslangicSatir) | B21: 46175 | C21: SAT-005 | D21: GELİR | E21: SATIŞ | F21: TİCARİ MAL | G21: TEMEL GIDA | H21: Yıldız Market | I21: Ayçiçek Yağı 5L | J21: BÖLGESEL SATIŞ | K21: Toptan satış | L21: 600 | M21: ADET | N21: 150 | O21: 90000 | P21: HARİÇ | Q21: 46175 | R21: 46218 | S21: HAYIR | T21: DEĞİŞKEN | U21: DOĞRUDAN | V21: TEKRARLAYAN | W21: HAYIR | X21: HAYIR | Y21: HAYIR | Z21: =IF($B21="",0,IF($S21="EVET",IF($D21="GELİR",$O21,-$O21),0)) | AA21: =IF($B21="",0,IF(OR($W21="EVET",$X21="EVET",$Y21="EVET"),0,IF($D21="GELİR",IF($E21="SATIŞ İADESİ/İSKONTO",-$O21,$O21),-$O21))) | AB21: =IF($B21="","",IF(OR($D21="",$E21="",$O21=""),"EKSİK",IF($O21<=0,"SIFIR/NEGATİF",IF(COUNTIFS($C$6:$C$5000,$C21,$O$6:$O$5000,$O21,$B$6:$B$5000,$B21)>1,"MÜKERRER","OK"))))
A22: =IF($B22="","",ROW()-BaslangicSatir) | B22: 46178 | C22: AL-004 | D22: GİDER | E22: SATIŞLARIN MALİYETİ | F22: HAMMADDE | G22: HUBUBAT | H22: Tarım Ürünleri A.Ş. | I22: Ayçiçek Çekirdeği | J22: OPERASYON | K22: Hammadde alımı | L22: 1000 | M22: KG | N22: 50 | O22: 50000 | P22: HARİÇ | Q22: 46178 | R22: 46178 | S22: EVET | T22: DEĞİŞKEN | U22: DOĞRUDAN | V22: TEKRARLAYAN | W22: HAYIR | X22: HAYIR | Y22: HAYIR | Z22: =IF($B22="",0,IF($S22="EVET",IF($D22="GELİR",$O22,-$O22),0)) | AA22: =IF($B22="",0,IF(OR($W22="EVET",$X22="EVET",$Y22="EVET"),0,IF($D22="GELİR",IF($E22="SATIŞ İADESİ/İSKONTO",-$O22,$O22),-$O22))) | AB22: =IF($B22="","",IF(OR($D22="",$E22="",$O22=""),"EKSİK",IF($O22<=0,"SIFIR/NEGATİF",IF(COUNTIFS($C$6:$C$5000,$C22,$O$6:$O$5000,$O22,$B$6:$B$5000,$B22)>1,"MÜKERRER","OK"))))
A23: =IF($B23="","",ROW()-BaslangicSatir) | B23: 46178 | C23: KIR-002 | D23: GİDER | E23: KİRA | F23: OFİS | G23: DESTEK GİDERİ | H23: Depo Sahibi | J23: OPERASYON | K23: Depo ve ofis kirası | L23: 1 | M23: AY | N23: 25000 | O23: 25000 | P23: DAHİL | Q23: 46178 | R23: 46178 | S23: EVET | T23: SABİT | U23: DOLAYLI | V23: TEKRARLAYAN | W23: HAYIR | X23: HAYIR | Y23: HAYIR | Z23: =IF($B23="",0,IF($S23="EVET",IF($D23="GELİR",$O23,-$O23),0)) | AA23: =IF($B23="",0,IF(OR($W23="EVET",$X23="EVET",$Y23="EVET"),0,IF($D23="GELİR",IF($E23="SATIŞ İADESİ/İSKONTO",-$O23,$O23),-$O23))) | AB23: =IF($B23="","",IF(OR($D23="",$E23="",$O23=""),"EKSİK",IF($O23<=0,"SIFIR/NEGATİF",IF(COUNTIFS($C$6:$C$5000,$C23,$O$6:$O$5000,$O23,$B$6:$B$5000,$B23)>1,"MÜKERRER","OK"))))
A24: =IF($B24="","",ROW()-BaslangicSatir) | B24: 46178 | C24: FIN-002 | D24: GİDER | E24: FİNANSMAN GİDERİ | F24: KOMİSYON | G24: BANKA HİZMETİ | H24: ABC Bankası | J24: OPERASYON | K24: Kredi faizi | L24: 1 | M24: AY | N24: 6000 | O24: 6000 | P24: DAHİL | Q24: 46178 | R24: 46178 | S24: EVET | T24: SABİT | U24: DOLAYLI | V24: TEKRARLAYAN | W24: HAYIR | X24: HAYIR | Y24: HAYIR | Z24: =IF($B24="",0,IF($S24="EVET",IF($D24="GELİR",$O24,-$O24),0)) | AA24: =IF($B24="",0,IF(OR($W24="EVET",$X24="EVET",$Y24="EVET"),0,IF($D24="GELİR",IF($E24="SATIŞ İADESİ/İSKONTO",-$O24,$O24),-$O24))) | AB24: =IF($B24="","",IF(OR($D24="",$E24="",$O24=""),"EKSİK",IF($O24<=0,"SIFIR/NEGATİF",IF(COUNTIFS($C$6:$C$5000,$C24,$O$6:$O$5000,$O24,$B$6:$B$5000,$B24)>1,"MÜKERRER","OK"))))
A25: =IF($B25="","",ROW()-BaslangicSatir) | B25: 46181 | C25: SAT-006 | D25: GELİR | E25: SATIŞ | F25: TİCARİ MAL | G25: TEMEL GIDA | H25: Can Bakkaliye | I25: Bulgur 50kg | J25: BÖLGESEL SATIŞ | K25: Toptan satış | L25: 700 | M25: ADET | N25: 100 | O25: 70000 | P25: HARİÇ | Q25: 46181 | R25: 46193 | S25: EVET | T25: DEĞİŞKEN | U25: DOĞRUDAN | V25: TEKRARLAYAN | W25: HAYIR | X25: HAYIR | Y25: HAYIR | Z25: =IF($B25="",0,IF($S25="EVET",IF($D25="GELİR",$O25,-$O25),0)) | AA25: =IF($B25="",0,IF(OR($W25="EVET",$X25="EVET",$Y25="EVET"),0,IF($D25="GELİR",IF($E25="SATIŞ İADESİ/İSKONTO",-$O25,$O25),-$O25))) | AB25: =IF($B25="","",IF(OR($D25="",$E25="",$O25=""),"EKSİK",IF($O25<=0,"SIFIR/NEGATİF",IF(COUNTIFS($C$6:$C$5000,$C25,$O$6:$O$5000,$O25,$B$6:$B$5000,$B25)>1,"MÜKERRER","OK"))))
A26: =IF($B26="","",ROW()-BaslangicSatir) | B26: 46185 | C26: AL-005 | D26: GİDER | E26: SATIŞLARIN MALİYETİ | F26: HAMMADDE | G26: HUBUBAT | H26: Tarım Ürünleri A.Ş. | I26: Bulgur Buğdayı | J26: OPERASYON | K26: Hammadde alımı | L26: 2400 | M26: KG | N26: 25 | O26: 60000 | P26: HARİÇ | Q26: 46185 | R26: 46218 | S26: HAYIR | T26: DEĞİŞKEN | U26: DOĞRUDAN | V26: TEKRARLAYAN | W26: HAYIR | X26: HAYIR | Y26: HAYIR | Z26: =IF($B26="",0,IF($S26="EVET",IF($D26="GELİR",$O26,-$O26),0)) | AA26: =IF($B26="",0,IF(OR($W26="EVET",$X26="EVET",$Y26="EVET"),0,IF($D26="GELİR",IF($E26="SATIŞ İADESİ/İSKONTO",-$O26,$O26),-$O26))) | AB26: =IF($B26="","",IF(OR($D26="",$E26="",$O26=""),"EKSİK",IF($O26<=0,"SIFIR/NEGATİF",IF(COUNTIFS($C$6:$C$5000,$C26,$O$6:$O$5000,$O26,$B$6:$B$5000,$B26)>1,"MÜKERRER","OK"))))
A27: =IF($B27="","",ROW()-BaslangicSatir) | B27: 46188 | C27: SAT-007 | D27: GELİR | E27: SATIŞ | F27: TİCARİ MAL | G27: TEMEL GIDA | H27: Mega Market | I27: Un 25kg | J27: BÖLGESEL SATIŞ | K27: Toptan satış | L27: 1100 | M27: ADET | N27: 100 | O27: 110000 | P27: HARİÇ | Q27: 46188 | R27: 46233 | S27: HAYIR | T27: DEĞİŞKEN | U27: DOĞRUDAN | V27: TEKRARLAYAN | W27: HAYIR | X27: HAYIR | Y27: HAYIR | Z27: =IF($B27="",0,IF($S27="EVET",IF($D27="GELİR",$O27,-$O27),0)) | AA27: =IF($B27="",0,IF(OR($W27="EVET",$X27="EVET",$Y27="EVET"),0,IF($D27="GELİR",IF($E27="SATIŞ İADESİ/İSKONTO",-$O27,$O27),-$O27))) | AB27: =IF($B27="","",IF(OR($D27="",$E27="",$O27=""),"EKSİK",IF($O27<=0,"SIFIR/NEGATİF",IF(COUNTIFS($C$6:$C$5000,$C27,$O$6:$O$5000,$O27,$B$6:$B$5000,$B27)>1,"MÜKERRER","OK"))))
A28: =IF($B28="","",ROW()-BaslangicSatir) | B28: 46191 | C28: PAZ-002 | D28: GİDER | E28: PAZARLAMA | F28: REKLAM | G28: DİJİTAL PAZARLAMA | H28: Medya Ajans | J28: OPERASYON | K28: Sosyal medya reklamı | L28: 1 | M28: AY | N28: 12000 | O28: 12000 | P28: DAHİL | Q28: 46191 | R28: 46223 | S28: HAYIR | T28: SABİT | U28: DOLAYLI | V28: TEKRARLAYAN | W28: HAYIR | X28: HAYIR | Y28: HAYIR | Z28: =IF($B28="",0,IF($S28="EVET",IF($D28="GELİR",$O28,-$O28),0)) | AA28: =IF($B28="",0,IF(OR($W28="EVET",$X28="EVET",$Y28="EVET"),0,IF($D28="GELİR",IF($E28="SATIŞ İADESİ/İSKONTO",-$O28,$O28),-$O28))) | AB28: =IF($B28="","",IF(OR($D28="",$E28="",$O28=""),"EKSİK",IF($O28<=0,"SIFIR/NEGATİF",IF(COUNTIFS($C$6:$C$5000,$C28,$O$6:$O$5000,$O28,$B$6:$B$5000,$B28)>1,"MÜKERRER","OK"))))
A29: =IF($B29="","",ROW()-BaslangicSatir) | B29: 46193 | C29: AL-006 | D29: GİDER | E29: SATIŞLARIN MALİYETİ | F29: HAMMADDE | G29: HUBUBAT | H29: Tarım Ürünleri A.Ş. | I29: Mercimek | J29: OPERASYON | K29: Hammadde alımı | L29: 1100 | M29: KG | N29: 50 | O29: 55000 | P29: HARİÇ | Q29: 46193 | R29: 46193 | S29: EVET | T29: DEĞİŞKEN | U29: DOĞRUDAN | V29: TEKRARLAYAN | W29: HAYIR | X29: HAYIR | Y29: HAYIR | Z29: =IF($B29="",0,IF($S29="EVET",IF($D29="GELİR",$O29,-$O29),0)) | AA29: =IF($B29="",0,IF(OR($W29="EVET",$X29="EVET",$Y29="EVET"),0,IF($D29="GELİR",IF($E29="SATIŞ İADESİ/İSKONTO",-$O29,$O29),-$O29))) | AB29: =IF($B29="","",IF(OR($D29="",$E29="",$O29=""),"EKSİK",IF($O29<=0,"SIFIR/NEGATİF",IF(COUNTIFS($C$6:$C$5000,$C29,$O$6:$O$5000,$O29,$B$6:$B$5000,$B29)>1,"MÜKERRER","OK"))))
A30: =IF($B30="","",ROW()-BaslangicSatir) | B30: 46193 | C30: KMS-001 | D30: GİDER | E30: DEĞİŞKEN GİDER | F30: KOMİSYON | G30: BANKA HİZMETİ | H30: Satış Danışman | J30: OPERASYON | K30: Satış komisyonu | L30: 1 | M30: AY | N30: 16000 | O30: 16000 | P30: DAHİL | Q30: 46193 | R30: 46228 | S30: HAYIR | T30: DEĞİŞKEN | U30: DOLAYLI | V30: TEKRARLAYAN | W30: HAYIR | X30: HAYIR | Y30: HAYIR | Z30: =IF($B30="",0,IF($S30="EVET",IF($D30="GELİR",$O30,-$O30),0)) | AA30: =IF($B30="",0,IF(OR($W30="EVET",$X30="EVET",$Y30="EVET"),0,IF($D30="GELİR",IF($E30="SATIŞ İADESİ/İSKONTO",-$O30,$O30),-$O30))) | AB30: =IF($B30="","",IF(OR($D30="",$E30="",$O30=""),"EKSİK",IF($O30<=0,"SIFIR/NEGATİF",IF(COUNTIFS($C$6:$C$5000,$C30,$O$6:$O$5000,$O30,$B$6:$B$5000,$B30)>1,"MÜKERRER","OK"))))
A31: =IF($B31="","",ROW()-BaslangicSatir) | B31: 46195 | C31: SAT-008 | D31: GELİR | E31: SATIŞ | F31: TİCARİ MAL | G31: TEMEL GIDA | H31: Süpermarket Zinciri | I31: Mercimek | J31: BÖLGESEL SATIŞ | K31: Toptan satış | L31: 1100 | M31: ADET | N31: 50 | O31: 55000 | P31: HARİÇ | Q31: 46195 | R31: 46201 | S31: EVET | T31: DEĞİŞKEN | U31: DOĞRUDAN | V31: TEKRARLAYAN | W31: HAYIR | X31: HAYIR | Y31: HAYIR | Z31: =IF($B31="",0,IF($S31="EVET",IF($D31="GELİR",$O31,-$O31),0)) | AA31: =IF($B31="",0,IF(OR($W31="EVET",$X31="EVET",$Y31="EVET"),0,IF($D31="GELİR",IF($E31="SATIŞ İADESİ/İSKONTO",-$O31,$O31),-$O31))) | AB31: =IF($B31="","",IF(OR($D31="",$E31="",$O31=""),"EKSİK",IF($O31<=0,"SIFIR/NEGATİF",IF(COUNTIFS($C$6:$C$5000,$C31,$O$6:$O$5000,$O31,$B$6:$B$5000,$B31)>1,"MÜKERRER","OK"))))
A32: =IF($B32="","",ROW()-BaslangicSatir) | B32: 46198 | C32: PER-002 | D32: GİDER | E32: PERSONEL | F32: İKRAMİYE | G32: MAAŞ YAN ÖDEMESİ | H32: Personel | J32: OPERASYON | K32: Maaş ödemesi | L32: 6 | M32: AY | N32: 9167 | O32: 55000 | P32: DAHİL | Q32: 46198 | R32: 46198 | S32: EVET | T32: SABİT | U32: DOLAYLI | V32: TEKRARLAYAN | W32: HAYIR | X32: HAYIR | Y32: HAYIR | Z32: =IF($B32="",0,IF($S32="EVET",IF($D32="GELİR",$O32,-$O32),0)) | AA32: =IF($B32="",0,IF(OR($W32="EVET",$X32="EVET",$Y32="EVET"),0,IF($D32="GELİR",IF($E32="SATIŞ İADESİ/İSKONTO",-$O32,$O32),-$O32))) | AB32: =IF($B32="","",IF(OR($D32="",$E32="",$O32=""),"EKSİK",IF($O32<=0,"SIFIR/NEGATİF",IF(COUNTIFS($C$6:$C$5000,$C32,$O$6:$O$5000,$O32,$B$6:$B$5000,$B32)>1,"MÜKERRER","OK"))))
A33: =IF($B33="","",ROW()-BaslangicSatir) | B33: 46201 | C33: SAT-009 | D33: GELİR | E33: SATIŞ | F33: TİCARİ MAL | G33: TEMEL GIDA | H33: Yıldız Market | I33: Ayçiçek Yağı 5L | J33: BÖLGESEL SATIŞ | K33: Toptan satış | L33: 250 | M33: ADET | N33: 100 | O33: 25000 | P33: HARİÇ | Q33: 46201 | R33: 46239 | S33: HAYIR | T33: DEĞİŞKEN | U33: DOĞRUDAN | V33: TEKRARLAYAN | W33: HAYIR | X33: HAYIR | Y33: HAYIR | Z33: =IF($B33="",0,IF($S33="EVET",IF($D33="GELİR",$O33,-$O33),0)) | AA33: =IF($B33="",0,IF(OR($W33="EVET",$X33="EVET",$Y33="EVET"),0,IF($D33="GELİR",IF($E33="SATIŞ İADESİ/İSKONTO",-$O33,$O33),-$O33))) | AB33: =IF($B33="","",IF(OR($D33="",$E33="",$O33=""),"EKSİK",IF($O33<=0,"SIFIR/NEGATİF",IF(COUNTIFS($C$6:$C$5000,$C33,$O$6:$O$5000,$O33,$B$6:$B$5000,$B33)>1,"MÜKERRER","OK"))))
A34: =IF($B34="","",ROW()-BaslangicSatir) | B34: 46203 | C34: VRG-002 | D34: GİDER | E34: VERGİ | F34: SİGORTA | G34: YASAL YÜKÜMLÜLÜK | H34: Vergi Dairesi | J34: OPERASYON | K34: Muhtasar/KDV vergisi | L34: 1 | M34: AY | N34: 4000 | O34: 4000 | P34: DAHİL | Q34: 46203 | R34: 46203 | S34: EVET | T34: SABİT | U34: DOLAYLI | V34: TEKRARLAYAN | W34: HAYIR | X34: HAYIR | Y34: HAYIR | Z34: =IF($B34="",0,IF($S34="EVET",IF($D34="GELİR",$O34,-$O34),0)) | AA34: =IF($B34="",0,IF(OR($W34="EVET",$X34="EVET",$Y34="EVET"),0,IF($D34="GELİR",IF($E34="SATIŞ İADESİ/İSKONTO",-$O34,$O34),-$O34))) | AB34: =IF($B34="","",IF(OR($D34="",$E34="",$O34=""),"EKSİK",IF($O34<=0,"SIFIR/NEGATİF",IF(COUNTIFS($C$6:$C$5000,$C34,$O$6:$O$5000,$O34,$B$6:$B$5000,$B34)>1,"MÜKERRER","OK"))))
A35: =IF($B35="","",ROW()-BaslangicSatir) | B35: 46203 | C35: AMR-002 | D35: GİDER | E35: AMORTİSMAN | F35: OFİS | G35: DESTEK GİDERİ | H35: - | J35: OPERASYON | K35: Demirbaş amortismanı | L35: 1 | M35: AY | N35: 3000 | O35: 3000 | P35: HARİÇ | Q35: 46203 | S35: HAYIR | T35: SABİT | U35: DOLAYLI | V35: TEKRARLAYAN | W35: HAYIR | X35: HAYIR | Y35: HAYIR | Z35: =IF($B35="",0,IF($S35="EVET",IF($D35="GELİR",$O35,-$O35),0)) | AA35: =IF($B35="",0,IF(OR($W35="EVET",$X35="EVET",$Y35="EVET"),0,IF($D35="GELİR",IF($E35="SATIŞ İADESİ/İSKONTO",-$O35,$O35),-$O35))) | AB35: =IF($B35="","",IF(OR($D35="",$E35="",$O35=""),"EKSİK",IF($O35<=0,"SIFIR/NEGATİF",IF(COUNTIFS($C$6:$C$5000,$C35,$O$6:$O$5000,$O35,$B$6:$B$5000,$B35)>1,"MÜKERRER","OK"))))
A36: =IF($B36="","",ROW()-BaslangicSatir) | B36: 46203 | C36: GY-002 | D36: GİDER | E36: GENEL YÖNETİM | F36: ELEKTRİK | G36: ENERJİ | H36: Elektrik Dağıtım | J36: OPERASYON | K36: Elektrik faturası | L36: 1 | M36: AY | N36: 10000 | O36: 10000 | P36: DAHİL | Q36: 46203 | R36: 46203 | S36: EVET | T36: SABİT | U36: DOLAYLI | V36: TEKRARLAYAN | W36: HAYIR | X36: HAYIR | Y36: HAYIR | Z36: =IF($B36="",0,IF($S36="EVET",IF($D36="GELİR",$O36,-$O36),0)) | AA36: =IF($B36="",0,IF(OR($W36="EVET",$X36="EVET",$Y36="EVET"),0,IF($D36="GELİR",IF($E36="SATIŞ İADESİ/İSKONTO",-$O36,$O36),-$O36))) | AB36: =IF($B36="","",IF(OR($D36="",$E36="",$O36=""),"EKSİK",IF($O36<=0,"SIFIR/NEGATİF",IF(COUNTIFS($C$6:$C$5000,$C36,$O$6:$O$5000,$O36,$B$6:$B$5000,$B36)>1,"MÜKERRER","OK"))))
A37: =IF($B37="","",ROW()-BaslangicSatir) | B37: 46206 | C37: SAT-010 | D37: GELİR | E37: SATIŞ | F37: TİCARİ MAL | G37: TEMEL GIDA | H37: Can Bakkaliye | I37: Bulgur 50kg | J37: BÖLGESEL SATIŞ | K37: Toptan satış | L37: 800 | M37: ADET | N37: 100 | O37: 80000 | P37: HARİÇ | Q37: 46206 | R37: 46223 | S37: EVET | T37: DEĞİŞKEN | U37: DOĞRUDAN | V37: TEKRARLAYAN | W37: HAYIR | X37: HAYIR | Y37: HAYIR | Z37: =IF($B37="",0,IF($S37="EVET",IF($D37="GELİR",$O37,-$O37),0)) | AA37: =IF($B37="",0,IF(OR($W37="EVET",$X37="EVET",$Y37="EVET"),0,IF($D37="GELİR",IF($E37="SATIŞ İADESİ/İSKONTO",-$O37,$O37),-$O37))) | AB37: =IF($B37="","",IF(OR($D37="",$E37="",$O37=""),"EKSİK",IF($O37<=0,"SIFIR/NEGATİF",IF(COUNTIFS($C$6:$C$5000,$C37,$O$6:$O$5000,$O37,$B$6:$B$5000,$B37)>1,"MÜKERRER","OK"))))
A38: =IF($B38="","",ROW()-BaslangicSatir) | B38: 46208 | C38: KIR-003 | D38: GİDER | E38: KİRA | F38: OFİS | G38: DESTEK GİDERİ | H38: Depo Sahibi | J38: OPERASYON | K38: Depo ve ofis kirası | L38: 1 | M38: AY | N38: 25000 | O38: 25000 | P38: DAHİL | Q38: 46208 | R38: 46208 | S38: EVET | T38: SABİT | U38: DOLAYLI | V38: TEKRARLAYAN | W38: HAYIR | X38: HAYIR | Y38: HAYIR | Z38: =IF($B38="",0,IF($S38="EVET",IF($D38="GELİR",$O38,-$O38),0)) | AA38: =IF($B38="",0,IF(OR($W38="EVET",$X38="EVET",$Y38="EVET"),0,IF($D38="GELİR",IF($E38="SATIŞ İADESİ/İSKONTO",-$O38,$O38),-$O38))) | AB38: =IF($B38="","",IF(OR($D38="",$E38="",$O38=""),"EKSİK",IF($O38<=0,"SIFIR/NEGATİF",IF(COUNTIFS($C$6:$C$5000,$C38,$O$6:$O$5000,$O38,$B$6:$B$5000,$B38)>1,"MÜKERRER","OK"))))
A39: =IF($B39="","",ROW()-BaslangicSatir) | B39: 46208 | C39: FIN-003 | D39: GİDER | E39: FİNANSMAN GİDERİ | F39: KOMİSYON | G39: BANKA HİZMETİ | H39: ABC Bankası | J39: OPERASYON | K39: Kredi faizi | L39: 1 | M39: AY | N39: 6000 | O39: 6000 | P39: DAHİL | Q39: 46208 | R39: 46208 | S39: EVET | T39: SABİT | U39: DOLAYLI | V39: TEKRARLAYAN | W39: HAYIR | X39: HAYIR | Y39: HAYIR | Z39: =IF($B39="",0,IF($S39="EVET",IF($D39="GELİR",$O39,-$O39),0)) | AA39: =IF($B39="",0,IF(OR($W39="EVET",$X39="EVET",$Y39="EVET"),0,IF($D39="GELİR",IF($E39="SATIŞ İADESİ/İSKONTO",-$O39,$O39),-$O39))) | AB39: =IF($B39="","",IF(OR($D39="",$E39="",$O39=""),"EKSİK",IF($O39<=0,"SIFIR/NEGATİF",IF(COUNTIFS($C$6:$C$5000,$C39,$O$6:$O$5000,$O39,$B$6:$B$5000,$B39)>1,"MÜKERRER","OK"))))
A40: =IF($B40="","",ROW()-BaslangicSatir) | B40: 46208 | C40: YAT-001 | D40: GİDER | E40: YATIRIM | F40: OFİS | G40: DESTEK GİDERİ | H40: Makine Firması | I40: Forklift | J40: YATIRIM PROGRAMI | K40: Forklift yatırımı | L40: 1 | M40: ADET | N40: 60000 | O40: 60000 | P40: DAHİL | Q40: 46208 | R40: 46208 | S40: EVET | T40: SABİT | U40: DOLAYLI | V40: TEK SEFERLİK | W40: HAYIR | X40: HAYIR | Y40: EVET | Z40: =IF($B40="",0,IF($S40="EVET",IF($D40="GELİR",$O40,-$O40),0)) | AA40: =IF($B40="",0,IF(OR($W40="EVET",$X40="EVET",$Y40="EVET"),0,IF($D40="GELİR",IF($E40="SATIŞ İADESİ/İSKONTO",-$O40,$O40),-$O40))) | AB40: =IF($B40="","",IF(OR($D40="",$E40="",$O40=""),"EKSİK",IF($O40<=0,"SIFIR/NEGATİF",IF(COUNTIFS($C$6:$C$5000,$C40,$O$6:$O$5000,$O40,$B$6:$B$5000,$B40)>1,"MÜKERRER","OK"))))
A41: =IF($B41="","",ROW()-BaslangicSatir) | B41: 46210 | C41: AL-007 | D41: GİDER | E41: SATIŞLARIN MALİYETİ | F41: HAMMADDE | G41: HUBUBAT | H41: Tarım Ürünleri A.Ş. | I41: Ayçiçek Çekirdeği | J41: OPERASYON | K41: Hammadde alımı | L41: 1400 | M41: KG | N41: 50 | O41: 70000 | P41: HARİÇ | Q41: 46210 | R41: 46210 | S41: EVET | T41: DEĞİŞKEN | U41: DOĞRUDAN | V41: TEKRARLAYAN | W41: HAYIR | X41: HAYIR | Y41: HAYIR | Z41: =IF($B41="",0,IF($S41="EVET",IF($D41="GELİR",$O41,-$O41),0)) | AA41: =IF($B41="",0,IF(OR($W41="EVET",$X41="EVET",$Y41="EVET"),0,IF($D41="GELİR",IF($E41="SATIŞ İADESİ/İSKONTO",-$O41,$O41),-$O41))) | AB41: =IF($B41="","",IF(OR($D41="",$E41="",$O41=""),"EKSİK",IF($O41<=0,"SIFIR/NEGATİF",IF(COUNTIFS($C$6:$C$5000,$C41,$O$6:$O$5000,$O41,$B$6:$B$5000,$B41)>1,"MÜKERRER","OK"))))
A42: =IF($B42="","",ROW()-BaslangicSatir) | B42: 46211 | C42: KRD-001 | D42: GİDER | E42: KREDİ ANAPARA | F42: KOMİSYON | G42: BANKA HİZMETİ | H42: ABC Bankası | J42: KREDİ YAPISI | K42: Kredi anapara ödemesi | L42: 1 | M42: AY | N42: 50000 | O42: 50000 | P42: DAHİL | Q42: 46211 | R42: 46211 | S42: EVET | T42: SABİT | U42: DOLAYLI | V42: TEKRARLAYAN | W42: HAYIR | X42: EVET | Y42: HAYIR | Z42: =IF($B42="",0,IF($S42="EVET",IF($D42="GELİR",$O42,-$O42),0)) | AA42: =IF($B42="",0,IF(OR($W42="EVET",$X42="EVET",$Y42="EVET"),0,IF($D42="GELİR",IF($E42="SATIŞ İADESİ/İSKONTO",-$O42,$O42),-$O42))) | AB42: =IF($B42="","",IF(OR($D42="",$E42="",$O42=""),"EKSİK",IF($O42<=0,"SIFIR/NEGATİF",IF(COUNTIFS($C$6:$C$5000,$C42,$O$6:$O$5000,$O42,$B$6:$B$5000,$B42)>1,"MÜKERRER","OK"))))
...

Sheet SATIS_MALIYET
A1: SATIS MALIYET — GÜNLÜK GELİR–GİDER VE GERÇEK KÂRLILIK SİSTEMİ
A2: Ürün/hizmet bazında satış ve maliyet bilgisi girin. Brüt Kâr ve Brüt Marj otomatik hesaplanır; PANO ürün/proje marjı grafiğini buradan besler.
A5: Ürün/Hizmet | B5: Kategori | C5: Satış Adedi | D5: Birim Fiyat | E5: Satış Tutarı | F5: Birim Maliyet | G5: Maliyet Tutarı | H5: Brüt Kâr | I5: Brüt Marj
A6: Ayçiçek Yağı 5L | B6: TİCARİ MAL | C6: 2250 | D6: 150 | E6: =IF($A6="","",$C6*$D6) | F6: 100 | G6: =IF($A6="","",$C6*$F6) | H6: =IF($A6="","",$E6-$G6) | I6: =IF($A6="","",IF($E6=0,"",$H6/$E6))
A7: Bulgur 50kg | B7: TİCARİ MAL | C7: 1900 | D7: 100 | E7: =IF($A7="","",$C7*$D7) | F7: 65 | G7: =IF($A7="","",$C7*$F7) | H7: =IF($A7="","",$E7-$G7) | I7: =IF($A7="","",IF($E7=0,"",$H7/$E7))
A8: Un 25kg | B8: TİCARİ MAL | C8: 2900 | D8: 100 | E8: =IF($A8="","",$C8*$D8) | F8: 70 | G8: =IF($A8="","",$C8*$F8) | H8: =IF($A8="","",$E8-$G8) | I8: =IF($A8="","",IF($E8=0,"",$H8/$E8))
A9: Mercimek | B9: TİCARİ MAL | C9: 2700 | D9: 50 | E9: =IF($A9="","",$C9*$D9) | F9: 32 | G9: =IF($A9="","",$C9*$F9) | H9: =IF($A9="","",$E9-$G9) | I9: =IF($A9="","",IF($E9=0,"",$H9/$E9))
E10: =IF($A10="","",$C10*$D10) | G10: =IF($A10="","",$C10*$F10) | H10: =IF($A10="","",$E10-$G10) | I10: =IF($A10="","",IF($E10=0,"",$H10/$E10))
E11: =IF($A11="","",$C11*$D11) | G11: =IF($A11="","",$C11*$F11) | H11: =IF($A11="","",$E11-$G11) | I11: =IF($A11="","",IF($E11=0,"",$H11/$E11))
E12: =IF($A12="","",$C12*$D12) | G12: =IF($A12="","",$C12*$F12) | H12: =IF($A12="","",$E12-$G12) | I12: =IF($A12="","",IF($E12=0,"",$H12/$E12))
E13: =IF($A13="","",$C13*$D13) | G13: =IF($A13="","",$C13*$F13) | H13: =IF($A13="","",$E13-$G13) | I13: =IF($A13="","",IF($E13=0,"",$H13/$E13))
E14: =IF($A14="","",$C14*$D14) | G14: =IF($A14="","",$C14*$F14) | H14: =IF($A14="","",$E14-$G14) | I14: =IF($A14="","",IF($E14=0,"",$H14/$E14))
E15: =IF($A15="","",$C15*$D15) | G15: =IF($A15="","",$C15*$F15) | H15: =IF($A15="","",$E15-$G15) | I15: =IF($A15="","",IF($E15=0,"",$H15/$E15))
E16: =IF($A16="","",$C16*$D16) | G16: =IF($A16="","",$C16*$F16) | H16: =IF($A16="","",$E16-$G16) | I16: =IF($A16="","",IF($E16=0,"",$H16/$E16))
E17: =IF($A17="","",$C17*$D17) | G17: =IF($A17="","",$C17*$F17) | H17: =IF($A17="","",$E17-$G17) | I17: =IF($A17="","",IF($E17=0,"",$H17/$E17))
E18: =IF($A18="","",$C18*$D18) | G18: =IF($A18="","",$C18*$F18) | H18: =IF($A18="","",$E18-$G18) | I18: =IF($A18="","",IF($E18=0,"",$H18/$E18))
E19: =IF($A19="","",$C19*$D19) | G19: =IF($A19="","",$C19*$F19) | H19: =IF($A19="","",$E19-$G19) | I19: =IF($A19="","",IF($E19=0,"",$H19/$E19))
E20: =IF($A20="","",$C20*$D20) | G20: =IF($A20="","",$C20*$F20) | H20: =IF($A20="","",$E20-$G20) | I20: =IF($A20="","",IF($E20=0,"",$H20/$E20))
E21: =IF($A21="","",$C21*$D21) | G21: =IF($A21="","",$C21*$F21) | H21: =IF($A21="","",$E21-$G21) | I21: =IF($A21="","",IF($E21=0,"",$H21/$E21))
... E200: =IF($A200="","",$C200*$D200) | G200: =IF($A200="","",$C200*$F200) | H200: =IF($A200="","",$E200-$G200) | I200: =IF($A200="","",IF($E200=0,"",$H200/$E200))

Sheet TAHAKKUK_NAKIT_ESLEME
A1: TAHAKKUK NAKIT ESLEME — GÜNLÜK GELİR–GİDER VE GERÇEK KÂRLILIK SİSTEMİ
A2: Muhasebe kârından gerçek nakit değişimine geçiş köprüsü. Her satırın tanımı ve veri kaynağı sağda görünür.
A4: GERÇEK KÂRLILIK KÖPRÜSÜ
A5: Açıklama | B5: Tutar (₺) | C5: Tanım | D5: Veri Kaynağı
A6: Muhasebe Net Sonucu | B6: =SUM(GELIR_GIDER_KAYIT!$AA$6:$AA$5000) | C6: Kârlılık Etkisi toplamı (tüm gelir - tüm kâr etkili gider) | D6: GELIR_GIDER_KAYIT!Kârlılık Etkisi
A7: + Amortisman | B7: =-SUMIFS(GELIR_GIDER_KAYIT!$AA$6:$AA$5000,GELIR_GIDER_KAYIT!$E$6:$E$5000,"AMORTİSMAN") | C7: Nakit etkisiz gider; kâra yazıldığı için geri eklenir | D7: Ana Sınıf = AMORTİSMAN
A8: - Tahsil Edilmemiş Satış Artışı | B8: =SUMIFS(GELIR_GIDER_KAYIT!$O$6:$O$5000,GELIR_GIDER_KAYIT!$D$6:$D$5000,"GELİR",GELIR_GIDER_KAYIT!$S$6:$S$5000,"HAYIR") | C8: Satışa yazıldı ama nakit tahsil edilmedi | D8: İşlem Türü=GELİR ve Nakit Gerçekleşti=HAYIR
A9: + Ödenmemiş Gider Artışı | B9: =SUMIFS(GELIR_GIDER_KAYIT!$O$6:$O$5000,GELIR_GIDER_KAYIT!$D$6:$D$5000,"GİDER",GELIR_GIDER_KAYIT!$S$6:$S$5000,"HAYIR",GELIR_GIDER_KAYIT!$E$6:$E$5000,"<>AMORTİSMAN") | C9: Gidere yazıldı ama henüz ödenmedi; nakit çıkışı olmadı | D9: İşlem Türü=GİDER, Nakit=HAYIR, AMORTİSMAN hariç
A10: - Stok Artışı | B10: =IF(KayitSayisi=0,"VERİ YOK",MAX(0,DonemSonuStok-DonemBasiStok)) | C10: Stoka bağlanan nakit kâr değildir | D10: AYARLAR!Dönem Başı/Sonu Stok
A11: - Kredi Anapara Ödemesi | B11: =SUMIFS(GELIR_GIDER_KAYIT!$O$6:$O$5000,GELIR_GIDER_KAYIT!$E$6:$E$5000,"KREDİ ANAPARA") | C11: Anapara geri ödemesi kârı etkilemez, nakdi azaltır | D11: Ana Sınıf = KREDİ ANAPARA
A12: - Yatırım Harcaması | B12: =SUMIFS(GELIR_GIDER_KAYIT!$O$6:$O$5000,GELIR_GIDER_KAYIT!$E$6:$E$5000,"YATIRIM") | C12: Yatırım gideri gider değil, nakit çıkışıdır | D12: Ana Sınıf = YATIRIM
A13: - Ortak Çekişi | B13: =SUMIFS(GELIR_GIDER_KAYIT!$O$6:$O$5000,GELIR_GIDER_KAYIT!$E$6:$E$5000,"ORTAK ÇEKİŞİ") | C13: Ortaklara çıkan nakit kâr değildir | D13: Ana Sınıf = ORTAK ÇEKİŞİ
A14: Gerçek Net Nakit Değişimi | B14: =B6+B7-B8+B9-B10-B11-B12-B13 | C14: Dönem içinde fiilen oluşan nakit değişimi | D14: Köprü toplamı
A16: ÇAPRAZ KONTROL
A17: Nakit Etkisi toplamı (doğrudan) | B17: =SUM(GELIR_GIDER_KAYIT!$Z$6:$Z$5000)
A18: Köprü ile fark (₺) | B18: =ABS(B14-B17)
A19: Tolerans (₺) | B19: =IF(KayitSayisi=0,"VERİ YOK",YuvarlamaToleransi)
A20: Durum | B20: =IF(B18<=B19,"UYUMLU","KONTROL GEREKLİ")

Sheet GUNLUK_OZET
A1: GUNLUK OZET — GÜNLÜK GELİR–GİDER VE GERÇEK KÂRLILIK SİSTEMİ
A2: Son 41 günün nakit ve kârlılık akışı otomatik özetlenir. Açık sarı hücreye dönem başı nakit bakiyesi girin.
A3: Dönem Başı Nakit Bakiyesi (₺) | B3: 250000
A5: Tarih | B5: Nakit Girişi | C5: Nakit Çıkışı | D5: Net Nakit | E5: Kârlılık | F5: Kümülatif Nakit
A6: =IF(RaporDonemBaslangici="","",RaporDonemBaslangici) | B6: =IF($A6="","",SUMIFS(GELIR_GIDER_KAYIT!$Z$6:$Z$5000,GELIR_GIDER_KAYIT!$B$6:$B$5000,$A6,GELIR_GIDER_KAYIT!$Z$6:$Z$5000,">0")) | C6: =IF($A6="","",-SUMIFS(GELIR_GIDER_KAYIT!$Z$6:$Z$5000,GELIR_GIDER_KAYIT!$B$6:$B$5000,$A6,GELIR_GIDER_KAYIT!$Z$6:$Z$5000,"<0")) | D6: =IF($A6="","",B6-C6) | E6: =IF($A6="","",SUMIFS(GELIR_GIDER_KAYIT!$AA$6:$AA$5000,GELIR_GIDER_KAYIT!$B$6:$B$5000,$A6)) | F6: =IF($A6="","",$B$3+D6)
A7: =IF($A6="","",IF($A6+1>RaporTarihi,"",$A6+1)) | B7: =IF($A7="","",SUMIFS(GELIR_GIDER_KAYIT!$Z$6:$Z$5000,GELIR_GIDER_KAYIT!$B$6:$B$5000,$A7,GELIR_GIDER_KAYIT!$Z$6:$Z$5000,">0")) | C7: =IF($A7="","",-SUMIFS(GELIR_GIDER_KAYIT!$Z$6:$Z$5000,GELIR_GIDER_KAYIT!$B$6:$B$5000,$A7,GELIR_GIDER_KAYIT!$Z$6:$Z$5000,"<0")) | D7: =IF($A7="","",B7-C7) | E7: =IF($A7="","",SUMIFS(GELIR_GIDER_KAYIT!$AA$6:$AA$5000,GELIR_GIDER_KAYIT!$B$6:$B$5000,$A7)) | F7: =IF($A7="","",F6+D7)
A8: =IF($A7="","",IF($A7+1>RaporTarihi,"",$A7+1)) | B8: =IF($A8="","",SUMIFS(GELIR_GIDER_KAYIT!$Z$6:$Z$5000,GELIR_GIDER_KAYIT!$B$6:$B$5000,$A8,GELIR_GIDER_KAYIT!$Z$6:$Z$5000,">0")) | C8: =IF($A8="","",-SUMIFS(GELIR_GIDER_KAYIT!$Z$6:$Z$5000,GELIR_GIDER_KAYIT!$B$6:$B$5000,$A8,GELIR_GIDER_KAYIT!$Z$6:$Z$5000,"<0")) | D8: =IF($A8="","",B8-C8) | E8: =IF($A8="","",SUMIFS(GELIR_GIDER_KAYIT!$AA$6:$AA$5000,GELIR_GIDER_KAYIT!$B$6:$B$5000,$A8)) | F8: =IF($A8="","",F7+D8)
A9: =IF($A8="","",IF($A8+1>RaporTarihi,"",$A8+1)) | B9: =IF($A9="","",SUMIFS(GELIR_GIDER_KAYIT!$Z$6:$Z$5000,GELIR_GIDER_KAYIT!$B$6:$B$5000,$A9,GELIR_GIDER_KAYIT!$Z$6:$Z$5000,">0")) | C9: =IF($A9="","",-SUMIFS(GELIR_GIDER_KAYIT!$Z$6:$Z$5000,GELIR_GIDER_KAYIT!$B$6:$B$5000,$A9,GELIR_GIDER_KAYIT!$Z$6:$Z$5000,"<0")) | D9: =IF($A9="","",B9-C9) | E9: =IF($A9="","",SUMIFS(GELIR_GIDER_KAYIT!$AA$6:$AA$5000,GELIR_GIDER_KAYIT!$B$6:$B$5000,$A9)) | F9: =IF($A9="","",F8+D9)
A10: =IF($A9="","",IF($A9+1>RaporTarihi,"",$A9+1)) | B10: =IF($A10="","",SUMIFS(GELIR_GIDER_KAYIT!$Z$6:$Z$5000,GELIR_GIDER_KAYIT!$B$6:$B$5000,$A10,GELIR_GIDER_KAYIT!$Z$6:$Z$5000,">0")) | C10: =IF($A10="","",-SUMIFS(GELIR_GIDER_KAYIT!$Z$6:$Z$5000,GELIR_GIDER_KAYIT!$B$6:$B$5000,$A10,GELIR_GIDER_KAYIT!$Z$6:$Z$5000,"<0")) | D10: =IF($A10="","",B10-C10) | E10: =IF($A10="","",SUMIFS(GELIR_GIDER_KAYIT!$AA$6:$AA$5000,GELIR_GIDER_KAYIT!$B$6:$B$5000,$A10)) | F10: =IF($A10="","",F9+D10)
A11: =IF($A10="","",IF($A10+1>RaporTarihi,"",$A10+1)) | B11: =IF($A11="","",SUMIFS(GELIR_GIDER_KAYIT!$Z$6:$Z$5000,GELIR_GIDER_KAYIT!$B$6:$B$5000,$A11,GELIR_GIDER_KAYIT!$Z$6:$Z$5000,">0")) | C11: =IF($A11="","",-SUMIFS(GELIR_GIDER_KAYIT!$Z$6:$Z$5000,GELIR_GIDER_KAYIT!$B$6:$B$5000,$A11,GELIR_GIDER_KAYIT!$Z$6:$Z$5000,"<0")) | D11: =IF($A11="","",B11-C11) | E11: =IF($A11="","",SUMIFS(GELIR_GIDER_KAYIT!$AA$6:$AA$5000,GELIR_GIDER_KAYIT!$B$6:$B$5000,$A11)) | F11: =IF($A11="","",F10+D11)
A12: =IF($A11="","",IF($A11+1>RaporTarihi,"",$A11+1)) | B12: =IF($A12="","",SUMIFS(GELIR_GIDER_KAYIT!$Z$6:$Z$5000,GELIR_GIDER_KAYIT!$B$6:$B$5000,$A12,GELIR_GIDER_KAYIT!$Z$6:$Z$5000,">0")) | C12: =IF($A12="","",-SUMIFS(GELIR_GIDER_KAYIT!$Z$6:$Z$5000,GELIR_GIDER_KAYIT!$B$6:$B$5000,$A12,GELIR_GIDER_KAYIT!$Z$6:$Z$5000,"<0")) | D12: =IF($A12="","",B12-C12) | E12: =IF($A12="","",SUMIFS(GELIR_GIDER_KAYIT!$AA$6:$AA$5000,GELIR_GIDER_KAYIT!$B$6:$B$5000,$A12)) | F12: =IF($A12="","",F11+D12)
A13: =IF($A12="","",IF($A12+1>RaporTarihi,"",$A12+1)) | B13: =IF($A13="","",SUMIFS(GELIR_GIDER_KAYIT!$Z$6:$Z$5000,GELIR_GIDER_KAYIT!$B$6:$B$5000,$A13,GELIR_GIDER_KAYIT!$Z$6:$Z$5000,">0")) | C13: =IF($A13="","",-SUMIFS(GELIR_GIDER_KAYIT!$Z$6:$Z$5000,GELIR_GIDER_KAYIT!$B$6:$B$5000,$A13,GELIR_GIDER_KAYIT!$Z$6:$Z$5000,"<0")) | D13: =IF($A13="","",B13-C13) | E13: =IF($A13="","",SUMIFS(GELIR_GIDER_KAYIT!$AA$6:$AA$5000,GELIR_GIDER_KAYIT!$B$6:$B$5000,$A13)) | F13: =IF($A13="","",F12+D13)
A14: =IF($A13="","",IF($A13+1>RaporTarihi,"",$A13+1)) | B14: =IF($A14="","",SUMIFS(GELIR_GIDER_KAYIT!$Z$6:$Z$5000,GELIR_GIDER_KAYIT!$B$6:$B$5000,$A14,GELIR_GIDER_KAYIT!$Z$6:$Z$5000,">0")) | C14: =IF($A14="","",-SUMIFS(GELIR_GIDER_KAYIT!$Z$6:$Z$5000,GELIR_GIDER_KAYIT!$B$6:$B$5000,$A14,GELIR_GIDER_KAYIT!$Z$6:$Z$5000,"<0")) | D14: =IF($A14="","",B14-C14) | E14: =IF($A14="","",SUMIFS(GELIR_GIDER_KAYIT!$AA$6:$AA$5000,GELIR_GIDER_KAYIT!$B$6:$B$5000,$A14)) | F14: =IF($A14="","",F13+D14)
A15: =IF($A14="","",IF($A14+1>RaporTarihi,"",$A14+1)) | B15: =IF($A15="","",SUMIFS(GELIR_GIDER_KAYIT!$Z$6:$Z$5000,GELIR_GIDER_KAYIT!$B$6:$B$5000,$A15,GELIR_GIDER_KAYIT!$Z$6:$Z$5000,">0")) | C15: =IF($A15="","",-SUMIFS(GELIR_GIDER_KAYIT!$Z$6:$Z$5000,GELIR_GIDER_KAYIT!$B$6:$B$5000,$A15,GELIR_GIDER_KAYIT!$Z$6:$Z$5000,"<0")) | D15: =IF($A15="","",B15-C15) | E15: =IF($A15="","",SUMIFS(GELIR_GIDER_KAYIT!$AA$6:$AA$5000,GELIR_GIDER_KAYIT!$B$6:$B$5000,$A15)) | F15: =IF($A15="","",F14+D15)
A16: =IF($A15="","",IF($A15+1>RaporTarihi,"",$A15+1)) | B16: =IF($A16="","",SUMIFS(GELIR_GIDER_KAYIT!$Z$6:$Z$5000,GELIR_GIDER_KAYIT!$B$6:$B$5000,$A16,GELIR_GIDER_KAYIT!$Z$6:$Z$5000,">0")) | C16: =IF($A16="","",-SUMIFS(GELIR_GIDER_KAYIT!$Z$6:$Z$5000,GELIR_GIDER_KAYIT!$B$6:$B$5000,$A16,GELIR_GIDER_KAYIT!$Z$6:$Z$5000,"<0")) | D16: =IF($A16="","",B16-C16) | E16: =IF($A16="","",SUMIFS(GELIR_GIDER_KAYIT!$AA$6:$AA$5000,GELIR_GIDER_KAYIT!$B$6:$B$5000,$A16)) | F16: =IF($A16="","",F15+D16)
A17: =IF($A16="","",IF($A16+1>RaporTarihi,"",$A16+1)) | B17: =IF($A17="","",SUMIFS(GELIR_GIDER_KAYIT!$Z$6:$Z$5000,GELIR_GIDER_KAYIT!$B$6:$B$5000,$A17,GELIR_GIDER_KAYIT!$Z$6:$Z$5000,">0")) | C17: =IF($A17="","",-SUMIFS(GELIR_GIDER_KAYIT!$Z$6:$Z$5000,GELIR_GIDER_KAYIT!$B$6:$B$5000,$A17,GELIR_GIDER_KAYIT!$Z$6:$Z$5000,"<0")) | D17: =IF($A17="","",B17-C17) | E17: =IF($A17="","",SUMIFS(GELIR_GIDER_KAYIT!$AA$6:$AA$5000,GELIR_GIDER_KAYIT!$B$6:$B$5000,$A17)) | F17: =IF($A17="","",F16+D17)
A18: =IF($A17="","",IF($A17+1>RaporTarihi,"",$A17+1)) | B18: =IF($A18="","",SUMIFS(GELIR_GIDER_KAYIT!$Z$6:$Z$5000,GELIR_GIDER_KAYIT!$B$6:$B$5000,$A18,GELIR_GIDER_KAYIT!$Z$6:$Z$5000,">0")) | C18: =IF($A18="","",-SUMIFS(GELIR_GIDER_KAYIT!$Z$6:$Z$5000,GELIR_GIDER_KAYIT!$B$6:$B$5000,$A18,GELIR_GIDER_KAYIT!$Z$6:$Z$5000,"<0")) | D18: =IF($A18="","",B18-C18) | E18: =IF($A18="","",SUMIFS(GELIR_GIDER_KAYIT!$AA$6:$AA$5000,GELIR_GIDER_KAYIT!$B$6:$B$5000,$A18)) | F18: =IF($A18="","",F17+D18)
... A105: =IF($A104="","",IF($A104+1>RaporTarihi,"",$A104+1)) | B105: =IF($A105="","",SUMIFS(GELIR_GIDER_KAYIT!$Z$6:$Z$5000,GELIR_GIDER_KAYIT!$B$6:$B$5000,$A105,GELIR_GIDER_KAYIT!$Z$6:$Z$5000,">0")) | C105: =IF($A105="","",-SUMIFS(GELIR_GIDER_KAYIT!$Z$6:$Z$5000,GELIR_GIDER_KAYIT!$B$6:$B$5000,$A105,GELIR_GIDER_KAYIT!$Z$6:$Z$5000,"<0")) | D105: =IF($A105="","",B105-C105) | E105: =IF($A105="","",SUMIFS(GELIR_GIDER_KAYIT!$AA$6:$AA$5000,GELIR_GIDER_KAYIT!$B$6:$B$5000,$A105)) | F105: =IF($A105="","",F104+D105)

Sheet AYLIK_KARLILIK
A1: AYLIK KARLILIK — GÜNLÜK GELİR–GİDER VE GERÇEK KÂRLILIK SİSTEMİ
A2: Ay bazında gelir tablosu otomatik hesaplanır. Kâr varmış gibi görünürken paranın neden azaldığını Net Nakit sütunu gösterir.
A5: Ay | B5: Net Satış | C5: Satış İade/İskonto | D5: Satışların Maliyeti | E5: Brüt Kâr | F5: Değişken Gider | G5: Katkı Payı | H5: Sabit Gider | I5: Faaliyet Kârı | J5: Finansman Gideri | K5: Vergi | L5: Net Sonuç | M5: Nakit Girişi | N5: Nakit Çıkışı | O5: Net Nakit
A6: OCAK | B6: =SUMPRODUCT((MONTH(GELIR_GIDER_KAYIT!$B$6:$B$5000)=MATCH($A6,$A$6:$A$17,0))*((GELIR_GIDER_KAYIT!$D$6:$D$5000="GELİR")*(GELIR_GIDER_KAYIT!$E$6:$E$5000="SATIŞ"))*GELIR_GIDER_KAYIT!$AA$6:$AA$5000) | C6: =-SUMPRODUCT((MONTH(GELIR_GIDER_KAYIT!$B$6:$B$5000)=MATCH($A6,$A$6:$A$17,0))*((GELIR_GIDER_KAYIT!$E$6:$E$5000="SATIŞ İADESİ/İSKONTO"))*GELIR_GIDER_KAYIT!$AA$6:$AA$5000) | D6: =-SUMPRODUCT((MONTH(GELIR_GIDER_KAYIT!$B$6:$B$5000)=MATCH($A6,$A$6:$A$17,0))*((GELIR_GIDER_KAYIT!$E$6:$E$5000="SATIŞLARIN MALİYETİ"))*GELIR_GIDER_KAYIT!$AA$6:$AA$5000) | E6: =B6-C6-D6 | F6: =-SUMPRODUCT((MONTH(GELIR_GIDER_KAYIT!$B$6:$B$5000)=MATCH($A6,$A$6:$A$17,0))*((GELIR_GIDER_KAYIT!$E$6:$E$5000="DEĞİŞKEN GİDER"))*GELIR_GIDER_KAYIT!$AA$6:$AA$5000) | G6: =E6-F6 | H6: =-SUMPRODUCT((MONTH(GELIR_GIDER_KAYIT!$B$6:$B$5000)=MATCH($A6,$A$6:$A$17,0))*((GELIR_GIDER_KAYIT!$E$6:$E$5000="PERSONEL")+(GELIR_GIDER_KAYIT!$E$6:$E$5000="KİRA")+(GELIR_GIDER_KAYIT!$E$6:$E$5000="PAZARLAMA")+(GELIR_GIDER_KAYIT!$E$6:$E$5000="LOJİSTİK")+(GELIR_GIDER_KAYIT!$E$6:$E$5000="GENEL YÖNETİM")+(GELIR_GIDER_KAYIT!$E$6:$E$5000="AMORTİSMAN"))*GELIR_GIDER_KAYIT!$AA$6:$AA$5000) | I6: =G6-H6 | J6: =-SUMPRODUCT((MONTH(GELIR_GIDER_KAYIT!$B$6:$B$5000)=MATCH($A6,$A$6:$A$17,0))*((GELIR_GIDER_KAYIT!$E$6:$E$5000="FİNANSMAN GİDERİ"))*GELIR_GIDER_KAYIT!$AA$6:$AA$5000) | K6: =-SUMPRODUCT((MONTH(GELIR_GIDER_KAYIT!$B$6:$B$5000)=MATCH($A6,$A$6:$A$17,0))*((GELIR_GIDER_KAYIT!$E$6:$E$5000="VERGİ"))*GELIR_GIDER_KAYIT!$AA$6:$AA$5000) | L6: =I6-J6-K6 | M6: =SUMPRODUCT((MONTH(GELIR_GIDER_KAYIT!$B$6:$B$5000)=MATCH($A6,$A$6:$A$17,0))*((GELIR_GIDER_KAYIT!$Z$6:$Z$5000>0))*GELIR_GIDER_KAYIT!$Z$6:$Z$5000) | N6: =-SUMPRODUCT((MONTH(GELIR_GIDER_KAYIT!$B$6:$B$5000)=MATCH($A6,$A$6:$A$17,0))*((GELIR_GIDER_KAYIT!$Z$6:$Z$5000<0))*GELIR_GIDER_KAYIT!$Z$6:$Z$5000) | O6: =M6-N6
A7: ŞUBAT | B7: =SUMPRODUCT((MONTH(GELIR_GIDER_KAYIT!$B$6:$B$5000)=MATCH($A7,$A$6:$A$17,0))*((GELIR_GIDER_KAYIT!$D$6:$D$5000="GELİR")*(GELIR_GIDER_KAYIT!$E$6:$E$5000="SATIŞ"))*GELIR_GIDER_KAYIT!$AA$6:$AA$5000) | C7: =-SUMPRODUCT((MONTH(GELIR_GIDER_KAYIT!$B$6:$B$5000)=MATCH($A7,$A$6:$A$17,0))*((GELIR_GIDER_KAYIT!$E$6:$E$5000="SATIŞ İADESİ/İSKONTO"))*GELIR_GIDER_KAYIT!$AA$6:$AA$5000) | D7: =-SUMPRODUCT((MONTH(GELIR_GIDER_KAYIT!$B$6:$B$5000)=MATCH($A7,$A$6:$A$17,0))*((GELIR_GIDER_KAYIT!$E$6:$E$5000="SATIŞLARIN MALİYETİ"))*GELIR_GIDER_KAYIT!$AA$6:$AA$5000) | E7: =B7-C7-D7 | F7: =-SUMPRODUCT((MONTH(GELIR_GIDER_KAYIT!$B$6:$B$5000)=MATCH($A7,$A$6:$A$17,0))*((GELIR_GIDER_KAYIT!$E$6:$E$5000="DEĞİŞKEN GİDER"))*GELIR_GIDER_KAYIT!$AA$6:$AA$5000) | G7: =E7-F7 | H7: =-SUMPRODUCT((MONTH(GELIR_GIDER_KAYIT!$B$6:$B$5000)=MATCH($A7,$A$6:$A$17,0))*((GELIR_GIDER_KAYIT!$E$6:$E$5000="PERSONEL")+(GELIR_GIDER_KAYIT!$E$6:$E$5000="KİRA")+(GELIR_GIDER_KAYIT!$E$6:$E$5000="PAZARLAMA")+(GELIR_GIDER_KAYIT!$E$6:$E$5000="LOJİSTİK")+(GELIR_GIDER_KAYIT!$E$6:$E$5000="GENEL YÖNETİM")+(GELIR_GIDER_KAYIT!$E$6:$E$5000="AMORTİSMAN"))*GELIR_GIDER_KAYIT!$AA$6:$AA$5000) | I7: =G7-H7 | J7: =-SUMPRODUCT((MONTH(GELIR_GIDER_KAYIT!$B$6:$B$5000)=MATCH($A7,$A$6:$A$17,0))*((GELIR_GIDER_KAYIT!$E$6:$E$5000="FİNANSMAN GİDERİ"))*GELIR_GIDER_KAYIT!$AA$6:$AA$5000) | K7: =-SUMPRODUCT((MONTH(GELIR_GIDER_KAYIT!$B$6:$B$5000)=MATCH($A7,$A$6:$A$17,0))*((GELIR_GIDER_KAYIT!$E$6:$E$5000="VERGİ"))*GELIR_GIDER_KAYIT!$AA$6:$AA$5000) | L7: =I7-J7-K7 | M7: =SUMPRODUCT((MONTH(GELIR_GIDER_KAYIT!$B$6:$B$5000)=MATCH($A7,$A$6:$A$17,0))*((GELIR_GIDER_KAYIT!$Z$6:$Z$5000>0))*GELIR_GIDER_KAYIT!$Z$6:$Z$5000) | N7: =-SUMPRODUCT((MONTH(GELIR_GIDER_KAYIT!$B$6:$B$5000)=MATCH($A7,$A$6:$A$17,0))*((GELIR_GIDER_KAYIT!$Z$6:$Z$5000<0))*GELIR_GIDER_KAYIT!$Z$6:$Z$5000) | O7: =M7-N7
A8: MART | B8: =SUMPRODUCT((MONTH(GELIR_GIDER_KAYIT!$B$6:$B$5000)=MATCH($A8,$A$6:$A$17,0))*((GELIR_GIDER_KAYIT!$D$6:$D$5000="GELİR")*(GELIR_GIDER_KAYIT!$E$6:$E$5000="SATIŞ"))*GELIR_GIDER_KAYIT!$AA$6:$AA$5000) | C8: =-SUMPRODUCT((MONTH(GELIR_GIDER_KAYIT!$B$6:$B$5000)=MATCH($A8,$A$6:$A$17,0))*((GELIR_GIDER_KAYIT!$E$6:$E$5000="SATIŞ İADESİ/İSKONTO"))*GELIR_GIDER_KAYIT!$AA$6:$AA$5000) | D8: =-SUMPRODUCT((MONTH(GELIR_GIDER_KAYIT!$B$6:$B$5000)=MATCH($A8,$A$6:$A$17,0))*((GELIR_GIDER_KAYIT!$E$6:$E$5000="SATIŞLARIN MALİYETİ"))*GELIR_GIDER_KAYIT!$AA$6:$AA$5000) | E8: =B8-C8-D8 | F8: =-SUMPRODUCT((MONTH(GELIR_GIDER_KAYIT!$B$6:$B$5000)=MATCH($A8,$A$6:$A$17,0))*((GELIR_GIDER_KAYIT!$E$6:$E$5000="DEĞİŞKEN GİDER"))*GELIR_GIDER_KAYIT!$AA$6:$AA$5000) | G8: =E8-F8 | H8: =-SUMPRODUCT((MONTH(GELIR_GIDER_KAYIT!$B$6:$B$5000)=MATCH($A8,$A$6:$A$17,0))*((GELIR_GIDER_KAYIT!$E$6:$E$5000="PERSONEL")+(GELIR_GIDER_KAYIT!$E$6:$E$5000="KİRA")+(GELIR_GIDER_KAYIT!$E$6:$E$5000="PAZARLAMA")+(GELIR_GIDER_KAYIT!$E$6:$E$5000="LOJİSTİK")+(GELIR_GIDER_KAYIT!$E$6:$E$5000="GENEL YÖNETİM")+(GELIR_GIDER_KAYIT!$E$6:$E$5000="AMORTİSMAN"))*GELIR_GIDER_KAYIT!$AA$6:$AA$5000) | I8: =G8-H8 | J8: =-SUMPRODUCT((MONTH(GELIR_GIDER_KAYIT!$B$6:$B$5000)=MATCH($A8,$A$6:$A$17,0))*((GELIR_GIDER_KAYIT!$E$6:$E$5000="FİNANSMAN GİDERİ"))*GELIR_GIDER_KAYIT!$AA$6:$AA$5000) | K8: =-SUMPRODUCT((MONTH(GELIR_GIDER_KAYIT!$B$6:$B$5000)=MATCH($A8,$A$6:$A$17,0))*((GELIR_GIDER_KAYIT!$E$6:$E$5000="VERGİ"))*GELIR_GIDER_KAYIT!$AA$6:$AA$5000) | L8: =I8-J8-K8 | M8: =SUMPRODUCT((MONTH(GELIR_GIDER_KAYIT!$B$6:$B$5000)=MATCH($A8,$A$6:$A$17,0))*((GELIR_GIDER_KAYIT!$Z$6:$Z$5000>0))*GELIR_GIDER_KAYIT!$Z$6:$Z$5000) | N8: =-SUMPRODUCT((MONTH(GELIR_GIDER_KAYIT!$B$6:$B$5000)=MATCH($A8,$A$6:$A$17,0))*((GELIR_GIDER_KAYIT!$Z$6:$Z$5000<0))*GELIR_GIDER_KAYIT!$Z$6:$Z$5000) | O8: =M8-N8
A9: NİSAN | B9: =SUMPRODUCT((MONTH(GELIR_GIDER_KAYIT!$B$6:$B$5000)=MATCH($A9,$A$6:$A$17,0))*((GELIR_GIDER_KAYIT!$D$6:$D$5000="GELİR")*(GELIR_GIDER_KAYIT!$E$6:$E$5000="SATIŞ"))*GELIR_GIDER_KAYIT!$AA$6:$AA$5000) | C9: =-SUMPRODUCT((MONTH(GELIR_GIDER_KAYIT!$B$6:$B$5000)=MATCH($A9,$A$6:$A$17,0))*((GELIR_GIDER_KAYIT!$E$6:$E$5000="SATIŞ İADESİ/İSKONTO"))*GELIR_GIDER_KAYIT!$AA$6:$AA$5000) | D9: =-SUMPRODUCT((MONTH(GELIR_GIDER_KAYIT!$B$6:$B$5000)=MATCH($A9,$A$6:$A$17,0))*((GELIR_GIDER_KAYIT!$E$6:$E$5000="SATIŞLARIN MALİYETİ"))*GELIR_GIDER_KAYIT!$AA$6:$AA$5000) | E9: =B9-C9-D9 | F9: =-SUMPRODUCT((MONTH(GELIR_GIDER_KAYIT!$B$6:$B$5000)=MATCH($A9,$A$6:$A$17,0))*((GELIR_GIDER_KAYIT!$E$6:$E$5000="DEĞİŞKEN GİDER"))*GELIR_GIDER_KAYIT!$AA$6:$AA$5000) | G9: =E9-F9 | H9: =-SUMPRODUCT((MONTH(GELIR_GIDER_KAYIT!$B$6:$B$5000)=MATCH($A9,$A$6:$A$17,0))*((GELIR_GIDER_KAYIT!$E$6:$E$5000="PERSONEL")+(GELIR_GIDER_KAYIT!$E$6:$E$5000="KİRA")+(GELIR_GIDER_KAYIT!$E$6:$E$5000="PAZARLAMA")+(GELIR_GIDER_KAYIT!$E$6:$E$5000="LOJİSTİK")+(GELIR_GIDER_KAYIT!$E$6:$E$5000="GENEL YÖNETİM")+(GELIR_GIDER_KAYIT!$E$6:$E$5000="AMORTİSMAN"))*GELIR_GIDER_KAYIT!$AA$6:$AA$5000) | I9: =G9-H9 | J9: =-SUMPRODUCT((MONTH(GELIR_GIDER_KAYIT!$B$6:$B$5000)=MATCH($A9,$A$6:$A$17,0))*((GELIR_GIDER_KAYIT!$E$6:$E$5000="FİNANSMAN GİDERİ"))*GELIR_GIDER_KAYIT!$AA$6:$AA$5000) | K9: =-SUMPRODUCT((MONTH(GELIR_GIDER_KAYIT!$B$6:$B$5000)=MATCH($A9,$A$6:$A$17,0))*((GELIR_GIDER_KAYIT!$E$6:$E$5000="VERGİ"))*GELIR_GIDER_KAYIT!$AA$6:$AA$5000) | L9: =I9-J9-K9 | M9: =SUMPRODUCT((MONTH(GELIR_GIDER_KAYIT!$B$6:$B$5000)=MATCH($A9,$A$6:$A$17,0))*((GELIR_GIDER_KAYIT!$Z$6:$Z$5000>0))*GELIR_GIDER_KAYIT!$Z$6:$Z$5000) | N9: =-SUMPRODUCT((MONTH(GELIR_GIDER_KAYIT!$B$6:$B$5000)=MATCH($A9,$A$6:$A$17,0))*((GELIR_GIDER_KAYIT!$Z$6:$Z$5000<0))*GELIR_GIDER_KAYIT!$Z$6:$Z$5000) | O9: =M9-N9
A10: MAYIS | B10: =SUMPRODUCT((MONTH(GELIR_GIDER_KAYIT!$B$6:$B$5000)=MATCH($A10,$A$6:$A$17,0))*((GELIR_GIDER_KAYIT!$D$6:$D$5000="GELİR")*(GELIR_GIDER_KAYIT!$E$6:$E$5000="SATIŞ"))*GELIR_GIDER_KAYIT!$AA$6:$AA$5000) | C10: =-SUMPRODUCT((MONTH(GELIR_GIDER_KAYIT!$B$6:$B$5000)=MATCH($A10,$A$6:$A$17,0))*((GELIR_GIDER_KAYIT!$E$6:$E$5000="SATIŞ İADESİ/İSKONTO"))*GELIR_GIDER_KAYIT!$AA$6:$AA$5000) | D10: =-SUMPRODUCT((MONTH(GELIR_GIDER_KAYIT!$B$6:$B$5000)=MATCH($A10,$A$6:$A$17,0))*((GELIR_GIDER_KAYIT!$E$6:$E$5000="SATIŞLARIN MALİYETİ"))*GELIR_GIDER_KAYIT!$AA$6:$AA$5000) | E10: =B10-C10-D10 | F10: =-SUMPRODUCT((MONTH(GELIR_GIDER_KAYIT!$B$6:$B$5000)=MATCH($A10,$A$6:$A$17,0))*((GELIR_GIDER_KAYIT!$E$6:$E$5000="DEĞİŞKEN GİDER"))*GELIR_GIDER_KAYIT!$AA$6:$AA$5000) | G10: =E10-F10 | H10: =-SUMPRODUCT((MONTH(GELIR_GIDER_KAYIT!$B$6:$B$5000)=MATCH($A10,$A$6:$A$17,0))*((GELIR_GIDER_KAYIT!$E$6:$E$5000="PERSONEL")+(GELIR_GIDER_KAYIT!$E$6:$E$5000="KİRA")+(GELIR_GIDER_KAYIT!$E$6:$E$5000="PAZARLAMA")+(GELIR_GIDER_KAYIT!$E$6:$E$5000="LOJİSTİK")+(GELIR_GIDER_KAYIT!$E$6:$E$5000="GENEL YÖNETİM")+(GELIR_GIDER_KAYIT!$E$6:$E$5000="AMORTİSMAN"))*GELIR_GIDER_KAYIT!$AA$6:$AA$5000) | I10: =G10-H10 | J10: =-SUMPRODUCT((MONTH(GELIR_GIDER_KAYIT!$B$6:$B$5000)=MATCH($A10,$A$6:$A$17,0))*((GELIR_GIDER_KAYIT!$E$6:$E$5000="FİNANSMAN GİDERİ"))*GELIR_GIDER_KAYIT!$AA$6:$AA$5000) | K10: =-SUMPRODUCT((MONTH(GELIR_GIDER_KAYIT!$B$6:$B$5000)=MATCH($A10,$A$6:$A$17,0))*((GELIR_GIDER_KAYIT!$E$6:$E$5000="VERGİ"))*GELIR_GIDER_KAYIT!$AA$6:$AA$5000) | L10: =I10-J10-K10 | M10: =SUMPRODUCT((MONTH(GELIR_GIDER_KAYIT!$B$6:$B$5000)=MATCH($A10,$A$6:$A$17,0))*((GELIR_GIDER_KAYIT!$Z$6:$Z$5000>0))*GELIR_GIDER_KAYIT!$Z$6:$Z$5000) | N10: =-SUMPRODUCT((MONTH(GELIR_GIDER_KAYIT!$B$6:$B$5000)=MATCH($A10,$A$6:$A$17,0))*((GELIR_GIDER_KAYIT!$Z$6:$Z$5000<0))*GELIR_GIDER_KAYIT!$Z$6:$Z$5000) | O10: =M10-N10
A11: HAZİRAN | B11: =SUMPRODUCT((MONTH(GELIR_GIDER_KAYIT!$B$6:$B$5000)=MATCH($A11,$A$6:$A$17,0))*((GELIR_GIDER_KAYIT!$D$6:$D$5000="GELİR")*(GELIR_GIDER_KAYIT!$E$6:$E$5000="SATIŞ"))*GELIR_GIDER_KAYIT!$AA$6:$AA$5000) | C11: =-SUMPRODUCT((MONTH(GELIR_GIDER_KAYIT!$B$6:$B$5000)=MATCH($A11,$A$6:$A$17,0))*((GELIR_GIDER_KAYIT!$E$6:$E$5000="SATIŞ İADESİ/İSKONTO"))*GELIR_GIDER_KAYIT!$AA$6:$AA$5000) | D11: =-SUMPRODUCT((MONTH(GELIR_GIDER_KAYIT!$B$6:$B$5000)=MATCH($A11,$A$6:$A$17,0))*((GELIR_GIDER_KAYIT!$E$6:$E$5000="SATIŞLARIN MALİYETİ"))*GELIR_GIDER_KAYIT!$AA$6:$AA$5000) | E11: =B11-C11-D11 | F11: =-SUMPRODUCT((MONTH(GELIR_GIDER_KAYIT!$B$6:$B$5000)=MATCH($A11,$A$6:$A$17,0))*((GELIR_GIDER_KAYIT!$E$6:$E$5000="DEĞİŞKEN GİDER"))*GELIR_GIDER_KAYIT!$AA$6:$AA$5000) | G11: =E11-F11 | H11: =-SUMPRODUCT((MONTH(GELIR_GIDER_KAYIT!$B$6:$B$5000)=MATCH($A11,$A$6:$A$17,0))*((GELIR_GIDER_KAYIT!$E$6:$E$5000="PERSONEL")+(GELIR_GIDER_KAYIT!$E$6:$E$5000="KİRA")+(GELIR_GIDER_KAYIT!$E$6:$E$5000="PAZARLAMA")+(GELIR_GIDER_KAYIT!$E$6:$E$5000="LOJİSTİK")+(GELIR_GIDER_KAYIT!$E$6:$E$5000="GENEL YÖNETİM")+(GELIR_GIDER_KAYIT!$E$6:$E$5000="AMORTİSMAN"))*GELIR_GIDER_KAYIT!$AA$6:$AA$5000) | I11: =G11-H11 | J11: =-SUMPRODUCT((MONTH(GELIR_GIDER_KAYIT!$B$6:$B$5000)=MATCH($A11,$A$6:$A$17,0))*((GELIR_GIDER_KAYIT!$E$6:$E$5000="FİNANSMAN GİDERİ"))*GELIR_GIDER_KAYIT!$AA$6:$AA$5000) | K11: =-SUMPRODUCT((MONTH(GELIR_GIDER_KAYIT!$B$6:$B$5000)=MATCH($A11,$A$6:$A$17,0))*((GELIR_GIDER_KAYIT!$E$6:$E$5000="VERGİ"))*GELIR_GIDER_KAYIT!$AA$6:$AA$5000) | L11: =I11-J11-K11 | M11: =SUMPRODUCT((MONTH(GELIR_GIDER_KAYIT!$B$6:$B$5000)=MATCH($A11,$A$6:$A$17,0))*((GELIR_GIDER_KAYIT!$Z$6:$Z$5000>0))*GELIR_GIDER_KAYIT!$Z$6:$Z$5000) | N11: =-SUMPRODUCT((MONTH(GELIR_GIDER_KAYIT!$B$6:$B$5000)=MATCH($A11,$A$6:$A$17,0))*((GELIR_GIDER_KAYIT!$Z$6:$Z$5000<0))*GELIR_GIDER_KAYIT!$Z$6:$Z$5000) | O11: =M11-N11
