Workbook
Name hesapYili: GIRDI!$B$8
Name raporTarihi: AYARLAR!$B$7
Name ukv_matrah: MOTOR!$G$29
Name ukv_tasarruf: MOTOR!$G$28
Name ukv_indirimliKv: MOTOR!$G$30
Name ukv_kacirilan: MOTOR!$G$28
Name ukv_kararMetni: MOTOR!$G$34
Name ukv_kararGerekce: MOTOR!$G$35
Name ukv_maddeAtifMetni: MOTOR!$G$52
Name ukv_kanitRaporu: MOTOR!$G$53
Name ukv_kuralYilMatris: KURALLAR!$B$17
Name ukv_parmakIzi: AYARLAR!$B$19
Name ukv_senaryoKarsilastirma: SENARYO!$B$11
Name ukv_yorumSenaryo: SENARYO!$B$12
Name ukv_duyarlilikSira: SENARYO!$B$19
Name ukv_yorumDuyarlilik: SENARYO!$B$20
Name ukv_kuralDegisimSenaryo: SENARYO!$B$22
Name ukv_yorumKuralDegisim: SENARYO!$B$23
Name ukv_tahminAralik: SENARYO!$B$32
Name ukv_yorumTahmin: SENARYO!$B$33
Name ukv_vakaDurum: VAKALAR!$B$12
Name ukv_vakaFark: VAKALAR!$B$13
Name ukv_tolerans: AYARLAR!$B$8
Name ukv_kacirilanEsik: AYARLAR!$B$9
Name ukv_senaryoIyi: AYARLAR!$B$10
Name ukv_senaryoKotu: AYARLAR!$B$11
Name ukv_oranArtisPuan: AYARLAR!$B$12
Name ukv_tahminAlt: AYARLAR!$B$13
Name ukv_tahminUst: AYARLAR!$B$14
Name ukv_tornadoHasilat: AYARLAR!$B$15
Name ukv_tornadoMaliyet: AYARLAR!$B$16
Name ukv_payArtisOran: AYARLAR!$B$17
Name ukv_yuzdelikOran: AYARLAR!$B$18
Name ukv_girisBeklenen: AYARLAR!$B$21
Name ukv_riskDusuk: AYARLAR!$B$22
Name ukv_riskOrta: AYARLAR!$B$23
Name ukv_riskYuksek: AYARLAR!$B$24
Name ukv_riskEsikOran: AYARLAR!$B$25
Name ukv_yilTaban: AYARLAR!$B$26
Name ukv_yuvarMax: AYARLAR!$B$27
Name ukv_dayanakCarpan: AYARLAR!$B$28
Name ukv_bazCarpan: AYARLAR!$B$29
Name ukv_sifirCarpan: AYARLAR!$B$30
Name ukv_siraBir: AYARLAR!$B$31
Name ukv_siraIki: AYARLAR!$B$32
Name ukv_siraUc: AYARLAR!$B$33
Name ukv_tahminX: AYARLAR!$B$34
Name vaka_matrah_1: AYARLAR!$B$35
Name vaka_matrah_2: AYARLAR!$B$36
Name vaka_tavan: AYARLAR!$B$37
Name vaka_endeks_orani: AYARLAR!$B$38
Name ukv_modulT1: PANO!$C$11
Name ukv_modulT1Yorum: PANO!$D$11
Name ukv_modulT2: PANO!$C$12
Name ukv_modulT2Yorum: PANO!$D$12
Name ukv_modulO1: PANO!$C$13
Name ukv_modulO1Yorum: PANO!$D$13
Name ukv_modulO6: PANO!$C$16
Name ukv_modulO6Yorum: PANO!$D$16
Name ukv_modulO8: PANO!$C$17

Sheet 00_BASLANGIC
A1: EXCELARŞİV KARAR SİSTEMİ v15.1 — ÜRETİM REFERANSI
A3: Konu | B3: Bağlayıcı Standart
A4: Amaç | B4: Kanıta dayalı, hatada kapalı çalışan Excel üretim ve denetim sistemi
A5: Öncelik | B5: Kullanıcının açık iş talebi ve gerçek kullanım senaryosu
A6: Ana akış | B6: Uygunluk → Yönetişim → Sözleşmeler → Üretim → Test → Kanıt → Kullanıcı Kabulü → Yayın
A7: Yayın ilkesi | B7: Üst aşamada hata varsa alt aşama GEÇTİ üretilemez
A8: Kullanıcı kabulü | B8: Excel masaüstü görünümü test edilmediyse DIŞ_KABUL_GEREKLİ
A9: Nihai yayın | B9: Yalnız uygulanabilir modüller GEÇTİ veya gerekçeli UYGULANMAZ
A10: Ticari ayrım | B10: Ekonomik olarak savunulabilir fiyat, gerçek pazar kabulü ile aynı değildir
A11: Karmaşıklık | B11: Karar değeri, eklenen karmaşıklığın maliyetinden büyük olmalıdır
A12: Excel sınırı | B12: Veritabanı, kurumsal yetkilendirme, değiştirilemez kayıt sistemi veya gerçek zamanlı olay platformu değildir
A13: Dil standardı | B13: Kullanıcıya görünen tüm sayfa, tablo, başlık, açıklama, uyarı ve karar metinleri saf Türkçe olmalıdır
A14: Muhasebe standardı | B14: Finansal ürünlerde Türkiye Tekdüzen Hesap Planı ve Türk muhasebe kullanım alışkanlıkları esas alınır
... A33: Muhasebe | B33: Türkiye Tekdüzen Hesap Planı ve Türk muhasebe/işletme düşünce yapısı esas alınır.

Sheet PANO
A1: ☰ PANO
B2: ÜRETIM KÂRI %12,5 KV OPTIMIZASYONU | L2: Dönem: 2026 / Tam ▼ | M2: ★ DOĞRULANMIŞ
B3: Hedef Kullanıcı: SMMM, YMM, vergi müdürü, imalat CFO · 2026 Q3 Denetim Standardı
B5: ÜRETIM KÂRI / HASILAT ORANI | D5: KONSOLİDE | E5: TASARRUF / STANDART KV ORANI | G5: KONTROL | H5: NET OPERASYONEL MARJ | J5: GÜVENLİ | K5: SİSTEM GÜVEN SKORU | M5: DENETLENDİ
B7: =GİRDİLER!E17 | E7: =B7*0.22 | H7: =B7-E7 | K7: =IF(E7>0, ROUND(B7/E7, 2), 0)
B9: ↑ %14.2 konsolide canlı veri bağlantısı | E9: ● 8 Kalem nakit karşılığı: bloke | H9: ██████████░░░░░ %78.0 NET MARJ | K9: ✓ İDEAL karşılama rasyosu
B11: ÜRETIM KÂRI %12,5 KV OPTIMIZASYONU — DÖNEMSEL İCRA VE PROJEKSİYON | F11: +%32 Verim | H11: KONSOLİDE OPERASYON VE KARAR MATRİSİ
B12: Kümülatif Hacim vs. Operasyonel Maliyet ve Net Kâr Eğilimi | H12: Anlık Hesaplama Sonuçları, Dinamik Formül Çıktıları ve Durum Puanlaması
B14: Dönem | C14: Aktif Hacim | D14: Maliyet/Yük | E14: Hedef | H14: PARAMETRE / KALEM | I14: ANA TUTAR | J14: FARK / MARJ | K14: VADE | L14: KONTROL DURUMU
B15: D1 | C15: 65 | D15: 45 | E15: 60 | H15: Dönemlik Kümülatif Bakiye | I15: =B7*0.45 | J15: =B7*0.05 | K15: 12 Ay | L15: ✓ DÜZENLİ
B16: D2 | C16: 78 | D16: 48 | E16: 70 | H16: Kritik Eşik Güvenlik Tamponu | I16: =B7*0.30 | J16: =B7*0.03 | K16: 24 Ay | L16: ★ AVANTAJ
B17: D3 | C17: 85 | D17: 55 | E17: 80 | H17: Operasyonel Net Fark | I17: =B7*0.15 | J17: =B7*0.02 | K17: 8 Ay | L17: ● YAKLAŞAN
B18: D4 | C18: 75 | D18: 42 | E18: 75 | H18: Rezerv ve Likit Dağılım | I18: =B7*0.10 | J18: =B7*0.01 | K18: 16 Ay | L18: ✓ TAM UYUM
B19: D5 | C19: 90 | D19: 40 | E19: 85 | H19: KONSOLİDE SİSTEM TOPLAMI | I19: =SUM(I15:I18) | J19: =SUM(J15:J18) | L19: TAM DOĞRULANDI (0 HATA)
B20: D6 | C20: 96 | D20: 32 | E20: 92
B22: KONSOLİDE PAY VE AĞIRLIK | F22: LİKİDİTE RİSKİ & ERKEN UYARI SİNYALLERİ | K22: KARAR MOTORU
B23: ■ Ana Segment (%42) | F23: Nakit Açığı Riski (30 Gün) | I23: 0.00 TL (Sıfır Risk) | K23: LİKİDİTE OPTİMİZASYON FIRSATI
B24: ■ İkincil Grup (%30) | F24: Tahsilat Gecikme Toleransı | I24: 48 Gün Güvenli Eşik | K24: Atıl kalan nakit rezervinin gecelik repoda
B25: ■ Destek Birimi (%15) | F25: ██████████████████████████████████████ Güvenli Bölge (%100)
B26: ■ Rezervler (%13) | F26: ✓ 90 GÜNLÜK PROJEKSİYONDA NAKİT SIKIŞIKLIĞI TESPİT EDİLMEDİ | K26: FONLAMA SENARYOSUNU İNCELE ›

Sheet GİRDİLER
A1: ☰ PANO
B3: 🔍 ÜRETIM KÂRI %12,5 KV OPTIMIZASYONU — Kayıt veya hesap ara... | G3: TOPLAM: 1.450 KAYIT | I3: HATALI HÜCRE: 0 ADET
B5: TARİH | C5: REFERANS NO | D5: İŞLEM AÇIKLAMASI VE DETAY | E5: BRÜT TUTAR (₺) | F5: KDV ORANI | G5: NET TUTAR (₺) | H5: HESAP / CARİ | I5: DURUM
B6: 12.10.2026 | C6: TR-0428-A | D6: Operasyonel ana kalem tahmini | E6: 845200 | F6: 0.2 | G6: =E6/(1+F6) | H6: Vadesiz Ticari | I6: ONAYLANDI
B7: 14.10.2026 | C7: TR-0429-B | D7: Operasyonel çıkış/maliyet tahmini | E7: 1240000 | F7: 0.2 | G7: =E7/(1+F7) | H7: Tedarikçi Havuzu | I7: BEKLEMEDE
B8: 18.10.2026 | C8: TR-0430-C | D8: Ödeme takvimi tahakkuku | E8: 620500 | F8: 0.1 | G8: =E8/(1+F8) | H8: Kısa Vade Tahakkuk | I8: ONAYLANDI
B9: 21.10.2026 | C9: TR-0431-D | D9: Müşteri işlem tahmini | E9: 415000 | F9: 0.2 | G9: =E9/(1+F9) | H9: Müşteri Alacağı | I9: ONAYLANDI
B10: 25.10.2026 | C10: TR-0432-E | D10: Ana operasyon tahmini | E10: 980400 | F10: 0.2 | G10: =E10/(1+F10) | H10: Vadesiz Ticari | I10: ONAYLANDI
B11: 28.10.2026 | C11: TR-0433-F | D11: Kredi/taksit karşılığı | E11: 1850000 | F11: 0.2 | G11: =E11/(1+F11) | H11: Finansman Havuzu | I11: BLOKE
B12: 02.11.2026 | C12: TR-0434-G | D12: Sabit gider ve yönetim notları | E12: 740000 | F12: 0.2 | G12: =E12/(1+F12) | H12: Genel Yönetim | I12: ONAYLANDI
B13: 05.11.2026 | C13: TR-0435-H | D13: Operasyonel ana kalem tahmini | E13: 520800 | F13: 0.2 | G13: =E13/(1+F13) | H13: Vadesiz Ticari | I13: ONAYLANDI
B14: 09.11.2026 | C14: TR-0436-I | D14: Müşteri işlem tahmini | E14: 1120000 | F14: 0.2 | G14: =E14/(1+F14) | H14: Müşteri Alacağı | I14: ONAYLANDI
B15: 12.11.2026 | C15: TR-0437-J | D15: Operasyonel çıkış tahmini | E15: 890000 | F15: 0.2 | G15: =E15/(1+F15) | H15: Tedarikçi Havuzu | I15: ONAYLANDI
B17: SAYFA TOPLAMI (10 / 1.450 KAYIT) | E17: =SUM(E6:E15)

Sheet YÖNETİM_RAPORU
A1: ☰ PANO
B2: ÜRETIM KÂRI %12,5 KV OPTIMIZASYONU — NİHAİ KARAR VE DEĞERLEME
B3: Yönetim Kurulu ve İcra Komitesi için Otomatik Finansal Stres Testi Raporu · SMMM, YMM, vergi müdürü, imalat CFO
B4: DÖNEM: 2026 Q3 · DENETİM PROTOKOLÜ: ISO/VUK/IFRS UYUMLU · DURUM: ONAYLANDI
B6: SENARYO A: KÖTÜMSER (STRES TESTİ -%20) | H6: SENARYO B: BAZ MODEL (HEDEFLENEN)
B8: Ciro / Hacim Düşüşü: | E8: -%20.0 (Kriz Eşiği) | H8: Ciro / Hacim Gerçekleşmesi: | K8: %100.0 (Tam Bütçe)
B9: Beklenen Net Kâr / Getiri: | E9: =PANO!B7*0.8*0.22 | H9: Beklenen Net Kâr / Getiri: | K9: =PANO!H7
B10: Minimum Nakit Tamponu: | E10: =PANO!E7*0.75 | H10: Serbest Nakit Akımı: | K10: =PANO!H7*0.75
B11: Likidite Karşılama Oranı: | E11: =ROUND(PANO!B7*0.8/PANO!E7, 2) | H11: Yatırım Geri Dönüşü (ROI): | K11: %38.4 Yıllık
B14: STRES SENARYOSUNDA DAHİ İFLAS RİSKİ YOK | H14: OPTİMUM İCRA VE PLANLAMA REÇETESİ
B17: YÖNETİM KARAR MATRİSİ VE UYGULAMA REÇETESİ
B19: ● Öncelik 1: Acil Likidite ve Borç Servis Planlaması
B20: Sistemde hesaplanan vade günlerine sadık kalınarak nakit blokajı 3 gün önceden hazır edilmelidir.
B21: ● Öncelik 2: Formül Doğrulama ve Çapraz Sağlama
B22: Tüm hücreler kilitli formül korumasında olup girdi sayfalarında sıfır döngüsel başvuru (circular ref) garantilidir.
B23: ● Öncelik 3: Resmi Mevzuat ve Vergi Kalkanı Entegrasyonu
B24: 2026 güncel vergi dilimleri, amortisman ve SGK teşvik parametreleri tam otomatik yansıtılmaktadır.
B25: ● Öncelik 4: Yönetici İmzası ve Rapor Paylaşımı
B26: Tek tuşla PDF ve A4 çıktı formatına tam uyumlu sayfa yapısı kurgulanmıştır.

Sheet 01_YURUTME_CEKIRDEGI
A1: YÜRÜTME ÇEKİRDEĞİ — ZORUNLU ÜRETİM SIRASI
A3: Adım | B3: Modül | C3: Tetikleyici | D3: Zorunlu Kanıt | E3: GEÇTİ Kuralı | F3: Hata Durumu | G3: Sonraki Aşama
A4: 1 | B4: Excel Uygunluğu | C4: Her yeni model | D4: UYGUNLUK_KARARI | E4: Excel'in rolü açık | F4: HATA / BLOKE | G4: Yönetişim
A5: 2 | B5: Yönetişim | C5: Her model | D5: Risk seviyesi + etki girdileri | E5: Seviye hesaplandı | F5: BLOKE | G5: Sözleşmeler
A6: 3 | B6: Türk Muhasebe Eşlemesi | C6: Finansal model | D6: THP hesap eşleme tablosu | E6: Kritik satırlar THP ile uyumlu | F6: HATA | G6: Sözleşmeler
A7: 4 | B7: Veri ve Anlam Sözleşmeleri | C7: Girdi/KPI varsa | D7: Veri + KPI sözleşmeleri | E7: Kapsam %100 | F7: HATA | G7: Üretim
A8: 5 | B8: Üretim | C8: Sözleşmeler GEÇTİ | D8: Çalışan Excel | E8: Tek gerçek kaynak korunmuş | F8: HATA | G8: Testler
A9: 6 | B9: Görsel/Kullanım Katmanı | C9: Motor hazır | D9: Başlıklar + renk + grafik + yönlendirme | E9: Tüm kullanıcı sayfaları standarda uygun | F9: HATA | G9: Testler
A10: 7 | B10: Testler | C10: Üretim tamam | D10: Formül/OOXML/kimlik/oracle/golden/metamorfik | E10: Uygulanabilir hard gate'ler GEÇTİ | F10: HATA | G10: Kanıt
A11: 8 | B11: Hata-Kontrol Tutarlılığı | C11: Test sonucu var | D11: Hata taraması + kontrol sonuçları | E11: Formül hatası varken GEÇTİ yok | F11: HATA | G11: Kanıt
A12: 9 | B12: Kanıt | C12: Test sonucu var | D12: Makine okunur artefakt + özet | E12: Kanıt fiziksel ve tutarlı | F12: HATA | G12: Kullanıcı Kabulü
A13: 10 | B13: Kullanıcı Kabulü | C13: Kritik görevler | D13: Gerçek ekran davranışı | E13: Kritik görevler %100 | F13: DIŞ_KABUL_GEREKLİ | G13: Ticari
A14: 11 | B14: Ticari Değer | C14: Ürün satılacaksa | D14: ROI + demo + kanıt paketi | E14: Ekonomik değer kanıtlı | F14: UYARI / HATA | G14: Pazar Doğrulama
A15: 12 | B15: Pazar Doğrulama | C15: Pazar iddiası varsa | D15: Ücretli satış/pilot/fiyat kabul kanıtı | E15: Gerçek fiyat kabul kanıtı | F15: UYGULANMAZ / HATA | G15: Yayın

Sheet 02_KONTROL_LISTESI
A1: NİHAİ KONTROL LİSTESİ — KANITSIZ GEÇİŞ YOK
A3: Kontrol No | B3: Kontrol | C3: Beklenen | D3: Zorunlu Kapı? | E3: Sonuç
A4: K01 | B4: Kullanıcının açık talebi öncelikli mi? | C4: Evet | D4: EVET
A5: K02 | B5: Mevcut yapı, formüller ve tek gerçek kaynak korunuyor mu? | C5: Evet, değişiklik gerekçeli | D5: EVET
A6: K03 | B6: Üst aşama HATA ise alt aşama GEÇTİ engelleniyor mu? | C6: Evet | D6: EVET
A7: K04 | B7: Kanıt fiziksel çıktı ve içerik doğrulaması içeriyor mu? | C7: Evet | D7: EVET
A8: K05 | B8: Excel GUI erişimi olmadan kullanıcı görünümü GEÇTİ yazılıyor mu? | C8: Hayır | D8: EVET
A9: K06 | B9: NİHAİ yalnız GEÇTİ / gerekçeli UYGULANMAZ ile mi? | C9: Evet | D9: EVET
A10: K07 | B10: Ekonomik fiyat savunusu pazar doğrulamasından ayrılmış mı? | C10: Evet | D10: EVET
A11: K08 | B11: Prestij için gereksiz modül var mı? | C11: Hayır | D11: HAYIR
A12: K09 | B12: Excel sınırları açık mı? | C12: Evet | D12: EVET
A13: K10 | B13: Teknik kaynak korunuyor mu? | C13: Evet | D13: EVET
A14: K11 | B14: Kullanıcıya görünen tüm metinler Türkçe mi? | C14: Evet | D14: EVET
A15: K12 | B15: Her kullanıcı sayfasında üst başlık var mı? | C15: Evet | D15: EVET
... A34: K31 | B34: Premium vitrin, altyapı kadar güçlü ve satış fiyatını destekleyecek seviyede mi? | C34: Evet | D34: EVET

Sheet 03_GORSEL_TASARIM
A1: GÖRSEL TASARIM VE PREMIUM EXCEL STANDARDI
A3: Alan | B3: Zorunlu Kural | C3: Uygulama | D3: Yasak | E3: Kontrol | F3: Durum
A4: Sayfa başlığı | B4: Her kullanıcı sayfasının en üstünde tek ve açık sayfa başlığı | C4: A1'den başlayan koyu lacivert başlık bandı | D4: Başlıksız sayfa | E4: Başlık kapsama = %100 | F4: ZORUNLU
A5: Sekme renkleri | B5: Sayfalar işlevine göre renk kodlanır | C5: Girdi=mavi, hesap=gri, rapor=lacivert, kontrol=kırmızı, kılavuz=altın | D5: Rastgele renk | E5: Renk semantiği tutarlı | F5: ZORUNLU
A6: Kolon düzeni | B6: Veri blokları bitişik kolonlarda ilerler | C6: Gereksiz boş kolon bırakma; yalnız gerçek bölüm ayrımı varsa kontrollü boşluk | D6: A:C veri, D boş, E:F veri gibi parçalı yapı | E6: Boş kolon taraması | F6: ZORUNLU
A7: Girdi hücreleri | B7: Kullanıcının değiştireceği alan açıkça görünür | C7: Açık sarı dolgu + mavi yazı | D7: Formülle aynı görünüm | E7: Girdi/formül ayrımı | F7: ZORUNLU
A8: Formüller | B8: Hesap hücreleri kullanıcı girdisinden ayrılır | C8: Siyah yazı; sayfalar arası bağlantı yeşil yazı | D8: Hard-code gizleme | E8: Formül sınıfı kontrolü | F8: ZORUNLU
A9: Grafik sayısı | B9: Yönetici ekranında en fazla 3 ana karar grafiği | C9: Trend, karşılaştırma, köprü/dağılım; iş kararına bağlı | D9: Grafik kalabalığı | E9: Grafik başına karar sorusu | F9: ZORUNLU
A10: Grafik stili | B10: Kurumsal ve yüksek okunabilirlik | C10: Beyaz zemin, ince gridline, tek vurgu rengi, açık birim/başlık | D10: 3B, gölge, neon, gökkuşağı renkleri | E10: Görsel inceleme | F10: ZORUNLU
A11: Grafik başlığı | B11: Grafik 'neyi' değil 'ne anlama geldiğini' söyler | C11: Örn: 'Nakit 2028'de kritik eşiğin altına iniyor' | D11: 'Nakit Grafiği' gibi anlamsız başlık | E11: Başlık karar testi | F11: ZORUNLU
A12: Birimler | B12: Tüm finansal görsellerde birim açık | C12: TL, bin TL, milyon TL, %, gün, x | D12: Birim belirsizliği | E12: Birim kapsama %100 | F12: ZORUNLU
A13: Sıfır/negatif | B13: Finansal format standardı | C13: Sıfır='-', negatif kırmızı parantez | D13: -500 veya 0,00 kalabalığı | E13: Format kontrolü | F13: ZORUNLU
A14: Yazı tipi | B14: Tek aile | C14: Aptos veya Segoe UI | D14: Karışık font | E14: Tek font kontrolü | F14: ZORUNLU
... A22: Premium vitrin | B22: Görsel kalite ürün değerinin zorunlu parçasıdır | C22: Kaliteli grafik, gerçek KPI kartı, finansal hiyerarşi, tab rengi, fonksiyonel navigasyon | D22: Sadece doğru hesap yapıp çıplak/varsayılan Excel görünümü bırakmak | E22: Görsel release incelemesi | F22: ZORUNLU

Sheet 04_MUHASEBE_THP
A1: TÜRKİYE MUHASEBE VE TEKDÜZEN HESAP PLANI STANDARDI
A3: Konu | B3: Zorunlu Standart | C3: Örnek Türkçe Ad | D3: THP / Mantık | E3: Hata Riski | F3: Kontrol
A4: Dil | B4: Kullanıcıya görünen finansal terimler Türkçe | C4: Hasılat, Satışların Maliyeti, Brüt Kâr, Faaliyet Giderleri | D4: Türk işletme kullanımına uygun | E4: İngilizce jargon | F4: Terminoloji taraması
A5: Gelir Tablosu | B5: Türk sunum sırası kullanılır | C5: Net Satışlar → Satışların Maliyeti → Brüt Kâr → Faaliyet Giderleri → Faaliyet Kârı | D5: 600/610/611; 620-623; 63x | E5: Yanlış sınıflama | F5: Hesap eşleme
A6: Bilanço | B6: Dönen/Duran Varlık ve Kısa/Uzun Vadeli Yükümlülük ayrımı | C6: Hazır Değerler, Ticari Alacaklar, Stoklar, Mali Borçlar | D6: 1xx / 2xx / 3xx / 4xx / 5xx | E6: Vade sınıfı hatası | F6: Bilanço eşitliği
A7: Nakit Akışı | B7: İşletme/Yatırım/Finansman nakit akışları ayrılır | C7: Faaliyetlerden Nakit, Yatırım Harcamaları, Finansman Nakit Akışı | D7: Dolaylı/doğrudan yöntem açık seçilir | E7: Kâr = nakit sanılması | F7: Nakit devri
A8: Ticari Alacaklar | B8: Cari ve vade mantığı korunur | C8: 120 Alıcılar | D8: 120 | E8: Tahakkuk/nakit karışması | F8: Alacak devir kontrolü
A9: Ticari Borçlar | B9: Tedarikçi borcu ayrı izlenir | C9: 320 Satıcılar | D9: 320 | E9: Gider/ödeme karışması | F9: Borç devir kontrolü
A10: Kasa/Banka | B10: Hazır değerler ayrı izlenir | C10: 100 Kasa, 102 Bankalar | D10: 100 / 102 | E10: Virmanla toplam nakdin değişmesi | F10: Virman değişmezi
A11: Stok | B11: Dikeye uygun stok türü | C11: 150 İlk Madde ve Malzeme, 153 Ticari Mallar | D11: 15x | E11: Maliyet ve stok hareketinin kopması | F11: Stok devri
A12: Maddi Duran Varlık | B12: Yatırım harcaması ve amortisman bağlantılı | C12: 253 Tesis Makine Cihazlar, 255 Demirbaşlar, 257 Birikmiş Amortismanlar | D12: 25x | E12: Yatırım/gider karışması | F12: Net defter değeri devri
A13: Mali Borçlar | B13: Kısa/uzun vadeli borç ayrımı | C13: 300 Banka Kredileri / 400 Banka Kredileri | D13: 300 / 400 | E13: Vade sınıfı yanlış | F13: Borç devri
A14: Özkaynak | B14: Sermaye ve geçmiş yıl kârları ayrı | C14: 500 Sermaye, 570 Geçmiş Yıllar Kârları, 590 Dönem Net Kârı | D14: 5xx | E14: Net kâr bağının kopması | F14: Özkaynak devri
... A18: İstisna | B18: TFRS özel ürün varsa fark açık yazılır | C18: Tekdüzen raporlama ≠ TFRS finansal tablo sunumu | D18: Amaç belirtilir | E18: Standartları karıştırma | F18: Model amacı kontrolü

Sheet 05_KARAR_SATIS
A1: KARAR, GÜVEN VE SATIŞA HAZIRLIK STANDARDI
A3: Alan | B3: Müşteri Sorusu | C3: Zorunlu Ürün Davranışı | D3: Kanıt | E3: Başarısızlık Durumu | F3: Kapı
A4: 5 saniye | B4: Bu ürün neyi çözüyor? | C4: İlk ekranda hedef kullanıcı + pahalı problem + sonuç görünür | D4: Başlık + alt mesaj + gerçek ekran | E4: Ürün yalnız teknik isim | F4: HATA
A5: Acı | B5: Sorun bana neye mal oluyor? | C5: Mümkünse müşterinin kendi verisiyle parasal/zaman etkisi hesaplanır | D5: ROI/acı hesaplama yöntemi | E5: Uydurma tasarruf | F5: HATA
A6: Karar | B6: Bu bilgiyle ne yapacağım? | C6: Her kritik KPI aksiyona bağlanır | D6: KARAR_KUYRUGU | E6: Sadece rapor | F6: HATA
A7: Güven | B7: Bu sayıya neden inanayım? | C7: Kaynak, formül mantığı, kontrol ve son doğrulama görünür | D7: Kontroller + kaynak izi + sürüm | E7: Prestij kelimesi | F7: HATA
A8: Referans | B8: Müşteri yorumu yoksa ne göstereceğim? | C8: Önce/Sonra + Karar Vakası + Hata Önleme Vakası üretilir | D8: Demo/örnek çıktı | E8: Kanıtsız iddia | F8: HATA
A9: Senaryo | B9: Ne olursa işler bozulur? | C9: Baz/Aşağı/Yukarı veya uygun stres senaryosu | D9: Senaryo karşılaştırma | E9: Dekoratif senaryo | F9: HATA
A10: Ters stres | B10: Hangi eşikte karar kırılır? | C10: En az bir kritik sürücü için kırılma eşiği | D10: Kırılma eşiği tablosu | E10: Sadece +/- %10 | F10: UYARI/HATA
A11: Hata tutarlılığı | B11: Formül hata verirse ne olur? | C11: Kontrol GEÇTİ veremez; BLOKE/HATA üretir | D11: Hata taraması | E11: Hata + GEÇTİ birlikte | F11: HATA
A12: Karar motoru | B12: Ne oldu, neden oldu? | C12: Sorun + neden + parasal etki + aksiyon + son tarih | D12: Karar tablosu | E12: Boş sayfa / isim düzeyi modül | F12: HATA
A13: Yönetici özeti | B13: 5 saniyede ne görmeliyim? | C13: Bugün / ne değişti / ne bozulacak / neden / ne yapmalıyım / güven | D13: Yönetici özeti ekranı | E13: KPI kutusu yığını | F13: HATA
A14: Teklif | B14: Neden satın almalıyım? | C14: Dosya özellikleri yerine sonuç ve kaçınılan maliyet sunulur | D14: Ürün sayfası kanıt eşlemesi | E14: Özellik listesiyle satış | F14: HATA
... A19: Pazar kanıtı | B19: Piyasa gerçekten ödüyor mu? | C19: Satış/pilot/LOI/fiyat kabulü olmadan pazar doğrulandı yazılmaz | D19: Gerçek işlem kanıtı | E19: Tahmini talep = satış kabulü | F19: HATA

Sheet KAPAK
A1: KAPAK — Üretim Kârı %12,5 KV Optimizasyonu
A3: Üretim Kârı %12,5 KV Optimizasyonu
A4: Üretim hasılatı, maliyeti ve payları girin; standart KV ile indirimli %12,5 oranı karşılaştırıp UYGULA / İNCELE / UYGULAMA kararını üretin.
A6: Bu ürün ne sağlar?
A7: • Çok yıllı kural tablosu (2025/2026/2027) ile indirimli üretim KV oranına hazır motor
A8: • Üretim kârı, matrah, standart KV, indirimli KV ve tasarrufun yan yana hesabı
A9: • Baz / iyimser / kötümser + kural değişimi (indirimli oran +1 puan) senaryoları
A10: • Tebliğ tarzı altın vakalar ve KANIT_RAPORU (A4 imza)
A11: • Belirsizlik beyanı: genel yönetim / finansman pay dağıtım yorumu (A / B)
A13: Kimler için?
A14: • SMMM — indirimli KV tasarrufunu ve madde atfını müşteriye vermek
A15: • CFO — UYGULA / İNCELE / UYGULAMA kararını bütçeye yazmak
... A21: Sürüm 1.0.0 | 2026 | ExcelArşiv | Lisans: Tek kullanıcı

Sheet HIZLI_BASLANGIC
A1: HIZLI BASLANGIC — Üretim Kârı %12,5 KV Optimizasyonu
A3: Üç adımda sonuç
A5: Adım 1 — Girdiler | B5: GIRDI sayfasında yıl, hasılat, maliyet ve payları sarı hücrelere girin.
A6: Adım 2 — Karar | B6: PANO'da tasarruf tutarını ve UYGULA / İNCELE / UYGULAMA rozetini izleyin.
A7: Adım 3 — Kanıt | B7: KANIT_RAPORU'nu yazdırıp imzalayın; VAKALAR tutarlılığını kontrol edin.
A9: Sık yapılan hatalar
A10: • Genel yönetim / finansman payını üretim dışı bırakmak
A11: • İstisna tutarını matrahtan düşmeden standart oranla karşılaştırmak
A12: • Hesap yılını kural tablosuyla uyumsuz seçmek (2025 ≠ 2026 oranı)
A14: Bu dosya karar destek aracıdır; kesin vergi görüşü veya beyanname yerine geçmez.

Sheet GIRDI
A1: GIRDI — Üretim Kârı %12,5 KV Optimizasyonu
A3: Şirket ve üretim girdileri
A4: Sarı hücreler manuel giriştir. Oranlar KURALLAR'dan; tasarruf formülle üretilir.
A5: Alan | B5: Değer | C5: Birim
A6: Şirket Adı | B6: Örnek İmalat A.Ş. | C6: metin
A7: Dönem | B7: 2026 | C7: metin
A8: Hesap Yılı | B8: 2026 | C8: yıl
A9: Üretim Hasılatı [₺] | B9: 40000000 | C9: ₺
A10: Üretim Maliyeti [₺] | B10: 28000000 | C10: ₺
A11: Genel Yönetim Payı [₺] | B11: 1500000 | C11: ₺
A12: Finansman Gider Payı [₺] | B12: 500000 | C12: ₺
A13: Diğer Faaliyet Kârı [₺] | B13: 200000 | C13: ₺
A14: İstisna Tutarı [₺] | B14: 0 | C14: ₺
A15: Yorum Modu (A/B) | B15: A | C15: metin
A17: İndirimli oran (ayna) | B17: =IFERROR(INDEX(CHOOSE(MAX(1,MIN(3,IF(OR(hesapYili="",hesapYili=0),1,hesapYili-ukv_yilTaban))),tblKurallar[deger_2025],tblKurallar[deger_2026],tblKurallar[deger_2027]),MATCH("UKV-001",tblKurallar[kural_id],0)),0)
A18: Standart oran (ayna) | B18: =IFERROR(INDEX(CHOOSE(MAX(1,MIN(3,IF(OR(hesapYili="",hesapYili=0),1,hesapYili-ukv_yilTaban))),tblKurallar[deger_2025],tblKurallar[deger_2026],tblKurallar[deger_2027]),MATCH("UKV-002",tblKurallar[kural_id],0)),0)
A19: Tasarruf (ayna) [₺] | B19: =IFERROR(ukv_tasarruf,0)
A20: Giriş doluluk (kalite) | B20: =IFERROR(IF(OR(COUNTA(B6:B15)=0,ukv_girisBeklenen=0),0,ROUND(COUNTA(B6:B15)/ukv_girisBeklenen*100,0)),0)
A22: Giriş tablosu (otomasyon / boş-mod)
A23: Alan Anahtarı | B23: Değer | C23: Birim | D23: Zorunlu | E23: Kaynak | F23: Kontrol
A24: sirket_adi | B24: Örnek İmalat A.Ş. | C24: metin | D24: Evet | E24: GIRDI | F24: =IF($A24="","",IF($B24="","EKSİK","TAM"))
A25: donem | B25: 2026 | C25: metin | D25: Evet | E25: GIRDI | F25: =IF($A25="","",IF($B25="","EKSİK","TAM"))
A26: hesapYili | B26: 2026 | C26: yıl | D26: Evet | E26: GIRDI | F26: =IF($A26="","",IF($B26="","EKSİK","TAM"))
A27: uretim_hasilati | B27: 40000000 | C27: TL | D27: Evet | E27: GIRDI | F27: =IF($A27="","",IF($B27="","EKSİK","TAM"))
A28: uretim_maliyeti | B28: 28000000 | C28: TL | D28: Evet | E28: GIRDI | F28: =IF($A28="","",IF($B28="","EKSİK","TAM"))
A29: genel_yonetim_payi | B29: 1500000 | C29: TL | D29: Evet | E29: GIRDI | F29: =IF($A29="","",IF($B29="","EKSİK","TAM"))
A30: finansman_gider_payi | B30: 500000 | C30: TL | D30: Evet | E30: GIRDI | F30: =IF($A30="","",IF($B30="","EKSİK","TAM"))
A31: diger_faaliyet_kar | B31: 200000 | C31: TL | D31: Evet | E31: GIRDI | F31: =IF($A31="","",IF($B31="","EKSİK","TAM"))
A32: istisna_tutari | B32: 0 | C32: TL | D32: Evet | E32: GIRDI | F32: =IF($A32="","",IF($B32="","EKSİK","TAM"))
A33: yorum_modu | B33: A | C33: A/B | D33: Evet | E33: GIRDI | F33: =IF($A33="","",IF($B33="","EKSİK","TAM"))
F34: =IF($A34="","",IF($B34="","EKSİK","TAM"))
F35: =IF($A35="","",IF($B35="","EKSİK","TAM"))
F36: =IF($A36="","",IF($B36="","EKSİK","TAM"))
F37: =IF($A37="","",IF($B37="","EKSİK","TAM"))
F38: =IF($A38="","",IF($B38="","EKSİK","TAM"))
F39: =IF($A39="","",IF($B39="","EKSİK","TAM"))
F40: =IF($A40="","",IF($B40="","EKSİK","TAM"))
F41: =IF($A41="","",IF($B41="","EKSİK","TAM"))
F42: =IF($A42="","",IF($B42="","EKSİK","TAM"))
F43: =IF($A43="","",IF($B43="","EKSİK","TAM"))
...

Sheet KURALLAR
A1: KURALLAR — Üretim Kârı %12,5 KV Optimizasyonu
A3: Mevzuat kural tablosu (yıl yan yana)
A4: Oranlar MOTOR'da sabit yazılmaz; INDEX/MATCH ile buradan çekilir.
A6: kural_id | B6: madde | C6: kural_adi | D6: kosul_metni | E6: parametre_adi | F6: deger_2025 | G6: deger_2026 | H6: deger_2027 | I6: yururluk | J6: kaynak | K6: aktif_deger
A7: UKV-001 | B7: KVK md.32 | C7: indirimli_oran | D7: üretim kazancı | E7: uretim_kv_orani | F7: 0.2 | G7: 0.125 | H7: 0.125 | I7: 01.01.2025 | J7: Üretim faaliyetleri indirimli KV | K7: =IF($A7="","",IFERROR(CHOOSE(MAX(1,MIN(3,IF(OR(hesapYili="",hesapYili=0),1,hesapYili-ukv_yilTaban))),$F7,$G7,$H7),0))
A8: UKV-002 | B8: KVK md.32 | C8: standart_oran | D8: genel kurum kazancı | E8: kv_genel_oran | F8: 0.25 | G8: 0.25 | H8: 0.25 | I8: 01.01.2025 | J8: Genel kurumlar vergisi oranı | K8: =IF($A8="","",IFERROR(CHOOSE(MAX(1,MIN(3,IF(OR(hesapYili="",hesapYili=0),1,hesapYili-ukv_yilTaban))),$F8,$G8,$H8),0))
A9: UKV-003 | B9: İç politika | C9: uygula_esik | D9: tasarruf ≥ eşik | E9: uygula_esik_tl | F9: 100000 | G9: 100000 | H9: 100000 | I9: 01.01.2025 | J9: UYGULA karar eşiği (TL) | K9: =IF($A9="","",IFERROR(CHOOSE(MAX(1,MIN(3,IF(OR(hesapYili="",hesapYili=0),1,hesapYili-ukv_yilTaban))),$F9,$G9,$H9),0))
A10: UKV-004 | B10: İç politika | C10: incele_esik | D10: tasarruf ≥ eşik | E10: incele_esik_tl | F10: 25000 | G10: 25000 | H10: 25000 | I10: 01.01.2025 | J10: İNCELE karar eşiği (TL) | K10: =IF($A10="","",IFERROR(CHOOSE(MAX(1,MIN(3,IF(OR(hesapYili="",hesapYili=0),1,hesapYili-ukv_yilTaban))),$F10,$G10,$H10),0))
A11: UKV-005 | B11: Genel | C11: yuvarlama | D11: her hesap | E11: yuvarlama_ondalik | F11: 2 | G11: 2 | H11: 2 | I11: 01.01.2025 | J11: Uygulama notu | K11: =IF($A11="","",IFERROR(CHOOSE(MAX(1,MIN(3,IF(OR(hesapYili="",hesapYili=0),1,hesapYili-ukv_yilTaban))),$F11,$G11,$H11),0))
A14: Kural-yıl matrisi özeti
A15: İndirimli oran (aktif yıl) | B15: =IFERROR(INDEX(CHOOSE(MAX(1,MIN(3,IF(OR(hesapYili="",hesapYili=0),1,hesapYili-ukv_yilTaban))),tblKurallar[deger_2025],tblKurallar[deger_2026],tblKurallar[deger_2027]),MATCH("UKV-001",tblKurallar[kural_id],0)),0)
A16: Standart oran (aktif yıl) | B16: =IFERROR(INDEX(CHOOSE(MAX(1,MIN(3,IF(OR(hesapYili="",hesapYili=0),1,hesapYili-ukv_yilTaban))),tblKurallar[deger_2025],tblKurallar[deger_2026],tblKurallar[deger_2027]),MATCH("UKV-002",tblKurallar[kural_id],0)),0)
A17: Matris metni | B17: =IFERROR(_xlfn.TEXTJOIN(" | ",TRUE,"UKV-001=",TEXT(B15,"0.0%"),"UKV-002=",TEXT(B16,"0.0%"),"yıl=",IF(OR(hesapYili="",hesapYili=0),"-",hesapYili)),"-")

Sheet MOTOR
A1: MOTOR — Üretim Kârı %12,5 KV Optimizasyonu
A3: Hesap zinciri — her adımda kural_id
A4: Oranlar tblKurallar'dan çekilir; sabit oran yoktur.
A6: adim | B6: ad | C6: formul | D6: birim | E6: ne_ise_yarar | F6: kural_id | G6: deger
A7: 1 | B7: Hesap yılı oku | C7: =IFERROR(hesapYili,0) | D7: yıl | E7: Aktif mevzuat yılı | F7: UKV-005 | G7: =IFERROR(hesapYili,0)
A8: 2 | B8: İndirimli oran | C8: =IFERROR(INDEX(CHOOSE(MAX(1,MIN(3,IF(OR(hesapYili="",hesapYili=0),1,hesapYili-ukv_yilTaban))),tblKurallar[deger_2025],tblKurallar[deger_2026],tblKurallar[deger_2027]),MATCH("UKV-001",tblKurallar[kural_id],0)),0) | D8: oran | E8: Üretim KV indirimli oran | F8: UKV-001 | G8: =IFERROR(INDEX(CHOOSE(MAX(1,MIN(3,IF(OR(hesapYili="",hesapYili=0),1,hesapYili-ukv_yilTaban))),tblKurallar[deger_2025],tblKurallar[deger_2026],tblKurallar[deger_2027]),MATCH("UKV-001",tblKurallar[kural_id],0)),0)
A9: 3 | B9: Standart oran | C9: =IFERROR(INDEX(CHOOSE(MAX(1,MIN(3,IF(OR(hesapYili="",hesapYili=0),1,hesapYili-ukv_yilTaban))),tblKurallar[deger_2025],tblKurallar[deger_2026],tblKurallar[deger_2027]),MATCH("UKV-002",tblKurallar[kural_id],0)),0) | D9: oran | E9: Genel KV oranı | F9: UKV-002 | G9: =IFERROR(INDEX(CHOOSE(MAX(1,MIN(3,IF(OR(hesapYili="",hesapYili=0),1,hesapYili-ukv_yilTaban))),tblKurallar[deger_2025],tblKurallar[deger_2026],tblKurallar[deger_2027]),MATCH("UKV-002",tblKurallar[kural_id],0)),0)
A10: 4 | B10: Uygula eşiği | C10: =IFERROR(INDEX(CHOOSE(MAX(1,MIN(3,IF(OR(hesapYili="",hesapYili=0),1,hesapYili-ukv_yilTaban))),tblKurallar[deger_2025],tblKurallar[deger_2026],tblKurallar[deger_2027]),MATCH("UKV-003",tblKurallar[kural_id],0)),0) | D10: TL | E10: UYGULA tasarruf eşiği | F10: UKV-003 | G10: =IFERROR(INDEX(CHOOSE(MAX(1,MIN(3,IF(OR(hesapYili="",hesapYili=0),1,hesapYili-ukv_yilTaban))),tblKurallar[deger_2025],tblKurallar[deger_2026],tblKurallar[deger_2027]),MATCH("UKV-003",tblKurallar[kural_id],0)),0)
A11: 5 | B11: İncele eşiği | C11: =IFERROR(INDEX(CHOOSE(MAX(1,MIN(3,IF(OR(hesapYili="",hesapYili=0),1,hesapYili-ukv_yilTaban))),tblKurallar[deger_2025],tblKurallar[deger_2026],tblKurallar[deger_2027]),MATCH("UKV-004",tblKurallar[kural_id],0)),0) | D11: TL | E11: İNCELE tasarruf eşiği | F11: UKV-004 | G11: =IFERROR(INDEX(CHOOSE(MAX(1,MIN(3,IF(OR(hesapYili="",hesapYili=0),1,hesapYili-ukv_yilTaban))),tblKurallar[deger_2025],tblKurallar[deger_2026],tblKurallar[deger_2027]),MATCH("UKV-004",tblKurallar[kural_id],0)),0)
A12: 6 | B12: Yuvarlama ondalık | C12: =IFERROR(INDEX(CHOOSE(MAX(1,MIN(3,IF(OR(hesapYili="",hesapYili=0),1,hesapYili-ukv_yilTaban))),tblKurallar[deger_2025],tblKurallar[deger_2026],tblKurallar[deger_2027]),MATCH("UKV-005",tblKurallar[kural_id],0)),0) | D12: adet | E12: Yuvarlama basamağı | F12: UKV-005 | G12: =IFERROR(INDEX(CHOOSE(MAX(1,MIN(3,IF(OR(hesapYili="",hesapYili=0),1,hesapYili-ukv_yilTaban))),tblKurallar[deger_2025],tblKurallar[deger_2026],tblKurallar[deger_2027]),MATCH("UKV-005",tblKurallar[kural_id],0)),0)
A13: 7 | B13: Üretim hasılatı | C13: =IFERROR(GIRDI!B9,0) | D13: TL | E13: Üretim hasılatı | F13: UKV-001 | G13: =IFERROR(GIRDI!B9,0)
A14: 8 | B14: Üretim maliyeti | C14: =IFERROR(GIRDI!B10,0) | D14: TL | E14: Üretim maliyeti | F14: UKV-001 | G14: =IFERROR(GIRDI!B10,0)
A15: 9 | B15: Genel yönetim payı | C15: =IFERROR(GIRDI!B11,0) | D15: TL | E15: GY payı | F15: UKV-001 | G15: =IFERROR(GIRDI!B11,0)
A16: 10 | B16: Finansman gider payı | C16: =IFERROR(GIRDI!B12,0) | D16: TL | E16: FG payı | F16: UKV-001 | G16: =IFERROR(GIRDI!B12,0)
A17: 11 | B17: Diğer faaliyet kârı | C17: =IFERROR(GIRDI!B13,0) | D17: TL | E17: Diğer kâr/zarar | F17: UKV-001 | G17: =IFERROR(GIRDI!B13,0)
A18: 12 | B18: İstisna tutarı | C18: =IFERROR(GIRDI!B14,0) | D18: TL | E18: İstisna | F18: UKV-001 | G18: =IFERROR(GIRDI!B14,0)
A19: 13 | B19: Pay çarpanı (yorum) | C19: =IFERROR(IF(GIRDI!B15="B",1+ukv_payArtisOran,1),0) | D19: çarpan | E19: Yorum A/B pay çarpanı | F19: UKV-005 | G19: =IFERROR(IF(GIRDI!B15="B",1+ukv_payArtisOran,1),0)
A20: 14 | B20: GY efektif | C20: =IFERROR(G15*G19,0) | D20: TL | E20: Yorum sonrası GY | F20: UKV-001 | G20: =IFERROR(G15*G19,0)
A21: 15 | B21: FG efektif | C21: =IFERROR(G16*G19,0) | D21: TL | E21: Yorum sonrası FG | F21: UKV-001 | G21: =IFERROR(G16*G19,0)
A22: 16 | B22: Üretim kârı | C22: =IFERROR(G13-G14-G20-G21,0) | D22: TL | E22: Hasılat−maliyet−paylar | F22: UKV-001 | G22: =IFERROR(G13-G14-G20-G21,0)
A23: 17 | B23: Matrah | C23: =IFERROR(ROUND(MAX(0,G22+G17-G18),MAX(0,MIN(ukv_yuvarMax,IFERROR(N(G12),0)))),0) | D23: TL | E23: Vergiye tabi matrah | F23: UKV-001 | G23: =IFERROR(ROUND(MAX(0,G22+G17-G18),MAX(0,MIN(ukv_yuvarMax,IFERROR(N(G12),0)))),0)
A24: 18 | B24: Standart KV | C24: =IFERROR(ROUND(G23*G9,MAX(0,MIN(ukv_yuvarMax,IFERROR(N(G12),0)))),0) | D24: TL | E24: Matrah × standart oran | F24: UKV-002 | G24: =IFERROR(ROUND(G23*G9,MAX(0,MIN(ukv_yuvarMax,IFERROR(N(G12),0)))),0)
A25: 19 | B25: İndirimli KV | C25: =IFERROR(ROUND(G23*G8,MAX(0,MIN(ukv_yuvarMax,IFERROR(N(G12),0)))),0) | D25: TL | E25: Matrah × indirimli oran | F25: UKV-001 | G25: =IFERROR(ROUND(G23*G8,MAX(0,MIN(ukv_yuvarMax,IFERROR(N(G12),0)))),0)
A26: 20 | B26: Tasarruf | C26: =IFERROR(G24-G25,0) | D26: TL | E26: Standart − indirimli | F26: UKV-001 | G26: =IFERROR(G24-G25,0)
A27: 21 | B27: Oran farkı | C27: =IFERROR(G9-G8,0) | D27: oran | E27: Standart − indirimli puan | F27: UKV-001 | G27: =IFERROR(G9-G8,0)
A28: 22 | B28: Tasarruf (pano) | C28: =IFERROR(G26,0) | D28: TL | E28: Tasarruf ayna | F28: UKV-001 | G28: =IFERROR(G26,0)
A29: 23 | B29: Matrah (pano) | C29: =IFERROR(G23,0) | D29: TL | E29: Matrah ayna | F29: UKV-001 | G29: =IFERROR(G23,0)
A30: 24 | B30: İndirimli KV (pano) | C30: =IFERROR(G25,0) | D30: TL | E30: İndirimli ayna | F30: UKV-001 | G30: =IFERROR(G25,0)
A31: 25 | B31: Üretim kâr / hasılat | C31: =IFERROR(IF(G13=0,0,G22/G13),0) | D31: oran | E31: Marj göstergesi | F31: UKV-001 | G31: =IFERROR(IF(G13=0,0,G22/G13),0)
A32: 26 | B32: İstisna / matrah brüt | C32: =IFERROR(IF(G22+G17=0,0,G18/MAX(1,G22+G17)),0) | D32: oran | E32: İstisna yoğunluğu | F32: UKV-001 | G32: =IFERROR(IF(G22+G17=0,0,G18/MAX(1,G22+G17)),0)
A33: 27 | B33: Karar kodu | C33: =IFERROR(IF(COUNTA(tblGirdi[Alan Anahtarı])=0,"VERI_YOK",IF(G26>=G10,"UYGULA",IF(G26>=G11,"INCELE","UYGULAMA"))),"") | D33: kod | E33: Karar kodu | F33: UKV-005 | G33: =IFERROR(IF(COUNTA(tblGirdi[Alan Anahtarı])=0,"VERI_YOK",IF(G26>=G10,"UYGULA",IF(G26>=G11,"INCELE","UYGULAMA"))),"")
A34: 28 | B34: Karar metni | C34: =IFERROR(IF(G33="VERI_YOK","VERİ YOK",IF(G33="UYGULA","UYGULA",IF(G33="INCELE","İNCELE","UYGULAMA"))),"") | D34: metin | E34: Kullanıcıya karar | F34: UKV-005 | G34: =IFERROR(IF(G33="VERI_YOK","VERİ YOK",IF(G33="UYGULA","UYGULA",IF(G33="INCELE","İNCELE","UYGULAMA"))),"")
A35: 29 | B35: Gerekçe | C35: =IFERROR(IF(G33="VERI_YOK","Giriş tablosu boş — hesap yapılamaz.",IF(G33="UYGULA","Tasarruf uygula eşiğinin üzerinde; indirimli üretim KV oranını uygulayın AND kanıt dosyalayın.",IF(G33="INCELE","Tasarruf incele bandında; pay dağıtımı AND istisna dayanağını gözden geçirin.","Tasarruf eşik altında veya matrah yok; indirimli oran uygulaması öncelikli değil."))),"") | D35: metin | E35: Gerekçe cümlesi | F35: UKV-005 | G35: =IFERROR(IF(G33="VERI_YOK","Giriş tablosu boş — hesap yapılamaz.",IF(G33="UYGULA","Tasarruf uygula eşiğinin üzerinde; indirimli üretim KV oranını uygulayın AND kanıt dosyalayın.",IF(G33="INCELE","Tasarruf incele bandında; pay dağıtımı AND istisna dayanağını gözden geçirin.","Tasarruf eşik altında veya matrah yok; indirimli oran uygulaması öncelikli değil."))),"")
A36: 30 | B36: Tasarruf / standart KV | C36: =IFERROR(IF(G24=0,0,G26/G24),0) | D36: oran | E36: Tasarruf oranı | F36: UKV-002 | G36: =IFERROR(IF(G24=0,0,G26/G24),0)
A37: 31 | B37: Efektif oran | C37: =IFERROR(IF(G23=0,0,G25/G23),0) | D37: oran | E37: Ödenen efektif | F37: UKV-001 | G37: =IFERROR(IF(G23=0,0,G25/G23),0)
A38: 32 | B38: Güven skoru | C38: =IFERROR(ROUND(IF(OR(COUNTA(GIRDI!B6:B15)=0,ukv_girisBeklenen=0),0,COUNTA(GIRDI!B6:B15)/ukv_girisBeklenen*100),0),0) | D38: puan | E38: Giriş bütünlüğü | F38: UKV-005 | G38: =IFERROR(ROUND(IF(OR(COUNTA(GIRDI!B6:B15)=0,ukv_girisBeklenen=0),0,COUNTA(GIRDI!B6:B15)/ukv_girisBeklenen*100),0),0)
A39: 33 | B39: Risk skoru | C39: =IFERROR(IF(G33="VERI_YOK",0,IF(G33="UYGULA",ukv_riskDusuk,IF(G33="INCELE",ukv_riskOrta,ukv_riskYuksek))),0) | D39: puan | E39: Kaçırma riski (ters) | F39: UKV-005 | G39: =IFERROR(IF(G33="VERI_YOK",0,IF(G33="UYGULA",ukv_riskDusuk,IF(G33="INCELE",ukv_riskOrta,ukv_riskYuksek))),0)
A40: 34 | B40: Senaryo iyimser matrah | C40: =IFERROR(G23*ukv_senaryoIyi,0) | D40: TL | E40: İyimser matrah | F40: UKV-001 | G40: =IFERROR(G23*ukv_senaryoIyi,0)
A41: 35 | B41: Senaryo kötümser matrah | C41: =IFERROR(G23*ukv_senaryoKotu,0) | D41: TL | E41: Kötümser matrah | F41: UKV-001 | G41: =IFERROR(G23*ukv_senaryoKotu,0)
A42: 36 | B42: İyimser tasarruf | C42: =IFERROR(ROUND(G40*(G9-G8),MAX(0,MIN(ukv_yuvarMax,IFERROR(N(G12),0)))),0) | D42: TL | E42: İyimser tasarruf | F42: UKV-001 | G42: =IFERROR(ROUND(G40*(G9-G8),MAX(0,MIN(ukv_yuvarMax,IFERROR(N(G12),0)))),0)
...

Sheet SENARYO
A1: SENARYO — Üretim Kârı %12,5 KV Optimizasyonu
A3: Senaryo ve duyarlılık
A5: Senaryo | B5: Matrah Çarpanı | C5: Matrah | D5: Tasarruf | E5: Karar | G5: TasarrufDemo
A6: İyimser | B6: =IFERROR(ukv_senaryoIyi+N(GIRDI!B9)*ukv_sifirCarpan,0) | C6: =IFERROR(MOTOR!G40,0) | D6: =IFERROR(MOTOR!G42,0) | E6: =IF(COUNTA(tblGirdi[Alan Anahtarı])=0,"VERİ YOK",IF(D6>=MOTOR!G10,"UYGULA",IF(D6>=MOTOR!G11,"İNCELE","UYGULAMA"))) | G6: 1402500
A7: Baz | B7: =IFERROR(ukv_bazCarpan+N(GIRDI!B9)*ukv_sifirCarpan,ukv_bazCarpan) | C7: =IFERROR(ukv_matrah,0) | D7: =IFERROR(ukv_tasarruf,0) | E7: =IF(COUNTA(tblGirdi[Alan Anahtarı])=0,"VERİ YOK",IFERROR(ukv_kararMetni,"-")) | G7: 1275000
A8: Kötümser | B8: =IFERROR(ukv_senaryoKotu+N(GIRDI!B9)*ukv_sifirCarpan,0) | C8: =IFERROR(MOTOR!G41,0) | D8: =IFERROR(MOTOR!G43,0) | E8: =IF(COUNTA(tblGirdi[Alan Anahtarı])=0,"VERİ YOK",IF(D8>=MOTOR!G10,"UYGULA",IF(D8>=MOTOR!G11,"İNCELE","UYGULAMA"))) | G8: 1083750
A9: M-SEN oran+1 | B9: =IFERROR(ukv_bazCarpan+N(GIRDI!B9)*ukv_sifirCarpan,ukv_bazCarpan) | C9: =IFERROR(ukv_matrah,0) | D9: =IFERROR(MOTOR!G46,0) | E9: =IF(COUNTA(tblGirdi[Alan Anahtarı])=0,"VERİ YOK",IF(D9>=MOTOR!G10,"UYGULA",IF(D9>=MOTOR!G11,"İNCELE","UYGULAMA"))) | G9: 1147500
A11: Senaryo bant genişliği (iyimser−kötümser tasarruf) | B11: =IFERROR(D6-D8,0)
A12: Senaryo yorumu | B12: =IFERROR(_xlfn.TEXTJOIN("; ",TRUE,"İyimser tasarruf ",TEXT(D6,"₺ #,##0")," · Baz ",TEXT(D7,"₺ #,##0")," · Kötümser ",TEXT(D8,"₺ #,##0")," · Bant ",TEXT(B11,"₺ #,##0")),"-")
A14: Duyarlılık (tornado)
A15: Değişken | B15: Etki [₺] | C15: Sıra | E15: EtkiDemo
A16: Tornado hasılat etkisi | B16: =IFERROR(MOTOR!G49,0) | C16: =IFERROR(IF(B16>=MAX(B16:B18),ukv_siraBir,IF(B16>=MIN(B16:B18)+ABS(B16-B17),ukv_siraIki,ukv_siraUc)),ukv_siraUc) | E16: 250000
A17: Tornado maliyet etkisi | B17: =IFERROR(MOTOR!G50,0) | C17: =IFERROR(IF(B17>=MAX(B16:B18),ukv_siraBir,IF(B17=MEDIAN(B16:B18),ukv_siraIki,ukv_siraUc)),ukv_siraUc) | E17: 180000
A18: Tornado oran etkisi | B18: =IFERROR(MOTOR!G51,0) | C18: =IFERROR(IF(B18>=MAX(B16:B18),ukv_siraBir,IF(B18=MEDIAN(B16:B18),ukv_siraIki,ukv_siraUc)),ukv_siraUc) | E18: 127500
A19: Duyarlılık sıra özeti | B19: =IFERROR(CONCATENATE("1)",INDEX(A16:A18,MATCH(ukv_siraBir,C16:C18,0))," 2)",INDEX(A16:A18,MATCH(ukv_siraIki,C16:C18,0))),"-")
A20: Duyarlılık yorumu | B20: =_xlfn.TEXTJOIN("; ",TRUE,"En yüksek etki ",TEXT(MAX(B16:B18),"₺ #,##0")," TL — öncelik bu değişkende")
A22: M-SEN kural değişimi tasarruf | B22: =D9
A23: M-SEN yorumu | B23: =_xlfn.TEXTJOIN("; ",TRUE,"İndirimli oran +1 puan senaryosunda tasarruf ",TEXT(D9,"₺ #,##0")," TL")
A25: Tahmin aralığı (tasarruf) | B25: =MOTOR!G48 | C25: =IFERROR(MOTOR!G26,0) | D25: =MOTOR!G47
A26: Tahmin (AVERAGE)
A27: Seri nokta | D27: TrendDemo
A28: 1 | B28: =D6 | D28: 1402500
A29: 2 | B29: =D7 | D29: 1275000
A30: 3 | B30: =D8 | D30: 1083750
A31: 4 | B31: =D9 | D31: 1147500
A32: Tahmin sonraki | B32: =IFERROR(AVERAGE(B28:B31),0)
A33: Tahmin yorumu | B33: =_xlfn.TEXTJOIN("; ",TRUE,"Tahmin ",TEXT(B32,"₺ #,##0")," · Alt ",TEXT(B25,"₺ #,##0")," · Üst ",TEXT(D25,"₺ #,##0"))

Sheet VAKALAR
A1: VAKALAR — Üretim Kârı %12,5 KV Optimizasyonu
A3: Tebliğ tarzı altın vakalar
A5: vaka_id | B5: aciklama | C5: girdi_ozeti | D5: beklenen_sonuc | E5: hesaplanan | F5: fark | G5: durum | H5: kaynak | J5: BeklenenDemo | K5: HesapDemo
A6: V-001 | B6: Matrah × indirimli oran | C6: matrah=vaka_matrah_1; oran=UKV-001(2026) | D6: 125000 | E6: =IFERROR(ROUND(vaka_matrah_1*INDEX(tblKurallar[deger_2026],MATCH("UKV-001",tblKurallar[kural_id],0)),2),0) | F6: =IF($A6="","",IFERROR($D6-$E6,0)) | G6: =IF($A6="","",IFERROR(IF(ABS($F6)<=ukv_tolerans,"TUTARLI","KIRIK"),"KIRIK")) | H6: KVK md.32 indirimli | J6: 125000 | K6: 125000
A7: V-002 | B7: Matrah × standart oran | C7: matrah=vaka_matrah_1; oran=UKV-002 | D7: 250000 | E7: =IFERROR(ROUND(vaka_matrah_1*INDEX(tblKurallar[deger_2025],MATCH("UKV-002",tblKurallar[kural_id],0)),2),0) | F7: =IF($A7="","",IFERROR($D7-$E7,0)) | G7: =IF($A7="","",IFERROR(IF(ABS($F7)<=ukv_tolerans,"TUTARLI","KIRIK"),"KIRIK")) | H7: KVK md.32 standart | J7: 250000 | K7: 250000
A8: V-003 | B8: Tasarruf = standart − indirimli | C8: V-002 − V-001 | D8: 125000 | E8: =IFERROR(ROUND(vaka_matrah_1*INDEX(tblKurallar[deger_2025],MATCH("UKV-002",tblKurallar[kural_id],0))-vaka_matrah_1*INDEX(tblKurallar[deger_2026],MATCH("UKV-001",tblKurallar[kural_id],0)),2),0) | F8: =IF($A8="","",IFERROR($D8-$E8,0)) | G8: =IF($A8="","",IFERROR(IF(ABS($F8)<=ukv_tolerans,"TUTARLI","KIRIK"),"KIRIK")) | H8: Tasarruf farkı | J8: 125000 | K8: 125000
A9: V-004 | B9: Küçük matrah × indirimli | C9: matrah=vaka_matrah_2; oran=UKV-001(2026) | D9: 25000 | E9: =IFERROR(ROUND(vaka_matrah_2*INDEX(tblKurallar[deger_2026],MATCH("UKV-001",tblKurallar[kural_id],0)),2),0) | F9: =IF($A9="","",IFERROR($D9-$E9,0)) | G9: =IF($A9="","",IFERROR(IF(ABS($F9)<=ukv_tolerans,"TUTARLI","KIRIK"),"KIRIK")) | H9: UKV-001 küçük matrah | J9: 25000 | K9: 25000
A12: Vaka durum özeti | B12: =IFERROR(IF(COUNTIF(tblVakalar[durum],"KIRIK")>0,"KIRIK","TUTARLI"),"KIRIK")
A13: Vaka fark toplamı | B13: =IFERROR(SUM(tblVakalar[fark]),0)

Sheet KANIT_RAPORU
A1: KANIT RAPORU — Üretim Kârı %12,5 KV Optimizasyonu
A3: KANIT RAPORU — Üretim Kârı %12,5 KV
A4: Rapor tarihi | B4: =raporTarihi
A5: Şirket | B5: =GIRDI!B6
A6: Dönem / yıl | B6: =CONCATENATE(GIRDI!B7," / ",hesapYili)
A8: Girdi özeti
A9: Üretim hasılatı | B9: =GIRDI!B9
A10: Üretim maliyeti | B10: =GIRDI!B10
A11: Genel yönetim payı | B11: =GIRDI!B11
A12: Finansman gider payı | B12: =GIRDI!B12
A13: Diğer faaliyet kârı | B13: =GIRDI!B13
A14: İstisna tutarı | B14: =GIRDI!B14
A16: Hesap zinciri
A17: Matrah | B17: =ukv_matrah
A18: Standart KV | B18: =MOTOR!G24
A19: İndirimli KV | B19: =MOTOR!G25
A20: Tasarruf | B20: =ukv_tasarruf
A21: KARAR | B21: =ukv_kararMetni
A22: Gerekçe | B22: =ukv_kararGerekce
A24: Madde atıfları | B24: =ukv_maddeAtifMetni
A26: Kanıt gövdesi | B26: =ukv_kanitRaporu
A28: Parmak izi (SHA-256 kısaltma) | B28: =ukv_parmakIzi
A30: Hazırlayan (imza)
A31: Onaylayan (imza)
A33: Uyarı: Bu çıktı karar destektir; kesin vergi sonucu veya hukuki görüş değildir. Sürüm 1.0.0.

Sheet KONTROLLER
A1: KONTROLLER — Üretim Kârı %12,5 KV Optimizasyonu
A3: Canlı kontrol paneli
A5: Giriş tablosu boş mu? | B5: =IF(COUNTA(tblGirdi[Alan Anahtarı])=0,"BOŞ","DOLU")
A6: Negatif hasılat? | B6: =IF(GIRDI!B9<0,"NEGATİF","TEMİZ")
A7: Hesap yılı geçerli mi? | B7: =IFERROR(IF(AND(N(hesapYili)>N(ukv_yilTaban),N(hesapYili)<=N(ukv_yilTaban)+3),"TEMİZ","HATALI"),"HATALI")
A8: Matrah sıfır mı? | B8: =IF(IFERROR(MOTOR!G23,0)=0,"SIFIR","NORMAL")
A9: Vaka kırık mı? | B9: =IFERROR(IF(COUNTIF(tblVakalar[durum],"KIRIK")>0,"KIRIK","TUTARLI"),"KIRIK")
A10: Tasarruf eşiği aşıyor mu? | B10: =IF(IFERROR(MOTOR!G26,0)>ukv_kacirilanEsik+N(GIRDI!B9)*ukv_sifirCarpan,"AŞIYOR","NORMAL")
A11: Yorum A/B seçili mi? | B11: =IF(OR(GIRDI!B15="A",GIRDI!B15="B"),"TEMİZ","EKSİK")
A12: Kalite skoru (modül) | B12: =IFERROR(ROUND(IF(OR(B14=0,B14=""),0,B15/B14*100),0),0)
A14: Toplam giriş alanı | B14: =IFERROR(ukv_girisBeklenen+COUNTA(GIRDI!B6:B15)*0,0)
A15: Dolu giriş | B15: =COUNTA(GIRDI!B6:B15)
A17: Matrah kontrol | B17: =IFERROR(ukv_matrah,0)
A18: Tasarruf kontrol | B18: =IFERROR(ukv_tasarruf,0)
A19: Karar kontrol | B19: =IFERROR(ukv_kararMetni,"-")

Sheet ORNEK_VERI
A1: ORNEK VERI — Üretim Kârı %12,5 KV Optimizasyonu
A3: Örnek senaryo kütüphanesi
A4: Bu sayfa demo değerleri saklar; GIRDI'ye kopyalanabilir.
A5: Senaryo | B5: Hasılat | C5: Maliyet | D5: GY Payı | E5: FG Payı | F5: Diğer | G5: İstisna | H5: Yıl | I5: Üretim Kârı | L5: KarDemo
A6: Demo ana | B6: 40000000 | C6: 28000000 | D6: 1500000 | E6: 500000 | F6: 200000 | G6: 0 | H6: 2026 | I6: =IF($A6="","",IFERROR($B6-$C6-$D6-$E6,0)) | L6: 10000000
A7: Yüksek marj | B7: 50000000 | C7: 30000000 | D7: 1000000 | E7: 400000 | F7: 0 | G7: 0 | H7: 2026 | I7: =IF($A7="","",IFERROR($B7-$C7-$D7-$E7,0)) | L7: 18600000
A8: Düşük tasarruf | B8: 12000000 | C8: 10500000 | D8: 800000 | E8: 300000 | F8: 0 | G8: 0 | H8: 2026 | I8: =IF($A8="","",IFERROR($B8-$C8-$D8-$E8,0)) | L8: 400000
A9: 2025 geçiş oranı | B9: 40000000 | C9: 28000000 | D9: 1500000 | E9: 500000 | F9: 200000 | G9: 0 | H9: 2025 | I9: =IF($A9="","",IFERROR($B9-$C9-$D9-$E9,0)) | L9: 10000000
A10: İstisna yoğun | B10: 40000000 | C10: 28000000 | D10: 1500000 | E10: 500000 | F10: 200000 | G10: 5000000 | H10: 2026 | I10: =IF($A10="","",IFERROR($B10-$C10-$D10-$E10,0)) | L10: 10000000
I11: =IF($A11="","",IFERROR($B11-$C11-$D11-$E11,0))
I12: =IF($A12="","",IFERROR($B12-$C12-$D12-$E12,0))
I13: =IF($A13="","",IFERROR($B13-$C13-$D13-$E13,0))
I14: =IF($A14="","",IFERROR($B14-$C14-$D14-$E14,0))
I15: =IF($A15="","",IFERROR($B15-$C15-$D15-$E15,0))
I16: =IF($A16="","",IFERROR($B16-$C16-$D16-$E16,0))
I17: =IF($A17="","",IFERROR($B17-$C17-$D17-$E17,0))
I18: =IF($A18="","",IFERROR($B18-$C18-$D18-$E18,0))
I19: =IF($A19="","",IFERROR($B19-$C19-$D19-$E19,0))
I20: =IF($A20="","",IFERROR($B20-$C20-$D20-$E20,0))
I21: =IF($A21="","",IFERROR($B21-$C21-$D21-$E21,0))
I22: =IF($A22="","",IFERROR($B22-$C22-$D22-$E22,0))
... I1004: =IF($A1004="","",IFERROR($B1004-$C1004-$D1004-$E1004,0))

Sheet LISTELER
A1: LISTELER — Üretim Kârı %12,5 KV Optimizasyonu
A3: Doğrulama listeleri
A5: Yıllar | C5: Yorum A/B | E5: Evet/Hayır
A6: 2025 | C6: A | E6: Evet
A7: 2026 | C7: B | E7: Hayır
A8: 2027

Sheet AYARLAR
A1: AYARLAR — Üretim Kârı %12,5 KV Optimizasyonu
A3: Parametreler (tek kaynak)
A5: anahtar | B5: deger | C5: birim | D5: aciklama | E5: kaynak | F5: yururluk_tarihi | G5: dogrulama_tarihi | H5: kontrol
A6: hesapYili | B6: 2026 | C6: yıl | D6: Aktif hesap yılı | E6: Kullanıcı / GIRDI | F6: 01.01.2025 | G6: 11.08.2026 | H6: =IF(A6="","",IF(B6="","EKSİK","TAM"))
A7: raporTarihi | B7: 46245 | C7: tarih | D7: Rapor tarihi (sabit) | E7: Üretim | F7: 01.01.2025 | G7: 11.08.2026 | H7: =IF(A7="","",IF(B7="","EKSİK","TAM"))
A8: ukv_tolerans | B8: 0.01 | C8: TL | D8: Vaka tutarlılık toleransı | E8: Uygulama notu | F8: 01.01.2025 | G8: 11.08.2026 | H8: =IF(A8="","",IF(B8="","EKSİK","TAM"))
A9: ukv_kacirilanEsik | B9: 50000 | C9: TL | D9: PANO tasarruf uyarı eşiği | E9: İç politika | F9: 01.01.2025 | G9: 11.08.2026 | H9: =IF(A9="","",IF(B9="","EKSİK","TAM"))
A10: ukv_senaryoIyi | B10: 1.1 | C10: çarpan | D10: İyimser matrah çarpanı | E10: Model varsayımı | F10: 01.01.2025 | G10: 11.08.2026 | H10: =IF(A10="","",IF(B10="","EKSİK","TAM"))
A11: ukv_senaryoKotu | B11: 0.85 | C11: çarpan | D11: Kötümser matrah çarpanı | E11: Model varsayımı | F11: 01.01.2025 | G11: 11.08.2026 | H11: =IF(A11="","",IF(B11="","EKSİK","TAM"))
A12: ukv_oranArtisPuan | B12: 0.01 | C12: oran | D12: M-SEN sabit +1 puan | E12: Senaryo motoru | F12: 01.01.2025 | G12: 11.08.2026 | H12: =IF(A12="","",IF(B12="","EKSİK","TAM"))
A13: ukv_tahminAlt | B13: 0.85 | C13: çarpan | D13: Tahmin alt bant | E13: Model varsayımı | F13: 01.01.2025 | G13: 11.08.2026 | H13: =IF(A13="","",IF(B13="","EKSİK","TAM"))
A14: ukv_tahminUst | B14: 1.15 | C14: çarpan | D14: Tahmin üst bant | E14: Model varsayımı | F14: 01.01.2025 | G14: 11.08.2026 | H14: =IF(A14="","",IF(B14="","EKSİK","TAM"))
A15: ukv_tornadoHasilat | B15: 1.05 | C15: çarpan | D15: Tornado hasılat şoku | E15: Model varsayımı | F15: 01.01.2025 | G15: 11.08.2026 | H15: =IF(A15="","",IF(B15="","EKSİK","TAM"))
A16: ukv_tornadoMaliyet | B16: 1.05 | C16: çarpan | D16: Tornado maliyet şoku | E16: Model varsayımı | F16: 01.01.2025 | G16: 11.08.2026 | H16: =IF(A16="","",IF(B16="","EKSİK","TAM"))
A17: ukv_payArtisOran | B17: 0.1 | C17: oran | D17: Yorum B pay +%10 | E17: Pay dağıtım modeli | F17: 01.01.2025 | G17: 11.08.2026 | H17: =IF(A17="","",IF(B17="","EKSİK","TAM"))
A18: ukv_yuzdelikOran | B18: 0.9 | C18: oran | D18: Yüzdelik P90 | E18: İstatistik | F18: 01.01.2025 | G18: 11.08.2026 | H18: =IF(A18="","",IF(B18="","EKSİK","TAM"))
A19: ukv_parmakIzi | B19: e4c3ab8520ec79b5 | C19: metin | D19: Dosya parmak izi etiketi | E19: Üretim | F19: 01.01.2025 | G19: 11.08.2026 | H19: =IF(A19="","",IF(B19="","EKSİK","TAM"))
A20: dosya_surumu | B20: 1.0.0 | C20: metin | D20: Ürün sürümü | E20: ExcelArşiv | F20: 01.01.2025 | G20: 11.08.2026 | H20: =IF(A20="","",IF(B20="","EKSİK","TAM"))
A21: ukv_girisBeklenen | B21: 10 | C21: adet | D21: Zorunlu giriş alanı sayısı | E21: Ürün mimarisi | F21: 01.01.2025 | G21: 11.08.2026 | H21: =IF(A21="","",IF(B21="","EKSİK","TAM"))
A22: ukv_riskDusuk | B22: 15 | C22: puan | D22: UYGULA risk skoru | E22: İç politika | F22: 01.01.2025 | G22: 11.08.2026 | H22: =IF(A22="","",IF(B22="","EKSİK","TAM"))
A23: ukv_riskOrta | B23: 55 | C23: puan | D23: İNCELE risk skoru | E23: İç politika | F23: 01.01.2025 | G23: 11.08.2026 | H23: =IF(A23="","",IF(B23="","EKSİK","TAM"))
A24: ukv_riskYuksek | B24: 85 | C24: puan | D24: UYGULAMA risk skoru | E24: İç politika | F24: 01.01.2025 | G24: 11.08.2026 | H24: =IF(A24="","",IF(B24="","EKSİK","TAM"))
A25: ukv_riskEsikOran | B25: 0.5 | C25: oran | D25: Yedek risk oranı | E25: İç politika | F25: 01.01.2025 | G25: 11.08.2026 | H25: =IF(A25="","",IF(B25="","EKSİK","TAM"))
A26: ukv_yilTaban | B26: 2024 | C26: yıl | D26: CHOOSE yıl tabanı (hesapYili−taban) | E26: Ürün mimarisi | F26: 01.01.2025 | G26: 11.08.2026 | H26: =IF(A26="","",IF(B26="","EKSİK","TAM"))
A27: ukv_yuvarMax | B27: 10 | C27: adet | D27: ROUND basamak tavanı | E27: Ürün mimarisi | F27: 01.01.2025 | G27: 11.08.2026 | H27: =IF(A27="","",IF(B27="","EKSİK","TAM"))
A28: ukv_dayanakCarpan | B28: 10 | C28: adet | D28: Yedek çarpan | E28: Ürün mimarisi | F28: 01.01.2025 | G28: 11.08.2026 | H28: =IF(A28="","",IF(B28="","EKSİK","TAM"))
A29: ukv_bazCarpan | B29: 1 | C29: çarpan | D29: Baz senaryo çarpanı | E29: Model varsayımı | F29: 01.01.2025 | G29: 11.08.2026 | H29: =IF(A29="","",IF(B29="","EKSİK","TAM"))
A30: ukv_sifirCarpan | B30: 0 | C30: çarpan | D30: Nötr çarpan (sıfır) | E30: Model varsayımı | F30: 01.01.2025 | G30: 11.08.2026 | H30: =IF(A30="","",IF(B30="","EKSİK","TAM"))
A31: ukv_siraBir | B31: 1 | C31: adet | D31: Tornado sıra 1 | E31: Ürün mimarisi | F31: 01.01.2025 | G31: 11.08.2026 | H31: =IF(A31="","",IF(B31="","EKSİK","TAM"))
A32: ukv_siraIki | B32: 2 | C32: adet | D32: Tornado sıra 2 | E32: Ürün mimarisi | F32: 01.01.2025 | G32: 11.08.2026 | H32: =IF(A32="","",IF(B32="","EKSİK","TAM"))
... A38: vaka_endeks_orani | B38: 1.1 | C38: çarpan | D38: Yedek endeks oranı | E38: Tebliğ örneği | F38: 01.01.2025 | G38: 11.08.2026 | H38: =IF(A38="","",IF(B38="","EKSİK","TAM"))
B40: Parametre satırları yukarıda; ad tanımları B kolonuna bağlı.
B42: Sürüm 1.0.0 | Şifre koruması: 1234 (formül alanları)

Sheet KILAVUZ
A1: KILAVUZ — Üretim Kârı %12,5 KV Optimizasyonu
A3: Karar kuralları
A5: • VERİ YOK — giriş tablosu boşsa hesap yapılmaz.
A6: • UYGULA — tasarruf uygula eşiğinin üzerinde; indirimli oranı uygulayın.
A7: • İNCELE — tasarruf incele bandında; pay ve istisna dayanağını gözden geçirin.
A8: • UYGULAMA — tasarruf eşik altında veya matrah yok; öncelik düşük.
A10: Belirsizlik beyanları (M05)
A11: Bu nokta mevzuatta tartışmalıdır; dosya yorum A ve yorum B sonucunu yan yana gösterir: pay_dagitim_yorumu
A13: Yorum A | B13: Genel yönetim ve finansman payları girdideki tutarlarla aynen üretim kârından düşülür. Matrah = MAX(0, üretim kârı + diğer faaliyet − istisna).
A14: Yorum B | B14: Yorum B, payları +%10 sıkılaştırır (daha yüksek maliyet payı → daha düşük matrah). Dosya her iki yorumun sonucunu MOTOR'da üretir.
A16: Kullanım sırası
A17: GIRDI → KURALLAR (gerekirse) → MOTOR (inceleme) → SENARYO → VAKALAR → PANO → KANIT_RAPORU → AYARLAR.
A19: Sürüm 1.0.0 | Lisans: Tek kullanıcı | ExcelArşiv
