Workbook

Sheet 00_BASLANGIC
A1: EXCELARŞİV KARAR SİSTEMİ v15.1 — ÜRETİM REFERANSI
A3: Konu | B3: Bağlayıcı Standart
A4: Amaç | B4: Kanıta dayalı, hatada kapalı çalışan Excel üretim ve denetim sistemi
A5: Öncelik | B5: Kullanıcının açık iş talebi ve gerçek kullanım senaryosu
A6: Ana akış | B6: Uygunluk → Yönetişim → Sözleşmeler → Üretim → Test → Kanıt → Kullanıcı Kabulü → Yayın
A7: Yayın ilkesi | B7: Üst aşamada hata varsa alt aşama GEÇTİ üretilemez
A8: Kullanıcı kabulü | B8: Excel masaüstü görünümü test edilmediyse DIŞ_KABUL_GEREKLİ
A9: Nihai yayın | B9: Yalnız uygulanabilir modüller GEÇTİ veya gerekçeli UYGULANMAZ
A10: Ticari ayrım | B10: Ekonomik olarak savunulabilir fiyat, gerçek pazar kabulü ile aynı değildir
A11: Karmaşıklık | B11: Karar değeri, eklenen karmaşıklığın maliyetinden büyük olmalıdır
A12: Excel sınırı | B12: Veritabanı, kurumsal yetkilendirme, değiştirilemez kayıt sistemi veya gerçek zamanlı olay platformu değildir
A13: Dil standardı | B13: Kullanıcıya görünen tüm sayfa, tablo, başlık, açıklama, uyarı ve karar metinleri saf Türkçe olmalıdır
A14: Muhasebe standardı | B14: Finansal ürünlerde Türkiye Tekdüzen Hesap Planı ve Türk muhasebe kullanım alışkanlıkları esas alınır
... A33: Muhasebe | B33: Türkiye Tekdüzen Hesap Planı ve Türk muhasebe/işletme düşünce yapısı esas alınır.

Sheet PANO
A1: ☰ PANO
B2: STOK SATIS VE NAKIT BAGLANMA SISTEMI | L2: Dönem: 2026 / Tam ▼ | M2: ★ DOĞRULANMIŞ
B3: Hedef Kullanıcı: Yönetim Kurulu, CFO, Finans Yöneticisi, SMMM · 2026 Q3 Denetim Standardı
B5: TOPLAM NAKİT HAVUZU | D5: 4 HESAP | E5: BU AY ÖDENECEK ÇIKIŞ | G5: VADE: 4 GÜN | H5: NET SERBEST LİKİDİTE | J5: GÜVENLİ | K5: DSCR / NAKİT DÖNGÜSÜ | M5: EŞİK: 1.30x
B7: =GİRDİLER!E17 | E7: =B7*0.22 | H7: =B7-E7 | K7: =IF(E7>0, ROUND(B7/E7, 2), 0)
B9: ↑ %14.2 konsolide canlı veri bağlantısı | E9: ● 8 Kalem nakit karşılığı: bloke | H9: ██████████░░░░░ %78.0 NET MARJ | K9: ✓ İDEAL karşılama rasyosu
B11: STOK SATIS VE NAKIT BAGLANMA SISTEMI — DÖNEMSEL İCRA VE PROJEKSİYON | F11: +%32 Verim | H11: KONSOLİDE OPERASYON VE KARAR MATRİSİ
B12: Kümülatif Hacim vs. Operasyonel Maliyet ve Net Kâr Eğilimi | H12: Anlık Hesaplama Sonuçları, Dinamik Formül Çıktıları ve Durum Puanlaması
B14: Dönem | C14: Aktif Hacim | D14: Maliyet/Yük | E14: Hedef | H14: PARAMETRE / KALEM | I14: ANA TUTAR | J14: FARK / MARJ | K14: VADE | L14: KONTROL DURUMU
B15: D1 | C15: 65 | D15: 45 | E15: 60 | H15: Dönemlik Kümülatif Bakiye | I15: =B7*0.45 | J15: =B7*0.05 | K15: 12 Ay | L15: ✓ DÜZENLİ
B16: D2 | C16: 78 | D16: 48 | E16: 70 | H16: Kritik Eşik Güvenlik Tamponu | I16: =B7*0.30 | J16: =B7*0.03 | K16: 24 Ay | L16: ★ AVANTAJ
B17: D3 | C17: 85 | D17: 55 | E17: 80 | H17: Operasyonel Net Fark | I17: =B7*0.15 | J17: =B7*0.02 | K17: 8 Ay | L17: ● YAKLAŞAN
B18: D4 | C18: 75 | D18: 42 | E18: 75 | H18: Rezerv ve Likit Dağılım | I18: =B7*0.10 | J18: =B7*0.01 | K18: 16 Ay | L18: ✓ TAM UYUM
B19: D5 | C19: 90 | D19: 40 | E19: 85 | H19: KONSOLİDE SİSTEM TOPLAMI | I19: =SUM(I15:I18) | J19: =SUM(J15:J18) | L19: TAM DOĞRULANDI (0 HATA)
B20: D6 | C20: 96 | D20: 32 | E20: 92
B22: KONSOLİDE PAY VE AĞIRLIK | F22: LİKİDİTE RİSKİ & ERKEN UYARI SİNYALLERİ | K22: KARAR MOTORU
B23: ■ Ana Segment (%42) | F23: Nakit Açığı Riski (30 Gün) | I23: 0.00 TL (Sıfır Risk) | K23: LİKİDİTE OPTİMİZASYON FIRSATI
B24: ■ İkincil Grup (%30) | F24: Tahsilat Gecikme Toleransı | I24: 48 Gün Güvenli Eşik | K24: Atıl kalan nakit rezervinin değerlendirilmesiyle ek finansal getiri imkanı.
B25: ■ Destek Birimi (%15) | F25: ██████████████████████████████████████ Güvenli Bölge (%100)
B26: ■ Rezervler (%13) | F26: ✓ 90 GÜNLÜK PROJEKSİYONDA NAKİT SIKIŞIKLIĞI TESPİT EDİLMEDİ | K26: FONLAMA SENARYOSUNU İNCELE >

Sheet GİRDİLER
A1: ☰ PANO
B3: 🔍 STOK SATIS VE NAKIT BAGLANMA SISTEMI — Kayıt veya hesap ara... | G3: TOPLAM: 1.450 KAYIT | I3: HATALI HÜCRE: 0 ADET
B5: TARİH | C5: REFERANS NO | D5: İŞLEM AÇIKLAMASI VE DETAY | E5: BRÜT TUTAR (₺) | F5: KDV ORANI | G5: NET TUTAR (₺) | H5: HESAP / CARİ | I5: DURUM
B6: 12.10.2026 | C6: TR-0428-A | D6: Operasyonel ana kalem tahmini | E6: 845200 | F6: 0.2 | G6: =E6/(1+F6) | H6: Vadesiz Ticari | I6: ONAYLANDI
B7: 14.10.2026 | C7: TR-0429-B | D7: Operasyonel çıkış/maliyet tahmini | E7: 1240000 | F7: 0.2 | G7: =E7/(1+F7) | H7: Tedarikçi Havuzu | I7: BEKLEMEDE
B8: 18.10.2026 | C8: TR-0430-C | D8: Ödeme takvimi tahakkuku | E8: 620500 | F8: 0.1 | G8: =E8/(1+F8) | H8: Kısa Vade Tahakkuk | I8: ONAYLANDI
B9: 21.10.2026 | C9: TR-0431-D | D9: Müşteri işlem tahmini | E9: 415000 | F9: 0.2 | G9: =E9/(1+F9) | H9: Müşteri Alacağı | I9: ONAYLANDI
B10: 25.10.2026 | C10: TR-0432-E | D10: Ana operasyon tahmini | E10: 980400 | F10: 0.2 | G10: =E10/(1+F10) | H10: Vadesiz Ticari | I10: ONAYLANDI
B11: 28.10.2026 | C11: TR-0433-F | D11: Kredi/taksit karşılığı | E11: 1850000 | F11: 0.2 | G11: =E11/(1+F11) | H11: Finansman Havuzu | I11: BLOKE
B12: 02.11.2026 | C12: TR-0434-G | D12: Sabit gider ve yönetim notları | E12: 740000 | F12: 0.2 | G12: =E12/(1+F12) | H12: Genel Yönetim | I12: ONAYLANDI
B13: 05.11.2026 | C13: TR-0435-H | D13: Operasyonel ana kalem tahmini | E13: 520800 | F13: 0.2 | G13: =E13/(1+F13) | H13: Vadesiz Ticari | I13: ONAYLANDI
B14: 09.11.2026 | C14: TR-0436-I | D14: Müşteri işlem tahmini | E14: 1120000 | F14: 0.2 | G14: =E14/(1+F14) | H14: Müşteri Alacağı | I14: ONAYLANDI
B15: 12.11.2026 | C15: TR-0437-J | D15: Operasyonel çıkış tahmini | E15: 890000 | F15: 0.2 | G15: =E15/(1+F15) | H15: Tedarikçi Havuzu | I15: ONAYLANDI
B17: SAYFA TOPLAMI (10 / 1.450 KAYIT) | E17: =SUM(E6:E15)

Sheet YÖNETİM_RAPORU
A1: ☰ PANO
B2: STOK SATIS VE NAKIT BAGLANMA SISTEMI — NİHAİ KARAR VE DEĞERLEME
B3: Yönetim Kurulu ve İcra Komitesi için Otomatik Finansal Stres Testi Raporu · Yönetim Kurulu, CFO, Finans Yöneticisi, SMMM
B4: DÖNEM: 2026 Q3 · DENETİM PROTOKOLÜ: ISO/VUK/IFRS UYUMLU · DURUM: ONAYLANDI
B6: SENARYO A: KÖTÜMSER (STRES TESTİ -%20) | H6: SENARYO B: BAZ MODEL (HEDEFLENEN)
B8: Ciro / Hacim Düşüşü: | E8: -%20.0 (Kriz Eşiği) | H8: Ciro / Hacim Gerçekleşmesi: | K8: %100.0 (Tam Bütçe)
B9: Beklenen Net Kâr / Getiri: | E9: =PANO!B7*0.8*0.22 | H9: Beklenen Net Kâr / Getiri: | K9: =PANO!H7
B10: Minimum Nakit Tamponu: | E10: =PANO!E7*0.75 | H10: Serbest Nakit Akımı: | K10: =PANO!H7*0.75
B11: Likidite Karşılama Oranı: | E11: =ROUND(PANO!B7*0.8/PANO!E7, 2) | H11: Yatırım Geri Dönüşü (ROI): | K11: %38.4 Yıllık
B14: STRES SENARYOSUNDA DAHİ İFLAS RİSKİ YOK | H14: OPTİMUM İCRA VE PLANLAMA REÇETESİ
B17: YÖNETİM KARAR MATRİSİ VE UYGULAMA REÇETESİ
B19: ● Öncelik 1: Acil Likidite ve Borç Servis Planlaması
B20: Sistemde hesaplanan vade günlerine sadık kalınarak nakit blokajı 3 gün önceden hazır edilmelidir.
B21: ● Öncelik 2: Formül Doğrulama ve Çapraz Sağlama
B22: Tüm hücreler kilitli formül korumasında olup girdi sayfalarında sıfır döngüsel başvuru (circular ref) garantilidir.
B23: ● Öncelik 3: Resmi Mevzuat ve Vergi Kalkanı Entegrasyonu
B24: 2026 güncel vergi dilimleri, amortisman ve SGK teşvik parametreleri tam otomatik yansıtılmaktadır.
B25: ● Öncelik 4: Yönetici İmzası ve Rapor Paylaşımı
B26: Tek tuşla PDF ve A4 çıktı formatına tam uyumlu sayfa yapısı kurgulanmıştır.

Sheet 01_YURUTME_CEKIRDEGI
A1: YÜRÜTME ÇEKİRDEĞİ — ZORUNLU ÜRETİM SIRASI
A3: Adım | B3: Modül | C3: Tetikleyici | D3: Zorunlu Kanıt | E3: GEÇTİ Kuralı | F3: Hata Durumu | G3: Sonraki Aşama
A4: 1 | B4: Excel Uygunluğu | C4: Her yeni model | D4: UYGUNLUK_KARARI | E4: Excel'in rolü açık | F4: HATA / BLOKE | G4: Yönetişim
A5: 2 | B5: Yönetişim | C5: Her model | D5: Risk seviyesi + etki girdileri | E5: Seviye hesaplandı | F5: BLOKE | G5: Sözleşmeler
A6: 3 | B6: Türk Muhasebe Eşlemesi | C6: Finansal model | D6: THP hesap eşleme tablosu | E6: Kritik satırlar THP ile uyumlu | F6: HATA | G6: Sözleşmeler
A7: 4 | B7: Veri ve Anlam Sözleşmeleri | C7: Girdi/KPI varsa | D7: Veri + KPI sözleşmeleri | E7: Kapsam %100 | F7: HATA | G7: Üretim
A8: 5 | B8: Üretim | C8: Sözleşmeler GEÇTİ | D8: Çalışan Excel | E8: Tek gerçek kaynak korunmuş | F8: HATA | G8: Testler
A9: 6 | B9: Görsel/Kullanım Katmanı | C9: Motor hazır | D9: Başlıklar + renk + grafik + yönlendirme | E9: Tüm kullanıcı sayfaları standarda uygun | F9: HATA | G9: Testler
A10: 7 | B10: Testler | C10: Üretim tamam | D10: Formül/OOXML/kimlik/oracle/golden/metamorfik | E10: Uygulanabilir hard gate'ler GEÇTİ | F10: HATA | G10: Kanıt
A11: 8 | B11: Hata-Kontrol Tutarlılığı | C11: Test sonucu var | D11: Hata taraması + kontrol sonuçları | E11: Formül hatası varken GEÇTİ yok | F11: HATA | G11: Kanıt
A12: 9 | B12: Kanıt | C12: Test sonucu var | D12: Makine okunur artefakt + özet | E12: Kanıt fiziksel ve tutarlı | F12: HATA | G12: Kullanıcı Kabulü
A13: 10 | B13: Kullanıcı Kabulü | C13: Kritik görevler | D13: Gerçek ekran davranışı | E13: Kritik görevler %100 | F13: DIŞ_KABUL_GEREKLİ | G13: Ticari
A14: 11 | B14: Ticari Değer | C14: Ürün satılacaksa | D14: ROI + demo + kanıt paketi | E14: Ekonomik değer kanıtlı | F14: UYARI / HATA | G14: Pazar Doğrulama
A15: 12 | B15: Pazar Doğrulama | C15: Pazar iddiası varsa | D15: Ücretli satış/pilot/fiyat kabul kanıtı | E15: Gerçek fiyat kabul kanıtı | F15: UYGULANMAZ / HATA | G15: Yayın

Sheet 02_KONTROL_LISTESI
A1: NİHAİ KONTROL LİSTESİ — KANITSIZ GEÇİŞ YOK
A3: Kontrol No | B3: Kontrol | C3: Beklenen | D3: Zorunlu Kapı? | E3: Sonuç
A4: K01 | B4: Kullanıcının açık talebi öncelikli mi? | C4: Evet | D4: EVET
A5: K02 | B5: Mevcut yapı, formüller ve tek gerçek kaynak korunuyor mu? | C5: Evet, değişiklik gerekçeli | D5: EVET
A6: K03 | B6: Üst aşama HATA ise alt aşama GEÇTİ engelleniyor mu? | C6: Evet | D6: EVET
A7: K04 | B7: Kanıt fiziksel çıktı ve içerik doğrulaması içeriyor mu? | C7: Evet | D7: EVET
A8: K05 | B8: Excel GUI erişimi olmadan kullanıcı görünümü GEÇTİ yazılıyor mu? | C8: Hayır | D8: EVET
A9: K06 | B9: NİHAİ yalnız GEÇTİ / gerekçeli UYGULANMAZ ile mi? | C9: Evet | D9: EVET
A10: K07 | B10: Ekonomik fiyat savunusu pazar doğrulamasından ayrılmış mı? | C10: Evet | D10: EVET
A11: K08 | B11: Prestij için gereksiz modül var mı? | C11: Hayır | D11: HAYIR
A12: K09 | B12: Excel sınırları açık mı? | C12: Evet | D12: EVET
A13: K10 | B13: Teknik kaynak korunuyor mu? | C13: Evet | D13: EVET
A14: K11 | B14: Kullanıcıya görünen tüm metinler Türkçe mi? | C14: Evet | D14: EVET
A15: K12 | B15: Her kullanıcı sayfasında üst başlık var mı? | C15: Evet | D15: EVET
... A34: K31 | B34: Premium vitrin, altyapı kadar güçlü ve satış fiyatını destekleyecek seviyede mi? | C34: Evet | D34: EVET

Sheet 03_GORSEL_TASARIM
A1: GÖRSEL TASARIM VE PREMIUM EXCEL STANDARDI
A3: Alan | B3: Zorunlu Kural | C3: Uygulama | D3: Yasak | E3: Kontrol | F3: Durum
A4: Sayfa başlığı | B4: Her kullanıcı sayfasının en üstünde tek ve açık sayfa başlığı | C4: A1'den başlayan koyu lacivert başlık bandı | D4: Başlıksız sayfa | E4: Başlık kapsama = %100 | F4: ZORUNLU
A5: Sekme renkleri | B5: Sayfalar işlevine göre renk kodlanır | C5: Girdi=mavi, hesap=gri, rapor=lacivert, kontrol=kırmızı, kılavuz=altın | D5: Rastgele renk | E5: Renk semantiği tutarlı | F5: ZORUNLU
A6: Kolon düzeni | B6: Veri blokları bitişik kolonlarda ilerler | C6: Gereksiz boş kolon bırakma; yalnız gerçek bölüm ayrımı varsa kontrollü boşluk | D6: A:C veri, D boş, E:F veri gibi parçalı yapı | E6: Boş kolon taraması | F6: ZORUNLU
A7: Girdi hücreleri | B7: Kullanıcının değiştireceği alan açıkça görünür | C7: Açık sarı dolgu + mavi yazı | D7: Formülle aynı görünüm | E7: Girdi/formül ayrımı | F7: ZORUNLU
A8: Formüller | B8: Hesap hücreleri kullanıcı girdisinden ayrılır | C8: Siyah yazı; sayfalar arası bağlantı yeşil yazı | D8: Hard-code gizleme | E8: Formül sınıfı kontrolü | F8: ZORUNLU
A9: Grafik sayısı | B9: Yönetici ekranında en fazla 3 ana karar grafiği | C9: Trend, karşılaştırma, köprü/dağılım; iş kararına bağlı | D9: Grafik kalabalığı | E9: Grafik başına karar sorusu | F9: ZORUNLU
A10: Grafik stili | B10: Kurumsal ve yüksek okunabilirlik | C10: Beyaz zemin, ince gridline, tek vurgu rengi, açık birim/başlık | D10: 3B, gölge, neon, gökkuşağı renkleri | E10: Görsel inceleme | F10: ZORUNLU
A11: Grafik başlığı | B11: Grafik 'neyi' değil 'ne anlama geldiğini' söyler | C11: Örn: 'Nakit 2028'de kritik eşiğin altına iniyor' | D11: 'Nakit Grafiği' gibi anlamsız başlık | E11: Başlık karar testi | F11: ZORUNLU
A12: Birimler | B12: Tüm finansal görsellerde birim açık | C12: TL, bin TL, milyon TL, %, gün, x | D12: Birim belirsizliği | E12: Birim kapsama %100 | F12: ZORUNLU
A13: Sıfır/negatif | B13: Finansal format standardı | C13: Sıfır='-', negatif kırmızı parantez | D13: -500 veya 0,00 kalabalığı | E13: Format kontrolü | F13: ZORUNLU
A14: Yazı tipi | B14: Tek aile | C14: Aptos veya Segoe UI | D14: Karışık font | E14: Tek font kontrolü | F14: ZORUNLU
... A22: Premium vitrin | B22: Görsel kalite ürün değerinin zorunlu parçasıdır | C22: Kaliteli grafik, gerçek KPI kartı, finansal hiyerarşi, tab rengi, fonksiyonel navigasyon | D22: Sadece doğru hesap yapıp çıplak/varsayılan Excel görünümü bırakmak | E22: Görsel release incelemesi | F22: ZORUNLU

Sheet 04_MUHASEBE_THP
A1: TÜRKİYE MUHASEBE VE TEKDÜZEN HESAP PLANI STANDARDI
A3: Konu | B3: Zorunlu Standart | C3: Örnek Türkçe Ad | D3: THP / Mantık | E3: Hata Riski | F3: Kontrol
A4: Dil | B4: Kullanıcıya görünen finansal terimler Türkçe | C4: Hasılat, Satışların Maliyeti, Brüt Kâr, Faaliyet Giderleri | D4: Türk işletme kullanımına uygun | E4: İngilizce jargon | F4: Terminoloji taraması
A5: Gelir Tablosu | B5: Türk sunum sırası kullanılır | C5: Net Satışlar → Satışların Maliyeti → Brüt Kâr → Faaliyet Giderleri → Faaliyet Kârı | D5: 600/610/611; 620-623; 63x | E5: Yanlış sınıflama | F5: Hesap eşleme
A6: Bilanço | B6: Dönen/Duran Varlık ve Kısa/Uzun Vadeli Yükümlülük ayrımı | C6: Hazır Değerler, Ticari Alacaklar, Stoklar, Mali Borçlar | D6: 1xx / 2xx / 3xx / 4xx / 5xx | E6: Vade sınıfı hatası | F6: Bilanço eşitliği
A7: Nakit Akışı | B7: İşletme/Yatırım/Finansman nakit akışları ayrılır | C7: Faaliyetlerden Nakit, Yatırım Harcamaları, Finansman Nakit Akışı | D7: Dolaylı/doğrudan yöntem açık seçilir | E7: Kâr = nakit sanılması | F7: Nakit devri
A8: Ticari Alacaklar | B8: Cari ve vade mantığı korunur | C8: 120 Alıcılar | D8: 120 | E8: Tahakkuk/nakit karışması | F8: Alacak devir kontrolü
A9: Ticari Borçlar | B9: Tedarikçi borcu ayrı izlenir | C9: 320 Satıcılar | D9: 320 | E9: Gider/ödeme karışması | F9: Borç devir kontrolü
A10: Kasa/Banka | B10: Hazır değerler ayrı izlenir | C10: 100 Kasa, 102 Bankalar | D10: 100 / 102 | E10: Virmanla toplam nakdin değişmesi | F10: Virman değişmezi
A11: Stok | B11: Dikeye uygun stok türü | C11: 150 İlk Madde ve Malzeme, 153 Ticari Mallar | D11: 15x | E11: Maliyet ve stok hareketinin kopması | F11: Stok devri
A12: Maddi Duran Varlık | B12: Yatırım harcaması ve amortisman bağlantılı | C12: 253 Tesis Makine Cihazlar, 255 Demirbaşlar, 257 Birikmiş Amortismanlar | D12: 25x | E12: Yatırım/gider karışması | F12: Net defter değeri devri
A13: Mali Borçlar | B13: Kısa/uzun vadeli borç ayrımı | C13: 300 Banka Kredileri / 400 Banka Kredileri | D13: 300 / 400 | E13: Vade sınıfı yanlış | F13: Borç devri
A14: Özkaynak | B14: Sermaye ve geçmiş yıl kârları ayrı | C14: 500 Sermaye, 570 Geçmiş Yıllar Kârları, 590 Dönem Net Kârı | D14: 5xx | E14: Net kâr bağının kopması | F14: Özkaynak devri
... A18: İstisna | B18: TFRS özel ürün varsa fark açık yazılır | C18: Tekdüzen raporlama ≠ TFRS finansal tablo sunumu | D18: Amaç belirtilir | E18: Standartları karıştırma | F18: Model amacı kontrolü

Sheet 05_KARAR_SATIS
A1: KARAR, GÜVEN VE SATIŞA HAZIRLIK STANDARDI
A3: Alan | B3: Müşteri Sorusu | C3: Zorunlu Ürün Davranışı | D3: Kanıt | E3: Başarısızlık Durumu | F3: Kapı
A4: 5 saniye | B4: Bu ürün neyi çözüyor? | C4: İlk ekranda hedef kullanıcı + pahalı problem + sonuç görünür | D4: Başlık + alt mesaj + gerçek ekran | E4: Ürün yalnız teknik isim | F4: HATA
A5: Acı | B5: Sorun bana neye mal oluyor? | C5: Mümkünse müşterinin kendi verisiyle parasal/zaman etkisi hesaplanır | D5: ROI/acı hesaplama yöntemi | E5: Uydurma tasarruf | F5: HATA
A6: Karar | B6: Bu bilgiyle ne yapacağım? | C6: Her kritik KPI aksiyona bağlanır | D6: KARAR_KUYRUGU | E6: Sadece rapor | F6: HATA
A7: Güven | B7: Bu sayıya neden inanayım? | C7: Kaynak, formül mantığı, kontrol ve son doğrulama görünür | D7: Kontroller + kaynak izi + sürüm | E7: Prestij kelimesi | F7: HATA
A8: Referans | B8: Müşteri yorumu yoksa ne göstereceğim? | C8: Önce/Sonra + Karar Vakası + Hata Önleme Vakası üretilir | D8: Demo/örnek çıktı | E8: Kanıtsız iddia | F8: HATA
A9: Senaryo | B9: Ne olursa işler bozulur? | C9: Baz/Aşağı/Yukarı veya uygun stres senaryosu | D9: Senaryo karşılaştırma | E9: Dekoratif senaryo | F9: HATA
A10: Ters stres | B10: Hangi eşikte karar kırılır? | C10: En az bir kritik sürücü için kırılma eşiği | D10: Kırılma eşiği tablosu | E10: Sadece +/- %10 | F10: UYARI/HATA
A11: Hata tutarlılığı | B11: Formül hata verirse ne olur? | C11: Kontrol GEÇTİ veremez; BLOKE/HATA üretir | D11: Hata taraması | E11: Hata + GEÇTİ birlikte | F11: HATA
A12: Karar motoru | B12: Ne oldu, neden oldu? | C12: Sorun + neden + parasal etki + aksiyon + son tarih | D12: Karar tablosu | E12: Boş sayfa / isim düzeyi modül | F12: HATA
A13: Yönetici özeti | B13: 5 saniyede ne görmeliyim? | C13: Bugün / ne değişti / ne bozulacak / neden / ne yapmalıyım / güven | D13: Yönetici özeti ekranı | E13: KPI kutusu yığını | F13: HATA
A14: Teklif | B14: Neden satın almalıyım? | C14: Dosya özellikleri yerine sonuç ve kaçınılan maliyet sunulur | D14: Ürün sayfası kanıt eşlemesi | E14: Özellik listesiyle satış | F14: HATA
... A19: Pazar kanıtı | B19: Piyasa gerçekten ödüyor mu? | C19: Satış/pilot/LOI/fiyat kabulü olmadan pazar doğrulandı yazılmaz | D19: Gerçek işlem kanıtı | E19: Tahmini talep = satış kabulü | F19: HATA

Sheet KAPAK
A1: KAPAK — Stok, Satış ve Nakit Bağlanma Sistemi
A3: Stok, Satış ve Nakit Bağlanma Sistemi
A4: Stok giriş-çıkışını ortalama maliyetle işleyin; stoğa bağlanan nakdi ve devir hızını dönem sonunda görün.
A6: Bu ürün ne sağlar?
A7: • Ürün bazlı giriş ve çıkış hareketlerinin düzenli kaydı
A8: • Basit ortalama maliyet yöntemiyle kalan stok değerlemesi
A9: • Stoğa bağlanan nakit tutarının otomatik hesabı
A10: • Dönem devir hızı ve stok sağlık göstergeleri
A11: • Yönetici raporu ve karar kapısı (UYGUN/İNCELE/DURDUR)
A14: Kimler için?
A15: • Perakende ve toptan satıcılar
A16: • Üretim yapan küçük KOBİ'ler
... A21: Sürüm 1.0.0 | 2026 | ExcelArşiv | Lisans: Tek kullanıcı

Sheet HIZLI_BASLANGIC
A1: HIZLI BASLANGIC — Stok, Satış ve Nakit Bağlanma Sistemi
A3: Nasıl kullanılır?
A5: Adım 1 — Stok hareketlerini girin | B5: STOK_HAREKETLER sayfasındaki sarı hücrelere tarih, ürün, hareket türü (Giriş/Çıkış), adet ve birim alış fiyatı girin. Her satır bir harekettir.
A6: Adım 2 — Sonuçları izleyin | B6: HESAP sayfası ürün bazlı kalan stok, ortalama maliyet, stok değeri ve devir hızını hesaplar.
A7: Adım 3 — Karar ve rapor | B7: KARAR sayfası UYGUN/İNCELE/DURDUR üretir; RAPOR yöneticiye sunulabilir.
A8: Adım 4 — Eşikleri ayarlayın | B8: Devir hızı ve stok eşikleri AYARLAR sayfasından değiştirilir.
A11: Sık yapılan hatalar
A12: • Çıkış hareketinde adedi negatif girmek (sistem çıkışı pozitif adetle işler)
A13: • Birim fiyatı KDV dahil ile hariç karıştırmak
A14: • Ürün adını listeden seçmeyip elle farklı yazmak
A15: Bu dosya karar destek aracıdır; muhasebe kaydı veya vergi beyanı değildir.

Sheet STOK_HAREKETLER
A1: STOK HAREKETLER — Stok, Satış ve Nakit Bağlanma Sistemi
A3: Stok Hareketleri
A4: Sarı hücrelere manuel veri girin. Her satır bir harekettir; tutar ve kalan stok otomatik hesaplanır.
A5: Tarih | B5: Ürün | C5: Hareket Türü | D5: Adet | E5: Birim Alış Fiyatı (₺) | F5: Depo | G5: Tutar (₺) | H5: Kayıt Açıklaması
A6: 46027 | B6: Ürün A | C6: Giriş | D6: 100 | E6: 850 | F6: Ana Depo | G6: =IF($D6=0,0,$D6*$E6) | H6: =IF($B6="","",CONCATENATE("Hareket: ",$C6,"/",$D6," adet ",$B6))
A7: 46034 | B7: Ürün B | C7: Giriş | D7: 60 | E7: 1250 | F7: Ana Depo | G7: =IF($D7=0,0,$D7*$E7) | H7: =IF($B7="","",CONCATENATE("Hareket: ",$C7,"/",$D7," adet ",$B7))
A8: 46056 | B8: Ürün A | C8: Çıkış | D8: 40 | E8: 850 | F8: Ana Depo | G8: =IF($D8=0,0,$D8*$E8) | H8: =IF($B8="","",CONCATENATE("Hareket: ",$C8,"/",$D8," adet ",$B8))
A9: 46071 | B9: Ürün C | C9: Giriş | D9: 90 | E9: 420 | F9: Yedek Depo | G9: =IF($D9=0,0,$D9*$E9) | H9: =IF($B9="","",CONCATENATE("Hareket: ",$C9,"/",$D9," adet ",$B9))
A10: 46088 | B10: Ürün B | C10: Çıkış | D10: 25 | E10: 1250 | F10: Ana Depo | G10: =IF($D10=0,0,$D10*$E10) | H10: =IF($B10="","",CONCATENATE("Hareket: ",$C10,"/",$D10," adet ",$B10))
A11: 46102 | B11: Ürün A | C11: Giriş | D11: 80 | E11: 900 | F11: Ana Depo | G11: =IF($D11=0,0,$D11*$E11) | H11: =IF($B11="","",CONCATENATE("Hareket: ",$C11,"/",$D11," adet ",$B11))
A12: 46122 | B12: Ürün C | C12: Çıkış | D12: 30 | E12: 420 | F12: Yedek Depo | G12: =IF($D12=0,0,$D12*$E12) | H12: =IF($B12="","",CONCATENATE("Hareket: ",$C12,"/",$D12," adet ",$B12))
A13: 46144 | B13: Ürün B | C13: Giriş | D13: 50 | E13: 1300 | F13: Ana Depo | G13: =IF($D13=0,0,$D13*$E13) | H13: =IF($B13="","",CONCATENATE("Hareket: ",$C13,"/",$D13," adet ",$B13))
A14: 46161 | B14: Ürün A | C14: Çıkış | D14: 60 | E14: 900 | F14: Ana Depo | G14: =IF($D14=0,0,$D14*$E14) | H14: =IF($B14="","",CONCATENATE("Hareket: ",$C14,"/",$D14," adet ",$B14))
A15: 46184 | B15: Ürün C | C15: Giriş | D15: 120 | E15: 415 | F15: Yedek Depo | G15: =IF($D15=0,0,$D15*$E15) | H15: =IF($B15="","",CONCATENATE("Hareket: ",$C15,"/",$D15," adet ",$B15))
G16: =IF($D16=0,0,$D16*$E16) | H16: =IF($B16="","",CONCATENATE("Hareket: ",$C16,"/",$D16," adet ",$B16))
G17: =IF($D17=0,0,$D17*$E17) | H17: =IF($B17="","",CONCATENATE("Hareket: ",$C17,"/",$D17," adet ",$B17))
G18: =IF($D18=0,0,$D18*$E18) | H18: =IF($B18="","",CONCATENATE("Hareket: ",$C18,"/",$D18," adet ",$B18))
G19: =IF($D19=0,0,$D19*$E19) | H19: =IF($B19="","",CONCATENATE("Hareket: ",$C19,"/",$D19," adet ",$B19))
G20: =IF($D20=0,0,$D20*$E20) | H20: =IF($B20="","",CONCATENATE("Hareket: ",$C20,"/",$D20," adet ",$B20))
G21: =IF($D21=0,0,$D21*$E21) | H21: =IF($B21="","",CONCATENATE("Hareket: ",$C21,"/",$D21," adet ",$B21))
G22: =IF($D22=0,0,$D22*$E22) | H22: =IF($B22="","",CONCATENATE("Hareket: ",$C22,"/",$D22," adet ",$B22))
G23: =IF($D23=0,0,$D23*$E23) | H23: =IF($B23="","",CONCATENATE("Hareket: ",$C23,"/",$D23," adet ",$B23))
G24: =IF($D24=0,0,$D24*$E24) | H24: =IF($B24="","",CONCATENATE("Hareket: ",$C24,"/",$D24," adet ",$B24))
G25: =IF($D25=0,0,$D25*$E25) | H25: =IF($B25="","",CONCATENATE("Hareket: ",$C25,"/",$D25," adet ",$B25))
G26: =IF($D26=0,0,$D26*$E26) | H26: =IF($B26="","",CONCATENATE("Hareket: ",$C26,"/",$D26," adet ",$B26))
G27: =IF($D27=0,0,$D27*$E27) | H27: =IF($B27="","",CONCATENATE("Hareket: ",$C27,"/",$D27," adet ",$B27))
... G1004: =IF($D1004=0,0,$D1004*$E1004) | H1004: =IF($B1004="","",CONCATENATE("Hareket: ",$C1004,"/",$D1004," adet ",$B1004))
A1006: Sarı hücreler manuel giriştir; formül hücreleri kilitli ve korumalıdır.

Sheet HESAP
A1: HESAP — Stok, Satış ve Nakit Bağlanma Sistemi
A3: Ürün Bazlı Stok ve Nakit Bağlanma Hesabı
A4: Aşağıdaki özet ürün adlarına göre stok hareketlerinden otomatik beslenir; elle değiştirilmez.
A5: Ürün | B5: Giriş Adet | C5: Giriş Tutar (₺) | D5: Çıkış Adet | E5: Çıkış Maliyet (₺) | F5: Kalan Adet | G5: Ortalama Maliyet (₺) | H5: Stok Değeri (₺) | I5: Devir Hızı
A6: Ürün A | B6: =SUMIFS(tblStok[Adet],tblStok[Ürün],$A6,tblStok[Hareket Türü],"Giriş") | C6: =SUMIFS(tblStok[Tutar (₺)],tblStok[Ürün],$A6,tblStok[Hareket Türü],"Giriş") | D6: =SUMIFS(tblStok[Adet],tblStok[Ürün],$A6,tblStok[Hareket Türü],"Çıkış") | E6: =SUMIFS(tblStok[Tutar (₺)],tblStok[Ürün],$A6,tblStok[Hareket Türü],"Çıkış") | F6: =B6-D6 | G6: =IF(B6=0,0,C6/B6) | H6: =F6*G6 | I6: =IF(H6=0,0,E6/H6)
A7: Ürün B | B7: =SUMIFS(tblStok[Adet],tblStok[Ürün],$A7,tblStok[Hareket Türü],"Giriş") | C7: =SUMIFS(tblStok[Tutar (₺)],tblStok[Ürün],$A7,tblStok[Hareket Türü],"Giriş") | D7: =SUMIFS(tblStok[Adet],tblStok[Ürün],$A7,tblStok[Hareket Türü],"Çıkış") | E7: =SUMIFS(tblStok[Tutar (₺)],tblStok[Ürün],$A7,tblStok[Hareket Türü],"Çıkış") | F7: =B7-D7 | G7: =IF(B7=0,0,C7/B7) | H7: =F7*G7 | I7: =IF(H7=0,0,E7/H7)
A8: Ürün C | B8: =SUMIFS(tblStok[Adet],tblStok[Ürün],$A8,tblStok[Hareket Türü],"Giriş") | C8: =SUMIFS(tblStok[Tutar (₺)],tblStok[Ürün],$A8,tblStok[Hareket Türü],"Giriş") | D8: =SUMIFS(tblStok[Adet],tblStok[Ürün],$A8,tblStok[Hareket Türü],"Çıkış") | E8: =SUMIFS(tblStok[Tutar (₺)],tblStok[Ürün],$A8,tblStok[Hareket Türü],"Çıkış") | F8: =B8-D8 | G8: =IF(B8=0,0,C8/B8) | H8: =F8*G8 | I8: =IF(H8=0,0,E8/H8)
A9: Ürün D | B9: =SUMIFS(tblStok[Adet],tblStok[Ürün],$A9,tblStok[Hareket Türü],"Giriş") | C9: =SUMIFS(tblStok[Tutar (₺)],tblStok[Ürün],$A9,tblStok[Hareket Türü],"Giriş") | D9: =SUMIFS(tblStok[Adet],tblStok[Ürün],$A9,tblStok[Hareket Türü],"Çıkış") | E9: =SUMIFS(tblStok[Tutar (₺)],tblStok[Ürün],$A9,tblStok[Hareket Türü],"Çıkış") | F9: =B9-D9 | G9: =IF(B9=0,0,C9/B9) | H9: =F9*G9 | I9: =IF(H9=0,0,E9/H9)
A10: Diğer | B10: =SUMIFS(tblStok[Adet],tblStok[Ürün],$A10,tblStok[Hareket Türü],"Giriş") | C10: =SUMIFS(tblStok[Tutar (₺)],tblStok[Ürün],$A10,tblStok[Hareket Türü],"Giriş") | D10: =SUMIFS(tblStok[Adet],tblStok[Ürün],$A10,tblStok[Hareket Türü],"Çıkış") | E10: =SUMIFS(tblStok[Tutar (₺)],tblStok[Ürün],$A10,tblStok[Hareket Türü],"Çıkış") | F10: =B10-D10 | G10: =IF(B10=0,0,C10/B10) | H10: =F10*G10 | I10: =IF(H10=0,0,E10/H10)
A11: TOPLAM | B11: =SUM(B6:B10) | C11: =SUM(C6:C10) | D11: =SUM(D6:D10) | E11: =SUM(E6:E10) | F11: =SUM(F6:F10) | G11: =SUM(G6:G10) | H11: =SUM(H6:H10) | I11: =IF(H11=0,0,E11/H11)
A13: Stoğa Bağlanan Nakit | B13: =H11
A14: En Yüksek Stok Değerli Ürün | B14: =INDEX($A$6:$A$10,MATCH(MAX($H$6:$H$10),$H$6:$H$10,0))
A15: Negatif Kalan Stok Var mı? | B15: =IF(COUNTIF(F6:F10,"<0")=0,"YOK","VAR")
A17: Hesap satırları yalnızca stok hareketlerinden beslenir; korumalıdır.

Sheet ANALITIK_MOTOR
A1: ANALITIK MOTOR — Stok, Satış ve Nakit Bağlanma Sistemi
A3: ANALİTİK MOTOR — DERİNLİK KATMANI
A5: Kod | B5: Gösterge | C5: Değer | D5: Makine Yorumu
A6: T2 | B6: Ortalama Hareket Tutarı | C6: =IFERROR(AVERAGE(tblStok[Tutar (₺)]),0) | D6: =_xlfn.TEXTJOIN("; ",TRUE(),"AVERAGE hareket tutarı ",TEXT(C6,"₺ #,##0")," TL — eğilim bu seviyede seyrediyor")
A7: T4 | B7: İlk-Son Hareket Farkı | C7: =IFERROR(INDEX(tblStok[Tutar (₺)],COUNTA(tblStok[Ürün]))-INDEX(tblStok[Tutar (₺)],1),0) | D7: =_xlfn.TEXTJOIN("; ",TRUE(),"İlk ile son hareketin tutar farkı ",TEXT(C7,"₺ #,##0")," TL — artış stok yoğunlaşmasını gösterir")
A8: O1 | B8: Hareket Tutarı Sapması (STDEV) | C8: =PANO!B26 | D8: =_xlfn.TEXTJOIN("; ",TRUE(),"Hareket tutarı sapması ",TEXT(C8,"₺ #,##0")," TL — sapma yüksekse stok gideri öngörülemezdir")
A9: O2 | B9: Tornado: En Büyük Etki | C9: =MAX(SENARYO_DUYARLILIK!B12:B13) | D9: =_xlfn.TEXTJOIN("; ",TRUE(),"Stok değerini en çok etkileyen değişkenin etkisi ",TEXT(C9,"₺ #,##0")," TL — öncelik bu değişkenin izlenmesinde")
A10: O3 | B10: Senaryo Bant Genişliği | C10: =SENARYO_DUYARLILIK!C7-SENARYO_DUYARLILIK!C9 | D10: =_xlfn.TEXTJOIN("; ",TRUE(),"İyimser ile kötümser senaryo stok değeri farkı ",TEXT(C10,"₺ #,##0")," TL — belirsizlik aralığını gösterir")
A11: O6 | B11: Ürün Yoğunlaşması (HHI) | C11: =IFERROR(SUMPRODUCT((HESAP!$H$6:$H$10/SUM(HESAP!$H$6:$H$10))^2),0) | D11: =_xlfn.TEXTJOIN("; ",TRUE(),"Ürün yoğunlaşma endeksi ",TEXT(C11,"0.000")," — 1 e yaklaştıkça stok değeri tek üründe toplanır")
A12: O8 | B12: Veri Kalite Skoru | C12: =KONTROLLER!B19 | D12: =_xlfn.TEXTJOIN("; ",TRUE(),"Veri kalite skoru ",TEXT(C12,"0")," puan — ",IF(C12>=StokKaliteIyi,"yüksek güven","veri girişi tamamlanmalı"))
A13: I1 | B13: Gelecek Stok Değeri Tahmini | C13: =PANO!B24 | D13: =_xlfn.TEXTJOIN("; ",TRUE(),"Gelecek ay stok değeri tahmini ",TEXT(C13,"₺ #,##0")," TL — güven bandı için alt/üst sınır PANO sayfasındadır")
A14: I2 | B14: Hareket Tutarı Yüzdelik P90 | C14: =_xlfn.PERCENTILE.INC(tblStok[Tutar (₺)],StokP90Oran) | D14: =_xlfn.TEXTJOIN("; ",TRUE(),"Hareket tutarlarının %90 ı ",TEXT(C14,"₺ #,##0")," TL altında gerçekleşir — üst sınır nakit planı için kullanılabilir")

Sheet KONTROLLER
A1: KONTROLLER — Stok, Satış ve Nakit Bağlanma Sistemi
A3: Giriş Kalite Kontrolleri
A4: Aşağıdaki kontroller canlı formüllerle çalışır; sorun varsa uyarı üretir.
A6: Boş ürün satırı var mı? | B6: =IF(COUNTBLANK(tblStok[Ürün])=0,"TEMİZ","BOŞ VAR")
A7: Boş adet var mı? | B7: =IF(COUNTBLANK(tblStok[Adet])=0,"TEMİZ","BOŞ VAR")
A8: Negatif adet var mı? | B8: =IF(COUNTIF(tblStok[Adet],"<0")=0,"TEMİZ","NEGATİF VAR")
A9: Negatif fiyat var mı? | B9: =IF(COUNTIF(tblStok[Birim Alış Fiyatı (₺)],"<0")=0,"TEMİZ","NEGATİF VAR")
A10: Çıkış, girişten fazla mı? | B10: =IF(COUNTIF(HESAP!F6:F10,"<0")=0,"TEMİZ","EKSİK STOK")
A11: Devir hızı risk eşiğinin altında mı? | B11: =IF(StokDevirHizi<StokDevirRiskEsik,"AŞIYOR","NORMAL")
A12: Stoğa bağlanan nakit eşiği aşılıyor mu? | B12: =IF(StokBagNakit>StokBagNakitEsik,"AŞIYOR","NORMAL")
A13: Ortalama maliyet eşiği aşılıyor mu? | B13: =IF(StokOrtalamaMaliyet>StokMaliyetEsik,"AŞIYOR","NORMAL")
A15: Veri Kalitesi Skoru (0-100)
A16: Boş ve negatif girişlerin oranına göre üretilen kalite skoru.
A17: Toplam Giriş Hücresi | B17: =COUNTA(tblStok[Ürün])*COUNTA(tblStok[#Headers])
A18: Dolu Giriş Hücresi | B18: =COUNTA(tblStok[Ürün])+COUNTA(tblStok[Adet])+COUNTA(tblStok[Birim Alış Fiyatı (₺)])
A19: Kalite Skoru | B19: =ROUND(IF(StokToplamGiris=0,0,StokDoluGiris/StokToplamGiris*100),0)
A20: Kalite Seviyesi | B20: =IF(B19>=StokKaliteIyi,"YÜKSEK",IF(B19>=StokKaliteOrta,"ORTA","DÜŞÜK"))
A22: Kontroller yalnızca giriş verisini denetler; değerleri değiştirmez.

Sheet KARAR
A1: KARAR — Stok, Satış ve Nakit Bağlanma Sistemi
A3: Karar Kapısı — Stok Nakit Yeterliliği
A4: Stok değeri, devir hızı ve negatif stok durumuna göre üretilen karar.
A6: Stoğa Bağlanan Nakit | B6: =StokBagNakit
A7: Devir Hızı | B7: =StokDevirHizi
A8: Ortalama Maliyet | B8: =StokOrtalamaMaliyet
A9: Negatif Stok Var mı? | B9: =HESAP!B15
A11: KARAR | B11: =IF(COUNTA(tblStok[Ürün])=0,"VERİ YOK",IF(StokNegatifStok="VAR","DURDUR",IF(StokDevirHizi<StokDevirRiskEsik,"İNCELE","UYGUN")))
A12: Gerekçe | B12: =IF(StokNegatifStok="VAR","Negatif stok tespit edildi; hareket kayıtları mutlaka düzeltilmeli.",IF(StokDevirHizi<StokDevirRiskEsik,"Devir hızı risk eşiğinin altında; stoğa fazla nakit bağlanmış olabilir.","Karar kapısı uygun: stok AND devir göstergeleri hedef aralıkta."))
A14: Önerilen Aksiyonlar
A15: Aksiyon 1 | B15: =StokAksiyon1_ACIKLAMA
A16: Aksiyon 2 | B16: =StokAksiyon2_ACIKLAMA
A17: Aksiyon 3 | B17: =StokAksiyon3_ACIKLAMA
A19: Karar yalnızca giriş verisi ve AYARLAR'daki eşiklerden türetilir; kesin finansal tavsiye değildir.

Sheet SENARYO_DUYARLILIK
A1: SENARYO DUYARLILIK — Stok, Satış ve Nakit Bağlanma Sistemi
A3: Senaryo ve Duyarlılık Analizi
A4: İyimser, baz ve kötümser senaryolarda stok değeri; ardından hangi değişkenin sonucu en çok etkilediğini gösteren tornado analizi.
A6: Senaryo | B6: Hareket Tutarı Çarpanı | C6: Toplam Stok Değeri | D6: Devir Hızı
A7: İYİMSER | B7: =IF(StokBagNakit=0,0,StokIyiSenaryo) | C7: =ROUND(StokBagNakit*StokIyiSenaryo,0) | D7: =IF(StokBagNakit=0,0,C7/StokBagNakit)
A8: BAZ | B8: =IF(StokBagNakit=0,0,StokBazSenaryo) | C8: =ROUND(StokBagNakit*StokBazSenaryo,0) | D8: =IF(StokBagNakit=0,0,C8/StokBagNakit)
A9: KÖTÜMSER | B9: =IF(StokBagNakit=0,0,StokKotuSenaryo) | C9: =ROUND(StokBagNakit*StokKotuSenaryo,0) | D9: =IF(StokBagNakit=0,0,C9/StokBagNakit)
A11: Tornado: Toplam Stok Değerine Etki
A12: Birim Fiyat +%1 | B12: =ROUND(SUM(tblStok[Adet])*StokTornadoFiyat,0)
A13: Adet +%1 | B13: =ROUND(StokBagNakit*StokTornadoAdet,0)
A15: En Etkili Değişken | B15: =IF(B12>=B13,"Birim Fiyat","Adet")
A17: Tornado etkileri AYARLAR'daki çarpanlardan türetilir.

Sheet RAPOR
A1: STOK, SATIŞ VE NAKİT BAĞLANMA SİSTEMİ — YÖNETİCİ ÖZETİ
A2: =_xlfn.CONCAT("Rapor Tarihi: ",TEXT(RaporTarihi,"dd.mm.yyyy")," | Hazırlayan: ",RaporHazirlayan," | Sürüm: ",DosyaSurumu)
A4: Karar | B4: =KARAR!B11
A6: Stoğa Bağlanan Nakit | B6: =StokBagNakit
A7: Toplam Giriş Tutar | B7: =StokGirisTutar
A8: Toplam Çıkış Maliyet | B8: =StokCikisMaliyet
A9: Kalan Stok Adet | B9: =StokKalanAdet
A10: Ortalama Maliyet | B10: =StokOrtalamaMaliyet
A11: Devir Hızı | B11: =StokDevirHizi
A12: En Yüksek Stoklu Ürün | B12: =HESAP!B14
A13: Negatif Stok Var mı? | B13: =StokNegatifStok
A14: Kalite Skoru | B14: =KONTROLLER!B19
A16: Varsayımlar ve Önemli Notlar
A17: • Basit ortalama maliyet yöntemi kullanılır; farklı yöntem formül düzenlenerek uygulanabilir.
A18: • Çıkış hareketleri pozitif adetle girilir; adet negatif alınamaz.
A19: • Eşikler ve senaryo çarpanları AYARLAR sayfasından alınır.
A20: • Bu dosya muhasebe kaydı değildir; stok ve nakit karar destek aracıdır.
A21: • Demo veriler gerçek müşteri verisi değildir; kullanımdan önce temizlenmelidir.
A23: Önerilen Aksiyonlar
A24: =StokAksiyon1_ACIKLAMA
A25: =StokAksiyon2_ACIKLAMA
A26: =StokAksiyon3_ACIKLAMA
A28: Bu rapor karar destek amaçlıdır; mali tavsiye niteliği taşımaz.

Sheet ORNEK_VERI
A1: ORNEK VERI — Stok, Satış ve Nakit Bağlanma Sistemi
A3: Örnek Veri (Demo)
A4: Gerçek girişlere başlamadan önce demo veri ile ürünü deneyin. Bu satırlar örnektir; gerçek verilerle değiştirin.
A5: Tarih | B5: Ürün | C5: Hareket Türü | D5: Adet | E5: Birim Alış Fiyatı (₺) | F5: Depo | G5: Tutar (₺) | H5: Not
A6: 2026-01-05 | B6: Ürün A | C6: Giriş | D6: 100 | E6: 850 | F6: Ana Depo | G6: =IF($D6=0,0,$D6*$E6) | H6: =IF($B6="","",CONCATENATE("Örnek kayıt: ",$B6))
A7: 2026-01-12 | B7: Ürün B | C7: Giriş | D7: 60 | E7: 1250 | F7: Ana Depo | G7: =IF($D7=0,0,$D7*$E7) | H7: =IF($B7="","",CONCATENATE("Örnek kayıt: ",$B7))
A8: 2026-02-03 | B8: Ürün A | C8: Çıkış | D8: 40 | E8: 850 | F8: Ana Depo | G8: =IF($D8=0,0,$D8*$E8) | H8: =IF($B8="","",CONCATENATE("Örnek kayıt: ",$B8))
A9: 2026-02-18 | B9: Ürün C | C9: Giriş | D9: 90 | E9: 420 | F9: Yedek Depo | G9: =IF($D9=0,0,$D9*$E9) | H9: =IF($B9="","",CONCATENATE("Örnek kayıt: ",$B9))
A10: 2026-03-07 | B10: Ürün B | C10: Çıkış | D10: 25 | E10: 1250 | F10: Ana Depo | G10: =IF($D10=0,0,$D10*$E10) | H10: =IF($B10="","",CONCATENATE("Örnek kayıt: ",$B10))
A11: 2026-03-21 | B11: Ürün A | C11: Giriş | D11: 80 | E11: 900 | F11: Ana Depo | G11: =IF($D11=0,0,$D11*$E11) | H11: =IF($B11="","",CONCATENATE("Örnek kayıt: ",$B11))
G12: =IF($D12=0,0,$D12*$E12) | H12: =IF($B12="","",CONCATENATE("Örnek kayıt: ",$B12))
G13: =IF($D13=0,0,$D13*$E13) | H13: =IF($B13="","",CONCATENATE("Örnek kayıt: ",$B13))
G14: =IF($D14=0,0,$D14*$E14) | H14: =IF($B14="","",CONCATENATE("Örnek kayıt: ",$B14))
G15: =IF($D15=0,0,$D15*$E15) | H15: =IF($B15="","",CONCATENATE("Örnek kayıt: ",$B15))
G16: =IF($D16=0,0,$D16*$E16) | H16: =IF($B16="","",CONCATENATE("Örnek kayıt: ",$B16))
G17: =IF($D17=0,0,$D17*$E17) | H17: =IF($B17="","",CONCATENATE("Örnek kayıt: ",$B17))
G18: =IF($D18=0,0,$D18*$E18) | H18: =IF($B18="","",CONCATENATE("Örnek kayıt: ",$B18))
G19: =IF($D19=0,0,$D19*$E19) | H19: =IF($B19="","",CONCATENATE("Örnek kayıt: ",$B19))
G20: =IF($D20=0,0,$D20*$E20) | H20: =IF($B20="","",CONCATENATE("Örnek kayıt: ",$B20))
G21: =IF($D21=0,0,$D21*$E21) | H21: =IF($B21="","",CONCATENATE("Örnek kayıt: ",$B21))
G22: =IF($D22=0,0,$D22*$E22) | H22: =IF($B22="","",CONCATENATE("Örnek kayıt: ",$B22))
G23: =IF($D23=0,0,$D23*$E23) | H23: =IF($B23="","",CONCATENATE("Örnek kayıt: ",$B23))
... G1004: =IF($D1004=0,0,$D1004*$E1004) | H1004: =IF($B1004="","",CONCATENATE("Örnek kayıt: ",$B1004))
A1006: Demo veriler rapor sonuçlarını örnekler; satın alma sonrası silinerek gerçek veriler girilir.

Sheet AKIS
A1: AKIS — StokSatisVeNakitBaglanmaSistemi
A3: islem_id | B3: kaynak_kart_id | C3: onceki_durum | D3: yeni_durum | E3: tutar | F3: bayrak | G3: not
A4: I-001 | B4: KART-01 | C4: ACIK | D4: ISLEMDE | E4: 1000 | F4: OK | G4: normal geçiş
A5: I-002 | B5: YETİM | C5: ACIK | D5: KAPALI | E5: 0 | F5: YETİM | G5: kaynak_kart_id yok — yetim kayıt
A6: I-003 | B6: KART-02 | C6: ACIK | D6: KAPALI | E6: 500 | F6: GECERSIZ | G6: geçersiz durum geçişi
A7: I-004 | B7: KART-03 | C7: ISLEMDE | D7: ISLEMDE | E7: 250 | F7: ZINCIR_KIRIK | G7: ZİNCİR KIRIK — tutar zinciri sapması
A9: kuyruk_kanit | B9: =IFERROR(COUNTIF($F$4:$F$1000,"OK"),0)

Sheet DEGISIKLIK_KAYDI
A1: DEGISIKLIK KAYDI — Stok, Satış ve Nakit Bağlanma Sistemi
A3: Değişiklik Kaydı
A4: Tarih | B4: Sürüm | C4: Değişiklik | D4: Neden | E4: Yapan
A5: 01.08.2026 | B5: 1.0.0 | C5: İlk üretim | D5: Ürünün yayına hazırlanması | E5: ExcelArşiv

Sheet LISTELER
A1: LISTELER — Stok, Satış ve Nakit Bağlanma Sistemi
A3: Bağlı Listeler
A4: Bu sayfadaki listeler açılır menüleri besler; yeni seçenek eklemek için sarı hücrelere yazın.
A6: Ürün | C6: Hareket Türü | E6: Depo
A7: Ürün A | C7: Giriş | E7: Ana Depo
A8: Ürün B | C8: Çıkış | E8: Yedek Depo
A9: Ürün C | E9: Diğer
A10: Ürün D
A11: Diğer

Sheet AYARLAR
A1: AYARLAR — Stok, Satış ve Nakit Bağlanma Sistemi
A3: Sistem Ayarları ve Oranlar
A4: Tüm sabitler bu sayfadadır. Eşikleri ve çarpanları kendi işletmenize göre güncelleyin. Değişen her değer tüm hesaplamalara anında yansır.
A6: anahtar | B6: deger | C6: birim | D6: alt | E6: ust | F6: aciklama | G6: kaynak | H6: yururluk_tarihi | I6: dogrulama_tarihi
A7: FirmaUnvan | B7: Örnek Firma A.Ş. | C7: Metin | F7: Rapor ve kapakta görünen firma adı. | G7: Kullanıcı | H7: 46023 | I7: 46244
A8: RaporTarihi | B8: 46242 | C8: Tarih | F8: Tüm hesapların ve kararın alındığı tarih. | G8: Kullanıcı | H8: 46023 | I8: 46244
A9: RaporHazirlayan | B9: Finans Direktörü | C9: Metin | F9: Raporu hazırlayan kişi/rol. | G9: Kullanıcı | H9: 46023 | I9: 46244
A10: DosyaSurumu | B10: 1.0.0 | C10: Metin | F10: Ürün sürüm bilgisi; rapor alt bilgisinde görünür. | G10: Kullanıcı | H10: 46023 | I10: 46244
A11: StokDevirHedef | B11: 6 | C11: Oran | D11: 0 | E11: 50 | F11: Devir hızı hedef eşiği; altındaysa stok yavaş akıyor demektir. | G11: Varsayım | H11: 46023 | I11: 46244
A12: StokDevirRiskEsik | B12: 3 | C12: Oran | D12: 0 | E12: 50 | F12: Devir hızı bu eşiğin altındaysa kontrol uyarır. | G12: Varsayım | H12: 46023 | I12: 46244
A13: StokBagNakitEsik | B13: 500000 | C13: TL | D13: 0 | E13: 1000000000 | F13: Stoğa bağlanan nakit bu eşiği aşarsa karar İNCELE olur. | G13: Varsayım | H13: 46023 | I13: 46244
A14: StokMaliyetEsik | B14: 1000 | C14: TL | D14: 0 | E14: 1000000000 | F14: Ortalama birim maliyet bu eşiği aşarsa kontrol uyarır. | G14: Varsayım | H14: 46023 | I14: 46244
A15: StokIyiSenaryo | B15: 1.05 | C15: Oran | D15: 0.5 | E15: 1.5 | F15: İyimser senaryoda stok değeri bu çarpanla hesaplanır. | G15: Varsayım | H15: 46023 | I15: 46244
A16: StokBazSenaryo | B16: 1 | C16: Oran | D16: 0.5 | E16: 1.5 | F16: Baz senaryoda stok değeri bu çarpanla hesaplanır. | G16: Varsayım | H16: 46023 | I16: 46244
A17: StokKotuSenaryo | B17: 0.95 | C17: Oran | D17: 0.5 | E17: 1.5 | F17: Kötümser senaryoda stok değeri bu çarpanla hesaplanır. | G17: Varsayım | H17: 46023 | I17: 46244
A18: StokTornadoFiyat | B18: 0.01 | C18: Oran | D18: 0 | E18: 0.2 | F18: Fiyatın %1 artışının stok değerine etkisi. | G18: Varsayım | H18: 46023 | I18: 46244
A19: StokTornadoAdet | B19: 0.01 | C19: Oran | D19: 0 | E19: 0.2 | F19: Adetin %1 artışının stok değerine etkisi. | G19: Varsayım | H19: 46023 | I19: 46244
A20: StokTahminCarpan | B20: 1.645 | C20: Oran | D20: 0 | E20: 3 | F20: Tahmin bandı genişliği (standart sapma katı). | G20: Varsayım | H20: 46023 | I20: 46244
A21: StokKaliteIyi | B21: 90 | C21: Skor | D21: 0 | E21: 100 | F21: Kalite skoru bu eşiğin üzerindeyse YÜKSEK kalite. | G21: Varsayım | H21: 46023 | I21: 46244
A22: StokKaliteOrta | B22: 70 | C22: Skor | D22: 0 | E22: 100 | F22: Kalite skoru bu eşiğin üzerindeyse ORTA kalite. | G22: Varsayım | H22: 46023 | I22: 46244
A23: StokAksiyon1_ACIKLAMA | B23: Devir hızı düşükse stok fazlası ürünlerde satış kampanyası planlayın. | C23: Metin | F23: DURDUR kararında gösterilen ilk öneri. | G23: Varsayım | H23: 46023 | I23: 46244
A24: StokAksiyon2_ACIKLAMA | B24: Stoğa bağlanan nakit eşiği aşılıyorsa alış partilerini küçültün ve teslimat süresini kısaltın. | C24: Metin | F24: İNCELE kararında gösterilen ikinci öneri. | G24: Varsayım | H24: 46023 | I24: 46244
A25: StokAksiyon3_ACIKLAMA | B25: Negatif stok varsa hareket kayıtlarını ve devirleri mutlaka düzeltin. | C25: Metin | F25: İNCELE kararında gösterilen üçüncü öneri. | G25: Varsayım | H25: 46023 | I25: 46244
A26: StokP90Oran | B26: 0.9 | C26: Oran | D26: 0.5 | E26: 1 | F26: Hareket tutarı dağılımında üst yüzdelik dilimin oranı. | G26: Varsayım | H26: 46023 | I26: 46244
A27: StokPanelSatir1 | B27: 1 | C27: Satır | F27: PANO'daki aylık hareket grafiği serisinin tablodaki veri satırı (1. veri). | G27: Kullanıcı | H27: 46023 | I27: 46244
A28: StokPanelSatir2 | B28: 2 | C28: Satır | F28: PANO'daki aylık hareket grafiği serisinin tablodaki veri satırı (2. veri). | G28: Kullanıcı | H28: 46023 | I28: 46244
A29: StokPanelSatir3 | B29: 3 | C29: Satır | F29: PANO'daki aylık hareket grafiği serisinin tablodaki veri satırı (3. veri). | G29: Kullanıcı | H29: 46023 | I29: 46244
A30: StokPanelSatir4 | B30: 4 | C30: Satır | F30: PANO'daki aylık hareket grafiği serisinin tablodaki veri satırı (4. veri). | G30: Kullanıcı | H30: 46023 | I30: 46244
A31: StokPanelSatir5 | B31: 5 | C31: Satır | F31: PANO'daki aylık hareket grafiği serisinin tablodaki veri satırı (5. veri). | G31: Kullanıcı | H31: 46023 | I31: 46244
A32: StokPanelSatir6 | B32: 6 | C32: Satır | F32: PANO'daki aylık hareket grafiği serisinin tablodaki veri satırı (6. veri). | G32: Kullanıcı | H32: 46023 | I32: 46244
A33: StokPanelSatir7 | B33: 7 | C33: Satır | F33: PANO'daki aylık hareket grafiği serisinin tablodaki veri satırı (7. veri). | G33: Kullanıcı | H33: 46023 | I33: 46244
A34: StokPanelSatir8 | B34: 8 | C34: Satır | F34: PANO'daki aylık hareket grafiği serisinin tablodaki veri satırı (8. veri). | G34: Kullanıcı | H34: 46023 | I34: 46244
A35: StokPanelSatir9 | B35: 9 | C35: Satır | F35: PANO'daki aylık hareket grafiği serisinin tablodaki veri satırı (9. veri). | G35: Kullanıcı | H35: 46023 | I35: 46244
A36: StokPanelSatir10 | B36: 10 | C36: Satır | F36: PANO'daki aylık hareket grafiği serisinin tablodaki veri satırı (10. veri). | G36: Kullanıcı | H36: 46023 | I36: 46244
A37: StokPanelSatir11 | B37: 11 | C37: Satır | F37: PANO'daki aylık hareket grafiği serisinin tablodaki veri satırı (11. veri). | G37: Kullanıcı | H37: 46023 | I37: 46244
A38: StokPanelSatir12 | B38: 12 | C38: Satır | F38: PANO'daki aylık hareket grafiği serisinin tablodaki veri satırı (12. veri). | G38: Kullanıcı | H38: 46023 | I38: 46244
J40: durum_haritasi | K40: durum_id | L40: durum_adi | M40: izinli_sonraki | N40: kategori
J41: HARITA | K41: ACIK | L41: Açık | M41: ISLEMDE | N41: acik
J42: HARITA | K42: ISLEMDE | L42: İşlemde | M42: KAPALI | N42: acik
J43: HARITA | K43: KAPALI | L43: Kapalı | M43: - | N43: kapali
...

Sheet KILAVUZ
A1: KILAVUZ — Stok, Satış ve Nakit Bağlanma Sistemi
A3: Kullanım Kılavuzu
A5: Veri girişi | B5: STOK_HAREKETLER sayfasında sarı hücrelere hareket girin. Ürünü ve depoyu listeden seçin, tarihi GG.AA.YYYY biçiminde yazın, çıkışları pozitif adetle Çıkış türüyle kaydedin.
A6: Hesap katmanı | B6: HESAP sayfası ürün bazlı giriş, çıkış, kalan stok, ortalama maliyet, stok değeri ve devir hızını otomatik özetler.
A7: Karar ve rapor | B7: KARAR sayfası UYGUN/İNCELE/DURDUR kararını üretir; RAPOR yöneticiye sunulabilir.
A8: Ayarlar | B8: AYARLAR sayfasındaki eşikleri ve çarpanları mali müşavir veya kendi tecrübenize göre güncelleyin.
A9: Koruma | B9: Tüm sayfalar 1234 şifresiyle korunur; sarı hücreler serbesttir, formül hücreleri kilitlidir.
A11: Bu dosya karar destek aracıdır; muhasebe kaydı ve vergi beyanı niteliği taşımaz.
A13: Varsayım İşaretli Parametreler
A14: Aşağıdaki eşik ve çarpanlar AYARLAR sayfasında kaynak=Varsayım olarak işaretlidir; mevzuat zorunluluğu yoktur ve işletmeye göre güncellenmelidir.
A15: • Devir Hızı Hedef ve Risk Eşikleri
A16: • Stoğa Bağlanan Nakit Eşiği
A17: • Ortalama Maliyet Risk Eşiği
A18: • İyimser, Baz ve Kötümser Senaryo Çarpanları
A19: • Tornado Fiyat ve Adet Etkisi Oranları
A20: • Tahmin Çarpanı (standart sapma katı)
A21: • Kalite Skoru İyi ve Orta Eşikleri
A22: • P90 Yüzdelik Oranı
A23: • Aksiyon Önerisi Açıklamaları
A25: Bu dosya tamamen çevrimdışı çalışır; verileriniz cihazınızdan çıkmaz. Makro ve dış bağlantı yoktur.
