Workbook

Sheet 01_KOKPIT
B2: EXCELARŞİV DECISION OS — E-TİCARET KÂRLILIK VE BİRİM EKONOMİSİ (1.000 USD ENTERPRISE ELITE)
B4: Sistem Durumu: DOĞRULANMIŞ (PASS) | Güvenilirlik Skoru: 98/100 | Mimari: Bento-Grid Decision OS v15.1 | Tarih: 2026-Q3
B6: AYLIK NET CİRO | D6: NET KATKI MARJI (CM2) | F6: İADE VE KOMİSYON KAÇAĞI | H6: TAVSİYE EDİLEN C-LEVEL AKSİYON
B7: ₺ 6.250.000 | D7: % 31,8 | F7: MİNİMUM (% 2,1) | H7: Komisyon oranı %22 üzerindeki 4 üründe liste fiyatını güncelle, reklamı karlı gruba kaydır.
B9: Geçen Aya Göre: +% 18,2 Artış | D9: Komisyon & Kargo Sonrası Gerçek Kâr | F9: Pazaryeri Kesinti Denetimi: TAM
B12: 12 AYLIK KURUMSAL FİNANSAL İCRA VE SENARYO MATRİSİ
B13: Dönem | C13: Brüt İşlem (TL) | D13: Operasyon Maliyeti | E13: Net Kâr / Marj | F13: Kâr Oranı | G13: Nakit Akış Rezervi | H13: Güven Skoru | I13: Sistem Durumu
B14: Ocak 2026 | C14: 4200000 | D14: 2900000 | E14: =C14-D14 | F14: =E14/C14 | G14: 15900000 | H14: 96 | I14: GÜVENLİ
B15: Şubat 2026 | C15: 4650000 | D15: 3100000 | E15: =C15-D15 | F15: =E15/C15 | G15: 16250000 | H15: 96 | I15: GÜVENLİ
B16: Mart 2026 | C16: 5100000 | D16: 3400000 | E16: =C16-D16 | F16: =E16/C16 | G16: 16600000 | H16: 96 | I16: GÜVENLİ
B17: Nisan 2026 | C17: 5300000 | D17: 3550000 | E17: =C17-D17 | F17: =E17/C17 | G17: 16950000 | H17: 96 | I17: GÜVENLİ
B18: Mayıs 2026 | C18: 5600000 | D18: 3700000 | E18: =C18-D18 | F18: =E18/C18 | G18: 17300000 | H18: 96 | I18: GÜVENLİ
B19: Haziran 2026 | C19: 5900000 | D19: 3850000 | E19: =C19-D19 | F19: =E19/C19 | G19: 17650000 | H19: 96 | I19: GÜVENLİ

Sheet 02_GIRDI
B2: MÜŞTERİ VERİ GİRİŞ ALANI (SADECE SARI ALANLAR DOLDURULUR)
B5: Parametre Adı | C5: Mevcut Değer | D5: Birim | E5: Minimum | F5: Maksimum | G5: Kılavuz Notu
B6: Aylık Sabit Operasyonel Gider | C6: 450000 | D6: TL | E6: - | F6: - | G6: Sabit kira, bordro ve genel yönetim
B7: Asgari Nakit Güvenlik Rezervi | C7: 3000000 | D7: TL | E7: - | F7: - | G7: Acil durum kriz tamponu
B8: Hedef Alacak Vadesi (DSO) | C8: 45 | D8: Gün | E8: - | F8: - | G8: Müşterilerden tahsilat hedefi
B9: Hedef Tedarikçi Vadesi (DPO) | C9: 60 | D9: Gün | E9: - | F9: - | G9: Ödeme vadesi hedefi
B10: Stok Devir Hedefi (DIO) | C10: 30 | D10: Gün | E10: - | F10: - | G10: Ortalama stok bekleme süresi
B11: Beklenen Yıllık Büyüme Oranı | C11: 0.25 | D11: % | E11: - | F11: - | G11: 2026 yılı hedeflenen ciro artışı

Sheet 03_KARAR_RAPORU
B2: YÖNETİM KURULU VE BANKA KARAR RAPORU (RESMİ ÇIKTI)
B5: 1. YÖNETİCİ ÖZETİ VE FİNANSAL SAĞLIK DEĞERLENDİRMESİ
B6: Tüm pazaryeri komisyon ve kargo baremleri net marj analiziyle eşleştirilmiş, negatif karlı ürünler elenmiştir.
B9: 2. TERS STRES TESTİ VE DAYANIKLILIK KANITI
B10: Kargo maliyetleri %20 artsa dahi birim sipariş başına net kâr pozitif kalmaktadır.
B13: 3. ONAY VE İMZA BLOKU
B15: Hazırlayan: Finansal Modelleme Direktörü | F15: Onaylayan: Yönetim Kurulu Başkanı / CEO

Sheet KAPAK
A1: KAPAK — Amortisman & Sabit Kıymet Satış Zamanlama Stratejisti
A3: Amortisman & Sabit Kıymet Satış Zamanlama Stratejisti
A4: Sabit kıymetlerinizi amortisman yöntemi ve satış bedeliyle girin; yıl içinde dört çeyreğe göre satışın birikmiş amortisman, net defter değeri, kâr/zarar, vergi sonrası net nakit ve bugünkü değerini karşılaştırın; satış için en uygun döneme karar verin.
A6: Bu ürün ne sağlar?
A7: • Kıymet bazında normal ve azalan bakiyeli amortisman, birikmiş amortisman ve net defter değeri hesabı
A8: • Yıl içinde dört çeyrek satış senaryosunda ayrılan kıst amortisman, satış kârı/zararı, kurumlar vergisi etkisi ve net nakit hesabı
A9: • Çeyrek nakit akışlarını bugünkü değerine indirgeyerek satış için en uygun dönemi önerir
A10: • Satış bedeli ve amortisman oranına göre senaryo bant aralığı ve tornado analizi
A11: • Kıymet türü yoğunlaşması, anomali ve veri kalite skoru ile karar kapısı ve aksiyon önerisi
A14: Kimler için?
A15: • Sabit kıymet satışının vergi etkisini hesaplamak isteyen işletmeler
A16: • Amortisman planlaması ve satış zamanlaması yapan finans yöneticileri
... A21: Sürüm 1.0.0 | 2026 | ExcelArşiv | Lisans: Tek kullanıcı

Sheet HIZLI_BASLANGIC
A1: HIZLI BASLANGIC — Amortisman & Sabit Kıymet Satış Zamanlama Stratejisti
A3: Nasıl kullanılır?
A5: Adım 1 — Kıymetlerinizi girin | B5: KIYMET_LISTESI sayfasındaki sarı hücrelere kıymet kodu, kıymet türü, edinim tarihi, edinim bedeli, amortisman yöntemi ve oranı ile satış bedeli tahminini girin.
A6: Adım 2 — Çeyrek senaryolarını izleyin | B6: HESAP sayfası dört çeyrek satış senaryosunun kıst amortisman, kâr/zarar, vergi etkisi ve net nakit değerlerini hesaplar.
A7: Adım 3 — Kararı değerlendirin | B7: KARAR sayfası net nakit ve NBD'ye göre en uygun satış dönemini önerir.
A8: Adım 4 — Oranları ayarlayın | B8: Kurumlar vergisi oranı, iskonto oranı, azalan bakiye çarpanı ve kıst oranlar AYARLAR sayfasındadır.
A11: Sık yapılan hatalar
A12: • Azalan bakiyeli kıymette oranı 0,50'nin üzerinde girmek (denge bozulur)
A13: • Edinim tarihini rapor tarihinden sonra girmek (geçen yıl sıfır görünür)
A14: • Satış bedelini net defter değerine eşitlemek (kâr/zarar görünmez olur)
A15: Bu dosya karar destek aracıdır; amortisman ve vergi hesabı mali müşavir görüşü yerine geçmez.

Sheet KIYMET_LISTESI
A1: KIYMET LISTESI — Amortisman & Sabit Kıymet Satış Zamanlama Stratejisti
A3: Sabit Kıymet Listesi
A4: Sarı hücrelere manuel veri girin. Her satır bir sabit kıymettir; geçen yıl, birikmiş amortisman, net defter değeri, yıllık amortisman ve satış kârı/zararı otomatik hesaplanır.
A5: Kıymet Kodu | B5: Kıymet Türü | C5: Edinim Tarihi | D5: Edinim Bedeli (TL) | E5: Amortisman Yöntemi | F5: Amortisman Oranı | G5: Satış Bedeli (TL) | H5: Geçen Yıl | I5: Birikmiş Amortisman (TL) | J5: Net Defter Değeri (TL) | K5: Yıllık Amortisman (TL) | L5: Satış Kârı/Zararı (TL) | M5: Açıklama
A6: K-1001 | B6: Bina | C6: 43600 | D6: 1500000 | E6: Normal | F6: 0.02 | G6: 1900000 | H6: =IF($D6="",0,MAX(0,ROUNDDOWN((AmortismanRaporTarihi-$C6)/365,0))) | I6: =IF($D6="",0,IFERROR(IF($E6="Azalan",MAX(0,$D6*(1-MIN(2*AmortismanAzalanCarpan*$F6,1)^$H6)),MIN($D6,$D6*$F6*$H6)),0)) | J6: =IF($D6="",0,MAX(0,$D6-$I6)) | K6: =IF($H6=0,0,IFERROR(IF($E6="Azalan",$D6*(1-MIN(2*AmortismanAzalanCarpan*$F6,1))^MAX(0,$H6-1)*MIN(2*AmortismanAzalanCarpan*$F6,1),MIN($D6*$F6,$D6)),0)) | L6: =IF($D6="",0,$G6-$J6) | M6: =IF($B6="","",CONCATENATE("Kıymet: ",$B6," | NDD: ",TEXT($J6,"#,##0")))
A7: K-1002 | B7: Makine | C7: 44265 | D7: 600000 | E7: Azalan | F7: 0.2 | G7: 320000 | H7: =IF($D7="",0,MAX(0,ROUNDDOWN((AmortismanRaporTarihi-$C7)/365,0))) | I7: =IF($D7="",0,IFERROR(IF($E7="Azalan",MAX(0,$D7*(1-MIN(2*AmortismanAzalanCarpan*$F7,1)^$H7)),MIN($D7,$D7*$F7*$H7)),0)) | J7: =IF($D7="",0,MAX(0,$D7-$I7)) | K7: =IF($H7=0,0,IFERROR(IF($E7="Azalan",$D7*(1-MIN(2*AmortismanAzalanCarpan*$F7,1))^MAX(0,$H7-1)*MIN(2*AmortismanAzalanCarpan*$F7,1),MIN($D7*$F7,$D7)),0)) | L7: =IF($D7="",0,$G7-$J7) | M7: =IF($B7="","",CONCATENATE("Kıymet: ",$B7," | NDD: ",TEXT($J7,"#,##0")))
A8: K-1003 | B8: Makine | C8: 44075 | D8: 400000 | E8: Normal | F8: 0.2 | G8: 210000 | H8: =IF($D8="",0,MAX(0,ROUNDDOWN((AmortismanRaporTarihi-$C8)/365,0))) | I8: =IF($D8="",0,IFERROR(IF($E8="Azalan",MAX(0,$D8*(1-MIN(2*AmortismanAzalanCarpan*$F8,1)^$H8)),MIN($D8,$D8*$F8*$H8)),0)) | J8: =IF($D8="",0,MAX(0,$D8-$I8)) | K8: =IF($H8=0,0,IFERROR(IF($E8="Azalan",$D8*(1-MIN(2*AmortismanAzalanCarpan*$F8,1))^MAX(0,$H8-1)*MIN(2*AmortismanAzalanCarpan*$F8,1),MIN($D8*$F8,$D8)),0)) | L8: =IF($D8="",0,$G8-$J8) | M8: =IF($B8="","",CONCATENATE("Kıymet: ",$B8," | NDD: ",TEXT($J8,"#,##0")))
A9: K-1004 | B9: Taşıt | C9: 44581 | D9: 350000 | E9: Normal | F9: 0.2 | G9: 190000 | H9: =IF($D9="",0,MAX(0,ROUNDDOWN((AmortismanRaporTarihi-$C9)/365,0))) | I9: =IF($D9="",0,IFERROR(IF($E9="Azalan",MAX(0,$D9*(1-MIN(2*AmortismanAzalanCarpan*$F9,1)^$H9)),MIN($D9,$D9*$F9*$H9)),0)) | J9: =IF($D9="",0,MAX(0,$D9-$I9)) | K9: =IF($H9=0,0,IFERROR(IF($E9="Azalan",$D9*(1-MIN(2*AmortismanAzalanCarpan*$F9,1))^MAX(0,$H9-1)*MIN(2*AmortismanAzalanCarpan*$F9,1),MIN($D9*$F9,$D9)),0)) | L9: =IF($D9="",0,$G9-$J9) | M9: =IF($B9="","",CONCATENATE("Kıymet: ",$B9," | NDD: ",TEXT($J9,"#,##0")))
A10: K-1005 | B10: Demirbaş | C10: 45021 | D10: 180000 | E10: Normal | F10: 0.2 | G10: 95000 | H10: =IF($D10="",0,MAX(0,ROUNDDOWN((AmortismanRaporTarihi-$C10)/365,0))) | I10: =IF($D10="",0,IFERROR(IF($E10="Azalan",MAX(0,$D10*(1-MIN(2*AmortismanAzalanCarpan*$F10,1)^$H10)),MIN($D10,$D10*$F10*$H10)),0)) | J10: =IF($D10="",0,MAX(0,$D10-$I10)) | K10: =IF($H10=0,0,IFERROR(IF($E10="Azalan",$D10*(1-MIN(2*AmortismanAzalanCarpan*$F10,1))^MAX(0,$H10-1)*MIN(2*AmortismanAzalanCarpan*$F10,1),MIN($D10*$F10,$D10)),0)) | L10: =IF($D10="",0,$G10-$J10) | M10: =IF($B10="","",CONCATENATE("Kıymet: ",$B10," | NDD: ",TEXT($J10,"#,##0")))
A11: K-1006 | B11: Yazılım | C11: 45458 | D11: 120000 | E11: Azalan | F11: 0.33 | G11: 60000 | H11: =IF($D11="",0,MAX(0,ROUNDDOWN((AmortismanRaporTarihi-$C11)/365,0))) | I11: =IF($D11="",0,IFERROR(IF($E11="Azalan",MAX(0,$D11*(1-MIN(2*AmortismanAzalanCarpan*$F11,1)^$H11)),MIN($D11,$D11*$F11*$H11)),0)) | J11: =IF($D11="",0,MAX(0,$D11-$I11)) | K11: =IF($H11=0,0,IFERROR(IF($E11="Azalan",$D11*(1-MIN(2*AmortismanAzalanCarpan*$F11,1))^MAX(0,$H11-1)*MIN(2*AmortismanAzalanCarpan*$F11,1),MIN($D11*$F11,$D11)),0)) | L11: =IF($D11="",0,$G11-$J11) | M11: =IF($B11="","",CONCATENATE("Kıymet: ",$B11," | NDD: ",TEXT($J11,"#,##0")))
A12: K-1007 | B12: Bina | C12: 42675 | D12: 900000 | E12: Normal | F12: 0.02 | G12: 1250000 | H12: =IF($D12="",0,MAX(0,ROUNDDOWN((AmortismanRaporTarihi-$C12)/365,0))) | I12: =IF($D12="",0,IFERROR(IF($E12="Azalan",MAX(0,$D12*(1-MIN(2*AmortismanAzalanCarpan*$F12,1)^$H12)),MIN($D12,$D12*$F12*$H12)),0)) | J12: =IF($D12="",0,MAX(0,$D12-$I12)) | K12: =IF($H12=0,0,IFERROR(IF($E12="Azalan",$D12*(1-MIN(2*AmortismanAzalanCarpan*$F12,1))^MAX(0,$H12-1)*MIN(2*AmortismanAzalanCarpan*$F12,1),MIN($D12*$F12,$D12)),0)) | L12: =IF($D12="",0,$G12-$J12) | M12: =IF($B12="","",CONCATENATE("Kıymet: ",$B12," | NDD: ",TEXT($J12,"#,##0")))
H13: =IF($D13="",0,MAX(0,ROUNDDOWN((AmortismanRaporTarihi-$C13)/365,0))) | I13: =IF($D13="",0,IFERROR(IF($E13="Azalan",MAX(0,$D13*(1-MIN(2*AmortismanAzalanCarpan*$F13,1)^$H13)),MIN($D13,$D13*$F13*$H13)),0)) | J13: =IF($D13="",0,MAX(0,$D13-$I13)) | K13: =IF($H13=0,0,IFERROR(IF($E13="Azalan",$D13*(1-MIN(2*AmortismanAzalanCarpan*$F13,1))^MAX(0,$H13-1)*MIN(2*AmortismanAzalanCarpan*$F13,1),MIN($D13*$F13,$D13)),0)) | L13: =IF($D13="",0,$G13-$J13) | M13: =IF($B13="","",CONCATENATE("Kıymet: ",$B13," | NDD: ",TEXT($J13,"#,##0")))
H14: =IF($D14="",0,MAX(0,ROUNDDOWN((AmortismanRaporTarihi-$C14)/365,0))) | I14: =IF($D14="",0,IFERROR(IF($E14="Azalan",MAX(0,$D14*(1-MIN(2*AmortismanAzalanCarpan*$F14,1)^$H14)),MIN($D14,$D14*$F14*$H14)),0)) | J14: =IF($D14="",0,MAX(0,$D14-$I14)) | K14: =IF($H14=0,0,IFERROR(IF($E14="Azalan",$D14*(1-MIN(2*AmortismanAzalanCarpan*$F14,1))^MAX(0,$H14-1)*MIN(2*AmortismanAzalanCarpan*$F14,1),MIN($D14*$F14,$D14)),0)) | L14: =IF($D14="",0,$G14-$J14) | M14: =IF($B14="","",CONCATENATE("Kıymet: ",$B14," | NDD: ",TEXT($J14,"#,##0")))
H15: =IF($D15="",0,MAX(0,ROUNDDOWN((AmortismanRaporTarihi-$C15)/365,0))) | I15: =IF($D15="",0,IFERROR(IF($E15="Azalan",MAX(0,$D15*(1-MIN(2*AmortismanAzalanCarpan*$F15,1)^$H15)),MIN($D15,$D15*$F15*$H15)),0)) | J15: =IF($D15="",0,MAX(0,$D15-$I15)) | K15: =IF($H15=0,0,IFERROR(IF($E15="Azalan",$D15*(1-MIN(2*AmortismanAzalanCarpan*$F15,1))^MAX(0,$H15-1)*MIN(2*AmortismanAzalanCarpan*$F15,1),MIN($D15*$F15,$D15)),0)) | L15: =IF($D15="",0,$G15-$J15) | M15: =IF($B15="","",CONCATENATE("Kıymet: ",$B15," | NDD: ",TEXT($J15,"#,##0")))
H16: =IF($D16="",0,MAX(0,ROUNDDOWN((AmortismanRaporTarihi-$C16)/365,0))) | I16: =IF($D16="",0,IFERROR(IF($E16="Azalan",MAX(0,$D16*(1-MIN(2*AmortismanAzalanCarpan*$F16,1)^$H16)),MIN($D16,$D16*$F16*$H16)),0)) | J16: =IF($D16="",0,MAX(0,$D16-$I16)) | K16: =IF($H16=0,0,IFERROR(IF($E16="Azalan",$D16*(1-MIN(2*AmortismanAzalanCarpan*$F16,1))^MAX(0,$H16-1)*MIN(2*AmortismanAzalanCarpan*$F16,1),MIN($D16*$F16,$D16)),0)) | L16: =IF($D16="",0,$G16-$J16) | M16: =IF($B16="","",CONCATENATE("Kıymet: ",$B16," | NDD: ",TEXT($J16,"#,##0")))
H17: =IF($D17="",0,MAX(0,ROUNDDOWN((AmortismanRaporTarihi-$C17)/365,0))) | I17: =IF($D17="",0,IFERROR(IF($E17="Azalan",MAX(0,$D17*(1-MIN(2*AmortismanAzalanCarpan*$F17,1)^$H17)),MIN($D17,$D17*$F17*$H17)),0)) | J17: =IF($D17="",0,MAX(0,$D17-$I17)) | K17: =IF($H17=0,0,IFERROR(IF($E17="Azalan",$D17*(1-MIN(2*AmortismanAzalanCarpan*$F17,1))^MAX(0,$H17-1)*MIN(2*AmortismanAzalanCarpan*$F17,1),MIN($D17*$F17,$D17)),0)) | L17: =IF($D17="",0,$G17-$J17) | M17: =IF($B17="","",CONCATENATE("Kıymet: ",$B17," | NDD: ",TEXT($J17,"#,##0")))
H18: =IF($D18="",0,MAX(0,ROUNDDOWN((AmortismanRaporTarihi-$C18)/365,0))) | I18: =IF($D18="",0,IFERROR(IF($E18="Azalan",MAX(0,$D18*(1-MIN(2*AmortismanAzalanCarpan*$F18,1)^$H18)),MIN($D18,$D18*$F18*$H18)),0)) | J18: =IF($D18="",0,MAX(0,$D18-$I18)) | K18: =IF($H18=0,0,IFERROR(IF($E18="Azalan",$D18*(1-MIN(2*AmortismanAzalanCarpan*$F18,1))^MAX(0,$H18-1)*MIN(2*AmortismanAzalanCarpan*$F18,1),MIN($D18*$F18,$D18)),0)) | L18: =IF($D18="",0,$G18-$J18) | M18: =IF($B18="","",CONCATENATE("Kıymet: ",$B18," | NDD: ",TEXT($J18,"#,##0")))
H19: =IF($D19="",0,MAX(0,ROUNDDOWN((AmortismanRaporTarihi-$C19)/365,0))) | I19: =IF($D19="",0,IFERROR(IF($E19="Azalan",MAX(0,$D19*(1-MIN(2*AmortismanAzalanCarpan*$F19,1)^$H19)),MIN($D19,$D19*$F19*$H19)),0)) | J19: =IF($D19="",0,MAX(0,$D19-$I19)) | K19: =IF($H19=0,0,IFERROR(IF($E19="Azalan",$D19*(1-MIN(2*AmortismanAzalanCarpan*$F19,1))^MAX(0,$H19-1)*MIN(2*AmortismanAzalanCarpan*$F19,1),MIN($D19*$F19,$D19)),0)) | L19: =IF($D19="",0,$G19-$J19) | M19: =IF($B19="","",CONCATENATE("Kıymet: ",$B19," | NDD: ",TEXT($J19,"#,##0")))
H20: =IF($D20="",0,MAX(0,ROUNDDOWN((AmortismanRaporTarihi-$C20)/365,0))) | I20: =IF($D20="",0,IFERROR(IF($E20="Azalan",MAX(0,$D20*(1-MIN(2*AmortismanAzalanCarpan*$F20,1)^$H20)),MIN($D20,$D20*$F20*$H20)),0)) | J20: =IF($D20="",0,MAX(0,$D20-$I20)) | K20: =IF($H20=0,0,IFERROR(IF($E20="Azalan",$D20*(1-MIN(2*AmortismanAzalanCarpan*$F20,1))^MAX(0,$H20-1)*MIN(2*AmortismanAzalanCarpan*$F20,1),MIN($D20*$F20,$D20)),0)) | L20: =IF($D20="",0,$G20-$J20) | M20: =IF($B20="","",CONCATENATE("Kıymet: ",$B20," | NDD: ",TEXT($J20,"#,##0")))
H21: =IF($D21="",0,MAX(0,ROUNDDOWN((AmortismanRaporTarihi-$C21)/365,0))) | I21: =IF($D21="",0,IFERROR(IF($E21="Azalan",MAX(0,$D21*(1-MIN(2*AmortismanAzalanCarpan*$F21,1)^$H21)),MIN($D21,$D21*$F21*$H21)),0)) | J21: =IF($D21="",0,MAX(0,$D21-$I21)) | K21: =IF($H21=0,0,IFERROR(IF($E21="Azalan",$D21*(1-MIN(2*AmortismanAzalanCarpan*$F21,1))^MAX(0,$H21-1)*MIN(2*AmortismanAzalanCarpan*$F21,1),MIN($D21*$F21,$D21)),0)) | L21: =IF($D21="",0,$G21-$J21) | M21: =IF($B21="","",CONCATENATE("Kıymet: ",$B21," | NDD: ",TEXT($J21,"#,##0")))
H22: =IF($D22="",0,MAX(0,ROUNDDOWN((AmortismanRaporTarihi-$C22)/365,0))) | I22: =IF($D22="",0,IFERROR(IF($E22="Azalan",MAX(0,$D22*(1-MIN(2*AmortismanAzalanCarpan*$F22,1)^$H22)),MIN($D22,$D22*$F22*$H22)),0)) | J22: =IF($D22="",0,MAX(0,$D22-$I22)) | K22: =IF($H22=0,0,IFERROR(IF($E22="Azalan",$D22*(1-MIN(2*AmortismanAzalanCarpan*$F22,1))^MAX(0,$H22-1)*MIN(2*AmortismanAzalanCarpan*$F22,1),MIN($D22*$F22,$D22)),0)) | L22: =IF($D22="",0,$G22-$J22) | M22: =IF($B22="","",CONCATENATE("Kıymet: ",$B22," | NDD: ",TEXT($J22,"#,##0")))
H23: =IF($D23="",0,MAX(0,ROUNDDOWN((AmortismanRaporTarihi-$C23)/365,0))) | I23: =IF($D23="",0,IFERROR(IF($E23="Azalan",MAX(0,$D23*(1-MIN(2*AmortismanAzalanCarpan*$F23,1)^$H23)),MIN($D23,$D23*$F23*$H23)),0)) | J23: =IF($D23="",0,MAX(0,$D23-$I23)) | K23: =IF($H23=0,0,IFERROR(IF($E23="Azalan",$D23*(1-MIN(2*AmortismanAzalanCarpan*$F23,1))^MAX(0,$H23-1)*MIN(2*AmortismanAzalanCarpan*$F23,1),MIN($D23*$F23,$D23)),0)) | L23: =IF($D23="",0,$G23-$J23) | M23: =IF($B23="","",CONCATENATE("Kıymet: ",$B23," | NDD: ",TEXT($J23,"#,##0")))
H24: =IF($D24="",0,MAX(0,ROUNDDOWN((AmortismanRaporTarihi-$C24)/365,0))) | I24: =IF($D24="",0,IFERROR(IF($E24="Azalan",MAX(0,$D24*(1-MIN(2*AmortismanAzalanCarpan*$F24,1)^$H24)),MIN($D24,$D24*$F24*$H24)),0)) | J24: =IF($D24="",0,MAX(0,$D24-$I24)) | K24: =IF($H24=0,0,IFERROR(IF($E24="Azalan",$D24*(1-MIN(2*AmortismanAzalanCarpan*$F24,1))^MAX(0,$H24-1)*MIN(2*AmortismanAzalanCarpan*$F24,1),MIN($D24*$F24,$D24)),0)) | L24: =IF($D24="",0,$G24-$J24) | M24: =IF($B24="","",CONCATENATE("Kıymet: ",$B24," | NDD: ",TEXT($J24,"#,##0")))
... H1004: =IF($D1004="",0,MAX(0,ROUNDDOWN((AmortismanRaporTarihi-$C1004)/365,0))) | I1004: =IF($D1004="",0,IFERROR(IF($E1004="Azalan",MAX(0,$D1004*(1-MIN(2*AmortismanAzalanCarpan*$F1004,1)^$H1004)),MIN($D1004,$D1004*$F1004*$H1004)),0)) | J1004: =IF($D1004="",0,MAX(0,$D1004-$I1004)) | K1004: =IF($H1004=0,0,IFERROR(IF($E1004="Azalan",$D1004*(1-MIN(2*AmortismanAzalanCarpan*$F1004,1))^MAX(0,$H1004-1)*MIN(2*AmortismanAzalanCarpan*$F1004,1),MIN($D1004*$F1004,$D1004)),0)) | L1004: =IF($D1004="",0,$G1004-$J1004) | M1004: =IF($B1004="","",CONCATENATE("Kıymet: ",$B1004," | NDD: ",TEXT($J1004,"#,##0")))
A1006: Sarı hücreler manuel giriştir; formül hücreleri kilitli ve korumalıdır.

Sheet HESAP
A1: HESAP — Amortisman & Sabit Kıymet Satış Zamanlama Stratejisti
A3: Kıymet Türü Bazlı Özet ve Satış Zamanlama Motoru
A4: Aşağıdaki özet kıymet listesinden otomatik beslenir; çeyrek satış senaryoları AYARLAR'daki oran ve kıst değerlerle canlı üretilir.
A5: Kıymet Türü | B5: Adet | C5: Edinim Bedeli (TL) | D5: Birikmiş Amortisman (TL) | E5: Net Defter Değeri (TL) | F5: Yıllık Amortisman (TL) | G5: Satış Bedeli (TL)
A6: Bina | B6: =IFERROR(COUNTIFS(tblKiyamet[Kıymet Türü],$A6,tblKiyamet[Edinim Bedeli (TL)],"<>0"),0) | C6: =SUMIFS(tblKiyamet[Edinim Bedeli (TL)],tblKiyamet[Kıymet Türü],$A6) | D6: =SUMIFS(tblKiyamet[Birikmiş Amortisman (TL)],tblKiyamet[Kıymet Türü],$A6) | E6: =SUMIFS(tblKiyamet[Net Defter Değeri (TL)],tblKiyamet[Kıymet Türü],$A6) | F6: =SUMIFS(tblKiyamet[Yıllık Amortisman (TL)],tblKiyamet[Kıymet Türü],$A6) | G6: =SUMIFS(tblKiyamet[Satış Bedeli (TL)],tblKiyamet[Kıymet Türü],$A6)
A7: Makine | B7: =IFERROR(COUNTIFS(tblKiyamet[Kıymet Türü],$A7,tblKiyamet[Edinim Bedeli (TL)],"<>0"),0) | C7: =SUMIFS(tblKiyamet[Edinim Bedeli (TL)],tblKiyamet[Kıymet Türü],$A7) | D7: =SUMIFS(tblKiyamet[Birikmiş Amortisman (TL)],tblKiyamet[Kıymet Türü],$A7) | E7: =SUMIFS(tblKiyamet[Net Defter Değeri (TL)],tblKiyamet[Kıymet Türü],$A7) | F7: =SUMIFS(tblKiyamet[Yıllık Amortisman (TL)],tblKiyamet[Kıymet Türü],$A7) | G7: =SUMIFS(tblKiyamet[Satış Bedeli (TL)],tblKiyamet[Kıymet Türü],$A7)
A8: Taşıt | B8: =IFERROR(COUNTIFS(tblKiyamet[Kıymet Türü],$A8,tblKiyamet[Edinim Bedeli (TL)],"<>0"),0) | C8: =SUMIFS(tblKiyamet[Edinim Bedeli (TL)],tblKiyamet[Kıymet Türü],$A8) | D8: =SUMIFS(tblKiyamet[Birikmiş Amortisman (TL)],tblKiyamet[Kıymet Türü],$A8) | E8: =SUMIFS(tblKiyamet[Net Defter Değeri (TL)],tblKiyamet[Kıymet Türü],$A8) | F8: =SUMIFS(tblKiyamet[Yıllık Amortisman (TL)],tblKiyamet[Kıymet Türü],$A8) | G8: =SUMIFS(tblKiyamet[Satış Bedeli (TL)],tblKiyamet[Kıymet Türü],$A8)
A9: Demirbaş | B9: =IFERROR(COUNTIFS(tblKiyamet[Kıymet Türü],$A9,tblKiyamet[Edinim Bedeli (TL)],"<>0"),0) | C9: =SUMIFS(tblKiyamet[Edinim Bedeli (TL)],tblKiyamet[Kıymet Türü],$A9) | D9: =SUMIFS(tblKiyamet[Birikmiş Amortisman (TL)],tblKiyamet[Kıymet Türü],$A9) | E9: =SUMIFS(tblKiyamet[Net Defter Değeri (TL)],tblKiyamet[Kıymet Türü],$A9) | F9: =SUMIFS(tblKiyamet[Yıllık Amortisman (TL)],tblKiyamet[Kıymet Türü],$A9) | G9: =SUMIFS(tblKiyamet[Satış Bedeli (TL)],tblKiyamet[Kıymet Türü],$A9)
A10: Yazılım | B10: =IFERROR(COUNTIFS(tblKiyamet[Kıymet Türü],$A10,tblKiyamet[Edinim Bedeli (TL)],"<>0"),0) | C10: =SUMIFS(tblKiyamet[Edinim Bedeli (TL)],tblKiyamet[Kıymet Türü],$A10) | D10: =SUMIFS(tblKiyamet[Birikmiş Amortisman (TL)],tblKiyamet[Kıymet Türü],$A10) | E10: =SUMIFS(tblKiyamet[Net Defter Değeri (TL)],tblKiyamet[Kıymet Türü],$A10) | F10: =SUMIFS(tblKiyamet[Yıllık Amortisman (TL)],tblKiyamet[Kıymet Türü],$A10) | G10: =SUMIFS(tblKiyamet[Satış Bedeli (TL)],tblKiyamet[Kıymet Türü],$A10)
A11: Diğer | B11: =IFERROR(COUNTIFS(tblKiyamet[Kıymet Türü],$A11,tblKiyamet[Edinim Bedeli (TL)],"<>0"),0) | C11: =SUMIFS(tblKiyamet[Edinim Bedeli (TL)],tblKiyamet[Kıymet Türü],$A11) | D11: =SUMIFS(tblKiyamet[Birikmiş Amortisman (TL)],tblKiyamet[Kıymet Türü],$A11) | E11: =SUMIFS(tblKiyamet[Net Defter Değeri (TL)],tblKiyamet[Kıymet Türü],$A11) | F11: =SUMIFS(tblKiyamet[Yıllık Amortisman (TL)],tblKiyamet[Kıymet Türü],$A11) | G11: =SUMIFS(tblKiyamet[Satış Bedeli (TL)],tblKiyamet[Kıymet Türü],$A11)
A13: TOPLAM BLOK
A14: Toplam Edinim Bedeli (TL) | B14: =SUM(C6:C11)
A15: Toplam Birikmiş Amortisman (TL) | B15: =SUM(D6:D11)
A16: TOPLAM NET DEFTER DEĞERİ (TL) | B16: =SUM(E6:E11)
A17: Toplam Yıllık Amortisman (TL) | B17: =SUM(F6:F11)
A18: Toplam Satış Bedeli (TL) | B18: =SUM(G6:G11)
A19: Kıymet Sayısı | B19: =COUNTA(tblKiyamet[Kıymet Kodu])
A20: Kıymet Türü Sayısı (farklı) | B20: =IFERROR(SUMPRODUCT((tblKiyamet[Kıymet Türü]<>"")/COUNTIF(tblKiyamet[Kıymet Türü],tblKiyamet[Kıymet Türü]&"")),0)
A22: 1. ÇEYREK SATIŞ SENARYOSU (mart sonu)
A23: Satış Yılı Kıst Amortismanı (TL) | B23: =B17*AYARLAR!$B$14
A24: Toplam Birikmiş Amortisman (TL) | B24: =B15+B23
A25: Net Defter Değeri (TL) | B25: =B14-B24
A26: Satış Kârı/Zararı (TL) | B26: =B18-B25
A27: Kurumlar Vergisi Etkisi (TL) | B27: =B26*AmortismanKurumlarVergiOran
A28: NET NAKİT ETKİ (TL) | B28: =B18-B27
A30: 2. ÇEYREK SATIŞ SENARYOSU (haziran sonu)
A31: Satış Yılı Kıst Amortismanı (TL) | B31: =B17*AYARLAR!$B$15
A32: Toplam Birikmiş Amortisman (TL) | B32: =B15+B31
A33: Net Defter Değeri (TL) | B33: =B14-B32
A34: Satış Kârı/Zararı (TL) | B34: =B18-B33
A35: Kurumlar Vergisi Etkisi (TL) | B35: =B34*AmortismanKurumlarVergiOran
A36: NET NAKİT ETKİ (TL) | B36: =B18-B35
A38: 3. ÇEYREK SATIŞ SENARYOSU (eylül sonu)
A39: Satış Yılı Kıst Amortismanı (TL) | B39: =B17*AYARLAR!$B$16
A40: Toplam Birikmiş Amortisman (TL) | B40: =B15+B39
A41: Net Defter Değeri (TL) | B41: =B14-B40
A42: Satış Kârı/Zararı (TL) | B42: =B18-B41
A43: Kurumlar Vergisi Etkisi (TL) | B43: =B42*AmortismanKurumlarVergiOran
A44: NET NAKİT ETKİ (TL) | B44: =B18-B43
A46: 4. ÇEYREK SATIŞ SENARYOSU (aralık sonu)
...

Sheet ANALITIK_MOTOR
A1: ANALITIK MOTOR — Amortisman & Sabit Kıymet Satış Zamanlama Stratejisti
A3: ANALİTİK MOTOR — DERİNLİK KATMANI
A5: Kod | B5: Gösterge | C5: Değer | D5: Makine Yorumu
A6: T1 | B6: Ortalama Amortisman Oranı | C6: =IFERROR(AVERAGE(tblKiyamet[Amortisman Oranı]),0) | D6: =_xlfn.TEXTJOIN("; ",TRUE(),"Ortalama amortisman oranı ",TEXT(C6,"0.0%")," — kıymet portföyünün ortalama amortisman hızını gösterir")
A7: T2 | B7: Ortalama Net Defter Değeri | C7: =IFERROR(AVERAGE(tblKiyamet[Net Defter Değeri (TL)]),0) | D7: =_xlfn.TEXTJOIN("; ",TRUE(),"Ortalama net defter değeri ",TEXT(C7,"₺ #,##0")," TL — portföyün ortalama kıymet büyüklüğünü gösterir")
A8: O1 | B8: NDD Sapması (MAD) | C8: =IFERROR(AVEDEV(tblKiyamet[Net Defter Değeri (TL)]),0) | D8: =_xlfn.TEXTJOIN("; ",TRUE(),"Net defter değeri ortalama mutlak sapması ",TEXT(C8,"₺ #,##0")," TL — sapma yüksekse kıymetler heterojendir")
A9: O2 | B9: En Yüksek Satış Kârı/Zararı | C9: =IFERROR(MAX(tblKiyamet[Satış Kârı/Zararı (TL)]),0) | D9: =_xlfn.TEXTJOIN("; ",TRUE(),"En yüksek satış kârı ",TEXT(C9,"₺ #,##0")," TL — bu kıymet satış zamanlamasında önceliklidir")
A10: O3 | B10: Senaryo Bant Genişliği | C10: =SENARYO_DUYARLILIK!C11 | D10: =_xlfn.TEXTJOIN("; ",TRUE(),"İyimser ile kritik senaryo net nakit farkı ",TEXT(C10,"₺ #,##0")," TL — satış bedeli belirsizliğinin etkisini gösterir")
A11: O6 | B11: Edinim Yoğunlaşması (HHI) | C11: =IFERROR(IF(SUM(HESAP!$C$6:$C$11)=0,0,SUMPRODUCT((HESAP!$C$6:$C$11/SUM(HESAP!$C$6:$C$11))^2)),0) | D11: =_xlfn.TEXTJOIN("; ",TRUE(),"Edinim yoğunlaşma endeksi ",TEXT(C11,"0.000")," — 1 e yaklaştıkça yatırım tek türde toplanır")
A12: O8 | B12: Veri Kalite Skoru | C12: =KONTROLLER!B19 | D12: =_xlfn.TEXTJOIN("; ",TRUE(),"Veri kalite skoru ",TEXT(C12,"0")," puan — ",IF(C12>=AmortismanKaliteIyi,"yüksek güven","veri girişi tamamlanmalı"))
A13: I1 | B13: Gelecek Dönem Amortisman Tahmini | C13: =PANO!B35 | D13: =_xlfn.TEXTJOIN("; ",TRUE(),"Gelecek dönem toplam amortisman tahmini ",TEXT(C13,"₺ #,##0")," TL — güven bandı için alt/üst sınır PANO sayfasındadır")
A14: I2 | B14: NDD Yüzdelik P90 | C14: =IFERROR(_xlfn.PERCENTILE.INC(tblKiyamet[Net Defter Değeri (TL)],AmortismanP90Oran),0) | D14: =_xlfn.TEXTJOIN("; ",TRUE(),"Kıymetlerin %90 ı ",TEXT(C14,"₺ #,##0")," TL altında net defter değerine sahiptir — üst sınır planlamada kullanılabilir")
A15: I3 | B15: NBD Farkı (1Ç − 4Ç) | C15: =HESAP!B68 | D15: =_xlfn.TEXTJOIN("; ",TRUE(),"NBD farkı ",TEXT(C15,"₺ #,##0")," TL — fark pozitifse erken satış bugünkü değerde avantajlıdır")

Sheet KONTROLLER
A1: KONTROLLER — Amortisman & Sabit Kıymet Satış Zamanlama Stratejisti
A3: Giriş Kalite Kontrolleri
A4: Aşağıdaki kontroller canlı formüllerle çalışır; sorun varsa uyarı üretir.
A6: Boş edinim bedeli satırı var mı? | B6: =IF(COUNTBLANK(tblKiyamet[Edinim Bedeli (TL)])=0,"TEMİZ","BOŞ VAR")
A7: Negatif edinim bedeli var mı? | B7: =IF(COUNTIF(tblKiyamet[Edinim Bedeli (TL)],"<0")=0,"TEMİZ","NEGATİF VAR")
A8: Negatif satış bedeli var mı? | B8: =IF(COUNTIF(tblKiyamet[Satış Bedeli (TL)],"<0")=0,"TEMİZ","NEGATİF VAR")
A9: Amortisman oranı 0,50 üzerinde mi? | B9: =IF(COUNTIF(tblKiyamet[Amortisman Oranı],">0.5")=0,"TEMİZ","ORAN >0,5 VAR")
A10: Edinimi 40 yıldan eski kıymet var mı? | B10: =IF(COUNTIF(tblKiyamet[Geçen Yıl],">40")=0,"TEMİZ","ESKİ VAR")
A11: NDD eşiği aşılıyor mu? | B11: =IF(HESAP!B16>AmortismanYuksekNddEsik,"AŞIYOR","NORMAL")
A12: En iyi çeyrek net nakit pozitif mi? | B12: =IF(HESAP!B60<=0,"AŞIYOR","NORMAL")
A13: NBD farkı hangi tarafı işaret ediyor? | B13: =IF(OR(HESAP!B66="1. ÇEYREK",HESAP!B66="2. ÇEYREK"),"ERKEN AVANTAJLI","GEÇ AVANTAJLI")
A15: Veri Kalitesi Skoru (0-100)
A16: Temel giriş kolonlarının dolu olma oranına göre üretilen kalite skoru.
A17: Toplam Giriş Hücresi | B17: =COUNTA(tblKiyamet[Kıymet Türü])*AmortismanTemelKolonSayisi
A18: Dolu Giriş Hücresi | B18: =COUNTA(tblKiyamet[Kıymet Türü])+COUNTA(tblKiyamet[Edinim Tarihi])+COUNTA(tblKiyamet[Edinim Bedeli (TL)])+COUNTA(tblKiyamet[Amortisman Yöntemi])+COUNTA(tblKiyamet[Amortisman Oranı])
A19: Kalite Skoru | B19: =ROUND(IF(AmortismanToplamGiris=0,0,AmortismanDoluGiris/AmortismanToplamGiris*100),0)
A20: Kalite Seviyesi | B20: =IF(B19>=AmortismanKaliteIyi,"YÜKSEK",IF(B19>=AmortismanKaliteOrta,"ORTA","DÜŞÜK"))
A22: Kontroller yalnızca giriş verisini denetler; değerleri değiştirmez.

Sheet KARAR
A1: KARAR — Amortisman & Sabit Kıymet Satış Zamanlama Stratejisti
A3: Karar Kapısı — Sat, Bekle mi?
A4: Net nakit, bugünkü değer zamanlaması ve kıymet verisi kalitesine göre üretilen satış zamanlama kararı.
A6: Toplam Net Defter Değeri (TL) | B6: =HESAP!B16
A7: En Yüksek Net Nakit (TL) | B7: =HESAP!B60
A8: En İyi NBD Çeyreği | B8: =HESAP!B66
A9: En İyi NBD Değeri (TL) | B9: =HESAP!B67
A11: KARAR | B11: =IF(COUNTA(tblKiyamet[Edinim Bedeli (TL)])=0,"VERİ YOK",IF(OR(COUNTIF(tblKiyamet[Edinim Bedeli (TL)],"<0")>0,COUNTIF(tblKiyamet[Satış Bedeli (TL)],"<0")>0),"DURDUR",IF(HESAP!B16<=0,"VERİ YOK",IF(HESAP!B60<=0,"BEKLE",IF(OR(HESAP!B66="1. ÇEYREK",HESAP!B66="2. ÇEYREK"),"SAT","BEKLE")))))
A12: Gerekçe | B12: =IF(COUNTIF(tblKiyamet[Edinim Bedeli (TL)],"<0")>0,"Negatif edinim bedeli girişi tespit edildi; veriler mutlaka düzeltilmeli.",IF(COUNTIF(tblKiyamet[Satış Bedeli (TL)],"<0")>0,"Negatif satış bedeli girişi tespit edildi; veriler mutlaka düzeltilmeli.",IF(HESAP!B16<=0,"Kıymet kaydı bulunmuyor; satış zamanlama kararı üretilemiyor.",IF(HESAP!B60<=0,"En iyi çeyrek net nakit pozitif değil; satışın nakit avantajı yok, satış bekletilmeli.",IF(OR(HESAP!B66="1. ÇEYREK",HESAP!B66="2. ÇEYREK"),"Erken çeyrek satışı bugünkü değerde en yüksek nakit akışını sağlıyor; satış yapılabilir.","Yıl sonu satışı bugünkü değerde en yüksek nakit akışını sağlıyor; satış için aralık sonu beklenmeli.")))))
A14: Önerilen Aksiyonlar
A15: Aksiyon 1 | B15: =AmortismanAksiyon1_ACIKLAMA
A16: Aksiyon 2 | B16: =AmortismanAksiyon2_ACIKLAMA
A17: Aksiyon 3 | B17: =AmortismanAksiyon3_ACIKLAMA
A19: Karar yalnızca giriş verisi ve AYARLAR'daki oran/eşiklerden türetilir; satış sonucu bağlayıcı değildir.

Sheet PANO
A1: PANO — Amortisman & Sabit Kıymet Satış Zamanlama Stratejisti
A3: Yönetim Paneli | B3: Toplam NDD (TL) | C3: En İyi Çeyrek Net Nakit (TL) | D3: En İyi NBD Çeyreği | E3: En İyi NBD (TL) | F3: Toplam Yıllık Amortisman (TL) | G3: Toplam Satış Bedeli (TL) | H3: Kıymet Sayısı
B4: =HESAP!B16 | C4: =HESAP!B60 | D4: =HESAP!B66 | E4: =HESAP!B67 | F4: =HESAP!B17 | G4: =HESAP!B18 | H4: =HESAP!B19
A6: Karar | B6: =KARAR!B11 | D6: Kalite Skoru | E6: =KONTROLLER!B19 | G6: En İyi NBD Çeyreği | H6: =HESAP!B66
A10: Kıymet Türü | B10: Edinim (TL) | C10: Birikmiş Amortisman (TL) | D10: NDD (TL) | E10: Yıllık Amortisman (TL)
A11: Bina | B11: =HESAP!C6 | C11: =HESAP!D6 | D11: =HESAP!E6 | E11: =HESAP!F6
A12: Makine | B12: =HESAP!C7 | C12: =HESAP!D7 | D12: =HESAP!E7 | E12: =HESAP!F7
A13: Taşıt | B13: =HESAP!C8 | C13: =HESAP!D8 | D13: =HESAP!E8 | E13: =HESAP!F8
A14: Demirbaş | B14: =HESAP!C9 | C14: =HESAP!D9 | D14: =HESAP!E9 | E14: =HESAP!F9
A15: Yazılım | B15: =HESAP!C10 | C15: =HESAP!D10 | D15: =HESAP!E10 | E15: =HESAP!F10
A16: Diğer | B16: =HESAP!C11 | C16: =HESAP!D11 | D16: =HESAP!E11 | E16: =HESAP!F11
G20: Kıymet Sırası | H20: NDD (TL)
G21: 1 | H21: =IFERROR(INDEX(tblKiyamet[Net Defter Değeri (TL)],AYARLAR!$B$34),0)
G22: 2 | H22: =IFERROR(INDEX(tblKiyamet[Net Defter Değeri (TL)],AYARLAR!$B$35),0)
G23: 3 | H23: =IFERROR(INDEX(tblKiyamet[Net Defter Değeri (TL)],AYARLAR!$B$36),0)
G24: 4 | H24: =IFERROR(INDEX(tblKiyamet[Net Defter Değeri (TL)],AYARLAR!$B$37),0)
G25: 5 | H25: =IFERROR(INDEX(tblKiyamet[Net Defter Değeri (TL)],AYARLAR!$B$38),0)
G26: 6 | H26: =IFERROR(INDEX(tblKiyamet[Net Defter Değeri (TL)],AYARLAR!$B$39),0)
G27: 7 | H27: =IFERROR(INDEX(tblKiyamet[Net Defter Değeri (TL)],AYARLAR!$B$40),0)
G28: 8 | H28: =IFERROR(INDEX(tblKiyamet[Net Defter Değeri (TL)],AYARLAR!$B$41),0)
G29: 9 | H29: =IFERROR(INDEX(tblKiyamet[Net Defter Değeri (TL)],AYARLAR!$B$42),0)
G30: 10 | H30: =IFERROR(INDEX(tblKiyamet[Net Defter Değeri (TL)],AYARLAR!$B$43),0)
G31: 11 | H31: =IFERROR(INDEX(tblKiyamet[Net Defter Değeri (TL)],AYARLAR!$B$44),0)
G32: 12 | H32: =IFERROR(INDEX(tblKiyamet[Net Defter Değeri (TL)],AYARLAR!$B$45),0)
A34: Ortalama Yıllık Amortisman | B34: =ROUND(IFERROR(AVERAGE(tblKiyamet[Yıllık Amortisman (TL)]),0),0)
A35: Gelecek Dönem Toplam Amortisman Tahmini | B35: =ROUND(IFERROR(forecast.lınear(AmortismanPanelSatir12,tblKiyamet[Yıllık Amortisman (TL)],ROW(tblKiyamet[Yıllık Amortisman (TL)])-ROW(tblKiyamet[[#Headers],[Yıllık Amortisman (TL)]])),0),0)
A36: Yıllık Amortisman Std Sapması | B36: =ROUND(IFERROR(stdev.p(INDEX(tblKiyamet[Yıllık Amortisman (TL)],AmortismanPanelSatir1):INDEX(tblKiyamet[Yıllık Amortisman (TL)],AmortismanPanelSatir12)),0),0)
A37: Alt Tahmin Sınırı | B37: =B34-B36*AmortismanTahminCarpan
A38: Üst Tahmin Sınırı | B38: =B34+B36*AmortismanTahminCarpan
A40: Çeyrek | B40: Net Nakit (TL) | C40: NBD (TL)
A41: 1. ÇEYREK | B41: =HESAP!B56 | C41: =HESAP!B62
A42: 2. ÇEYREK | B42: =HESAP!B57 | C42: =HESAP!B63
A43: 3. ÇEYREK | B43: =HESAP!B58 | C43: =HESAP!B64
A44: 4. ÇEYREK | B44: =HESAP!B59 | C44: =HESAP!B65
E45: Senaryo | F45: Net Nakit (TL)
E46: İyimser | F46: =SENARYO_DUYARLILIK!C7
E47: Baz | F47: =SENARYO_DUYARLILIK!C8
E48: Kötümser | F48: =SENARYO_DUYARLILIK!C9
E49: Kritik | F49: =SENARYO_DUYARLILIK!C10
A50: Paneldeki tüm göstergeler canlı formüllerden beslenir.

Sheet SENARYO_DUYARLILIK
A1: SENARYO DUYARLILIK — Amortisman & Sabit Kıymet Satış Zamanlama Stratejisti
A3: Senaryo ve Duyarlılık Analizi
A4: Farklı satış bedeli çarpanı senaryolarında en iyi çeyrek net nakit bant aralığı; ardından hangi değişkenin net nakiti en çok etkilediğini gösteren tornado analizi.
A6: Senaryo | B6: Satış Bedeli Çarpanı | C6: En İyi Çeyrek Net Nakit (TL) | D6: Durum
A7: İYİMSER | B7: =AYARLAR!$B$18 | C7: =IFERROR(AmortismanNetNakitEnIyi+AmortismanToplamSatis*B7*(1-AmortismanKurumlarVergiOran),0) | D7: =IF(C7>=AmortismanNetNakitEnIyi,"AVANTAJLI","DEĞERLENDİR")
A8: BAZ | B8: =AYARLAR!$B$19 | C8: =IFERROR(AmortismanNetNakitEnIyi+AmortismanToplamSatis*B8*(1-AmortismanKurumlarVergiOran),0) | D8: =IF(C8>=AmortismanNetNakitEnIyi,"AVANTAJLI","DEĞERLENDİR")
A9: KÖTÜMSER | B9: =AYARLAR!$B$20 | C9: =IFERROR(AmortismanNetNakitEnIyi+AmortismanToplamSatis*B9*(1-AmortismanKurumlarVergiOran),0) | D9: =IF(C9>=AmortismanNetNakitEnIyi,"AVANTAJLI","DEĞERLENDİR")
A10: KRİTİK | B10: =AYARLAR!$B$21 | C10: =IFERROR(AmortismanNetNakitEnIyi+AmortismanToplamSatis*B10*(1-AmortismanKurumlarVergiOran),0) | D10: =IF(C10>=AmortismanNetNakitEnIyi,"AVANTAJLI","DEĞERLENDİR")
A11: Senaryo Bant Genişliği (İyi − Kritik) | C11: =C7-C10
A13: Tornado: Net Nakite Etki
A14: Satış Bedeli Düşüşü Etkisi | B14: =IFERROR(ABS(AmortismanToplamSatis*AYARLAR!$B$20*(1-AmortismanKurumlarVergiOran)),0)
A15: Amortisman Oranı Artışı Etkisi | B15: =IFERROR(ABS(HESAP!B17*AYARLAR!$B$28/IF(AVERAGE(tblKiyamet[Amortisman Oranı])<>0,AVERAGE(tblKiyamet[Amortisman Oranı]),1)),0)
A17: En Etkili Değişken | B17: =IF(B14>=B15,"Satış Bedeli","Amortisman Oranı")
A19: Senaryo çarpanları ve tornado adımları AYARLAR'dan türetilir.

Sheet RAPOR
A1: SABİT KIYMET SATIŞ ZAMANLAMA — YÖNETİCİ ÖZETİ
A2: =_xlfn.CONCAT("Rapor Tarihi: ",TEXT(AmortismanRaporTarihi,"dd.mm.yyyy")," | Hazırlayan: ",AmortismanRaporHazirlayan," | Sürüm: ",AmortismanDosyaSurumu)
A4: Karar | B4: =KARAR!B11
A6: Toplam Net Defter Değeri (TL) | B6: =HESAP!B16
A7: Toplam Yıllık Amortisman (TL) | B7: =HESAP!B17
A8: Toplam Satış Bedeli (TL) | B8: =HESAP!B18
A9: En Yüksek Net Nakit (TL) | B9: =HESAP!B60
A10: En İyi NBD Çeyreği | B10: =HESAP!B66
A11: En İyi NBD Değeri (TL) | B11: =HESAP!B67
A12: NBD Farkı (1Ç − 4Ç) (TL) | B12: =HESAP!B68
A13: Kıymet Sayısı | B13: =HESAP!B19
A14: Kalite Skoru | B14: =KONTROLLER!B19
A16: Varsayımlar ve Önemli Notlar
A17: • Normal yöntemde amortisman edinim bedelinin oranla çarpımıyla; azalan bakiyede VUK Md. 315 çerçevesinde normal oranın 2 katına kadar çarpanla hesaplanır.
A18: • Yıl içi satış senaryolarında satış yılına isabet eden kıst amortisman AYARLAR'daki kıst oranlarıyla ayrılır (3/12, 6/12, 9/12, 12/12).
A19: • Satış kârı/zararı satış bedeli ile satış anındaki net defter değeri arasındaki farktır; vergi etkisi kurumlar vergisi oranıyla hesaplanır.
A20: • NBD karşılaştırması çeyrek nakit akışlarını iskonto oranıyla bugünkü değere indirger; iskonto oranı AYARLAR'dadır.
A21: • Bu dosya karar destek aracıdır; amortisman ve vergi hesabı mali müşavir görüşü yerine geçmez.
A22: • Demo veriler gerçek müşteri verisi değildir; kullanımdan önce temizlenmelidir.
A24: Önerilen Aksiyonlar
A25: =AmortismanAksiyon1_ACIKLAMA
A26: =AmortismanAksiyon2_ACIKLAMA
A27: =AmortismanAksiyon3_ACIKLAMA
A29: Bu rapor karar destek amaçlıdır; mali tavsiye niteliği taşımaz.

Sheet ORNEK_VERI
A1: ORNEK VERI — Amortisman & Sabit Kıymet Satış Zamanlama Stratejisti
A3: Örnek Veri (Demo)
A4: Gerçek girişlere başlamadan önce demo veri ile ürünü deneyin. Bu satırlar örnektir; gerçek verilerle değiştirin.
A5: Kıymet Kodu | B5: Kıymet Türü | C5: Edinim Tarihi | D5: Edinim Bedeli (TL) | E5: Amortisman Yöntemi | F5: Amortisman Oranı | G5: Birikmiş Amortisman (TL) | H5: NDD (TL) | I5: Açıklama
A6: K-1001 | B6: Bina | C6: 43600 | D6: 1500000 | E6: Normal | F6: 0.02 | G6: =IF($D6="",0,MIN($D6,$D6*$F6*MAX(0,ROUNDDOWN((AmortismanRaporTarihi-$C6)/365,0)))) | H6: =IF($D6="",0,MAX(0,$D6-$G6)) | I6: =IF($B6="","",CONCATENATE("Örnek kıymet: ",$B6))
A7: K-1002 | B7: Makine | C7: 44265 | D7: 600000 | E7: Azalan | F7: 0.2 | G7: =IF($D7="",0,MIN($D7,$D7*$F7*MAX(0,ROUNDDOWN((AmortismanRaporTarihi-$C7)/365,0)))) | H7: =IF($D7="",0,MAX(0,$D7-$G7)) | I7: =IF($B7="","",CONCATENATE("Örnek kıymet: ",$B7))
A8: K-1003 | B8: Makine | C8: 44075 | D8: 400000 | E8: Normal | F8: 0.2 | G8: =IF($D8="",0,MIN($D8,$D8*$F8*MAX(0,ROUNDDOWN((AmortismanRaporTarihi-$C8)/365,0)))) | H8: =IF($D8="",0,MAX(0,$D8-$G8)) | I8: =IF($B8="","",CONCATENATE("Örnek kıymet: ",$B8))
A9: K-1004 | B9: Taşıt | C9: 44581 | D9: 350000 | E9: Normal | F9: 0.2 | G9: =IF($D9="",0,MIN($D9,$D9*$F9*MAX(0,ROUNDDOWN((AmortismanRaporTarihi-$C9)/365,0)))) | H9: =IF($D9="",0,MAX(0,$D9-$G9)) | I9: =IF($B9="","",CONCATENATE("Örnek kıymet: ",$B9))
A10: K-1005 | B10: Demirbaş | C10: 45021 | D10: 180000 | E10: Normal | F10: 0.2 | G10: =IF($D10="",0,MIN($D10,$D10*$F10*MAX(0,ROUNDDOWN((AmortismanRaporTarihi-$C10)/365,0)))) | H10: =IF($D10="",0,MAX(0,$D10-$G10)) | I10: =IF($B10="","",CONCATENATE("Örnek kıymet: ",$B10))
A11: K-1006 | B11: Yazılım | C11: 45458 | D11: 120000 | E11: Azalan | F11: 0.33 | G11: =IF($D11="",0,MIN($D11,$D11*$F11*MAX(0,ROUNDDOWN((AmortismanRaporTarihi-$C11)/365,0)))) | H11: =IF($D11="",0,MAX(0,$D11-$G11)) | I11: =IF($B11="","",CONCATENATE("Örnek kıymet: ",$B11))
G12: =IF($D12="",0,MIN($D12,$D12*$F12*MAX(0,ROUNDDOWN((AmortismanRaporTarihi-$C12)/365,0)))) | H12: =IF($D12="",0,MAX(0,$D12-$G12)) | I12: =IF($B12="","",CONCATENATE("Örnek kıymet: ",$B12))
G13: =IF($D13="",0,MIN($D13,$D13*$F13*MAX(0,ROUNDDOWN((AmortismanRaporTarihi-$C13)/365,0)))) | H13: =IF($D13="",0,MAX(0,$D13-$G13)) | I13: =IF($B13="","",CONCATENATE("Örnek kıymet: ",$B13))
G14: =IF($D14="",0,MIN($D14,$D14*$F14*MAX(0,ROUNDDOWN((AmortismanRaporTarihi-$C14)/365,0)))) | H14: =IF($D14="",0,MAX(0,$D14-$G14)) | I14: =IF($B14="","",CONCATENATE("Örnek kıymet: ",$B14))
G15: =IF($D15="",0,MIN($D15,$D15*$F15*MAX(0,ROUNDDOWN((AmortismanRaporTarihi-$C15)/365,0)))) | H15: =IF($D15="",0,MAX(0,$D15-$G15)) | I15: =IF($B15="","",CONCATENATE("Örnek kıymet: ",$B15))
G16: =IF($D16="",0,MIN($D16,$D16*$F16*MAX(0,ROUNDDOWN((AmortismanRaporTarihi-$C16)/365,0)))) | H16: =IF($D16="",0,MAX(0,$D16-$G16)) | I16: =IF($B16="","",CONCATENATE("Örnek kıymet: ",$B16))
G17: =IF($D17="",0,MIN($D17,$D17*$F17*MAX(0,ROUNDDOWN((AmortismanRaporTarihi-$C17)/365,0)))) | H17: =IF($D17="",0,MAX(0,$D17-$G17)) | I17: =IF($B17="","",CONCATENATE("Örnek kıymet: ",$B17))
G18: =IF($D18="",0,MIN($D18,$D18*$F18*MAX(0,ROUNDDOWN((AmortismanRaporTarihi-$C18)/365,0)))) | H18: =IF($D18="",0,MAX(0,$D18-$G18)) | I18: =IF($B18="","",CONCATENATE("Örnek kıymet: ",$B18))
G19: =IF($D19="",0,MIN($D19,$D19*$F19*MAX(0,ROUNDDOWN((AmortismanRaporTarihi-$C19)/365,0)))) | H19: =IF($D19="",0,MAX(0,$D19-$G19)) | I19: =IF($B19="","",CONCATENATE("Örnek kıymet: ",$B19))
G20: =IF($D20="",0,MIN($D20,$D20*$F20*MAX(0,ROUNDDOWN((AmortismanRaporTarihi-$C20)/365,0)))) | H20: =IF($D20="",0,MAX(0,$D20-$G20)) | I20: =IF($B20="","",CONCATENATE("Örnek kıymet: ",$B20))
G21: =IF($D21="",0,MIN($D21,$D21*$F21*MAX(0,ROUNDDOWN((AmortismanRaporTarihi-$C21)/365,0)))) | H21: =IF($D21="",0,MAX(0,$D21-$G21)) | I21: =IF($B21="","",CONCATENATE("Örnek kıymet: ",$B21))
G22: =IF($D22="",0,MIN($D22,$D22*$F22*MAX(0,ROUNDDOWN((AmortismanRaporTarihi-$C22)/365,0)))) | H22: =IF($D22="",0,MAX(0,$D22-$G22)) | I22: =IF($B22="","",CONCATENATE("Örnek kıymet: ",$B22))
G23: =IF($D23="",0,MIN($D23,$D23*$F23*MAX(0,ROUNDDOWN((AmortismanRaporTarihi-$C23)/365,0)))) | H23: =IF($D23="",0,MAX(0,$D23-$G23)) | I23: =IF($B23="","",CONCATENATE("Örnek kıymet: ",$B23))
... G1004: =IF($D1004="",0,MIN($D1004,$D1004*$F1004*MAX(0,ROUNDDOWN((AmortismanRaporTarihi-$C1004)/365,0)))) | H1004: =IF($D1004="",0,MAX(0,$D1004-$G1004)) | I1004: =IF($B1004="","",CONCATENATE("Örnek kıymet: ",$B1004))
A1006: Demo veriler rapor sonuçlarını örnekler; satın alma sonrası silinerek gerçek veriler girilir.

Sheet KURALLAR
A1: KURALLAR — amort_uretildi
A3: kural_id | B3: aciklama | C3: deger_2025 | D3: deger_2026 | E3: deger_2027 | F3: kaynak
A4: K1 | B4: Kurumlar vergisi oranı | C4: 0.25 | D4: 0.25 | E4: 0.25 | F4: KV
A5: K2 | B5: İskonto / referans oran | C5: 0.2 | D5: 0.2 | E5: 0.2 | F5: AYARLAR

Sheet VAKALAR
A1: VAKALAR — amort_uretildi
A3: Tebliğ tarzı altın vakalar
A5: vaka_id | B5: aciklama | C5: girdi_ozeti | D5: beklenen_sonuc | E5: hesaplanan | F5: fark | G5: durum | H5: kaynak
A6: V1 | B6: Baz senaryo tutarlılık | C6: örnek girdi | D6: 0 | E6: 0 | F6: 0 | G6: TUTARLI | H6: iç test

Sheet DEGISIKLIK_KAYDI
A1: DEGISIKLIK KAYDI — Amortisman & Sabit Kıymet Satış Zamanlama Stratejisti
A3: Değişiklik Kaydı
A4: Tarih | B4: Sürüm | C4: Değişiklik | D4: Neden | E4: Yapan
A5: 10.08.2026 | B5: 1.0.0 | C5: İlk üretim | D5: Ürünün yayına hazırlanması | E5: ExcelArşiv

Sheet LISTELER
A1: LISTELER — Amortisman & Sabit Kıymet Satış Zamanlama Stratejisti
A3: Bağlı Listeler
A4: Bu sayfadaki listeler açılır menüleri besler; yeni seçenek eklemek için sarı hücrelere yazın.
A6: Kıymet Türü | C6: Amortisman Yöntemi | E6: Çeyrekler
A7: Bina | C7: Normal | E7: 1. ÇEYREK
A8: Makine | C8: Azalan | E8: 2. ÇEYREK
A9: Taşıt | E9: 3. ÇEYREK
A10: Demirbaş | E10: 4. ÇEYREK
A11: Yazılım
A12: Diğer

Sheet AYARLAR
A1: AYARLAR — Amortisman & Sabit Kıymet Satış Zamanlama Stratejisti
A3: Sistem Ayarları ve Oranlar
A4: Tüm sabitler bu sayfadadır. Kurumlar vergisi oranı, iskonto oranı, azalan bakiye çarpanı ve kıst oranlarını güncelleyin; değişen her değer tüm hesaplamalara anında yansır.
A6: anahtar | B6: deger | C6: birim | D6: alt | E6: ust | F6: aciklama | G6: kaynak | H6: yururluk_tarihi | I6: dogrulama_tarihi
A7: FirmaUnvan | B7: Örnek Firma A.Ş. | C7: Metin | F7: Firma unvanı rapor başlığında görünür. | G7: Kullanıcı | H7: 45658 | I7: 46244
A8: RaporTarihi | B8: 46244 | C8: Tarih | F8: Amortisman ve satış hesabının dayanak tarihi. | G8: Kullanıcı | H8: 45658 | I8: 46244
A9: RaporHazirlayan | B9: Mali İşler Direktörü | C9: Metin | F9: Raporu hazırlayan kişi. | G9: Kullanıcı | H9: 45658 | I9: 46244
A10: DosyaSurumu | B10: 1.0.0 | C10: Metin | F10: Dosya sürümü. | G10: Kullanıcı | H10: 45658 | I10: 46244
A11: KurumlarVergiOran | B11: 0.25 | C11: Oran | D11: 0 | E11: 1 | F11: Kurumlar vergisi oranı; satış kârının vergi etkisinde kullanılır. | G11: Mevzuat (KVK Md. 32) | H11: 45658 | I11: 46244
A12: IskontoOrani | B12: 0.2 | C12: Oran | D12: 0 | E12: 1 | F12: Çeyrek nakit akışlarını bugünkü değere indirgemedeki iskonto oranı. | G12: Varsayım | H12: 45658 | I12: 46244
A13: AmortismanAzalanCarpan | B13: 2 | C13: Oran | D13: 1 | E13: 2 | F13: Azalan bakiyede normal oranın çarpım çarpanı (VUK en çok 2 kat). | G13: Mevzuat (VUK Md. 315) | H13: 45658 | I13: 46244
A14: KistCeyrek1 | B14: 0.25 | C14: Oran | D14: 0 | E14: 1 | F14: 1. çeyrek satışında ayrılan yıllık amortisman oranı (3/12). | G14: Varsayım | H14: 45658 | I14: 46244
A15: KistCeyrek2 | B15: 0.5 | C15: Oran | D15: 0 | E15: 1 | F15: 2. çeyrek satışında ayrılan yıllık amortisman oranı (6/12). | G15: Varsayım | H15: 45658 | I15: 46244
A16: KistCeyrek3 | B16: 0.75 | C16: Oran | D16: 0 | E16: 1 | F16: 3. çeyrek satışında ayrılan yıllık amortisman oranı (9/12). | G16: Varsayım | H16: 45658 | I16: 46244
A17: KistCeyrek4 | B17: 1 | C17: Oran | D17: 0 | E17: 1 | F17: 4. çeyrek satışında ayrılan yıllık amortisman oranı (12/12). | G17: Varsayım | H17: 45658 | I17: 46244
A18: SenIyiSatis | B18: 0.1 | C18: Oran | D18: -0.5 | E18: 0.5 | F18: İyimser senaryo satış bedeli çarpanı. | G18: Varsayım | H18: 45658 | I18: 46244
A19: SenBazSatis | B19: 0 | C19: Oran | D19: -0.5 | E19: 0.5 | F19: Baz senaryo satış bedeli çarpanı. | G19: Varsayım | H19: 45658 | I19: 46244
A20: SenKotuSatis | B20: -0.15 | C20: Oran | D20: -0.5 | E20: 0.5 | F20: Kötümser senaryo satış bedeli çarpanı. | G20: Varsayım | H20: 45658 | I20: 46244
A21: SenKritikSatis | B21: -0.3 | C21: Oran | D21: -0.5 | E21: 0.5 | F21: Kritik senaryo satış bedeli çarpanı. | G21: Varsayım | H21: 45658 | I21: 46244
A22: AmortismanTahminCarpan | B22: 1.645 | C22: Çarpan | D22: 0 | E22: 10 | F22: Tahmin güven bandı çarpanı (%90 normal dağılım). | G22: Varsayım | H22: 45658 | I22: 46244
... A30: AmortismanYuksekNddEsik | B30: 2000000 | C30: TL | D30: 0 | E30: 100000000000 | F30: Yüksek net defter değeri eşiği. | G30: Varsayım | H30: 45658 | I30: 46244
A31: AmortismanAksiyon1_ACIKLAMA | B31: Erken çeyrek satışı bugünkü değerde avantajlı; satışı planlayın, kıst amortismanı kapatarak satış işlemini gerçekleştirin. | C31: Metin | F31: SAT kararında gösterilen ilk öneri. | G31: Varsayım | H31: 45658 | I31: 46244
A32: AmortismanAksiyon2_ACIKLAMA | B32: Yıl sonu satışı bugünkü değerde avantajlı; satışı aralık sonuna erteleyin ve aradaki amortismanı kıst esasına göre ayırın. | C32: Metin | F32: BEKLE kararında gösterilen ikinci öneri. | G32: Varsayım | H32: 45658 | I32: 46244
A33: AmortismanAksiyon3_ACIKLAMA | B33: Satışın nakit avantajı görünmüyor; satış bedeli tahminlerini ve kıymet portföyünü gözden geçirin, gerekirse kıymet bazlı seçim yapın. | C33: Metin | F33: BEKLE/DURDUR kararında gösterilen üçüncü öneri. | G33: Varsayım | H33: 45658 | I33: 46244
A35: AmortismanPanelSatir1 | B35: 1 | C35: Satır | F35: PANO'daki kıymet kalemi bazlı NDD grafiğinin tablodaki veri satırı (1. veri). | G35: Kullanıcı | H35: 45658 | I35: 46244
A36: AmortismanPanelSatir2 | B36: 2 | C36: Satır | F36: PANO'daki kıymet kalemi bazlı NDD grafiğinin tablodaki veri satırı (2. veri). | G36: Kullanıcı | H36: 45658 | I36: 46244
A37: AmortismanPanelSatir3 | B37: 3 | C37: Satır | F37: PANO'daki kıymet kalemi bazlı NDD grafiğinin tablodaki veri satırı (3. veri). | G37: Kullanıcı | H37: 45658 | I37: 46244
A38: AmortismanPanelSatir4 | B38: 4 | C38: Satır | F38: PANO'daki kıymet kalemi bazlı NDD grafiğinin tablodaki veri satırı (4. veri). | G38: Kullanıcı | H38: 45658 | I38: 46244
A39: AmortismanPanelSatir5 | B39: 5 | C39: Satır | F39: PANO'daki kıymet kalemi bazlı NDD grafiğinin tablodaki veri satırı (5. veri). | G39: Kullanıcı | H39: 45658 | I39: 46244
A40: AmortismanPanelSatir6 | B40: 6 | C40: Satır | F40: PANO'daki kıymet kalemi bazlı NDD grafiğinin tablodaki veri satırı (6. veri). | G40: Kullanıcı | H40: 45658 | I40: 46244
A41: AmortismanPanelSatir7 | B41: 7 | C41: Satır | F41: PANO'daki kıymet kalemi bazlı NDD grafiğinin tablodaki veri satırı (7. veri). | G41: Kullanıcı | H41: 45658 | I41: 46244
A42: AmortismanPanelSatir8 | B42: 8 | C42: Satır | F42: PANO'daki kıymet kalemi bazlı NDD grafiğinin tablodaki veri satırı (8. veri). | G42: Kullanıcı | H42: 45658 | I42: 46244
A43: AmortismanPanelSatir9 | B43: 9 | C43: Satır | F43: PANO'daki kıymet kalemi bazlı NDD grafiğinin tablodaki veri satırı (9. veri). | G43: Kullanıcı | H43: 45658 | I43: 46244
A44: AmortismanPanelSatir10 | B44: 10 | C44: Satır | F44: PANO'daki kıymet kalemi bazlı NDD grafiğinin tablodaki veri satırı (10. veri). | G44: Kullanıcı | H44: 45658 | I44: 46244
A45: AmortismanPanelSatir11 | B45: 11 | C45: Satır | F45: PANO'daki kıymet kalemi bazlı NDD grafiğinin tablodaki veri satırı (11. veri). | G45: Kullanıcı | H45: 45658 | I45: 46244
A46: AmortismanPanelSatir12 | B46: 12 | C46: Satır | F46: PANO'daki kıymet kalemi bazlı NDD grafiğinin tablodaki veri satırı (12. veri). | G46: Kullanıcı | H46: 45658 | I46: 46244

Sheet KILAVUZ
A1: KILAVUZ — Amortisman & Sabit Kıymet Satış Zamanlama Stratejisti
A3: Kullanım Kılavuzu
A5: Veri girişi | B5: KIYMET_LISTESI sayfasında sarı hücrelere kıymetlerinizi girin. Kıymet türünü ve amortisman yöntemini listeden seçin; edinim tarihi, edinim bedeli, amortisman oranı ve satış bedeli tahminini girin. Geçen yıl, birikmiş amortisman, net defter değeri ve satış kârı/zararı otomatik hesaplanır.
A6: Çeyrek senaryoları | B6: HESAP sayfası yıl içinde dört çeyreğe göre kıst amortisman, satış kârı/zararı, kurumlar vergisi etkisi ve net nakit üretir; NBD ile bugünkü değere indirger.
A7: Karar ve aksiyon | B7: KARAR sayfası net nakit ve NBD zamanlamasına göre SAT/BEKLE kararını gerekçesiyle üretir ve önerilen aksiyonları gösterir.
A8: Oranlar ve senaryolar | B8: AYARLAR sayfasından kurumlar vergisi oranı, iskonto oranı, azalan bakiye çarpanı, kıst oranlar ve senaryo çarpanlarını güncelleyin; PANO ve SENARYO_DUYARLILIK anında güncellenir.
A9: Güven ve karar kalitesi | B9: Veri kalite skoru girişlerin tamlığını ölçer. Kıymet girişi yokken karar VERİ YOK; negatif girişte DURDUR üretir. Verileriniz cihazınızdan çıkmaz; dosya tamamen çevrimdışıdır.
A10: Uyumluluk | B10: Excel 2016-365 (Windows ve Mac), LibreOffice ve Google Sheets ile uyumludur. Makro içermez; formüller ayrıştırıcı ile denetlenmiştir.
