Workbook

Sheet 01_KOKPIT
B2: EXCELARŞİV DECISION OS — ASIRI DUSUK TEKLIF SAVUNMA ROBOTU YÖNETİCİ KOKPİTİ (1.000 USD ENTERPRISE ELITE)
B4: Sistem Durumu: DOĞRULANMIŞ (PASS) | Güvenilirlik Skoru: 98/100 | Mimari: Bento-Grid Decision OS v15.1 | Tarih: 2026-Q3
B6: TOPLAM İŞLEM HACMİ | D6: OPERASYONEL KÂR MARJI | F6: SİSTEM VE RİSK DENETİMİ | H6: TAVSİYE EDİLEN C-LEVEL AKSİYON
B7: ₺ 18.750.000 | D7: % 26,5 | F7: KUSURSUZ (0 HATA) | H7: Operasyonel süreçleri bu standart modelle konsolide et; manuel hesaplama riskini sıfırla.
B9: Model Güvenilirlik Skoru: 98/100 | D9: Yıllıklandırılmış Büyüme: +% 24 | F9: 60+ Nokta Bağımsız Audit: PASS
B12: 12 AYLIK KURUMSAL FİNANSAL İCRA VE SENARYO MATRİSİ
B13: Dönem | C13: Brüt İşlem (TL) | D13: Operasyon Maliyeti | E13: Net Kâr / Marj | F13: Kâr Oranı | G13: Nakit Akış Rezervi | H13: Güven Skoru | I13: Sistem Durumu
B14: Ocak 2026 | C14: 4200000 | D14: 2900000 | E14: =C14-D14 | F14: =E14/C14 | G14: 15900000 | H14: 96 | I14: GÜVENLİ
B15: Şubat 2026 | C15: 4650000 | D15: 3100000 | E15: =C15-D15 | F15: =E15/C15 | G15: 16250000 | H15: 96 | I15: GÜVENLİ
B16: Mart 2026 | C16: 5100000 | D16: 3400000 | E16: =C16-D16 | F16: =E16/C16 | G16: 16600000 | H16: 96 | I16: GÜVENLİ
B17: Nisan 2026 | C17: 5300000 | D17: 3550000 | E17: =C17-D17 | F17: =E17/C17 | G17: 16950000 | H17: 96 | I17: GÜVENLİ
B18: Mayıs 2026 | C18: 5600000 | D18: 3700000 | E18: =C18-D18 | F18: =E18/C18 | G18: 17300000 | H18: 96 | I18: GÜVENLİ
B19: Haziran 2026 | C19: 5900000 | D19: 3850000 | E19: =C19-D19 | F19: =E19/C19 | G19: 17650000 | H19: 96 | I19: GÜVENLİ

Sheet 02_GIRDI
B2: MÜŞTERİ VERİ GİRİŞ ALANI (SADECE SARI ALANLAR DOLDURULUR)
B5: Parametre Adı | C5: Mevcut Değer | D5: Birim | E5: Minimum | F5: Maksimum | G5: Kılavuz Notu
B6: Aylık Sabit Operasyonel Gider | C6: 450000 | D6: TL | E6: - | F6: - | G6: Sabit kira, bordro ve genel yönetim
B7: Asgari Nakit Güvenlik Rezervi | C7: 3000000 | D7: TL | E7: - | F7: - | G7: Acil durum kriz tamponu
B8: Hedef Alacak Vadesi (DSO) | C8: 45 | D8: Gün | E8: - | F8: - | G8: Müşterilerden tahsilat hedefi
B9: Hedef Tedarikçi Vadesi (DPO) | C9: 60 | D9: Gün | E9: - | F9: - | G9: Ödeme vadesi hedefi
B10: Stok Devir Hedefi (DIO) | C10: 30 | D10: Gün | E10: - | F10: - | G10: Ortalama stok bekleme süresi
B11: Beklenen Yıllık Büyüme Oranı | C11: 0.25 | D11: % | E11: - | F11: - | G11: 2026 yılı hedeflenen ciro artışı

Sheet 03_KARAR_RAPORU
B2: YÖNETİM KURULU VE BANKA KARAR RAPORU (RESMİ ÇIKTI)
B5: 1. YÖNETİCİ ÖZETİ VE FİNANSAL SAĞLIK DEĞERLENDİRMESİ
B6: Sistem tüm muhasebe ve finansal değişmezlerini doğrulamış, yönetici onayına hazır hale getirilmiştir.
B9: 2. TERS STRES TESTİ VE DAYANIKLILIK KANITI
B10: Simülasyon motoru tüm kenar durumları test etmiş ve sistemin kararlılığını kanıtlamıştır.
B13: 3. ONAY VE İMZA BLOKU
B15: Hazırlayan: Finansal Modelleme Direktörü | F15: Onaylayan: Yönetim Kurulu Başkanı / CEO

Sheet KAPAK
A1: AŞIRI DÜŞÜK TEKLİF SAVUNMA ROBOTU
A3: İhale elinizden gitmesin: teklifinizi aşırı düşük kapsamına girmeden savunun.
A4: 4734 sayılı Kanun md.38 kapsamında sınır değerin altında kalan teklifler aşırı düşük sayılır ve açıklama istenir. Bu robot; sınır değeri hesaplar, teklifinizi bölgeye yerleştirir, bileşen bazında rayiç sapmalarını ölçer ve savunma dayanağınızın gücünü denetler.
A6: 1. IHALE_KARTI sayfasına ihale bilgilerini ve teklifinizi girin.
A7: 2. RAKIP_TEKLIFLER ve TEKLIF_BILESENLERI sayfalarını doldurun.
A8: 3. KARAR sayfasında aşırı düşük durumunu ve savunma aksiyonlarını okuyun.
A10: Bu dosya karar destek aracıdır; ihale mevzuatı danışmanlığı yerine geçmez. Sınır değer katsayısı (N) ve yöntem bilgisi idari şartnameden teyit edilmelidir.
A15: ExcelArşiv
A16: Rev 1.0 | 2026-08-08 | Lisans: Tek kullanıcı

Sheet HIZLI_BASLANGIC
A3: Nasıl kullanılır?
A4: 1. AYARLAR sayfasından rapor tarihini ve eşikleri (aşırı düşük, dikkat, anomali Z, dayanak) kontrol edin.
A5: 2. IHALE_KARTI sayfasına ihale adı, yaklaşık maliyet, sınır değer yöntemi, N katsayısı ve kendi teklifinizi girin.
A6: 3. RAKIP_TEKLIFLER sayfasına rakip tekliflerini girin; her teklifin sınır değer oranı otomatik hesaplanır.
A7: 4. TEKLIF_BILESENLERI sayfasına kalem bazında birim fiyat ve rayiç fiyatı girin; sapma ve bayraklar otomatik üretilir.
A8: 5. FIYAT_FARKI_ENDEX sayfasına (fiyat farkı maddesi varsa) endeks değerlerini girin; tahmin üretilir.
A9: 6. KARAR sayfası UYGUN / İNCELE / DURDUR kararını, gerekçeyi ve aksiyonları gösterir.
A10: 7. PANO ve RAPOR sayfaları yönetici özetini ve yazdırılabilir raporu sunar.
A12: Sık yapılan hatalar
A13: Sınır değer katsayısını (N) idari şartnameden teyit etmeden girmek — yanlış katsayı tüm bölge kararını bozar.
A14: Rakip teklif tablosuna geçersiz (değerlendirme dışı) teklifleri de yazmak — ortalamayı saptırır.
A15: Bileşen birim fiyatına rayiç yerine kendi fiyatını yazmak — rayiç sapması anlamsız çıkar.
... A19: Tüm eşikler ve katsayılar AYARLAR sayfasından beslenir; formüle gömülü sayı kullanılmaz.

Sheet IHALE_KARTI
A1: IHALE KARTI — AŞIRI DÜŞÜK TEKLİF SAVUNMA ROBOTU
A3: İhale Bilgileri ve Teklif Kartı
A4: Sarı hücrelere manuel veri girin. Sınır değer katsayısı (N) ve yöntem bilgisi idari şartnameden alınır; teyitsiz değer kullanmayın.
A5: İhale Adı | B5: Örnek: Yol Yapım İşi
A6: İdare Adı | B6: Örnek: Belediye
A7: İhale Tarihi | B7: 46280
A8: Yaklaşık Maliyet (₺) | B8: 12500000
A9: Sınır Değer Yöntemi | B9: Ortalamanın Altındakilerin Ortalaması
A10: Sınır Değer Katsayısı (N) | B10: 1
A11: Kendi Teklif Tutarı (₺) | B11: 11150000
A12: Fiyat Farkı Maddesi Var mı? | B12: EVET
A14: Yaklaşık maliyet, rakip teklifler ve kendi teklif tutarı aynı para birimiyle (₺) girilmelidir.

Sheet RAKIP_TEKLIFLER
A1: RAKIP TEKLIFLER — AŞIRI DÜŞÜK TEKLİF SAVUNMA ROBOTU
A3: Rakip Teklifler
A4: Her satır bir istekliyi temsil eder. Değerlendirme dışı kalan teklifler için Geçerli mi? kolonuna HAYIR yazın; bu teklifler ortalamaya girmez.
A5: Sıra | B5: Rakip Adı | C5: Teklif Tutarı (₺) | D5: Geçerli mi? | E5: Teklif/Sınır Değer Oranı | F5: Anomali Z | G5: Durum | H5: Not
A6: 1 | B6: Yapı A A.Ş. | C6: 11900000 | D6: EVET | E6: =IF(C6="","",IFERROR(C6/MOTOR!$B$14,0)) | F6: =IF(C6="","",IFERROR((C6-MOTOR!$B$8)/MOTOR!$B$11,0)) | G6: =IF(C6="","",IF(E6<AYARLAR!$C$11,"AŞIRI DÜŞÜK",IF(E6<AYARLAR!$C$12,"SINIRDA","GÜVENLİ"))) | H6: Örnek teklif
A7: 2 | B7: İnşaat B Ltd. | C7: 12300000 | D7: EVET | E7: =IF(C7="","",IFERROR(C7/MOTOR!$B$14,0)) | F7: =IF(C7="","",IFERROR((C7-MOTOR!$B$8)/MOTOR!$B$11,0)) | G7: =IF(C7="","",IF(E7<AYARLAR!$C$11,"AŞIRI DÜŞÜK",IF(E7<AYARLAR!$C$12,"SINIRDA","GÜVENLİ"))) | H7: Örnek teklif
A8: 3 | B8: C Yapım | C8: 12800000 | D8: EVET | E8: =IF(C8="","",IFERROR(C8/MOTOR!$B$14,0)) | F8: =IF(C8="","",IFERROR((C8-MOTOR!$B$8)/MOTOR!$B$11,0)) | G8: =IF(C8="","",IF(E8<AYARLAR!$C$11,"AŞIRI DÜŞÜK",IF(E8<AYARLAR!$C$12,"SINIRDA","GÜVENLİ"))) | H8: Örnek teklif
A9: 4 | B9: Delta Mühendislik | C9: 10600000 | D9: EVET | E9: =IF(C9="","",IFERROR(C9/MOTOR!$B$14,0)) | F9: =IF(C9="","",IFERROR((C9-MOTOR!$B$8)/MOTOR!$B$11,0)) | G9: =IF(C9="","",IF(E9<AYARLAR!$C$11,"AŞIRI DÜŞÜK",IF(E9<AYARLAR!$C$12,"SINIRDA","GÜVENLİ"))) | H9: Örnek teklif
A10: 5 | B10: E Enerji | C10: 13200000 | D10: HAYIR | E10: =IF(C10="","",IFERROR(C10/MOTOR!$B$14,0)) | F10: =IF(C10="","",IFERROR((C10-MOTOR!$B$8)/MOTOR!$B$11,0)) | G10: =IF(C10="","",IF(E10<AYARLAR!$C$11,"AŞIRI DÜŞÜK",IF(E10<AYARLAR!$C$12,"SINIRDA","GÜVENLİ"))) | H10: Örnek: değerlendirme dışı
A11: 6 | B11: F Yapı | C11: 12600000 | D11: EVET | E11: =IF(C11="","",IFERROR(C11/MOTOR!$B$14,0)) | F11: =IF(C11="","",IFERROR((C11-MOTOR!$B$8)/MOTOR!$B$11,0)) | G11: =IF(C11="","",IF(E11<AYARLAR!$C$11,"AŞIRI DÜŞÜK",IF(E11<AYARLAR!$C$12,"SINIRDA","GÜVENLİ"))) | H11: Örnek teklif
A12: 7 | B12: G İnşaat A.Ş. | C12: 11450000 | D12: EVET | E12: =IF(C12="","",IFERROR(C12/MOTOR!$B$14,0)) | F12: =IF(C12="","",IFERROR((C12-MOTOR!$B$8)/MOTOR!$B$11,0)) | G12: =IF(C12="","",IF(E12<AYARLAR!$C$11,"AŞIRI DÜŞÜK",IF(E12<AYARLAR!$C$12,"SINIRDA","GÜVENLİ"))) | H12: Örnek teklif
A13: 8 | B13: H Taahhüt | C13: 12100000 | D13: EVET | E13: =IF(C13="","",IFERROR(C13/MOTOR!$B$14,0)) | F13: =IF(C13="","",IFERROR((C13-MOTOR!$B$8)/MOTOR!$B$11,0)) | G13: =IF(C13="","",IF(E13<AYARLAR!$C$11,"AŞIRI DÜŞÜK",IF(E13<AYARLAR!$C$12,"SINIRDA","GÜVENLİ"))) | H13: Örnek teklif
A14: 9 | B14: I Yapım Ltd. | C14: 13050000 | D14: HAYIR | E14: =IF(C14="","",IFERROR(C14/MOTOR!$B$14,0)) | F14: =IF(C14="","",IFERROR((C14-MOTOR!$B$8)/MOTOR!$B$11,0)) | G14: =IF(C14="","",IF(E14<AYARLAR!$C$11,"AŞIRI DÜŞÜK",IF(E14<AYARLAR!$C$12,"SINIRDA","GÜVENLİ"))) | H14: Örnek: eksik belge
A15: 10 | B15: J Müteahhit | C15: 11600000 | D15: EVET | E15: =IF(C15="","",IFERROR(C15/MOTOR!$B$14,0)) | F15: =IF(C15="","",IFERROR((C15-MOTOR!$B$8)/MOTOR!$B$11,0)) | G15: =IF(C15="","",IF(E15<AYARLAR!$C$11,"AŞIRI DÜŞÜK",IF(E15<AYARLAR!$C$12,"SINIRDA","GÜVENLİ"))) | H15: Örnek teklif
A16: 11 | B16: K İnşaat | C16: 12450000 | D16: EVET | E16: =IF(C16="","",IFERROR(C16/MOTOR!$B$14,0)) | F16: =IF(C16="","",IFERROR((C16-MOTOR!$B$8)/MOTOR!$B$11,0)) | G16: =IF(C16="","",IF(E16<AYARLAR!$C$11,"AŞIRI DÜŞÜK",IF(E16<AYARLAR!$C$12,"SINIRDA","GÜVENLİ"))) | H16: Örnek teklif
A17: 12 | B17: L Yapı | C17: 11850000 | D17: EVET | E17: =IF(C17="","",IFERROR(C17/MOTOR!$B$14,0)) | F17: =IF(C17="","",IFERROR((C17-MOTOR!$B$8)/MOTOR!$B$11,0)) | G17: =IF(C17="","",IF(E17<AYARLAR!$C$11,"AŞIRI DÜŞÜK",IF(E17<AYARLAR!$C$12,"SINIRDA","GÜVENLİ"))) | H17: Örnek teklif
A18: 13 | E18: =IF(C18="","",IFERROR(C18/MOTOR!$B$14,0)) | F18: =IF(C18="","",IFERROR((C18-MOTOR!$B$8)/MOTOR!$B$11,0)) | G18: =IF(C18="","",IF(E18<AYARLAR!$C$11,"AŞIRI DÜŞÜK",IF(E18<AYARLAR!$C$12,"SINIRDA","GÜVENLİ")))
A19: 14 | E19: =IF(C19="","",IFERROR(C19/MOTOR!$B$14,0)) | F19: =IF(C19="","",IFERROR((C19-MOTOR!$B$8)/MOTOR!$B$11,0)) | G19: =IF(C19="","",IF(E19<AYARLAR!$C$11,"AŞIRI DÜŞÜK",IF(E19<AYARLAR!$C$12,"SINIRDA","GÜVENLİ")))
A20: 15 | E20: =IF(C20="","",IFERROR(C20/MOTOR!$B$14,0)) | F20: =IF(C20="","",IFERROR((C20-MOTOR!$B$8)/MOTOR!$B$11,0)) | G20: =IF(C20="","",IF(E20<AYARLAR!$C$11,"AŞIRI DÜŞÜK",IF(E20<AYARLAR!$C$12,"SINIRDA","GÜVENLİ")))
A21: 16 | E21: =IF(C21="","",IFERROR(C21/MOTOR!$B$14,0)) | F21: =IF(C21="","",IFERROR((C21-MOTOR!$B$8)/MOTOR!$B$11,0)) | G21: =IF(C21="","",IF(E21<AYARLAR!$C$11,"AŞIRI DÜŞÜK",IF(E21<AYARLAR!$C$12,"SINIRDA","GÜVENLİ")))
A22: 17 | E22: =IF(C22="","",IFERROR(C22/MOTOR!$B$14,0)) | F22: =IF(C22="","",IFERROR((C22-MOTOR!$B$8)/MOTOR!$B$11,0)) | G22: =IF(C22="","",IF(E22<AYARLAR!$C$11,"AŞIRI DÜŞÜK",IF(E22<AYARLAR!$C$12,"SINIRDA","GÜVENLİ")))
A23: 18 | E23: =IF(C23="","",IFERROR(C23/MOTOR!$B$14,0)) | F23: =IF(C23="","",IFERROR((C23-MOTOR!$B$8)/MOTOR!$B$11,0)) | G23: =IF(C23="","",IF(E23<AYARLAR!$C$11,"AŞIRI DÜŞÜK",IF(E23<AYARLAR!$C$12,"SINIRDA","GÜVENLİ")))
A24: 19 | E24: =IF(C24="","",IFERROR(C24/MOTOR!$B$14,0)) | F24: =IF(C24="","",IFERROR((C24-MOTOR!$B$8)/MOTOR!$B$11,0)) | G24: =IF(C24="","",IF(E24<AYARLAR!$C$11,"AŞIRI DÜŞÜK",IF(E24<AYARLAR!$C$12,"SINIRDA","GÜVENLİ")))
A25: 20 | E25: =IF(C25="","",IFERROR(C25/MOTOR!$B$14,0)) | F25: =IF(C25="","",IFERROR((C25-MOTOR!$B$8)/MOTOR!$B$11,0)) | G25: =IF(C25="","",IF(E25<AYARLAR!$C$11,"AŞIRI DÜŞÜK",IF(E25<AYARLAR!$C$12,"SINIRDA","GÜVENLİ")))
A26: 21 | E26: =IF(C26="","",IFERROR(C26/MOTOR!$B$14,0)) | F26: =IF(C26="","",IFERROR((C26-MOTOR!$B$8)/MOTOR!$B$11,0)) | G26: =IF(C26="","",IF(E26<AYARLAR!$C$11,"AŞIRI DÜŞÜK",IF(E26<AYARLAR!$C$12,"SINIRDA","GÜVENLİ")))
A27: 22 | E27: =IF(C27="","",IFERROR(C27/MOTOR!$B$14,0)) | F27: =IF(C27="","",IFERROR((C27-MOTOR!$B$8)/MOTOR!$B$11,0)) | G27: =IF(C27="","",IF(E27<AYARLAR!$C$11,"AŞIRI DÜŞÜK",IF(E27<AYARLAR!$C$12,"SINIRDA","GÜVENLİ")))
A28: 23 | E28: =IF(C28="","",IFERROR(C28/MOTOR!$B$14,0)) | F28: =IF(C28="","",IFERROR((C28-MOTOR!$B$8)/MOTOR!$B$11,0)) | G28: =IF(C28="","",IF(E28<AYARLAR!$C$11,"AŞIRI DÜŞÜK",IF(E28<AYARLAR!$C$12,"SINIRDA","GÜVENLİ")))
A29: 24 | E29: =IF(C29="","",IFERROR(C29/MOTOR!$B$14,0)) | F29: =IF(C29="","",IFERROR((C29-MOTOR!$B$8)/MOTOR!$B$11,0)) | G29: =IF(C29="","",IF(E29<AYARLAR!$C$11,"AŞIRI DÜŞÜK",IF(E29<AYARLAR!$C$12,"SINIRDA","GÜVENLİ")))
... A1004: 999 | E1004: =IF(C1004="","",IFERROR(C1004/MOTOR!$B$14,0)) | F1004: =IF(C1004="","",IFERROR((C1004-MOTOR!$B$8)/MOTOR!$B$11,0)) | G1004: =IF(C1004="","",IF(E1004<AYARLAR!$C$11,"AŞIRI DÜŞÜK",IF(E1004<AYARLAR!$C$12,"SINIRDA","GÜVENLİ")))
A1006: Sıra, oran, anomali Z ve durum kolonları hesaplanmıştır; yalnızca sarı kolonlara yazın.

Sheet TEKLIF_BILESENLERI
A1: TEKLIF BILESENLERI — AŞIRI DÜŞÜK TEKLİF SAVUNMA ROBOTU
A3: Teklif Bileşenleri (Açıklama Seti)
A4: Teklif bedelini oluşturan kalemleri girin. Birim fiyat ile rayiç birim fiyat arasındaki sapma aşırı düşük açıklamasında sorgulanır; dayanak türü seçin.
A5: Kalem Adı | B5: Birim | C5: Miktar | D5: Birim Fiyat (₺) | E5: Rayiç Birim Fiyat (₺) | F5: Dayanak Türü | G5: Tutar (₺) | H5: Rayiç Tutar (₺) | I5: Rayiç Sapması | J5: Risk Bayrağı | K5: Ağırlık (%) | L5: Dayanak Tam mı? | M5: Not
A6: Beton C30 | B6: m³ | C6: 1500 | D6: 2100 | E6: 1950 | F6: Fatura | G6: =IF(C6="","",C6*D6) | H6: =IF(C6="","",C6*E6) | I6: =IF(C6="","",IFERROR(D6/(E6+(E6=0))-1,0)) | J6: =IF(C6="","",IF(ABS(I6)>AYARLAR!$C$14,"RİSKLİ","NORMAL")) | K6: =IF(G6="","",IFERROR(G6/MOTOR!$B$20,0)) | L6: =IF(C6="","",IF(F6="","EKSİK","TAM")) | M6: Örnek kalem
A7: Demir Donatı | B7: ton | C7: 236 | D7: 28500 | E7: 27500 | F7: Rayiç | G7: =IF(C7="","",C7*D7) | H7: =IF(C7="","",C7*E7) | I7: =IF(C7="","",IFERROR(D7/(E7+(E7=0))-1,0)) | J7: =IF(C7="","",IF(ABS(I7)>AYARLAR!$C$14,"RİSKLİ","NORMAL")) | K7: =IF(G7="","",IFERROR(G7/MOTOR!$B$20,0)) | L7: =IF(C7="","",IF(F7="","EKSİK","TAM")) | M7: Örnek kalem
A8: Kalıp İşçiliği | B8: m² | C8: 4200 | D8: 145 | E8: 138 | F8: Analiz | G8: =IF(C8="","",C8*D8) | H8: =IF(C8="","",C8*E8) | I8: =IF(C8="","",IFERROR(D8/(E8+(E8=0))-1,0)) | J8: =IF(C8="","",IF(ABS(I8)>AYARLAR!$C$14,"RİSKLİ","NORMAL")) | K8: =IF(G8="","",IFERROR(G8/MOTOR!$B$20,0)) | L8: =IF(C8="","",IF(F8="","EKSİK","TAM")) | M8: Örnek kalem
A9: Cephe İskele | B9: m² | C9: 1800 | D9: 95 | E9: 102 | F9: Teklif | G9: =IF(C9="","",C9*D9) | H9: =IF(C9="","",C9*E9) | I9: =IF(C9="","",IFERROR(D9/(E9+(E9=0))-1,0)) | J9: =IF(C9="","",IF(ABS(I9)>AYARLAR!$C$14,"RİSKLİ","NORMAL")) | K9: =IF(G9="","",IFERROR(G9/MOTOR!$B$20,0)) | L9: =IF(C9="","",IF(F9="","EKSİK","TAM")) | M9: Örnek kalem
A10: Şantiye Şefliği | B10: işçilik | C10: 4 | D10: 85000 | E10: 82000 | F10: Yönetmelik | G10: =IF(C10="","",C10*D10) | H10: =IF(C10="","",C10*E10) | I10: =IF(C10="","",IFERROR(D10/(E10+(E10=0))-1,0)) | J10: =IF(C10="","",IF(ABS(I10)>AYARLAR!$C$14,"RİSKLİ","NORMAL")) | K10: =IF(G10="","",IFERROR(G10/MOTOR!$B$20,0)) | L10: =IF(C10="","",IF(F10="","EKSİK","TAM")) | M10: Örnek kalem
A11: Kazı İşleri | B11: m³ | C11: 2200 | D11: 88 | E11: 84 | F11: Analiz | G11: =IF(C11="","",C11*D11) | H11: =IF(C11="","",C11*E11) | I11: =IF(C11="","",IFERROR(D11/(E11+(E11=0))-1,0)) | J11: =IF(C11="","",IF(ABS(I11)>AYARLAR!$C$14,"RİSKLİ","NORMAL")) | K11: =IF(G11="","",IFERROR(G11/MOTOR!$B$20,0)) | L11: =IF(C11="","",IF(F11="","EKSİK","TAM")) | M11: Örnek kalem
A12: Betonarme Kalıp | B12: m² | C12: 3800 | D12: 160 | E12: 152 | F12: Analiz | G12: =IF(C12="","",C12*D12) | H12: =IF(C12="","",C12*E12) | I12: =IF(C12="","",IFERROR(D12/(E12+(E12=0))-1,0)) | J12: =IF(C12="","",IF(ABS(I12)>AYARLAR!$C$14,"RİSKLİ","NORMAL")) | K12: =IF(G12="","",IFERROR(G12/MOTOR!$B$20,0)) | L12: =IF(C12="","",IF(F12="","EKSİK","TAM")) | M12: Örnek kalem
A13: Mermer Döşeme | B13: m² | C13: 750 | D13: 480 | E13: 460 | F13: Fatura | G13: =IF(C13="","",C13*D13) | H13: =IF(C13="","",C13*E13) | I13: =IF(C13="","",IFERROR(D13/(E13+(E13=0))-1,0)) | J13: =IF(C13="","",IF(ABS(I13)>AYARLAR!$C$14,"RİSKLİ","NORMAL")) | K13: =IF(G13="","",IFERROR(G13/MOTOR!$B$20,0)) | L13: =IF(C13="","",IF(F13="","EKSİK","TAM")) | M13: Örnek kalem
A14: Alçı Sıva | B14: m² | C14: 5200 | D14: 95 | E14: 90 | F14: Rayiç | G14: =IF(C14="","",C14*D14) | H14: =IF(C14="","",C14*E14) | I14: =IF(C14="","",IFERROR(D14/(E14+(E14=0))-1,0)) | J14: =IF(C14="","",IF(ABS(I14)>AYARLAR!$C$14,"RİSKLİ","NORMAL")) | K14: =IF(G14="","",IFERROR(G14/MOTOR!$B$20,0)) | L14: =IF(C14="","",IF(F14="","EKSİK","TAM")) | M14: Örnek kalem
A15: Asma Tavan | B15: m² | C15: 1300 | D15: 220 | E15: 215 | F15: Teklif | G15: =IF(C15="","",C15*D15) | H15: =IF(C15="","",C15*E15) | I15: =IF(C15="","",IFERROR(D15/(E15+(E15=0))-1,0)) | J15: =IF(C15="","",IF(ABS(I15)>AYARLAR!$C$14,"RİSKLİ","NORMAL")) | K15: =IF(G15="","",IFERROR(G15/MOTOR!$B$20,0)) | L15: =IF(C15="","",IF(F15="","EKSİK","TAM")) | M15: Örnek kalem
A16: Elektrik Tesisatı | B16: m² | C16: 6100 | D16: 120 | E16: 115 | F16: Analiz | G16: =IF(C16="","",C16*D16) | H16: =IF(C16="","",C16*E16) | I16: =IF(C16="","",IFERROR(D16/(E16+(E16=0))-1,0)) | J16: =IF(C16="","",IF(ABS(I16)>AYARLAR!$C$14,"RİSKLİ","NORMAL")) | K16: =IF(G16="","",IFERROR(G16/MOTOR!$B$20,0)) | L16: =IF(C16="","",IF(F16="","EKSİK","TAM")) | M16: Örnek kalem
A17: Mekanik Tesisat | B17: m² | C17: 6100 | D17: 175 | E17: 168 | F17: Fatura | G17: =IF(C17="","",C17*D17) | H17: =IF(C17="","",C17*E17) | I17: =IF(C17="","",IFERROR(D17/(E17+(E17=0))-1,0)) | J17: =IF(C17="","",IF(ABS(I17)>AYARLAR!$C$14,"RİSKLİ","NORMAL")) | K17: =IF(G17="","",IFERROR(G17/MOTOR!$B$20,0)) | L17: =IF(C17="","",IF(F17="","EKSİK","TAM")) | M17: Örnek kalem
... A19: Çatı Kaplama | B19: m² | C19: 2100 | D19: 130 | E19: 125 | F19: Teklif | G19: =IF(C19="","",C19*D19) | H19: =IF(C19="","",C19*E19) | I19: =IF(C19="","",IFERROR(D19/(E19+(E19=0))-1,0)) | J19: =IF(C19="","",IF(ABS(I19)>AYARLAR!$C$14,"RİSKLİ","NORMAL")) | K19: =IF(G19="","",IFERROR(G19/MOTOR!$B$20,0)) | L19: =IF(C19="","",IF(F19="","EKSİK","TAM")) | M19: Örnek kalem
G20: =IF(C20="","",C20*D20) | H20: =IF(C20="","",C20*E20) | I20: =IF(C20="","",IFERROR(D20/(E20+(E20=0))-1,0)) | J20: =IF(C20="","",IF(ABS(I20)>AYARLAR!$C$14,"RİSKLİ","NORMAL")) | K20: =IF(G20="","",IFERROR(G20/MOTOR!$B$20,0)) | L20: =IF(C20="","",IF(F20="","EKSİK","TAM"))
G21: =IF(C21="","",C21*D21) | H21: =IF(C21="","",C21*E21) | I21: =IF(C21="","",IFERROR(D21/(E21+(E21=0))-1,0)) | J21: =IF(C21="","",IF(ABS(I21)>AYARLAR!$C$14,"RİSKLİ","NORMAL")) | K21: =IF(G21="","",IFERROR(G21/MOTOR!$B$20,0)) | L21: =IF(C21="","",IF(F21="","EKSİK","TAM"))
G22: =IF(C22="","",C22*D22) | H22: =IF(C22="","",C22*E22) | I22: =IF(C22="","",IFERROR(D22/(E22+(E22=0))-1,0)) | J22: =IF(C22="","",IF(ABS(I22)>AYARLAR!$C$14,"RİSKLİ","NORMAL")) | K22: =IF(G22="","",IFERROR(G22/MOTOR!$B$20,0)) | L22: =IF(C22="","",IF(F22="","EKSİK","TAM"))
G23: =IF(C23="","",C23*D23) | H23: =IF(C23="","",C23*E23) | I23: =IF(C23="","",IFERROR(D23/(E23+(E23=0))-1,0)) | J23: =IF(C23="","",IF(ABS(I23)>AYARLAR!$C$14,"RİSKLİ","NORMAL")) | K23: =IF(G23="","",IFERROR(G23/MOTOR!$B$20,0)) | L23: =IF(C23="","",IF(F23="","EKSİK","TAM"))
G24: =IF(C24="","",C24*D24) | H24: =IF(C24="","",C24*E24) | I24: =IF(C24="","",IFERROR(D24/(E24+(E24=0))-1,0)) | J24: =IF(C24="","",IF(ABS(I24)>AYARLAR!$C$14,"RİSKLİ","NORMAL")) | K24: =IF(G24="","",IFERROR(G24/MOTOR!$B$20,0)) | L24: =IF(C24="","",IF(F24="","EKSİK","TAM"))
G25: =IF(C25="","",C25*D25) | H25: =IF(C25="","",C25*E25) | I25: =IF(C25="","",IFERROR(D25/(E25+(E25=0))-1,0)) | J25: =IF(C25="","",IF(ABS(I25)>AYARLAR!$C$14,"RİSKLİ","NORMAL")) | K25: =IF(G25="","",IFERROR(G25/MOTOR!$B$20,0)) | L25: =IF(C25="","",IF(F25="","EKSİK","TAM"))
G26: =IF(C26="","",C26*D26) | H26: =IF(C26="","",C26*E26) | I26: =IF(C26="","",IFERROR(D26/(E26+(E26=0))-1,0)) | J26: =IF(C26="","",IF(ABS(I26)>AYARLAR!$C$14,"RİSKLİ","NORMAL")) | K26: =IF(G26="","",IFERROR(G26/MOTOR!$B$20,0)) | L26: =IF(C26="","",IF(F26="","EKSİK","TAM"))
G27: =IF(C27="","",C27*D27) | H27: =IF(C27="","",C27*E27) | I27: =IF(C27="","",IFERROR(D27/(E27+(E27=0))-1,0)) | J27: =IF(C27="","",IF(ABS(I27)>AYARLAR!$C$14,"RİSKLİ","NORMAL")) | K27: =IF(G27="","",IFERROR(G27/MOTOR!$B$20,0)) | L27: =IF(C27="","",IF(F27="","EKSİK","TAM"))
G28: =IF(C28="","",C28*D28) | H28: =IF(C28="","",C28*E28) | I28: =IF(C28="","",IFERROR(D28/(E28+(E28=0))-1,0)) | J28: =IF(C28="","",IF(ABS(I28)>AYARLAR!$C$14,"RİSKLİ","NORMAL")) | K28: =IF(G28="","",IFERROR(G28/MOTOR!$B$20,0)) | L28: =IF(C28="","",IF(F28="","EKSİK","TAM"))
G29: =IF(C29="","",C29*D29) | H29: =IF(C29="","",C29*E29) | I29: =IF(C29="","",IFERROR(D29/(E29+(E29=0))-1,0)) | J29: =IF(C29="","",IF(ABS(I29)>AYARLAR!$C$14,"RİSKLİ","NORMAL")) | K29: =IF(G29="","",IFERROR(G29/MOTOR!$B$20,0)) | L29: =IF(C29="","",IF(F29="","EKSİK","TAM"))
G30: =IF(C30="","",C30*D30) | H30: =IF(C30="","",C30*E30) | I30: =IF(C30="","",IFERROR(D30/(E30+(E30=0))-1,0)) | J30: =IF(C30="","",IF(ABS(I30)>AYARLAR!$C$14,"RİSKLİ","NORMAL")) | K30: =IF(G30="","",IFERROR(G30/MOTOR!$B$20,0)) | L30: =IF(C30="","",IF(F30="","EKSİK","TAM"))
G31: =IF(C31="","",C31*D31) | H31: =IF(C31="","",C31*E31) | I31: =IF(C31="","",IFERROR(D31/(E31+(E31=0))-1,0)) | J31: =IF(C31="","",IF(ABS(I31)>AYARLAR!$C$14,"RİSKLİ","NORMAL")) | K31: =IF(G31="","",IFERROR(G31/MOTOR!$B$20,0)) | L31: =IF(C31="","",IF(F31="","EKSİK","TAM"))
... G1004: =IF(C1004="","",C1004*D1004) | H1004: =IF(C1004="","",C1004*E1004) | I1004: =IF(C1004="","",IFERROR(D1004/(E1004+(E1004=0))-1,0)) | J1004: =IF(C1004="","",IF(ABS(I1004)>AYARLAR!$C$14,"RİSKLİ","NORMAL")) | K1004: =IF(G1004="","",IFERROR(G1004/MOTOR!$B$20,0)) | L1004: =IF(C1004="","",IF(F1004="","EKSİK","TAM"))
A1006: Tutar, rayiç tutar, sapma, bayrak, ağırlık ve dayanak durumu hesaplanır; yalnızca sarı kolonlara yazın.

Sheet FIYAT_FARKI_ENDEX
A1: FIYAT FARKI ENDEX — AŞIRI DÜŞÜK TEKLİF SAVUNMA ROBOTU
A3: Fiyat Farkı Endeksi ve Projeksiyonu
A4: İdari şartnamede fiyat farkı maddesi varsa, sözleşmedeki endeks türüne ait dönem değerlerini girin. Hareketli ortalama ve tahmin aralığı otomatik üretilir.
A5: Dönem | B5: Endeks Değeri | C5: 3 Dönem Hareketli Ortalama | D5: Not
A6: 2025/09 | B6: 1900 | C6: =IF(B6="",0,IFERROR(AVERAGE(B4,B5,B6),0)) | D6: Örnek dönem
A7: 2025/10 | B7: 1950 | C7: =IF(B7="",0,IFERROR(AVERAGE(B5,B6,B7),0)) | D7: Örnek dönem
A8: 2025/11 | B8: 1980 | C8: =IF(B8="",0,IFERROR(AVERAGE(B6,B7,B8),0)) | D8: Örnek dönem
A9: 2025/12 | B9: 2010 | C9: =IF(B9="",0,IFERROR(AVERAGE(B7,B8,B9),0)) | D9: Örnek dönem
A10: 2026/01 | B10: 2050 | C10: =IF(B10="",0,IFERROR(AVERAGE(B8,B9,B10),0)) | D10: Örnek dönem
A11: 2026/02 | B11: 2090 | C11: =IF(B11="",0,IFERROR(AVERAGE(B9,B10,B11),0)) | D11: Örnek dönem
A12: 2026/03 | B12: 2120 | C12: =IF(B12="",0,IFERROR(AVERAGE(B10,B11,B12),0)) | D12: Örnek dönem
A13: 2026/04 | B13: 2160 | C13: =IF(B13="",0,IFERROR(AVERAGE(B11,B12,B13),0)) | D13: Örnek dönem
A14: 2026/05 | B14: 2190 | C14: =IF(B14="",0,IFERROR(AVERAGE(B12,B13,B14),0)) | D14: Örnek dönem
A15: 2026/06 | B15: 2215 | C15: =IF(B15="",0,IFERROR(AVERAGE(B13,B14,B15),0)) | D15: Örnek dönem
A16: 2026/07 | B16: 2240 | C16: =IF(B16="",0,IFERROR(AVERAGE(B14,B15,B16),0)) | D16: Örnek dönem
A17: 2026/08 | B17: 2270 | C17: =IF(B17="",0,IFERROR(AVERAGE(B15,B16,B17),0)) | D17: Örnek dönem
... A21: 2026/12 | B21: 2370 | C21: =IF(B21="",0,IFERROR(AVERAGE(B19,B20,B21),0)) | D21: Örnek dönem
C22: =IF(B22="",0,IFERROR(AVERAGE(B20,B21,B22),0))
C23: =IF(B23="",0,IFERROR(AVERAGE(B21,B22,B23),0))
C24: =IF(B24="",0,IFERROR(AVERAGE(B22,B23,B24),0))
C25: =IF(B25="",0,IFERROR(AVERAGE(B23,B24,B25),0))
C26: =IF(B26="",0,IFERROR(AVERAGE(B24,B25,B26),0))
C27: =IF(B27="",0,IFERROR(AVERAGE(B25,B26,B27),0))
C28: =IF(B28="",0,IFERROR(AVERAGE(B26,B27,B28),0))
C29: =IF(B29="",0,IFERROR(AVERAGE(B27,B28,B29),0))
C30: =IF(B30="",0,IFERROR(AVERAGE(B28,B29,B30),0))
C31: =IF(B31="",0,IFERROR(AVERAGE(B29,B30,B31),0))
C32: =IF(B32="",0,IFERROR(AVERAGE(B30,B31,B32),0))
C33: =IF(B33="",0,IFERROR(AVERAGE(B31,B32,B33),0))
... C1004: =IF(B1004="",0,IFERROR(AVERAGE(B1002,B1003,B1004),0))
A1006: Hareketli ortalama ve tahmin aralığı otomatik hesaplanır; yalnızca sarı kolonlara yazın.

Sheet MOTOR
A1: MOTOR — AŞIRI DÜŞÜK TEKLİF SAVUNMA ROBOTU
A3: Hesaplama Motoru
A4: Tüm ara hesaplar bu sayfada üretilir. Bu sayfa elle değiştirilmez; giriş sayfalarından beslenir.
A6: Geçerli Teklif Sayısı (adet) | B6: =COUNTIF(tblRakipler[Geçerli mi?],"EVET")
A7: Geçersiz Teklif Sayısı (adet) | B7: =COUNTIF(tblRakipler[Geçerli mi?],"HAYIR")
A8: Tüm Geçerli Teklif Ortalaması (₺) | B8: =IFERROR(AVERAGEIF(tblRakipler[Geçerli mi?],"EVET",tblRakipler[Teklif Tutarı (₺)]),0)
A9: Ortalama Altı Teklif Sayısı (adet) | B9: =IFERROR(COUNTIFS(tblRakipler[Geçerli mi?],"EVET",tblRakipler[Teklif Tutarı (₺)],"<"&SdOrtalamaTeklif),0)
A10: Ortalamanın Altındakilerin Ortalaması (₺) | B10: =IFERROR(AVERAGEIFS(tblRakipler[Teklif Tutarı (₺)],tblRakipler[Geçerli mi?],"EVET",tblRakipler[Teklif Tutarı (₺)],"<"&SdOrtalamaTeklif),0)
A11: Teklif Tutarları Standart Sapması (₺) | B11: =IFERROR(_xlfn.STDEV.P(tblRakipler[Teklif Tutarı (₺)]),0)
A12: Teklif Tutarları Medyanı (₺) | B12: =IFERROR(MEDIAN(tblRakipler[Teklif Tutarı (₺)]),0)
A13: Sınır Değer Tabanı (Yönteme Göre) (₺) | B13: =IF(SinirDegerYontem=ListeYontemAlti,SdOrtalamaAlti,SdOrtalamaTeklif)
A14: SINIR DEĞER (₺) | B14: =SinirDegerKatsayisi*SdYontemTaban
A15: Kendi Teklif / Sınır Değer Oranı | B15: =IF(SdSinirDeger=0,0,KendiTeklifTutari/SdSinirDeger)
A16: Güvenlik Payı (Oran) | B16: =SdOran-AsiriDusukEsik
A17: Aşırı Düşük Kontrol | B17: =IF(SdOran<AsiriDusukEsik,"AŞIRI DÜŞÜK",IF(SdOran<DikkatEsik,"SINIRDA","GÜVENLİ"))
A19: Teklif Bileşen Mutabakatı
A20: Bileşen Toplam Tutarı (₺) | B20: =SUM(tblBilesenler[Tutar (₺)])
A21: Bileşen Toplam Rayiç Tutarı (₺) | B21: =SUM(tblBilesenler[Rayiç Tutar (₺)])
A22: Mutabakat Farkı (₺) | B22: =SdBilesenToplam-KendiTeklifTutari
A23: Mutabakat Farkı Yüzdesi | B23: =IF(KendiTeklifTutari=0,0,SdMutabakatFarki/KendiTeklifTutari)
A24: Mutabakat Durumu | B24: =IF(SdBilesenToplam=0,"VERİ YOK",IF(ABS(SdMutabakatFarki)<=KabulEdilebilirFark,"MUTABIK","FARK VAR"))
A25: Dayanaklı Bileşen Ağırlığı (%) | B25: =IFERROR(SUMIFS(tblBilesenler[Ağırlık (%)],tblBilesenler[Dayanak Tam mı?],"TAM"),0)
A26: Savunma Gücü | B26: =IF(SdDayanakliAgirlik=0,"VERİ YOK",IF(SdDayanakliAgirlik<DayanakEsik,"ZAYIF","YETERLİ"))
A28: Fiyat Farkı Endeksi Özeti
A29: Endeks Ortalaması | B29: =IFERROR(AVERAGE(tblProjeksiyon[Endeks Değeri]),0)
A30: Endeks Eğilimi (Dönem Başına) | B30: =IFERROR(SLOPE(tblProjeksiyon[Endeks Değeri],ROW(tblProjeksiyon[Endeks Değeri])-ROW(tblProjeksiyon[[#Headers],[Endeks Değeri]])),0)
A31: Tahmini İleri Dönem Endeksi | B31: =IFERROR(forecast.lınear(COUNT(tblProjeksiyon[Endeks Değeri])+ProjeksiyonIleriDonem,tblProjeksiyon[Endeks Değeri],ROW(tblProjeksiyon[Endeks Değeri])-ROW(tblProjeksiyon[[#Headers],[Endeks Değeri]])),0)
A32: Tahmini Fiyat Farkı Etkisi (%) | B32: =IF(FiyatFarkiVarMi="HAYIR",0,IF(SdEndeksOrtalama=0,0,SdEndeksTahmin/SdEndeksOrtalama-1))
A33: Son Dönem Endeks Değişimi (%) | B33: =IFERROR(INDEX(tblProjeksiyon[Endeks Değeri],COUNT(tblProjeksiyon[Endeks Değeri]))/INDEX(tblProjeksiyon[Endeks Değeri],MAX(1,COUNT(tblProjeksiyon[Endeks Değeri])-1))-1,0)
A34: İlk Üç Kalem Toplamı (₺) | B34: =IFERROR(LARGE(tblBilesenler[Tutar (₺)],1)+LARGE(tblBilesenler[Tutar (₺)],2)+LARGE(tblBilesenler[Tutar (₺)],3),0)
A36: Analitik Modüller (Derinlik Katmanı)
A37: T2 Endeks Eğilimi | B37: =SdEndeksEgim
A38: T3 Pareto: İlk 3 Kalem Payı (%) | B38: =IF(SdBilesenToplam=0,0,SdIlkUcKalem/SdBilesenToplam)
A39: T6 Bileşen Kırılım Oranı | B39: =IF(KendiTeklifTutari=0,0,SdBilesenToplam/KendiTeklifTutari)
A40: O1 Anomali Teklif Sayısı (adet) | B40: =SUMPRODUCT((ABS(IF(ISNUMBER(tblRakipler[Anomali Z]),tblRakipler[Anomali Z],0))>AnomaliZEsik)*1)
A41: O2 Tornado Zirve | B41: =SENARYO_DUYARLILIK!B18
A42: O3 Senaryo Baz (₺) | B42: =SENARYO_DUYARLILIK!B8
A43: O8 Veri Kalitesi Skoru | B43: =KaliteSkoru
A44: I1 İleri Dönem Tahmini (₺) | B44: =SdEndeksTahmin
A45: I2 Yüzdelik: P90 Teklif (₺) | B45: =IFERROR(PERCENTILE(tblRakipler[Teklif Tutarı (₺)],0.9),0)
...

Sheet KONTROL
A1: KONTROL — AŞIRI DÜŞÜK TEKLİF SAVUNMA ROBOTU
A3: Giriş Kalite Kontrolleri
A4: Aşağıdaki kontroller canlı formüllerle çalışır; sorun varsa uyarı üretir.
A6: Geçerli teklif var mı? | B6: =IF(SdGecerliSayi=0,"BOŞ","TAM")
A7: Boş teklif satırı var mı? | B7: =IF(COUNTBLANK(tblRakipler[Teklif Tutarı (₺)])=0,"TEMİZ","BOŞ VAR")
A8: Negatif teklif var mı? | B8: =IF(COUNTIF(tblRakipler[Teklif Tutarı (₺)],"<0")=0,"TEMİZ","NEGATİF VAR")
A9: Rayiç eşiği altında kalan bileşen var mı? | B9: =IF(SUMPRODUCT((tblBilesenler[Rayiç Sapması]<-RayicSapmaEsik)*1)=0,"TEMİZ","RİSKLİ VAR")
A10: Dayanağı eksik bileşen var mı? | B10: =IF(COUNTIF(tblBilesenler[Dayanak Tam mı?],"EKSİK")=0,"TEMİZ","EKSİK VAR")
A11: Bileşen mutabakatı sağlandı mı? | B11: =SdMutabakatDurumu
A12: Savunma gücü yeterli mi? | B12: =SdSavunmaGucu
A13: Endeks verisi tam mı? | B13: =IF(COUNTBLANK(tblProjeksiyon[Endeks Değeri])>0,"EKSİK","TAM")
A15: Veri Kalitesi Skoru (0-100)
A16: Dolu giriş hücresi sayısının toplam giriş hücresine oranı; düşük skor tüm çıktılara güven damgası vurur.
A17: Giriş Doluluk Oranı | B17: =IF(ToplamGirisHucre=0,0,DoluGirisHucre/ToplamGirisHucre)
A18: Dolu Giriş Hücresi | B18: =COUNTA(tblRakipler[Rakip Adı])+COUNTA(tblRakipler[Teklif Tutarı (₺)])+COUNTA(tblRakipler[Geçerli mi?])+COUNTA(tblRakipler[Not])+COUNTA(tblBilesenler[Kalem Adı])+COUNTA(tblBilesenler[Birim])+COUNTA(tblBilesenler[Miktar])+COUNTA(tblBilesenler[Birim Fiyat (₺)])+COUNTA(tblBilesenler[Rayiç Birim Fiyat (₺)])+COUNTA(tblBilesenler[Dayanak Türü])+COUNTA(tblBilesenler[Not])+COUNTA(tblProjeksiyon[Dönem])+COUNTA(tblProjeksiyon[Endeks Değeri])+COUNTA(tblProjeksiyon[Not])
A19: Kalite Skoru | B19: =ROUND(100*MIN(DoluGirisHucre,ToplamGirisHucre)/ToplamGirisHucre,0)
A20: Kalite Seviyesi | B20: =IF(KaliteSkoru>=KaliteIyi,"YÜKSEK",IF(KaliteSkoru>=KaliteOrta,"ORTA","DÜŞÜK"))
A22: Kontroller yalnızca giriş verisini denetler; değerleri değiştirmez.

Sheet KARAR
A1: KARAR — AŞIRI DÜŞÜK TEKLİF SAVUNMA ROBOTU
A3: Karar Kapısı — Aşırı Düşük Teklif Durumu
A4: Sınır değer oranı, savunma gücü, mutabakat ve veri kalitesine göre üretilen karar.
A6: Sınır Değer (₺) | B6: =SdSinirDeger
A7: Kendi Teklif (₺) | B7: =KendiTeklifTutari
A8: Teklif / Sınır Değer Oranı | B8: =SdOran
A9: Veri Kalitesi Skoru | B9: =KaliteSkoru
A11: KARAR | B11: =IF(DoluGirisHucre=0,"VERİ YOK",IF(SdKontrol="AŞIRI DÜŞÜK",IF(SdSavunmaGucu="ZAYIF","DURDUR","İNCELE"),IF(OR(SdKontrol="SINIRDA",SdMutabakatDurumu="FARK VAR",KaliteSkoru<KaliteOrta),"İNCELE","UYGUN")))
A12: Gerekçe | B12: =_xlfn.TEXTJOIN(" | ",TRUE(),IF(SdKontrol="AŞIRI DÜŞÜK","Teklif sınır değerin altında; açıklama sunulması zorunlu","Teklif sınır değerin üzerinde"),IF(SdSavunmaGucu="ZAYIF","Savunma dayanak ağırlığı eşiğin altında","Savunma dayanak ağırlığı yeterli"),IF(SdMutabakatDurumu="FARK VAR","Bileşen toplamı ile teklif tutarı uyumsuz","Bileşen mutabakatı sağlandı"),IF(KaliteSkoru<KaliteOrta,"Veri kalitesi düşük; girişler tamamlanmalı","Veri kalitesi yeterli"))
A14: Önerilen Aksiyonlar
A15: Aksiyon 1 | B15: =IF(SdKontrol="AŞIRI DÜŞÜK","Rayiç eşiği altında kalan bileşenlere teyitli fatura/teklif dayanağı ekleyin; açıklama dosyasını idarenin belirlediği sürede sunun.","Sınır değer üzerindesiniz; açıklama yükümlülüğü yok, ancak rayiçleri periyodik teyit edin.")
A16: Aksiyon 2 | B16: =IF(SdMutabakatDurumu="FARK VAR","Bileşen toplamı ile teklif tutarını kalem kalem mutabakat edin; eksik kalem ekleyin veya indirim maddesini belgeleyin.","Bileşen mutabakatı sağlandı; kalem yapısını koruyun.")
A17: Aksiyon 3 | B17: =IF(KaliteSkoru<KaliteOrta,"Boş ve teyitsiz alanları doldurup dosyayı yeniden hesaplayın.","Veri kalitesi yeterli; teklif açıklama ekinizi güncel rayiçlerle güçlendirin.")
A19: Karar yalnızca giriş verisi ve AYARLAR'daki eşiklerden türetilir; kesin hukuki/finansal tavsiye değildir.

Sheet PANO
A1: PANO — AŞIRI DÜŞÜK TEKLİF SAVUNMA ROBOTU
A3: Yaklaşık Maliyet | B3: Sınır Değer | C3: Kendi Teklif | D3: Teklif/Sınır Değer | E3: Kalite Skoru | F3: Karar
A4: =YaklasikMaliyet | B4: =SdSinirDeger | C4: =KendiTeklifTutari | D4: =SdOran | E4: =KaliteSkoru | F4: =KararSonuc
A6: Karar Gerekçesi | B6: =KARAR!B12
A9: Rakip Teklifleri (₺) | B9: Teklif (₺) | D9: Sınır Değer Karşılaştırması | E9: Tutar (₺) | F9: Bileşen Tutar Dağılımı | G9: Tutar (₺) | H9: Rayiç Sapması (%) | I9: Sapma | J9: Endeks ve Hareketli Ortalama | K9: Endeks | L9: Tahmin | M9: Z Skorları | N9: Z | P9: Karar Destek Modülleri
A10: =IFERROR(INDEX(tblRakipler[Rakip Adı],ROW()-ROW($B$9)),"") | B10: =IFERROR(INDEX(tblRakipler[Teklif Tutarı (₺)],ROW()-ROW($B$9)),0) | D10: Sınır Değer | E10: =SdSinirDeger | F10: =IFERROR(INDEX(tblBilesenler[Kalem Adı],ROW()-ROW($B$9)),"") | G10: =IFERROR(INDEX(tblBilesenler[Tutar (₺)],ROW()-ROW($B$9)),0) | I10: =IFERROR(INDEX(tblBilesenler[Rayiç Sapması],ROW()-ROW($B$9)),0) | J10: =IFERROR(INDEX(tblProjeksiyon[Dönem],ROW()-ROW($B$9)),"") | K10: =IFERROR(INDEX(tblProjeksiyon[Endeks Değeri],ROW()-ROW($B$9)),0) | L10: =IFERROR(INDEX(tblProjeksiyon[3 Dönem Hareketli Ortalama],ROW()-ROW($B$9)),0) | N10: =IFERROR(INDEX(tblRakipler[Anomali Z],ROW()-ROW($B$9)),0) | P10: Anomali Teklif Sayısı | Q10: =modulO1AnomaliSayisi
A11: =IFERROR(INDEX(tblRakipler[Rakip Adı],ROW()-ROW($B$9)),"") | B11: =IFERROR(INDEX(tblRakipler[Teklif Tutarı (₺)],ROW()-ROW($B$9)),0) | D11: Kendi Teklif | E11: =KendiTeklifTutari | F11: =IFERROR(INDEX(tblBilesenler[Kalem Adı],ROW()-ROW($B$9)),"") | G11: =IFERROR(INDEX(tblBilesenler[Tutar (₺)],ROW()-ROW($B$9)),0) | I11: =IFERROR(INDEX(tblBilesenler[Rayiç Sapması],ROW()-ROW($B$9)),0) | J11: =IFERROR(INDEX(tblProjeksiyon[Dönem],ROW()-ROW($B$9)),"") | K11: =IFERROR(INDEX(tblProjeksiyon[Endeks Değeri],ROW()-ROW($B$9)),0) | L11: =IFERROR(INDEX(tblProjeksiyon[3 Dönem Hareketli Ortalama],ROW()-ROW($B$9)),0) | N11: =IFERROR(INDEX(tblRakipler[Anomali Z],ROW()-ROW($B$9)),0) | P11: Pareto: İlk 3 Kalem Payı | Q11: =modulT3ParetoPayi
A12: =IFERROR(INDEX(tblRakipler[Rakip Adı],ROW()-ROW($B$9)),"") | B12: =IFERROR(INDEX(tblRakipler[Teklif Tutarı (₺)],ROW()-ROW($B$9)),0) | F12: =IFERROR(INDEX(tblBilesenler[Kalem Adı],ROW()-ROW($B$9)),"") | G12: =IFERROR(INDEX(tblBilesenler[Tutar (₺)],ROW()-ROW($B$9)),0) | I12: =IFERROR(INDEX(tblBilesenler[Rayiç Sapması],ROW()-ROW($B$9)),0) | J12: =IFERROR(INDEX(tblProjeksiyon[Dönem],ROW()-ROW($B$9)),"") | K12: =IFERROR(INDEX(tblProjeksiyon[Endeks Değeri],ROW()-ROW($B$9)),0) | L12: =IFERROR(INDEX(tblProjeksiyon[3 Dönem Hareketli Ortalama],ROW()-ROW($B$9)),0) | N12: =IFERROR(INDEX(tblRakipler[Anomali Z],ROW()-ROW($B$9)),0) | P12: Kırılım Oranı (Bileşen/Teklif) | Q12: =modulT6KirilimOrani
A13: =IFERROR(INDEX(tblRakipler[Rakip Adı],ROW()-ROW($B$9)),"") | B13: =IFERROR(INDEX(tblRakipler[Teklif Tutarı (₺)],ROW()-ROW($B$9)),0) | F13: =IFERROR(INDEX(tblBilesenler[Kalem Adı],ROW()-ROW($B$9)),"") | G13: =IFERROR(INDEX(tblBilesenler[Tutar (₺)],ROW()-ROW($B$9)),0) | I13: =IFERROR(INDEX(tblBilesenler[Rayiç Sapması],ROW()-ROW($B$9)),0) | J13: =IFERROR(INDEX(tblProjeksiyon[Dönem],ROW()-ROW($B$9)),"") | K13: =IFERROR(INDEX(tblProjeksiyon[Endeks Değeri],ROW()-ROW($B$9)),0) | L13: =IFERROR(INDEX(tblProjeksiyon[3 Dönem Hareketli Ortalama],ROW()-ROW($B$9)),0) | N13: =IFERROR(INDEX(tblRakipler[Anomali Z],ROW()-ROW($B$9)),0) | P13: Veri Kalitesi Skoru | Q13: =KaliteSkoru
A14: =IFERROR(INDEX(tblRakipler[Rakip Adı],ROW()-ROW($B$9)),"") | B14: =IFERROR(INDEX(tblRakipler[Teklif Tutarı (₺)],ROW()-ROW($B$9)),0) | F14: =IFERROR(INDEX(tblBilesenler[Kalem Adı],ROW()-ROW($B$9)),"") | G14: =IFERROR(INDEX(tblBilesenler[Tutar (₺)],ROW()-ROW($B$9)),0) | I14: =IFERROR(INDEX(tblBilesenler[Rayiç Sapması],ROW()-ROW($B$9)),0) | J14: =IFERROR(INDEX(tblProjeksiyon[Dönem],ROW()-ROW($B$9)),"") | K14: =IFERROR(INDEX(tblProjeksiyon[Endeks Değeri],ROW()-ROW($B$9)),0) | L14: =IFERROR(INDEX(tblProjeksiyon[3 Dönem Hareketli Ortalama],ROW()-ROW($B$9)),0) | N14: =IFERROR(INDEX(tblRakipler[Anomali Z],ROW()-ROW($B$9)),0) | P14: Endeks Eğilimi | Q14: =modulT2EndeksEgim
A15: =IFERROR(INDEX(tblRakipler[Rakip Adı],ROW()-ROW($B$9)),"") | B15: =IFERROR(INDEX(tblRakipler[Teklif Tutarı (₺)],ROW()-ROW($B$9)),0) | F15: =IFERROR(INDEX(tblBilesenler[Kalem Adı],ROW()-ROW($B$9)),"") | G15: =IFERROR(INDEX(tblBilesenler[Tutar (₺)],ROW()-ROW($B$9)),0) | I15: =IFERROR(INDEX(tblBilesenler[Rayiç Sapması],ROW()-ROW($B$9)),0) | J15: =IFERROR(INDEX(tblProjeksiyon[Dönem],ROW()-ROW($B$9)),"") | K15: =IFERROR(INDEX(tblProjeksiyon[Endeks Değeri],ROW()-ROW($B$9)),0) | L15: =IFERROR(INDEX(tblProjeksiyon[3 Dönem Hareketli Ortalama],ROW()-ROW($B$9)),0) | N15: =IFERROR(INDEX(tblRakipler[Anomali Z],ROW()-ROW($B$9)),0) | P15: İleri Dönem Tahmini | Q15: =modulI1TahminOrta
A16: =IFERROR(INDEX(tblRakipler[Rakip Adı],ROW()-ROW($B$9)),"") | B16: =IFERROR(INDEX(tblRakipler[Teklif Tutarı (₺)],ROW()-ROW($B$9)),0) | F16: =IFERROR(INDEX(tblBilesenler[Kalem Adı],ROW()-ROW($B$9)),"") | G16: =IFERROR(INDEX(tblBilesenler[Tutar (₺)],ROW()-ROW($B$9)),0) | I16: =IFERROR(INDEX(tblBilesenler[Rayiç Sapması],ROW()-ROW($B$9)),0) | J16: =IFERROR(INDEX(tblProjeksiyon[Dönem],ROW()-ROW($B$9)),"") | K16: =IFERROR(INDEX(tblProjeksiyon[Endeks Değeri],ROW()-ROW($B$9)),0) | L16: =IFERROR(INDEX(tblProjeksiyon[3 Dönem Hareketli Ortalama],ROW()-ROW($B$9)),0) | N16: =IFERROR(INDEX(tblRakipler[Anomali Z],ROW()-ROW($B$9)),0) | P16: P90 Teklif (₺) | Q16: =modulI2P90
A17: =IFERROR(INDEX(tblRakipler[Rakip Adı],ROW()-ROW($B$9)),"") | B17: =IFERROR(INDEX(tblRakipler[Teklif Tutarı (₺)],ROW()-ROW($B$9)),0) | F17: =IFERROR(INDEX(tblBilesenler[Kalem Adı],ROW()-ROW($B$9)),"") | G17: =IFERROR(INDEX(tblBilesenler[Tutar (₺)],ROW()-ROW($B$9)),0) | I17: =IFERROR(INDEX(tblBilesenler[Rayiç Sapması],ROW()-ROW($B$9)),0) | J17: =IFERROR(INDEX(tblProjeksiyon[Dönem],ROW()-ROW($B$9)),"") | K17: =IFERROR(INDEX(tblProjeksiyon[Endeks Değeri],ROW()-ROW($B$9)),0) | L17: =IFERROR(INDEX(tblProjeksiyon[3 Dönem Hareketli Ortalama],ROW()-ROW($B$9)),0) | N17: =IFERROR(INDEX(tblRakipler[Anomali Z],ROW()-ROW($B$9)),0) | P17: Senaryo Baz Sınır Değer (₺) | Q17: =modulO3SenaryoBaz
A18: =IFERROR(INDEX(tblRakipler[Rakip Adı],ROW()-ROW($B$9)),"") | B18: =IFERROR(INDEX(tblRakipler[Teklif Tutarı (₺)],ROW()-ROW($B$9)),0) | J18: =IFERROR(INDEX(tblProjeksiyon[Dönem],ROW()-ROW($B$9)),"") | K18: =IFERROR(INDEX(tblProjeksiyon[Endeks Değeri],ROW()-ROW($B$9)),0) | L18: =IFERROR(INDEX(tblProjeksiyon[3 Dönem Hareketli Ortalama],ROW()-ROW($B$9)),0) | P18: Tornado Zirve Değişken | Q18: =modulO2TornadoZirve
A19: =IFERROR(INDEX(tblRakipler[Rakip Adı],ROW()-ROW($B$9)),"") | B19: =IFERROR(INDEX(tblRakipler[Teklif Tutarı (₺)],ROW()-ROW($B$9)),0) | J19: =IFERROR(INDEX(tblProjeksiyon[Dönem],ROW()-ROW($B$9)),"") | K19: =IFERROR(INDEX(tblProjeksiyon[Endeks Değeri],ROW()-ROW($B$9)),0) | L19: =IFERROR(INDEX(tblProjeksiyon[3 Dönem Hareketli Ortalama],ROW()-ROW($B$9)),0) | P19: Aşırı Düşük Bölge Sayısı | Q19: =SUMPRODUCT((tblRakipler[Durum]="AŞIRI DÜŞÜK")*1)
A20: =IFERROR(INDEX(tblRakipler[Rakip Adı],ROW()-ROW($B$9)),"") | B20: =IFERROR(INDEX(tblRakipler[Teklif Tutarı (₺)],ROW()-ROW($B$9)),0) | J20: =IFERROR(INDEX(tblProjeksiyon[Dönem],ROW()-ROW($B$9)),"") | K20: =IFERROR(INDEX(tblProjeksiyon[Endeks Değeri],ROW()-ROW($B$9)),0) | L20: =IFERROR(INDEX(tblProjeksiyon[3 Dönem Hareketli Ortalama],ROW()-ROW($B$9)),0)
A21: =IFERROR(INDEX(tblRakipler[Rakip Adı],ROW()-ROW($B$9)),"") | B21: =IFERROR(INDEX(tblRakipler[Teklif Tutarı (₺)],ROW()-ROW($B$9)),0) | J21: =IFERROR(INDEX(tblProjeksiyon[Dönem],ROW()-ROW($B$9)),"") | K21: =IFERROR(INDEX(tblProjeksiyon[Endeks Değeri],ROW()-ROW($B$9)),0) | L21: =IFERROR(INDEX(tblProjeksiyon[3 Dönem Hareketli Ortalama],ROW()-ROW($B$9)),0)
A60: Paneldeki tüm göstergeler canlı formüllerden beslenir; elle yazılmaz.

Sheet SENARYO_DUYARLILIK
A1: SENARYO DUYARLILIK — AŞIRI DÜŞÜK TEKLİF SAVUNMA ROBOTU
A3: Senaryo ve Duyarlılık Analizi
A4: İyimser, baz ve kötümser senaryolarda sınır değer ve bölge; ardından hangi değişkenin sonucu en çok etkilediğini gösteren tornado analizi.
A6: Senaryo | B6: Senaryo Sınır Değer (₺) | C6: Senaryo Oranı | D6: Karar
A7: İYİMSER | B7: =SdYontemTaban*(SinirDegerKatsayisi*IyiN) | C7: =IF(B7=0,0,(KendiTeklifTutari*IyiTeklif)/B7) | D7: =IF(C7<AsiriDusukEsik,"AŞIRI DÜŞÜK",IF(C7<DikkatEsik,"SINIRDA","GÜVENLİ"))
A8: BAZ | B8: =SdYontemTaban*(SinirDegerKatsayisi*BazN) | C8: =IF(B8=0,0,(KendiTeklifTutari*BazTeklif)/B8) | D8: =IF(C8<AsiriDusukEsik,"AŞIRI DÜŞÜK",IF(C8<DikkatEsik,"SINIRDA","GÜVENLİ"))
A9: KÖTÜMSER | B9: =SdYontemTaban*(SinirDegerKatsayisi*KotuN) | C9: =IF(B9=0,0,(KendiTeklifTutari*KotuTeklif)/B9) | D9: =IF(C9<AsiriDusukEsik,"AŞIRI DÜŞÜK",IF(C9<DikkatEsik,"SINIRDA","GÜVENLİ"))
A11: Tornado: Sınır Değer ve Orana Etki
A12: Değişken | B12: +%10 Etkisi | C12: -%10 Etkisi | D12: Mutlak Etki
A13: N Katsayısı | B13: =IFERROR(ABS((SinirDegerKatsayisi*(1+TornadoN))*SdYontemTaban-SdSinirDeger),0) | C13: =IFERROR(ABS((SinirDegerKatsayisi*(1-TornadoN))*SdYontemTaban-SdSinirDeger),0) | D13: =MAX(B13,C13)
A14: Kendi Teklif Etkisi | B14: =IFERROR(ABS((KendiTeklifTutari*(1+TornadoTeklif))/SdSinirDeger-SdOran),0) | C14: =IFERROR(ABS((KendiTeklifTutari*(1-TornadoTeklif))/SdSinirDeger-SdOran),0) | D14: =MAX(B14,C14)
A15: Rakip Ortalaması | B15: =IFERROR(ABS(SinirDegerKatsayisi*(SdYontemTaban*(1+TornadoRakip))-SdSinirDeger),0) | C15: =IFERROR(ABS(SinirDegerKatsayisi*(SdYontemTaban*(1-TornadoRakip))-SdSinirDeger),0) | D15: =MAX(B15,C15)
A16: Rayiç Fiyatlar | B16: =IFERROR(ABS(SdBilesenRayicToplam*(1+TornadoRayic)-SdBilesenRayicToplam),0) | C16: =IFERROR(ABS(SdBilesenRayicToplam*(1-TornadoRayic)-SdBilesenRayicToplam),0) | D16: =MAX(B16,C16)
A18: En Etkili Değişken | B18: =INDEX({"N Katsayısı","Kendi Teklif Etkisi","Rakip Ortalaması","Rayiç Fiyatlar"},MATCH(MAX(D13:D16),D13:D16,0))
A20: Senaryo ve tornado etkileri AYARLAR'daki çarpanlardan türetilir.

Sheet RAPOR
A1: AŞIRI DÜŞÜK TEKLİF SAVUNMA ROBOTU — YÖNETİCİ ÖZETİ
A2: =_xlfn.CONCAT("Rapor Tarihi: ",TEXT(RaporTarihi,"dd.mm.yyyy")," | Hazırlayan: ",RaporHazirlayan," | Sürüm: ",DosyaSurumu)
A4: Karar | B4: =KararSonuc | D4: Gerekçe | E4: =KARAR!B12
A6: Yaklaşık Maliyet (₺) | B6: =YaklasikMaliyet
A7: Sınır Değer (₺) | B7: =SdSinirDeger
A8: Kendi Teklif (₺) | B8: =KendiTeklifTutari
A9: Teklif / Sınır Değer Oranı | B9: =SdOran
A10: Güvenlik Payı | B10: =SdGuvenlikPayi
A11: Bileşen Toplam Tutarı (₺) | B11: =SdBilesenToplam
A12: Mutabakat Durumu | B12: =SdMutabakatDurumu
A13: Savunma Gücü | B13: =SdSavunmaGucu
A14: Veri Kalitesi Skoru | B14: =KaliteSkoru
A15: Tahmini Fiyat Farkı Etkisi (%) | B15: =SdFiyatFarkiEtki
A16: En Etkili Değişken | B16: =SENARYO_DUYARLILIK!B18
A18: Varsayımlar ve Önemli Notlar
A19: • Sınır değer katsayısı (N) ve yöntem bilgisi idari şartnameden alınmalı; Varsayım kaynaklı değerler AYARLAR'da işaretlidir.
A20: • Aşırı düşük tespiti 4734 sayılı Kanun md.38 ve YİUY esaslarına göre modelin yaptığı bir ön değerlendirmedir; idare kararı bağlayıcıdır.
A21: • Rayiç değerler açıklama tarihi itibarıyla güncellenmelidir; teyitsiz rayiç savunmanın kabulünü zayıflatır.
A22: • Demo veriler gerçek ihale verisi değildir; kullanımdan önce temizlenmelidir.
A23: • Bu dosya karar destek aracıdır; ihale hukuku ve mali danışmanlık görüşünün yerine geçmez.
A25: Önerilen Aksiyonlar
A26: =KARAR!B15
A27: =KARAR!B16
A28: =KARAR!B17
A30: Bu rapor karar destek amaçlıdır; kesin ihale/mali tavsiye niteliği taşımaz.

Sheet ORNEK_VERI
A1: ORNEK VERI — AŞIRI DÜŞÜK TEKLİF SAVUNMA ROBOTU
A3: Örnek Veri (Demo)
A4: Gerçek ihaleye başlamadan önce demo veri ile ürünü deneyin. Bu satırlar örnektir; gerçek verilerle değiştirin.
A5: Tür | B5: Kalem veya Rakip | C5: Tutar (₺) | D5: Rayiç (₺) | E5: Not
A6: Rakip | B6: Yapı A A.Ş. | C6: 11900000 | E6: Örnek teklif
A7: Rakip | B7: İnşaat B Ltd. | C7: 12300000 | E7: Örnek teklif
A8: Rakip | B8: C Yapım | C8: 10600000 | E8: Örnek teklif
A9: Bileşen | B9: Beton C30 | C9: 3150000 | D9: 2925000 | E9: Örnek kalem
A10: Bileşen | B10: Demir Donatı | C10: 6726000 | D10: 6490000 | E10: Örnek kalem
A11: Bileşen | B11: Kalıp İşçiliği | C11: 609000 | D11: 579600 | E11: Örnek kalem
A1006: Demo veriler rapor sonuçlarını örnekler; satın alma sonrası silinerek gerçek veriler girilir.

Sheet KURALLAR
A1: KURALLAR — eski35_asiri-dusuk-teklif-savunma-robotu_uretildi
A3: kural_id | B3: aciklama | C3: deger_2025 | D3: deger_2026 | E3: deger_2027 | F3: kaynak
A4: K1 | B4: Kurumlar vergisi oranı | C4: 0.25 | D4: 0.25 | E4: 0.25 | F4: KV
A5: K2 | B5: İskonto / referans oran | C5: 0.2 | D5: 0.2 | E5: 0.2 | F5: AYARLAR

Sheet VAKALAR
A1: VAKALAR — eski35_asiri-dusuk-teklif-savunma-robotu_uretildi
A3: Tebliğ tarzı altın vakalar
A5: vaka_id | B5: aciklama | C5: girdi_ozeti | D5: beklenen_sonuc | E5: hesaplanan | F5: fark | G5: durum | H5: kaynak
A6: V1 | B6: Baz senaryo tutarlılık | C6: örnek girdi | D6: 0 | E6: 0 | F6: 0 | G6: TUTARLI | H6: iç test

Sheet DEGISIKLIK_KAYDI
A1: DEGISIKLIK KAYDI — AŞIRI DÜŞÜK TEKLİF SAVUNMA ROBOTU
A3: Değişiklik Kaydı
A4: Tarih | B4: Sürüm | C4: Değişiklik | D4: Neden | E4: Yapan
A5: 08.08.2026 | B5: 1.0.0 | C5: İlk üretim | D5: Ürünün yayına hazırlanması | E5: ExcelArşiv
A8: Sürüm ve lisans bilgisi KAPAK ve AYARLAR sayfalarında da bulunur.

Sheet LISTELER
A1: LISTELER — AŞIRI DÜŞÜK TEKLİF SAVUNMA ROBOTU
A3: Bağlı Listeler
A4: Bu sayfadaki listeler açılır menüleri besler; yeni seçenek eklemek için sarı hücrelere yazın.
A5: Sınır Değer Yöntemi | C5: Birim | E5: Dayanak Türü | G5: Evet/Hayır | I5: Kalite Seviyesi
A6: Ortalamanın Altındakilerin Ortalaması | C6: Adet | E6: Fatura | G6: EVET | I6: YÜKSEK
A7: Tüm Geçerli Tekliflerin Ortalaması | C7: kg | E7: Teklif | G7: HAYIR | I7: ORTA
C8: ton | E8: Rayiç | I8: DÜŞÜK
C9: m³ | E9: Analiz
C10: m² | E10: Yönetmelik
C11: m
C12: sayaç
C13: Takım
C14: Lot
C15: işçilik

Sheet AYARLAR
A1: AYARLAR — AŞIRI DÜŞÜK TEKLİF SAVUNMA ROBOTU
A3: Sistem Ayarları ve Eşikler
A4: Tüm katsayı ve eşikler bu sayfadadır. Mevzuat değişikliklerinde AYARLAR'dan güncellenir; formüller değişmez. Kaynak sütunu hangi değerin varsayım olduğunu gösterir.
A6: Ayar Adı | B6: Anahtar | C6: Değer | D6: Birim | E6: Açıklama | F6: kaynak | G6: yururluk_tarihi | H6: dogrulama_tarihi
A7: Firma Ünvanı | B7: FirmaUnvan | C7: Örnek Yapı A.Ş. | D7: metin | E7: Rapor kimliği; ticari unvan. | F7: Kullanıcı | G7: 09.08.2026 | H7: 09.08.2026
A8: Rapor Tarihi | B8: RaporTarihi | C8: 46242 | D8: tarih | E8: Kararın tarihlendirildiği gün. | F8: Kullanıcı | G8: 09.08.2026 | H8: 09.08.2026
A9: Raporu Hazırlayan | B9: RaporHazirlayan | C9: Teklif Direktörü | D9: metin | E9: Raporu düzenleyen sorumlu. | F9: Kullanıcı | G9: 09.08.2026 | H9: 09.08.2026
A10: Dosya Sürümü | B10: DosyaSurumu | C10: 1.0.0 | D10: metin | E10: Sürüm tanımlayıcı. | F10: Sabit | G10: 09.08.2026 | H10: 09.08.2026
A11: Aşırı Düşük Eşiği (Oran) | B11: AsiriDusukEsik | C11: 1 | D11: oran | E11: Teklif/sınır değer oranı bu değerin altındaysa aşırı düşük sayılır; açıklama istenir. | F11: 4734 s. KİK md.38; YİUY md.61-62 | G11: 01.01.2003 | H11: 01.01.2003
A12: Dikkat Eşiği (Oran) | B12: DikkatEsik | C12: 1.05 | D12: oran | E12: Güvenlik payı; %5 altı SINIRDA bölgesi. | F12: Varsayım | G12: 09.08.2026 | H12: 09.08.2026
A13: Anomali Z Eşiği | B13: AnomaliZEsik | C13: 2 | D13: adet | E13: Teklif Z skoru bu değeri aşarsa anomali bayrağı. | F13: Varsayım | G13: 09.08.2026 | H13: 09.08.2026
A14: Rayiç Sapma Eşiği (%) | B14: RayicSapmaEsik | C14: 0.2 | D14: oran | E14: Birim fiyatın rayiçten %20'den fazla sapması riskli kabul edilir. | F14: Varsayım | G14: 09.08.2026 | H14: 09.08.2026
A15: Dayanak Ağırlığı Eşiği (%) | B15: DayanakEsik | C15: 0.8 | D15: oran | E15: Açıklanan bileşen ağırlığı %80 altında ise savunma ZAYIF. | F15: Varsayım | G15: 09.08.2026 | H15: 09.08.2026
A16: Kabul Edilebilir Mutabakat Farkı (₺) | B16: KabulEdilebilirFark | C16: 25000 | D16: ₺ | E16: Bileşen toplamı ile teklif tutarı arasındaki kabul edilebilir fark. | F16: Varsayım | G16: 09.08.2026 | H16: 09.08.2026
A17: İyimser Senaryo N Çarpanı | B17: IyiN | C17: 1 | D17: oran | E17: İyimser senaryoda N katsayı çarpanı. | F17: Varsayım | G17: 09.08.2026 | H17: 09.08.2026
A18: İyimser Senaryo Teklif Çarpanı | B18: IyiTeklif | C18: 0.9 | D18: oran | E18: İyimser senaryoda teklif çarpanı. | F18: Varsayım | G18: 09.08.2026 | H18: 09.08.2026
A19: Baz Senaryo N Çarpanı | B19: BazN | C19: 1 | D19: oran | E19: Baz senaryoda N katsayı çarpanı. | F19: Varsayım | G19: 09.08.2026 | H19: 09.08.2026
A20: Baz Senaryo Teklif Çarpanı | B20: BazTeklif | C20: 1 | D20: oran | E20: Baz senaryoda teklif çarpanı. | F20: Varsayım | G20: 09.08.2026 | H20: 09.08.2026
A21: Kötümser Senaryo N Çarpanı | B21: KotuN | C21: 1 | D21: oran | E21: Kötümser senaryoda N katsayı çarpanı. | F21: Varsayım | G21: 09.08.2026 | H21: 09.08.2026
A22: Kötümser Senaryo Teklif Çarpanı | B22: KotuTeklif | C22: 1.15 | D22: oran | E22: Kötümser senaryoda teklif çarpanı. | F22: Varsayım | G22: 09.08.2026 | H22: 09.08.2026
... A34: Değer Ölçer: Yıllık Hata Azalması (%) | B34: DegerOlcerHata | C34: 0.2 | D34: oran | E34: Yıllık hata azalma oranı. | F34: Varsayım | G34: 09.08.2026 | H34: 09.08.2026

Sheet KILAVUZ
A1: KILAVUZ — AŞIRI DÜŞÜK TEKLİF SAVUNMA ROBOTU
A3: Kullanım Kılavuzu
A4: 1. Genel Bakış
A5: 2. İlk Kurulum
A6: 3. İhale Bilgisi
A7: 4. Rakip Teklifleri
A8: 5. Teklif Bileşenleri
A9: 6. Fiyat Farkı
A10: 7. Karar ve Aksiyon
A11: 8. Koruma
A12: 9. Yasal Çekince
A13: Bu araç karar destek amaçlıdır; mali müşavir/hukuk danışmanı görüşünün yerine geçmez.
A26: Destek: ExcelArşiv — mevzuat değişikliklerinde sürüm güncellemeleri satın alma döneminden itibaren 12 ay ücretsizdir.
