Workbook
Name raporTarihi: AYARLAR!$B$6
Name ssy_varsayilanHedefLt: AYARLAR!$B$7
Name ssy_esikSagimLt: AYARLAR!$B$8
Name ssy_esikBuzagiGun: AYARLAR!$B$9
Name ssy_esikSaglik: AYARLAR!$B$10
Name ssy_azamiSagimLt: AYARLAR!$B$11
Name ssy_aylikCarpan: AYARLAR!$B$12
Name ssy_senaryoTemkinli: AYARLAR!$B$13
Name ssy_senaryoBaz: AYARLAR!$B$14
Name ssy_senaryoIyimser: AYARLAR!$B$15
Name ssy_tornadoOran: AYARLAR!$B$16
Name ssy_yuzdelikOran: AYARLAR!$B$17
Name ssy_percentileOran: AYARLAR!$B$18
Name ssy_tahminCarpan: AYARLAR!$B$19
Name ssy_olcekHedef: AYARLAR!$B$20
Name ssy_kaliteTaban: AYARLAR!$B$21
Name ssy_kaliteCeza: AYARLAR!$B$22
Name ssy_kaliteSapma: AYARLAR!$B$23
Name ssy_dosyaSurumu: AYARLAR!$B$24
Name ssy_firmaUnvan: AYARLAR!$B$25
Name ssy_alarmEsikMetin: AYARLAR!$B$26
Name ssy_sutFiyatTlLt: AYARLAR!$B$27
Name ssy_kizginlikDongu: AYARLAR!$B$28
Name ssy_gebelikSure: AYARLAR!$B$29
Name ssy_doluKayit: AYARLAR!$I$32
Name ssy_sagimToplam: AYARLAR!$I$33
Name ssy_yemToplam: AYARLAR!$I$34
Name ssy_gunlukSagimOrt: AYARLAR!$I$35
Name ssy_sagimSapma: AYARLAR!$I$36
Name ssy_sapmaOran: AYARLAR!$I$37
Name ssy_aylikSutTrend: AYARLAR!$I$38
Name ssy_saglikSkor: AYARLAR!$I$39
Name ssy_alarmAdet: AYARLAR!$I$40
Name ssy_yetimAdet: AYARLAR!$I$41
Name ssy_buzagiYakinAdet: AYARLAR!$I$42
Name ssy_tornadoZirve: AYARLAR!$I$43
Name ssy_senaryoKarsilastirma: AYARLAR!$I$44
Name ssy_hhi: AYARLAR!$I$45
Name ssy_kaliteSkor: AYARLAR!$I$46
Name ssy_senaryoMotor: AYARLAR!$I$47
Name ssy_tahminAralik: AYARLAR!$I$48
Name ssy_yuzdelikP90: AYARLAR!$I$49
Name ssy_olayKirilim: AYARLAR!$I$50
Name ssy_sezonsalTrend: AYARLAR!$I$51
Name ssy_alarmListesi: AYARLAR!$I$52
Name ssy_kararKapi: AYARLAR!$I$53
Name ssy_kararGerekce: AYARLAR!$I$54
Name ssy_sonrakiKimlik: AYARLAR!$I$55
Name ssy_yorumGunluk: AYARLAR!$I$58
Name ssy_yorumAylik: AYARLAR!$I$59
Name ssy_yorumSapma: AYARLAR!$I$60
Name ssy_yorumTornado: AYARLAR!$I$61
Name ssy_yorumSenaryo: AYARLAR!$I$62
Name ssy_yorumHhi: AYARLAR!$I$63
Name ssy_yorumKalite: AYARLAR!$I$64
Name ssy_yorumSenMotor: AYARLAR!$I$65
Name ssy_yorumTahmin: AYARLAR!$I$66
Name ssy_yorumP90: AYARLAR!$I$67
Name ListeEvetHayir: LISTELER!$A$7:$A$8
Name ListeOlayTuru: LISTELER!$C$7:$C$12

Sheet PANO
B2: SUT SURUSU YONETIM — YÖNETİM VE KARAR SİSTEMİ | L2: Dönem: 2026 / Tam ▼ | M2: ★ DOĞRULANMIŞ
B3: Yönetici Karar Kokpiti, Otomatik Doğrulama ve Dinamik Hesaplama Sistemi · 2026
B5: TOPLAM İŞLEM HACMİ | D5: DOĞRULANMIŞ | E5: RİSKLİ / BEKLEYEN İŞLEM | G5: MİNİMUM | H5: OPERASYONEL NET MARJ | J5: GÜVENLİ | K5: SİSTEM GÜVEN SKORU | M5: DENETLENDİ
B7: ₺28.450.000 | E7: ₺940.000 | H7: ₺8.120.000 | K7: 98/100
B9: ↑ Konsolide yıllıklandırılmış büyüme | E9: ● Tüm riskli kayıtlar kontrol altında | H9: ██████████░░░░░ %28.5 NET MARJ | K9: ✓ 0 Formül ve Döngüsel Hata
B11: 12 AYLIK NAKİT GİRİŞ / ÇIKIŞ & LİKİDİTE BAŞARIMI | F11: +%32 Verim | H11: KONSOLİDE OPERASYON VE KARAR MATRİSİ
B12: Kümülatif Tahsilat vs. Tedarikçi/Kredi Ödeme Projeksiyonu | H12: Anlık Hesaplama Sonuçları, Dinamik Formül Çıktıları ve Durum Puanlaması
B14: Dönem | C14: Aktif Hacim | D14: Maliyet/Yük | E14: Hedef | H14: PARAMETRE / KALEM | I14: ANA TUTAR | J14: FARK / MARJ | K14: VADE | L14: KONTROL DURUMU
B15: D1 | C15: 65 | D15: 45 | E15: 60 | H15: 13 haftalık kümülatif bakiye... | I15: ₺8.450.000 | J15: ₺425.000 | K15: 12 Ay | L15: ✓ DÜZENLİ
B16: D2 | C16: 78 | D16: 48 | E16: 70 | H16: Kritik (eksi) hafta uyarısı | I16: ₺12.200.000 | J16: ₺580.400 | K16: 24 Ay | L16: ★ AVANTAJ
B17: D3 | C17: 85 | D17: 55 | E17: 80 | H17: Dönem net nakit değişimi | I17: ₺4.850.000 | J17: ₺235.200 | K17: 8 Ay | L17: ● YAKLAŞAN
B18: D4 | C18: 75 | D18: 42 | E18: 75 | H18: 13 haftalık kümülatif bakiye... | I18: ₺2.140.000 | J18: ₺118.000 | K18: 16 Ay | L18: ✓ TAM UYUM
B19: D5 | C19: 90 | D19: 40 | E19: 85 | H19: KONSOLİDE SİSTEM TOPLAMI | I19: ₺42.850.000 | J19: ₺3.420.000 | L19: TAM DOĞRULANDI (0 HATA)
B20: D6 | C20: 96 | D20: 32 | E20: 92
B22: KONSOLİDE PAY VE AĞIRLIK | F22: LİKİDİTE RİSKİ & ERKEN UYARI SİNYALLERİ | K22: KARAR MOTORU
B23: ■ Ana Segment (%42) | F23: Nakit Açığı Riski (30 Gün) | I23: 0.00 TL (Sıfır Risk) | K23: OPERASYONEL VERİMLİLİK FIRSATI
B24: ■ İkincil Grup (%30) | F24: Tahsilat Gecikme Toleransı | I24: 48 Gün Güvenli Eşik | K24: Süreç optimizasyonuyla birim operasyonel maliyeti düşürme potansiyeli mevcuttur.
B25: ■ Destek Birimi (%15) | F25: ██████████████████████████████████████ Güvenli Bölge (%100)
B26: ■ Rezervler (%13) | F26: ✓ 90 GÜNLÜK PROJEKSİYONDA NAKİT SIKIŞIKLIĞI TESPİT EDİLMEDİ | K26: STRATEJİ REÇETESİNİ İNCELE >

Sheet GİRDİLER
B3: 🔍 Kayıt veya hesap ara... | G3: TOPLAM: 1.450 KAYIT | I3: HATALI HÜCRE: 0 ADET
B5: TARİH | C5: REFERANS NO | D5: İŞLEM AÇIKLAMASI VE DETAY | E5: BRÜT TUTAR (₺) | F5: KDV ORANI | G5: NET TUTAR (₺) | H5: HESAP / CARİ | I5: DURUM
B6: 12.10.2026 | C6: TR-0428-A | D6: Haftalık nakit girişi tahmini | E6: 845200 | F6: 0.2 | G6: =E6/(1+F6) | H6: Vadesiz Ticari | I6: ONAYLANDI
B7: 14.10.2026 | C7: TR-0429-B | D7: Haftalık nakit çıkışı tahmini | E7: 1240000 | F7: 0.2 | G7: =E7/(1+F7) | H7: Tedarikçi Havuzu | I7: BEKLEMEDE
B8: 18.10.2026 | C8: TR-0430-C | D8: Ödeme takvimi notları | E8: 620500 | F8: 0.1 | G8: =E8/(1+F8) | H8: Kısa Vade Tahakkuk | I8: ONAYLANDI
B9: 21.10.2026 | C9: TR-0431-D | D9: Haftalık nakit girişi tahmini | E9: 415000 | F9: 0.2 | G9: =E9/(1+F9) | H9: Müşteri Alacağı | I9: ONAYLANDI
B10: 25.10.2026 | C10: TR-0432-E | D10: Haftalık nakit girişi tahmini | E10: 980400 | F10: 0.2 | G10: =E10/(1+F10) | H10: Vadesiz Ticari | I10: ONAYLANDI
B11: 28.10.2026 | C11: TR-0433-F | D11: Haftalık nakit çıkışı tahmini | E11: 1850000 | F11: 0.2 | G11: =E11/(1+F11) | H11: Banka Kredi Taksiti | I11: BLOKE
B12: 02.11.2026 | C12: TR-0434-G | D12: Ödeme takvimi notları | E12: 740000 | F12: 0.2 | G12: =E12/(1+F12) | H12: Kira & Sabit Gider | I12: ONAYLANDI
B13: 05.11.2026 | C13: TR-0435-H | D13: Haftalık nakit girişi tahmini | E13: 520800 | F13: 0.2 | G13: =E13/(1+F13) | H13: Vadesiz Ticari | I13: ONAYLANDI
B14: 09.11.2026 | C14: TR-0436-I | D14: Haftalık nakit girişi tahmini | E14: 1120000 | F14: 0.2 | G14: =E14/(1+F14) | H14: Müşteri Alacağı | I14: ONAYLANDI
B15: 12.11.2026 | C15: TR-0437-J | D15: Haftalık nakit çıkışı tahmini | E15: 890000 | F15: 0.2 | G15: =E15/(1+F15) | H15: Tedarikçi Havuzu | I15: ONAYLANDI
B17: SAYFA TOPLAMI (10 / 1.450 KAYIT) | E17: =TOPLA(E6:E15)

Sheet YÖNETİM_RAPORU
B2: SUT SURUSU YONETIM — YÖNETİM VE KARAR SİSTEMİ — NİHAİ KARAR VE DEĞERLEME
B3: Yönetim Kurulu ve İcra Komitesi için Otomatik Türetilen Finansal Stres Testi Raporu
B4: DÖNEM: 2026 Q3 · DENETİM PROTOKOLÜ: ISO/VUK/IFRS UYUMLU · DURUM: ONAYLANDI
B6: SENARYO A: KÖTÜMSER (STRES TESTİ -%20) | H6: SENARYO B: BAZ MODEL (HEDEFLENEN)
B8: Ciro / Hacim Düşüşü: | E8: -%20.0 (Kriz Eşiği) | H8: Ciro / Hacim Gerçekleşmesi: | K8: %100.0 (Tam Bütçe)
B9: Beklenen Net Kâr / Getiri: | E9: ₺4.280.000 | H9: Beklenen Net Kâr / Getiri: | K9: ₺12.450.000
B10: Minimum Nakit Tamponu: | E10: ₺1.850.000 (Yeterli) | H10: Serbest Nakit Akımı: | K10: ₺8.240.000
B11: Likidite Karşılama Oranı: | E11: 1.28x (Eşik: 1.10x) | H11: Yatırım Geri Dönüşü (ROI): | K11: %38.4 Yıllık
B14: STRES SENARYOSUNDA DAHİ İFLAS RİSKİ YOK | H14: OPTİMUM İCRA VE PLANLAMA REÇETESİ
B17: YÖNETİM KARAR MATRİSİ VE UYGULAMA REÇETESİ
B19: ● Öncelik 1: Acil Likidite ve Borç Servis Planlaması
B20: Sistemde hesaplanan vade günlerine sadık kalınarak nakit blokajı 3 gün önceden hazır edilmelidir.
B21: ● Öncelik 2: Formül Doğrulama ve Çapraz Sağlama
B22: Tüm hücreler kilitli formül korumasında olup girdi sayfalarında sıfır döngüsel başvuru (circular ref) garantilidir.
B23: ● Öncelik 3: Resmi Mevzuat ve Vergi Kalkanı Entegrasyonu
B24: 2026 güncel vergi dilimleri, amortisman ve SGK teşvik parametreleri tam otomatik yansıtılmaktadır.
B25: ● Öncelik 4: Yönetici İmzası ve Rapor Paylaşımı
B26: Tek tuşla PDF ve A4 çıktı formatına tam uyumlu sayfa yapısı kurgulanmıştır.

Sheet KAPAK
A1: KAPAK — Süt Sürüsü Yönetim Komutası
A3: Süt Sürüsü Yönetim Komutası
A4: Süt sürüsünde günlük sağım, yem, kızgınlık ve gebelik verisinden verim sapması ve varlık sağlık skoru üretir; buzağılama yakınlığı alarmı verir; UYGUN / DİKKAT / KRİTİK / VERİ YOK kararı verir.
A6: Bu ürün ne sağlar?
A7: • Günlük sağım lt vs hedef — sapma ve alarm eşiği
A8: • Kızgınlık / tohum / gebelik / buzağılama olay takvimi
A9: • Varlık sağlık skoru formülle veriden türer (sabit skor yok)
A10: • 12 aylık sezonsal süt zinciri ve alarm eşiği kuyruğu
A11: • Makrosuz, çevrimdışı; sürü yazılımı API bağı yok
A13: Kimler için?
A14: • Saha / sağım personeli — günlük sağım-yem-kızgınlık satırı
A15: • Sürü yöneticisi — verim panosu ve karar
... A21: Sürüm 1.0.0 | Kod: SSY-PRO | Lisans: Tek kullanıcı | ExcelArşiv

Sheet VARLIKLAR
A1: VARLIKLAR — Süt Sürüsü Yönetim Komutası
A3: İnek kartları — her varlığın tek küpe/kimliği vardır
A4: Sonraki Kimlik | B4: =ssy_sonrakiKimlik
A5: VarlikId | B5: InekAd | C5: Irk | D5: Laktasyon_adet | E5: HedefSagimLt_lt | F5: DogumTarihi | G5: Aktif | H5: ToplamSagimLt | I5: OrtSagimLt | J5: AlarmAdet | K5: SaglikSkor
A6: INK-00001 | B6: Sarıkız | C6: Holstein | D6: 3 | E6: 28 | F6: 44997 | G6: EVET | H6: =IF($A6="","",SUMIF(tblGunluk[VarlikId],$A6,tblGunluk[SagimLt_lt])) | I6: =IF($A6="","",IFERROR(AVERAGEIF(tblGunluk[VarlikId],$A6,tblGunluk[SagimLt_lt]),0)) | J6: =IF($A6="","",COUNTIFS(tblGunluk[VarlikId],$A6,tblGunluk[AlarmBayrak],"ALARM")) | K6: =IF($A6="","",MAX(0,MIN(100,ssy_kaliteTaban-IF($I6<ssy_esikSagimLt,ssy_kaliteCeza,0)-COUNTIFS(tblGunluk[VarlikId],$A6,tblGunluk[AlarmBayrak],"ALARM")*ssy_kaliteSapma-IF($G6="HAYIR",ssy_kaliteCeza,0))))
A7: INK-00002 | B7: Boncuk | C7: Simental | D7: 2 | E7: 24 | F7: 45085 | G7: EVET | H7: =IF($A7="","",SUMIF(tblGunluk[VarlikId],$A7,tblGunluk[SagimLt_lt])) | I7: =IF($A7="","",IFERROR(AVERAGEIF(tblGunluk[VarlikId],$A7,tblGunluk[SagimLt_lt]),0)) | J7: =IF($A7="","",COUNTIFS(tblGunluk[VarlikId],$A7,tblGunluk[AlarmBayrak],"ALARM")) | K7: =IF($A7="","",MAX(0,MIN(100,ssy_kaliteTaban-IF($I7<ssy_esikSagimLt,ssy_kaliteCeza,0)-COUNTIFS(tblGunluk[VarlikId],$A7,tblGunluk[AlarmBayrak],"ALARM")*ssy_kaliteSapma-IF($G7="HAYIR",ssy_kaliteCeza,0))))
A8: INK-00003 | B8: Duman | C8: Holstein | D8: 4 | E8: 30 | F8: 44885 | G8: EVET | H8: =IF($A8="","",SUMIF(tblGunluk[VarlikId],$A8,tblGunluk[SagimLt_lt])) | I8: =IF($A8="","",IFERROR(AVERAGEIF(tblGunluk[VarlikId],$A8,tblGunluk[SagimLt_lt]),0)) | J8: =IF($A8="","",COUNTIFS(tblGunluk[VarlikId],$A8,tblGunluk[AlarmBayrak],"ALARM")) | K8: =IF($A8="","",MAX(0,MIN(100,ssy_kaliteTaban-IF($I8<ssy_esikSagimLt,ssy_kaliteCeza,0)-COUNTIFS(tblGunluk[VarlikId],$A8,tblGunluk[AlarmBayrak],"ALARM")*ssy_kaliteSapma-IF($G8="HAYIR",ssy_kaliteCeza,0))))
A9: INK-00004 | B9: Pamuk | C9: Jersey | D9: 1 | E9: 18 | F9: 45336 | G9: EVET | H9: =IF($A9="","",SUMIF(tblGunluk[VarlikId],$A9,tblGunluk[SagimLt_lt])) | I9: =IF($A9="","",IFERROR(AVERAGEIF(tblGunluk[VarlikId],$A9,tblGunluk[SagimLt_lt]),0)) | J9: =IF($A9="","",COUNTIFS(tblGunluk[VarlikId],$A9,tblGunluk[AlarmBayrak],"ALARM")) | K9: =IF($A9="","",MAX(0,MIN(100,ssy_kaliteTaban-IF($I9<ssy_esikSagimLt,ssy_kaliteCeza,0)-COUNTIFS(tblGunluk[VarlikId],$A9,tblGunluk[AlarmBayrak],"ALARM")*ssy_kaliteSapma-IF($G9="HAYIR",ssy_kaliteCeza,0))))
A10: INK-00005 | B10: Yıldız | C10: Holstein | D10: 2 | E10: 26 | F10: 45170 | G10: EVET | H10: =IF($A10="","",SUMIF(tblGunluk[VarlikId],$A10,tblGunluk[SagimLt_lt])) | I10: =IF($A10="","",IFERROR(AVERAGEIF(tblGunluk[VarlikId],$A10,tblGunluk[SagimLt_lt]),0)) | J10: =IF($A10="","",COUNTIFS(tblGunluk[VarlikId],$A10,tblGunluk[AlarmBayrak],"ALARM")) | K10: =IF($A10="","",MAX(0,MIN(100,ssy_kaliteTaban-IF($I10<ssy_esikSagimLt,ssy_kaliteCeza,0)-COUNTIFS(tblGunluk[VarlikId],$A10,tblGunluk[AlarmBayrak],"ALARM")*ssy_kaliteSapma-IF($G10="HAYIR",ssy_kaliteCeza,0))))
A11: INK-00006 | B11: Melek | C11: Simental | D11: 3 | E11: 25 | F11: 44792 | G11: EVET | H11: =IF($A11="","",SUMIF(tblGunluk[VarlikId],$A11,tblGunluk[SagimLt_lt])) | I11: =IF($A11="","",IFERROR(AVERAGEIF(tblGunluk[VarlikId],$A11,tblGunluk[SagimLt_lt]),0)) | J11: =IF($A11="","",COUNTIFS(tblGunluk[VarlikId],$A11,tblGunluk[AlarmBayrak],"ALARM")) | K11: =IF($A11="","",MAX(0,MIN(100,ssy_kaliteTaban-IF($I11<ssy_esikSagimLt,ssy_kaliteCeza,0)-COUNTIFS(tblGunluk[VarlikId],$A11,tblGunluk[AlarmBayrak],"ALARM")*ssy_kaliteSapma-IF($G11="HAYIR",ssy_kaliteCeza,0))))
A12: INK-00007 | B12: Nazlı | C12: Holstein | D12: 5 | E12: 32 | F12: 44535 | G12: EVET | H12: =IF($A12="","",SUMIF(tblGunluk[VarlikId],$A12,tblGunluk[SagimLt_lt])) | I12: =IF($A12="","",IFERROR(AVERAGEIF(tblGunluk[VarlikId],$A12,tblGunluk[SagimLt_lt]),0)) | J12: =IF($A12="","",COUNTIFS(tblGunluk[VarlikId],$A12,tblGunluk[AlarmBayrak],"ALARM")) | K12: =IF($A12="","",MAX(0,MIN(100,ssy_kaliteTaban-IF($I12<ssy_esikSagimLt,ssy_kaliteCeza,0)-COUNTIFS(tblGunluk[VarlikId],$A12,tblGunluk[AlarmBayrak],"ALARM")*ssy_kaliteSapma-IF($G12="HAYIR",ssy_kaliteCeza,0))))
A13: INK-00008 | B13: Gül | C13: Jersey | D13: 2 | E13: 20 | F13: 45044 | G13: EVET | H13: =IF($A13="","",SUMIF(tblGunluk[VarlikId],$A13,tblGunluk[SagimLt_lt])) | I13: =IF($A13="","",IFERROR(AVERAGEIF(tblGunluk[VarlikId],$A13,tblGunluk[SagimLt_lt]),0)) | J13: =IF($A13="","",COUNTIFS(tblGunluk[VarlikId],$A13,tblGunluk[AlarmBayrak],"ALARM")) | K13: =IF($A13="","",MAX(0,MIN(100,ssy_kaliteTaban-IF($I13<ssy_esikSagimLt,ssy_kaliteCeza,0)-COUNTIFS(tblGunluk[VarlikId],$A13,tblGunluk[AlarmBayrak],"ALARM")*ssy_kaliteSapma-IF($G13="HAYIR",ssy_kaliteCeza,0))))
H14: =IF($A14="","",SUMIF(tblGunluk[VarlikId],$A14,tblGunluk[SagimLt_lt])) | I14: =IF($A14="","",IFERROR(AVERAGEIF(tblGunluk[VarlikId],$A14,tblGunluk[SagimLt_lt]),0)) | J14: =IF($A14="","",COUNTIFS(tblGunluk[VarlikId],$A14,tblGunluk[AlarmBayrak],"ALARM")) | K14: =IF($A14="","",MAX(0,MIN(100,ssy_kaliteTaban-IF($I14<ssy_esikSagimLt,ssy_kaliteCeza,0)-COUNTIFS(tblGunluk[VarlikId],$A14,tblGunluk[AlarmBayrak],"ALARM")*ssy_kaliteSapma-IF($G14="HAYIR",ssy_kaliteCeza,0))))
H15: =IF($A15="","",SUMIF(tblGunluk[VarlikId],$A15,tblGunluk[SagimLt_lt])) | I15: =IF($A15="","",IFERROR(AVERAGEIF(tblGunluk[VarlikId],$A15,tblGunluk[SagimLt_lt]),0)) | J15: =IF($A15="","",COUNTIFS(tblGunluk[VarlikId],$A15,tblGunluk[AlarmBayrak],"ALARM")) | K15: =IF($A15="","",MAX(0,MIN(100,ssy_kaliteTaban-IF($I15<ssy_esikSagimLt,ssy_kaliteCeza,0)-COUNTIFS(tblGunluk[VarlikId],$A15,tblGunluk[AlarmBayrak],"ALARM")*ssy_kaliteSapma-IF($G15="HAYIR",ssy_kaliteCeza,0))))
H16: =IF($A16="","",SUMIF(tblGunluk[VarlikId],$A16,tblGunluk[SagimLt_lt])) | I16: =IF($A16="","",IFERROR(AVERAGEIF(tblGunluk[VarlikId],$A16,tblGunluk[SagimLt_lt]),0)) | J16: =IF($A16="","",COUNTIFS(tblGunluk[VarlikId],$A16,tblGunluk[AlarmBayrak],"ALARM")) | K16: =IF($A16="","",MAX(0,MIN(100,ssy_kaliteTaban-IF($I16<ssy_esikSagimLt,ssy_kaliteCeza,0)-COUNTIFS(tblGunluk[VarlikId],$A16,tblGunluk[AlarmBayrak],"ALARM")*ssy_kaliteSapma-IF($G16="HAYIR",ssy_kaliteCeza,0))))
H17: =IF($A17="","",SUMIF(tblGunluk[VarlikId],$A17,tblGunluk[SagimLt_lt])) | I17: =IF($A17="","",IFERROR(AVERAGEIF(tblGunluk[VarlikId],$A17,tblGunluk[SagimLt_lt]),0)) | J17: =IF($A17="","",COUNTIFS(tblGunluk[VarlikId],$A17,tblGunluk[AlarmBayrak],"ALARM")) | K17: =IF($A17="","",MAX(0,MIN(100,ssy_kaliteTaban-IF($I17<ssy_esikSagimLt,ssy_kaliteCeza,0)-COUNTIFS(tblGunluk[VarlikId],$A17,tblGunluk[AlarmBayrak],"ALARM")*ssy_kaliteSapma-IF($G17="HAYIR",ssy_kaliteCeza,0))))
H18: =IF($A18="","",SUMIF(tblGunluk[VarlikId],$A18,tblGunluk[SagimLt_lt])) | I18: =IF($A18="","",IFERROR(AVERAGEIF(tblGunluk[VarlikId],$A18,tblGunluk[SagimLt_lt]),0)) | J18: =IF($A18="","",COUNTIFS(tblGunluk[VarlikId],$A18,tblGunluk[AlarmBayrak],"ALARM")) | K18: =IF($A18="","",MAX(0,MIN(100,ssy_kaliteTaban-IF($I18<ssy_esikSagimLt,ssy_kaliteCeza,0)-COUNTIFS(tblGunluk[VarlikId],$A18,tblGunluk[AlarmBayrak],"ALARM")*ssy_kaliteSapma-IF($G18="HAYIR",ssy_kaliteCeza,0))))
H19: =IF($A19="","",SUMIF(tblGunluk[VarlikId],$A19,tblGunluk[SagimLt_lt])) | I19: =IF($A19="","",IFERROR(AVERAGEIF(tblGunluk[VarlikId],$A19,tblGunluk[SagimLt_lt]),0)) | J19: =IF($A19="","",COUNTIFS(tblGunluk[VarlikId],$A19,tblGunluk[AlarmBayrak],"ALARM")) | K19: =IF($A19="","",MAX(0,MIN(100,ssy_kaliteTaban-IF($I19<ssy_esikSagimLt,ssy_kaliteCeza,0)-COUNTIFS(tblGunluk[VarlikId],$A19,tblGunluk[AlarmBayrak],"ALARM")*ssy_kaliteSapma-IF($G19="HAYIR",ssy_kaliteCeza,0))))
H20: =IF($A20="","",SUMIF(tblGunluk[VarlikId],$A20,tblGunluk[SagimLt_lt])) | I20: =IF($A20="","",IFERROR(AVERAGEIF(tblGunluk[VarlikId],$A20,tblGunluk[SagimLt_lt]),0)) | J20: =IF($A20="","",COUNTIFS(tblGunluk[VarlikId],$A20,tblGunluk[AlarmBayrak],"ALARM")) | K20: =IF($A20="","",MAX(0,MIN(100,ssy_kaliteTaban-IF($I20<ssy_esikSagimLt,ssy_kaliteCeza,0)-COUNTIFS(tblGunluk[VarlikId],$A20,tblGunluk[AlarmBayrak],"ALARM")*ssy_kaliteSapma-IF($G20="HAYIR",ssy_kaliteCeza,0))))
H21: =IF($A21="","",SUMIF(tblGunluk[VarlikId],$A21,tblGunluk[SagimLt_lt])) | I21: =IF($A21="","",IFERROR(AVERAGEIF(tblGunluk[VarlikId],$A21,tblGunluk[SagimLt_lt]),0)) | J21: =IF($A21="","",COUNTIFS(tblGunluk[VarlikId],$A21,tblGunluk[AlarmBayrak],"ALARM")) | K21: =IF($A21="","",MAX(0,MIN(100,ssy_kaliteTaban-IF($I21<ssy_esikSagimLt,ssy_kaliteCeza,0)-COUNTIFS(tblGunluk[VarlikId],$A21,tblGunluk[AlarmBayrak],"ALARM")*ssy_kaliteSapma-IF($G21="HAYIR",ssy_kaliteCeza,0))))
H22: =IF($A22="","",SUMIF(tblGunluk[VarlikId],$A22,tblGunluk[SagimLt_lt])) | I22: =IF($A22="","",IFERROR(AVERAGEIF(tblGunluk[VarlikId],$A22,tblGunluk[SagimLt_lt]),0)) | J22: =IF($A22="","",COUNTIFS(tblGunluk[VarlikId],$A22,tblGunluk[AlarmBayrak],"ALARM")) | K22: =IF($A22="","",MAX(0,MIN(100,ssy_kaliteTaban-IF($I22<ssy_esikSagimLt,ssy_kaliteCeza,0)-COUNTIFS(tblGunluk[VarlikId],$A22,tblGunluk[AlarmBayrak],"ALARM")*ssy_kaliteSapma-IF($G22="HAYIR",ssy_kaliteCeza,0))))
H23: =IF($A23="","",SUMIF(tblGunluk[VarlikId],$A23,tblGunluk[SagimLt_lt])) | I23: =IF($A23="","",IFERROR(AVERAGEIF(tblGunluk[VarlikId],$A23,tblGunluk[SagimLt_lt]),0)) | J23: =IF($A23="","",COUNTIFS(tblGunluk[VarlikId],$A23,tblGunluk[AlarmBayrak],"ALARM")) | K23: =IF($A23="","",MAX(0,MIN(100,ssy_kaliteTaban-IF($I23<ssy_esikSagimLt,ssy_kaliteCeza,0)-COUNTIFS(tblGunluk[VarlikId],$A23,tblGunluk[AlarmBayrak],"ALARM")*ssy_kaliteSapma-IF($G23="HAYIR",ssy_kaliteCeza,0))))
H24: =IF($A24="","",SUMIF(tblGunluk[VarlikId],$A24,tblGunluk[SagimLt_lt])) | I24: =IF($A24="","",IFERROR(AVERAGEIF(tblGunluk[VarlikId],$A24,tblGunluk[SagimLt_lt]),0)) | J24: =IF($A24="","",COUNTIFS(tblGunluk[VarlikId],$A24,tblGunluk[AlarmBayrak],"ALARM")) | K24: =IF($A24="","",MAX(0,MIN(100,ssy_kaliteTaban-IF($I24<ssy_esikSagimLt,ssy_kaliteCeza,0)-COUNTIFS(tblGunluk[VarlikId],$A24,tblGunluk[AlarmBayrak],"ALARM")*ssy_kaliteSapma-IF($G24="HAYIR",ssy_kaliteCeza,0))))
H25: =IF($A25="","",SUMIF(tblGunluk[VarlikId],$A25,tblGunluk[SagimLt_lt])) | I25: =IF($A25="","",IFERROR(AVERAGEIF(tblGunluk[VarlikId],$A25,tblGunluk[SagimLt_lt]),0)) | J25: =IF($A25="","",COUNTIFS(tblGunluk[VarlikId],$A25,tblGunluk[AlarmBayrak],"ALARM")) | K25: =IF($A25="","",MAX(0,MIN(100,ssy_kaliteTaban-IF($I25<ssy_esikSagimLt,ssy_kaliteCeza,0)-COUNTIFS(tblGunluk[VarlikId],$A25,tblGunluk[AlarmBayrak],"ALARM")*ssy_kaliteSapma-IF($G25="HAYIR",ssy_kaliteCeza,0))))
... H255: =IF($A255="","",SUMIF(tblGunluk[VarlikId],$A255,tblGunluk[SagimLt_lt])) | I255: =IF($A255="","",IFERROR(AVERAGEIF(tblGunluk[VarlikId],$A255,tblGunluk[SagimLt_lt]),0)) | J255: =IF($A255="","",COUNTIFS(tblGunluk[VarlikId],$A255,tblGunluk[AlarmBayrak],"ALARM")) | K255: =IF($A255="","",MAX(0,MIN(100,ssy_kaliteTaban-IF($I255<ssy_esikSagimLt,ssy_kaliteCeza,0)-COUNTIFS(tblGunluk[VarlikId],$A255,tblGunluk[AlarmBayrak],"ALARM")*ssy_kaliteSapma-IF($G255="HAYIR",ssy_kaliteCeza,0))))

Sheet GUNLUK_GIRIS
A1: GUNLUK GIRIS — Süt Sürüsü Yönetim Komutası
A3: GÜNLÜK saha girişi — satır başına en fazla 6 manuel alan (S02)
A5: SatirId | B5: VarlikId | C5: Tarih | D5: SagimLt_lt | E5: YemKg_kg | F5: KizginlikDurum | G5: GebelikGun_gun | H5: OlayTuru | I5: FormulHedef_lt | J5: FormulSapma_lt | K5: FormulSapmaOran_oran | L5: FormulBuzagiYakin | M5: SaglikSkor_puan | N5: AlarmBayrak | O5: FormulKayitDolu | P5: FormulYetim
A6: SSY-00001 | B6: INK-00001 | C6: 46242 | D6: 24.6 | E6: 16.5 | F6: HAYIR | G6: 51 | H6: KIZGINLIK | I6: =IF($A6="","",IFERROR(SUMIF(tblVarliklar[VarlikId],$B6,tblVarliklar[HedefSagimLt_lt]),ssy_varsayilanHedefLt)) | J6: =IF($A6="","",$D6-$I6) | K6: =IF(OR($A6="",$I6=0),"",$J6/$I6) | L6: =IF($A6="","",IF($G6>=ssy_esikBuzagiGun,"YAKIN","NORMAL")) | M6: =IF($A6="","",MAX(0,MIN(100,ssy_kaliteTaban-IF($D6<ssy_esikSagimLt,ssy_kaliteCeza,0)-IF($L6="YAKIN",ssy_kaliteSapma,0)-IF($F6="EVET",0,0)-IF($P6="YETIM",ssy_kaliteCeza,0)))) | N6: =IF($A6="","",IF(OR($D6<ssy_esikSagimLt,$G6>=ssy_esikBuzagiGun,$M6<ssy_esikSaglik),"ALARM","UYGUN")) | O6: =IF($A6="","",1) | P6: =IF($A6="","",IF(OR($B6="",COUNTIF(tblVarliklar[VarlikId],$B6)=0),"YETIM","TAMAM"))
A7: SSY-00002 | B7: INK-00002 | C7: 46239 | D7: 21.8 | E7: 16.9 | F7: HAYIR | G7: 62 | H7: TOHUM | I7: =IF($A7="","",IFERROR(SUMIF(tblVarliklar[VarlikId],$B7,tblVarliklar[HedefSagimLt_lt]),ssy_varsayilanHedefLt)) | J7: =IF($A7="","",$D7-$I7) | K7: =IF(OR($A7="",$I7=0),"",$J7/$I7) | L7: =IF($A7="","",IF($G7>=ssy_esikBuzagiGun,"YAKIN","NORMAL")) | M7: =IF($A7="","",MAX(0,MIN(100,ssy_kaliteTaban-IF($D7<ssy_esikSagimLt,ssy_kaliteCeza,0)-IF($L7="YAKIN",ssy_kaliteSapma,0)-IF($F7="EVET",0,0)-IF($P7="YETIM",ssy_kaliteCeza,0)))) | N7: =IF($A7="","",IF(OR($D7<ssy_esikSagimLt,$G7>=ssy_esikBuzagiGun,$M7<ssy_esikSaglik),"ALARM","UYGUN")) | O7: =IF($A7="","",1) | P7: =IF($A7="","",IF(OR($B7="",COUNTIF(tblVarliklar[VarlikId],$B7)=0),"YETIM","TAMAM"))
A8: SSY-00003 | B8: INK-00003 | C8: 46236 | D8: 28.2 | E8: 18.6 | F8: HAYIR | G8: 73 | H8: GEBELIK | I8: =IF($A8="","",IFERROR(SUMIF(tblVarliklar[VarlikId],$B8,tblVarliklar[HedefSagimLt_lt]),ssy_varsayilanHedefLt)) | J8: =IF($A8="","",$D8-$I8) | K8: =IF(OR($A8="",$I8=0),"",$J8/$I8) | L8: =IF($A8="","",IF($G8>=ssy_esikBuzagiGun,"YAKIN","NORMAL")) | M8: =IF($A8="","",MAX(0,MIN(100,ssy_kaliteTaban-IF($D8<ssy_esikSagimLt,ssy_kaliteCeza,0)-IF($L8="YAKIN",ssy_kaliteSapma,0)-IF($F8="EVET",0,0)-IF($P8="YETIM",ssy_kaliteCeza,0)))) | N8: =IF($A8="","",IF(OR($D8<ssy_esikSagimLt,$G8>=ssy_esikBuzagiGun,$M8<ssy_esikSaglik),"ALARM","UYGUN")) | O8: =IF($A8="","",1) | P8: =IF($A8="","",IF(OR($B8="",COUNTIF(tblVarliklar[VarlikId],$B8)=0),"YETIM","TAMAM"))
A9: SSY-00004 | B9: INK-00004 | C9: 46233 | D9: 17.5 | E9: 17.8 | F9: HAYIR | G9: 84 | H9: BUZAGILAMA | I9: =IF($A9="","",IFERROR(SUMIF(tblVarliklar[VarlikId],$B9,tblVarliklar[HedefSagimLt_lt]),ssy_varsayilanHedefLt)) | J9: =IF($A9="","",$D9-$I9) | K9: =IF(OR($A9="",$I9=0),"",$J9/$I9) | L9: =IF($A9="","",IF($G9>=ssy_esikBuzagiGun,"YAKIN","NORMAL")) | M9: =IF($A9="","",MAX(0,MIN(100,ssy_kaliteTaban-IF($D9<ssy_esikSagimLt,ssy_kaliteCeza,0)-IF($L9="YAKIN",ssy_kaliteSapma,0)-IF($F9="EVET",0,0)-IF($P9="YETIM",ssy_kaliteCeza,0)))) | N9: =IF($A9="","",IF(OR($D9<ssy_esikSagimLt,$G9>=ssy_esikBuzagiGun,$M9<ssy_esikSaglik),"ALARM","UYGUN")) | O9: =IF($A9="","",1) | P9: =IF($A9="","",IF(OR($B9="",COUNTIF(tblVarliklar[VarlikId],$B9)=0),"YETIM","TAMAM"))
A10: SSY-00005 | B10: INK-00005 | C10: 46230 | D10: 22.1 | E10: 19.3 | F10: HAYIR | G10: 95 | H10: DIGER | I10: =IF($A10="","",IFERROR(SUMIF(tblVarliklar[VarlikId],$B10,tblVarliklar[HedefSagimLt_lt]),ssy_varsayilanHedefLt)) | J10: =IF($A10="","",$D10-$I10) | K10: =IF(OR($A10="",$I10=0),"",$J10/$I10) | L10: =IF($A10="","",IF($G10>=ssy_esikBuzagiGun,"YAKIN","NORMAL")) | M10: =IF($A10="","",MAX(0,MIN(100,ssy_kaliteTaban-IF($D10<ssy_esikSagimLt,ssy_kaliteCeza,0)-IF($L10="YAKIN",ssy_kaliteSapma,0)-IF($F10="EVET",0,0)-IF($P10="YETIM",ssy_kaliteCeza,0)))) | N10: =IF($A10="","",IF(OR($D10<ssy_esikSagimLt,$G10>=ssy_esikBuzagiGun,$M10<ssy_esikSaglik),"ALARM","UYGUN")) | O10: =IF($A10="","",1) | P10: =IF($A10="","",IF(OR($B10="",COUNTIF(tblVarliklar[VarlikId],$B10)=0),"YETIM","TAMAM"))
A11: SSY-00006 | B11: INK-00006 | C11: 46227 | D11: 22 | E11: 15.3 | F11: HAYIR | G11: 106 | H11: SAGIM | I11: =IF($A11="","",IFERROR(SUMIF(tblVarliklar[VarlikId],$B11,tblVarliklar[HedefSagimLt_lt]),ssy_varsayilanHedefLt)) | J11: =IF($A11="","",$D11-$I11) | K11: =IF(OR($A11="",$I11=0),"",$J11/$I11) | L11: =IF($A11="","",IF($G11>=ssy_esikBuzagiGun,"YAKIN","NORMAL")) | M11: =IF($A11="","",MAX(0,MIN(100,ssy_kaliteTaban-IF($D11<ssy_esikSagimLt,ssy_kaliteCeza,0)-IF($L11="YAKIN",ssy_kaliteSapma,0)-IF($F11="EVET",0,0)-IF($P11="YETIM",ssy_kaliteCeza,0)))) | N11: =IF($A11="","",IF(OR($D11<ssy_esikSagimLt,$G11>=ssy_esikBuzagiGun,$M11<ssy_esikSaglik),"ALARM","UYGUN")) | O11: =IF($A11="","",1) | P11: =IF($A11="","",IF(OR($B11="",COUNTIF(tblVarliklar[VarlikId],$B11)=0),"YETIM","TAMAM"))
A12: SSY-00007 | B12: INK-00007 | C12: 46224 | D12: 29.1 | E12: 17.2 | F12: EVET | G12: 117 | H12: KIZGINLIK | I12: =IF($A12="","",IFERROR(SUMIF(tblVarliklar[VarlikId],$B12,tblVarliklar[HedefSagimLt_lt]),ssy_varsayilanHedefLt)) | J12: =IF($A12="","",$D12-$I12) | K12: =IF(OR($A12="",$I12=0),"",$J12/$I12) | L12: =IF($A12="","",IF($G12>=ssy_esikBuzagiGun,"YAKIN","NORMAL")) | M12: =IF($A12="","",MAX(0,MIN(100,ssy_kaliteTaban-IF($D12<ssy_esikSagimLt,ssy_kaliteCeza,0)-IF($L12="YAKIN",ssy_kaliteSapma,0)-IF($F12="EVET",0,0)-IF($P12="YETIM",ssy_kaliteCeza,0)))) | N12: =IF($A12="","",IF(OR($D12<ssy_esikSagimLt,$G12>=ssy_esikBuzagiGun,$M12<ssy_esikSaglik),"ALARM","UYGUN")) | O12: =IF($A12="","",1) | P12: =IF($A12="","",IF(OR($B12="",COUNTIF(tblVarliklar[VarlikId],$B12)=0),"YETIM","TAMAM"))
A13: SSY-00008 | B13: INK-00008 | C13: 46221 | D13: 18.8 | E13: 16.4 | F13: HAYIR | G13: 128 | H13: TOHUM | I13: =IF($A13="","",IFERROR(SUMIF(tblVarliklar[VarlikId],$B13,tblVarliklar[HedefSagimLt_lt]),ssy_varsayilanHedefLt)) | J13: =IF($A13="","",$D13-$I13) | K13: =IF(OR($A13="",$I13=0),"",$J13/$I13) | L13: =IF($A13="","",IF($G13>=ssy_esikBuzagiGun,"YAKIN","NORMAL")) | M13: =IF($A13="","",MAX(0,MIN(100,ssy_kaliteTaban-IF($D13<ssy_esikSagimLt,ssy_kaliteCeza,0)-IF($L13="YAKIN",ssy_kaliteSapma,0)-IF($F13="EVET",0,0)-IF($P13="YETIM",ssy_kaliteCeza,0)))) | N13: =IF($A13="","",IF(OR($D13<ssy_esikSagimLt,$G13>=ssy_esikBuzagiGun,$M13<ssy_esikSaglik),"ALARM","UYGUN")) | O13: =IF($A13="","",1) | P13: =IF($A13="","",IF(OR($B13="",COUNTIF(tblVarliklar[VarlikId],$B13)=0),"YETIM","TAMAM"))
A14: SSY-00009 | B14: INK-00001 | C14: 46218 | D14: 27.2 | E14: 18.5 | F14: HAYIR | G14: 0 | H14: GEBELIK | I14: =IF($A14="","",IFERROR(SUMIF(tblVarliklar[VarlikId],$B14,tblVarliklar[HedefSagimLt_lt]),ssy_varsayilanHedefLt)) | J14: =IF($A14="","",$D14-$I14) | K14: =IF(OR($A14="",$I14=0),"",$J14/$I14) | L14: =IF($A14="","",IF($G14>=ssy_esikBuzagiGun,"YAKIN","NORMAL")) | M14: =IF($A14="","",MAX(0,MIN(100,ssy_kaliteTaban-IF($D14<ssy_esikSagimLt,ssy_kaliteCeza,0)-IF($L14="YAKIN",ssy_kaliteSapma,0)-IF($F14="EVET",0,0)-IF($P14="YETIM",ssy_kaliteCeza,0)))) | N14: =IF($A14="","",IF(OR($D14<ssy_esikSagimLt,$G14>=ssy_esikBuzagiGun,$M14<ssy_esikSaglik),"ALARM","UYGUN")) | O14: =IF($A14="","",1) | P14: =IF($A14="","",IF(OR($B14="",COUNTIF(tblVarliklar[VarlikId],$B14)=0),"YETIM","TAMAM"))
A15: SSY-00010 | B15: INK-00002 | C15: 46215 | D15: 20.4 | E15: 18.3 | F15: HAYIR | G15: 150 | H15: BUZAGILAMA | I15: =IF($A15="","",IFERROR(SUMIF(tblVarliklar[VarlikId],$B15,tblVarliklar[HedefSagimLt_lt]),ssy_varsayilanHedefLt)) | J15: =IF($A15="","",$D15-$I15) | K15: =IF(OR($A15="",$I15=0),"",$J15/$I15) | L15: =IF($A15="","",IF($G15>=ssy_esikBuzagiGun,"YAKIN","NORMAL")) | M15: =IF($A15="","",MAX(0,MIN(100,ssy_kaliteTaban-IF($D15<ssy_esikSagimLt,ssy_kaliteCeza,0)-IF($L15="YAKIN",ssy_kaliteSapma,0)-IF($F15="EVET",0,0)-IF($P15="YETIM",ssy_kaliteCeza,0)))) | N15: =IF($A15="","",IF(OR($D15<ssy_esikSagimLt,$G15>=ssy_esikBuzagiGun,$M15<ssy_esikSaglik),"ALARM","UYGUN")) | O15: =IF($A15="","",1) | P15: =IF($A15="","",IF(OR($B15="",COUNTIF(tblVarliklar[VarlikId],$B15)=0),"YETIM","TAMAM"))
A16: SSY-00011 | B16: INK-00003 | C16: 46212 | D16: 26.4 | E16: 20 | F16: HAYIR | G16: 161 | H16: DIGER | I16: =IF($A16="","",IFERROR(SUMIF(tblVarliklar[VarlikId],$B16,tblVarliklar[HedefSagimLt_lt]),ssy_varsayilanHedefLt)) | J16: =IF($A16="","",$D16-$I16) | K16: =IF(OR($A16="",$I16=0),"",$J16/$I16) | L16: =IF($A16="","",IF($G16>=ssy_esikBuzagiGun,"YAKIN","NORMAL")) | M16: =IF($A16="","",MAX(0,MIN(100,ssy_kaliteTaban-IF($D16<ssy_esikSagimLt,ssy_kaliteCeza,0)-IF($L16="YAKIN",ssy_kaliteSapma,0)-IF($F16="EVET",0,0)-IF($P16="YETIM",ssy_kaliteCeza,0)))) | N16: =IF($A16="","",IF(OR($D16<ssy_esikSagimLt,$G16>=ssy_esikBuzagiGun,$M16<ssy_esikSaglik),"ALARM","UYGUN")) | O16: =IF($A16="","",1) | P16: =IF($A16="","",IF(OR($B16="",COUNTIF(tblVarliklar[VarlikId],$B16)=0),"YETIM","TAMAM"))
A17: SSY-00012 | B17: INK-00004 | C17: 46209 | D17: 9.9 | E17: 13.5 | F17: HAYIR | G17: 172 | H17: SAGIM | I17: =IF($A17="","",IFERROR(SUMIF(tblVarliklar[VarlikId],$B17,tblVarliklar[HedefSagimLt_lt]),ssy_varsayilanHedefLt)) | J17: =IF($A17="","",$D17-$I17) | K17: =IF(OR($A17="",$I17=0),"",$J17/$I17) | L17: =IF($A17="","",IF($G17>=ssy_esikBuzagiGun,"YAKIN","NORMAL")) | M17: =IF($A17="","",MAX(0,MIN(100,ssy_kaliteTaban-IF($D17<ssy_esikSagimLt,ssy_kaliteCeza,0)-IF($L17="YAKIN",ssy_kaliteSapma,0)-IF($F17="EVET",0,0)-IF($P17="YETIM",ssy_kaliteCeza,0)))) | N17: =IF($A17="","",IF(OR($D17<ssy_esikSagimLt,$G17>=ssy_esikBuzagiGun,$M17<ssy_esikSaglik),"ALARM","UYGUN")) | O17: =IF($A17="","",1) | P17: =IF($A17="","",IF(OR($B17="",COUNTIF(tblVarliklar[VarlikId],$B17)=0),"YETIM","TAMAM"))
... A34: SSY-00029 | B34: INK-00005 | C34: 46158 | D34: 25.2 | E34: 19.8 | F34: HAYIR | G34: 119 | H34: DIGER | I34: =IF($A34="","",IFERROR(SUMIF(tblVarliklar[VarlikId],$B34,tblVarliklar[HedefSagimLt_lt]),ssy_varsayilanHedefLt)) | J34: =IF($A34="","",$D34-$I34) | K34: =IF(OR($A34="",$I34=0),"",$J34/$I34) | L34: =IF($A34="","",IF($G34>=ssy_esikBuzagiGun,"YAKIN","NORMAL")) | M34: =IF($A34="","",MAX(0,MIN(100,ssy_kaliteTaban-IF($D34<ssy_esikSagimLt,ssy_kaliteCeza,0)-IF($L34="YAKIN",ssy_kaliteSapma,0)-IF($F34="EVET",0,0)-IF($P34="YETIM",ssy_kaliteCeza,0)))) | N34: =IF($A34="","",IF(OR($D34<ssy_esikSagimLt,$G34>=ssy_esikBuzagiGun,$M34<ssy_esikSaglik),"ALARM","UYGUN")) | O34: =IF($A34="","",1) | P34: =IF($A34="","",IF(OR($B34="",COUNTIF(tblVarliklar[VarlikId],$B34)=0),"YETIM","TAMAM"))
A35: SSY-00030 | C35: 46155 | D35: 21.2 | E35: 15.2 | F35: HAYIR | G35: 130 | H35: SAGIM | I35: =IF($A35="","",IFERROR(SUMIF(tblVarliklar[VarlikId],$B35,tblVarliklar[HedefSagimLt_lt]),ssy_varsayilanHedefLt)) | J35: =IF($A35="","",$D35-$I35) | K35: =IF(OR($A35="",$I35=0),"",$J35/$I35) | L35: =IF($A35="","",IF($G35>=ssy_esikBuzagiGun,"YAKIN","NORMAL")) | M35: =IF($A35="","",MAX(0,MIN(100,ssy_kaliteTaban-IF($D35<ssy_esikSagimLt,ssy_kaliteCeza,0)-IF($L35="YAKIN",ssy_kaliteSapma,0)-IF($F35="EVET",0,0)-IF($P35="YETIM",ssy_kaliteCeza,0)))) | N35: =IF($A35="","",IF(OR($D35<ssy_esikSagimLt,$G35>=ssy_esikBuzagiGun,$M35<ssy_esikSaglik),"ALARM","UYGUN")) | O35: =IF($A35="","",1) | P35: =IF($A35="","",IF(OR($B35="",COUNTIF(tblVarliklar[VarlikId],$B35)=0),"YETIM","TAMAM"))
A36: SSY-00031 | B36: INK-00007 | C36: 46152 | D36: 28.2 | E36: 17 | F36: HAYIR | G36: 141 | H36: KIZGINLIK | I36: =IF($A36="","",IFERROR(SUMIF(tblVarliklar[VarlikId],$B36,tblVarliklar[HedefSagimLt_lt]),ssy_varsayilanHedefLt)) | J36: =IF($A36="","",$D36-$I36) | K36: =IF(OR($A36="",$I36=0),"",$J36/$I36) | L36: =IF($A36="","",IF($G36>=ssy_esikBuzagiGun,"YAKIN","NORMAL")) | M36: =IF($A36="","",MAX(0,MIN(100,ssy_kaliteTaban-IF($D36<ssy_esikSagimLt,ssy_kaliteCeza,0)-IF($L36="YAKIN",ssy_kaliteSapma,0)-IF($F36="EVET",0,0)-IF($P36="YETIM",ssy_kaliteCeza,0)))) | N36: =IF($A36="","",IF(OR($D36<ssy_esikSagimLt,$G36>=ssy_esikBuzagiGun,$M36<ssy_esikSaglik),"ALARM","UYGUN")) | O36: =IF($A36="","",1) | P36: =IF($A36="","",IF(OR($B36="",COUNTIF(tblVarliklar[VarlikId],$B36)=0),"YETIM","TAMAM"))
A37: SSY-00032 | B37: INK-00008 | C37: 46149 | D37: 18.2 | E37: 16.3 | F37: HAYIR | G37: 152 | H37: TOHUM | I37: =IF($A37="","",IFERROR(SUMIF(tblVarliklar[VarlikId],$B37,tblVarliklar[HedefSagimLt_lt]),ssy_varsayilanHedefLt)) | J37: =IF($A37="","",$D37-$I37) | K37: =IF(OR($A37="",$I37=0),"",$J37/$I37) | L37: =IF($A37="","",IF($G37>=ssy_esikBuzagiGun,"YAKIN","NORMAL")) | M37: =IF($A37="","",MAX(0,MIN(100,ssy_kaliteTaban-IF($D37<ssy_esikSagimLt,ssy_kaliteCeza,0)-IF($L37="YAKIN",ssy_kaliteSapma,0)-IF($F37="EVET",0,0)-IF($P37="YETIM",ssy_kaliteCeza,0)))) | N37: =IF($A37="","",IF(OR($D37<ssy_esikSagimLt,$G37>=ssy_esikBuzagiGun,$M37<ssy_esikSaglik),"ALARM","UYGUN")) | O37: =IF($A37="","",1) | P37: =IF($A37="","",IF(OR($B37="",COUNTIF(tblVarliklar[VarlikId],$B37)=0),"YETIM","TAMAM"))
A38: SSY-00033 | B38: INK-99999 | C38: 46146 | D38: 26.3 | E38: 18.3 | F38: HAYIR | G38: 163 | H38: GEBELIK | I38: =IF($A38="","",IFERROR(SUMIF(tblVarliklar[VarlikId],$B38,tblVarliklar[HedefSagimLt_lt]),ssy_varsayilanHedefLt)) | J38: =IF($A38="","",$D38-$I38) | K38: =IF(OR($A38="",$I38=0),"",$J38/$I38) | L38: =IF($A38="","",IF($G38>=ssy_esikBuzagiGun,"YAKIN","NORMAL")) | M38: =IF($A38="","",MAX(0,MIN(100,ssy_kaliteTaban-IF($D38<ssy_esikSagimLt,ssy_kaliteCeza,0)-IF($L38="YAKIN",ssy_kaliteSapma,0)-IF($F38="EVET",0,0)-IF($P38="YETIM",ssy_kaliteCeza,0)))) | N38: =IF($A38="","",IF(OR($D38<ssy_esikSagimLt,$G38>=ssy_esikBuzagiGun,$M38<ssy_esikSaglik),"ALARM","UYGUN")) | O38: =IF($A38="","",1) | P38: =IF($A38="","",IF(OR($B38="",COUNTIF(tblVarliklar[VarlikId],$B38)=0),"YETIM","TAMAM"))
A39: SSY-00034 | B39: INK-00002 | C39: 46143 | D39: 23.3 | E39: 18.7 | F39: HAYIR | G39: 174 | H39: BUZAGILAMA | I39: =IF($A39="","",IFERROR(SUMIF(tblVarliklar[VarlikId],$B39,tblVarliklar[HedefSagimLt_lt]),ssy_varsayilanHedefLt)) | J39: =IF($A39="","",$D39-$I39) | K39: =IF(OR($A39="",$I39=0),"",$J39/$I39) | L39: =IF($A39="","",IF($G39>=ssy_esikBuzagiGun,"YAKIN","NORMAL")) | M39: =IF($A39="","",MAX(0,MIN(100,ssy_kaliteTaban-IF($D39<ssy_esikSagimLt,ssy_kaliteCeza,0)-IF($L39="YAKIN",ssy_kaliteSapma,0)-IF($F39="EVET",0,0)-IF($P39="YETIM",ssy_kaliteCeza,0)))) | N39: =IF($A39="","",IF(OR($D39<ssy_esikSagimLt,$G39>=ssy_esikBuzagiGun,$M39<ssy_esikSaglik),"ALARM","UYGUN")) | O39: =IF($A39="","",1) | P39: =IF($A39="","",IF(OR($B39="",COUNTIF(tblVarliklar[VarlikId],$B39)=0),"YETIM","TAMAM"))
A40: SSY-00035 | B40: INK-00003 | C40: 46140 | D40: 25.5 | E40: 19.8 | F40: EVET | G40: 185 | H40: DIGER | I40: =IF($A40="","",IFERROR(SUMIF(tblVarliklar[VarlikId],$B40,tblVarliklar[HedefSagimLt_lt]),ssy_varsayilanHedefLt)) | J40: =IF($A40="","",$D40-$I40) | K40: =IF(OR($A40="",$I40=0),"",$J40/$I40) | L40: =IF($A40="","",IF($G40>=ssy_esikBuzagiGun,"YAKIN","NORMAL")) | M40: =IF($A40="","",MAX(0,MIN(100,ssy_kaliteTaban-IF($D40<ssy_esikSagimLt,ssy_kaliteCeza,0)-IF($L40="YAKIN",ssy_kaliteSapma,0)-IF($F40="EVET",0,0)-IF($P40="YETIM",ssy_kaliteCeza,0)))) | N40: =IF($A40="","",IF(OR($D40<ssy_esikSagimLt,$G40>=ssy_esikBuzagiGun,$M40<ssy_esikSaglik),"ALARM","UYGUN")) | O40: =IF($A40="","",1) | P40: =IF($A40="","",IF(OR($B40="",COUNTIF(tblVarliklar[VarlikId],$B40)=0),"YETIM","TAMAM"))
A41: SSY-00036 | B41: INK-00004 | C41: 46137 | D41: 15.8 | E41: 14.4 | F41: HAYIR | G41: 0 | H41: SAGIM | I41: =IF($A41="","",IFERROR(SUMIF(tblVarliklar[VarlikId],$B41,tblVarliklar[HedefSagimLt_lt]),ssy_varsayilanHedefLt)) | J41: =IF($A41="","",$D41-$I41) | K41: =IF(OR($A41="",$I41=0),"",$J41/$I41) | L41: =IF($A41="","",IF($G41>=ssy_esikBuzagiGun,"YAKIN","NORMAL")) | M41: =IF($A41="","",MAX(0,MIN(100,ssy_kaliteTaban-IF($D41<ssy_esikSagimLt,ssy_kaliteCeza,0)-IF($L41="YAKIN",ssy_kaliteSapma,0)-IF($F41="EVET",0,0)-IF($P41="YETIM",ssy_kaliteCeza,0)))) | N41: =IF($A41="","",IF(OR($D41<ssy_esikSagimLt,$G41>=ssy_esikBuzagiGun,$M41<ssy_esikSaglik),"ALARM","UYGUN")) | O41: =IF($A41="","",1) | P41: =IF($A41="","",IF(OR($B41="",COUNTIF(tblVarliklar[VarlikId],$B41)=0),"YETIM","TAMAM"))
I42: =IF($A42="","",IFERROR(SUMIF(tblVarliklar[VarlikId],$B42,tblVarliklar[HedefSagimLt_lt]),ssy_varsayilanHedefLt)) | J42: =IF($A42="","",$D42-$I42) | K42: =IF(OR($A42="",$I42=0),"",$J42/$I42) | L42: =IF($A42="","",IF($G42>=ssy_esikBuzagiGun,"YAKIN","NORMAL")) | M42: =IF($A42="","",MAX(0,MIN(100,ssy_kaliteTaban-IF($D42<ssy_esikSagimLt,ssy_kaliteCeza,0)-IF($L42="YAKIN",ssy_kaliteSapma,0)-IF($F42="EVET",0,0)-IF($P42="YETIM",ssy_kaliteCeza,0)))) | N42: =IF($A42="","",IF(OR($D42<ssy_esikSagimLt,$G42>=ssy_esikBuzagiGun,$M42<ssy_esikSaglik),"ALARM","UYGUN")) | O42: =IF($A42="","",1) | P42: =IF($A42="","",IF(OR($B42="",COUNTIF(tblVarliklar[VarlikId],$B42)=0),"YETIM","TAMAM"))
I43: =IF($A43="","",IFERROR(SUMIF(tblVarliklar[VarlikId],$B43,tblVarliklar[HedefSagimLt_lt]),ssy_varsayilanHedefLt)) | J43: =IF($A43="","",$D43-$I43) | K43: =IF(OR($A43="",$I43=0),"",$J43/$I43) | L43: =IF($A43="","",IF($G43>=ssy_esikBuzagiGun,"YAKIN","NORMAL")) | M43: =IF($A43="","",MAX(0,MIN(100,ssy_kaliteTaban-IF($D43<ssy_esikSagimLt,ssy_kaliteCeza,0)-IF($L43="YAKIN",ssy_kaliteSapma,0)-IF($F43="EVET",0,0)-IF($P43="YETIM",ssy_kaliteCeza,0)))) | N43: =IF($A43="","",IF(OR($D43<ssy_esikSagimLt,$G43>=ssy_esikBuzagiGun,$M43<ssy_esikSaglik),"ALARM","UYGUN")) | O43: =IF($A43="","",1) | P43: =IF($A43="","",IF(OR($B43="",COUNTIF(tblVarliklar[VarlikId],$B43)=0),"YETIM","TAMAM"))
I44: =IF($A44="","",IFERROR(SUMIF(tblVarliklar[VarlikId],$B44,tblVarliklar[HedefSagimLt_lt]),ssy_varsayilanHedefLt)) | J44: =IF($A44="","",$D44-$I44) | K44: =IF(OR($A44="",$I44=0),"",$J44/$I44) | L44: =IF($A44="","",IF($G44>=ssy_esikBuzagiGun,"YAKIN","NORMAL")) | M44: =IF($A44="","",MAX(0,MIN(100,ssy_kaliteTaban-IF($D44<ssy_esikSagimLt,ssy_kaliteCeza,0)-IF($L44="YAKIN",ssy_kaliteSapma,0)-IF($F44="EVET",0,0)-IF($P44="YETIM",ssy_kaliteCeza,0)))) | N44: =IF($A44="","",IF(OR($D44<ssy_esikSagimLt,$G44>=ssy_esikBuzagiGun,$M44<ssy_esikSaglik),"ALARM","UYGUN")) | O44: =IF($A44="","",1) | P44: =IF($A44="","",IF(OR($B44="",COUNTIF(tblVarliklar[VarlikId],$B44)=0),"YETIM","TAMAM"))
I45: =IF($A45="","",IFERROR(SUMIF(tblVarliklar[VarlikId],$B45,tblVarliklar[HedefSagimLt_lt]),ssy_varsayilanHedefLt)) | J45: =IF($A45="","",$D45-$I45) | K45: =IF(OR($A45="",$I45=0),"",$J45/$I45) | L45: =IF($A45="","",IF($G45>=ssy_esikBuzagiGun,"YAKIN","NORMAL")) | M45: =IF($A45="","",MAX(0,MIN(100,ssy_kaliteTaban-IF($D45<ssy_esikSagimLt,ssy_kaliteCeza,0)-IF($L45="YAKIN",ssy_kaliteSapma,0)-IF($F45="EVET",0,0)-IF($P45="YETIM",ssy_kaliteCeza,0)))) | N45: =IF($A45="","",IF(OR($D45<ssy_esikSagimLt,$G45>=ssy_esikBuzagiGun,$M45<ssy_esikSaglik),"ALARM","UYGUN")) | O45: =IF($A45="","",1) | P45: =IF($A45="","",IF(OR($B45="",COUNTIF(tblVarliklar[VarlikId],$B45)=0),"YETIM","TAMAM"))
I46: =IF($A46="","",IFERROR(SUMIF(tblVarliklar[VarlikId],$B46,tblVarliklar[HedefSagimLt_lt]),ssy_varsayilanHedefLt)) | J46: =IF($A46="","",$D46-$I46) | K46: =IF(OR($A46="",$I46=0),"",$J46/$I46) | L46: =IF($A46="","",IF($G46>=ssy_esikBuzagiGun,"YAKIN","NORMAL")) | M46: =IF($A46="","",MAX(0,MIN(100,ssy_kaliteTaban-IF($D46<ssy_esikSagimLt,ssy_kaliteCeza,0)-IF($L46="YAKIN",ssy_kaliteSapma,0)-IF($F46="EVET",0,0)-IF($P46="YETIM",ssy_kaliteCeza,0)))) | N46: =IF($A46="","",IF(OR($D46<ssy_esikSagimLt,$G46>=ssy_esikBuzagiGun,$M46<ssy_esikSaglik),"ALARM","UYGUN")) | O46: =IF($A46="","",1) | P46: =IF($A46="","",IF(OR($B46="",COUNTIF(tblVarliklar[VarlikId],$B46)=0),"YETIM","TAMAM"))
I47: =IF($A47="","",IFERROR(SUMIF(tblVarliklar[VarlikId],$B47,tblVarliklar[HedefSagimLt_lt]),ssy_varsayilanHedefLt)) | J47: =IF($A47="","",$D47-$I47) | K47: =IF(OR($A47="",$I47=0),"",$J47/$I47) | L47: =IF($A47="","",IF($G47>=ssy_esikBuzagiGun,"YAKIN","NORMAL")) | M47: =IF($A47="","",MAX(0,MIN(100,ssy_kaliteTaban-IF($D47<ssy_esikSagimLt,ssy_kaliteCeza,0)-IF($L47="YAKIN",ssy_kaliteSapma,0)-IF($F47="EVET",0,0)-IF($P47="YETIM",ssy_kaliteCeza,0)))) | N47: =IF($A47="","",IF(OR($D47<ssy_esikSagimLt,$G47>=ssy_esikBuzagiGun,$M47<ssy_esikSaglik),"ALARM","UYGUN")) | O47: =IF($A47="","",1) | P47: =IF($A47="","",IF(OR($B47="",COUNTIF(tblVarliklar[VarlikId],$B47)=0),"YETIM","TAMAM"))
I48: =IF($A48="","",IFERROR(SUMIF(tblVarliklar[VarlikId],$B48,tblVarliklar[HedefSagimLt_lt]),ssy_varsayilanHedefLt)) | J48: =IF($A48="","",$D48-$I48) | K48: =IF(OR($A48="",$I48=0),"",$J48/$I48) | L48: =IF($A48="","",IF($G48>=ssy_esikBuzagiGun,"YAKIN","NORMAL")) | M48: =IF($A48="","",MAX(0,MIN(100,ssy_kaliteTaban-IF($D48<ssy_esikSagimLt,ssy_kaliteCeza,0)-IF($L48="YAKIN",ssy_kaliteSapma,0)-IF($F48="EVET",0,0)-IF($P48="YETIM",ssy_kaliteCeza,0)))) | N48: =IF($A48="","",IF(OR($D48<ssy_esikSagimLt,$G48>=ssy_esikBuzagiGun,$M48<ssy_esikSaglik),"ALARM","UYGUN")) | O48: =IF($A48="","",1) | P48: =IF($A48="","",IF(OR($B48="",COUNTIF(tblVarliklar[VarlikId],$B48)=0),"YETIM","TAMAM"))
I49: =IF($A49="","",IFERROR(SUMIF(tblVarliklar[VarlikId],$B49,tblVarliklar[HedefSagimLt_lt]),ssy_varsayilanHedefLt)) | J49: =IF($A49="","",$D49-$I49) | K49: =IF(OR($A49="",$I49=0),"",$J49/$I49) | L49: =IF($A49="","",IF($G49>=ssy_esikBuzagiGun,"YAKIN","NORMAL")) | M49: =IF($A49="","",MAX(0,MIN(100,ssy_kaliteTaban-IF($D49<ssy_esikSagimLt,ssy_kaliteCeza,0)-IF($L49="YAKIN",ssy_kaliteSapma,0)-IF($F49="EVET",0,0)-IF($P49="YETIM",ssy_kaliteCeza,0)))) | N49: =IF($A49="","",IF(OR($D49<ssy_esikSagimLt,$G49>=ssy_esikBuzagiGun,$M49<ssy_esikSaglik),"ALARM","UYGUN")) | O49: =IF($A49="","",1) | P49: =IF($A49="","",IF(OR($B49="",COUNTIF(tblVarliklar[VarlikId],$B49)=0),"YETIM","TAMAM"))
I50: =IF($A50="","",IFERROR(SUMIF(tblVarliklar[VarlikId],$B50,tblVarliklar[HedefSagimLt_lt]),ssy_varsayilanHedefLt)) | J50: =IF($A50="","",$D50-$I50) | K50: =IF(OR($A50="",$I50=0),"",$J50/$I50) | L50: =IF($A50="","",IF($G50>=ssy_esikBuzagiGun,"YAKIN","NORMAL")) | M50: =IF($A50="","",MAX(0,MIN(100,ssy_kaliteTaban-IF($D50<ssy_esikSagimLt,ssy_kaliteCeza,0)-IF($L50="YAKIN",ssy_kaliteSapma,0)-IF($F50="EVET",0,0)-IF($P50="YETIM",ssy_kaliteCeza,0)))) | N50: =IF($A50="","",IF(OR($D50<ssy_esikSagimLt,$G50>=ssy_esikBuzagiGun,$M50<ssy_esikSaglik),"ALARM","UYGUN")) | O50: =IF($A50="","",1) | P50: =IF($A50="","",IF(OR($B50="",COUNTIF(tblVarliklar[VarlikId],$B50)=0),"YETIM","TAMAM"))
I51: =IF($A51="","",IFERROR(SUMIF(tblVarliklar[VarlikId],$B51,tblVarliklar[HedefSagimLt_lt]),ssy_varsayilanHedefLt)) | J51: =IF($A51="","",$D51-$I51) | K51: =IF(OR($A51="",$I51=0),"",$J51/$I51) | L51: =IF($A51="","",IF($G51>=ssy_esikBuzagiGun,"YAKIN","NORMAL")) | M51: =IF($A51="","",MAX(0,MIN(100,ssy_kaliteTaban-IF($D51<ssy_esikSagimLt,ssy_kaliteCeza,0)-IF($L51="YAKIN",ssy_kaliteSapma,0)-IF($F51="EVET",0,0)-IF($P51="YETIM",ssy_kaliteCeza,0)))) | N51: =IF($A51="","",IF(OR($D51<ssy_esikSagimLt,$G51>=ssy_esikBuzagiGun,$M51<ssy_esikSaglik),"ALARM","UYGUN")) | O51: =IF($A51="","",1) | P51: =IF($A51="","",IF(OR($B51="",COUNTIF(tblVarliklar[VarlikId],$B51)=0),"YETIM","TAMAM"))
I52: =IF($A52="","",IFERROR(SUMIF(tblVarliklar[VarlikId],$B52,tblVarliklar[HedefSagimLt_lt]),ssy_varsayilanHedefLt)) | J52: =IF($A52="","",$D52-$I52) | K52: =IF(OR($A52="",$I52=0),"",$J52/$I52) | L52: =IF($A52="","",IF($G52>=ssy_esikBuzagiGun,"YAKIN","NORMAL")) | M52: =IF($A52="","",MAX(0,MIN(100,ssy_kaliteTaban-IF($D52<ssy_esikSagimLt,ssy_kaliteCeza,0)-IF($L52="YAKIN",ssy_kaliteSapma,0)-IF($F52="EVET",0,0)-IF($P52="YETIM",ssy_kaliteCeza,0)))) | N52: =IF($A52="","",IF(OR($D52<ssy_esikSagimLt,$G52>=ssy_esikBuzagiGun,$M52<ssy_esikSaglik),"ALARM","UYGUN")) | O52: =IF($A52="","",1) | P52: =IF($A52="","",IF(OR($B52="",COUNTIF(tblVarliklar[VarlikId],$B52)=0),"YETIM","TAMAM"))
I53: =IF($A53="","",IFERROR(SUMIF(tblVarliklar[VarlikId],$B53,tblVarliklar[HedefSagimLt_lt]),ssy_varsayilanHedefLt)) | J53: =IF($A53="","",$D53-$I53) | K53: =IF(OR($A53="",$I53=0),"",$J53/$I53) | L53: =IF($A53="","",IF($G53>=ssy_esikBuzagiGun,"YAKIN","NORMAL")) | M53: =IF($A53="","",MAX(0,MIN(100,ssy_kaliteTaban-IF($D53<ssy_esikSagimLt,ssy_kaliteCeza,0)-IF($L53="YAKIN",ssy_kaliteSapma,0)-IF($F53="EVET",0,0)-IF($P53="YETIM",ssy_kaliteCeza,0)))) | N53: =IF($A53="","",IF(OR($D53<ssy_esikSagimLt,$G53>=ssy_esikBuzagiGun,$M53<ssy_esikSaglik),"ALARM","UYGUN")) | O53: =IF($A53="","",1) | P53: =IF($A53="","",IF(OR($B53="",COUNTIF(tblVarliklar[VarlikId],$B53)=0),"YETIM","TAMAM"))
... I255: =IF($A255="","",IFERROR(SUMIF(tblVarliklar[VarlikId],$B255,tblVarliklar[HedefSagimLt_lt]),ssy_varsayilanHedefLt)) | J255: =IF($A255="","",$D255-$I255) | K255: =IF(OR($A255="",$I255=0),"",$J255/$I255) | L255: =IF($A255="","",IF($G255>=ssy_esikBuzagiGun,"YAKIN","NORMAL")) | M255: =IF($A255="","",MAX(0,MIN(100,ssy_kaliteTaban-IF($D255<ssy_esikSagimLt,ssy_kaliteCeza,0)-IF($L255="YAKIN",ssy_kaliteSapma,0)-IF($F255="EVET",0,0)-IF($P255="YETIM",ssy_kaliteCeza,0)))) | N255: =IF($A255="","",IF(OR($D255<ssy_esikSagimLt,$G255>=ssy_esikBuzagiGun,$M255<ssy_esikSaglik),"ALARM","UYGUN")) | O255: =IF($A255="","",1) | P255: =IF($A255="","",IF(OR($B255="",COUNTIF(tblVarliklar[VarlikId],$B255)=0),"YETIM","TAMAM"))

Sheet DONEM_ANALIZ
A1: DONEM ANALIZ — Süt Sürüsü Yönetim Komutası
A3: 12 aylık sezonsallık — süt ve buzağılama zinciri (S03)
A5: Ay | B5: Ay_Anahtari | C5: Sut lt | D5: Buzagilama adet | E5: Ort Sagim lt | F5: Sezonsal Etiket
A6: Ocak | B6: Ay_1 | C6: 18500 | D6: 4 | E6: 22.5 | F6: 12_AY_SEZONSAL
A7: Subat | B7: Ay_2 | C7: 17800 | D7: 3 | E7: 21.8 | F7: 12_AY_SEZONSAL
A8: Mart | B8: Ay_3 | C8: 19200 | D8: 5 | E8: 23.1 | F8: 12_AY_SEZONSAL
A9: Nisan | B9: Ay_4 | C9: 20500 | D9: 6 | E9: 24 | F9: 12_AY_SEZONSAL
A10: Mayis | B10: Ay_5 | C10: 21800 | D10: 7 | E10: 25.2 | F10: 12_AY_SEZONSAL
A11: Haziran | B11: Ay_6 | C11: 23200 | D11: 8 | E11: 26.5 | F11: 12_AY_SEZONSAL
A12: Temmuz | B12: Ay_7 | C12: 24500 | D12: 6 | E12: 27.8 | F12: 12_AY_SEZONSAL
A13: Agustos | B13: Ay_8 | C13: 23800 | D13: 5 | E13: 27.1 | F13: 12_AY_SEZONSAL
A14: Eylul | B14: Ay_9 | C14: 22000 | D14: 4 | E14: 25.5 | F14: 12_AY_SEZONSAL
A15: Ekim | B15: Ay_10 | C15: 20500 | D15: 3 | E15: 24 | F15: 12_AY_SEZONSAL
A16: Kasim | B16: Ay_11 | C16: 19000 | D16: 4 | E16: 22.8 | F16: 12_AY_SEZONSAL
A17: Aralik | B17: Ay_12 | C17: 18200 | D17: 5 | E17: 22 | F17: 12_AY_SEZONSAL
A20: Sezonsal Trend Özeti | B20: =ssy_sezonsalTrend
A22: 12 Ay Toplam Süt | B22: =SUM(C6:C17)
A23: 12 Ay Buzağılama | B23: =SUM(D6:D17)
A24: 12 Ay Ort Sağım | B24: =AVERAGE(E6:E17)
A25: Canlı dönem sağım | B25: =ssy_sagimToplam
A26: Canlı dönem ort | B26: =ssy_gunlukSagimOrt

Sheet HESAP
A1: HESAP — Süt Sürüsü Yönetim Komutası
A3: Hesap motoru — ≥40 adım; sabitler AYARLAR'dan
A5: Adım | B5: Açıklama | C5: Değer
A6: H01 | B6: Toplam günlük kayıt | C6: =COUNTA(tblGunluk[SatirId])
A7: H02 | B7: Dolu kayıt | C7: =SUM(tblGunluk[FormulKayitDolu])
A8: H03 | B8: Toplam sağım lt | C8: =SUM(tblGunluk[SagimLt_lt])
A9: H04 | B9: Toplam yem kg | C9: =SUM(tblGunluk[YemKg_kg])
A10: H05 | B10: Toplam sapma lt | C10: =SUM(tblGunluk[FormulSapma_lt])
A11: H06 | B11: Ort hedef lt | C11: =IFERROR(AVERAGE(tblGunluk[FormulHedef_lt]),0)
A12: H07 | B12: Ort sağım lt | C12: =IFERROR(AVERAGEIF(tblGunluk[SagimLt_lt],">0"),0)
A13: H08 | B13: Sapma oranı | C13: =IFERROR(C10/MAX(C11,1),0)
A14: H09 | B14: Net sağım | C14: =SUM(tblGunluk[SagimLt_lt])
A15: H10 | B15: Aktif inek adet | C15: =COUNTIF(tblVarliklar[Aktif],"EVET")
A16: H11 | B16: Toplam inek kart | C16: =COUNTA(tblVarliklar[VarlikId])
A17: H12 | B17: Alarm adet | C17: =COUNTIF(tblGunluk[AlarmBayrak],"ALARM")
A18: H13 | B18: Yetim kayıt | C18: =COUNTIF(tblGunluk[FormulYetim],"YETIM")
A19: H14 | B19: Ortalama sağlık skor | C19: =IFERROR(AVERAGEIF(tblGunluk[SaglikSkor_puan],">0"),0)
A20: H15 | B20: Min sağlık skor | C20: =IFERROR(MIN(tblGunluk[SaglikSkor_puan]),0)
A21: H16 | B21: Sağım eşik altı adet | C21: =COUNTIFS(tblGunluk[SagimLt_lt],"<"&ssy_esikSagimLt,tblGunluk[FormulKayitDolu],">0")
A22: H17 | B22: Buzağı yakın adet | C22: =COUNTIFS(tblGunluk[GebelikGun_gun],">="&ssy_esikBuzagiGun,tblGunluk[FormulKayitDolu],">0")
A23: H18 | B23: Düşük sağlık adet | C23: =COUNTIFS(tblGunluk[SaglikSkor_puan],"<"&ssy_esikSaglik,tblGunluk[FormulKayitDolu],">0")
A24: H19 | B24: Günlük sağım ort | C24: =IFERROR(AVERAGEIF(tblGunluk[SagimLt_lt],">0"),0)
A25: H20 | B25: Aylık süt proxy | C25: =C8*ssy_aylikCarpan
A26: H21 | B26: Sağım sapma abs | C26: =IFERROR(ABS(C12-ssy_esikSagimLt),0)
A27: H22 | B27: Sağım olay pay | C27: =IFERROR(COUNTIF(tblGunluk[OlayTuru],"SAGIM")/MAX(C7,1),0)
A28: H23 | B28: Kızgınlık olay pay | C28: =IFERROR(COUNTIF(tblGunluk[OlayTuru],"KIZGINLIK")/MAX(C7,1),0)
A29: H24 | B29: Tohum olay pay | C29: =IFERROR(COUNTIF(tblGunluk[OlayTuru],"TOHUM")/MAX(C7,1),0)
A30: H25 | B30: Buzağılama olay pay | C30: =IFERROR(COUNTIF(tblGunluk[OlayTuru],"BUZAGILAMA")/MAX(C7,1),0)
A31: H26 | B31: Temkinli senaryo | C31: =C8*ssy_senaryoTemkinli
A32: H27 | B32: Baz senaryo | C32: =C8*ssy_senaryoBaz
A33: H28 | B33: İyimser senaryo | C33: =C8*ssy_senaryoIyimser
A34: H29 | B34: Senaryo farkı | C34: =C33-C31
A35: H30 | B35: Tornado sağım etki | C35: =C8*ssy_tornadoOran
A36: H31 | B36: Tornado yem etki | C36: =C9*ssy_tornadoOran
A37: H32 | B37: Tornado sapma etki | C37: =ABS(C10)*ssy_tornadoOran
A38: H33 | B38: Tornado zirve | C38: =MAX(C35,C36,C37)
A39: H34 | B39: HHI proxy | C39: =IFERROR(C27^2+C28^2+C29^2+C30^2,0)
A40: H35 | B40: Kalite skor | C40: =MAX(0,ssy_kaliteTaban-C21*ssy_kaliteCeza-C22*ssy_kaliteSapma-C23*ssy_kaliteSapma)
A41: H36 | B41: Tahmin aralık | C41: =C32*ssy_tahminCarpan
A42: H37 | B42: P90 sağım | C42: =IFERROR(PERCENTILE(tblGunluk[SagimLt_lt],ssy_percentileOran),C8*ssy_yuzdelikOran)
...

Sheet ALARMLAR
A1: ALARMLAR — Süt Sürüsü Yönetim Komutası
A3: Alarm listesi — varlık + eşik + süre (S05)
A5: Varlık | B5: Alarm | C5: Eşik | D5: Süre / Tarih | E5: Ort Sağım lt | F5: Sağlık Skor
A6: INK-00001 | B6: =IF(OR(COUNTIFS(tblGunluk[VarlikId],A6,tblGunluk[AlarmBayrak],"ALARM")>0,IFERROR(SUMIF(tblVarliklar[VarlikId],A6,tblVarliklar[SaglikSkor]),100)<ssy_esikSaglik),"ALARM","YOK") | C6: =IFERROR(ABS(E6-ssy_esikSagimLt),0) | D6: =raporTarihi | E6: =IFERROR(SUMIF(tblVarliklar[VarlikId],A6,tblVarliklar[OrtSagimLt]),0) | F6: =IFERROR(SUMIF(tblVarliklar[VarlikId],A6,tblVarliklar[SaglikSkor]),0)
A7: INK-00002 | B7: =IF(OR(COUNTIFS(tblGunluk[VarlikId],A7,tblGunluk[AlarmBayrak],"ALARM")>0,IFERROR(SUMIF(tblVarliklar[VarlikId],A7,tblVarliklar[SaglikSkor]),100)<ssy_esikSaglik),"ALARM","YOK") | C7: =IFERROR(ABS(E7-ssy_esikSagimLt),0) | D7: =raporTarihi | E7: =IFERROR(SUMIF(tblVarliklar[VarlikId],A7,tblVarliklar[OrtSagimLt]),0) | F7: =IFERROR(SUMIF(tblVarliklar[VarlikId],A7,tblVarliklar[SaglikSkor]),0)
A8: INK-00003 | B8: =IF(OR(COUNTIFS(tblGunluk[VarlikId],A8,tblGunluk[AlarmBayrak],"ALARM")>0,IFERROR(SUMIF(tblVarliklar[VarlikId],A8,tblVarliklar[SaglikSkor]),100)<ssy_esikSaglik),"ALARM","YOK") | C8: =IFERROR(ABS(E8-ssy_esikSagimLt),0) | D8: =raporTarihi | E8: =IFERROR(SUMIF(tblVarliklar[VarlikId],A8,tblVarliklar[OrtSagimLt]),0) | F8: =IFERROR(SUMIF(tblVarliklar[VarlikId],A8,tblVarliklar[SaglikSkor]),0)
A9: INK-00004 | B9: =IF(OR(COUNTIFS(tblGunluk[VarlikId],A9,tblGunluk[AlarmBayrak],"ALARM")>0,IFERROR(SUMIF(tblVarliklar[VarlikId],A9,tblVarliklar[SaglikSkor]),100)<ssy_esikSaglik),"ALARM","YOK") | C9: =IFERROR(ABS(E9-ssy_esikSagimLt),0) | D9: =raporTarihi | E9: =IFERROR(SUMIF(tblVarliklar[VarlikId],A9,tblVarliklar[OrtSagimLt]),0) | F9: =IFERROR(SUMIF(tblVarliklar[VarlikId],A9,tblVarliklar[SaglikSkor]),0)
A10: INK-00005 | B10: =IF(OR(COUNTIFS(tblGunluk[VarlikId],A10,tblGunluk[AlarmBayrak],"ALARM")>0,IFERROR(SUMIF(tblVarliklar[VarlikId],A10,tblVarliklar[SaglikSkor]),100)<ssy_esikSaglik),"ALARM","YOK") | C10: =IFERROR(ABS(E10-ssy_esikSagimLt),0) | D10: =raporTarihi | E10: =IFERROR(SUMIF(tblVarliklar[VarlikId],A10,tblVarliklar[OrtSagimLt]),0) | F10: =IFERROR(SUMIF(tblVarliklar[VarlikId],A10,tblVarliklar[SaglikSkor]),0)
A11: INK-00006 | B11: =IF(OR(COUNTIFS(tblGunluk[VarlikId],A11,tblGunluk[AlarmBayrak],"ALARM")>0,IFERROR(SUMIF(tblVarliklar[VarlikId],A11,tblVarliklar[SaglikSkor]),100)<ssy_esikSaglik),"ALARM","YOK") | C11: =IFERROR(ABS(E11-ssy_esikSagimLt),0) | D11: =raporTarihi | E11: =IFERROR(SUMIF(tblVarliklar[VarlikId],A11,tblVarliklar[OrtSagimLt]),0) | F11: =IFERROR(SUMIF(tblVarliklar[VarlikId],A11,tblVarliklar[SaglikSkor]),0)
A12: INK-00007 | B12: =IF(OR(COUNTIFS(tblGunluk[VarlikId],A12,tblGunluk[AlarmBayrak],"ALARM")>0,IFERROR(SUMIF(tblVarliklar[VarlikId],A12,tblVarliklar[SaglikSkor]),100)<ssy_esikSaglik),"ALARM","YOK") | C12: =IFERROR(ABS(E12-ssy_esikSagimLt),0) | D12: =raporTarihi | E12: =IFERROR(SUMIF(tblVarliklar[VarlikId],A12,tblVarliklar[OrtSagimLt]),0) | F12: =IFERROR(SUMIF(tblVarliklar[VarlikId],A12,tblVarliklar[SaglikSkor]),0)
A13: INK-00008 | B13: =IF(OR(COUNTIFS(tblGunluk[VarlikId],A13,tblGunluk[AlarmBayrak],"ALARM")>0,IFERROR(SUMIF(tblVarliklar[VarlikId],A13,tblVarliklar[SaglikSkor]),100)<ssy_esikSaglik),"ALARM","YOK") | C13: =IFERROR(ABS(E13-ssy_esikSagimLt),0) | D13: =raporTarihi | E13: =IFERROR(SUMIF(tblVarliklar[VarlikId],A13,tblVarliklar[OrtSagimLt]),0) | F13: =IFERROR(SUMIF(tblVarliklar[VarlikId],A13,tblVarliklar[SaglikSkor]),0)
A16: Alarm Özeti | B16: =ssy_alarmListesi
A18: Toplam Alarm Satır | B18: =COUNTIF(B6:B13,"ALARM")

Sheet RAPOR
A1: RAPOR — Süt Sürüsü Yönetim Komutası
A3: Dönemsel yönetim raporu — yazdırılabilir kanıt
A5: Ürün | B5: Süt Sürüsü Yönetim Komutası
A6: Sürüm | B6: 1.0.0
A7: Rapor Tarihi | B7: =raporTarihi
A8: Firma | B8: =ssy_firmaUnvan
A10: KARAR | B10: =ssy_kararKapi
A11: Ort Sağım lt | B11: =ssy_gunlukSagimOrt
A12: Toplam Sağım lt | B12: =ssy_sagimToplam
A13: Toplam Yem kg | B13: =ssy_yemToplam
A14: Sağlık Skor | B14: =ssy_saglikSkor
A15: Alarm Adet | B15: =ssy_alarmAdet
A17: Kalem | B17: Değer
A18: Sağım sapma | B18: =ssy_sagimSapma
A19: Sapma oranı | B19: =ssy_sapmaOran
A20: Günlük sağım ort | B20: =ssy_gunlukSagimOrt
A21: Kalite skor | B21: =ssy_kaliteSkor
A24: Varsayımlar
A25: Sağım sapması = günlük sağım − inek hedefi. Eşikler AYARLAR'dan gelir. Gebelik ≥ eşik günü buzağılama yakın alarmı üretir. Karar destek çıktısıdır; veteriner veya mali tavsiye değildir.
A28: İmza — Sürü Yöneticisi | C28: ________________
A29: İmza — Çiftlik Sahibi / Denetçi | C29: ________________
A31: SHA notu: sevk paketinde SHA-256 yer alır | 1.0.0

Sheet KONTROLLER
A1: KONTROLLER — Süt Sürüsü Yönetim Komutası
A3: Canlı sağlık kontrolleri — formülle
A5: Kontrol | B5: Sonuç | C5: Değer
A6: Dolu kayıt > 0 | B6: =IF(ssy_doluKayit>0,"GEÇTİ","KALDI") | C6: =ssy_doluKayit
A7: Yetim kayıt = 0 | B7: =IF(ssy_yetimAdet=0,"GEÇTİ","UYARI") | C7: =ssy_yetimAdet
A8: Sağım hesaplı | B8: =IF(ssy_sagimToplam>=0,"GEÇTİ","KALDI") | C8: =ssy_sagimToplam
A9: Sağlık skor formül | B9: =IF(ssy_saglikSkor>=0,"GEÇTİ","KALDI") | C9: =ssy_saglikSkor
A10: Alarm listesi | B10: =IF(ssy_alarmAdet>=0,"GEÇTİ","KALDI") | C10: =ssy_alarmAdet
A11: Karar dolu | B11: =IF(ssy_kararKapi<>"","GEÇTİ","KALDI") | C11: =ssy_kararKapi
A12: 12 ay sezonsal | B12: =IF(DONEM_ANALIZ!B22>=0,"GEÇTİ","KALDI") | C12: =DONEM_ANALIZ!B22
A13: Kalite skor | B13: =IF(ssy_kaliteSkor>=0,"GEÇTİ","KALDI") | C13: =ssy_kaliteSkor
A14: Tornado | B14: =IF(ssy_tornadoZirve>=0,"GEÇTİ","KALDI") | C14: =ssy_tornadoZirve
A15: P90 | B15: =IF(ssy_yuzdelikP90>=0,"GEÇTİ","KALDI") | C15: =ssy_yuzdelikP90

Sheet ORNEK_VERI
A1: ORNEK VERI — Süt Sürüsü Yönetim Komutası
A3: Örnek günlük satırlar — kopyalanabilir referans
A5: SatirId | B5: VarlikId | C5: Tarih | D5: SagimLt_lt | E5: YemKg_kg | F5: KizginlikDurum | G5: GebelikGun_gun | H5: OlayTuru
A6: SSY-00001 | B6: INK-00001 | C6: 46242 | D6: 24.6 | E6: 16.5 | F6: HAYIR | G6: 51 | H6: KIZGINLIK
A7: SSY-00002 | B7: INK-00002 | C7: 46239 | D7: 21.8 | E7: 16.9 | F7: HAYIR | G7: 62 | H7: TOHUM
A8: SSY-00003 | B8: INK-00003 | C8: 46236 | D8: 28.2 | E8: 18.6 | F8: HAYIR | G8: 73 | H8: GEBELIK
A9: SSY-00004 | B9: INK-00004 | C9: 46233 | D9: 17.5 | E9: 17.8 | F9: HAYIR | G9: 84 | H9: BUZAGILAMA
A10: SSY-00005 | B10: INK-00005 | C10: 46230 | D10: 22.1 | E10: 19.3 | F10: HAYIR | G10: 95 | H10: DIGER
A11: SSY-00006 | B11: INK-00006 | C11: 46227 | D11: 22 | E11: 15.3 | F11: HAYIR | G11: 106 | H11: SAGIM
A12: SSY-00007 | B12: INK-00007 | C12: 46224 | D12: 29.1 | E12: 17.2 | F12: EVET | G12: 117 | H12: KIZGINLIK
A13: SSY-00008 | B13: INK-00008 | C13: 46221 | D13: 18.8 | E13: 16.4 | F13: HAYIR | G13: 128 | H13: TOHUM
A14: SSY-00009 | B14: INK-00001 | C14: 46218 | D14: 27.2 | E14: 18.5 | F14: HAYIR | G14: 0 | H14: GEBELIK
A15: SSY-00010 | B15: INK-00002 | C15: 46215 | D15: 20.4 | E15: 18.3 | F15: HAYIR | G15: 150 | H15: BUZAGILAMA
A16: SSY-00011 | B16: INK-00003 | C16: 46212 | D16: 26.4 | E16: 20 | F16: HAYIR | G16: 161 | H16: DIGER
A17: SSY-00012 | B17: INK-00004 | C17: 46209 | D17: 9.9 | E17: 13.5 | F17: HAYIR | G17: 172 | H17: SAGIM
... A25: SSY-00020 | B25: INK-00004 | C25: 46185 | D25: 15.3 | E25: 15.9 | F25: HAYIR | G25: 260 | H25: TOHUM

Sheet LISTELER
A1: LISTELER — Süt Sürüsü Yönetim Komutası
A3: Evet / Hayır | C3: Olay Türü | E3: Irk
A6: Secim | C6: Tur | E6: Irk
A7: EVET | C7: SAGIM | E7: Holstein
A8: HAYIR | C8: KIZGINLIK | E8: Simental
C9: TOHUM | E9: Jersey
C10: GEBELIK
C11: BUZAGILAMA
C12: DIGER

Sheet AYARLAR
A1: AYARLAR — Süt Sürüsü Yönetim Komutası
A3: Tek kaynak parametreler + alarm eşikleri (S05)
A5: anahtar | B5: deger | C5: birim | D5: kaynak | E5: yururluk_tarihi | F5: aciklama
A6: raporTarihi | B6: 46245 | C6: tarih | D6: Kullanıcı / dönem kapanışı | E6: 01.01.2026 | F6: Rapor tarihi (TODAY yok)
A7: ssy_varsayilanHedefLt | B7: 24 | C7: lt | D7: Sürü hedef / laktasyon | E7: 01.01.2026 | F7: Varsayılan günlük hedef sağım lt
A8: ssy_esikSagimLt | B8: 18 | C8: lt | D8: Alarm eşiği — sağım | E8: 01.01.2026 | F8: Günlük sağım alt alarm eşiği
A9: ssy_esikBuzagiGun | B9: 270 | C9: gun | D9: Alarm eşiği — buzağılama | E9: 01.01.2026 | F9: Gebelik günü buzağı yakın eşiği
A10: ssy_esikSaglik | B10: 60 | C10: puan | D10: Alarm eşiği — sağlık skor | E10: 01.01.2026 | F10: Sağlık skor alt eşiği
A11: ssy_azamiSagimLt | B11: 80 | C11: lt | D11: Alarm eşiği — azami sağım | E11: 01.01.2026 | F11: Günlük sağım üst (uç değer) eşiği
A12: ssy_aylikCarpan | B12: 1 | C12: oran | D12: Aylık proxy | E12: 01.01.2026 | F12: Aylık süt çarpan
A13: ssy_senaryoTemkinli | B13: 0.9 | C13: oran | D13: Senaryo motoru | E13: 01.01.2026 | F13: Temkinli çarpan
A14: ssy_senaryoBaz | B14: 1 | C14: oran | D14: Senaryo motoru | E14: 01.01.2026 | F14: Baz çarpan
A15: ssy_senaryoIyimser | B15: 1.1 | C15: oran | D15: Senaryo motoru | E15: 01.01.2026 | F15: İyimser çarpan
A16: ssy_tornadoOran | B16: 0.08 | C16: oran | D16: Duyarlılık | E16: 01.01.2026 | F16: Tornado etki oranı
A17: ssy_yuzdelikOran | B17: 1.15 | C17: oran | D17: İstatistik kuralı | E17: 01.01.2026 | F17: P90 çarpan proxy
... A23: ssy_kaliteSapma | B23: 3 | C23: puan | D23: Kalite / sağlık modeli | E23: 01.01.2026 | F23: Sapma / alarm cezası
A24: ssy_dosyaSurumu | B24: 1.0.0 | C24: metin | D24: Sürüm yönetimi | E24: 01.01.2026 | F24: Ürün sürümü
A25: ssy_firmaUnvan | B25: Örnek Süt Çiftliği Ltd. | C25: metin | D25: Kullanıcı girişi | E25: 01.01.2026 | F25: Firma unvanı
A26: ssy_alarmEsikMetin | B26: Sağım / buzağı / sağlık eşikleri | C26: metin | D26: S05 alarm | E26: 01.01.2026 | F26: Alarm eşiği tanımı
A27: ssy_sutFiyatTlLt | B27: 14.5 | C27: TL/lt | D27: İç süt fiyatı | E27: 01.01.2026 | F27: Süt birim değeri TL/lt (iç)
A28: ssy_kizginlikDongu | B28: 21 | C28: gun | D28: Kızgınlık döngüsü | E28: 01.01.2026 | F28: Tipik kızgınlık döngü günü
A29: ssy_gebelikSure | B29: 280 | C29: gun | D29: Gebelik süresi | E29: 01.01.2026 | F29: Tipik gebelik süresi gün
H30: Motor Çıktıları
H31: anahtar | I31: deger
H32: ssy_doluKayit | I32: =HESAP!C7
H33: ssy_sagimToplam | I33: =HESAP!C8
H34: ssy_yemToplam | I34: =HESAP!C9
H35: ssy_gunlukSagimOrt | I35: =HESAP!C12
H36: ssy_sagimSapma | I36: =HESAP!C10
H37: ssy_sapmaOran | I37: =HESAP!C13
H38: ssy_aylikSutTrend | I38: =HESAP!C25
H39: ssy_saglikSkor | I39: =HESAP!C19
H40: ssy_alarmAdet | I40: =HESAP!C17
H41: ssy_yetimAdet | I41: =HESAP!C18
H42: ssy_buzagiYakinAdet | I42: =HESAP!C22
H43: ssy_tornadoZirve | I43: =HESAP!C38
H44: ssy_senaryoKarsilastirma | I44: =HESAP!C34
H45: ssy_hhi | I45: =HESAP!C39
H46: ssy_kaliteSkor | I46: =HESAP!C40
H47: ssy_senaryoMotor | I47: =HESAP!C43
...

Sheet KILAVUZ
A1: KILAVUZ — Süt Sürüsü Yönetim Komutası
A3: Kullanım Kılavuzu
A5: 1. VARLIKLAR sayfasına inek kartı ekleyin; sonraki kimliği kullanın.
A6: 2. GUNLUK_GIRIS: varlık, tarih, sağım lt, yem kg, kızgınlık, gebelik gün, olay (≤6 manuel alan).
A7: 3. Sağım sapması = günlük sağım − inek hedefi; sağlık skoru formülle türer.
A8: 4. DONEM_ANALIZ 12 aylık sezonsal süt-buzağılama zincirini gösterir.
