Workbook
Name raporTarihi: AYARLAR!$B$6
Name zincirTolerans: AYARLAR!$B$7
Name kad_esikGecikmeGun: AYARLAR!$B$8
Name kad_esikGeciken: AYARLAR!$B$9
Name kad_gecikmeOranGun: AYARLAR!$B$10
Name kad_senaryoTemkinli: AYARLAR!$B$11
Name kad_senaryoBaz: AYARLAR!$B$12
Name kad_senaryoIyimser: AYARLAR!$B$13
Name kad_tornadoOran: AYARLAR!$B$14
Name kad_yuzdelikOran: AYARLAR!$B$15
Name kad_olcekHedef: AYARLAR!$B$16
Name kad_azamiTutar: AYARLAR!$B$17
Name kad_mahsupTolerans: AYARLAR!$B$18
Name kad_durumHaritasi: AYARLAR!$B$19
Name kad_kuyrukOzeti_metin: AYARLAR!$B$20
Name kad_kapaliDusum_metin: AYARLAR!$B$21
Name kad_kanitRaporu_metin: AYARLAR!$B$22
Name kad_dosyaSurumu: AYARLAR!$B$23
Name kad_malikAdi: AYARLAR!$B$24
Name kad_acikAdet: AYARLAR!$I$40
Name kad_acikTutar: AYARLAR!$I$41
Name kad_gecikenAdet: AYARLAR!$I$42
Name kad_gecikmeMaliyeti: AYARLAR!$I$43
Name kad_yetimKayit: AYARLAR!$I$44
Name kad_gecersizGecis: AYARLAR!$I$45
Name kad_zincirKirik: AYARLAR!$I$46
Name kad_yasKova: AYARLAR!$I$47
Name kad_tahminAralik: AYARLAR!$I$48
Name kad_senaryoKarsilastirma: AYARLAR!$I$49
Name kad_tornadoZirve: AYARLAR!$I$50
Name kad_odemeOncelik: AYARLAR!$I$51
Name kad_paretoGecikme: AYARLAR!$I$52
Name kad_kapaliDusum: AYARLAR!$I$53
Name kad_kuyrukOzeti: AYARLAR!$I$54
Name kad_kanitRaporu: AYARLAR!$I$55
Name kad_sonrakiKimlik: AYARLAR!$I$56
Name kad_avansMahsup: AYARLAR!$I$57
Name kad_modulO8: AYARLAR!$I$58
Name kad_modulI2: AYARLAR!$I$59
Name kad_yorumYas: AYARLAR!$I$63
Name kad_yorumGecikme: AYARLAR!$I$64
Name kad_yorumTahmin: AYARLAR!$I$65
Name kad_yorumSenaryo: AYARLAR!$I$66
Name kad_yorumTornado: AYARLAR!$I$67
Name kad_yorumOncelik: AYARLAR!$I$68
Name kad_yorumPareto: AYARLAR!$I$69
Name kad_modulO8Yorum: AYARLAR!$I$70
Name kad_modulI2Yorum: AYARLAR!$I$71
Name kad_kararKapi: PANO!$B$4
Name kad_dekont: DEKONT!$A$20
Name ListeDurumlar: LISTELER!$A$7:$A$11
Name ListeIzinliGecis: LISTELER!$C$7:$C$11
Name ListeEvetHayir: LISTELER!$E$7:$E$8
Name ListeKartlar: LISTELER!$I$7:$I$14

Sheet 00_BASLANGIC
A1: EXCELARŞİV KARAR SİSTEMİ v15.1 — ÜRETİM REFERANSI
A3: Konu | B3: Bağlayıcı Standart
A4: Amaç | B4: Kanıta dayalı, hatada kapalı çalışan Excel üretim ve denetim sistemi
A5: Öncelik | B5: Kullanıcının açık iş talebi ve gerçek kullanım senaryosu
A6: Ana akış | B6: Uygunluk → Yönetişim → Sözleşmeler → Üretim → Test → Kanıt → Kullanıcı Kabulü → Yayın
A7: Yayın ilkesi | B7: Üst aşamada hata varsa alt aşama GEÇTİ üretilemez
A8: Kullanıcı kabulü | B8: Excel masaüstü görünümü test edilmediyse DIŞ_KABUL_GEREKLİ
A9: Nihai yayın | B9: Yalnız uygulanabilir modüller GEÇTİ veya gerekçeli UYGULANMAZ
A10: Ticari ayrım | B10: Ekonomik olarak savunulabilir fiyat, gerçek pazar kabulü ile aynı değildir
A11: Karmaşıklık | B11: Karar değeri, eklenen karmaşıklığın maliyetinden büyük olmalıdır
A12: Excel sınırı | B12: Veritabanı, kurumsal yetkilendirme, değiştirilemez kayıt sistemi veya gerçek zamanlı olay platformu değildir
A13: Dil standardı | B13: Kullanıcıya görünen tüm sayfa, tablo, başlık, açıklama, uyarı ve karar metinleri saf Türkçe olmalıdır
A14: Muhasebe standardı | B14: Finansal ürünlerde Türkiye Tekdüzen Hesap Planı ve Türk muhasebe kullanım alışkanlıkları esas alınır
... A33: Muhasebe | B33: Türkiye Tekdüzen Hesap Planı ve Türk muhasebe/işletme düşünce yapısı esas alınır.

Sheet PANO
A1: ☰ PANO
B2: KIRA AVANS TAKIP DEKONT — YÖNETİM VE KARAR SİSTEMİ | L2: Dönem: 2026 / Tam ▼ | M2: ★ DOĞRULANMIŞ
B3: Yönetici Karar Kokpiti, Otomatik Doğrulama ve Dinamik Hesaplama Sistemi · 2026
B5: TOPLAM İŞLEM HACMİ | D5: DOĞRULANMIŞ | E5: RİSKLİ / BEKLEYEN İŞLEM | G5: MİNİMUM | H5: OPERASYONEL NET MARJ | J5: GÜVENLİ | K5: SİSTEM GÜVEN SKORU | M5: DENETLENDİ
B7: ₺28.450.000 | E7: ₺940.000 | H7: ₺8.120.000 | K7: 98/100
B9: ↑ Konsolide yıllıklandırılmış büyüme | E9: ● Tüm riskli kayıtlar kontrol altında | H9: ██████████░░░░░ %28.5 NET MARJ | K9: ✓ 0 Formül ve Döngüsel Hata
B11: 12 AYLIK NAKİT GİRİŞ / ÇIKIŞ & LİKİDİTE BAŞARIMI | F11: +%32 Verim | H11: KONSOLİDE OPERASYON VE KARAR MATRİSİ
B12: Kümülatif Tahsilat vs. Tedarikçi/Kredi Ödeme Projeksiyonu | H12: Anlık Hesaplama Sonuçları, Dinamik Formül Çıktıları ve Durum Puanlaması
B14: Dönem | C14: Aktif Hacim | D14: Maliyet/Yük | E14: Hedef | H14: PARAMETRE / KALEM | I14: ANA TUTAR | J14: FARK / MARJ | K14: VADE | L14: KONTROL DURUMU
B15: D1 | C15: 65 | D15: 45 | E15: 60 | H15: 13 haftalık kümülatif bakiye... | I15: ₺8.450.000 | J15: ₺425.000 | K15: 12 Ay | L15: ✓ DÜZENLİ
B16: D2 | C16: 78 | D16: 48 | E16: 70 | H16: Kritik (eksi) hafta uyarısı | I16: ₺12.200.000 | J16: ₺580.400 | K16: 24 Ay | L16: ★ AVANTAJ
B17: D3 | C17: 85 | D17: 55 | E17: 80 | H17: Dönem net nakit değişimi | I17: ₺4.850.000 | J17: ₺235.200 | K17: 8 Ay | L17: ● YAKLAŞAN
B18: D4 | C18: 75 | D18: 42 | E18: 75 | H18: 13 haftalık kümülatif bakiye... | I18: ₺2.140.000 | J18: ₺118.000 | K18: 16 Ay | L18: ✓ TAM UYUM
B19: D5 | C19: 90 | D19: 40 | E19: 85 | H19: KONSOLİDE SİSTEM TOPLAMI | I19: ₺42.850.000 | J19: ₺3.420.000 | L19: TAM DOĞRULANDI (0 HATA)
B20: D6 | C20: 96 | D20: 32 | E20: 92
B22: KONSOLİDE PAY VE AĞIRLIK | F22: LİKİDİTE RİSKİ & ERKEN UYARI SİNYALLERİ | K22: KARAR MOTORU
B23: ■ Ana Segment (%42) | F23: Nakit Açığı Riski (30 Gün) | I23: 0.00 TL (Sıfır Risk) | K23: OPERASYONEL VERİMLİLİK FIRSATI
B24: ■ İkincil Grup (%30) | F24: Tahsilat Gecikme Toleransı | I24: 48 Gün Güvenli Eşik | K24: Süreç optimizasyonuyla birim operasyonel maliyeti düşürme potansiyeli mevcuttur.
B25: ■ Destek Birimi (%15) | F25: ██████████████████████████████████████ Güvenli Bölge (%100)
B26: ■ Rezervler (%13) | F26: ✓ 90 GÜNLÜK PROJEKSİYONDA NAKİT SIKIŞIKLIĞI TESPİT EDİLMEDİ | K26: STRATEJİ REÇETESİNİ İNCELE >

Sheet GİRDİLER
A1: ☰ PANO
B3: 🔍 Kayıt veya hesap ara... | G3: TOPLAM: 1.450 KAYIT | I3: HATALI HÜCRE: 0 ADET
B5: TARİH | C5: REFERANS NO | D5: İŞLEM AÇIKLAMASI VE DETAY | E5: BRÜT TUTAR (₺) | F5: KDV ORANI | G5: NET TUTAR (₺) | H5: HESAP / CARİ | I5: DURUM
B6: 12.10.2026 | C6: TR-0428-A | D6: Haftalık operasyon tahmini | E6: 845200 | F6: 0.2 | G6: =E6/(1+F6) | H6: Vadesiz Ticari | I6: ONAYLANDI
B7: 14.10.2026 | C7: TR-0429-B | D7: Haftalık operasyon tahmini | E7: 1240000 | F7: 0.2 | G7: =E7/(1+F7) | H7: Tedarikçi Havuzu | I7: BEKLEMEDE
B8: 18.10.2026 | C8: TR-0430-C | D8: Ödeme takvimi notları | E8: 620500 | F8: 0.1 | G8: =E8/(1+F8) | H8: Kısa Vade Tahakkuk | I8: ONAYLANDI
B9: 21.10.2026 | C9: TR-0431-D | D9: Haftalık operasyon tahmini | E9: 415000 | F9: 0.2 | G9: =E9/(1+F9) | H9: Müşteri Alacağı | I9: ONAYLANDI
B10: 25.10.2026 | C10: TR-0432-E | D10: Haftalık operasyon tahmini | E10: 980400 | F10: 0.2 | G10: =E10/(1+F10) | H10: Vadesiz Ticari | I10: ONAYLANDI
B11: 28.10.2026 | C11: TR-0433-F | D11: Haftalık operasyon tahmini | E11: 1850000 | F11: 0.2 | G11: =E11/(1+F11) | H11: Banka Kredi Taksiti | I11: BLOKE
B12: 02.11.2026 | C12: TR-0434-G | D12: Ödeme takvimi notları | E12: 740000 | F12: 0.2 | G12: =E12/(1+F12) | H12: Kira & Sabit Gider | I12: ONAYLANDI
B13: 05.11.2026 | C13: TR-0435-H | D13: Haftalık operasyon tahmini | E13: 520800 | F13: 0.2 | G13: =E13/(1+F13) | H13: Vadesiz Ticari | I13: ONAYLANDI
B14: 09.11.2026 | C14: TR-0436-I | D14: Haftalık operasyon tahmini | E14: 1120000 | F14: 0.2 | G14: =E14/(1+F14) | H14: Müşteri Alacağı | I14: ONAYLANDI
B15: 12.11.2026 | C15: TR-0437-J | D15: Haftalık operasyon tahmini | E15: 890000 | F15: 0.2 | G15: =E15/(1+F15) | H15: Tedarikçi Havuzu | I15: ONAYLANDI
B17: SAYFA TOPLAMI (10 / 1.450 KAYIT) | E17: =TOPLA(E6:E15)

Sheet YÖNETİM_RAPORU
A1: ☰ PANO
B2: KIRA AVANS TAKIP DEKONT — YÖNETİM VE KARAR SİSTEMİ — NİHAİ KARAR VE DEĞERLEME
B3: Yönetim Kurulu ve İcra Komitesi için Otomatik Türetilen Finansal Stres Testi Raporu
B4: DÖNEM: 2026 Q3 · DENETİM PROTOKOLÜ: ISO/VUK/IFRS UYUMLU · DURUM: ONAYLANDI
B6: SENARYO A: KÖTÜMSER (STRES TESTİ -%20) | H6: SENARYO B: BAZ MODEL (HEDEFLENEN)
B8: Ciro / Hacim Düşüşü: | E8: -%20.0 (Kriz Eşiği) | H8: Ciro / Hacim Gerçekleşmesi: | K8: %100.0 (Tam Bütçe)
B9: Beklenen Net Kâr / Getiri: | E9: ₺4.280.000 | H9: Beklenen Net Kâr / Getiri: | K9: ₺12.450.000
B10: Minimum Nakit Tamponu: | E10: ₺1.850.000 (Yeterli) | H10: Serbest Nakit Akımı: | K10: ₺8.240.000
B11: Likidite Karşılama Oranı: | E11: 1.28x (Eşik: 1.10x) | H11: Yatırım Geri Dönüşü (ROI): | K11: %38.4 Yıllık
B14: STRES SENARYOSUNDA DAHİ İFLAS RİSKİ YOK | H14: OPTİMUM İCRA VE PLANLAMA REÇETESİ
B17: YÖNETİM KARAR MATRİSİ VE UYGULAMA REÇETESİ
B19: ● Öncelik 1: Acil Likidite ve Borç Servis Planlaması
B20: Sistemde hesaplanan vade günlerine sadık kalınarak nakit blokajı 3 gün önceden hazır edilmelidir.
B21: ● Öncelik 2: Formül Doğrulama ve Çapraz Sağlama
B22: Tüm hücreler kilitli formül korumasında olup girdi sayfalarında sıfır döngüsel başvuru (circular ref) garantilidir.
B23: ● Öncelik 3: Resmi Mevzuat ve Vergi Kalkanı Entegrasyonu
B24: 2026 güncel vergi dilimleri, amortisman ve SGK teşvik parametreleri tam otomatik yansıtılmaktadır.
B25: ● Öncelik 4: Yönetici İmzası ve Rapor Paylaşımı
B26: Tek tuşla PDF ve A4 çıktı formatına tam uyumlu sayfa yapısı kurgulanmıştır.

Sheet 01_YURUTME_CEKIRDEGI
A1: YÜRÜTME ÇEKİRDEĞİ — ZORUNLU ÜRETİM SIRASI
A3: Adım | B3: Modül | C3: Tetikleyici | D3: Zorunlu Kanıt | E3: GEÇTİ Kuralı | F3: Hata Durumu | G3: Sonraki Aşama
A4: 1 | B4: Excel Uygunluğu | C4: Her yeni model | D4: UYGUNLUK_KARARI | E4: Excel'in rolü açık | F4: HATA / BLOKE | G4: Yönetişim
A5: 2 | B5: Yönetişim | C5: Her model | D5: Risk seviyesi + etki girdileri | E5: Seviye hesaplandı | F5: BLOKE | G5: Sözleşmeler
A6: 3 | B6: Türk Muhasebe Eşlemesi | C6: Finansal model | D6: THP hesap eşleme tablosu | E6: Kritik satırlar THP ile uyumlu | F6: HATA | G6: Sözleşmeler
A7: 4 | B7: Veri ve Anlam Sözleşmeleri | C7: Girdi/KPI varsa | D7: Veri + KPI sözleşmeleri | E7: Kapsam %100 | F7: HATA | G7: Üretim
A8: 5 | B8: Üretim | C8: Sözleşmeler GEÇTİ | D8: Çalışan Excel | E8: Tek gerçek kaynak korunmuş | F8: HATA | G8: Testler
A9: 6 | B9: Görsel/Kullanım Katmanı | C9: Motor hazır | D9: Başlıklar + renk + grafik + yönlendirme | E9: Tüm kullanıcı sayfaları standarda uygun | F9: HATA | G9: Testler
A10: 7 | B10: Testler | C10: Üretim tamam | D10: Formül/OOXML/kimlik/oracle/golden/metamorfik | E10: Uygulanabilir hard gate'ler GEÇTİ | F10: HATA | G10: Kanıt
A11: 8 | B11: Hata-Kontrol Tutarlılığı | C11: Test sonucu var | D11: Hata taraması + kontrol sonuçları | E11: Formül hatası varken GEÇTİ yok | F11: HATA | G11: Kanıt
A12: 9 | B12: Kanıt | C12: Test sonucu var | D12: Makine okunur artefakt + özet | E12: Kanıt fiziksel ve tutarlı | F12: HATA | G12: Kullanıcı Kabulü
A13: 10 | B13: Kullanıcı Kabulü | C13: Kritik görevler | D13: Gerçek ekran davranışı | E13: Kritik görevler %100 | F13: DIŞ_KABUL_GEREKLİ | G13: Ticari
A14: 11 | B14: Ticari Değer | C14: Ürün satılacaksa | D14: ROI + demo + kanıt paketi | E14: Ekonomik değer kanıtlı | F14: UYARI / HATA | G14: Pazar Doğrulama
A15: 12 | B15: Pazar Doğrulama | C15: Pazar iddiası varsa | D15: Ücretli satış/pilot/fiyat kabul kanıtı | E15: Gerçek fiyat kabul kanıtı | F15: UYGULANMAZ / HATA | G15: Yayın

Sheet 02_KONTROL_LISTESI
A1: NİHAİ KONTROL LİSTESİ — KANITSIZ GEÇİŞ YOK
A3: Kontrol No | B3: Kontrol | C3: Beklenen | D3: Zorunlu Kapı? | E3: Sonuç
A4: K01 | B4: Kullanıcının açık talebi öncelikli mi? | C4: Evet | D4: EVET
A5: K02 | B5: Mevcut yapı, formüller ve tek gerçek kaynak korunuyor mu? | C5: Evet, değişiklik gerekçeli | D5: EVET
A6: K03 | B6: Üst aşama HATA ise alt aşama GEÇTİ engelleniyor mu? | C6: Evet | D6: EVET
A7: K04 | B7: Kanıt fiziksel çıktı ve içerik doğrulaması içeriyor mu? | C7: Evet | D7: EVET
A8: K05 | B8: Excel GUI erişimi olmadan kullanıcı görünümü GEÇTİ yazılıyor mu? | C8: Hayır | D8: EVET
A9: K06 | B9: NİHAİ yalnız GEÇTİ / gerekçeli UYGULANMAZ ile mi? | C9: Evet | D9: EVET
A10: K07 | B10: Ekonomik fiyat savunusu pazar doğrulamasından ayrılmış mı? | C10: Evet | D10: EVET
A11: K08 | B11: Prestij için gereksiz modül var mı? | C11: Hayır | D11: HAYIR
A12: K09 | B12: Excel sınırları açık mı? | C12: Evet | D12: EVET
A13: K10 | B13: Teknik kaynak korunuyor mu? | C13: Evet | D13: EVET
A14: K11 | B14: Kullanıcıya görünen tüm metinler Türkçe mi? | C14: Evet | D14: EVET
A15: K12 | B15: Her kullanıcı sayfasında üst başlık var mı? | C15: Evet | D15: EVET
... A34: K31 | B34: Premium vitrin, altyapı kadar güçlü ve satış fiyatını destekleyecek seviyede mi? | C34: Evet | D34: EVET

Sheet 03_GORSEL_TASARIM
A1: GÖRSEL TASARIM VE PREMIUM EXCEL STANDARDI
A3: Alan | B3: Zorunlu Kural | C3: Uygulama | D3: Yasak | E3: Kontrol | F3: Durum
A4: Sayfa başlığı | B4: Her kullanıcı sayfasının en üstünde tek ve açık sayfa başlığı | C4: A1'den başlayan koyu lacivert başlık bandı | D4: Başlıksız sayfa | E4: Başlık kapsama = %100 | F4: ZORUNLU
A5: Sekme renkleri | B5: Sayfalar işlevine göre renk kodlanır | C5: Girdi=mavi, hesap=gri, rapor=lacivert, kontrol=kırmızı, kılavuz=altın | D5: Rastgele renk | E5: Renk semantiği tutarlı | F5: ZORUNLU
A6: Kolon düzeni | B6: Veri blokları bitişik kolonlarda ilerler | C6: Gereksiz boş kolon bırakma; yalnız gerçek bölüm ayrımı varsa kontrollü boşluk | D6: A:C veri, D boş, E:F veri gibi parçalı yapı | E6: Boş kolon taraması | F6: ZORUNLU
A7: Girdi hücreleri | B7: Kullanıcının değiştireceği alan açıkça görünür | C7: Açık sarı dolgu + mavi yazı | D7: Formülle aynı görünüm | E7: Girdi/formül ayrımı | F7: ZORUNLU
A8: Formüller | B8: Hesap hücreleri kullanıcı girdisinden ayrılır | C8: Siyah yazı; sayfalar arası bağlantı yeşil yazı | D8: Hard-code gizleme | E8: Formül sınıfı kontrolü | F8: ZORUNLU
A9: Grafik sayısı | B9: Yönetici ekranında en fazla 3 ana karar grafiği | C9: Trend, karşılaştırma, köprü/dağılım; iş kararına bağlı | D9: Grafik kalabalığı | E9: Grafik başına karar sorusu | F9: ZORUNLU
A10: Grafik stili | B10: Kurumsal ve yüksek okunabilirlik | C10: Beyaz zemin, ince gridline, tek vurgu rengi, açık birim/başlık | D10: 3B, gölge, neon, gökkuşağı renkleri | E10: Görsel inceleme | F10: ZORUNLU
A11: Grafik başlığı | B11: Grafik 'neyi' değil 'ne anlama geldiğini' söyler | C11: Örn: 'Nakit 2028'de kritik eşiğin altına iniyor' | D11: 'Nakit Grafiği' gibi anlamsız başlık | E11: Başlık karar testi | F11: ZORUNLU
A12: Birimler | B12: Tüm finansal görsellerde birim açık | C12: TL, bin TL, milyon TL, %, gün, x | D12: Birim belirsizliği | E12: Birim kapsama %100 | F12: ZORUNLU
A13: Sıfır/negatif | B13: Finansal format standardı | C13: Sıfır='-', negatif kırmızı parantez | D13: -500 veya 0,00 kalabalığı | E13: Format kontrolü | F13: ZORUNLU
A14: Yazı tipi | B14: Tek aile | C14: Aptos veya Segoe UI | D14: Karışık font | E14: Tek font kontrolü | F14: ZORUNLU
... A22: Premium vitrin | B22: Görsel kalite ürün değerinin zorunlu parçasıdır | C22: Kaliteli grafik, gerçek KPI kartı, finansal hiyerarşi, tab rengi, fonksiyonel navigasyon | D22: Sadece doğru hesap yapıp çıplak/varsayılan Excel görünümü bırakmak | E22: Görsel release incelemesi | F22: ZORUNLU

Sheet 04_MUHASEBE_THP
A1: TÜRKİYE MUHASEBE VE TEKDÜZEN HESAP PLANI STANDARDI
A3: Konu | B3: Zorunlu Standart | C3: Örnek Türkçe Ad | D3: THP / Mantık | E3: Hata Riski | F3: Kontrol
A4: Dil | B4: Kullanıcıya görünen finansal terimler Türkçe | C4: Hasılat, Satışların Maliyeti, Brüt Kâr, Faaliyet Giderleri | D4: Türk işletme kullanımına uygun | E4: İngilizce jargon | F4: Terminoloji taraması
A5: Gelir Tablosu | B5: Türk sunum sırası kullanılır | C5: Net Satışlar → Satışların Maliyeti → Brüt Kâr → Faaliyet Giderleri → Faaliyet Kârı | D5: 600/610/611; 620-623; 63x | E5: Yanlış sınıflama | F5: Hesap eşleme
A6: Bilanço | B6: Dönen/Duran Varlık ve Kısa/Uzun Vadeli Yükümlülük ayrımı | C6: Hazır Değerler, Ticari Alacaklar, Stoklar, Mali Borçlar | D6: 1xx / 2xx / 3xx / 4xx / 5xx | E6: Vade sınıfı hatası | F6: Bilanço eşitliği
A7: Nakit Akışı | B7: İşletme/Yatırım/Finansman nakit akışları ayrılır | C7: Faaliyetlerden Nakit, Yatırım Harcamaları, Finansman Nakit Akışı | D7: Dolaylı/doğrudan yöntem açık seçilir | E7: Kâr = nakit sanılması | F7: Nakit devri
A8: Ticari Alacaklar | B8: Cari ve vade mantığı korunur | C8: 120 Alıcılar | D8: 120 | E8: Tahakkuk/nakit karışması | F8: Alacak devir kontrolü
A9: Ticari Borçlar | B9: Tedarikçi borcu ayrı izlenir | C9: 320 Satıcılar | D9: 320 | E9: Gider/ödeme karışması | F9: Borç devir kontrolü
A10: Kasa/Banka | B10: Hazır değerler ayrı izlenir | C10: 100 Kasa, 102 Bankalar | D10: 100 / 102 | E10: Virmanla toplam nakdin değişmesi | F10: Virman değişmezi
A11: Stok | B11: Dikeye uygun stok türü | C11: 150 İlk Madde ve Malzeme, 153 Ticari Mallar | D11: 15x | E11: Maliyet ve stok hareketinin kopması | F11: Stok devri
A12: Maddi Duran Varlık | B12: Yatırım harcaması ve amortisman bağlantılı | C12: 253 Tesis Makine Cihazlar, 255 Demirbaşlar, 257 Birikmiş Amortismanlar | D12: 25x | E12: Yatırım/gider karışması | F12: Net defter değeri devri
A13: Mali Borçlar | B13: Kısa/uzun vadeli borç ayrımı | C13: 300 Banka Kredileri / 400 Banka Kredileri | D13: 300 / 400 | E13: Vade sınıfı yanlış | F13: Borç devri
A14: Özkaynak | B14: Sermaye ve geçmiş yıl kârları ayrı | C14: 500 Sermaye, 570 Geçmiş Yıllar Kârları, 590 Dönem Net Kârı | D14: 5xx | E14: Net kâr bağının kopması | F14: Özkaynak devri
... A18: İstisna | B18: TFRS özel ürün varsa fark açık yazılır | C18: Tekdüzen raporlama ≠ TFRS finansal tablo sunumu | D18: Amaç belirtilir | E18: Standartları karıştırma | F18: Model amacı kontrolü

Sheet 05_KARAR_SATIS
A1: KARAR, GÜVEN VE SATIŞA HAZIRLIK STANDARDI
A3: Alan | B3: Müşteri Sorusu | C3: Zorunlu Ürün Davranışı | D3: Kanıt | E3: Başarısızlık Durumu | F3: Kapı
A4: 5 saniye | B4: Bu ürün neyi çözüyor? | C4: İlk ekranda hedef kullanıcı + pahalı problem + sonuç görünür | D4: Başlık + alt mesaj + gerçek ekran | E4: Ürün yalnız teknik isim | F4: HATA
A5: Acı | B5: Sorun bana neye mal oluyor? | C5: Mümkünse müşterinin kendi verisiyle parasal/zaman etkisi hesaplanır | D5: ROI/acı hesaplama yöntemi | E5: Uydurma tasarruf | F5: HATA
A6: Karar | B6: Bu bilgiyle ne yapacağım? | C6: Her kritik KPI aksiyona bağlanır | D6: KARAR_KUYRUGU | E6: Sadece rapor | F6: HATA
A7: Güven | B7: Bu sayıya neden inanayım? | C7: Kaynak, formül mantığı, kontrol ve son doğrulama görünür | D7: Kontroller + kaynak izi + sürüm | E7: Prestij kelimesi | F7: HATA
A8: Referans | B8: Müşteri yorumu yoksa ne göstereceğim? | C8: Önce/Sonra + Karar Vakası + Hata Önleme Vakası üretilir | D8: Demo/örnek çıktı | E8: Kanıtsız iddia | F8: HATA
A9: Senaryo | B9: Ne olursa işler bozulur? | C9: Baz/Aşağı/Yukarı veya uygun stres senaryosu | D9: Senaryo karşılaştırma | E9: Dekoratif senaryo | F9: HATA
A10: Ters stres | B10: Hangi eşikte karar kırılır? | C10: En az bir kritik sürücü için kırılma eşiği | D10: Kırılma eşiği tablosu | E10: Sadece +/- %10 | F10: UYARI/HATA
A11: Hata tutarlılığı | B11: Formül hata verirse ne olur? | C11: Kontrol GEÇTİ veremez; BLOKE/HATA üretir | D11: Hata taraması | E11: Hata + GEÇTİ birlikte | F11: HATA
A12: Karar motoru | B12: Ne oldu, neden oldu? | C12: Sorun + neden + parasal etki + aksiyon + son tarih | D12: Karar tablosu | E12: Boş sayfa / isim düzeyi modül | F12: HATA
A13: Yönetici özeti | B13: 5 saniyede ne görmeliyim? | C13: Bugün / ne değişti / ne bozulacak / neden / ne yapmalıyım / güven | D13: Yönetici özeti ekranı | E13: KPI kutusu yığını | F13: HATA
A14: Teklif | B14: Neden satın almalıyım? | C14: Dosya özellikleri yerine sonuç ve kaçınılan maliyet sunulur | D14: Ürün sayfası kanıt eşlemesi | E14: Özellik listesiyle satış | F14: HATA
... A19: Pazar kanıtı | B19: Piyasa gerçekten ödüyor mu? | C19: Satış/pilot/LOI/fiyat kabulü olmadan pazar doğrulandı yazılmaz | D19: Gerçek işlem kanıtı | E19: Tahmini talep = satış kabulü | F19: HATA

Sheet KAPAK
A1: KAPAK — Kira ve Avans Takip + Dekont
A3: Kira ve Avans Takip + Dekont
A4: Kira tahsilatını avans mahsup motoru ve yazdırılabilir dekont ile yönetir; durum makinesi, yaşlandırma ve boş veride VERİ YOK kararı üretir.
A6: Bu ürün ne sağlar?
A7: • Makrosuz durum makinesi: Bekliyor → Tahsil → Mahsup → Kapalı / İptal
A8: • Avans mahsup motoru — kalan bakiye ve aşım bayrağı
A9: • Yazdırılabilir tahsilat dekontu (PDF baskı alanı)
A10: • Kuyruk + yaşlandırma kovaları (0-7 / 8-30 / 31-60 / 60+)
A11: • Karar kapısı: VERİ YOK / UYGUN / DİKKAT / KRİTİK
A13: Kimler için?
A14: • Ev sahibi — kira ve avans tahsilatını işler
A15: • Malik — bakiye ve mahsup kararını görür
... A21: Sürüm 1.0.0 | Lisans: Tek kullanıcı | ExcelArşiv

Sheet KARTLAR
A1: KARTLAR — Kira ve Avans Takip + Dekont
A3: Kiracı / taşınmaz kartları — her kaydın tek kimliği vardır
A4: Sonraki Kimlik | B4: =kad_sonrakiKimlik
A5: KartId | B5: Unvan | C5: Tasinmaz | D5: Sehir | E5: SozlesmeNo | F5: AylikKira | G5: RiskNotu | H5: Aktif | I5: AvansBakiye | J5: ToplamKira | K5: OrtGecikme
A6: KIR-00001 | B6: Ayşe Demir | C6: Kadıköy Daire 3 | D6: İstanbul | E6: SZL-2026-001 | F6: 18000 | G6: Normal | H6: EVET | I6: =IF($A6="","",SUMIF(tblAvans[KaynakKartId],$A6,tblAvans[KalanBakiye])) | J6: =IF($A6="","",SUMIF(tblAkis[KaynakKartId],$A6,tblAkis[Tutar])) | K6: =IF($A6="","",IFERROR(AVERAGEIF(tblAkis[KaynakKartId],$A6,tblAkis[YasGun]),0))
A7: KIR-00002 | B7: Mehmet Kaya | C7: Çankaya Ofis 12 | D7: Ankara | E7: SZL-2026-002 | F7: 22000 | G7: Normal | H7: EVET | I7: =IF($A7="","",SUMIF(tblAvans[KaynakKartId],$A7,tblAvans[KalanBakiye])) | J7: =IF($A7="","",SUMIF(tblAkis[KaynakKartId],$A7,tblAkis[Tutar])) | K7: =IF($A7="","",IFERROR(AVERAGEIF(tblAkis[KaynakKartId],$A7,tblAkis[YasGun]),0))
A8: KIR-00003 | B8: Elif Yıldız | C8: Bornova Dükkan | D8: İzmir | E8: SZL-2026-003 | F8: 16000 | G8: Normal | H8: EVET | I8: =IF($A8="","",SUMIF(tblAvans[KaynakKartId],$A8,tblAvans[KalanBakiye])) | J8: =IF($A8="","",SUMIF(tblAkis[KaynakKartId],$A8,tblAkis[Tutar])) | K8: =IF($A8="","",IFERROR(AVERAGEIF(tblAkis[KaynakKartId],$A8,tblAkis[YasGun]),0))
A9: KIR-00004 | B9: Can Özkan | C9: Nilüfer Konut | D9: Bursa | E9: SZL-2026-004 | F9: 14000 | G9: Normal | H9: EVET | I9: =IF($A9="","",SUMIF(tblAvans[KaynakKartId],$A9,tblAvans[KalanBakiye])) | J9: =IF($A9="","",SUMIF(tblAkis[KaynakKartId],$A9,tblAkis[Tutar])) | K9: =IF($A9="","",IFERROR(AVERAGEIF(tblAkis[KaynakKartId],$A9,tblAkis[YasGun]),0))
A10: KIR-00005 | B10: Zeynep Arslan | C10: Muratpaşa Villa | D10: Antalya | E10: SZL-2026-005 | F10: 28000 | G10: Normal | H10: EVET | I10: =IF($A10="","",SUMIF(tblAvans[KaynakKartId],$A10,tblAvans[KalanBakiye])) | J10: =IF($A10="","",SUMIF(tblAkis[KaynakKartId],$A10,tblAkis[Tutar])) | K10: =IF($A10="","",IFERROR(AVERAGEIF(tblAkis[KaynakKartId],$A10,tblAkis[YasGun]),0))
A11: KIR-00006 | B11: Hakan Çelik | C11: İzmit Loft | D11: Kocaeli | E11: SZL-2026-006 | F11: 15000 | G11: Normal | H11: EVET | I11: =IF($A11="","",SUMIF(tblAvans[KaynakKartId],$A11,tblAvans[KalanBakiye])) | J11: =IF($A11="","",SUMIF(tblAkis[KaynakKartId],$A11,tblAkis[Tutar])) | K11: =IF($A11="","",IFERROR(AVERAGEIF(tblAkis[KaynakKartId],$A11,tblAkis[YasGun]),0))
A12: KIR-00007 | B12: Selin Aydın | C12: Seyhan Daire | D12: Adana | E12: SZL-2026-007 | F12: 12000 | G12: Normal | H12: EVET | I12: =IF($A12="","",SUMIF(tblAvans[KaynakKartId],$A12,tblAvans[KalanBakiye])) | J12: =IF($A12="","",SUMIF(tblAkis[KaynakKartId],$A12,tblAkis[Tutar])) | K12: =IF($A12="","",IFERROR(AVERAGEIF(tblAkis[KaynakKartId],$A12,tblAkis[YasGun]),0))
A13: KIR-00008 | B13: Burak Şahin | C13: Şehitkamil Dükkan | D13: Gaziantep | E13: SZL-2026-008 | F13: 11000 | G13: Normal | H13: EVET | I13: =IF($A13="","",SUMIF(tblAvans[KaynakKartId],$A13,tblAvans[KalanBakiye])) | J13: =IF($A13="","",SUMIF(tblAkis[KaynakKartId],$A13,tblAkis[Tutar])) | K13: =IF($A13="","",IFERROR(AVERAGEIF(tblAkis[KaynakKartId],$A13,tblAkis[YasGun]),0))
I14: =IF($A14="","",SUMIF(tblAvans[KaynakKartId],$A14,tblAvans[KalanBakiye])) | J14: =IF($A14="","",SUMIF(tblAkis[KaynakKartId],$A14,tblAkis[Tutar])) | K14: =IF($A14="","",IFERROR(AVERAGEIF(tblAkis[KaynakKartId],$A14,tblAkis[YasGun]),0))
I15: =IF($A15="","",SUMIF(tblAvans[KaynakKartId],$A15,tblAvans[KalanBakiye])) | J15: =IF($A15="","",SUMIF(tblAkis[KaynakKartId],$A15,tblAkis[Tutar])) | K15: =IF($A15="","",IFERROR(AVERAGEIF(tblAkis[KaynakKartId],$A15,tblAkis[YasGun]),0))
I16: =IF($A16="","",SUMIF(tblAvans[KaynakKartId],$A16,tblAvans[KalanBakiye])) | J16: =IF($A16="","",SUMIF(tblAkis[KaynakKartId],$A16,tblAkis[Tutar])) | K16: =IF($A16="","",IFERROR(AVERAGEIF(tblAkis[KaynakKartId],$A16,tblAkis[YasGun]),0))
I17: =IF($A17="","",SUMIF(tblAvans[KaynakKartId],$A17,tblAvans[KalanBakiye])) | J17: =IF($A17="","",SUMIF(tblAkis[KaynakKartId],$A17,tblAkis[Tutar])) | K17: =IF($A17="","",IFERROR(AVERAGEIF(tblAkis[KaynakKartId],$A17,tblAkis[YasGun]),0))
I18: =IF($A18="","",SUMIF(tblAvans[KaynakKartId],$A18,tblAvans[KalanBakiye])) | J18: =IF($A18="","",SUMIF(tblAkis[KaynakKartId],$A18,tblAkis[Tutar])) | K18: =IF($A18="","",IFERROR(AVERAGEIF(tblAkis[KaynakKartId],$A18,tblAkis[YasGun]),0))
I19: =IF($A19="","",SUMIF(tblAvans[KaynakKartId],$A19,tblAvans[KalanBakiye])) | J19: =IF($A19="","",SUMIF(tblAkis[KaynakKartId],$A19,tblAkis[Tutar])) | K19: =IF($A19="","",IFERROR(AVERAGEIF(tblAkis[KaynakKartId],$A19,tblAkis[YasGun]),0))
I20: =IF($A20="","",SUMIF(tblAvans[KaynakKartId],$A20,tblAvans[KalanBakiye])) | J20: =IF($A20="","",SUMIF(tblAkis[KaynakKartId],$A20,tblAkis[Tutar])) | K20: =IF($A20="","",IFERROR(AVERAGEIF(tblAkis[KaynakKartId],$A20,tblAkis[YasGun]),0))
I21: =IF($A21="","",SUMIF(tblAvans[KaynakKartId],$A21,tblAvans[KalanBakiye])) | J21: =IF($A21="","",SUMIF(tblAkis[KaynakKartId],$A21,tblAkis[Tutar])) | K21: =IF($A21="","",IFERROR(AVERAGEIF(tblAkis[KaynakKartId],$A21,tblAkis[YasGun]),0))
I22: =IF($A22="","",SUMIF(tblAvans[KaynakKartId],$A22,tblAvans[KalanBakiye])) | J22: =IF($A22="","",SUMIF(tblAkis[KaynakKartId],$A22,tblAkis[Tutar])) | K22: =IF($A22="","",IFERROR(AVERAGEIF(tblAkis[KaynakKartId],$A22,tblAkis[YasGun]),0))
I23: =IF($A23="","",SUMIF(tblAvans[KaynakKartId],$A23,tblAvans[KalanBakiye])) | J23: =IF($A23="","",SUMIF(tblAkis[KaynakKartId],$A23,tblAkis[Tutar])) | K23: =IF($A23="","",IFERROR(AVERAGEIF(tblAkis[KaynakKartId],$A23,tblAkis[YasGun]),0))
I24: =IF($A24="","",SUMIF(tblAvans[KaynakKartId],$A24,tblAvans[KalanBakiye])) | J24: =IF($A24="","",SUMIF(tblAkis[KaynakKartId],$A24,tblAkis[Tutar])) | K24: =IF($A24="","",IFERROR(AVERAGEIF(tblAkis[KaynakKartId],$A24,tblAkis[YasGun]),0))
I25: =IF($A25="","",SUMIF(tblAvans[KaynakKartId],$A25,tblAvans[KalanBakiye])) | J25: =IF($A25="","",SUMIF(tblAkis[KaynakKartId],$A25,tblAkis[Tutar])) | K25: =IF($A25="","",IFERROR(AVERAGEIF(tblAkis[KaynakKartId],$A25,tblAkis[YasGun]),0))
... I255: =IF($A255="","",SUMIF(tblAvans[KaynakKartId],$A255,tblAvans[KalanBakiye])) | J255: =IF($A255="","",SUMIF(tblAkis[KaynakKartId],$A255,tblAkis[Tutar])) | K255: =IF($A255="","",IFERROR(AVERAGEIF(tblAkis[KaynakKartId],$A255,tblAkis[YasGun]),0))

Sheet AKIS
A1: AKIS — Kira ve Avans Takip + Dekont
A3: Kira olay satırları — durum makinesi + yetim + geçersiz geçiş + zincir bayrakları
A5: IslemId | B5: KaynakKartId | C5: Tarih | D5: OncekiDurum | E5: Durum | F5: SozlesmeTutar | G5: AvansTutar | H5: KiraTutar | I5: MahsupTutar | J5: DekontTutar | K5: Tutar | L5: Donem | M5: Aciklama | N5: YasGun | O5: YasKova | P5: YetimBayrak | Q5: GecisUyarisi | R5: ZincirBayrak | S5: KayitDolu
A6: KAD-00001 | B6: KIR-00001 | C6: 46245 | E6: BEKLIYOR | F6: 18000 | G6: 36000 | H6: 18000 | I6: 0 | J6: 0 | K6: 18000 | L6: 2026-08 | M6: Kira tahsil kalemi 1 | N6: =IF($A6="","",IF($C6="","",raporTarihi-$C6)) | O6: =IF($A6="","",IF($N6="","",IF($N6<=7,"0-7",IF($N6<=30,"8-30",IF($N6<=60,"31-60","60+"))))) | P6: =IF($A6="","",IF($B6="","YETİM",IF(COUNTIF(tblKartlar[KartId],$B6)=0,"YETİM",""))) | Q6: =IF(OR($A6="",$D6=""),"",IF(OR($D6&"|"&$E6="",COUNTIF(ListeIzinliGecis,$D6&"|"&$E6)>0),"","GEÇERSİZ GEÇİŞ")) | R6: =IF($A6="","",IF(OR($F6="",$H6=""),"",IF(ABS($H6-$F6)>zincirTolerans,"ZİNCİR KIRIK","OK"))) | S6: =IF($A6="","",1)
A7: KAD-00002 | B7: KIR-00002 | C7: 46242 | D7: BEKLIYOR | E7: TAHSIL | F7: 22000 | G7: 44000 | H7: 22000 | I7: 0 | J7: 22000 | K7: 22000 | L7: 2026-08 | M7: Kira tahsil kalemi 2 | N7: =IF($A7="","",IF($C7="","",raporTarihi-$C7)) | O7: =IF($A7="","",IF($N7="","",IF($N7<=7,"0-7",IF($N7<=30,"8-30",IF($N7<=60,"31-60","60+"))))) | P7: =IF($A7="","",IF($B7="","YETİM",IF(COUNTIF(tblKartlar[KartId],$B7)=0,"YETİM",""))) | Q7: =IF(OR($A7="",$D7=""),"",IF(OR($D7&"|"&$E7="",COUNTIF(ListeIzinliGecis,$D7&"|"&$E7)>0),"","GEÇERSİZ GEÇİŞ")) | R7: =IF($A7="","",IF(OR($F7="",$H7=""),"",IF(ABS($H7-$F7)>zincirTolerans,"ZİNCİR KIRIK","OK"))) | S7: =IF($A7="","",1)
A8: KAD-00003 | B8: KIR-00003 | C8: 46239 | D8: TAHSIL | E8: MAHSUP | F8: 16000 | G8: 32000 | H8: 16000 | I8: 16000 | J8: 0 | K8: 16000 | L8: 2026-08 | M8: Kira tahsil kalemi 3 | N8: =IF($A8="","",IF($C8="","",raporTarihi-$C8)) | O8: =IF($A8="","",IF($N8="","",IF($N8<=7,"0-7",IF($N8<=30,"8-30",IF($N8<=60,"31-60","60+"))))) | P8: =IF($A8="","",IF($B8="","YETİM",IF(COUNTIF(tblKartlar[KartId],$B8)=0,"YETİM",""))) | Q8: =IF(OR($A8="",$D8=""),"",IF(OR($D8&"|"&$E8="",COUNTIF(ListeIzinliGecis,$D8&"|"&$E8)>0),"","GEÇERSİZ GEÇİŞ")) | R8: =IF($A8="","",IF(OR($F8="",$H8=""),"",IF(ABS($H8-$F8)>zincirTolerans,"ZİNCİR KIRIK","OK"))) | S8: =IF($A8="","",1)
A9: KAD-00004 | B9: KIR-00004 | C9: 46236 | D9: MAHSUP | E9: KAPALI | F9: 14000 | G9: 28000 | H9: 14000 | I9: 0 | J9: 14000 | K9: 14000 | L9: 2026-08 | M9: Kira tahsil kalemi 4 | N9: =IF($A9="","",IF($C9="","",raporTarihi-$C9)) | O9: =IF($A9="","",IF($N9="","",IF($N9<=7,"0-7",IF($N9<=30,"8-30",IF($N9<=60,"31-60","60+"))))) | P9: =IF($A9="","",IF($B9="","YETİM",IF(COUNTIF(tblKartlar[KartId],$B9)=0,"YETİM",""))) | Q9: =IF(OR($A9="",$D9=""),"",IF(OR($D9&"|"&$E9="",COUNTIF(ListeIzinliGecis,$D9&"|"&$E9)>0),"","GEÇERSİZ GEÇİŞ")) | R9: =IF($A9="","",IF(OR($F9="",$H9=""),"",IF(ABS($H9-$F9)>zincirTolerans,"ZİNCİR KIRIK","OK"))) | S9: =IF($A9="","",1)
A10: KAD-00005 | B10: KIR-00005 | C10: 46233 | D10: BEKLIYOR | E10: IPTAL | F10: 28000 | G10: 56000 | H10: 28000 | I10: 0 | J10: 0 | K10: 28000 | L10: 2026-08 | M10: Kira tahsil kalemi 5 | N10: =IF($A10="","",IF($C10="","",raporTarihi-$C10)) | O10: =IF($A10="","",IF($N10="","",IF($N10<=7,"0-7",IF($N10<=30,"8-30",IF($N10<=60,"31-60","60+"))))) | P10: =IF($A10="","",IF($B10="","YETİM",IF(COUNTIF(tblKartlar[KartId],$B10)=0,"YETİM",""))) | Q10: =IF(OR($A10="",$D10=""),"",IF(OR($D10&"|"&$E10="",COUNTIF(ListeIzinliGecis,$D10&"|"&$E10)>0),"","GEÇERSİZ GEÇİŞ")) | R10: =IF($A10="","",IF(OR($F10="",$H10=""),"",IF(ABS($H10-$F10)>zincirTolerans,"ZİNCİR KIRIK","OK"))) | S10: =IF($A10="","",1)
A11: KAD-00006 | B11: KIR-00006 | C11: 46230 | D11: BEKLIYOR | E11: TAHSIL | F11: 15000 | G11: 30000 | H11: 15000 | I11: 0 | J11: 15000 | K11: 15000 | L11: 2026-08 | M11: Kira tahsil kalemi 6 | N11: =IF($A11="","",IF($C11="","",raporTarihi-$C11)) | O11: =IF($A11="","",IF($N11="","",IF($N11<=7,"0-7",IF($N11<=30,"8-30",IF($N11<=60,"31-60","60+"))))) | P11: =IF($A11="","",IF($B11="","YETİM",IF(COUNTIF(tblKartlar[KartId],$B11)=0,"YETİM",""))) | Q11: =IF(OR($A11="",$D11=""),"",IF(OR($D11&"|"&$E11="",COUNTIF(ListeIzinliGecis,$D11&"|"&$E11)>0),"","GEÇERSİZ GEÇİŞ")) | R11: =IF($A11="","",IF(OR($F11="",$H11=""),"",IF(ABS($H11-$F11)>zincirTolerans,"ZİNCİR KIRIK","OK"))) | S11: =IF($A11="","",1)
A12: KAD-00007 | B12: KIR-00007 | C12: 46227 | E12: BEKLIYOR | F12: 12000 | G12: 24000 | H12: 12000 | I12: 0 | J12: 0 | K12: 12000 | L12: 2026-08 | M12: Kira tahsil kalemi 7 | N12: =IF($A12="","",IF($C12="","",raporTarihi-$C12)) | O12: =IF($A12="","",IF($N12="","",IF($N12<=7,"0-7",IF($N12<=30,"8-30",IF($N12<=60,"31-60","60+"))))) | P12: =IF($A12="","",IF($B12="","YETİM",IF(COUNTIF(tblKartlar[KartId],$B12)=0,"YETİM",""))) | Q12: =IF(OR($A12="",$D12=""),"",IF(OR($D12&"|"&$E12="",COUNTIF(ListeIzinliGecis,$D12&"|"&$E12)>0),"","GEÇERSİZ GEÇİŞ")) | R12: =IF($A12="","",IF(OR($F12="",$H12=""),"",IF(ABS($H12-$F12)>zincirTolerans,"ZİNCİR KIRIK","OK"))) | S12: =IF($A12="","",1)
A13: KAD-00008 | B13: KIR-00008 | C13: 46224 | D13: TAHSIL | E13: TAHSIL | F13: 11000 | G13: 22000 | H13: 11000 | I13: 0 | J13: 11000 | K13: 11000 | L13: 2026-08 | M13: Kira tahsil kalemi 8 | N13: =IF($A13="","",IF($C13="","",raporTarihi-$C13)) | O13: =IF($A13="","",IF($N13="","",IF($N13<=7,"0-7",IF($N13<=30,"8-30",IF($N13<=60,"31-60","60+"))))) | P13: =IF($A13="","",IF($B13="","YETİM",IF(COUNTIF(tblKartlar[KartId],$B13)=0,"YETİM",""))) | Q13: =IF(OR($A13="",$D13=""),"",IF(OR($D13&"|"&$E13="",COUNTIF(ListeIzinliGecis,$D13&"|"&$E13)>0),"","GEÇERSİZ GEÇİŞ")) | R13: =IF($A13="","",IF(OR($F13="",$H13=""),"",IF(ABS($H13-$F13)>zincirTolerans,"ZİNCİR KIRIK","OK"))) | S13: =IF($A13="","",1)
A14: KAD-00009 | B14: KIR-00001 | C14: 46221 | E14: BEKLIYOR | F14: 18000 | G14: 36000 | H14: 18000 | I14: 0 | J14: 0 | K14: 18000 | L14: 2026-08 | M14: Kira tahsil kalemi 9 | N14: =IF($A14="","",IF($C14="","",raporTarihi-$C14)) | O14: =IF($A14="","",IF($N14="","",IF($N14<=7,"0-7",IF($N14<=30,"8-30",IF($N14<=60,"31-60","60+"))))) | P14: =IF($A14="","",IF($B14="","YETİM",IF(COUNTIF(tblKartlar[KartId],$B14)=0,"YETİM",""))) | Q14: =IF(OR($A14="",$D14=""),"",IF(OR($D14&"|"&$E14="",COUNTIF(ListeIzinliGecis,$D14&"|"&$E14)>0),"","GEÇERSİZ GEÇİŞ")) | R14: =IF($A14="","",IF(OR($F14="",$H14=""),"",IF(ABS($H14-$F14)>zincirTolerans,"ZİNCİR KIRIK","OK"))) | S14: =IF($A14="","",1)
A15: KAD-00010 | B15: KIR-00002 | C15: 46218 | D15: BEKLIYOR | E15: TAHSIL | F15: 22000 | G15: 44000 | H15: 22000 | I15: 0 | J15: 22000 | K15: 22000 | L15: 2026-08 | M15: Kira tahsil kalemi 10 | N15: =IF($A15="","",IF($C15="","",raporTarihi-$C15)) | O15: =IF($A15="","",IF($N15="","",IF($N15<=7,"0-7",IF($N15<=30,"8-30",IF($N15<=60,"31-60","60+"))))) | P15: =IF($A15="","",IF($B15="","YETİM",IF(COUNTIF(tblKartlar[KartId],$B15)=0,"YETİM",""))) | Q15: =IF(OR($A15="",$D15=""),"",IF(OR($D15&"|"&$E15="",COUNTIF(ListeIzinliGecis,$D15&"|"&$E15)>0),"","GEÇERSİZ GEÇİŞ")) | R15: =IF($A15="","",IF(OR($F15="",$H15=""),"",IF(ABS($H15-$F15)>zincirTolerans,"ZİNCİR KIRIK","OK"))) | S15: =IF($A15="","",1)
A16: KAD-00011 | B16: KIR-00003 | C16: 46215 | D16: TAHSIL | E16: MAHSUP | F16: 16000 | G16: 32000 | H16: 16000 | I16: 16000 | J16: 0 | K16: 16000 | L16: 2026-08 | M16: Kira tahsil kalemi 11 | N16: =IF($A16="","",IF($C16="","",raporTarihi-$C16)) | O16: =IF($A16="","",IF($N16="","",IF($N16<=7,"0-7",IF($N16<=30,"8-30",IF($N16<=60,"31-60","60+"))))) | P16: =IF($A16="","",IF($B16="","YETİM",IF(COUNTIF(tblKartlar[KartId],$B16)=0,"YETİM",""))) | Q16: =IF(OR($A16="",$D16=""),"",IF(OR($D16&"|"&$E16="",COUNTIF(ListeIzinliGecis,$D16&"|"&$E16)>0),"","GEÇERSİZ GEÇİŞ")) | R16: =IF($A16="","",IF(OR($F16="",$H16=""),"",IF(ABS($H16-$F16)>zincirTolerans,"ZİNCİR KIRIK","OK"))) | S16: =IF($A16="","",1)
A17: KAD-00012 | B17: KIR-00004 | C17: 46212 | D17: MAHSUP | E17: KAPALI | F17: 14000 | G17: 28000 | H17: 18500 | I17: 0 | J17: 18500 | K17: 18500 | L17: 2026-08 | M17: Kira tahsil kalemi 12 | N17: =IF($A17="","",IF($C17="","",raporTarihi-$C17)) | O17: =IF($A17="","",IF($N17="","",IF($N17<=7,"0-7",IF($N17<=30,"8-30",IF($N17<=60,"31-60","60+"))))) | P17: =IF($A17="","",IF($B17="","YETİM",IF(COUNTIF(tblKartlar[KartId],$B17)=0,"YETİM",""))) | Q17: =IF(OR($A17="",$D17=""),"",IF(OR($D17&"|"&$E17="",COUNTIF(ListeIzinliGecis,$D17&"|"&$E17)>0),"","GEÇERSİZ GEÇİŞ")) | R17: =IF($A17="","",IF(OR($F17="",$H17=""),"",IF(ABS($H17-$F17)>zincirTolerans,"ZİNCİR KIRIK","OK"))) | S17: =IF($A17="","",1)
A18: KAD-00013 | B18: KIR-00005 | C18: 46209 | D18: BEKLIYOR | E18: IPTAL | F18: 28000 | G18: 56000 | H18: 28000 | I18: 0 | J18: 0 | K18: 28000 | L18: 2026-08 | M18: Kira tahsil kalemi 13 | N18: =IF($A18="","",IF($C18="","",raporTarihi-$C18)) | O18: =IF($A18="","",IF($N18="","",IF($N18<=7,"0-7",IF($N18<=30,"8-30",IF($N18<=60,"31-60","60+"))))) | P18: =IF($A18="","",IF($B18="","YETİM",IF(COUNTIF(tblKartlar[KartId],$B18)=0,"YETİM",""))) | Q18: =IF(OR($A18="",$D18=""),"",IF(OR($D18&"|"&$E18="",COUNTIF(ListeIzinliGecis,$D18&"|"&$E18)>0),"","GEÇERSİZ GEÇİŞ")) | R18: =IF($A18="","",IF(OR($F18="",$H18=""),"",IF(ABS($H18-$F18)>zincirTolerans,"ZİNCİR KIRIK","OK"))) | S18: =IF($A18="","",1)
A19: KAD-00014 | B19: KIR-00006 | C19: 46206 | D19: BEKLIYOR | E19: TAHSIL | F19: 15000 | G19: 30000 | H19: 15000 | I19: 0 | J19: 15000 | K19: 15000 | L19: 2026-08 | M19: Kira tahsil kalemi 14 | N19: =IF($A19="","",IF($C19="","",raporTarihi-$C19)) | O19: =IF($A19="","",IF($N19="","",IF($N19<=7,"0-7",IF($N19<=30,"8-30",IF($N19<=60,"31-60","60+"))))) | P19: =IF($A19="","",IF($B19="","YETİM",IF(COUNTIF(tblKartlar[KartId],$B19)=0,"YETİM",""))) | Q19: =IF(OR($A19="",$D19=""),"",IF(OR($D19&"|"&$E19="",COUNTIF(ListeIzinliGecis,$D19&"|"&$E19)>0),"","GEÇERSİZ GEÇİŞ")) | R19: =IF($A19="","",IF(OR($F19="",$H19=""),"",IF(ABS($H19-$F19)>zincirTolerans,"ZİNCİR KIRIK","OK"))) | S19: =IF($A19="","",1)
A20: KAD-00015 | B20: KIR-00007 | C20: 46203 | E20: BEKLIYOR | F20: 12000 | G20: 24000 | H20: 12000 | I20: 0 | J20: 0 | K20: 12000 | L20: 2026-08 | M20: Kira tahsil kalemi 15 | N20: =IF($A20="","",IF($C20="","",raporTarihi-$C20)) | O20: =IF($A20="","",IF($N20="","",IF($N20<=7,"0-7",IF($N20<=30,"8-30",IF($N20<=60,"31-60","60+"))))) | P20: =IF($A20="","",IF($B20="","YETİM",IF(COUNTIF(tblKartlar[KartId],$B20)=0,"YETİM",""))) | Q20: =IF(OR($A20="",$D20=""),"",IF(OR($D20&"|"&$E20="",COUNTIF(ListeIzinliGecis,$D20&"|"&$E20)>0),"","GEÇERSİZ GEÇİŞ")) | R20: =IF($A20="","",IF(OR($F20="",$H20=""),"",IF(ABS($H20-$F20)>zincirTolerans,"ZİNCİR KIRIK","OK"))) | S20: =IF($A20="","",1)
A21: KAD-00016 | B21: KIR-00008 | C21: 46200 | D21: TAHSIL | E21: TAHSIL | F21: 11000 | G21: 22000 | H21: 11000 | I21: 0 | J21: 11000 | K21: 11000 | L21: 2026-08 | M21: Kira tahsil kalemi 16 | N21: =IF($A21="","",IF($C21="","",raporTarihi-$C21)) | O21: =IF($A21="","",IF($N21="","",IF($N21<=7,"0-7",IF($N21<=30,"8-30",IF($N21<=60,"31-60","60+"))))) | P21: =IF($A21="","",IF($B21="","YETİM",IF(COUNTIF(tblKartlar[KartId],$B21)=0,"YETİM",""))) | Q21: =IF(OR($A21="",$D21=""),"",IF(OR($D21&"|"&$E21="",COUNTIF(ListeIzinliGecis,$D21&"|"&$E21)>0),"","GEÇERSİZ GEÇİŞ")) | R21: =IF($A21="","",IF(OR($F21="",$H21=""),"",IF(ABS($H21-$F21)>zincirTolerans,"ZİNCİR KIRIK","OK"))) | S21: =IF($A21="","",1)
A22: KAD-00017 | B22: KIR-00001 | C22: 46197 | E22: BEKLIYOR | F22: 18000 | G22: 36000 | H22: 18000 | I22: 0 | J22: 0 | K22: 18000 | L22: 2026-08 | M22: Kira tahsil kalemi 17 | N22: =IF($A22="","",IF($C22="","",raporTarihi-$C22)) | O22: =IF($A22="","",IF($N22="","",IF($N22<=7,"0-7",IF($N22<=30,"8-30",IF($N22<=60,"31-60","60+"))))) | P22: =IF($A22="","",IF($B22="","YETİM",IF(COUNTIF(tblKartlar[KartId],$B22)=0,"YETİM",""))) | Q22: =IF(OR($A22="",$D22=""),"",IF(OR($D22&"|"&$E22="",COUNTIF(ListeIzinliGecis,$D22&"|"&$E22)>0),"","GEÇERSİZ GEÇİŞ")) | R22: =IF($A22="","",IF(OR($F22="",$H22=""),"",IF(ABS($H22-$F22)>zincirTolerans,"ZİNCİR KIRIK","OK"))) | S22: =IF($A22="","",1)
A23: KAD-00018 | B23: KIR-00002 | C23: 46194 | D23: BEKLIYOR | E23: KAPALI | F23: 22000 | G23: 44000 | H23: 22000 | I23: 0 | J23: 22000 | K23: 22000 | L23: 2026-08 | M23: Kira tahsil kalemi 18 | N23: =IF($A23="","",IF($C23="","",raporTarihi-$C23)) | O23: =IF($A23="","",IF($N23="","",IF($N23<=7,"0-7",IF($N23<=30,"8-30",IF($N23<=60,"31-60","60+"))))) | P23: =IF($A23="","",IF($B23="","YETİM",IF(COUNTIF(tblKartlar[KartId],$B23)=0,"YETİM",""))) | Q23: =IF(OR($A23="",$D23=""),"",IF(OR($D23&"|"&$E23="",COUNTIF(ListeIzinliGecis,$D23&"|"&$E23)>0),"","GEÇERSİZ GEÇİŞ")) | R23: =IF($A23="","",IF(OR($F23="",$H23=""),"",IF(ABS($H23-$F23)>zincirTolerans,"ZİNCİR KIRIK","OK"))) | S23: =IF($A23="","",1)
A24: KAD-00019 | B24: KIR-00003 | C24: 46191 | D24: TAHSIL | E24: MAHSUP | F24: 16000 | G24: 32000 | H24: 20500 | I24: 16000 | J24: 4500 | K24: 20500 | L24: 2026-08 | M24: Kira tahsil kalemi 19 | N24: =IF($A24="","",IF($C24="","",raporTarihi-$C24)) | O24: =IF($A24="","",IF($N24="","",IF($N24<=7,"0-7",IF($N24<=30,"8-30",IF($N24<=60,"31-60","60+"))))) | P24: =IF($A24="","",IF($B24="","YETİM",IF(COUNTIF(tblKartlar[KartId],$B24)=0,"YETİM",""))) | Q24: =IF(OR($A24="",$D24=""),"",IF(OR($D24&"|"&$E24="",COUNTIF(ListeIzinliGecis,$D24&"|"&$E24)>0),"","GEÇERSİZ GEÇİŞ")) | R24: =IF($A24="","",IF(OR($F24="",$H24=""),"",IF(ABS($H24-$F24)>zincirTolerans,"ZİNCİR KIRIK","OK"))) | S24: =IF($A24="","",1)
A25: KAD-00020 | B25: KIR-00004 | C25: 46188 | D25: KAPALI | E25: TAHSIL | F25: 14000 | G25: 28000 | H25: 14000 | I25: 0 | J25: 14000 | K25: 14000 | L25: 2026-08 | M25: Kira tahsil kalemi 20 | N25: =IF($A25="","",IF($C25="","",raporTarihi-$C25)) | O25: =IF($A25="","",IF($N25="","",IF($N25<=7,"0-7",IF($N25<=30,"8-30",IF($N25<=60,"31-60","60+"))))) | P25: =IF($A25="","",IF($B25="","YETİM",IF(COUNTIF(tblKartlar[KartId],$B25)=0,"YETİM",""))) | Q25: =IF(OR($A25="",$D25=""),"",IF(OR($D25&"|"&$E25="",COUNTIF(ListeIzinliGecis,$D25&"|"&$E25)>0),"","GEÇERSİZ GEÇİŞ")) | R25: =IF($A25="","",IF(OR($F25="",$H25=""),"",IF(ABS($H25-$F25)>zincirTolerans,"ZİNCİR KIRIK","OK"))) | S25: =IF($A25="","",1)
A26: KAD-00021 | B26: KIR-00005 | C26: 46185 | D26: BEKLIYOR | E26: IPTAL | F26: 28000 | G26: 56000 | H26: 28000 | I26: 0 | J26: 0 | K26: 28000 | L26: 2026-08 | M26: Kira tahsil kalemi 21 | N26: =IF($A26="","",IF($C26="","",raporTarihi-$C26)) | O26: =IF($A26="","",IF($N26="","",IF($N26<=7,"0-7",IF($N26<=30,"8-30",IF($N26<=60,"31-60","60+"))))) | P26: =IF($A26="","",IF($B26="","YETİM",IF(COUNTIF(tblKartlar[KartId],$B26)=0,"YETİM",""))) | Q26: =IF(OR($A26="",$D26=""),"",IF(OR($D26&"|"&$E26="",COUNTIF(ListeIzinliGecis,$D26&"|"&$E26)>0),"","GEÇERSİZ GEÇİŞ")) | R26: =IF($A26="","",IF(OR($F26="",$H26=""),"",IF(ABS($H26-$F26)>zincirTolerans,"ZİNCİR KIRIK","OK"))) | S26: =IF($A26="","",1)
A27: KAD-00022 | C27: 46182 | D27: BEKLIYOR | E27: TAHSIL | F27: 15000 | G27: 30000 | H27: 15000 | I27: 0 | J27: 15000 | K27: 15000 | L27: 2026-08 | M27: Kira tahsil kalemi 22 | N27: =IF($A27="","",IF($C27="","",raporTarihi-$C27)) | O27: =IF($A27="","",IF($N27="","",IF($N27<=7,"0-7",IF($N27<=30,"8-30",IF($N27<=60,"31-60","60+"))))) | P27: =IF($A27="","",IF($B27="","YETİM",IF(COUNTIF(tblKartlar[KartId],$B27)=0,"YETİM",""))) | Q27: =IF(OR($A27="",$D27=""),"",IF(OR($D27&"|"&$E27="",COUNTIF(ListeIzinliGecis,$D27&"|"&$E27)>0),"","GEÇERSİZ GEÇİŞ")) | R27: =IF($A27="","",IF(OR($F27="",$H27=""),"",IF(ABS($H27-$F27)>zincirTolerans,"ZİNCİR KIRIK","OK"))) | S27: =IF($A27="","",1)
A28: KAD-00023 | B28: KIR-00007 | C28: 46179 | E28: BEKLIYOR | F28: 12000 | G28: 24000 | H28: 12000 | I28: 0 | J28: 0 | K28: 12000 | L28: 2026-08 | M28: Kira tahsil kalemi 23 | N28: =IF($A28="","",IF($C28="","",raporTarihi-$C28)) | O28: =IF($A28="","",IF($N28="","",IF($N28<=7,"0-7",IF($N28<=30,"8-30",IF($N28<=60,"31-60","60+"))))) | P28: =IF($A28="","",IF($B28="","YETİM",IF(COUNTIF(tblKartlar[KartId],$B28)=0,"YETİM",""))) | Q28: =IF(OR($A28="",$D28=""),"",IF(OR($D28&"|"&$E28="",COUNTIF(ListeIzinliGecis,$D28&"|"&$E28)>0),"","GEÇERSİZ GEÇİŞ")) | R28: =IF($A28="","",IF(OR($F28="",$H28=""),"",IF(ABS($H28-$F28)>zincirTolerans,"ZİNCİR KIRIK","OK"))) | S28: =IF($A28="","",1)
A29: KAD-00024 | B29: KIR-00008 | C29: 46176 | D29: TAHSIL | E29: TAHSIL | F29: 11000 | G29: 22000 | H29: 11000 | I29: 0 | J29: 11000 | K29: 11000 | L29: 2026-08 | M29: Kira tahsil kalemi 24 | N29: =IF($A29="","",IF($C29="","",raporTarihi-$C29)) | O29: =IF($A29="","",IF($N29="","",IF($N29<=7,"0-7",IF($N29<=30,"8-30",IF($N29<=60,"31-60","60+"))))) | P29: =IF($A29="","",IF($B29="","YETİM",IF(COUNTIF(tblKartlar[KartId],$B29)=0,"YETİM",""))) | Q29: =IF(OR($A29="",$D29=""),"",IF(OR($D29&"|"&$E29="",COUNTIF(ListeIzinliGecis,$D29&"|"&$E29)>0),"","GEÇERSİZ GEÇİŞ")) | R29: =IF($A29="","",IF(OR($F29="",$H29=""),"",IF(ABS($H29-$F29)>zincirTolerans,"ZİNCİR KIRIK","OK"))) | S29: =IF($A29="","",1)
A30: KAD-00025 | B30: KIR-99999 | C30: 46248 | E30: BEKLIYOR | F30: 18000 | G30: 36000 | H30: 18000 | I30: 0 | J30: 0 | K30: 18000 | L30: 2026-08 | M30: Kira tahsil kalemi 25 | N30: =IF($A30="","",IF($C30="","",raporTarihi-$C30)) | O30: =IF($A30="","",IF($N30="","",IF($N30<=7,"0-7",IF($N30<=30,"8-30",IF($N30<=60,"31-60","60+"))))) | P30: =IF($A30="","",IF($B30="","YETİM",IF(COUNTIF(tblKartlar[KartId],$B30)=0,"YETİM",""))) | Q30: =IF(OR($A30="",$D30=""),"",IF(OR($D30&"|"&$E30="",COUNTIF(ListeIzinliGecis,$D30&"|"&$E30)>0),"","GEÇERSİZ GEÇİŞ")) | R30: =IF($A30="","",IF(OR($F30="",$H30=""),"",IF(ABS($H30-$F30)>zincirTolerans,"ZİNCİR KIRIK","OK"))) | S30: =IF($A30="","",1)
A31: KAD-00026 | B31: KIR-00002 | C31: 46245 | D31: BEKLIYOR | E31: TAHSIL | F31: 22000 | G31: 44000 | H31: 22000 | I31: 0 | J31: 22000 | K31: 22000 | L31: 2026-08 | M31: Kira tahsil kalemi 26 | N31: =IF($A31="","",IF($C31="","",raporTarihi-$C31)) | O31: =IF($A31="","",IF($N31="","",IF($N31<=7,"0-7",IF($N31<=30,"8-30",IF($N31<=60,"31-60","60+"))))) | P31: =IF($A31="","",IF($B31="","YETİM",IF(COUNTIF(tblKartlar[KartId],$B31)=0,"YETİM",""))) | Q31: =IF(OR($A31="",$D31=""),"",IF(OR($D31&"|"&$E31="",COUNTIF(ListeIzinliGecis,$D31&"|"&$E31)>0),"","GEÇERSİZ GEÇİŞ")) | R31: =IF($A31="","",IF(OR($F31="",$H31=""),"",IF(ABS($H31-$F31)>zincirTolerans,"ZİNCİR KIRIK","OK"))) | S31: =IF($A31="","",1)
A32: KAD-00027 | B32: KIR-00003 | C32: 46242 | D32: TAHSIL | E32: MAHSUP | F32: 16000 | G32: 32000 | H32: 16000 | I32: 16000 | J32: 0 | K32: 16000 | L32: 2026-08 | M32: Kira tahsil kalemi 27 | N32: =IF($A32="","",IF($C32="","",raporTarihi-$C32)) | O32: =IF($A32="","",IF($N32="","",IF($N32<=7,"0-7",IF($N32<=30,"8-30",IF($N32<=60,"31-60","60+"))))) | P32: =IF($A32="","",IF($B32="","YETİM",IF(COUNTIF(tblKartlar[KartId],$B32)=0,"YETİM",""))) | Q32: =IF(OR($A32="",$D32=""),"",IF(OR($D32&"|"&$E32="",COUNTIF(ListeIzinliGecis,$D32&"|"&$E32)>0),"","GEÇERSİZ GEÇİŞ")) | R32: =IF($A32="","",IF(OR($F32="",$H32=""),"",IF(ABS($H32-$F32)>zincirTolerans,"ZİNCİR KIRIK","OK"))) | S32: =IF($A32="","",1)
A33: KAD-00028 | B33: KIR-00004 | C33: 46239 | D33: MAHSUP | E33: KAPALI | F33: 14000 | G33: 28000 | H33: 14000 | I33: 0 | J33: 14000 | K33: 14000 | L33: 2026-08 | M33: Kira tahsil kalemi 28 | N33: =IF($A33="","",IF($C33="","",raporTarihi-$C33)) | O33: =IF($A33="","",IF($N33="","",IF($N33<=7,"0-7",IF($N33<=30,"8-30",IF($N33<=60,"31-60","60+"))))) | P33: =IF($A33="","",IF($B33="","YETİM",IF(COUNTIF(tblKartlar[KartId],$B33)=0,"YETİM",""))) | Q33: =IF(OR($A33="",$D33=""),"",IF(OR($D33&"|"&$E33="",COUNTIF(ListeIzinliGecis,$D33&"|"&$E33)>0),"","GEÇERSİZ GEÇİŞ")) | R33: =IF($A33="","",IF(OR($F33="",$H33=""),"",IF(ABS($H33-$F33)>zincirTolerans,"ZİNCİR KIRIK","OK"))) | S33: =IF($A33="","",1)
N34: =IF($A34="","",IF($C34="","",raporTarihi-$C34)) | O34: =IF($A34="","",IF($N34="","",IF($N34<=7,"0-7",IF($N34<=30,"8-30",IF($N34<=60,"31-60","60+"))))) | P34: =IF($A34="","",IF($B34="","YETİM",IF(COUNTIF(tblKartlar[KartId],$B34)=0,"YETİM",""))) | Q34: =IF(OR($A34="",$D34=""),"",IF(OR($D34&"|"&$E34="",COUNTIF(ListeIzinliGecis,$D34&"|"&$E34)>0),"","GEÇERSİZ GEÇİŞ")) | R34: =IF($A34="","",IF(OR($F34="",$H34=""),"",IF(ABS($H34-$F34)>zincirTolerans,"ZİNCİR KIRIK","OK"))) | S34: =IF($A34="","",1)
N35: =IF($A35="","",IF($C35="","",raporTarihi-$C35)) | O35: =IF($A35="","",IF($N35="","",IF($N35<=7,"0-7",IF($N35<=30,"8-30",IF($N35<=60,"31-60","60+"))))) | P35: =IF($A35="","",IF($B35="","YETİM",IF(COUNTIF(tblKartlar[KartId],$B35)=0,"YETİM",""))) | Q35: =IF(OR($A35="",$D35=""),"",IF(OR($D35&"|"&$E35="",COUNTIF(ListeIzinliGecis,$D35&"|"&$E35)>0),"","GEÇERSİZ GEÇİŞ")) | R35: =IF($A35="","",IF(OR($F35="",$H35=""),"",IF(ABS($H35-$F35)>zincirTolerans,"ZİNCİR KIRIK","OK"))) | S35: =IF($A35="","",1)
N36: =IF($A36="","",IF($C36="","",raporTarihi-$C36)) | O36: =IF($A36="","",IF($N36="","",IF($N36<=7,"0-7",IF($N36<=30,"8-30",IF($N36<=60,"31-60","60+"))))) | P36: =IF($A36="","",IF($B36="","YETİM",IF(COUNTIF(tblKartlar[KartId],$B36)=0,"YETİM",""))) | Q36: =IF(OR($A36="",$D36=""),"",IF(OR($D36&"|"&$E36="",COUNTIF(ListeIzinliGecis,$D36&"|"&$E36)>0),"","GEÇERSİZ GEÇİŞ")) | R36: =IF($A36="","",IF(OR($F36="",$H36=""),"",IF(ABS($H36-$F36)>zincirTolerans,"ZİNCİR KIRIK","OK"))) | S36: =IF($A36="","",1)
N37: =IF($A37="","",IF($C37="","",raporTarihi-$C37)) | O37: =IF($A37="","",IF($N37="","",IF($N37<=7,"0-7",IF($N37<=30,"8-30",IF($N37<=60,"31-60","60+"))))) | P37: =IF($A37="","",IF($B37="","YETİM",IF(COUNTIF(tblKartlar[KartId],$B37)=0,"YETİM",""))) | Q37: =IF(OR($A37="",$D37=""),"",IF(OR($D37&"|"&$E37="",COUNTIF(ListeIzinliGecis,$D37&"|"&$E37)>0),"","GEÇERSİZ GEÇİŞ")) | R37: =IF($A37="","",IF(OR($F37="",$H37=""),"",IF(ABS($H37-$F37)>zincirTolerans,"ZİNCİR KIRIK","OK"))) | S37: =IF($A37="","",1)
N38: =IF($A38="","",IF($C38="","",raporTarihi-$C38)) | O38: =IF($A38="","",IF($N38="","",IF($N38<=7,"0-7",IF($N38<=30,"8-30",IF($N38<=60,"31-60","60+"))))) | P38: =IF($A38="","",IF($B38="","YETİM",IF(COUNTIF(tblKartlar[KartId],$B38)=0,"YETİM",""))) | Q38: =IF(OR($A38="",$D38=""),"",IF(OR($D38&"|"&$E38="",COUNTIF(ListeIzinliGecis,$D38&"|"&$E38)>0),"","GEÇERSİZ GEÇİŞ")) | R38: =IF($A38="","",IF(OR($F38="",$H38=""),"",IF(ABS($H38-$F38)>zincirTolerans,"ZİNCİR KIRIK","OK"))) | S38: =IF($A38="","",1)
N39: =IF($A39="","",IF($C39="","",raporTarihi-$C39)) | O39: =IF($A39="","",IF($N39="","",IF($N39<=7,"0-7",IF($N39<=30,"8-30",IF($N39<=60,"31-60","60+"))))) | P39: =IF($A39="","",IF($B39="","YETİM",IF(COUNTIF(tblKartlar[KartId],$B39)=0,"YETİM",""))) | Q39: =IF(OR($A39="",$D39=""),"",IF(OR($D39&"|"&$E39="",COUNTIF(ListeIzinliGecis,$D39&"|"&$E39)>0),"","GEÇERSİZ GEÇİŞ")) | R39: =IF($A39="","",IF(OR($F39="",$H39=""),"",IF(ABS($H39-$F39)>zincirTolerans,"ZİNCİR KIRIK","OK"))) | S39: =IF($A39="","",1)
N40: =IF($A40="","",IF($C40="","",raporTarihi-$C40)) | O40: =IF($A40="","",IF($N40="","",IF($N40<=7,"0-7",IF($N40<=30,"8-30",IF($N40<=60,"31-60","60+"))))) | P40: =IF($A40="","",IF($B40="","YETİM",IF(COUNTIF(tblKartlar[KartId],$B40)=0,"YETİM",""))) | Q40: =IF(OR($A40="",$D40=""),"",IF(OR($D40&"|"&$E40="",COUNTIF(ListeIzinliGecis,$D40&"|"&$E40)>0),"","GEÇERSİZ GEÇİŞ")) | R40: =IF($A40="","",IF(OR($F40="",$H40=""),"",IF(ABS($H40-$F40)>zincirTolerans,"ZİNCİR KIRIK","OK"))) | S40: =IF($A40="","",1)
N41: =IF($A41="","",IF($C41="","",raporTarihi-$C41)) | O41: =IF($A41="","",IF($N41="","",IF($N41<=7,"0-7",IF($N41<=30,"8-30",IF($N41<=60,"31-60","60+"))))) | P41: =IF($A41="","",IF($B41="","YETİM",IF(COUNTIF(tblKartlar[KartId],$B41)=0,"YETİM",""))) | Q41: =IF(OR($A41="",$D41=""),"",IF(OR($D41&"|"&$E41="",COUNTIF(ListeIzinliGecis,$D41&"|"&$E41)>0),"","GEÇERSİZ GEÇİŞ")) | R41: =IF($A41="","",IF(OR($F41="",$H41=""),"",IF(ABS($H41-$F41)>zincirTolerans,"ZİNCİR KIRIK","OK"))) | S41: =IF($A41="","",1)
N42: =IF($A42="","",IF($C42="","",raporTarihi-$C42)) | O42: =IF($A42="","",IF($N42="","",IF($N42<=7,"0-7",IF($N42<=30,"8-30",IF($N42<=60,"31-60","60+"))))) | P42: =IF($A42="","",IF($B42="","YETİM",IF(COUNTIF(tblKartlar[KartId],$B42)=0,"YETİM",""))) | Q42: =IF(OR($A42="",$D42=""),"",IF(OR($D42&"|"&$E42="",COUNTIF(ListeIzinliGecis,$D42&"|"&$E42)>0),"","GEÇERSİZ GEÇİŞ")) | R42: =IF($A42="","",IF(OR($F42="",$H42=""),"",IF(ABS($H42-$F42)>zincirTolerans,"ZİNCİR KIRIK","OK"))) | S42: =IF($A42="","",1)
...

Sheet KUYRUKLAR
A1: KUYRUKLAR — Kira ve Avans Takip + Dekont
A3: Durum bazlı canlı kuyruk — kapalı kayıtlar düşer
A5: Kuyruk | B5: Adet | C5: Tutar
A6: Bekliyor | B6: =COUNTIFS(tblAkis[durum],"BEKLIYOR",tblAkis[tutar],">0") | C6: =SUMIFS(tblAkis[tutar],tblAkis[durum],"BEKLIYOR")
A7: Tahsil | B7: =COUNTIFS(tblAkis[durum],"TAHSIL",tblAkis[tutar],">0") | C7: =SUMIFS(tblAkis[tutar],tblAkis[durum],"TAHSIL")
A8: Mahsup | B8: =COUNTIFS(tblAkis[durum],"MAHSUP",tblAkis[tutar],">0") | C8: =SUMIFS(tblAkis[tutar],tblAkis[durum],"MAHSUP")
A9: Geciken (açık, yaş>eşik) | B9: =COUNTIFS(tblAkis[YasGun],">"&kad_esikGecikmeGun,tblAkis[Durum],"<>KAPALI",tblAkis[Durum],"<>IPTAL",tblAkis[Tutar],">0") | C9: =SUMIFS(tblAkis[Tutar],tblAkis[YasGun],">"&kad_esikGecikmeGun,tblAkis[Durum],"<>KAPALI",tblAkis[Durum],"<>IPTAL")
A11: Kapalı (Kapalı+İptal) — kuyruktan düşer
A12: Kapalı | B12: =COUNTIFS(tblAkis[durum],"KAPALI",tblAkis[tutar],">0") | C12: =SUMIFS(tblAkis[tutar],tblAkis[durum],"KAPALI")
A13: İptal | B13: =COUNTIFS(tblAkis[durum],"IPTAL",tblAkis[tutar],">0") | C13: =SUMIFS(tblAkis[tutar],tblAkis[durum],"IPTAL")
A15: Kuyruk Özeti | B15: =kad_kuyrukOzeti
A17: Yaş Kova Dağılımı
A18: 0-7 | B18: =COUNTIF(tblAkis[YasKova],"0-7") | C18: =SUMIF(tblAkis[YasKova],"0-7",tblAkis[Tutar])
A19: 8-30 | B19: =COUNTIF(tblAkis[YasKova],"8-30") | C19: =SUMIF(tblAkis[YasKova],"8-30",tblAkis[Tutar])
A20: 31-60 | B20: =COUNTIF(tblAkis[YasKova],"31-60") | C20: =SUMIF(tblAkis[YasKova],"31-60",tblAkis[Tutar])
A21: 60+ | B21: =COUNTIF(tblAkis[YasKova],"60+") | C21: =SUMIF(tblAkis[YasKova],"60+",tblAkis[Tutar])

Sheet AVANS
A1: AVANS — Kira ve Avans Takip + Dekont
A3: Avans mahsup motoru — anapara, mahsup edilen, kalan bakiye, aşım bayrağı
A4: Avans Anapara | B4: =SUM(tblAvans[AvansTutar]) | C4: Mahsup Edilen | D4: =SUM(tblAvans[MahsupEdilen]) | E4: Kalan Bakiye | F4: =SUM(tblAvans[KalanBakiye]) | G4: Aşım Adet | H4: =COUNTIF(tblAvans[AsimBayrak],"AŞIM") | O4: Kart | P4: Anapara | Q4: Kalan
A5: AvansId | B5: KaynakKartId | C5: Tarih | D5: AvansTutar | E5: Donem | F5: Aciklama | G5: MahsupEdilen | H5: KalanBakiye | I5: YasGun | J5: YasKova | K5: YetimBayrak | L5: AsimBayrak | O5: KIR-00001 | P5: 36000 | Q5: 28000
A6: AVN-00001 | B6: KIR-00001 | C6: 46214 | D6: 36000 | E6: 2026-07 | F6: Sözleşme avansı 1 | G6: =IF($A6="","",SUMIFS(tblAkis[MahsupTutar],tblAkis[KaynakKartId],$B6,tblAkis[Durum],"MAHSUP")) | H6: =IF($A6="","",MAX(0,$D6-$G6)) | I6: =IF($A6="","",IF($C6="","",raporTarihi-$C6)) | J6: =IF($A6="","",IF($I6="","",IF($I6<=7,"0-7",IF($I6<=30,"8-30",IF($I6<=60,"31-60","60+"))))) | K6: =IF($A6="","",IF($B6="","YETİM",IF(COUNTIF(tblKartlar[KartId],$B6)=0,"YETİM",""))) | L6: =IF($A6="","",IF($G6>$D6+kad_mahsupTolerans,"AŞIM","UYGUN")) | O6: KIR-00002 | P6: 44000 | Q6: 36000
A7: AVN-00002 | B7: KIR-00002 | C7: 46210 | D7: 44000 | E7: 2026-07 | F7: Sözleşme avansı 2 | G7: =IF($A7="","",SUMIFS(tblAkis[MahsupTutar],tblAkis[KaynakKartId],$B7,tblAkis[Durum],"MAHSUP")) | H7: =IF($A7="","",MAX(0,$D7-$G7)) | I7: =IF($A7="","",IF($C7="","",raporTarihi-$C7)) | J7: =IF($A7="","",IF($I7="","",IF($I7<=7,"0-7",IF($I7<=30,"8-30",IF($I7<=60,"31-60","60+"))))) | K7: =IF($A7="","",IF($B7="","YETİM",IF(COUNTIF(tblKartlar[KartId],$B7)=0,"YETİM",""))) | L7: =IF($A7="","",IF($G7>$D7+kad_mahsupTolerans,"AŞIM","UYGUN")) | O7: KIR-00003 | P7: 32000 | Q7: 24000
A8: AVN-00003 | B8: KIR-00003 | C8: 46206 | D8: 32000 | E8: 2026-07 | F8: Sözleşme avansı 3 | G8: =IF($A8="","",SUMIFS(tblAkis[MahsupTutar],tblAkis[KaynakKartId],$B8,tblAkis[Durum],"MAHSUP")) | H8: =IF($A8="","",MAX(0,$D8-$G8)) | I8: =IF($A8="","",IF($C8="","",raporTarihi-$C8)) | J8: =IF($A8="","",IF($I8="","",IF($I8<=7,"0-7",IF($I8<=30,"8-30",IF($I8<=60,"31-60","60+"))))) | K8: =IF($A8="","",IF($B8="","YETİM",IF(COUNTIF(tblKartlar[KartId],$B8)=0,"YETİM",""))) | L8: =IF($A8="","",IF($G8>$D8+kad_mahsupTolerans,"AŞIM","UYGUN")) | O8: KIR-00004 | P8: 28000 | Q8: 20000
A9: AVN-00004 | B9: KIR-00004 | C9: 46202 | D9: 28000 | E9: 2026-07 | F9: Sözleşme avansı 4 | G9: =IF($A9="","",SUMIFS(tblAkis[MahsupTutar],tblAkis[KaynakKartId],$B9,tblAkis[Durum],"MAHSUP")) | H9: =IF($A9="","",MAX(0,$D9-$G9)) | I9: =IF($A9="","",IF($C9="","",raporTarihi-$C9)) | J9: =IF($A9="","",IF($I9="","",IF($I9<=7,"0-7",IF($I9<=30,"8-30",IF($I9<=60,"31-60","60+"))))) | K9: =IF($A9="","",IF($B9="","YETİM",IF(COUNTIF(tblKartlar[KartId],$B9)=0,"YETİM",""))) | L9: =IF($A9="","",IF($G9>$D9+kad_mahsupTolerans,"AŞIM","UYGUN")) | O9: KIR-00005 | P9: 56000 | Q9: 48000
A10: AVN-00005 | B10: KIR-00005 | C10: 46198 | D10: 56000 | E10: 2026-07 | F10: Sözleşme avansı 5 | G10: =IF($A10="","",SUMIFS(tblAkis[MahsupTutar],tblAkis[KaynakKartId],$B10,tblAkis[Durum],"MAHSUP")) | H10: =IF($A10="","",MAX(0,$D10-$G10)) | I10: =IF($A10="","",IF($C10="","",raporTarihi-$C10)) | J10: =IF($A10="","",IF($I10="","",IF($I10<=7,"0-7",IF($I10<=30,"8-30",IF($I10<=60,"31-60","60+"))))) | K10: =IF($A10="","",IF($B10="","YETİM",IF(COUNTIF(tblKartlar[KartId],$B10)=0,"YETİM",""))) | L10: =IF($A10="","",IF($G10>$D10+kad_mahsupTolerans,"AŞIM","UYGUN")) | O10: KIR-00006 | P10: 30000 | Q10: 22000
A11: AVN-00006 | B11: KIR-00006 | C11: 46194 | D11: 30000 | E11: 2026-07 | F11: Sözleşme avansı 6 | G11: =IF($A11="","",SUMIFS(tblAkis[MahsupTutar],tblAkis[KaynakKartId],$B11,tblAkis[Durum],"MAHSUP")) | H11: =IF($A11="","",MAX(0,$D11-$G11)) | I11: =IF($A11="","",IF($C11="","",raporTarihi-$C11)) | J11: =IF($A11="","",IF($I11="","",IF($I11<=7,"0-7",IF($I11<=30,"8-30",IF($I11<=60,"31-60","60+"))))) | K11: =IF($A11="","",IF($B11="","YETİM",IF(COUNTIF(tblKartlar[KartId],$B11)=0,"YETİM",""))) | L11: =IF($A11="","",IF($G11>$D11+kad_mahsupTolerans,"AŞIM","UYGUN")) | O11: KIR-00007 | P11: 24000 | Q11: 16000
A12: AVN-00007 | B12: KIR-00007 | C12: 46190 | D12: 24000 | E12: 2026-07 | F12: Sözleşme avansı 7 | G12: =IF($A12="","",SUMIFS(tblAkis[MahsupTutar],tblAkis[KaynakKartId],$B12,tblAkis[Durum],"MAHSUP")) | H12: =IF($A12="","",MAX(0,$D12-$G12)) | I12: =IF($A12="","",IF($C12="","",raporTarihi-$C12)) | J12: =IF($A12="","",IF($I12="","",IF($I12<=7,"0-7",IF($I12<=30,"8-30",IF($I12<=60,"31-60","60+"))))) | K12: =IF($A12="","",IF($B12="","YETİM",IF(COUNTIF(tblKartlar[KartId],$B12)=0,"YETİM",""))) | L12: =IF($A12="","",IF($G12>$D12+kad_mahsupTolerans,"AŞIM","UYGUN")) | O12: KIR-00008 | P12: 22000 | Q12: 14000
A13: AVN-00008 | B13: KIR-00008 | C13: 46186 | D13: 22000 | E13: 2026-07 | F13: Sözleşme avansı 8 | G13: =IF($A13="","",SUMIFS(tblAkis[MahsupTutar],tblAkis[KaynakKartId],$B13,tblAkis[Durum],"MAHSUP")) | H13: =IF($A13="","",MAX(0,$D13-$G13)) | I13: =IF($A13="","",IF($C13="","",raporTarihi-$C13)) | J13: =IF($A13="","",IF($I13="","",IF($I13<=7,"0-7",IF($I13<=30,"8-30",IF($I13<=60,"31-60","60+"))))) | K13: =IF($A13="","",IF($B13="","YETİM",IF(COUNTIF(tblKartlar[KartId],$B13)=0,"YETİM",""))) | L13: =IF($A13="","",IF($G13>$D13+kad_mahsupTolerans,"AŞIM","UYGUN"))
G14: =IF($A14="","",SUMIFS(tblAkis[MahsupTutar],tblAkis[KaynakKartId],$B14,tblAkis[Durum],"MAHSUP")) | H14: =IF($A14="","",MAX(0,$D14-$G14)) | I14: =IF($A14="","",IF($C14="","",raporTarihi-$C14)) | J14: =IF($A14="","",IF($I14="","",IF($I14<=7,"0-7",IF($I14<=30,"8-30",IF($I14<=60,"31-60","60+"))))) | K14: =IF($A14="","",IF($B14="","YETİM",IF(COUNTIF(tblKartlar[KartId],$B14)=0,"YETİM",""))) | L14: =IF($A14="","",IF($G14>$D14+kad_mahsupTolerans,"AŞIM","UYGUN"))
G15: =IF($A15="","",SUMIFS(tblAkis[MahsupTutar],tblAkis[KaynakKartId],$B15,tblAkis[Durum],"MAHSUP")) | H15: =IF($A15="","",MAX(0,$D15-$G15)) | I15: =IF($A15="","",IF($C15="","",raporTarihi-$C15)) | J15: =IF($A15="","",IF($I15="","",IF($I15<=7,"0-7",IF($I15<=30,"8-30",IF($I15<=60,"31-60","60+"))))) | K15: =IF($A15="","",IF($B15="","YETİM",IF(COUNTIF(tblKartlar[KartId],$B15)=0,"YETİM",""))) | L15: =IF($A15="","",IF($G15>$D15+kad_mahsupTolerans,"AŞIM","UYGUN"))
G16: =IF($A16="","",SUMIFS(tblAkis[MahsupTutar],tblAkis[KaynakKartId],$B16,tblAkis[Durum],"MAHSUP")) | H16: =IF($A16="","",MAX(0,$D16-$G16)) | I16: =IF($A16="","",IF($C16="","",raporTarihi-$C16)) | J16: =IF($A16="","",IF($I16="","",IF($I16<=7,"0-7",IF($I16<=30,"8-30",IF($I16<=60,"31-60","60+"))))) | K16: =IF($A16="","",IF($B16="","YETİM",IF(COUNTIF(tblKartlar[KartId],$B16)=0,"YETİM",""))) | L16: =IF($A16="","",IF($G16>$D16+kad_mahsupTolerans,"AŞIM","UYGUN"))
G17: =IF($A17="","",SUMIFS(tblAkis[MahsupTutar],tblAkis[KaynakKartId],$B17,tblAkis[Durum],"MAHSUP")) | H17: =IF($A17="","",MAX(0,$D17-$G17)) | I17: =IF($A17="","",IF($C17="","",raporTarihi-$C17)) | J17: =IF($A17="","",IF($I17="","",IF($I17<=7,"0-7",IF($I17<=30,"8-30",IF($I17<=60,"31-60","60+"))))) | K17: =IF($A17="","",IF($B17="","YETİM",IF(COUNTIF(tblKartlar[KartId],$B17)=0,"YETİM",""))) | L17: =IF($A17="","",IF($G17>$D17+kad_mahsupTolerans,"AŞIM","UYGUN"))
G18: =IF($A18="","",SUMIFS(tblAkis[MahsupTutar],tblAkis[KaynakKartId],$B18,tblAkis[Durum],"MAHSUP")) | H18: =IF($A18="","",MAX(0,$D18-$G18)) | I18: =IF($A18="","",IF($C18="","",raporTarihi-$C18)) | J18: =IF($A18="","",IF($I18="","",IF($I18<=7,"0-7",IF($I18<=30,"8-30",IF($I18<=60,"31-60","60+"))))) | K18: =IF($A18="","",IF($B18="","YETİM",IF(COUNTIF(tblKartlar[KartId],$B18)=0,"YETİM",""))) | L18: =IF($A18="","",IF($G18>$D18+kad_mahsupTolerans,"AŞIM","UYGUN"))
