Workbook
Name hesapYili: GIRDI!$B$8
Name raporTarihi: AYARLAR!$B$7
Name tbo_oranBesPuan: MOTOR!$G$8
Name tbo_oranIlave: MOTOR!$G$9
Name tbo_oranKadinGenc: MOTOR!$G$11
Name tbo_mevcutTesvik: MOTOR!$G$19
Name tbo_potansiyelTasarruf: MOTOR!$G$28
Name tbo_kacirilan: MOTOR!$G$30
Name tbo_kararMetni: MOTOR!$G$34
Name tbo_kararGerekce: MOTOR!$G$35
Name tbo_maddeAtifMetni: MOTOR!$G$52
Name tbo_kanitRaporu: MOTOR!$G$53
Name tbo_kuralYilMatris: KURALLAR!$B$17
Name tbo_parmakIzi: AYARLAR!$B$19
Name tbo_senaryoKarsilastirma: SENARYO!$B$14
Name tbo_yorumSenaryo: SENARYO!$B$15
Name tbo_duyarlilikSira: SENARYO!$B$23
Name tbo_yorumDuyarlilik: SENARYO!$B$24
Name tbo_kuralDegisimSenaryo: SENARYO!$B$26
Name tbo_yorumKuralDegisim: SENARYO!$B$27
Name tbo_tahminAralik: SENARYO!$B$40
Name tbo_yorumTahmin: SENARYO!$B$41
Name tbo_kisiKodMatris: MATRIS!$R$7
Name tbo_vakaDurum: VAKALAR!$B$12
Name tbo_vakaFark: VAKALAR!$B$13
Name tbo_tolerans: AYARLAR!$B$8
Name tbo_kacirilanEsik: AYARLAR!$B$9
Name tbo_senaryoIyi: AYARLAR!$B$10
Name tbo_senaryoKotu: AYARLAR!$B$11
Name tbo_oranArtisPuan: AYARLAR!$B$12
Name tbo_tahminAlt: AYARLAR!$B$13
Name tbo_tahminUst: AYARLAR!$B$14
Name tbo_tornadoMatrah: AYARLAR!$B$15
Name tbo_tornadoMevcut: AYARLAR!$B$16
Name tbo_isverenOran: AYARLAR!$B$17
Name tbo_yuzdelikOran: AYARLAR!$B$18
Name tbo_girisBeklenen: AYARLAR!$B$21
Name tbo_riskDusuk: AYARLAR!$B$22
Name tbo_riskOrta: AYARLAR!$B$23
Name tbo_riskYuksek: AYARLAR!$B$24
Name tbo_riskEsikOran: AYARLAR!$B$25
Name tbo_yilTaban: AYARLAR!$B$26
Name tbo_yuvarMax: AYARLAR!$B$27
Name tbo_azamiMatrahEsik: AYARLAR!$B$28
Name vaka_matrah_1: AYARLAR!$B$29
Name vaka_matrah_2: AYARLAR!$B$30
Name vaka_tavan: AYARLAR!$B$31
Name tbo_modulT1: PANO!$C$11
Name tbo_modulT1Yorum: PANO!$D$11
Name tbo_modulT2: PANO!$C$12
Name tbo_modulT2Yorum: PANO!$D$12
Name tbo_modulO1: PANO!$C$13
Name tbo_modulO1Yorum: PANO!$D$13
Name tbo_modulO6: PANO!$C$16
Name tbo_modulO6Yorum: PANO!$D$16
Name tbo_modulO8: PANO!$C$17
Name tbo_modulO8Yorum: PANO!$D$17
Name tbo_modulI2: PANO!$C$20
Name tbo_modulI2Yorum: PANO!$D$20
Name ListeYillar: LISTELER!$A$6:$A$8

Sheet 00_BASLANGIC
A1: EXCELARŞİV KARAR SİSTEMİ v15.1 — ÜRETİM REFERANSI
A3: Konu | B3: Bağlayıcı Standart
A4: Amaç | B4: Kanıta dayalı, hatada kapalı çalışan Excel üretim ve denetim sistemi
A5: Öncelik | B5: Kullanıcının açık iş talebi ve gerçek kullanım senaryosu
A6: Ana akış | B6: Uygunluk → Yönetişim → Sözleşmeler → Üretim → Test → Kanıt → Kullanıcı Kabulü → Yayın
A7: Yayın ilkesi | B7: Üst aşamada hata varsa alt aşama GEÇTİ üretilemez
A8: Kullanıcı kabulü | B8: Excel masaüstü görünümü test edilmediyse DIŞ_KABUL_GEREKLİ
A9: Nihai yayın | B9: Yalnız uygulanabilir modüller GEÇTİ veya gerekçeli UYGULANMAZ
A10: Ticari ayrım | B10: Ekonomik olarak savunulabilir fiyat, gerçek pazar kabulü ile aynı değildir
A11: Karmaşıklık | B11: Karar değeri, eklenen karmaşıklığın maliyetinden büyük olmalıdır
A12: Excel sınırı | B12: Veritabanı, kurumsal yetkilendirme, değiştirilemez kayıt sistemi veya gerçek zamanlı olay platformu değildir
A13: Dil standardı | B13: Kullanıcıya görünen tüm sayfa, tablo, başlık, açıklama, uyarı ve karar metinleri saf Türkçe olmalıdır
A14: Muhasebe standardı | B14: Finansal ürünlerde Türkiye Tekdüzen Hesap Planı ve Türk muhasebe kullanım alışkanlıkları esas alınır
... A33: Muhasebe | B33: Türkiye Tekdüzen Hesap Planı ve Türk muhasebe/işletme düşünce yapısı esas alınır.

Sheet PANO
A1: ☰ PANO
B2: TEŞVIKLI BORDRO OPTIMIZASYON | L2: Dönem: 2026 / Tam ▼ | M2: ★ DOĞRULANMIŞ
B3: Hedef Kullanıcı: İK, bordro, SMMM, CFO · 2026 Q3 Denetim Standardı
B5: KAPSAM MATRAH | D5: KONSOLİDE | E5: MEVCUT/POTANSIYEL | G5: KONTROL | H5: NET OPERASYONEL MARJ | J5: GÜVENLİ | K5: SİSTEM GÜVEN SKORU | M5: DENETLENDİ
B7: =GİRDİLER!E17 | E7: =B7*0.22 | H7: =B7-E7 | K7: =IF(E7>0, ROUND(B7/E7, 2), 0)
B9: ↑ %14.2 konsolide canlı veri bağlantısı | E9: ● 8 Kalem nakit karşılığı: bloke | H9: ██████████░░░░░ %78.0 NET MARJ | K9: ✓ İDEAL karşılama rasyosu
B11: TEŞVIKLI BORDRO OPTIMIZASYON — DÖNEMSEL İCRA VE PROJEKSİYON | F11: +%32 Verim | H11: KONSOLİDE OPERASYON VE KARAR MATRİSİ
B12: Kümülatif Hacim vs. Operasyonel Maliyet ve Net Kâr Eğilimi | H12: Anlık Hesaplama Sonuçları, Dinamik Formül Çıktıları ve Durum Puanlaması
B14: Dönem | C14: Aktif Hacim | D14: Maliyet/Yük | E14: Hedef | H14: PARAMETRE / KALEM | I14: ANA TUTAR | J14: FARK / MARJ | K14: VADE | L14: KONTROL DURUMU
B15: D1 | C15: 65 | D15: 45 | E15: 60 | H15: Dönemlik Kümülatif Bakiye | I15: =B7*0.45 | J15: =B7*0.05 | K15: 12 Ay | L15: ✓ DÜZENLİ
B16: D2 | C16: 78 | D16: 48 | E16: 70 | H16: Kritik Eşik Güvenlik Tamponu | I16: =B7*0.30 | J16: =B7*0.03 | K16: 24 Ay | L16: ★ AVANTAJ
B17: D3 | C17: 85 | D17: 55 | E17: 80 | H17: Operasyonel Net Fark | I17: =B7*0.15 | J17: =B7*0.02 | K17: 8 Ay | L17: ● YAKLAŞAN
B18: D4 | C18: 75 | D18: 42 | E18: 75 | H18: Rezerv ve Likit Dağılım | I18: =B7*0.10 | J18: =B7*0.01 | K18: 16 Ay | L18: ✓ TAM UYUM
B19: D5 | C19: 90 | D19: 40 | E19: 85 | H19: KONSOLİDE SİSTEM TOPLAMI | I19: =SUM(I15:I18) | J19: =SUM(J15:J18) | L19: TAM DOĞRULANDI (0 HATA)
B20: D6 | C20: 96 | D20: 32 | E20: 92
B22: KONSOLİDE PAY VE AĞIRLIK | F22: LİKİDİTE RİSKİ & ERKEN UYARI SİNYALLERİ | K22: KARAR MOTORU
B23: ■ Ana Segment (%42) | F23: Nakit Açığı Riski (30 Gün) | I23: 0.00 TL (Sıfır Risk) | K23: LİKİDİTE OPTİMİZASYON FIRSATI
B24: ■ İkincil Grup (%30) | F24: Tahsilat Gecikme Toleransı | I24: 48 Gün Güvenli Eşik | K24: Atıl kalan nakit rezervinin gecelik repoda
B25: ■ Destek Birimi (%15) | F25: ██████████████████████████████████████ Güvenli Bölge (%100)
B26: ■ Rezervler (%13) | F26: ✓ 90 GÜNLÜK PROJEKSİYONDA NAKİT SIKIŞIKLIĞI TESPİT EDİLMEDİ | K26: FONLAMA SENARYOSUNU İNCELE ›

Sheet GİRDİLER
A1: ☰ PANO
B3: 🔍 TEŞVIKLI BORDRO OPTIMIZASYON — Kayıt veya hesap ara... | G3: TOPLAM: 1.450 KAYIT | I3: HATALI HÜCRE: 0 ADET
B5: TARİH | C5: REFERANS NO | D5: İŞLEM AÇIKLAMASI VE DETAY | E5: BRÜT TUTAR (₺) | F5: KDV ORANI | G5: NET TUTAR (₺) | H5: HESAP / CARİ | I5: DURUM
B6: 12.10.2026 | C6: TR-0428-A | D6: Operasyonel ana kalem tahmini | E6: 845200 | F6: 0.2 | G6: =E6/(1+F6) | H6: Vadesiz Ticari | I6: ONAYLANDI
B7: 14.10.2026 | C7: TR-0429-B | D7: Operasyonel çıkış/maliyet tahmini | E7: 1240000 | F7: 0.2 | G7: =E7/(1+F7) | H7: Tedarikçi Havuzu | I7: BEKLEMEDE
B8: 18.10.2026 | C8: TR-0430-C | D8: Ödeme takvimi tahakkuku | E8: 620500 | F8: 0.1 | G8: =E8/(1+F8) | H8: Kısa Vade Tahakkuk | I8: ONAYLANDI
B9: 21.10.2026 | C9: TR-0431-D | D9: Müşteri işlem tahmini | E9: 415000 | F9: 0.2 | G9: =E9/(1+F9) | H9: Müşteri Alacağı | I9: ONAYLANDI
B10: 25.10.2026 | C10: TR-0432-E | D10: Ana operasyon tahmini | E10: 980400 | F10: 0.2 | G10: =E10/(1+F10) | H10: Vadesiz Ticari | I10: ONAYLANDI
B11: 28.10.2026 | C11: TR-0433-F | D11: Kredi/taksit karşılığı | E11: 1850000 | F11: 0.2 | G11: =E11/(1+F11) | H11: Finansman Havuzu | I11: BLOKE
B12: 02.11.2026 | C12: TR-0434-G | D12: Sabit gider ve yönetim notları | E12: 740000 | F12: 0.2 | G12: =E12/(1+F12) | H12: Genel Yönetim | I12: ONAYLANDI
B13: 05.11.2026 | C13: TR-0435-H | D13: Operasyonel ana kalem tahmini | E13: 520800 | F13: 0.2 | G13: =E13/(1+F13) | H13: Vadesiz Ticari | I13: ONAYLANDI
B14: 09.11.2026 | C14: TR-0436-I | D14: Müşteri işlem tahmini | E14: 1120000 | F14: 0.2 | G14: =E14/(1+F14) | H14: Müşteri Alacağı | I14: ONAYLANDI
B15: 12.11.2026 | C15: TR-0437-J | D15: Operasyonel çıkış tahmini | E15: 890000 | F15: 0.2 | G15: =E15/(1+F15) | H15: Tedarikçi Havuzu | I15: ONAYLANDI
B17: SAYFA TOPLAMI (10 / 1.450 KAYIT) | E17: =SUM(E6:E15)

Sheet YÖNETİM_RAPORU
A1: ☰ PANO
B2: TEŞVIKLI BORDRO OPTIMIZASYON — NİHAİ KARAR VE DEĞERLEME
B3: Yönetim Kurulu ve İcra Komitesi için Otomatik Finansal Stres Testi Raporu · İK, bordro, SMMM, CFO
B4: DÖNEM: 2026 Q3 · DENETİM PROTOKOLÜ: ISO/VUK/IFRS UYUMLU · DURUM: ONAYLANDI
B6: SENARYO A: KÖTÜMSER (STRES TESTİ -%20) | H6: SENARYO B: BAZ MODEL (HEDEFLENEN)
B8: Ciro / Hacim Düşüşü: | E8: -%20.0 (Kriz Eşiği) | H8: Ciro / Hacim Gerçekleşmesi: | K8: %100.0 (Tam Bütçe)
B9: Beklenen Net Kâr / Getiri: | E9: =PANO!B7*0.8*0.22 | H9: Beklenen Net Kâr / Getiri: | K9: =PANO!H7
B10: Minimum Nakit Tamponu: | E10: =PANO!E7*0.75 | H10: Serbest Nakit Akımı: | K10: =PANO!H7*0.75
B11: Likidite Karşılama Oranı: | E11: =ROUND(PANO!B7*0.8/PANO!E7, 2) | H11: Yatırım Geri Dönüşü (ROI): | K11: %38.4 Yıllık
B14: STRES SENARYOSUNDA DAHİ İFLAS RİSKİ YOK | H14: OPTİMUM İCRA VE PLANLAMA REÇETESİ
B17: YÖNETİM KARAR MATRİSİ VE UYGULAMA REÇETESİ
B19: ● Öncelik 1: Acil Likidite ve Borç Servis Planlaması
B20: Sistemde hesaplanan vade günlerine sadık kalınarak nakit blokajı 3 gün önceden hazır edilmelidir.
B21: ● Öncelik 2: Formül Doğrulama ve Çapraz Sağlama
B22: Tüm hücreler kilitli formül korumasında olup girdi sayfalarında sıfır döngüsel başvuru (circular ref) garantilidir.
B23: ● Öncelik 3: Resmi Mevzuat ve Vergi Kalkanı Entegrasyonu
B24: 2026 güncel vergi dilimleri, amortisman ve SGK teşvik parametreleri tam otomatik yansıtılmaktadır.
B25: ● Öncelik 4: Yönetici İmzası ve Rapor Paylaşımı
B26: Tek tuşla PDF ve A4 çıktı formatına tam uyumlu sayfa yapısı kurgulanmıştır.

Sheet 01_YURUTME_CEKIRDEGI
A1: YÜRÜTME ÇEKİRDEĞİ — ZORUNLU ÜRETİM SIRASI
A3: Adım | B3: Modül | C3: Tetikleyici | D3: Zorunlu Kanıt | E3: GEÇTİ Kuralı | F3: Hata Durumu | G3: Sonraki Aşama
A4: 1 | B4: Excel Uygunluğu | C4: Her yeni model | D4: UYGUNLUK_KARARI | E4: Excel'in rolü açık | F4: HATA / BLOKE | G4: Yönetişim
A5: 2 | B5: Yönetişim | C5: Her model | D5: Risk seviyesi + etki girdileri | E5: Seviye hesaplandı | F5: BLOKE | G5: Sözleşmeler
A6: 3 | B6: Türk Muhasebe Eşlemesi | C6: Finansal model | D6: THP hesap eşleme tablosu | E6: Kritik satırlar THP ile uyumlu | F6: HATA | G6: Sözleşmeler
A7: 4 | B7: Veri ve Anlam Sözleşmeleri | C7: Girdi/KPI varsa | D7: Veri + KPI sözleşmeleri | E7: Kapsam %100 | F7: HATA | G7: Üretim
A8: 5 | B8: Üretim | C8: Sözleşmeler GEÇTİ | D8: Çalışan Excel | E8: Tek gerçek kaynak korunmuş | F8: HATA | G8: Testler
A9: 6 | B9: Görsel/Kullanım Katmanı | C9: Motor hazır | D9: Başlıklar + renk + grafik + yönlendirme | E9: Tüm kullanıcı sayfaları standarda uygun | F9: HATA | G9: Testler
A10: 7 | B10: Testler | C10: Üretim tamam | D10: Formül/OOXML/kimlik/oracle/golden/metamorfik | E10: Uygulanabilir hard gate'ler GEÇTİ | F10: HATA | G10: Kanıt
A11: 8 | B11: Hata-Kontrol Tutarlılığı | C11: Test sonucu var | D11: Hata taraması + kontrol sonuçları | E11: Formül hatası varken GEÇTİ yok | F11: HATA | G11: Kanıt
A12: 9 | B12: Kanıt | C12: Test sonucu var | D12: Makine okunur artefakt + özet | E12: Kanıt fiziksel ve tutarlı | F12: HATA | G12: Kullanıcı Kabulü
A13: 10 | B13: Kullanıcı Kabulü | C13: Kritik görevler | D13: Gerçek ekran davranışı | E13: Kritik görevler %100 | F13: DIŞ_KABUL_GEREKLİ | G13: Ticari
A14: 11 | B14: Ticari Değer | C14: Ürün satılacaksa | D14: ROI + demo + kanıt paketi | E14: Ekonomik değer kanıtlı | F14: UYARI / HATA | G14: Pazar Doğrulama
A15: 12 | B15: Pazar Doğrulama | C15: Pazar iddiası varsa | D15: Ücretli satış/pilot/fiyat kabul kanıtı | E15: Gerçek fiyat kabul kanıtı | F15: UYGULANMAZ / HATA | G15: Yayın

Sheet 02_KONTROL_LISTESI
A1: NİHAİ KONTROL LİSTESİ — KANITSIZ GEÇİŞ YOK
A3: Kontrol No | B3: Kontrol | C3: Beklenen | D3: Zorunlu Kapı? | E3: Sonuç
A4: K01 | B4: Kullanıcının açık talebi öncelikli mi? | C4: Evet | D4: EVET
A5: K02 | B5: Mevcut yapı, formüller ve tek gerçek kaynak korunuyor mu? | C5: Evet, değişiklik gerekçeli | D5: EVET
A6: K03 | B6: Üst aşama HATA ise alt aşama GEÇTİ engelleniyor mu? | C6: Evet | D6: EVET
A7: K04 | B7: Kanıt fiziksel çıktı ve içerik doğrulaması içeriyor mu? | C7: Evet | D7: EVET
A8: K05 | B8: Excel GUI erişimi olmadan kullanıcı görünümü GEÇTİ yazılıyor mu? | C8: Hayır | D8: EVET
A9: K06 | B9: NİHAİ yalnız GEÇTİ / gerekçeli UYGULANMAZ ile mi? | C9: Evet | D9: EVET
A10: K07 | B10: Ekonomik fiyat savunusu pazar doğrulamasından ayrılmış mı? | C10: Evet | D10: EVET
A11: K08 | B11: Prestij için gereksiz modül var mı? | C11: Hayır | D11: HAYIR
A12: K09 | B12: Excel sınırları açık mı? | C12: Evet | D12: EVET
A13: K10 | B13: Teknik kaynak korunuyor mu? | C13: Evet | D13: EVET
A14: K11 | B14: Kullanıcıya görünen tüm metinler Türkçe mi? | C14: Evet | D14: EVET
A15: K12 | B15: Her kullanıcı sayfasında üst başlık var mı? | C15: Evet | D15: EVET
... A34: K31 | B34: Premium vitrin, altyapı kadar güçlü ve satış fiyatını destekleyecek seviyede mi? | C34: Evet | D34: EVET

Sheet 03_GORSEL_TASARIM
A1: GÖRSEL TASARIM VE PREMIUM EXCEL STANDARDI
A3: Alan | B3: Zorunlu Kural | C3: Uygulama | D3: Yasak | E3: Kontrol | F3: Durum
A4: Sayfa başlığı | B4: Her kullanıcı sayfasının en üstünde tek ve açık sayfa başlığı | C4: A1'den başlayan koyu lacivert başlık bandı | D4: Başlıksız sayfa | E4: Başlık kapsama = %100 | F4: ZORUNLU
A5: Sekme renkleri | B5: Sayfalar işlevine göre renk kodlanır | C5: Girdi=mavi, hesap=gri, rapor=lacivert, kontrol=kırmızı, kılavuz=altın | D5: Rastgele renk | E5: Renk semantiği tutarlı | F5: ZORUNLU
A6: Kolon düzeni | B6: Veri blokları bitişik kolonlarda ilerler | C6: Gereksiz boş kolon bırakma; yalnız gerçek bölüm ayrımı varsa kontrollü boşluk | D6: A:C veri, D boş, E:F veri gibi parçalı yapı | E6: Boş kolon taraması | F6: ZORUNLU
A7: Girdi hücreleri | B7: Kullanıcının değiştireceği alan açıkça görünür | C7: Açık sarı dolgu + mavi yazı | D7: Formülle aynı görünüm | E7: Girdi/formül ayrımı | F7: ZORUNLU
A8: Formüller | B8: Hesap hücreleri kullanıcı girdisinden ayrılır | C8: Siyah yazı; sayfalar arası bağlantı yeşil yazı | D8: Hard-code gizleme | E8: Formül sınıfı kontrolü | F8: ZORUNLU
A9: Grafik sayısı | B9: Yönetici ekranında en fazla 3 ana karar grafiği | C9: Trend, karşılaştırma, köprü/dağılım; iş kararına bağlı | D9: Grafik kalabalığı | E9: Grafik başına karar sorusu | F9: ZORUNLU
A10: Grafik stili | B10: Kurumsal ve yüksek okunabilirlik | C10: Beyaz zemin, ince gridline, tek vurgu rengi, açık birim/başlık | D10: 3B, gölge, neon, gökkuşağı renkleri | E10: Görsel inceleme | F10: ZORUNLU
A11: Grafik başlığı | B11: Grafik 'neyi' değil 'ne anlama geldiğini' söyler | C11: Örn: 'Nakit 2028'de kritik eşiğin altına iniyor' | D11: 'Nakit Grafiği' gibi anlamsız başlık | E11: Başlık karar testi | F11: ZORUNLU
A12: Birimler | B12: Tüm finansal görsellerde birim açık | C12: TL, bin TL, milyon TL, %, gün, x | D12: Birim belirsizliği | E12: Birim kapsama %100 | F12: ZORUNLU
A13: Sıfır/negatif | B13: Finansal format standardı | C13: Sıfır='-', negatif kırmızı parantez | D13: -500 veya 0,00 kalabalığı | E13: Format kontrolü | F13: ZORUNLU
A14: Yazı tipi | B14: Tek aile | C14: Aptos veya Segoe UI | D14: Karışık font | E14: Tek font kontrolü | F14: ZORUNLU
... A22: Premium vitrin | B22: Görsel kalite ürün değerinin zorunlu parçasıdır | C22: Kaliteli grafik, gerçek KPI kartı, finansal hiyerarşi, tab rengi, fonksiyonel navigasyon | D22: Sadece doğru hesap yapıp çıplak/varsayılan Excel görünümü bırakmak | E22: Görsel release incelemesi | F22: ZORUNLU

Sheet 04_MUHASEBE_THP
A1: TÜRKİYE MUHASEBE VE TEKDÜZEN HESAP PLANI STANDARDI
A3: Konu | B3: Zorunlu Standart | C3: Örnek Türkçe Ad | D3: THP / Mantık | E3: Hata Riski | F3: Kontrol
A4: Dil | B4: Kullanıcıya görünen finansal terimler Türkçe | C4: Hasılat, Satışların Maliyeti, Brüt Kâr, Faaliyet Giderleri | D4: Türk işletme kullanımına uygun | E4: İngilizce jargon | F4: Terminoloji taraması
A5: Gelir Tablosu | B5: Türk sunum sırası kullanılır | C5: Net Satışlar → Satışların Maliyeti → Brüt Kâr → Faaliyet Giderleri → Faaliyet Kârı | D5: 600/610/611; 620-623; 63x | E5: Yanlış sınıflama | F5: Hesap eşleme
A6: Bilanço | B6: Dönen/Duran Varlık ve Kısa/Uzun Vadeli Yükümlülük ayrımı | C6: Hazır Değerler, Ticari Alacaklar, Stoklar, Mali Borçlar | D6: 1xx / 2xx / 3xx / 4xx / 5xx | E6: Vade sınıfı hatası | F6: Bilanço eşitliği
A7: Nakit Akışı | B7: İşletme/Yatırım/Finansman nakit akışları ayrılır | C7: Faaliyetlerden Nakit, Yatırım Harcamaları, Finansman Nakit Akışı | D7: Dolaylı/doğrudan yöntem açık seçilir | E7: Kâr = nakit sanılması | F7: Nakit devri
A8: Ticari Alacaklar | B8: Cari ve vade mantığı korunur | C8: 120 Alıcılar | D8: 120 | E8: Tahakkuk/nakit karışması | F8: Alacak devir kontrolü
A9: Ticari Borçlar | B9: Tedarikçi borcu ayrı izlenir | C9: 320 Satıcılar | D9: 320 | E9: Gider/ödeme karışması | F9: Borç devir kontrolü
A10: Kasa/Banka | B10: Hazır değerler ayrı izlenir | C10: 100 Kasa, 102 Bankalar | D10: 100 / 102 | E10: Virmanla toplam nakdin değişmesi | F10: Virman değişmezi
A11: Stok | B11: Dikeye uygun stok türü | C11: 150 İlk Madde ve Malzeme, 153 Ticari Mallar | D11: 15x | E11: Maliyet ve stok hareketinin kopması | F11: Stok devri
A12: Maddi Duran Varlık | B12: Yatırım harcaması ve amortisman bağlantılı | C12: 253 Tesis Makine Cihazlar, 255 Demirbaşlar, 257 Birikmiş Amortismanlar | D12: 25x | E12: Yatırım/gider karışması | F12: Net defter değeri devri
A13: Mali Borçlar | B13: Kısa/uzun vadeli borç ayrımı | C13: 300 Banka Kredileri / 400 Banka Kredileri | D13: 300 / 400 | E13: Vade sınıfı yanlış | F13: Borç devri
A14: Özkaynak | B14: Sermaye ve geçmiş yıl kârları ayrı | C14: 500 Sermaye, 570 Geçmiş Yıllar Kârları, 590 Dönem Net Kârı | D14: 5xx | E14: Net kâr bağının kopması | F14: Özkaynak devri
... A18: İstisna | B18: TFRS özel ürün varsa fark açık yazılır | C18: Tekdüzen raporlama ≠ TFRS finansal tablo sunumu | D18: Amaç belirtilir | E18: Standartları karıştırma | F18: Model amacı kontrolü

Sheet 05_KARAR_SATIS
A1: KARAR, GÜVEN VE SATIŞA HAZIRLIK STANDARDI
A3: Alan | B3: Müşteri Sorusu | C3: Zorunlu Ürün Davranışı | D3: Kanıt | E3: Başarısızlık Durumu | F3: Kapı
A4: 5 saniye | B4: Bu ürün neyi çözüyor? | C4: İlk ekranda hedef kullanıcı + pahalı problem + sonuç görünür | D4: Başlık + alt mesaj + gerçek ekran | E4: Ürün yalnız teknik isim | F4: HATA
A5: Acı | B5: Sorun bana neye mal oluyor? | C5: Mümkünse müşterinin kendi verisiyle parasal/zaman etkisi hesaplanır | D5: ROI/acı hesaplama yöntemi | E5: Uydurma tasarruf | F5: HATA
A6: Karar | B6: Bu bilgiyle ne yapacağım? | C6: Her kritik KPI aksiyona bağlanır | D6: KARAR_KUYRUGU | E6: Sadece rapor | F6: HATA
A7: Güven | B7: Bu sayıya neden inanayım? | C7: Kaynak, formül mantığı, kontrol ve son doğrulama görünür | D7: Kontroller + kaynak izi + sürüm | E7: Prestij kelimesi | F7: HATA
A8: Referans | B8: Müşteri yorumu yoksa ne göstereceğim? | C8: Önce/Sonra + Karar Vakası + Hata Önleme Vakası üretilir | D8: Demo/örnek çıktı | E8: Kanıtsız iddia | F8: HATA
A9: Senaryo | B9: Ne olursa işler bozulur? | C9: Baz/Aşağı/Yukarı veya uygun stres senaryosu | D9: Senaryo karşılaştırma | E9: Dekoratif senaryo | F9: HATA
A10: Ters stres | B10: Hangi eşikte karar kırılır? | C10: En az bir kritik sürücü için kırılma eşiği | D10: Kırılma eşiği tablosu | E10: Sadece +/- %10 | F10: UYARI/HATA
A11: Hata tutarlılığı | B11: Formül hata verirse ne olur? | C11: Kontrol GEÇTİ veremez; BLOKE/HATA üretir | D11: Hata taraması | E11: Hata + GEÇTİ birlikte | F11: HATA
A12: Karar motoru | B12: Ne oldu, neden oldu? | C12: Sorun + neden + parasal etki + aksiyon + son tarih | D12: Karar tablosu | E12: Boş sayfa / isim düzeyi modül | F12: HATA
A13: Yönetici özeti | B13: 5 saniyede ne görmeliyim? | C13: Bugün / ne değişti / ne bozulacak / neden / ne yapmalıyım / güven | D13: Yönetici özeti ekranı | E13: KPI kutusu yığını | F13: HATA
A14: Teklif | B14: Neden satın almalıyım? | C14: Dosya özellikleri yerine sonuç ve kaçınılan maliyet sunulur | D14: Ürün sayfası kanıt eşlemesi | E14: Özellik listesiyle satış | F14: HATA
... A19: Pazar kanıtı | B19: Piyasa gerçekten ödüyor mu? | C19: Satış/pilot/LOI/fiyat kabulü olmadan pazar doğrulandı yazılmaz | D19: Gerçek işlem kanıtı | E19: Tahmini talep = satış kabulü | F19: HATA

Sheet GIRDI
A1: GIRDI — Teşvikli Bordro Optimizasyon
A3: Dönem ve işveren
A4: Sarı hücreler manuel giriştir. Potansiyel tasarruf formülle üretilir.
A5: Alan | B5: Değer | C5: Birim
A6: İşveren Adı | B6: Örnek Üretim A.Ş. | C6: metin
A7: Dönem | B7: 2025-01 | C7: metin
A8: Hesap Yılı | B8: 2025 | C8: yıl
A9: Aylık Brüt Prim Matrahı [₺] | B9: 500000 | C9: ₺
A10: Çalışan Sayısı | B10: 20 | C10: adet
A11: 5 Puan Kapsam Matrahı [₺] | B11: 300000 | C11: ₺
A12: İlave İstihdam Matrahı [₺] | B12: 100000 | C12: ₺
A13: Kadın/Genç Matrahı [₺] | B13: 50000 | C13: ₺
A14: Engelli Matrahı [₺] | B14: 30000 | C14: ₺
A15: Mevcut Teşvik Tutarı [₺] | B15: 10000 | C15: ₺
A16: Birikim Yorumu (A/B) | B16: A | C16: metin
A18: Potansiyel Tasarruf (ayna) [₺] | B18: =IFERROR(tbo_potansiyelTasarruf,0)
A19: Giriş doluluk (kalite) | B19: =IFERROR(IF(OR(COUNTA(B6:B16)=0,tbo_girisBeklenen=0),0,ROUND(COUNTA(B6:B16)/tbo_girisBeklenen*100,0)),0)
A22: Giriş tablosu (otomasyon / boş-mod)
A23: Alan Anahtarı | B23: Değer | C23: Birim | D23: Zorunlu | E23: Kaynak | F23: Kontrol
A24: isveren_adi | B24: Örnek Üretim A.Ş. | C24: metin | D24: Evet | E24: GIRDI | F24: =IF($A24="","",IF($B24="","EKSİK","TAM"))
A25: donem | B25: 2025-01 | C25: metin | D25: Evet | E25: GIRDI | F25: =IF($A25="","",IF($B25="","EKSİK","TAM"))
A26: hesapYili | B26: 2025 | C26: yıl | D26: Evet | E26: GIRDI | F26: =IF($A26="","",IF($B26="","EKSİK","TAM"))
A27: aylik_brut_matrah | B27: 500000 | C27: TL | D27: Evet | E27: GIRDI | F27: =IF($A27="","",IF($B27="","EKSİK","TAM"))
A28: calisan_sayisi | B28: 20 | C28: adet | D28: Evet | E28: GIRDI | F28: =IF($A28="","",IF($B28="","EKSİK","TAM"))
A29: bes_puan_matrah | B29: 300000 | C29: TL | D29: Evet | E29: GIRDI | F29: =IF($A29="","",IF($B29="","EKSİK","TAM"))
A30: ilave_istihdam_matrah | B30: 100000 | C30: TL | D30: Evet | E30: GIRDI | F30: =IF($A30="","",IF($B30="","EKSİK","TAM"))
A31: kadin_genc_matrah | B31: 50000 | C31: TL | D31: Evet | E31: GIRDI | F31: =IF($A31="","",IF($B31="","EKSİK","TAM"))
A32: engelli_matrah | B32: 30000 | C32: TL | D32: Evet | E32: GIRDI | F32: =IF($A32="","",IF($B32="","EKSİK","TAM"))
A33: mevcut_tesvik_tutari | B33: 10000 | C33: TL | D33: Evet | E33: GIRDI | F33: =IF($A33="","",IF($B33="","EKSİK","TAM"))
A34: birikim_yorumu | B34: A | C34: A/B | D34: Evet | E34: GIRDI | F34: =IF($A34="","",IF($B34="","EKSİK","TAM"))
F35: =IF($A35="","",IF($B35="","EKSİK","TAM"))
F36: =IF($A36="","",IF($B36="","EKSİK","TAM"))
F37: =IF($A37="","",IF($B37="","EKSİK","TAM"))
F38: =IF($A38="","",IF($B38="","EKSİK","TAM"))
F39: =IF($A39="","",IF($B39="","EKSİK","TAM"))
F40: =IF($A40="","",IF($B40="","EKSİK","TAM"))
F41: =IF($A41="","",IF($B41="","EKSİK","TAM"))
F42: =IF($A42="","",IF($B42="","EKSİK","TAM"))
F43: =IF($A43="","",IF($B43="","EKSİK","TAM"))
F44: =IF($A44="","",IF($B44="","EKSİK","TAM"))
...

Sheet BORDRO
A1: BORDRO — Teşvikli Bordro Optimizasyon
A3: Çalışan satır bordrosu — kişi başı en avantajlı teşvik
A4: Sarı hücreler manuel giriş. En avantajlı kod ve tasarruf formülle üretilir (oranlar KURALLAR tablosundan; sabit oran yok). | R4: Çalışan adedi | S4: =IFERROR(COUNTA(tblBordro[CalisanNo]),0)
R5: Toplam brüt matrah | S5: =IFERROR(SUM(tblBordro[BrutMatrah]),0)
A6: CalisanNo | B6: AdSoyad | C6: BrutMatrah | D6: BesPuanUygun | E6: IlaveUygun | F6: KadinGencUygun | G6: EngelliUygun | H6: MevcutKod | I6: EnAvantajliKod | J6: EnAvantajliTutar | K6: MevcutTutar | L6: Kacirilan | R6: En avantajlı toplam | S6: =IFERROR(SUM(tblBordro[EnAvantajliTutar]),0)
A7: 1 | B7: Ali Yılmaz | C7: 25000 | D7: Evet | E7: Hayır | F7: Hayır | G7: Hayır | H7: TBO-001 | I7: =IF($A7="","",IF($J7=0,"YOK",IF(AND($E7="Evet",ROUND($C7*tbo_oranIlave,2)=$J7),"TBO-002",IF(AND($D7="Evet",ROUND($C7*tbo_oranBesPuan,2)=$J7),"TBO-001",IF(AND($F7="Evet",ROUND($C7*tbo_oranKadinGenc,2)=$J7),"TBO-004","TBO-ENG"))))) | J7: =IF($A7="","",MAX(IF($D7="Evet",ROUND($C7*tbo_oranBesPuan,2),0),IF($E7="Evet",ROUND($C7*tbo_oranIlave,2),0),IF($F7="Evet",ROUND($C7*tbo_oranKadinGenc,2),0),IF($G7="Evet",ROUND($C7*tbo_isverenOran,2),0))) | K7: =IF($A7="","",IF($H7="TBO-001",IF($D7="Evet",ROUND($C7*tbo_oranBesPuan,2),0),IF($H7="TBO-002",IF($E7="Evet",ROUND($C7*tbo_oranIlave,2),0),IF($H7="TBO-004",IF($F7="Evet",ROUND($C7*tbo_oranKadinGenc,2),0),IF($H7="TBO-ENG",IF($G7="Evet",ROUND($C7*tbo_isverenOran,2),0),0))))) | L7: =IF($A7="","",MAX(0,$J7-$K7)) | R7: Mevcut toplam | S7: =IFERROR(SUM(tblBordro[MevcutTutar]),0)
A8: 2 | B8: Ayşe Demir | C8: 22000 | D8: Evet | E8: Evet | F8: Hayır | G8: Hayır | H8: TBO-001 | I8: =IF($A8="","",IF($J8=0,"YOK",IF(AND($E8="Evet",ROUND($C8*tbo_oranIlave,2)=$J8),"TBO-002",IF(AND($D8="Evet",ROUND($C8*tbo_oranBesPuan,2)=$J8),"TBO-001",IF(AND($F8="Evet",ROUND($C8*tbo_oranKadinGenc,2)=$J8),"TBO-004","TBO-ENG"))))) | J8: =IF($A8="","",MAX(IF($D8="Evet",ROUND($C8*tbo_oranBesPuan,2),0),IF($E8="Evet",ROUND($C8*tbo_oranIlave,2),0),IF($F8="Evet",ROUND($C8*tbo_oranKadinGenc,2),0),IF($G8="Evet",ROUND($C8*tbo_isverenOran,2),0))) | K8: =IF($A8="","",IF($H8="TBO-001",IF($D8="Evet",ROUND($C8*tbo_oranBesPuan,2),0),IF($H8="TBO-002",IF($E8="Evet",ROUND($C8*tbo_oranIlave,2),0),IF($H8="TBO-004",IF($F8="Evet",ROUND($C8*tbo_oranKadinGenc,2),0),IF($H8="TBO-ENG",IF($G8="Evet",ROUND($C8*tbo_isverenOran,2),0),0))))) | L8: =IF($A8="","",MAX(0,$J8-$K8)) | R8: Kaçırılan toplam | S8: =IFERROR(SUM(tblBordro[Kacirilan]),0)
A9: 3 | B9: Mehmet Kaya | C9: 28000 | D9: Evet | E9: Hayır | F9: Evet | G9: Hayır | H9: TBO-004 | I9: =IF($A9="","",IF($J9=0,"YOK",IF(AND($E9="Evet",ROUND($C9*tbo_oranIlave,2)=$J9),"TBO-002",IF(AND($D9="Evet",ROUND($C9*tbo_oranBesPuan,2)=$J9),"TBO-001",IF(AND($F9="Evet",ROUND($C9*tbo_oranKadinGenc,2)=$J9),"TBO-004","TBO-ENG"))))) | J9: =IF($A9="","",MAX(IF($D9="Evet",ROUND($C9*tbo_oranBesPuan,2),0),IF($E9="Evet",ROUND($C9*tbo_oranIlave,2),0),IF($F9="Evet",ROUND($C9*tbo_oranKadinGenc,2),0),IF($G9="Evet",ROUND($C9*tbo_isverenOran,2),0))) | K9: =IF($A9="","",IF($H9="TBO-001",IF($D9="Evet",ROUND($C9*tbo_oranBesPuan,2),0),IF($H9="TBO-002",IF($E9="Evet",ROUND($C9*tbo_oranIlave,2),0),IF($H9="TBO-004",IF($F9="Evet",ROUND($C9*tbo_oranKadinGenc,2),0),IF($H9="TBO-ENG",IF($G9="Evet",ROUND($C9*tbo_isverenOran,2),0),0))))) | L9: =IF($A9="","",MAX(0,$J9-$K9)) | R9: En sık avantajlı kod | S9: =IFERROR(IF(COUNTA(tblBordro[CalisanNo])=0,"VERİ YOK",IF(COUNTIF(tblBordro[EnAvantajliKod],"TBO-002")>=MAX(COUNTIF(tblBordro[EnAvantajliKod],"TBO-001"),COUNTIF(tblBordro[EnAvantajliKod],"TBO-002"),COUNTIF(tblBordro[EnAvantajliKod],"TBO-004")),"TBO-002",IF(COUNTIF(tblBordro[EnAvantajliKod],"TBO-001")>=COUNTIF(tblBordro[EnAvantajliKod],"TBO-004"),"TBO-001","TBO-004"))),"-")
A10: 4 | B10: Zeynep Arslan | C10: 20000 | D10: Hayır | E10: Evet | F10: Hayır | G10: Hayır | H10: YOK | I10: =IF($A10="","",IF($J10=0,"YOK",IF(AND($E10="Evet",ROUND($C10*tbo_oranIlave,2)=$J10),"TBO-002",IF(AND($D10="Evet",ROUND($C10*tbo_oranBesPuan,2)=$J10),"TBO-001",IF(AND($F10="Evet",ROUND($C10*tbo_oranKadinGenc,2)=$J10),"TBO-004","TBO-ENG"))))) | J10: =IF($A10="","",MAX(IF($D10="Evet",ROUND($C10*tbo_oranBesPuan,2),0),IF($E10="Evet",ROUND($C10*tbo_oranIlave,2),0),IF($F10="Evet",ROUND($C10*tbo_oranKadinGenc,2),0),IF($G10="Evet",ROUND($C10*tbo_isverenOran,2),0))) | K10: =IF($A10="","",IF($H10="TBO-001",IF($D10="Evet",ROUND($C10*tbo_oranBesPuan,2),0),IF($H10="TBO-002",IF($E10="Evet",ROUND($C10*tbo_oranIlave,2),0),IF($H10="TBO-004",IF($F10="Evet",ROUND($C10*tbo_oranKadinGenc,2),0),IF($H10="TBO-ENG",IF($G10="Evet",ROUND($C10*tbo_isverenOran,2),0),0))))) | L10: =IF($A10="","",MAX(0,$J10-$K10))
A11: 5 | B11: Can Öztürk | C11: 30000 | D11: Evet | E11: Evet | F11: Hayır | G11: Evet | H11: TBO-001 | I11: =IF($A11="","",IF($J11=0,"YOK",IF(AND($E11="Evet",ROUND($C11*tbo_oranIlave,2)=$J11),"TBO-002",IF(AND($D11="Evet",ROUND($C11*tbo_oranBesPuan,2)=$J11),"TBO-001",IF(AND($F11="Evet",ROUND($C11*tbo_oranKadinGenc,2)=$J11),"TBO-004","TBO-ENG"))))) | J11: =IF($A11="","",MAX(IF($D11="Evet",ROUND($C11*tbo_oranBesPuan,2),0),IF($E11="Evet",ROUND($C11*tbo_oranIlave,2),0),IF($F11="Evet",ROUND($C11*tbo_oranKadinGenc,2),0),IF($G11="Evet",ROUND($C11*tbo_isverenOran,2),0))) | K11: =IF($A11="","",IF($H11="TBO-001",IF($D11="Evet",ROUND($C11*tbo_oranBesPuan,2),0),IF($H11="TBO-002",IF($E11="Evet",ROUND($C11*tbo_oranIlave,2),0),IF($H11="TBO-004",IF($F11="Evet",ROUND($C11*tbo_oranKadinGenc,2),0),IF($H11="TBO-ENG",IF($G11="Evet",ROUND($C11*tbo_isverenOran,2),0),0))))) | L11: =IF($A11="","",MAX(0,$J11-$K11))
A12: 6 | B12: Elif Şahin | C12: 18000 | D12: Evet | E12: Hayır | F12: Evet | G12: Hayır | H12: TBO-001 | I12: =IF($A12="","",IF($J12=0,"YOK",IF(AND($E12="Evet",ROUND($C12*tbo_oranIlave,2)=$J12),"TBO-002",IF(AND($D12="Evet",ROUND($C12*tbo_oranBesPuan,2)=$J12),"TBO-001",IF(AND($F12="Evet",ROUND($C12*tbo_oranKadinGenc,2)=$J12),"TBO-004","TBO-ENG"))))) | J12: =IF($A12="","",MAX(IF($D12="Evet",ROUND($C12*tbo_oranBesPuan,2),0),IF($E12="Evet",ROUND($C12*tbo_oranIlave,2),0),IF($F12="Evet",ROUND($C12*tbo_oranKadinGenc,2),0),IF($G12="Evet",ROUND($C12*tbo_isverenOran,2),0))) | K12: =IF($A12="","",IF($H12="TBO-001",IF($D12="Evet",ROUND($C12*tbo_oranBesPuan,2),0),IF($H12="TBO-002",IF($E12="Evet",ROUND($C12*tbo_oranIlave,2),0),IF($H12="TBO-004",IF($F12="Evet",ROUND($C12*tbo_oranKadinGenc,2),0),IF($H12="TBO-ENG",IF($G12="Evet",ROUND($C12*tbo_isverenOran,2),0),0))))) | L12: =IF($A12="","",MAX(0,$J12-$K12)) | R12: Kod | S12: AdetDemo
A13: 7 | B13: Burak Çelik | C13: 35000 | D13: Evet | E13: Evet | F13: Hayır | G13: Hayır | H13: TBO-002 | I13: =IF($A13="","",IF($J13=0,"YOK",IF(AND($E13="Evet",ROUND($C13*tbo_oranIlave,2)=$J13),"TBO-002",IF(AND($D13="Evet",ROUND($C13*tbo_oranBesPuan,2)=$J13),"TBO-001",IF(AND($F13="Evet",ROUND($C13*tbo_oranKadinGenc,2)=$J13),"TBO-004","TBO-ENG"))))) | J13: =IF($A13="","",MAX(IF($D13="Evet",ROUND($C13*tbo_oranBesPuan,2),0),IF($E13="Evet",ROUND($C13*tbo_oranIlave,2),0),IF($F13="Evet",ROUND($C13*tbo_oranKadinGenc,2),0),IF($G13="Evet",ROUND($C13*tbo_isverenOran,2),0))) | K13: =IF($A13="","",IF($H13="TBO-001",IF($D13="Evet",ROUND($C13*tbo_oranBesPuan,2),0),IF($H13="TBO-002",IF($E13="Evet",ROUND($C13*tbo_oranIlave,2),0),IF($H13="TBO-004",IF($F13="Evet",ROUND($C13*tbo_oranKadinGenc,2),0),IF($H13="TBO-ENG",IF($G13="Evet",ROUND($C13*tbo_isverenOran,2),0),0))))) | L13: =IF($A13="","",MAX(0,$J13-$K13)) | R13: TBO-001 | S13: 4
A14: 8 | B14: Selin Aydın | C14: 24000 | D14: Hayır | E14: Hayır | F14: Evet | G14: Hayır | H14: YOK | I14: =IF($A14="","",IF($J14=0,"YOK",IF(AND($E14="Evet",ROUND($C14*tbo_oranIlave,2)=$J14),"TBO-002",IF(AND($D14="Evet",ROUND($C14*tbo_oranBesPuan,2)=$J14),"TBO-001",IF(AND($F14="Evet",ROUND($C14*tbo_oranKadinGenc,2)=$J14),"TBO-004","TBO-ENG"))))) | J14: =IF($A14="","",MAX(IF($D14="Evet",ROUND($C14*tbo_oranBesPuan,2),0),IF($E14="Evet",ROUND($C14*tbo_oranIlave,2),0),IF($F14="Evet",ROUND($C14*tbo_oranKadinGenc,2),0),IF($G14="Evet",ROUND($C14*tbo_isverenOran,2),0))) | K14: =IF($A14="","",IF($H14="TBO-001",IF($D14="Evet",ROUND($C14*tbo_oranBesPuan,2),0),IF($H14="TBO-002",IF($E14="Evet",ROUND($C14*tbo_oranIlave,2),0),IF($H14="TBO-004",IF($F14="Evet",ROUND($C14*tbo_oranKadinGenc,2),0),IF($H14="TBO-ENG",IF($G14="Evet",ROUND($C14*tbo_isverenOran,2),0),0))))) | L14: =IF($A14="","",MAX(0,$J14-$K14)) | R14: TBO-002 | S14: 3
A15: 9 | B15: Emre Koç | C15: 27000 | D15: Evet | E15: Hayır | F15: Hayır | G15: Evet | H15: TBO-001 | I15: =IF($A15="","",IF($J15=0,"YOK",IF(AND($E15="Evet",ROUND($C15*tbo_oranIlave,2)=$J15),"TBO-002",IF(AND($D15="Evet",ROUND($C15*tbo_oranBesPuan,2)=$J15),"TBO-001",IF(AND($F15="Evet",ROUND($C15*tbo_oranKadinGenc,2)=$J15),"TBO-004","TBO-ENG"))))) | J15: =IF($A15="","",MAX(IF($D15="Evet",ROUND($C15*tbo_oranBesPuan,2),0),IF($E15="Evet",ROUND($C15*tbo_oranIlave,2),0),IF($F15="Evet",ROUND($C15*tbo_oranKadinGenc,2),0),IF($G15="Evet",ROUND($C15*tbo_isverenOran,2),0))) | K15: =IF($A15="","",IF($H15="TBO-001",IF($D15="Evet",ROUND($C15*tbo_oranBesPuan,2),0),IF($H15="TBO-002",IF($E15="Evet",ROUND($C15*tbo_oranIlave,2),0),IF($H15="TBO-004",IF($F15="Evet",ROUND($C15*tbo_oranKadinGenc,2),0),IF($H15="TBO-ENG",IF($G15="Evet",ROUND($C15*tbo_isverenOran,2),0),0))))) | L15: =IF($A15="","",MAX(0,$J15-$K15)) | R15: TBO-004 | S15: 2
A16: 10 | B16: Deniz Yıldız | C16: 21000 | D16: Evet | E16: Evet | F16: Evet | G16: Hayır | H16: TBO-001 | I16: =IF($A16="","",IF($J16=0,"YOK",IF(AND($E16="Evet",ROUND($C16*tbo_oranIlave,2)=$J16),"TBO-002",IF(AND($D16="Evet",ROUND($C16*tbo_oranBesPuan,2)=$J16),"TBO-001",IF(AND($F16="Evet",ROUND($C16*tbo_oranKadinGenc,2)=$J16),"TBO-004","TBO-ENG"))))) | J16: =IF($A16="","",MAX(IF($D16="Evet",ROUND($C16*tbo_oranBesPuan,2),0),IF($E16="Evet",ROUND($C16*tbo_oranIlave,2),0),IF($F16="Evet",ROUND($C16*tbo_oranKadinGenc,2),0),IF($G16="Evet",ROUND($C16*tbo_isverenOran,2),0))) | K16: =IF($A16="","",IF($H16="TBO-001",IF($D16="Evet",ROUND($C16*tbo_oranBesPuan,2),0),IF($H16="TBO-002",IF($E16="Evet",ROUND($C16*tbo_oranIlave,2),0),IF($H16="TBO-004",IF($F16="Evet",ROUND($C16*tbo_oranKadinGenc,2),0),IF($H16="TBO-ENG",IF($G16="Evet",ROUND($C16*tbo_isverenOran,2),0),0))))) | L16: =IF($A16="","",MAX(0,$J16-$K16)) | R16: YOK | S16: 1
I17: =IF($A17="","",IF($J17=0,"YOK",IF(AND($E17="Evet",ROUND($C17*tbo_oranIlave,2)=$J17),"TBO-002",IF(AND($D17="Evet",ROUND($C17*tbo_oranBesPuan,2)=$J17),"TBO-001",IF(AND($F17="Evet",ROUND($C17*tbo_oranKadinGenc,2)=$J17),"TBO-004","TBO-ENG"))))) | J17: =IF($A17="","",MAX(IF($D17="Evet",ROUND($C17*tbo_oranBesPuan,2),0),IF($E17="Evet",ROUND($C17*tbo_oranIlave,2),0),IF($F17="Evet",ROUND($C17*tbo_oranKadinGenc,2),0),IF($G17="Evet",ROUND($C17*tbo_isverenOran,2),0))) | K17: =IF($A17="","",IF($H17="TBO-001",IF($D17="Evet",ROUND($C17*tbo_oranBesPuan,2),0),IF($H17="TBO-002",IF($E17="Evet",ROUND($C17*tbo_oranIlave,2),0),IF($H17="TBO-004",IF($F17="Evet",ROUND($C17*tbo_oranKadinGenc,2),0),IF($H17="TBO-ENG",IF($G17="Evet",ROUND($C17*tbo_isverenOran,2),0),0))))) | L17: =IF($A17="","",MAX(0,$J17-$K17))
I18: =IF($A18="","",IF($J18=0,"YOK",IF(AND($E18="Evet",ROUND($C18*tbo_oranIlave,2)=$J18),"TBO-002",IF(AND($D18="Evet",ROUND($C18*tbo_oranBesPuan,2)=$J18),"TBO-001",IF(AND($F18="Evet",ROUND($C18*tbo_oranKadinGenc,2)=$J18),"TBO-004","TBO-ENG"))))) | J18: =IF($A18="","",MAX(IF($D18="Evet",ROUND($C18*tbo_oranBesPuan,2),0),IF($E18="Evet",ROUND($C18*tbo_oranIlave,2),0),IF($F18="Evet",ROUND($C18*tbo_oranKadinGenc,2),0),IF($G18="Evet",ROUND($C18*tbo_isverenOran,2),0))) | K18: =IF($A18="","",IF($H18="TBO-001",IF($D18="Evet",ROUND($C18*tbo_oranBesPuan,2),0),IF($H18="TBO-002",IF($E18="Evet",ROUND($C18*tbo_oranIlave,2),0),IF($H18="TBO-004",IF($F18="Evet",ROUND($C18*tbo_oranKadinGenc,2),0),IF($H18="TBO-ENG",IF($G18="Evet",ROUND($C18*tbo_isverenOran,2),0),0))))) | L18: =IF($A18="","",MAX(0,$J18-$K18))
I19: =IF($A19="","",IF($J19=0,"YOK",IF(AND($E19="Evet",ROUND($C19*tbo_oranIlave,2)=$J19),"TBO-002",IF(AND($D19="Evet",ROUND($C19*tbo_oranBesPuan,2)=$J19),"TBO-001",IF(AND($F19="Evet",ROUND($C19*tbo_oranKadinGenc,2)=$J19),"TBO-004","TBO-ENG"))))) | J19: =IF($A19="","",MAX(IF($D19="Evet",ROUND($C19*tbo_oranBesPuan,2),0),IF($E19="Evet",ROUND($C19*tbo_oranIlave,2),0),IF($F19="Evet",ROUND($C19*tbo_oranKadinGenc,2),0),IF($G19="Evet",ROUND($C19*tbo_isverenOran,2),0))) | K19: =IF($A19="","",IF($H19="TBO-001",IF($D19="Evet",ROUND($C19*tbo_oranBesPuan,2),0),IF($H19="TBO-002",IF($E19="Evet",ROUND($C19*tbo_oranIlave,2),0),IF($H19="TBO-004",IF($F19="Evet",ROUND($C19*tbo_oranKadinGenc,2),0),IF($H19="TBO-ENG",IF($G19="Evet",ROUND($C19*tbo_isverenOran,2),0),0))))) | L19: =IF($A19="","",MAX(0,$J19-$K19))
I20: =IF($A20="","",IF($J20=0,"YOK",IF(AND($E20="Evet",ROUND($C20*tbo_oranIlave,2)=$J20),"TBO-002",IF(AND($D20="Evet",ROUND($C20*tbo_oranBesPuan,2)=$J20),"TBO-001",IF(AND($F20="Evet",ROUND($C20*tbo_oranKadinGenc,2)=$J20),"TBO-004","TBO-ENG"))))) | J20: =IF($A20="","",MAX(IF($D20="Evet",ROUND($C20*tbo_oranBesPuan,2),0),IF($E20="Evet",ROUND($C20*tbo_oranIlave,2),0),IF($F20="Evet",ROUND($C20*tbo_oranKadinGenc,2),0),IF($G20="Evet",ROUND($C20*tbo_isverenOran,2),0))) | K20: =IF($A20="","",IF($H20="TBO-001",IF($D20="Evet",ROUND($C20*tbo_oranBesPuan,2),0),IF($H20="TBO-002",IF($E20="Evet",ROUND($C20*tbo_oranIlave,2),0),IF($H20="TBO-004",IF($F20="Evet",ROUND($C20*tbo_oranKadinGenc,2),0),IF($H20="TBO-ENG",IF($G20="Evet",ROUND($C20*tbo_isverenOran,2),0),0))))) | L20: =IF($A20="","",MAX(0,$J20-$K20))
I21: =IF($A21="","",IF($J21=0,"YOK",IF(AND($E21="Evet",ROUND($C21*tbo_oranIlave,2)=$J21),"TBO-002",IF(AND($D21="Evet",ROUND($C21*tbo_oranBesPuan,2)=$J21),"TBO-001",IF(AND($F21="Evet",ROUND($C21*tbo_oranKadinGenc,2)=$J21),"TBO-004","TBO-ENG"))))) | J21: =IF($A21="","",MAX(IF($D21="Evet",ROUND($C21*tbo_oranBesPuan,2),0),IF($E21="Evet",ROUND($C21*tbo_oranIlave,2),0),IF($F21="Evet",ROUND($C21*tbo_oranKadinGenc,2),0),IF($G21="Evet",ROUND($C21*tbo_isverenOran,2),0))) | K21: =IF($A21="","",IF($H21="TBO-001",IF($D21="Evet",ROUND($C21*tbo_oranBesPuan,2),0),IF($H21="TBO-002",IF($E21="Evet",ROUND($C21*tbo_oranIlave,2),0),IF($H21="TBO-004",IF($F21="Evet",ROUND($C21*tbo_oranKadinGenc,2),0),IF($H21="TBO-ENG",IF($G21="Evet",ROUND($C21*tbo_isverenOran,2),0),0))))) | L21: =IF($A21="","",MAX(0,$J21-$K21))
I22: =IF($A22="","",IF($J22=0,"YOK",IF(AND($E22="Evet",ROUND($C22*tbo_oranIlave,2)=$J22),"TBO-002",IF(AND($D22="Evet",ROUND($C22*tbo_oranBesPuan,2)=$J22),"TBO-001",IF(AND($F22="Evet",ROUND($C22*tbo_oranKadinGenc,2)=$J22),"TBO-004","TBO-ENG"))))) | J22: =IF($A22="","",MAX(IF($D22="Evet",ROUND($C22*tbo_oranBesPuan,2),0),IF($E22="Evet",ROUND($C22*tbo_oranIlave,2),0),IF($F22="Evet",ROUND($C22*tbo_oranKadinGenc,2),0),IF($G22="Evet",ROUND($C22*tbo_isverenOran,2),0))) | K22: =IF($A22="","",IF($H22="TBO-001",IF($D22="Evet",ROUND($C22*tbo_oranBesPuan,2),0),IF($H22="TBO-002",IF($E22="Evet",ROUND($C22*tbo_oranIlave,2),0),IF($H22="TBO-004",IF($F22="Evet",ROUND($C22*tbo_oranKadinGenc,2),0),IF($H22="TBO-ENG",IF($G22="Evet",ROUND($C22*tbo_isverenOran,2),0),0))))) | L22: =IF($A22="","",MAX(0,$J22-$K22))
I23: =IF($A23="","",IF($J23=0,"YOK",IF(AND($E23="Evet",ROUND($C23*tbo_oranIlave,2)=$J23),"TBO-002",IF(AND($D23="Evet",ROUND($C23*tbo_oranBesPuan,2)=$J23),"TBO-001",IF(AND($F23="Evet",ROUND($C23*tbo_oranKadinGenc,2)=$J23),"TBO-004","TBO-ENG"))))) | J23: =IF($A23="","",MAX(IF($D23="Evet",ROUND($C23*tbo_oranBesPuan,2),0),IF($E23="Evet",ROUND($C23*tbo_oranIlave,2),0),IF($F23="Evet",ROUND($C23*tbo_oranKadinGenc,2),0),IF($G23="Evet",ROUND($C23*tbo_isverenOran,2),0))) | K23: =IF($A23="","",IF($H23="TBO-001",IF($D23="Evet",ROUND($C23*tbo_oranBesPuan,2),0),IF($H23="TBO-002",IF($E23="Evet",ROUND($C23*tbo_oranIlave,2),0),IF($H23="TBO-004",IF($F23="Evet",ROUND($C23*tbo_oranKadinGenc,2),0),IF($H23="TBO-ENG",IF($G23="Evet",ROUND($C23*tbo_isverenOran,2),0),0))))) | L23: =IF($A23="","",MAX(0,$J23-$K23))
I24: =IF($A24="","",IF($J24=0,"YOK",IF(AND($E24="Evet",ROUND($C24*tbo_oranIlave,2)=$J24),"TBO-002",IF(AND($D24="Evet",ROUND($C24*tbo_oranBesPuan,2)=$J24),"TBO-001",IF(AND($F24="Evet",ROUND($C24*tbo_oranKadinGenc,2)=$J24),"TBO-004","TBO-ENG"))))) | J24: =IF($A24="","",MAX(IF($D24="Evet",ROUND($C24*tbo_oranBesPuan,2),0),IF($E24="Evet",ROUND($C24*tbo_oranIlave,2),0),IF($F24="Evet",ROUND($C24*tbo_oranKadinGenc,2),0),IF($G24="Evet",ROUND($C24*tbo_isverenOran,2),0))) | K24: =IF($A24="","",IF($H24="TBO-001",IF($D24="Evet",ROUND($C24*tbo_oranBesPuan,2),0),IF($H24="TBO-002",IF($E24="Evet",ROUND($C24*tbo_oranIlave,2),0),IF($H24="TBO-004",IF($F24="Evet",ROUND($C24*tbo_oranKadinGenc,2),0),IF($H24="TBO-ENG",IF($G24="Evet",ROUND($C24*tbo_isverenOran,2),0),0))))) | L24: =IF($A24="","",MAX(0,$J24-$K24))
I25: =IF($A25="","",IF($J25=0,"YOK",IF(AND($E25="Evet",ROUND($C25*tbo_oranIlave,2)=$J25),"TBO-002",IF(AND($D25="Evet",ROUND($C25*tbo_oranBesPuan,2)=$J25),"TBO-001",IF(AND($F25="Evet",ROUND($C25*tbo_oranKadinGenc,2)=$J25),"TBO-004","TBO-ENG"))))) | J25: =IF($A25="","",MAX(IF($D25="Evet",ROUND($C25*tbo_oranBesPuan,2),0),IF($E25="Evet",ROUND($C25*tbo_oranIlave,2),0),IF($F25="Evet",ROUND($C25*tbo_oranKadinGenc,2),0),IF($G25="Evet",ROUND($C25*tbo_isverenOran,2),0))) | K25: =IF($A25="","",IF($H25="TBO-001",IF($D25="Evet",ROUND($C25*tbo_oranBesPuan,2),0),IF($H25="TBO-002",IF($E25="Evet",ROUND($C25*tbo_oranIlave,2),0),IF($H25="TBO-004",IF($F25="Evet",ROUND($C25*tbo_oranKadinGenc,2),0),IF($H25="TBO-ENG",IF($G25="Evet",ROUND($C25*tbo_isverenOran,2),0),0))))) | L25: =IF($A25="","",MAX(0,$J25-$K25))
I26: =IF($A26="","",IF($J26=0,"YOK",IF(AND($E26="Evet",ROUND($C26*tbo_oranIlave,2)=$J26),"TBO-002",IF(AND($D26="Evet",ROUND($C26*tbo_oranBesPuan,2)=$J26),"TBO-001",IF(AND($F26="Evet",ROUND($C26*tbo_oranKadinGenc,2)=$J26),"TBO-004","TBO-ENG"))))) | J26: =IF($A26="","",MAX(IF($D26="Evet",ROUND($C26*tbo_oranBesPuan,2),0),IF($E26="Evet",ROUND($C26*tbo_oranIlave,2),0),IF($F26="Evet",ROUND($C26*tbo_oranKadinGenc,2),0),IF($G26="Evet",ROUND($C26*tbo_isverenOran,2),0))) | K26: =IF($A26="","",IF($H26="TBO-001",IF($D26="Evet",ROUND($C26*tbo_oranBesPuan,2),0),IF($H26="TBO-002",IF($E26="Evet",ROUND($C26*tbo_oranIlave,2),0),IF($H26="TBO-004",IF($F26="Evet",ROUND($C26*tbo_oranKadinGenc,2),0),IF($H26="TBO-ENG",IF($G26="Evet",ROUND($C26*tbo_isverenOran,2),0),0))))) | L26: =IF($A26="","",MAX(0,$J26-$K26))
I27: =IF($A27="","",IF($J27=0,"YOK",IF(AND($E27="Evet",ROUND($C27*tbo_oranIlave,2)=$J27),"TBO-002",IF(AND($D27="Evet",ROUND($C27*tbo_oranBesPuan,2)=$J27),"TBO-001",IF(AND($F27="Evet",ROUND($C27*tbo_oranKadinGenc,2)=$J27),"TBO-004","TBO-ENG"))))) | J27: =IF($A27="","",MAX(IF($D27="Evet",ROUND($C27*tbo_oranBesPuan,2),0),IF($E27="Evet",ROUND($C27*tbo_oranIlave,2),0),IF($F27="Evet",ROUND($C27*tbo_oranKadinGenc,2),0),IF($G27="Evet",ROUND($C27*tbo_isverenOran,2),0))) | K27: =IF($A27="","",IF($H27="TBO-001",IF($D27="Evet",ROUND($C27*tbo_oranBesPuan,2),0),IF($H27="TBO-002",IF($E27="Evet",ROUND($C27*tbo_oranIlave,2),0),IF($H27="TBO-004",IF($F27="Evet",ROUND($C27*tbo_oranKadinGenc,2),0),IF($H27="TBO-ENG",IF($G27="Evet",ROUND($C27*tbo_isverenOran,2),0),0))))) | L27: =IF($A27="","",MAX(0,$J27-$K27))
I28: =IF($A28="","",IF($J28=0,"YOK",IF(AND($E28="Evet",ROUND($C28*tbo_oranIlave,2)=$J28),"TBO-002",IF(AND($D28="Evet",ROUND($C28*tbo_oranBesPuan,2)=$J28),"TBO-001",IF(AND($F28="Evet",ROUND($C28*tbo_oranKadinGenc,2)=$J28),"TBO-004","TBO-ENG"))))) | J28: =IF($A28="","",MAX(IF($D28="Evet",ROUND($C28*tbo_oranBesPuan,2),0),IF($E28="Evet",ROUND($C28*tbo_oranIlave,2),0),IF($F28="Evet",ROUND($C28*tbo_oranKadinGenc,2),0),IF($G28="Evet",ROUND($C28*tbo_isverenOran,2),0))) | K28: =IF($A28="","",IF($H28="TBO-001",IF($D28="Evet",ROUND($C28*tbo_oranBesPuan,2),0),IF($H28="TBO-002",IF($E28="Evet",ROUND($C28*tbo_oranIlave,2),0),IF($H28="TBO-004",IF($F28="Evet",ROUND($C28*tbo_oranKadinGenc,2),0),IF($H28="TBO-ENG",IF($G28="Evet",ROUND($C28*tbo_isverenOran,2),0),0))))) | L28: =IF($A28="","",MAX(0,$J28-$K28))
... I1006: =IF($A1006="","",IF($J1006=0,"YOK",IF(AND($E1006="Evet",ROUND($C1006*tbo_oranIlave,2)=$J1006),"TBO-002",IF(AND($D1006="Evet",ROUND($C1006*tbo_oranBesPuan,2)=$J1006),"TBO-001",IF(AND($F1006="Evet",ROUND($C1006*tbo_oranKadinGenc,2)=$J1006),"TBO-004","TBO-ENG"))))) | J1006: =IF($A1006="","",MAX(IF($D1006="Evet",ROUND($C1006*tbo_oranBesPuan,2),0),IF($E1006="Evet",ROUND($C1006*tbo_oranIlave,2),0),IF($F1006="Evet",ROUND($C1006*tbo_oranKadinGenc,2),0),IF($G1006="Evet",ROUND($C1006*tbo_isverenOran,2),0))) | K1006: =IF($A1006="","",IF($H1006="TBO-001",IF($D1006="Evet",ROUND($C1006*tbo_oranBesPuan,2),0),IF($H1006="TBO-002",IF($E1006="Evet",ROUND($C1006*tbo_oranIlave,2),0),IF($H1006="TBO-004",IF($F1006="Evet",ROUND($C1006*tbo_oranKadinGenc,2),0),IF($H1006="TBO-ENG",IF($G1006="Evet",ROUND($C1006*tbo_isverenOran,2),0),0))))) | L1006: =IF($A1006="","",MAX(0,$J1006-$K1006))
A1008: BORDRO: sarı = giriş; EnAvantajliKod formülle seçilir.

Sheet MATRIS
A1: MATRIS — Teşvikli Bordro Optimizasyon
A3: Kişi × teşvik kodu optimizasyon matrisi
A4: Sarı hücreler giriş. Her kod kolonu o kişi için o teşvikin tutarını üretir; EnIyiKod satır bazında MAX ile seçilir (INDEX/MATCH yok — ölçek dostu). | Q4: Kişi sayısı | R4: =IFERROR(COUNTA(tblMatris[CalisanNo]),0)
Q5: En iyi set toplamı | R5: =IFERROR(SUM(tblMatris[EnIyiTutar]),0)
A6: CalisanNo | B6: AdSoyad | C6: BrutMatrah | D6: BesPuanUygun | E6: IlaveUygun | F6: KadinGencUygun | G6: EngelliUygun | H6: TBO001 | I6: TBO002 | J6: TBO004 | K6: TBOENG | L6: EnIyiKod | M6: EnIyiTutar | N6: MevcutKod | O6: Fark | Q6: Matris kaçırılan | R6: =IFERROR(SUM(tblMatris[Fark]),0)
A7: 1 | B7: Ali Yılmaz | C7: 25000 | D7: Evet | E7: Hayır | F7: Hayır | G7: Hayır | H7: =IF($A7="","",IF($D7="Evet",ROUND($C7*tbo_oranBesPuan,2),0)) | I7: =IF($A7="","",IF($E7="Evet",ROUND($C7*tbo_oranIlave,2),0)) | J7: =IF($A7="","",IF($F7="Evet",ROUND($C7*tbo_oranKadinGenc,2),0)) | K7: =IF($A7="","",IF($G7="Evet",ROUND($C7*tbo_isverenOran,2),0)) | L7: =IF($A7="","",IF($M7=0,"YOK",IF($I7=$M7,"TBO-002",IF($H7=$M7,"TBO-001",IF($J7=$M7,"TBO-004","TBO-ENG"))))) | M7: =IF($A7="","",MAX($H7,$I7,$J7,$K7)) | N7: TBO-001 | O7: =IF($A7="","",MAX(0,$M7-IF($N7="TBO-001",$H7,IF($N7="TBO-002",$I7,IF($N7="TBO-004",$J7,IF($N7="TBO-ENG",$K7,0)))))) | Q7: Kod seti özeti | R7: =IFERROR(IF(COUNTA(tblMatris[CalisanNo])=0,"VERİ YOK",_xlfn.TEXTJOIN(" · ",TRUE,"TBO-001=",COUNTIF(tblMatris[EnIyiKod],"TBO-001"),"TBO-002=",COUNTIF(tblMatris[EnIyiKod],"TBO-002"),"TBO-004=",COUNTIF(tblMatris[EnIyiKod],"TBO-004"),"TBO-ENG=",COUNTIF(tblMatris[EnIyiKod],"TBO-ENG"),"YOK=",COUNTIF(tblMatris[EnIyiKod],"YOK"))),"-")
A8: 2 | B8: Ayşe Demir | C8: 22000 | D8: Evet | E8: Evet | F8: Hayır | G8: Hayır | H8: =IF($A8="","",IF($D8="Evet",ROUND($C8*tbo_oranBesPuan,2),0)) | I8: =IF($A8="","",IF($E8="Evet",ROUND($C8*tbo_oranIlave,2),0)) | J8: =IF($A8="","",IF($F8="Evet",ROUND($C8*tbo_oranKadinGenc,2),0)) | K8: =IF($A8="","",IF($G8="Evet",ROUND($C8*tbo_isverenOran,2),0)) | L8: =IF($A8="","",IF($M8=0,"YOK",IF($I8=$M8,"TBO-002",IF($H8=$M8,"TBO-001",IF($J8=$M8,"TBO-004","TBO-ENG"))))) | M8: =IF($A8="","",MAX($H8,$I8,$J8,$K8)) | N8: TBO-001 | O8: =IF($A8="","",MAX(0,$M8-IF($N8="TBO-001",$H8,IF($N8="TBO-002",$I8,IF($N8="TBO-004",$J8,IF($N8="TBO-ENG",$K8,0)))))) | Q8: Optimizasyon kararı | R8: =IFERROR(IF(COUNTA(tblMatris[CalisanNo])=0,"VERİ YOK",IF(R6=0,"UYGUN",IF(R6>=tbo_kacirilanEsik,"UYGULA","İNCELE"))),"-")
A9: 3 | B9: Mehmet Kaya | C9: 28000 | D9: Evet | E9: Hayır | F9: Evet | G9: Hayır | H9: =IF($A9="","",IF($D9="Evet",ROUND($C9*tbo_oranBesPuan,2),0)) | I9: =IF($A9="","",IF($E9="Evet",ROUND($C9*tbo_oranIlave,2),0)) | J9: =IF($A9="","",IF($F9="Evet",ROUND($C9*tbo_oranKadinGenc,2),0)) | K9: =IF($A9="","",IF($G9="Evet",ROUND($C9*tbo_isverenOran,2),0)) | L9: =IF($A9="","",IF($M9=0,"YOK",IF($I9=$M9,"TBO-002",IF($H9=$M9,"TBO-001",IF($J9=$M9,"TBO-004","TBO-ENG"))))) | M9: =IF($A9="","",MAX($H9,$I9,$J9,$K9)) | N9: TBO-004 | O9: =IF($A9="","",MAX(0,$M9-IF($N9="TBO-001",$H9,IF($N9="TBO-002",$I9,IF($N9="TBO-004",$J9,IF($N9="TBO-ENG",$K9,0))))))
A10: 4 | B10: Zeynep Arslan | C10: 20000 | D10: Hayır | E10: Evet | F10: Hayır | G10: Hayır | H10: =IF($A10="","",IF($D10="Evet",ROUND($C10*tbo_oranBesPuan,2),0)) | I10: =IF($A10="","",IF($E10="Evet",ROUND($C10*tbo_oranIlave,2),0)) | J10: =IF($A10="","",IF($F10="Evet",ROUND($C10*tbo_oranKadinGenc,2),0)) | K10: =IF($A10="","",IF($G10="Evet",ROUND($C10*tbo_isverenOran,2),0)) | L10: =IF($A10="","",IF($M10=0,"YOK",IF($I10=$M10,"TBO-002",IF($H10=$M10,"TBO-001",IF($J10=$M10,"TBO-004","TBO-ENG"))))) | M10: =IF($A10="","",MAX($H10,$I10,$J10,$K10)) | N10: YOK | O10: =IF($A10="","",MAX(0,$M10-IF($N10="TBO-001",$H10,IF($N10="TBO-002",$I10,IF($N10="TBO-004",$J10,IF($N10="TBO-ENG",$K10,0)))))) | Q10: Kod | R10: SetAdetDemo
A11: 5 | B11: Can Öztürk | C11: 30000 | D11: Evet | E11: Evet | F11: Hayır | G11: Evet | H11: =IF($A11="","",IF($D11="Evet",ROUND($C11*tbo_oranBesPuan,2),0)) | I11: =IF($A11="","",IF($E11="Evet",ROUND($C11*tbo_oranIlave,2),0)) | J11: =IF($A11="","",IF($F11="Evet",ROUND($C11*tbo_oranKadinGenc,2),0)) | K11: =IF($A11="","",IF($G11="Evet",ROUND($C11*tbo_isverenOran,2),0)) | L11: =IF($A11="","",IF($M11=0,"YOK",IF($I11=$M11,"TBO-002",IF($H11=$M11,"TBO-001",IF($J11=$M11,"TBO-004","TBO-ENG"))))) | M11: =IF($A11="","",MAX($H11,$I11,$J11,$K11)) | N11: TBO-001 | O11: =IF($A11="","",MAX(0,$M11-IF($N11="TBO-001",$H11,IF($N11="TBO-002",$I11,IF($N11="TBO-004",$J11,IF($N11="TBO-ENG",$K11,0)))))) | Q11: TBO-001 | R11: 4
A12: 6 | B12: Elif Şahin | C12: 18000 | D12: Evet | E12: Hayır | F12: Evet | G12: Hayır | H12: =IF($A12="","",IF($D12="Evet",ROUND($C12*tbo_oranBesPuan,2),0)) | I12: =IF($A12="","",IF($E12="Evet",ROUND($C12*tbo_oranIlave,2),0)) | J12: =IF($A12="","",IF($F12="Evet",ROUND($C12*tbo_oranKadinGenc,2),0)) | K12: =IF($A12="","",IF($G12="Evet",ROUND($C12*tbo_isverenOran,2),0)) | L12: =IF($A12="","",IF($M12=0,"YOK",IF($I12=$M12,"TBO-002",IF($H12=$M12,"TBO-001",IF($J12=$M12,"TBO-004","TBO-ENG"))))) | M12: =IF($A12="","",MAX($H12,$I12,$J12,$K12)) | N12: TBO-001 | O12: =IF($A12="","",MAX(0,$M12-IF($N12="TBO-001",$H12,IF($N12="TBO-002",$I12,IF($N12="TBO-004",$J12,IF($N12="TBO-ENG",$K12,0)))))) | Q12: TBO-002 | R12: 3
A13: 7 | B13: Burak Çelik | C13: 35000 | D13: Evet | E13: Evet | F13: Hayır | G13: Hayır | H13: =IF($A13="","",IF($D13="Evet",ROUND($C13*tbo_oranBesPuan,2),0)) | I13: =IF($A13="","",IF($E13="Evet",ROUND($C13*tbo_oranIlave,2),0)) | J13: =IF($A13="","",IF($F13="Evet",ROUND($C13*tbo_oranKadinGenc,2),0)) | K13: =IF($A13="","",IF($G13="Evet",ROUND($C13*tbo_isverenOran,2),0)) | L13: =IF($A13="","",IF($M13=0,"YOK",IF($I13=$M13,"TBO-002",IF($H13=$M13,"TBO-001",IF($J13=$M13,"TBO-004","TBO-ENG"))))) | M13: =IF($A13="","",MAX($H13,$I13,$J13,$K13)) | N13: TBO-002 | O13: =IF($A13="","",MAX(0,$M13-IF($N13="TBO-001",$H13,IF($N13="TBO-002",$I13,IF($N13="TBO-004",$J13,IF($N13="TBO-ENG",$K13,0)))))) | Q13: TBO-004 | R13: 2
A14: 8 | B14: Selin Aydın | C14: 24000 | D14: Hayır | E14: Hayır | F14: Evet | G14: Hayır | H14: =IF($A14="","",IF($D14="Evet",ROUND($C14*tbo_oranBesPuan,2),0)) | I14: =IF($A14="","",IF($E14="Evet",ROUND($C14*tbo_oranIlave,2),0)) | J14: =IF($A14="","",IF($F14="Evet",ROUND($C14*tbo_oranKadinGenc,2),0)) | K14: =IF($A14="","",IF($G14="Evet",ROUND($C14*tbo_isverenOran,2),0)) | L14: =IF($A14="","",IF($M14=0,"YOK",IF($I14=$M14,"TBO-002",IF($H14=$M14,"TBO-001",IF($J14=$M14,"TBO-004","TBO-ENG"))))) | M14: =IF($A14="","",MAX($H14,$I14,$J14,$K14)) | N14: YOK | O14: =IF($A14="","",MAX(0,$M14-IF($N14="TBO-001",$H14,IF($N14="TBO-002",$I14,IF($N14="TBO-004",$J14,IF($N14="TBO-ENG",$K14,0)))))) | Q14: TBO-ENG | R14: 1
A15: 9 | B15: Emre Koç | C15: 27000 | D15: Evet | E15: Hayır | F15: Hayır | G15: Evet | H15: =IF($A15="","",IF($D15="Evet",ROUND($C15*tbo_oranBesPuan,2),0)) | I15: =IF($A15="","",IF($E15="Evet",ROUND($C15*tbo_oranIlave,2),0)) | J15: =IF($A15="","",IF($F15="Evet",ROUND($C15*tbo_oranKadinGenc,2),0)) | K15: =IF($A15="","",IF($G15="Evet",ROUND($C15*tbo_isverenOran,2),0)) | L15: =IF($A15="","",IF($M15=0,"YOK",IF($I15=$M15,"TBO-002",IF($H15=$M15,"TBO-001",IF($J15=$M15,"TBO-004","TBO-ENG"))))) | M15: =IF($A15="","",MAX($H15,$I15,$J15,$K15)) | N15: TBO-001 | O15: =IF($A15="","",MAX(0,$M15-IF($N15="TBO-001",$H15,IF($N15="TBO-002",$I15,IF($N15="TBO-004",$J15,IF($N15="TBO-ENG",$K15,0))))))
A16: 10 | B16: Deniz Yıldız | C16: 21000 | D16: Evet | E16: Evet | F16: Evet | G16: Hayır | H16: =IF($A16="","",IF($D16="Evet",ROUND($C16*tbo_oranBesPuan,2),0)) | I16: =IF($A16="","",IF($E16="Evet",ROUND($C16*tbo_oranIlave,2),0)) | J16: =IF($A16="","",IF($F16="Evet",ROUND($C16*tbo_oranKadinGenc,2),0)) | K16: =IF($A16="","",IF($G16="Evet",ROUND($C16*tbo_isverenOran,2),0)) | L16: =IF($A16="","",IF($M16=0,"YOK",IF($I16=$M16,"TBO-002",IF($H16=$M16,"TBO-001",IF($J16=$M16,"TBO-004","TBO-ENG"))))) | M16: =IF($A16="","",MAX($H16,$I16,$J16,$K16)) | N16: TBO-001 | O16: =IF($A16="","",MAX(0,$M16-IF($N16="TBO-001",$H16,IF($N16="TBO-002",$I16,IF($N16="TBO-004",$J16,IF($N16="TBO-ENG",$K16,0))))))
H17: =IF($A17="","",IF($D17="Evet",ROUND($C17*tbo_oranBesPuan,2),0)) | I17: =IF($A17="","",IF($E17="Evet",ROUND($C17*tbo_oranIlave,2),0)) | J17: =IF($A17="","",IF($F17="Evet",ROUND($C17*tbo_oranKadinGenc,2),0)) | K17: =IF($A17="","",IF($G17="Evet",ROUND($C17*tbo_isverenOran,2),0)) | L17: =IF($A17="","",IF($M17=0,"YOK",IF($I17=$M17,"TBO-002",IF($H17=$M17,"TBO-001",IF($J17=$M17,"TBO-004","TBO-ENG"))))) | M17: =IF($A17="","",MAX($H17,$I17,$J17,$K17)) | O17: =IF($A17="","",MAX(0,$M17-IF($N17="TBO-001",$H17,IF($N17="TBO-002",$I17,IF($N17="TBO-004",$J17,IF($N17="TBO-ENG",$K17,0))))))
H18: =IF($A18="","",IF($D18="Evet",ROUND($C18*tbo_oranBesPuan,2),0)) | I18: =IF($A18="","",IF($E18="Evet",ROUND($C18*tbo_oranIlave,2),0)) | J18: =IF($A18="","",IF($F18="Evet",ROUND($C18*tbo_oranKadinGenc,2),0)) | K18: =IF($A18="","",IF($G18="Evet",ROUND($C18*tbo_isverenOran,2),0)) | L18: =IF($A18="","",IF($M18=0,"YOK",IF($I18=$M18,"TBO-002",IF($H18=$M18,"TBO-001",IF($J18=$M18,"TBO-004","TBO-ENG"))))) | M18: =IF($A18="","",MAX($H18,$I18,$J18,$K18)) | O18: =IF($A18="","",MAX(0,$M18-IF($N18="TBO-001",$H18,IF($N18="TBO-002",$I18,IF($N18="TBO-004",$J18,IF($N18="TBO-ENG",$K18,0))))))
H19: =IF($A19="","",IF($D19="Evet",ROUND($C19*tbo_oranBesPuan,2),0)) | I19: =IF($A19="","",IF($E19="Evet",ROUND($C19*tbo_oranIlave,2),0)) | J19: =IF($A19="","",IF($F19="Evet",ROUND($C19*tbo_oranKadinGenc,2),0)) | K19: =IF($A19="","",IF($G19="Evet",ROUND($C19*tbo_isverenOran,2),0)) | L19: =IF($A19="","",IF($M19=0,"YOK",IF($I19=$M19,"TBO-002",IF($H19=$M19,"TBO-001",IF($J19=$M19,"TBO-004","TBO-ENG"))))) | M19: =IF($A19="","",MAX($H19,$I19,$J19,$K19)) | O19: =IF($A19="","",MAX(0,$M19-IF($N19="TBO-001",$H19,IF($N19="TBO-002",$I19,IF($N19="TBO-004",$J19,IF($N19="TBO-ENG",$K19,0))))))
H20: =IF($A20="","",IF($D20="Evet",ROUND($C20*tbo_oranBesPuan,2),0)) | I20: =IF($A20="","",IF($E20="Evet",ROUND($C20*tbo_oranIlave,2),0)) | J20: =IF($A20="","",IF($F20="Evet",ROUND($C20*tbo_oranKadinGenc,2),0)) | K20: =IF($A20="","",IF($G20="Evet",ROUND($C20*tbo_isverenOran,2),0)) | L20: =IF($A20="","",IF($M20=0,"YOK",IF($I20=$M20,"TBO-002",IF($H20=$M20,"TBO-001",IF($J20=$M20,"TBO-004","TBO-ENG"))))) | M20: =IF($A20="","",MAX($H20,$I20,$J20,$K20)) | O20: =IF($A20="","",MAX(0,$M20-IF($N20="TBO-001",$H20,IF($N20="TBO-002",$I20,IF($N20="TBO-004",$J20,IF($N20="TBO-ENG",$K20,0))))))
H21: =IF($A21="","",IF($D21="Evet",ROUND($C21*tbo_oranBesPuan,2),0)) | I21: =IF($A21="","",IF($E21="Evet",ROUND($C21*tbo_oranIlave,2),0)) | J21: =IF($A21="","",IF($F21="Evet",ROUND($C21*tbo_oranKadinGenc,2),0)) | K21: =IF($A21="","",IF($G21="Evet",ROUND($C21*tbo_isverenOran,2),0)) | L21: =IF($A21="","",IF($M21=0,"YOK",IF($I21=$M21,"TBO-002",IF($H21=$M21,"TBO-001",IF($J21=$M21,"TBO-004","TBO-ENG"))))) | M21: =IF($A21="","",MAX($H21,$I21,$J21,$K21)) | O21: =IF($A21="","",MAX(0,$M21-IF($N21="TBO-001",$H21,IF($N21="TBO-002",$I21,IF($N21="TBO-004",$J21,IF($N21="TBO-ENG",$K21,0))))))
H22: =IF($A22="","",IF($D22="Evet",ROUND($C22*tbo_oranBesPuan,2),0)) | I22: =IF($A22="","",IF($E22="Evet",ROUND($C22*tbo_oranIlave,2),0)) | J22: =IF($A22="","",IF($F22="Evet",ROUND($C22*tbo_oranKadinGenc,2),0)) | K22: =IF($A22="","",IF($G22="Evet",ROUND($C22*tbo_isverenOran,2),0)) | L22: =IF($A22="","",IF($M22=0,"YOK",IF($I22=$M22,"TBO-002",IF($H22=$M22,"TBO-001",IF($J22=$M22,"TBO-004","TBO-ENG"))))) | M22: =IF($A22="","",MAX($H22,$I22,$J22,$K22)) | O22: =IF($A22="","",MAX(0,$M22-IF($N22="TBO-001",$H22,IF($N22="TBO-002",$I22,IF($N22="TBO-004",$J22,IF($N22="TBO-ENG",$K22,0))))))
H23: =IF($A23="","",IF($D23="Evet",ROUND($C23*tbo_oranBesPuan,2),0)) | I23: =IF($A23="","",IF($E23="Evet",ROUND($C23*tbo_oranIlave,2),0)) | J23: =IF($A23="","",IF($F23="Evet",ROUND($C23*tbo_oranKadinGenc,2),0)) | K23: =IF($A23="","",IF($G23="Evet",ROUND($C23*tbo_isverenOran,2),0)) | L23: =IF($A23="","",IF($M23=0,"YOK",IF($I23=$M23,"TBO-002",IF($H23=$M23,"TBO-001",IF($J23=$M23,"TBO-004","TBO-ENG"))))) | M23: =IF($A23="","",MAX($H23,$I23,$J23,$K23)) | O23: =IF($A23="","",MAX(0,$M23-IF($N23="TBO-001",$H23,IF($N23="TBO-002",$I23,IF($N23="TBO-004",$J23,IF($N23="TBO-ENG",$K23,0))))))
H24: =IF($A24="","",IF($D24="Evet",ROUND($C24*tbo_oranBesPuan,2),0)) | I24: =IF($A24="","",IF($E24="Evet",ROUND($C24*tbo_oranIlave,2),0)) | J24: =IF($A24="","",IF($F24="Evet",ROUND($C24*tbo_oranKadinGenc,2),0)) | K24: =IF($A24="","",IF($G24="Evet",ROUND($C24*tbo_isverenOran,2),0)) | L24: =IF($A24="","",IF($M24=0,"YOK",IF($I24=$M24,"TBO-002",IF($H24=$M24,"TBO-001",IF($J24=$M24,"TBO-004","TBO-ENG"))))) | M24: =IF($A24="","",MAX($H24,$I24,$J24,$K24)) | O24: =IF($A24="","",MAX(0,$M24-IF($N24="TBO-001",$H24,IF($N24="TBO-002",$I24,IF($N24="TBO-004",$J24,IF($N24="TBO-ENG",$K24,0))))))
H25: =IF($A25="","",IF($D25="Evet",ROUND($C25*tbo_oranBesPuan,2),0)) | I25: =IF($A25="","",IF($E25="Evet",ROUND($C25*tbo_oranIlave,2),0)) | J25: =IF($A25="","",IF($F25="Evet",ROUND($C25*tbo_oranKadinGenc,2),0)) | K25: =IF($A25="","",IF($G25="Evet",ROUND($C25*tbo_isverenOran,2),0)) | L25: =IF($A25="","",IF($M25=0,"YOK",IF($I25=$M25,"TBO-002",IF($H25=$M25,"TBO-001",IF($J25=$M25,"TBO-004","TBO-ENG"))))) | M25: =IF($A25="","",MAX($H25,$I25,$J25,$K25)) | O25: =IF($A25="","",MAX(0,$M25-IF($N25="TBO-001",$H25,IF($N25="TBO-002",$I25,IF($N25="TBO-004",$J25,IF($N25="TBO-ENG",$K25,0))))))
H26: =IF($A26="","",IF($D26="Evet",ROUND($C26*tbo_oranBesPuan,2),0)) | I26: =IF($A26="","",IF($E26="Evet",ROUND($C26*tbo_oranIlave,2),0)) | J26: =IF($A26="","",IF($F26="Evet",ROUND($C26*tbo_oranKadinGenc,2),0)) | K26: =IF($A26="","",IF($G26="Evet",ROUND($C26*tbo_isverenOran,2),0)) | L26: =IF($A26="","",IF($M26=0,"YOK",IF($I26=$M26,"TBO-002",IF($H26=$M26,"TBO-001",IF($J26=$M26,"TBO-004","TBO-ENG"))))) | M26: =IF($A26="","",MAX($H26,$I26,$J26,$K26)) | O26: =IF($A26="","",MAX(0,$M26-IF($N26="TBO-001",$H26,IF($N26="TBO-002",$I26,IF($N26="TBO-004",$J26,IF($N26="TBO-ENG",$K26,0))))))
H27: =IF($A27="","",IF($D27="Evet",ROUND($C27*tbo_oranBesPuan,2),0)) | I27: =IF($A27="","",IF($E27="Evet",ROUND($C27*tbo_oranIlave,2),0)) | J27: =IF($A27="","",IF($F27="Evet",ROUND($C27*tbo_oranKadinGenc,2),0)) | K27: =IF($A27="","",IF($G27="Evet",ROUND($C27*tbo_isverenOran,2),0)) | L27: =IF($A27="","",IF($M27=0,"YOK",IF($I27=$M27,"TBO-002",IF($H27=$M27,"TBO-001",IF($J27=$M27,"TBO-004","TBO-ENG"))))) | M27: =IF($A27="","",MAX($H27,$I27,$J27,$K27)) | O27: =IF($A27="","",MAX(0,$M27-IF($N27="TBO-001",$H27,IF($N27="TBO-002",$I27,IF($N27="TBO-004",$J27,IF($N27="TBO-ENG",$K27,0))))))
H28: =IF($A28="","",IF($D28="Evet",ROUND($C28*tbo_oranBesPuan,2),0)) | I28: =IF($A28="","",IF($E28="Evet",ROUND($C28*tbo_oranIlave,2),0)) | J28: =IF($A28="","",IF($F28="Evet",ROUND($C28*tbo_oranKadinGenc,2),0)) | K28: =IF($A28="","",IF($G28="Evet",ROUND($C28*tbo_isverenOran,2),0)) | L28: =IF($A28="","",IF($M28=0,"YOK",IF($I28=$M28,"TBO-002",IF($H28=$M28,"TBO-001",IF($J28=$M28,"TBO-004","TBO-ENG"))))) | M28: =IF($A28="","",MAX($H28,$I28,$J28,$K28)) | O28: =IF($A28="","",MAX(0,$M28-IF($N28="TBO-001",$H28,IF($N28="TBO-002",$I28,IF($N28="TBO-004",$J28,IF($N28="TBO-ENG",$K28,0))))))
... H1006: =IF($A1006="","",IF($D1006="Evet",ROUND($C1006*tbo_oranBesPuan,2),0)) | I1006: =IF($A1006="","",IF($E1006="Evet",ROUND($C1006*tbo_oranIlave,2),0)) | J1006: =IF($A1006="","",IF($F1006="Evet",ROUND($C1006*tbo_oranKadinGenc,2),0)) | K1006: =IF($A1006="","",IF($G1006="Evet",ROUND($C1006*tbo_isverenOran,2),0)) | L1006: =IF($A1006="","",IF($M1006=0,"YOK",IF($I1006=$M1006,"TBO-002",IF($H1006=$M1006,"TBO-001",IF($J1006=$M1006,"TBO-004","TBO-ENG"))))) | M1006: =IF($A1006="","",MAX($H1006,$I1006,$J1006,$K1006)) | O1006: =IF($A1006="","",MAX(0,$M1006-IF($N1006="TBO-001",$H1006,IF($N1006="TBO-002",$I1006,IF($N1006="TBO-004",$J1006,IF($N1006="TBO-ENG",$K1006,0))))))
A1008: MATRIS: sarı = giriş; kod tutarları formülle üretilir.

Sheet KURALLAR
A1: KURALLAR — Teşvikli Bordro Optimizasyon
A3: Mevzuat kural tablosu (yıl yan yana)
A4: Oranlar MOTOR'da sabit yazılmaz; INDEX/MATCH ile buradan çekilir.
A6: kural_id | B6: madde | C6: kural_adi | D6: kosul_metni | E6: parametre_adi | F6: deger_2025 | G6: deger_2026 | H6: deger_2027 | I6: yururluk | J6: kaynak | K6: aktif_deger
A7: TBO-001 | B7: 5510 md.81 | C7: bes_puan_oran | D7: kapsam_matrah>0 | E7: bes_puan_oran | F7: 0.05 | G7: 0.05 | H7: 0.05 | I7: 01.01.2025 | J7: 5510 s.K. md.81 | K7: =IF($A7="","",IFERROR(CHOOSE(MAX(1,MIN(3,IF(OR(hesapYili="",hesapYili=0),1,hesapYili-tbo_yilTaban))),$F7,$G7,$H7),0))
A8: TBO-002 | B8: 4447 geç.10 | C8: ilave_istihdam_oran | D8: ilave_matrah>0 | E8: ilave_istihdam_oran | F8: 0.145 | G8: 0.145 | H8: 0.145 | I8: 01.01.2025 | J8: 4447 s.K. geç.10 | K8: =IF($A8="","",IFERROR(CHOOSE(MAX(1,MIN(3,IF(OR(hesapYili="",hesapYili=0),1,hesapYili-tbo_yilTaban))),$F8,$G8,$H8),0))
