Workbook
Name raporTarihi: AYARLAR!$B$5
Name toleransKurus: AYARLAR!$B$6
Name zincirTolerans: AYARLAR!$B$7
Name say_gecikmeZammi: AYARLAR!$B$8
Name say_icapEsikGun: AYARLAR!$B$9
Name say_esikFark: AYARLAR!$B$10
Name say_ikincilUzunluk: AYARLAR!$B$11
Name say_hedefTahsilat: AYARLAR!$B$12
Name say_senaryoIyimser: AYARLAR!$B$13
Name say_senaryoKotumser: AYARLAR!$B$14
Name say_fiyatModeli: AYARLAR!$B$15
Name say_olcekHedef: AYARLAR!$B$16
Name say_trendOcak: AYARLAR!$B$17
Name say_trendSubat: AYARLAR!$B$18
Name say_trendMart: AYARLAR!$B$19
Name say_trendNisan: AYARLAR!$B$20
Name say_trendMayis: AYARLAR!$B$21
Name say_trendHaziran: AYARLAR!$B$22
Name say_trendTemmuz: AYARLAR!$B$23
Name say_trendAgustos: AYARLAR!$B$24
Name say_trendEylul: AYARLAR!$B$25
Name say_trendEkim: AYARLAR!$B$26
Name say_trendKasim: AYARLAR!$B$27
Name say_trendAralik: AYARLAR!$B$28
Name say_toplamBorc: AYARLAR!$N$7
Name say_toplamTahsilat: AYARLAR!$N$8
Name say_tahsilatOrani: AYARLAR!$N$9
Name say_kasaBakiye: AYARLAR!$N$10
Name say_gecikenMalik: AYARLAR!$N$11
Name say_icapKuyruk: AYARLAR!$N$12
Name say_yetimKayit: AYARLAR!$N$13
Name say_gecersizGecis: AYARLAR!$N$14
Name say_zincirKirik: AYARLAR!$N$15
Name say_eslesmeOrani: AYARLAR!$N$16
Name say_giderSapma: AYARLAR!$N$17
Name say_kararSayisi: AYARLAR!$N$18
Name say_kovaButunluk: AYARLAR!$N$19
Name say_kararKapi: AYARLAR!$N$20
Name say_kararGerekce: AYARLAR!$N$21
Name say_normAnahtar: AYARLAR!$N$22
Name say_tanimsizKova: AYARLAR!$N$23
Name say_durumHaritasi: AYARLAR!$N$24
Name say_kanitRaporu: AYARLAR!$N$25
Name say_kapaliDusum: AYARLAR!$N$26
Name say_modulT1: AYARLAR!$N$27
Name say_modulT1Yorum: AYARLAR!$N$28
Name say_modulT2: AYARLAR!$N$29
Name say_modulT2Yorum: AYARLAR!$N$30
Name say_modulO1: AYARLAR!$N$31
Name say_modulO1Yorum: AYARLAR!$N$32
Name say_modulO2: AYARLAR!$N$33
Name say_modulO2Yorum: AYARLAR!$N$34
Name say_modulO3: AYARLAR!$N$35
Name say_modulO3Yorum: AYARLAR!$N$36
Name say_modulO6: AYARLAR!$N$37
Name say_modulO6Yorum: AYARLAR!$N$38
Name say_modulO8: AYARLAR!$N$39
Name say_modulO8Yorum: AYARLAR!$N$40
Name say_modulI1: AYARLAR!$N$41
Name say_modulI1Yorum: AYARLAR!$N$42

Sheet 00_BASLANGIC
A1: EXCELARŞİV KARAR SİSTEMİ v15.1 — ÜRETİM REFERANSI
A3: Konu | B3: Bağlayıcı Standart
A4: Amaç | B4: Kanıta dayalı, hatada kapalı çalışan Excel üretim ve denetim sistemi
A5: Öncelik | B5: Kullanıcının açık iş talebi ve gerçek kullanım senaryosu
A6: Ana akış | B6: Uygunluk → Yönetişim → Sözleşmeler → Üretim → Test → Kanıt → Kullanıcı Kabulü → Yayın
A7: Yayın ilkesi | B7: Üst aşamada hata varsa alt aşama GEÇTİ üretilemez
A8: Kullanıcı kabulü | B8: Excel masaüstü görünümü test edilmediyse DIŞ_KABUL_GEREKLİ
A9: Nihai yayın | B9: Yalnız uygulanabilir modüller GEÇTİ veya gerekçeli UYGULANMAZ
A10: Ticari ayrım | B10: Ekonomik olarak savunulabilir fiyat, gerçek pazar kabulü ile aynı değildir
A11: Karmaşıklık | B11: Karar değeri, eklenen karmaşıklığın maliyetinden büyük olmalıdır
A12: Excel sınırı | B12: Veritabanı, kurumsal yetkilendirme, değiştirilemez kayıt sistemi veya gerçek zamanlı olay platformu değildir
A13: Dil standardı | B13: Kullanıcıya görünen tüm sayfa, tablo, başlık, açıklama, uyarı ve karar metinleri saf Türkçe olmalıdır
A14: Muhasebe standardı | B14: Finansal ürünlerde Türkiye Tekdüzen Hesap Planı ve Türk muhasebe kullanım alışkanlıkları esas alınır
... A33: Muhasebe | B33: Türkiye Tekdüzen Hesap Planı ve Türk muhasebe/işletme düşünce yapısı esas alınır.

Sheet PANO
A1: ☰ PANO
B2: SITE/APARTMAN YÖNETIM SISTEMI | L2: Dönem: 2026 / Tam ▼ | M2: ★ DOĞRULANMIŞ
B3: Hedef Kullanıcı: Site yöneticisi, yönetim kurulu, kat malikleri temsilcisi, SMMM · 2026 Q3 Denetim Standardı
B5: TAHSILAT ORANI | D5: KONSOLİDE | E5: AIDAT TREND | G5: KONTROL | H5: NET OPERASYONEL MARJ | J5: GÜVENLİ | K5: SİSTEM GÜVEN SKORU | M5: DENETLENDİ
B7: =GİRDİLER!E17 | E7: =B7*0.22 | H7: =B7-E7 | K7: =EĞER(E7>0; YUVARLA(B7/E7; 2); 0)
B9: ↑ %14.2 konsolide canlı veri bağlantısı | E9: ● 8 Kalem nakit karşılığı: bloke | H9: ██████████░░░░░ %78.0 NET MARJ | K9: ✓ İDEAL karşılama rasyosu
B11: SITE/APARTMAN YÖNETIM SISTEMI — DÖNEMSEL İCRA VE PROJEKSİYON | F11: +%32 Verim | H11: KONSOLİDE OPERASYON VE KARAR MATRİSİ
B12: Kümülatif Hacim vs. Operasyonel Maliyet ve Net Kâr Eğilimi | H12: Anlık Hesaplama Sonuçları, Dinamik Formül Çıktıları ve Durum Puanlaması
B14: Dönem | C14: Aktif Hacim | D14: Maliyet/Yük | E14: Hedef | H14: PARAMETRE / KALEM | I14: ANA TUTAR | J14: FARK / MARJ | K14: VADE | L14: KONTROL DURUMU
B15: D1 | C15: 65 | D15: 45 | E15: 60 | H15: Dönemlik Kümülatif Bakiye | I15: =B7*0.45 | J15: =B7*0.05 | K15: 12 Ay | L15: ✓ DÜZENLİ
B16: D2 | C16: 78 | D16: 48 | E16: 70 | H16: Kritik Eşik Güvenlik Tamponu | I16: =B7*0.30 | J16: =B7*0.03 | K16: 24 Ay | L16: ★ AVANTAJ
B17: D3 | C17: 85 | D17: 55 | E17: 80 | H17: Operasyonel Net Fark | I17: =B7*0.15 | J17: =B7*0.02 | K17: 8 Ay | L17: ● YAKLAŞAN
B18: D4 | C18: 75 | D18: 42 | E18: 75 | H18: Rezerv ve Likit Dağılım | I18: =B7*0.10 | J18: =B7*0.01 | K18: 16 Ay | L18: ✓ TAM UYUM
B19: D5 | C19: 90 | D19: 40 | E19: 85 | H19: KONSOLİDE SİSTEM TOPLAMI | I19: =TOPLA(I15:I18) | J19: =TOPLA(J15:J18) | L19: TAM DOĞRULANDI (0 HATA)
B20: D6 | C20: 96 | D20: 32 | E20: 92
B22: KONSOLİDE PAY VE AĞIRLIK | F22: LİKİDİTE RİSKİ & ERKEN UYARI SİNYALLERİ | K22: KARAR MOTORU
B23: ■ Ana Segment (%42) | F23: Nakit Açığı Riski (30 Gün) | I23: 0.00 TL (Sıfır Risk) | K23: STRATEJİK VERİMLİLİK FIRSATI
B24: ■ İkincil Grup (%30) | F24: Tahsilat Gecikme Toleransı | I24: 48 Gün Güvenli Eşik | K24: Operasyonel süreç optimizasyonu ile kârlılık artış potansiyeli tespit edildi.
B25: ■ Destek Birimi (%15) | F25: ██████████████████████████████████████ Güvenli Bölge (%100)
B26: ■ Rezervler (%13) | F26: ✓ 90 GÜNLÜK PROJEKSİYONDA NAKİT SIKIŞIKLIĞI TESPİT EDİLMEDİ | K26: STRATEJİ REÇETESİNİ İNCELE >

Sheet GİRDİLER
A1: ☰ PANO
B3: 🔍 SITE/APARTMAN YÖNETIM SISTEMI — Kayıt veya hesap ara... | G3: TOPLAM: 1.450 KAYIT | I3: HATALI HÜCRE: 0 ADET
B5: TARİH | C5: REFERANS NO | D5: İŞLEM AÇIKLAMASI VE DETAY | E5: BRÜT TUTAR (₺) | F5: KDV ORANI | G5: NET TUTAR (₺) | H5: HESAP / CARİ | I5: DURUM
B6: 12.10.2026 | C6: TR-0428-A | D6: Operasyonel ana kalem tahmini | E6: 845200 | F6: 0.2 | G6: =E6/(1+F6) | H6: Vadesiz Ticari | I6: ONAYLANDI
B7: 14.10.2026 | C7: TR-0429-B | D7: Operasyonel çıkış/maliyet tahmini | E7: 1240000 | F7: 0.2 | G7: =E7/(1+F7) | H7: Tedarikçi Havuzu | I7: BEKLEMEDE
B8: 18.10.2026 | C8: TR-0430-C | D8: Ödeme takvimi tahakkuku | E8: 620500 | F8: 0.1 | G8: =E8/(1+F8) | H8: Kısa Vade Tahakkuk | I8: ONAYLANDI
B9: 21.10.2026 | C9: TR-0431-D | D9: Müşteri işlem tahmini | E9: 415000 | F9: 0.2 | G9: =E9/(1+F9) | H9: Müşteri Alacağı | I9: ONAYLANDI
B10: 25.10.2026 | C10: TR-0432-E | D10: Ana operasyon tahmini | E10: 980400 | F10: 0.2 | G10: =E10/(1+F10) | H10: Vadesiz Ticari | I10: ONAYLANDI
B11: 28.10.2026 | C11: TR-0433-F | D11: Kredi/taksit karşılığı | E11: 1850000 | F11: 0.2 | G11: =E11/(1+F11) | H11: Finansman Havuzu | I11: BLOKE
B12: 02.11.2026 | C12: TR-0434-G | D12: Sabit gider ve yönetim notları | E12: 740000 | F12: 0.2 | G12: =E12/(1+F12) | H12: Genel Yönetim | I12: ONAYLANDI
B13: 05.11.2026 | C13: TR-0435-H | D13: Operasyonel ana kalem tahmini | E13: 520800 | F13: 0.2 | G13: =E13/(1+F13) | H13: Vadesiz Ticari | I13: ONAYLANDI
B14: 09.11.2026 | C14: TR-0436-I | D14: Müşteri işlem tahmini | E14: 1120000 | F14: 0.2 | G14: =E14/(1+F14) | H14: Müşteri Alacağı | I14: ONAYLANDI
B15: 12.11.2026 | C15: TR-0437-J | D15: Operasyonel çıkış tahmini | E15: 890000 | F15: 0.2 | G15: =E15/(1+F15) | H15: Tedarikçi Havuzu | I15: ONAYLANDI
B17: SAYFA TOPLAMI (10 / 1.450 KAYIT) | E17: =TOPLA(E6:E15)

Sheet YÖNETİM_RAPORU
A1: ☰ PANO
B2: SITE/APARTMAN YÖNETIM SISTEMI — NİHAİ KARAR VE DEĞERLEME
B3: Yönetim Kurulu ve İcra Komitesi için Otomatik Finansal Stres Testi Raporu · Site yöneticisi, yönetim kurulu, kat malikleri temsilcisi, SMMM
B4: DÖNEM: 2026 Q3 · DENETİM PROTOKOLÜ: ISO/VUK/IFRS UYUMLU · DURUM: ONAYLANDI
B6: SENARYO A: KÖTÜMSER (STRES TESTİ -%20) | H6: SENARYO B: BAZ MODEL (HEDEFLENEN)
B8: Ciro / Hacim Düşüşü: | E8: -%20.0 (Kriz Eşiği) | H8: Ciro / Hacim Gerçekleşmesi: | K8: %100.0 (Tam Bütçe)
B9: Beklenen Net Kâr / Getiri: | E9: =PANO!B7*0.8*0.22 | H9: Beklenen Net Kâr / Getiri: | K9: =PANO!H7
B10: Minimum Nakit Tamponu: | E10: =PANO!E7*0.75 | H10: Serbest Nakit Akımı: | K10: =PANO!H7*0.75
B11: Likidite Karşılama Oranı: | E11: =YUVARLA(PANO!B7*0.8/PANO!E7; 2) | H11: Yatırım Geri Dönüşü (ROI): | K11: %38.4 Yıllık
B14: STRES SENARYOSUNDA DAHİ İFLAS RİSKİ YOK | H14: OPTİMUM İCRA VE PLANLAMA REÇETESİ
B17: YÖNETİM KARAR MATRİSİ VE UYGULAMA REÇETESİ
B19: ● Öncelik 1: Acil Likidite ve Borç Servis Planlaması
B20: Sistemde hesaplanan vade günlerine sadık kalınarak nakit blokajı 3 gün önceden hazır edilmelidir.
B21: ● Öncelik 2: Formül Doğrulama ve Çapraz Sağlama
B22: Tüm hücreler kilitli formül korumasında olup girdi sayfalarında sıfır döngüsel başvuru (circular ref) garantilidir.
B23: ● Öncelik 3: Resmi Mevzuat ve Vergi Kalkanı Entegrasyonu
B24: 2026 güncel vergi dilimleri, amortisman ve SGK teşvik parametreleri tam otomatik yansıtılmaktadır.
B25: ● Öncelik 4: Yönetici İmzası ve Rapor Paylaşımı
B26: Tek tuşla PDF ve A4 çıktı formatına tam uyumlu sayfa yapısı kurgulanmıştır.

Sheet 01_YURUTME_CEKIRDEGI
A1: YÜRÜTME ÇEKİRDEĞİ — ZORUNLU ÜRETİM SIRASI
A3: Adım | B3: Modül | C3: Tetikleyici | D3: Zorunlu Kanıt | E3: GEÇTİ Kuralı | F3: Hata Durumu | G3: Sonraki Aşama
A4: 1 | B4: Excel Uygunluğu | C4: Her yeni model | D4: UYGUNLUK_KARARI | E4: Excel'in rolü açık | F4: HATA / BLOKE | G4: Yönetişim
A5: 2 | B5: Yönetişim | C5: Her model | D5: Risk seviyesi + etki girdileri | E5: Seviye hesaplandı | F5: BLOKE | G5: Sözleşmeler
A6: 3 | B6: Türk Muhasebe Eşlemesi | C6: Finansal model | D6: THP hesap eşleme tablosu | E6: Kritik satırlar THP ile uyumlu | F6: HATA | G6: Sözleşmeler
A7: 4 | B7: Veri ve Anlam Sözleşmeleri | C7: Girdi/KPI varsa | D7: Veri + KPI sözleşmeleri | E7: Kapsam %100 | F7: HATA | G7: Üretim
A8: 5 | B8: Üretim | C8: Sözleşmeler GEÇTİ | D8: Çalışan Excel | E8: Tek gerçek kaynak korunmuş | F8: HATA | G8: Testler
A9: 6 | B9: Görsel/Kullanım Katmanı | C9: Motor hazır | D9: Başlıklar + renk + grafik + yönlendirme | E9: Tüm kullanıcı sayfaları standarda uygun | F9: HATA | G9: Testler
A10: 7 | B10: Testler | C10: Üretim tamam | D10: Formül/OOXML/kimlik/oracle/golden/metamorfik | E10: Uygulanabilir hard gate'ler GEÇTİ | F10: HATA | G10: Kanıt
A11: 8 | B11: Hata-Kontrol Tutarlılığı | C11: Test sonucu var | D11: Hata taraması + kontrol sonuçları | E11: Formül hatası varken GEÇTİ yok | F11: HATA | G11: Kanıt
A12: 9 | B12: Kanıt | C12: Test sonucu var | D12: Makine okunur artefakt + özet | E12: Kanıt fiziksel ve tutarlı | F12: HATA | G12: Kullanıcı Kabulü
A13: 10 | B13: Kullanıcı Kabulü | C13: Kritik görevler | D13: Gerçek ekran davranışı | E13: Kritik görevler %100 | F13: DIŞ_KABUL_GEREKLİ | G13: Ticari
A14: 11 | B14: Ticari Değer | C14: Ürün satılacaksa | D14: ROI + demo + kanıt paketi | E14: Ekonomik değer kanıtlı | F14: UYARI / HATA | G14: Pazar Doğrulama
A15: 12 | B15: Pazar Doğrulama | C15: Pazar iddiası varsa | D15: Ücretli satış/pilot/fiyat kabul kanıtı | E15: Gerçek fiyat kabul kanıtı | F15: UYGULANMAZ / HATA | G15: Yayın

Sheet 02_KONTROL_LISTESI
A1: NİHAİ KONTROL LİSTESİ — KANITSIZ GEÇİŞ YOK
A3: Kontrol No | B3: Kontrol | C3: Beklenen | D3: Zorunlu Kapı? | E3: Sonuç
A4: K01 | B4: Kullanıcının açık talebi öncelikli mi? | C4: Evet | D4: EVET
A5: K02 | B5: Mevcut yapı, formüller ve tek gerçek kaynak korunuyor mu? | C5: Evet, değişiklik gerekçeli | D5: EVET
A6: K03 | B6: Üst aşama HATA ise alt aşama GEÇTİ engelleniyor mu? | C6: Evet | D6: EVET
A7: K04 | B7: Kanıt fiziksel çıktı ve içerik doğrulaması içeriyor mu? | C7: Evet | D7: EVET
A8: K05 | B8: Excel GUI erişimi olmadan kullanıcı görünümü GEÇTİ yazılıyor mu? | C8: Hayır | D8: EVET
A9: K06 | B9: NİHAİ yalnız GEÇTİ / gerekçeli UYGULANMAZ ile mi? | C9: Evet | D9: EVET
A10: K07 | B10: Ekonomik fiyat savunusu pazar doğrulamasından ayrılmış mı? | C10: Evet | D10: EVET
A11: K08 | B11: Prestij için gereksiz modül var mı? | C11: Hayır | D11: HAYIR
A12: K09 | B12: Excel sınırları açık mı? | C12: Evet | D12: EVET
A13: K10 | B13: Teknik kaynak korunuyor mu? | C13: Evet | D13: EVET
A14: K11 | B14: Kullanıcıya görünen tüm metinler Türkçe mi? | C14: Evet | D14: EVET
A15: K12 | B15: Her kullanıcı sayfasında üst başlık var mı? | C15: Evet | D15: EVET
... A34: K31 | B34: Premium vitrin, altyapı kadar güçlü ve satış fiyatını destekleyecek seviyede mi? | C34: Evet | D34: EVET

Sheet 03_GORSEL_TASARIM
A1: GÖRSEL TASARIM VE PREMIUM EXCEL STANDARDI
A3: Alan | B3: Zorunlu Kural | C3: Uygulama | D3: Yasak | E3: Kontrol | F3: Durum
A4: Sayfa başlığı | B4: Her kullanıcı sayfasının en üstünde tek ve açık sayfa başlığı | C4: A1'den başlayan koyu lacivert başlık bandı | D4: Başlıksız sayfa | E4: Başlık kapsama = %100 | F4: ZORUNLU
A5: Sekme renkleri | B5: Sayfalar işlevine göre renk kodlanır | C5: Girdi=mavi, hesap=gri, rapor=lacivert, kontrol=kırmızı, kılavuz=altın | D5: Rastgele renk | E5: Renk semantiği tutarlı | F5: ZORUNLU
A6: Kolon düzeni | B6: Veri blokları bitişik kolonlarda ilerler | C6: Gereksiz boş kolon bırakma; yalnız gerçek bölüm ayrımı varsa kontrollü boşluk | D6: A:C veri, D boş, E:F veri gibi parçalı yapı | E6: Boş kolon taraması | F6: ZORUNLU
A7: Girdi hücreleri | B7: Kullanıcının değiştireceği alan açıkça görünür | C7: Açık sarı dolgu + mavi yazı | D7: Formülle aynı görünüm | E7: Girdi/formül ayrımı | F7: ZORUNLU
A8: Formüller | B8: Hesap hücreleri kullanıcı girdisinden ayrılır | C8: Siyah yazı; sayfalar arası bağlantı yeşil yazı | D8: Hard-code gizleme | E8: Formül sınıfı kontrolü | F8: ZORUNLU
A9: Grafik sayısı | B9: Yönetici ekranında en fazla 3 ana karar grafiği | C9: Trend, karşılaştırma, köprü/dağılım; iş kararına bağlı | D9: Grafik kalabalığı | E9: Grafik başına karar sorusu | F9: ZORUNLU
A10: Grafik stili | B10: Kurumsal ve yüksek okunabilirlik | C10: Beyaz zemin, ince gridline, tek vurgu rengi, açık birim/başlık | D10: 3B, gölge, neon, gökkuşağı renkleri | E10: Görsel inceleme | F10: ZORUNLU
A11: Grafik başlığı | B11: Grafik 'neyi' değil 'ne anlama geldiğini' söyler | C11: Örn: 'Nakit 2028'de kritik eşiğin altına iniyor' | D11: 'Nakit Grafiği' gibi anlamsız başlık | E11: Başlık karar testi | F11: ZORUNLU
A12: Birimler | B12: Tüm finansal görsellerde birim açık | C12: TL, bin TL, milyon TL, %, gün, x | D12: Birim belirsizliği | E12: Birim kapsama %100 | F12: ZORUNLU
A13: Sıfır/negatif | B13: Finansal format standardı | C13: Sıfır='-', negatif kırmızı parantez | D13: -500 veya 0,00 kalabalığı | E13: Format kontrolü | F13: ZORUNLU
A14: Yazı tipi | B14: Tek aile | C14: Aptos veya Segoe UI | D14: Karışık font | E14: Tek font kontrolü | F14: ZORUNLU
... A22: Premium vitrin | B22: Görsel kalite ürün değerinin zorunlu parçasıdır | C22: Kaliteli grafik, gerçek KPI kartı, finansal hiyerarşi, tab rengi, fonksiyonel navigasyon | D22: Sadece doğru hesap yapıp çıplak/varsayılan Excel görünümü bırakmak | E22: Görsel release incelemesi | F22: ZORUNLU

Sheet 04_MUHASEBE_THP
A1: TÜRKİYE MUHASEBE VE TEKDÜZEN HESAP PLANI STANDARDI
A3: Konu | B3: Zorunlu Standart | C3: Örnek Türkçe Ad | D3: THP / Mantık | E3: Hata Riski | F3: Kontrol
A4: Dil | B4: Kullanıcıya görünen finansal terimler Türkçe | C4: Hasılat, Satışların Maliyeti, Brüt Kâr, Faaliyet Giderleri | D4: Türk işletme kullanımına uygun | E4: İngilizce jargon | F4: Terminoloji taraması
A5: Gelir Tablosu | B5: Türk sunum sırası kullanılır | C5: Net Satışlar → Satışların Maliyeti → Brüt Kâr → Faaliyet Giderleri → Faaliyet Kârı | D5: 600/610/611; 620-623; 63x | E5: Yanlış sınıflama | F5: Hesap eşleme
A6: Bilanço | B6: Dönen/Duran Varlık ve Kısa/Uzun Vadeli Yükümlülük ayrımı | C6: Hazır Değerler, Ticari Alacaklar, Stoklar, Mali Borçlar | D6: 1xx / 2xx / 3xx / 4xx / 5xx | E6: Vade sınıfı hatası | F6: Bilanço eşitliği
A7: Nakit Akışı | B7: İşletme/Yatırım/Finansman nakit akışları ayrılır | C7: Faaliyetlerden Nakit, Yatırım Harcamaları, Finansman Nakit Akışı | D7: Dolaylı/doğrudan yöntem açık seçilir | E7: Kâr = nakit sanılması | F7: Nakit devri
A8: Ticari Alacaklar | B8: Cari ve vade mantığı korunur | C8: 120 Alıcılar | D8: 120 | E8: Tahakkuk/nakit karışması | F8: Alacak devir kontrolü
A9: Ticari Borçlar | B9: Tedarikçi borcu ayrı izlenir | C9: 320 Satıcılar | D9: 320 | E9: Gider/ödeme karışması | F9: Borç devir kontrolü
A10: Kasa/Banka | B10: Hazır değerler ayrı izlenir | C10: 100 Kasa, 102 Bankalar | D10: 100 / 102 | E10: Virmanla toplam nakdin değişmesi | F10: Virman değişmezi
A11: Stok | B11: Dikeye uygun stok türü | C11: 150 İlk Madde ve Malzeme, 153 Ticari Mallar | D11: 15x | E11: Maliyet ve stok hareketinin kopması | F11: Stok devri
A12: Maddi Duran Varlık | B12: Yatırım harcaması ve amortisman bağlantılı | C12: 253 Tesis Makine Cihazlar, 255 Demirbaşlar, 257 Birikmiş Amortismanlar | D12: 25x | E12: Yatırım/gider karışması | F12: Net defter değeri devri
A13: Mali Borçlar | B13: Kısa/uzun vadeli borç ayrımı | C13: 300 Banka Kredileri / 400 Banka Kredileri | D13: 300 / 400 | E13: Vade sınıfı yanlış | F13: Borç devri
A14: Özkaynak | B14: Sermaye ve geçmiş yıl kârları ayrı | C14: 500 Sermaye, 570 Geçmiş Yıllar Kârları, 590 Dönem Net Kârı | D14: 5xx | E14: Net kâr bağının kopması | F14: Özkaynak devri
... A18: İstisna | B18: TFRS özel ürün varsa fark açık yazılır | C18: Tekdüzen raporlama ≠ TFRS finansal tablo sunumu | D18: Amaç belirtilir | E18: Standartları karıştırma | F18: Model amacı kontrolü

Sheet 05_KARAR_SATIS
A1: KARAR, GÜVEN VE SATIŞA HAZIRLIK STANDARDI
A3: Alan | B3: Müşteri Sorusu | C3: Zorunlu Ürün Davranışı | D3: Kanıt | E3: Başarısızlık Durumu | F3: Kapı
A4: 5 saniye | B4: Bu ürün neyi çözüyor? | C4: İlk ekranda hedef kullanıcı + pahalı problem + sonuç görünür | D4: Başlık + alt mesaj + gerçek ekran | E4: Ürün yalnız teknik isim | F4: HATA
A5: Acı | B5: Sorun bana neye mal oluyor? | C5: Mümkünse müşterinin kendi verisiyle parasal/zaman etkisi hesaplanır | D5: ROI/acı hesaplama yöntemi | E5: Uydurma tasarruf | F5: HATA
A6: Karar | B6: Bu bilgiyle ne yapacağım? | C6: Her kritik KPI aksiyona bağlanır | D6: KARAR_KUYRUGU | E6: Sadece rapor | F6: HATA
A7: Güven | B7: Bu sayıya neden inanayım? | C7: Kaynak, formül mantığı, kontrol ve son doğrulama görünür | D7: Kontroller + kaynak izi + sürüm | E7: Prestij kelimesi | F7: HATA
A8: Referans | B8: Müşteri yorumu yoksa ne göstereceğim? | C8: Önce/Sonra + Karar Vakası + Hata Önleme Vakası üretilir | D8: Demo/örnek çıktı | E8: Kanıtsız iddia | F8: HATA
A9: Senaryo | B9: Ne olursa işler bozulur? | C9: Baz/Aşağı/Yukarı veya uygun stres senaryosu | D9: Senaryo karşılaştırma | E9: Dekoratif senaryo | F9: HATA
A10: Ters stres | B10: Hangi eşikte karar kırılır? | C10: En az bir kritik sürücü için kırılma eşiği | D10: Kırılma eşiği tablosu | E10: Sadece +/- %10 | F10: UYARI/HATA
A11: Hata tutarlılığı | B11: Formül hata verirse ne olur? | C11: Kontrol GEÇTİ veremez; BLOKE/HATA üretir | D11: Hata taraması | E11: Hata + GEÇTİ birlikte | F11: HATA
A12: Karar motoru | B12: Ne oldu, neden oldu? | C12: Sorun + neden + parasal etki + aksiyon + son tarih | D12: Karar tablosu | E12: Boş sayfa / isim düzeyi modül | F12: HATA
A13: Yönetici özeti | B13: 5 saniyede ne görmeliyim? | C13: Bugün / ne değişti / ne bozulacak / neden / ne yapmalıyım / güven | D13: Yönetici özeti ekranı | E13: KPI kutusu yığını | F13: HATA
A14: Teklif | B14: Neden satın almalıyım? | C14: Dosya özellikleri yerine sonuç ve kaçınılan maliyet sunulur | D14: Ürün sayfası kanıt eşlemesi | E14: Özellik listesiyle satış | F14: HATA
... A19: Pazar kanıtı | B19: Piyasa gerçekten ödüyor mu? | C19: Satış/pilot/LOI/fiyat kabulü olmadan pazar doğrulandı yazılmaz | D19: Gerçek işlem kanıtı | E19: Tahmini talep = satış kabulü | F19: HATA

Sheet KAPAK
A1: KAPAK — Site/Apartman Yönetim Sistemi
A3: Site/Apartman Yönetim Sistemi
A4: Aidat borçlandırma ve tahsilatı eşleştirin; icap kuyruğunu yönetin; genel kurula sunulacak dönem kanıt raporunu üretin (KMK md.20).
A6: Bu ürün ne sağlar?
A7: • Borç↔tahsilat dört kova mutabakatı — sapmada kök neden + TANIMSIZ kova
A8: • İcap durum makinesi: Açık → Hatırlatma → İcap → Tahsil/Kapalı
A9: • KMK md.20 gecikme zammı oranı AYARLAR'dan; gömülü sabit yok
A10: • Bütçe vs gerçekleşen gider + genel kurul karar defteri
A11: • Makrosuz, çevrimdışı; site yazılımı / API bağı yok
A13: Kimler için?
A14: • Site yöneticisi — aidat, tahsilat, icap girişi
A15: • Kat malikleri / yönetim kurulu — PANO karar özeti
... A19: Başlamak: HIZLI_BASLANGIC → GIRDI → PAYDASLAR → DONEMLER → TAHSILAT → PANO

Sheet HIZLI_BASLANGIC
A1: HIZLI BASLANGIC — Site/Apartman Yönetim Sistemi
A3: 3 adımda başlayın
A5: 1. Paydaşlar | B5: PAYDASLAR sayfasında malik kimliklerini girin (sarı hücreler).
A6: 2. Borç & tahsilat | B6: DONEMLER'de aidat borçlandırın; TAHSILAT'ta ödemeleri girin.
A7: 3. Karar | B7: PANO ve KARAR'da tahsilat oranı + icap kuyruğunu okuyun.
A9: Anlık karar kapısı
A10: Karar | B10: =say_kararKapi
A11: Tahsilat oranı | B11: =say_tahsilatOrani
A12: Kasa bakiyesi | B12: =say_kasaBakiye

Sheet GIRDI
A1: GIRDI — Site/Apartman Yönetim Sistemi
A3: Site ve dönem parametreleri
A4: Alan | B4: Değer
A5: Site adı | B5: Güneş Sitesi
A6: Bağımsız bölüm sayısı | B6: 48
A7: Dönem kodu | B7: 2026-08
A8: Aylık aidat tabanı (TL) | B8: 2500
A9: Hedef tahsilat oranı | B9: 0.92
A10: İcap eşiği (gün) | B10: 30
A11: Bütçe ayı gider tavanı | B11: 80000
A12: Senaryo çarpanı | B12: 1

Sheet PAYDASLAR
A1: PAYDASLAR — Site/Apartman Yönetim Sistemi
A3: Malik / paydaş kartları — ID disiplini (bakiye türetilir)
A5: MalikId | B5: BagimsizBolum | C5: AdSoyad | D5: PayKatsayi | E5: Aktif | F5: BorcToplam | G5: TahsilToplam | H5: Bakiye | I5: KayitDolu | J5: MotorAdim
A6: MLK-001 | B6: A Blok 1 | C6: Ayşe Yılmaz | D6: 1 | E6: EVET | F6: =IF($A6="","",SUMIF(tblDonem[MalikId],$A6,tblDonem[BorcTutari])) | G6: =IF($A6="","",SUMIF(tblTahsilat[MalikId],$A6,tblTahsilat[OdemeTutari])) | H6: =IF($A6="","",$F6-$G6) | I6: =IF($A6="","",1) | J6: =IF($A6="","",($H6>0)+($E6="EVET"))
A7: MLK-002 | B7: A Blok 2 | C7: Mehmet Demir | D7: 1 | E7: EVET | F7: =IF($A7="","",SUMIF(tblDonem[MalikId],$A7,tblDonem[BorcTutari])) | G7: =IF($A7="","",SUMIF(tblTahsilat[MalikId],$A7,tblTahsilat[OdemeTutari])) | H7: =IF($A7="","",$F7-$G7) | I7: =IF($A7="","",1) | J7: =IF($A7="","",($H7>0)+($E7="EVET"))
A8: MLK-003 | B8: A Blok 3 | C8: Zeynep Kaya | D8: 1 | E8: EVET | F8: =IF($A8="","",SUMIF(tblDonem[MalikId],$A8,tblDonem[BorcTutari])) | G8: =IF($A8="","",SUMIF(tblTahsilat[MalikId],$A8,tblTahsilat[OdemeTutari])) | H8: =IF($A8="","",$F8-$G8) | I8: =IF($A8="","",1) | J8: =IF($A8="","",($H8>0)+($E8="EVET"))
A9: MLK-004 | B9: B Blok 1 | C9: Ali Çelik | D9: 1.2 | E9: EVET | F9: =IF($A9="","",SUMIF(tblDonem[MalikId],$A9,tblDonem[BorcTutari])) | G9: =IF($A9="","",SUMIF(tblTahsilat[MalikId],$A9,tblTahsilat[OdemeTutari])) | H9: =IF($A9="","",$F9-$G9) | I9: =IF($A9="","",1) | J9: =IF($A9="","",($H9>0)+($E9="EVET"))
A10: MLK-005 | B10: B Blok 2 | C10: Fatma Şahin | D10: 1 | E10: EVET | F10: =IF($A10="","",SUMIF(tblDonem[MalikId],$A10,tblDonem[BorcTutari])) | G10: =IF($A10="","",SUMIF(tblTahsilat[MalikId],$A10,tblTahsilat[OdemeTutari])) | H10: =IF($A10="","",$F10-$G10) | I10: =IF($A10="","",1) | J10: =IF($A10="","",($H10>0)+($E10="EVET"))
A11: MLK-006 | B11: B Blok 3 | C11: Hasan Aydın | D11: 1 | E11: HAYIR | F11: =IF($A11="","",SUMIF(tblDonem[MalikId],$A11,tblDonem[BorcTutari])) | G11: =IF($A11="","",SUMIF(tblTahsilat[MalikId],$A11,tblTahsilat[OdemeTutari])) | H11: =IF($A11="","",$F11-$G11) | I11: =IF($A11="","",1) | J11: =IF($A11="","",($H11>0)+($E11="EVET"))
A12: MLK-007 | B12: C Blok 1 | C12: Elif Arslan | D12: 1.5 | E12: EVET | F12: =IF($A12="","",SUMIF(tblDonem[MalikId],$A12,tblDonem[BorcTutari])) | G12: =IF($A12="","",SUMIF(tblTahsilat[MalikId],$A12,tblTahsilat[OdemeTutari])) | H12: =IF($A12="","",$F12-$G12) | I12: =IF($A12="","",1) | J12: =IF($A12="","",($H12>0)+($E12="EVET"))
A13: MLK-008 | B13: C Blok 2 | C13: Mustafa Öztürk | D13: 1 | E13: EVET | F13: =IF($A13="","",SUMIF(tblDonem[MalikId],$A13,tblDonem[BorcTutari])) | G13: =IF($A13="","",SUMIF(tblTahsilat[MalikId],$A13,tblTahsilat[OdemeTutari])) | H13: =IF($A13="","",$F13-$G13) | I13: =IF($A13="","",1) | J13: =IF($A13="","",($H13>0)+($E13="EVET"))
A14: MLK-009 | B14: C Blok 3 | C14: Selin Koç | D14: 1 | E14: EVET | F14: =IF($A14="","",SUMIF(tblDonem[MalikId],$A14,tblDonem[BorcTutari])) | G14: =IF($A14="","",SUMIF(tblTahsilat[MalikId],$A14,tblTahsilat[OdemeTutari])) | H14: =IF($A14="","",$F14-$G14) | I14: =IF($A14="","",1) | J14: =IF($A14="","",($H14>0)+($E14="EVET"))
A15: MLK-010 | B15: D Blok 1 | C15: Emre Yıldız | D15: 1 | E15: EVET | F15: =IF($A15="","",SUMIF(tblDonem[MalikId],$A15,tblDonem[BorcTutari])) | G15: =IF($A15="","",SUMIF(tblTahsilat[MalikId],$A15,tblTahsilat[OdemeTutari])) | H15: =IF($A15="","",$F15-$G15) | I15: =IF($A15="","",1) | J15: =IF($A15="","",($H15>0)+($E15="EVET"))
A16: MLK-011 | B16: D Blok 2 | C16: Deniz Acar | D16: 1 | E16: EVET | F16: =IF($A16="","",SUMIF(tblDonem[MalikId],$A16,tblDonem[BorcTutari])) | G16: =IF($A16="","",SUMIF(tblTahsilat[MalikId],$A16,tblTahsilat[OdemeTutari])) | H16: =IF($A16="","",$F16-$G16) | I16: =IF($A16="","",1) | J16: =IF($A16="","",($H16>0)+($E16="EVET"))
A17: MLK-012 | B17: D Blok 3 | C17: Burak Polat | D17: 1 | E17: EVET | F17: =IF($A17="","",SUMIF(tblDonem[MalikId],$A17,tblDonem[BorcTutari])) | G17: =IF($A17="","",SUMIF(tblTahsilat[MalikId],$A17,tblTahsilat[OdemeTutari])) | H17: =IF($A17="","",$F17-$G17) | I17: =IF($A17="","",1) | J17: =IF($A17="","",($H17>0)+($E17="EVET"))
F18: =IF($A18="","",SUMIF(tblDonem[MalikId],$A18,tblDonem[BorcTutari])) | G18: =IF($A18="","",SUMIF(tblTahsilat[MalikId],$A18,tblTahsilat[OdemeTutari])) | H18: =IF($A18="","",$F18-$G18) | I18: =IF($A18="","",1) | J18: =IF($A18="","",($H18>0)+($E18="EVET"))
F19: =IF($A19="","",SUMIF(tblDonem[MalikId],$A19,tblDonem[BorcTutari])) | G19: =IF($A19="","",SUMIF(tblTahsilat[MalikId],$A19,tblTahsilat[OdemeTutari])) | H19: =IF($A19="","",$F19-$G19) | I19: =IF($A19="","",1) | J19: =IF($A19="","",($H19>0)+($E19="EVET"))
F20: =IF($A20="","",SUMIF(tblDonem[MalikId],$A20,tblDonem[BorcTutari])) | G20: =IF($A20="","",SUMIF(tblTahsilat[MalikId],$A20,tblTahsilat[OdemeTutari])) | H20: =IF($A20="","",$F20-$G20) | I20: =IF($A20="","",1) | J20: =IF($A20="","",($H20>0)+($E20="EVET"))
F21: =IF($A21="","",SUMIF(tblDonem[MalikId],$A21,tblDonem[BorcTutari])) | G21: =IF($A21="","",SUMIF(tblTahsilat[MalikId],$A21,tblTahsilat[OdemeTutari])) | H21: =IF($A21="","",$F21-$G21) | I21: =IF($A21="","",1) | J21: =IF($A21="","",($H21>0)+($E21="EVET"))
F22: =IF($A22="","",SUMIF(tblDonem[MalikId],$A22,tblDonem[BorcTutari])) | G22: =IF($A22="","",SUMIF(tblTahsilat[MalikId],$A22,tblTahsilat[OdemeTutari])) | H22: =IF($A22="","",$F22-$G22) | I22: =IF($A22="","",1) | J22: =IF($A22="","",($H22>0)+($E22="EVET"))
F23: =IF($A23="","",SUMIF(tblDonem[MalikId],$A23,tblDonem[BorcTutari])) | G23: =IF($A23="","",SUMIF(tblTahsilat[MalikId],$A23,tblTahsilat[OdemeTutari])) | H23: =IF($A23="","",$F23-$G23) | I23: =IF($A23="","",1) | J23: =IF($A23="","",($H23>0)+($E23="EVET"))
F24: =IF($A24="","",SUMIF(tblDonem[MalikId],$A24,tblDonem[BorcTutari])) | G24: =IF($A24="","",SUMIF(tblTahsilat[MalikId],$A24,tblTahsilat[OdemeTutari])) | H24: =IF($A24="","",$F24-$G24) | I24: =IF($A24="","",1) | J24: =IF($A24="","",($H24>0)+($E24="EVET"))
F25: =IF($A25="","",SUMIF(tblDonem[MalikId],$A25,tblDonem[BorcTutari])) | G25: =IF($A25="","",SUMIF(tblTahsilat[MalikId],$A25,tblTahsilat[OdemeTutari])) | H25: =IF($A25="","",$F25-$G25) | I25: =IF($A25="","",1) | J25: =IF($A25="","",($H25>0)+($E25="EVET"))
F26: =IF($A26="","",SUMIF(tblDonem[MalikId],$A26,tblDonem[BorcTutari])) | G26: =IF($A26="","",SUMIF(tblTahsilat[MalikId],$A26,tblTahsilat[OdemeTutari])) | H26: =IF($A26="","",$F26-$G26) | I26: =IF($A26="","",1) | J26: =IF($A26="","",($H26>0)+($E26="EVET"))
F27: =IF($A27="","",SUMIF(tblDonem[MalikId],$A27,tblDonem[BorcTutari])) | G27: =IF($A27="","",SUMIF(tblTahsilat[MalikId],$A27,tblTahsilat[OdemeTutari])) | H27: =IF($A27="","",$F27-$G27) | I27: =IF($A27="","",1) | J27: =IF($A27="","",($H27>0)+($E27="EVET"))
F28: =IF($A28="","",SUMIF(tblDonem[MalikId],$A28,tblDonem[BorcTutari])) | G28: =IF($A28="","",SUMIF(tblTahsilat[MalikId],$A28,tblTahsilat[OdemeTutari])) | H28: =IF($A28="","",$F28-$G28) | I28: =IF($A28="","",1) | J28: =IF($A28="","",($H28>0)+($E28="EVET"))
F29: =IF($A29="","",SUMIF(tblDonem[MalikId],$A29,tblDonem[BorcTutari])) | G29: =IF($A29="","",SUMIF(tblTahsilat[MalikId],$A29,tblTahsilat[OdemeTutari])) | H29: =IF($A29="","",$F29-$G29) | I29: =IF($A29="","",1) | J29: =IF($A29="","",($H29>0)+($E29="EVET"))
... F86: =IF($A86="","",SUMIF(tblDonem[MalikId],$A86,tblDonem[BorcTutari])) | G86: =IF($A86="","",SUMIF(tblTahsilat[MalikId],$A86,tblTahsilat[OdemeTutari])) | H86: =IF($A86="","",$F86-$G86) | I86: =IF($A86="","",1) | J86: =IF($A86="","",($H86>0)+($E86="EVET"))

Sheet DONEMLER
A1: DONEMLER — Site/Apartman Yönetim Sistemi
A3: Dönem borçlandırma motoru — aidat + gecikme zammı tabanı
A5: BorcId | B5: MalikId | C5: Donem | D5: BorcTutari | E5: VadeTarihi | F5: HamAnahtar | G5: GecikmeGun | H5: ZamTutari | I5: ToplamBorc | J5: MotorAdim
A6: BRC-001 | B6: MLK-001 | C6: 2026-07 | D6: 2700 | E6: 46213 | F6: =IF($B6="","",UPPER(TRIM(SUBSTITUTE($B6&$C6," ","")))) | G6: =IF($A6="","",IF($E6="","",raporTarihi-$E6)) | H6: =IF($A6="","",IF($G6>say_icapEsikGun,ROUND($D6*say_gecikmeZammi,2),0)) | I6: =IF($A6="","",$D6+$H6) | J6: =IF($A6="","",($H6>0)+1)
A7: BRC-002 | B7: MLK-002 | C7: 2026-07 | D7: 2900 | E7: 46213 | F7: =IF($B7="","",UPPER(TRIM(SUBSTITUTE($B7&$C7," ","")))) | G7: =IF($A7="","",IF($E7="","",raporTarihi-$E7)) | H7: =IF($A7="","",IF($G7>say_icapEsikGun,ROUND($D7*say_gecikmeZammi,2),0)) | I7: =IF($A7="","",$D7+$H7) | J7: =IF($A7="","",($H7>0)+1)
A8: BRC-003 | B8: MLK-003 | C8: 2026-07 | D8: 2700 | E8: 46213 | F8: =IF($B8="","",UPPER(TRIM(SUBSTITUTE($B8&$C8," ","")))) | G8: =IF($A8="","",IF($E8="","",raporTarihi-$E8)) | H8: =IF($A8="","",IF($G8>say_icapEsikGun,ROUND($D8*say_gecikmeZammi,2),0)) | I8: =IF($A8="","",$D8+$H8) | J8: =IF($A8="","",($H8>0)+1)
A9: BRC-004 | B9: MLK-004 | C9: 2026-07 | D9: 2700 | E9: 46213 | F9: =IF($B9="","",UPPER(TRIM(SUBSTITUTE($B9&$C9," ","")))) | G9: =IF($A9="","",IF($E9="","",raporTarihi-$E9)) | H9: =IF($A9="","",IF($G9>say_icapEsikGun,ROUND($D9*say_gecikmeZammi,2),0)) | I9: =IF($A9="","",$D9+$H9) | J9: =IF($A9="","",($H9>0)+1)
A10: BRC-005 | B10: MLK-005 | C10: 2026-07 | D10: 2900 | E10: 46213 | F10: =IF($B10="","",UPPER(TRIM(SUBSTITUTE($B10&$C10," ","")))) | G10: =IF($A10="","",IF($E10="","",raporTarihi-$E10)) | H10: =IF($A10="","",IF($G10>say_icapEsikGun,ROUND($D10*say_gecikmeZammi,2),0)) | I10: =IF($A10="","",$D10+$H10) | J10: =IF($A10="","",($H10>0)+1)
A11: BRC-006 | B11: MLK-006 | C11: 2026-07 | D11: 2500 | E11: 46213 | F11: =IF($B11="","",UPPER(TRIM(SUBSTITUTE($B11&$C11," ","")))) | G11: =IF($A11="","",IF($E11="","",raporTarihi-$E11)) | H11: =IF($A11="","",IF($G11>say_icapEsikGun,ROUND($D11*say_gecikmeZammi,2),0)) | I11: =IF($A11="","",$D11+$H11) | J11: =IF($A11="","",($H11>0)+1)
A12: BRC-007 | B12: MLK-007 | C12: 2026-07 | D12: 2700 | E12: 46213 | F12: =IF($B12="","",UPPER(TRIM(SUBSTITUTE($B12&$C12," ","")))) | G12: =IF($A12="","",IF($E12="","",raporTarihi-$E12)) | H12: =IF($A12="","",IF($G12>say_icapEsikGun,ROUND($D12*say_gecikmeZammi,2),0)) | I12: =IF($A12="","",$D12+$H12) | J12: =IF($A12="","",($H12>0)+1)
A13: BRC-008 | B13: MLK-008 | C13: 2026-07 | D13: 2900 | E13: 46213 | F13: =IF($B13="","",UPPER(TRIM(SUBSTITUTE($B13&$C13," ","")))) | G13: =IF($A13="","",IF($E13="","",raporTarihi-$E13)) | H13: =IF($A13="","",IF($G13>say_icapEsikGun,ROUND($D13*say_gecikmeZammi,2),0)) | I13: =IF($A13="","",$D13+$H13) | J13: =IF($A13="","",($H13>0)+1)
A14: BRC-009 | B14: MLK-009 | C14: 2026-07 | D14: 2500 | E14: 46213 | F14: =IF($B14="","",UPPER(TRIM(SUBSTITUTE($B14&$C14," ","")))) | G14: =IF($A14="","",IF($E14="","",raporTarihi-$E14)) | H14: =IF($A14="","",IF($G14>say_icapEsikGun,ROUND($D14*say_gecikmeZammi,2),0)) | I14: =IF($A14="","",$D14+$H14) | J14: =IF($A14="","",($H14>0)+1)
A15: BRC-010 | B15: MLK-010 | C15: 2026-07 | D15: 2700 | E15: 46213 | F15: =IF($B15="","",UPPER(TRIM(SUBSTITUTE($B15&$C15," ","")))) | G15: =IF($A15="","",IF($E15="","",raporTarihi-$E15)) | H15: =IF($A15="","",IF($G15>say_icapEsikGun,ROUND($D15*say_gecikmeZammi,2),0)) | I15: =IF($A15="","",$D15+$H15) | J15: =IF($A15="","",($H15>0)+1)
A16: BRC-011 | B16: MLK-001 | C16: 2026-08 | D16: 2950 | E16: 46244 | F16: =IF($B16="","",UPPER(TRIM(SUBSTITUTE($B16&$C16," ","")))) | G16: =IF($A16="","",IF($E16="","",raporTarihi-$E16)) | H16: =IF($A16="","",IF($G16>say_icapEsikGun,ROUND($D16*say_gecikmeZammi,2),0)) | I16: =IF($A16="","",$D16+$H16) | J16: =IF($A16="","",($H16>0)+1)
A17: BRC-012 | B17: MLK-002 | C17: 2026-08 | D17: 2500 | E17: 46244 | F17: =IF($B17="","",UPPER(TRIM(SUBSTITUTE($B17&$C17," ","")))) | G17: =IF($A17="","",IF($E17="","",raporTarihi-$E17)) | H17: =IF($A17="","",IF($G17>say_icapEsikGun,ROUND($D17*say_gecikmeZammi,2),0)) | I17: =IF($A17="","",$D17+$H17) | J17: =IF($A17="","",($H17>0)+1)
... A25: BRC-026 | B25: MLK-012 | C25: 2026-08 | D25: 2550 | E25: 46244 | F25: =IF($B25="","",UPPER(TRIM(SUBSTITUTE($B25&$C25," ","")))) | G25: =IF($A25="","",IF($E25="","",raporTarihi-$E25)) | H25: =IF($A25="","",IF($G25>say_icapEsikGun,ROUND($D25*say_gecikmeZammi,2),0)) | I25: =IF($A25="","",$D25+$H25) | J25: =IF($A25="","",($H25>0)+1)
F26: =IF($B26="","",UPPER(TRIM(SUBSTITUTE($B26&$C26," ","")))) | G26: =IF($A26="","",IF($E26="","",raporTarihi-$E26)) | H26: =IF($A26="","",IF($G26>say_icapEsikGun,ROUND($D26*say_gecikmeZammi,2),0)) | I26: =IF($A26="","",$D26+$H26) | J26: =IF($A26="","",($H26>0)+1)
F27: =IF($B27="","",UPPER(TRIM(SUBSTITUTE($B27&$C27," ","")))) | G27: =IF($A27="","",IF($E27="","",raporTarihi-$E27)) | H27: =IF($A27="","",IF($G27>say_icapEsikGun,ROUND($D27*say_gecikmeZammi,2),0)) | I27: =IF($A27="","",$D27+$H27) | J27: =IF($A27="","",($H27>0)+1)
F28: =IF($B28="","",UPPER(TRIM(SUBSTITUTE($B28&$C28," ","")))) | G28: =IF($A28="","",IF($E28="","",raporTarihi-$E28)) | H28: =IF($A28="","",IF($G28>say_icapEsikGun,ROUND($D28*say_gecikmeZammi,2),0)) | I28: =IF($A28="","",$D28+$H28) | J28: =IF($A28="","",($H28>0)+1)
F29: =IF($B29="","",UPPER(TRIM(SUBSTITUTE($B29&$C29," ","")))) | G29: =IF($A29="","",IF($E29="","",raporTarihi-$E29)) | H29: =IF($A29="","",IF($G29>say_icapEsikGun,ROUND($D29*say_gecikmeZammi,2),0)) | I29: =IF($A29="","",$D29+$H29) | J29: =IF($A29="","",($H29>0)+1)
F30: =IF($B30="","",UPPER(TRIM(SUBSTITUTE($B30&$C30," ","")))) | G30: =IF($A30="","",IF($E30="","",raporTarihi-$E30)) | H30: =IF($A30="","",IF($G30>say_icapEsikGun,ROUND($D30*say_gecikmeZammi,2),0)) | I30: =IF($A30="","",$D30+$H30) | J30: =IF($A30="","",($H30>0)+1)
F31: =IF($B31="","",UPPER(TRIM(SUBSTITUTE($B31&$C31," ","")))) | G31: =IF($A31="","",IF($E31="","",raporTarihi-$E31)) | H31: =IF($A31="","",IF($G31>say_icapEsikGun,ROUND($D31*say_gecikmeZammi,2),0)) | I31: =IF($A31="","",$D31+$H31) | J31: =IF($A31="","",($H31>0)+1)
F32: =IF($B32="","",UPPER(TRIM(SUBSTITUTE($B32&$C32," ","")))) | G32: =IF($A32="","",IF($E32="","",raporTarihi-$E32)) | H32: =IF($A32="","",IF($G32>say_icapEsikGun,ROUND($D32*say_gecikmeZammi,2),0)) | I32: =IF($A32="","",$D32+$H32) | J32: =IF($A32="","",($H32>0)+1)
F33: =IF($B33="","",UPPER(TRIM(SUBSTITUTE($B33&$C33," ","")))) | G33: =IF($A33="","",IF($E33="","",raporTarihi-$E33)) | H33: =IF($A33="","",IF($G33>say_icapEsikGun,ROUND($D33*say_gecikmeZammi,2),0)) | I33: =IF($A33="","",$D33+$H33) | J33: =IF($A33="","",($H33>0)+1)
F34: =IF($B34="","",UPPER(TRIM(SUBSTITUTE($B34&$C34," ","")))) | G34: =IF($A34="","",IF($E34="","",raporTarihi-$E34)) | H34: =IF($A34="","",IF($G34>say_icapEsikGun,ROUND($D34*say_gecikmeZammi,2),0)) | I34: =IF($A34="","",$D34+$H34) | J34: =IF($A34="","",($H34>0)+1)
F35: =IF($B35="","",UPPER(TRIM(SUBSTITUTE($B35&$C35," ","")))) | G35: =IF($A35="","",IF($E35="","",raporTarihi-$E35)) | H35: =IF($A35="","",IF($G35>say_icapEsikGun,ROUND($D35*say_gecikmeZammi,2),0)) | I35: =IF($A35="","",$D35+$H35) | J35: =IF($A35="","",($H35>0)+1)
F36: =IF($B36="","",UPPER(TRIM(SUBSTITUTE($B36&$C36," ","")))) | G36: =IF($A36="","",IF($E36="","",raporTarihi-$E36)) | H36: =IF($A36="","",IF($G36>say_icapEsikGun,ROUND($D36*say_gecikmeZammi,2),0)) | I36: =IF($A36="","",$D36+$H36) | J36: =IF($A36="","",($H36>0)+1)
F37: =IF($B37="","",UPPER(TRIM(SUBSTITUTE($B37&$C37," ","")))) | G37: =IF($A37="","",IF($E37="","",raporTarihi-$E37)) | H37: =IF($A37="","",IF($G37>say_icapEsikGun,ROUND($D37*say_gecikmeZammi,2),0)) | I37: =IF($A37="","",$D37+$H37) | J37: =IF($A37="","",($H37>0)+1)
... F86: =IF($B86="","",UPPER(TRIM(SUBSTITUTE($B86&$C86," ","")))) | G86: =IF($A86="","",IF($E86="","",raporTarihi-$E86)) | H86: =IF($A86="","",IF($G86>say_icapEsikGun,ROUND($D86*say_gecikmeZammi,2),0)) | I86: =IF($A86="","",$D86+$H86) | J86: =IF($A86="","",($H86>0)+1)

Sheet TAHSILAT
A1: TAHSILAT — Site/Apartman Yönetim Sistemi
A3: Ödeme girişi — eşleştirme motoruna besleme
A5: OdemeId | B5: MalikId | C5: Donem | D5: OdemeTutari | E5: OdemeTarihi | F5: HamAnahtar | G5: KaynakKartId | H5: MotorAdim
A6: ODM-001 | B6: MLK-001 | C6: 2026-07 | D6: 2700 | E6: 46219 | F6: =IF($B6="","",UPPER(TRIM(SUBSTITUTE($B6&$C6," ","")))) | G6: =IF($A6="","",$B6) | H6: =IF($A6="","",1)
A7: ODM-002 | B7: MLK-002 | C7: 2026-07 | D7: 2900 | E7: 46220 | F7: =IF($B7="","",UPPER(TRIM(SUBSTITUTE($B7&$C7," ","")))) | G7: =IF($A7="","",$B7) | H7: =IF($A7="","",1)
A8: ODM-003 | B8: MLK-003 | C8: 2026-07 | D8: 2700 | E8: 46221 | F8: =IF($B8="","",UPPER(TRIM(SUBSTITUTE($B8&$C8," ","")))) | G8: =IF($A8="","",$B8) | H8: =IF($A8="","",1)
A9: ODM-004 | B9: MLK-004 | C9: 2026-07 | D9: 2700 | E9: 46222 | F9: =IF($B9="","",UPPER(TRIM(SUBSTITUTE($B9&$C9," ","")))) | G9: =IF($A9="","",$B9) | H9: =IF($A9="","",1)
A10: ODM-005 | B10: MLK-005 | C10: 2026-07 | D10: 2850 | E10: 46223 | F10: =IF($B10="","",UPPER(TRIM(SUBSTITUTE($B10&$C10," ","")))) | G10: =IF($A10="","",$B10) | H10: =IF($A10="","",1)
A11: ODM-006 | B11: MLK-006 | C11: 2026-07 | D11: 2500 | E11: 46224 | F11: =IF($B11="","",UPPER(TRIM(SUBSTITUTE($B11&$C11," ","")))) | G11: =IF($A11="","",$B11) | H11: =IF($A11="","",1)
A12: ODM-007 | B12: MLK-007 | C12: 2026-07 | D12: 2700 | E12: 46225 | F12: =IF($B12="","",UPPER(TRIM(SUBSTITUTE($B12&$C12," ","")))) | G12: =IF($A12="","",$B12) | H12: =IF($A12="","",1)
A13: ODM-008 | B13: MLK-008 | C13: 2026-07 | D13: 2900 | E13: 46226 | F13: =IF($B13="","",UPPER(TRIM(SUBSTITUTE($B13&$C13," ","")))) | G13: =IF($A13="","",$B13) | H13: =IF($A13="","",1)
A14: ODM-009 | B14: MLK-009 | C14: 2026-07 | D14: 2450 | E14: 46227 | F14: =IF($B14="","",UPPER(TRIM(SUBSTITUTE($B14&$C14," ","")))) | G14: =IF($A14="","",$B14) | H14: =IF($A14="","",1)
A15: ODM-010 | B15: MLK-010 | C15: 2026-07 | D15: 2700 | E15: 46228 | F15: =IF($B15="","",UPPER(TRIM(SUBSTITUTE($B15&$C15," ","")))) | G15: =IF($A15="","",$B15) | H15: =IF($A15="","",1)
A16: ODM-011 | B16: MLK-001 | C16: 2026-08 | D16: 2950 | E16: 46229 | F16: =IF($B16="","",UPPER(TRIM(SUBSTITUTE($B16&$C16," ","")))) | G16: =IF($A16="","",$B16) | H16: =IF($A16="","",1)
A17: ODM-012 | B17: MLK-002 | C17: 2026-08 | D17: 2500 | E17: 46230 | F17: =IF($B17="","",UPPER(TRIM(SUBSTITUTE($B17&$C17," ","")))) | G17: =IF($A17="","",$B17) | H17: =IF($A17="","",1)
... A21: ODM-022 | B21: MLK-999 | C21: 2026-08 | D21: 2500 | E21: 46239 | F21: =IF($B21="","",UPPER(TRIM(SUBSTITUTE($B21&$C21," ","")))) | G21: =IF($A21="","",$B21) | H21: =IF($A21="","",1)
F22: =IF($B22="","",UPPER(TRIM(SUBSTITUTE($B22&$C22," ","")))) | G22: =IF($A22="","",$B22) | H22: =IF($A22="","",1)
F23: =IF($B23="","",UPPER(TRIM(SUBSTITUTE($B23&$C23," ","")))) | G23: =IF($A23="","",$B23) | H23: =IF($A23="","",1)
F24: =IF($B24="","",UPPER(TRIM(SUBSTITUTE($B24&$C24," ","")))) | G24: =IF($A24="","",$B24) | H24: =IF($A24="","",1)
F25: =IF($B25="","",UPPER(TRIM(SUBSTITUTE($B25&$C25," ","")))) | G25: =IF($A25="","",$B25) | H25: =IF($A25="","",1)
F26: =IF($B26="","",UPPER(TRIM(SUBSTITUTE($B26&$C26," ","")))) | G26: =IF($A26="","",$B26) | H26: =IF($A26="","",1)
F27: =IF($B27="","",UPPER(TRIM(SUBSTITUTE($B27&$C27," ","")))) | G27: =IF($A27="","",$B27) | H27: =IF($A27="","",1)
F28: =IF($B28="","",UPPER(TRIM(SUBSTITUTE($B28&$C28," ","")))) | G28: =IF($A28="","",$B28) | H28: =IF($A28="","",1)
F29: =IF($B29="","",UPPER(TRIM(SUBSTITUTE($B29&$C29," ","")))) | G29: =IF($A29="","",$B29) | H29: =IF($A29="","",1)
F30: =IF($B30="","",UPPER(TRIM(SUBSTITUTE($B30&$C30," ","")))) | G30: =IF($A30="","",$B30) | H30: =IF($A30="","",1)
F31: =IF($B31="","",UPPER(TRIM(SUBSTITUTE($B31&$C31," ","")))) | G31: =IF($A31="","",$B31) | H31: =IF($A31="","",1)
F32: =IF($B32="","",UPPER(TRIM(SUBSTITUTE($B32&$C32," ","")))) | G32: =IF($A32="","",$B32) | H32: =IF($A32="","",1)
F33: =IF($B33="","",UPPER(TRIM(SUBSTITUTE($B33&$C33," ","")))) | G33: =IF($A33="","",$B33) | H33: =IF($A33="","",1)
... F86: =IF($B86="","",UPPER(TRIM(SUBSTITUTE($B86&$C86," ","")))) | G86: =IF($A86="","",$B86) | H86: =IF($A86="","",1)

Sheet ANAHTAR
A1: ANAHTAR — Site/Apartman Yönetim Sistemi
A3: Normalize malik+dönem anahtarı + duplike (E01/E05)
A4: A Tarafı (Borç) | I4: B Tarafı (Tahsilat)
A5: Ham | B5: Norm | C5: NormUzunluk | D5: IkincilAnahtar | E5: KaynakTaraf | F5: Duplike | G5: SatirNo | I5: HamB | J5: NormB | K5: NormUzunlukB | L5: IkincilB | M5: KaynakB | N5: DuplikeB | O5: SatirNoB
A6: =IF(DONEMLER!A6="","",DONEMLER!F6) | B6: =IF($A6="","",UPPER(TRIM(SUBSTITUTE($A6," ","")))) | C6: =IF($B6="",0,LEN($B6)) | D6: =IF($B6="","",LEFT($B6,say_ikincilUzunluk)) | E6: ="A" | F6: =IF($B6="","",IF(COUNTIF(tblAnahtarA[Norm],$B6)>1,"EVET","HAYIR")) | G6: =IF($A6="","",ROW()-ROW($A$5)) | I6: =IF(TAHSILAT!A6="","",TAHSILAT!F6) | J6: =IF($I6="","",UPPER(TRIM(SUBSTITUTE($I6," ","")))) | K6: =IF($J6="",0,LEN($J6)) | L6: =IF($J6="","",LEFT($J6,say_ikincilUzunluk)) | M6: ="B" | N6: =IF($J6="","",IF(COUNTIF(tblAnahtarB[NormB],$J6)>1,"EVET","HAYIR")) | O6: =IF($I6="","",ROW()-ROW($I$5))
A7: =IF(DONEMLER!A7="","",DONEMLER!F7) | B7: =IF($A7="","",UPPER(TRIM(SUBSTITUTE($A7," ","")))) | C7: =IF($B7="",0,LEN($B7)) | D7: =IF($B7="","",LEFT($B7,say_ikincilUzunluk)) | E7: ="A" | F7: =IF($B7="","",IF(COUNTIF(tblAnahtarA[Norm],$B7)>1,"EVET","HAYIR")) | G7: =IF($A7="","",ROW()-ROW($A$5)) | I7: =IF(TAHSILAT!A7="","",TAHSILAT!F7) | J7: =IF($I7="","",UPPER(TRIM(SUBSTITUTE($I7," ","")))) | K7: =IF($J7="",0,LEN($J7)) | L7: =IF($J7="","",LEFT($J7,say_ikincilUzunluk)) | M7: ="B" | N7: =IF($J7="","",IF(COUNTIF(tblAnahtarB[NormB],$J7)>1,"EVET","HAYIR")) | O7: =IF($I7="","",ROW()-ROW($I$5))
A8: =IF(DONEMLER!A8="","",DONEMLER!F8) | B8: =IF($A8="","",UPPER(TRIM(SUBSTITUTE($A8," ","")))) | C8: =IF($B8="",0,LEN($B8)) | D8: =IF($B8="","",LEFT($B8,say_ikincilUzunluk)) | E8: ="A" | F8: =IF($B8="","",IF(COUNTIF(tblAnahtarA[Norm],$B8)>1,"EVET","HAYIR")) | G8: =IF($A8="","",ROW()-ROW($A$5)) | I8: =IF(TAHSILAT!A8="","",TAHSILAT!F8) | J8: =IF($I8="","",UPPER(TRIM(SUBSTITUTE($I8," ","")))) | K8: =IF($J8="",0,LEN($J8)) | L8: =IF($J8="","",LEFT($J8,say_ikincilUzunluk)) | M8: ="B" | N8: =IF($J8="","",IF(COUNTIF(tblAnahtarB[NormB],$J8)>1,"EVET","HAYIR")) | O8: =IF($I8="","",ROW()-ROW($I$5))
A9: =IF(DONEMLER!A9="","",DONEMLER!F9) | B9: =IF($A9="","",UPPER(TRIM(SUBSTITUTE($A9," ","")))) | C9: =IF($B9="",0,LEN($B9)) | D9: =IF($B9="","",LEFT($B9,say_ikincilUzunluk)) | E9: ="A" | F9: =IF($B9="","",IF(COUNTIF(tblAnahtarA[Norm],$B9)>1,"EVET","HAYIR")) | G9: =IF($A9="","",ROW()-ROW($A$5)) | I9: =IF(TAHSILAT!A9="","",TAHSILAT!F9) | J9: =IF($I9="","",UPPER(TRIM(SUBSTITUTE($I9," ","")))) | K9: =IF($J9="",0,LEN($J9)) | L9: =IF($J9="","",LEFT($J9,say_ikincilUzunluk)) | M9: ="B" | N9: =IF($J9="","",IF(COUNTIF(tblAnahtarB[NormB],$J9)>1,"EVET","HAYIR")) | O9: =IF($I9="","",ROW()-ROW($I$5))
A10: =IF(DONEMLER!A10="","",DONEMLER!F10) | B10: =IF($A10="","",UPPER(TRIM(SUBSTITUTE($A10," ","")))) | C10: =IF($B10="",0,LEN($B10)) | D10: =IF($B10="","",LEFT($B10,say_ikincilUzunluk)) | E10: ="A" | F10: =IF($B10="","",IF(COUNTIF(tblAnahtarA[Norm],$B10)>1,"EVET","HAYIR")) | G10: =IF($A10="","",ROW()-ROW($A$5)) | I10: =IF(TAHSILAT!A10="","",TAHSILAT!F10) | J10: =IF($I10="","",UPPER(TRIM(SUBSTITUTE($I10," ","")))) | K10: =IF($J10="",0,LEN($J10)) | L10: =IF($J10="","",LEFT($J10,say_ikincilUzunluk)) | M10: ="B" | N10: =IF($J10="","",IF(COUNTIF(tblAnahtarB[NormB],$J10)>1,"EVET","HAYIR")) | O10: =IF($I10="","",ROW()-ROW($I$5))
A11: =IF(DONEMLER!A11="","",DONEMLER!F11) | B11: =IF($A11="","",UPPER(TRIM(SUBSTITUTE($A11," ","")))) | C11: =IF($B11="",0,LEN($B11)) | D11: =IF($B11="","",LEFT($B11,say_ikincilUzunluk)) | E11: ="A" | F11: =IF($B11="","",IF(COUNTIF(tblAnahtarA[Norm],$B11)>1,"EVET","HAYIR")) | G11: =IF($A11="","",ROW()-ROW($A$5)) | I11: =IF(TAHSILAT!A11="","",TAHSILAT!F11) | J11: =IF($I11="","",UPPER(TRIM(SUBSTITUTE($I11," ","")))) | K11: =IF($J11="",0,LEN($J11)) | L11: =IF($J11="","",LEFT($J11,say_ikincilUzunluk)) | M11: ="B" | N11: =IF($J11="","",IF(COUNTIF(tblAnahtarB[NormB],$J11)>1,"EVET","HAYIR")) | O11: =IF($I11="","",ROW()-ROW($I$5))
A12: =IF(DONEMLER!A12="","",DONEMLER!F12) | B12: =IF($A12="","",UPPER(TRIM(SUBSTITUTE($A12," ","")))) | C12: =IF($B12="",0,LEN($B12)) | D12: =IF($B12="","",LEFT($B12,say_ikincilUzunluk)) | E12: ="A" | F12: =IF($B12="","",IF(COUNTIF(tblAnahtarA[Norm],$B12)>1,"EVET","HAYIR")) | G12: =IF($A12="","",ROW()-ROW($A$5)) | I12: =IF(TAHSILAT!A12="","",TAHSILAT!F12) | J12: =IF($I12="","",UPPER(TRIM(SUBSTITUTE($I12," ","")))) | K12: =IF($J12="",0,LEN($J12)) | L12: =IF($J12="","",LEFT($J12,say_ikincilUzunluk)) | M12: ="B" | N12: =IF($J12="","",IF(COUNTIF(tblAnahtarB[NormB],$J12)>1,"EVET","HAYIR")) | O12: =IF($I12="","",ROW()-ROW($I$5))
A13: =IF(DONEMLER!A13="","",DONEMLER!F13) | B13: =IF($A13="","",UPPER(TRIM(SUBSTITUTE($A13," ","")))) | C13: =IF($B13="",0,LEN($B13)) | D13: =IF($B13="","",LEFT($B13,say_ikincilUzunluk)) | E13: ="A" | F13: =IF($B13="","",IF(COUNTIF(tblAnahtarA[Norm],$B13)>1,"EVET","HAYIR")) | G13: =IF($A13="","",ROW()-ROW($A$5)) | I13: =IF(TAHSILAT!A13="","",TAHSILAT!F13) | J13: =IF($I13="","",UPPER(TRIM(SUBSTITUTE($I13," ","")))) | K13: =IF($J13="",0,LEN($J13)) | L13: =IF($J13="","",LEFT($J13,say_ikincilUzunluk)) | M13: ="B" | N13: =IF($J13="","",IF(COUNTIF(tblAnahtarB[NormB],$J13)>1,"EVET","HAYIR")) | O13: =IF($I13="","",ROW()-ROW($I$5))
A14: =IF(DONEMLER!A14="","",DONEMLER!F14) | B14: =IF($A14="","",UPPER(TRIM(SUBSTITUTE($A14," ","")))) | C14: =IF($B14="",0,LEN($B14)) | D14: =IF($B14="","",LEFT($B14,say_ikincilUzunluk)) | E14: ="A" | F14: =IF($B14="","",IF(COUNTIF(tblAnahtarA[Norm],$B14)>1,"EVET","HAYIR")) | G14: =IF($A14="","",ROW()-ROW($A$5)) | I14: =IF(TAHSILAT!A14="","",TAHSILAT!F14) | J14: =IF($I14="","",UPPER(TRIM(SUBSTITUTE($I14," ","")))) | K14: =IF($J14="",0,LEN($J14)) | L14: =IF($J14="","",LEFT($J14,say_ikincilUzunluk)) | M14: ="B" | N14: =IF($J14="","",IF(COUNTIF(tblAnahtarB[NormB],$J14)>1,"EVET","HAYIR")) | O14: =IF($I14="","",ROW()-ROW($I$5))
A15: =IF(DONEMLER!A15="","",DONEMLER!F15) | B15: =IF($A15="","",UPPER(TRIM(SUBSTITUTE($A15," ","")))) | C15: =IF($B15="",0,LEN($B15)) | D15: =IF($B15="","",LEFT($B15,say_ikincilUzunluk)) | E15: ="A" | F15: =IF($B15="","",IF(COUNTIF(tblAnahtarA[Norm],$B15)>1,"EVET","HAYIR")) | G15: =IF($A15="","",ROW()-ROW($A$5)) | I15: =IF(TAHSILAT!A15="","",TAHSILAT!F15) | J15: =IF($I15="","",UPPER(TRIM(SUBSTITUTE($I15," ","")))) | K15: =IF($J15="",0,LEN($J15)) | L15: =IF($J15="","",LEFT($J15,say_ikincilUzunluk)) | M15: ="B" | N15: =IF($J15="","",IF(COUNTIF(tblAnahtarB[NormB],$J15)>1,"EVET","HAYIR")) | O15: =IF($I15="","",ROW()-ROW($I$5))
A16: =IF(DONEMLER!A16="","",DONEMLER!F16) | B16: =IF($A16="","",UPPER(TRIM(SUBSTITUTE($A16," ","")))) | C16: =IF($B16="",0,LEN($B16)) | D16: =IF($B16="","",LEFT($B16,say_ikincilUzunluk)) | E16: ="A" | F16: =IF($B16="","",IF(COUNTIF(tblAnahtarA[Norm],$B16)>1,"EVET","HAYIR")) | G16: =IF($A16="","",ROW()-ROW($A$5)) | I16: =IF(TAHSILAT!A16="","",TAHSILAT!F16) | J16: =IF($I16="","",UPPER(TRIM(SUBSTITUTE($I16," ","")))) | K16: =IF($J16="",0,LEN($J16)) | L16: =IF($J16="","",LEFT($J16,say_ikincilUzunluk)) | M16: ="B" | N16: =IF($J16="","",IF(COUNTIF(tblAnahtarB[NormB],$J16)>1,"EVET","HAYIR")) | O16: =IF($I16="","",ROW()-ROW($I$5))
A17: =IF(DONEMLER!A17="","",DONEMLER!F17) | B17: =IF($A17="","",UPPER(TRIM(SUBSTITUTE($A17," ","")))) | C17: =IF($B17="",0,LEN($B17)) | D17: =IF($B17="","",LEFT($B17,say_ikincilUzunluk)) | E17: ="A" | F17: =IF($B17="","",IF(COUNTIF(tblAnahtarA[Norm],$B17)>1,"EVET","HAYIR")) | G17: =IF($A17="","",ROW()-ROW($A$5)) | I17: =IF(TAHSILAT!A17="","",TAHSILAT!F17) | J17: =IF($I17="","",UPPER(TRIM(SUBSTITUTE($I17," ","")))) | K17: =IF($J17="",0,LEN($J17)) | L17: =IF($J17="","",LEFT($J17,say_ikincilUzunluk)) | M17: ="B" | N17: =IF($J17="","",IF(COUNTIF(tblAnahtarB[NormB],$J17)>1,"EVET","HAYIR")) | O17: =IF($I17="","",ROW()-ROW($I$5))
... A26: =IF(DONEMLER!A26="","",DONEMLER!F26) | B26: =IF($A26="","",UPPER(TRIM(SUBSTITUTE($A26," ","")))) | C26: =IF($B26="",0,LEN($B26)) | D26: =IF($B26="","",LEFT($B26,say_ikincilUzunluk)) | E26: ="A" | F26: =IF($B26="","",IF(COUNTIF(tblAnahtarA[Norm],$B26)>1,"EVET","HAYIR")) | G26: =IF($A26="","",ROW()-ROW($A$5)) | I26: =IF(TAHSILAT!A26="","",TAHSILAT!F26) | J26: =IF($I26="","",UPPER(TRIM(SUBSTITUTE($I26," ","")))) | K26: =IF($J26="",0,LEN($J26)) | L26: =IF($J26="","",LEFT($J26,say_ikincilUzunluk)) | M26: ="B" | N26: =IF($J26="","",IF(COUNTIF(tblAnahtarB[NormB],$J26)>1,"EVET","HAYIR")) | O26: =IF($I26="","",ROW()-ROW($I$5))
A27: =IF(DONEMLER!A27="","",DONEMLER!F27) | B27: =IF($A27="","",UPPER(TRIM(SUBSTITUTE($A27," ","")))) | C27: =IF($B27="",0,LEN($B27)) | D27: =IF($B27="","",LEFT($B27,say_ikincilUzunluk)) | E27: ="A" | F27: =IF($B27="","",IF(COUNTIF(tblAnahtarA[Norm],$B27)>1,"EVET","HAYIR")) | G27: =IF($A27="","",ROW()-ROW($A$5)) | J27: =IF($I27="","",UPPER(TRIM(SUBSTITUTE($I27," ","")))) | K27: =IF($J27="",0,LEN($J27)) | L27: =IF($J27="","",LEFT($J27,say_ikincilUzunluk)) | M27: ="B" | N27: =IF($J27="","",IF(COUNTIF(tblAnahtarB[NormB],$J27)>1,"EVET","HAYIR")) | O27: =IF($I27="","",ROW()-ROW($I$5))
A28: =IF(DONEMLER!A28="","",DONEMLER!F28) | B28: =IF($A28="","",UPPER(TRIM(SUBSTITUTE($A28," ","")))) | C28: =IF($B28="",0,LEN($B28)) | D28: =IF($B28="","",LEFT($B28,say_ikincilUzunluk)) | E28: ="A" | F28: =IF($B28="","",IF(COUNTIF(tblAnahtarA[Norm],$B28)>1,"EVET","HAYIR")) | G28: =IF($A28="","",ROW()-ROW($A$5)) | J28: =IF($I28="","",UPPER(TRIM(SUBSTITUTE($I28," ","")))) | K28: =IF($J28="",0,LEN($J28)) | L28: =IF($J28="","",LEFT($J28,say_ikincilUzunluk)) | M28: ="B" | N28: =IF($J28="","",IF(COUNTIF(tblAnahtarB[NormB],$J28)>1,"EVET","HAYIR")) | O28: =IF($I28="","",ROW()-ROW($I$5))
A29: =IF(DONEMLER!A29="","",DONEMLER!F29) | B29: =IF($A29="","",UPPER(TRIM(SUBSTITUTE($A29," ","")))) | C29: =IF($B29="",0,LEN($B29)) | D29: =IF($B29="","",LEFT($B29,say_ikincilUzunluk)) | E29: ="A" | F29: =IF($B29="","",IF(COUNTIF(tblAnahtarA[Norm],$B29)>1,"EVET","HAYIR")) | G29: =IF($A29="","",ROW()-ROW($A$5)) | J29: =IF($I29="","",UPPER(TRIM(SUBSTITUTE($I29," ","")))) | K29: =IF($J29="",0,LEN($J29)) | L29: =IF($J29="","",LEFT($J29,say_ikincilUzunluk)) | M29: ="B" | N29: =IF($J29="","",IF(COUNTIF(tblAnahtarB[NormB],$J29)>1,"EVET","HAYIR")) | O29: =IF($I29="","",ROW()-ROW($I$5))
A30: =IF(DONEMLER!A30="","",DONEMLER!F30) | B30: =IF($A30="","",UPPER(TRIM(SUBSTITUTE($A30," ","")))) | C30: =IF($B30="",0,LEN($B30)) | D30: =IF($B30="","",LEFT($B30,say_ikincilUzunluk)) | E30: ="A" | F30: =IF($B30="","",IF(COUNTIF(tblAnahtarA[Norm],$B30)>1,"EVET","HAYIR")) | G30: =IF($A30="","",ROW()-ROW($A$5)) | J30: =IF($I30="","",UPPER(TRIM(SUBSTITUTE($I30," ","")))) | K30: =IF($J30="",0,LEN($J30)) | L30: =IF($J30="","",LEFT($J30,say_ikincilUzunluk)) | M30: ="B" | N30: =IF($J30="","",IF(COUNTIF(tblAnahtarB[NormB],$J30)>1,"EVET","HAYIR")) | O30: =IF($I30="","",ROW()-ROW($I$5))
B31: =IF($A31="","",UPPER(TRIM(SUBSTITUTE($A31," ","")))) | C31: =IF($B31="",0,LEN($B31)) | D31: =IF($B31="","",LEFT($B31,say_ikincilUzunluk)) | E31: ="A" | F31: =IF($B31="","",IF(COUNTIF(tblAnahtarA[Norm],$B31)>1,"EVET","HAYIR")) | G31: =IF($A31="","",ROW()-ROW($A$5)) | J31: =IF($I31="","",UPPER(TRIM(SUBSTITUTE($I31," ","")))) | K31: =IF($J31="",0,LEN($J31)) | L31: =IF($J31="","",LEFT($J31,say_ikincilUzunluk)) | M31: ="B" | N31: =IF($J31="","",IF(COUNTIF(tblAnahtarB[NormB],$J31)>1,"EVET","HAYIR")) | O31: =IF($I31="","",ROW()-ROW($I$5))
B32: =IF($A32="","",UPPER(TRIM(SUBSTITUTE($A32," ","")))) | C32: =IF($B32="",0,LEN($B32)) | D32: =IF($B32="","",LEFT($B32,say_ikincilUzunluk)) | E32: ="A" | F32: =IF($B32="","",IF(COUNTIF(tblAnahtarA[Norm],$B32)>1,"EVET","HAYIR")) | G32: =IF($A32="","",ROW()-ROW($A$5)) | J32: =IF($I32="","",UPPER(TRIM(SUBSTITUTE($I32," ","")))) | K32: =IF($J32="",0,LEN($J32)) | L32: =IF($J32="","",LEFT($J32,say_ikincilUzunluk)) | M32: ="B" | N32: =IF($J32="","",IF(COUNTIF(tblAnahtarB[NormB],$J32)>1,"EVET","HAYIR")) | O32: =IF($I32="","",ROW()-ROW($I$5))
B33: =IF($A33="","",UPPER(TRIM(SUBSTITUTE($A33," ","")))) | C33: =IF($B33="",0,LEN($B33)) | D33: =IF($B33="","",LEFT($B33,say_ikincilUzunluk)) | E33: ="A" | F33: =IF($B33="","",IF(COUNTIF(tblAnahtarA[Norm],$B33)>1,"EVET","HAYIR")) | G33: =IF($A33="","",ROW()-ROW($A$5)) | J33: =IF($I33="","",UPPER(TRIM(SUBSTITUTE($I33," ","")))) | K33: =IF($J33="",0,LEN($J33)) | L33: =IF($J33="","",LEFT($J33,say_ikincilUzunluk)) | M33: ="B" | N33: =IF($J33="","",IF(COUNTIF(tblAnahtarB[NormB],$J33)>1,"EVET","HAYIR")) | O33: =IF($I33="","",ROW()-ROW($I$5))
B34: =IF($A34="","",UPPER(TRIM(SUBSTITUTE($A34," ","")))) | C34: =IF($B34="",0,LEN($B34)) | D34: =IF($B34="","",LEFT($B34,say_ikincilUzunluk)) | E34: ="A" | F34: =IF($B34="","",IF(COUNTIF(tblAnahtarA[Norm],$B34)>1,"EVET","HAYIR")) | G34: =IF($A34="","",ROW()-ROW($A$5)) | J34: =IF($I34="","",UPPER(TRIM(SUBSTITUTE($I34," ","")))) | K34: =IF($J34="",0,LEN($J34)) | L34: =IF($J34="","",LEFT($J34,say_ikincilUzunluk)) | M34: ="B" | N34: =IF($J34="","",IF(COUNTIF(tblAnahtarB[NormB],$J34)>1,"EVET","HAYIR")) | O34: =IF($I34="","",ROW()-ROW($I$5))
B35: =IF($A35="","",UPPER(TRIM(SUBSTITUTE($A35," ","")))) | C35: =IF($B35="",0,LEN($B35)) | D35: =IF($B35="","",LEFT($B35,say_ikincilUzunluk)) | E35: ="A" | F35: =IF($B35="","",IF(COUNTIF(tblAnahtarA[Norm],$B35)>1,"EVET","HAYIR")) | G35: =IF($A35="","",ROW()-ROW($A$5)) | J35: =IF($I35="","",UPPER(TRIM(SUBSTITUTE($I35," ","")))) | K35: =IF($J35="",0,LEN($J35)) | L35: =IF($J35="","",LEFT($J35,say_ikincilUzunluk)) | M35: ="B" | N35: =IF($J35="","",IF(COUNTIF(tblAnahtarB[NormB],$J35)>1,"EVET","HAYIR")) | O35: =IF($I35="","",ROW()-ROW($I$5))
B36: =IF($A36="","",UPPER(TRIM(SUBSTITUTE($A36," ","")))) | C36: =IF($B36="",0,LEN($B36)) | D36: =IF($B36="","",LEFT($B36,say_ikincilUzunluk)) | E36: ="A" | F36: =IF($B36="","",IF(COUNTIF(tblAnahtarA[Norm],$B36)>1,"EVET","HAYIR")) | G36: =IF($A36="","",ROW()-ROW($A$5)) | J36: =IF($I36="","",UPPER(TRIM(SUBSTITUTE($I36," ","")))) | K36: =IF($J36="",0,LEN($J36)) | L36: =IF($J36="","",LEFT($J36,say_ikincilUzunluk)) | M36: ="B" | N36: =IF($J36="","",IF(COUNTIF(tblAnahtarB[NormB],$J36)>1,"EVET","HAYIR")) | O36: =IF($I36="","",ROW()-ROW($I$5))
B37: =IF($A37="","",UPPER(TRIM(SUBSTITUTE($A37," ","")))) | C37: =IF($B37="",0,LEN($B37)) | D37: =IF($B37="","",LEFT($B37,say_ikincilUzunluk)) | E37: ="A" | F37: =IF($B37="","",IF(COUNTIF(tblAnahtarA[Norm],$B37)>1,"EVET","HAYIR")) | G37: =IF($A37="","",ROW()-ROW($A$5)) | J37: =IF($I37="","",UPPER(TRIM(SUBSTITUTE($I37," ","")))) | K37: =IF($J37="",0,LEN($J37)) | L37: =IF($J37="","",LEFT($J37,say_ikincilUzunluk)) | M37: ="B" | N37: =IF($J37="","",IF(COUNTIF(tblAnahtarB[NormB],$J37)>1,"EVET","HAYIR")) | O37: =IF($I37="","",ROW()-ROW($I$5))
B38: =IF($A38="","",UPPER(TRIM(SUBSTITUTE($A38," ","")))) | C38: =IF($B38="",0,LEN($B38)) | D38: =IF($B38="","",LEFT($B38,say_ikincilUzunluk)) | E38: ="A" | F38: =IF($B38="","",IF(COUNTIF(tblAnahtarA[Norm],$B38)>1,"EVET","HAYIR")) | G38: =IF($A38="","",ROW()-ROW($A$5)) | J38: =IF($I38="","",UPPER(TRIM(SUBSTITUTE($I38," ","")))) | K38: =IF($J38="",0,LEN($J38)) | L38: =IF($J38="","",LEFT($J38,say_ikincilUzunluk)) | M38: ="B" | N38: =IF($J38="","",IF(COUNTIF(tblAnahtarB[NormB],$J38)>1,"EVET","HAYIR")) | O38: =IF($I38="","",ROW()-ROW($I$5))
B39: =IF($A39="","",UPPER(TRIM(SUBSTITUTE($A39," ","")))) | C39: =IF($B39="",0,LEN($B39)) | D39: =IF($B39="","",LEFT($B39,say_ikincilUzunluk)) | E39: ="A" | F39: =IF($B39="","",IF(COUNTIF(tblAnahtarA[Norm],$B39)>1,"EVET","HAYIR")) | G39: =IF($A39="","",ROW()-ROW($A$5)) | J39: =IF($I39="","",UPPER(TRIM(SUBSTITUTE($I39," ","")))) | K39: =IF($J39="",0,LEN($J39)) | L39: =IF($J39="","",LEFT($J39,say_ikincilUzunluk)) | M39: ="B" | N39: =IF($J39="","",IF(COUNTIF(tblAnahtarB[NormB],$J39)>1,"EVET","HAYIR")) | O39: =IF($I39="","",ROW()-ROW($I$5))
B40: =IF($A40="","",UPPER(TRIM(SUBSTITUTE($A40," ","")))) | C40: =IF($B40="",0,LEN($B40)) | D40: =IF($B40="","",LEFT($B40,say_ikincilUzunluk)) | E40: ="A" | F40: =IF($B40="","",IF(COUNTIF(tblAnahtarA[Norm],$B40)>1,"EVET","HAYIR")) | G40: =IF($A40="","",ROW()-ROW($A$5)) | J40: =IF($I40="","",UPPER(TRIM(SUBSTITUTE($I40," ","")))) | K40: =IF($J40="",0,LEN($J40)) | L40: =IF($J40="","",LEFT($J40,say_ikincilUzunluk)) | M40: ="B" | N40: =IF($J40="","",IF(COUNTIF(tblAnahtarB[NormB],$J40)>1,"EVET","HAYIR")) | O40: =IF($I40="","",ROW()-ROW($I$5))
B41: =IF($A41="","",UPPER(TRIM(SUBSTITUTE($A41," ","")))) | C41: =IF($B41="",0,LEN($B41)) | D41: =IF($B41="","",LEFT($B41,say_ikincilUzunluk)) | E41: ="A" | F41: =IF($B41="","",IF(COUNTIF(tblAnahtarA[Norm],$B41)>1,"EVET","HAYIR")) | G41: =IF($A41="","",ROW()-ROW($A$5)) | J41: =IF($I41="","",UPPER(TRIM(SUBSTITUTE($I41," ","")))) | K41: =IF($J41="",0,LEN($J41)) | L41: =IF($J41="","",LEFT($J41,say_ikincilUzunluk)) | M41: ="B" | N41: =IF($J41="","",IF(COUNTIF(tblAnahtarB[NormB],$J41)>1,"EVET","HAYIR")) | O41: =IF($I41="","",ROW()-ROW($I$5))
B42: =IF($A42="","",UPPER(TRIM(SUBSTITUTE($A42," ","")))) | C42: =IF($B42="",0,LEN($B42)) | D42: =IF($B42="","",LEFT($B42,say_ikincilUzunluk)) | E42: ="A" | F42: =IF($B42="","",IF(COUNTIF(tblAnahtarA[Norm],$B42)>1,"EVET","HAYIR")) | G42: =IF($A42="","",ROW()-ROW($A$5)) | J42: =IF($I42="","",UPPER(TRIM(SUBSTITUTE($I42," ","")))) | K42: =IF($J42="",0,LEN($J42)) | L42: =IF($J42="","",LEFT($J42,say_ikincilUzunluk)) | M42: ="B" | N42: =IF($J42="","",IF(COUNTIF(tblAnahtarB[NormB],$J42)>1,"EVET","HAYIR")) | O42: =IF($I42="","",ROW()-ROW($I$5))
... B86: =IF($A86="","",UPPER(TRIM(SUBSTITUTE($A86," ","")))) | C86: =IF($B86="",0,LEN($B86)) | D86: =IF($B86="","",LEFT($B86,say_ikincilUzunluk)) | E86: ="A" | F86: =IF($B86="","",IF(COUNTIF(tblAnahtarA[Norm],$B86)>1,"EVET","HAYIR")) | G86: =IF($A86="","",ROW()-ROW($A$5)) | J86: =IF($I86="","",UPPER(TRIM(SUBSTITUTE($I86," ","")))) | K86: =IF($J86="",0,LEN($J86)) | L86: =IF($J86="","",LEFT($J86,say_ikincilUzunluk)) | M86: ="B" | N86: =IF($J86="","",IF(COUNTIF(tblAnahtarB[NormB],$J86)>1,"EVET","HAYIR")) | O86: =IF($I86="","",ROW()-ROW($I$5))

Sheet ESLESTIRME
A1: ESLESTIRME — Site/Apartman Yönetim Sistemi
A2: Kova bütünlük | C2: =IF(COUNTIF(tblEslesme[Kova],"eslesti")+COUNTIF(tblEslesme[Kova],"tolerans_icinde")+COUNTIF(tblEslesme[Kova],"tutar_farki")+COUNTIF(tblEslesme[Kova],"eslesmedi")=COUNTA(tblEslesme[A_Norm]),"BUTUN","KAYIP")
A3: Dört kova — borç↔tahsilat (E02/E03)
A5: A_Norm | B5: B_Sayim | C5: B_Tutar | D5: A_Tutar | E5: Fark | F5: AbsFark | G5: Kova | H5: IkincilEslesme | I5: DuplikeBayrak | J5: FarkOran | K5: YuvarlakA | L5: YuvarlakB | M5: ToleransTest | N5: EsikUstu | O5: NetKatki | P5: MotorAdim
