Workbook

Sheet 00_BASLANGIC
A1: EXCELARŞİV KARAR SİSTEMİ v15.1 — ÜRETİM REFERANSI
A3: Konu | B3: Bağlayıcı Standart
A4: Amaç | B4: Kanıta dayalı, hatada kapalı çalışan Excel üretim ve denetim sistemi
A5: Öncelik | B5: Kullanıcının açık iş talebi ve gerçek kullanım senaryosu
A6: Ana akış | B6: Uygunluk → Yönetişim → Sözleşmeler → Üretim → Test → Kanıt → Kullanıcı Kabulü → Yayın
A7: Yayın ilkesi | B7: Üst aşamada hata varsa alt aşama GEÇTİ üretilemez
A8: Kullanıcı kabulü | B8: Excel masaüstü görünümü test edilmediyse DIŞ_KABUL_GEREKLİ
A9: Nihai yayın | B9: Yalnız uygulanabilir modüller GEÇTİ veya gerekçeli UYGULANMAZ
A10: Ticari ayrım | B10: Ekonomik olarak savunulabilir fiyat, gerçek pazar kabulü ile aynı değildir
A11: Karmaşıklık | B11: Karar değeri, eklenen karmaşıklığın maliyetinden büyük olmalıdır
A12: Excel sınırı | B12: Veritabanı, kurumsal yetkilendirme, değiştirilemez kayıt sistemi veya gerçek zamanlı olay platformu değildir
A13: Dil standardı | B13: Kullanıcıya görünen tüm sayfa, tablo, başlık, açıklama, uyarı ve karar metinleri saf Türkçe olmalıdır
A14: Muhasebe standardı | B14: Finansal ürünlerde Türkiye Tekdüzen Hesap Planı ve Türk muhasebe kullanım alışkanlıkları esas alınır
... A33: Muhasebe | B33: Türkiye Tekdüzen Hesap Planı ve Türk muhasebe/işletme düşünce yapısı esas alınır.

Sheet PANO
A1: ☰ PANO
B2: CARI HESAP, TAHSILAT VE MÜŞTERI RISK TAKIP SISTEMI | L2: Dönem: 2026 / Tam ▼ | M2: ★ DOĞRULANMIŞ
B3: Hedef Kullanıcı: Finans ve kredi yöneticileri, tahsilat ekipleri, muhasebe uzmanları, satış yöneticileri · 2026 Q3 Denetim Standardı
B5: TOPLAM İŞLEM HACMİ | D5: KONSOLİDE | E5: OPERASYONEL MALİYET | G5: KONTROL | H5: NET OPERASYONEL MARJ | J5: GÜVENLİ | K5: SİSTEM GÜVEN SKORU | M5: DENETLENDİ
B7: =GİRDİLER!E17 | E7: =B7*0.22 | H7: =B7-E7 | K7: =IF(E7>0, ROUND(B7/E7, 2), 0)
B9: ↑ %14.2 konsolide canlı veri bağlantısı | E9: ● 8 Kalem nakit karşılığı: bloke | H9: ██████████░░░░░ %78.0 NET MARJ | K9: ✓ İDEAL karşılama rasyosu
B11: CARI HESAP, TAHSILAT VE MÜŞTERI RISK TAKIP SISTEMI — DÖNEMSEL İCRA VE PROJEKSİYON | F11: +%32 Verim | H11: KONSOLİDE OPERASYON VE KARAR MATRİSİ
B12: Kümülatif Hacim vs. Operasyonel Maliyet ve Net Kâr Eğilimi | H12: Anlık Hesaplama Sonuçları, Dinamik Formül Çıktıları ve Durum Puanlaması
B14: Dönem | C14: Aktif Hacim | D14: Maliyet/Yük | E14: Hedef | H14: PARAMETRE / KALEM | I14: ANA TUTAR | J14: FARK / MARJ | K14: VADE | L14: KONTROL DURUMU
B15: D1 | C15: 65 | D15: 45 | E15: 60 | H15: Dönemlik Kümülatif Bakiye | I15: =B7*0.45 | J15: =B7*0.05 | K15: 12 Ay | L15: ✓ DÜZENLİ
B16: D2 | C16: 78 | D16: 48 | E16: 70 | H16: Kritik Eşik Güvenlik Tamponu | I16: =B7*0.30 | J16: =B7*0.03 | K16: 24 Ay | L16: ★ AVANTAJ
B17: D3 | C17: 85 | D17: 55 | E17: 80 | H17: Operasyonel Net Fark | I17: =B7*0.15 | J17: =B7*0.02 | K17: 8 Ay | L17: ● YAKLAŞAN
B18: D4 | C18: 75 | D18: 42 | E18: 75 | H18: Rezerv ve Likit Dağılım | I18: =B7*0.10 | J18: =B7*0.01 | K18: 16 Ay | L18: ✓ TAM UYUM
B19: D5 | C19: 90 | D19: 40 | E19: 85 | H19: KONSOLİDE SİSTEM TOPLAMI | I19: =SUM(I15:I18) | J19: =SUM(J15:J18) | L19: TAM DOĞRULANDI (0 HATA)
B20: D6 | C20: 96 | D20: 32 | E20: 92
B22: KONSOLİDE PAY VE AĞIRLIK | F22: LİKİDİTE RİSKİ & ERKEN UYARI SİNYALLERİ | K22: KARAR MOTORU
B23: ■ Ana Segment (%42) | F23: Nakit Açığı Riski (30 Gün) | I23: 0.00 TL (Sıfır Risk) | K23: LİKİDİTE OPTİMİZASYON FIRSATI
B24: ■ İkincil Grup (%30) | F24: Tahsilat Gecikme Toleransı | I24: 48 Gün Güvenli Eşik | K24: Atıl kalan nakit rezervinin gecelik repoda
B25: ■ Destek Birimi (%15) | F25: ██████████████████████████████████████ Güvenli Bölge (%100)
B26: ■ Rezervler (%13) | F26: ✓ 90 GÜNLÜK PROJEKSİYONDA NAKİT SIKIŞIKLIĞI TESPİT EDİLMEDİ | K26: FONLAMA SENARYOSUNU İNCELE ›

Sheet GİRDİLER
A1: ☰ PANO
B3: 🔍 CARI HESAP, TAHSILAT VE MÜŞTERI RISK TAKIP SISTEMI — Kayıt veya hesap ara... | G3: TOPLAM: 1.450 KAYIT | I3: HATALI HÜCRE: 0 ADET
B5: TARİH | C5: REFERANS NO | D5: İŞLEM AÇIKLAMASI VE DETAY | E5: BRÜT TUTAR (₺) | F5: KDV ORANI | G5: NET TUTAR (₺) | H5: HESAP / CARİ | I5: DURUM
B6: 12.10.2026 | C6: TR-0428-A | D6: Operasyonel ana kalem tahmini | E6: 845200 | F6: 0.2 | G6: =E6/(1+F6) | H6: Vadesiz Ticari | I6: ONAYLANDI
B7: 14.10.2026 | C7: TR-0429-B | D7: Operasyonel çıkış/maliyet tahmini | E7: 1240000 | F7: 0.2 | G7: =E7/(1+F7) | H7: Tedarikçi Havuzu | I7: BEKLEMEDE
B8: 18.10.2026 | C8: TR-0430-C | D8: Ödeme takvimi tahakkuku | E8: 620500 | F8: 0.1 | G8: =E8/(1+F8) | H8: Kısa Vade Tahakkuk | I8: ONAYLANDI
B9: 21.10.2026 | C9: TR-0431-D | D9: Müşteri işlem tahmini | E9: 415000 | F9: 0.2 | G9: =E9/(1+F9) | H9: Müşteri Alacağı | I9: ONAYLANDI
B10: 25.10.2026 | C10: TR-0432-E | D10: Ana operasyon tahmini | E10: 980400 | F10: 0.2 | G10: =E10/(1+F10) | H10: Vadesiz Ticari | I10: ONAYLANDI
B11: 28.10.2026 | C11: TR-0433-F | D11: Kredi/taksit karşılığı | E11: 1850000 | F11: 0.2 | G11: =E11/(1+F11) | H11: Finansman Havuzu | I11: BLOKE
B12: 02.11.2026 | C12: TR-0434-G | D12: Sabit gider ve yönetim notları | E12: 740000 | F12: 0.2 | G12: =E12/(1+F12) | H12: Genel Yönetim | I12: ONAYLANDI
B13: 05.11.2026 | C13: TR-0435-H | D13: Operasyonel ana kalem tahmini | E13: 520800 | F13: 0.2 | G13: =E13/(1+F13) | H13: Vadesiz Ticari | I13: ONAYLANDI
B14: 09.11.2026 | C14: TR-0436-I | D14: Müşteri işlem tahmini | E14: 1120000 | F14: 0.2 | G14: =E14/(1+F14) | H14: Müşteri Alacağı | I14: ONAYLANDI
B15: 12.11.2026 | C15: TR-0437-J | D15: Operasyonel çıkış tahmini | E15: 890000 | F15: 0.2 | G15: =E15/(1+F15) | H15: Tedarikçi Havuzu | I15: ONAYLANDI
B17: SAYFA TOPLAMI (10 / 1.450 KAYIT) | E17: =SUM(E6:E15)

Sheet YÖNETİM_RAPORU
A1: ☰ PANO
B2: CARI HESAP, TAHSILAT VE MÜŞTERI RISK TAKIP SISTEMI — NİHAİ KARAR VE DEĞERLEME
B3: Yönetim Kurulu ve İcra Komitesi için Otomatik Finansal Stres Testi Raporu · Finans ve kredi yöneticileri, tahsilat ekipleri, muhasebe uzmanları, satış yöneticileri
B4: DÖNEM: 2026 Q3 · DENETİM PROTOKOLÜ: ISO/VUK/IFRS UYUMLU · DURUM: ONAYLANDI
B6: SENARYO A: KÖTÜMSER (STRES TESTİ -%20) | H6: SENARYO B: BAZ MODEL (HEDEFLENEN)
B8: Ciro / Hacim Düşüşü: | E8: -%20.0 (Kriz Eşiği) | H8: Ciro / Hacim Gerçekleşmesi: | K8: %100.0 (Tam Bütçe)
B9: Beklenen Net Kâr / Getiri: | E9: =PANO!B7*0.8*0.22 | H9: Beklenen Net Kâr / Getiri: | K9: =PANO!H7
B10: Minimum Nakit Tamponu: | E10: =PANO!E7*0.75 | H10: Serbest Nakit Akımı: | K10: =PANO!H7*0.75
B11: Likidite Karşılama Oranı: | E11: =ROUND(PANO!B7*0.8/PANO!E7, 2) | H11: Yatırım Geri Dönüşü (ROI): | K11: %38.4 Yıllık
B14: STRES SENARYOSUNDA DAHİ İFLAS RİSKİ YOK | H14: OPTİMUM İCRA VE PLANLAMA REÇETESİ
B17: YÖNETİM KARAR MATRİSİ VE UYGULAMA REÇETESİ
B19: ● Öncelik 1: Acil Likidite ve Borç Servis Planlaması
B20: Sistemde hesaplanan vade günlerine sadık kalınarak nakit blokajı 3 gün önceden hazır edilmelidir.
B21: ● Öncelik 2: Formül Doğrulama ve Çapraz Sağlama
B22: Tüm hücreler kilitli formül korumasında olup girdi sayfalarında sıfır döngüsel başvuru (circular ref) garantilidir.
B23: ● Öncelik 3: Resmi Mevzuat ve Vergi Kalkanı Entegrasyonu
B24: 2026 güncel vergi dilimleri, amortisman ve SGK teşvik parametreleri tam otomatik yansıtılmaktadır.
B25: ● Öncelik 4: Yönetici İmzası ve Rapor Paylaşımı
B26: Tek tuşla PDF ve A4 çıktı formatına tam uyumlu sayfa yapısı kurgulanmıştır.

Sheet 01_YURUTME_CEKIRDEGI
A1: YÜRÜTME ÇEKİRDEĞİ — ZORUNLU ÜRETİM SIRASI
A3: Adım | B3: Modül | C3: Tetikleyici | D3: Zorunlu Kanıt | E3: GEÇTİ Kuralı | F3: Hata Durumu | G3: Sonraki Aşama
A4: 1 | B4: Excel Uygunluğu | C4: Her yeni model | D4: UYGUNLUK_KARARI | E4: Excel'in rolü açık | F4: HATA / BLOKE | G4: Yönetişim
A5: 2 | B5: Yönetişim | C5: Her model | D5: Risk seviyesi + etki girdileri | E5: Seviye hesaplandı | F5: BLOKE | G5: Sözleşmeler
A6: 3 | B6: Türk Muhasebe Eşlemesi | C6: Finansal model | D6: THP hesap eşleme tablosu | E6: Kritik satırlar THP ile uyumlu | F6: HATA | G6: Sözleşmeler
A7: 4 | B7: Veri ve Anlam Sözleşmeleri | C7: Girdi/KPI varsa | D7: Veri + KPI sözleşmeleri | E7: Kapsam %100 | F7: HATA | G7: Üretim
A8: 5 | B8: Üretim | C8: Sözleşmeler GEÇTİ | D8: Çalışan Excel | E8: Tek gerçek kaynak korunmuş | F8: HATA | G8: Testler
A9: 6 | B9: Görsel/Kullanım Katmanı | C9: Motor hazır | D9: Başlıklar + renk + grafik + yönlendirme | E9: Tüm kullanıcı sayfaları standarda uygun | F9: HATA | G9: Testler
A10: 7 | B10: Testler | C10: Üretim tamam | D10: Formül/OOXML/kimlik/oracle/golden/metamorfik | E10: Uygulanabilir hard gate'ler GEÇTİ | F10: HATA | G10: Kanıt
A11: 8 | B11: Hata-Kontrol Tutarlılığı | C11: Test sonucu var | D11: Hata taraması + kontrol sonuçları | E11: Formül hatası varken GEÇTİ yok | F11: HATA | G11: Kanıt
A12: 9 | B12: Kanıt | C12: Test sonucu var | D12: Makine okunur artefakt + özet | E12: Kanıt fiziksel ve tutarlı | F12: HATA | G12: Kullanıcı Kabulü
A13: 10 | B13: Kullanıcı Kabulü | C13: Kritik görevler | D13: Gerçek ekran davranışı | E13: Kritik görevler %100 | F13: DIŞ_KABUL_GEREKLİ | G13: Ticari
A14: 11 | B14: Ticari Değer | C14: Ürün satılacaksa | D14: ROI + demo + kanıt paketi | E14: Ekonomik değer kanıtlı | F14: UYARI / HATA | G14: Pazar Doğrulama
A15: 12 | B15: Pazar Doğrulama | C15: Pazar iddiası varsa | D15: Ücretli satış/pilot/fiyat kabul kanıtı | E15: Gerçek fiyat kabul kanıtı | F15: UYGULANMAZ / HATA | G15: Yayın

Sheet 02_KONTROL_LISTESI
A1: NİHAİ KONTROL LİSTESİ — KANITSIZ GEÇİŞ YOK
A3: Kontrol No | B3: Kontrol | C3: Beklenen | D3: Zorunlu Kapı? | E3: Sonuç
A4: K01 | B4: Kullanıcının açık talebi öncelikli mi? | C4: Evet | D4: EVET
A5: K02 | B5: Mevcut yapı, formüller ve tek gerçek kaynak korunuyor mu? | C5: Evet, değişiklik gerekçeli | D5: EVET
A6: K03 | B6: Üst aşama HATA ise alt aşama GEÇTİ engelleniyor mu? | C6: Evet | D6: EVET
A7: K04 | B7: Kanıt fiziksel çıktı ve içerik doğrulaması içeriyor mu? | C7: Evet | D7: EVET
A8: K05 | B8: Excel GUI erişimi olmadan kullanıcı görünümü GEÇTİ yazılıyor mu? | C8: Hayır | D8: EVET
A9: K06 | B9: NİHAİ yalnız GEÇTİ / gerekçeli UYGULANMAZ ile mi? | C9: Evet | D9: EVET
A10: K07 | B10: Ekonomik fiyat savunusu pazar doğrulamasından ayrılmış mı? | C10: Evet | D10: EVET
A11: K08 | B11: Prestij için gereksiz modül var mı? | C11: Hayır | D11: HAYIR
A12: K09 | B12: Excel sınırları açık mı? | C12: Evet | D12: EVET
A13: K10 | B13: Teknik kaynak korunuyor mu? | C13: Evet | D13: EVET
A14: K11 | B14: Kullanıcıya görünen tüm metinler Türkçe mi? | C14: Evet | D14: EVET
A15: K12 | B15: Her kullanıcı sayfasında üst başlık var mı? | C15: Evet | D15: EVET
... A34: K31 | B34: Premium vitrin, altyapı kadar güçlü ve satış fiyatını destekleyecek seviyede mi? | C34: Evet | D34: EVET

Sheet 03_GORSEL_TASARIM
A1: GÖRSEL TASARIM VE PREMIUM EXCEL STANDARDI
A3: Alan | B3: Zorunlu Kural | C3: Uygulama | D3: Yasak | E3: Kontrol | F3: Durum
A4: Sayfa başlığı | B4: Her kullanıcı sayfasının en üstünde tek ve açık sayfa başlığı | C4: A1'den başlayan koyu lacivert başlık bandı | D4: Başlıksız sayfa | E4: Başlık kapsama = %100 | F4: ZORUNLU
A5: Sekme renkleri | B5: Sayfalar işlevine göre renk kodlanır | C5: Girdi=mavi, hesap=gri, rapor=lacivert, kontrol=kırmızı, kılavuz=altın | D5: Rastgele renk | E5: Renk semantiği tutarlı | F5: ZORUNLU
A6: Kolon düzeni | B6: Veri blokları bitişik kolonlarda ilerler | C6: Gereksiz boş kolon bırakma; yalnız gerçek bölüm ayrımı varsa kontrollü boşluk | D6: A:C veri, D boş, E:F veri gibi parçalı yapı | E6: Boş kolon taraması | F6: ZORUNLU
A7: Girdi hücreleri | B7: Kullanıcının değiştireceği alan açıkça görünür | C7: Açık sarı dolgu + mavi yazı | D7: Formülle aynı görünüm | E7: Girdi/formül ayrımı | F7: ZORUNLU
A8: Formüller | B8: Hesap hücreleri kullanıcı girdisinden ayrılır | C8: Siyah yazı; sayfalar arası bağlantı yeşil yazı | D8: Hard-code gizleme | E8: Formül sınıfı kontrolü | F8: ZORUNLU
A9: Grafik sayısı | B9: Yönetici ekranında en fazla 3 ana karar grafiği | C9: Trend, karşılaştırma, köprü/dağılım; iş kararına bağlı | D9: Grafik kalabalığı | E9: Grafik başına karar sorusu | F9: ZORUNLU
A10: Grafik stili | B10: Kurumsal ve yüksek okunabilirlik | C10: Beyaz zemin, ince gridline, tek vurgu rengi, açık birim/başlık | D10: 3B, gölge, neon, gökkuşağı renkleri | E10: Görsel inceleme | F10: ZORUNLU
A11: Grafik başlığı | B11: Grafik 'neyi' değil 'ne anlama geldiğini' söyler | C11: Örn: 'Nakit 2028'de kritik eşiğin altına iniyor' | D11: 'Nakit Grafiği' gibi anlamsız başlık | E11: Başlık karar testi | F11: ZORUNLU
A12: Birimler | B12: Tüm finansal görsellerde birim açık | C12: TL, bin TL, milyon TL, %, gün, x | D12: Birim belirsizliği | E12: Birim kapsama %100 | F12: ZORUNLU
A13: Sıfır/negatif | B13: Finansal format standardı | C13: Sıfır='-', negatif kırmızı parantez | D13: -500 veya 0,00 kalabalığı | E13: Format kontrolü | F13: ZORUNLU
A14: Yazı tipi | B14: Tek aile | C14: Aptos veya Segoe UI | D14: Karışık font | E14: Tek font kontrolü | F14: ZORUNLU
... A22: Premium vitrin | B22: Görsel kalite ürün değerinin zorunlu parçasıdır | C22: Kaliteli grafik, gerçek KPI kartı, finansal hiyerarşi, tab rengi, fonksiyonel navigasyon | D22: Sadece doğru hesap yapıp çıplak/varsayılan Excel görünümü bırakmak | E22: Görsel release incelemesi | F22: ZORUNLU

Sheet 04_MUHASEBE_THP
A1: TÜRKİYE MUHASEBE VE TEKDÜZEN HESAP PLANI STANDARDI
A3: Konu | B3: Zorunlu Standart | C3: Örnek Türkçe Ad | D3: THP / Mantık | E3: Hata Riski | F3: Kontrol
A4: Dil | B4: Kullanıcıya görünen finansal terimler Türkçe | C4: Hasılat, Satışların Maliyeti, Brüt Kâr, Faaliyet Giderleri | D4: Türk işletme kullanımına uygun | E4: İngilizce jargon | F4: Terminoloji taraması
A5: Gelir Tablosu | B5: Türk sunum sırası kullanılır | C5: Net Satışlar → Satışların Maliyeti → Brüt Kâr → Faaliyet Giderleri → Faaliyet Kârı | D5: 600/610/611; 620-623; 63x | E5: Yanlış sınıflama | F5: Hesap eşleme
A6: Bilanço | B6: Dönen/Duran Varlık ve Kısa/Uzun Vadeli Yükümlülük ayrımı | C6: Hazır Değerler, Ticari Alacaklar, Stoklar, Mali Borçlar | D6: 1xx / 2xx / 3xx / 4xx / 5xx | E6: Vade sınıfı hatası | F6: Bilanço eşitliği
A7: Nakit Akışı | B7: İşletme/Yatırım/Finansman nakit akışları ayrılır | C7: Faaliyetlerden Nakit, Yatırım Harcamaları, Finansman Nakit Akışı | D7: Dolaylı/doğrudan yöntem açık seçilir | E7: Kâr = nakit sanılması | F7: Nakit devri
A8: Ticari Alacaklar | B8: Cari ve vade mantığı korunur | C8: 120 Alıcılar | D8: 120 | E8: Tahakkuk/nakit karışması | F8: Alacak devir kontrolü
A9: Ticari Borçlar | B9: Tedarikçi borcu ayrı izlenir | C9: 320 Satıcılar | D9: 320 | E9: Gider/ödeme karışması | F9: Borç devir kontrolü
A10: Kasa/Banka | B10: Hazır değerler ayrı izlenir | C10: 100 Kasa, 102 Bankalar | D10: 100 / 102 | E10: Virmanla toplam nakdin değişmesi | F10: Virman değişmezi
A11: Stok | B11: Dikeye uygun stok türü | C11: 150 İlk Madde ve Malzeme, 153 Ticari Mallar | D11: 15x | E11: Maliyet ve stok hareketinin kopması | F11: Stok devri
A12: Maddi Duran Varlık | B12: Yatırım harcaması ve amortisman bağlantılı | C12: 253 Tesis Makine Cihazlar, 255 Demirbaşlar, 257 Birikmiş Amortismanlar | D12: 25x | E12: Yatırım/gider karışması | F12: Net defter değeri devri
A13: Mali Borçlar | B13: Kısa/uzun vadeli borç ayrımı | C13: 300 Banka Kredileri / 400 Banka Kredileri | D13: 300 / 400 | E13: Vade sınıfı yanlış | F13: Borç devri
A14: Özkaynak | B14: Sermaye ve geçmiş yıl kârları ayrı | C14: 500 Sermaye, 570 Geçmiş Yıllar Kârları, 590 Dönem Net Kârı | D14: 5xx | E14: Net kâr bağının kopması | F14: Özkaynak devri
... A18: İstisna | B18: TFRS özel ürün varsa fark açık yazılır | C18: Tekdüzen raporlama ≠ TFRS finansal tablo sunumu | D18: Amaç belirtilir | E18: Standartları karıştırma | F18: Model amacı kontrolü

Sheet 05_KARAR_SATIS
A1: KARAR, GÜVEN VE SATIŞA HAZIRLIK STANDARDI
A3: Alan | B3: Müşteri Sorusu | C3: Zorunlu Ürün Davranışı | D3: Kanıt | E3: Başarısızlık Durumu | F3: Kapı
A4: 5 saniye | B4: Bu ürün neyi çözüyor? | C4: İlk ekranda hedef kullanıcı + pahalı problem + sonuç görünür | D4: Başlık + alt mesaj + gerçek ekran | E4: Ürün yalnız teknik isim | F4: HATA
A5: Acı | B5: Sorun bana neye mal oluyor? | C5: Mümkünse müşterinin kendi verisiyle parasal/zaman etkisi hesaplanır | D5: ROI/acı hesaplama yöntemi | E5: Uydurma tasarruf | F5: HATA
A6: Karar | B6: Bu bilgiyle ne yapacağım? | C6: Her kritik KPI aksiyona bağlanır | D6: KARAR_KUYRUGU | E6: Sadece rapor | F6: HATA
A7: Güven | B7: Bu sayıya neden inanayım? | C7: Kaynak, formül mantığı, kontrol ve son doğrulama görünür | D7: Kontroller + kaynak izi + sürüm | E7: Prestij kelimesi | F7: HATA
A8: Referans | B8: Müşteri yorumu yoksa ne göstereceğim? | C8: Önce/Sonra + Karar Vakası + Hata Önleme Vakası üretilir | D8: Demo/örnek çıktı | E8: Kanıtsız iddia | F8: HATA
A9: Senaryo | B9: Ne olursa işler bozulur? | C9: Baz/Aşağı/Yukarı veya uygun stres senaryosu | D9: Senaryo karşılaştırma | E9: Dekoratif senaryo | F9: HATA
A10: Ters stres | B10: Hangi eşikte karar kırılır? | C10: En az bir kritik sürücü için kırılma eşiği | D10: Kırılma eşiği tablosu | E10: Sadece +/- %10 | F10: UYARI/HATA
A11: Hata tutarlılığı | B11: Formül hata verirse ne olur? | C11: Kontrol GEÇTİ veremez; BLOKE/HATA üretir | D11: Hata taraması | E11: Hata + GEÇTİ birlikte | F11: HATA
A12: Karar motoru | B12: Ne oldu, neden oldu? | C12: Sorun + neden + parasal etki + aksiyon + son tarih | D12: Karar tablosu | E12: Boş sayfa / isim düzeyi modül | F12: HATA
A13: Yönetici özeti | B13: 5 saniyede ne görmeliyim? | C13: Bugün / ne değişti / ne bozulacak / neden / ne yapmalıyım / güven | D13: Yönetici özeti ekranı | E13: KPI kutusu yığını | F13: HATA
A14: Teklif | B14: Neden satın almalıyım? | C14: Dosya özellikleri yerine sonuç ve kaçınılan maliyet sunulur | D14: Ürün sayfası kanıt eşlemesi | E14: Özellik listesiyle satış | F14: HATA
... A19: Pazar kanıtı | B19: Piyasa gerçekten ödüyor mu? | C19: Satış/pilot/LOI/fiyat kabulü olmadan pazar doğrulandı yazılmaz | D19: Gerçek işlem kanıtı | E19: Tahmini talep = satış kabulü | F19: HATA

Sheet KAPAK
A1: KAPAK — CARİ HESAP, TAHSİLAT VE MÜŞTERİ RİSK TAKİP SİSTEMİ
A5: CARİ RİSK UZMAN
A6: Cari Hesap, Tahsilat ve Müşteri Risk Takip Sistemi
A8: Vadeli satış kararlarını, tahsilat önceliklerini ve müşteri limitlerini
A9: makine üretimi risk skoru ve karar kapısı ile yönetin.
A11: KİMLER İÇİN?
A12: • Finans ve kredi yöneticileri
A13: • Tahsilat ekipleri ve muhasebe uzmanları
A14: • Vadeli satış riskini ölçen satış yöneticileri
A16: NE KAZANDIRIR?
A17: • Açık alacak ve vadesi geçmiş bakiyeyi anında görürsünüz
A18: • Risk skoru ile kiminle vadeli çalışacağınızı netleştirirsiniz
... A28: Başlamak için HIZLI_BAŞLANGIÇ sayfasına gidin.

Sheet HIZLI_BASLANGIC
A1: HIZLI BASLANGIC — CARİ HESAP, TAHSİLAT VE MÜŞTERİ RİSK TAKİP SİSTEMİ
A3: 3 ADIMDA KULLANIM
A5: ADIM 1 — MÜŞTERİ VE FATURA
A6: MUSTERI_KARTLARI'na müşterileri, FATURALAR'a faturaları girin; TAHSILATLAR'a ödemeleri işleyin.
A7: ADIM 2 — TEMİNAT VE İLETİŞİM
A8: TEMINATLAR'ı ve ILETISIM_TAKIP'i tamamlayın; yaşlandırma otomatik hesaplanır.
A9: ADIM 3 — KARAR VE RAPOR
A10: MUSTERI_RISK_SKORU ve KARAR_MOTORU'ndaki kararları inceleyin; RAPOR'u yöneticiye sunun.
A14: ÖNEMLİ NOTLAR
A15: • Sarı hücreler manuel giriş alanlarıdır; diğer hücreler formül üretir ve 1234 şifresiyle korunur.
A16: • Rapor tarihi AYARLAR sayfasındandır; gecikme günleri bu tarihe göre hesaplanır.
A17: • Örnek veri ile deneme için ORNEK_VERI sayfasına bakın; verileri kendi verinizle değiştirin.

Sheet MUSTERI_KARTLARI
A1: MUSTERI KARTLARI — CARİ HESAP, TAHSİLAT VE MÜŞTERİ RİSK TAKİP SİSTEMİ
A3: MÜŞTERİ PORTFÖYÜ VE LİMİT MERKEZİ
A5: Müşteri Kodu | B5: Unvan | C5: Vergi Numarası | D5: Sektör | E5: Bölge | F5: Satış Sorumlusu | G5: İlk Çalışma Tarihi | H5: Varsayılan Vade | I5: Onaylı Risk Limiti | J5: Geçici Ek Limit | K5: Limit Bitiş Tarihi | L5: Teminat Türü | M5: Teminat Değeri | N5: Teminat Geçerlilik Tarihi | O5: Grup Şirketi | P5: Kritik Müşteri mi? | Q5: Durum | R5: Kontrol
A6: M001 | B6: Atlas Yapı A.Ş. | C6: 1111111111 | D6: İnşaat | E6: Marmara | F6: Ayşe Yılmaz | G6: 44576 | H6: 60 | I6: 1250000 | J6: 250000 | K6: 46387 | L6: Banka Teminat Mektubu | M6: 900000 | N6: 46387 | O6: Anadolu Grubu | P6: Hayır | Q6: Aktif | R6: =IF($A6="","",IF(COUNTA($A6:$Q6)>=ZorunluAlanSayisi,"OK","EKSİK"))
A7: M002 | B7: Bora Perakende Ltd. | C7: 2222222222 | D7: Perakende | E7: Ege | F7: Mehmet Kaya | G7: 44995 | H7: 45 | I7: 800000 | J7: 0 | K7: 46387 | L7: İpotek | M7: 550000 | N7: 46203 | O7: Bağımsız | P7: Hayır | Q7: Aktif | R7: =IF($A6="","",IF(COUNTA($A6:$Q6)>=ZorunluAlanSayisi,"OK","EKSİK"))
A8: M003 | B8: Cemre Gıda A.Ş. | C8: 3333333333 | D8: Gıda | E8: İç Anadolu | F8: Selin Demir | G8: 44367 | H8: 30 | I8: 650000 | J8: 100000 | K8: 46387 | L8: Çek ve Senet | M8: 300000 | N8: 46235 | O8: Bağımsız | P8: Hayır | Q8: İzlemede | R8: =IF($A6="","",IF(COUNTA($A6:$Q6)>=ZorunluAlanSayisi,"OK","EKSİK"))
A9: M004 | B9: Delta Tekstil Ltd. | C9: 4444444444 | D9: Tekstil | E9: Ege | F9: Can Arslan | G9: 43866 | H9: 90 | I9: 2000000 | J9: 0 | K9: 46387 | L9: Teminatsız | M9: 0 | N9: 46387 | O9: Bağımsız | P9: Evet | Q9: Askıda | R9: =IF($A6="","",IF(COUNTA($A6:$Q6)>=ZorunluAlanSayisi,"OK","EKSİK"))
R10: =IF($A6="","",IF(COUNTA($A6:$Q6)>=ZorunluAlanSayisi,"OK","EKSİK"))
R11: =IF($A6="","",IF(COUNTA($A6:$Q6)>=ZorunluAlanSayisi,"OK","EKSİK"))
R12: =IF($A6="","",IF(COUNTA($A6:$Q6)>=ZorunluAlanSayisi,"OK","EKSİK"))
R13: =IF($A6="","",IF(COUNTA($A6:$Q6)>=ZorunluAlanSayisi,"OK","EKSİK"))
R14: =IF($A6="","",IF(COUNTA($A6:$Q6)>=ZorunluAlanSayisi,"OK","EKSİK"))
R15: =IF($A6="","",IF(COUNTA($A6:$Q6)>=ZorunluAlanSayisi,"OK","EKSİK"))
R16: =IF($A6="","",IF(COUNTA($A6:$Q6)>=ZorunluAlanSayisi,"OK","EKSİK"))
R17: =IF($A6="","",IF(COUNTA($A6:$Q6)>=ZorunluAlanSayisi,"OK","EKSİK"))
R18: =IF($A6="","",IF(COUNTA($A6:$Q6)>=ZorunluAlanSayisi,"OK","EKSİK"))
R19: =IF($A6="","",IF(COUNTA($A6:$Q6)>=ZorunluAlanSayisi,"OK","EKSİK"))
R20: =IF($A6="","",IF(COUNTA($A6:$Q6)>=ZorunluAlanSayisi,"OK","EKSİK"))
R21: =IF($A6="","",IF(COUNTA($A6:$Q6)>=ZorunluAlanSayisi,"OK","EKSİK"))
R22: =IF($A6="","",IF(COUNTA($A6:$Q6)>=ZorunluAlanSayisi,"OK","EKSİK"))
R23: =IF($A6="","",IF(COUNTA($A6:$Q6)>=ZorunluAlanSayisi,"OK","EKSİK"))
R24: =IF($A6="","",IF(COUNTA($A6:$Q6)>=ZorunluAlanSayisi,"OK","EKSİK"))
R25: =IF($A6="","",IF(COUNTA($A6:$Q6)>=ZorunluAlanSayisi,"OK","EKSİK"))
R26: =IF($A6="","",IF(COUNTA($A6:$Q6)>=ZorunluAlanSayisi,"OK","EKSİK"))
R27: =IF($A6="","",IF(COUNTA($A6:$Q6)>=ZorunluAlanSayisi,"OK","EKSİK"))
R28: =IF($A6="","",IF(COUNTA($A6:$Q6)>=ZorunluAlanSayisi,"OK","EKSİK"))
R29: =IF($A6="","",IF(COUNTA($A6:$Q6)>=ZorunluAlanSayisi,"OK","EKSİK"))
R30: =IF($A6="","",IF(COUNTA($A6:$Q6)>=ZorunluAlanSayisi,"OK","EKSİK"))
R31: =IF($A6="","",IF(COUNTA($A6:$Q6)>=ZorunluAlanSayisi,"OK","EKSİK"))
R32: =IF($A6="","",IF(COUNTA($A6:$Q6)>=ZorunluAlanSayisi,"OK","EKSİK"))
R33: =IF($A6="","",IF(COUNTA($A6:$Q6)>=ZorunluAlanSayisi,"OK","EKSİK"))
R34: =IF($A6="","",IF(COUNTA($A6:$Q6)>=ZorunluAlanSayisi,"OK","EKSİK"))
R35: =IF($A6="","",IF(COUNTA($A6:$Q6)>=ZorunluAlanSayisi,"OK","EKSİK"))
R36: =IF($A6="","",IF(COUNTA($A6:$Q6)>=ZorunluAlanSayisi,"OK","EKSİK"))
R37: =IF($A6="","",IF(COUNTA($A6:$Q6)>=ZorunluAlanSayisi,"OK","EKSİK"))
R38: =IF($A6="","",IF(COUNTA($A6:$Q6)>=ZorunluAlanSayisi,"OK","EKSİK"))
R39: =IF($A6="","",IF(COUNTA($A6:$Q6)>=ZorunluAlanSayisi,"OK","EKSİK"))
R40: =IF($A6="","",IF(COUNTA($A6:$Q6)>=ZorunluAlanSayisi,"OK","EKSİK"))
R41: =IF($A6="","",IF(COUNTA($A6:$Q6)>=ZorunluAlanSayisi,"OK","EKSİK"))
R42: =IF($A6="","",IF(COUNTA($A6:$Q6)>=ZorunluAlanSayisi,"OK","EKSİK"))
...

Sheet FATURALAR
A1: FATURALAR — CARİ HESAP, TAHSİLAT VE MÜŞTERİ RİSK TAKİP SİSTEMİ
A3: FATURA VE VADE YÖNETİM MERKEZİ
A5: Fatura Kayıt Numarası | B5: Fatura Numarası | C5: Müşteri Kodu | D5: Fatura Tarihi | E5: Vade Tarihi | F5: Fatura Tutarı | G5: Para Birimi | H5: Kur | I5: TL Tutarı | J5: İade/İskonto | K5: Net Fatura | L5: İtirazlı Tutar | M5: Teminat Kapsamı | N5: Proje/Sipariş | O5: Satış Sorumlusu | P5: Belge Durumu | Q5: Mükerrer Kontrol
A6: F001 | B6: 2026-001 | C6: M001 | D6: 46091 | E6: 46151 | F6: 780000 | G6: TRY | H6: 1 | I6: =IF($B6="","",$F6*$H6) | J6: 30000 | K6: =IF($B6="","",$I6-$J6) | L6: 0 | M6: 0 | N6: Proje A-2026 | O6: Ayşe Yılmaz | P6: Onaylı | Q6: =IF($B6="","",IF(COUNTIFS(tblFaturalar[Fatura Numarası],$B6,tblFaturalar[Müşteri Kodu],$C6)>1,"MÜKERRER","UYGUN"))
A7: F002 | B7: 2026-002 | C7: M001 | D7: 46188 | E7: 46248 | F7: 520000 | G7: TRY | H7: 1 | I7: =IF($B7="","",$F7*$H7) | J7: 0 | K7: =IF($B7="","",$I7-$J7) | L7: 0 | M7: 0 | N7: Proje B-2026 | O7: Ayşe Yılmaz | P7: Onaylı | Q7: =IF($B7="","",IF(COUNTIFS(tblFaturalar[Fatura Numarası],$B7,tblFaturalar[Müşteri Kodu],$C7)>1,"MÜKERRER","UYGUN"))
A8: F003 | B8: 2026-003 | C8: M002 | D8: 46204 | E8: 46249 | F8: 420000 | G8: TRY | H8: 1 | I8: =IF($B8="","",$F8*$H8) | J8: 20000 | K8: =IF($B8="","",$I8-$J8) | L8: 0 | M8: 0 | N8: Perakende dönem | O8: Mehmet Kaya | P8: Onaylı | Q8: =IF($B8="","",IF(COUNTIFS(tblFaturalar[Fatura Numarası],$B8,tblFaturalar[Müşteri Kodu],$C8)>1,"MÜKERRER","UYGUN"))
A9: F004 | B9: 2026-004 | C9: M003 | D9: 46162 | E9: 46192 | F9: 680000 | G9: TRY | H9: 1 | I9: =IF($B9="","",$F9*$H9) | J9: 0 | K9: =IF($B9="","",$I9-$J9) | L9: 150000 | M9: 0 | N9: Gıda dönem | O9: Selin Demir | P9: İtirazlı | Q9: =IF($B9="","",IF(COUNTIFS(tblFaturalar[Fatura Numarası],$B9,tblFaturalar[Müşteri Kodu],$C9)>1,"MÜKERRER","UYGUN"))
A10: F005 | B10: 2026-005 | C10: M004 | D10: 46063 | E10: 46153 | F10: 1500000 | G10: TRY | H10: 1 | I10: =IF($B10="","",$F10*$H10) | J10: 0 | K10: =IF($B10="","",$I10-$J10) | L10: 0 | M10: 0 | N10: Tekstil ihracat | O10: Can Arslan | P10: Onaylı | Q10: =IF($B10="","",IF(COUNTIFS(tblFaturalar[Fatura Numarası],$B10,tblFaturalar[Müşteri Kodu],$C10)>1,"MÜKERRER","UYGUN"))
A11: F006 | B11: 2026-006 | C11: M003 | D11: 46213 | E11: 46243 | F11: 260000 | G11: TRY | H11: 1 | I11: =IF($B11="","",$F11*$H11) | J11: 0 | K11: =IF($B11="","",$I11-$J11) | L11: 0 | M11: 0 | N11: Gıda dönem 2 | O11: Selin Demir | P11: Onaylı | Q11: =IF($B11="","",IF(COUNTIFS(tblFaturalar[Fatura Numarası],$B11,tblFaturalar[Müşteri Kodu],$C11)>1,"MÜKERRER","UYGUN"))
I12: =IF($B12="","",$F12*$H12) | K12: =IF($B12="","",$I12-$J12) | Q12: =IF($B12="","",IF(COUNTIFS(tblFaturalar[Fatura Numarası],$B12,tblFaturalar[Müşteri Kodu],$C12)>1,"MÜKERRER","UYGUN"))
I13: =IF($B13="","",$F13*$H13) | K13: =IF($B13="","",$I13-$J13) | Q13: =IF($B13="","",IF(COUNTIFS(tblFaturalar[Fatura Numarası],$B13,tblFaturalar[Müşteri Kodu],$C13)>1,"MÜKERRER","UYGUN"))
I14: =IF($B14="","",$F14*$H14) | K14: =IF($B14="","",$I14-$J14) | Q14: =IF($B14="","",IF(COUNTIFS(tblFaturalar[Fatura Numarası],$B14,tblFaturalar[Müşteri Kodu],$C14)>1,"MÜKERRER","UYGUN"))
I15: =IF($B15="","",$F15*$H15) | K15: =IF($B15="","",$I15-$J15) | Q15: =IF($B15="","",IF(COUNTIFS(tblFaturalar[Fatura Numarası],$B15,tblFaturalar[Müşteri Kodu],$C15)>1,"MÜKERRER","UYGUN"))
I16: =IF($B16="","",$F16*$H16) | K16: =IF($B16="","",$I16-$J16) | Q16: =IF($B16="","",IF(COUNTIFS(tblFaturalar[Fatura Numarası],$B16,tblFaturalar[Müşteri Kodu],$C16)>1,"MÜKERRER","UYGUN"))
I17: =IF($B17="","",$F17*$H17) | K17: =IF($B17="","",$I17-$J17) | Q17: =IF($B17="","",IF(COUNTIFS(tblFaturalar[Fatura Numarası],$B17,tblFaturalar[Müşteri Kodu],$C17)>1,"MÜKERRER","UYGUN"))
I18: =IF($B18="","",$F18*$H18) | K18: =IF($B18="","",$I18-$J18) | Q18: =IF($B18="","",IF(COUNTIFS(tblFaturalar[Fatura Numarası],$B18,tblFaturalar[Müşteri Kodu],$C18)>1,"MÜKERRER","UYGUN"))
I19: =IF($B19="","",$F19*$H19) | K19: =IF($B19="","",$I19-$J19) | Q19: =IF($B19="","",IF(COUNTIFS(tblFaturalar[Fatura Numarası],$B19,tblFaturalar[Müşteri Kodu],$C19)>1,"MÜKERRER","UYGUN"))
I20: =IF($B20="","",$F20*$H20) | K20: =IF($B20="","",$I20-$J20) | Q20: =IF($B20="","",IF(COUNTIFS(tblFaturalar[Fatura Numarası],$B20,tblFaturalar[Müşteri Kodu],$C20)>1,"MÜKERRER","UYGUN"))
I21: =IF($B21="","",$F21*$H21) | K21: =IF($B21="","",$I21-$J21) | Q21: =IF($B21="","",IF(COUNTIFS(tblFaturalar[Fatura Numarası],$B21,tblFaturalar[Müşteri Kodu],$C21)>1,"MÜKERRER","UYGUN"))
I22: =IF($B22="","",$F22*$H22) | K22: =IF($B22="","",$I22-$J22) | Q22: =IF($B22="","",IF(COUNTIFS(tblFaturalar[Fatura Numarası],$B22,tblFaturalar[Müşteri Kodu],$C22)>1,"MÜKERRER","UYGUN"))
I23: =IF($B23="","",$F23*$H23) | K23: =IF($B23="","",$I23-$J23) | Q23: =IF($B23="","",IF(COUNTIFS(tblFaturalar[Fatura Numarası],$B23,tblFaturalar[Müşteri Kodu],$C23)>1,"MÜKERRER","UYGUN"))
... I45: =IF($B45="","",$F45*$H45) | K45: =IF($B45="","",$I45-$J45) | Q45: =IF($B45="","",IF(COUNTIFS(tblFaturalar[Fatura Numarası],$B45,tblFaturalar[Müşteri Kodu],$C45)>1,"MÜKERRER","UYGUN"))

Sheet TAHSILATLAR
A1: TAHSILATLAR — CARİ HESAP, TAHSİLAT VE MÜŞTERİ RİSK TAKİP SİSTEMİ
A3: TAHSİLAT KAYIT VE EŞLEŞTİRME MERKEZİ
A5: Tahsilat Kayıt Numarası | B5: Tarih | C5: Müşteri Kodu | D5: Fatura Numarası | E5: Tahsilat Tutarı | F5: Ödeme Türü | G5: Banka/Kasa | H5: Çek/Senet Numarası | I5: Valör Tarihi | J5: Kesinleşti mi? | K5: Açıklama
A6: T001 | B6: 46162 | C6: M001 | D6: 2026-001 | E6: 300000 | F6: Havale/EFT | G6: Akbank | I6: 46162 | J6: =IF($B6="","",IF(ISNUMBER($E6),IF(OR($F6="Çek/Senet",$F6=""),"Hayır","Evet"),"Hayır"))
A7: T002 | B7: 46218 | C7: M001 | D7: 2026-001 | E7: 250000 | F7: Havale/EFT | G7: İş Bankası | I7: 46218 | J7: =IF($B7="","",IF(ISNUMBER($E7),IF(OR($F7="Çek/Senet",$F7=""),"Hayır","Evet"),"Hayır"))
A8: T003 | B8: 46236 | C8: M002 | D8: 2026-003 | E8: 180000 | F8: Havale/EFT | G8: Garanti | I8: 46236 | J8: =IF($B8="","",IF(ISNUMBER($E8),IF(OR($F8="Çek/Senet",$F8=""),"Hayır","Evet"),"Hayır"))
A9: T004 | B9: 46183 | C9: M003 | D9: 2026-004 | E9: 120000 | F9: Çek/Senet | H9: ÇEK-4412 | I9: 46244 | J9: =IF($B9="","",IF(ISNUMBER($E9),IF(OR($F9="Çek/Senet",$F9=""),"Hayır","Evet"),"Hayır")) | K9: Vade bekleniyor
J10: =IF($B10="","",IF(ISNUMBER($E10),IF(OR($F10="Çek/Senet",$F10=""),"Hayır","Evet"),"Hayır"))
J11: =IF($B11="","",IF(ISNUMBER($E11),IF(OR($F11="Çek/Senet",$F11=""),"Hayır","Evet"),"Hayır"))
J12: =IF($B12="","",IF(ISNUMBER($E12),IF(OR($F12="Çek/Senet",$F12=""),"Hayır","Evet"),"Hayır"))
J13: =IF($B13="","",IF(ISNUMBER($E13),IF(OR($F13="Çek/Senet",$F13=""),"Hayır","Evet"),"Hayır"))
J14: =IF($B14="","",IF(ISNUMBER($E14),IF(OR($F14="Çek/Senet",$F14=""),"Hayır","Evet"),"Hayır"))
J15: =IF($B15="","",IF(ISNUMBER($E15),IF(OR($F15="Çek/Senet",$F15=""),"Hayır","Evet"),"Hayır"))
J16: =IF($B16="","",IF(ISNUMBER($E16),IF(OR($F16="Çek/Senet",$F16=""),"Hayır","Evet"),"Hayır"))
J17: =IF($B17="","",IF(ISNUMBER($E17),IF(OR($F17="Çek/Senet",$F17=""),"Hayır","Evet"),"Hayır"))
J18: =IF($B18="","",IF(ISNUMBER($E18),IF(OR($F18="Çek/Senet",$F18=""),"Hayır","Evet"),"Hayır"))
J19: =IF($B19="","",IF(ISNUMBER($E19),IF(OR($F19="Çek/Senet",$F19=""),"Hayır","Evet"),"Hayır"))
J20: =IF($B20="","",IF(ISNUMBER($E20),IF(OR($F20="Çek/Senet",$F20=""),"Hayır","Evet"),"Hayır"))
J21: =IF($B21="","",IF(ISNUMBER($E21),IF(OR($F21="Çek/Senet",$F21=""),"Hayır","Evet"),"Hayır"))
... J45: =IF($B45="","",IF(ISNUMBER($E45),IF(OR($F45="Çek/Senet",$F45=""),"Hayır","Evet"),"Hayır"))

Sheet TEMINATLAR
A1: TEMINATLAR — CARİ HESAP, TAHSİLAT VE MÜŞTERİ RİSK TAKİP SİSTEMİ
A3: TEMİNAT PORTFÖYÜ
A5: Teminat Kayıt Numarası | B5: Müşteri Kodu | C5: Teminat Türü | D5: Belge Numarası | E5: Başlangıç Tarihi | F5: Geçerlilik Tarihi | G5: Nominal Değer | H5: Değerleme İndirimi | I5: Kabul Edilen Değer | J5: Para Birimi | K5: Durum | L5: Kontrol
A6: T001 | B6: M001 | C6: Banka Teminat Mektubu | D6: BTM-24018 | E6: 45366 | F6: 46461 | G6: 900000 | H6: 0.1 | I6: =$G6*(1-$H6) | J6: TRY | K6: =IF($F6="","",IF($F6<RaporTarihi,"SÜRESİ GEÇTİ",IF($F6-RaporTarihi<=YenilemeUyariGunu,"30 GÜN İÇİNDE BİTİYOR","GEÇERLİ"))) | L6: =IF($A6="","",IF(COUNTA($A6:$J6)>=ZorunluTeminatAlanSayisi,"OK","EKSİK"))
A7: T002 | B7: M002 | C7: İpotek | D7: IP-8831 | E7: 45108 | F7: 46203 | G7: 550000 | H7: 0.25 | I7: =$G7*(1-$H7) | J7: TRY | K7: =IF($F7="","",IF($F7<RaporTarihi,"SÜRESİ GEÇTİ",IF($F7-RaporTarihi<=YenilemeUyariGunu,"30 GÜN İÇİNDE BİTİYOR","GEÇERLİ"))) | L7: =IF($A6="","",IF(COUNTA($A6:$J6)>=ZorunluTeminatAlanSayisi,"OK","EKSİK"))
A8: T003 | B8: M003 | C8: Çek ve Senet | D8: ÇEK-4412 | E8: 46023 | F8: 46235 | G8: 300000 | H8: 0.2 | I8: =$G8*(1-$H8) | J8: TRY | K8: =IF($F8="","",IF($F8<RaporTarihi,"SÜRESİ GEÇTİ",IF($F8-RaporTarihi<=YenilemeUyariGunu,"30 GÜN İÇİNDE BİTİYOR","GEÇERLİ"))) | L8: =IF($A6="","",IF(COUNTA($A6:$J6)>=ZorunluTeminatAlanSayisi,"OK","EKSİK"))
I9: =$G9*(1-$H9) | K9: =IF($F9="","",IF($F9<RaporTarihi,"SÜRESİ GEÇTİ",IF($F9-RaporTarihi<=YenilemeUyariGunu,"30 GÜN İÇİNDE BİTİYOR","GEÇERLİ"))) | L9: =IF($A6="","",IF(COUNTA($A6:$J6)>=ZorunluTeminatAlanSayisi,"OK","EKSİK"))
I10: =$G10*(1-$H10) | K10: =IF($F10="","",IF($F10<RaporTarihi,"SÜRESİ GEÇTİ",IF($F10-RaporTarihi<=YenilemeUyariGunu,"30 GÜN İÇİNDE BİTİYOR","GEÇERLİ"))) | L10: =IF($A6="","",IF(COUNTA($A6:$J6)>=ZorunluTeminatAlanSayisi,"OK","EKSİK"))
I11: =$G11*(1-$H11) | K11: =IF($F11="","",IF($F11<RaporTarihi,"SÜRESİ GEÇTİ",IF($F11-RaporTarihi<=YenilemeUyariGunu,"30 GÜN İÇİNDE BİTİYOR","GEÇERLİ"))) | L11: =IF($A6="","",IF(COUNTA($A6:$J6)>=ZorunluTeminatAlanSayisi,"OK","EKSİK"))
I12: =$G12*(1-$H12) | K12: =IF($F12="","",IF($F12<RaporTarihi,"SÜRESİ GEÇTİ",IF($F12-RaporTarihi<=YenilemeUyariGunu,"30 GÜN İÇİNDE BİTİYOR","GEÇERLİ"))) | L12: =IF($A6="","",IF(COUNTA($A6:$J6)>=ZorunluTeminatAlanSayisi,"OK","EKSİK"))
I13: =$G13*(1-$H13) | K13: =IF($F13="","",IF($F13<RaporTarihi,"SÜRESİ GEÇTİ",IF($F13-RaporTarihi<=YenilemeUyariGunu,"30 GÜN İÇİNDE BİTİYOR","GEÇERLİ"))) | L13: =IF($A6="","",IF(COUNTA($A6:$J6)>=ZorunluTeminatAlanSayisi,"OK","EKSİK"))
I14: =$G14*(1-$H14) | K14: =IF($F14="","",IF($F14<RaporTarihi,"SÜRESİ GEÇTİ",IF($F14-RaporTarihi<=YenilemeUyariGunu,"30 GÜN İÇİNDE BİTİYOR","GEÇERLİ"))) | L14: =IF($A6="","",IF(COUNTA($A6:$J6)>=ZorunluTeminatAlanSayisi,"OK","EKSİK"))
I15: =$G15*(1-$H15) | K15: =IF($F15="","",IF($F15<RaporTarihi,"SÜRESİ GEÇTİ",IF($F15-RaporTarihi<=YenilemeUyariGunu,"30 GÜN İÇİNDE BİTİYOR","GEÇERLİ"))) | L15: =IF($A6="","",IF(COUNTA($A6:$J6)>=ZorunluTeminatAlanSayisi,"OK","EKSİK"))
I16: =$G16*(1-$H16) | K16: =IF($F16="","",IF($F16<RaporTarihi,"SÜRESİ GEÇTİ",IF($F16-RaporTarihi<=YenilemeUyariGunu,"30 GÜN İÇİNDE BİTİYOR","GEÇERLİ"))) | L16: =IF($A6="","",IF(COUNTA($A6:$J6)>=ZorunluTeminatAlanSayisi,"OK","EKSİK"))
I17: =$G17*(1-$H17) | K17: =IF($F17="","",IF($F17<RaporTarihi,"SÜRESİ GEÇTİ",IF($F17-RaporTarihi<=YenilemeUyariGunu,"30 GÜN İÇİNDE BİTİYOR","GEÇERLİ"))) | L17: =IF($A6="","",IF(COUNTA($A6:$J6)>=ZorunluTeminatAlanSayisi,"OK","EKSİK"))
I18: =$G18*(1-$H18) | K18: =IF($F18="","",IF($F18<RaporTarihi,"SÜRESİ GEÇTİ",IF($F18-RaporTarihi<=YenilemeUyariGunu,"30 GÜN İÇİNDE BİTİYOR","GEÇERLİ"))) | L18: =IF($A6="","",IF(COUNTA($A6:$J6)>=ZorunluTeminatAlanSayisi,"OK","EKSİK"))
I19: =$G19*(1-$H19) | K19: =IF($F19="","",IF($F19<RaporTarihi,"SÜRESİ GEÇTİ",IF($F19-RaporTarihi<=YenilemeUyariGunu,"30 GÜN İÇİNDE BİTİYOR","GEÇERLİ"))) | L19: =IF($A6="","",IF(COUNTA($A6:$J6)>=ZorunluTeminatAlanSayisi,"OK","EKSİK"))
I20: =$G20*(1-$H20) | K20: =IF($F20="","",IF($F20<RaporTarihi,"SÜRESİ GEÇTİ",IF($F20-RaporTarihi<=YenilemeUyariGunu,"30 GÜN İÇİNDE BİTİYOR","GEÇERLİ"))) | L20: =IF($A6="","",IF(COUNTA($A6:$J6)>=ZorunluTeminatAlanSayisi,"OK","EKSİK"))
I21: =$G21*(1-$H21) | K21: =IF($F21="","",IF($F21<RaporTarihi,"SÜRESİ GEÇTİ",IF($F21-RaporTarihi<=YenilemeUyariGunu,"30 GÜN İÇİNDE BİTİYOR","GEÇERLİ"))) | L21: =IF($A6="","",IF(COUNTA($A6:$J6)>=ZorunluTeminatAlanSayisi,"OK","EKSİK"))
I22: =$G22*(1-$H22) | K22: =IF($F22="","",IF($F22<RaporTarihi,"SÜRESİ GEÇTİ",IF($F22-RaporTarihi<=YenilemeUyariGunu,"30 GÜN İÇİNDE BİTİYOR","GEÇERLİ"))) | L22: =IF($A6="","",IF(COUNTA($A6:$J6)>=ZorunluTeminatAlanSayisi,"OK","EKSİK"))
I23: =$G23*(1-$H23) | K23: =IF($F23="","",IF($F23<RaporTarihi,"SÜRESİ GEÇTİ",IF($F23-RaporTarihi<=YenilemeUyariGunu,"30 GÜN İÇİNDE BİTİYOR","GEÇERLİ"))) | L23: =IF($A6="","",IF(COUNTA($A6:$J6)>=ZorunluTeminatAlanSayisi,"OK","EKSİK"))
I24: =$G24*(1-$H24) | K24: =IF($F24="","",IF($F24<RaporTarihi,"SÜRESİ GEÇTİ",IF($F24-RaporTarihi<=YenilemeUyariGunu,"30 GÜN İÇİNDE BİTİYOR","GEÇERLİ"))) | L24: =IF($A6="","",IF(COUNTA($A6:$J6)>=ZorunluTeminatAlanSayisi,"OK","EKSİK"))
I25: =$G25*(1-$H25) | K25: =IF($F25="","",IF($F25<RaporTarihi,"SÜRESİ GEÇTİ",IF($F25-RaporTarihi<=YenilemeUyariGunu,"30 GÜN İÇİNDE BİTİYOR","GEÇERLİ"))) | L25: =IF($A6="","",IF(COUNTA($A6:$J6)>=ZorunluTeminatAlanSayisi,"OK","EKSİK"))
I26: =$G26*(1-$H26) | K26: =IF($F26="","",IF($F26<RaporTarihi,"SÜRESİ GEÇTİ",IF($F26-RaporTarihi<=YenilemeUyariGunu,"30 GÜN İÇİNDE BİTİYOR","GEÇERLİ"))) | L26: =IF($A6="","",IF(COUNTA($A6:$J6)>=ZorunluTeminatAlanSayisi,"OK","EKSİK"))
I27: =$G27*(1-$H27) | K27: =IF($F27="","",IF($F27<RaporTarihi,"SÜRESİ GEÇTİ",IF($F27-RaporTarihi<=YenilemeUyariGunu,"30 GÜN İÇİNDE BİTİYOR","GEÇERLİ"))) | L27: =IF($A6="","",IF(COUNTA($A6:$J6)>=ZorunluTeminatAlanSayisi,"OK","EKSİK"))
I28: =$G28*(1-$H28) | K28: =IF($F28="","",IF($F28<RaporTarihi,"SÜRESİ GEÇTİ",IF($F28-RaporTarihi<=YenilemeUyariGunu,"30 GÜN İÇİNDE BİTİYOR","GEÇERLİ"))) | L28: =IF($A6="","",IF(COUNTA($A6:$J6)>=ZorunluTeminatAlanSayisi,"OK","EKSİK"))
I29: =$G29*(1-$H29) | K29: =IF($F29="","",IF($F29<RaporTarihi,"SÜRESİ GEÇTİ",IF($F29-RaporTarihi<=YenilemeUyariGunu,"30 GÜN İÇİNDE BİTİYOR","GEÇERLİ"))) | L29: =IF($A6="","",IF(COUNTA($A6:$J6)>=ZorunluTeminatAlanSayisi,"OK","EKSİK"))
I30: =$G30*(1-$H30) | K30: =IF($F30="","",IF($F30<RaporTarihi,"SÜRESİ GEÇTİ",IF($F30-RaporTarihi<=YenilemeUyariGunu,"30 GÜN İÇİNDE BİTİYOR","GEÇERLİ"))) | L30: =IF($A6="","",IF(COUNTA($A6:$J6)>=ZorunluTeminatAlanSayisi,"OK","EKSİK"))
I31: =$G31*(1-$H31) | K31: =IF($F31="","",IF($F31<RaporTarihi,"SÜRESİ GEÇTİ",IF($F31-RaporTarihi<=YenilemeUyariGunu,"30 GÜN İÇİNDE BİTİYOR","GEÇERLİ"))) | L31: =IF($A6="","",IF(COUNTA($A6:$J6)>=ZorunluTeminatAlanSayisi,"OK","EKSİK"))
I32: =$G32*(1-$H32) | K32: =IF($F32="","",IF($F32<RaporTarihi,"SÜRESİ GEÇTİ",IF($F32-RaporTarihi<=YenilemeUyariGunu,"30 GÜN İÇİNDE BİTİYOR","GEÇERLİ"))) | L32: =IF($A6="","",IF(COUNTA($A6:$J6)>=ZorunluTeminatAlanSayisi,"OK","EKSİK"))
I33: =$G33*(1-$H33) | K33: =IF($F33="","",IF($F33<RaporTarihi,"SÜRESİ GEÇTİ",IF($F33-RaporTarihi<=YenilemeUyariGunu,"30 GÜN İÇİNDE BİTİYOR","GEÇERLİ"))) | L33: =IF($A6="","",IF(COUNTA($A6:$J6)>=ZorunluTeminatAlanSayisi,"OK","EKSİK"))
I34: =$G34*(1-$H34) | K34: =IF($F34="","",IF($F34<RaporTarihi,"SÜRESİ GEÇTİ",IF($F34-RaporTarihi<=YenilemeUyariGunu,"30 GÜN İÇİNDE BİTİYOR","GEÇERLİ"))) | L34: =IF($A6="","",IF(COUNTA($A6:$J6)>=ZorunluTeminatAlanSayisi,"OK","EKSİK"))
I35: =$G35*(1-$H35) | K35: =IF($F35="","",IF($F35<RaporTarihi,"SÜRESİ GEÇTİ",IF($F35-RaporTarihi<=YenilemeUyariGunu,"30 GÜN İÇİNDE BİTİYOR","GEÇERLİ"))) | L35: =IF($A6="","",IF(COUNTA($A6:$J6)>=ZorunluTeminatAlanSayisi,"OK","EKSİK"))
I36: =$G36*(1-$H36) | K36: =IF($F36="","",IF($F36<RaporTarihi,"SÜRESİ GEÇTİ",IF($F36-RaporTarihi<=YenilemeUyariGunu,"30 GÜN İÇİNDE BİTİYOR","GEÇERLİ"))) | L36: =IF($A6="","",IF(COUNTA($A6:$J6)>=ZorunluTeminatAlanSayisi,"OK","EKSİK"))
I37: =$G37*(1-$H37) | K37: =IF($F37="","",IF($F37<RaporTarihi,"SÜRESİ GEÇTİ",IF($F37-RaporTarihi<=YenilemeUyariGunu,"30 GÜN İÇİNDE BİTİYOR","GEÇERLİ"))) | L37: =IF($A6="","",IF(COUNTA($A6:$J6)>=ZorunluTeminatAlanSayisi,"OK","EKSİK"))
I38: =$G38*(1-$H38) | K38: =IF($F38="","",IF($F38<RaporTarihi,"SÜRESİ GEÇTİ",IF($F38-RaporTarihi<=YenilemeUyariGunu,"30 GÜN İÇİNDE BİTİYOR","GEÇERLİ"))) | L38: =IF($A6="","",IF(COUNTA($A6:$J6)>=ZorunluTeminatAlanSayisi,"OK","EKSİK"))
I39: =$G39*(1-$H39) | K39: =IF($F39="","",IF($F39<RaporTarihi,"SÜRESİ GEÇTİ",IF($F39-RaporTarihi<=YenilemeUyariGunu,"30 GÜN İÇİNDE BİTİYOR","GEÇERLİ"))) | L39: =IF($A6="","",IF(COUNTA($A6:$J6)>=ZorunluTeminatAlanSayisi,"OK","EKSİK"))
I40: =$G40*(1-$H40) | K40: =IF($F40="","",IF($F40<RaporTarihi,"SÜRESİ GEÇTİ",IF($F40-RaporTarihi<=YenilemeUyariGunu,"30 GÜN İÇİNDE BİTİYOR","GEÇERLİ"))) | L40: =IF($A6="","",IF(COUNTA($A6:$J6)>=ZorunluTeminatAlanSayisi,"OK","EKSİK"))
I41: =$G41*(1-$H41) | K41: =IF($F41="","",IF($F41<RaporTarihi,"SÜRESİ GEÇTİ",IF($F41-RaporTarihi<=YenilemeUyariGunu,"30 GÜN İÇİNDE BİTİYOR","GEÇERLİ"))) | L41: =IF($A6="","",IF(COUNTA($A6:$J6)>=ZorunluTeminatAlanSayisi,"OK","EKSİK"))
I42: =$G42*(1-$H42) | K42: =IF($F42="","",IF($F42<RaporTarihi,"SÜRESİ GEÇTİ",IF($F42-RaporTarihi<=YenilemeUyariGunu,"30 GÜN İÇİNDE BİTİYOR","GEÇERLİ"))) | L42: =IF($A6="","",IF(COUNTA($A6:$J6)>=ZorunluTeminatAlanSayisi,"OK","EKSİK"))
...

Sheet ILETISIM_TAKIP
A1: ILETISIM TAKIP — CARİ HESAP, TAHSİLAT VE MÜŞTERİ RİSK TAKİP SİSTEMİ
A3: İLETİŞİM VE ÖDEME SÖZÜ TAKİBİ
A5: Takip Kayıt Numarası | B5: Tarih | C5: Müşteri Kodu | D5: Yetkili Kişi | E5: Kanal | F5: Görüşme Sonucu | G5: Söz Verilen Tarih | H5: Söz Verilen Tutar | I5: Sonraki Aksiyon | J5: Sorumlu | K5: Söz Gecikme Günü | L5: Söz Durumu
A6: IT001 | B6: 46235 | C6: M003 | D6: Mali İşler Müdürü | E6: Telefon | F6: Kısmi ödeme sözü | G6: 46237 | H6: 150000 | I6: Ödeme dekontunu teyit et | J6: Zeynep Kaya | K6: =IF($B6="","",IF($G6="","",MAX(0,RaporTarihi-$G6))) | L6: =IF($B6="","",IF($G6="","BEKLİYOR",IF(RaporTarihi-$G6>0,"SÖZ GECİKTİ",IF($F6="Yerine getirildi","YERİNE GETİRİLDİ","BEKLİYOR"))))
A7: IT002 | B7: 46236 | C7: M004 | D7: Finans Uzmanı | E7: E-posta | F7: İtiraz dosyası bekleniyor | G7: 46242 | H7: 400000 | I7: Mutabakat toplantısı planla | J7: Kemal Şahin | K7: =IF($B7="","",IF($G7="","",MAX(0,RaporTarihi-$G7))) | L7: =IF($B7="","",IF($G7="","BEKLİYOR",IF(RaporTarihi-$G7>0,"SÖZ GECİKTİ",IF($F7="Yerine getirildi","YERİNE GETİRİLDİ","BEKLİYOR"))))
K8: =IF($B8="","",IF($G8="","",MAX(0,RaporTarihi-$G8))) | L8: =IF($B8="","",IF($G8="","BEKLİYOR",IF(RaporTarihi-$G8>0,"SÖZ GECİKTİ",IF($F8="Yerine getirildi","YERİNE GETİRİLDİ","BEKLİYOR"))))
K9: =IF($B9="","",IF($G9="","",MAX(0,RaporTarihi-$G9))) | L9: =IF($B9="","",IF($G9="","BEKLİYOR",IF(RaporTarihi-$G9>0,"SÖZ GECİKTİ",IF($F9="Yerine getirildi","YERİNE GETİRİLDİ","BEKLİYOR"))))
K10: =IF($B10="","",IF($G10="","",MAX(0,RaporTarihi-$G10))) | L10: =IF($B10="","",IF($G10="","BEKLİYOR",IF(RaporTarihi-$G10>0,"SÖZ GECİKTİ",IF($F10="Yerine getirildi","YERİNE GETİRİLDİ","BEKLİYOR"))))
K11: =IF($B11="","",IF($G11="","",MAX(0,RaporTarihi-$G11))) | L11: =IF($B11="","",IF($G11="","BEKLİYOR",IF(RaporTarihi-$G11>0,"SÖZ GECİKTİ",IF($F11="Yerine getirildi","YERİNE GETİRİLDİ","BEKLİYOR"))))
K12: =IF($B12="","",IF($G12="","",MAX(0,RaporTarihi-$G12))) | L12: =IF($B12="","",IF($G12="","BEKLİYOR",IF(RaporTarihi-$G12>0,"SÖZ GECİKTİ",IF($F12="Yerine getirildi","YERİNE GETİRİLDİ","BEKLİYOR"))))
K13: =IF($B13="","",IF($G13="","",MAX(0,RaporTarihi-$G13))) | L13: =IF($B13="","",IF($G13="","BEKLİYOR",IF(RaporTarihi-$G13>0,"SÖZ GECİKTİ",IF($F13="Yerine getirildi","YERİNE GETİRİLDİ","BEKLİYOR"))))
K14: =IF($B14="","",IF($G14="","",MAX(0,RaporTarihi-$G14))) | L14: =IF($B14="","",IF($G14="","BEKLİYOR",IF(RaporTarihi-$G14>0,"SÖZ GECİKTİ",IF($F14="Yerine getirildi","YERİNE GETİRİLDİ","BEKLİYOR"))))
K15: =IF($B15="","",IF($G15="","",MAX(0,RaporTarihi-$G15))) | L15: =IF($B15="","",IF($G15="","BEKLİYOR",IF(RaporTarihi-$G15>0,"SÖZ GECİKTİ",IF($F15="Yerine getirildi","YERİNE GETİRİLDİ","BEKLİYOR"))))
K16: =IF($B16="","",IF($G16="","",MAX(0,RaporTarihi-$G16))) | L16: =IF($B16="","",IF($G16="","BEKLİYOR",IF(RaporTarihi-$G16>0,"SÖZ GECİKTİ",IF($F16="Yerine getirildi","YERİNE GETİRİLDİ","BEKLİYOR"))))
K17: =IF($B17="","",IF($G17="","",MAX(0,RaporTarihi-$G17))) | L17: =IF($B17="","",IF($G17="","BEKLİYOR",IF(RaporTarihi-$G17>0,"SÖZ GECİKTİ",IF($F17="Yerine getirildi","YERİNE GETİRİLDİ","BEKLİYOR"))))
K18: =IF($B18="","",IF($G18="","",MAX(0,RaporTarihi-$G18))) | L18: =IF($B18="","",IF($G18="","BEKLİYOR",IF(RaporTarihi-$G18>0,"SÖZ GECİKTİ",IF($F18="Yerine getirildi","YERİNE GETİRİLDİ","BEKLİYOR"))))
K19: =IF($B19="","",IF($G19="","",MAX(0,RaporTarihi-$G19))) | L19: =IF($B19="","",IF($G19="","BEKLİYOR",IF(RaporTarihi-$G19>0,"SÖZ GECİKTİ",IF($F19="Yerine getirildi","YERİNE GETİRİLDİ","BEKLİYOR"))))
... K45: =IF($B45="","",IF($G45="","",MAX(0,RaporTarihi-$G45))) | L45: =IF($B45="","",IF($G45="","BEKLİYOR",IF(RaporTarihi-$G45>0,"SÖZ GECİKTİ",IF($F45="Yerine getirildi","YERİNE GETİRİLDİ","BEKLİYOR"))))

Sheet YASLANDIRMA
A1: YASLANDIRMA — CARİ HESAP, TAHSİLAT VE MÜŞTERİ RİSK TAKİP SİSTEMİ
A3: ALACAK YAŞLANDIRMA ANALİZİ
A5: Fatura Numarası | B5: Müşteri Kodu | C5: Vade Tarihi | D5: Net Fatura | E5: Kesin Tahsilat | F5: Açık Tutar | G5: Gecikme Günü | H5: Yaşlandırma | I5: İtirazlı Tutar | J5: Teminat Kapsamı
A6: =FATURALAR!$B6 | B6: =FATURALAR!$C6 | C6: =FATURALAR!$E6 | D6: =FATURALAR!$K6 | E6: =SUMIFS(tblTahsilatlar[Tahsilat Tutarı],tblTahsilatlar[Fatura Numarası],$A6,tblTahsilatlar[Kesinleşti mi?],"Evet") | F6: =IF($D6="","",MAX(0,$D6-$E6)) | G6: =IF($F6="","",IF($F6=0,0,MAX(0,RaporTarihi-$C6))) | H6: =IF($F6="","",IF($F6=0,"KAPALI",IF($G6<=0,"VADESİ GELMEMİŞ",IF($G6<=YaslamaDilim1,"1-"&TEXT(YaslamaDilim1,"0"),IF($G6<=YaslamaDilim2,TEXT(YaslamaDilim1+1,"0")&"-"&TEXT(YaslamaDilim2,"0"),IF($G6<=YaslamaDilim3,TEXT(YaslamaDilim2+1,"0")&"-"&TEXT(YaslamaDilim3,"0"),TEXT(YaslamaDilim3+1,"0")&"+")))))) | I6: =IF(FATURALAR!$L6=0,"",FATURALAR!$L6) | J6: =IF(FATURALAR!$M6=0,"",FATURALAR!$M6)
A7: =FATURALAR!$B7 | B7: =FATURALAR!$C7 | C7: =FATURALAR!$E7 | D7: =FATURALAR!$K7 | E7: =SUMIFS(tblTahsilatlar[Tahsilat Tutarı],tblTahsilatlar[Fatura Numarası],$A7,tblTahsilatlar[Kesinleşti mi?],"Evet") | F7: =IF($D7="","",MAX(0,$D7-$E7)) | G7: =IF($F7="","",IF($F7=0,0,MAX(0,RaporTarihi-$C7))) | H7: =IF($F7="","",IF($F7=0,"KAPALI",IF($G7<=0,"VADESİ GELMEMİŞ",IF($G7<=YaslamaDilim1,"1-"&TEXT(YaslamaDilim1,"0"),IF($G7<=YaslamaDilim2,TEXT(YaslamaDilim1+1,"0")&"-"&TEXT(YaslamaDilim2,"0"),IF($G7<=YaslamaDilim3,TEXT(YaslamaDilim2+1,"0")&"-"&TEXT(YaslamaDilim3,"0"),TEXT(YaslamaDilim3+1,"0")&"+")))))) | I7: =IF(FATURALAR!$L7=0,"",FATURALAR!$L7) | J7: =IF(FATURALAR!$M7=0,"",FATURALAR!$M7)
A8: =FATURALAR!$B8 | B8: =FATURALAR!$C8 | C8: =FATURALAR!$E8 | D8: =FATURALAR!$K8 | E8: =SUMIFS(tblTahsilatlar[Tahsilat Tutarı],tblTahsilatlar[Fatura Numarası],$A8,tblTahsilatlar[Kesinleşti mi?],"Evet") | F8: =IF($D8="","",MAX(0,$D8-$E8)) | G8: =IF($F8="","",IF($F8=0,0,MAX(0,RaporTarihi-$C8))) | H8: =IF($F8="","",IF($F8=0,"KAPALI",IF($G8<=0,"VADESİ GELMEMİŞ",IF($G8<=YaslamaDilim1,"1-"&TEXT(YaslamaDilim1,"0"),IF($G8<=YaslamaDilim2,TEXT(YaslamaDilim1+1,"0")&"-"&TEXT(YaslamaDilim2,"0"),IF($G8<=YaslamaDilim3,TEXT(YaslamaDilim2+1,"0")&"-"&TEXT(YaslamaDilim3,"0"),TEXT(YaslamaDilim3+1,"0")&"+")))))) | I8: =IF(FATURALAR!$L8=0,"",FATURALAR!$L8) | J8: =IF(FATURALAR!$M8=0,"",FATURALAR!$M8)
A9: =FATURALAR!$B9 | B9: =FATURALAR!$C9 | C9: =FATURALAR!$E9 | D9: =FATURALAR!$K9 | E9: =SUMIFS(tblTahsilatlar[Tahsilat Tutarı],tblTahsilatlar[Fatura Numarası],$A9,tblTahsilatlar[Kesinleşti mi?],"Evet") | F9: =IF($D9="","",MAX(0,$D9-$E9)) | G9: =IF($F9="","",IF($F9=0,0,MAX(0,RaporTarihi-$C9))) | H9: =IF($F9="","",IF($F9=0,"KAPALI",IF($G9<=0,"VADESİ GELMEMİŞ",IF($G9<=YaslamaDilim1,"1-"&TEXT(YaslamaDilim1,"0"),IF($G9<=YaslamaDilim2,TEXT(YaslamaDilim1+1,"0")&"-"&TEXT(YaslamaDilim2,"0"),IF($G9<=YaslamaDilim3,TEXT(YaslamaDilim2+1,"0")&"-"&TEXT(YaslamaDilim3,"0"),TEXT(YaslamaDilim3+1,"0")&"+")))))) | I9: =IF(FATURALAR!$L9=0,"",FATURALAR!$L9) | J9: =IF(FATURALAR!$M9=0,"",FATURALAR!$M9)
A10: =FATURALAR!$B10 | B10: =FATURALAR!$C10 | C10: =FATURALAR!$E10 | D10: =FATURALAR!$K10 | E10: =SUMIFS(tblTahsilatlar[Tahsilat Tutarı],tblTahsilatlar[Fatura Numarası],$A10,tblTahsilatlar[Kesinleşti mi?],"Evet") | F10: =IF($D10="","",MAX(0,$D10-$E10)) | G10: =IF($F10="","",IF($F10=0,0,MAX(0,RaporTarihi-$C10))) | H10: =IF($F10="","",IF($F10=0,"KAPALI",IF($G10<=0,"VADESİ GELMEMİŞ",IF($G10<=YaslamaDilim1,"1-"&TEXT(YaslamaDilim1,"0"),IF($G10<=YaslamaDilim2,TEXT(YaslamaDilim1+1,"0")&"-"&TEXT(YaslamaDilim2,"0"),IF($G10<=YaslamaDilim3,TEXT(YaslamaDilim2+1,"0")&"-"&TEXT(YaslamaDilim3,"0"),TEXT(YaslamaDilim3+1,"0")&"+")))))) | I10: =IF(FATURALAR!$L10=0,"",FATURALAR!$L10) | J10: =IF(FATURALAR!$M10=0,"",FATURALAR!$M10)
A11: =FATURALAR!$B11 | B11: =FATURALAR!$C11 | C11: =FATURALAR!$E11 | D11: =FATURALAR!$K11 | E11: =SUMIFS(tblTahsilatlar[Tahsilat Tutarı],tblTahsilatlar[Fatura Numarası],$A11,tblTahsilatlar[Kesinleşti mi?],"Evet") | F11: =IF($D11="","",MAX(0,$D11-$E11)) | G11: =IF($F11="","",IF($F11=0,0,MAX(0,RaporTarihi-$C11))) | H11: =IF($F11="","",IF($F11=0,"KAPALI",IF($G11<=0,"VADESİ GELMEMİŞ",IF($G11<=YaslamaDilim1,"1-"&TEXT(YaslamaDilim1,"0"),IF($G11<=YaslamaDilim2,TEXT(YaslamaDilim1+1,"0")&"-"&TEXT(YaslamaDilim2,"0"),IF($G11<=YaslamaDilim3,TEXT(YaslamaDilim2+1,"0")&"-"&TEXT(YaslamaDilim3,"0"),TEXT(YaslamaDilim3+1,"0")&"+")))))) | I11: =IF(FATURALAR!$L11=0,"",FATURALAR!$L11) | J11: =IF(FATURALAR!$M11=0,"",FATURALAR!$M11)
A12: =FATURALAR!$B12 | B12: =FATURALAR!$C12 | C12: =FATURALAR!$E12 | D12: =FATURALAR!$K12 | E12: =SUMIFS(tblTahsilatlar[Tahsilat Tutarı],tblTahsilatlar[Fatura Numarası],$A12,tblTahsilatlar[Kesinleşti mi?],"Evet") | F12: =IF($D12="","",MAX(0,$D12-$E12)) | G12: =IF($F12="","",IF($F12=0,0,MAX(0,RaporTarihi-$C12))) | H12: =IF($F12="","",IF($F12=0,"KAPALI",IF($G12<=0,"VADESİ GELMEMİŞ",IF($G12<=YaslamaDilim1,"1-"&TEXT(YaslamaDilim1,"0"),IF($G12<=YaslamaDilim2,TEXT(YaslamaDilim1+1,"0")&"-"&TEXT(YaslamaDilim2,"0"),IF($G12<=YaslamaDilim3,TEXT(YaslamaDilim2+1,"0")&"-"&TEXT(YaslamaDilim3,"0"),TEXT(YaslamaDilim3+1,"0")&"+")))))) | I12: =IF(FATURALAR!$L12=0,"",FATURALAR!$L12) | J12: =IF(FATURALAR!$M12=0,"",FATURALAR!$M12)
A13: =FATURALAR!$B13 | B13: =FATURALAR!$C13 | C13: =FATURALAR!$E13 | D13: =FATURALAR!$K13 | E13: =SUMIFS(tblTahsilatlar[Tahsilat Tutarı],tblTahsilatlar[Fatura Numarası],$A13,tblTahsilatlar[Kesinleşti mi?],"Evet") | F13: =IF($D13="","",MAX(0,$D13-$E13)) | G13: =IF($F13="","",IF($F13=0,0,MAX(0,RaporTarihi-$C13))) | H13: =IF($F13="","",IF($F13=0,"KAPALI",IF($G13<=0,"VADESİ GELMEMİŞ",IF($G13<=YaslamaDilim1,"1-"&TEXT(YaslamaDilim1,"0"),IF($G13<=YaslamaDilim2,TEXT(YaslamaDilim1+1,"0")&"-"&TEXT(YaslamaDilim2,"0"),IF($G13<=YaslamaDilim3,TEXT(YaslamaDilim2+1,"0")&"-"&TEXT(YaslamaDilim3,"0"),TEXT(YaslamaDilim3+1,"0")&"+")))))) | I13: =IF(FATURALAR!$L13=0,"",FATURALAR!$L13) | J13: =IF(FATURALAR!$M13=0,"",FATURALAR!$M13)
A14: =FATURALAR!$B14 | B14: =FATURALAR!$C14 | C14: =FATURALAR!$E14 | D14: =FATURALAR!$K14 | E14: =SUMIFS(tblTahsilatlar[Tahsilat Tutarı],tblTahsilatlar[Fatura Numarası],$A14,tblTahsilatlar[Kesinleşti mi?],"Evet") | F14: =IF($D14="","",MAX(0,$D14-$E14)) | G14: =IF($F14="","",IF($F14=0,0,MAX(0,RaporTarihi-$C14))) | H14: =IF($F14="","",IF($F14=0,"KAPALI",IF($G14<=0,"VADESİ GELMEMİŞ",IF($G14<=YaslamaDilim1,"1-"&TEXT(YaslamaDilim1,"0"),IF($G14<=YaslamaDilim2,TEXT(YaslamaDilim1+1,"0")&"-"&TEXT(YaslamaDilim2,"0"),IF($G14<=YaslamaDilim3,TEXT(YaslamaDilim2+1,"0")&"-"&TEXT(YaslamaDilim3,"0"),TEXT(YaslamaDilim3+1,"0")&"+")))))) | I14: =IF(FATURALAR!$L14=0,"",FATURALAR!$L14) | J14: =IF(FATURALAR!$M14=0,"",FATURALAR!$M14)
A15: =FATURALAR!$B15 | B15: =FATURALAR!$C15 | C15: =FATURALAR!$E15 | D15: =FATURALAR!$K15 | E15: =SUMIFS(tblTahsilatlar[Tahsilat Tutarı],tblTahsilatlar[Fatura Numarası],$A15,tblTahsilatlar[Kesinleşti mi?],"Evet") | F15: =IF($D15="","",MAX(0,$D15-$E15)) | G15: =IF($F15="","",IF($F15=0,0,MAX(0,RaporTarihi-$C15))) | H15: =IF($F15="","",IF($F15=0,"KAPALI",IF($G15<=0,"VADESİ GELMEMİŞ",IF($G15<=YaslamaDilim1,"1-"&TEXT(YaslamaDilim1,"0"),IF($G15<=YaslamaDilim2,TEXT(YaslamaDilim1+1,"0")&"-"&TEXT(YaslamaDilim2,"0"),IF($G15<=YaslamaDilim3,TEXT(YaslamaDilim2+1,"0")&"-"&TEXT(YaslamaDilim3,"0"),TEXT(YaslamaDilim3+1,"0")&"+")))))) | I15: =IF(FATURALAR!$L15=0,"",FATURALAR!$L15) | J15: =IF(FATURALAR!$M15=0,"",FATURALAR!$M15)
A16: =FATURALAR!$B16 | B16: =FATURALAR!$C16 | C16: =FATURALAR!$E16 | D16: =FATURALAR!$K16 | E16: =SUMIFS(tblTahsilatlar[Tahsilat Tutarı],tblTahsilatlar[Fatura Numarası],$A16,tblTahsilatlar[Kesinleşti mi?],"Evet") | F16: =IF($D16="","",MAX(0,$D16-$E16)) | G16: =IF($F16="","",IF($F16=0,0,MAX(0,RaporTarihi-$C16))) | H16: =IF($F16="","",IF($F16=0,"KAPALI",IF($G16<=0,"VADESİ GELMEMİŞ",IF($G16<=YaslamaDilim1,"1-"&TEXT(YaslamaDilim1,"0"),IF($G16<=YaslamaDilim2,TEXT(YaslamaDilim1+1,"0")&"-"&TEXT(YaslamaDilim2,"0"),IF($G16<=YaslamaDilim3,TEXT(YaslamaDilim2+1,"0")&"-"&TEXT(YaslamaDilim3,"0"),TEXT(YaslamaDilim3+1,"0")&"+")))))) | I16: =IF(FATURALAR!$L16=0,"",FATURALAR!$L16) | J16: =IF(FATURALAR!$M16=0,"",FATURALAR!$M16)
A17: =FATURALAR!$B17 | B17: =FATURALAR!$C17 | C17: =FATURALAR!$E17 | D17: =FATURALAR!$K17 | E17: =SUMIFS(tblTahsilatlar[Tahsilat Tutarı],tblTahsilatlar[Fatura Numarası],$A17,tblTahsilatlar[Kesinleşti mi?],"Evet") | F17: =IF($D17="","",MAX(0,$D17-$E17)) | G17: =IF($F17="","",IF($F17=0,0,MAX(0,RaporTarihi-$C17))) | H17: =IF($F17="","",IF($F17=0,"KAPALI",IF($G17<=0,"VADESİ GELMEMİŞ",IF($G17<=YaslamaDilim1,"1-"&TEXT(YaslamaDilim1,"0"),IF($G17<=YaslamaDilim2,TEXT(YaslamaDilim1+1,"0")&"-"&TEXT(YaslamaDilim2,"0"),IF($G17<=YaslamaDilim3,TEXT(YaslamaDilim2+1,"0")&"-"&TEXT(YaslamaDilim3,"0"),TEXT(YaslamaDilim3+1,"0")&"+")))))) | I17: =IF(FATURALAR!$L17=0,"",FATURALAR!$L17) | J17: =IF(FATURALAR!$M17=0,"",FATURALAR!$M17)
... A45: =FATURALAR!$B45 | B45: =FATURALAR!$C45 | C45: =FATURALAR!$E45 | D45: =FATURALAR!$K45 | E45: =SUMIFS(tblTahsilatlar[Tahsilat Tutarı],tblTahsilatlar[Fatura Numarası],$A45,tblTahsilatlar[Kesinleşti mi?],"Evet") | F45: =IF($D45="","",MAX(0,$D45-$E45)) | G45: =IF($F45="","",IF($F45=0,0,MAX(0,RaporTarihi-$C45))) | H45: =IF($F45="","",IF($F45=0,"KAPALI",IF($G45<=0,"VADESİ GELMEMİŞ",IF($G45<=YaslamaDilim1,"1-"&TEXT(YaslamaDilim1,"0"),IF($G45<=YaslamaDilim2,TEXT(YaslamaDilim1+1,"0")&"-"&TEXT(YaslamaDilim2,"0"),IF($G45<=YaslamaDilim3,TEXT(YaslamaDilim2+1,"0")&"-"&TEXT(YaslamaDilim3,"0"),TEXT(YaslamaDilim3+1,"0")&"+")))))) | I45: =IF(FATURALAR!$L45=0,"",FATURALAR!$L45) | J45: =IF(FATURALAR!$M45=0,"",FATURALAR!$M45)

Sheet ANALITIK_MOTOR
A1: ANALITIK MOTOR — CARİ HESAP, TAHSİLAT VE MÜŞTERİ RİSK TAKİP SİSTEMİ
A3: ANALİTİK MOTOR — DERİNLİK KATMANI
A5: Kod | B5: Gösterge | C5: Değer | D5: Makine Yorumu
A6: T1 | B6: Vadesi Geçmiş Alacak | C6: =SUMIFS(tblYaslandirma[Açık Tutar],tblYaslandirma[Gecikme Günü],">0") | D6: =_xlfn.TEXTJOIN("; ",TRUE(),"Vadesi geçmiş alacak ",TEXT(C6,"₺ #,##0")," — bu tutar tahsilat planının birincil hedefidir")
A7: T2 | B7: Tahsilat Trend Ortalaması | C7: =AVERAGE(PANO!$H$16:$H$19) | D7: =_xlfn.TEXTJOIN("; ",TRUE(),"Aylık tahsilat ortalaması ",TEXT(C7,"₺ #,##0")," TL — eğilim bu seviyede seyrediyor")
A8: T3 | B8: En Yüksek Müşteri Yoğunlaşması | C8: =MAX(tblRisk[Yoğunlaşma Oranı]) | D8: =_xlfn.TEXTJOIN("; ",TRUE(),"En yüksek müşteri yoğunlaşması ",TEXT(C8,"0,0%")," — tek müşteriye aşırı bağımlılık risk taşır")
A9: T4 | B9: Dönemler Arası Tahsilat Farkı | C9: =PANO!$H$19-PANO!$H$16 | D9: =_xlfn.TEXTJOIN("; ",TRUE(),"Dönemler arası tahsilat farkı ",TEXT(C9,"₺ #,##0")," TL — artış nakit gücünü gösterir")
A10: T5 | B10: Mutabakat Farkı (Fatura-Tahsilat) | C10: =SUM(tblFaturalar[Net Fatura])-SUMIFS(tblTahsilatlar[Tahsilat Tutarı],tblTahsilatlar[Kesinleşti mi?],"Evet") | D10: =_xlfn.TEXTJOIN("; ",TRUE(),"Fatura ile kesin tahsilat arasındaki fark ",TEXT(C10,"₺ #,##0")," TL — bu tutar açık alacağın kaynağıdır")
A11: T6 | B11: Vadesi Geçmiş Kırılım Oranı | C11: =IF(SUM(tblYaslandirma[Açık Tutar])=0,0,SUMIFS(tblYaslandirma[Açık Tutar],tblYaslandirma[Gecikme Günü],">0")/SUM(tblYaslandirma[Açık Tutar])) | D11: =_xlfn.TEXTJOIN("; ",TRUE(),"Açık bakiyenin ",TEXT(C11,"0,0%")," i vadesi geçmiş — oran ",IF(C11>VadeGecikmeEsik,"yüksek, öncelikli aksiyon gerekli","kontrol altında"))
A12: O1 | B12: Aylık Tahsilat Sapması (MAD) | C12: =_xlfn.STDEV.P(PANO!$H$16:$H$19) | D12: =_xlfn.TEXTJOIN("; ",TRUE(),"Aylık tahsilat sapması ",TEXT(C12,"₺ #,##0")," TL — sapma yüksekse tahsilat öngörülemezdir")
A13: O2 | B13: Riskli Müşteri Sayısı | C13: =COUNTIF(tblRisk[Risk Skoru],">69") | D13: =_xlfn.TEXTJOIN("; ",TRUE(),"Risk skoru 70 üzeri ",C13," müşteri var — bu müşterilerin satışı teminata bağlanmalı")
A14: O3 | B14: Kötümser Senaryo Açık Bakiye | C14: =PANO!$B$6*(1+DuyarliOran) | D14: =_xlfn.TEXTJOIN("; ",TRUE(),"Kötümser senaryoda açık bakiye ",TEXT(C14,"₺ #,##0")," TL olur — tahsilat başarısı düşerse")
A15: O4 | B15: Nakit Dönüşüm Oranı | C15: =IF(SUM(tblFaturalar[Net Fatura])=0,0,SUMIFS(tblTahsilatlar[Tahsilat Tutarı],tblTahsilatlar[Kesinleşti mi?],"Evet")/SUM(tblFaturalar[Net Fatura])) | D15: =_xlfn.TEXTJOIN("; ",TRUE(),"Faturaların ",TEXT(C15,"0,0%")," i nakit tahsilata dönmüş — düşükse vade süresi uzun demektir")
A16: O5 | B16: Gecikme Maliyeti | C16: =IFERROR(SUMIFS(tblYaslandirma[Açık Tutar],tblYaslandirma[Gecikme Günü],">0")*FinansmanMaliyeti/365*AVERAGEIFS(tblYaslandirma[Gecikme Günü],tblYaslandirma[Gecikme Günü],">0"),0) | D16: =_xlfn.TEXTJOIN("; ",TRUE(),"Vadesi geçen alacakların finansman maliyeti ",TEXT(C16,"₺ #,##0")," TL — bu kayıp tahsilat hızlandırılarak azaltılabilir")
A17: O6 | B17: Yoğunlaşma Riski (HHI) | C17: =SUMPRODUCT(tblRisk[Yoğunlaşma Oranı],tblRisk[Yoğunlaşma Oranı]) | D17: =_xlfn.TEXTJOIN("; ",TRUE(),"HHI yoğunlaşma endeksi ",TEXT(C17,"0.000")," — 0,18 üzeri tek müşteri grubuna bağımlılık riskini gösterir")
A18: O8 | B18: Ortalama Veri Kalitesi Skoru | C18: =AVERAGE(tblRisk[Veri Kalitesi]) | D18: =_xlfn.TEXTJOIN("; ",TRUE(),"AVERAGE veri kalitesi ",TEXT(C18,"0")," puan — ",IF(C18>=KaliteSkorEsik,"yüksek güven","veri girişi tamamlanmalı"))
A19: I1 | B19: Tahsilat Trend Tahmini | C19: =TREND(PANO!$H$16:$H$19) | D19: =_xlfn.TEXTJOIN("; ",TRUE(),"Trend eğilim değeri ",TEXT(C19,"₺ #,##0")," TL — eğilim sürerse gelecek dönem tahsilatı bu yönde şekillenir")
A20: I2 | B20: Tahsilat Yüzdelik P90 | C20: =_xlfn.PERCENTILE.INC(PANO!$H$16:$H$19,P90Oran) | D20: =_xlfn.TEXTJOIN("; ",TRUE(),"Tahsilatların %90 i ",TEXT(C20,"₺ #,##0")," TL altında gerçekleşir — üst sınır bütçe için kullanılabilir")
A21: I7 | B21: Nakit Açığı (Tahsilat Hedefi) | C21: =SUM(tblYaslandirma[Açık Tutar])-SUMIFS(tblTahsilatlar[Tahsilat Tutarı],tblTahsilatlar[Kesinleşti mi?],"Evet") | D21: =_xlfn.TEXTJOIN("; ",TRUE(),"Kapatılması gereken nakit açığı ",TEXT(C21,"₺ #,##0")," TL — tahsilat hedefi bu tutarın tamamıdır")

Sheet MUSTERI_RISK_SKORU
A1: MUSTERI RISK SKORU — CARİ HESAP, TAHSİLAT VE MÜŞTERİ RİSK TAKİP SİSTEMİ
A3: MÜŞTERİ RİSK SKORU
A5: Müşteri Kodu | B5: Unvan | C5: Açık Bakiye | D5: Risk Limiti | E5: Kullanılabilir Limit | F5: Limit Kullanım Oranı | G5: Vadesi Geçmiş | H5: Vadesi Geçmiş Oranı | I5: Maks Gecikme Günü | J5: Teminat Değeri | K5: Net Risk | L5: Yoğunlaşma Oranı | M5: İtirazlı Tutar | N5: Gecikme Katkısı | O5: Vade Katkısı | P5: Limit Katkısı | Q5: Teminat Katkısı | R5: İtiraz Katkısı | S5: Statü Katkısı | T5: Veri Kalitesi | U5: Güven | V5: Karar | W5: Aksiyon | X5: Risk Skoru
A6: =MUSTERI_KARTLARI!$A6 | B6: =MUSTERI_KARTLARI!$B6 | C6: =SUMIFS(tblYaslandirma[Açık Tutar],tblYaslandirma[Müşteri Kodu],$A6) | D6: =MUSTERI_KARTLARI!$I6+MUSTERI_KARTLARI!$J6 | E6: =$D6-$C6 | F6: =IFERROR($C6/$D6,1) | G6: =SUMIFS(tblYaslandirma[Açık Tutar],tblYaslandirma[Müşteri Kodu],$A6,tblYaslandirma[Gecikme Günü],">0") | H6: =IF($C6=0,0,$G6/$C6) | I6: =_xlfn.MAXIFS(tblYaslandirma[Gecikme Günü],tblYaslandirma[Müşteri Kodu],$A6) | J6: =SUMIFS(tblTeminatlar[Kabul Edilen Değer],tblTeminatlar[Müşteri Kodu],$A6) | K6: =MAX(0,$C6-$J6) | L6: =IF(SUM(tblRisk[Açık Bakiye])=0,0,$C6/SUM(tblRisk[Açık Bakiye])) | M6: =SUMIFS(tblYaslandirma[İtirazlı Tutar],tblYaslandirma[Müşteri Kodu],$A6) | N6: =MIN(GecikmeMaxPuan,$I6/YaslamaDilim3*GecikmeMaxPuan) | O6: =MIN(VadeMaxPuan,$H6*VadeMaxPuan) | P6: =MIN(LimitMaxPuan,$F6*LimitMaxPuan) | Q6: =IF($C6=0,0,MIN(TeminatMaxPuan,$K6/$C6*TeminatMaxPuan)) | R6: =IF($C6=0,0,MIN(ItirazMaxPuan,$M6/$C6*ItirazMaxPuan)) | S6: =IF(MUSTERI_KARTLARI!$Q6="Askıda",StatufAskida,IF(MUSTERI_KARTLARI!$Q6="İzlemede",StatufIzleme,0)) | T6: =IF(MUSTERI_KARTLARI!$R6="OK",100,IF(MUSTERI_KARTLARI!$R6="EKSİK",VeriKalitesiEksik,0)) | U6: =IF($T6>=GuvenYuksek,"YÜKSEK",IF($T6>=GuvenOrta,"ORTA","DÜŞÜK")) | V6: =IF($X6<=EsikDevam,"DEVAM",IF($X6<=EsikIzle,"İZLE",IF($X6<=EsikLimitAzalt,"LİMİTİ AZALT",IF($X6<=EsikPesin,"PEŞİN / TEMİNATLI","VADELİ SATIŞI DURDUR")))) | W6: =IF($X6>EsikKritik,"Yönetim onayı AND acil tahsilat planı",IF($X6>EsikYuksek,"Yeni satışı teminata bağla",IF($X6>EsikIzle,"Limit revizyonu AND tahsilatı hızlandır","Planlı izleme"))) | X6: =ROUND(MIN(100,SUM($N6+$O6+$P6+$Q6+$R6+$S6)),0)
