Workbook
Name raporTarihi: AYARLAR!$B$6
Name odk_varsayilanCevrim: AYARLAR!$B$7
Name odk_esikOee: AYARLAR!$B$8
Name odk_esikDurusDk: AYARLAR!$B$9
Name odk_esikSaglik: AYARLAR!$B$10
Name odk_aylikCarpan: AYARLAR!$B$11
Name odk_senaryoTemkinli: AYARLAR!$B$12
Name odk_senaryoBaz: AYARLAR!$B$13
Name odk_senaryoIyimser: AYARLAR!$B$14
Name odk_tornadoOran: AYARLAR!$B$15
Name odk_yuzdelikOran: AYARLAR!$B$16
Name odk_percentileOran: AYARLAR!$B$17
Name odk_tahminCarpan: AYARLAR!$B$18
Name odk_olcekHedef: AYARLAR!$B$19
Name odk_kaliteTaban: AYARLAR!$B$20
Name odk_kaliteCeza: AYARLAR!$B$21
Name odk_kaliteSapma: AYARLAR!$B$22
Name odk_dosyaSurumu: AYARLAR!$B$23
Name odk_firmaUnvan: AYARLAR!$B$24
Name odk_alarmEsikMetin: AYARLAR!$B$25
Name odk_dakikaSn: AYARLAR!$B$26
Name odk_oeeReferans: AYARLAR!$B$27
Name odk_durusMaliyetTlDk: AYARLAR!$B$28
Name odk_doluKayit: AYARLAR!$I$32
Name odk_toplamDurus: AYARLAR!$I$33
Name odk_toplamUretim: AYARLAR!$I$34
Name odk_oeeOrani: AYARLAR!$I$35
Name odk_kullanilabilirlik: AYARLAR!$I$36
Name odk_performans: AYARLAR!$I$37
Name odk_kaliteOrani: AYARLAR!$I$38
Name odk_gunlukOeeOrt: AYARLAR!$I$39
Name odk_aylikDurusTrend: AYARLAR!$I$40
Name odk_saglikSkor: AYARLAR!$I$41
Name odk_alarmAdet: AYARLAR!$I$42
Name odk_yetimAdet: AYARLAR!$I$43
Name odk_oeeSapma: AYARLAR!$I$44
Name odk_tornadoZirve: AYARLAR!$I$45
Name odk_senaryoKarsilastirma: AYARLAR!$I$46
Name odk_hhi: AYARLAR!$I$47
Name odk_kaliteSkor: AYARLAR!$I$48
Name odk_senaryoMotor: AYARLAR!$I$49
Name odk_tahminAralik: AYARLAR!$I$50
Name odk_yuzdelikP90: AYARLAR!$I$51
Name odk_kokNedenKirilim: AYARLAR!$I$52
Name odk_sezonsalTrend: AYARLAR!$I$53
Name odk_alarmListesi: AYARLAR!$I$54
Name odk_kararKapi: AYARLAR!$I$55
Name odk_kararGerekce: AYARLAR!$I$56
Name odk_sonrakiKimlik: AYARLAR!$I$57
Name odk_yorumGunluk: AYARLAR!$I$60
Name odk_yorumAylik: AYARLAR!$I$61
Name odk_yorumSapma: AYARLAR!$I$62
Name odk_yorumTornado: AYARLAR!$I$63
Name odk_yorumSenaryo: AYARLAR!$I$64
Name odk_yorumHhi: AYARLAR!$I$65
Name odk_yorumKalite: AYARLAR!$I$66
Name odk_yorumSenMotor: AYARLAR!$I$67
Name odk_yorumTahmin: AYARLAR!$I$68
Name odk_yorumP90: AYARLAR!$I$69
Name ListeEvetHayir: LISTELER!$A$7:$A$8

Sheet KAPAK
A1: KAPAK — OEE & Duruş Kök-Neden Komutası
A3: OEE & Duruş Kök-Neden Komutası
A4: Üretim hatlarında günlük plan süre, duruş, üretim ve fire verisinden OEE'yi hesaplar; duruş kök-neden Pareto kırılımı ve varlık sağlık skoru üretir; UYGUN / DİKKAT / KRİTİK / VERİ YOK kararı verir.
A6: Bu ürün ne sağlar?
A7: • OEE = kullanılabilirlik × performans × kalite — tek formül, sabit skor yok
A8: • Günlük saha girişi en fazla 6 manuel alan — 30 saniye hedefi
A9: • Duruş kök-neden Pareto (ARIZA / AYAR / MALZEME / OPERATÖR / KALIP / BEKLEME)
A10: • 12 aylık sezonsal OEE-duruş zinciri ve alarm eşiği kuyruğu
A11: • Makrosuz, çevrimdışı; MES / SCADA API bağı yok
A13: Kimler için?
A14: • Vardiya / hat operatörü — günlük plan-duruş-üretim-fire-kök neden satırı
A15: • Üretim müdürü / OEE sahibi — OEE panosu ve karar
... A21: Sürüm 1.0.0 | Kod: ODK-PRO | Lisans: Tek kullanıcı | ExcelArşiv

Sheet VARLIKLAR
A1: VARLIKLAR — OEE & Duruş Kök-Neden Komutası
A3: Makine / hat kartları — her varlığın tek kimliği vardır
A4: Sonraki Kimlik | B4: =odk_sonrakiKimlik
A5: VarlikId | B5: MakineAd | C5: Hat | D5: IdealCevrim_sn | E5: VardiyaSure_dk | F5: HedefOee_oran | G5: Aktif | H5: ToplamDurus_dk | I5: OrtOee | J5: ToplamUretim_adet | K5: SaglikSkor
A6: MAK-00001 | B6: Pres Hat 1 | C6: HAT-A | D6: 12 | E6: 480 | F6: 0.75 | G6: EVET | H6: =IF($A6="","",SUMIF(tblGunluk[VarlikId],$A6,tblGunluk[DurusSure_dk])) | I6: =IF($A6="","",IFERROR(AVERAGEIF(tblGunluk[VarlikId],$A6,tblGunluk[FormulOee_oran]),0)) | J6: =IF($A6="","",SUMIF(tblGunluk[VarlikId],$A6,tblGunluk[UretimAdet_adet])) | K6: =IF($A6="","",MAX(0,MIN(100,odk_kaliteTaban-IF($I6<odk_esikOee,odk_kaliteCeza,0)-COUNTIFS(tblGunluk[VarlikId],$A6,tblGunluk[AlarmBayrak],"ALARM")*odk_kaliteSapma-IF($G6="HAYIR",odk_kaliteCeza,0))))
A7: MAK-00002 | B7: Torna CNC 2 | C7: HAT-A | D7: 45 | E7: 480 | F7: 0.72 | G7: EVET | H7: =IF($A7="","",SUMIF(tblGunluk[VarlikId],$A7,tblGunluk[DurusSure_dk])) | I7: =IF($A7="","",IFERROR(AVERAGEIF(tblGunluk[VarlikId],$A7,tblGunluk[FormulOee_oran]),0)) | J7: =IF($A7="","",SUMIF(tblGunluk[VarlikId],$A7,tblGunluk[UretimAdet_adet])) | K7: =IF($A7="","",MAX(0,MIN(100,odk_kaliteTaban-IF($I7<odk_esikOee,odk_kaliteCeza,0)-COUNTIFS(tblGunluk[VarlikId],$A7,tblGunluk[AlarmBayrak],"ALARM")*odk_kaliteSapma-IF($G7="HAYIR",odk_kaliteCeza,0))))
A8: MAK-00003 | B8: Montaj Hatti B | C8: HAT-B | D8: 18 | E8: 480 | F8: 0.78 | G8: EVET | H8: =IF($A8="","",SUMIF(tblGunluk[VarlikId],$A8,tblGunluk[DurusSure_dk])) | I8: =IF($A8="","",IFERROR(AVERAGEIF(tblGunluk[VarlikId],$A8,tblGunluk[FormulOee_oran]),0)) | J8: =IF($A8="","",SUMIF(tblGunluk[VarlikId],$A8,tblGunluk[UretimAdet_adet])) | K8: =IF($A8="","",MAX(0,MIN(100,odk_kaliteTaban-IF($I8<odk_esikOee,odk_kaliteCeza,0)-COUNTIFS(tblGunluk[VarlikId],$A8,tblGunluk[AlarmBayrak],"ALARM")*odk_kaliteSapma-IF($G8="HAYIR",odk_kaliteCeza,0))))
A9: MAK-00004 | B9: Kaynak Robot 4 | C9: HAT-B | D9: 30 | E9: 480 | F9: 0.7 | G9: EVET | H9: =IF($A9="","",SUMIF(tblGunluk[VarlikId],$A9,tblGunluk[DurusSure_dk])) | I9: =IF($A9="","",IFERROR(AVERAGEIF(tblGunluk[VarlikId],$A9,tblGunluk[FormulOee_oran]),0)) | J9: =IF($A9="","",SUMIF(tblGunluk[VarlikId],$A9,tblGunluk[UretimAdet_adet])) | K9: =IF($A9="","",MAX(0,MIN(100,odk_kaliteTaban-IF($I9<odk_esikOee,odk_kaliteCeza,0)-COUNTIFS(tblGunluk[VarlikId],$A9,tblGunluk[AlarmBayrak],"ALARM")*odk_kaliteSapma-IF($G9="HAYIR",odk_kaliteCeza,0))))
A10: MAK-00005 | B10: Enjeksiyon 5 | C10: HAT-C | D10: 22 | E10: 480 | F10: 0.74 | G10: EVET | H10: =IF($A10="","",SUMIF(tblGunluk[VarlikId],$A10,tblGunluk[DurusSure_dk])) | I10: =IF($A10="","",IFERROR(AVERAGEIF(tblGunluk[VarlikId],$A10,tblGunluk[FormulOee_oran]),0)) | J10: =IF($A10="","",SUMIF(tblGunluk[VarlikId],$A10,tblGunluk[UretimAdet_adet])) | K10: =IF($A10="","",MAX(0,MIN(100,odk_kaliteTaban-IF($I10<odk_esikOee,odk_kaliteCeza,0)-COUNTIFS(tblGunluk[VarlikId],$A10,tblGunluk[AlarmBayrak],"ALARM")*odk_kaliteSapma-IF($G10="HAYIR",odk_kaliteCeza,0))))
A11: MAK-00006 | B11: Paketleme 6 | C11: HAT-C | D11: 8 | E11: 480 | F11: 0.8 | G11: EVET | H11: =IF($A11="","",SUMIF(tblGunluk[VarlikId],$A11,tblGunluk[DurusSure_dk])) | I11: =IF($A11="","",IFERROR(AVERAGEIF(tblGunluk[VarlikId],$A11,tblGunluk[FormulOee_oran]),0)) | J11: =IF($A11="","",SUMIF(tblGunluk[VarlikId],$A11,tblGunluk[UretimAdet_adet])) | K11: =IF($A11="","",MAX(0,MIN(100,odk_kaliteTaban-IF($I11<odk_esikOee,odk_kaliteCeza,0)-COUNTIFS(tblGunluk[VarlikId],$A11,tblGunluk[AlarmBayrak],"ALARM")*odk_kaliteSapma-IF($G11="HAYIR",odk_kaliteCeza,0))))
A12: MAK-00007 | B12: Kesim Lazer 7 | C12: HAT-A | D12: 35 | E12: 480 | F12: 0.71 | G12: EVET | H12: =IF($A12="","",SUMIF(tblGunluk[VarlikId],$A12,tblGunluk[DurusSure_dk])) | I12: =IF($A12="","",IFERROR(AVERAGEIF(tblGunluk[VarlikId],$A12,tblGunluk[FormulOee_oran]),0)) | J12: =IF($A12="","",SUMIF(tblGunluk[VarlikId],$A12,tblGunluk[UretimAdet_adet])) | K12: =IF($A12="","",MAX(0,MIN(100,odk_kaliteTaban-IF($I12<odk_esikOee,odk_kaliteCeza,0)-COUNTIFS(tblGunluk[VarlikId],$A12,tblGunluk[AlarmBayrak],"ALARM")*odk_kaliteSapma-IF($G12="HAYIR",odk_kaliteCeza,0))))
A13: MAK-00008 | B13: Kalip Pres 8 | C13: HAT-B | D13: 15 | E13: 480 | F13: 0.76 | G13: EVET | H13: =IF($A13="","",SUMIF(tblGunluk[VarlikId],$A13,tblGunluk[DurusSure_dk])) | I13: =IF($A13="","",IFERROR(AVERAGEIF(tblGunluk[VarlikId],$A13,tblGunluk[FormulOee_oran]),0)) | J13: =IF($A13="","",SUMIF(tblGunluk[VarlikId],$A13,tblGunluk[UretimAdet_adet])) | K13: =IF($A13="","",MAX(0,MIN(100,odk_kaliteTaban-IF($I13<odk_esikOee,odk_kaliteCeza,0)-COUNTIFS(tblGunluk[VarlikId],$A13,tblGunluk[AlarmBayrak],"ALARM")*odk_kaliteSapma-IF($G13="HAYIR",odk_kaliteCeza,0))))
H14: =IF($A14="","",SUMIF(tblGunluk[VarlikId],$A14,tblGunluk[DurusSure_dk])) | I14: =IF($A14="","",IFERROR(AVERAGEIF(tblGunluk[VarlikId],$A14,tblGunluk[FormulOee_oran]),0)) | J14: =IF($A14="","",SUMIF(tblGunluk[VarlikId],$A14,tblGunluk[UretimAdet_adet])) | K14: =IF($A14="","",MAX(0,MIN(100,odk_kaliteTaban-IF($I14<odk_esikOee,odk_kaliteCeza,0)-COUNTIFS(tblGunluk[VarlikId],$A14,tblGunluk[AlarmBayrak],"ALARM")*odk_kaliteSapma-IF($G14="HAYIR",odk_kaliteCeza,0))))
H15: =IF($A15="","",SUMIF(tblGunluk[VarlikId],$A15,tblGunluk[DurusSure_dk])) | I15: =IF($A15="","",IFERROR(AVERAGEIF(tblGunluk[VarlikId],$A15,tblGunluk[FormulOee_oran]),0)) | J15: =IF($A15="","",SUMIF(tblGunluk[VarlikId],$A15,tblGunluk[UretimAdet_adet])) | K15: =IF($A15="","",MAX(0,MIN(100,odk_kaliteTaban-IF($I15<odk_esikOee,odk_kaliteCeza,0)-COUNTIFS(tblGunluk[VarlikId],$A15,tblGunluk[AlarmBayrak],"ALARM")*odk_kaliteSapma-IF($G15="HAYIR",odk_kaliteCeza,0))))
H16: =IF($A16="","",SUMIF(tblGunluk[VarlikId],$A16,tblGunluk[DurusSure_dk])) | I16: =IF($A16="","",IFERROR(AVERAGEIF(tblGunluk[VarlikId],$A16,tblGunluk[FormulOee_oran]),0)) | J16: =IF($A16="","",SUMIF(tblGunluk[VarlikId],$A16,tblGunluk[UretimAdet_adet])) | K16: =IF($A16="","",MAX(0,MIN(100,odk_kaliteTaban-IF($I16<odk_esikOee,odk_kaliteCeza,0)-COUNTIFS(tblGunluk[VarlikId],$A16,tblGunluk[AlarmBayrak],"ALARM")*odk_kaliteSapma-IF($G16="HAYIR",odk_kaliteCeza,0))))
H17: =IF($A17="","",SUMIF(tblGunluk[VarlikId],$A17,tblGunluk[DurusSure_dk])) | I17: =IF($A17="","",IFERROR(AVERAGEIF(tblGunluk[VarlikId],$A17,tblGunluk[FormulOee_oran]),0)) | J17: =IF($A17="","",SUMIF(tblGunluk[VarlikId],$A17,tblGunluk[UretimAdet_adet])) | K17: =IF($A17="","",MAX(0,MIN(100,odk_kaliteTaban-IF($I17<odk_esikOee,odk_kaliteCeza,0)-COUNTIFS(tblGunluk[VarlikId],$A17,tblGunluk[AlarmBayrak],"ALARM")*odk_kaliteSapma-IF($G17="HAYIR",odk_kaliteCeza,0))))
H18: =IF($A18="","",SUMIF(tblGunluk[VarlikId],$A18,tblGunluk[DurusSure_dk])) | I18: =IF($A18="","",IFERROR(AVERAGEIF(tblGunluk[VarlikId],$A18,tblGunluk[FormulOee_oran]),0)) | J18: =IF($A18="","",SUMIF(tblGunluk[VarlikId],$A18,tblGunluk[UretimAdet_adet])) | K18: =IF($A18="","",MAX(0,MIN(100,odk_kaliteTaban-IF($I18<odk_esikOee,odk_kaliteCeza,0)-COUNTIFS(tblGunluk[VarlikId],$A18,tblGunluk[AlarmBayrak],"ALARM")*odk_kaliteSapma-IF($G18="HAYIR",odk_kaliteCeza,0))))
H19: =IF($A19="","",SUMIF(tblGunluk[VarlikId],$A19,tblGunluk[DurusSure_dk])) | I19: =IF($A19="","",IFERROR(AVERAGEIF(tblGunluk[VarlikId],$A19,tblGunluk[FormulOee_oran]),0)) | J19: =IF($A19="","",SUMIF(tblGunluk[VarlikId],$A19,tblGunluk[UretimAdet_adet])) | K19: =IF($A19="","",MAX(0,MIN(100,odk_kaliteTaban-IF($I19<odk_esikOee,odk_kaliteCeza,0)-COUNTIFS(tblGunluk[VarlikId],$A19,tblGunluk[AlarmBayrak],"ALARM")*odk_kaliteSapma-IF($G19="HAYIR",odk_kaliteCeza,0))))
H20: =IF($A20="","",SUMIF(tblGunluk[VarlikId],$A20,tblGunluk[DurusSure_dk])) | I20: =IF($A20="","",IFERROR(AVERAGEIF(tblGunluk[VarlikId],$A20,tblGunluk[FormulOee_oran]),0)) | J20: =IF($A20="","",SUMIF(tblGunluk[VarlikId],$A20,tblGunluk[UretimAdet_adet])) | K20: =IF($A20="","",MAX(0,MIN(100,odk_kaliteTaban-IF($I20<odk_esikOee,odk_kaliteCeza,0)-COUNTIFS(tblGunluk[VarlikId],$A20,tblGunluk[AlarmBayrak],"ALARM")*odk_kaliteSapma-IF($G20="HAYIR",odk_kaliteCeza,0))))
H21: =IF($A21="","",SUMIF(tblGunluk[VarlikId],$A21,tblGunluk[DurusSure_dk])) | I21: =IF($A21="","",IFERROR(AVERAGEIF(tblGunluk[VarlikId],$A21,tblGunluk[FormulOee_oran]),0)) | J21: =IF($A21="","",SUMIF(tblGunluk[VarlikId],$A21,tblGunluk[UretimAdet_adet])) | K21: =IF($A21="","",MAX(0,MIN(100,odk_kaliteTaban-IF($I21<odk_esikOee,odk_kaliteCeza,0)-COUNTIFS(tblGunluk[VarlikId],$A21,tblGunluk[AlarmBayrak],"ALARM")*odk_kaliteSapma-IF($G21="HAYIR",odk_kaliteCeza,0))))
H22: =IF($A22="","",SUMIF(tblGunluk[VarlikId],$A22,tblGunluk[DurusSure_dk])) | I22: =IF($A22="","",IFERROR(AVERAGEIF(tblGunluk[VarlikId],$A22,tblGunluk[FormulOee_oran]),0)) | J22: =IF($A22="","",SUMIF(tblGunluk[VarlikId],$A22,tblGunluk[UretimAdet_adet])) | K22: =IF($A22="","",MAX(0,MIN(100,odk_kaliteTaban-IF($I22<odk_esikOee,odk_kaliteCeza,0)-COUNTIFS(tblGunluk[VarlikId],$A22,tblGunluk[AlarmBayrak],"ALARM")*odk_kaliteSapma-IF($G22="HAYIR",odk_kaliteCeza,0))))
H23: =IF($A23="","",SUMIF(tblGunluk[VarlikId],$A23,tblGunluk[DurusSure_dk])) | I23: =IF($A23="","",IFERROR(AVERAGEIF(tblGunluk[VarlikId],$A23,tblGunluk[FormulOee_oran]),0)) | J23: =IF($A23="","",SUMIF(tblGunluk[VarlikId],$A23,tblGunluk[UretimAdet_adet])) | K23: =IF($A23="","",MAX(0,MIN(100,odk_kaliteTaban-IF($I23<odk_esikOee,odk_kaliteCeza,0)-COUNTIFS(tblGunluk[VarlikId],$A23,tblGunluk[AlarmBayrak],"ALARM")*odk_kaliteSapma-IF($G23="HAYIR",odk_kaliteCeza,0))))
H24: =IF($A24="","",SUMIF(tblGunluk[VarlikId],$A24,tblGunluk[DurusSure_dk])) | I24: =IF($A24="","",IFERROR(AVERAGEIF(tblGunluk[VarlikId],$A24,tblGunluk[FormulOee_oran]),0)) | J24: =IF($A24="","",SUMIF(tblGunluk[VarlikId],$A24,tblGunluk[UretimAdet_adet])) | K24: =IF($A24="","",MAX(0,MIN(100,odk_kaliteTaban-IF($I24<odk_esikOee,odk_kaliteCeza,0)-COUNTIFS(tblGunluk[VarlikId],$A24,tblGunluk[AlarmBayrak],"ALARM")*odk_kaliteSapma-IF($G24="HAYIR",odk_kaliteCeza,0))))
H25: =IF($A25="","",SUMIF(tblGunluk[VarlikId],$A25,tblGunluk[DurusSure_dk])) | I25: =IF($A25="","",IFERROR(AVERAGEIF(tblGunluk[VarlikId],$A25,tblGunluk[FormulOee_oran]),0)) | J25: =IF($A25="","",SUMIF(tblGunluk[VarlikId],$A25,tblGunluk[UretimAdet_adet])) | K25: =IF($A25="","",MAX(0,MIN(100,odk_kaliteTaban-IF($I25<odk_esikOee,odk_kaliteCeza,0)-COUNTIFS(tblGunluk[VarlikId],$A25,tblGunluk[AlarmBayrak],"ALARM")*odk_kaliteSapma-IF($G25="HAYIR",odk_kaliteCeza,0))))
... H255: =IF($A255="","",SUMIF(tblGunluk[VarlikId],$A255,tblGunluk[DurusSure_dk])) | I255: =IF($A255="","",IFERROR(AVERAGEIF(tblGunluk[VarlikId],$A255,tblGunluk[FormulOee_oran]),0)) | J255: =IF($A255="","",SUMIF(tblGunluk[VarlikId],$A255,tblGunluk[UretimAdet_adet])) | K255: =IF($A255="","",MAX(0,MIN(100,odk_kaliteTaban-IF($I255<odk_esikOee,odk_kaliteCeza,0)-COUNTIFS(tblGunluk[VarlikId],$A255,tblGunluk[AlarmBayrak],"ALARM")*odk_kaliteSapma-IF($G255="HAYIR",odk_kaliteCeza,0))))

Sheet GUNLUK_GIRIS
A1: GUNLUK GIRIS — OEE & Duruş Kök-Neden Komutası
A3: GÜNLÜK saha girişi — satır başına en fazla 6 manuel alan (S02)
A5: SatirId | B5: VarlikId | C5: Tarih | D5: PlanSure_dk | E5: DurusSure_dk | F5: UretimAdet_adet | G5: FireAdet_adet | H5: KokNedenKodu | I5: FormulIdealCevrim_sn | J5: FormulCalisma_dk | K5: FormulKullanilabilirlik_oran | L5: FormulTeorikAdet_adet | M5: FormulPerformans_oran | N5: FormulKalite_oran | O5: FormulOee_oran | P5: FormulDurusPay_oran | Q5: SaglikSkor_puan | R5: AlarmBayrak | S5: FormulKayitDolu | T5: FormulYetim
A6: ODK-00001 | B6: MAK-00001 | C6: 46242 | D6: 480 | E6: 48 | F6: 1814 | G6: 45 | H6: AYAR | I6: =IF($A6="","",IFERROR(SUMIF(tblVarliklar[VarlikId],$B6,tblVarliklar[IdealCevrim_sn]),odk_varsayilanCevrim)) | J6: =IF($A6="","",IFERROR(MAX(0,$D6-$E6),0)) | K6: =IF($A6="","",IFERROR($J6/$D6,0)) | L6: =IF($A6="","",IFERROR($J6*odk_dakikaSn/$I6,0)) | M6: =IF($A6="","",IFERROR($F6/$L6,0)) | N6: =IF($A6="","",IFERROR(($F6-$G6)/$F6,0)) | O6: =IF($A6="","",IFERROR(N($K6)*N($M6)*N($N6),0)) | P6: =IF($A6="","",IFERROR($E6/$D6,0)) | Q6: =IF($A6="","",IFERROR(MAX(0,MIN(100,odk_kaliteTaban-IF(N($O6)<odk_esikOee,odk_kaliteCeza,0)-IF($E6>odk_esikDurusDk,odk_kaliteSapma,0)-IF($T6="YETIM",odk_kaliteCeza,0))),0)) | R6: =IF($A6="","",IF(OR(N($O6)<odk_esikOee,$E6>odk_esikDurusDk,N($Q6)<odk_esikSaglik),"ALARM","UYGUN")) | S6: =IF($A6="","",1) | T6: =IF($A6="","",IF(OR($B6="",COUNTIF(tblVarliklar[VarlikId],$B6)=0),"YETIM","TAMAM"))
A7: ODK-00002 | B7: MAK-00002 | C7: 46239 | D7: 480 | E7: 56 | F7: 486 | G7: 15 | H7: MALZEME | I7: =IF($A7="","",IFERROR(SUMIF(tblVarliklar[VarlikId],$B7,tblVarliklar[IdealCevrim_sn]),odk_varsayilanCevrim)) | J7: =IF($A7="","",IFERROR(MAX(0,$D7-$E7),0)) | K7: =IF($A7="","",IFERROR($J7/$D7,0)) | L7: =IF($A7="","",IFERROR($J7*odk_dakikaSn/$I7,0)) | M7: =IF($A7="","",IFERROR($F7/$L7,0)) | N7: =IF($A7="","",IFERROR(($F7-$G7)/$F7,0)) | O7: =IF($A7="","",IFERROR(N($K7)*N($M7)*N($N7),0)) | P7: =IF($A7="","",IFERROR($E7/$D7,0)) | Q7: =IF($A7="","",IFERROR(MAX(0,MIN(100,odk_kaliteTaban-IF(N($O7)<odk_esikOee,odk_kaliteCeza,0)-IF($E7>odk_esikDurusDk,odk_kaliteSapma,0)-IF($T7="YETIM",odk_kaliteCeza,0))),0)) | R7: =IF($A7="","",IF(OR(N($O7)<odk_esikOee,$E7>odk_esikDurusDk,N($Q7)<odk_esikSaglik),"ALARM","UYGUN")) | S7: =IF($A7="","",1) | T7: =IF($A7="","",IF(OR($B7="",COUNTIF(tblVarliklar[VarlikId],$B7)=0),"YETIM","TAMAM"))
A8: ODK-00003 | B8: MAK-00003 | C8: 46236 | D8: 480 | E8: 64 | F8: 1221 | G8: 43 | H8: OPERATOR | I8: =IF($A8="","",IFERROR(SUMIF(tblVarliklar[VarlikId],$B8,tblVarliklar[IdealCevrim_sn]),odk_varsayilanCevrim)) | J8: =IF($A8="","",IFERROR(MAX(0,$D8-$E8),0)) | K8: =IF($A8="","",IFERROR($J8/$D8,0)) | L8: =IF($A8="","",IFERROR($J8*odk_dakikaSn/$I8,0)) | M8: =IF($A8="","",IFERROR($F8/$L8,0)) | N8: =IF($A8="","",IFERROR(($F8-$G8)/$F8,0)) | O8: =IF($A8="","",IFERROR(N($K8)*N($M8)*N($N8),0)) | P8: =IF($A8="","",IFERROR($E8/$D8,0)) | Q8: =IF($A8="","",IFERROR(MAX(0,MIN(100,odk_kaliteTaban-IF(N($O8)<odk_esikOee,odk_kaliteCeza,0)-IF($E8>odk_esikDurusDk,odk_kaliteSapma,0)-IF($T8="YETIM",odk_kaliteCeza,0))),0)) | R8: =IF($A8="","",IF(OR(N($O8)<odk_esikOee,$E8>odk_esikDurusDk,N($Q8)<odk_esikSaglik),"ALARM","UYGUN")) | S8: =IF($A8="","",1) | T8: =IF($A8="","",IF(OR($B8="",COUNTIF(tblVarliklar[VarlikId],$B8)=0),"YETIM","TAMAM"))
A9: ODK-00004 | B9: MAK-00004 | C9: 46233 | D9: 480 | E9: 72 | F9: 734 | G9: 15 | H9: KALIP | I9: =IF($A9="","",IFERROR(SUMIF(tblVarliklar[VarlikId],$B9,tblVarliklar[IdealCevrim_sn]),odk_varsayilanCevrim)) | J9: =IF($A9="","",IFERROR(MAX(0,$D9-$E9),0)) | K9: =IF($A9="","",IFERROR($J9/$D9,0)) | L9: =IF($A9="","",IFERROR($J9*odk_dakikaSn/$I9,0)) | M9: =IF($A9="","",IFERROR($F9/$L9,0)) | N9: =IF($A9="","",IFERROR(($F9-$G9)/$F9,0)) | O9: =IF($A9="","",IFERROR(N($K9)*N($M9)*N($N9),0)) | P9: =IF($A9="","",IFERROR($E9/$D9,0)) | Q9: =IF($A9="","",IFERROR(MAX(0,MIN(100,odk_kaliteTaban-IF(N($O9)<odk_esikOee,odk_kaliteCeza,0)-IF($E9>odk_esikDurusDk,odk_kaliteSapma,0)-IF($T9="YETIM",odk_kaliteCeza,0))),0)) | R9: =IF($A9="","",IF(OR(N($O9)<odk_esikOee,$E9>odk_esikDurusDk,N($Q9)<odk_esikSaglik),"ALARM","UYGUN")) | S9: =IF($A9="","",1) | T9: =IF($A9="","",IF(OR($B9="",COUNTIF(tblVarliklar[VarlikId],$B9)=0),"YETIM","TAMAM"))
A10: ODK-00005 | B10: MAK-00005 | C10: 46230 | D10: 480 | E10: 80 | F10: 895 | G10: 22 | H10: BEKLEME | I10: =IF($A10="","",IFERROR(SUMIF(tblVarliklar[VarlikId],$B10,tblVarliklar[IdealCevrim_sn]),odk_varsayilanCevrim)) | J10: =IF($A10="","",IFERROR(MAX(0,$D10-$E10),0)) | K10: =IF($A10="","",IFERROR($J10/$D10,0)) | L10: =IF($A10="","",IFERROR($J10*odk_dakikaSn/$I10,0)) | M10: =IF($A10="","",IFERROR($F10/$L10,0)) | N10: =IF($A10="","",IFERROR(($F10-$G10)/$F10,0)) | O10: =IF($A10="","",IFERROR(N($K10)*N($M10)*N($N10),0)) | P10: =IF($A10="","",IFERROR($E10/$D10,0)) | Q10: =IF($A10="","",IFERROR(MAX(0,MIN(100,odk_kaliteTaban-IF(N($O10)<odk_esikOee,odk_kaliteCeza,0)-IF($E10>odk_esikDurusDk,odk_kaliteSapma,0)-IF($T10="YETIM",odk_kaliteCeza,0))),0)) | R10: =IF($A10="","",IF(OR(N($O10)<odk_esikOee,$E10>odk_esikDurusDk,N($Q10)<odk_esikSaglik),"ALARM","UYGUN")) | S10: =IF($A10="","",1) | T10: =IF($A10="","",IF(OR($B10="",COUNTIF(tblVarliklar[VarlikId],$B10)=0),"YETIM","TAMAM"))
A11: ODK-00006 | B11: MAK-00006 | C11: 46227 | D11: 480 | E11: 88 | F11: 2470 | G11: 74 | H11: DIGER | I11: =IF($A11="","",IFERROR(SUMIF(tblVarliklar[VarlikId],$B11,tblVarliklar[IdealCevrim_sn]),odk_varsayilanCevrim)) | J11: =IF($A11="","",IFERROR(MAX(0,$D11-$E11),0)) | K11: =IF($A11="","",IFERROR($J11/$D11,0)) | L11: =IF($A11="","",IFERROR($J11*odk_dakikaSn/$I11,0)) | M11: =IF($A11="","",IFERROR($F11/$L11,0)) | N11: =IF($A11="","",IFERROR(($F11-$G11)/$F11,0)) | O11: =IF($A11="","",IFERROR(N($K11)*N($M11)*N($N11),0)) | P11: =IF($A11="","",IFERROR($E11/$D11,0)) | Q11: =IF($A11="","",IFERROR(MAX(0,MIN(100,odk_kaliteTaban-IF(N($O11)<odk_esikOee,odk_kaliteCeza,0)-IF($E11>odk_esikDurusDk,odk_kaliteSapma,0)-IF($T11="YETIM",odk_kaliteCeza,0))),0)) | R11: =IF($A11="","",IF(OR(N($O11)<odk_esikOee,$E11>odk_esikDurusDk,N($Q11)<odk_esikSaglik),"ALARM","UYGUN")) | S11: =IF($A11="","",1) | T11: =IF($A11="","",IF(OR($B11="",COUNTIF(tblVarliklar[VarlikId],$B11)=0),"YETIM","TAMAM"))
A12: ODK-00007 | B12: MAK-00007 | C12: 46224 | D12: 480 | E12: 40 | F12: 648 | G12: 23 | H12: ARIZA | I12: =IF($A12="","",IFERROR(SUMIF(tblVarliklar[VarlikId],$B12,tblVarliklar[IdealCevrim_sn]),odk_varsayilanCevrim)) | J12: =IF($A12="","",IFERROR(MAX(0,$D12-$E12),0)) | K12: =IF($A12="","",IFERROR($J12/$D12,0)) | L12: =IF($A12="","",IFERROR($J12*odk_dakikaSn/$I12,0)) | M12: =IF($A12="","",IFERROR($F12/$L12,0)) | N12: =IF($A12="","",IFERROR(($F12-$G12)/$F12,0)) | O12: =IF($A12="","",IFERROR(N($K12)*N($M12)*N($N12),0)) | P12: =IF($A12="","",IFERROR($E12/$D12,0)) | Q12: =IF($A12="","",IFERROR(MAX(0,MIN(100,odk_kaliteTaban-IF(N($O12)<odk_esikOee,odk_kaliteCeza,0)-IF($E12>odk_esikDurusDk,odk_kaliteSapma,0)-IF($T12="YETIM",odk_kaliteCeza,0))),0)) | R12: =IF($A12="","",IF(OR(N($O12)<odk_esikOee,$E12>odk_esikDurusDk,N($Q12)<odk_esikSaglik),"ALARM","UYGUN")) | S12: =IF($A12="","",1) | T12: =IF($A12="","",IF(OR($B12="",COUNTIF(tblVarliklar[VarlikId],$B12)=0),"YETIM","TAMAM"))
A13: ODK-00008 | B13: MAK-00008 | C13: 46221 | D13: 480 | E13: 48 | F13: 1521 | G13: 30 | H13: AYAR | I13: =IF($A13="","",IFERROR(SUMIF(tblVarliklar[VarlikId],$B13,tblVarliklar[IdealCevrim_sn]),odk_varsayilanCevrim)) | J13: =IF($A13="","",IFERROR(MAX(0,$D13-$E13),0)) | K13: =IF($A13="","",IFERROR($J13/$D13,0)) | L13: =IF($A13="","",IFERROR($J13*odk_dakikaSn/$I13,0)) | M13: =IF($A13="","",IFERROR($F13/$L13,0)) | N13: =IF($A13="","",IFERROR(($F13-$G13)/$F13,0)) | O13: =IF($A13="","",IFERROR(N($K13)*N($M13)*N($N13),0)) | P13: =IF($A13="","",IFERROR($E13/$D13,0)) | Q13: =IF($A13="","",IFERROR(MAX(0,MIN(100,odk_kaliteTaban-IF(N($O13)<odk_esikOee,odk_kaliteCeza,0)-IF($E13>odk_esikDurusDk,odk_kaliteSapma,0)-IF($T13="YETIM",odk_kaliteCeza,0))),0)) | R13: =IF($A13="","",IF(OR(N($O13)<odk_esikOee,$E13>odk_esikDurusDk,N($Q13)<odk_esikSaglik),"ALARM","UYGUN")) | S13: =IF($A13="","",1) | T13: =IF($A13="","",IF(OR($B13="",COUNTIF(tblVarliklar[VarlikId],$B13)=0),"YETIM","TAMAM"))
A14: ODK-00009 | B14: MAK-00001 | C14: 46218 | D14: 480 | E14: 56 | F14: 1908 | G14: 48 | H14: MALZEME | I14: =IF($A14="","",IFERROR(SUMIF(tblVarliklar[VarlikId],$B14,tblVarliklar[IdealCevrim_sn]),odk_varsayilanCevrim)) | J14: =IF($A14="","",IFERROR(MAX(0,$D14-$E14),0)) | K14: =IF($A14="","",IFERROR($J14/$D14,0)) | L14: =IF($A14="","",IFERROR($J14*odk_dakikaSn/$I14,0)) | M14: =IF($A14="","",IFERROR($F14/$L14,0)) | N14: =IF($A14="","",IFERROR(($F14-$G14)/$F14,0)) | O14: =IF($A14="","",IFERROR(N($K14)*N($M14)*N($N14),0)) | P14: =IF($A14="","",IFERROR($E14/$D14,0)) | Q14: =IF($A14="","",IFERROR(MAX(0,MIN(100,odk_kaliteTaban-IF(N($O14)<odk_esikOee,odk_kaliteCeza,0)-IF($E14>odk_esikDurusDk,odk_kaliteSapma,0)-IF($T14="YETIM",odk_kaliteCeza,0))),0)) | R14: =IF($A14="","",IF(OR(N($O14)<odk_esikOee,$E14>odk_esikDurusDk,N($Q14)<odk_esikSaglik),"ALARM","UYGUN")) | S14: =IF($A14="","",1) | T14: =IF($A14="","",IF(OR($B14="",COUNTIF(tblVarliklar[VarlikId],$B14)=0),"YETIM","TAMAM"))
A15: ODK-00010 | B15: MAK-00002 | C15: 46215 | D15: 480 | E15: 64 | F15: 455 | G15: 14 | H15: OPERATOR | I15: =IF($A15="","",IFERROR(SUMIF(tblVarliklar[VarlikId],$B15,tblVarliklar[IdealCevrim_sn]),odk_varsayilanCevrim)) | J15: =IF($A15="","",IFERROR(MAX(0,$D15-$E15),0)) | K15: =IF($A15="","",IFERROR($J15/$D15,0)) | L15: =IF($A15="","",IFERROR($J15*odk_dakikaSn/$I15,0)) | M15: =IF($A15="","",IFERROR($F15/$L15,0)) | N15: =IF($A15="","",IFERROR(($F15-$G15)/$F15,0)) | O15: =IF($A15="","",IFERROR(N($K15)*N($M15)*N($N15),0)) | P15: =IF($A15="","",IFERROR($E15/$D15,0)) | Q15: =IF($A15="","",IFERROR(MAX(0,MIN(100,odk_kaliteTaban-IF(N($O15)<odk_esikOee,odk_kaliteCeza,0)-IF($E15>odk_esikDurusDk,odk_kaliteSapma,0)-IF($T15="YETIM",odk_kaliteCeza,0))),0)) | R15: =IF($A15="","",IF(OR(N($O15)<odk_esikOee,$E15>odk_esikDurusDk,N($Q15)<odk_esikSaglik),"ALARM","UYGUN")) | S15: =IF($A15="","",1) | T15: =IF($A15="","",IF(OR($B15="",COUNTIF(tblVarliklar[VarlikId],$B15)=0),"YETIM","TAMAM"))
A16: ODK-00011 | B16: MAK-00003 | C16: 46212 | D16: 480 | E16: 72 | F16: 1142 | G16: 40 | H16: KALIP | I16: =IF($A16="","",IFERROR(SUMIF(tblVarliklar[VarlikId],$B16,tblVarliklar[IdealCevrim_sn]),odk_varsayilanCevrim)) | J16: =IF($A16="","",IFERROR(MAX(0,$D16-$E16),0)) | K16: =IF($A16="","",IFERROR($J16/$D16,0)) | L16: =IF($A16="","",IFERROR($J16*odk_dakikaSn/$I16,0)) | M16: =IF($A16="","",IFERROR($F16/$L16,0)) | N16: =IF($A16="","",IFERROR(($F16-$G16)/$F16,0)) | O16: =IF($A16="","",IFERROR(N($K16)*N($M16)*N($N16),0)) | P16: =IF($A16="","",IFERROR($E16/$D16,0)) | Q16: =IF($A16="","",IFERROR(MAX(0,MIN(100,odk_kaliteTaban-IF(N($O16)<odk_esikOee,odk_kaliteCeza,0)-IF($E16>odk_esikDurusDk,odk_kaliteSapma,0)-IF($T16="YETIM",odk_kaliteCeza,0))),0)) | R16: =IF($A16="","",IF(OR(N($O16)<odk_esikOee,$E16>odk_esikDurusDk,N($Q16)<odk_esikSaglik),"ALARM","UYGUN")) | S16: =IF($A16="","",1) | T16: =IF($A16="","",IF(OR($B16="",COUNTIF(tblVarliklar[VarlikId],$B16)=0),"YETIM","TAMAM"))
A17: ODK-00012 | B17: MAK-00004 | C17: 46209 | D17: 480 | E17: 180 | F17: 330 | G17: 26 | H17: BEKLEME | I17: =IF($A17="","",IFERROR(SUMIF(tblVarliklar[VarlikId],$B17,tblVarliklar[IdealCevrim_sn]),odk_varsayilanCevrim)) | J17: =IF($A17="","",IFERROR(MAX(0,$D17-$E17),0)) | K17: =IF($A17="","",IFERROR($J17/$D17,0)) | L17: =IF($A17="","",IFERROR($J17*odk_dakikaSn/$I17,0)) | M17: =IF($A17="","",IFERROR($F17/$L17,0)) | N17: =IF($A17="","",IFERROR(($F17-$G17)/$F17,0)) | O17: =IF($A17="","",IFERROR(N($K17)*N($M17)*N($N17),0)) | P17: =IF($A17="","",IFERROR($E17/$D17,0)) | Q17: =IF($A17="","",IFERROR(MAX(0,MIN(100,odk_kaliteTaban-IF(N($O17)<odk_esikOee,odk_kaliteCeza,0)-IF($E17>odk_esikDurusDk,odk_kaliteSapma,0)-IF($T17="YETIM",odk_kaliteCeza,0))),0)) | R17: =IF($A17="","",IF(OR(N($O17)<odk_esikOee,$E17>odk_esikDurusDk,N($Q17)<odk_esikSaglik),"ALARM","UYGUN")) | S17: =IF($A17="","",1) | T17: =IF($A17="","",IF(OR($B17="",COUNTIF(tblVarliklar[VarlikId],$B17)=0),"YETIM","TAMAM"))
... A34: ODK-00029 | B34: MAK-00005 | C34: 46158 | D34: 480 | E34: 48 | F34: 1060 | G34: 26 | H34: AYAR | I34: =IF($A34="","",IFERROR(SUMIF(tblVarliklar[VarlikId],$B34,tblVarliklar[IdealCevrim_sn]),odk_varsayilanCevrim)) | J34: =IF($A34="","",IFERROR(MAX(0,$D34-$E34),0)) | K34: =IF($A34="","",IFERROR($J34/$D34,0)) | L34: =IF($A34="","",IFERROR($J34*odk_dakikaSn/$I34,0)) | M34: =IF($A34="","",IFERROR($F34/$L34,0)) | N34: =IF($A34="","",IFERROR(($F34-$G34)/$F34,0)) | O34: =IF($A34="","",IFERROR(N($K34)*N($M34)*N($N34),0)) | P34: =IF($A34="","",IFERROR($E34/$D34,0)) | Q34: =IF($A34="","",IFERROR(MAX(0,MIN(100,odk_kaliteTaban-IF(N($O34)<odk_esikOee,odk_kaliteCeza,0)-IF($E34>odk_esikDurusDk,odk_kaliteSapma,0)-IF($T34="YETIM",odk_kaliteCeza,0))),0)) | R34: =IF($A34="","",IF(OR(N($O34)<odk_esikOee,$E34>odk_esikDurusDk,N($Q34)<odk_esikSaglik),"ALARM","UYGUN")) | S34: =IF($A34="","",1) | T34: =IF($A34="","",IF(OR($B34="",COUNTIF(tblVarliklar[VarlikId],$B34)=0),"YETIM","TAMAM"))
A35: ODK-00030 | C35: 46155 | D35: 480 | E35: 56 | F35: 2608 | G35: 78 | H35: MALZEME | I35: =IF($A35="","",IFERROR(SUMIF(tblVarliklar[VarlikId],$B35,tblVarliklar[IdealCevrim_sn]),odk_varsayilanCevrim)) | J35: =IF($A35="","",IFERROR(MAX(0,$D35-$E35),0)) | K35: =IF($A35="","",IFERROR($J35/$D35,0)) | L35: =IF($A35="","",IFERROR($J35*odk_dakikaSn/$I35,0)) | M35: =IF($A35="","",IFERROR($F35/$L35,0)) | N35: =IF($A35="","",IFERROR(($F35-$G35)/$F35,0)) | O35: =IF($A35="","",IFERROR(N($K35)*N($M35)*N($N35),0)) | P35: =IF($A35="","",IFERROR($E35/$D35,0)) | Q35: =IF($A35="","",IFERROR(MAX(0,MIN(100,odk_kaliteTaban-IF(N($O35)<odk_esikOee,odk_kaliteCeza,0)-IF($E35>odk_esikDurusDk,odk_kaliteSapma,0)-IF($T35="YETIM",odk_kaliteCeza,0))),0)) | R35: =IF($A35="","",IF(OR(N($O35)<odk_esikOee,$E35>odk_esikDurusDk,N($Q35)<odk_esikSaglik),"ALARM","UYGUN")) | S35: =IF($A35="","",1) | T35: =IF($A35="","",IF(OR($B35="",COUNTIF(tblVarliklar[VarlikId],$B35)=0),"YETIM","TAMAM"))
A36: ODK-00031 | B36: MAK-00007 | C36: 46152 | D36: 480 | E36: 64 | F36: 599 | G36: 21 | H36: OPERATOR | I36: =IF($A36="","",IFERROR(SUMIF(tblVarliklar[VarlikId],$B36,tblVarliklar[IdealCevrim_sn]),odk_varsayilanCevrim)) | J36: =IF($A36="","",IFERROR(MAX(0,$D36-$E36),0)) | K36: =IF($A36="","",IFERROR($J36/$D36,0)) | L36: =IF($A36="","",IFERROR($J36*odk_dakikaSn/$I36,0)) | M36: =IF($A36="","",IFERROR($F36/$L36,0)) | N36: =IF($A36="","",IFERROR(($F36-$G36)/$F36,0)) | O36: =IF($A36="","",IFERROR(N($K36)*N($M36)*N($N36),0)) | P36: =IF($A36="","",IFERROR($E36/$D36,0)) | Q36: =IF($A36="","",IFERROR(MAX(0,MIN(100,odk_kaliteTaban-IF(N($O36)<odk_esikOee,odk_kaliteCeza,0)-IF($E36>odk_esikDurusDk,odk_kaliteSapma,0)-IF($T36="YETIM",odk_kaliteCeza,0))),0)) | R36: =IF($A36="","",IF(OR(N($O36)<odk_esikOee,$E36>odk_esikDurusDk,N($Q36)<odk_esikSaglik),"ALARM","UYGUN")) | S36: =IF($A36="","",1) | T36: =IF($A36="","",IF(OR($B36="",COUNTIF(tblVarliklar[VarlikId],$B36)=0),"YETIM","TAMAM"))
A37: ODK-00032 | B37: MAK-00008 | C37: 46149 | D37: 480 | E37: 72 | F37: 1404 | G37: 28 | H37: KALIP | I37: =IF($A37="","",IFERROR(SUMIF(tblVarliklar[VarlikId],$B37,tblVarliklar[IdealCevrim_sn]),odk_varsayilanCevrim)) | J37: =IF($A37="","",IFERROR(MAX(0,$D37-$E37),0)) | K37: =IF($A37="","",IFERROR($J37/$D37,0)) | L37: =IF($A37="","",IFERROR($J37*odk_dakikaSn/$I37,0)) | M37: =IF($A37="","",IFERROR($F37/$L37,0)) | N37: =IF($A37="","",IFERROR(($F37-$G37)/$F37,0)) | O37: =IF($A37="","",IFERROR(N($K37)*N($M37)*N($N37),0)) | P37: =IF($A37="","",IFERROR($E37/$D37,0)) | Q37: =IF($A37="","",IFERROR(MAX(0,MIN(100,odk_kaliteTaban-IF(N($O37)<odk_esikOee,odk_kaliteCeza,0)-IF($E37>odk_esikDurusDk,odk_kaliteSapma,0)-IF($T37="YETIM",odk_kaliteCeza,0))),0)) | R37: =IF($A37="","",IF(OR(N($O37)<odk_esikOee,$E37>odk_esikDurusDk,N($Q37)<odk_esikSaglik),"ALARM","UYGUN")) | S37: =IF($A37="","",1) | T37: =IF($A37="","",IF(OR($B37="",COUNTIF(tblVarliklar[VarlikId],$B37)=0),"YETIM","TAMAM"))
A38: ODK-00033 | B38: MAK-99999 | C38: 46146 | D38: 480 | E38: 80 | F38: 1760 | G38: 44 | H38: BEKLEME | I38: =IF($A38="","",IFERROR(SUMIF(tblVarliklar[VarlikId],$B38,tblVarliklar[IdealCevrim_sn]),odk_varsayilanCevrim)) | J38: =IF($A38="","",IFERROR(MAX(0,$D38-$E38),0)) | K38: =IF($A38="","",IFERROR($J38/$D38,0)) | L38: =IF($A38="","",IFERROR($J38*odk_dakikaSn/$I38,0)) | M38: =IF($A38="","",IFERROR($F38/$L38,0)) | N38: =IF($A38="","",IFERROR(($F38-$G38)/$F38,0)) | O38: =IF($A38="","",IFERROR(N($K38)*N($M38)*N($N38),0)) | P38: =IF($A38="","",IFERROR($E38/$D38,0)) | Q38: =IF($A38="","",IFERROR(MAX(0,MIN(100,odk_kaliteTaban-IF(N($O38)<odk_esikOee,odk_kaliteCeza,0)-IF($E38>odk_esikDurusDk,odk_kaliteSapma,0)-IF($T38="YETIM",odk_kaliteCeza,0))),0)) | R38: =IF($A38="","",IF(OR(N($O38)<odk_esikOee,$E38>odk_esikDurusDk,N($Q38)<odk_esikSaglik),"ALARM","UYGUN")) | S38: =IF($A38="","",1) | T38: =IF($A38="","",IF(OR($B38="",COUNTIF(tblVarliklar[VarlikId],$B38)=0),"YETIM","TAMAM"))
A39: ODK-00034 | B39: MAK-00002 | C39: 46143 | D39: 480 | E39: 88 | F39: 471 | G39: 14 | H39: DIGER | I39: =IF($A39="","",IFERROR(SUMIF(tblVarliklar[VarlikId],$B39,tblVarliklar[IdealCevrim_sn]),odk_varsayilanCevrim)) | J39: =IF($A39="","",IFERROR(MAX(0,$D39-$E39),0)) | K39: =IF($A39="","",IFERROR($J39/$D39,0)) | L39: =IF($A39="","",IFERROR($J39*odk_dakikaSn/$I39,0)) | M39: =IF($A39="","",IFERROR($F39/$L39,0)) | N39: =IF($A39="","",IFERROR(($F39-$G39)/$F39,0)) | O39: =IF($A39="","",IFERROR(N($K39)*N($M39)*N($N39),0)) | P39: =IF($A39="","",IFERROR($E39/$D39,0)) | Q39: =IF($A39="","",IFERROR(MAX(0,MIN(100,odk_kaliteTaban-IF(N($O39)<odk_esikOee,odk_kaliteCeza,0)-IF($E39>odk_esikDurusDk,odk_kaliteSapma,0)-IF($T39="YETIM",odk_kaliteCeza,0))),0)) | R39: =IF($A39="","",IF(OR(N($O39)<odk_esikOee,$E39>odk_esikDurusDk,N($Q39)<odk_esikSaglik),"ALARM","UYGUN")) | S39: =IF($A39="","",1) | T39: =IF($A39="","",IF(OR($B39="",COUNTIF(tblVarliklar[VarlikId],$B39)=0),"YETIM","TAMAM"))
A40: ODK-00035 | B40: MAK-00003 | C40: 46140 | D40: 480 | E40: 40 | F40: 1203 | G40: 42 | H40: ARIZA | I40: =IF($A40="","",IFERROR(SUMIF(tblVarliklar[VarlikId],$B40,tblVarliklar[IdealCevrim_sn]),odk_varsayilanCevrim)) | J40: =IF($A40="","",IFERROR(MAX(0,$D40-$E40),0)) | K40: =IF($A40="","",IFERROR($J40/$D40,0)) | L40: =IF($A40="","",IFERROR($J40*odk_dakikaSn/$I40,0)) | M40: =IF($A40="","",IFERROR($F40/$L40,0)) | N40: =IF($A40="","",IFERROR(($F40-$G40)/$F40,0)) | O40: =IF($A40="","",IFERROR(N($K40)*N($M40)*N($N40),0)) | P40: =IF($A40="","",IFERROR($E40/$D40,0)) | Q40: =IF($A40="","",IFERROR(MAX(0,MIN(100,odk_kaliteTaban-IF(N($O40)<odk_esikOee,odk_kaliteCeza,0)-IF($E40>odk_esikDurusDk,odk_kaliteSapma,0)-IF($T40="YETIM",odk_kaliteCeza,0))),0)) | R40: =IF($A40="","",IF(OR(N($O40)<odk_esikOee,$E40>odk_esikDurusDk,N($Q40)<odk_esikSaglik),"ALARM","UYGUN")) | S40: =IF($A40="","",1) | T40: =IF($A40="","",IF(OR($B40="",COUNTIF(tblVarliklar[VarlikId],$B40)=0),"YETIM","TAMAM"))
A41: ODK-00036 | B41: MAK-00004 | C41: 46137 | D41: 480 | E41: 48 | F41: 726 | G41: 15 | H41: AYAR | I41: =IF($A41="","",IFERROR(SUMIF(tblVarliklar[VarlikId],$B41,tblVarliklar[IdealCevrim_sn]),odk_varsayilanCevrim)) | J41: =IF($A41="","",IFERROR(MAX(0,$D41-$E41),0)) | K41: =IF($A41="","",IFERROR($J41/$D41,0)) | L41: =IF($A41="","",IFERROR($J41*odk_dakikaSn/$I41,0)) | M41: =IF($A41="","",IFERROR($F41/$L41,0)) | N41: =IF($A41="","",IFERROR(($F41-$G41)/$F41,0)) | O41: =IF($A41="","",IFERROR(N($K41)*N($M41)*N($N41),0)) | P41: =IF($A41="","",IFERROR($E41/$D41,0)) | Q41: =IF($A41="","",IFERROR(MAX(0,MIN(100,odk_kaliteTaban-IF(N($O41)<odk_esikOee,odk_kaliteCeza,0)-IF($E41>odk_esikDurusDk,odk_kaliteSapma,0)-IF($T41="YETIM",odk_kaliteCeza,0))),0)) | R41: =IF($A41="","",IF(OR(N($O41)<odk_esikOee,$E41>odk_esikDurusDk,N($Q41)<odk_esikSaglik),"ALARM","UYGUN")) | S41: =IF($A41="","",1) | T41: =IF($A41="","",IF(OR($B41="",COUNTIF(tblVarliklar[VarlikId],$B41)=0),"YETIM","TAMAM"))
I42: =IF($A42="","",IFERROR(SUMIF(tblVarliklar[VarlikId],$B42,tblVarliklar[IdealCevrim_sn]),odk_varsayilanCevrim)) | J42: =IF($A42="","",IFERROR(MAX(0,$D42-$E42),0)) | K42: =IF($A42="","",IFERROR($J42/$D42,0)) | L42: =IF($A42="","",IFERROR($J42*odk_dakikaSn/$I42,0)) | M42: =IF($A42="","",IFERROR($F42/$L42,0)) | N42: =IF($A42="","",IFERROR(($F42-$G42)/$F42,0)) | O42: =IF($A42="","",IFERROR(N($K42)*N($M42)*N($N42),0)) | P42: =IF($A42="","",IFERROR($E42/$D42,0)) | Q42: =IF($A42="","",IFERROR(MAX(0,MIN(100,odk_kaliteTaban-IF(N($O42)<odk_esikOee,odk_kaliteCeza,0)-IF($E42>odk_esikDurusDk,odk_kaliteSapma,0)-IF($T42="YETIM",odk_kaliteCeza,0))),0)) | R42: =IF($A42="","",IF(OR(N($O42)<odk_esikOee,$E42>odk_esikDurusDk,N($Q42)<odk_esikSaglik),"ALARM","UYGUN")) | S42: =IF($A42="","",1) | T42: =IF($A42="","",IF(OR($B42="",COUNTIF(tblVarliklar[VarlikId],$B42)=0),"YETIM","TAMAM"))
I43: =IF($A43="","",IFERROR(SUMIF(tblVarliklar[VarlikId],$B43,tblVarliklar[IdealCevrim_sn]),odk_varsayilanCevrim)) | J43: =IF($A43="","",IFERROR(MAX(0,$D43-$E43),0)) | K43: =IF($A43="","",IFERROR($J43/$D43,0)) | L43: =IF($A43="","",IFERROR($J43*odk_dakikaSn/$I43,0)) | M43: =IF($A43="","",IFERROR($F43/$L43,0)) | N43: =IF($A43="","",IFERROR(($F43-$G43)/$F43,0)) | O43: =IF($A43="","",IFERROR(N($K43)*N($M43)*N($N43),0)) | P43: =IF($A43="","",IFERROR($E43/$D43,0)) | Q43: =IF($A43="","",IFERROR(MAX(0,MIN(100,odk_kaliteTaban-IF(N($O43)<odk_esikOee,odk_kaliteCeza,0)-IF($E43>odk_esikDurusDk,odk_kaliteSapma,0)-IF($T43="YETIM",odk_kaliteCeza,0))),0)) | R43: =IF($A43="","",IF(OR(N($O43)<odk_esikOee,$E43>odk_esikDurusDk,N($Q43)<odk_esikSaglik),"ALARM","UYGUN")) | S43: =IF($A43="","",1) | T43: =IF($A43="","",IF(OR($B43="",COUNTIF(tblVarliklar[VarlikId],$B43)=0),"YETIM","TAMAM"))
I44: =IF($A44="","",IFERROR(SUMIF(tblVarliklar[VarlikId],$B44,tblVarliklar[IdealCevrim_sn]),odk_varsayilanCevrim)) | J44: =IF($A44="","",IFERROR(MAX(0,$D44-$E44),0)) | K44: =IF($A44="","",IFERROR($J44/$D44,0)) | L44: =IF($A44="","",IFERROR($J44*odk_dakikaSn/$I44,0)) | M44: =IF($A44="","",IFERROR($F44/$L44,0)) | N44: =IF($A44="","",IFERROR(($F44-$G44)/$F44,0)) | O44: =IF($A44="","",IFERROR(N($K44)*N($M44)*N($N44),0)) | P44: =IF($A44="","",IFERROR($E44/$D44,0)) | Q44: =IF($A44="","",IFERROR(MAX(0,MIN(100,odk_kaliteTaban-IF(N($O44)<odk_esikOee,odk_kaliteCeza,0)-IF($E44>odk_esikDurusDk,odk_kaliteSapma,0)-IF($T44="YETIM",odk_kaliteCeza,0))),0)) | R44: =IF($A44="","",IF(OR(N($O44)<odk_esikOee,$E44>odk_esikDurusDk,N($Q44)<odk_esikSaglik),"ALARM","UYGUN")) | S44: =IF($A44="","",1) | T44: =IF($A44="","",IF(OR($B44="",COUNTIF(tblVarliklar[VarlikId],$B44)=0),"YETIM","TAMAM"))
I45: =IF($A45="","",IFERROR(SUMIF(tblVarliklar[VarlikId],$B45,tblVarliklar[IdealCevrim_sn]),odk_varsayilanCevrim)) | J45: =IF($A45="","",IFERROR(MAX(0,$D45-$E45),0)) | K45: =IF($A45="","",IFERROR($J45/$D45,0)) | L45: =IF($A45="","",IFERROR($J45*odk_dakikaSn/$I45,0)) | M45: =IF($A45="","",IFERROR($F45/$L45,0)) | N45: =IF($A45="","",IFERROR(($F45-$G45)/$F45,0)) | O45: =IF($A45="","",IFERROR(N($K45)*N($M45)*N($N45),0)) | P45: =IF($A45="","",IFERROR($E45/$D45,0)) | Q45: =IF($A45="","",IFERROR(MAX(0,MIN(100,odk_kaliteTaban-IF(N($O45)<odk_esikOee,odk_kaliteCeza,0)-IF($E45>odk_esikDurusDk,odk_kaliteSapma,0)-IF($T45="YETIM",odk_kaliteCeza,0))),0)) | R45: =IF($A45="","",IF(OR(N($O45)<odk_esikOee,$E45>odk_esikDurusDk,N($Q45)<odk_esikSaglik),"ALARM","UYGUN")) | S45: =IF($A45="","",1) | T45: =IF($A45="","",IF(OR($B45="",COUNTIF(tblVarliklar[VarlikId],$B45)=0),"YETIM","TAMAM"))
I46: =IF($A46="","",IFERROR(SUMIF(tblVarliklar[VarlikId],$B46,tblVarliklar[IdealCevrim_sn]),odk_varsayilanCevrim)) | J46: =IF($A46="","",IFERROR(MAX(0,$D46-$E46),0)) | K46: =IF($A46="","",IFERROR($J46/$D46,0)) | L46: =IF($A46="","",IFERROR($J46*odk_dakikaSn/$I46,0)) | M46: =IF($A46="","",IFERROR($F46/$L46,0)) | N46: =IF($A46="","",IFERROR(($F46-$G46)/$F46,0)) | O46: =IF($A46="","",IFERROR(N($K46)*N($M46)*N($N46),0)) | P46: =IF($A46="","",IFERROR($E46/$D46,0)) | Q46: =IF($A46="","",IFERROR(MAX(0,MIN(100,odk_kaliteTaban-IF(N($O46)<odk_esikOee,odk_kaliteCeza,0)-IF($E46>odk_esikDurusDk,odk_kaliteSapma,0)-IF($T46="YETIM",odk_kaliteCeza,0))),0)) | R46: =IF($A46="","",IF(OR(N($O46)<odk_esikOee,$E46>odk_esikDurusDk,N($Q46)<odk_esikSaglik),"ALARM","UYGUN")) | S46: =IF($A46="","",1) | T46: =IF($A46="","",IF(OR($B46="",COUNTIF(tblVarliklar[VarlikId],$B46)=0),"YETIM","TAMAM"))
I47: =IF($A47="","",IFERROR(SUMIF(tblVarliklar[VarlikId],$B47,tblVarliklar[IdealCevrim_sn]),odk_varsayilanCevrim)) | J47: =IF($A47="","",IFERROR(MAX(0,$D47-$E47),0)) | K47: =IF($A47="","",IFERROR($J47/$D47,0)) | L47: =IF($A47="","",IFERROR($J47*odk_dakikaSn/$I47,0)) | M47: =IF($A47="","",IFERROR($F47/$L47,0)) | N47: =IF($A47="","",IFERROR(($F47-$G47)/$F47,0)) | O47: =IF($A47="","",IFERROR(N($K47)*N($M47)*N($N47),0)) | P47: =IF($A47="","",IFERROR($E47/$D47,0)) | Q47: =IF($A47="","",IFERROR(MAX(0,MIN(100,odk_kaliteTaban-IF(N($O47)<odk_esikOee,odk_kaliteCeza,0)-IF($E47>odk_esikDurusDk,odk_kaliteSapma,0)-IF($T47="YETIM",odk_kaliteCeza,0))),0)) | R47: =IF($A47="","",IF(OR(N($O47)<odk_esikOee,$E47>odk_esikDurusDk,N($Q47)<odk_esikSaglik),"ALARM","UYGUN")) | S47: =IF($A47="","",1) | T47: =IF($A47="","",IF(OR($B47="",COUNTIF(tblVarliklar[VarlikId],$B47)=0),"YETIM","TAMAM"))
I48: =IF($A48="","",IFERROR(SUMIF(tblVarliklar[VarlikId],$B48,tblVarliklar[IdealCevrim_sn]),odk_varsayilanCevrim)) | J48: =IF($A48="","",IFERROR(MAX(0,$D48-$E48),0)) | K48: =IF($A48="","",IFERROR($J48/$D48,0)) | L48: =IF($A48="","",IFERROR($J48*odk_dakikaSn/$I48,0)) | M48: =IF($A48="","",IFERROR($F48/$L48,0)) | N48: =IF($A48="","",IFERROR(($F48-$G48)/$F48,0)) | O48: =IF($A48="","",IFERROR(N($K48)*N($M48)*N($N48),0)) | P48: =IF($A48="","",IFERROR($E48/$D48,0)) | Q48: =IF($A48="","",IFERROR(MAX(0,MIN(100,odk_kaliteTaban-IF(N($O48)<odk_esikOee,odk_kaliteCeza,0)-IF($E48>odk_esikDurusDk,odk_kaliteSapma,0)-IF($T48="YETIM",odk_kaliteCeza,0))),0)) | R48: =IF($A48="","",IF(OR(N($O48)<odk_esikOee,$E48>odk_esikDurusDk,N($Q48)<odk_esikSaglik),"ALARM","UYGUN")) | S48: =IF($A48="","",1) | T48: =IF($A48="","",IF(OR($B48="",COUNTIF(tblVarliklar[VarlikId],$B48)=0),"YETIM","TAMAM"))
I49: =IF($A49="","",IFERROR(SUMIF(tblVarliklar[VarlikId],$B49,tblVarliklar[IdealCevrim_sn]),odk_varsayilanCevrim)) | J49: =IF($A49="","",IFERROR(MAX(0,$D49-$E49),0)) | K49: =IF($A49="","",IFERROR($J49/$D49,0)) | L49: =IF($A49="","",IFERROR($J49*odk_dakikaSn/$I49,0)) | M49: =IF($A49="","",IFERROR($F49/$L49,0)) | N49: =IF($A49="","",IFERROR(($F49-$G49)/$F49,0)) | O49: =IF($A49="","",IFERROR(N($K49)*N($M49)*N($N49),0)) | P49: =IF($A49="","",IFERROR($E49/$D49,0)) | Q49: =IF($A49="","",IFERROR(MAX(0,MIN(100,odk_kaliteTaban-IF(N($O49)<odk_esikOee,odk_kaliteCeza,0)-IF($E49>odk_esikDurusDk,odk_kaliteSapma,0)-IF($T49="YETIM",odk_kaliteCeza,0))),0)) | R49: =IF($A49="","",IF(OR(N($O49)<odk_esikOee,$E49>odk_esikDurusDk,N($Q49)<odk_esikSaglik),"ALARM","UYGUN")) | S49: =IF($A49="","",1) | T49: =IF($A49="","",IF(OR($B49="",COUNTIF(tblVarliklar[VarlikId],$B49)=0),"YETIM","TAMAM"))
I50: =IF($A50="","",IFERROR(SUMIF(tblVarliklar[VarlikId],$B50,tblVarliklar[IdealCevrim_sn]),odk_varsayilanCevrim)) | J50: =IF($A50="","",IFERROR(MAX(0,$D50-$E50),0)) | K50: =IF($A50="","",IFERROR($J50/$D50,0)) | L50: =IF($A50="","",IFERROR($J50*odk_dakikaSn/$I50,0)) | M50: =IF($A50="","",IFERROR($F50/$L50,0)) | N50: =IF($A50="","",IFERROR(($F50-$G50)/$F50,0)) | O50: =IF($A50="","",IFERROR(N($K50)*N($M50)*N($N50),0)) | P50: =IF($A50="","",IFERROR($E50/$D50,0)) | Q50: =IF($A50="","",IFERROR(MAX(0,MIN(100,odk_kaliteTaban-IF(N($O50)<odk_esikOee,odk_kaliteCeza,0)-IF($E50>odk_esikDurusDk,odk_kaliteSapma,0)-IF($T50="YETIM",odk_kaliteCeza,0))),0)) | R50: =IF($A50="","",IF(OR(N($O50)<odk_esikOee,$E50>odk_esikDurusDk,N($Q50)<odk_esikSaglik),"ALARM","UYGUN")) | S50: =IF($A50="","",1) | T50: =IF($A50="","",IF(OR($B50="",COUNTIF(tblVarliklar[VarlikId],$B50)=0),"YETIM","TAMAM"))
I51: =IF($A51="","",IFERROR(SUMIF(tblVarliklar[VarlikId],$B51,tblVarliklar[IdealCevrim_sn]),odk_varsayilanCevrim)) | J51: =IF($A51="","",IFERROR(MAX(0,$D51-$E51),0)) | K51: =IF($A51="","",IFERROR($J51/$D51,0)) | L51: =IF($A51="","",IFERROR($J51*odk_dakikaSn/$I51,0)) | M51: =IF($A51="","",IFERROR($F51/$L51,0)) | N51: =IF($A51="","",IFERROR(($F51-$G51)/$F51,0)) | O51: =IF($A51="","",IFERROR(N($K51)*N($M51)*N($N51),0)) | P51: =IF($A51="","",IFERROR($E51/$D51,0)) | Q51: =IF($A51="","",IFERROR(MAX(0,MIN(100,odk_kaliteTaban-IF(N($O51)<odk_esikOee,odk_kaliteCeza,0)-IF($E51>odk_esikDurusDk,odk_kaliteSapma,0)-IF($T51="YETIM",odk_kaliteCeza,0))),0)) | R51: =IF($A51="","",IF(OR(N($O51)<odk_esikOee,$E51>odk_esikDurusDk,N($Q51)<odk_esikSaglik),"ALARM","UYGUN")) | S51: =IF($A51="","",1) | T51: =IF($A51="","",IF(OR($B51="",COUNTIF(tblVarliklar[VarlikId],$B51)=0),"YETIM","TAMAM"))
I52: =IF($A52="","",IFERROR(SUMIF(tblVarliklar[VarlikId],$B52,tblVarliklar[IdealCevrim_sn]),odk_varsayilanCevrim)) | J52: =IF($A52="","",IFERROR(MAX(0,$D52-$E52),0)) | K52: =IF($A52="","",IFERROR($J52/$D52,0)) | L52: =IF($A52="","",IFERROR($J52*odk_dakikaSn/$I52,0)) | M52: =IF($A52="","",IFERROR($F52/$L52,0)) | N52: =IF($A52="","",IFERROR(($F52-$G52)/$F52,0)) | O52: =IF($A52="","",IFERROR(N($K52)*N($M52)*N($N52),0)) | P52: =IF($A52="","",IFERROR($E52/$D52,0)) | Q52: =IF($A52="","",IFERROR(MAX(0,MIN(100,odk_kaliteTaban-IF(N($O52)<odk_esikOee,odk_kaliteCeza,0)-IF($E52>odk_esikDurusDk,odk_kaliteSapma,0)-IF($T52="YETIM",odk_kaliteCeza,0))),0)) | R52: =IF($A52="","",IF(OR(N($O52)<odk_esikOee,$E52>odk_esikDurusDk,N($Q52)<odk_esikSaglik),"ALARM","UYGUN")) | S52: =IF($A52="","",1) | T52: =IF($A52="","",IF(OR($B52="",COUNTIF(tblVarliklar[VarlikId],$B52)=0),"YETIM","TAMAM"))
I53: =IF($A53="","",IFERROR(SUMIF(tblVarliklar[VarlikId],$B53,tblVarliklar[IdealCevrim_sn]),odk_varsayilanCevrim)) | J53: =IF($A53="","",IFERROR(MAX(0,$D53-$E53),0)) | K53: =IF($A53="","",IFERROR($J53/$D53,0)) | L53: =IF($A53="","",IFERROR($J53*odk_dakikaSn/$I53,0)) | M53: =IF($A53="","",IFERROR($F53/$L53,0)) | N53: =IF($A53="","",IFERROR(($F53-$G53)/$F53,0)) | O53: =IF($A53="","",IFERROR(N($K53)*N($M53)*N($N53),0)) | P53: =IF($A53="","",IFERROR($E53/$D53,0)) | Q53: =IF($A53="","",IFERROR(MAX(0,MIN(100,odk_kaliteTaban-IF(N($O53)<odk_esikOee,odk_kaliteCeza,0)-IF($E53>odk_esikDurusDk,odk_kaliteSapma,0)-IF($T53="YETIM",odk_kaliteCeza,0))),0)) | R53: =IF($A53="","",IF(OR(N($O53)<odk_esikOee,$E53>odk_esikDurusDk,N($Q53)<odk_esikSaglik),"ALARM","UYGUN")) | S53: =IF($A53="","",1) | T53: =IF($A53="","",IF(OR($B53="",COUNTIF(tblVarliklar[VarlikId],$B53)=0),"YETIM","TAMAM"))
... I255: =IF($A255="","",IFERROR(SUMIF(tblVarliklar[VarlikId],$B255,tblVarliklar[IdealCevrim_sn]),odk_varsayilanCevrim)) | J255: =IF($A255="","",IFERROR(MAX(0,$D255-$E255),0)) | K255: =IF($A255="","",IFERROR($J255/$D255,0)) | L255: =IF($A255="","",IFERROR($J255*odk_dakikaSn/$I255,0)) | M255: =IF($A255="","",IFERROR($F255/$L255,0)) | N255: =IF($A255="","",IFERROR(($F255-$G255)/$F255,0)) | O255: =IF($A255="","",IFERROR(N($K255)*N($M255)*N($N255),0)) | P255: =IF($A255="","",IFERROR($E255/$D255,0)) | Q255: =IF($A255="","",IFERROR(MAX(0,MIN(100,odk_kaliteTaban-IF(N($O255)<odk_esikOee,odk_kaliteCeza,0)-IF($E255>odk_esikDurusDk,odk_kaliteSapma,0)-IF($T255="YETIM",odk_kaliteCeza,0))),0)) | R255: =IF($A255="","",IF(OR(N($O255)<odk_esikOee,$E255>odk_esikDurusDk,N($Q255)<odk_esikSaglik),"ALARM","UYGUN")) | S255: =IF($A255="","",1) | T255: =IF($A255="","",IF(OR($B255="",COUNTIF(tblVarliklar[VarlikId],$B255)=0),"YETIM","TAMAM"))

Sheet DONEM_ANALIZ
A1: DONEM ANALIZ — OEE & Duruş Kök-Neden Komutası
A3: 12 aylık sezonsallık — OEE ve duruş zinciri (S03)
A5: Ay | B5: Ay_Anahtari | C5: Durus dk | D5: Uretim adet | E5: OEE Ort | F5: Sezonsal Etiket
A6: Ocak | B6: Ay_1 | C6: 9200 | D6: 42000 | E6: 0.62 | F6: 12_AY_SEZONSAL
A7: Subat | B7: Ay_2 | C7: 8800 | D7: 45000 | E7: 0.65 | F7: 12_AY_SEZONSAL
A8: Mart | B8: Ay_3 | C8: 7600 | D8: 51000 | E8: 0.7 | F8: 12_AY_SEZONSAL
A9: Nisan | B9: Ay_4 | C9: 7200 | D9: 54000 | E9: 0.72 | F9: 12_AY_SEZONSAL
A10: Mayis | B10: Ay_5 | C10: 6800 | D10: 58000 | E10: 0.75 | F10: 12_AY_SEZONSAL
A11: Haziran | B11: Ay_6 | C11: 6400 | D11: 60000 | E11: 0.78 | F11: 12_AY_SEZONSAL
A12: Temmuz | B12: Ay_7 | C12: 7000 | D12: 57000 | E12: 0.74 | F12: 12_AY_SEZONSAL
A13: Agustos | B13: Ay_8 | C13: 7400 | D13: 55000 | E13: 0.72 | F13: 12_AY_SEZONSAL
A14: Eylul | B14: Ay_9 | C14: 7800 | D14: 52000 | E14: 0.7 | F14: 12_AY_SEZONSAL
A15: Ekim | B15: Ay_10 | C15: 8200 | D15: 48000 | E15: 0.67 | F15: 12_AY_SEZONSAL
A16: Kasim | B16: Ay_11 | C16: 8600 | D16: 44000 | E16: 0.64 | F16: 12_AY_SEZONSAL
A17: Aralik | B17: Ay_12 | C17: 9000 | D17: 41000 | E17: 0.61 | F17: 12_AY_SEZONSAL
A20: Sezonsal Trend Özeti | B20: =odk_sezonsalTrend
A22: 12 Ay Toplam Duruş | B22: =SUM(C6:C17)
A23: 12 Ay Toplam Üretim | B23: =SUM(D6:D17)
A24: 12 Ay Ort OEE | B24: =AVERAGE(E6:E17)
A25: Canlı dönem duruş | B25: =odk_toplamDurus
A26: Canlı dönem OEE | B26: =odk_oeeOrani

Sheet HESAP
A1: HESAP — OEE & Duruş Kök-Neden Komutası
A3: Hesap motoru — ≥40 adım; sabitler AYARLAR'dan
A5: Adım | B5: Açıklama | C5: Değer
A6: H01 | B6: Toplam günlük kayıt | C6: =COUNTA(tblGunluk[SatirId])
A7: H02 | B7: Dolu kayıt | C7: =SUM(tblGunluk[FormulKayitDolu])
A8: H03 | B8: Toplam plan dk | C8: =SUM(tblGunluk[PlanSure_dk])
A9: H04 | B9: Toplam duruş dk | C9: =SUM(tblGunluk[DurusSure_dk])
A10: H05 | B10: Toplam üretim adet | C10: =SUM(tblGunluk[UretimAdet_adet])
A11: H06 | B11: Toplam fire adet | C11: =SUM(tblGunluk[FireAdet_adet])
A12: H07 | B12: Toplam çalışma dk | C12: =SUM(tblGunluk[FormulCalisma_dk])
A13: H08 | B13: Kullanılabilirlik | C13: =IFERROR(C12/MAX(C8,1),0)
A14: H09 | B14: Toplam teorik adet | C14: =SUM(tblGunluk[FormulTeorikAdet_adet])
A15: H10 | B15: Performans | C15: =IFERROR(C10/MAX(C14,1),0)
A16: H11 | B16: Kalite oranı | C16: =IFERROR((C10-C11)/MAX(C10,1),0)
A17: H12 | B17: OEE oranı | C17: =IFERROR(C13*C15*C16,0)
A18: H13 | B18: Duruş payı | C18: =IFERROR(C9/MAX(C8,1),0)
A19: H14 | B19: Aktif makine adet | C19: =COUNTIF(tblVarliklar[Aktif],"EVET")
A20: H15 | B20: Toplam makine kart | C20: =COUNTA(tblVarliklar[VarlikId])
A21: H16 | B21: Alarm adet | C21: =COUNTIF(tblGunluk[AlarmBayrak],"ALARM")
A22: H17 | B22: Yetim kayıt | C22: =COUNTIF(tblGunluk[FormulYetim],"YETIM")
A23: H18 | B23: Ortalama sağlık skor | C23: =IFERROR(AVERAGEIF(tblGunluk[SaglikSkor_puan],">0"),0)
A24: H19 | B24: Min sağlık skor | C24: =IFERROR(MIN(tblGunluk[SaglikSkor_puan]),0)
A25: H20 | B25: OEE eşik altı adet | C25: =COUNTIFS(tblGunluk[FormulOee_oran],"<"&odk_esikOee,tblGunluk[FormulKayitDolu],">0")
A26: H21 | B26: Duruş eşik aşımı | C26: =COUNTIFS(tblGunluk[DurusSure_dk],">"&odk_esikDurusDk,tblGunluk[FormulKayitDolu],">0")
A27: H22 | B27: Düşük sağlık adet | C27: =COUNTIFS(tblGunluk[SaglikSkor_puan],"<"&odk_esikSaglik,tblGunluk[FormulKayitDolu],">0")
A28: H23 | B28: Günlük OEE ort | C28: =IFERROR(AVERAGEIF(tblGunluk[FormulOee_oran],">0"),0)
A29: H24 | B29: Aylık duruş proxy | C29: =C9*odk_aylikCarpan
A30: H25 | B30: OEE sapma | C30: =IFERROR(ABS(C17-odk_esikOee),0)
A31: H26 | B31: ARIZA kök pay | C31: =IFERROR(COUNTIF(tblGunluk[KokNedenKodu],"ARIZA")/MAX(C7,1),0)
A32: H27 | B32: AYAR kök pay | C32: =IFERROR(COUNTIF(tblGunluk[KokNedenKodu],"AYAR")/MAX(C7,1),0)
A33: H28 | B33: MALZEME kök pay | C33: =IFERROR(COUNTIF(tblGunluk[KokNedenKodu],"MALZEME")/MAX(C7,1),0)
A34: H29 | B34: OPERATOR kök pay | C34: =IFERROR(COUNTIF(tblGunluk[KokNedenKodu],"OPERATOR")/MAX(C7,1),0)
A35: H30 | B35: Temkinli senaryo | C35: =C17*odk_senaryoTemkinli
A36: H31 | B36: Baz senaryo | C36: =C17*odk_senaryoBaz
A37: H32 | B37: İyimser senaryo | C37: =C17*odk_senaryoIyimser
A38: H33 | B38: Senaryo farkı | C38: =C37-C35
A39: H34 | B39: Tornado duruş etki | C39: =C9*odk_tornadoOran
A40: H35 | B40: Tornado fire etki | C40: =C11*odk_tornadoOran
A41: H36 | B41: Tornado OEE etki | C41: =C17*odk_tornadoOran
A42: H37 | B42: Tornado zirve | C42: =MAX(C39,C40,C41)
...

Sheet PANO
A1: PANO — OEE & Duruş Kök-Neden Komutası
A3: Karar panosu — OEE, duruş, kök neden, sezonsal trend
A5: KARAR | B5: =odk_kararKapi
A6: Gösterge | B6: Değer
A7: Dolu Kayıt | B7: =odk_doluKayit | D7: Gerekçe | E7: =odk_kararGerekce
A8: Toplam Duruş dk | B8: =odk_toplamDurus
A9: Toplam Üretim adet | B9: =odk_toplamUretim
A10: OEE Oranı | B10: =odk_oeeOrani | D10: Öneri 1 | E10: =_xlfn.TEXTJOIN(" ",TRUE,"OEE",TEXT(odk_oeeOrani,"0.0%"),"— eşik",TEXT(odk_esikOee,"0.0%"))
A11: Kullanılabilirlik | B11: =odk_kullanilabilirlik | D11: Öneri 2 | E11: =_xlfn.TEXTJOIN(" ",TRUE,"Alarm",odk_alarmAdet,"adet — sağlık",TEXT(odk_saglikSkor,"0"))
A12: Performans | B12: =odk_performans | D12: Öneri 3 | E12: =_xlfn.TEXTJOIN(" ",TRUE,"Duruş",TEXT(odk_toplamDurus,"0"),"dk — kök",odk_kokNedenKirilim)
A13: Kalite Oranı | B13: =odk_kaliteOrani
A14: Günlük OEE Ort | B14: =odk_gunlukOeeOrt
A15: Sağlık Skor Ort | B15: =odk_saglikSkor
A16: Alarm Adet | B16: =odk_alarmAdet
A17: Yetim Kayıt | B17: =odk_yetimAdet
A18: Kalite Skor | B18: =odk_kaliteSkor
A19: Tornado Zirve | B19: =odk_tornadoZirve
A20: Kök Neden Kırılım | B20: =odk_kokNedenKirilim
A22: KokNeden | B22: Adet | D22: Senaryo | E22: OEE | G22: Hafta | H22: Durus | J22: Ay | K22: OEE
A23: ARIZA | B23: 9 | D23: Temkinli | E23: 0.58 | G23: H1 | H23: 135 | J23: Haziran | K23: 0.62
A24: AYAR | B24: 7 | D24: Baz | E24: 0.68 | G24: H2 | H24: 150 | J24: Temmuz | K24: 0.68
A25: MALZEME | B25: 6 | D25: İyimser | E25: 0.78 | G25: H3 | H25: 165 | J25: Agustos | K25: 0.72
A26: OPERATOR | B26: 5 | G26: H4 | H26: 180 | J26: Eylul | K26: 0.76
G27: H5 | H27: 195
G28: H6 | H28: 210
G29: H7 | H29: 225
G30: H8 | H30: 240

Sheet ALARMLAR
A1: ALARMLAR — OEE & Duruş Kök-Neden Komutası
A3: Alarm listesi — varlık + eşik + süre (S05)
A5: Varlık | B5: Alarm | C5: Eşik | D5: Süre / Tarih | E5: OEE Ort | F5: Sağlık Skor
A6: MAK-00001 | B6: =IF(OR(COUNTIFS(tblGunluk[VarlikId],A6,tblGunluk[AlarmBayrak],"ALARM")>0,IFERROR(SUMIF(tblVarliklar[VarlikId],A6,tblVarliklar[SaglikSkor]),100)<odk_esikSaglik),"ALARM","YOK") | C6: =IFERROR(ABS(E6-odk_esikOee),0) | D6: =raporTarihi | E6: =IFERROR(SUMIF(tblVarliklar[VarlikId],A6,tblVarliklar[OrtOee]),0) | F6: =IFERROR(SUMIF(tblVarliklar[VarlikId],A6,tblVarliklar[SaglikSkor]),0)
A7: MAK-00002 | B7: =IF(OR(COUNTIFS(tblGunluk[VarlikId],A7,tblGunluk[AlarmBayrak],"ALARM")>0,IFERROR(SUMIF(tblVarliklar[VarlikId],A7,tblVarliklar[SaglikSkor]),100)<odk_esikSaglik),"ALARM","YOK") | C7: =IFERROR(ABS(E7-odk_esikOee),0) | D7: =raporTarihi | E7: =IFERROR(SUMIF(tblVarliklar[VarlikId],A7,tblVarliklar[OrtOee]),0) | F7: =IFERROR(SUMIF(tblVarliklar[VarlikId],A7,tblVarliklar[SaglikSkor]),0)
A8: MAK-00003 | B8: =IF(OR(COUNTIFS(tblGunluk[VarlikId],A8,tblGunluk[AlarmBayrak],"ALARM")>0,IFERROR(SUMIF(tblVarliklar[VarlikId],A8,tblVarliklar[SaglikSkor]),100)<odk_esikSaglik),"ALARM","YOK") | C8: =IFERROR(ABS(E8-odk_esikOee),0) | D8: =raporTarihi | E8: =IFERROR(SUMIF(tblVarliklar[VarlikId],A8,tblVarliklar[OrtOee]),0) | F8: =IFERROR(SUMIF(tblVarliklar[VarlikId],A8,tblVarliklar[SaglikSkor]),0)
A9: MAK-00004 | B9: =IF(OR(COUNTIFS(tblGunluk[VarlikId],A9,tblGunluk[AlarmBayrak],"ALARM")>0,IFERROR(SUMIF(tblVarliklar[VarlikId],A9,tblVarliklar[SaglikSkor]),100)<odk_esikSaglik),"ALARM","YOK") | C9: =IFERROR(ABS(E9-odk_esikOee),0) | D9: =raporTarihi | E9: =IFERROR(SUMIF(tblVarliklar[VarlikId],A9,tblVarliklar[OrtOee]),0) | F9: =IFERROR(SUMIF(tblVarliklar[VarlikId],A9,tblVarliklar[SaglikSkor]),0)
A10: MAK-00005 | B10: =IF(OR(COUNTIFS(tblGunluk[VarlikId],A10,tblGunluk[AlarmBayrak],"ALARM")>0,IFERROR(SUMIF(tblVarliklar[VarlikId],A10,tblVarliklar[SaglikSkor]),100)<odk_esikSaglik),"ALARM","YOK") | C10: =IFERROR(ABS(E10-odk_esikOee),0) | D10: =raporTarihi | E10: =IFERROR(SUMIF(tblVarliklar[VarlikId],A10,tblVarliklar[OrtOee]),0) | F10: =IFERROR(SUMIF(tblVarliklar[VarlikId],A10,tblVarliklar[SaglikSkor]),0)
A11: MAK-00006 | B11: =IF(OR(COUNTIFS(tblGunluk[VarlikId],A11,tblGunluk[AlarmBayrak],"ALARM")>0,IFERROR(SUMIF(tblVarliklar[VarlikId],A11,tblVarliklar[SaglikSkor]),100)<odk_esikSaglik),"ALARM","YOK") | C11: =IFERROR(ABS(E11-odk_esikOee),0) | D11: =raporTarihi | E11: =IFERROR(SUMIF(tblVarliklar[VarlikId],A11,tblVarliklar[OrtOee]),0) | F11: =IFERROR(SUMIF(tblVarliklar[VarlikId],A11,tblVarliklar[SaglikSkor]),0)
A12: MAK-00007 | B12: =IF(OR(COUNTIFS(tblGunluk[VarlikId],A12,tblGunluk[AlarmBayrak],"ALARM")>0,IFERROR(SUMIF(tblVarliklar[VarlikId],A12,tblVarliklar[SaglikSkor]),100)<odk_esikSaglik),"ALARM","YOK") | C12: =IFERROR(ABS(E12-odk_esikOee),0) | D12: =raporTarihi | E12: =IFERROR(SUMIF(tblVarliklar[VarlikId],A12,tblVarliklar[OrtOee]),0) | F12: =IFERROR(SUMIF(tblVarliklar[VarlikId],A12,tblVarliklar[SaglikSkor]),0)
A13: MAK-00008 | B13: =IF(OR(COUNTIFS(tblGunluk[VarlikId],A13,tblGunluk[AlarmBayrak],"ALARM")>0,IFERROR(SUMIF(tblVarliklar[VarlikId],A13,tblVarliklar[SaglikSkor]),100)<odk_esikSaglik),"ALARM","YOK") | C13: =IFERROR(ABS(E13-odk_esikOee),0) | D13: =raporTarihi | E13: =IFERROR(SUMIF(tblVarliklar[VarlikId],A13,tblVarliklar[OrtOee]),0) | F13: =IFERROR(SUMIF(tblVarliklar[VarlikId],A13,tblVarliklar[SaglikSkor]),0)
A16: Alarm Özeti | B16: =odk_alarmListesi
A18: Toplam Alarm Satır | B18: =COUNTIF(B6:B13,"ALARM")

Sheet RAPOR
A1: RAPOR — OEE & Duruş Kök-Neden Komutası
A3: Dönemsel yönetim raporu — yazdırılabilir kanıt
A5: Ürün | B5: OEE & Duruş Kök-Neden Komutası
A6: Sürüm | B6: 1.0.0
A7: Rapor Tarihi | B7: =raporTarihi
A8: Firma | B8: =odk_firmaUnvan
A10: KARAR | B10: =odk_kararKapi
A11: OEE Oranı | B11: =odk_oeeOrani
A12: Toplam Duruş dk | B12: =odk_toplamDurus
A13: Toplam Üretim adet | B13: =odk_toplamUretim
A14: Sağlık Skor | B14: =odk_saglikSkor
A15: Alarm Adet | B15: =odk_alarmAdet
A17: Kalem | B17: Değer
A18: Kullanılabilirlik | B18: =odk_kullanilabilirlik
A19: Performans | B19: =odk_performans
A20: Kalite oranı | B20: =odk_kaliteOrani
A21: Günlük OEE ort | B21: =odk_gunlukOeeOrt
A22: Kalite skor | B22: =odk_kaliteSkor
A23: Kök neden kırılım | B23: =odk_kokNedenKirilim
A26: Varsayımlar
A27: OEE = kullanılabilirlik × performans × kalite. Eşikler AYARLAR'dan gelir. Karar destek çıktısıdır; sertifikasyon veya kalite tavsiyesi değildir. Duruş kök-neden kodları saha sınıflandırmasıdır.
A30: İmza — Üretim Müdürü / OEE Sahibi | C30: ________________
A31: İmza — Kalite Müdürü / Fabrika Yöneticisi | C31: ________________
A33: SHA notu: sevk paketinde SHA-256 yer alır | 1.0.0

Sheet KONTROLLER
A1: KONTROLLER — OEE & Duruş Kök-Neden Komutası
A3: Canlı sağlık kontrolleri — formülle
A5: Kontrol | B5: Sonuç | C5: Değer
A6: Dolu kayıt > 0 | B6: =IF(odk_doluKayit>0,"GEÇTİ","KALDI") | C6: =odk_doluKayit
A7: Yetim kayıt = 0 | B7: =IF(odk_yetimAdet=0,"GEÇTİ","UYARI") | C7: =odk_yetimAdet
A8: OEE hesaplı | B8: =IF(odk_oeeOrani>=0,"GEÇTİ","KALDI") | C8: =odk_oeeOrani
A9: Sağlık skor formül | B9: =IF(odk_saglikSkor>=0,"GEÇTİ","KALDI") | C9: =odk_saglikSkor
A10: Alarm listesi | B10: =IF(odk_alarmAdet>=0,"GEÇTİ","KALDI") | C10: =odk_alarmAdet
A11: Karar dolu | B11: =IF(odk_kararKapi<>"","GEÇTİ","KALDI") | C11: =odk_kararKapi
A12: 12 ay sezonsal | B12: =IF(DONEM_ANALIZ!B22>=0,"GEÇTİ","KALDI") | C12: =DONEM_ANALIZ!B22
A13: Kalite skor | B13: =IF(odk_kaliteSkor>=0,"GEÇTİ","KALDI") | C13: =odk_kaliteSkor
A14: Tornado | B14: =IF(odk_tornadoZirve>=0,"GEÇTİ","KALDI") | C14: =odk_tornadoZirve
A15: P90 | B15: =IF(odk_yuzdelikP90>=0,"GEÇTİ","KALDI") | C15: =odk_yuzdelikP90

Sheet ORNEK_VERI
A1: ORNEK VERI — OEE & Duruş Kök-Neden Komutası
A3: Örnek günlük satırlar — kopyalanabilir referans
A5: SatirId | B5: VarlikId | C5: Tarih | D5: PlanSure_dk | E5: DurusSure_dk | F5: UretimAdet_adet | G5: FireAdet_adet | H5: KokNedenKodu
A6: ODK-00001 | B6: MAK-00001 | C6: 46242 | D6: 480 | E6: 48 | F6: 1814 | G6: 45 | H6: AYAR
A7: ODK-00002 | B7: MAK-00002 | C7: 46239 | D7: 480 | E7: 56 | F7: 486 | G7: 15 | H7: MALZEME
A8: ODK-00003 | B8: MAK-00003 | C8: 46236 | D8: 480 | E8: 64 | F8: 1221 | G8: 43 | H8: OPERATOR
A9: ODK-00004 | B9: MAK-00004 | C9: 46233 | D9: 480 | E9: 72 | F9: 734 | G9: 15 | H9: KALIP
A10: ODK-00005 | B10: MAK-00005 | C10: 46230 | D10: 480 | E10: 80 | F10: 895 | G10: 22 | H10: BEKLEME
A11: ODK-00006 | B11: MAK-00006 | C11: 46227 | D11: 480 | E11: 88 | F11: 2470 | G11: 74 | H11: DIGER
A12: ODK-00007 | B12: MAK-00007 | C12: 46224 | D12: 480 | E12: 40 | F12: 648 | G12: 23 | H12: ARIZA
A13: ODK-00008 | B13: MAK-00008 | C13: 46221 | D13: 480 | E13: 48 | F13: 1521 | G13: 30 | H13: AYAR
A14: ODK-00009 | B14: MAK-00001 | C14: 46218 | D14: 480 | E14: 56 | F14: 1908 | G14: 48 | H14: MALZEME
A15: ODK-00010 | B15: MAK-00002 | C15: 46215 | D15: 480 | E15: 64 | F15: 455 | G15: 14 | H15: OPERATOR
A16: ODK-00011 | B16: MAK-00003 | C16: 46212 | D16: 480 | E16: 72 | F16: 1142 | G16: 40 | H16: KALIP
A17: ODK-00012 | B17: MAK-00004 | C17: 46209 | D17: 480 | E17: 180 | F17: 330 | G17: 26 | H17: BEKLEME
... A25: ODK-00020 | B25: MAK-00004 | C25: 46185 | D25: 480 | E25: 88 | F25: 643 | G25: 13 | H25: DIGER

Sheet LISTELER
A1: LISTELER — OEE & Duruş Kök-Neden Komutası
A3: Evet / Hayır | C3: Kök Neden | E3: Hat Tipi
A6: Secim | C6: Kod | E6: Hat
A7: EVET | C7: ARIZA | E7: HAT-A
A8: HAYIR | C8: AYAR | E8: HAT-B
C9: MALZEME | E9: HAT-C
C10: OPERATOR
C11: KALIP
C12: BEKLEME
C13: DIGER

Sheet AYARLAR
A1: AYARLAR — OEE & Duruş Kök-Neden Komutası
A3: Tek kaynak parametreler + alarm eşikleri (S05)
A5: anahtar | B5: deger | C5: birim | D5: kaynak | E5: yururluk_tarihi | F5: aciklama
A6: raporTarihi | B6: 46245 | C6: tarih | D6: Kullanıcı / dönem kapanışı | E6: 01.01.2026 | F6: Rapor tarihi (TODAY yok)
A7: odk_varsayilanCevrim | B7: 20 | C7: sn | D7: Makine kartı / iş etüdü | E7: 01.01.2026 | F7: Varsayılan ideal çevrim sn
A8: odk_esikOee | B8: 0.65 | C8: oran | D8: Alarm eşiği — OEE | E8: 01.01.2026 | F8: OEE alt alarm eşiği
A9: odk_esikDurusDk | B9: 120 | C9: dk | D9: Alarm eşiği — duruş | E9: 01.01.2026 | F9: Günlük duruş alarm eşiği
A10: odk_esikSaglik | B10: 60 | C10: puan | D10: Alarm eşiği — sağlık skor | E10: 01.01.2026 | F10: Sağlık skor alt eşiği
A11: odk_aylikCarpan | B11: 1 | C11: oran | D11: Aylık proxy | E11: 01.01.2026 | F11: Aylık duruş çarpan
A12: odk_senaryoTemkinli | B12: 0.9 | C12: oran | D12: Senaryo motoru | E12: 01.01.2026 | F12: Temkinli çarpan
