Workbook
Name hesapYili: GIRDI!$B$8
Name raporTarihi: AYARLAR!$B$7
Name ydv_karTl: MOTOR!$G$20
Name ydv_toplamVergi: MOTOR!$G$28
Name ydv_efektifVergi: MOTOR!$G$29
Name ydv_ciftVergi: MOTOR!$G$30
Name ydv_trEkMatrah: MOTOR!$G$31
Name ydv_kararMetni: MOTOR!$G$33
Name ydv_yapiOneri: MOTOR!$G$34
Name ydv_kararGerekce: MOTOR!$G$35
Name ydv_maddeAtifMetni: MOTOR!$G$54
Name ydv_kanitRaporu: MOTOR!$G$55
Name ydv_kuralYilMatris: KURALLAR!$B$17
Name ydv_parmakIzi: AYARLAR!$B$19
Name ydv_senaryoKarsilastirma: SENARYO!$B$11
Name ydv_yorumSenaryo: SENARYO!$B$12
Name ydv_duyarlilikSira: SENARYO!$B$19
Name ydv_yorumDuyarlilik: SENARYO!$B$20
Name ydv_kuralDegisimSenaryo: SENARYO!$B$22
Name ydv_yorumKuralDegisim: SENARYO!$B$23
Name ydv_tahminAralik: SENARYO!$B$32
Name ydv_yorumTahmin: SENARYO!$B$33
Name ydv_vakaDurum: VAKALAR!$B$12
Name ydv_vakaFark: VAKALAR!$B$13
Name ydv_tolerans: AYARLAR!$B$8
Name ydv_kacirilanEsik: AYARLAR!$B$9
Name ydv_senaryoIyi: AYARLAR!$B$10
Name ydv_senaryoKotu: AYARLAR!$B$11
Name ydv_oranArtisPuan: AYARLAR!$B$12
Name ydv_tahminAlt: AYARLAR!$B$13
Name ydv_tahminUst: AYARLAR!$B$14
Name ydv_tornadoKur: AYARLAR!$B$15
Name ydv_tornadoTf: AYARLAR!$B$16
Name ydv_peArtisOran: AYARLAR!$B$17
Name ydv_yuzdelikOran: AYARLAR!$B$18
Name ydv_girisBeklenen: AYARLAR!$B$21
Name ydv_riskDusuk: AYARLAR!$B$22
Name ydv_riskOrta: AYARLAR!$B$23
Name ydv_riskYuksek: AYARLAR!$B$24
Name ydv_yilTaban: AYARLAR!$B$25
Name ydv_yuvarMax: AYARLAR!$B$26
Name ydv_bazCarpan: AYARLAR!$B$27
Name ydv_sifirCarpan: AYARLAR!$B$28
Name ydv_siraBir: AYARLAR!$B$29
Name ydv_siraIki: AYARLAR!$B$30
Name ydv_siraUc: AYARLAR!$B$31
Name ydv_tahminX: AYARLAR!$B$32
Name ydv_ofisMatrahOran: AYARLAR!$B$33
Name ydv_dagitimOran: AYARLAR!$B$34
Name ydv_tfBolum: AYARLAR!$B$35
Name ydv_ekMatrahCarpan: AYARLAR!$B$36
Name ydv_ciftVergiEsik: AYARLAR!$B$37
Name ydv_dikkatEsik: AYARLAR!$B$38
Name ydv_dikkatCiftEsik: AYARLAR!$B$39
Name ydv_subeEfektifEsik: AYARLAR!$B$40
Name vaka_kar_1: AYARLAR!$B$41
Name vaka_yerel_oran: AYARLAR!$B$42
Name vaka_tf_puan: AYARLAR!$B$43
Name ydv_modulT1: PANO!$C$12
Name ydv_modulT1Yorum: PANO!$D$12

Sheet 00_BASLANGIC
A1: EXCELARŞİV KARAR SİSTEMİ v15.1 — ÜRETİM REFERANSI
A3: Konu | B3: Bağlayıcı Standart
A4: Amaç | B4: Kanıta dayalı, hatada kapalı çalışan Excel üretim ve denetim sistemi
A5: Öncelik | B5: Kullanıcının açık iş talebi ve gerçek kullanım senaryosu
A6: Ana akış | B6: Uygunluk → Yönetişim → Sözleşmeler → Üretim → Test → Kanıt → Kullanıcı Kabulü → Yayın
A7: Yayın ilkesi | B7: Üst aşamada hata varsa alt aşama GEÇTİ üretilemez
A8: Kullanıcı kabulü | B8: Excel masaüstü görünümü test edilmediyse DIŞ_KABUL_GEREKLİ
A9: Nihai yayın | B9: Yalnız uygulanabilir modüller GEÇTİ veya gerekçeli UYGULANMAZ
A10: Ticari ayrım | B10: Ekonomik olarak savunulabilir fiyat, gerçek pazar kabulü ile aynı değildir
A11: Karmaşıklık | B11: Karar değeri, eklenen karmaşıklığın maliyetinden büyük olmalıdır
A12: Excel sınırı | B12: Veritabanı, kurumsal yetkilendirme, değiştirilemez kayıt sistemi veya gerçek zamanlı olay platformu değildir
A13: Dil standardı | B13: Kullanıcıya görünen tüm sayfa, tablo, başlık, açıklama, uyarı ve karar metinleri saf Türkçe olmalıdır
A14: Muhasebe standardı | B14: Finansal ürünlerde Türkiye Tekdüzen Hesap Planı ve Türk muhasebe kullanım alışkanlıkları esas alınır
... A33: Muhasebe | B33: Türkiye Tekdüzen Hesap Planı ve Türk muhasebe/işletme düşünce yapısı esas alınır.

Sheet PANO
A1: ☰ PANO
B2: YURT DISI YAPILANMA VERGI SIMULATORU — YÖNETİM VE KARAR SİSTEMİ | L2: Dönem: 2026 / Tam ▼ | M2: ★ DOĞRULANMIŞ
B3: Yönetici Karar Kokpiti, Otomatik Doğrulama ve Dinamik Hesaplama Sistemi · 2026
B5: TOPLAM İŞLEM HACMİ | D5: DOĞRULANMIŞ | E5: RİSKLİ / BEKLEYEN İŞLEM | G5: MİNİMUM | H5: OPERASYONEL NET MARJ | J5: GÜVENLİ | K5: SİSTEM GÜVEN SKORU | M5: DENETLENDİ
B7: ₺28.450.000 | E7: ₺940.000 | H7: ₺8.120.000 | K7: 98/100
B9: ↑ Konsolide yıllıklandırılmış büyüme | E9: ● Tüm riskli kayıtlar kontrol altında | H9: ██████████░░░░░ %28.5 NET MARJ | K9: ✓ 0 Formül ve Döngüsel Hata
B11: 12 AYLIK NAKİT GİRİŞ / ÇIKIŞ & LİKİDİTE BAŞARIMI | F11: +%32 Verim | H11: KONSOLİDE OPERASYON VE KARAR MATRİSİ
B12: Kümülatif Tahsilat vs. Tedarikçi/Kredi Ödeme Projeksiyonu | H12: Anlık Hesaplama Sonuçları, Dinamik Formül Çıktıları ve Durum Puanlaması
B14: Dönem | C14: Aktif Hacim | D14: Maliyet/Yük | E14: Hedef | H14: PARAMETRE / KALEM | I14: ANA TUTAR | J14: FARK / MARJ | K14: VADE | L14: KONTROL DURUMU
B15: D1 | C15: 65 | D15: 45 | E15: 60 | H15: 13 haftalık kümülatif bakiye... | I15: ₺8.450.000 | J15: ₺425.000 | K15: 12 Ay | L15: ✓ DÜZENLİ
B16: D2 | C16: 78 | D16: 48 | E16: 70 | H16: Kritik (eksi) hafta uyarısı | I16: ₺12.200.000 | J16: ₺580.400 | K16: 24 Ay | L16: ★ AVANTAJ
B17: D3 | C17: 85 | D17: 55 | E17: 80 | H17: Dönem net nakit değişimi | I17: ₺4.850.000 | J17: ₺235.200 | K17: 8 Ay | L17: ● YAKLAŞAN
B18: D4 | C18: 75 | D18: 42 | E18: 75 | H18: 13 haftalık kümülatif bakiye... | I18: ₺2.140.000 | J18: ₺118.000 | K18: 16 Ay | L18: ✓ TAM UYUM
B19: D5 | C19: 90 | D19: 40 | E19: 85 | H19: KONSOLİDE SİSTEM TOPLAMI | I19: ₺42.850.000 | J19: ₺3.420.000 | L19: TAM DOĞRULANDI (0 HATA)
B20: D6 | C20: 96 | D20: 32 | E20: 92
B22: KONSOLİDE PAY VE AĞIRLIK | F22: LİKİDİTE RİSKİ & ERKEN UYARI SİNYALLERİ | K22: KARAR MOTORU
B23: ■ Ana Segment (%42) | F23: Nakit Açığı Riski (30 Gün) | I23: 0.00 TL (Sıfır Risk) | K23: OPERASYONEL VERİMLİLİK FIRSATI
B24: ■ İkincil Grup (%30) | F24: Tahsilat Gecikme Toleransı | I24: 48 Gün Güvenli Eşik | K24: Süreç optimizasyonuyla birim operasyonel maliyeti düşürme potansiyeli mevcuttur.
B25: ■ Destek Birimi (%15) | F25: ██████████████████████████████████████ Güvenli Bölge (%100)
B26: ■ Rezervler (%13) | F26: ✓ 90 GÜNLÜK PROJEKSİYONDA NAKİT SIKIŞIKLIĞI TESPİT EDİLMEDİ | K26: STRATEJİ REÇETESİNİ İNCELE >

Sheet GİRDİLER
A1: ☰ PANO
B3: 🔍 Kayıt veya hesap ara... | G3: TOPLAM: 1.450 KAYIT | I3: HATALI HÜCRE: 0 ADET
B5: TARİH | C5: REFERANS NO | D5: İŞLEM AÇIKLAMASI VE DETAY | E5: BRÜT TUTAR (₺) | F5: KDV ORANI | G5: NET TUTAR (₺) | H5: HESAP / CARİ | I5: DURUM
B6: 12.10.2026 | C6: TR-0428-A | D6: Haftalık operasyon tahmini | E6: 845200 | F6: 0.2 | G6: =E6/(1+F6) | H6: Vadesiz Ticari | I6: ONAYLANDI
B7: 14.10.2026 | C7: TR-0429-B | D7: Haftalık operasyon tahmini | E7: 1240000 | F7: 0.2 | G7: =E7/(1+F7) | H7: Tedarikçi Havuzu | I7: BEKLEMEDE
B8: 18.10.2026 | C8: TR-0430-C | D8: Ödeme takvimi notları | E8: 620500 | F8: 0.1 | G8: =E8/(1+F8) | H8: Kısa Vade Tahakkuk | I8: ONAYLANDI
B9: 21.10.2026 | C9: TR-0431-D | D9: Haftalık operasyon tahmini | E9: 415000 | F9: 0.2 | G9: =E9/(1+F9) | H9: Müşteri Alacağı | I9: ONAYLANDI
B10: 25.10.2026 | C10: TR-0432-E | D10: Haftalık operasyon tahmini | E10: 980400 | F10: 0.2 | G10: =E10/(1+F10) | H10: Vadesiz Ticari | I10: ONAYLANDI
B11: 28.10.2026 | C11: TR-0433-F | D11: Haftalık operasyon tahmini | E11: 1850000 | F11: 0.2 | G11: =E11/(1+F11) | H11: Banka Kredi Taksiti | I11: BLOKE
B12: 02.11.2026 | C12: TR-0434-G | D12: Ödeme takvimi notları | E12: 740000 | F12: 0.2 | G12: =E12/(1+F12) | H12: Kira & Sabit Gider | I12: ONAYLANDI
B13: 05.11.2026 | C13: TR-0435-H | D13: Haftalık operasyon tahmini | E13: 520800 | F13: 0.2 | G13: =E13/(1+F13) | H13: Vadesiz Ticari | I13: ONAYLANDI
B14: 09.11.2026 | C14: TR-0436-I | D14: Haftalık operasyon tahmini | E14: 1120000 | F14: 0.2 | G14: =E14/(1+F14) | H14: Müşteri Alacağı | I14: ONAYLANDI
B15: 12.11.2026 | C15: TR-0437-J | D15: Haftalık operasyon tahmini | E15: 890000 | F15: 0.2 | G15: =E15/(1+F15) | H15: Tedarikçi Havuzu | I15: ONAYLANDI
B17: SAYFA TOPLAMI (10 / 1.450 KAYIT) | E17: =TOPLA(E6:E15)

Sheet YÖNETİM_RAPORU
A1: ☰ PANO
B2: YURT DISI YAPILANMA VERGI SIMULATORU — YÖNETİM VE KARAR SİSTEMİ — NİHAİ KARAR VE DEĞERLEME
B3: Yönetim Kurulu ve İcra Komitesi için Otomatik Türetilen Finansal Stres Testi Raporu
B4: DÖNEM: 2026 Q3 · DENETİM PROTOKOLÜ: ISO/VUK/IFRS UYUMLU · DURUM: ONAYLANDI
B6: SENARYO A: KÖTÜMSER (STRES TESTİ -%20) | H6: SENARYO B: BAZ MODEL (HEDEFLENEN)
B8: Ciro / Hacim Düşüşü: | E8: -%20.0 (Kriz Eşiği) | H8: Ciro / Hacim Gerçekleşmesi: | K8: %100.0 (Tam Bütçe)
B9: Beklenen Net Kâr / Getiri: | E9: ₺4.280.000 | H9: Beklenen Net Kâr / Getiri: | K9: ₺12.450.000
B10: Minimum Nakit Tamponu: | E10: ₺1.850.000 (Yeterli) | H10: Serbest Nakit Akımı: | K10: ₺8.240.000
B11: Likidite Karşılama Oranı: | E11: 1.28x (Eşik: 1.10x) | H11: Yatırım Geri Dönüşü (ROI): | K11: %38.4 Yıllık
B14: STRES SENARYOSUNDA DAHİ İFLAS RİSKİ YOK | H14: OPTİMUM İCRA VE PLANLAMA REÇETESİ
B17: YÖNETİM KARAR MATRİSİ VE UYGULAMA REÇETESİ
B19: ● Öncelik 1: Acil Likidite ve Borç Servis Planlaması
B20: Sistemde hesaplanan vade günlerine sadık kalınarak nakit blokajı 3 gün önceden hazır edilmelidir.
B21: ● Öncelik 2: Formül Doğrulama ve Çapraz Sağlama
B22: Tüm hücreler kilitli formül korumasında olup girdi sayfalarında sıfır döngüsel başvuru (circular ref) garantilidir.
B23: ● Öncelik 3: Resmi Mevzuat ve Vergi Kalkanı Entegrasyonu
B24: 2026 güncel vergi dilimleri, amortisman ve SGK teşvik parametreleri tam otomatik yansıtılmaktadır.
B25: ● Öncelik 4: Yönetici İmzası ve Rapor Paylaşımı
B26: Tek tuşla PDF ve A4 çıktı formatına tam uyumlu sayfa yapısı kurgulanmıştır.

Sheet 01_YURUTME_CEKIRDEGI
A1: YÜRÜTME ÇEKİRDEĞİ — ZORUNLU ÜRETİM SIRASI
A3: Adım | B3: Modül | C3: Tetikleyici | D3: Zorunlu Kanıt | E3: GEÇTİ Kuralı | F3: Hata Durumu | G3: Sonraki Aşama
A4: 1 | B4: Excel Uygunluğu | C4: Her yeni model | D4: UYGUNLUK_KARARI | E4: Excel'in rolü açık | F4: HATA / BLOKE | G4: Yönetişim
A5: 2 | B5: Yönetişim | C5: Her model | D5: Risk seviyesi + etki girdileri | E5: Seviye hesaplandı | F5: BLOKE | G5: Sözleşmeler
A6: 3 | B6: Türk Muhasebe Eşlemesi | C6: Finansal model | D6: THP hesap eşleme tablosu | E6: Kritik satırlar THP ile uyumlu | F6: HATA | G6: Sözleşmeler
A7: 4 | B7: Veri ve Anlam Sözleşmeleri | C7: Girdi/KPI varsa | D7: Veri + KPI sözleşmeleri | E7: Kapsam %100 | F7: HATA | G7: Üretim
A8: 5 | B8: Üretim | C8: Sözleşmeler GEÇTİ | D8: Çalışan Excel | E8: Tek gerçek kaynak korunmuş | F8: HATA | G8: Testler
A9: 6 | B9: Görsel/Kullanım Katmanı | C9: Motor hazır | D9: Başlıklar + renk + grafik + yönlendirme | E9: Tüm kullanıcı sayfaları standarda uygun | F9: HATA | G9: Testler
A10: 7 | B10: Testler | C10: Üretim tamam | D10: Formül/OOXML/kimlik/oracle/golden/metamorfik | E10: Uygulanabilir hard gate'ler GEÇTİ | F10: HATA | G10: Kanıt
A11: 8 | B11: Hata-Kontrol Tutarlılığı | C11: Test sonucu var | D11: Hata taraması + kontrol sonuçları | E11: Formül hatası varken GEÇTİ yok | F11: HATA | G11: Kanıt
A12: 9 | B12: Kanıt | C12: Test sonucu var | D12: Makine okunur artefakt + özet | E12: Kanıt fiziksel ve tutarlı | F12: HATA | G12: Kullanıcı Kabulü
A13: 10 | B13: Kullanıcı Kabulü | C13: Kritik görevler | D13: Gerçek ekran davranışı | E13: Kritik görevler %100 | F13: DIŞ_KABUL_GEREKLİ | G13: Ticari
A14: 11 | B14: Ticari Değer | C14: Ürün satılacaksa | D14: ROI + demo + kanıt paketi | E14: Ekonomik değer kanıtlı | F14: UYARI / HATA | G14: Pazar Doğrulama
A15: 12 | B15: Pazar Doğrulama | C15: Pazar iddiası varsa | D15: Ücretli satış/pilot/fiyat kabul kanıtı | E15: Gerçek fiyat kabul kanıtı | F15: UYGULANMAZ / HATA | G15: Yayın

Sheet 02_KONTROL_LISTESI
A1: NİHAİ KONTROL LİSTESİ — KANITSIZ GEÇİŞ YOK
A3: Kontrol No | B3: Kontrol | C3: Beklenen | D3: Zorunlu Kapı? | E3: Sonuç
A4: K01 | B4: Kullanıcının açık talebi öncelikli mi? | C4: Evet | D4: EVET
A5: K02 | B5: Mevcut yapı, formüller ve tek gerçek kaynak korunuyor mu? | C5: Evet, değişiklik gerekçeli | D5: EVET
A6: K03 | B6: Üst aşama HATA ise alt aşama GEÇTİ engelleniyor mu? | C6: Evet | D6: EVET
A7: K04 | B7: Kanıt fiziksel çıktı ve içerik doğrulaması içeriyor mu? | C7: Evet | D7: EVET
A8: K05 | B8: Excel GUI erişimi olmadan kullanıcı görünümü GEÇTİ yazılıyor mu? | C8: Hayır | D8: EVET
A9: K06 | B9: NİHAİ yalnız GEÇTİ / gerekçeli UYGULANMAZ ile mi? | C9: Evet | D9: EVET
A10: K07 | B10: Ekonomik fiyat savunusu pazar doğrulamasından ayrılmış mı? | C10: Evet | D10: EVET
A11: K08 | B11: Prestij için gereksiz modül var mı? | C11: Hayır | D11: HAYIR
A12: K09 | B12: Excel sınırları açık mı? | C12: Evet | D12: EVET
A13: K10 | B13: Teknik kaynak korunuyor mu? | C13: Evet | D13: EVET
A14: K11 | B14: Kullanıcıya görünen tüm metinler Türkçe mi? | C14: Evet | D14: EVET
A15: K12 | B15: Her kullanıcı sayfasında üst başlık var mı? | C15: Evet | D15: EVET
... A34: K31 | B34: Premium vitrin, altyapı kadar güçlü ve satış fiyatını destekleyecek seviyede mi? | C34: Evet | D34: EVET

Sheet 03_GORSEL_TASARIM
A1: GÖRSEL TASARIM VE PREMIUM EXCEL STANDARDI
A3: Alan | B3: Zorunlu Kural | C3: Uygulama | D3: Yasak | E3: Kontrol | F3: Durum
A4: Sayfa başlığı | B4: Her kullanıcı sayfasının en üstünde tek ve açık sayfa başlığı | C4: A1'den başlayan koyu lacivert başlık bandı | D4: Başlıksız sayfa | E4: Başlık kapsama = %100 | F4: ZORUNLU
A5: Sekme renkleri | B5: Sayfalar işlevine göre renk kodlanır | C5: Girdi=mavi, hesap=gri, rapor=lacivert, kontrol=kırmızı, kılavuz=altın | D5: Rastgele renk | E5: Renk semantiği tutarlı | F5: ZORUNLU
A6: Kolon düzeni | B6: Veri blokları bitişik kolonlarda ilerler | C6: Gereksiz boş kolon bırakma; yalnız gerçek bölüm ayrımı varsa kontrollü boşluk | D6: A:C veri, D boş, E:F veri gibi parçalı yapı | E6: Boş kolon taraması | F6: ZORUNLU
A7: Girdi hücreleri | B7: Kullanıcının değiştireceği alan açıkça görünür | C7: Açık sarı dolgu + mavi yazı | D7: Formülle aynı görünüm | E7: Girdi/formül ayrımı | F7: ZORUNLU
A8: Formüller | B8: Hesap hücreleri kullanıcı girdisinden ayrılır | C8: Siyah yazı; sayfalar arası bağlantı yeşil yazı | D8: Hard-code gizleme | E8: Formül sınıfı kontrolü | F8: ZORUNLU
A9: Grafik sayısı | B9: Yönetici ekranında en fazla 3 ana karar grafiği | C9: Trend, karşılaştırma, köprü/dağılım; iş kararına bağlı | D9: Grafik kalabalığı | E9: Grafik başına karar sorusu | F9: ZORUNLU
A10: Grafik stili | B10: Kurumsal ve yüksek okunabilirlik | C10: Beyaz zemin, ince gridline, tek vurgu rengi, açık birim/başlık | D10: 3B, gölge, neon, gökkuşağı renkleri | E10: Görsel inceleme | F10: ZORUNLU
A11: Grafik başlığı | B11: Grafik 'neyi' değil 'ne anlama geldiğini' söyler | C11: Örn: 'Nakit 2028'de kritik eşiğin altına iniyor' | D11: 'Nakit Grafiği' gibi anlamsız başlık | E11: Başlık karar testi | F11: ZORUNLU
A12: Birimler | B12: Tüm finansal görsellerde birim açık | C12: TL, bin TL, milyon TL, %, gün, x | D12: Birim belirsizliği | E12: Birim kapsama %100 | F12: ZORUNLU
A13: Sıfır/negatif | B13: Finansal format standardı | C13: Sıfır='-', negatif kırmızı parantez | D13: -500 veya 0,00 kalabalığı | E13: Format kontrolü | F13: ZORUNLU
A14: Yazı tipi | B14: Tek aile | C14: Aptos veya Segoe UI | D14: Karışık font | E14: Tek font kontrolü | F14: ZORUNLU
... A22: Premium vitrin | B22: Görsel kalite ürün değerinin zorunlu parçasıdır | C22: Kaliteli grafik, gerçek KPI kartı, finansal hiyerarşi, tab rengi, fonksiyonel navigasyon | D22: Sadece doğru hesap yapıp çıplak/varsayılan Excel görünümü bırakmak | E22: Görsel release incelemesi | F22: ZORUNLU

Sheet 04_MUHASEBE_THP
A1: TÜRKİYE MUHASEBE VE TEKDÜZEN HESAP PLANI STANDARDI
A3: Konu | B3: Zorunlu Standart | C3: Örnek Türkçe Ad | D3: THP / Mantık | E3: Hata Riski | F3: Kontrol
A4: Dil | B4: Kullanıcıya görünen finansal terimler Türkçe | C4: Hasılat, Satışların Maliyeti, Brüt Kâr, Faaliyet Giderleri | D4: Türk işletme kullanımına uygun | E4: İngilizce jargon | F4: Terminoloji taraması
A5: Gelir Tablosu | B5: Türk sunum sırası kullanılır | C5: Net Satışlar → Satışların Maliyeti → Brüt Kâr → Faaliyet Giderleri → Faaliyet Kârı | D5: 600/610/611; 620-623; 63x | E5: Yanlış sınıflama | F5: Hesap eşleme
A6: Bilanço | B6: Dönen/Duran Varlık ve Kısa/Uzun Vadeli Yükümlülük ayrımı | C6: Hazır Değerler, Ticari Alacaklar, Stoklar, Mali Borçlar | D6: 1xx / 2xx / 3xx / 4xx / 5xx | E6: Vade sınıfı hatası | F6: Bilanço eşitliği
A7: Nakit Akışı | B7: İşletme/Yatırım/Finansman nakit akışları ayrılır | C7: Faaliyetlerden Nakit, Yatırım Harcamaları, Finansman Nakit Akışı | D7: Dolaylı/doğrudan yöntem açık seçilir | E7: Kâr = nakit sanılması | F7: Nakit devri
A8: Ticari Alacaklar | B8: Cari ve vade mantığı korunur | C8: 120 Alıcılar | D8: 120 | E8: Tahakkuk/nakit karışması | F8: Alacak devir kontrolü
A9: Ticari Borçlar | B9: Tedarikçi borcu ayrı izlenir | C9: 320 Satıcılar | D9: 320 | E9: Gider/ödeme karışması | F9: Borç devir kontrolü
A10: Kasa/Banka | B10: Hazır değerler ayrı izlenir | C10: 100 Kasa, 102 Bankalar | D10: 100 / 102 | E10: Virmanla toplam nakdin değişmesi | F10: Virman değişmezi
A11: Stok | B11: Dikeye uygun stok türü | C11: 150 İlk Madde ve Malzeme, 153 Ticari Mallar | D11: 15x | E11: Maliyet ve stok hareketinin kopması | F11: Stok devri
A12: Maddi Duran Varlık | B12: Yatırım harcaması ve amortisman bağlantılı | C12: 253 Tesis Makine Cihazlar, 255 Demirbaşlar, 257 Birikmiş Amortismanlar | D12: 25x | E12: Yatırım/gider karışması | F12: Net defter değeri devri
A13: Mali Borçlar | B13: Kısa/uzun vadeli borç ayrımı | C13: 300 Banka Kredileri / 400 Banka Kredileri | D13: 300 / 400 | E13: Vade sınıfı yanlış | F13: Borç devri
A14: Özkaynak | B14: Sermaye ve geçmiş yıl kârları ayrı | C14: 500 Sermaye, 570 Geçmiş Yıllar Kârları, 590 Dönem Net Kârı | D14: 5xx | E14: Net kâr bağının kopması | F14: Özkaynak devri
... A18: İstisna | B18: TFRS özel ürün varsa fark açık yazılır | C18: Tekdüzen raporlama ≠ TFRS finansal tablo sunumu | D18: Amaç belirtilir | E18: Standartları karıştırma | F18: Model amacı kontrolü

Sheet 05_KARAR_SATIS
A1: KARAR, GÜVEN VE SATIŞA HAZIRLIK STANDARDI
A3: Alan | B3: Müşteri Sorusu | C3: Zorunlu Ürün Davranışı | D3: Kanıt | E3: Başarısızlık Durumu | F3: Kapı
A4: 5 saniye | B4: Bu ürün neyi çözüyor? | C4: İlk ekranda hedef kullanıcı + pahalı problem + sonuç görünür | D4: Başlık + alt mesaj + gerçek ekran | E4: Ürün yalnız teknik isim | F4: HATA
A5: Acı | B5: Sorun bana neye mal oluyor? | C5: Mümkünse müşterinin kendi verisiyle parasal/zaman etkisi hesaplanır | D5: ROI/acı hesaplama yöntemi | E5: Uydurma tasarruf | F5: HATA
A6: Karar | B6: Bu bilgiyle ne yapacağım? | C6: Her kritik KPI aksiyona bağlanır | D6: KARAR_KUYRUGU | E6: Sadece rapor | F6: HATA
A7: Güven | B7: Bu sayıya neden inanayım? | C7: Kaynak, formül mantığı, kontrol ve son doğrulama görünür | D7: Kontroller + kaynak izi + sürüm | E7: Prestij kelimesi | F7: HATA
A8: Referans | B8: Müşteri yorumu yoksa ne göstereceğim? | C8: Önce/Sonra + Karar Vakası + Hata Önleme Vakası üretilir | D8: Demo/örnek çıktı | E8: Kanıtsız iddia | F8: HATA
A9: Senaryo | B9: Ne olursa işler bozulur? | C9: Baz/Aşağı/Yukarı veya uygun stres senaryosu | D9: Senaryo karşılaştırma | E9: Dekoratif senaryo | F9: HATA
A10: Ters stres | B10: Hangi eşikte karar kırılır? | C10: En az bir kritik sürücü için kırılma eşiği | D10: Kırılma eşiği tablosu | E10: Sadece +/- %10 | F10: UYARI/HATA
A11: Hata tutarlılığı | B11: Formül hata verirse ne olur? | C11: Kontrol GEÇTİ veremez; BLOKE/HATA üretir | D11: Hata taraması | E11: Hata + GEÇTİ birlikte | F11: HATA
A12: Karar motoru | B12: Ne oldu, neden oldu? | C12: Sorun + neden + parasal etki + aksiyon + son tarih | D12: Karar tablosu | E12: Boş sayfa / isim düzeyi modül | F12: HATA
A13: Yönetici özeti | B13: 5 saniyede ne görmeliyim? | C13: Bugün / ne değişti / ne bozulacak / neden / ne yapmalıyım / güven | D13: Yönetici özeti ekranı | E13: KPI kutusu yığını | F13: HATA
A14: Teklif | B14: Neden satın almalıyım? | C14: Dosya özellikleri yerine sonuç ve kaçınılan maliyet sunulur | D14: Ürün sayfası kanıt eşlemesi | E14: Özellik listesiyle satış | F14: HATA
... A19: Pazar kanıtı | B19: Piyasa gerçekten ödüyor mu? | C19: Satış/pilot/LOI/fiyat kabulü olmadan pazar doğrulandı yazılmaz | D19: Gerçek işlem kanıtı | E19: Tahmini talep = satış kabulü | F19: HATA

Sheet KAPAK
A1: KAPAK — Yurt Dışı Yapılanma Vergi Simülatörü
A3: Yurt Dışı Yapılanma Vergi Simülatörü
A4: Ülke, yapılanma tipi ve kâr girdilerini girin; efektif vergi, çift vergilendirme yükü ve şube / iştirak / ofis kararını senaryolu üretin.
A6: Bu ürün ne sağlar?
A7: • Şube / iştirak / limited / ofis senaryolarında efektif vergi karşılaştırması
A8: • Çift vergilendirme yükü, TR ek matrah riski ve TF puanı ile risk rozeti
A9: • Çok yıllı kural tablosu (2025/2026/2027) + M-SEN kural değişimi
A10: • Altın vakalar ve KANIT_RAPORU (A4 imza)
A11: • Belirsizlik beyanı: PE atıf yorumu A / B
A13: Kimler için?
A14: • SMMM / YMM — yapı önerisini imzalı kanıtla sunmak
A15: • CFO — efektif vergi ve çift vergi yükünü bütçelemek
... A21: Sürüm 1.0.0 | 2026 | ExcelArşiv | Lisans: Tek kullanıcı

Sheet HIZLI_BASLANGIC
A1: HIZLI BASLANGIC — Yurt Dışı Yapılanma Vergi Simülatörü
A3: Üç adımda sonuç
A5: Adım 1 — Girdiler | B5: GIRDI'de ülke, yapılanma tipi, YD kâr, yerel oran, stopaj, kur, istisna ve TF puanını girin.
A6: Adım 2 — Karar | B6: PANO'da efektif vergi, çift vergi yükü, yapı önerisi ve UYGUN/DİKKAT/RİSKLİ rozetini izleyin.
A7: Adım 3 — Kanıt | B7: KANIT_RAPORU'nu yazdırıp imzalayın; VAKALAR tutarlılığını kontrol edin.
A9: Sık yapılan hatalar
A10: • YD kârı TL yerine döviz biriminde girip kuru 1 bırakmak
A11: • İştirak istisnasını yanlış işaretlemek
A12: • TF risk puanını boş bırakmak
A14: Bu dosya karar destek aracıdır; kesin vergi sonucu veya hukuki görüş yerine geçmez.

Sheet GIRDI
A1: GIRDI — Yurt Dışı Yapılanma Vergi Simülatörü
A3: Yapılanma girdileri
A4: Sarı hücreler manuel giriştir. TL dönüşümü ve vergi formülle üretilir.
A5: Alan | B5: Değer | C5: Birim
A6: Şirket Adı | B6: Örnek Holding A.Ş. | C6: metin
A7: Dönem | B7: 2026 | C7: metin
A8: Hesap Yılı | B8: 2026 | C8: yıl
A9: Ülke | B9: Almanya | C9: metin
A10: Yapılanma Tipi | B10: İŞTİRAK | C10: metin
A11: Yurt Dışı Kâr [PB] | B11: 500000 | C11: PB
A12: Yerel Vergi Oranı [%] | B12: 0.3 | C12: %
A13: Stopaj Oranı [%] | B13: 0.05 | C13: %
A14: Döviz Kuru [TL/PB] | B14: 36 | C14: TL/PB
A15: İştirak İstisnası | B15: Evet | C15: metin
A16: TF Risk Puanı | B16: 40 | C16: puan
A17: PE Atıf Yorumu (A/B) | B17: A | C17: metin
A19: YD Kâr TL [₺] | B19: =IFERROR(B11*B14,0)
A20: Giriş doluluk (kalite) | B20: =IFERROR(IF(OR(COUNTA(B6:B17)=0,ydv_girisBeklenen=0),0,ROUND(COUNTA(B6:B17)/ydv_girisBeklenen*100,0)),0)
A22: Giriş tablosu (otomasyon / boş-mod)
A23: Alan Anahtarı | B23: Değer | C23: Birim | D23: Zorunlu | E23: Kaynak | F23: Kontrol
A24: sirket_adi | B24: Örnek Holding A.Ş. | C24: metin | D24: Evet | E24: GIRDI | F24: =IF($A24="","",IF($B24="","EKSİK","TAM"))
A25: donem | B25: 2026 | C25: metin | D25: Evet | E25: GIRDI | F25: =IF($A25="","",IF($B25="","EKSİK","TAM"))
A26: hesapYili | B26: 2026 | C26: yıl | D26: Evet | E26: GIRDI | F26: =IF($A26="","",IF($B26="","EKSİK","TAM"))
A27: ulke | B27: Almanya | C27: metin | D27: Evet | E27: GIRDI | F27: =IF($A27="","",IF($B27="","EKSİK","TAM"))
A28: yapilanma_tipi | B28: İŞTİRAK | C28: liste | D28: Evet | E28: GIRDI | F28: =IF($A28="","",IF($B28="","EKSİK","TAM"))
A29: yurt_disi_kar | B29: 500000 | C29: PB | D29: Evet | E29: GIRDI | F29: =IF($A29="","",IF($B29="","EKSİK","TAM"))
A30: yerel_vergi_orani | B30: 0.3 | C30: % | D30: Evet | E30: GIRDI | F30: =IF($A30="","",IF($B30="","EKSİK","TAM"))
A31: stopaj_orani | B31: 0.05 | C31: % | D31: Evet | E31: GIRDI | F31: =IF($A31="","",IF($B31="","EKSİK","TAM"))
A32: doviz_kuru | B32: 36 | C32: TL/PB | D32: Evet | E32: GIRDI | F32: =IF($A32="","",IF($B32="","EKSİK","TAM"))
A33: istirak_istisnasi | B33: Evet | C33: E/H | D33: Evet | E33: GIRDI | F33: =IF($A33="","",IF($B33="","EKSİK","TAM"))
A34: tf_risk_puani | B34: 40 | C34: puan | D34: Evet | E34: GIRDI | F34: =IF($A34="","",IF($B34="","EKSİK","TAM"))
A35: yorum_modu | B35: A | C35: A/B | D35: Evet | E35: GIRDI | F35: =IF($A35="","",IF($B35="","EKSİK","TAM"))
F36: =IF($A36="","",IF($B36="","EKSİK","TAM"))
F37: =IF($A37="","",IF($B37="","EKSİK","TAM"))
F38: =IF($A38="","",IF($B38="","EKSİK","TAM"))
F39: =IF($A39="","",IF($B39="","EKSİK","TAM"))
F40: =IF($A40="","",IF($B40="","EKSİK","TAM"))
F41: =IF($A41="","",IF($B41="","EKSİK","TAM"))
F42: =IF($A42="","",IF($B42="","EKSİK","TAM"))
F43: =IF($A43="","",IF($B43="","EKSİK","TAM"))
...

Sheet KURALLAR
A1: KURALLAR — Yurt Dışı Yapılanma Vergi Simülatörü
A3: Mevzuat kural tablosu (yıl yan yana)
A4: Oranlar MOTOR'da sabit yazılmaz; INDEX/MATCH ile buradan çekilir.
A6: kural_id | B6: madde | C6: kural_adi | D6: kosul_metni | E6: parametre_adi | F6: deger_2025 | G6: deger_2026 | H6: deger_2027 | I6: yururluk | J6: kaynak | K6: aktif_deger
A7: YDV-001 | B7: KVK md.32 | C7: tr_kv_orani | D7: her zaman | E7: tr_kv_orani | F7: 0.25 | G7: 0.25 | H7: 0.25 | I7: 01.01.2025 | J7: KVK md.32 | K7: =IF($A7="","",IFERROR(CHOOSE(MAX(1,MIN(3,IF(OR(hesapYili="",hesapYili=0),1,hesapYili-ydv_yilTaban))),$F7,$G7,$H7),0))
A8: YDV-002 | B8: KVK md.5/1-a | C8: istirak_istisna_orani | D8: istirak+koşul | E8: istirak_istisna_orani | F8: 1 | G8: 1 | H8: 1 | I8: 01.01.2025 | J8: KVK md.5/1-a | K8: =IF($A8="","",IFERROR(CHOOSE(MAX(1,MIN(3,IF(OR(hesapYili="",hesapYili=0),1,hesapYili-ydv_yilTaban))),$F8,$G8,$H8),0))
A9: YDV-003 | B9: KVK md.33 | C9: mahsup_tavan_carpan | D9: yabanci_vergi>0 | E9: mahsup_tavan_carpan | F9: 1 | G9: 1 | H9: 1 | I9: 01.01.2025 | J9: KVK md.33 | K9: =IF($A9="","",IFERROR(CHOOSE(MAX(1,MIN(3,IF(OR(hesapYili="",hesapYili=0),1,hesapYili-ydv_yilTaban))),$F9,$G9,$H9),0))
A10: YDV-004 | B10: VUK/TF | C10: tf_risk_esik | D10: her zaman | E10: tf_risk_esik | F10: 70 | G10: 70 | H10: 70 | I10: 01.01.2025 | J10: TF mevzuatı | K10: =IF($A10="","",IFERROR(CHOOSE(MAX(1,MIN(3,IF(OR(hesapYili="",hesapYili=0),1,hesapYili-ydv_yilTaban))),$F10,$G10,$H10),0))
A11: YDV-005 | B11: Genel | C11: yuvarlama | D11: her hesap | E11: yuvarlama_ondalik | F11: 2 | G11: 2 | H11: 2 | I11: 01.01.2025 | J11: Uygulama notu | K11: =IF($A11="","",IFERROR(CHOOSE(MAX(1,MIN(3,IF(OR(hesapYili="",hesapYili=0),1,hesapYili-ydv_yilTaban))),$F11,$G11,$H11),0))
A14: Kural-yıl matrisi özeti
A15: TR KV oranı (aktif yıl) | B15: =IFERROR(INDEX(CHOOSE(MAX(1,MIN(3,IF(OR(hesapYili="",hesapYili=0),1,hesapYili-ydv_yilTaban))),tblKurallar[deger_2025],tblKurallar[deger_2026],tblKurallar[deger_2027]),MATCH("YDV-001",tblKurallar[kural_id],0)),0)
A16: İştirak istisna oranı | B16: =IFERROR(INDEX(CHOOSE(MAX(1,MIN(3,IF(OR(hesapYili="",hesapYili=0),1,hesapYili-ydv_yilTaban))),tblKurallar[deger_2025],tblKurallar[deger_2026],tblKurallar[deger_2027]),MATCH("YDV-002",tblKurallar[kural_id],0)),0)
A17: Matris metni | B17: =_xlfn.TEXTJOIN(" | ",TRUE,"YDV-001=",TEXT(B15,"0.0%"),"YDV-002=",TEXT(B16,"0.0%"),"yıl=",hesapYili)

Sheet MOTOR
A1: MOTOR — Yurt Dışı Yapılanma Vergi Simülatörü
A3: Hesap zinciri — her adımda kural_id
A4: Oranlar tblKurallar'dan çekilir; sabit oran yoktur.
A6: adim | B6: ad | C6: formul | D6: birim | E6: ne_ise_yarar | F6: kural_id | G6: deger
A7: 1 | B7: Hesap yılı oku | C7: =IFERROR(hesapYili,0) | D7: yıl | E7: Aktif mevzuat yılı | F7: YDV-005 | G7: =IFERROR(hesapYili,0)
A8: 2 | B8: TR KV oranı | C8: =IFERROR(INDEX(CHOOSE(MAX(1,MIN(3,IF(OR(hesapYili="",hesapYili=0),1,hesapYili-ydv_yilTaban))),tblKurallar[deger_2025],tblKurallar[deger_2026],tblKurallar[deger_2027]),MATCH("YDV-001",tblKurallar[kural_id],0)),0) | D8: oran | E8: KVK md.32 oranı | F8: YDV-001 | G8: =IFERROR(INDEX(CHOOSE(MAX(1,MIN(3,IF(OR(hesapYili="",hesapYili=0),1,hesapYili-ydv_yilTaban))),tblKurallar[deger_2025],tblKurallar[deger_2026],tblKurallar[deger_2027]),MATCH("YDV-001",tblKurallar[kural_id],0)),0)
A9: 3 | B9: İştirak istisna oranı | C9: =IFERROR(INDEX(CHOOSE(MAX(1,MIN(3,IF(OR(hesapYili="",hesapYili=0),1,hesapYili-ydv_yilTaban))),tblKurallar[deger_2025],tblKurallar[deger_2026],tblKurallar[deger_2027]),MATCH("YDV-002",tblKurallar[kural_id],0)),0) | D9: oran | E9: KVK md.5/1-a | F9: YDV-002 | G9: =IFERROR(INDEX(CHOOSE(MAX(1,MIN(3,IF(OR(hesapYili="",hesapYili=0),1,hesapYili-ydv_yilTaban))),tblKurallar[deger_2025],tblKurallar[deger_2026],tblKurallar[deger_2027]),MATCH("YDV-002",tblKurallar[kural_id],0)),0)
A10: 4 | B10: Mahsup tavan çarpanı | C10: =IFERROR(INDEX(CHOOSE(MAX(1,MIN(3,IF(OR(hesapYili="",hesapYili=0),1,hesapYili-ydv_yilTaban))),tblKurallar[deger_2025],tblKurallar[deger_2026],tblKurallar[deger_2027]),MATCH("YDV-003",tblKurallar[kural_id],0)),0) | D10: çarpan | E10: KVK md.33 tavan | F10: YDV-003 | G10: =IFERROR(INDEX(CHOOSE(MAX(1,MIN(3,IF(OR(hesapYili="",hesapYili=0),1,hesapYili-ydv_yilTaban))),tblKurallar[deger_2025],tblKurallar[deger_2026],tblKurallar[deger_2027]),MATCH("YDV-003",tblKurallar[kural_id],0)),0)
A11: 5 | B11: TF risk eşiği | C11: =IFERROR(INDEX(CHOOSE(MAX(1,MIN(3,IF(OR(hesapYili="",hesapYili=0),1,hesapYili-ydv_yilTaban))),tblKurallar[deger_2025],tblKurallar[deger_2026],tblKurallar[deger_2027]),MATCH("YDV-004",tblKurallar[kural_id],0)),0) | D11: puan | E11: TF eşik puanı | F11: YDV-004 | G11: =IFERROR(INDEX(CHOOSE(MAX(1,MIN(3,IF(OR(hesapYili="",hesapYili=0),1,hesapYili-ydv_yilTaban))),tblKurallar[deger_2025],tblKurallar[deger_2026],tblKurallar[deger_2027]),MATCH("YDV-004",tblKurallar[kural_id],0)),0)
A12: 6 | B12: Yuvarlama ondalık | C12: =IFERROR(INDEX(CHOOSE(MAX(1,MIN(3,IF(OR(hesapYili="",hesapYili=0),1,hesapYili-ydv_yilTaban))),tblKurallar[deger_2025],tblKurallar[deger_2026],tblKurallar[deger_2027]),MATCH("YDV-005",tblKurallar[kural_id],0)),0) | D12: adet | E12: Yuvarlama basamağı | F12: YDV-005 | G12: =IFERROR(INDEX(CHOOSE(MAX(1,MIN(3,IF(OR(hesapYili="",hesapYili=0),1,hesapYili-ydv_yilTaban))),tblKurallar[deger_2025],tblKurallar[deger_2026],tblKurallar[deger_2027]),MATCH("YDV-005",tblKurallar[kural_id],0)),0)
A13: 7 | B13: YD kâr PB | C13: =IFERROR(GIRDI!B11,0) | D13: PB | E13: Yerel para kârı | F13: YDV-001 | G13: =IFERROR(GIRDI!B11,0)
A14: 8 | B14: Yerel vergi oranı | C14: =IFERROR(GIRDI!B12,0) | D14: oran | E14: Ülke KV oranı | F14: YDV-001 | G14: =IFERROR(GIRDI!B12,0)
A15: 9 | B15: Stopaj oranı | C15: =IFERROR(GIRDI!B13,0) | D15: oran | E15: Stopaj | F15: YDV-001 | G15: =IFERROR(GIRDI!B13,0)
A16: 10 | B16: Döviz kuru | C16: =IFERROR(GIRDI!B14,0) | D16: kur | E16: TL / PB | F16: YDV-005 | G16: =IFERROR(GIRDI!B14,0)
A17: 11 | B17: TF risk puanı | C17: =IFERROR(GIRDI!B16,0) | D17: puan | E17: Transfer fiyat riski | F17: YDV-004 | G17: =IFERROR(GIRDI!B16,0)
A18: 12 | B18: İstisna bayrağı | C18: =IFERROR(IF(GIRDI!B15="Evet",1,0),0) | D18: bayrak | E18: İştirak istisnası | F18: YDV-002 | G18: =IFERROR(IF(GIRDI!B15="Evet",1,0),0)
A19: 13 | B19: Yorum çarpanı | C19: =IFERROR(IF(GIRDI!B17="B",1+ydv_peArtisOran,1),0) | D19: çarpan | E19: PE atıf A/B | F19: YDV-005 | G19: =IFERROR(IF(GIRDI!B17="B",1+ydv_peArtisOran,1),0)
A20: 14 | B20: YD kâr TL | C20: =IFERROR(ROUND(G13*G16,MAX(0,MIN(ydv_yuvarMax,IFERROR(N(G12),0)))),0) | D20: TL | E20: Kâr × kur | F20: YDV-005 | G20: =IFERROR(ROUND(G13*G16,MAX(0,MIN(ydv_yuvarMax,IFERROR(N(G12),0)))),0)
A21: 15 | B21: Yerel vergi TL | C21: =IFERROR(ROUND(G20*G14,MAX(0,MIN(ydv_yuvarMax,IFERROR(N(G12),0)))),0) | D21: TL | E21: YD kâr × yerel oran | F21: YDV-001 | G21: =IFERROR(ROUND(G20*G14,MAX(0,MIN(ydv_yuvarMax,IFERROR(N(G12),0)))),0)
A22: 16 | B22: Stopaj TL | C22: =IFERROR(ROUND(G20*G15,MAX(0,MIN(ydv_yuvarMax,IFERROR(N(G12),0)))),0) | D22: TL | E22: YD kâr × stopaj | F22: YDV-001 | G22: =IFERROR(ROUND(G20*G15,MAX(0,MIN(ydv_yuvarMax,IFERROR(N(G12),0)))),0)
A23: 17 | B23: TR matrah | C23: =IFERROR(ROUND(IF(GIRDI!B10="ŞUBE",G20,IF(GIRDI!B10="OFİS",G20*ydv_ofisMatrahOran*G19,IF(AND(OR(GIRDI!B10="İŞTİRAK",GIRDI!B10="LİMİTED"),G18=1),G20*(1-G9)*ydv_dagitimOran,G20))),MAX(0,MIN(ydv_yuvarMax,IFERROR(N(G12),0)))),0) | D23: TL | E23: Yapıya göre TR matrah | F23: YDV-002 | G23: =IFERROR(ROUND(IF(GIRDI!B10="ŞUBE",G20,IF(GIRDI!B10="OFİS",G20*ydv_ofisMatrahOran*G19,IF(AND(OR(GIRDI!B10="İŞTİRAK",GIRDI!B10="LİMİTED"),G18=1),G20*(1-G9)*ydv_dagitimOran,G20))),MAX(0,MIN(ydv_yuvarMax,IFERROR(N(G12),0)))),0)
A24: 18 | B24: TR brüt KV | C24: =IFERROR(ROUND(G23*G8,MAX(0,MIN(ydv_yuvarMax,IFERROR(N(G12),0)))),0) | D24: TL | E24: Matrah × TR KV | F24: YDV-001 | G24: =IFERROR(ROUND(G23*G8,MAX(0,MIN(ydv_yuvarMax,IFERROR(N(G12),0)))),0)
A25: 19 | B25: Mahsup tavan | C25: =IFERROR(ROUND(G24*G10,MAX(0,MIN(ydv_yuvarMax,IFERROR(N(G12),0)))),0) | D25: TL | E25: Mahsup tavanı | F25: YDV-003 | G25: =IFERROR(ROUND(G24*G10,MAX(0,MIN(ydv_yuvarMax,IFERROR(N(G12),0)))),0)
A26: 20 | B26: Mahsup tutarı | C26: =IFERROR(MIN(G21+G22,G25),0) | D26: TL | E26: Yabancı vergi mahsubu | F26: YDV-003 | G26: =IFERROR(MIN(G21+G22,G25),0)
A27: 21 | B27: TR net KV | C27: =IFERROR(MAX(0,G24-G26),0) | D27: TL | E27: TR'de kalan KV | F27: YDV-003 | G27: =IFERROR(MAX(0,G24-G26),0)
A28: 22 | B28: Toplam vergi | C28: =IFERROR(G21+G22+G27,0) | D28: TL | E28: Yerel+stopaj+TR net | F28: YDV-001 | G28: =IFERROR(G21+G22+G27,0)
A29: 23 | B29: Efektif vergi | C29: =IFERROR(IF(G20=0,0,G28/G20),0) | D29: oran | E29: Toplam/kâr | F29: YDV-001 | G29: =IFERROR(IF(G20=0,0,G28/G20),0)
A30: 24 | B30: Çift vergi yükü | C30: =IFERROR(MAX(0,G21+G22+G27-G24),0) | D30: TL | E30: Çakışan yük | F30: YDV-003 | G30: =IFERROR(MAX(0,G21+G22+G27-G24),0)
A31: 25 | B31: TR ek matrah riski | C31: =IFERROR(ROUND(G20*G17/ydv_tfBolum*ydv_ekMatrahCarpan*G19,MAX(0,MIN(ydv_yuvarMax,IFERROR(N(G12),0)))),0) | D31: TL | E31: TF kaynaklı ek matrah | F31: YDV-004 | G31: =IFERROR(ROUND(G20*G17/ydv_tfBolum*ydv_ekMatrahCarpan*G19,MAX(0,MIN(ydv_yuvarMax,IFERROR(N(G12),0)))),0)
A32: 26 | B32: Karar kodu | C32: =IFERROR(IF(COUNTA(tblGirdi[Alan Anahtarı])=0,"VERI_YOK",IF(OR(G17>=G11,G30>G20*ydv_ciftVergiEsik),"RISKLI",IF(OR(G17>=ydv_dikkatEsik,G30>G20*ydv_dikkatCiftEsik),"DIKKAT","UYGUN"))),"") | D32: kod | E32: Risk karar kodu | F32: YDV-004 | G32: =IFERROR(IF(COUNTA(tblGirdi[Alan Anahtarı])=0,"VERI_YOK",IF(OR(G17>=G11,G30>G20*ydv_ciftVergiEsik),"RISKLI",IF(OR(G17>=ydv_dikkatEsik,G30>G20*ydv_dikkatCiftEsik),"DIKKAT","UYGUN"))),"")
A33: 27 | B33: Karar metni | C33: =IFERROR(IF(G32="VERI_YOK","VERİ YOK",IF(G32="RISKLI","RİSKLİ",IF(G32="DIKKAT","DİKKAT","UYGUN"))),"") | D33: metin | E33: Kullanıcıya karar | F33: YDV-004 | G33: =IFERROR(IF(G32="VERI_YOK","VERİ YOK",IF(G32="RISKLI","RİSKLİ",IF(G32="DIKKAT","DİKKAT","UYGUN"))),"")
A34: 28 | B34: Yapı önerisi | C34: =IFERROR(IF(G32="VERI_YOK","VERİ YOK",IF(AND(G18=1,OR(GIRDI!B10="İŞTİRAK",GIRDI!B10="LİMİTED")),"İŞTİRAK",IF(GIRDI!B10="OFİS","OFİS",IF(G29<=ydv_subeEfektifEsik,"ŞUBE","İŞTİRAK")))),"") | D34: metin | E34: Önerilen yapı | F34: YDV-002 | G34: =IFERROR(IF(G32="VERI_YOK","VERİ YOK",IF(AND(G18=1,OR(GIRDI!B10="İŞTİRAK",GIRDI!B10="LİMİTED")),"İŞTİRAK",IF(GIRDI!B10="OFİS","OFİS",IF(G29<=ydv_subeEfektifEsik,"ŞUBE","İŞTİRAK")))),"")
A35: 29 | B35: Gerekçe | C35: =IFERROR(IF(G32="VERI_YOK","Giriş tablosu boş — hesap yapılamaz.",IF(G32="RISKLI","TF eşiği aşıldı veya çift vergi yükü yüksek; yapı ve TF dosyasını gözden geçirin.",IF(G32="DIKKAT","Orta risk: mahsup, stopaj ve PE atıfını doğrulayın.","Efektif vergi ve TF profili kabul edilebilir aralıkta."))),"") | D35: metin | E35: Gerekçe cümlesi | F35: YDV-004 | G35: =IFERROR(IF(G32="VERI_YOK","Giriş tablosu boş — hesap yapılamaz.",IF(G32="RISKLI","TF eşiği aşıldı veya çift vergi yükü yüksek; yapı ve TF dosyasını gözden geçirin.",IF(G32="DIKKAT","Orta risk: mahsup, stopaj ve PE atıfını doğrulayın.","Efektif vergi ve TF profili kabul edilebilir aralıkta."))),"")
A36: 30 | B36: Yerel / kâr payı | C36: =IFERROR(IF(G20=0,0,G21/G20),0) | D36: oran | E36: T1 pay | F36: YDV-001 | G36: =IFERROR(IF(G20=0,0,G21/G20),0)
A37: 31 | B37: TR net / toplam | C37: =IFERROR(IF(G28=0,0,G27/G28),0) | D37: oran | E37: T2 pay | F37: YDV-001 | G37: =IFERROR(IF(G28=0,0,G27/G28),0)
A38: 32 | B38: Mahsup / brüt | C38: =IFERROR(IF(G24=0,0,G26/G24),0) | D38: oran | E38: O6 yoğunluk | F38: YDV-003 | G38: =IFERROR(IF(G24=0,0,G26/G24),0)
A39: 33 | B39: Güven skoru | C39: =IFERROR(ROUND(IF(OR(COUNTA(GIRDI!B6:B17)=0,ydv_girisBeklenen=0),0,COUNTA(GIRDI!B6:B17)/ydv_girisBeklenen*100),0),0) | D39: puan | E39: Giriş bütünlüğü | F39: YDV-005 | G39: =IFERROR(ROUND(IF(OR(COUNTA(GIRDI!B6:B17)=0,ydv_girisBeklenen=0),0,COUNTA(GIRDI!B6:B17)/ydv_girisBeklenen*100),0),0)
A40: 34 | B40: Risk skoru | C40: =IFERROR(IF(G32="VERI_YOK",0,IF(G32="UYGUN",ydv_riskDusuk,IF(G32="DIKKAT",ydv_riskOrta,ydv_riskYuksek))),0) | D40: puan | E40: Risk skoru | F40: YDV-004 | G40: =IFERROR(IF(G32="VERI_YOK",0,IF(G32="UYGUN",ydv_riskDusuk,IF(G32="DIKKAT",ydv_riskOrta,ydv_riskYuksek))),0)
A41: 35 | B41: Senaryo iyimser kâr | C41: =IFERROR(G20*ydv_senaryoIyi,0) | D41: TL | E41: İyimser kâr TL | F41: YDV-001 | G41: =IFERROR(G20*ydv_senaryoIyi,0)
A42: 36 | B42: Senaryo kötümser kâr | C42: =IFERROR(G20*ydv_senaryoKotu,0) | D42: TL | E42: Kötümser kâr TL | F42: YDV-001 | G42: =IFERROR(G20*ydv_senaryoKotu,0)
...

Sheet SENARYO
A1: SENARYO — Yurt Dışı Yapılanma Vergi Simülatörü
A3: Senaryo ve duyarlılık
A5: Senaryo | B5: Kâr Çarpanı | C5: Toplam Vergi | D5: Efektif | E5: Karar | G5: VergiDemo
A6: İyimser | B6: =IFERROR(ydv_senaryoIyi+N(GIRDI!B11)*ydv_sifirCarpan,0) | C6: =IFERROR(ROUND(IFERROR(ydv_karTl,0)*B6*IFERROR(ydv_efektifVergi,0),2),0) | D6: =IFERROR(ydv_efektifVergi,0) | E6: =IF(COUNTA(tblGirdi[Alan Anahtarı])=0,"VERİ YOK",IFERROR(ydv_kararMetni,"-")) | G6: 5940000
A7: Baz | B7: =IFERROR(ydv_bazCarpan+N(GIRDI!B11)*ydv_sifirCarpan,ydv_bazCarpan) | C7: =IFERROR(ydv_toplamVergi,0) | D7: =IFERROR(ydv_efektifVergi,0) | E7: =IF(COUNTA(tblGirdi[Alan Anahtarı])=0,"VERİ YOK",IFERROR(ydv_kararMetni,"-")) | G7: 6300000
A8: Kötümser | B8: =IFERROR(ydv_senaryoKotu+N(GIRDI!B11)*ydv_sifirCarpan,0) | C8: =IFERROR(ROUND(IFERROR(ydv_karTl,0)*B8*IFERROR(ydv_efektifVergi,0),2),0) | D8: =IFERROR(ydv_efektifVergi,0) | E8: =IF(COUNTA(tblGirdi[Alan Anahtarı])=0,"VERİ YOK",IFERROR(ydv_kararMetni,"-")) | G8: 7200000
A9: M-SEN TR+1 | B9: =IFERROR(ydv_bazCarpan+N(GIRDI!B11)*ydv_sifirCarpan,ydv_bazCarpan) | C9: =IFERROR(MOTOR!G48,0) | D9: =IFERROR(IF(ydv_karTl=0,0,MOTOR!G48/ydv_karTl),0) | E9: =IF(COUNTA(tblGirdi[Alan Anahtarı])=0,"VERİ YOK","DİKKAT") | G9: 6750000
A11: Senaryo bant genişliği (iyimser−kötümser vergi) | B11: =IFERROR(C6-C8,0)
A12: Senaryo yorumu | B12: =IFERROR(_xlfn.TEXTJOIN("; ",TRUE,"İyimser ",TEXT(C6,"₺ #,##0")," · Baz ",TEXT(C7,"₺ #,##0")," · Kötümser ",TEXT(C8,"₺ #,##0")," · Bant ",TEXT(B11,"₺ #,##0")),"-")
A14: Duyarlılık (tornado)
A15: Değişken | B15: Etki [₺] | C15: Sıra | E15: EtkiDemo
A16: Tornado kur etkisi | B16: =IFERROR(MOTOR!G51,0) | C16: =IFERROR(IF(B16>=MAX(B16:B18),ydv_siraBir,IF(B16>=MIN(B16:B18)+ABS(B16-B17),ydv_siraIki,ydv_siraUc)),ydv_siraUc) | E16: 270000
A17: Tornado yerel oran | B17: =IFERROR(MOTOR!G52,0) | C17: =IFERROR(IF(B17>=MAX(B16:B18),ydv_siraBir,IF(B17=MEDIAN(B16:B18),ydv_siraIki,ydv_siraUc)),ydv_siraUc) | E17: 180000
A18: Tornado TF etkisi | B18: =IFERROR(MOTOR!G53,0) | C18: =IFERROR(IF(B18>=MAX(B16:B18),ydv_siraBir,IF(B18=MEDIAN(B16:B18),ydv_siraIki,ydv_siraUc)),ydv_siraUc) | E18: 360000
A19: Duyarlılık sıra özeti | B19: =IFERROR(CONCATENATE("1)",INDEX(A16:A18,MATCH(ydv_siraBir,C16:C18,0))," 2)",INDEX(A16:A18,MATCH(ydv_siraIki,C16:C18,0))),"-")
A20: Duyarlılık yorumu | B20: =_xlfn.TEXTJOIN("; ",TRUE,"En yüksek etki ",TEXT(MAX(B16:B18),"₺ #,##0")," TL — öncelik bu değişkende")
A22: M-SEN kural değişimi toplam | B22: =C9
A23: M-SEN yorumu | B23: =_xlfn.TEXTJOIN("; ",TRUE,"TR KV +1 puan senaryosunda toplam vergi ",TEXT(C9,"₺ #,##0")," TL")
A25: Tahmin aralığı (toplam vergi) | B25: =MOTOR!G50 | C25: =ydv_toplamVergi | D25: =MOTOR!G49
A26: Tahmin (FORECAST)
A27: Seri nokta | D27: TrendDemo
A28: 1 | B28: =C6 | D28: 5940000
A29: 2 | B29: =C7 | D29: 6300000
A30: 3 | B30: =C8 | D30: 7200000
A31: 4 | B31: =C9 | D31: 6750000
A32: Tahmin sonraki | B32: =IFERROR(FORECAST.LINEAR(ydv_tahminX,B28:B31,A28:A31),0)
A33: Tahmin yorumu | B33: =_xlfn.TEXTJOIN("; ",TRUE,"Tahmin ",TEXT(B32,"₺ #,##0")," · Alt ",TEXT(B25,"₺ #,##0")," · Üst ",TEXT(D25,"₺ #,##0"))

Sheet VAKALAR
A1: VAKALAR — Yurt Dışı Yapılanma Vergi Simülatörü
A3: Tebliğ tarzı altın vakalar
A5: vaka_id | B5: aciklama | C5: girdi_ozeti | D5: beklenen_sonuc | E5: hesaplanan | F5: fark | G5: durum | H5: kaynak | J5: Beklenen | K5: Hesaplanan
A6: V-001 | B6: Yerel vergi — Almanya %30 | C6: kar_tl=vaka_kar_1; oran=vaka_yerel_oran | D6: 5400000 | E6: =IFERROR(ROUND(vaka_kar_1*vaka_yerel_oran+N(GIRDI!B11)*ydv_sifirCarpan,2),0) | F6: =IFERROR(D6-E6,0) | G6: =IF($A6="","",IFERROR(IF(ABS($F6)<=ydv_tolerans,"TUTARLI","KIRIK"),"KIRIK")) | H6: Yerel KV örnek | J6: 5400000 | K6: 5400000
A7: V-002 | B7: TR brüt KV — şube matrah | C7: kar_tl=vaka_kar_1; TR=%25 | D7: 4500000 | E7: =IFERROR(ROUND(vaka_kar_1*INDEX(tblKurallar[deger_2025],MATCH("YDV-001",tblKurallar[kural_id],0)),2),0) | F7: =IFERROR(D7-E7,0) | G7: =IF($A7="","",IFERROR(IF(ABS($F7)<=ydv_tolerans,"TUTARLI","KIRIK"),"KIRIK")) | H7: KVK md.32 | J7: 4500000 | K7: 4500000
A8: V-003 | B8: İştirak istisna sonrası TR matrah | C8: kar=vaka_kar_1; istisna=%100; dağıtım=ydv_dagitimOran | D8: 0 | E8: =IFERROR(ROUND(vaka_kar_1*(1-INDEX(tblKurallar[deger_2025],MATCH("YDV-002",tblKurallar[kural_id],0)))*ydv_dagitimOran,2),0) | F8: =IFERROR(D8-E8,0) | G8: =IF($A8="","",IFERROR(IF(ABS($F8)<=ydv_tolerans,"TUTARLI","KIRIK"),"KIRIK")) | H8: KVK md.5/1-a | J8: 0 | K8: 0
A9: V-004 | B9: TF eşik kontrolü | C9: esik=YDV-004; puan=vaka_tf_puan | D9: 70 | E9: =IFERROR(INDEX(tblKurallar[deger_2025],MATCH("YDV-004",tblKurallar[kural_id],0)),0) | F9: =IFERROR(D9-E9,0) | G9: =IF($A9="","",IFERROR(IF(ABS($F9)<=ydv_tolerans,"TUTARLI","KIRIK"),"KIRIK")) | H9: TF mevzuatı | J9: 70 | K9: 70
A11: Vaka özeti
A12: Durum | B12: =IFERROR(IF(COUNTIF(G6:G9,"KIRIK")>0,"KIRIK","TUTARLI"),"KIRIK")
A13: Toplam fark | B13: =IFERROR(SUM(F6:F9),0)

Sheet KANIT_RAPORU
A1: KANIT RAPORU — Yurt Dışı Yapılanma Vergi Simülatörü
A3: KANIT RAPORU — Yurt Dışı Yapılanma Vergi
A4: Rapor tarihi | B4: =raporTarihi
A5: Şirket | B5: =GIRDI!B6
A6: Dönem / yıl / ülke | B6: =CONCATENATE(GIRDI!B7," / ",hesapYili," / ",GIRDI!B9)
A8: Girdi özeti
A9: Yapılanma tipi | B9: =GIRDI!B10
A10: YD kâr (PB) | B10: =GIRDI!B11
A11: Yerel vergi oranı | B11: =GIRDI!B12
A12: Stopaj oranı | B12: =GIRDI!B13
A13: Döviz kuru | B13: =GIRDI!B14
A14: İştirak istisnası | B14: =GIRDI!B15
A15: TF risk puanı | B15: =GIRDI!B16
A17: Hesap zinciri
A18: YD kâr TL | B18: =ydv_karTl
A19: Efektif vergi | B19: =ydv_efektifVergi
A20: Çift vergi yükü | B20: =ydv_ciftVergi
A21: TR ek matrah riski | B21: =ydv_trEkMatrah
A22: KARAR | B22: =ydv_kararMetni
A23: Yapı önerisi | B23: =ydv_yapiOneri
A24: Gerekçe | B24: =ydv_kararGerekce
A26: Madde atıfları | B26: =ydv_maddeAtifMetni
A28: Kanıt gövdesi | B28: =ydv_kanitRaporu
A30: Parmak izi (SHA-256 kısaltma) | B30: =ydv_parmakIzi
A32: Hazırlayan (imza)
A33: Onaylayan (imza)
A35: Uyarı: Bu çıktı karar destektir; kesin vergi sonucu veya hukuki görüş değildir. Sürüm 1.0.0.

Sheet KONTROLLER
A1: KONTROLLER — Yurt Dışı Yapılanma Vergi Simülatörü
A3: Canlı kontrol paneli
A5: Giriş tablosu boş mu? | B5: =IF(COUNTA(tblGirdi[Alan Anahtarı])=0,"BOŞ","DOLU")
A6: Negatif YD kâr? | B6: =IF(GIRDI!B11<0,"NEGATİF","TEMİZ")
A7: Hesap yılı geçerli mi? | B7: =IFERROR(IF(AND(N(hesapYili)>N(ydv_yilTaban),N(hesapYili)<=N(ydv_yilTaban)+3),"TEMİZ","HATALI"),"HATALI")
A8: Kâr TL sıfır mı? | B8: =IF(IFERROR(MOTOR!G20,0)=0,"SIFIR","NORMAL")
A9: Vaka kırık mı? | B9: =IFERROR(IF(COUNTIF(tblVakalar[durum],"KIRIK")>0,"KIRIK","TUTARLI"),"KIRIK")
A10: Çift vergi eşiği aşıyor mu? | B10: =IF(IFERROR(MOTOR!G30,0)>ydv_kacirilanEsik+N(GIRDI!B11)*ydv_sifirCarpan,"AŞIYOR","NORMAL")
A11: Yorum A/B seçili mi? | B11: =IF(OR(GIRDI!B17="A",GIRDI!B17="B"),"TEMİZ","EKSİK")
A12: Kalite skoru (modül) | B12: =IFERROR(ROUND(IF(OR(B14=0,B14=""),0,B15/B14*100),0),0)
A14: Toplam giriş alanı | B14: =IFERROR(ydv_girisBeklenen+COUNTA(GIRDI!B6:B17)*0,0)
A15: Dolu giriş | B15: =COUNTA(GIRDI!B6:B17)
A17: Kâr TL kontrol | B17: =IFERROR(ydv_karTl,0)
A18: Efektif kontrol | B18: =IFERROR(ydv_efektifVergi,0)
A19: Karar kontrol | B19: =IFERROR(ydv_kararMetni,"-")

Sheet ORNEK_VERI
A1: ORNEK VERI — Yurt Dışı Yapılanma Vergi Simülatörü
A3: Örnek senaryo kütüphanesi
A4: Bu sayfa demo değerleri saklar; GIRDI'ye kopyalanabilir.
A5: Senaryo | B5: Ülke | C5: Yapı | D5: YDKâr | E5: YerelOran | F5: Stopaj | G5: Kur | H5: İstisna | I5: TF | J5: Yıl | K5: Yorum | L5: KârTL | N5: KarDemo
A6: Demo ana | B6: Almanya | C6: İŞTİRAK | D6: 500000 | E6: 0.3 | F6: 0.05 | G6: 36 | H6: Evet | I6: 40 | J6: 2026 | K6: A | L6: =IF($A6="","",IFERROR($D6*$G6,0)) | N6: 18000000
A7: Şube yüksek vergi | B7: Fransa | C7: ŞUBE | D7: 400000 | E7: 0.28 | F7: 0 | G7: 36 | H7: Hayır | I7: 55 | J7: 2026 | K7: A | L7: =IF($A7="","",IFERROR($D7*$G7,0)) | N7: 14400000
A8: Ofis düşük risk | B8: BAE | C8: OFİS | D8: 100000 | E8: 0.09 | F8: 0 | G8: 10 | H8: Hayır | I8: 20 | J8: 2026 | K8: A | L8: =IF($A8="","",IFERROR($D8*$G8,0)) | N8: 1000000
A9: TF riskli limited | B9: Hollanda | C9: LİMİTED | D9: 600000 | E9: 0.25 | F9: 0.05 | G9: 36 | H9: Evet | I9: 85 | J9: 2026 | K9: B | L9: =IF($A9="","",IFERROR($D9*$G9,0)) | N9: 21600000
A10: 2025 geçiş | B10: Almanya | C10: İŞTİRAK | D10: 500000 | E10: 0.3 | F10: 0.05 | G10: 34 | H10: Evet | I10: 40 | J10: 2025 | K10: A | L10: =IF($A10="","",IFERROR($D10*$G10,0)) | N10: 17000000
L11: =IF($A11="","",IFERROR($D11*$G11,0))
L12: =IF($A12="","",IFERROR($D12*$G12,0))
L13: =IF($A13="","",IFERROR($D13*$G13,0))
L14: =IF($A14="","",IFERROR($D14*$G14,0))
L15: =IF($A15="","",IFERROR($D15*$G15,0))
L16: =IF($A16="","",IFERROR($D16*$G16,0))
L17: =IF($A17="","",IFERROR($D17*$G17,0))
L18: =IF($A18="","",IFERROR($D18*$G18,0))
L19: =IF($A19="","",IFERROR($D19*$G19,0))
L20: =IF($A20="","",IFERROR($D20*$G20,0))
L21: =IF($A21="","",IFERROR($D21*$G21,0))
L22: =IF($A22="","",IFERROR($D22*$G22,0))
... L1004: =IF($A1004="","",IFERROR($D1004*$G1004,0))

Sheet LISTELER
A1: LISTELER — Yurt Dışı Yapılanma Vergi Simülatörü
A3: Doğrulama listeleri
A5: Yıllar | C5: Yorum A/B | E5: Evet/Hayır | G5: Yapılanma
A6: 2025 | C6: A | E6: Evet | G6: ŞUBE
A7: 2026 | C7: B | E7: Hayır | G7: İŞTİRAK
A8: 2027 | G8: LİMİTED
G9: OFİS

Sheet AYARLAR
A1: AYARLAR — Yurt Dışı Yapılanma Vergi Simülatörü
A3: Parametreler (tek kaynak)
A5: anahtar | B5: deger | C5: birim | D5: aciklama | E5: kaynak | F5: yururluk_tarihi | G5: dogrulama_tarihi | H5: kontrol
A6: hesapYili | B6: 2026 | C6: yıl | D6: Aktif hesap yılı | E6: Kullanıcı / GIRDI | F6: 01.01.2025 | G6: 11.08.2026 | H6: =IF(A6="","",IF(B6="","EKSİK","TAM"))
A7: raporTarihi | B7: 46245 | C7: tarih | D7: Rapor tarihi (sabit) | E7: Üretim | F7: 01.01.2025 | G7: 11.08.2026 | H7: =IF(A7="","",IF(B7="","EKSİK","TAM"))
A8: ydv_tolerans | B8: 0.01 | C8: TL | D8: Vaka tutarlılık toleransı | E8: Uygulama notu | F8: 01.01.2025 | G8: 11.08.2026 | H8: =IF(A8="","",IF(B8="","EKSİK","TAM"))
A9: ydv_kacirilanEsik | B9: 500000 | C9: TL | D9: Çift vergi uyarı eşiği | E9: İç politika | F9: 01.01.2025 | G9: 11.08.2026 | H9: =IF(A9="","",IF(B9="","EKSİK","TAM"))
A10: ydv_senaryoIyi | B10: 0.9 | C10: çarpan | D10: İyimser kâr çarpanı | E10: Model varsayımı | F10: 01.01.2025 | G10: 11.08.2026 | H10: =IF(A10="","",IF(B10="","EKSİK","TAM"))
A11: ydv_senaryoKotu | B11: 1.15 | C11: çarpan | D11: Kötümser kâr çarpanı | E11: Model varsayımı | F11: 01.01.2025 | G11: 11.08.2026 | H11: =IF(A11="","",IF(B11="","EKSİK","TAM"))
A12: ydv_oranArtisPuan | B12: 0.01 | C12: oran | D12: M-SEN sabit +1 puan | E12: Senaryo motoru | F12: 01.01.2025 | G12: 11.08.2026 | H12: =IF(A12="","",IF(B12="","EKSİK","TAM"))
A13: ydv_tahminAlt | B13: 0.85 | C13: çarpan | D13: Tahmin alt bant | E13: Model varsayımı | F13: 01.01.2025 | G13: 11.08.2026 | H13: =IF(A13="","",IF(B13="","EKSİK","TAM"))
A14: ydv_tahminUst | B14: 1.15 | C14: çarpan | D14: Tahmin üst bant | E14: Model varsayımı | F14: 01.01.2025 | G14: 11.08.2026 | H14: =IF(A14="","",IF(B14="","EKSİK","TAM"))
A15: ydv_tornadoKur | B15: 1.05 | C15: çarpan | D15: Tornado kur şoku | E15: Model varsayımı | F15: 01.01.2025 | G15: 11.08.2026 | H15: =IF(A15="","",IF(B15="","EKSİK","TAM"))
A16: ydv_tornadoTf | B16: 10 | C16: puan | D16: Tornado TF şoku | E16: Model varsayımı | F16: 01.01.2025 | G16: 11.08.2026 | H16: =IF(A16="","",IF(B16="","EKSİK","TAM"))
A17: ydv_peArtisOran | B17: 0.1 | C17: oran | D17: Yorum B PE +%10 | E17: PE atıf modeli | F17: 01.01.2025 | G17: 11.08.2026 | H17: =IF(A17="","",IF(B17="","EKSİK","TAM"))
A18: ydv_yuzdelikOran | B18: 0.9 | C18: oran | D18: Yüzdelik P90 | E18: İstatistik | F18: 01.01.2025 | G18: 11.08.2026 | H18: =IF(A18="","",IF(B18="","EKSİK","TAM"))
A19: ydv_parmakIzi | B19: 3df93af9ca63ea19 | C19: metin | D19: Dosya parmak izi etiketi | E19: Üretim | F19: 01.01.2025 | G19: 11.08.2026 | H19: =IF(A19="","",IF(B19="","EKSİK","TAM"))
A20: dosya_surumu | B20: 1.0.0 | C20: metin | D20: Ürün sürümü | E20: ExcelArşiv | F20: 01.01.2025 | G20: 11.08.2026 | H20: =IF(A20="","",IF(B20="","EKSİK","TAM"))
A21: ydv_girisBeklenen | B21: 12 | C21: adet | D21: Zorunlu giriş alanı sayısı | E21: Ürün mimarisi | F21: 01.01.2025 | G21: 11.08.2026 | H21: =IF(A21="","",IF(B21="","EKSİK","TAM"))
A22: ydv_riskDusuk | B22: 15 | C22: puan | D22: UYGUN risk skoru | E22: İç politika | F22: 01.01.2025 | G22: 11.08.2026 | H22: =IF(A22="","",IF(B22="","EKSİK","TAM"))
A23: ydv_riskOrta | B23: 55 | C23: puan | D23: DİKKAT risk skoru | E23: İç politika | F23: 01.01.2025 | G23: 11.08.2026 | H23: =IF(A23="","",IF(B23="","EKSİK","TAM"))
A24: ydv_riskYuksek | B24: 85 | C24: puan | D24: RİSKLİ risk skoru | E24: İç politika | F24: 01.01.2025 | G24: 11.08.2026 | H24: =IF(A24="","",IF(B24="","EKSİK","TAM"))
A25: ydv_yilTaban | B25: 2024 | C25: yıl | D25: CHOOSE yıl tabanı | E25: Ürün mimarisi | F25: 01.01.2025 | G25: 11.08.2026 | H25: =IF(A25="","",IF(B25="","EKSİK","TAM"))
A26: ydv_yuvarMax | B26: 10 | C26: adet | D26: ROUND basamak tavanı | E26: Ürün mimarisi | F26: 01.01.2025 | G26: 11.08.2026 | H26: =IF(A26="","",IF(B26="","EKSİK","TAM"))
A27: ydv_bazCarpan | B27: 1 | C27: çarpan | D27: Baz senaryo çarpanı | E27: Model varsayımı | F27: 01.01.2025 | G27: 11.08.2026 | H27: =IF(A27="","",IF(B27="","EKSİK","TAM"))
A28: ydv_sifirCarpan | B28: 0 | C28: çarpan | D28: Nötr çarpan (sıfır) | E28: Model varsayımı | F28: 01.01.2025 | G28: 11.08.2026 | H28: =IF(A28="","",IF(B28="","EKSİK","TAM"))
A29: ydv_siraBir | B29: 1 | C29: adet | D29: Tornado sıra 1 | E29: Ürün mimarisi | F29: 01.01.2025 | G29: 11.08.2026 | H29: =IF(A29="","",IF(B29="","EKSİK","TAM"))
A30: ydv_siraIki | B30: 2 | C30: adet | D30: Tornado sıra 2 | E30: Ürün mimarisi | F30: 01.01.2025 | G30: 11.08.2026 | H30: =IF(A30="","",IF(B30="","EKSİK","TAM"))
A31: ydv_siraUc | B31: 3 | C31: adet | D31: Tornado sıra 3 | E31: Ürün mimarisi | F31: 01.01.2025 | G31: 11.08.2026 | H31: =IF(A31="","",IF(B31="","EKSİK","TAM"))
A32: ydv_tahminX | B32: 5 | C32: adet | D32: FORECAST X noktası | E32: Model varsayımı | F32: 01.01.2025 | G32: 11.08.2026 | H32: =IF(A32="","",IF(B32="","EKSİK","TAM"))
... A43: vaka_tf_puan | B43: 70 | C43: puan | D43: Vaka4 TF eşik beklenen | E43: Tebliğ örneği | F43: 01.01.2025 | G43: 11.08.2026 | H43: =IF(A43="","",IF(B43="","EKSİK","TAM"))
B45: Parametre satırları yukarıda; ad tanımları B kolonuna bağlı.
B47: Sürüm 1.0.0 | Şifre koruması: 1234 (formül alanları)

Sheet KILAVUZ
A1: KILAVUZ — Yurt Dışı Yapılanma Vergi Simülatörü
A3: Karar kuralları
A5: • VERİ YOK — giriş tablosu boşsa hesap yapılmaz.
A6: • UYGUN — TF ve çift vergi yükü düşük; mevcut yapı sürdürülebilir.
A7: • DİKKAT — orta risk; mahsup, stopaj ve PE atıfını doğrulayın.
A8: • RİSKLİ — TF eşiği aşıldı veya çift vergi yüksek; yapıyı yeniden değerlendirin.
A9: • Yapı önerisi — İŞTİRAK / ŞUBE / OFİS / VERİ YOK (risk + efektif vergiye göre).
A11: Belirsizlik beyanları (M05)
A12: Bu nokta mevzuatta tartışmalıdır; dosya yorum A ve yorum B sonucunu yan yana gösterir: pe_atif_yorumu
A14: Yorum A | B14: PE atıfı ve ofis matrah payı girdideki oranlarla aynen uygulanır. İştirak istisnası işaretliyse TR matrahı dağıtım payına iner.
A15: Yorum B | B15: Yorum B, PE / ofis atıfını +%10 sıkılaştırır (daha yüksek TR matrah ve ek risk). Dosya her iki yorumun etkisini MOTOR'da üretir.
A17: Kullanım sırası
A18: GIRDI → KURALLAR (gerekirse) → MOTOR → SENARYO → VAKALAR → PANO → KANIT_RAPORU → AYARLAR.
A20: Sürüm 1.0.0 | Lisans: Tek kullanıcı | ExcelArşiv
