Workbook
Name hesapYili: GIRDI!$B$8
Name raporTarihi: AYARLAR!$B$7
Name sgk_mevcutTesvik: GIRDI!$B$15
Name sgk_potansiyelTasarruf: MOTOR!$G$28
Name sgk_kacirilan: MOTOR!$G$30
Name sgk_kararMetni: MOTOR!$G$34
Name sgk_kararGerekce: MOTOR!$G$35
Name sgk_maddeAtifMetni: MOTOR!$G$52
Name sgk_kanitRaporu: MOTOR!$G$53
Name sgk_kuralYilMatris: KURALLAR!$B$17
Name sgk_parmakIzi: AYARLAR!$B$19
Name sgk_senaryoKarsilastirma: SENARYO!$B$11
Name sgk_yorumSenaryo: SENARYO!$B$12
Name sgk_duyarlilikSira: SENARYO!$B$19
Name sgk_yorumDuyarlilik: SENARYO!$B$20
Name sgk_kuralDegisimSenaryo: SENARYO!$B$22
Name sgk_yorumKuralDegisim: SENARYO!$B$23
Name sgk_tahminAralik: SENARYO!$B$32
Name sgk_yorumTahmin: SENARYO!$B$33
Name sgk_vakaDurum: VAKALAR!$B$12
Name sgk_vakaFark: VAKALAR!$B$13
Name sgk_tolerans: AYARLAR!$B$8
Name sgk_kacirilanEsik: AYARLAR!$B$9
Name sgk_senaryoIyi: AYARLAR!$B$10
Name sgk_senaryoKotu: AYARLAR!$B$11
Name sgk_oranArtisPuan: AYARLAR!$B$12
Name sgk_tahminAlt: AYARLAR!$B$13
Name sgk_tahminUst: AYARLAR!$B$14
Name sgk_tornadoMatrah: AYARLAR!$B$15
Name sgk_tornadoMevcut: AYARLAR!$B$16
Name sgk_isverenOran: AYARLAR!$B$17
Name sgk_yuzdelikOran: AYARLAR!$B$18
Name sgk_girisBeklenen: AYARLAR!$B$21
Name sgk_riskDusuk: AYARLAR!$B$22
Name sgk_riskOrta: AYARLAR!$B$23
Name sgk_riskYuksek: AYARLAR!$B$24
Name sgk_riskEsikOran: AYARLAR!$B$25
Name sgk_yilTaban: AYARLAR!$B$26
Name sgk_yuvarMax: AYARLAR!$B$27
Name vaka_matrah_1: AYARLAR!$B$28
Name vaka_matrah_2: AYARLAR!$B$29
Name vaka_tavan: AYARLAR!$B$30
Name sgk_modulT1: PANO!$C$11
Name sgk_modulT1Yorum: PANO!$D$11
Name sgk_modulT2: PANO!$C$12
Name sgk_modulT2Yorum: PANO!$D$12
Name sgk_modulO1: PANO!$C$13
Name sgk_modulO1Yorum: PANO!$D$13
Name sgk_modulO6: PANO!$C$16
Name sgk_modulO6Yorum: PANO!$D$16
Name sgk_modulO8: PANO!$C$17
Name sgk_modulO8Yorum: PANO!$D$17
Name sgk_modulI2: PANO!$C$20
Name sgk_modulI2Yorum: PANO!$D$20
Name ListeYillar: LISTELER!$A$6:$A$8
Name ListeYorumAB: LISTELER!$C$6:$C$7
Name ListeEvetHayir: LISTELER!$E$6:$E$7

Sheet 00_BASLANGIC
A1: EXCELARŞİV KARAR SİSTEMİ v15.1 — ÜRETİM REFERANSI
A3: Konu | B3: Bağlayıcı Standart
A4: Amaç | B4: Kanıta dayalı, hatada kapalı çalışan Excel üretim ve denetim sistemi
A5: Öncelik | B5: Kullanıcının açık iş talebi ve gerçek kullanım senaryosu
A6: Ana akış | B6: Uygunluk → Yönetişim → Sözleşmeler → Üretim → Test → Kanıt → Kullanıcı Kabulü → Yayın
A7: Yayın ilkesi | B7: Üst aşamada hata varsa alt aşama GEÇTİ üretilemez
A8: Kullanıcı kabulü | B8: Excel masaüstü görünümü test edilmediyse DIŞ_KABUL_GEREKLİ
A9: Nihai yayın | B9: Yalnız uygulanabilir modüller GEÇTİ veya gerekçeli UYGULANMAZ
A10: Ticari ayrım | B10: Ekonomik olarak savunulabilir fiyat, gerçek pazar kabulü ile aynı değildir
A11: Karmaşıklık | B11: Karar değeri, eklenen karmaşıklığın maliyetinden büyük olmalıdır
A12: Excel sınırı | B12: Veritabanı, kurumsal yetkilendirme, değiştirilemez kayıt sistemi veya gerçek zamanlı olay platformu değildir
A13: Dil standardı | B13: Kullanıcıya görünen tüm sayfa, tablo, başlık, açıklama, uyarı ve karar metinleri saf Türkçe olmalıdır
A14: Muhasebe standardı | B14: Finansal ürünlerde Türkiye Tekdüzen Hesap Planı ve Türk muhasebe kullanım alışkanlıkları esas alınır
... A33: Muhasebe | B33: Türkiye Tekdüzen Hesap Planı ve Türk muhasebe/işletme düşünce yapısı esas alınır.

Sheet PANO
A1: ☰ PANO
B2: SGK PRIM TEŞVIKLERI OPTIMIZASYON MOTORU | L2: Dönem: 2026 / Tam ▼ | M2: ★ DOĞRULANMIŞ
B3: Hedef Kullanıcı: İK, SMMM, bordro · 2026 Q3 Denetim Standardı
B5: KAPSAM / MATRAH | D5: KONSOLİDE | E5: MEVCUT / POTANSIYEL | G5: KONTROL | H5: NET OPERASYONEL MARJ | J5: GÜVENLİ | K5: SİSTEM GÜVEN SKORU | M5: DENETLENDİ
B7: =GİRDİLER!E17 | E7: =B7*0.22 | H7: =B7-E7 | K7: =EĞER(E7>0; YUVARLA(B7/E7; 2); 0)
B9: ↑ %14.2 konsolide canlı veri bağlantısı | E9: ● 8 Kalem nakit karşılığı: bloke | H9: ██████████░░░░░ %78.0 NET MARJ | K9: ✓ İDEAL karşılama rasyosu
B11: SGK PRIM TEŞVIKLERI OPTIMIZASYON MOTORU — DÖNEMSEL İCRA VE PROJEKSİYON | F11: +%32 Verim | H11: KONSOLİDE OPERASYON VE KARAR MATRİSİ
B12: Kümülatif Hacim vs. Operasyonel Maliyet ve Net Kâr Eğilimi | H12: Anlık Hesaplama Sonuçları, Dinamik Formül Çıktıları ve Durum Puanlaması
B14: Dönem | C14: Aktif Hacim | D14: Maliyet/Yük | E14: Hedef | H14: PARAMETRE / KALEM | I14: ANA TUTAR | J14: FARK / MARJ | K14: VADE | L14: KONTROL DURUMU
B15: D1 | C15: 65 | D15: 45 | E15: 60 | H15: Dönemlik Kümülatif Bakiye | I15: =B7*0.45 | J15: =B7*0.05 | K15: 12 Ay | L15: ✓ DÜZENLİ
B16: D2 | C16: 78 | D16: 48 | E16: 70 | H16: Kritik Eşik Güvenlik Tamponu | I16: =B7*0.30 | J16: =B7*0.03 | K16: 24 Ay | L16: ★ AVANTAJ
B17: D3 | C17: 85 | D17: 55 | E17: 80 | H17: Operasyonel Net Fark | I17: =B7*0.15 | J17: =B7*0.02 | K17: 8 Ay | L17: ● YAKLAŞAN
B18: D4 | C18: 75 | D18: 42 | E18: 75 | H18: Rezerv ve Likit Dağılım | I18: =B7*0.10 | J18: =B7*0.01 | K18: 16 Ay | L18: ✓ TAM UYUM
B19: D5 | C19: 90 | D19: 40 | E19: 85 | H19: KONSOLİDE SİSTEM TOPLAMI | I19: =TOPLA(I15:I18) | J19: =TOPLA(J15:J18) | L19: TAM DOĞRULANDI (0 HATA)
B20: D6 | C20: 96 | D20: 32 | E20: 92
B22: KONSOLİDE PAY VE AĞIRLIK | F22: LİKİDİTE RİSKİ & ERKEN UYARI SİNYALLERİ | K22: KARAR MOTORU
B23: ■ Ana Segment (%42) | F23: Nakit Açığı Riski (30 Gün) | I23: 0.00 TL (Sıfır Risk) | K23: STRATEJİK VERİMLİLİK FIRSATI
B24: ■ İkincil Grup (%30) | F24: Tahsilat Gecikme Toleransı | I24: 48 Gün Güvenli Eşik | K24: Operasyonel süreç optimizasyonu ile kârlılık artış potansiyeli tespit edildi.
B25: ■ Destek Birimi (%15) | F25: ██████████████████████████████████████ Güvenli Bölge (%100)
B26: ■ Rezervler (%13) | F26: ✓ 90 GÜNLÜK PROJEKSİYONDA NAKİT SIKIŞIKLIĞI TESPİT EDİLMEDİ | K26: STRATEJİ REÇETESİNİ İNCELE >

Sheet GİRDİLER
A1: ☰ PANO
B3: 🔍 SGK PRIM TEŞVIKLERI OPTIMIZASYON MOTORU — Kayıt veya hesap ara... | G3: TOPLAM: 1.450 KAYIT | I3: HATALI HÜCRE: 0 ADET
B5: TARİH | C5: REFERANS NO | D5: İŞLEM AÇIKLAMASI VE DETAY | E5: BRÜT TUTAR (₺) | F5: KDV ORANI | G5: NET TUTAR (₺) | H5: HESAP / CARİ | I5: DURUM
B6: 12.10.2026 | C6: TR-0428-A | D6: Operasyonel ana kalem tahmini | E6: 845200 | F6: 0.2 | G6: =E6/(1+F6) | H6: Vadesiz Ticari | I6: ONAYLANDI
B7: 14.10.2026 | C7: TR-0429-B | D7: Operasyonel çıkış/maliyet tahmini | E7: 1240000 | F7: 0.2 | G7: =E7/(1+F7) | H7: Tedarikçi Havuzu | I7: BEKLEMEDE
B8: 18.10.2026 | C8: TR-0430-C | D8: Ödeme takvimi tahakkuku | E8: 620500 | F8: 0.1 | G8: =E8/(1+F8) | H8: Kısa Vade Tahakkuk | I8: ONAYLANDI
B9: 21.10.2026 | C9: TR-0431-D | D9: Müşteri işlem tahmini | E9: 415000 | F9: 0.2 | G9: =E9/(1+F9) | H9: Müşteri Alacağı | I9: ONAYLANDI
B10: 25.10.2026 | C10: TR-0432-E | D10: Ana operasyon tahmini | E10: 980400 | F10: 0.2 | G10: =E10/(1+F10) | H10: Vadesiz Ticari | I10: ONAYLANDI
B11: 28.10.2026 | C11: TR-0433-F | D11: Kredi/taksit karşılığı | E11: 1850000 | F11: 0.2 | G11: =E11/(1+F11) | H11: Finansman Havuzu | I11: BLOKE
B12: 02.11.2026 | C12: TR-0434-G | D12: Sabit gider ve yönetim notları | E12: 740000 | F12: 0.2 | G12: =E12/(1+F12) | H12: Genel Yönetim | I12: ONAYLANDI
B13: 05.11.2026 | C13: TR-0435-H | D13: Operasyonel ana kalem tahmini | E13: 520800 | F13: 0.2 | G13: =E13/(1+F13) | H13: Vadesiz Ticari | I13: ONAYLANDI
B14: 09.11.2026 | C14: TR-0436-I | D14: Müşteri işlem tahmini | E14: 1120000 | F14: 0.2 | G14: =E14/(1+F14) | H14: Müşteri Alacağı | I14: ONAYLANDI
B15: 12.11.2026 | C15: TR-0437-J | D15: Operasyonel çıkış tahmini | E15: 890000 | F15: 0.2 | G15: =E15/(1+F15) | H15: Tedarikçi Havuzu | I15: ONAYLANDI
B17: SAYFA TOPLAMI (10 / 1.450 KAYIT) | E17: =TOPLA(E6:E15)

Sheet YÖNETİM_RAPORU
A1: ☰ PANO
B2: SGK PRIM TEŞVIKLERI OPTIMIZASYON MOTORU — NİHAİ KARAR VE DEĞERLEME
B3: Yönetim Kurulu ve İcra Komitesi için Otomatik Finansal Stres Testi Raporu · İK, SMMM, bordro
B4: DÖNEM: 2026 Q3 · DENETİM PROTOKOLÜ: ISO/VUK/IFRS UYUMLU · DURUM: ONAYLANDI
B6: SENARYO A: KÖTÜMSER (STRES TESTİ -%20) | H6: SENARYO B: BAZ MODEL (HEDEFLENEN)
B8: Ciro / Hacim Düşüşü: | E8: -%20.0 (Kriz Eşiği) | H8: Ciro / Hacim Gerçekleşmesi: | K8: %100.0 (Tam Bütçe)
B9: Beklenen Net Kâr / Getiri: | E9: =PANO!B7*0.8*0.22 | H9: Beklenen Net Kâr / Getiri: | K9: =PANO!H7
B10: Minimum Nakit Tamponu: | E10: =PANO!E7*0.75 | H10: Serbest Nakit Akımı: | K10: =PANO!H7*0.75
B11: Likidite Karşılama Oranı: | E11: =YUVARLA(PANO!B7*0.8/PANO!E7; 2) | H11: Yatırım Geri Dönüşü (ROI): | K11: %38.4 Yıllık
B14: STRES SENARYOSUNDA DAHİ İFLAS RİSKİ YOK | H14: OPTİMUM İCRA VE PLANLAMA REÇETESİ
B17: YÖNETİM KARAR MATRİSİ VE UYGULAMA REÇETESİ
B19: ● Öncelik 1: Acil Likidite ve Borç Servis Planlaması
B20: Sistemde hesaplanan vade günlerine sadık kalınarak nakit blokajı 3 gün önceden hazır edilmelidir.
B21: ● Öncelik 2: Formül Doğrulama ve Çapraz Sağlama
B22: Tüm hücreler kilitli formül korumasında olup girdi sayfalarında sıfır döngüsel başvuru (circular ref) garantilidir.
B23: ● Öncelik 3: Resmi Mevzuat ve Vergi Kalkanı Entegrasyonu
B24: 2026 güncel vergi dilimleri, amortisman ve SGK teşvik parametreleri tam otomatik yansıtılmaktadır.
B25: ● Öncelik 4: Yönetici İmzası ve Rapor Paylaşımı
B26: Tek tuşla PDF ve A4 çıktı formatına tam uyumlu sayfa yapısı kurgulanmıştır.

Sheet 01_YURUTME_CEKIRDEGI
A1: YÜRÜTME ÇEKİRDEĞİ — ZORUNLU ÜRETİM SIRASI
A3: Adım | B3: Modül | C3: Tetikleyici | D3: Zorunlu Kanıt | E3: GEÇTİ Kuralı | F3: Hata Durumu | G3: Sonraki Aşama
A4: 1 | B4: Excel Uygunluğu | C4: Her yeni model | D4: UYGUNLUK_KARARI | E4: Excel'in rolü açık | F4: HATA / BLOKE | G4: Yönetişim
A5: 2 | B5: Yönetişim | C5: Her model | D5: Risk seviyesi + etki girdileri | E5: Seviye hesaplandı | F5: BLOKE | G5: Sözleşmeler
A6: 3 | B6: Türk Muhasebe Eşlemesi | C6: Finansal model | D6: THP hesap eşleme tablosu | E6: Kritik satırlar THP ile uyumlu | F6: HATA | G6: Sözleşmeler
A7: 4 | B7: Veri ve Anlam Sözleşmeleri | C7: Girdi/KPI varsa | D7: Veri + KPI sözleşmeleri | E7: Kapsam %100 | F7: HATA | G7: Üretim
A8: 5 | B8: Üretim | C8: Sözleşmeler GEÇTİ | D8: Çalışan Excel | E8: Tek gerçek kaynak korunmuş | F8: HATA | G8: Testler
A9: 6 | B9: Görsel/Kullanım Katmanı | C9: Motor hazır | D9: Başlıklar + renk + grafik + yönlendirme | E9: Tüm kullanıcı sayfaları standarda uygun | F9: HATA | G9: Testler
A10: 7 | B10: Testler | C10: Üretim tamam | D10: Formül/OOXML/kimlik/oracle/golden/metamorfik | E10: Uygulanabilir hard gate'ler GEÇTİ | F10: HATA | G10: Kanıt
A11: 8 | B11: Hata-Kontrol Tutarlılığı | C11: Test sonucu var | D11: Hata taraması + kontrol sonuçları | E11: Formül hatası varken GEÇTİ yok | F11: HATA | G11: Kanıt
A12: 9 | B12: Kanıt | C12: Test sonucu var | D12: Makine okunur artefakt + özet | E12: Kanıt fiziksel ve tutarlı | F12: HATA | G12: Kullanıcı Kabulü
A13: 10 | B13: Kullanıcı Kabulü | C13: Kritik görevler | D13: Gerçek ekran davranışı | E13: Kritik görevler %100 | F13: DIŞ_KABUL_GEREKLİ | G13: Ticari
A14: 11 | B14: Ticari Değer | C14: Ürün satılacaksa | D14: ROI + demo + kanıt paketi | E14: Ekonomik değer kanıtlı | F14: UYARI / HATA | G14: Pazar Doğrulama
A15: 12 | B15: Pazar Doğrulama | C15: Pazar iddiası varsa | D15: Ücretli satış/pilot/fiyat kabul kanıtı | E15: Gerçek fiyat kabul kanıtı | F15: UYGULANMAZ / HATA | G15: Yayın

Sheet 02_KONTROL_LISTESI
A1: NİHAİ KONTROL LİSTESİ — KANITSIZ GEÇİŞ YOK
A3: Kontrol No | B3: Kontrol | C3: Beklenen | D3: Zorunlu Kapı? | E3: Sonuç
A4: K01 | B4: Kullanıcının açık talebi öncelikli mi? | C4: Evet | D4: EVET
A5: K02 | B5: Mevcut yapı, formüller ve tek gerçek kaynak korunuyor mu? | C5: Evet, değişiklik gerekçeli | D5: EVET
A6: K03 | B6: Üst aşama HATA ise alt aşama GEÇTİ engelleniyor mu? | C6: Evet | D6: EVET
A7: K04 | B7: Kanıt fiziksel çıktı ve içerik doğrulaması içeriyor mu? | C7: Evet | D7: EVET
A8: K05 | B8: Excel GUI erişimi olmadan kullanıcı görünümü GEÇTİ yazılıyor mu? | C8: Hayır | D8: EVET
A9: K06 | B9: NİHAİ yalnız GEÇTİ / gerekçeli UYGULANMAZ ile mi? | C9: Evet | D9: EVET
A10: K07 | B10: Ekonomik fiyat savunusu pazar doğrulamasından ayrılmış mı? | C10: Evet | D10: EVET
A11: K08 | B11: Prestij için gereksiz modül var mı? | C11: Hayır | D11: HAYIR
A12: K09 | B12: Excel sınırları açık mı? | C12: Evet | D12: EVET
A13: K10 | B13: Teknik kaynak korunuyor mu? | C13: Evet | D13: EVET
A14: K11 | B14: Kullanıcıya görünen tüm metinler Türkçe mi? | C14: Evet | D14: EVET
A15: K12 | B15: Her kullanıcı sayfasında üst başlık var mı? | C15: Evet | D15: EVET
... A34: K31 | B34: Premium vitrin, altyapı kadar güçlü ve satış fiyatını destekleyecek seviyede mi? | C34: Evet | D34: EVET

Sheet 03_GORSEL_TASARIM
A1: GÖRSEL TASARIM VE PREMIUM EXCEL STANDARDI
A3: Alan | B3: Zorunlu Kural | C3: Uygulama | D3: Yasak | E3: Kontrol | F3: Durum
A4: Sayfa başlığı | B4: Her kullanıcı sayfasının en üstünde tek ve açık sayfa başlığı | C4: A1'den başlayan koyu lacivert başlık bandı | D4: Başlıksız sayfa | E4: Başlık kapsama = %100 | F4: ZORUNLU
A5: Sekme renkleri | B5: Sayfalar işlevine göre renk kodlanır | C5: Girdi=mavi, hesap=gri, rapor=lacivert, kontrol=kırmızı, kılavuz=altın | D5: Rastgele renk | E5: Renk semantiği tutarlı | F5: ZORUNLU
A6: Kolon düzeni | B6: Veri blokları bitişik kolonlarda ilerler | C6: Gereksiz boş kolon bırakma; yalnız gerçek bölüm ayrımı varsa kontrollü boşluk | D6: A:C veri, D boş, E:F veri gibi parçalı yapı | E6: Boş kolon taraması | F6: ZORUNLU
A7: Girdi hücreleri | B7: Kullanıcının değiştireceği alan açıkça görünür | C7: Açık sarı dolgu + mavi yazı | D7: Formülle aynı görünüm | E7: Girdi/formül ayrımı | F7: ZORUNLU
A8: Formüller | B8: Hesap hücreleri kullanıcı girdisinden ayrılır | C8: Siyah yazı; sayfalar arası bağlantı yeşil yazı | D8: Hard-code gizleme | E8: Formül sınıfı kontrolü | F8: ZORUNLU
A9: Grafik sayısı | B9: Yönetici ekranında en fazla 3 ana karar grafiği | C9: Trend, karşılaştırma, köprü/dağılım; iş kararına bağlı | D9: Grafik kalabalığı | E9: Grafik başına karar sorusu | F9: ZORUNLU
A10: Grafik stili | B10: Kurumsal ve yüksek okunabilirlik | C10: Beyaz zemin, ince gridline, tek vurgu rengi, açık birim/başlık | D10: 3B, gölge, neon, gökkuşağı renkleri | E10: Görsel inceleme | F10: ZORUNLU
A11: Grafik başlığı | B11: Grafik 'neyi' değil 'ne anlama geldiğini' söyler | C11: Örn: 'Nakit 2028'de kritik eşiğin altına iniyor' | D11: 'Nakit Grafiği' gibi anlamsız başlık | E11: Başlık karar testi | F11: ZORUNLU
A12: Birimler | B12: Tüm finansal görsellerde birim açık | C12: TL, bin TL, milyon TL, %, gün, x | D12: Birim belirsizliği | E12: Birim kapsama %100 | F12: ZORUNLU
A13: Sıfır/negatif | B13: Finansal format standardı | C13: Sıfır='-', negatif kırmızı parantez | D13: -500 veya 0,00 kalabalığı | E13: Format kontrolü | F13: ZORUNLU
A14: Yazı tipi | B14: Tek aile | C14: Aptos veya Segoe UI | D14: Karışık font | E14: Tek font kontrolü | F14: ZORUNLU
... A22: Premium vitrin | B22: Görsel kalite ürün değerinin zorunlu parçasıdır | C22: Kaliteli grafik, gerçek KPI kartı, finansal hiyerarşi, tab rengi, fonksiyonel navigasyon | D22: Sadece doğru hesap yapıp çıplak/varsayılan Excel görünümü bırakmak | E22: Görsel release incelemesi | F22: ZORUNLU

Sheet 04_MUHASEBE_THP
A1: TÜRKİYE MUHASEBE VE TEKDÜZEN HESAP PLANI STANDARDI
A3: Konu | B3: Zorunlu Standart | C3: Örnek Türkçe Ad | D3: THP / Mantık | E3: Hata Riski | F3: Kontrol
A4: Dil | B4: Kullanıcıya görünen finansal terimler Türkçe | C4: Hasılat, Satışların Maliyeti, Brüt Kâr, Faaliyet Giderleri | D4: Türk işletme kullanımına uygun | E4: İngilizce jargon | F4: Terminoloji taraması
A5: Gelir Tablosu | B5: Türk sunum sırası kullanılır | C5: Net Satışlar → Satışların Maliyeti → Brüt Kâr → Faaliyet Giderleri → Faaliyet Kârı | D5: 600/610/611; 620-623; 63x | E5: Yanlış sınıflama | F5: Hesap eşleme
A6: Bilanço | B6: Dönen/Duran Varlık ve Kısa/Uzun Vadeli Yükümlülük ayrımı | C6: Hazır Değerler, Ticari Alacaklar, Stoklar, Mali Borçlar | D6: 1xx / 2xx / 3xx / 4xx / 5xx | E6: Vade sınıfı hatası | F6: Bilanço eşitliği
A7: Nakit Akışı | B7: İşletme/Yatırım/Finansman nakit akışları ayrılır | C7: Faaliyetlerden Nakit, Yatırım Harcamaları, Finansman Nakit Akışı | D7: Dolaylı/doğrudan yöntem açık seçilir | E7: Kâr = nakit sanılması | F7: Nakit devri
A8: Ticari Alacaklar | B8: Cari ve vade mantığı korunur | C8: 120 Alıcılar | D8: 120 | E8: Tahakkuk/nakit karışması | F8: Alacak devir kontrolü
A9: Ticari Borçlar | B9: Tedarikçi borcu ayrı izlenir | C9: 320 Satıcılar | D9: 320 | E9: Gider/ödeme karışması | F9: Borç devir kontrolü
A10: Kasa/Banka | B10: Hazır değerler ayrı izlenir | C10: 100 Kasa, 102 Bankalar | D10: 100 / 102 | E10: Virmanla toplam nakdin değişmesi | F10: Virman değişmezi
A11: Stok | B11: Dikeye uygun stok türü | C11: 150 İlk Madde ve Malzeme, 153 Ticari Mallar | D11: 15x | E11: Maliyet ve stok hareketinin kopması | F11: Stok devri
A12: Maddi Duran Varlık | B12: Yatırım harcaması ve amortisman bağlantılı | C12: 253 Tesis Makine Cihazlar, 255 Demirbaşlar, 257 Birikmiş Amortismanlar | D12: 25x | E12: Yatırım/gider karışması | F12: Net defter değeri devri
A13: Mali Borçlar | B13: Kısa/uzun vadeli borç ayrımı | C13: 300 Banka Kredileri / 400 Banka Kredileri | D13: 300 / 400 | E13: Vade sınıfı yanlış | F13: Borç devri
A14: Özkaynak | B14: Sermaye ve geçmiş yıl kârları ayrı | C14: 500 Sermaye, 570 Geçmiş Yıllar Kârları, 590 Dönem Net Kârı | D14: 5xx | E14: Net kâr bağının kopması | F14: Özkaynak devri
... A18: İstisna | B18: TFRS özel ürün varsa fark açık yazılır | C18: Tekdüzen raporlama ≠ TFRS finansal tablo sunumu | D18: Amaç belirtilir | E18: Standartları karıştırma | F18: Model amacı kontrolü

Sheet 05_KARAR_SATIS
A1: KARAR, GÜVEN VE SATIŞA HAZIRLIK STANDARDI
A3: Alan | B3: Müşteri Sorusu | C3: Zorunlu Ürün Davranışı | D3: Kanıt | E3: Başarısızlık Durumu | F3: Kapı
A4: 5 saniye | B4: Bu ürün neyi çözüyor? | C4: İlk ekranda hedef kullanıcı + pahalı problem + sonuç görünür | D4: Başlık + alt mesaj + gerçek ekran | E4: Ürün yalnız teknik isim | F4: HATA
A5: Acı | B5: Sorun bana neye mal oluyor? | C5: Mümkünse müşterinin kendi verisiyle parasal/zaman etkisi hesaplanır | D5: ROI/acı hesaplama yöntemi | E5: Uydurma tasarruf | F5: HATA
A6: Karar | B6: Bu bilgiyle ne yapacağım? | C6: Her kritik KPI aksiyona bağlanır | D6: KARAR_KUYRUGU | E6: Sadece rapor | F6: HATA
A7: Güven | B7: Bu sayıya neden inanayım? | C7: Kaynak, formül mantığı, kontrol ve son doğrulama görünür | D7: Kontroller + kaynak izi + sürüm | E7: Prestij kelimesi | F7: HATA
A8: Referans | B8: Müşteri yorumu yoksa ne göstereceğim? | C8: Önce/Sonra + Karar Vakası + Hata Önleme Vakası üretilir | D8: Demo/örnek çıktı | E8: Kanıtsız iddia | F8: HATA
A9: Senaryo | B9: Ne olursa işler bozulur? | C9: Baz/Aşağı/Yukarı veya uygun stres senaryosu | D9: Senaryo karşılaştırma | E9: Dekoratif senaryo | F9: HATA
A10: Ters stres | B10: Hangi eşikte karar kırılır? | C10: En az bir kritik sürücü için kırılma eşiği | D10: Kırılma eşiği tablosu | E10: Sadece +/- %10 | F10: UYARI/HATA
A11: Hata tutarlılığı | B11: Formül hata verirse ne olur? | C11: Kontrol GEÇTİ veremez; BLOKE/HATA üretir | D11: Hata taraması | E11: Hata + GEÇTİ birlikte | F11: HATA
A12: Karar motoru | B12: Ne oldu, neden oldu? | C12: Sorun + neden + parasal etki + aksiyon + son tarih | D12: Karar tablosu | E12: Boş sayfa / isim düzeyi modül | F12: HATA
A13: Yönetici özeti | B13: 5 saniyede ne görmeliyim? | C13: Bugün / ne değişti / ne bozulacak / neden / ne yapmalıyım / güven | D13: Yönetici özeti ekranı | E13: KPI kutusu yığını | F13: HATA
A14: Teklif | B14: Neden satın almalıyım? | C14: Dosya özellikleri yerine sonuç ve kaçınılan maliyet sunulur | D14: Ürün sayfası kanıt eşlemesi | E14: Özellik listesiyle satış | F14: HATA
... A19: Pazar kanıtı | B19: Piyasa gerçekten ödüyor mu? | C19: Satış/pilot/LOI/fiyat kabulü olmadan pazar doğrulandı yazılmaz | D19: Gerçek işlem kanıtı | E19: Tahmini talep = satış kabulü | F19: HATA

Sheet KAPAK
A1: KAPAK — SGK Prim Teşvikleri Optimizasyon Motoru
A3: SGK Prim Teşvikleri Optimizasyon Motoru
A4: Bordro matrahınızı girin; SGK prim teşvik uygunluğunu, birikimli tasarrufu ve kaçırılan fırsatı senaryolu olarak üretin.
A6: Bu ürün ne sağlar?
A7: • Çok yıllı kural tablosu (2025/2026/2027) ile oran ve tavan güncellemesine hazır motor
A8: • 5 puan, ilave istihdam, kadın/genç ve engelli teşvik kalemlerinin yan yana hesabı
A9: • Baz / iyimser / kötümser + kural değişimi (oran +1 puan) senaryoları
A10: • Tebliğ tarzı altın vakalar ve KANIT_RAPORU (A4 imza)
A11: • Belirsizlik beyanı: teşvik birikim sırası (yorum A / B)
A13: Kimler için?
A14: • İK / bordro — uygun teşvik kodlarını seçmek
A15: • SMMM — imzalı kanıt raporu dosyalamak
... A21: Sürüm 1.0.0 | 2026 | ExcelArşiv | Lisans: Tek kullanıcı

Sheet HIZLI_BASLANGIC
A1: HIZLI BASLANGIC — SGK Prim Teşvikleri Optimizasyon Motoru
A3: Üç adımda sonuç
A5: Adım 1 — Girdiler | B5: GIRDI sayfasında yıl, matrah, kapsam kalemleri ve mevcut teşviki sarı hücrelere girin.
A6: Adım 2 — Karar | B6: PANO'da potansiyel tasarruf, kaçırılan tutar ve karar rozetini izleyin.
A7: Adım 3 — Kanıt | B7: KANIT_RAPORU'nu yazdırıp imzalayın; VAKALAR tutarlılığını kontrol edin.
A9: Sık yapılan hatalar
A10: • Net ücret girmek — prim matrahı brüt olmalıdır
A11: • Kapsam matrahını toplam matrahtan büyük yazmak
A12: • Hesap yılını kural tablosuyla uyumsuz seçmek
A14: Bu dosya karar destek aracıdır; SGK başvurusu veya mali müşavir görüşü yerine geçmez.

Sheet GIRDI
A1: GIRDI — SGK Prim Teşvikleri Optimizasyon Motoru
A3: Dönem ve işveren
A4: Sarı hücreler manuel giriştir. Potansiyel tasarruf formülle üretilir.
A5: Alan | B5: Değer | C5: Birim
A6: İşveren Adı | B6: Örnek Üretim A.Ş. | C6: metin
A7: Dönem | B7: 2025-01 | C7: metin
A8: Hesap Yılı | B8: 2025 | C8: yıl
A9: Aylık Brüt Prim Matrahı [₺] | B9: 500000 | C9: ₺
A10: Çalışan Sayısı | B10: 20 | C10: adet
A11: 5 Puan Kapsam Matrahı [₺] | B11: 300000 | C11: ₺
A12: İlave İstihdam Matrahı [₺] | B12: 100000 | C12: ₺
A13: Kadın/Genç Matrahı [₺] | B13: 50000 | C13: ₺
A14: Engelli Matrahı [₺] | B14: 30000 | C14: ₺
A15: Mevcut Teşvik Tutarı [₺] | B15: 10000 | C15: ₺
A16: Birikim Yorumu (A/B) | B16: A | C16: metin
A18: Potansiyel Tasarruf (ayna) [₺] | B18: =IFERROR(sgk_potansiyelTasarruf,0)
A19: Giriş doluluk (kalite) | B19: =IFERROR(IF(OR(COUNTA(B6:B16)=0,sgk_girisBeklenen=0),0,ROUND(COUNTA(B6:B16)/sgk_girisBeklenen*100,0)),0)
A22: Giriş tablosu (otomasyon / boş-mod)
A23: Alan Anahtarı | B23: Değer | C23: Birim | D23: Zorunlu | E23: Kaynak | F23: Kontrol
A24: isveren_adi | B24: Örnek Üretim A.Ş. | C24: metin | D24: Evet | E24: GIRDI | F24: =IF($A24="","",IF($B24="","EKSİK","TAM"))
A25: donem | B25: 2025-01 | C25: metin | D25: Evet | E25: GIRDI | F25: =IF($A25="","",IF($B25="","EKSİK","TAM"))
A26: hesapYili | B26: 2025 | C26: yıl | D26: Evet | E26: GIRDI | F26: =IF($A26="","",IF($B26="","EKSİK","TAM"))
A27: aylik_brut_matrah | B27: 500000 | C27: TL | D27: Evet | E27: GIRDI | F27: =IF($A27="","",IF($B27="","EKSİK","TAM"))
A28: calisan_sayisi | B28: 20 | C28: adet | D28: Evet | E28: GIRDI | F28: =IF($A28="","",IF($B28="","EKSİK","TAM"))
A29: bes_puan_matrah | B29: 300000 | C29: TL | D29: Evet | E29: GIRDI | F29: =IF($A29="","",IF($B29="","EKSİK","TAM"))
A30: ilave_istihdam_matrah | B30: 100000 | C30: TL | D30: Evet | E30: GIRDI | F30: =IF($A30="","",IF($B30="","EKSİK","TAM"))
A31: kadin_genc_matrah | B31: 50000 | C31: TL | D31: Evet | E31: GIRDI | F31: =IF($A31="","",IF($B31="","EKSİK","TAM"))
A32: engelli_matrah | B32: 30000 | C32: TL | D32: Evet | E32: GIRDI | F32: =IF($A32="","",IF($B32="","EKSİK","TAM"))
A33: mevcut_tesvik_tutari | B33: 10000 | C33: TL | D33: Evet | E33: GIRDI | F33: =IF($A33="","",IF($B33="","EKSİK","TAM"))
A34: birikim_yorumu | B34: A | C34: A/B | D34: Evet | E34: GIRDI | F34: =IF($A34="","",IF($B34="","EKSİK","TAM"))
F35: =IF($A35="","",IF($B35="","EKSİK","TAM"))
F36: =IF($A36="","",IF($B36="","EKSİK","TAM"))
F37: =IF($A37="","",IF($B37="","EKSİK","TAM"))
F38: =IF($A38="","",IF($B38="","EKSİK","TAM"))
F39: =IF($A39="","",IF($B39="","EKSİK","TAM"))
F40: =IF($A40="","",IF($B40="","EKSİK","TAM"))
F41: =IF($A41="","",IF($B41="","EKSİK","TAM"))
F42: =IF($A42="","",IF($B42="","EKSİK","TAM"))
F43: =IF($A43="","",IF($B43="","EKSİK","TAM"))
F44: =IF($A44="","",IF($B44="","EKSİK","TAM"))
...

Sheet KURALLAR
A1: KURALLAR — SGK Prim Teşvikleri Optimizasyon Motoru
A3: Mevzuat kural tablosu (yıl yan yana)
A4: Oranlar MOTOR'da sabit yazılmaz; INDEX/MATCH ile buradan çekilir.
A6: kural_id | B6: madde | C6: kural_adi | D6: kosul_metni | E6: parametre_adi | F6: deger_2025 | G6: deger_2026 | H6: deger_2027 | I6: yururluk | J6: kaynak | K6: aktif_deger
A7: SGK-001 | B7: 5510 md.81 | C7: bes_puan_oran | D7: kapsam_matrah>0 | E7: bes_puan_oran | F7: 0.05 | G7: 0.05 | H7: 0.05 | I7: 01.01.2025 | J7: 5510 s.K. md.81 | K7: =IF($A7="","",IFERROR(CHOOSE(MAX(1,MIN(3,IF(OR(hesapYili="",hesapYili=0),1,hesapYili-sgk_yilTaban))),$F7,$G7,$H7),0))
A8: SGK-002 | B8: 4447 geç.10 | C8: ilave_istihdam_oran | D8: ilave_matrah>0 | E8: ilave_istihdam_oran | F8: 0.145 | G8: 0.145 | H8: 0.145 | I8: 01.01.2025 | J8: 4447 s.K. geç.10 | K8: =IF($A8="","",IFERROR(CHOOSE(MAX(1,MIN(3,IF(OR(hesapYili="",hesapYili=0),1,hesapYili-sgk_yilTaban))),$F8,$G8,$H8),0))
A9: SGK-003 | B9: SGK tavan | C9: prim_tavani | D9: her hesap | E9: prim_tavani | F9: 150000 | G9: 165000 | H9: 180000 | I9: 01.01.2025 | J9: SGK prim tavanı | K9: =IF($A9="","",IFERROR(CHOOSE(MAX(1,MIN(3,IF(OR(hesapYili="",hesapYili=0),1,hesapYili-sgk_yilTaban))),$F9,$G9,$H9),0))
A10: SGK-004 | B10: 4447 / 5510 | C10: kadin_genc_oran | D10: kadin_genc_matrah>0 | E10: kadin_genc_oran | F10: 0.05 | G10: 0.05 | H10: 0.05 | I10: 01.01.2025 | J10: Kadın/genç istihdam | K10: =IF($A10="","",IFERROR(CHOOSE(MAX(1,MIN(3,IF(OR(hesapYili="",hesapYili=0),1,hesapYili-sgk_yilTaban))),$F10,$G10,$H10),0))
A11: SGK-005 | B11: Genel | C11: yuvarlama | D11: her hesap | E11: yuvarlama_ondalik | F11: 2 | G11: 2 | H11: 2 | I11: 01.01.2025 | J11: Uygulama notu | K11: =IF($A11="","",IFERROR(CHOOSE(MAX(1,MIN(3,IF(OR(hesapYili="",hesapYili=0),1,hesapYili-sgk_yilTaban))),$F11,$G11,$H11),0))
A14: Kural-yıl matrisi özeti
A15: 5 puan oranı (aktif yıl) | B15: =IFERROR(INDEX(CHOOSE(MAX(1,MIN(3,IF(OR(hesapYili="",hesapYili=0),1,hesapYili-sgk_yilTaban))),tblKurallar[deger_2025],tblKurallar[deger_2026],tblKurallar[deger_2027]),MATCH("SGK-001",tblKurallar[kural_id],0)),0)
A16: İlave istihdam oranı (aktif yıl) | B16: =IFERROR(INDEX(CHOOSE(MAX(1,MIN(3,IF(OR(hesapYili="",hesapYili=0),1,hesapYili-sgk_yilTaban))),tblKurallar[deger_2025],tblKurallar[deger_2026],tblKurallar[deger_2027]),MATCH("SGK-002",tblKurallar[kural_id],0)),0)
A17: Matris metni | B17: =IFERROR(_xlfn.TEXTJOIN(" | ",TRUE,"SGK-001=",TEXT(B15,"0.0%"),"SGK-002=",TEXT(B16,"0.0%"),"yıl=",IF(OR(hesapYili="",hesapYili=0),"-",hesapYili)),"-")

Sheet MOTOR
A1: MOTOR — SGK Prim Teşvikleri Optimizasyon Motoru
A3: Hesap zinciri — her adımda kural_id
A4: Oranlar tblKurallar'dan çekilir; sabit oran yoktur.
A6: adim | B6: ad | C6: formul | D6: birim | E6: ne_ise_yarar | F6: kural_id | G6: deger
A7: 1 | B7: Hesap yılı oku | C7: =IFERROR(hesapYili,0) | D7: yıl | E7: Aktif mevzuat yılı | F7: SGK-005 | G7: =IFERROR(hesapYili,0)
A8: 2 | B8: 5 puan oranı | C8: =IFERROR(INDEX(CHOOSE(MAX(1,MIN(3,IF(OR(hesapYili="",hesapYili=0),1,hesapYili-sgk_yilTaban))),tblKurallar[deger_2025],tblKurallar[deger_2026],tblKurallar[deger_2027]),MATCH("SGK-001",tblKurallar[kural_id],0)),0) | D8: oran | E8: 5510 md.81 oranı | F8: SGK-001 | G8: =IFERROR(INDEX(CHOOSE(MAX(1,MIN(3,IF(OR(hesapYili="",hesapYili=0),1,hesapYili-sgk_yilTaban))),tblKurallar[deger_2025],tblKurallar[deger_2026],tblKurallar[deger_2027]),MATCH("SGK-001",tblKurallar[kural_id],0)),0)
A9: 3 | B9: İlave istihdam oranı | C9: =IFERROR(INDEX(CHOOSE(MAX(1,MIN(3,IF(OR(hesapYili="",hesapYili=0),1,hesapYili-sgk_yilTaban))),tblKurallar[deger_2025],tblKurallar[deger_2026],tblKurallar[deger_2027]),MATCH("SGK-002",tblKurallar[kural_id],0)),0) | D9: oran | E9: 4447 geç.10 oranı | F9: SGK-002 | G9: =IFERROR(INDEX(CHOOSE(MAX(1,MIN(3,IF(OR(hesapYili="",hesapYili=0),1,hesapYili-sgk_yilTaban))),tblKurallar[deger_2025],tblKurallar[deger_2026],tblKurallar[deger_2027]),MATCH("SGK-002",tblKurallar[kural_id],0)),0)
A10: 4 | B10: Prim tavanı | C10: =IFERROR(INDEX(CHOOSE(MAX(1,MIN(3,IF(OR(hesapYili="",hesapYili=0),1,hesapYili-sgk_yilTaban))),tblKurallar[deger_2025],tblKurallar[deger_2026],tblKurallar[deger_2027]),MATCH("SGK-003",tblKurallar[kural_id],0)),0) | D10: TL | E10: Aylık prim tavanı | F10: SGK-003 | G10: =IFERROR(INDEX(CHOOSE(MAX(1,MIN(3,IF(OR(hesapYili="",hesapYili=0),1,hesapYili-sgk_yilTaban))),tblKurallar[deger_2025],tblKurallar[deger_2026],tblKurallar[deger_2027]),MATCH("SGK-003",tblKurallar[kural_id],0)),0)
A11: 5 | B11: Kadın/genç oranı | C11: =IFERROR(INDEX(CHOOSE(MAX(1,MIN(3,IF(OR(hesapYili="",hesapYili=0),1,hesapYili-sgk_yilTaban))),tblKurallar[deger_2025],tblKurallar[deger_2026],tblKurallar[deger_2027]),MATCH("SGK-004",tblKurallar[kural_id],0)),0) | D11: oran | E11: Kadın/genç teşvik oranı | F11: SGK-004 | G11: =IFERROR(INDEX(CHOOSE(MAX(1,MIN(3,IF(OR(hesapYili="",hesapYili=0),1,hesapYili-sgk_yilTaban))),tblKurallar[deger_2025],tblKurallar[deger_2026],tblKurallar[deger_2027]),MATCH("SGK-004",tblKurallar[kural_id],0)),0)
A12: 6 | B12: Yuvarlama ondalık | C12: =IFERROR(INDEX(CHOOSE(MAX(1,MIN(3,IF(OR(hesapYili="",hesapYili=0),1,hesapYili-sgk_yilTaban))),tblKurallar[deger_2025],tblKurallar[deger_2026],tblKurallar[deger_2027]),MATCH("SGK-005",tblKurallar[kural_id],0)),0) | D12: adet | E12: Yuvarlama basamağı | F12: SGK-005 | G12: =IFERROR(INDEX(CHOOSE(MAX(1,MIN(3,IF(OR(hesapYili="",hesapYili=0),1,hesapYili-sgk_yilTaban))),tblKurallar[deger_2025],tblKurallar[deger_2026],tblKurallar[deger_2027]),MATCH("SGK-005",tblKurallar[kural_id],0)),0)
A13: 7 | B13: Aylık brüt matrah | C13: =IFERROR(GIRDI!B9,0) | D13: TL | E13: Ham brüt matrah | F13: SGK-003 | G13: =IFERROR(GIRDI!B9,0)
A14: 8 | B14: Çalışan sayısı | C14: =IFERROR(GIRDI!B10,0) | D14: adet | E14: Bildirilen çalışan | F14: SGK-003 | G14: =IFERROR(GIRDI!B10,0)
A15: 9 | B15: 5 puan kapsam | C15: =IFERROR(GIRDI!B11,0) | D15: TL | E15: 5 puan uygun matrah | F15: SGK-001 | G15: =IFERROR(GIRDI!B11,0)
A16: 10 | B16: İlave kapsam | C16: =IFERROR(GIRDI!B12,0) | D16: TL | E16: İlave uygun matrah | F16: SGK-002 | G16: =IFERROR(GIRDI!B12,0)
A17: 11 | B17: Kadın/genç kapsam | C17: =IFERROR(GIRDI!B13,0) | D17: TL | E17: Kadın/genç matrah | F17: SGK-004 | G17: =IFERROR(GIRDI!B13,0)
A18: 12 | B18: Engelli kapsam | C18: =IFERROR(GIRDI!B14,0) | D18: TL | E18: Engelli matrah | F18: SGK-002 | G18: =IFERROR(GIRDI!B14,0)
A19: 13 | B19: Mevcut teşvik | C19: =IFERROR(GIRDI!B15,0) | D19: TL | E19: Fiili uygulanan | F19: SGK-005 | G19: =IFERROR(GIRDI!B15,0)
A20: 14 | B20: Tavan üst sınırı | C20: =IFERROR(G10*G14,0) | D20: TL | E20: Tavan × çalışan | F20: SGK-003 | G20: =IFERROR(G10*G14,0)
A21: 15 | B21: Matrah tavanlı | C21: =IFERROR(MIN(G13,G20),0) | D21: TL | E21: Tavan kesilmiş matrah | F21: SGK-003 | G21: =IFERROR(MIN(G13,G20),0)
A22: 16 | B22: 5 puan (kesilmiş) | C22: =IFERROR(ROUND(MIN(G15,G21)*G8,MAX(0,MIN(sgk_yuvarMax,IFERROR(N(G12),0)))),0) | D22: TL | E22: 5 puan tasarrufu | F22: SGK-001 | G22: =IFERROR(ROUND(MIN(G15,G21)*G8,MAX(0,MIN(sgk_yuvarMax,IFERROR(N(G12),0)))),0)
A23: 17 | B23: İlave (kesilmiş) | C23: =IFERROR(ROUND(MIN(G16,G21)*G9,MAX(0,MIN(sgk_yuvarMax,IFERROR(N(G12),0)))),0) | D23: TL | E23: İlave tasarrufu | F23: SGK-002 | G23: =IFERROR(ROUND(MIN(G16,G21)*G9,MAX(0,MIN(sgk_yuvarMax,IFERROR(N(G12),0)))),0)
A24: 18 | B24: Kadın/genç (kesilmiş) | C24: =IFERROR(ROUND(MIN(G17,G21)*G11,MAX(0,MIN(sgk_yuvarMax,IFERROR(N(G12),0)))),0) | D24: TL | E24: Kadın/genç tasarrufu | F24: SGK-004 | G24: =IFERROR(ROUND(MIN(G17,G21)*G11,MAX(0,MIN(sgk_yuvarMax,IFERROR(N(G12),0)))),0)
A25: 19 | B25: Engelli (işveren payı) | C25: =IFERROR(ROUND(MIN(G18,G21)*sgk_isverenOran,MAX(0,MIN(sgk_yuvarMax,IFERROR(N(G12),0)))),0) | D25: TL | E25: Engelli işveren payı muafiyeti | F25: SGK-002 | G25: =IFERROR(ROUND(MIN(G18,G21)*sgk_isverenOran,MAX(0,MIN(sgk_yuvarMax,IFERROR(N(G12),0)))),0)
A26: 20 | B26: Birikimli toplam (A) | C26: =IFERROR(G22+G23+G24+G25,0) | D26: TL | E26: Yorum A birikim | F26: SGK-005 | G26: =IFERROR(G22+G23+G24+G25,0)
A27: 21 | B27: En yüksek tek kalem (B) | C27: =IFERROR(MAX(G22,G23,G24,G25),0) | D27: TL | E27: Yorum B tek seçim | F27: SGK-005 | G27: =IFERROR(MAX(G22,G23,G24,G25),0)
A28: 22 | B28: Potansiyel tasarruf | C28: =IFERROR(IF(GIRDI!B16="B",G27,G26),0) | D28: TL | E28: Seçili yoruma göre | F28: SGK-005 | G28: =IFERROR(IF(GIRDI!B16="B",G27,G26),0)
A29: 23 | B29: Kaçırılan (ham) | C29: =IFERROR(G28-G19,0) | D29: TL | E29: Potansiyel − mevcut | F29: SGK-005 | G29: =IFERROR(G28-G19,0)
A30: 24 | B30: Kaçırılan (sıfır altı yok) | C30: =IFERROR(MAX(0,G29),0) | D30: TL | E30: Optimizasyon fırsatı | F30: SGK-005 | G30: =IFERROR(MAX(0,G29),0)
A31: 25 | B31: Yıllık potansiyel | C31: =IFERROR(G28*12,0) | D31: TL | E31: 12 ay projeksiyon | F31: SGK-005 | G31: =IFERROR(G28*12,0)
A32: 26 | B32: Yıllık kaçırılan | C32: =IFERROR(G30*12,0) | D32: TL | E32: 12 ay kaçırılan | F32: SGK-005 | G32: =IFERROR(G30*12,0)
A33: 27 | B33: Karar kodu | C33: =IFERROR(IF(COUNTA(tblGirdi[Alan Anahtarı])=0,"VERI_YOK",IF(G30=0,"TAM","FIRSAT")),"") | D33: kod | E33: Karar kodu | F33: SGK-005 | G33: =IFERROR(IF(COUNTA(tblGirdi[Alan Anahtarı])=0,"VERI_YOK",IF(G30=0,"TAM","FIRSAT")),"")
A34: 28 | B34: Karar metni | C34: =IFERROR(IF(G33="VERI_YOK","VERİ YOK",IF(G33="TAM","UYGUN / TEŞVİK TAM",IF(G30>=sgk_kacirilanEsik,"OPTİMİZE ET / DİKKAT","İNCELE / FIRSAT"))),"") | D34: metin | E34: Kullanıcıya karar | F34: SGK-005 | G34: =IFERROR(IF(G33="VERI_YOK","VERİ YOK",IF(G33="TAM","UYGUN / TEŞVİK TAM",IF(G30>=sgk_kacirilanEsik,"OPTİMİZE ET / DİKKAT","İNCELE / FIRSAT"))),"")
A35: 29 | B35: Gerekçe | C35: =IFERROR(IF(G33="VERI_YOK","Giriş tablosu boş — hesap yapılamaz.",IF(G33="TAM","Mevcut teşvik potansiyeli karşılıyor; ek fırsat yok.","Potansiyel teşvik mevcut uygulamanın üzerinde; optimizasyon fırsatı var.")),"") | D35: metin | E35: Gerekçe cümlesi | F35: SGK-005 | G35: =IFERROR(IF(G33="VERI_YOK","Giriş tablosu boş — hesap yapılamaz.",IF(G33="TAM","Mevcut teşvik potansiyeli karşılıyor; ek fırsat yok.","Potansiyel teşvik mevcut uygulamanın üzerinde; optimizasyon fırsatı var.")),"")
A36: 30 | B36: Kapsam / matrah oranı | C36: =IFERROR(IF(G21=0,0,(G15+G16+G17+G18)/G21),0) | D36: oran | E36: Kapsam yoğunluğu | F36: SGK-003 | G36: =IFERROR(IF(G21=0,0,(G15+G16+G17+G18)/G21),0)
A37: 31 | B37: Mevcut / potansiyel | C37: =IFERROR(IF(G28=0,0,G19/G28),0) | D37: oran | E37: Karşılama oranı | F37: SGK-005 | G37: =IFERROR(IF(G28=0,0,G19/G28),0)
A38: 32 | B38: Güven skoru | C38: =IFERROR(ROUND(IF(OR(COUNTA(GIRDI!B6:B16)=0,sgk_girisBeklenen=0),0,COUNTA(GIRDI!B6:B16)/sgk_girisBeklenen*100),0),0) | D38: puan | E38: Giriş bütünlüğü | F38: SGK-005 | G38: =IFERROR(ROUND(IF(OR(COUNTA(GIRDI!B6:B16)=0,sgk_girisBeklenen=0),0,COUNTA(GIRDI!B6:B16)/sgk_girisBeklenen*100),0),0)
A39: 33 | B39: Risk skoru | C39: =IFERROR(IF(G33="VERI_YOK",0,IF(G30=0,sgk_riskDusuk,IF(G30/MAX(G28,1)>sgk_riskEsikOran,sgk_riskYuksek,sgk_riskOrta))),0) | D39: puan | E39: Kaçırılan riski | F39: SGK-005 | G39: =IFERROR(IF(G33="VERI_YOK",0,IF(G30=0,sgk_riskDusuk,IF(G30/MAX(G28,1)>sgk_riskEsikOran,sgk_riskYuksek,sgk_riskOrta))),0)
A40: 34 | B40: Senaryo iyimser matrah | C40: =IFERROR(G21*sgk_senaryoIyi,0) | D40: TL | E40: İyimser matrah | F40: SGK-003 | G40: =IFERROR(G21*sgk_senaryoIyi,0)
A41: 35 | B41: Senaryo kötümser matrah | C41: =IFERROR(G21*sgk_senaryoKotu,0) | D41: TL | E41: Kötümser matrah | F41: SGK-003 | G41: =IFERROR(G21*sgk_senaryoKotu,0)
A42: 36 | B42: İyimser potansiyel | C42: =IFERROR(ROUND(MIN(G15,G40)*G8+MIN(G16,G40)*G9+MIN(G17,G40)*G11+MIN(G18,G40)*sgk_isverenOran,MAX(0,MIN(sgk_yuvarMax,IFERROR(N(G12),0)))),0) | D42: TL | E42: İyimser birikim | F42: SGK-001 | G42: =IFERROR(ROUND(MIN(G15,G40)*G8+MIN(G16,G40)*G9+MIN(G17,G40)*G11+MIN(G18,G40)*sgk_isverenOran,MAX(0,MIN(sgk_yuvarMax,IFERROR(N(G12),0)))),0)
...

Sheet SENARYO
A1: SENARYO — SGK Prim Teşvikleri Optimizasyon Motoru
A3: Senaryo ve duyarlılık
A5: Senaryo | B5: Matrah Çarpanı | C5: Potansiyel | D5: Kaçırılan | E5: Karar | G5: KacirilanDemo
A6: İyimser | B6: =IFERROR(sgk_senaryoIyi+N(GIRDI!B9)*0,0) | C6: =IFERROR(ROUND((IFERROR(sgk_potansiyelTasarruf,0))*B6,2),0) | D6: =IFERROR(MAX(0,C6-(IFERROR(sgk_mevcutTesvik,0))),0) | E6: =IF(COUNTA(tblGirdi[Alan Anahtarı])=0,"VERİ YOK",IF(D6=0,"UYGUN","FIRSAT")) | G6: 18800
A7: Baz | B7: =IFERROR(1+N(GIRDI!B9)*0,1) | C7: =IFERROR(ROUND((IFERROR(sgk_potansiyelTasarruf,0))*B7,2),0) | D7: =IFERROR(MAX(0,C7-(IFERROR(sgk_mevcutTesvik,0))),0) | E7: =IF(COUNTA(tblGirdi[Alan Anahtarı])=0,"VERİ YOK",IF(D7=0,"UYGUN","FIRSAT")) | G7: 22000
A8: Kötümser | B8: =IFERROR(sgk_senaryoKotu+N(GIRDI!B9)*0,0) | C8: =IFERROR(ROUND((IFERROR(sgk_potansiyelTasarruf,0))*B8,2),0) | D8: =IFERROR(MAX(0,C8-(IFERROR(sgk_mevcutTesvik,0))),0) | E8: =IF(COUNTA(tblGirdi[Alan Anahtarı])=0,"VERİ YOK",IF(D8=0,"UYGUN","FIRSAT")) | G8: 26400
A9: M-SEN +1 puan | B9: =IFERROR(1+N(GIRDI!B9)*0,1) | C9: =IFERROR(MOTOR!G45,0) | D9: =IFERROR(MOTOR!G46,0) | E9: =IF(COUNTA(tblGirdi[Alan Anahtarı])=0,"VERİ YOK",IF(D9=0,"UYGUN","FIRSAT")) | G9: 23500
A11: Senaryo bant genişliği (iyimser−kötümser kaçırılan) | B11: =IFERROR(D6-D8,0)
A12: Senaryo yorumu | B12: =IFERROR(_xlfn.TEXTJOIN("; ",TRUE,"İyimser kaçırılan ",TEXT(D6,"₺ #,##0")," · Baz ",TEXT(D7,"₺ #,##0")," · Kötümser ",TEXT(D8,"₺ #,##0")," · Bant ",TEXT(B11,"₺ #,##0")),"-")
A14: Duyarlılık (tornado)
A15: Değişken | B15: Etki [₺] | C15: Sıra | E15: EtkiDemo
A16: Tornado matrah etkisi | B16: =IFERROR(MOTOR!G49,0) | C16: =IFERROR(IF(B16>=MAX(B16:B18),1,IF(B16>=MIN(B16:B18)+ABS(B16-B17),2,3)),3) | E16: 1600
A17: Tornado mevcut etkisi | B17: =IFERROR(MOTOR!G50,0) | C17: =IFERROR(IF(B17>=MAX(B16:B18),1,IF(B17=MEDIAN(B16:B18),2,3)),3) | E17: 1100
A18: Tornado oran etkisi | B18: =IFERROR(MOTOR!G51,0) | C18: =IFERROR(IF(B18>=MAX(B16:B18),1,IF(B18=MEDIAN(B16:B18),2,3)),3) | E18: 1500
A19: Duyarlılık sıra özeti | B19: =IFERROR(CONCATENATE("1)",INDEX(A16:A18,MATCH(1,C16:C18,0))," 2)",INDEX(A16:A18,MATCH(2,C16:C18,0))),"-")
A20: Duyarlılık yorumu | B20: =_xlfn.TEXTJOIN("; ",TRUE,"En yüksek etki ",TEXT(MAX(B16:B18),"₺ #,##0")," TL — öncelik bu değişkende")
A22: M-SEN kural değişimi kaçırılan | B22: =D9
A23: M-SEN yorumu | B23: =_xlfn.TEXTJOIN("; ",TRUE,"5 puan oranı +1 puan senaryosunda kaçırılan ",TEXT(D9,"₺ #,##0")," TL")
A25: Tahmin aralığı (kaçırılan) | B25: =MOTOR!G48 | C25: =sgk_kacirilan | D25: =MOTOR!G47
A26: Tahmin (FORECAST)
A27: Seri nokta | D27: TrendDemo
A28: 1 | B28: =D6 | D28: 18800
A29: 2 | B29: =D7 | D29: 22000
A30: 3 | B30: =D8 | D30: 26400
A31: 4 | B31: =D9 | D31: 23500
A32: Tahmin sonraki | B32: =IFERROR(FORECAST.LINEAR(5,B28:B31,A28:A31),0)
A33: Tahmin yorumu | B33: =_xlfn.TEXTJOIN("; ",TRUE,"Tahmin ",TEXT(B32,"₺ #,##0")," · Alt ",TEXT(B25,"₺ #,##0")," · Üst ",TEXT(D25,"₺ #,##0"))

Sheet VAKALAR
A1: VAKALAR — SGK Prim Teşvikleri Optimizasyon Motoru
A3: Tebliğ tarzı altın vakalar
A5: vaka_id | B5: aciklama | C5: girdi_ozeti | D5: beklenen_sonuc | E5: hesaplanan | F5: fark | G5: durum | H5: kaynak | J5: BeklenenDemo | K5: HesapDemo
A6: V-001 | B6: Tebliğ örnek 1 — 5 puan | C6: bes_puan_matrah=vaka_matrah_1 | D6: 15000 | E6: =IFERROR(ROUND(vaka_matrah_1*INDEX(tblKurallar[deger_2025],MATCH("SGK-001",tblKurallar[kural_id],0)),2),0) | F6: =IF($A6="","",IFERROR($D6-$E6,0)) | G6: =IF($A6="","",IFERROR(IF(ABS($F6)<=sgk_tolerans,"TUTARLI","KIRIK"),"KIRIK")) | H6: 5510 md.81 örnek | J6: 15000 | K6: 15000
A7: V-002 | B7: Tebliğ örnek 2 — ilave istihdam | C7: ilave_matrah=vaka_matrah_2 | D7: 14500 | E7: =IFERROR(ROUND(vaka_matrah_2*INDEX(tblKurallar[deger_2025],MATCH("SGK-002",tblKurallar[kural_id],0)),2),0) | F7: =IF($A7="","",IFERROR($D7-$E7,0)) | G7: =IF($A7="","",IFERROR(IF(ABS($F7)<=sgk_tolerans,"TUTARLI","KIRIK"),"KIRIK")) | H7: 4447 geç.10 örnek | J7: 14500 | K7: 14500
A8: V-003 | B8: Tebliğ örnek 3 — birikimli A | C8: 5 puan + ilave | D8: 29500 | E8: =IFERROR(ROUND(vaka_matrah_1*INDEX(tblKurallar[deger_2025],MATCH("SGK-001",tblKurallar[kural_id],0))+vaka_matrah_2*INDEX(tblKurallar[deger_2025],MATCH("SGK-002",tblKurallar[kural_id],0)),2),0) | F8: =IF($A8="","",IFERROR($D8-$E8,0)) | G8: =IF($A8="","",IFERROR(IF(ABS($F8)<=sgk_tolerans,"TUTARLI","KIRIK"),"KIRIK")) | H8: Birikim yorum A | J8: 29500 | K8: 29500
A9: V-004 | B9: Tavan × 5 puan kontrol | C9: tavan=vaka_tavan; oran SGK-001 | D9: 7500 | E9: =IFERROR(ROUND(vaka_tavan*INDEX(tblKurallar[deger_2025],MATCH("SGK-001",tblKurallar[kural_id],0)),2),0) | F9: =IF($A9="","",IFERROR($D9-$E9,0)) | G9: =IF($A9="","",IFERROR(IF(ABS($F9)<=sgk_tolerans,"TUTARLI","KIRIK"),"KIRIK")) | H9: SGK-003 tavan kontrol | J9: 7500 | K9: 7500
A12: Vaka durum özeti | B12: =IFERROR(IF(COUNTIF(tblVakalar[durum],"KIRIK")>0,"KIRIK","TUTARLI"),"KIRIK")
A13: Vaka fark toplamı | B13: =IFERROR(SUM(tblVakalar[fark]),0)

Sheet KANIT_RAPORU
A1: KANIT RAPORU — SGK Prim Teşvikleri Optimizasyon Motoru
A3: KANIT RAPORU — SGK Prim Teşvikleri
A4: Rapor tarihi | B4: =raporTarihi
A5: İşveren | B5: =GIRDI!B6
A6: Dönem / yıl | B6: =CONCATENATE(GIRDI!B7," / ",hesapYili)
A8: Girdi özeti
A9: Aylık brüt matrah | B9: =GIRDI!B9
A10: Çalışan sayısı | B10: =GIRDI!B10
A11: 5 puan kapsam | B11: =GIRDI!B11
A12: İlave istihdam | B12: =GIRDI!B12
A13: Kadın/genç | B13: =GIRDI!B13
A14: Engelli | B14: =GIRDI!B14
A15: Mevcut teşvik | B15: =sgk_mevcutTesvik
A17: Hesap zinciri
A18: Potansiyel tasarruf | B18: =sgk_potansiyelTasarruf
A19: Kaçırılan | B19: =sgk_kacirilan
A20: KARAR | B20: =sgk_kararMetni
A21: Gerekçe | B21: =sgk_kararGerekce
A23: Madde atıfları | B23: =sgk_maddeAtifMetni
A25: Kanıt gövdesi | B25: =sgk_kanitRaporu
A27: Parmak izi (SHA-256 kısaltma) | B27: =sgk_parmakIzi
A29: Hazırlayan (imza)
A30: Onaylayan (imza)
A32: Uyarı: Bu çıktı karar destektir; kesin SGK tahakkuku veya hukuki görüş değildir. Sürüm 1.0.0.

Sheet KONTROLLER
A1: KONTROLLER — SGK Prim Teşvikleri Optimizasyon Motoru
A3: Canlı kontrol paneli
A5: Giriş tablosu boş mu? | B5: =IF(COUNTA(tblGirdi[Alan Anahtarı])=0,"BOŞ","DOLU")
A6: Negatif brüt matrah? | B6: =IF(GIRDI!B9<0,"NEGATİF","TEMİZ")
A7: Hesap yılı geçerli mi? | B7: =IFERROR(IF(AND(N(hesapYili)>N(sgk_yilTaban),N(hesapYili)<=N(sgk_yilTaban)+3),"TEMİZ","HATALI"),"HATALI")
A8: Matrah sıfır mı? | B8: =IF(IFERROR(MOTOR!G21,0)=0,"SIFIR","NORMAL")
A9: Vaka kırık mı? | B9: =IFERROR(IF(COUNTIF(tblVakalar[durum],"KIRIK")>0,"KIRIK","TUTARLI"),"KIRIK")
A10: Kaçırılan eşiği aşıyor mu? | B10: =IF(IFERROR(sgk_kacirilan,0)>sgk_kacirilanEsik,"AŞIYOR","NORMAL")
A11: Yorum A/B seçili mi? | B11: =IF(OR(GIRDI!B16="A",GIRDI!B16="B"),"TEMİZ","EKSİK")
A12: Kalite skoru (modül) | B12: =IFERROR(ROUND(IF(OR(B14=0,B14=""),0,B15/B14*100),0),0)
A14: Toplam giriş alanı | B14: =IFERROR(sgk_girisBeklenen+COUNTA(GIRDI!B6:B16)*0,0)
A15: Dolu giriş | B15: =COUNTA(GIRDI!B6:B16)
A17: Potansiyel kontrol | B17: =IFERROR(sgk_potansiyelTasarruf,0)
A18: Kaçırılan kontrol | B18: =IFERROR(sgk_kacirilan,0)
A19: Karar kontrol | B19: =IFERROR(sgk_kararMetni,"-")

Sheet ORNEK_VERI
A1: ORNEK VERI — SGK Prim Teşvikleri Optimizasyon Motoru
A3: Örnek senaryo kütüphanesi
A4: Bu sayfa demo değerleri saklar; GIRDI'ye kopyalanabilir.
A5: Senaryo | B5: Brüt Matrah | C5: 5 Puan | D5: İlave | E5: Kadın/Genç | F5: Engelli | G5: Mevcut | H5: Potansiyel | I5: Kaçırılan | L5: KacirilanDemo
A6: Demo ana | B6: 500000 | C6: 300000 | D6: 100000 | E6: 50000 | F6: 30000 | G6: 10000 | H6: =IF($A6="","",IFERROR(ROUND($C6*INDEX(tblKurallar[deger_2025],MATCH("SGK-001",tblKurallar[kural_id],0))+$D6*INDEX(tblKurallar[deger_2025],MATCH("SGK-002",tblKurallar[kural_id],0))+$E6*INDEX(tblKurallar[deger_2025],MATCH("SGK-004",tblKurallar[kural_id],0))+$F6*sgk_isverenOran,2),0)) | I6: =IF($A6="","",IFERROR(MAX(0,$H6-$G6),0)) | L6: 28150
A7: Yüksek mevcut | B7: 500000 | C7: 300000 | D7: 100000 | E7: 50000 | F7: 30000 | G7: 40000 | H7: =IF($A7="","",IFERROR(ROUND($C7*INDEX(tblKurallar[deger_2025],MATCH("SGK-001",tblKurallar[kural_id],0))+$D7*INDEX(tblKurallar[deger_2025],MATCH("SGK-002",tblKurallar[kural_id],0))+$E7*INDEX(tblKurallar[deger_2025],MATCH("SGK-004",tblKurallar[kural_id],0))+$F7*sgk_isverenOran,2),0)) | I7: =IF($A7="","",IFERROR(MAX(0,$H7-$G7),0)) | L7: 0
A8: Düşük matrah | B8: 200000 | C8: 120000 | D8: 40000 | E8: 20000 | F8: 10000 | G8: 5000 | H8: =IF($A8="","",IFERROR(ROUND($C8*INDEX(tblKurallar[deger_2025],MATCH("SGK-001",tblKurallar[kural_id],0))+$D8*INDEX(tblKurallar[deger_2025],MATCH("SGK-002",tblKurallar[kural_id],0))+$E8*INDEX(tblKurallar[deger_2025],MATCH("SGK-004",tblKurallar[kural_id],0))+$F8*sgk_isverenOran,2),0)) | I8: =IF($A8="","",IFERROR(MAX(0,$H8-$G8),0)) | L8: 15200
A9: Sadece 5 puan | B9: 400000 | C9: 400000 | D9: 0 | E9: 0 | F9: 0 | G9: 5000 | H9: =IF($A9="","",IFERROR(ROUND($C9*INDEX(tblKurallar[deger_2025],MATCH("SGK-001",tblKurallar[kural_id],0))+$D9*INDEX(tblKurallar[deger_2025],MATCH("SGK-002",tblKurallar[kural_id],0))+$E9*INDEX(tblKurallar[deger_2025],MATCH("SGK-004",tblKurallar[kural_id],0))+$F9*sgk_isverenOran,2),0)) | I9: =IF($A9="","",IFERROR(MAX(0,$H9-$G9),0)) | L9: 15000
A10: Sıfır kaçırılan | B10: 300000 | C10: 200000 | D10: 50000 | E10: 0 | F10: 0 | G10: 17250 | H10: =IF($A10="","",IFERROR(ROUND($C10*INDEX(tblKurallar[deger_2025],MATCH("SGK-001",tblKurallar[kural_id],0))+$D10*INDEX(tblKurallar[deger_2025],MATCH("SGK-002",tblKurallar[kural_id],0))+$E10*INDEX(tblKurallar[deger_2025],MATCH("SGK-004",tblKurallar[kural_id],0))+$F10*sgk_isverenOran,2),0)) | I10: =IF($A10="","",IFERROR(MAX(0,$H10-$G10),0)) | L10: 0
H11: =IF($A11="","",IFERROR(ROUND($C11*INDEX(tblKurallar[deger_2025],MATCH("SGK-001",tblKurallar[kural_id],0))+$D11*INDEX(tblKurallar[deger_2025],MATCH("SGK-002",tblKurallar[kural_id],0))+$E11*INDEX(tblKurallar[deger_2025],MATCH("SGK-004",tblKurallar[kural_id],0))+$F11*sgk_isverenOran,2),0)) | I11: =IF($A11="","",IFERROR(MAX(0,$H11-$G11),0))
H12: =IF($A12="","",IFERROR(ROUND($C12*INDEX(tblKurallar[deger_2025],MATCH("SGK-001",tblKurallar[kural_id],0))+$D12*INDEX(tblKurallar[deger_2025],MATCH("SGK-002",tblKurallar[kural_id],0))+$E12*INDEX(tblKurallar[deger_2025],MATCH("SGK-004",tblKurallar[kural_id],0))+$F12*sgk_isverenOran,2),0)) | I12: =IF($A12="","",IFERROR(MAX(0,$H12-$G12),0))
H13: =IF($A13="","",IFERROR(ROUND($C13*INDEX(tblKurallar[deger_2025],MATCH("SGK-001",tblKurallar[kural_id],0))+$D13*INDEX(tblKurallar[deger_2025],MATCH("SGK-002",tblKurallar[kural_id],0))+$E13*INDEX(tblKurallar[deger_2025],MATCH("SGK-004",tblKurallar[kural_id],0))+$F13*sgk_isverenOran,2),0)) | I13: =IF($A13="","",IFERROR(MAX(0,$H13-$G13),0))
H14: =IF($A14="","",IFERROR(ROUND($C14*INDEX(tblKurallar[deger_2025],MATCH("SGK-001",tblKurallar[kural_id],0))+$D14*INDEX(tblKurallar[deger_2025],MATCH("SGK-002",tblKurallar[kural_id],0))+$E14*INDEX(tblKurallar[deger_2025],MATCH("SGK-004",tblKurallar[kural_id],0))+$F14*sgk_isverenOran,2),0)) | I14: =IF($A14="","",IFERROR(MAX(0,$H14-$G14),0))
H15: =IF($A15="","",IFERROR(ROUND($C15*INDEX(tblKurallar[deger_2025],MATCH("SGK-001",tblKurallar[kural_id],0))+$D15*INDEX(tblKurallar[deger_2025],MATCH("SGK-002",tblKurallar[kural_id],0))+$E15*INDEX(tblKurallar[deger_2025],MATCH("SGK-004",tblKurallar[kural_id],0))+$F15*sgk_isverenOran,2),0)) | I15: =IF($A15="","",IFERROR(MAX(0,$H15-$G15),0))
H16: =IF($A16="","",IFERROR(ROUND($C16*INDEX(tblKurallar[deger_2025],MATCH("SGK-001",tblKurallar[kural_id],0))+$D16*INDEX(tblKurallar[deger_2025],MATCH("SGK-002",tblKurallar[kural_id],0))+$E16*INDEX(tblKurallar[deger_2025],MATCH("SGK-004",tblKurallar[kural_id],0))+$F16*sgk_isverenOran,2),0)) | I16: =IF($A16="","",IFERROR(MAX(0,$H16-$G16),0))
H17: =IF($A17="","",IFERROR(ROUND($C17*INDEX(tblKurallar[deger_2025],MATCH("SGK-001",tblKurallar[kural_id],0))+$D17*INDEX(tblKurallar[deger_2025],MATCH("SGK-002",tblKurallar[kural_id],0))+$E17*INDEX(tblKurallar[deger_2025],MATCH("SGK-004",tblKurallar[kural_id],0))+$F17*sgk_isverenOran,2),0)) | I17: =IF($A17="","",IFERROR(MAX(0,$H17-$G17),0))
H18: =IF($A18="","",IFERROR(ROUND($C18*INDEX(tblKurallar[deger_2025],MATCH("SGK-001",tblKurallar[kural_id],0))+$D18*INDEX(tblKurallar[deger_2025],MATCH("SGK-002",tblKurallar[kural_id],0))+$E18*INDEX(tblKurallar[deger_2025],MATCH("SGK-004",tblKurallar[kural_id],0))+$F18*sgk_isverenOran,2),0)) | I18: =IF($A18="","",IFERROR(MAX(0,$H18-$G18),0))
H19: =IF($A19="","",IFERROR(ROUND($C19*INDEX(tblKurallar[deger_2025],MATCH("SGK-001",tblKurallar[kural_id],0))+$D19*INDEX(tblKurallar[deger_2025],MATCH("SGK-002",tblKurallar[kural_id],0))+$E19*INDEX(tblKurallar[deger_2025],MATCH("SGK-004",tblKurallar[kural_id],0))+$F19*sgk_isverenOran,2),0)) | I19: =IF($A19="","",IFERROR(MAX(0,$H19-$G19),0))
H20: =IF($A20="","",IFERROR(ROUND($C20*INDEX(tblKurallar[deger_2025],MATCH("SGK-001",tblKurallar[kural_id],0))+$D20*INDEX(tblKurallar[deger_2025],MATCH("SGK-002",tblKurallar[kural_id],0))+$E20*INDEX(tblKurallar[deger_2025],MATCH("SGK-004",tblKurallar[kural_id],0))+$F20*sgk_isverenOran,2),0)) | I20: =IF($A20="","",IFERROR(MAX(0,$H20-$G20),0))
H21: =IF($A21="","",IFERROR(ROUND($C21*INDEX(tblKurallar[deger_2025],MATCH("SGK-001",tblKurallar[kural_id],0))+$D21*INDEX(tblKurallar[deger_2025],MATCH("SGK-002",tblKurallar[kural_id],0))+$E21*INDEX(tblKurallar[deger_2025],MATCH("SGK-004",tblKurallar[kural_id],0))+$F21*sgk_isverenOran,2),0)) | I21: =IF($A21="","",IFERROR(MAX(0,$H21-$G21),0))
H22: =IF($A22="","",IFERROR(ROUND($C22*INDEX(tblKurallar[deger_2025],MATCH("SGK-001",tblKurallar[kural_id],0))+$D22*INDEX(tblKurallar[deger_2025],MATCH("SGK-002",tblKurallar[kural_id],0))+$E22*INDEX(tblKurallar[deger_2025],MATCH("SGK-004",tblKurallar[kural_id],0))+$F22*sgk_isverenOran,2),0)) | I22: =IF($A22="","",IFERROR(MAX(0,$H22-$G22),0))
... H1004: =IF($A1004="","",IFERROR(ROUND($C1004*INDEX(tblKurallar[deger_2025],MATCH("SGK-001",tblKurallar[kural_id],0))+$D1004*INDEX(tblKurallar[deger_2025],MATCH("SGK-002",tblKurallar[kural_id],0))+$E1004*INDEX(tblKurallar[deger_2025],MATCH("SGK-004",tblKurallar[kural_id],0))+$F1004*sgk_isverenOran,2),0)) | I1004: =IF($A1004="","",IFERROR(MAX(0,$H1004-$G1004),0))

Sheet LISTELER
A1: LISTELER — SGK Prim Teşvikleri Optimizasyon Motoru
A3: Doğrulama listeleri
A5: Yıllar | C5: Yorum A/B | E5: Evet/Hayır
A6: 2025 | C6: A | E6: Evet
A7: 2026 | C7: B | E7: Hayır
A8: 2027

Sheet AYARLAR
A1: AYARLAR — SGK Prim Teşvikleri Optimizasyon Motoru
A3: Parametreler (tek kaynak)
A5: anahtar | B5: deger | C5: birim | D5: aciklama | E5: kaynak | F5: yururluk_tarihi | G5: dogrulama_tarihi | H5: kontrol
A6: hesapYili | B6: 2025 | C6: yıl | D6: Aktif hesap yılı | E6: Kullanıcı / GIRDI | F6: 01.01.2025 | G6: 11.08.2026 | H6: =IF(A6="","",IF(B6="","EKSİK","TAM"))
A7: raporTarihi | B7: 46245 | C7: tarih | D7: Rapor tarihi (sabit) | E7: Üretim | F7: 01.01.2025 | G7: 11.08.2026 | H7: =IF(A7="","",IF(B7="","EKSİK","TAM"))
A8: sgk_tolerans | B8: 0.01 | C8: TL | D8: Vaka tutarlılık toleransı | E8: Uygulama notu | F8: 01.01.2025 | G8: 11.08.2026 | H8: =IF(A8="","",IF(B8="","EKSİK","TAM"))
A9: sgk_kacirilanEsik | B9: 15000 | C9: TL | D9: PANO kaçırılan uyarı eşiği | E9: İç politika | F9: 01.01.2025 | G9: 11.08.2026 | H9: =IF(A9="","",IF(B9="","EKSİK","TAM"))
A10: sgk_senaryoIyi | B10: 0.9 | C10: çarpan | D10: İyimser matrah çarpanı | E10: Model varsayımı | F10: 01.01.2025 | G10: 11.08.2026 | H10: =IF(A10="","",IF(B10="","EKSİK","TAM"))
A11: sgk_senaryoKotu | B11: 1.1 | C11: çarpan | D11: Kötümser matrah çarpanı | E11: Model varsayımı | F11: 01.01.2025 | G11: 11.08.2026 | H11: =IF(A11="","",IF(B11="","EKSİK","TAM"))
A12: sgk_oranArtisPuan | B12: 0.01 | C12: oran | D12: M-SEN +1 puan | E12: Senaryo motoru | F12: 01.01.2025 | G12: 11.08.2026 | H12: =IF(A12="","",IF(B12="","EKSİK","TAM"))
A13: sgk_tahminAlt | B13: 0.85 | C13: çarpan | D13: Tahmin alt bant | E13: Model varsayımı | F13: 01.01.2025 | G13: 11.08.2026 | H13: =IF(A13="","",IF(B13="","EKSİK","TAM"))
A14: sgk_tahminUst | B14: 1.15 | C14: çarpan | D14: Tahmin üst bant | E14: Model varsayımı | F14: 01.01.2025 | G14: 11.08.2026 | H14: =IF(A14="","",IF(B14="","EKSİK","TAM"))
A15: sgk_tornadoMatrah | B15: 1.05 | C15: çarpan | D15: Tornado matrah şoku | E15: Model varsayımı | F15: 01.01.2025 | G15: 11.08.2026 | H15: =IF(A15="","",IF(B15="","EKSİK","TAM"))
A16: sgk_tornadoMevcut | B16: 0.95 | C16: çarpan | D16: Tornado mevcut şoku | E16: Model varsayımı | F16: 01.01.2025 | G16: 11.08.2026 | H16: =IF(A16="","",IF(B16="","EKSİK","TAM"))
A17: sgk_isverenOran | B17: 0.205 | C17: oran | D17: İşveren SGK payı (engelli) | E17: 5510 s.K. | F17: 01.01.2025 | G17: 11.08.2026 | H17: =IF(A17="","",IF(B17="","EKSİK","TAM"))
A18: sgk_yuzdelikOran | B18: 0.9 | C18: oran | D18: Yüzdelik P90 | E18: İstatistik | F18: 01.01.2025 | G18: 11.08.2026 | H18: =IF(A18="","",IF(B18="","EKSİK","TAM"))
A19: sgk_parmakIzi | B19: 1c2390061c8d81f9 | C19: metin | D19: Dosya parmak izi etiketi | E19: Üretim | F19: 01.01.2025 | G19: 11.08.2026 | H19: =IF(A19="","",IF(B19="","EKSİK","TAM"))
A20: dosya_surumu | B20: 1.0.0 | C20: metin | D20: Ürün sürümü | E20: ExcelArşiv | F20: 01.01.2025 | G20: 11.08.2026 | H20: =IF(A20="","",IF(B20="","EKSİK","TAM"))
A21: sgk_girisBeklenen | B21: 11 | C21: adet | D21: Zorunlu giriş alanı sayısı | E21: Ürün mimarisi | F21: 01.01.2025 | G21: 11.08.2026 | H21: =IF(A21="","",IF(B21="","EKSİK","TAM"))
A22: sgk_riskDusuk | B22: 15 | C22: puan | D22: Düşük risk skoru | E22: İç politika | F22: 01.01.2025 | G22: 11.08.2026 | H22: =IF(A22="","",IF(B22="","EKSİK","TAM"))
A23: sgk_riskOrta | B23: 55 | C23: puan | D23: Orta risk skoru | E23: İç politika | F23: 01.01.2025 | G23: 11.08.2026 | H23: =IF(A23="","",IF(B23="","EKSİK","TAM"))
A24: sgk_riskYuksek | B24: 85 | C24: puan | D24: Yüksek risk skoru | E24: İç politika | F24: 01.01.2025 | G24: 11.08.2026 | H24: =IF(A24="","",IF(B24="","EKSİK","TAM"))
A25: sgk_riskEsikOran | B25: 0.5 | C25: oran | D25: Yüksek risk kaçırılan/potansiyel | E25: İç politika | F25: 01.01.2025 | G25: 11.08.2026 | H25: =IF(A25="","",IF(B25="","EKSİK","TAM"))
A26: sgk_yilTaban | B26: 2024 | C26: yıl | D26: CHOOSE yıl tabanı (hesapYili−taban) | E26: Ürün mimarisi | F26: 01.01.2025 | G26: 11.08.2026 | H26: =IF(A26="","",IF(B26="","EKSİK","TAM"))
A27: sgk_yuvarMax | B27: 10 | C27: adet | D27: ROUND basamak tavanı | E27: Ürün mimarisi | F27: 01.01.2025 | G27: 11.08.2026 | H27: =IF(A27="","",IF(B27="","EKSİK","TAM"))
A28: vaka_matrah_1 | B28: 300000 | C28: TL | D28: Vaka1 5 puan matrah | E28: Tebliğ örneği | F28: 01.01.2025 | G28: 11.08.2026 | H28: =IF(A28="","",IF(B28="","EKSİK","TAM"))
A29: vaka_matrah_2 | B29: 100000 | C29: TL | D29: Vaka2 ilave matrah | E29: Tebliğ örneği | F29: 01.01.2025 | G29: 11.08.2026 | H29: =IF(A29="","",IF(B29="","EKSİK","TAM"))
A30: vaka_tavan | B30: 150000 | C30: TL | D30: Vaka4 tavan | E30: Tebliğ örneği | F30: 01.01.2025 | G30: 11.08.2026 | H30: =IF(A30="","",IF(B30="","EKSİK","TAM"))
B32: Parametre satırları yukarıda; ad tanımları B kolonuna bağlı.
B34: Sürüm 1.0.0 | Şifre koruması: 1234 (formül alanları)

Sheet KILAVUZ
A1: KILAVUZ — SGK Prim Teşvikleri Optimizasyon Motoru
A3: Karar kuralları
A5: • VERİ YOK — giriş tablosu boşsa hesap yapılmaz.
A6: • UYGUN / TEŞVİK TAM — mevcut teşvik ≥ potansiyel (kaçırılan = 0).
A7: • İNCELE / FIRSAT — kaçırılan > 0 ama eşik altında; gözden geçirin.
A8: • OPTİMİZE ET / DİKKAT — kaçırılan ≥ eşik; bordro teşvik kodlarını optimize edin.
A10: Belirsizlik beyanları (M05)
A11: Bu nokta mevzuatta tartışmalıdır; dosya yorum A ve yorum B sonucunu yan yana gösterir: tesvik_birikim_sirasi
A13: Yorum A | B13: Uygun teşvik kalemleri birikimli toplanır (5 puan + ilave + kadın/genç + engelli). Bu nokta mevzuatta tartışmalıdır; sonuç yorum B ile yan yana okunmalıdır.
A14: Yorum B | B14: Aynı dönemde yalnızca en yüksek tek teşvik kalemi alınır. Dosya her iki yorumun sonucunu MOTOR'da üretir.
A16: Kullanım sırası
A17: GIRDI → KURALLAR (gerekirse) → MOTOR (inceleme) → SENARYO → VAKALAR → PANO → KANIT_RAPORU → AYARLAR.
A19: Sürüm 1.0.0 | Lisans: Tek kullanıcı | ExcelArşiv
