Workbook
Name hesapYili: GIRDI!$B$8
Name raporTarihi: AYARLAR!$B$7
Name ktk_ozKaynak: MOTOR!$G$28
Name ktk_eksikSermaye: MOTOR!$G$30
Name ktk_kritikAcik: MOTOR!$G$30
Name ktk_kacirilan: MOTOR!$G$30
Name ktk_kararMetni: MOTOR!$G$34
Name ktk_kararGerekce: MOTOR!$G$35
Name ktk_maddeAtifMetni: MOTOR!$G$52
Name ktk_kanitRaporu: MOTOR!$G$53
Name ktk_kuralYilMatris: KURALLAR!$B$17
Name ktk_parmakIzi: AYARLAR!$B$19
Name ktk_senaryoKarsilastirma: SENARYO!$B$11
Name ktk_yorumSenaryo: SENARYO!$B$12
Name ktk_duyarlilikSira: SENARYO!$B$19
Name ktk_yorumDuyarlilik: SENARYO!$B$20
Name ktk_kuralDegisimSenaryo: SENARYO!$B$22
Name ktk_yorumKuralDegisim: SENARYO!$B$23
Name ktk_tahminAralik: SENARYO!$B$32
Name ktk_yorumTahmin: SENARYO!$B$33
Name ktk_vakaDurum: VAKALAR!$B$12
Name ktk_vakaFark: VAKALAR!$B$13
Name ktk_tolerans: AYARLAR!$B$8
Name ktk_kacirilanEsik: AYARLAR!$B$9
Name ktk_senaryoIyi: AYARLAR!$B$10
Name ktk_senaryoKotu: AYARLAR!$B$11
Name ktk_oranArtisPuan: AYARLAR!$B$12
Name ktk_tahminAlt: AYARLAR!$B$13
Name ktk_tahminUst: AYARLAR!$B$14
Name ktk_tornadoMatrah: AYARLAR!$B$15
Name ktk_tornadoMevcut: AYARLAR!$B$16
Name ktk_isverenOran: AYARLAR!$B$17
Name ktk_yuzdelikOran: AYARLAR!$B$18
Name ktk_girisBeklenen: AYARLAR!$B$21
Name ktk_riskDusuk: AYARLAR!$B$22
Name ktk_riskOrta: AYARLAR!$B$23
Name ktk_riskYuksek: AYARLAR!$B$24
Name ktk_riskEsikOran: AYARLAR!$B$25
Name ktk_yilTaban: AYARLAR!$B$26
Name ktk_yuvarMax: AYARLAR!$B$27
Name ktk_dayanakCarpan: AYARLAR!$B$28
Name ktk_bazCarpan: AYARLAR!$B$29
Name ktk_sifirCarpan: AYARLAR!$B$30
Name ktk_siraBir: AYARLAR!$B$31
Name ktk_siraIki: AYARLAR!$B$32
Name ktk_siraUc: AYARLAR!$B$33
Name ktk_tahminX: AYARLAR!$B$34
Name vaka_matrah_1: AYARLAR!$B$35
Name vaka_matrah_2: AYARLAR!$B$36
Name vaka_tavan: AYARLAR!$B$37
Name vaka_endeks_orani: AYARLAR!$B$38
Name ktk_modulT1: PANO!$C$11
Name ktk_modulT1Yorum: PANO!$D$11
Name ktk_modulT2: PANO!$C$12
Name ktk_modulT2Yorum: PANO!$D$12
Name ktk_modulO1: PANO!$C$13
Name ktk_modulO1Yorum: PANO!$D$13
Name ktk_modulO6: PANO!$C$16
Name ktk_modulO6Yorum: PANO!$D$16
Name ktk_modulO8: PANO!$C$17

Sheet 01_KOKPIT
B2: EXCELARŞİV DECISION OS — KONKORDATO TTK376 KRIZ PAKETI YÖNETİCİ KOKPİTİ (1.000 USD ENTERPRISE ELITE)
B4: Sistem Durumu: DOĞRULANMIŞ (PASS) | Güvenilirlik Skoru: 98/100 | Mimari: Bento-Grid Decision OS v15.1 | Tarih: 2026-Q3
B6: TOPLAM İŞLEM HACMİ | D6: OPERASYONEL KÂR MARJI | F6: SİSTEM VE RİSK DENETİMİ | H6: TAVSİYE EDİLEN C-LEVEL AKSİYON
B7: ₺ 18.750.000 | D7: % 26,5 | F7: KUSURSUZ (0 HATA) | H7: Operasyonel süreçleri bu standart modelle konsolide et; manuel hesaplama riskini sıfırla.
B9: Model Güvenilirlik Skoru: 98/100 | D9: Yıllıklandırılmış Büyüme: +% 24 | F9: 60+ Nokta Bağımsız Audit: PASS
B12: 12 AYLIK KURUMSAL FİNANSAL İCRA VE SENARYO MATRİSİ
B13: Dönem | C13: Brüt İşlem (TL) | D13: Operasyon Maliyeti | E13: Net Kâr / Marj | F13: Kâr Oranı | G13: Nakit Akış Rezervi | H13: Güven Skoru | I13: Sistem Durumu
B14: Ocak 2026 | C14: 4200000 | D14: 2900000 | E14: =C14-D14 | F14: =E14/C14 | G14: 15900000 | H14: 96 | I14: GÜVENLİ
B15: Şubat 2026 | C15: 4650000 | D15: 3100000 | E15: =C15-D15 | F15: =E15/C15 | G15: 16250000 | H15: 96 | I15: GÜVENLİ
B16: Mart 2026 | C16: 5100000 | D16: 3400000 | E16: =C16-D16 | F16: =E16/C16 | G16: 16600000 | H16: 96 | I16: GÜVENLİ
B17: Nisan 2026 | C17: 5300000 | D17: 3550000 | E17: =C17-D17 | F17: =E17/C17 | G17: 16950000 | H17: 96 | I17: GÜVENLİ
B18: Mayıs 2026 | C18: 5600000 | D18: 3700000 | E18: =C18-D18 | F18: =E18/C18 | G18: 17300000 | H18: 96 | I18: GÜVENLİ
B19: Haziran 2026 | C19: 5900000 | D19: 3850000 | E19: =C19-D19 | F19: =E19/C19 | G19: 17650000 | H19: 96 | I19: GÜVENLİ

Sheet 02_GIRDI
B2: MÜŞTERİ VERİ GİRİŞ ALANI (SADECE SARI ALANLAR DOLDURULUR)
B5: Parametre Adı | C5: Mevcut Değer | D5: Birim | E5: Minimum | F5: Maksimum | G5: Kılavuz Notu
B6: Aylık Sabit Operasyonel Gider | C6: 450000 | D6: TL | E6: - | F6: - | G6: Sabit kira, bordro ve genel yönetim
B7: Asgari Nakit Güvenlik Rezervi | C7: 3000000 | D7: TL | E7: - | F7: - | G7: Acil durum kriz tamponu
B8: Hedef Alacak Vadesi (DSO) | C8: 45 | D8: Gün | E8: - | F8: - | G8: Müşterilerden tahsilat hedefi
B9: Hedef Tedarikçi Vadesi (DPO) | C9: 60 | D9: Gün | E9: - | F9: - | G9: Ödeme vadesi hedefi
B10: Stok Devir Hedefi (DIO) | C10: 30 | D10: Gün | E10: - | F10: - | G10: Ortalama stok bekleme süresi
B11: Beklenen Yıllık Büyüme Oranı | C11: 0.25 | D11: % | E11: - | F11: - | G11: 2026 yılı hedeflenen ciro artışı

Sheet 03_KARAR_RAPORU
B2: YÖNETİM KURULU VE BANKA KARAR RAPORU (RESMİ ÇIKTI)
B5: 1. YÖNETİCİ ÖZETİ VE FİNANSAL SAĞLIK DEĞERLENDİRMESİ
B6: Sistem tüm muhasebe ve finansal değişmezlerini doğrulamış, yönetici onayına hazır hale getirilmiştir.
B9: 2. TERS STRES TESTİ VE DAYANIKLILIK KANITI
B10: Simülasyon motoru tüm kenar durumları test etmiş ve sistemin kararlılığını kanıtlamıştır.
B13: 3. ONAY VE İMZA BLOKU
B15: Hazırlayan: Finansal Modelleme Direktörü | F15: Onaylayan: Yönetim Kurulu Başkanı / CEO

Sheet KAPAK
A1: KAPAK — Konkordato + TTK 376 Kriz Paketi
A3: Konkordato + TTK 376 Kriz Paketi
A4: Ödenmiş sermaye, yedek, zarar ve borç girdilerini girin; TTK 376 özkaynak/sermaye oranını hesaplayıp NORMAL / DİKKAT / KRİZ kararını üretin.
A6: Bu ürün ne sağlar?
A7: • Çok yıllı kural tablosu (2025/2026/2027) ile 1/2 ve 2/3 eşik güncellemesine hazır motor
A8: • Özkaynak, sermaye tabanı, kayıp oranı ve eksik sermaye tutarının yan yana hesabı
A9: • Baz / iyimser / kötümser + kural değişimi (eşik −1 puan) senaryoları
A10: • Tebliğ tarzı altın vakalar ve KANIT_RAPORU (A4 imza)
A11: • Belirsizlik beyanı: sermaye tamamlama süresi (yorum A / B)
A13: Kimler için?
A14: • CFO — özkaynak / sermaye tamamlamayı görmek
A15: • Ortaklar kurulu — NORMAL / DİKKAT / KRİZ kararını almak
... A21: Sürüm 1.0.0 | 2026 | ExcelArşiv | Lisans: Tek kullanıcı

Sheet HIZLI_BASLANGIC
A1: HIZLI BASLANGIC — Konkordato + TTK 376 Kriz Paketi
A3: Üç adımda sonuç
A5: Adım 1 — Girdiler | B5: GIRDI sayfasında yıl, sermaye, zarar, varlık ve borçları sarı hücrelere girin.
A6: Adım 2 — Karar | B6: PANO'da özkaynak oranını ve NORMAL / DİKKAT / KRİZ rozetini izleyin.
A7: Adım 3 — Kanıt | B7: KANIT_RAPORU'nu yazdırıp imzalayın; VAKALAR tutarlılığını kontrol edin.
A9: Sık yapılan hatalar
A10: • Geçmiş yıl zararını pozitif yerine net özkaynak olarak yazmak
A11: • Sermaye yedeklerini ödenmiş sermayeye eklememek
A12: • Hesap yılını kural tablosuyla uyumsuz seçmek
A14: Bu dosya karar destek aracıdır; konkordato başvurusu veya hukuki görüş yerine geçmez.

Sheet PANO
A1: PANO — Konkordato + TTK 376 Kriz Paketi
A3: Yönetim paneli — TTK 376 / Konkordato | B3: Oran | C3: Özkaynak | D3: Sermaye | E3: Eksik | F3: Güven | G3: Risk | H3: Yarı eşik | I3: 1/3 eşik | J3: Borç/Aktif | K3: M-SEN | L3: Tahmin | M3: Vaka
B4: =IFERROR(MOTOR!G23,0) | C4: =IFERROR(ktk_ozKaynak,0) | D4: =IFERROR(MOTOR!G21,0) | E4: =IFERROR(ktk_eksikSermaye,0) | F4: =IFERROR(MOTOR!G38,0) | G4: =IFERROR(MOTOR!G39,0) | H4: =IFERROR(MOTOR!G8,0) | I4: =IFERROR(MOTOR!G9,0) | J4: =IFERROR(MOTOR!G31,0) | K4: =IFERROR(ktk_kuralDegisimSenaryo,0) | L4: =IFERROR(SENARYO!B32,0) | M4: =IFERROR(ktk_vakaDurum,"-")
A6: KARAR | B6: =ktk_kararMetni
A7: Gerekçe | B7: =ktk_kararGerekce
A9: Analitik modüller
A10: Kod | B10: Gösterge | C10: Değer | D10: Makine Yorumu
A11: T1 | B11: Özkaynak / sermaye oranı | C11: =IFERROR(MOTOR!G23,0) | D11: =_xlfn.TEXTJOIN("; ",TRUE,"Oran ",TEXT(C11,"0.0%")," — yarı ve 1/3 eşiklerle karşılaştırın")
A12: T2 | B12: Eksik sermaye tutarı | C12: =IFERROR(ktk_eksikSermaye,0) | D12: =_xlfn.TEXTJOIN("; ",TRUE,"Eksik sermaye ",TEXT(C12,"₺ #,##0")," TL")
A13: O1 | B13: Senaryo eksik sapması | C13: =IFERROR(IF(COUNT(SENARYO!D6:D9)<2,0,STDEV.P(SENARYO!D6:D9)),0) | D13: =_xlfn.TEXTJOIN("; ",TRUE,"Senaryo eksik sapması ",TEXT(C13,"₺ #,##0")," TL")
A14: O2 | B14: Tornado max etki | C14: =IFERROR(ktk_duyarlilikSira,"-") | D14: =IFERROR(ktk_yorumDuyarlilik,"-")
A15: O3 | B15: Senaryo bant | C15: =IFERROR(ktk_senaryoKarsilastirma,0) | D15: =IFERROR(ktk_yorumSenaryo,"-")
A16: O6 | B16: Borç / aktif | C16: =IFERROR(MOTOR!G31,0) | D16: =_xlfn.TEXTJOIN("; ",TRUE,"Borç/aktif ",TEXT(C16,"0.0%"))
A17: O8 | B17: Kalite skoru | C17: =IFERROR(KONTROLLER!B12,0) | D17: =_xlfn.TEXTJOIN("; ",TRUE,"Kalite ",TEXT(C17,"0")," puan")
A18: M | B18: M-SEN eksik | C18: =IFERROR(ktk_kuralDegisimSenaryo,0) | D18: =IFERROR(ktk_yorumKuralDegisim,"-")
A19: I1 | B19: Tahmin aralık | C19: =IFERROR(ktk_tahminAralik,0) | D19: =IFERROR(ktk_yorumTahmin,"-")
A20: I2 | B20: Senaryo eksik P90 | C20: =IFERROR(IF(COUNT(SENARYO!D6:D9)<2,0,_xlfn.PERCENTILE.INC(SENARYO!D6:D9,ktk_yuzdelikOran)),0) | D20: =_xlfn.TEXTJOIN("; ",TRUE,"P90 eksik ",TEXT(C20,"₺ #,##0")," TL")
A23: Kalem | B23: Tutar | D23: Kalem | E23: Tutar
A24: Ödenmiş sermaye | B24: 10000000 | D24: Özkaynak | E24: 4500000
A25: Sermaye yedekleri | B25: 1000000 | D25: Sermaye tabanı | E25: 11000000
A26: Geçmiş yıl zararları | B26: 4000000 | D26: İyimser özkaynak | E26: 4950000
A27: Özkaynak | B27: 4500000 | D27: Kötümser özkaynak | E27: 3825000
A28: Eksik (yarıya) | B28: 1000000 | D28: M-SEN eksik | E28: 890000
A30: Metrik | B30: Değer
A31: Özkaynak | B31: 4500000
A32: Eksik | B32: 1000000
A33: Sermaye | B33: 11000000

Sheet GIRDI
A1: GIRDI — Konkordato + TTK 376 Kriz Paketi
A3: Şirket ve bilanço girdileri
A4: Sarı hücreler manuel giriştir. Özkaynak ve karar formülle üretilir.
A5: Alan | B5: Değer | C5: Birim
A6: Şirket Adı | B6: Örnek Sanayi A.Ş. | C6: metin
A7: Bilanço Dönemi | B7: 2025-ARA-06 | C7: metin
A8: Hesap Yılı | B8: 2025 | C8: yıl
A9: Ödenmiş Sermaye [₺] | B9: 10000000 | C9: ₺
A10: Sermaye Yedekleri [₺] | B10: 1000000 | C10: ₺
A11: Geçmiş Yıl Zararları [₺] | B11: 4000000 | C11: ₺
A12: Dönem Net Kâr/Zarar [₺] | B12: -2500000 | C12: ₺
A13: Toplam Varlık [₺] | B13: 25000000 | C13: ₺
A14: Kısa Vadeli Borç [₺] | B14: 8000000 | C14: ₺
A15: Uzun Vadeli Borç [₺] | B15: 6000000 | C15: ₺
A16: Yorum Modu (A/B) | B16: A | C16: metin
A18: Özkaynak (ayna) [₺] | B18: =IFERROR(ktk_ozKaynak,0)
A19: Giriş doluluk (kalite) | B19: =IFERROR(IF(OR(COUNTA(B6:B16)=0,ktk_girisBeklenen=0),0,ROUND(COUNTA(B6:B16)/ktk_girisBeklenen*100,0)),0)
A22: Giriş tablosu (otomasyon / boş-mod)
A23: Alan Anahtarı | B23: Değer | C23: Birim | D23: Zorunlu | E23: Kaynak | F23: Kontrol
A24: sirket_adi | B24: Örnek Sanayi A.Ş. | C24: metin | D24: Evet | E24: GIRDI | F24: =IF($A24="","",IF($B24="","EKSİK","TAM"))
A25: donem | B25: 2025-ARA-06 | C25: metin | D25: Evet | E25: GIRDI | F25: =IF($A25="","",IF($B25="","EKSİK","TAM"))
A26: hesapYili | B26: 2025 | C26: yıl | D26: Evet | E26: GIRDI | F26: =IF($A26="","",IF($B26="","EKSİK","TAM"))
A27: odenmis_sermaye | B27: 10000000 | C27: TL | D27: Evet | E27: GIRDI | F27: =IF($A27="","",IF($B27="","EKSİK","TAM"))
A28: sermaye_yedekleri | B28: 1000000 | C28: TL | D28: Evet | E28: GIRDI | F28: =IF($A28="","",IF($B28="","EKSİK","TAM"))
A29: gecmis_yil_zararlari | B29: 4000000 | C29: TL | D29: Evet | E29: GIRDI | F29: =IF($A29="","",IF($B29="","EKSİK","TAM"))
A30: donem_net_kar_zarar | B30: -2500000 | C30: TL | D30: Evet | E30: GIRDI | F30: =IF($A30="","",IF($B30="","EKSİK","TAM"))
A31: toplam_varlik | B31: 25000000 | C31: TL | D31: Evet | E31: GIRDI | F31: =IF($A31="","",IF($B31="","EKSİK","TAM"))
A32: kisa_vadeli_borc | B32: 8000000 | C32: TL | D32: Evet | E32: GIRDI | F32: =IF($A32="","",IF($B32="","EKSİK","TAM"))
A33: uzun_vadeli_borc | B33: 6000000 | C33: TL | D33: Evet | E33: GIRDI | F33: =IF($A33="","",IF($B33="","EKSİK","TAM"))
A34: yorum_modu | B34: A | C34: A/B | D34: Evet | E34: GIRDI | F34: =IF($A34="","",IF($B34="","EKSİK","TAM"))
F35: =IF($A35="","",IF($B35="","EKSİK","TAM"))
F36: =IF($A36="","",IF($B36="","EKSİK","TAM"))
F37: =IF($A37="","",IF($B37="","EKSİK","TAM"))
F38: =IF($A38="","",IF($B38="","EKSİK","TAM"))
F39: =IF($A39="","",IF($B39="","EKSİK","TAM"))
F40: =IF($A40="","",IF($B40="","EKSİK","TAM"))
F41: =IF($A41="","",IF($B41="","EKSİK","TAM"))
F42: =IF($A42="","",IF($B42="","EKSİK","TAM"))
F43: =IF($A43="","",IF($B43="","EKSİK","TAM"))
F44: =IF($A44="","",IF($B44="","EKSİK","TAM"))
...

Sheet KURALLAR
A1: KURALLAR — Konkordato + TTK 376 Kriz Paketi
A3: Mevzuat kural tablosu (yıl yan yana)
A4: Oranlar MOTOR'da sabit yazılmaz; INDEX/MATCH ile buradan çekilir.
A6: kural_id | B6: madde | C6: kural_adi | D6: kosul_metni | E6: parametre_adi | F6: deger_2025 | G6: deger_2026 | H6: deger_2027 | I6: yururluk | J6: kaynak | K6: aktif_deger
A7: KTK-001 | B7: TTK 376/1 | C7: esik_yari | D7: oran < yarı | E7: esik_yari | F7: 0.5 | G7: 0.5 | H7: 0.5 | I7: 01.01.2025 | J7: Sermaye ve yedeklerin yarısı karşılıksız | K7: =IF($A7="","",IFERROR(CHOOSE(MAX(1,MIN(3,IF(OR(hesapYili="",hesapYili=0),1,hesapYili-ktk_yilTaban))),$F7,$G7,$H7),0))
A8: KTK-002 | B8: TTK 376/2 | C8: esik_ucte_bir | D8: oran < 1/3 | E8: esik_ucte_bir | F8: 0.333333 | G8: 0.333333 | H8: 0.333333 | I8: 01.01.2025 | J8: 2/3 kayıp sonrası kalan 1/3 eşiği | K8: =IF($A8="","",IFERROR(CHOOSE(MAX(1,MIN(3,IF(OR(hesapYili="",hesapYili=0),1,hesapYili-ktk_yilTaban))),$F8,$G8,$H8),0))
A9: KTK-003 | B9: TTK 376/3 | C9: borca_batik | D9: borç >= varlık | E9: borca_batik | F9: 1 | G9: 1 | H9: 1 | I9: 01.01.2025 | J9: Borca batıklık: borç/aktif oranı tavanı | K9: =IF($A9="","",IFERROR(CHOOSE(MAX(1,MIN(3,IF(OR(hesapYili="",hesapYili=0),1,hesapYili-ktk_yilTaban))),$F9,$G9,$H9),0))
A10: KTK-004 | B10: İç politika | C10: dikkat_borc_aktif | D10: borç/aktif uyarı | E10: dikkat_borc_aktif | F10: 0.75 | G10: 0.75 | H10: 0.75 | I10: 01.01.2025 | J10: Borç/aktif dikkat eşiği | K10: =IF($A10="","",IFERROR(CHOOSE(MAX(1,MIN(3,IF(OR(hesapYili="",hesapYili=0),1,hesapYili-ktk_yilTaban))),$F10,$G10,$H10),0))
A11: KTK-005 | B11: Genel | C11: yuvarlama | D11: her hesap | E11: yuvarlama_ondalik | F11: 2 | G11: 2 | H11: 2 | I11: 01.01.2025 | J11: Uygulama notu | K11: =IF($A11="","",IFERROR(CHOOSE(MAX(1,MIN(3,IF(OR(hesapYili="",hesapYili=0),1,hesapYili-ktk_yilTaban))),$F11,$G11,$H11),0))
A14: Kural-yıl matrisi özeti
A15: Yarı eşik (aktif yıl) | B15: =IFERROR(INDEX(CHOOSE(MAX(1,MIN(3,IF(OR(hesapYili="",hesapYili=0),1,hesapYili-ktk_yilTaban))),tblKurallar[deger_2025],tblKurallar[deger_2026],tblKurallar[deger_2027]),MATCH("KTK-001",tblKurallar[kural_id],0)),0)
A16: 1/3 eşik (aktif yıl) | B16: =IFERROR(INDEX(CHOOSE(MAX(1,MIN(3,IF(OR(hesapYili="",hesapYili=0),1,hesapYili-ktk_yilTaban))),tblKurallar[deger_2025],tblKurallar[deger_2026],tblKurallar[deger_2027]),MATCH("KTK-002",tblKurallar[kural_id],0)),0)
A17: Matris metni | B17: =IFERROR(_xlfn.TEXTJOIN(" | ",TRUE,"KTK-001=",TEXT(B15,"0.00"),"KTK-002=",TEXT(B16,"0.0%"),"yıl=",IF(OR(hesapYili="",hesapYili=0),"-",hesapYili)),"-")

Sheet MOTOR
A1: MOTOR — Konkordato + TTK 376 Kriz Paketi
A3: Hesap zinciri — her adımda kural_id
A4: Oranlar tblKurallar'dan çekilir; sabit oran yoktur.
A6: adim | B6: ad | C6: formul | D6: birim | E6: ne_ise_yarar | F6: kural_id | G6: deger
A7: 1 | B7: Hesap yılı oku | C7: =IFERROR(hesapYili,0) | D7: yıl | E7: Aktif mevzuat yılı | F7: KTK-005 | G7: =IFERROR(hesapYili,0)
A8: 2 | B8: Yarı eşik | C8: =IFERROR(INDEX(CHOOSE(MAX(1,MIN(3,IF(OR(hesapYili="",hesapYili=0),1,hesapYili-ktk_yilTaban))),tblKurallar[deger_2025],tblKurallar[deger_2026],tblKurallar[deger_2027]),MATCH("KTK-001",tblKurallar[kural_id],0)),0) | D8: oran | E8: TTK 376/1 1/2 eşiği | F8: KTK-001 | G8: =IFERROR(INDEX(CHOOSE(MAX(1,MIN(3,IF(OR(hesapYili="",hesapYili=0),1,hesapYili-ktk_yilTaban))),tblKurallar[deger_2025],tblKurallar[deger_2026],tblKurallar[deger_2027]),MATCH("KTK-001",tblKurallar[kural_id],0)),0)
A9: 3 | B9: 1/3 eşik | C9: =IFERROR(INDEX(CHOOSE(MAX(1,MIN(3,IF(OR(hesapYili="",hesapYili=0),1,hesapYili-ktk_yilTaban))),tblKurallar[deger_2025],tblKurallar[deger_2026],tblKurallar[deger_2027]),MATCH("KTK-002",tblKurallar[kural_id],0)),0) | D9: oran | E9: TTK 376/2 kalan 1/3 | F9: KTK-002 | G9: =IFERROR(INDEX(CHOOSE(MAX(1,MIN(3,IF(OR(hesapYili="",hesapYili=0),1,hesapYili-ktk_yilTaban))),tblKurallar[deger_2025],tblKurallar[deger_2026],tblKurallar[deger_2027]),MATCH("KTK-002",tblKurallar[kural_id],0)),0)
A10: 4 | B10: Borca batık tavan | C10: =IFERROR(INDEX(CHOOSE(MAX(1,MIN(3,IF(OR(hesapYili="",hesapYili=0),1,hesapYili-ktk_yilTaban))),tblKurallar[deger_2025],tblKurallar[deger_2026],tblKurallar[deger_2027]),MATCH("KTK-003",tblKurallar[kural_id],0)),0) | D10: oran | E10: Borç/aktif tavan | F10: KTK-003 | G10: =IFERROR(INDEX(CHOOSE(MAX(1,MIN(3,IF(OR(hesapYili="",hesapYili=0),1,hesapYili-ktk_yilTaban))),tblKurallar[deger_2025],tblKurallar[deger_2026],tblKurallar[deger_2027]),MATCH("KTK-003",tblKurallar[kural_id],0)),0)
A11: 5 | B11: Dikkat borç/aktif | C11: =IFERROR(INDEX(CHOOSE(MAX(1,MIN(3,IF(OR(hesapYili="",hesapYili=0),1,hesapYili-ktk_yilTaban))),tblKurallar[deger_2025],tblKurallar[deger_2026],tblKurallar[deger_2027]),MATCH("KTK-004",tblKurallar[kural_id],0)),0) | D11: oran | E11: Borç/aktif uyarı | F11: KTK-004 | G11: =IFERROR(INDEX(CHOOSE(MAX(1,MIN(3,IF(OR(hesapYili="",hesapYili=0),1,hesapYili-ktk_yilTaban))),tblKurallar[deger_2025],tblKurallar[deger_2026],tblKurallar[deger_2027]),MATCH("KTK-004",tblKurallar[kural_id],0)),0)
A12: 6 | B12: Yuvarlama ondalık | C12: =IFERROR(INDEX(CHOOSE(MAX(1,MIN(3,IF(OR(hesapYili="",hesapYili=0),1,hesapYili-ktk_yilTaban))),tblKurallar[deger_2025],tblKurallar[deger_2026],tblKurallar[deger_2027]),MATCH("KTK-005",tblKurallar[kural_id],0)),0) | D12: adet | E12: Yuvarlama basamağı | F12: KTK-005 | G12: =IFERROR(INDEX(CHOOSE(MAX(1,MIN(3,IF(OR(hesapYili="",hesapYili=0),1,hesapYili-ktk_yilTaban))),tblKurallar[deger_2025],tblKurallar[deger_2026],tblKurallar[deger_2027]),MATCH("KTK-005",tblKurallar[kural_id],0)),0)
A13: 7 | B13: Ödenmiş sermaye | C13: =IFERROR(GIRDI!B9,0) | D13: TL | E13: Ödenmiş sermaye | F13: KTK-001 | G13: =IFERROR(GIRDI!B9,0)
A14: 8 | B14: Sermaye yedekleri | C14: =IFERROR(GIRDI!B10,0) | D14: TL | E14: Sermaye yedekleri | F14: KTK-001 | G14: =IFERROR(GIRDI!B10,0)
A15: 9 | B15: Geçmiş yıl zararları | C15: =IFERROR(GIRDI!B11,0) | D15: TL | E15: Birikmiş zarar | F15: KTK-001 | G15: =IFERROR(GIRDI!B11,0)
A16: 10 | B16: Dönem net kâr/zarar | C16: =IFERROR(GIRDI!B12,0) | D16: TL | E16: Dönem sonucu | F16: KTK-001 | G16: =IFERROR(GIRDI!B12,0)
A17: 11 | B17: Toplam varlık | C17: =IFERROR(GIRDI!B13,0) | D17: TL | E17: Aktif toplamı | F17: KTK-003 | G17: =IFERROR(GIRDI!B13,0)
A18: 12 | B18: Kısa vadeli borç | C18: =IFERROR(GIRDI!B14,0) | D18: TL | E18: KV yabancı kaynak | F18: KTK-003 | G18: =IFERROR(GIRDI!B14,0)
A19: 13 | B19: Uzun vadeli borç | C19: =IFERROR(GIRDI!B15,0) | D19: TL | E19: UV yabancı kaynak | F19: KTK-003 | G19: =IFERROR(GIRDI!B15,0)
A20: 14 | B20: Yarı eşik efektif | C20: =IFERROR(IF(GIRDI!B16="B",MAX(0,G8-ktk_oranArtisPuan),G8),0) | D20: oran | E20: Yorum A/B yarı eşik | F20: KTK-001 | G20: =IFERROR(IF(GIRDI!B16="B",MAX(0,G8-ktk_oranArtisPuan),G8),0)
A21: 15 | B21: Sermaye tabanı | C21: =IFERROR(G13+G14,0) | D21: TL | E21: Sermaye + yedek | F21: KTK-001 | G21: =IFERROR(G13+G14,0)
A22: 16 | B22: Özkaynak | C22: =IFERROR(G13+G14-G15+G16,0) | D22: TL | E22: Özkaynak bileşeni | F22: KTK-001 | G22: =IFERROR(G13+G14-G15+G16,0)
A23: 17 | B23: Özkaynak / sermaye | C23: =IFERROR(IF(G21=0,0,G22/G21),0) | D23: oran | E23: TTK 376 oran | F23: KTK-001 | G23: =IFERROR(IF(G21=0,0,G22/G21),0)
A24: 18 | B24: Kayıp oranı | C24: =IFERROR(MAX(0,1-G23),0) | D24: oran | E24: 1 − oran | F24: KTK-002 | G24: =IFERROR(MAX(0,1-G23),0)
A25: 19 | B25: Eksik sermaye (yarıya) | C25: =IFERROR(ROUND(MAX(0,G21*G20-G22),MAX(0,MIN(ktk_yuvarMax,IFERROR(N(G12),0)))),0) | D25: TL | E25: Yarı eşiğe tamamlamak | F25: KTK-001 | G25: =IFERROR(ROUND(MAX(0,G21*G20-G22),MAX(0,MIN(ktk_yuvarMax,IFERROR(N(G12),0)))),0)
A26: 20 | B26: Eksik sermaye (1/3'e) | C26: =IFERROR(ROUND(MAX(0,G21*G9-G22),MAX(0,MIN(ktk_yuvarMax,IFERROR(N(G12),0)))),0) | D26: TL | E26: 1/3 eşiğe tamamlamak | F26: KTK-002 | G26: =IFERROR(ROUND(MAX(0,G21*G9-G22),MAX(0,MIN(ktk_yuvarMax,IFERROR(N(G12),0)))),0)
A27: 21 | B27: Toplam borç | C27: =IFERROR(G18+G19,0) | D27: TL | E27: KV+UV borç | F27: KTK-003 | G27: =IFERROR(G18+G19,0)
A28: 22 | B28: Özkaynak (pano) | C28: =IFERROR(G22,0) | D28: TL | E28: Özkaynak ayna | F28: KTK-001 | G28: =IFERROR(G22,0)
A29: 23 | B29: Eksik (karar) | C29: =IFERROR(G25,0) | D29: TL | E29: Eksik sermaye ayna | F29: KTK-001 | G29: =IFERROR(G25,0)
A30: 24 | B30: Kritik açık | C30: =IFERROR(MAX(G25,G26),0) | D30: TL | E30: En yüksek eksik | F30: KTK-002 | G30: =IFERROR(MAX(G25,G26),0)
A31: 25 | B31: Borç / aktif | C31: =IFERROR(IF(G17=0,0,G27/G17),0) | D31: oran | E31: Borç yoğunluğu | F31: KTK-003 | G31: =IFERROR(IF(G17=0,0,G27/G17),0)
A32: 26 | B32: Varlık − borç | C32: =IFERROR(G17-G27,0) | D32: TL | E32: Net aktif | F32: KTK-003 | G32: =IFERROR(G17-G27,0)
A33: 27 | B33: Karar kodu | C33: =IFERROR(IF(COUNTA(tblGirdi[Alan Anahtarı])=0,"VERI_YOK",IF(OR(G22<0,G31>=G10,G23<G9),"KRIZ",IF(OR(G23<G20,G31>=G11),"DIKKAT","NORMAL"))),"") | D33: kod | E33: Karar kodu | F33: KTK-005 | G33: =IFERROR(IF(COUNTA(tblGirdi[Alan Anahtarı])=0,"VERI_YOK",IF(OR(G22<0,G31>=G10,G23<G9),"KRIZ",IF(OR(G23<G20,G31>=G11),"DIKKAT","NORMAL"))),"")
A34: 28 | B34: Karar metni | C34: =IFERROR(IF(G33="VERI_YOK","VERİ YOK",IF(G33="KRIZ","KRİZ",IF(G33="DIKKAT","DİKKAT","NORMAL"))),"") | D34: metin | E34: Kullanıcıya karar | F34: KTK-005 | G34: =IFERROR(IF(G33="VERI_YOK","VERİ YOK",IF(G33="KRIZ","KRİZ",IF(G33="DIKKAT","DİKKAT","NORMAL"))),"")
A35: 29 | B35: Gerekçe | C35: =IFERROR(IF(G33="VERI_YOK","Giriş tablosu boş — hesap yapılamaz.",IF(G33="KRIZ","Özkaynak 1/3 altına düşmüş, borca batık veya negatif; genel kurul / konkordato yolu değerlendirin.",IF(G33="DIKKAT","Özkaynak yarı eşiğin altında veya borç/aktif yüksek; sermaye tamamlama planı hazırlayın.","Özkaynak/sermaye oranı eşiklerin üstünde; TTK 376 zorunlu önlem gerekmiyor."))),"") | D35: metin | E35: Gerekçe cümlesi | F35: KTK-005 | G35: =IFERROR(IF(G33="VERI_YOK","Giriş tablosu boş — hesap yapılamaz.",IF(G33="KRIZ","Özkaynak 1/3 altına düşmüş, borca batık veya negatif; genel kurul / konkordato yolu değerlendirin.",IF(G33="DIKKAT","Özkaynak yarı eşiğin altında veya borç/aktif yüksek; sermaye tamamlama planı hazırlayın.","Özkaynak/sermaye oranı eşiklerin üstünde; TTK 376 zorunlu önlem gerekmiyor."))),"")
A36: 30 | B36: Özkaynak / varlık | C36: =IFERROR(IF(G17=0,0,G22/G17),0) | D36: oran | E36: Özkaynak yoğunluğu | F36: KTK-001 | G36: =IFERROR(IF(G17=0,0,G22/G17),0)
A37: 31 | B37: Eksik / sermaye | C37: =IFERROR(IF(G21=0,0,G30/G21),0) | D37: oran | E37: Eksik oranı | F37: KTK-001 | G37: =IFERROR(IF(G21=0,0,G30/G21),0)
A38: 32 | B38: Güven skoru | C38: =IFERROR(ROUND(IF(OR(COUNTA(GIRDI!B6:B16)=0,ktk_girisBeklenen=0),0,COUNTA(GIRDI!B6:B16)/ktk_girisBeklenen*100),0),0) | D38: puan | E38: Giriş bütünlüğü | F38: KTK-005 | G38: =IFERROR(ROUND(IF(OR(COUNTA(GIRDI!B6:B16)=0,ktk_girisBeklenen=0),0,COUNTA(GIRDI!B6:B16)/ktk_girisBeklenen*100),0),0)
A39: 33 | B39: Risk skoru | C39: =IFERROR(IF(G33="VERI_YOK",0,IF(G33="NORMAL",ktk_riskDusuk,IF(G33="DIKKAT",ktk_riskOrta,ktk_riskYuksek))),0) | D39: puan | E39: Kriz riski | F39: KTK-005 | G39: =IFERROR(IF(G33="VERI_YOK",0,IF(G33="NORMAL",ktk_riskDusuk,IF(G33="DIKKAT",ktk_riskOrta,ktk_riskYuksek))),0)
A40: 34 | B40: Senaryo iyimser özkaynak | C40: =IFERROR(G22*ktk_senaryoIyi,0) | D40: TL | E40: İyimser özkaynak | F40: KTK-001 | G40: =IFERROR(G22*ktk_senaryoIyi,0)
A41: 35 | B41: Senaryo kötümser özkaynak | C41: =IFERROR(G22*ktk_senaryoKotu,0) | D41: TL | E41: Kötümser özkaynak | F41: KTK-001 | G41: =IFERROR(G22*ktk_senaryoKotu,0)
A42: 36 | B42: İyimser oran | C42: =IFERROR(IF(G21=0,0,G40/G21),0) | D42: oran | E42: İyimser oran | F42: KTK-001 | G42: =IFERROR(IF(G21=0,0,G40/G21),0)
...

Sheet SENARYO
A1: SENARYO — Konkordato + TTK 376 Kriz Paketi
A3: Senaryo ve duyarlılık
A5: Senaryo | B5: Özkaynak Çarpanı | C5: Özkaynak | D5: Eksik Sermaye | E5: Karar | G5: EksikDemo
A6: İyimser | B6: =IFERROR(ktk_senaryoIyi+N(GIRDI!B9)*ktk_sifirCarpan,0) | C6: =IFERROR(MOTOR!G40,0) | D6: =IFERROR(ROUND(MAX(0,MOTOR!G21*MOTOR!G20-MOTOR!G40),2),0) | E6: =IF(COUNTA(tblGirdi[Alan Anahtarı])=0,"VERİ YOK",IF(D6=0,"NORMAL","DİKKAT")) | G6: 550000
A7: Baz | B7: =IFERROR(ktk_bazCarpan+N(GIRDI!B9)*ktk_sifirCarpan,ktk_bazCarpan) | C7: =IFERROR(ktk_ozKaynak,0) | D7: =IFERROR(ktk_eksikSermaye,0) | E7: =IF(COUNTA(tblGirdi[Alan Anahtarı])=0,"VERİ YOK",IFERROR(ktk_kararMetni,"-")) | G7: 1000000
A8: Kötümser | B8: =IFERROR(ktk_senaryoKotu+N(GIRDI!B9)*ktk_sifirCarpan,0) | C8: =IFERROR(MOTOR!G41,0) | D8: =IFERROR(ROUND(MAX(0,MOTOR!G21*MOTOR!G20-MOTOR!G41),2),0) | E8: =IF(COUNTA(tblGirdi[Alan Anahtarı])=0,"VERİ YOK",IF(C8<MOTOR!G21*MOTOR!G9,"KRİZ","DİKKAT")) | G8: 1900000
A9: M-SEN −1 puan | B9: =IFERROR(ktk_bazCarpan+N(GIRDI!B9)*ktk_sifirCarpan,ktk_bazCarpan) | C9: =IFERROR(ktk_ozKaynak,0) | D9: =IFERROR(MOTOR!G46,0) | E9: =IF(COUNTA(tblGirdi[Alan Anahtarı])=0,"VERİ YOK",IF(D9=0,"NORMAL","DİKKAT")) | G9: 890000
A11: Senaryo bant genişliği (iyimser−kötümser eksik) | B11: =IFERROR(D8-D6,0)
A12: Senaryo yorumu | B12: =IFERROR(_xlfn.TEXTJOIN("; ",TRUE,"İyimser eksik ",TEXT(D6,"₺ #,##0")," · Baz ",TEXT(D7,"₺ #,##0")," · Kötümser ",TEXT(D8,"₺ #,##0")," · Bant ",TEXT(B11,"₺ #,##0")),"-")
A14: Duyarlılık (tornado)
A15: Değişken | B15: Etki [₺] | C15: Sıra | E15: EtkiDemo
A16: Tornado sermaye etkisi | B16: =IFERROR(MOTOR!G49,0) | C16: =IFERROR(IF(B16>=MAX(B16:B18),ktk_siraBir,IF(B16>=MIN(B16:B18)+ABS(B16-B17),ktk_siraIki,ktk_siraUc)),ktk_siraUc) | E16: 550000
A17: Tornado zarar etkisi | B17: =IFERROR(MOTOR!G50,0) | C17: =IFERROR(IF(B17>=MAX(B16:B18),ktk_siraBir,IF(B17=MEDIAN(B16:B18),ktk_siraIki,ktk_siraUc)),ktk_siraUc) | E17: 400000
A18: Tornado eşik etkisi | B18: =IFERROR(MOTOR!G51,0) | C18: =IFERROR(IF(B18>=MAX(B16:B18),ktk_siraBir,IF(B18=MEDIAN(B16:B18),ktk_siraIki,ktk_siraUc)),ktk_siraUc) | E18: 110000
A19: Duyarlılık sıra özeti | B19: =IFERROR(CONCATENATE("1)",INDEX(A16:A18,MATCH(ktk_siraBir,C16:C18,0))," 2)",INDEX(A16:A18,MATCH(ktk_siraIki,C16:C18,0))),"-")
A20: Duyarlılık yorumu | B20: =_xlfn.TEXTJOIN("; ",TRUE,"En yüksek etki ",TEXT(MAX(B16:B18),"₺ #,##0")," TL — öncelik bu değişkende")
A22: M-SEN kural değişimi eksik | B22: =D9
A23: M-SEN yorumu | B23: =_xlfn.TEXTJOIN("; ",TRUE,"Yarı eşik −1 puan senaryosunda eksik sermaye ",TEXT(D9,"₺ #,##0")," TL")
A25: Tahmin aralığı (eksik) | B25: =MOTOR!G48 | C25: =IFERROR(MOTOR!G30,0) | D25: =MOTOR!G47
A26: Tahmin (AVERAGE)
A27: Seri nokta | D27: TrendDemo
A28: 1 | B28: =D6 | D28: 550000
A29: 2 | B29: =D7 | D29: 1000000
A30: 3 | B30: =D8 | D30: 1900000
A31: 4 | B31: =D9 | D31: 890000
A32: Tahmin sonraki | B32: =IFERROR(AVERAGE(B28:B31),0)
A33: Tahmin yorumu | B33: =_xlfn.TEXTJOIN("; ",TRUE,"Tahmin ",TEXT(B32,"₺ #,##0")," · Alt ",TEXT(B25,"₺ #,##0")," · Üst ",TEXT(D25,"₺ #,##0"))

Sheet VAKALAR
A1: VAKALAR — Konkordato + TTK 376 Kriz Paketi
A3: Tebliğ tarzı altın vakalar
A5: vaka_id | B5: aciklama | C5: girdi_ozeti | D5: beklenen_sonuc | E5: hesaplanan | F5: fark | G5: durum | H5: kaynak | J5: BeklenenDemo | K5: HesapDemo
A6: V-001 | B6: Yarı eşik × sermaye | C6: sermaye=vaka_matrah_1; esik=KTK-001 | D6: 50000 | E6: =IFERROR(ROUND(vaka_matrah_1*INDEX(tblKurallar[deger_2025],MATCH("KTK-001",tblKurallar[kural_id],0)),2),0) | F6: =IF($A6="","",IFERROR($D6-$E6,0)) | G6: =IF($A6="","",IFERROR(IF(ABS($F6)<=ktk_tolerans,"TUTARLI","KIRIK"),"KIRIK")) | H6: TTK 376/1 yarı eşik | J6: 50000 | K6: 50000
A7: V-002 | B7: 1/3 eşik × sermaye | C7: sermaye=vaka_matrah_2; esik=KTK-002 | D7: 66666.6 | E7: =IFERROR(ROUND(vaka_matrah_2*INDEX(tblKurallar[deger_2025],MATCH("KTK-002",tblKurallar[kural_id],0)),2),0) | F7: =IF($A7="","",IFERROR($D7-$E7,0)) | G7: =IF($A7="","",IFERROR(IF(ABS($F7)<=ktk_tolerans,"TUTARLI","KIRIK"),"KIRIK")) | H7: TTK 376/2 1/3 eşik | J7: 66666.6 | K7: 66666.6
A8: V-003 | B8: Birikimli yarı + 1/3 | C8: V-001 + V-002 | D8: 116666.6 | E8: =IFERROR(ROUND(vaka_matrah_1*INDEX(tblKurallar[deger_2025],MATCH("KTK-001",tblKurallar[kural_id],0))+vaka_matrah_2*INDEX(tblKurallar[deger_2025],MATCH("KTK-002",tblKurallar[kural_id],0)),2),0) | F8: =IF($A8="","",IFERROR($D8-$E8,0)) | G8: =IF($A8="","",IFERROR(IF(ABS($F8)<=ktk_tolerans,"TUTARLI","KIRIK"),"KIRIK")) | H8: Birikim yorum A | J8: 116666.6 | K8: 116666.6
A9: V-004 | B9: Varlık × borç/aktif dikkat | C9: varlik=vaka_tavan; oran=KTK-004 | D9: 112500 | E9: =IFERROR(ROUND(vaka_tavan*INDEX(tblKurallar[deger_2025],MATCH("KTK-004",tblKurallar[kural_id],0)),2),0) | F9: =IF($A9="","",IFERROR($D9-$E9,0)) | G9: =IF($A9="","",IFERROR(IF(ABS($F9)<=ktk_tolerans,"TUTARLI","KIRIK"),"KIRIK")) | H9: KTK-004 borç/aktif | J9: 112500 | K9: 112500
A12: Vaka durum özeti | B12: =IFERROR(IF(COUNTIF(tblVakalar[durum],"KIRIK")>0,"KIRIK","TUTARLI"),"KIRIK")
A13: Vaka fark toplamı | B13: =IFERROR(SUM(tblVakalar[fark]),0)

Sheet KANIT_RAPORU
A1: KANIT RAPORU — Konkordato + TTK 376 Kriz Paketi
A3: KANIT RAPORU — Konkordato + TTK 376 Kriz
A4: Rapor tarihi | B4: =raporTarihi
A5: Şirket | B5: =GIRDI!B6
A6: Dönem / yıl | B6: =CONCATENATE(GIRDI!B7," / ",hesapYili)
A8: Girdi özeti
A9: Ödenmiş sermaye | B9: =GIRDI!B9
A10: Sermaye yedekleri | B10: =GIRDI!B10
A11: Geçmiş yıl zararları | B11: =GIRDI!B11
A12: Dönem net kâr/zarar | B12: =GIRDI!B12
A13: Toplam varlık | B13: =GIRDI!B13
A14: Kısa vadeli borç | B14: =GIRDI!B14
A15: Uzun vadeli borç | B15: =GIRDI!B15
A17: Hesap zinciri
A18: Özkaynak | B18: =ktk_ozKaynak
A19: Eksik sermaye (karar) | B19: =ktk_eksikSermaye
A20: KARAR | B20: =ktk_kararMetni
A21: Gerekçe | B21: =ktk_kararGerekce
A23: Madde atıfları | B23: =ktk_maddeAtifMetni
A25: Kanıt gövdesi | B25: =ktk_kanitRaporu
A27: Parmak izi (SHA-256 kısaltma) | B27: =ktk_parmakIzi
A29: Hazırlayan (imza)
A30: Onaylayan (imza)
A32: Uyarı: Bu çıktı karar destektir; kesin konkordato / TTK 376 sonucu veya hukuki görüş değildir. Sürüm 1.0.0.

Sheet KONTROLLER
A1: KONTROLLER — Konkordato + TTK 376 Kriz Paketi
A3: Canlı kontrol paneli
A5: Giriş tablosu boş mu? | B5: =IF(COUNTA(tblGirdi[Alan Anahtarı])=0,"BOŞ","DOLU")
A6: Negatif ödenmiş sermaye? | B6: =IF(GIRDI!B9<0,"NEGATİF","TEMİZ")
A7: Hesap yılı geçerli mi? | B7: =IFERROR(IF(AND(N(hesapYili)>N(ktk_yilTaban),N(hesapYili)<=N(ktk_yilTaban)+3),"TEMİZ","HATALI"),"HATALI")
A8: Sermaye tabanı sıfır mı? | B8: =IF(IFERROR(MOTOR!G21,0)=0,"SIFIR","NORMAL")
A9: Vaka kırık mı? | B9: =IFERROR(IF(COUNTIF(tblVakalar[durum],"KIRIK")>0,"KIRIK","TUTARLI"),"KIRIK")
A10: Eksik eşiği aşıyor mu? | B10: =IF(IFERROR(MOTOR!G30,0)>ktk_kacirilanEsik+N(GIRDI!B9)*ktk_sifirCarpan,"AŞIYOR","NORMAL")
A11: Yorum A/B seçili mi? | B11: =IF(OR(GIRDI!B16="A",GIRDI!B16="B"),"TEMİZ","EKSİK")
A12: Kalite skoru (modül) | B12: =IFERROR(ROUND(IF(OR(B14=0,B14=""),0,B15/B14*100),0),0)
A14: Toplam giriş alanı | B14: =IFERROR(ktk_girisBeklenen+COUNTA(GIRDI!B6:B16)*0,0)
A15: Dolu giriş | B15: =COUNTA(GIRDI!B6:B16)
A17: Özkaynak kontrol | B17: =IFERROR(ktk_ozKaynak,0)
A18: Eksik (karar) kontrol | B18: =IFERROR(ktk_eksikSermaye,0)
A19: Karar kontrol | B19: =IFERROR(ktk_kararMetni,"-")

Sheet ORNEK_VERI
A1: ORNEK VERI — Konkordato + TTK 376 Kriz Paketi
A3: Örnek senaryo kütüphanesi
A4: Bu sayfa demo değerleri saklar; GIRDI'ye kopyalanabilir.
A5: Senaryo | B5: Ödenmiş | C5: Yedek | D5: Geçmiş Zarar | E5: Dönem Net | F5: Varlık | G5: KV Borç | H5: UV Borç | I5: Özkaynak | L5: OzDemo
A6: Demo ana | B6: 10000000 | C6: 1000000 | D6: 4000000 | E6: -2500000 | F6: 25000000 | G6: 8000000 | H6: 6000000 | I6: =IF($A6="","",IFERROR($B6+$C6-$D6+$E6,0)) | L6: 4500000
A7: Kriz | B7: 5000000 | C7: 200000 | D7: 3500000 | E7: -1200000 | F7: 12000000 | G7: 7000000 | H7: 5000000 | I7: =IF($A7="","",IFERROR($B7+$C7-$D7+$E7,0)) | L7: 500000
A8: Normal | B8: 8000000 | C8: 2000000 | D8: 500000 | E8: 800000 | F8: 30000000 | G8: 4000000 | H8: 3000000 | I8: =IF($A8="","",IFERROR($B8+$C8-$D8+$E8,0)) | L8: 10300000
A9: Yarı eşiğe yakın | B9: 6000000 | C9: 500000 | D9: 2800000 | E9: -200000 | F9: 18000000 | G9: 6000000 | H9: 4000000 | I9: =IF($A9="","",IFERROR($B9+$C9-$D9+$E9,0)) | L9: 3500000
A10: Borca batık | B10: 3000000 | C10: 100000 | D10: 2000000 | E10: -800000 | F10: 8000000 | G10: 5000000 | H10: 4000000 | I10: =IF($A10="","",IFERROR($B10+$C10-$D10+$E10,0)) | L10: 300000
I11: =IF($A11="","",IFERROR($B11+$C11-$D11+$E11,0))
I12: =IF($A12="","",IFERROR($B12+$C12-$D12+$E12,0))
I13: =IF($A13="","",IFERROR($B13+$C13-$D13+$E13,0))
I14: =IF($A14="","",IFERROR($B14+$C14-$D14+$E14,0))
I15: =IF($A15="","",IFERROR($B15+$C15-$D15+$E15,0))
I16: =IF($A16="","",IFERROR($B16+$C16-$D16+$E16,0))
I17: =IF($A17="","",IFERROR($B17+$C17-$D17+$E17,0))
I18: =IF($A18="","",IFERROR($B18+$C18-$D18+$E18,0))
I19: =IF($A19="","",IFERROR($B19+$C19-$D19+$E19,0))
I20: =IF($A20="","",IFERROR($B20+$C20-$D20+$E20,0))
I21: =IF($A21="","",IFERROR($B21+$C21-$D21+$E21,0))
I22: =IF($A22="","",IFERROR($B22+$C22-$D22+$E22,0))
... I1004: =IF($A1004="","",IFERROR($B1004+$C1004-$D1004+$E1004,0))

Sheet LISTELER
A1: LISTELER — Konkordato + TTK 376 Kriz Paketi
A3: Doğrulama listeleri
A5: Yıllar | C5: Yorum A/B | E5: Evet/Hayır
A6: 2025 | C6: A | E6: Evet
A7: 2026 | C7: B | E7: Hayır
A8: 2027

Sheet AYARLAR
A1: AYARLAR — Konkordato + TTK 376 Kriz Paketi
A3: Parametreler (tek kaynak)
A5: anahtar | B5: deger | C5: birim | D5: aciklama | E5: kaynak | F5: yururluk_tarihi | G5: dogrulama_tarihi | H5: kontrol
A6: hesapYili | B6: 2025 | C6: yıl | D6: Aktif hesap yılı | E6: Kullanıcı / GIRDI | F6: 01.01.2025 | G6: 11.08.2026 | H6: =IF(A6="","",IF(B6="","EKSİK","TAM"))
A7: raporTarihi | B7: 46245 | C7: tarih | D7: Rapor tarihi (sabit) | E7: Üretim | F7: 01.01.2025 | G7: 11.08.2026 | H7: =IF(A7="","",IF(B7="","EKSİK","TAM"))
A8: ktk_tolerans | B8: 0.01 | C8: TL | D8: Vaka tutarlılık toleransı | E8: Uygulama notu | F8: 01.01.2025 | G8: 11.08.2026 | H8: =IF(A8="","",IF(B8="","EKSİK","TAM"))
A9: ktk_kacirilanEsik | B9: 50000 | C9: TL | D9: PANO fark uyarı eşiği | E9: İç politika | F9: 01.01.2025 | G9: 11.08.2026 | H9: =IF(A9="","",IF(B9="","EKSİK","TAM"))
A10: ktk_senaryoIyi | B10: 0.9 | C10: çarpan | D10: İyimser endeks çarpanı | E10: Model varsayımı | F10: 01.01.2025 | G10: 11.08.2026 | H10: =IF(A10="","",IF(B10="","EKSİK","TAM"))
A11: ktk_senaryoKotu | B11: 1.1 | C11: çarpan | D11: Kötümser endeks çarpanı | E11: Model varsayımı | F11: 01.01.2025 | G11: 11.08.2026 | H11: =IF(A11="","",IF(B11="","EKSİK","TAM"))
A12: ktk_oranArtisPuan | B12: 0.01 | C12: oran | D12: M-SEN sabit +1 puan | E12: Senaryo motoru | F12: 01.01.2025 | G12: 11.08.2026 | H12: =IF(A12="","",IF(B12="","EKSİK","TAM"))
A13: ktk_tahminAlt | B13: 0.85 | C13: çarpan | D13: Tahmin alt bant | E13: Model varsayımı | F13: 01.01.2025 | G13: 11.08.2026 | H13: =IF(A13="","",IF(B13="","EKSİK","TAM"))
A14: ktk_tahminUst | B14: 1.15 | C14: çarpan | D14: Tahmin üst bant | E14: Model varsayımı | F14: 01.01.2025 | G14: 11.08.2026 | H14: =IF(A14="","",IF(B14="","EKSİK","TAM"))
A15: ktk_tornadoMatrah | B15: 1.05 | C15: çarpan | D15: Tornado endeks şoku | E15: Model varsayımı | F15: 01.01.2025 | G15: 11.08.2026 | H15: =IF(A15="","",IF(B15="","EKSİK","TAM"))
A16: ktk_tornadoMevcut | B16: 0.95 | C16: çarpan | D16: Tornado hakediş şoku | E16: Model varsayımı | F16: 01.01.2025 | G16: 11.08.2026 | H16: =IF(A16="","",IF(B16="","EKSİK","TAM"))
A17: ktk_isverenOran | B17: 0.1 | C17: oran | D17: Yorum B yedek sabit artışı | E17: Fiyat farkı model | F17: 01.01.2025 | G17: 11.08.2026 | H17: =IF(A17="","",IF(B17="","EKSİK","TAM"))
A18: ktk_yuzdelikOran | B18: 0.9 | C18: oran | D18: Yüzdelik P90 | E18: İstatistik | F18: 01.01.2025 | G18: 11.08.2026 | H18: =IF(A18="","",IF(B18="","EKSİK","TAM"))
A19: ktk_parmakIzi | B19: 8ccea06fc0b6bbb1 | C19: metin | D19: Dosya parmak izi etiketi | E19: Üretim | F19: 01.01.2025 | G19: 11.08.2026 | H19: =IF(A19="","",IF(B19="","EKSİK","TAM"))
A20: dosya_surumu | B20: 1.0.0 | C20: metin | D20: Ürün sürümü | E20: ExcelArşiv | F20: 01.01.2025 | G20: 11.08.2026 | H20: =IF(A20="","",IF(B20="","EKSİK","TAM"))
A21: ktk_girisBeklenen | B21: 11 | C21: adet | D21: Zorunlu giriş alanı sayısı | E21: Ürün mimarisi | F21: 01.01.2025 | G21: 11.08.2026 | H21: =IF(A21="","",IF(B21="","EKSİK","TAM"))
A22: ktk_riskDusuk | B22: 15 | C22: puan | D22: TALEP ET risk skoru | E22: İç politika | F22: 01.01.2025 | G22: 11.08.2026 | H22: =IF(A22="","",IF(B22="","EKSİK","TAM"))
A23: ktk_riskOrta | B23: 55 | C23: puan | D23: BEKLE risk skoru | E23: İç politika | F23: 01.01.2025 | G23: 11.08.2026 | H23: =IF(A23="","",IF(B23="","EKSİK","TAM"))
A24: ktk_riskYuksek | B24: 85 | C24: puan | D24: VAZGEÇ risk skoru | E24: İç politika | F24: 01.01.2025 | G24: 11.08.2026 | H24: =IF(A24="","",IF(B24="","EKSİK","TAM"))
A25: ktk_riskEsikOran | B25: 0.5 | C25: oran | D25: Yedek risk oranı | E25: İç politika | F25: 01.01.2025 | G25: 11.08.2026 | H25: =IF(A25="","",IF(B25="","EKSİK","TAM"))
A26: ktk_yilTaban | B26: 2024 | C26: yıl | D26: CHOOSE yıl tabanı (hesapYili−taban) | E26: Ürün mimarisi | F26: 01.01.2025 | G26: 11.08.2026 | H26: =IF(A26="","",IF(B26="","EKSİK","TAM"))
A27: ktk_yuvarMax | B27: 10 | C27: adet | D27: ROUND basamak tavanı | E27: Ürün mimarisi | F27: 01.01.2025 | G27: 11.08.2026 | H27: =IF(A27="","",IF(B27="","EKSİK","TAM"))
A28: ktk_dayanakCarpan | B28: 10 | C28: adet | D28: Yedek çarpan | E28: Ürün mimarisi | F28: 01.01.2025 | G28: 11.08.2026 | H28: =IF(A28="","",IF(B28="","EKSİK","TAM"))
A29: ktk_bazCarpan | B29: 1 | C29: çarpan | D29: Baz senaryo çarpanı | E29: Model varsayımı | F29: 01.01.2025 | G29: 11.08.2026 | H29: =IF(A29="","",IF(B29="","EKSİK","TAM"))
A30: ktk_sifirCarpan | B30: 0 | C30: çarpan | D30: Nötr çarpan (sıfır) | E30: Model varsayımı | F30: 01.01.2025 | G30: 11.08.2026 | H30: =IF(A30="","",IF(B30="","EKSİK","TAM"))
A31: ktk_siraBir | B31: 1 | C31: adet | D31: Tornado sıra 1 | E31: Ürün mimarisi | F31: 01.01.2025 | G31: 11.08.2026 | H31: =IF(A31="","",IF(B31="","EKSİK","TAM"))
A32: ktk_siraIki | B32: 2 | C32: adet | D32: Tornado sıra 2 | E32: Ürün mimarisi | F32: 01.01.2025 | G32: 11.08.2026 | H32: =IF(A32="","",IF(B32="","EKSİK","TAM"))
... A38: vaka_endeks_orani | B38: 1.1 | C38: çarpan | D38: Vaka1/3 endeks oranı | E38: Tebliğ örneği | F38: 01.01.2025 | G38: 11.08.2026 | H38: =IF(A38="","",IF(B38="","EKSİK","TAM"))
B40: Parametre satırları yukarıda; ad tanımları B kolonuna bağlı.
B42: Sürüm 1.0.0 | Şifre koruması: 1234 (formül alanları)

Sheet KILAVUZ
A1: KILAVUZ — Konkordato + TTK 376 Kriz Paketi
A3: Karar kuralları
A5: • VERİ YOK — giriş tablosu boşsa hesap yapılmaz.
A6: • TALEP ET — fiyat farkı oranı talep eşiğinin üzerinde; talep dosyası hazırlayın.
A7: • BEKLE — fark bekle bandında; endeks ve hakediş dönemini izleyin.
A8: • VAZGEÇ — fark düşük veya olumsuz; talep maliyetine değmeyebilir.
A10: Belirsizlik beyanları (M05)
A11: Bu nokta mevzuatta tartışmalıdır; dosya yorum A ve yorum B sonucunu yan yana gösterir: endeks_secimi
A13: Yorum A | B13: Pn = sabit pay + (1 − sabit pay) × (güncel endeks / baz endeks); fiyat farkı = hakediş × (Pn − 1). Endeks seçimi tartışmalıdır; yorum B ile yan yana okunmalıdır.
A14: Yorum B | B14: Yorum B, sabit payı +1 puan sıkılaştırır. Dosya her iki yorumun sonucunu MOTOR'da üretir.
A16: Kullanım sırası
A17: GIRDI → KURALLAR (gerekirse) → MOTOR (inceleme) → SENARYO → VAKALAR → PANO → KANIT_RAPORU → AYARLAR.
A19: Sürüm 1.0.0 | Lisans: Tek kullanıcı | ExcelArşiv
