Workbook
Name raporTarihi: AYARLAR!$B$7
Name sfn_birimMaliyet: MOTOR!$G$62
Name sfn_netNavlun: MOTOR!$G$63
Name sfn_donusYukuKatki: MOTOR!$G$66
Name sfn_npv: MOTOR!$G$64
Name sfn_irr: MOTOR!$G$65
Name sfn_kararMetni: MOTOR!$G$48
Name sfn_kararGerekce: MOTOR!$G$49
Name sfn_bilesimAlarm: RECETE!$B$14
Name sfn_donusumTablo: AYARLAR!$A$41
Name sfn_varyansKopru: VARYANS!$B$12
Name sfn_finansmanKarsilastirma: FINANSMAN!$B$11
Name sfn_senaryoKarsilastirma: SENARYO!$B$11
Name sfn_yorumSenaryo: SENARYO!$B$12
Name sfn_duyarlilikSira: SENARYO!$B$19
Name sfn_yorumDuyarlilik: SENARYO!$B$20
Name sfn_tahminAralik: SENARYO!$B$32
Name sfn_yorumTahmin: SENARYO!$B$33
Name sfn_tolerans: AYARLAR!$B$8
Name sfn_bilesimTolerans: AYARLAR!$B$9
Name sfn_hedefYuzde: AYARLAR!$B$10
Name sfn_senaryoIyi: AYARLAR!$B$11
Name sfn_senaryoKotu: AYARLAR!$B$12
Name sfn_tornadoYakit: AYARLAR!$B$13
Name sfn_tornadoDonus: AYARLAR!$B$14
Name sfn_tornadoKm: AYARLAR!$B$15
Name sfn_tahminAlt: AYARLAR!$B$16
Name sfn_tahminUst: AYARLAR!$B$17
Name sfn_yuzdelikOran: AYARLAR!$B$18
Name sfn_parmakIzi: AYARLAR!$B$19
Name sfn_girisBeklenen: AYARLAR!$B$20
Name sfn_riskDusuk: AYARLAR!$B$21
Name sfn_riskOrta: AYARLAR!$B$22
Name sfn_riskYuksek: AYARLAR!$B$23
Name sfn_yuvarMax: AYARLAR!$B$24
Name sfn_bazCarpan: AYARLAR!$B$25
Name sfn_sifirCarpan: AYARLAR!$B$26
Name sfn_siraBir: AYARLAR!$B$27
Name sfn_npvDikkat: AYARLAR!$B$28
Name sfn_gidisDonus: AYARLAR!$B$29
Name sfn_kmSaat: AYARLAR!$B$30
Name sfn_donusCarpan: AYARLAR!$B$31
Name sfn_varyansFiyatPay: AYARLAR!$B$32
Name sfn_varyansMiktarPay: AYARLAR!$B$33
Name sfn_varyansKarisimPay: AYARLAR!$B$34
Name sfn_senaryoIyiIrr: AYARLAR!$B$35
Name sfn_senaryoKotuIrr: AYARLAR!$B$36
Name sfn_modulT1: PANO!$C$11
Name sfn_modulT1Yorum: PANO!$D$11
Name sfn_modulT2: PANO!$C$12
Name sfn_modulT2Yorum: PANO!$D$12
Name sfn_modulO1: PANO!$C$13
Name sfn_modulO1Yorum: PANO!$D$13
Name sfn_modulO6: PANO!$C$16
Name sfn_modulO6Yorum: PANO!$D$16
Name sfn_modulO8: PANO!$C$17
Name sfn_modulO8Yorum: PANO!$D$17
Name sfn_modulI2: PANO!$C$19
Name sfn_modulI2Yorum: PANO!$D$19
Name ListeArac: LISTELER!$A$6:$A$8

Sheet 00_BASLANGIC
A1: EXCELARŞİV KARAR SİSTEMİ v15.1 — ÜRETİM REFERANSI
A3: Konu | B3: Bağlayıcı Standart
A4: Amaç | B4: Kanıta dayalı, hatada kapalı çalışan Excel üretim ve denetim sistemi
A5: Öncelik | B5: Kullanıcının açık iş talebi ve gerçek kullanım senaryosu
A6: Ana akış | B6: Uygunluk → Yönetişim → Sözleşmeler → Üretim → Test → Kanıt → Kullanıcı Kabulü → Yayın
A7: Yayın ilkesi | B7: Üst aşamada hata varsa alt aşama GEÇTİ üretilemez
A8: Kullanıcı kabulü | B8: Excel masaüstü görünümü test edilmediyse DIŞ_KABUL_GEREKLİ
A9: Nihai yayın | B9: Yalnız uygulanabilir modüller GEÇTİ veya gerekçeli UYGULANMAZ
A10: Ticari ayrım | B10: Ekonomik olarak savunulabilir fiyat, gerçek pazar kabulü ile aynı değildir
A11: Karmaşıklık | B11: Karar değeri, eklenen karmaşıklığın maliyetinden büyük olmalıdır
A12: Excel sınırı | B12: Veritabanı, kurumsal yetkilendirme, değiştirilemez kayıt sistemi veya gerçek zamanlı olay platformu değildir
A13: Dil standardı | B13: Kullanıcıya görünen tüm sayfa, tablo, başlık, açıklama, uyarı ve karar metinleri saf Türkçe olmalıdır
A14: Muhasebe standardı | B14: Finansal ürünlerde Türkiye Tekdüzen Hesap Planı ve Türk muhasebe kullanım alışkanlıkları esas alınır
... A33: Muhasebe | B33: Türkiye Tekdüzen Hesap Planı ve Türk muhasebe/işletme düşünce yapısı esas alınır.

Sheet PANO
A1: ☰ PANO
B2: SEVKIYAT FIYATLAMA & NAVLUN MALIYET MOTORU | L2: Dönem: 2026 / Tam ▼ | M2: ★ DOĞRULANMIŞ
B3: Hedef Kullanıcı: Lojistik müdürü, sevkiyat fiyatlandırma, filo planlama, CFO · 2026 Q3 Denetim Standardı
B5: NAVLUN BIRIM MALIYET | D5: KONSOLİDE | E5: DÖNÜŞ YÜKÜ KATKISI | G5: KONTROL | H5: NET OPERASYONEL MARJ | J5: GÜVENLİ | K5: SİSTEM GÜVEN SKORU | M5: DENETLENDİ
B7: =GİRDİLER!E17 | E7: =B7*0.22 | H7: =B7-E7 | K7: =EĞER(E7>0; YUVARLA(B7/E7; 2); 0)
B9: ↑ %14.2 konsolide canlı veri bağlantısı | E9: ● 8 Kalem nakit karşılığı: bloke | H9: ██████████░░░░░ %78.0 NET MARJ | K9: ✓ İDEAL karşılama rasyosu
B11: SEVKIYAT FIYATLAMA & NAVLUN MALIYET MOTORU — DÖNEMSEL İCRA VE PROJEKSİYON | F11: +%32 Verim | H11: KONSOLİDE OPERASYON VE KARAR MATRİSİ
B12: Kümülatif Hacim vs. Operasyonel Maliyet ve Net Kâr Eğilimi | H12: Anlık Hesaplama Sonuçları, Dinamik Formül Çıktıları ve Durum Puanlaması
B14: Dönem | C14: Aktif Hacim | D14: Maliyet/Yük | E14: Hedef | H14: PARAMETRE / KALEM | I14: ANA TUTAR | J14: FARK / MARJ | K14: VADE | L14: KONTROL DURUMU
B15: D1 | C15: 65 | D15: 45 | E15: 60 | H15: Dönemlik Kümülatif Bakiye | I15: =B7*0.45 | J15: =B7*0.05 | K15: 12 Ay | L15: ✓ DÜZENLİ
B16: D2 | C16: 78 | D16: 48 | E16: 70 | H16: Kritik Eşik Güvenlik Tamponu | I16: =B7*0.30 | J16: =B7*0.03 | K16: 24 Ay | L16: ★ AVANTAJ
B17: D3 | C17: 85 | D17: 55 | E17: 80 | H17: Operasyonel Net Fark | I17: =B7*0.15 | J17: =B7*0.02 | K17: 8 Ay | L17: ● YAKLAŞAN
B18: D4 | C18: 75 | D18: 42 | E18: 75 | H18: Rezerv ve Likit Dağılım | I18: =B7*0.10 | J18: =B7*0.01 | K18: 16 Ay | L18: ✓ TAM UYUM
B19: D5 | C19: 90 | D19: 40 | E19: 85 | H19: KONSOLİDE SİSTEM TOPLAMI | I19: =TOPLA(I15:I18) | J19: =TOPLA(J15:J18) | L19: TAM DOĞRULANDI (0 HATA)
B20: D6 | C20: 96 | D20: 32 | E20: 92
B22: KONSOLİDE PAY VE AĞIRLIK | F22: LİKİDİTE RİSKİ & ERKEN UYARI SİNYALLERİ | K22: KARAR MOTORU
B23: ■ Ana Segment (%42) | F23: Nakit Açığı Riski (30 Gün) | I23: 0.00 TL (Sıfır Risk) | K23: STRATEJİK VERİMLİLİK FIRSATI
B24: ■ İkincil Grup (%30) | F24: Tahsilat Gecikme Toleransı | I24: 48 Gün Güvenli Eşik | K24: Operasyonel süreç optimizasyonu ile kârlılık artış potansiyeli tespit edildi.
B25: ■ Destek Birimi (%15) | F25: ██████████████████████████████████████ Güvenli Bölge (%100)
B26: ■ Rezervler (%13) | F26: ✓ 90 GÜNLÜK PROJEKSİYONDA NAKİT SIKIŞIKLIĞI TESPİT EDİLMEDİ | K26: STRATEJİ REÇETESİNİ İNCELE >

Sheet GİRDİLER
A1: ☰ PANO
B3: 🔍 SEVKIYAT FIYATLAMA & NAVLUN MALIYET MOTORU — Kayıt veya hesap ara... | G3: TOPLAM: 1.450 KAYIT | I3: HATALI HÜCRE: 0 ADET
B5: TARİH | C5: REFERANS NO | D5: İŞLEM AÇIKLAMASI VE DETAY | E5: BRÜT TUTAR (₺) | F5: KDV ORANI | G5: NET TUTAR (₺) | H5: HESAP / CARİ | I5: DURUM
B6: 12.10.2026 | C6: TR-0428-A | D6: Operasyonel ana kalem tahmini | E6: 845200 | F6: 0.2 | G6: =E6/(1+F6) | H6: Vadesiz Ticari | I6: ONAYLANDI
B7: 14.10.2026 | C7: TR-0429-B | D7: Operasyonel çıkış/maliyet tahmini | E7: 1240000 | F7: 0.2 | G7: =E7/(1+F7) | H7: Tedarikçi Havuzu | I7: BEKLEMEDE
B8: 18.10.2026 | C8: TR-0430-C | D8: Ödeme takvimi tahakkuku | E8: 620500 | F8: 0.1 | G8: =E8/(1+F8) | H8: Kısa Vade Tahakkuk | I8: ONAYLANDI
B9: 21.10.2026 | C9: TR-0431-D | D9: Müşteri işlem tahmini | E9: 415000 | F9: 0.2 | G9: =E9/(1+F9) | H9: Müşteri Alacağı | I9: ONAYLANDI
B10: 25.10.2026 | C10: TR-0432-E | D10: Ana operasyon tahmini | E10: 980400 | F10: 0.2 | G10: =E10/(1+F10) | H10: Vadesiz Ticari | I10: ONAYLANDI
B11: 28.10.2026 | C11: TR-0433-F | D11: Kredi/taksit karşılığı | E11: 1850000 | F11: 0.2 | G11: =E11/(1+F11) | H11: Finansman Havuzu | I11: BLOKE
B12: 02.11.2026 | C12: TR-0434-G | D12: Sabit gider ve yönetim notları | E12: 740000 | F12: 0.2 | G12: =E12/(1+F12) | H12: Genel Yönetim | I12: ONAYLANDI
B13: 05.11.2026 | C13: TR-0435-H | D13: Operasyonel ana kalem tahmini | E13: 520800 | F13: 0.2 | G13: =E13/(1+F13) | H13: Vadesiz Ticari | I13: ONAYLANDI
B14: 09.11.2026 | C14: TR-0436-I | D14: Müşteri işlem tahmini | E14: 1120000 | F14: 0.2 | G14: =E14/(1+F14) | H14: Müşteri Alacağı | I14: ONAYLANDI
B15: 12.11.2026 | C15: TR-0437-J | D15: Operasyonel çıkış tahmini | E15: 890000 | F15: 0.2 | G15: =E15/(1+F15) | H15: Tedarikçi Havuzu | I15: ONAYLANDI
B17: SAYFA TOPLAMI (10 / 1.450 KAYIT) | E17: =TOPLA(E6:E15)

Sheet YÖNETİM_RAPORU
A1: ☰ PANO
B2: SEVKIYAT FIYATLAMA & NAVLUN MALIYET MOTORU — NİHAİ KARAR VE DEĞERLEME
B3: Yönetim Kurulu ve İcra Komitesi için Otomatik Finansal Stres Testi Raporu · Lojistik müdürü, sevkiyat fiyatlandırma, filo planlama, CFO
B4: DÖNEM: 2026 Q3 · DENETİM PROTOKOLÜ: ISO/VUK/IFRS UYUMLU · DURUM: ONAYLANDI
B6: SENARYO A: KÖTÜMSER (STRES TESTİ -%20) | H6: SENARYO B: BAZ MODEL (HEDEFLENEN)
B8: Ciro / Hacim Düşüşü: | E8: -%20.0 (Kriz Eşiği) | H8: Ciro / Hacim Gerçekleşmesi: | K8: %100.0 (Tam Bütçe)
B9: Beklenen Net Kâr / Getiri: | E9: =PANO!B7*0.8*0.22 | H9: Beklenen Net Kâr / Getiri: | K9: =PANO!H7
B10: Minimum Nakit Tamponu: | E10: =PANO!E7*0.75 | H10: Serbest Nakit Akımı: | K10: =PANO!H7*0.75
B11: Likidite Karşılama Oranı: | E11: =YUVARLA(PANO!B7*0.8/PANO!E7; 2) | H11: Yatırım Geri Dönüşü (ROI): | K11: %38.4 Yıllık
B14: STRES SENARYOSUNDA DAHİ İFLAS RİSKİ YOK | H14: OPTİMUM İCRA VE PLANLAMA REÇETESİ
B17: YÖNETİM KARAR MATRİSİ VE UYGULAMA REÇETESİ
B19: ● Öncelik 1: Acil Likidite ve Borç Servis Planlaması
B20: Sistemde hesaplanan vade günlerine sadık kalınarak nakit blokajı 3 gün önceden hazır edilmelidir.
B21: ● Öncelik 2: Formül Doğrulama ve Çapraz Sağlama
B22: Tüm hücreler kilitli formül korumasında olup girdi sayfalarında sıfır döngüsel başvuru (circular ref) garantilidir.
B23: ● Öncelik 3: Resmi Mevzuat ve Vergi Kalkanı Entegrasyonu
B24: 2026 güncel vergi dilimleri, amortisman ve SGK teşvik parametreleri tam otomatik yansıtılmaktadır.
B25: ● Öncelik 4: Yönetici İmzası ve Rapor Paylaşımı
B26: Tek tuşla PDF ve A4 çıktı formatına tam uyumlu sayfa yapısı kurgulanmıştır.

Sheet 01_YURUTME_CEKIRDEGI
A1: YÜRÜTME ÇEKİRDEĞİ — ZORUNLU ÜRETİM SIRASI
A3: Adım | B3: Modül | C3: Tetikleyici | D3: Zorunlu Kanıt | E3: GEÇTİ Kuralı | F3: Hata Durumu | G3: Sonraki Aşama
A4: 1 | B4: Excel Uygunluğu | C4: Her yeni model | D4: UYGUNLUK_KARARI | E4: Excel'in rolü açık | F4: HATA / BLOKE | G4: Yönetişim
A5: 2 | B5: Yönetişim | C5: Her model | D5: Risk seviyesi + etki girdileri | E5: Seviye hesaplandı | F5: BLOKE | G5: Sözleşmeler
A6: 3 | B6: Türk Muhasebe Eşlemesi | C6: Finansal model | D6: THP hesap eşleme tablosu | E6: Kritik satırlar THP ile uyumlu | F6: HATA | G6: Sözleşmeler
A7: 4 | B7: Veri ve Anlam Sözleşmeleri | C7: Girdi/KPI varsa | D7: Veri + KPI sözleşmeleri | E7: Kapsam %100 | F7: HATA | G7: Üretim
A8: 5 | B8: Üretim | C8: Sözleşmeler GEÇTİ | D8: Çalışan Excel | E8: Tek gerçek kaynak korunmuş | F8: HATA | G8: Testler
A9: 6 | B9: Görsel/Kullanım Katmanı | C9: Motor hazır | D9: Başlıklar + renk + grafik + yönlendirme | E9: Tüm kullanıcı sayfaları standarda uygun | F9: HATA | G9: Testler
A10: 7 | B10: Testler | C10: Üretim tamam | D10: Formül/OOXML/kimlik/oracle/golden/metamorfik | E10: Uygulanabilir hard gate'ler GEÇTİ | F10: HATA | G10: Kanıt
A11: 8 | B11: Hata-Kontrol Tutarlılığı | C11: Test sonucu var | D11: Hata taraması + kontrol sonuçları | E11: Formül hatası varken GEÇTİ yok | F11: HATA | G11: Kanıt
A12: 9 | B12: Kanıt | C12: Test sonucu var | D12: Makine okunur artefakt + özet | E12: Kanıt fiziksel ve tutarlı | F12: HATA | G12: Kullanıcı Kabulü
A13: 10 | B13: Kullanıcı Kabulü | C13: Kritik görevler | D13: Gerçek ekran davranışı | E13: Kritik görevler %100 | F13: DIŞ_KABUL_GEREKLİ | G13: Ticari
A14: 11 | B14: Ticari Değer | C14: Ürün satılacaksa | D14: ROI + demo + kanıt paketi | E14: Ekonomik değer kanıtlı | F14: UYARI / HATA | G14: Pazar Doğrulama
A15: 12 | B15: Pazar Doğrulama | C15: Pazar iddiası varsa | D15: Ücretli satış/pilot/fiyat kabul kanıtı | E15: Gerçek fiyat kabul kanıtı | F15: UYGULANMAZ / HATA | G15: Yayın

Sheet 02_KONTROL_LISTESI
A1: NİHAİ KONTROL LİSTESİ — KANITSIZ GEÇİŞ YOK
A3: Kontrol No | B3: Kontrol | C3: Beklenen | D3: Zorunlu Kapı? | E3: Sonuç
A4: K01 | B4: Kullanıcının açık talebi öncelikli mi? | C4: Evet | D4: EVET
A5: K02 | B5: Mevcut yapı, formüller ve tek gerçek kaynak korunuyor mu? | C5: Evet, değişiklik gerekçeli | D5: EVET
A6: K03 | B6: Üst aşama HATA ise alt aşama GEÇTİ engelleniyor mu? | C6: Evet | D6: EVET
A7: K04 | B7: Kanıt fiziksel çıktı ve içerik doğrulaması içeriyor mu? | C7: Evet | D7: EVET
A8: K05 | B8: Excel GUI erişimi olmadan kullanıcı görünümü GEÇTİ yazılıyor mu? | C8: Hayır | D8: EVET
A9: K06 | B9: NİHAİ yalnız GEÇTİ / gerekçeli UYGULANMAZ ile mi? | C9: Evet | D9: EVET
A10: K07 | B10: Ekonomik fiyat savunusu pazar doğrulamasından ayrılmış mı? | C10: Evet | D10: EVET
A11: K08 | B11: Prestij için gereksiz modül var mı? | C11: Hayır | D11: HAYIR
A12: K09 | B12: Excel sınırları açık mı? | C12: Evet | D12: EVET
A13: K10 | B13: Teknik kaynak korunuyor mu? | C13: Evet | D13: EVET
A14: K11 | B14: Kullanıcıya görünen tüm metinler Türkçe mi? | C14: Evet | D14: EVET
A15: K12 | B15: Her kullanıcı sayfasında üst başlık var mı? | C15: Evet | D15: EVET
... A34: K31 | B34: Premium vitrin, altyapı kadar güçlü ve satış fiyatını destekleyecek seviyede mi? | C34: Evet | D34: EVET

Sheet 03_GORSEL_TASARIM
A1: GÖRSEL TASARIM VE PREMIUM EXCEL STANDARDI
A3: Alan | B3: Zorunlu Kural | C3: Uygulama | D3: Yasak | E3: Kontrol | F3: Durum
A4: Sayfa başlığı | B4: Her kullanıcı sayfasının en üstünde tek ve açık sayfa başlığı | C4: A1'den başlayan koyu lacivert başlık bandı | D4: Başlıksız sayfa | E4: Başlık kapsama = %100 | F4: ZORUNLU
A5: Sekme renkleri | B5: Sayfalar işlevine göre renk kodlanır | C5: Girdi=mavi, hesap=gri, rapor=lacivert, kontrol=kırmızı, kılavuz=altın | D5: Rastgele renk | E5: Renk semantiği tutarlı | F5: ZORUNLU
A6: Kolon düzeni | B6: Veri blokları bitişik kolonlarda ilerler | C6: Gereksiz boş kolon bırakma; yalnız gerçek bölüm ayrımı varsa kontrollü boşluk | D6: A:C veri, D boş, E:F veri gibi parçalı yapı | E6: Boş kolon taraması | F6: ZORUNLU
A7: Girdi hücreleri | B7: Kullanıcının değiştireceği alan açıkça görünür | C7: Açık sarı dolgu + mavi yazı | D7: Formülle aynı görünüm | E7: Girdi/formül ayrımı | F7: ZORUNLU
A8: Formüller | B8: Hesap hücreleri kullanıcı girdisinden ayrılır | C8: Siyah yazı; sayfalar arası bağlantı yeşil yazı | D8: Hard-code gizleme | E8: Formül sınıfı kontrolü | F8: ZORUNLU
A9: Grafik sayısı | B9: Yönetici ekranında en fazla 3 ana karar grafiği | C9: Trend, karşılaştırma, köprü/dağılım; iş kararına bağlı | D9: Grafik kalabalığı | E9: Grafik başına karar sorusu | F9: ZORUNLU
A10: Grafik stili | B10: Kurumsal ve yüksek okunabilirlik | C10: Beyaz zemin, ince gridline, tek vurgu rengi, açık birim/başlık | D10: 3B, gölge, neon, gökkuşağı renkleri | E10: Görsel inceleme | F10: ZORUNLU
A11: Grafik başlığı | B11: Grafik 'neyi' değil 'ne anlama geldiğini' söyler | C11: Örn: 'Nakit 2028'de kritik eşiğin altına iniyor' | D11: 'Nakit Grafiği' gibi anlamsız başlık | E11: Başlık karar testi | F11: ZORUNLU
A12: Birimler | B12: Tüm finansal görsellerde birim açık | C12: TL, bin TL, milyon TL, %, gün, x | D12: Birim belirsizliği | E12: Birim kapsama %100 | F12: ZORUNLU
A13: Sıfır/negatif | B13: Finansal format standardı | C13: Sıfır='-', negatif kırmızı parantez | D13: -500 veya 0,00 kalabalığı | E13: Format kontrolü | F13: ZORUNLU
A14: Yazı tipi | B14: Tek aile | C14: Aptos veya Segoe UI | D14: Karışık font | E14: Tek font kontrolü | F14: ZORUNLU
... A22: Premium vitrin | B22: Görsel kalite ürün değerinin zorunlu parçasıdır | C22: Kaliteli grafik, gerçek KPI kartı, finansal hiyerarşi, tab rengi, fonksiyonel navigasyon | D22: Sadece doğru hesap yapıp çıplak/varsayılan Excel görünümü bırakmak | E22: Görsel release incelemesi | F22: ZORUNLU

Sheet 04_MUHASEBE_THP
A1: TÜRKİYE MUHASEBE VE TEKDÜZEN HESAP PLANI STANDARDI
A3: Konu | B3: Zorunlu Standart | C3: Örnek Türkçe Ad | D3: THP / Mantık | E3: Hata Riski | F3: Kontrol
A4: Dil | B4: Kullanıcıya görünen finansal terimler Türkçe | C4: Hasılat, Satışların Maliyeti, Brüt Kâr, Faaliyet Giderleri | D4: Türk işletme kullanımına uygun | E4: İngilizce jargon | F4: Terminoloji taraması
A5: Gelir Tablosu | B5: Türk sunum sırası kullanılır | C5: Net Satışlar → Satışların Maliyeti → Brüt Kâr → Faaliyet Giderleri → Faaliyet Kârı | D5: 600/610/611; 620-623; 63x | E5: Yanlış sınıflama | F5: Hesap eşleme
A6: Bilanço | B6: Dönen/Duran Varlık ve Kısa/Uzun Vadeli Yükümlülük ayrımı | C6: Hazır Değerler, Ticari Alacaklar, Stoklar, Mali Borçlar | D6: 1xx / 2xx / 3xx / 4xx / 5xx | E6: Vade sınıfı hatası | F6: Bilanço eşitliği
A7: Nakit Akışı | B7: İşletme/Yatırım/Finansman nakit akışları ayrılır | C7: Faaliyetlerden Nakit, Yatırım Harcamaları, Finansman Nakit Akışı | D7: Dolaylı/doğrudan yöntem açık seçilir | E7: Kâr = nakit sanılması | F7: Nakit devri
A8: Ticari Alacaklar | B8: Cari ve vade mantığı korunur | C8: 120 Alıcılar | D8: 120 | E8: Tahakkuk/nakit karışması | F8: Alacak devir kontrolü
A9: Ticari Borçlar | B9: Tedarikçi borcu ayrı izlenir | C9: 320 Satıcılar | D9: 320 | E9: Gider/ödeme karışması | F9: Borç devir kontrolü
A10: Kasa/Banka | B10: Hazır değerler ayrı izlenir | C10: 100 Kasa, 102 Bankalar | D10: 100 / 102 | E10: Virmanla toplam nakdin değişmesi | F10: Virman değişmezi
A11: Stok | B11: Dikeye uygun stok türü | C11: 150 İlk Madde ve Malzeme, 153 Ticari Mallar | D11: 15x | E11: Maliyet ve stok hareketinin kopması | F11: Stok devri
A12: Maddi Duran Varlık | B12: Yatırım harcaması ve amortisman bağlantılı | C12: 253 Tesis Makine Cihazlar, 255 Demirbaşlar, 257 Birikmiş Amortismanlar | D12: 25x | E12: Yatırım/gider karışması | F12: Net defter değeri devri
A13: Mali Borçlar | B13: Kısa/uzun vadeli borç ayrımı | C13: 300 Banka Kredileri / 400 Banka Kredileri | D13: 300 / 400 | E13: Vade sınıfı yanlış | F13: Borç devri
A14: Özkaynak | B14: Sermaye ve geçmiş yıl kârları ayrı | C14: 500 Sermaye, 570 Geçmiş Yıllar Kârları, 590 Dönem Net Kârı | D14: 5xx | E14: Net kâr bağının kopması | F14: Özkaynak devri
... A18: İstisna | B18: TFRS özel ürün varsa fark açık yazılır | C18: Tekdüzen raporlama ≠ TFRS finansal tablo sunumu | D18: Amaç belirtilir | E18: Standartları karıştırma | F18: Model amacı kontrolü

Sheet 05_KARAR_SATIS
A1: KARAR, GÜVEN VE SATIŞA HAZIRLIK STANDARDI
A3: Alan | B3: Müşteri Sorusu | C3: Zorunlu Ürün Davranışı | D3: Kanıt | E3: Başarısızlık Durumu | F3: Kapı
A4: 5 saniye | B4: Bu ürün neyi çözüyor? | C4: İlk ekranda hedef kullanıcı + pahalı problem + sonuç görünür | D4: Başlık + alt mesaj + gerçek ekran | E4: Ürün yalnız teknik isim | F4: HATA
A5: Acı | B5: Sorun bana neye mal oluyor? | C5: Mümkünse müşterinin kendi verisiyle parasal/zaman etkisi hesaplanır | D5: ROI/acı hesaplama yöntemi | E5: Uydurma tasarruf | F5: HATA
A6: Karar | B6: Bu bilgiyle ne yapacağım? | C6: Her kritik KPI aksiyona bağlanır | D6: KARAR_KUYRUGU | E6: Sadece rapor | F6: HATA
A7: Güven | B7: Bu sayıya neden inanayım? | C7: Kaynak, formül mantığı, kontrol ve son doğrulama görünür | D7: Kontroller + kaynak izi + sürüm | E7: Prestij kelimesi | F7: HATA
A8: Referans | B8: Müşteri yorumu yoksa ne göstereceğim? | C8: Önce/Sonra + Karar Vakası + Hata Önleme Vakası üretilir | D8: Demo/örnek çıktı | E8: Kanıtsız iddia | F8: HATA
A9: Senaryo | B9: Ne olursa işler bozulur? | C9: Baz/Aşağı/Yukarı veya uygun stres senaryosu | D9: Senaryo karşılaştırma | E9: Dekoratif senaryo | F9: HATA
A10: Ters stres | B10: Hangi eşikte karar kırılır? | C10: En az bir kritik sürücü için kırılma eşiği | D10: Kırılma eşiği tablosu | E10: Sadece +/- %10 | F10: UYARI/HATA
A11: Hata tutarlılığı | B11: Formül hata verirse ne olur? | C11: Kontrol GEÇTİ veremez; BLOKE/HATA üretir | D11: Hata taraması | E11: Hata + GEÇTİ birlikte | F11: HATA
A12: Karar motoru | B12: Ne oldu, neden oldu? | C12: Sorun + neden + parasal etki + aksiyon + son tarih | D12: Karar tablosu | E12: Boş sayfa / isim düzeyi modül | F12: HATA
A13: Yönetici özeti | B13: 5 saniyede ne görmeliyim? | C13: Bugün / ne değişti / ne bozulacak / neden / ne yapmalıyım / güven | D13: Yönetici özeti ekranı | E13: KPI kutusu yığını | F13: HATA
A14: Teklif | B14: Neden satın almalıyım? | C14: Dosya özellikleri yerine sonuç ve kaçınılan maliyet sunulur | D14: Ürün sayfası kanıt eşlemesi | E14: Özellik listesiyle satış | F14: HATA
... A19: Pazar kanıtı | B19: Piyasa gerçekten ödüyor mu? | C19: Satış/pilot/LOI/fiyat kabulü olmadan pazar doğrulandı yazılmaz | D19: Gerçek işlem kanıtı | E19: Tahmini talep = satış kabulü | F19: HATA

Sheet KAPAK
A1: KAPAK — Sevkiyat Fiyatlama & Navlun Maliyet Motoru
A3: Sevkiyat Fiyatlama & Navlun Maliyet Motoru
A4: Km × araç tipi × dönüş yükü ile net navlun maliyetini hesaplayın; reçete bileşiminden fiyat önerin; hat yatırımı için YATIRIM YAPILIR / YATIRIM YAPMA kararını üretin.
A6: Bu ürün ne sağlar?
A7: • Navlun maliyet reçetesi: hammadde (yakıt) + işçilik + ambalaj + genel gider = %100
A8: • Fire (boş km) kolonu ve AYARLAR birim dönüşüm tablosu
A9: • Dönüş yükü katkısı ile net navlun ve önerilen teklif fiyatı
A10: • CAPEX/OPEX + öz kaynak / kredi + NPV / IRR tornado
A11: • Kötümser YATIRIM YAPMA yolu; boş girişte VERİ YOK
A13: Kimler için?
A14: • Sevkiyat fiyatlandırma — km ve araç tipine göre teklif satırı
A15: • Lojistik müdürü — hat açılışı ve kârlılık kararı
... A21: Sürüm 1.0.0 | 2026 | ExcelArşiv | Lisans: Tek kullanıcı | Kod: SFN-PRO

Sheet HIZLI_BASLANGIC
A1: HIZLI BASLANGIC — Sevkiyat Fiyatlama & Navlun Maliyet Motoru
A3: Üç adımda sonuç
A5: Adım 1 — Girdiler | B5: GIRDI'de km, araç tipi, dönüş yükü; HAMMADDE'de fiyatlar; RECETE'de bileşim %.
A6: Adım 2 — Karar | B6: PANO ve KARAR'da birim maliyet, önerilen fiyat, NPV/IRR ve karar görünür.
A7: Adım 3 — Kanıt | B7: KANIT_RAPORU yazdırın; SENARYO tornado ve VARYANS köprüsünü kontrol edin.
A9: Formüller
A10: Brüt maliyet = yakıt+işçilik+ambalaj+genel (fire dahil) | Net = brüt − dönüş yükü katkısı | Önerilen fiyat = net ÷ (1 − hedef marj)
A12: Sarı = manuel giriş | Yeşil = formül çıktısı | Şifre 1234 formül alanlarını korur.

Sheet GIRDI
A1: GIRDI — Sevkiyat Fiyatlama & Navlun Maliyet Motoru
A3: Sevkiyat ve hat yatırımı girdileri
A4: Sarı hücreler manuel giriştir. Bileşim RECETE'de; dönüşüm AYARLAR'da.
A5: Alan | B5: Değer | C5: Birim
A6: Şirket / Hat | B6: Örnek Lojistik A.Ş. | C6: metin
A7: Dönem | B7: 2026-Q3 | C7: metin
A8: Sefer km [tek yön] | B8: 450 | C8: adet
A9: Araç tipi | B9: TIR | C9: metin
A10: Yük [ton] | B10: 20 | C10: adet
A11: Dönüş yükü oranı | B11: 0.4 | C11: %
A12: Hedef marj | B12: 0.18 | C12: %
A13: Yıllık sefer [adet] | B13: 200 | C13: adet
A14: CAPEX / YATIRIM [₺] | B14: 2500000 | C14: ₺
A15: WACC [%] | B15: 0.2 | C15: %
A16: NPV dönem [yıl] | B16: 5 | C16: adet
A17: Kredi faiz oranı [%] | B17: 0.35 | C17: %
A18: Öz kaynak oranı [%] | B18: 0.4 | C18: %
A20: Birim maliyet (ayna) | B20: =IFERROR(sfn_birimMaliyet,0)
A21: Net navlun (ayna) | B21: =IFERROR(sfn_netNavlun,0)
A22: Giriş doluluk | B22: =IFERROR(IF(OR(COUNTA(B6:B18)=0,sfn_girisBeklenen=0),0,ROUND(COUNTA(B6:B18)/sfn_girisBeklenen*100,0)),0)
A24: Giriş tablosu (otomasyon / boş-mod)
A25: Alan Anahtarı | B25: Değer | C25: Birim | D25: Zorunlu | E25: Kaynak | F25: Kontrol
A26: sirket_adi | B26: Örnek Lojistik A.Ş. | C26: metin | D26: Evet | E26: GIRDI | F26: =IF($A26="","",IF($B26="","EKSİK","TAM"))
A27: donem | B27: 2026-Q3 | C27: metin | D27: Evet | E27: GIRDI | F27: =IF($A27="","",IF($B27="","EKSİK","TAM"))
A28: sefer_km | B28: 450 | C28: km | D28: Evet | E28: GIRDI | F28: =IF($A28="","",IF($B28="","EKSİK","TAM"))
A29: arac_tipi | B29: TIR | C29: kod | D29: Evet | E29: GIRDI | F29: =IF($A29="","",IF($B29="","EKSİK","TAM"))
A30: yuk_ton | B30: 20 | C30: ton | D30: Evet | E30: GIRDI | F30: =IF($A30="","",IF($B30="","EKSİK","TAM"))
A31: donus_yuku_oran | B31: 0.4 | C31: oran | D31: Evet | E31: GIRDI | F31: =IF($A31="","",IF($B31="","EKSİK","TAM"))
A32: hedef_marj | B32: 0.18 | C32: oran | D32: Evet | E32: GIRDI | F32: =IF($A32="","",IF($B32="","EKSİK","TAM"))
A33: yillik_sefer | B33: 200 | C33: adet | D33: Evet | E33: GIRDI | F33: =IF($A33="","",IF($B33="","EKSİK","TAM"))
A34: capex_tl | B34: 2500000 | C34: TL | D34: Evet | E34: GIRDI | F34: =IF($A34="","",IF($B34="","EKSİK","TAM"))
A35: wacc | B35: 0.2 | C35: oran | D35: Evet | E35: GIRDI | F35: =IF($A35="","",IF($B35="","EKSİK","TAM"))
A36: npv_donem | B36: 5 | C36: yıl | D36: Evet | E36: GIRDI | F36: =IF($A36="","",IF($B36="","EKSİK","TAM"))
A37: kredi_orani | B37: 0.35 | C37: oran | D37: Evet | E37: GIRDI | F37: =IF($A37="","",IF($B37="","EKSİK","TAM"))
A38: oz_kaynak_oran | B38: 0.4 | C38: oran | D38: Evet | E38: GIRDI | F38: =IF($A38="","",IF($B38="","EKSİK","TAM"))
F39: =IF($A39="","",IF($B39="","EKSİK","TAM"))
F40: =IF($A40="","",IF($B40="","EKSİK","TAM"))
F41: =IF($A41="","",IF($B41="","EKSİK","TAM"))
F42: =IF($A42="","",IF($B42="","EKSİK","TAM"))
F43: =IF($A43="","",IF($B43="","EKSİK","TAM"))
...

Sheet HAMMADDE
A1: HAMMADDE — Sevkiyat Fiyatlama & Navlun Maliyet Motoru
A3: Maliyet kalem kartı — hammadde / işçilik / ambalaj / genel gider
A4: Alım birimi → kullanım birimi dönüşümü AYARLAR dönüşüm tablosundan geçer.
A6: kalem_id | B6: kalem_ad | C6: sinif | D6: alim_birim | E6: kullanim_birim | F6: birim_fiyat | G6: fire | H6: tedarikci | I6: guncelleme | J6: net_birim
A7: HM-01 | B7: Yakıt (dizel) | C7: HAMMADDE | D7: L | E7: L | F7: 45 | G7: 0.08 | H7: Akaryakıt | I7: 46245 | J7: =IF($A7="","",IFERROR($F7*(1+$G7),0))
A8: HM-02 | B8: Şoför ücreti | C8: ISCILIK | D8: saat | E8: saat | F8: 280 | G8: 0 | H8: Bordro | I8: 46245 | J8: =IF($A8="","",IFERROR($F8*(1+$G8),0))
A9: HM-03 | B9: Ambalaj / bağlama | C9: AMBALAJ | D9: adet | E9: adet | F9: 1200 | G9: 0.02 | H9: Depo | I9: 46245 | J9: =IF($A9="","",IFERROR($F9*(1+$G9),0))
A10: HM-04 | B10: Genel gider payı | C10: GENEL_GIDER | D10: km | E10: km | F10: 2.5 | G10: 0 | H10: Muhasebe | I10: 46245 | J10: =IF($A10="","",IFERROR($F10*(1+$G10),0))
A11: HM-05 | B11: Tüketim (L/100km) | C11: HAMMADDE | D11: L100 | E11: L_km | F11: 32 | G11: 0 | H11: Araç kartı | I11: 46245 | J11: =IF($A11="","",IFERROR($F11*(1+$G11),0))
J12: =IF($A12="","",IFERROR($F12*(1+$G12),0))
J13: =IF($A13="","",IFERROR($F13*(1+$G13),0))
A14: Yakıt birim fiyat [₺/L] | B14: =IFERROR(INDEX(tblHammadde[birim_fiyat],MATCH("HM-01",tblHammadde[kalem_id],0)),0) | J14: =IF($A14="","",IFERROR($F14*(1+$G14),0))
A15: İşçilik birim [₺/saat] | B15: =IFERROR(INDEX(tblHammadde[birim_fiyat],MATCH("HM-02",tblHammadde[kalem_id],0)),0) | J15: =IF($A15="","",IFERROR($F15*(1+$G15),0))
A16: Ambalaj birim [₺] | B16: =IFERROR(INDEX(tblHammadde[birim_fiyat],MATCH("HM-03",tblHammadde[kalem_id],0)),0) | J16: =IF($A16="","",IFERROR($F16*(1+$G16),0))
A17: Genel gider [₺/km] | B17: =IFERROR(INDEX(tblHammadde[birim_fiyat],MATCH("HM-04",tblHammadde[kalem_id],0)),0) | J17: =IF($A17="","",IFERROR($F17*(1+$G17),0))
A18: Tüketim L/100km | B18: =IFERROR(INDEX(tblHammadde[birim_fiyat],MATCH("HM-05",tblHammadde[kalem_id],0)),0) | J18: =IF($A18="","",IFERROR($F18*(1+$G18),0))
A19: Fire (yakıt boş km) | B19: =IFERROR(INDEX(tblHammadde[fire],MATCH("HM-01",tblHammadde[kalem_id],0)),0) | J19: =IF($A19="","",IFERROR($F19*(1+$G19),0))
J20: =IF($A20="","",IFERROR($F20*(1+$G20),0))
J21: =IF($A21="","",IFERROR($F21*(1+$G21),0))
J22: =IF($A22="","",IFERROR($F22*(1+$G22),0))
J23: =IF($A23="","",IFERROR($F23*(1+$G23),0))
J24: =IF($A24="","",IFERROR($F24*(1+$G24),0))
J25: =IF($A25="","",IFERROR($F25*(1+$G25),0))
J26: =IF($A26="","",IFERROR($F26*(1+$G26),0))
J27: =IF($A27="","",IFERROR($F27*(1+$G27),0))
J28: =IF($A28="","",IFERROR($F28*(1+$G28),0))
J29: =IF($A29="","",IFERROR($F29*(1+$G29),0))
J30: =IF($A30="","",IFERROR($F30*(1+$G30),0))
J31: =IF($A31="","",IFERROR($F31*(1+$G31),0))
... J1004: =IF($A1004="","",IFERROR($F1004*(1+$G1004),0))

Sheet RECETE
A1: RECETE — Sevkiyat Fiyatlama & Navlun Maliyet Motoru
A3: Navlun maliyet bileşim reçetesi — toplam %100 ± tolerans
A5: satir_id | B5: kalem | C5: sinif | D5: oran | E5: fire | F5: versiyon | G5: miktar_pay | H5: not
A6: R-01 | B6: Yakıt payı | C6: HAMMADDE | D6: 0.42 | E6: 0.08 | F6: V1 | G6: =IF($A6="","",IFERROR($D6*(1+$E6),0)) | H6: Gidiş yakıt
A7: R-02 | B7: İşçilik payı | C7: ISCILIK | D7: 0.28 | E7: 0 | F7: V1 | G7: =IF($A7="","",IFERROR($D7*(1+$E7),0)) | H7: Şoför süresi
A8: R-03 | B8: Ambalaj payı | C8: AMBALAJ | D8: 0.08 | E8: 0.02 | F8: V1 | G8: =IF($A8="","",IFERROR($D8*(1+$E8),0)) | H8: Bağlama
A9: R-04 | B9: Genel gider payı | C9: GENEL_GIDER | D9: 0.22 | E9: 0 | F9: V1 | G9: =IF($A9="","",IFERROR($D9*(1+$E9),0)) | H9: Otoyol/sigorta
G10: =IF($A10="","",IFERROR($D10*(1+$E10),0))
G11: =IF($A11="","",IFERROR($D11*(1+$E11),0))
A12: Bileşim toplamı [%] | B12: =IFERROR(SUM(tblRecete[oran]),0) | G12: =IF($A12="","",IFERROR($D12*(1+$E12),0))
A13: Sapma (hedef %100) | B13: =IFERROR(ABS(B12-sfn_hedefYuzde),0) | G13: =IF($A13="","",IFERROR($D13*(1+$E13),0))
A14: Bileşim alarm | B14: =IF(B13>sfn_bilesimTolerans,"ALARM: bileşim %100 dışı — KIRMIZI","TAM: %100 ±tolerans") | G14: =IF($A14="","",IFERROR($D14*(1+$E14),0))
A15: Aktif versiyon | B15: V1 | G15: =IF($A15="","",IFERROR($D15*(1+$E15),0))
G16: =IF($A16="","",IFERROR($D16*(1+$E16),0))
G17: =IF($A17="","",IFERROR($D17*(1+$E17),0))
G18: =IF($A18="","",IFERROR($D18*(1+$E18),0))
G19: =IF($A19="","",IFERROR($D19*(1+$E19),0))
G20: =IF($A20="","",IFERROR($D20*(1+$E20),0))
G21: =IF($A21="","",IFERROR($D21*(1+$E21),0))
G22: =IF($A22="","",IFERROR($D22*(1+$E22),0))
G23: =IF($A23="","",IFERROR($D23*(1+$E23),0))
G24: =IF($A24="","",IFERROR($D24*(1+$E24),0))
G25: =IF($A25="","",IFERROR($D25*(1+$E25),0))
G26: =IF($A26="","",IFERROR($D26*(1+$E26),0))
G27: =IF($A27="","",IFERROR($D27*(1+$E27),0))
... G1004: =IF($A1004="","",IFERROR($D1004*(1+$E1004),0))

Sheet MOTOR
A1: MOTOR — Sevkiyat Fiyatlama & Navlun Maliyet Motoru
A3: Navlun maliyet + hat yatırım motoru
A4: Hammadde/işçilik/ambalaj/genel gider kırılımı; dönüşüm AYARLAR'dan.
A6: adim | B6: ad | C6: formul | D6: birim | E6: aciklama | F6: kaynak | G6: deger
A7: 1 | B7: Sefer km | C7: =IFERROR(GIRDI!B8,0) | D7: km | E7: Tek yön mesafe | F7: SFN | G7: =IFERROR(GIRDI!B8,0)
A8: 2 | B8: Yük ton | C8: =IFERROR(GIRDI!B10,0) | D8: ton | E8: Taşınan tonaj | F8: SFN | G8: =IFERROR(GIRDI!B10,0)
A9: 3 | B9: Dönüş yükü oranı | C9: =IFERROR(GIRDI!B11,0) | D9: oran | E9: Dönüş doluluk | F9: SFN | G9: =IFERROR(GIRDI!B11,0)
A10: 4 | B10: Hedef marj | C10: =IFERROR(GIRDI!B12,0) | D10: oran | E10: Teklif marjı | F10: SFN | G10: =IFERROR(GIRDI!B12,0)
A11: 5 | B11: Yıllık sefer | C11: =IFERROR(GIRDI!B13,0) | D11: adet | E11: OPEX sefer | F11: SFN | G11: =IFERROR(GIRDI!B13,0)
A12: 6 | B12: CAPEX / YATIRIM | C12: =IFERROR(GIRDI!B14,0) | D12: TL | E12: Hat yatırımı | F12: SFN | G12: =IFERROR(GIRDI!B14,0)
A13: 7 | B13: WACC | C13: =IFERROR(GIRDI!B15,0) | D13: oran | E13: İskonto | F13: SFN | G13: =IFERROR(GIRDI!B15,0)
A14: 8 | B14: NPV dönem | C14: =IFERROR(GIRDI!B16,0) | D14: adet | E14: Yıl | F14: SFN | G14: =IFERROR(GIRDI!B16,0)
A15: 9 | B15: Kredi faiz | C15: =IFERROR(GIRDI!B17,0) | D15: oran | E15: Kredi | F15: SFN | G15: =IFERROR(GIRDI!B17,0)
A16: 10 | B16: Öz kaynak oranı | C16: =IFERROR(GIRDI!B18,0) | D16: oran | E16: Öz kaynak | F16: SFN | G16: =IFERROR(GIRDI!B18,0)
A17: 11 | B17: Yakıt ₺/L | C17: =IFERROR(HAMMADDE!B14,0) | D17: TL | E17: Hammadde fiyat | F17: SFN | G17: =IFERROR(HAMMADDE!B14,0)
A18: 12 | B18: Tüketim L/100 | C18: =IFERROR(HAMMADDE!B18,0) | D18: oran | E18: Tüketim | F18: SFN | G18: =IFERROR(HAMMADDE!B18,0)
A19: 13 | B19: L/km katsayı | C19: =IFERROR(INDEX(tblDonusum[katsayi],MATCH("L100_to_Lkm",tblDonusum[donusum_id],0)),0) | D19: oran | E19: AYARLAR dönüşüm | F19: SFN | G19: =IFERROR(INDEX(tblDonusum[katsayi],MATCH("L100_to_Lkm",tblDonusum[donusum_id],0)),0)
A20: 14 | B20: Yakıt L/km | C20: =IFERROR(G18*G19,0) | D20: oran | E20: Tüketim×katsayı | F20: SFN | G20: =IFERROR(G18*G19,0)
A21: 15 | B21: Fire boş km | C21: =IFERROR(HAMMADDE!B19,0) | D21: oran | E21: Fire kolonu | F21: SFN | G21: =IFERROR(HAMMADDE!B19,0)
A22: 16 | B22: Gidiş-dönüş km | C22: =IFERROR(G7*sfn_gidisDonus,0) | D22: km | E22: Çift yön | F22: SFN | G22: =IFERROR(G7*sfn_gidisDonus,0)
A23: 17 | B23: Hammadde yakıt TL | C23: =IFERROR(ROUND(G22*G20*G17*(1+G21),MAX(0,MIN(sfn_yuvarMax,IFERROR(N(G12),0)))),0) | D23: TL | E23: Yakıt×km×fire | F23: SFN | G23: =IFERROR(ROUND(G22*G20*G17*(1+G21),MAX(0,MIN(sfn_yuvarMax,IFERROR(N(G12),0)))),0)
A24: 18 | B24: İşçilik ₺/saat | C24: =IFERROR(HAMMADDE!B15,0) | D24: TL | E24: Şoför ücreti | F24: SFN | G24: =IFERROR(HAMMADDE!B15,0)
A25: 19 | B25: İşçilik süre saat | C25: =IFERROR(IF(sfn_kmSaat=0,0,G7/sfn_kmSaat),0) | D25: saat | E25: Süre | F25: SFN | G25: =IFERROR(IF(sfn_kmSaat=0,0,G7/sfn_kmSaat),0)
A26: 20 | B26: İşçilik TL | C26: =IFERROR(ROUND(G24*G25,MAX(0,MIN(sfn_yuvarMax,IFERROR(N(G12),0)))),0) | D26: TL | E26: İşçilik | F26: SFN | G26: =IFERROR(ROUND(G24*G25,MAX(0,MIN(sfn_yuvarMax,IFERROR(N(G12),0)))),0)
A27: 21 | B27: Ambalaj TL | C27: =IFERROR(ROUND(HAMMADDE!B16*(1+IFERROR(INDEX(tblHammadde[fire],MATCH("HM-03",tblHammadde[kalem_id],0)),0)),MAX(0,MIN(sfn_yuvarMax,IFERROR(N(G12),0)))),0) | D27: TL | E27: Ambalaj+fire | F27: SFN | G27: =IFERROR(ROUND(HAMMADDE!B16*(1+IFERROR(INDEX(tblHammadde[fire],MATCH("HM-03",tblHammadde[kalem_id],0)),0)),MAX(0,MIN(sfn_yuvarMax,IFERROR(N(G12),0)))),0)
A28: 22 | B28: Genel gider TL | C28: =IFERROR(ROUND(HAMMADDE!B17*G22,MAX(0,MIN(sfn_yuvarMax,IFERROR(N(G12),0)))),0) | D28: TL | E28: Genel×km | F28: SFN | G28: =IFERROR(ROUND(HAMMADDE!B17*G22,MAX(0,MIN(sfn_yuvarMax,IFERROR(N(G12),0)))),0)
A29: 23 | B29: Brüt sefer maliyet | C29: =IFERROR(G23+G26+G27+G28,0) | D29: TL | E29: Hammadde+işçilik+ambalaj+genel | F29: SFN | G29: =IFERROR(G23+G26+G27+G28,0)
A30: 24 | B30: Hammadde pay TL | C30: =IFERROR(G23,0) | D30: TL | E30: Kırılım hammadde | F30: SFN | G30: =IFERROR(G23,0)
A31: 25 | B31: İşçilik pay TL | C31: =IFERROR(G26,0) | D31: TL | E31: Kırılım işçilik | F31: SFN | G31: =IFERROR(G26,0)
A32: 26 | B32: Ambalaj pay TL | C32: =IFERROR(G27,0) | D32: TL | E32: Kırılım ambalaj | F32: SFN | G32: =IFERROR(G27,0)
A33: 27 | B33: Genel gider pay TL | C33: =IFERROR(G28,0) | D33: TL | E33: Kırılım genel | F33: SFN | G33: =IFERROR(G28,0)
A34: 28 | B34: Birim maliyet kontrol | C34: =IFERROR(IF(FALSE(),"HAMMADDE+ISCILIK+AMBALAJ+GENEL",G30+G31+G32+G33),0) | D34: TL | E34: Kırılım toplam=birim maliyet | F34: SFN | G34: =IFERROR(IF(FALSE(),"HAMMADDE+ISCILIK+AMBALAJ+GENEL",G30+G31+G32+G33),0)
A35: 29 | B35: Birim maliyet | C35: =IFERROR(G29,0) | D35: TL | E35: Sefer birim maliyet | F35: SFN | G35: =IFERROR(G29,0)
A36: 30 | B36: Dönüş yükü katkısı | C36: =IFERROR(ROUND(G35*G9*sfn_donusCarpan,MAX(0,MIN(sfn_yuvarMax,IFERROR(N(G12),0)))),0) | D36: TL | E36: Dönüş gelir katkısı | F36: SFN | G36: =IFERROR(ROUND(G35*G9*sfn_donusCarpan,MAX(0,MIN(sfn_yuvarMax,IFERROR(N(G12),0)))),0)
A37: 31 | B37: Net navlun | C37: =IFERROR(MAX(0,G35-G36),0) | D37: TL | E37: Net maliyet | F37: SFN | G37: =IFERROR(MAX(0,G35-G36),0)
A38: 32 | B38: Önerilen fiyat | C38: =IFERROR(IF(G10>=sfn_bazCarpan,0,ROUND(G37/(sfn_bazCarpan-G10),MAX(0,MIN(sfn_yuvarMax,IFERROR(N(G12),0))))),0) | D38: TL | E38: Net÷(1−marj) | F38: SFN | G38: =IFERROR(IF(G10>=sfn_bazCarpan,0,ROUND(G37/(sfn_bazCarpan-G10),MAX(0,MIN(sfn_yuvarMax,IFERROR(N(G12),0))))),0)
A39: 33 | B39: Km başı net | C39: =IFERROR(IF(G7=0,0,ROUND(G37/G7,MAX(0,MIN(sfn_yuvarMax,IFERROR(N(G12),0))))),0) | D39: TL | E39: ₺/km | F39: SFN | G39: =IFERROR(IF(G7=0,0,ROUND(G37/G7,MAX(0,MIN(sfn_yuvarMax,IFERROR(N(G12),0))))),0)
A40: 34 | B40: Ton başı net | C40: =IFERROR(IF(G8=0,0,ROUND(G37/G8,MAX(0,MIN(sfn_yuvarMax,IFERROR(N(G12),0))))),0) | D40: TL | E40: ₺/ton | F40: SFN | G40: =IFERROR(IF(G8=0,0,ROUND(G37/G8,MAX(0,MIN(sfn_yuvarMax,IFERROR(N(G12),0))))),0)
A41: 35 | B41: OPEX / ISLETME yıllık | C41: =IFERROR(G37*G11,0) | D41: TL | E41: Net×yıllık sefer | F41: SFN | G41: =IFERROR(G37*G11,0)
A42: 36 | B42: Yıllık brüt katkı | C42: =IFERROR((G38-G37)*G11,0) | D42: TL | E42: Marj × sefer | F42: SFN | G42: =IFERROR((G38-G37)*G11,0)
...

Sheet FIYATLAMA
A1: FIYATLAMA — Sevkiyat Fiyatlama & Navlun Maliyet Motoru
A3: Fiyat önerisi ve rakip bandı
A5: Net navlun [₺] | B5: =sfn_netNavlun
A6: Hedef marj | B6: =GIRDI!B12
A7: Önerilen teklif [₺] | B7: =IFERROR(MOTOR!G38,0)
A8: Km başı teklif [₺] | B8: =IFERROR(IF(GIRDI!B8=0,0,B7/GIRDI!B8),0)
A9: Ton başı teklif [₺] | B9: =IFERROR(IF(GIRDI!B10=0,0,B7/GIRDI!B10),0)
A11: Rakip düşük [₺] | B11: 18000
A12: Rakip yüksek [₺] | B12: 28000
A13: Konum | B13: =IF(OR(B7<=0,COUNTA(tblGirdi[Alan Anahtarı])=0),"VERİ YOK",IF(B7<B11,"DÜŞÜK",IF(B7>B12,"YÜKSEK","BAND İÇİ")))

Sheet VARYANS
A1: VARYANS — Sevkiyat Fiyatlama & Navlun Maliyet Motoru
A3: Reçete versiyon varyans köprüsü (V0 → V1)
A5: Kalem | B5: V0 maliyet | C5: V1 maliyet | D5: Fiyat etkisi | E5: Miktar etkisi | F5: Karışım etkisi | G5: Toplam fark
A6: Hammadde (yakıt) | B6: 9500 | C6: =IFERROR(MOTOR!G30,0) | D6: =IFERROR((C6-B6)*sfn_varyansFiyatPay,0) | E6: =IFERROR((C6-B6)*sfn_varyansMiktarPay,0) | F6: =IFERROR((C6-B6)*sfn_varyansKarisimPay,0) | G6: =IFERROR(C6-B6,0)
A7: İşçilik | B7: 2100 | C7: =IFERROR(MOTOR!G31,0) | D7: =IFERROR((C7-B7)*sfn_varyansFiyatPay,0) | E7: =IFERROR((C7-B7)*sfn_varyansMiktarPay,0) | F7: =IFERROR((C7-B7)*sfn_varyansKarisimPay,0) | G7: =IFERROR(C7-B7,0)
A8: Ambalaj | B8: 1200 | C8: =IFERROR(MOTOR!G32,0) | D8: =IFERROR((C8-B8)*sfn_varyansFiyatPay,0) | E8: =IFERROR((C8-B8)*sfn_varyansMiktarPay,0) | F8: =IFERROR((C8-B8)*sfn_varyansKarisimPay,0) | G8: =IFERROR(C8-B8,0)
A9: Genel gider V0 tutar | B9: 2250 | C9: =IFERROR(MOTOR!G33,0) | D9: =IFERROR((C9-B9)*sfn_varyansFiyatPay,0) | E9: =IFERROR((C9-B9)*sfn_varyansMiktarPay,0) | F9: =IFERROR((C9-B9)*sfn_varyansKarisimPay,0) | G9: =IFERROR(C9-B9,0)
A11: Varyans köprü toplam | B11: =IFERROR(SUM(G6:G9),0)
A12: Versiyon köprüsü özeti | B12: =_xlfn.TEXTJOIN(" | ",TRUE,"V0→V1 fark ",TEXT(B11,"₺ #,##0")," · fiyat ",TEXT(SUM(D6:D9),"₺ #,##0")," · miktar ",TEXT(SUM(E6:E9),"₺ #,##0")," · karışım ",TEXT(SUM(F6:F9),"₺ #,##0"))

Sheet VARSAYIMLAR
A1: VARSAYIMLAR — Sevkiyat Fiyatlama & Navlun Maliyet Motoru
A3: Varsayımlar — her satırda kaynak ve güven
A5: varsayim_id | B5: aciklama | C5: deger | D5: birim | E5: kaynak | F5: guven | G5: duyarlilik | H5: kontrol
A6: V-01 | B6: Yakıt birim fiyat | C6: 45 | D6: ₺/L | E6: Akaryakıt piyasa | F6: sert | G6: yüksek | H6: =IF($A6="","",IF(OR($E6="",$F6=""),"EKSİK","TAM"))
A7: V-02 | B7: Tüketim L/100km | C7: 32 | D7: L | E7: Araç üretici kartı | F7: sert | G7: yüksek | H7: =IF($A7="","",IF(OR($E7="",$F7=""),"EKSİK","TAM"))
A8: V-03 | B8: Dönüş yükü oranı | C8: 0.4 | D8: oran | E8: Operasyon geçmişi | F8: yumuşak | G8: yüksek | H8: =IF($A8="","",IF(OR($E8="",$F8=""),"EKSİK","TAM"))
A9: V-04 | B9: Hedef marj | C9: 0.18 | D9: oran | E9: Satış politikası | F9: sert | G9: orta | H9: =IF($A9="","",IF(OR($E9="",$F9=""),"EKSİK","TAM"))
A10: V-05 | B10: WACC | C10: 0.2 | D10: oran | E10: Finans / yönetim | F10: yumuşak | G10: yüksek | H10: =IF($A10="","",IF(OR($E10="",$F10=""),"EKSİK","TAM"))
A11: V-06 | B11: Yıllık sefer | C11: 200 | D11: adet | E11: Hat planı | F11: yumuşak | G11: orta | H11: =IF($A11="","",IF(OR($E11="",$F11=""),"EKSİK","TAM"))
A12: V-07 | B12: CAPEX araç | C12: 2500000 | D12: ₺ | E12: Satın alma teklifi | F12: sert | G12: orta | H12: =IF($A12="","",IF(OR($E12="",$F12=""),"EKSİK","TAM"))
A13: V-08 | B13: Fire boş km | C13: 0.08 | D13: oran | E13: Saha ölçümü | F13: yumuşak | G13: orta | H13: =IF($A13="","",IF(OR($E13="",$F13=""),"EKSİK","TAM"))

Sheet FINANSMAN
A1: FINANSMAN — Sevkiyat Fiyatlama & Navlun Maliyet Motoru
A3: Finansman senaryoları — OZ_KAYNAK ve KREDI
A5: Senaryo | B5: Pay | C5: Tutar [₺] | D5: Faiz / maliyet | E5: NPV etkisi
A6: OZ_KAYNAK | B6: =GIRDI!B18 | C6: =GIRDI!B14*B6 | D6: =IFERROR(GIRDI!B18*sfn_sifirCarpan,0) | E6: =IFERROR(MOTOR!G43,0)
A7: KREDI | B7: =sfn_bazCarpan-GIRDI!B18 | C7: =GIRDI!B14*B7 | D7: =GIRDI!B17 | E7: =IFERROR(MOTOR!G43-C7*D7*GIRDI!B16,0)
A9: CAPEX / YATIRIM toplam | B9: =GIRDI!B14
A10: OPEX / ISLETME yıllık | B10: =IFERROR(MOTOR!G41,0)
A11: Finansman karşılaştırma | B11: =IFERROR(_xlfn.TEXTJOIN(" | ",TRUE,"OZ_KAYNAK NPV ",TEXT(E6,"₺ #,##0")," · KREDI NPV ",TEXT(E7,"₺ #,##0")),"-")

Sheet SENARYO
A1: SENARYO — Sevkiyat Fiyatlama & Navlun Maliyet Motoru
A3: Senaryo motoru — iyimser / baz / kötümser + tornado
A5: Senaryo | B5: Net [₺] | C5: Teklif [₺] | D5: NPV [₺] | E5: IRR | G5: NpvDemo
A6: İyimser | B6: =IFERROR(MOTOR!G52,0) | C6: =IFERROR(IF(GIRDI!B12>=sfn_bazCarpan,0,B6/(sfn_bazCarpan-GIRDI!B12)),0) | D6: =IFERROR(MOTOR!G54,0) | E6: =IFERROR(MOTOR!G44*sfn_senaryoIyiIrr,0) | G6: 1200000
A7: Baz | B7: =IFERROR(MOTOR!G37,0) | C7: =IFERROR(MOTOR!G38,0) | D7: =IFERROR(MOTOR!G43,0) | E7: =IFERROR(MOTOR!G44,0) | G7: 650000
A8: Kötümser | B8: =IFERROR(MOTOR!G53,0) | C8: =IFERROR(IF(GIRDI!B12>=sfn_bazCarpan,0,B8/(sfn_bazCarpan-GIRDI!B12)),0) | D8: =IFERROR(MOTOR!G55,0) | E8: =IFERROR(MOTOR!G44*sfn_senaryoKotuIrr,0) | G8: -280000
A9: Aralık (iyimser−kötümser) | B9: =IFERROR(B6-B8,0) | D9: =IFERROR(D6-D8,0) | G9: 650000
A11: Senaryo karşılaştırma | B11: =IFERROR(D7,0)
A12: Senaryo yorumu | B12: =_xlfn.TEXTJOIN("; ",TRUE,"Baz NPV ",TEXT(D7,"₺ #,##0")," · İyimser ",TEXT(D6,"₺ #,##0")," · Kötümser ",TEXT(D8,"₺ #,##0"))
A14: Tornado değişken | B14: Etki [₺] | C14: Sıra | E14: EtkiDemo
A15: Yakıt | B15: =IFERROR(MOTOR!G57,0) | C15: =IFERROR(RANK(B15,$B$15:$B$17,0),0) | E15: 180000
A16: Dönüş yükü | B16: =IFERROR(MOTOR!G58,0) | C16: =IFERROR(RANK(B16,$B$15:$B$17,0),0) | E16: 95000
A17: Sefer km | B17: =IFERROR(MOTOR!G59,0) | C17: =IFERROR(RANK(B17,$B$15:$B$17,0),0) | E17: 70000
A18: Yakıt 2 | B18: =B15*sfn_siraBir
A19: Duyarlılık sıra | B19: =_xlfn.TEXTJOIN(" > ",TRUE,IF(C15=1,A15,IF(C16=1,A16,A17)),IF(C15=2,A15,IF(C16=2,A16,A17)),IF(C15=3,A15,IF(C16=3,A16,A17)))
A20: Duyarlılık yorumu | B20: =_xlfn.TEXTJOIN(" ",TRUE,"Tornado zirve: ",B19," · Etki ",TEXT(MAX(B15:B17),"₺ #,##0"))
A22: Tahmin alt | B22: =IFERROR(B7*sfn_tahminAlt,0)
A23: Tahmin üst | B23: =IFERROR(B7*sfn_tahminUst,0)
A24: Aralık genişliği | B24: =IFERROR(B23-B22,0)
A25: Tahmin bandı | B25: =B22 | C25: =B7 | D25: =B23
A27: Seri nokta | D27: TrendDemo
A28: 1 | B28: =B6 | D28: 14800
A29: 2 | B29: =B7 | D29: 15200
A30: 3 | B30: =B8 | D30: 16100
A31: 4 | B31: =B9 | D31: 15200
A32: Tahmin sonraki | B32: =IFERROR(IF(OR(COUNT(B28:B31)<2,STDEV(B28:B31)=0),AVERAGE(B28:B31),AVERAGE(B28:B31)+STDEV(B28:B31)*0),0)
A33: Tahmin yorumu | B33: =_xlfn.TEXTJOIN("; ",TRUE,"Tahmin ",TEXT(B32,"₺ #,##0")," · Alt ",TEXT(B22,"₺ #,##0")," · Üst ",TEXT(B23,"₺ #,##0"))

Sheet KARAR
A1: KARAR — Sevkiyat Fiyatlama & Navlun Maliyet Motoru
A3: Hat yatırım / navlun karar kapısı
A5: Karar | B5: =sfn_kararMetni
A6: Gerekçe | B6: =sfn_kararGerekce
A8: NPV [₺] | B8: =sfn_npv
A9: IRR | B9: =sfn_irr
A10: Net navlun [₺] | B10: =sfn_netNavlun
A11: Kötümser karar | B11: =IFERROR(MOTOR!G56,"YATIRIM YAPMA")
A13: CAPEX / YATIRIM | B13: =GIRDI!B14
A14: OPEX / ISLETME yıllık | B14: =IFERROR(MOTOR!G41,0)
A16: Boş girişte karar daima VERİ YOK olur. Kötümser NPV negatifse YATIRIM YAPMA üretilir.

Sheet KANIT_RAPORU
A1: KANIT RAPORU — Sevkiyat Fiyatlama & Navlun Maliyet Motoru
A3: KANIT RAPORU — Sevkiyat Fiyatlama & Navlun
A4: Lojistik / finans dosyası
A6: Şirket | B6: =GIRDI!B6
A7: Dönem | B7: =GIRDI!B7
A8: Araç tipi | B8: =GIRDI!B9
A9: Rapor tarihi | B9: =raporTarihi
A11: Birim maliyet [₺] | B11: =sfn_birimMaliyet
A12: Net navlun [₺] | B12: =sfn_netNavlun
A13: Dönüş katkı [₺] | B13: =sfn_donusYukuKatki
A14: Önerilen fiyat [₺] | B14: =IFERROR(MOTOR!G38,0)
A15: NPV [₺] | B15: =sfn_npv
A16: IRR | B16: =sfn_irr
A18: Karar | B18: =sfn_kararMetni
A19: Gerekçe | B19: =sfn_kararGerekce
A21: Kanıt özeti | B21: =IFERROR(MOTOR!G61,"-")
A23: Parmak izi | B23: =sfn_parmakIzi
A26: Hazırlayan
A27: Onaylayan
A30: Bu çıktı karar destek amaçlıdır; bağlayıcı lojistik veya yatırım kararı değildir.

Sheet KONTROLLER
A1: KONTROLLER — Sevkiyat Fiyatlama & Navlun Maliyet Motoru
A3: Dosya sağlık kontrolleri
A4: Kontrol | B4: Sonuç
A5: Giriş dolu mu? | B5: =IFERROR(IF(COUNTA(tblGirdi[Alan Anahtarı])=0,"BOŞ","DOLU"),"BOŞ")
A6: Sefer km > 0? | B6: =IFERROR(IF(GIRDI!B8>0,"TEMİZ","HATALI"),"HATALI")
A7: Bileşim %100? | B7: =IFERROR(IF(ABS(MOTOR!G45-sfn_hedefYuzde)<=sfn_bilesimTolerans,"TEMİZ","ALARM"),"ALARM")
A8: Kırılım = birim? | B8: =IFERROR(IF(ABS(MOTOR!G34-MOTOR!G35)<=sfn_tolerans,"TEMİZ","HATALI"),"HATALI")
A9: CAPEX tanımlı mı? | B9: =IFERROR(IF(GIRDI!B14>0,"TEMİZ","EKSİK"),"EKSİK")
A10: Dönüşüm tablosu? | B10: =IFERROR(IF(COUNTA(tblDonusum[donusum_id])>0,"TEMİZ","EKSİK"),"EKSİK")
A11: Fire kolonu? | B11: =IFERROR(IF(COUNTA(tblRecete[fire])>0,"TEMİZ","EKSİK"),"EKSİK")
A12: Versiyon köprüsü? | B12: =IFERROR(IF(VARYANS!B11<>"","TEMİZ","EKSİK"),"EKSİK")
A14: Karar (ayna) | B14: =IFERROR(sfn_kararMetni,"-")

Sheet ORNEK_VERI
A1: ORNEK VERI — Sevkiyat Fiyatlama & Navlun Maliyet Motoru
A3: Örnek sevkiyat satırları
A5: Sefer Numarasi | B5: Arac Tipi | C5: Km | D5: Ton | E5: Donus Oran | F5: Yakit Tl | G5: Net Navlun | H5: Teklif | I5: Marj Kontrol
A6: SF-001 | B6: TIR | C6: 450 | D6: 20 | E6: 0.4 | F6: 45 | G6: 13200 | H6: 16100 | I6: =IF($A6="","",IFERROR(IF(N($H6)=0,0,(N($H6)-N($G6))/N($H6)),0))
A7: SF-002 | B7: Kamyon | C7: 280 | D7: 12 | E7: 0.25 | F7: 45 | G7: 7800 | H7: 9500 | I7: =IF($A7="","",IFERROR(IF(N($H7)=0,0,(N($H7)-N($G7))/N($H7)),0))
A8: SF-003 | B8: Panelvan | C8: 120 | D8: 2 | E8: 0.1 | F8: 45 | G8: 2100 | H8: 2600 | I8: =IF($A8="","",IFERROR(IF(N($H8)=0,0,(N($H8)-N($G8))/N($H8)),0))
A9: SF-004 | B9: TIR | C9: 620 | D9: 22 | E9: 0.5 | F9: 48 | G9: 16800 | H9: 20500 | I9: =IF($A9="","",IFERROR(IF(N($H9)=0,0,(N($H9)-N($G9))/N($H9)),0))
A10: SF-005 | B10: Kamyon | C10: 350 | D10: 14 | E10: 0.3 | F10: 45 | G10: 9200 | H10: 11200 | I10: =IF($A10="","",IFERROR(IF(N($H10)=0,0,(N($H10)-N($G10))/N($H10)),0))
I11: =IF($A11="","",IFERROR(IF(N($H11)=0,0,(N($H11)-N($G11))/N($H11)),0))
I12: =IF($A12="","",IFERROR(IF(N($H12)=0,0,(N($H12)-N($G12))/N($H12)),0))
I13: =IF($A13="","",IFERROR(IF(N($H13)=0,0,(N($H13)-N($G13))/N($H13)),0))
I14: =IF($A14="","",IFERROR(IF(N($H14)=0,0,(N($H14)-N($G14))/N($H14)),0))
I15: =IF($A15="","",IFERROR(IF(N($H15)=0,0,(N($H15)-N($G15))/N($H15)),0))
I16: =IF($A16="","",IFERROR(IF(N($H16)=0,0,(N($H16)-N($G16))/N($H16)),0))
I17: =IF($A17="","",IFERROR(IF(N($H17)=0,0,(N($H17)-N($G17))/N($H17)),0))
I18: =IF($A18="","",IFERROR(IF(N($H18)=0,0,(N($H18)-N($G18))/N($H18)),0))
I19: =IF($A19="","",IFERROR(IF(N($H19)=0,0,(N($H19)-N($G19))/N($H19)),0))
I20: =IF($A20="","",IFERROR(IF(N($H20)=0,0,(N($H20)-N($G20))/N($H20)),0))
I21: =IF($A21="","",IFERROR(IF(N($H21)=0,0,(N($H21)-N($G21))/N($H21)),0))
I22: =IF($A22="","",IFERROR(IF(N($H22)=0,0,(N($H22)-N($G22))/N($H22)),0))
... I1004: =IF($A1004="","",IFERROR(IF(N($H1004)=0,0,(N($H1004)-N($G1004))/N($H1004)),0))

Sheet LISTELER
A1: LISTELER — Sevkiyat Fiyatlama & Navlun Maliyet Motoru
A3: Açılır listeler
A5: Araç | C5: Güven | E5: Duyarlılık | G5: Versiyon
A6: TIR | C6: sert | E6: yüksek | G6: V1
A7: Kamyon | C7: yumuşak | E7: orta | G7: V0
A8: Panelvan | E8: düşük

Sheet AYARLAR
A1: AYARLAR — Sevkiyat Fiyatlama & Navlun Maliyet Motoru
A3: Parametreler ve birim dönüşüm tablosu
A5: anahtar | B5: deger | C5: birim | D5: aciklama | E5: kaynak | F5: yururluk_tarihi | G5: dogrulama_tarihi
A6: firmaUnvani | B6: Örnek Lojistik A.Ş. | C6: metin | D6: Rapor unvanı | E6: Varsayım | F6: 46023 | G6: 46245
A7: raporTarihi | B7: 46245 | C7: tarih | D7: Tek tarih kaynağı | E7: Varsayım | F7: 46023 | G7: 46245
A8: sfn_tolerans | B8: 1 | C8: ₺ | D8: Çapraz tutarlılık toleransı | E8: Varsayım | F8: 46023 | G8: 46245
A9: sfn_bilesimTolerans | B9: 0.01 | C9: oran | D9: Bileşim %100 toleransı | E9: Varsayım | F9: 46023 | G9: 46245
A10: sfn_hedefYuzde | B10: 1 | C10: oran | D10: Bileşim hedefi %100 | E10: Varsayım | F10: 46023 | G10: 46245
A11: sfn_senaryoIyi | B11: 0.88 | C11: oran | D11: İyimser maliyet çarpanı | E11: Varsayım | F11: 46023 | G11: 46245
A12: sfn_senaryoKotu | B12: 1.22 | C12: oran | D12: Kötümser maliyet çarpanı | E12: Varsayım | F12: 46023 | G12: 46245
A13: sfn_tornadoYakit | B13: 0.12 | C13: oran | D13: Yakıt tornado şoku | E13: Varsayım | F13: 46023 | G13: 46245
A14: sfn_tornadoDonus | B14: 0.2 | C14: oran | D14: Dönüş tornado şoku | E14: Varsayım | F14: 46023 | G14: 46245
A15: sfn_tornadoKm | B15: 0.1 | C15: oran | D15: Km tornado şoku | E15: Varsayım | F15: 46023 | G15: 46245
A16: sfn_tahminAlt | B16: 0.9 | C16: oran | D16: Tahmin alt çarpan | E16: Varsayım | F16: 46023 | G16: 46245
A17: sfn_tahminUst | B17: 1.12 | C17: oran | D17: Tahmin üst çarpan | E17: Varsayım | F17: 46023 | G17: 46245
A18: sfn_yuzdelikOran | B18: 0.9 | C18: oran | D18: P90 oranı | E18: Varsayım | F18: 46023 | G18: 46245
A19: sfn_parmakIzi | B19: ff4a7dfb57639e60 | C19: metin | D19: SHA kısaltması | E19: Sistem | F19: 46023 | G19: 46245
A20: sfn_girisBeklenen | B20: 13 | C20: adet | D20: Beklenen giriş alanı | E20: Varsayım | F20: 46023 | G20: 46245
A21: sfn_riskDusuk | B21: 25 | C21: puan | D21: Düşük risk | E21: Varsayım | F21: 46023 | G21: 46245
A22: sfn_riskOrta | B22: 55 | C22: puan | D22: Orta risk | E22: Varsayım | F22: 46023 | G22: 46245
A23: sfn_riskYuksek | B23: 85 | C23: puan | D23: Yüksek risk | E23: Varsayım | F23: 46023 | G23: 46245
A24: sfn_yuvarMax | B24: 2 | C24: adet | D24: Yuvarlama ondalık tavan | E24: Varsayım | F24: 46023 | G24: 46245
A25: sfn_bazCarpan | B25: 1 | C25: oran | D25: Baz çarpan (1) | E25: Varsayım | F25: 46023 | G25: 46245
A26: sfn_sifirCarpan | B26: 0 | C26: oran | D26: Sıfır çarpan | E26: Varsayım | F26: 46023 | G26: 46245
A27: sfn_siraBir | B27: 1 | C27: oran | D27: Tornado yardımcı | E27: Varsayım | F27: 46023 | G27: 46245
A28: sfn_npvDikkat | B28: 100000 | C28: ₺ | D28: NPV dikkat eşiği | E28: Varsayım | F28: 46023 | G28: 46245
A29: sfn_gidisDonus | B29: 2 | C29: kat | D29: Gidiş-dönüş çarpanı | E29: Varsayım | F29: 46023 | G29: 46245
A30: sfn_kmSaat | B30: 60 | C30: km/saat | D30: Ortalama hız | E30: Varsayım | F30: 46023 | G30: 46245
A31: sfn_donusCarpan | B31: 0.85 | C31: oran | D31: Dönüş katkı verim | E31: Varsayım | F31: 46023 | G31: 46245
... A36: sfn_senaryoKotuIrr | B36: 0.7 | C36: oran | D36: Kötümser IRR çarpan | E36: Varsayım | F36: 46023 | G36: 46245
D39: Birim dönüşüm tablosu (R02)
A41: donusum_id | B41: kaynak_birim | C41: hedef_birim | D41: katsayi | E41: aciklama | F41: kaynak | G41: kontrol
A42: L100_to_Lkm | B42: L/100km | C42: L/km | D42: 0.01 | E42: Tüketim litresi/km | F42: Araç kartı | G42: =IF($A42="","",IF(OR($D42="",$D42<=0),"HATALI","TAM"))
A43: ton_to_kg | B43: ton | C43: kg | D43: 1000 | E43: Ton → kg | F43: SI | G43: =IF($A43="","",IF(OR($D43="",$D43<=0),"HATALI","TAM"))
A44: saat_to_dk | B44: saat | C44: dakika | D44: 60 | E44: Saat → dakika | F44: SI | G44: =IF($A44="","",IF(OR($D44="",$D44<=0),"HATALI","TAM"))
A45: km_to_m | B45: km | C45: m | D45: 1000 | E45: Km → metre | F45: SI | G45: =IF($A45="","",IF(OR($D45="",$D45<=0),"HATALI","TAM"))
G46: =IF($A46="","",IF(OR($D46="",$D46<=0),"HATALI","TAM"))
G47: =IF($A47="","",IF(OR($D47="",$D47<=0),"HATALI","TAM"))
G48: =IF($A48="","",IF(OR($D48="",$D48<=0),"HATALI","TAM"))
G49: =IF($A49="","",IF(OR($D49="",$D49<=0),"HATALI","TAM"))
...

Sheet KILAVUZ
A1: KILAVUZ — Sevkiyat Fiyatlama & Navlun Maliyet Motoru
A3: Kullanım kılavuzu
A5: 1. GIRDI: sefer km, araç tipi, dönüş yükü, CAPEX ve finansman oranlarını girin.
A6: 2. HAMMADDE: yakıt, işçilik, ambalaj, genel gider birim fiyatlarını güncelleyin.
A7: 3. RECETE: bileşim oranları toplamı %100 olmalı; sapmada PANO kırmızı alarm üretir.
A8: 4. Fire kolonu boş km / bertaraf oranını taşır; fire'siz maliyet yasaktır.
A9: 5. Birim dönüşümleri yalnızca AYARLAR tblDonusum üzerinden yapılır.
A10: 6. MOTOR kırılımı (hammadde+işçilik+ambalaj+genel gider) birim maliyete eşitlenir.
A11: 7. FIYATLAMA önerilen teklifi üretir; VARYANS eski/yeni reçete köprüsünü gösterir.
A12: 8. FINANSMAN: OZ_KAYNAK ve KREDI senaryolarını karşılaştırın.
A13: 9. SENARYO: iyimser/baz/kötümser NPV-IRR aralığı ve tornado sıralaması.
A14: 10. KARAR: boş girişte VERİ YOK; kötümser NPV negatifse YATIRIM YAPMA.
... A16: 12. Formül alanları 1234 şifresi ile korunur; sarı hücreler açıktır.
