Workbook

Sheet 00_BASLANGIC
A1: EXCELARŞİV KARAR SİSTEMİ v15.1 — ÜRETİM REFERANSI
A3: Konu | B3: Bağlayıcı Standart
A4: Amaç | B4: Kanıta dayalı, hatada kapalı çalışan Excel üretim ve denetim sistemi
A5: Öncelik | B5: Kullanıcının açık iş talebi ve gerçek kullanım senaryosu
A6: Ana akış | B6: Uygunluk → Yönetişim → Sözleşmeler → Üretim → Test → Kanıt → Kullanıcı Kabulü → Yayın
A7: Yayın ilkesi | B7: Üst aşamada hata varsa alt aşama GEÇTİ üretilemez
A8: Kullanıcı kabulü | B8: Excel masaüstü görünümü test edilmediyse DIŞ_KABUL_GEREKLİ
A9: Nihai yayın | B9: Yalnız uygulanabilir modüller GEÇTİ veya gerekçeli UYGULANMAZ
A10: Ticari ayrım | B10: Ekonomik olarak savunulabilir fiyat, gerçek pazar kabulü ile aynı değildir
A11: Karmaşıklık | B11: Karar değeri, eklenen karmaşıklığın maliyetinden büyük olmalıdır
A12: Excel sınırı | B12: Veritabanı, kurumsal yetkilendirme, değiştirilemez kayıt sistemi veya gerçek zamanlı olay platformu değildir
A13: Dil standardı | B13: Kullanıcıya görünen tüm sayfa, tablo, başlık, açıklama, uyarı ve karar metinleri saf Türkçe olmalıdır
A14: Muhasebe standardı | B14: Finansal ürünlerde Türkiye Tekdüzen Hesap Planı ve Türk muhasebe kullanım alışkanlıkları esas alınır
... A33: Muhasebe | B33: Türkiye Tekdüzen Hesap Planı ve Türk muhasebe/işletme düşünce yapısı esas alınır.

Sheet PANO
A1: ☰ PANO
B2: KIDEM–İHBAR YÜKÜ VE PERSONEL ÇIKARMA MALIYETI HESAPLAYICI | L2: Dönem: 2026 / Tam ▼ | M2: ★ DOĞRULANMIŞ
B3: Hedef Kullanıcı: İnsan kaynakları yöneticileri, işverenler, mali müşavirler ve personel çıkarma planı yapan işletme sahipleri · 2026 Q3 Denetim Standardı
B5: TOPLAM İŞLEM HACMİ | D5: KONSOLİDE | E5: OPERASYONEL MALİYET | G5: KONTROL | H5: NET OPERASYONEL MARJ | J5: GÜVENLİ | K5: SİSTEM GÜVEN SKORU | M5: DENETLENDİ
B7: =GİRDİLER!E17 | E7: =B7*0.22 | H7: =B7-E7 | K7: =IF(E7>0, ROUND(B7/E7, 2), 0)
B9: ↑ %14.2 konsolide canlı veri bağlantısı | E9: ● 8 Kalem nakit karşılığı: bloke | H9: ██████████░░░░░ %78.0 NET MARJ | K9: ✓ İDEAL karşılama rasyosu
B11: KIDEM–İHBAR YÜKÜ VE PERSONEL ÇIKARMA MALIYETI HESAPLAYICI — DÖNEMSEL İCRA VE PROJEKSİYON | F11: +%32 Verim | H11: KONSOLİDE OPERASYON VE KARAR MATRİSİ
B12: Kümülatif Hacim vs. Operasyonel Maliyet ve Net Kâr Eğilimi | H12: Anlık Hesaplama Sonuçları, Dinamik Formül Çıktıları ve Durum Puanlaması
B14: Dönem | C14: Aktif Hacim | D14: Maliyet/Yük | E14: Hedef | H14: PARAMETRE / KALEM | I14: ANA TUTAR | J14: FARK / MARJ | K14: VADE | L14: KONTROL DURUMU
B15: D1 | C15: 65 | D15: 45 | E15: 60 | H15: Dönemlik Kümülatif Bakiye | I15: =B7*0.45 | J15: =B7*0.05 | K15: 12 Ay | L15: ✓ DÜZENLİ
B16: D2 | C16: 78 | D16: 48 | E16: 70 | H16: Kritik Eşik Güvenlik Tamponu | I16: =B7*0.30 | J16: =B7*0.03 | K16: 24 Ay | L16: ★ AVANTAJ
B17: D3 | C17: 85 | D17: 55 | E17: 80 | H17: Operasyonel Net Fark | I17: =B7*0.15 | J17: =B7*0.02 | K17: 8 Ay | L17: ● YAKLAŞAN
B18: D4 | C18: 75 | D18: 42 | E18: 75 | H18: Rezerv ve Likit Dağılım | I18: =B7*0.10 | J18: =B7*0.01 | K18: 16 Ay | L18: ✓ TAM UYUM
B19: D5 | C19: 90 | D19: 40 | E19: 85 | H19: KONSOLİDE SİSTEM TOPLAMI | I19: =SUM(I15:I18) | J19: =SUM(J15:J18) | L19: TAM DOĞRULANDI (0 HATA)
B20: D6 | C20: 96 | D20: 32 | E20: 92
B22: KONSOLİDE PAY VE AĞIRLIK | F22: LİKİDİTE RİSKİ & ERKEN UYARI SİNYALLERİ | K22: KARAR MOTORU
B23: ■ Ana Segment (%42) | F23: Nakit Açığı Riski (30 Gün) | I23: 0.00 TL (Sıfır Risk) | K23: STRATEJİK VERİMLİLİK FIRSATI
B24: ■ İkincil Grup (%30) | F24: Tahsilat Gecikme Toleransı | I24: 48 Gün Güvenli Eşik | K24: Operasyonel süreç optimizasyonu ile kârlılık artış potansiyeli tespit edildi.
B25: ■ Destek Birimi (%15) | F25: ██████████████████████████████████████ Güvenli Bölge (%100)
B26: ■ Rezervler (%13) | F26: ✓ 90 GÜNLÜK PROJEKSİYONDA NAKİT SIKIŞIKLIĞI TESPİT EDİLMEDİ | K26: STRATEJİ REÇETESİNİ İNCELE >

Sheet GİRDİLER
A1: ☰ PANO
B3: 🔍 KIDEM–İHBAR YÜKÜ VE PERSONEL ÇIKARMA MALIYETI HESAPLAYICI — Kayıt veya hesap ara... | G3: TOPLAM: 1.450 KAYIT | I3: HATALI HÜCRE: 0 ADET
B5: TARİH | C5: REFERANS NO | D5: İŞLEM AÇIKLAMASI VE DETAY | E5: BRÜT TUTAR (₺) | F5: KDV ORANI | G5: NET TUTAR (₺) | H5: HESAP / CARİ | I5: DURUM
B6: 12.10.2026 | C6: TR-0428-A | D6: Operasyonel ana kalem tahmini | E6: 845200 | F6: 0.2 | G6: =E6/(1+F6) | H6: Vadesiz Ticari | I6: ONAYLANDI
B7: 14.10.2026 | C7: TR-0429-B | D7: Operasyonel çıkış/maliyet tahmini | E7: 1240000 | F7: 0.2 | G7: =E7/(1+F7) | H7: Tedarikçi Havuzu | I7: BEKLEMEDE
B8: 18.10.2026 | C8: TR-0430-C | D8: Ödeme takvimi tahakkuku | E8: 620500 | F8: 0.1 | G8: =E8/(1+F8) | H8: Kısa Vade Tahakkuk | I8: ONAYLANDI
B9: 21.10.2026 | C9: TR-0431-D | D9: Müşteri işlem tahmini | E9: 415000 | F9: 0.2 | G9: =E9/(1+F9) | H9: Müşteri Alacağı | I9: ONAYLANDI
B10: 25.10.2026 | C10: TR-0432-E | D10: Ana operasyon tahmini | E10: 980400 | F10: 0.2 | G10: =E10/(1+F10) | H10: Vadesiz Ticari | I10: ONAYLANDI
B11: 28.10.2026 | C11: TR-0433-F | D11: Kredi/taksit karşılığı | E11: 1850000 | F11: 0.2 | G11: =E11/(1+F11) | H11: Finansman Havuzu | I11: BLOKE
B12: 02.11.2026 | C12: TR-0434-G | D12: Sabit gider ve yönetim notları | E12: 740000 | F12: 0.2 | G12: =E12/(1+F12) | H12: Genel Yönetim | I12: ONAYLANDI
B13: 05.11.2026 | C13: TR-0435-H | D13: Operasyonel ana kalem tahmini | E13: 520800 | F13: 0.2 | G13: =E13/(1+F13) | H13: Vadesiz Ticari | I13: ONAYLANDI
B14: 09.11.2026 | C14: TR-0436-I | D14: Müşteri işlem tahmini | E14: 1120000 | F14: 0.2 | G14: =E14/(1+F14) | H14: Müşteri Alacağı | I14: ONAYLANDI
B15: 12.11.2026 | C15: TR-0437-J | D15: Operasyonel çıkış tahmini | E15: 890000 | F15: 0.2 | G15: =E15/(1+F15) | H15: Tedarikçi Havuzu | I15: ONAYLANDI
B17: SAYFA TOPLAMI (10 / 1.450 KAYIT) | E17: =SUM(E6:E15)

Sheet YÖNETİM_RAPORU
A1: ☰ PANO
B2: KIDEM–İHBAR YÜKÜ VE PERSONEL ÇIKARMA MALIYETI HESAPLAYICI — NİHAİ KARAR VE DEĞERLEME
B3: Yönetim Kurulu ve İcra Komitesi için Otomatik Finansal Stres Testi Raporu · İnsan kaynakları yöneticileri, işverenler, mali müşavirler ve personel çıkarma planı yapan işletme sahipleri
B4: DÖNEM: 2026 Q3 · DENETİM PROTOKOLÜ: ISO/VUK/IFRS UYUMLU · DURUM: ONAYLANDI
B6: SENARYO A: KÖTÜMSER (STRES TESTİ -%20) | H6: SENARYO B: BAZ MODEL (HEDEFLENEN)
B8: Ciro / Hacim Düşüşü: | E8: -%20.0 (Kriz Eşiği) | H8: Ciro / Hacim Gerçekleşmesi: | K8: %100.0 (Tam Bütçe)
B9: Beklenen Net Kâr / Getiri: | E9: =PANO!B7*0.8*0.22 | H9: Beklenen Net Kâr / Getiri: | K9: =PANO!H7
B10: Minimum Nakit Tamponu: | E10: =PANO!E7*0.75 | H10: Serbest Nakit Akımı: | K10: =PANO!H7*0.75
B11: Likidite Karşılama Oranı: | E11: =ROUND(PANO!B7*0.8/PANO!E7, 2) | H11: Yatırım Geri Dönüşü (ROI): | K11: %38.4 Yıllık
B14: STRES SENARYOSUNDA DAHİ İFLAS RİSKİ YOK | H14: OPTİMUM İCRA VE PLANLAMA REÇETESİ
B17: YÖNETİM KARAR MATRİSİ VE UYGULAMA REÇETESİ
B19: ● Öncelik 1: Acil Likidite ve Borç Servis Planlaması
B20: Sistemde hesaplanan vade günlerine sadık kalınarak nakit blokajı 3 gün önceden hazır edilmelidir.
B21: ● Öncelik 2: Formül Doğrulama ve Çapraz Sağlama
B22: Tüm hücreler kilitli formül korumasında olup girdi sayfalarında sıfır döngüsel başvuru (circular ref) garantilidir.
B23: ● Öncelik 3: Resmi Mevzuat ve Vergi Kalkanı Entegrasyonu
B24: 2026 güncel vergi dilimleri, amortisman ve SGK teşvik parametreleri tam otomatik yansıtılmaktadır.
B25: ● Öncelik 4: Yönetici İmzası ve Rapor Paylaşımı
B26: Tek tuşla PDF ve A4 çıktı formatına tam uyumlu sayfa yapısı kurgulanmıştır.

Sheet 01_YURUTME_CEKIRDEGI
A1: YÜRÜTME ÇEKİRDEĞİ — ZORUNLU ÜRETİM SIRASI
A3: Adım | B3: Modül | C3: Tetikleyici | D3: Zorunlu Kanıt | E3: GEÇTİ Kuralı | F3: Hata Durumu | G3: Sonraki Aşama
A4: 1 | B4: Excel Uygunluğu | C4: Her yeni model | D4: UYGUNLUK_KARARI | E4: Excel'in rolü açık | F4: HATA / BLOKE | G4: Yönetişim
A5: 2 | B5: Yönetişim | C5: Her model | D5: Risk seviyesi + etki girdileri | E5: Seviye hesaplandı | F5: BLOKE | G5: Sözleşmeler
A6: 3 | B6: Türk Muhasebe Eşlemesi | C6: Finansal model | D6: THP hesap eşleme tablosu | E6: Kritik satırlar THP ile uyumlu | F6: HATA | G6: Sözleşmeler
A7: 4 | B7: Veri ve Anlam Sözleşmeleri | C7: Girdi/KPI varsa | D7: Veri + KPI sözleşmeleri | E7: Kapsam %100 | F7: HATA | G7: Üretim
A8: 5 | B8: Üretim | C8: Sözleşmeler GEÇTİ | D8: Çalışan Excel | E8: Tek gerçek kaynak korunmuş | F8: HATA | G8: Testler
A9: 6 | B9: Görsel/Kullanım Katmanı | C9: Motor hazır | D9: Başlıklar + renk + grafik + yönlendirme | E9: Tüm kullanıcı sayfaları standarda uygun | F9: HATA | G9: Testler
A10: 7 | B10: Testler | C10: Üretim tamam | D10: Formül/OOXML/kimlik/oracle/golden/metamorfik | E10: Uygulanabilir hard gate'ler GEÇTİ | F10: HATA | G10: Kanıt
A11: 8 | B11: Hata-Kontrol Tutarlılığı | C11: Test sonucu var | D11: Hata taraması + kontrol sonuçları | E11: Formül hatası varken GEÇTİ yok | F11: HATA | G11: Kanıt
A12: 9 | B12: Kanıt | C12: Test sonucu var | D12: Makine okunur artefakt + özet | E12: Kanıt fiziksel ve tutarlı | F12: HATA | G12: Kullanıcı Kabulü
A13: 10 | B13: Kullanıcı Kabulü | C13: Kritik görevler | D13: Gerçek ekran davranışı | E13: Kritik görevler %100 | F13: DIŞ_KABUL_GEREKLİ | G13: Ticari
A14: 11 | B14: Ticari Değer | C14: Ürün satılacaksa | D14: ROI + demo + kanıt paketi | E14: Ekonomik değer kanıtlı | F14: UYARI / HATA | G14: Pazar Doğrulama
A15: 12 | B15: Pazar Doğrulama | C15: Pazar iddiası varsa | D15: Ücretli satış/pilot/fiyat kabul kanıtı | E15: Gerçek fiyat kabul kanıtı | F15: UYGULANMAZ / HATA | G15: Yayın

Sheet 02_KONTROL_LISTESI
A1: NİHAİ KONTROL LİSTESİ — KANITSIZ GEÇİŞ YOK
A3: Kontrol No | B3: Kontrol | C3: Beklenen | D3: Zorunlu Kapı? | E3: Sonuç
A4: K01 | B4: Kullanıcının açık talebi öncelikli mi? | C4: Evet | D4: EVET
A5: K02 | B5: Mevcut yapı, formüller ve tek gerçek kaynak korunuyor mu? | C5: Evet, değişiklik gerekçeli | D5: EVET
A6: K03 | B6: Üst aşama HATA ise alt aşama GEÇTİ engelleniyor mu? | C6: Evet | D6: EVET
A7: K04 | B7: Kanıt fiziksel çıktı ve içerik doğrulaması içeriyor mu? | C7: Evet | D7: EVET
A8: K05 | B8: Excel GUI erişimi olmadan kullanıcı görünümü GEÇTİ yazılıyor mu? | C8: Hayır | D8: EVET
A9: K06 | B9: NİHAİ yalnız GEÇTİ / gerekçeli UYGULANMAZ ile mi? | C9: Evet | D9: EVET
A10: K07 | B10: Ekonomik fiyat savunusu pazar doğrulamasından ayrılmış mı? | C10: Evet | D10: EVET
A11: K08 | B11: Prestij için gereksiz modül var mı? | C11: Hayır | D11: HAYIR
A12: K09 | B12: Excel sınırları açık mı? | C12: Evet | D12: EVET
A13: K10 | B13: Teknik kaynak korunuyor mu? | C13: Evet | D13: EVET
A14: K11 | B14: Kullanıcıya görünen tüm metinler Türkçe mi? | C14: Evet | D14: EVET
A15: K12 | B15: Her kullanıcı sayfasında üst başlık var mı? | C15: Evet | D15: EVET
... A34: K31 | B34: Premium vitrin, altyapı kadar güçlü ve satış fiyatını destekleyecek seviyede mi? | C34: Evet | D34: EVET

Sheet 03_GORSEL_TASARIM
A1: GÖRSEL TASARIM VE PREMIUM EXCEL STANDARDI
A3: Alan | B3: Zorunlu Kural | C3: Uygulama | D3: Yasak | E3: Kontrol | F3: Durum
A4: Sayfa başlığı | B4: Her kullanıcı sayfasının en üstünde tek ve açık sayfa başlığı | C4: A1'den başlayan koyu lacivert başlık bandı | D4: Başlıksız sayfa | E4: Başlık kapsama = %100 | F4: ZORUNLU
A5: Sekme renkleri | B5: Sayfalar işlevine göre renk kodlanır | C5: Girdi=mavi, hesap=gri, rapor=lacivert, kontrol=kırmızı, kılavuz=altın | D5: Rastgele renk | E5: Renk semantiği tutarlı | F5: ZORUNLU
A6: Kolon düzeni | B6: Veri blokları bitişik kolonlarda ilerler | C6: Gereksiz boş kolon bırakma; yalnız gerçek bölüm ayrımı varsa kontrollü boşluk | D6: A:C veri, D boş, E:F veri gibi parçalı yapı | E6: Boş kolon taraması | F6: ZORUNLU
A7: Girdi hücreleri | B7: Kullanıcının değiştireceği alan açıkça görünür | C7: Açık sarı dolgu + mavi yazı | D7: Formülle aynı görünüm | E7: Girdi/formül ayrımı | F7: ZORUNLU
A8: Formüller | B8: Hesap hücreleri kullanıcı girdisinden ayrılır | C8: Siyah yazı; sayfalar arası bağlantı yeşil yazı | D8: Hard-code gizleme | E8: Formül sınıfı kontrolü | F8: ZORUNLU
A9: Grafik sayısı | B9: Yönetici ekranında en fazla 3 ana karar grafiği | C9: Trend, karşılaştırma, köprü/dağılım; iş kararına bağlı | D9: Grafik kalabalığı | E9: Grafik başına karar sorusu | F9: ZORUNLU
A10: Grafik stili | B10: Kurumsal ve yüksek okunabilirlik | C10: Beyaz zemin, ince gridline, tek vurgu rengi, açık birim/başlık | D10: 3B, gölge, neon, gökkuşağı renkleri | E10: Görsel inceleme | F10: ZORUNLU
A11: Grafik başlığı | B11: Grafik 'neyi' değil 'ne anlama geldiğini' söyler | C11: Örn: 'Nakit 2028'de kritik eşiğin altına iniyor' | D11: 'Nakit Grafiği' gibi anlamsız başlık | E11: Başlık karar testi | F11: ZORUNLU
A12: Birimler | B12: Tüm finansal görsellerde birim açık | C12: TL, bin TL, milyon TL, %, gün, x | D12: Birim belirsizliği | E12: Birim kapsama %100 | F12: ZORUNLU
A13: Sıfır/negatif | B13: Finansal format standardı | C13: Sıfır='-', negatif kırmızı parantez | D13: -500 veya 0,00 kalabalığı | E13: Format kontrolü | F13: ZORUNLU
A14: Yazı tipi | B14: Tek aile | C14: Aptos veya Segoe UI | D14: Karışık font | E14: Tek font kontrolü | F14: ZORUNLU
... A22: Premium vitrin | B22: Görsel kalite ürün değerinin zorunlu parçasıdır | C22: Kaliteli grafik, gerçek KPI kartı, finansal hiyerarşi, tab rengi, fonksiyonel navigasyon | D22: Sadece doğru hesap yapıp çıplak/varsayılan Excel görünümü bırakmak | E22: Görsel release incelemesi | F22: ZORUNLU

Sheet 04_MUHASEBE_THP
A1: TÜRKİYE MUHASEBE VE TEKDÜZEN HESAP PLANI STANDARDI
A3: Konu | B3: Zorunlu Standart | C3: Örnek Türkçe Ad | D3: THP / Mantık | E3: Hata Riski | F3: Kontrol
A4: Dil | B4: Kullanıcıya görünen finansal terimler Türkçe | C4: Hasılat, Satışların Maliyeti, Brüt Kâr, Faaliyet Giderleri | D4: Türk işletme kullanımına uygun | E4: İngilizce jargon | F4: Terminoloji taraması
A5: Gelir Tablosu | B5: Türk sunum sırası kullanılır | C5: Net Satışlar → Satışların Maliyeti → Brüt Kâr → Faaliyet Giderleri → Faaliyet Kârı | D5: 600/610/611; 620-623; 63x | E5: Yanlış sınıflama | F5: Hesap eşleme
A6: Bilanço | B6: Dönen/Duran Varlık ve Kısa/Uzun Vadeli Yükümlülük ayrımı | C6: Hazır Değerler, Ticari Alacaklar, Stoklar, Mali Borçlar | D6: 1xx / 2xx / 3xx / 4xx / 5xx | E6: Vade sınıfı hatası | F6: Bilanço eşitliği
A7: Nakit Akışı | B7: İşletme/Yatırım/Finansman nakit akışları ayrılır | C7: Faaliyetlerden Nakit, Yatırım Harcamaları, Finansman Nakit Akışı | D7: Dolaylı/doğrudan yöntem açık seçilir | E7: Kâr = nakit sanılması | F7: Nakit devri
A8: Ticari Alacaklar | B8: Cari ve vade mantığı korunur | C8: 120 Alıcılar | D8: 120 | E8: Tahakkuk/nakit karışması | F8: Alacak devir kontrolü
A9: Ticari Borçlar | B9: Tedarikçi borcu ayrı izlenir | C9: 320 Satıcılar | D9: 320 | E9: Gider/ödeme karışması | F9: Borç devir kontrolü
A10: Kasa/Banka | B10: Hazır değerler ayrı izlenir | C10: 100 Kasa, 102 Bankalar | D10: 100 / 102 | E10: Virmanla toplam nakdin değişmesi | F10: Virman değişmezi
A11: Stok | B11: Dikeye uygun stok türü | C11: 150 İlk Madde ve Malzeme, 153 Ticari Mallar | D11: 15x | E11: Maliyet ve stok hareketinin kopması | F11: Stok devri
A12: Maddi Duran Varlık | B12: Yatırım harcaması ve amortisman bağlantılı | C12: 253 Tesis Makine Cihazlar, 255 Demirbaşlar, 257 Birikmiş Amortismanlar | D12: 25x | E12: Yatırım/gider karışması | F12: Net defter değeri devri
A13: Mali Borçlar | B13: Kısa/uzun vadeli borç ayrımı | C13: 300 Banka Kredileri / 400 Banka Kredileri | D13: 300 / 400 | E13: Vade sınıfı yanlış | F13: Borç devri
A14: Özkaynak | B14: Sermaye ve geçmiş yıl kârları ayrı | C14: 500 Sermaye, 570 Geçmiş Yıllar Kârları, 590 Dönem Net Kârı | D14: 5xx | E14: Net kâr bağının kopması | F14: Özkaynak devri
... A18: İstisna | B18: TFRS özel ürün varsa fark açık yazılır | C18: Tekdüzen raporlama ≠ TFRS finansal tablo sunumu | D18: Amaç belirtilir | E18: Standartları karıştırma | F18: Model amacı kontrolü

Sheet 05_KARAR_SATIS
A1: KARAR, GÜVEN VE SATIŞA HAZIRLIK STANDARDI
A3: Alan | B3: Müşteri Sorusu | C3: Zorunlu Ürün Davranışı | D3: Kanıt | E3: Başarısızlık Durumu | F3: Kapı
A4: 5 saniye | B4: Bu ürün neyi çözüyor? | C4: İlk ekranda hedef kullanıcı + pahalı problem + sonuç görünür | D4: Başlık + alt mesaj + gerçek ekran | E4: Ürün yalnız teknik isim | F4: HATA
A5: Acı | B5: Sorun bana neye mal oluyor? | C5: Mümkünse müşterinin kendi verisiyle parasal/zaman etkisi hesaplanır | D5: ROI/acı hesaplama yöntemi | E5: Uydurma tasarruf | F5: HATA
A6: Karar | B6: Bu bilgiyle ne yapacağım? | C6: Her kritik KPI aksiyona bağlanır | D6: KARAR_KUYRUGU | E6: Sadece rapor | F6: HATA
A7: Güven | B7: Bu sayıya neden inanayım? | C7: Kaynak, formül mantığı, kontrol ve son doğrulama görünür | D7: Kontroller + kaynak izi + sürüm | E7: Prestij kelimesi | F7: HATA
A8: Referans | B8: Müşteri yorumu yoksa ne göstereceğim? | C8: Önce/Sonra + Karar Vakası + Hata Önleme Vakası üretilir | D8: Demo/örnek çıktı | E8: Kanıtsız iddia | F8: HATA
A9: Senaryo | B9: Ne olursa işler bozulur? | C9: Baz/Aşağı/Yukarı veya uygun stres senaryosu | D9: Senaryo karşılaştırma | E9: Dekoratif senaryo | F9: HATA
A10: Ters stres | B10: Hangi eşikte karar kırılır? | C10: En az bir kritik sürücü için kırılma eşiği | D10: Kırılma eşiği tablosu | E10: Sadece +/- %10 | F10: UYARI/HATA
A11: Hata tutarlılığı | B11: Formül hata verirse ne olur? | C11: Kontrol GEÇTİ veremez; BLOKE/HATA üretir | D11: Hata taraması | E11: Hata + GEÇTİ birlikte | F11: HATA
A12: Karar motoru | B12: Ne oldu, neden oldu? | C12: Sorun + neden + parasal etki + aksiyon + son tarih | D12: Karar tablosu | E12: Boş sayfa / isim düzeyi modül | F12: HATA
A13: Yönetici özeti | B13: 5 saniyede ne görmeliyim? | C13: Bugün / ne değişti / ne bozulacak / neden / ne yapmalıyım / güven | D13: Yönetici özeti ekranı | E13: KPI kutusu yığını | F13: HATA
A14: Teklif | B14: Neden satın almalıyım? | C14: Dosya özellikleri yerine sonuç ve kaçınılan maliyet sunulur | D14: Ürün sayfası kanıt eşlemesi | E14: Özellik listesiyle satış | F14: HATA
... A19: Pazar kanıtı | B19: Piyasa gerçekten ödüyor mu? | C19: Satış/pilot/LOI/fiyat kabulü olmadan pazar doğrulandı yazılmaz | D19: Gerçek işlem kanıtı | E19: Tahmini talep = satış kabulü | F19: HATA

Sheet KAPAK
A1: KIDEM–İHBAR YÜKÜ VE PERSONEL ÇIKARMA MALİYETİ HESAPLAYICI
A3: Personel çıkarma kararınızın maliyetini tam ve mevzuata uygun hesaplayın.
A4: Kıdem tazminatı (1475 s. md.14), ihbar tazminatı (4857 s. md.17) ve kullanılmamış yıllık izin ücreti (4857 s. md.53) her çalışan için otomatik hesaplanır. Toplam çıkarma maliyeti bütçeyle karşılaştırılır; UYGUN / İNCELE / DURDUR kararı üretilir.
A6: 1. CALISANLAR sayfasına çalışan bilgilerini ve brüt ücretleri girin.
A7: 2. Kıdem, ihbar, izin ve toplam maliyet formülle hesaplanır; MOTOR ve PANO sonuçları gösterir.
A8: 3. KARAR sayfasında maliyet-bütçe uyumu ve aksiyonları okuyun.
A10: Bu dosya karar destek aracıdır; iş hukuku veya mali müşavirlik danışmanlığı yerine geçmez. Kıdem tazminatı tavanı yıllık Resmi Gazete duyurusuyla güncellenir; AYARLAR'dan takip edilmelidir.
A15: ExcelArşiv
A16: Rev 1.0 | 2026-08-09 | Lisans: Tek kullanıcı

Sheet HIZLI_BASLANGIC
A1: ☰ PANO
A3: Nasıl kullanılır?
A4: 1. AYARLAR sayfasından kıdem tazminatı tavanını (yıllık Resmi Gazete), bütçe eşiğini ve diğer parametreleri kontrol edin.
A5: 2. CALISANLAR sayfasına her çalışan için ad, işe giriş, işten çıkış, brüt ücret ve ücret türünü girin.
A6: 3. Kıdem yıl/gün, kıdem tazminatı, ihbar gün/tazminatı ve izin ücreti formülle hesaplanır.
A7: 4. Kullanılan izin gününü sarı hücreye girin; kalan izin ücreti otomatik düşer.
A8: 5. KARAR sayfası toplam çıkarma maliyetini bütçeyle karşılaştırır; UYGUN / İNCELE / DURDUR kararı üretir.
A9: 6. PANO ve RAPOR sayfaları yönetici özetini ve yazdırılabilir raporu sunar.
A10: 7. SENARYO_DUYARLILIK sayfası ücret/çalışan değişiminde maliyet ve kararı üretir.
A12: Sık yapılan hatalar
A13: Kıdem tazminatı tavanını güncel tutmamak — tavanı aşan ücretlerde fazla hesaplama yapılır.
A14: İşten çıkış tarihini boş bırakmak — kıdem hesabı hatalı olur; aktif çalışanlar için çıkış tarihi gerekmezse satır silinir.
... A19: Tüm oranlar ve eşikler AYARLAR sayfasından beslenir; formüle gömülü sayı kullanılmaz.

Sheet CALISANLAR
A1: CALISANLAR — KIDEM–İHBAR YÜKÜ VE PERSONEL ÇIKARMA MALİYETİ HESAPLAYICI
A3: Çalışanlar, Kıdem ve Çıkarma Maliyeti
A5: Çalışan Adı | B5: İşe Giriş Tarihi | C5: İşten Çıkış Tarihi | D5: Brüt Ücret (₺) | E5: Ücret Türü | F5: Günlük Ücret (₺) | G5: Kıdem Yıl | H5: Kıdem Gün | I5: Kıdem Tazminatı (₺) | J5: İhbar Gün | K5: İhbar Tazminatı (₺) | L5: İzin Hakkı (Gün) | M5: Kullanılan İzin (Gün) | N5: Toplam Çıkarma Maliyeti (₺)
A6: Ahmet Yılmaz | B6: 43891 | C6: 46235 | D6: 45000 | E6: Aylık | F6: =IF(OR($A6="",$D6=""),"",IF($E6="Günlük",$D6,$D6/UcretGunSayisi)) | G6: =IF(OR($A6="",$B6="",$C6=""),"",IFERROR(MAX(0,DATEDIF($B6,$C6,"Y")),0)) | H6: =IF(OR($A6="",$B6="",$C6=""),"",IFERROR(MAX(0,DATEDIF($B6,$C6,"D")),0)) | I6: =IF(OR($F6="",$G6="",$H6=""),"",IFERROR(MIN($F6*UcretGunSayisi,KidemTavan)*(IFERROR($G6,0)+IFERROR($H6,0)/365),0)) | J6: =IF(OR($H6="",$C6=""),"",IFERROR(IF($H6<IhbarEsik1Gun,IhbarSure1,IF($H6<IhbarEsik2Gun,IhbarSure2,IF($H6<IhbarEsik3Gun,IhbarSure3,IhbarSure4))),0)) | K6: =IF(OR($F6="",$J6=""),"",IFERROR(MAX(0,$F6*$J6),0)) | L6: =IF(OR($G6="",$C6=""),"",IFERROR(IF($G6>=IzinEsik2,IzinHakki3,IF($G6>=IzinEsik1,IzinHakki2,IzinHakki1)),0)) | M6: 5 | N6: =IF(OR($I6="",$K6="",$L6="",$M6=""),"",IFERROR(MAX(0,$I6+$K6+IFERROR(MAX(0,$L6-$M6),0)*$F6),0))
A7: Ayşe Kaya | B7: 42156 | C7: 46266 | D7: 55000 | E7: Aylık | F7: =IF(OR($A7="",$D7=""),"",IF($E7="Günlük",$D7,$D7/UcretGunSayisi)) | G7: =IF(OR($A7="",$B7="",$C7=""),"",IFERROR(MAX(0,DATEDIF($B7,$C7,"Y")),0)) | H7: =IF(OR($A7="",$B7="",$C7=""),"",IFERROR(MAX(0,DATEDIF($B7,$C7,"D")),0)) | I7: =IF(OR($F7="",$G7="",$H7=""),"",IFERROR(MIN($F7*UcretGunSayisi,KidemTavan)*(IFERROR($G7,0)+IFERROR($H7,0)/365),0)) | J7: =IF(OR($H7="",$C7=""),"",IFERROR(IF($H7<IhbarEsik1Gun,IhbarSure1,IF($H7<IhbarEsik2Gun,IhbarSure2,IF($H7<IhbarEsik3Gun,IhbarSure3,IhbarSure4))),0)) | K7: =IF(OR($F7="",$J7=""),"",IFERROR(MAX(0,$F7*$J7),0)) | L7: =IF(OR($G7="",$C7=""),"",IFERROR(IF($G7>=IzinEsik2,IzinHakki3,IF($G7>=IzinEsik1,IzinHakki2,IzinHakki1)),0)) | M7: 8 | N7: =IF(OR($I7="",$K7="",$L7="",$M7=""),"",IFERROR(MAX(0,$I7+$K7+IFERROR(MAX(0,$L7-$M7),0)*$F7),0))
A8: Mehmet Demir | B8: 44576 | C8: 46218 | D8: 1800 | E8: Günlük | F8: =IF(OR($A8="",$D8=""),"",IF($E8="Günlük",$D8,$D8/UcretGunSayisi)) | G8: =IF(OR($A8="",$B8="",$C8=""),"",IFERROR(MAX(0,DATEDIF($B8,$C8,"Y")),0)) | H8: =IF(OR($A8="",$B8="",$C8=""),"",IFERROR(MAX(0,DATEDIF($B8,$C8,"D")),0)) | I8: =IF(OR($F8="",$G8="",$H8=""),"",IFERROR(MIN($F8*UcretGunSayisi,KidemTavan)*(IFERROR($G8,0)+IFERROR($H8,0)/365),0)) | J8: =IF(OR($H8="",$C8=""),"",IFERROR(IF($H8<IhbarEsik1Gun,IhbarSure1,IF($H8<IhbarEsik2Gun,IhbarSure2,IF($H8<IhbarEsik3Gun,IhbarSure3,IhbarSure4))),0)) | K8: =IF(OR($F8="",$J8=""),"",IFERROR(MAX(0,$F8*$J8),0)) | L8: =IF(OR($G8="",$C8=""),"",IFERROR(IF($G8>=IzinEsik2,IzinHakki3,IF($G8>=IzinEsik1,IzinHakki2,IzinHakki1)),0)) | M8: 2 | N8: =IF(OR($I8="",$K8="",$L8="",$M8=""),"",IFERROR(MAX(0,$I8+$K8+IFERROR(MAX(0,$L8-$M8),0)*$F8),0))
A9: Zeynep Çelik | B9: 43191 | C9: 46296 | D9: 40000 | E9: Aylık | F9: =IF(OR($A9="",$D9=""),"",IF($E9="Günlük",$D9,$D9/UcretGunSayisi)) | G9: =IF(OR($A9="",$B9="",$C9=""),"",IFERROR(MAX(0,DATEDIF($B9,$C9,"Y")),0)) | H9: =IF(OR($A9="",$B9="",$C9=""),"",IFERROR(MAX(0,DATEDIF($B9,$C9,"D")),0)) | I9: =IF(OR($F9="",$G9="",$H9=""),"",IFERROR(MIN($F9*UcretGunSayisi,KidemTavan)*(IFERROR($G9,0)+IFERROR($H9,0)/365),0)) | J9: =IF(OR($H9="",$C9=""),"",IFERROR(IF($H9<IhbarEsik1Gun,IhbarSure1,IF($H9<IhbarEsik2Gun,IhbarSure2,IF($H9<IhbarEsik3Gun,IhbarSure3,IhbarSure4))),0)) | K9: =IF(OR($F9="",$J9=""),"",IFERROR(MAX(0,$F9*$J9),0)) | L9: =IF(OR($G9="",$C9=""),"",IFERROR(IF($G9>=IzinEsik2,IzinHakki3,IF($G9>=IzinEsik1,IzinHakki2,IzinHakki1)),0)) | M9: 10 | N9: =IF(OR($I9="",$K9="",$L9="",$M9=""),"",IFERROR(MAX(0,$I9+$K9+IFERROR(MAX(0,$L9-$M9),0)*$F9),0))
A10: Mustafa Aydın | B10: 40210 | C10: 46249 | D10: 60000 | E10: Aylık | F10: =IF(OR($A10="",$D10=""),"",IF($E10="Günlük",$D10,$D10/UcretGunSayisi)) | G10: =IF(OR($A10="",$B10="",$C10=""),"",IFERROR(MAX(0,DATEDIF($B10,$C10,"Y")),0)) | H10: =IF(OR($A10="",$B10="",$C10=""),"",IFERROR(MAX(0,DATEDIF($B10,$C10,"D")),0)) | I10: =IF(OR($F10="",$G10="",$H10=""),"",IFERROR(MIN($F10*UcretGunSayisi,KidemTavan)*(IFERROR($G10,0)+IFERROR($H10,0)/365),0)) | J10: =IF(OR($H10="",$C10=""),"",IFERROR(IF($H10<IhbarEsik1Gun,IhbarSure1,IF($H10<IhbarEsik2Gun,IhbarSure2,IF($H10<IhbarEsik3Gun,IhbarSure3,IhbarSure4))),0)) | K10: =IF(OR($F10="",$J10=""),"",IFERROR(MAX(0,$F10*$J10),0)) | L10: =IF(OR($G10="",$C10=""),"",IFERROR(IF($G10>=IzinEsik2,IzinHakki3,IF($G10>=IzinEsik1,IzinHakki2,IzinHakki1)),0)) | M10: 12 | N10: =IF(OR($I10="",$K10="",$L10="",$M10=""),"",IFERROR(MAX(0,$I10+$K10+IFERROR(MAX(0,$L10-$M10),0)*$F10),0))
A11: Elif Şahin | B11: 44440 | C11: 46327 | D11: 35000 | E11: Aylık | F11: =IF(OR($A11="",$D11=""),"",IF($E11="Günlük",$D11,$D11/UcretGunSayisi)) | G11: =IF(OR($A11="",$B11="",$C11=""),"",IFERROR(MAX(0,DATEDIF($B11,$C11,"Y")),0)) | H11: =IF(OR($A11="",$B11="",$C11=""),"",IFERROR(MAX(0,DATEDIF($B11,$C11,"D")),0)) | I11: =IF(OR($F11="",$G11="",$H11=""),"",IFERROR(MIN($F11*UcretGunSayisi,KidemTavan)*(IFERROR($G11,0)+IFERROR($H11,0)/365),0)) | J11: =IF(OR($H11="",$C11=""),"",IFERROR(IF($H11<IhbarEsik1Gun,IhbarSure1,IF($H11<IhbarEsik2Gun,IhbarSure2,IF($H11<IhbarEsik3Gun,IhbarSure3,IhbarSure4))),0)) | K11: =IF(OR($F11="",$J11=""),"",IFERROR(MAX(0,$F11*$J11),0)) | L11: =IF(OR($G11="",$C11=""),"",IFERROR(IF($G11>=IzinEsik2,IzinHakki3,IF($G11>=IzinEsik1,IzinHakki2,IzinHakki1)),0)) | M11: 3 | N11: =IF(OR($I11="",$K11="",$L11="",$M11=""),"",IFERROR(MAX(0,$I11+$K11+IFERROR(MAX(0,$L11-$M11),0)*$F11),0))
A12: Hasan Yıldız | B12: 43647 | C12: 46280 | D12: 1700 | E12: Günlük | F12: =IF(OR($A12="",$D12=""),"",IF($E12="Günlük",$D12,$D12/UcretGunSayisi)) | G12: =IF(OR($A12="",$B12="",$C12=""),"",IFERROR(MAX(0,DATEDIF($B12,$C12,"Y")),0)) | H12: =IF(OR($A12="",$B12="",$C12=""),"",IFERROR(MAX(0,DATEDIF($B12,$C12,"D")),0)) | I12: =IF(OR($F12="",$G12="",$H12=""),"",IFERROR(MIN($F12*UcretGunSayisi,KidemTavan)*(IFERROR($G12,0)+IFERROR($H12,0)/365),0)) | J12: =IF(OR($H12="",$C12=""),"",IFERROR(IF($H12<IhbarEsik1Gun,IhbarSure1,IF($H12<IhbarEsik2Gun,IhbarSure2,IF($H12<IhbarEsik3Gun,IhbarSure3,IhbarSure4))),0)) | K12: =IF(OR($F12="",$J12=""),"",IFERROR(MAX(0,$F12*$J12),0)) | L12: =IF(OR($G12="",$C12=""),"",IFERROR(IF($G12>=IzinEsik2,IzinHakki3,IF($G12>=IzinEsik1,IzinHakki2,IzinHakki1)),0)) | M12: 4 | N12: =IF(OR($I12="",$K12="",$L12="",$M12=""),"",IFERROR(MAX(0,$I12+$K12+IFERROR(MAX(0,$L12-$M12),0)*$F12),0))
A13: Fatma Arslan | B13: 42370 | C13: 46357 | D13: 48000 | E13: Aylık | F13: =IF(OR($A13="",$D13=""),"",IF($E13="Günlük",$D13,$D13/UcretGunSayisi)) | G13: =IF(OR($A13="",$B13="",$C13=""),"",IFERROR(MAX(0,DATEDIF($B13,$C13,"Y")),0)) | H13: =IF(OR($A13="",$B13="",$C13=""),"",IFERROR(MAX(0,DATEDIF($B13,$C13,"D")),0)) | I13: =IF(OR($F13="",$G13="",$H13=""),"",IFERROR(MIN($F13*UcretGunSayisi,KidemTavan)*(IFERROR($G13,0)+IFERROR($H13,0)/365),0)) | J13: =IF(OR($H13="",$C13=""),"",IFERROR(IF($H13<IhbarEsik1Gun,IhbarSure1,IF($H13<IhbarEsik2Gun,IhbarSure2,IF($H13<IhbarEsik3Gun,IhbarSure3,IhbarSure4))),0)) | K13: =IF(OR($F13="",$J13=""),"",IFERROR(MAX(0,$F13*$J13),0)) | L13: =IF(OR($G13="",$C13=""),"",IFERROR(IF($G13>=IzinEsik2,IzinHakki3,IF($G13>=IzinEsik1,IzinHakki2,IzinHakki1)),0)) | M13: 15 | N13: =IF(OR($I13="",$K13="",$L13="",$M13=""),"",IFERROR(MAX(0,$I13+$K13+IFERROR(MAX(0,$L13-$M13),0)*$F13),0))
A14: İbrahim Koç | B14: 41414 | C14: 46310 | D14: 68000 | E14: Aylık | F14: =IF(OR($A14="",$D14=""),"",IF($E14="Günlük",$D14,$D14/UcretGunSayisi)) | G14: =IF(OR($A14="",$B14="",$C14=""),"",IFERROR(MAX(0,DATEDIF($B14,$C14,"Y")),0)) | H14: =IF(OR($A14="",$B14="",$C14=""),"",IFERROR(MAX(0,DATEDIF($B14,$C14,"D")),0)) | I14: =IF(OR($F14="",$G14="",$H14=""),"",IFERROR(MIN($F14*UcretGunSayisi,KidemTavan)*(IFERROR($G14,0)+IFERROR($H14,0)/365),0)) | J14: =IF(OR($H14="",$C14=""),"",IFERROR(IF($H14<IhbarEsik1Gun,IhbarSure1,IF($H14<IhbarEsik2Gun,IhbarSure2,IF($H14<IhbarEsik3Gun,IhbarSure3,IhbarSure4))),0)) | K14: =IF(OR($F14="",$J14=""),"",IFERROR(MAX(0,$F14*$J14),0)) | L14: =IF(OR($G14="",$C14=""),"",IFERROR(IF($G14>=IzinEsik2,IzinHakki3,IF($G14>=IzinEsik1,IzinHakki2,IzinHakki1)),0)) | M14: 20 | N14: =IF(OR($I14="",$K14="",$L14="",$M14=""),"",IFERROR(MAX(0,$I14+$K14+IFERROR(MAX(0,$L14-$M14),0)*$F14),0))
A15: Merve Çetin | B15: 44958 | C15: 46264 | D15: 1600 | E15: Günlük | F15: =IF(OR($A15="",$D15=""),"",IF($E15="Günlük",$D15,$D15/UcretGunSayisi)) | G15: =IF(OR($A15="",$B15="",$C15=""),"",IFERROR(MAX(0,DATEDIF($B15,$C15,"Y")),0)) | H15: =IF(OR($A15="",$B15="",$C15=""),"",IFERROR(MAX(0,DATEDIF($B15,$C15,"D")),0)) | I15: =IF(OR($F15="",$G15="",$H15=""),"",IFERROR(MIN($F15*UcretGunSayisi,KidemTavan)*(IFERROR($G15,0)+IFERROR($H15,0)/365),0)) | J15: =IF(OR($H15="",$C15=""),"",IFERROR(IF($H15<IhbarEsik1Gun,IhbarSure1,IF($H15<IhbarEsik2Gun,IhbarSure2,IF($H15<IhbarEsik3Gun,IhbarSure3,IhbarSure4))),0)) | K15: =IF(OR($F15="",$J15=""),"",IFERROR(MAX(0,$F15*$J15),0)) | L15: =IF(OR($G15="",$C15=""),"",IFERROR(IF($G15>=IzinEsik2,IzinHakki3,IF($G15>=IzinEsik1,IzinHakki2,IzinHakki1)),0)) | M15: 0 | N15: =IF(OR($I15="",$K15="",$L15="",$M15=""),"",IFERROR(MAX(0,$I15+$K15+IFERROR(MAX(0,$L15-$M15),0)*$F15),0))
A16: Ali Demir | B16: 42948 | C16: 46266 | D16: 42000 | E16: Aylık | F16: =IF(OR($A16="",$D16=""),"",IF($E16="Günlük",$D16,$D16/UcretGunSayisi)) | G16: =IF(OR($A16="",$B16="",$C16=""),"",IFERROR(MAX(0,DATEDIF($B16,$C16,"Y")),0)) | H16: =IF(OR($A16="",$B16="",$C16=""),"",IFERROR(MAX(0,DATEDIF($B16,$C16,"D")),0)) | I16: =IF(OR($F16="",$G16="",$H16=""),"",IFERROR(MIN($F16*UcretGunSayisi,KidemTavan)*(IFERROR($G16,0)+IFERROR($H16,0)/365),0)) | J16: =IF(OR($H16="",$C16=""),"",IFERROR(IF($H16<IhbarEsik1Gun,IhbarSure1,IF($H16<IhbarEsik2Gun,IhbarSure2,IF($H16<IhbarEsik3Gun,IhbarSure3,IhbarSure4))),0)) | K16: =IF(OR($F16="",$J16=""),"",IFERROR(MAX(0,$F16*$J16),0)) | L16: =IF(OR($G16="",$C16=""),"",IFERROR(IF($G16>=IzinEsik2,IzinHakki3,IF($G16>=IzinEsik1,IzinHakki2,IzinHakki1)),0)) | M16: 6 | N16: =IF(OR($I16="",$K16="",$L16="",$M16=""),"",IFERROR(MAX(0,$I16+$K16+IFERROR(MAX(0,$L16-$M16),0)*$F16),0))
A17: Selin Korkmaz | B17: 41958 | C17: 46341 | D17: 52000 | E17: Aylık | F17: =IF(OR($A17="",$D17=""),"",IF($E17="Günlük",$D17,$D17/UcretGunSayisi)) | G17: =IF(OR($A17="",$B17="",$C17=""),"",IFERROR(MAX(0,DATEDIF($B17,$C17,"Y")),0)) | H17: =IF(OR($A17="",$B17="",$C17=""),"",IFERROR(MAX(0,DATEDIF($B17,$C17,"D")),0)) | I17: =IF(OR($F17="",$G17="",$H17=""),"",IFERROR(MIN($F17*UcretGunSayisi,KidemTavan)*(IFERROR($G17,0)+IFERROR($H17,0)/365),0)) | J17: =IF(OR($H17="",$C17=""),"",IFERROR(IF($H17<IhbarEsik1Gun,IhbarSure1,IF($H17<IhbarEsik2Gun,IhbarSure2,IF($H17<IhbarEsik3Gun,IhbarSure3,IhbarSure4))),0)) | K17: =IF(OR($F17="",$J17=""),"",IFERROR(MAX(0,$F17*$J17),0)) | L17: =IF(OR($G17="",$C17=""),"",IFERROR(IF($G17>=IzinEsik2,IzinHakki3,IF($G17>=IzinEsik1,IzinHakki2,IzinHakki1)),0)) | M17: 9 | N17: =IF(OR($I17="",$K17="",$L17="",$M17=""),"",IFERROR(MAX(0,$I17+$K17+IFERROR(MAX(0,$L17-$M17),0)*$F17),0))
... A19: Gülay Öztürk | B19: 40787 | C19: 46296 | D19: 75000 | E19: Aylık | F19: =IF(OR($A19="",$D19=""),"",IF($E19="Günlük",$D19,$D19/UcretGunSayisi)) | G19: =IF(OR($A19="",$B19="",$C19=""),"",IFERROR(MAX(0,DATEDIF($B19,$C19,"Y")),0)) | H19: =IF(OR($A19="",$B19="",$C19=""),"",IFERROR(MAX(0,DATEDIF($B19,$C19,"D")),0)) | I19: =IF(OR($F19="",$G19="",$H19=""),"",IFERROR(MIN($F19*UcretGunSayisi,KidemTavan)*(IFERROR($G19,0)+IFERROR($H19,0)/365),0)) | J19: =IF(OR($H19="",$C19=""),"",IFERROR(IF($H19<IhbarEsik1Gun,IhbarSure1,IF($H19<IhbarEsik2Gun,IhbarSure2,IF($H19<IhbarEsik3Gun,IhbarSure3,IhbarSure4))),0)) | K19: =IF(OR($F19="",$J19=""),"",IFERROR(MAX(0,$F19*$J19),0)) | L19: =IF(OR($G19="",$C19=""),"",IFERROR(IF($G19>=IzinEsik2,IzinHakki3,IF($G19>=IzinEsik1,IzinHakki2,IzinHakki1)),0)) | M19: 18 | N19: =IF(OR($I19="",$K19="",$L19="",$M19=""),"",IFERROR(MAX(0,$I19+$K19+IFERROR(MAX(0,$L19-$M19),0)*$F19),0))
A1006: Günlük ücret, kıdem, kıdem/ihbar/izin ve toplam maliyet formülle üretilir; sarı hücreler giriştir.

Sheet MOTOR
A1: MOTOR — KIDEM–İHBAR YÜKÜ VE PERSONEL ÇIKARMA MALİYETİ HESAPLAYICI
A3: Hesaplama Motoru — Kıdem, İhbar, İzin ve Maliyet
A6: Toplam Çalışan Sayısı | B6: =IFERROR(COUNT(tblCalisan[Çalışan Adı]),0)
A7: Toplam Kıdem Tazminatı | B7: =IFERROR(ROUND(SUM(tblCalisan[Kıdem Tazminatı (₺)]),0),0)
A8: Toplam İhbar Tazminatı | B8: =IFERROR(ROUND(SUM(tblCalisan[İhbar Tazminatı (₺)]),0),0)
A9: Toplam İzin Ücreti | B9: =IFERROR(ROUND(SUMPRODUCT(tblCalisan[İzin Hakkı (Gün)],tblCalisan[Günlük Ücret (₺)])-SUMPRODUCT(tblCalisan[Kullanılan İzin (Gün)],tblCalisan[Günlük Ücret (₺)]),0),0)
A10: Toplam Çıkarma Maliyeti | B10: =IFERROR(ROUND(SUM(tblCalisan[Toplam Çıkarma Maliyeti (₺)]),0),0)
A11: Ortalama Kıdem Yılı | B11: =IFERROR(AVERAGE(tblCalisan[Kıdem Yıl]),0)
A12: Ortalama Günlük Ücret | B12: =IFERROR(AVERAGE(tblCalisan[Günlük Ücret (₺)]),0)
A13: En Yüksek Çalışan Maliyeti | B13: =IFERROR(MAX(tblCalisan[Toplam Çıkarma Maliyeti (₺)]),0)
A14: Maliyet Yoğunlaşma Oranı | B14: =IFERROR(IF(ToplamCikarmaMaliyeti=0,0,EnYuksekCalisanMaliyeti/ToplamCikarmaMaliyeti),0)
A15: Ortalama İhbar Günü | B15: =IFERROR(AVERAGE(tblCalisan[İhbar Gün]),0)
A16: Aylık Brüt Ücret Yükü | B16: =IFERROR(ROUND(SUM(tblCalisan[Brüt Ücret (₺)]),0),0)
A17: Yıllık İşçilik Yükü | B17: =IFERROR(AylikBrutUcretYuku*12,0)
A18: Çıkarma Bütçesi Kullanım Oranı | B18: =IFERROR(IF(CikarmaButceEsik=0,0,ToplamCikarmaMaliyeti/CikarmaButceEsik),0)
A19: Bütçe Farkı | B19: =IFERROR(CikarmaButceEsik-ToplamCikarmaMaliyeti,0)
A20: Anomali Çalışan Adedi | B20: =SUMPRODUCT(--(tblCalisan[Brüt Ücret (₺)]<>""),--(ABS(tblCalisan[Brüt Ücret (₺)]-IFERROR(AVERAGE(tblCalisan[Brüt Ücret (₺)]),0))>UcretAnomaliZEsik*IFERROR(stdev.p(tblCalisan[Brüt Ücret (₺)]),0)))
A21: İzin Kullanım Oranı | B21: =IFERROR(IF(SUMPRODUCT(tblCalisan[İzin Hakkı (Gün)])>0,1-SUMPRODUCT(tblCalisan[Kullanılan İzin (Gün)])/SUMPRODUCT(tblCalisan[İzin Hakkı (Gün)]),0),0)
A25: Analitik Modül Hesapları
A26: Modül T1: Çalışan Zaman Kapsamı | B26: =IFERROR(MAX(tblCalisan[İşten Çıkış Tarihi])-MIN(tblCalisan[İşe Giriş Tarihi]),0)
A27: Modül T2: Ücret Eğilimi (çalışan başına) | B27: =IFERROR(SLOPE(tblCalisan[Brüt Ücret (₺)],ROW(tblCalisan[Brüt Ücret (₺)])-ROW(tblCalisan[[#Headers],[Brüt Ücret (₺)]])),0)
A28: Modül T3: En Yüksek Maliyetli Çalışanın Payı | B28: =IFERROR(LARGE(tblCalisan[Toplam Çıkarma Maliyeti (₺)],1)/MAX(1,SUM(tblCalisan[Toplam Çıkarma Maliyeti (₺)])),0)
A29: Modül T5: Bütçe Mutabakat Farkı | B29: =IFERROR(CikarmaButceEsik-ToplamCikarmaMaliyeti,0)
A30: Modül T6: Kıdem Tazminatının Maliyet İçindeki Payı | B30: =IFERROR(IF(ToplamCikarmaMaliyeti=0,0,ToplamKidem/ToplamCikarmaMaliyeti),0)
A31: Modül O1: Anomali Oranı | B31: =IFERROR(IF(COUNT(tblCalisan[Çalışan Adı])=0,0,AnomaliCalisanAdedi/COUNT(tblCalisan[Çalışan Adı])),0)
A32: Modül O2: En Etkili Değişken (Tornado) | B32: =IFERROR(INDEX(SENARYO_DUYARLILIK!$A$13:$A$14,MATCH(MAX(SENARYO_DUYARLILIK!$G$13:$G$14),SENARYO_DUYARLILIK!$G$13:$G$14,0)),"VERİ YOK")
A33: Modül O3: Baz Senaryo Maliyeti | B33: =SENARYO_DUYARLILIK!$D$8
A34: Modül O4: Ortalama Kıdem (Ay) | B34: =IFERROR(AVERAGE(tblCalisan[Kıdem Gün])/30,0)
A35: Modül O6: Maliyet Yoğunlaşması (HHI) | B35: =IFERROR(SUMPRODUCT((IF(ISNUMBER(tblCalisan[Toplam Çıkarma Maliyeti (₺)]),tblCalisan[Toplam Çıkarma Maliyeti (₺)],0)/MAX(1,SUM(tblCalisan[Toplam Çıkarma Maliyeti (₺)])))^2),0)
A36: Modül O8: Veri Kalite Skoru | B36: =KONTROL!$B$21
A37: Modül I1: Maliyet Tahmin Orta Noktası | B37: =IFERROR(FORECAST(COUNTA(tblCalisan[Çalışan Adı])+1,tblCalisan[Toplam Çıkarma Maliyeti (₺)],ROW(tblCalisan[Toplam Çıkarma Maliyeti (₺)])-ROW(tblCalisan[[#Headers],[Toplam Çıkarma Maliyeti (₺)]])),0)
A38: Modül I2: Çalışan Maliyeti P90 | B38: =IFERROR(PERCENTILE(tblCalisan[Toplam Çıkarma Maliyeti (₺)],P90Kuantil),0)
A39: Modül I3: Maliyet Yükü Net Bugünkü Değeri | B39: =IFERROR(NPV(IskontoOrani,tblCalisan[Toplam Çıkarma Maliyeti (₺)]),0)
A40: Modül I7: Bütçe Açığı Köprüsü (Ek Kaynak İhtiyacı) | B40: =IFERROR(ABS(ButceFarki)/MAX(0.01,1),0)
A41: Değer Ölçer: Toplam Yük | B41: =IFERROR(MAX(0,ToplamCikarmaMaliyeti),0)
A42: Değer Ölçer: Bütçe Aşımı | B42: =IFERROR(MAX(0,ToplamCikarmaMaliyeti-CikarmaButceEsik),0)
A44: Modül Makine Yorumları
A45: T1 Zaman Kapsamı | B45: =modulT1CalisanYasOrt | C45: =_xlfn.TEXTJOIN(" | ",TRUE(),"T1: Çalışan kayıtları "&modulT1CalisanYasOrt&" günlük aralığa yayılıyor",IF(modulT1CalisanYasOrt>365,"kadro bir yılı aşıyor, kıdem yükü yükselebilir","kadro tek yıl içinde"))
A46: T2 Ücret Eğilimi | B46: =modulT2UcretEgim | C46: =_xlfn.TEXTJOIN(" | ",TRUE(),"T2: Ücret eğilimi çalışan başına "&TEXT(modulT2UcretEgim,"#,##0")&" TL değişim",IF(modulT2UcretEgim>0,"ücretler yükselme eğiliminde, yük maliyeti artıyor","ücretler düşme eğiliminde"))
A47: T3 Pareto Maliyet Payı | B47: =modulT3MaliyetParetoPay | C47: =_xlfn.TEXTJOIN(" | ",TRUE(),"T3: En yüksek maliyetli çalışan toplamın "&TEXT(modulT3MaliyetParetoPay*100,"0")&"% tutarında",IF(modulT3MaliyetParetoPay>ParetoEsikOran,"maliyet tek çalışanda yoğun, planlama dikkatli yapılmalı","maliyet çalışanlara dağılmış"))
...

Sheet KONTROL
A1: KONTROL — KIDEM–İHBAR YÜKÜ VE PERSONEL ÇIKARMA MALİYETİ HESAPLAYICI
A3: Veri Kalitesi ve Sağlık Kontrolü
A5: A. GİRİŞ TAMLIK KONTROLÜ
A7: Çalışan Adı Boş | B7: =IF(COUNTIF(tblCalisan[Çalışan Adı],"")>0,"FAIL","PASS")
A8: İşe Giriş Tarihi Boş | B8: =IF(COUNTBLANK(tblCalisan[İşe Giriş Tarihi])>0,"FAIL","PASS")
A9: Brüt Ücret Boş/Sıfır | B9: =IF(SUMPRODUCT(--(tblCalisan[Brüt Ücret (₺)]=""))+SUMPRODUCT(--(tblCalisan[Brüt Ücret (₺)]<=0))>0,"FAIL","PASS")
A10: Çıkış Tarihi Eksik | B10: =IF(COUNTIF(tblCalisan[İşten Çıkış Tarihi],"")>0,"WARN","PASS")
A11: Çalışan Kaydı Yok | B11: =IF(COUNT(tblCalisan[Brüt Ücret (₺)])=0,"FAIL","PASS")
A12: Toplam Maliyet Bütçeyi Aşıyor | B12: =IF(ToplamCikarmaMaliyeti>CikarmaButceEsik,"WARN","PASS")
A13: Ortalama Kıdem Yüksek | B13: =IF(OrtalamaKidemYil>KidemYilEsik,"WARN","PASS")
A14: Ücret Anomalisi Var | B14: =IF(AnomaliCalisanAdedi>0,"WARN","PASS")
A15: İzin Kullanımı Girilmemiş | B15: =IF(SUMPRODUCT(tblCalisan[İzin Hakkı (Gün)])>SUMPRODUCT(tblCalisan[Kullanılan İzin (Gün)]),"WARN","PASS")
A16: Kıdem Tazminatı Tavanı Kontrolü | B16: =IF(MAX(tblCalisan[Günlük Ücret (₺)])*UcretGunSayisi>KidemTavan,"WARN","PASS")
A18: B. SKOR VE SAĞLIK
A19: PASS Sayısı | B19: =COUNTIF(B7:B16,"PASS")
A20: FAIL Sayısı | B20: =COUNTIF(B7:B16,"FAIL")
A21: Veri Kalite Skoru (0-100) | B21: =IF(COUNTIF(B7:B16,"FAIL")=0,ROUND(100-COUNTIF(B7:B16,"WARN")*VeriKaliteUyariCeza,0),0)
A22: Güven Seviyesi | B22: =IF(VeriKaliteSkoru=0,"VERİ YOK",IF(VeriKaliteSkoru>=VeriKaliteIyiEsik,"YÜKSEK",IF(VeriKaliteSkoru>=VeriKaliteOrtaEsik,"ORTA","DÜŞÜK")))
A24: Durum | B24: =IF(FAIL_Sayisi=0,"SAĞLIKLI","İNCELE")
A26: Skor ve sağlık durumu formülle üretilir; sahte veri yoktur.

Sheet KARAR
A1: KARAR — KIDEM–İHBAR YÜKÜ VE PERSONEL ÇIKARMA MALİYETİ HESAPLAYICI
A3: Karar Motoru
A5: ÇIKARMA MALİYETİ ÖZETİ
A6: Toplam Çıkarma Maliyeti | B6: =ToplamCikarmaMaliyeti
A7: Çıkarma Bütçesi | B7: =IFERROR(ButceFarki+ToplamCikarmaMaliyeti,CikarmaButceEsik)
A8: Bütçe Kullanım Oranı | B8: =ButceKullanimOrani
A9: Ortalama Kıdem Yılı | B9: =OrtalamaKidemYil
A11: KARAR | B11: =IF(VeriKaliteSkoru=0,"VERİ YOK",IF(OR(ToplamCikarmaMaliyeti<0,AnomaliCalisanAdedi<0),"DURDUR",IF(ToplamCikarmaMaliyeti>CikarmaButceEsik,"DURDUR",IF(ButceKullanimOrani>ButceKullanimEsik,"İNCELE",IF(OrtalamaKidemYil>KidemYilEsik,"İNCELE","UYGUN")))))
A12: GEREKÇE | B12: =IF(VeriKaliteSkoru=0,"Girdi eksik; lütfen sarı hücreleri doldurun.",IF(ToplamCikarmaMaliyeti<0,"Çıkarma maliyeti negatif: ücret kayıtlarını kontrol edin.",IF(ToplamCikarmaMaliyeti>CikarmaButceEsik,"Toplam maliyet "&TEXT(ToplamCikarmaMaliyeti,"#,##0")&" ₺ bütçeyi aşıyor; planı revize edin.",IF(ButceKullanimOrani>ButceKullanimEsik,"Bütçenin "&TEXT(ButceKullanimOrani,"0.0%")&" kullanılıyor; kaynak planına ihtiyaç var.",IF(OrtalamaKidemYil>KidemYilEsik,"AVERAGE kıdem "&TEXT(OrtalamaKidemYil,"0")&" yıl eşik üstünde; kıdem yükü yüksek.","Kıdem, ihbar AND izin yükü bütçe AND eşikler içinde kabul edilebilir.")))))
A14: AKSİYONLAR
A15: =IF(OR(KararSonuc="VERİ YOK",KararSonuc="DURDUR"),"Çalışan ücret AND tarih kayıtlarını bordroyla mutabakat edin; tavanı AND bütçeyi yeniden değerlendirin",IF(ButceKullanimOrani>ButceKullanimEsik,"Çıkarma planını dönemlere yayın AND bütçeyi revize edin","Çıkarma planını AND ödeme takvimini bütçeye işleyin"))
A16: =IF(OrtalamaKidemYil>KidemYilEsik,"Kıdem yükü yüksek çalışanlar için tavan AND sözleşme koşullarını teyit edin","Kıdem yükü kabul edilebilir seviyede")
A17: =IF(AnomaliCalisanAdedi>0,"Anomali ücretli çalışanların bordro AND sözleşmelerini inceleyin","Ücret dağılımı tutarlı")
A18: =IF(ButceFarki<0,"Bütçe açığı "&TEXT(ABS(ButceFarki),"#,##0")&" ₺; kaynak planını güçlendirin","Bütçe farkı pozitif; planlama sürdürülebilir")
A21: Karar, gerekçe ve aksiyonlar makine tarafından üretilir; yalnızca sarı hücreler değiştirilebilir.

Sheet SENARYO_DUYARLILIK
A1: SENARYO DUYARLILIK — KIDEM–İHBAR YÜKÜ VE PERSONEL ÇIKARMA MALİYETİ HESAPLAYICI
A3: Senaryo ve Duyarlılık Analizi
A5: A. SENARYO MOTORU
A6: Senaryo | B6: Ücret Çarpanı | C6: Çalışan Çarpanı | D6: Toplam Maliyet (₺) | E6: Bütçe Kullanımı | F6: İzin Ücreti (₺) | G6: Karar
A7: KÖTÜMSER | B7: =IFERROR(IF(COUNT(tblCalisan[Brüt Ücret (₺)])=0,1+SenaryoKotumserKat,MAX(1+SenaryoKotumserKat,MAX(tblCalisan[Brüt Ücret (₺)])/IFERROR(AVERAGE(tblCalisan[Brüt Ücret (₺)]),1))),1+SenaryoKotumserKat) | C7: =IFERROR(IF(COUNT(tblCalisan[Çalışan Adı])=0,1+SenaryoKotumserKat,1+SenaryoKotumserKat),1+SenaryoKotumserKat) | D7: =IFERROR(ToplamCikarmaMaliyeti*B7*C7,0) | E7: =IFERROR(IF(CikarmaButceEsik=0,0,D7/CikarmaButceEsik),0) | F7: =IFERROR(ToplamIzinUcreti*B7*C7,0) | G7: =IF(VeriKaliteSkoru=0,"VERİ YOK",IF(D7>CikarmaButceEsik,"DURDUR",IF(E7>ButceKullanimEsik,"İNCELE","UYGUN")))
A8: BAZ | B8: =1 | C8: =1 | D8: =IFERROR(ToplamCikarmaMaliyeti*B8*C8,0) | E8: =IFERROR(IF(CikarmaButceEsik=0,0,D8/CikarmaButceEsik),0) | F8: =IFERROR(ToplamIzinUcreti*B8*C8,0) | G8: =IF(VeriKaliteSkoru=0,"VERİ YOK",IF(D8>CikarmaButceEsik,"DURDUR",IF(E8>ButceKullanimEsik,"İNCELE","UYGUN")))
A9: İYİMSER | B9: =IFERROR(IF(COUNT(tblCalisan[Brüt Ücret (₺)])=0,1-SenaryoIyimserKat,MAX(1-SenaryoIyimserKat,MIN(tblCalisan[Brüt Ücret (₺)])/IFERROR(AVERAGE(tblCalisan[Brüt Ücret (₺)]),1))),1-SenaryoIyimserKat) | C9: =IFERROR(IF(COUNT(tblCalisan[Çalışan Adı])=0,1-SenaryoIyimserKat,1-SenaryoIyimserKat),1-SenaryoIyimserKat) | D9: =IFERROR(ToplamCikarmaMaliyeti*B9*C9,0) | E9: =IFERROR(IF(CikarmaButceEsik=0,0,D9/CikarmaButceEsik),0) | F9: =IFERROR(ToplamIzinUcreti*B9*C9,0) | G9: =IF(VeriKaliteSkoru=0,"VERİ YOK",IF(D9>CikarmaButceEsik,"DURDUR",IF(E9>ButceKullanimEsik,"İNCELE","UYGUN")))
A11: B. TORNADO / DUYARLILIK
A12: Değişken | B12: Alt (-%5) | C12: Baz | D12: Üst (+%5) | E12: Maliyet Alt | F12: Maliyet Üst | G12: Etki (puan)
A13: Ücret Seviyesi | B13: =ToplamCikarmaMaliyeti*(1-DuyarliDegisim) | C13: =ToplamCikarmaMaliyeti | D13: =ToplamCikarmaMaliyeti*(1+DuyarliDegisim) | E13: =B13/CikarmaButceEsik | F13: =D13/CikarmaButceEsik | G13: =ABS(F13-E13)
A14: Çalışan Sayısı | B14: =ToplamCikarmaMaliyeti*(1-DuyarliDegisim) | C14: =ToplamCikarmaMaliyeti | D14: =ToplamCikarmaMaliyeti*(1+DuyarliDegisim) | E14: =B14/CikarmaButceEsik | F14: =D14/CikarmaButceEsik | G14: =ABS(F14-E14)
A16: C. EŞİK / KIRILIM ANALİZİ
A17: Kırılım: Maliyeti Bütçeye Çeken Ücret Azaltımı | B17: =IFERROR(IF(ToplamCikarmaMaliyeti=0,0,(ToplamCikarmaMaliyeti-CikarmaButceEsik)/ToplamCikarmaMaliyeti),0)
A18: Bütçe Kullanım Oranı - Eşik Farkı | B18: =IFERROR(ButceKullanimOrani-ButceKullanimEsik,0)
A19: Değer Ölçer: Toplam Maliyet + Bütçe Aşımı | B19: =IFERROR(ToplamCikarmaMaliyeti+MAX(0,ToplamCikarmaMaliyeti-CikarmaButceEsik),0)
A21: Senaryo çarpanları ve duyarlılık oranı AYARLAR'dan gelir.

Sheet RAPOR
A1: KIDEM–İHBAR YÜKÜ VE ÇIKARMA MALİYETİ RAPORU
A2: =firmaUnvani
A3: =TEXT(raporTarihi,"gg.aa.yyyy") & " | Rapor: " & TEXT(raporTarihi,"gg.aa.yyyy")
A5: 1. ÖZET
A6: Toplam Çalışan Sayısı | B6: =ToplamCalisanSayisi
A7: Toplam Çıkarma Maliyeti | B7: =ToplamCikarmaMaliyeti
A8: Bütçe Kullanım Oranı | B8: =ButceKullanimOrani
A9: Ortalama Kıdem Yılı | B9: =OrtalamaKidemYil
A10: Karar | B10: =KararSonuc
A12: 2. KARAR GEREKÇESİ
A13: =KararGerekce
A15: 3. VARSAYIMLAR
A16: • Kıdem tazminatı tavanı yıllık Resmi Gazete duyurusundan AYARLAR'a işlenir; dosya yalnızca oradan okur.
A17: • İhbar süreleri 4857 s. Kanun md.17 kıdem dilimlerinden (2/4/6/8 hafta) formülle seçilir.
A18: • Yıllık izin hakkı 4857 s. Kanun md.53 çalışma yılına göre (14/20/26 gün) belirlenir.
A19: • Kullanılmamış izin ücreti hak edilen izin günü eksi kullanılan izin günü ile günlük ücretin çarpımıdır.
A20: • Toplam çıkarma maliyeti; kıdem + ihbar + kullanılmamış izin ücretinden oluşur; diğer ödemeler (SGK eksik prim, kıdem avansı) dahil değildir.
A22: 4. UYARILAR
A23: =IF(ToplamCikarmaMaliyeti>CikarmaButceEsik,"Toplam maliyet bütçeyi aşıyor; planı revize edin.","Maliyet bütçe içinde görünüyor.")
A24: =IF(OrtalamaKidemYil>KidemYilEsik,"AVERAGE kıdem eşik üstünde; kıdem yükü yüksek.","Kıdem yükü kabul edilebilir seviyede.")
A26: 5. ÖNERİLEN AKSİYONLAR
A27: =Aksiyon1
A28: =Aksiyon2
A29: =Aksiyon3
A31: =firmaUnvani & " | " & TEXT(raporTarihi,"gg.aa.yyyy") & " | Rev 1.0"
A32: Bu rapor karar destek çıktısıdır; iş hukuku veya mali müşavirlik danışmanlığı yerine geçmez.

Sheet ORNEK_VERI
A1: ORNEK VERI — KIDEM–İHBAR YÜKÜ VE PERSONEL ÇIKARMA MALİYETİ HESAPLAYICI
A3: Örnek Veri ve İçe Aktarma Yapısı
A4: Bu sayfa otomasyon ve içe aktarma için yapıdır; çalışan satırlarını CSV/Excel'den kopyalayabilirsiniz.
A6: Çalışan Adı | B6: İşe Giriş Tarihi | C6: İşten Çıkış Tarihi | D6: Brüt Ücret (₺) | E6: Ücret Türü | F6: Kullanılan İzin
A7: Ahmet Yılmaz | B7: 43891 | C7: 46235 | D7: 45000 | E7: Aylık | F7: 5
A8: Ayşe Kaya | B8: 42156 | C8: 46266 | D8: 55000 | E8: Aylık | F8: 8
A9: Mehmet Demir | B9: 44576 | C9: 46218 | D9: 1800 | E9: Günlük | F9: 2
A12: Örnek veri giriş sayfalarını beslemek için değil, yapıyı göstermek içindir.

Sheet KURALLAR
A1: KURALLAR — eski35_kidem-ihbar-yuku-ve-personel-cikarma-maliyeti-hesaplayici_uretildi
A3: kural_id | B3: aciklama | C3: deger_2025 | D3: deger_2026 | E3: deger_2027 | F3: kaynak
A4: K1 | B4: Kurumlar vergisi oranı | C4: 0.25 | D4: 0.25 | E4: 0.25 | F4: KV
A5: K2 | B5: İskonto / referans oran | C5: 0.2 | D5: 0.2 | E5: 0.2 | F5: AYARLAR

Sheet VAKALAR
A1: VAKALAR — eski35_kidem-ihbar-yuku-ve-personel-cikarma-maliyeti-hesaplayici_uretildi
A3: Tebliğ tarzı altın vakalar
A5: vaka_id | B5: aciklama | C5: girdi_ozeti | D5: beklenen_sonuc | E5: hesaplanan | F5: fark | G5: durum | H5: kaynak
A6: V1 | B6: Baz senaryo tutarlılık | C6: örnek girdi | D6: 0 | E6: 0 | F6: 0 | G6: TUTARLI | H6: iç test

Sheet DEGISIKLIK_KAYDI
A1: DEGISIKLIK KAYDI — KIDEM–İHBAR YÜKÜ VE PERSONEL ÇIKARMA MALİYETİ HESAPLAYICI
A3: Değişiklik Kaydı
A5: Tarih | B5: Sürüm | C5: Değişiklik
A6: 09.08.2026 | B6: 1.0 | C6: İlk sürüm: 1475 md.14 kıdem tazminatı (tavan sınırlı), 4857 md.17 ihbar süreleri, 4857 md.53 izin hakkı ve toplam çıkarma maliyeti.
A8: Sürüm izi ve lisans bilgisi KAPAK sayfasında da yer alır.

Sheet LISTELER
A1: LISTELER — KIDEM–İHBAR YÜKÜ VE PERSONEL ÇIKARMA MALİYETİ HESAPLAYICI
A3: Açılır Liste Kaynakları
A4: Ücret Türü
A6: Aylık
A7: Günlük
A10: Listeler AYARLAR sayfasındaki ayarlarla birlikte doğrulama aralıklarını besler.

Sheet AYARLAR
A1: AYARLAR — KIDEM–İHBAR YÜKÜ VE PERSONEL ÇIKARMA MALİYETİ HESAPLAYICI
A3: Ayarlar ve Eşikler (Formüle Sabit Sayı Girilmez)
A4: Tüm katsayı ve eşikler bu sayfadadır. Mevzuat değişikliklerinde AYARLAR'dan güncellenir; formüller değişmez. Kaynağı Varsayım işaretli değerler kullanıcı tarafından doğrulanmalıdır.
A5: Grup | B5: Anahtar | C5: Değer | D5: Birim | E5: Açıklama | F5: kaynak | G5: yururluk_tarihi | H5: dogrulama_tarihi
A6: Genel | B6: firmaUnvani | C6: Örnek Şirket A.Ş. | D6: metin | E6: Rapor başlığında görünen firma adı | F6: Kullanıcı | G6: 09.08.2026 | H6: 09.08.2026
A7: Genel | B7: raporTarihi | C7: =TODAY() | D7: tarih | E7: Dosyadaki tek tarih kaynağı; tüm rapor tarihleri buradan okunur. | F7: Kullanıcı | G7: 09.08.2026 | H7: 09.08.2026
A8: Kıdem | B8: KidemTavan | C8: 45000 | D8: ₺ | E8: Kıdem tazminatı aylık tavanı; yıllık Resmi Gazete duyurusundan güncellenir. | F8: Hazine ve Maliye Bakanlığı duyurusu (yıllık); güncel değer kullanıcı doğrulamalı | G8: 09.08.2026 | H8: 09.08.2026
A9: Kıdem | B9: UcretGunSayisi | C9: 30 | D9: gün | E9: Aylık ücretin günlük karşılığı için bölünen gün sayısı. | F9: 1475 s. Kanun md.14 uygulaması | G9: 01.09.1971 | H9: 09.08.2026
A10: İhbar | B10: IhbarSure1 | C10: 14 | D10: gün | E10: Kıdem 6 aydan az: bildirim süresi (2 hafta). | F10: 4857 s. Kanun md.17 | G10: 10.06.2003 | H10: 09.08.2026
A11: İhbar | B11: IhbarSure2 | C11: 28 | D11: gün | E11: Kıdem 6 ay-1,5 yıl: bildirim süresi (4 hafta). | F11: 4857 s. Kanun md.17 | G11: 10.06.2003 | H11: 09.08.2026
A12: İhbar | B12: IhbarSure3 | C12: 42 | D12: gün | E12: Kıdem 1,5-3 yıl: bildirim süresi (6 hafta). | F12: 4857 s. Kanun md.17 | G12: 10.06.2003 | H12: 09.08.2026
A13: İhbar | B13: IhbarSure4 | C13: 56 | D13: gün | E13: Kıdem 3 yıldan fazla: bildirim süresi (8 hafta). | F13: 4857 s. Kanun md.17 | G13: 10.06.2003 | H13: 09.08.2026
A14: İhbar | B14: IhbarEsik1Gun | C14: 180 | D14: gün | E14: İhbar 2. kademe geçiş kıdem eşiği (6 ay). | F14: 4857 s. Kanun md.17 | G14: 10.06.2003 | H14: 09.08.2026
A15: İhbar | B15: IhbarEsik2Gun | C15: 547 | D15: gün | E15: İhbar 3. kademe geçiş kıdem eşiği (1,5 yıl). | F15: 4857 s. Kanun md.17 | G15: 10.06.2003 | H15: 09.08.2026
A16: İhbar | B16: IhbarEsik3Gun | C16: 1095 | D16: gün | E16: İhbar 4. kademe geçiş kıdem eşiği (3 yıl). | F16: 4857 s. Kanun md.17 | G16: 10.06.2003 | H16: 09.08.2026
A17: İzin | B17: IzinHakki1 | C17: 14 | D17: gün | E17: Kıdem 1-5 yıl: yıllık izin hakkı. | F17: 4857 s. Kanun md.53 | G17: 10.06.2003 | H17: 09.08.2026
A18: İzin | B18: IzinHakki2 | C18: 20 | D18: gün | E18: Kıdem 5-15 yıl: yıllık izin hakkı. | F18: 4857 s. Kanun md.53 | G18: 10.06.2003 | H18: 09.08.2026
A19: İzin | B19: IzinHakki3 | C19: 26 | D19: gün | E19: Kıdem 15 yıl ve üzeri: yıllık izin hakkı. | F19: 4857 s. Kanun md.53 | G19: 10.06.2003 | H19: 09.08.2026
... A35: Nakit | B35: IskontoOrani | C35: 0.1 | D35: oran | E35: Maliyet yükü net bugünkü değer hesabında iskonto oranı. | F35: Varsayım | G35: 09.08.2026 | H35: 09.08.2026
A37: Not: raporTarihi dışında TODAY()/NOW() gibi volatil fonksiyon kullanılmaz.
A39: Gelişmiş ayarlar; ana kullanıcının değiştirmesi gerekmez.

Sheet KILAVUZ
A1: KILAVUZ — KIDEM–İHBAR YÜKÜ VE PERSONEL ÇIKARMA MALİYETİ HESAPLAYICI
A3: Kullanım Kılavuzu
A5: 1. Ne yapar?
A6: 2. Hangi sayfa sırasıyla gidilir?
A7: 3. Sarı hücreler ne demek?
A8: 4. Kıdem tazminatı nasıl hesaplanır?
A9: 5. İhbar süresi nasıl belirlenir?
A10: 6. İzin ücreti nasıl hesaplanır?
A11: 7. Karar nasıl okunur?
A12: 8. Güvenlik ve KVKK
A13: 9. Kaynaklar ve varsayımlar
A14: 10. Ortam beyanı
... A28: ExcelArşiv | Kıdem–İhbar Yükü ve Personel Çıkarma Maliyeti Hesaplayıcı | Rev 1.0 | 2026-08-09
