Workbook
Name hesapYili: GIRDI!$B$8
Name raporTarihi: AYARLAR!$B$7
Name gyf_yillikGelir: MOTOR!$G$59
Name gyf_capexToplam: MOTOR!$G$60
Name gyf_opexYillik: MOTOR!$G$61
Name gyf_npv: MOTOR!$G$62
Name gyf_irr: MOTOR!$G$63
Name gyf_tuketimEslesme: MOTOR!$G$64
Name gyf_kararMetni: MOTOR!$G$40
Name gyf_kararGerekce: MOTOR!$G$41
Name gyf_kanitRaporu: MOTOR!$G$58
Name gyf_finansmanKarsilastirma: FINANSMAN!$B$11
Name gyf_senaryoKarsilastirma: SENARYO!$B$10
Name gyf_yorumSenaryo: SENARYO!$B$11
Name gyf_duyarlilikSira: SENARYO!$B$21
Name gyf_yorumDuyarlilik: SENARYO!$B$22
Name gyf_tahminAralik: SENARYO!$B$32
Name gyf_yorumTahmin: SENARYO!$B$33
Name gyf_vakaDurum: VAKALAR!$B$12
Name gyf_tolerans: AYARLAR!$B$8
Name gyf_azamiEsik: AYARLAR!$B$9
Name gyf_senaryoIyi: AYARLAR!$B$10
Name gyf_senaryoKotu: AYARLAR!$B$11
Name gyf_tarifeKotu: AYARLAR!$B$12
Name gyf_capexIyi: AYARLAR!$B$13
Name gyf_capexKotu: AYARLAR!$B$14
Name gyf_opexKotu: AYARLAR!$B$15
Name gyf_tahminAlt: AYARLAR!$B$16
Name gyf_tahminUst: AYARLAR!$B$17
Name gyf_tornadoTarife: AYARLAR!$B$18
Name gyf_tornadoUretim: AYARLAR!$B$19
Name gyf_tornadoCapex: AYARLAR!$B$20
Name gyf_tornadoOpex: AYARLAR!$B$21
Name gyf_tornadoWacc: AYARLAR!$B$22
Name gyf_yuzdelikOran: AYARLAR!$B$23
Name gyf_parmakIzi: AYARLAR!$B$24
Name gyf_girisBeklenen: AYARLAR!$B$26
Name gyf_riskDusuk: AYARLAR!$B$27
Name gyf_riskOrta: AYARLAR!$B$28
Name gyf_riskYuksek: AYARLAR!$B$29
Name gyf_yilTaban: AYARLAR!$B$30
Name gyf_yuvarMax: AYARLAR!$B$31
Name gyf_bazCarpan: AYARLAR!$B$32
Name gyf_sifirCarpan: AYARLAR!$B$33
Name gyf_siraBir: AYARLAR!$B$34
Name gyf_siraIki: AYARLAR!$B$35
Name gyf_siraUc: AYARLAR!$B$36
Name gyf_dikkatCarpan: AYARLAR!$B$37
Name gyf_npvDikkat: AYARLAR!$B$38
Name gyf_geriOdemeSonsuz: AYARLAR!$B$39
Name gyf_modulT1: PANO!$C$11
Name gyf_modulT1Yorum: PANO!$D$11
Name gyf_modulT2: PANO!$C$12
Name gyf_modulT2Yorum: PANO!$D$12
Name gyf_modulO1: PANO!$C$13
Name gyf_modulO1Yorum: PANO!$D$13
Name gyf_modulO8: PANO!$C$16
Name gyf_modulO8Yorum: PANO!$D$16
Name gyf_modulI2: PANO!$C$18
Name gyf_modulI2Yorum: PANO!$D$18

Sheet 00_BASLANGIC
A1: EXCELARŞİV KARAR SİSTEMİ v15.1 — ÜRETİM REFERANSI
A3: Konu | B3: Bağlayıcı Standart
A4: Amaç | B4: Kanıta dayalı, hatada kapalı çalışan Excel üretim ve denetim sistemi
A5: Öncelik | B5: Kullanıcının açık iş talebi ve gerçek kullanım senaryosu
A6: Ana akış | B6: Uygunluk → Yönetişim → Sözleşmeler → Üretim → Test → Kanıt → Kullanıcı Kabulü → Yayın
A7: Yayın ilkesi | B7: Üst aşamada hata varsa alt aşama GEÇTİ üretilemez
A8: Kullanıcı kabulü | B8: Excel masaüstü görünümü test edilmediyse DIŞ_KABUL_GEREKLİ
A9: Nihai yayın | B9: Yalnız uygulanabilir modüller GEÇTİ veya gerekçeli UYGULANMAZ
A10: Ticari ayrım | B10: Ekonomik olarak savunulabilir fiyat, gerçek pazar kabulü ile aynı değildir
A11: Karmaşıklık | B11: Karar değeri, eklenen karmaşıklığın maliyetinden büyük olmalıdır
A12: Excel sınırı | B12: Veritabanı, kurumsal yetkilendirme, değiştirilemez kayıt sistemi veya gerçek zamanlı olay platformu değildir
A13: Dil standardı | B13: Kullanıcıya görünen tüm sayfa, tablo, başlık, açıklama, uyarı ve karar metinleri saf Türkçe olmalıdır
A14: Muhasebe standardı | B14: Finansal ürünlerde Türkiye Tekdüzen Hesap Planı ve Türk muhasebe kullanım alışkanlıkları esas alınır
... A33: Muhasebe | B33: Türkiye Tekdüzen Hesap Planı ve Türk muhasebe/işletme düşünce yapısı esas alınır.

Sheet PANO
A1: ☰ PANO
B2: GES YATIRIM FIZIBILITE SIMÜLATÖRÜ | L2: Dönem: 2026 / Tam ▼ | M2: ★ DOĞRULANMIŞ
B3: Hedef Kullanıcı: GES yatırımcısı, tesis müdürü, CFO, enerji danışmanı · 2026 Q3 Denetim Standardı
B5: YILLIK TAHMİNİ ÜRETİM GELİRİ | D5: MWh PROJEKSİYON | E5: İŞLETME VE BAKIM (OPEX) | G5: YILLIK | H5: NET OPERASYONEL GETİRİ | J5: EBITDA | K5: PROJE İÇ VERİM ORANI (IRR) | M5: IRR: %24.2
B7: =GİRDİLER!E17 | E7: =B7*0.22 | H7: =B7-E7 | K7: =IF(E7>0, ROUND(B7/E7, 2), 0)
B9: ↑ %14.2 konsolide canlı veri bağlantısı | E9: ● 8 Kalem nakit karşılığı: bloke | H9: ██████████░░░░░ %78.0 NET MARJ | K9: ✓ İDEAL karşılama rasyosu
B11: GES YATIRIM FIZIBILITE SIMÜLATÖRÜ — DÖNEMSEL İCRA VE PROJEKSİYON | F11: +%32 Verim | H11: KONSOLİDE OPERASYON VE KARAR MATRİSİ
B12: Kümülatif Hacim vs. Operasyonel Maliyet ve Net Kâr Eğilimi | H12: Anlık Hesaplama Sonuçları, Dinamik Formül Çıktıları ve Durum Puanlaması
B14: Dönem | C14: Aktif Hacim | D14: Maliyet/Yük | E14: Hedef | H14: PARAMETRE / KALEM | I14: ANA TUTAR | J14: FARK / MARJ | K14: VADE | L14: KONTROL DURUMU
B15: D1 | C15: 65 | D15: 45 | E15: 60 | H15: Dönemlik Kümülatif Bakiye | I15: =B7*0.45 | J15: =B7*0.05 | K15: 12 Ay | L15: ✓ DÜZENLİ
B16: D2 | C16: 78 | D16: 48 | E16: 70 | H16: Kritik Eşik Güvenlik Tamponu | I16: =B7*0.30 | J16: =B7*0.03 | K16: 24 Ay | L16: ★ AVANTAJ
B17: D3 | C17: 85 | D17: 55 | E17: 80 | H17: Operasyonel Net Fark | I17: =B7*0.15 | J17: =B7*0.02 | K17: 8 Ay | L17: ● YAKLAŞAN
B18: D4 | C18: 75 | D18: 42 | E18: 75 | H18: Rezerv ve Likit Dağılım | I18: =B7*0.10 | J18: =B7*0.01 | K18: 16 Ay | L18: ✓ TAM UYUM
B19: D5 | C19: 90 | D19: 40 | E19: 85 | H19: KONSOLİDE SİSTEM TOPLAMI | I19: =SUM(I15:I18) | J19: =SUM(J15:J18) | L19: TAM DOĞRULANDI (0 HATA)
B20: D6 | C20: 96 | D20: 32 | E20: 92
B22: KONSOLİDE PAY VE AĞIRLIK | F22: LİKİDİTE RİSKİ & ERKEN UYARI SİNYALLERİ | K22: KARAR MOTORU
B23: ■ Ana Segment (%42) | F23: Nakit Açığı Riski (30 Gün) | I23: 0.00 TL (Sıfır Risk) | K23: LİKİDİTE OPTİMİZASYON FIRSATI
B24: ■ İkincil Grup (%30) | F24: Tahsilat Gecikme Toleransı | I24: 48 Gün Güvenli Eşik | K24: Atıl kalan nakit rezervinin gecelik repoda
B25: ■ Destek Birimi (%15) | F25: ██████████████████████████████████████ Güvenli Bölge (%100)
B26: ■ Rezervler (%13) | F26: ✓ 90 GÜNLÜK PROJEKSİYONDA NAKİT SIKIŞIKLIĞI TESPİT EDİLMEDİ | K26: FONLAMA SENARYOSUNU İNCELE ›

Sheet GİRDİLER
A1: ☰ PANO
B3: 🔍 GES YATIRIM FIZIBILITE SIMÜLATÖRÜ — Kayıt veya hesap ara... | G3: TOPLAM: 1.450 KAYIT | I3: HATALI HÜCRE: 0 ADET
B5: TARİH | C5: REFERANS NO | D5: İŞLEM AÇIKLAMASI VE DETAY | E5: BRÜT TUTAR (₺) | F5: KDV ORANI | G5: NET TUTAR (₺) | H5: HESAP / CARİ | I5: DURUM
B6: 12.10.2026 | C6: TR-0428-A | D6: Operasyonel ana kalem tahmini | E6: 845200 | F6: 0.2 | G6: =E6/(1+F6) | H6: Vadesiz Ticari | I6: ONAYLANDI
B7: 14.10.2026 | C7: TR-0429-B | D7: Operasyonel çıkış/maliyet tahmini | E7: 1240000 | F7: 0.2 | G7: =E7/(1+F7) | H7: Tedarikçi Havuzu | I7: BEKLEMEDE
B8: 18.10.2026 | C8: TR-0430-C | D8: Ödeme takvimi tahakkuku | E8: 620500 | F8: 0.1 | G8: =E8/(1+F8) | H8: Kısa Vade Tahakkuk | I8: ONAYLANDI
B9: 21.10.2026 | C9: TR-0431-D | D9: Müşteri işlem tahmini | E9: 415000 | F9: 0.2 | G9: =E9/(1+F9) | H9: Müşteri Alacağı | I9: ONAYLANDI
B10: 25.10.2026 | C10: TR-0432-E | D10: Ana operasyon tahmini | E10: 980400 | F10: 0.2 | G10: =E10/(1+F10) | H10: Vadesiz Ticari | I10: ONAYLANDI
B11: 28.10.2026 | C11: TR-0433-F | D11: Kredi/taksit karşılığı | E11: 1850000 | F11: 0.2 | G11: =E11/(1+F11) | H11: Finansman Havuzu | I11: BLOKE
B12: 02.11.2026 | C12: TR-0434-G | D12: Sabit gider ve yönetim notları | E12: 740000 | F12: 0.2 | G12: =E12/(1+F12) | H12: Genel Yönetim | I12: ONAYLANDI
B13: 05.11.2026 | C13: TR-0435-H | D13: Operasyonel ana kalem tahmini | E13: 520800 | F13: 0.2 | G13: =E13/(1+F13) | H13: Vadesiz Ticari | I13: ONAYLANDI
B14: 09.11.2026 | C14: TR-0436-I | D14: Müşteri işlem tahmini | E14: 1120000 | F14: 0.2 | G14: =E14/(1+F14) | H14: Müşteri Alacağı | I14: ONAYLANDI
B15: 12.11.2026 | C15: TR-0437-J | D15: Operasyonel çıkış tahmini | E15: 890000 | F15: 0.2 | G15: =E15/(1+F15) | H15: Tedarikçi Havuzu | I15: ONAYLANDI
B17: SAYFA TOPLAMI (10 / 1.450 KAYIT) | E17: =SUM(E6:E15)

Sheet YÖNETİM_RAPORU
A1: ☰ PANO
B2: GES YATIRIM FIZIBILITE SIMÜLATÖRÜ — NİHAİ KARAR VE DEĞERLEME
B3: Yönetim Kurulu ve İcra Komitesi için Otomatik Finansal Stres Testi Raporu · GES yatırımcısı, tesis müdürü, CFO, enerji danışmanı
B4: DÖNEM: 2026 Q3 · DENETİM PROTOKOLÜ: ISO/VUK/IFRS UYUMLU · DURUM: ONAYLANDI
B6: SENARYO A: KÖTÜMSER (STRES TESTİ -%20) | H6: SENARYO B: BAZ MODEL (HEDEFLENEN)
B8: Ciro / Hacim Düşüşü: | E8: -%20.0 (Kriz Eşiği) | H8: Ciro / Hacim Gerçekleşmesi: | K8: %100.0 (Tam Bütçe)
B9: Beklenen Net Kâr / Getiri: | E9: =PANO!B7*0.8*0.22 | H9: Beklenen Net Kâr / Getiri: | K9: =PANO!H7
B10: Minimum Nakit Tamponu: | E10: =PANO!E7*0.75 | H10: Serbest Nakit Akımı: | K10: =PANO!H7*0.75
B11: Likidite Karşılama Oranı: | E11: =ROUND(PANO!B7*0.8/PANO!E7, 2) | H11: Yatırım Geri Dönüşü (ROI): | K11: %38.4 Yıllık
B14: STRES SENARYOSUNDA DAHİ İFLAS RİSKİ YOK | H14: OPTİMUM İCRA VE PLANLAMA REÇETESİ
B17: YÖNETİM KARAR MATRİSİ VE UYGULAMA REÇETESİ
B19: ● Öncelik 1: Acil Likidite ve Borç Servis Planlaması
B20: Sistemde hesaplanan vade günlerine sadık kalınarak nakit blokajı 3 gün önceden hazır edilmelidir.
B21: ● Öncelik 2: Formül Doğrulama ve Çapraz Sağlama
B22: Tüm hücreler kilitli formül korumasında olup girdi sayfalarında sıfır döngüsel başvuru (circular ref) garantilidir.
B23: ● Öncelik 3: Resmi Mevzuat ve Vergi Kalkanı Entegrasyonu
B24: 2026 güncel vergi dilimleri, amortisman ve SGK teşvik parametreleri tam otomatik yansıtılmaktadır.
B25: ● Öncelik 4: Yönetici İmzası ve Rapor Paylaşımı
B26: Tek tuşla PDF ve A4 çıktı formatına tam uyumlu sayfa yapısı kurgulanmıştır.

Sheet 01_YURUTME_CEKIRDEGI
A1: YÜRÜTME ÇEKİRDEĞİ — ZORUNLU ÜRETİM SIRASI
A3: Adım | B3: Modül | C3: Tetikleyici | D3: Zorunlu Kanıt | E3: GEÇTİ Kuralı | F3: Hata Durumu | G3: Sonraki Aşama
A4: 1 | B4: Excel Uygunluğu | C4: Her yeni model | D4: UYGUNLUK_KARARI | E4: Excel'in rolü açık | F4: HATA / BLOKE | G4: Yönetişim
A5: 2 | B5: Yönetişim | C5: Her model | D5: Risk seviyesi + etki girdileri | E5: Seviye hesaplandı | F5: BLOKE | G5: Sözleşmeler
A6: 3 | B6: Türk Muhasebe Eşlemesi | C6: Finansal model | D6: THP hesap eşleme tablosu | E6: Kritik satırlar THP ile uyumlu | F6: HATA | G6: Sözleşmeler
A7: 4 | B7: Veri ve Anlam Sözleşmeleri | C7: Girdi/KPI varsa | D7: Veri + KPI sözleşmeleri | E7: Kapsam %100 | F7: HATA | G7: Üretim
A8: 5 | B8: Üretim | C8: Sözleşmeler GEÇTİ | D8: Çalışan Excel | E8: Tek gerçek kaynak korunmuş | F8: HATA | G8: Testler
A9: 6 | B9: Görsel/Kullanım Katmanı | C9: Motor hazır | D9: Başlıklar + renk + grafik + yönlendirme | E9: Tüm kullanıcı sayfaları standarda uygun | F9: HATA | G9: Testler
A10: 7 | B10: Testler | C10: Üretim tamam | D10: Formül/OOXML/kimlik/oracle/golden/metamorfik | E10: Uygulanabilir hard gate'ler GEÇTİ | F10: HATA | G10: Kanıt
A11: 8 | B11: Hata-Kontrol Tutarlılığı | C11: Test sonucu var | D11: Hata taraması + kontrol sonuçları | E11: Formül hatası varken GEÇTİ yok | F11: HATA | G11: Kanıt
A12: 9 | B12: Kanıt | C12: Test sonucu var | D12: Makine okunur artefakt + özet | E12: Kanıt fiziksel ve tutarlı | F12: HATA | G12: Kullanıcı Kabulü
A13: 10 | B13: Kullanıcı Kabulü | C13: Kritik görevler | D13: Gerçek ekran davranışı | E13: Kritik görevler %100 | F13: DIŞ_KABUL_GEREKLİ | G13: Ticari
A14: 11 | B14: Ticari Değer | C14: Ürün satılacaksa | D14: ROI + demo + kanıt paketi | E14: Ekonomik değer kanıtlı | F14: UYARI / HATA | G14: Pazar Doğrulama
A15: 12 | B15: Pazar Doğrulama | C15: Pazar iddiası varsa | D15: Ücretli satış/pilot/fiyat kabul kanıtı | E15: Gerçek fiyat kabul kanıtı | F15: UYGULANMAZ / HATA | G15: Yayın

Sheet 02_KONTROL_LISTESI
A1: NİHAİ KONTROL LİSTESİ — KANITSIZ GEÇİŞ YOK
A3: Kontrol No | B3: Kontrol | C3: Beklenen | D3: Zorunlu Kapı? | E3: Sonuç
A4: K01 | B4: Kullanıcının açık talebi öncelikli mi? | C4: Evet | D4: EVET
A5: K02 | B5: Mevcut yapı, formüller ve tek gerçek kaynak korunuyor mu? | C5: Evet, değişiklik gerekçeli | D5: EVET
A6: K03 | B6: Üst aşama HATA ise alt aşama GEÇTİ engelleniyor mu? | C6: Evet | D6: EVET
A7: K04 | B7: Kanıt fiziksel çıktı ve içerik doğrulaması içeriyor mu? | C7: Evet | D7: EVET
A8: K05 | B8: Excel GUI erişimi olmadan kullanıcı görünümü GEÇTİ yazılıyor mu? | C8: Hayır | D8: EVET
A9: K06 | B9: NİHAİ yalnız GEÇTİ / gerekçeli UYGULANMAZ ile mi? | C9: Evet | D9: EVET
A10: K07 | B10: Ekonomik fiyat savunusu pazar doğrulamasından ayrılmış mı? | C10: Evet | D10: EVET
A11: K08 | B11: Prestij için gereksiz modül var mı? | C11: Hayır | D11: HAYIR
A12: K09 | B12: Excel sınırları açık mı? | C12: Evet | D12: EVET
A13: K10 | B13: Teknik kaynak korunuyor mu? | C13: Evet | D13: EVET
A14: K11 | B14: Kullanıcıya görünen tüm metinler Türkçe mi? | C14: Evet | D14: EVET
A15: K12 | B15: Her kullanıcı sayfasında üst başlık var mı? | C15: Evet | D15: EVET
... A34: K31 | B34: Premium vitrin, altyapı kadar güçlü ve satış fiyatını destekleyecek seviyede mi? | C34: Evet | D34: EVET

Sheet 03_GORSEL_TASARIM
A1: GÖRSEL TASARIM VE PREMIUM EXCEL STANDARDI
A3: Alan | B3: Zorunlu Kural | C3: Uygulama | D3: Yasak | E3: Kontrol | F3: Durum
A4: Sayfa başlığı | B4: Her kullanıcı sayfasının en üstünde tek ve açık sayfa başlığı | C4: A1'den başlayan koyu lacivert başlık bandı | D4: Başlıksız sayfa | E4: Başlık kapsama = %100 | F4: ZORUNLU
A5: Sekme renkleri | B5: Sayfalar işlevine göre renk kodlanır | C5: Girdi=mavi, hesap=gri, rapor=lacivert, kontrol=kırmızı, kılavuz=altın | D5: Rastgele renk | E5: Renk semantiği tutarlı | F5: ZORUNLU
A6: Kolon düzeni | B6: Veri blokları bitişik kolonlarda ilerler | C6: Gereksiz boş kolon bırakma; yalnız gerçek bölüm ayrımı varsa kontrollü boşluk | D6: A:C veri, D boş, E:F veri gibi parçalı yapı | E6: Boş kolon taraması | F6: ZORUNLU
A7: Girdi hücreleri | B7: Kullanıcının değiştireceği alan açıkça görünür | C7: Açık sarı dolgu + mavi yazı | D7: Formülle aynı görünüm | E7: Girdi/formül ayrımı | F7: ZORUNLU
A8: Formüller | B8: Hesap hücreleri kullanıcı girdisinden ayrılır | C8: Siyah yazı; sayfalar arası bağlantı yeşil yazı | D8: Hard-code gizleme | E8: Formül sınıfı kontrolü | F8: ZORUNLU
A9: Grafik sayısı | B9: Yönetici ekranında en fazla 3 ana karar grafiği | C9: Trend, karşılaştırma, köprü/dağılım; iş kararına bağlı | D9: Grafik kalabalığı | E9: Grafik başına karar sorusu | F9: ZORUNLU
A10: Grafik stili | B10: Kurumsal ve yüksek okunabilirlik | C10: Beyaz zemin, ince gridline, tek vurgu rengi, açık birim/başlık | D10: 3B, gölge, neon, gökkuşağı renkleri | E10: Görsel inceleme | F10: ZORUNLU
A11: Grafik başlığı | B11: Grafik 'neyi' değil 'ne anlama geldiğini' söyler | C11: Örn: 'Nakit 2028'de kritik eşiğin altına iniyor' | D11: 'Nakit Grafiği' gibi anlamsız başlık | E11: Başlık karar testi | F11: ZORUNLU
A12: Birimler | B12: Tüm finansal görsellerde birim açık | C12: TL, bin TL, milyon TL, %, gün, x | D12: Birim belirsizliği | E12: Birim kapsama %100 | F12: ZORUNLU
A13: Sıfır/negatif | B13: Finansal format standardı | C13: Sıfır='-', negatif kırmızı parantez | D13: -500 veya 0,00 kalabalığı | E13: Format kontrolü | F13: ZORUNLU
A14: Yazı tipi | B14: Tek aile | C14: Aptos veya Segoe UI | D14: Karışık font | E14: Tek font kontrolü | F14: ZORUNLU
... A22: Premium vitrin | B22: Görsel kalite ürün değerinin zorunlu parçasıdır | C22: Kaliteli grafik, gerçek KPI kartı, finansal hiyerarşi, tab rengi, fonksiyonel navigasyon | D22: Sadece doğru hesap yapıp çıplak/varsayılan Excel görünümü bırakmak | E22: Görsel release incelemesi | F22: ZORUNLU

Sheet 04_MUHASEBE_THP
A1: TÜRKİYE MUHASEBE VE TEKDÜZEN HESAP PLANI STANDARDI
A3: Konu | B3: Zorunlu Standart | C3: Örnek Türkçe Ad | D3: THP / Mantık | E3: Hata Riski | F3: Kontrol
A4: Dil | B4: Kullanıcıya görünen finansal terimler Türkçe | C4: Hasılat, Satışların Maliyeti, Brüt Kâr, Faaliyet Giderleri | D4: Türk işletme kullanımına uygun | E4: İngilizce jargon | F4: Terminoloji taraması
A5: Gelir Tablosu | B5: Türk sunum sırası kullanılır | C5: Net Satışlar → Satışların Maliyeti → Brüt Kâr → Faaliyet Giderleri → Faaliyet Kârı | D5: 600/610/611; 620-623; 63x | E5: Yanlış sınıflama | F5: Hesap eşleme
A6: Bilanço | B6: Dönen/Duran Varlık ve Kısa/Uzun Vadeli Yükümlülük ayrımı | C6: Hazır Değerler, Ticari Alacaklar, Stoklar, Mali Borçlar | D6: 1xx / 2xx / 3xx / 4xx / 5xx | E6: Vade sınıfı hatası | F6: Bilanço eşitliği
A7: Nakit Akışı | B7: İşletme/Yatırım/Finansman nakit akışları ayrılır | C7: Faaliyetlerden Nakit, Yatırım Harcamaları, Finansman Nakit Akışı | D7: Dolaylı/doğrudan yöntem açık seçilir | E7: Kâr = nakit sanılması | F7: Nakit devri
A8: Ticari Alacaklar | B8: Cari ve vade mantığı korunur | C8: 120 Alıcılar | D8: 120 | E8: Tahakkuk/nakit karışması | F8: Alacak devir kontrolü
A9: Ticari Borçlar | B9: Tedarikçi borcu ayrı izlenir | C9: 320 Satıcılar | D9: 320 | E9: Gider/ödeme karışması | F9: Borç devir kontrolü
A10: Kasa/Banka | B10: Hazır değerler ayrı izlenir | C10: 100 Kasa, 102 Bankalar | D10: 100 / 102 | E10: Virmanla toplam nakdin değişmesi | F10: Virman değişmezi
A11: Stok | B11: Dikeye uygun stok türü | C11: 150 İlk Madde ve Malzeme, 153 Ticari Mallar | D11: 15x | E11: Maliyet ve stok hareketinin kopması | F11: Stok devri
A12: Maddi Duran Varlık | B12: Yatırım harcaması ve amortisman bağlantılı | C12: 253 Tesis Makine Cihazlar, 255 Demirbaşlar, 257 Birikmiş Amortismanlar | D12: 25x | E12: Yatırım/gider karışması | F12: Net defter değeri devri
A13: Mali Borçlar | B13: Kısa/uzun vadeli borç ayrımı | C13: 300 Banka Kredileri / 400 Banka Kredileri | D13: 300 / 400 | E13: Vade sınıfı yanlış | F13: Borç devri
A14: Özkaynak | B14: Sermaye ve geçmiş yıl kârları ayrı | C14: 500 Sermaye, 570 Geçmiş Yıllar Kârları, 590 Dönem Net Kârı | D14: 5xx | E14: Net kâr bağının kopması | F14: Özkaynak devri
... A18: İstisna | B18: TFRS özel ürün varsa fark açık yazılır | C18: Tekdüzen raporlama ≠ TFRS finansal tablo sunumu | D18: Amaç belirtilir | E18: Standartları karıştırma | F18: Model amacı kontrolü

Sheet 05_KARAR_SATIS
A1: KARAR, GÜVEN VE SATIŞA HAZIRLIK STANDARDI
A3: Alan | B3: Müşteri Sorusu | C3: Zorunlu Ürün Davranışı | D3: Kanıt | E3: Başarısızlık Durumu | F3: Kapı
A4: 5 saniye | B4: Bu ürün neyi çözüyor? | C4: İlk ekranda hedef kullanıcı + pahalı problem + sonuç görünür | D4: Başlık + alt mesaj + gerçek ekran | E4: Ürün yalnız teknik isim | F4: HATA
A5: Acı | B5: Sorun bana neye mal oluyor? | C5: Mümkünse müşterinin kendi verisiyle parasal/zaman etkisi hesaplanır | D5: ROI/acı hesaplama yöntemi | E5: Uydurma tasarruf | F5: HATA
A6: Karar | B6: Bu bilgiyle ne yapacağım? | C6: Her kritik KPI aksiyona bağlanır | D6: KARAR_KUYRUGU | E6: Sadece rapor | F6: HATA
A7: Güven | B7: Bu sayıya neden inanayım? | C7: Kaynak, formül mantığı, kontrol ve son doğrulama görünür | D7: Kontroller + kaynak izi + sürüm | E7: Prestij kelimesi | F7: HATA
A8: Referans | B8: Müşteri yorumu yoksa ne göstereceğim? | C8: Önce/Sonra + Karar Vakası + Hata Önleme Vakası üretilir | D8: Demo/örnek çıktı | E8: Kanıtsız iddia | F8: HATA
A9: Senaryo | B9: Ne olursa işler bozulur? | C9: Baz/Aşağı/Yukarı veya uygun stres senaryosu | D9: Senaryo karşılaştırma | E9: Dekoratif senaryo | F9: HATA
A10: Ters stres | B10: Hangi eşikte karar kırılır? | C10: En az bir kritik sürücü için kırılma eşiği | D10: Kırılma eşiği tablosu | E10: Sadece +/- %10 | F10: UYARI/HATA
A11: Hata tutarlılığı | B11: Formül hata verirse ne olur? | C11: Kontrol GEÇTİ veremez; BLOKE/HATA üretir | D11: Hata taraması | E11: Hata + GEÇTİ birlikte | F11: HATA
A12: Karar motoru | B12: Ne oldu, neden oldu? | C12: Sorun + neden + parasal etki + aksiyon + son tarih | D12: Karar tablosu | E12: Boş sayfa / isim düzeyi modül | F12: HATA
A13: Yönetici özeti | B13: 5 saniyede ne görmeliyim? | C13: Bugün / ne değişti / ne bozulacak / neden / ne yapmalıyım / güven | D13: Yönetici özeti ekranı | E13: KPI kutusu yığını | F13: HATA
A14: Teklif | B14: Neden satın almalıyım? | C14: Dosya özellikleri yerine sonuç ve kaçınılan maliyet sunulur | D14: Ürün sayfası kanıt eşlemesi | E14: Özellik listesiyle satış | F14: HATA
... A19: Pazar kanıtı | B19: Piyasa gerçekten ödüyor mu? | C19: Satış/pilot/LOI/fiyat kabulü olmadan pazar doğrulandı yazılmaz | D19: Gerçek işlem kanıtı | E19: Tahmini talep = satış kabulü | F19: HATA

Sheet KAPAK
A1: KAPAK — GES Yatırım Fizibilite Simülatörü
A3: GES Yatırım Fizibilite Simülatörü
A4: Çatı veya saha GES kapasitesi, tüketim eşleştirme, CAPEX/OPEX ve tarife girdilerini işleyin; NPV/IRR aralığı ile YATIRIM YAPILIR / YATIRIM YAPMA kararını üretin.
A6: Bu ürün ne sağlar?
A7: • Tüketim eşleştirmeli gelir: öz tüketim tasarrufu + şebeke satış
A8: • CAPEX / OPEX ayrımı + yıllık degradasyonlu nakit akışı
A9: • Öz kaynak / kredi finansman senaryosu (F01)
A10: • NPV / IRR aralık + tornado; kötümser YATIRIM YAPMA yolu (F04–F05)
A11: • Varsayım kaynak+güven ve KANIT_RAPORU (banka/yatırımcı)
A13: Kimler için?
A14: • Tesis sahibi / mühendis — kapasite ve tüketim eşleştirmesini girmek
A15: • Yatırımcı / CFO — NPV/IRR ile yatırım kararı vermek
... A21: Sürüm 1.0.0 | 2026 | ExcelArşiv | Lisans: Tek kullanıcı | Kod: GYF-PRO

Sheet HIZLI_BASLANGIC
A1: HIZLI BASLANGIC — GES Yatırım Fizibilite Simülatörü
A3: Üç adımda sonuç
A5: Adım 1 — Girdiler | B5: GIRDI'de proje tipi, kWp, özgül üretim, öz tüketim ve tarifeleri sarı hücrelere girin.
A6: Adım 2 — Karar | B6: PANO ve KARAR'da NPV/IRR aralığı ve YATIRIM YAPILIR / YATIRIM YAPMA görün.
A7: Adım 3 — Kanıt | B7: KANIT_RAPORU'nu yazdırın; FINANSMAN ve SENARYO ile doğrulayın.
A9: Formüller
A10: Üretim = kWp × özgül × (1−degradasyon)^yıl | Gelir = öz tüketim×perakende + satış×şebeke | NPV = Σ(net/(1+WACC)^t) − CAPEX
A12: Sarı = manuel giriş | Yeşil = formül çıktısı | Şifre 1234 formül alanlarını korur.

Sheet GIRDI
A1: GIRDI — GES Yatırım Fizibilite Simülatörü
A3: GES proje girdileri
A4: Sarı hücreler manuel giriştir. Tarifeler KURALLAR'dan ayna ile doğrulanır.
A5: Alan | B5: Değer | C5: Birim
A6: Şirket / Proje | B6: Örnek Enerji Yatırım A.Ş. | C6: metin
A7: Dönem | B7: 2026-Q3 | C7: metin
A8: Hesap Yılı | B8: 2026 | C8: yıl
A9: Proje Tipi | B9: CATI | C9: metin
A10: Kurulu güç [kWp] | B10: 100 | C10: kWp
A11: Özgül üretim [kWh/kWp] | B11: 1400 | C11: kWh
A12: Degradasyon [%/yıl] | B12: 0.005 | C12: %
A13: Öz tüketim oranı [%] | B13: 0.7 | C13: %
A14: Yıllık tüketim [kWh] | B14: 200000 | C14: kWh
A15: Perakende tarife [₺/kWh] | B15: 3.5 | C15: ₺/kWh
A16: Şebeke satış tarife [₺/kWh] | B16: 1.2 | C16: ₺/kWh
A17: CAPEX birim [₺/kWp] | B17: 12000 | C17: ₺
A18: OPEX oranı [% CAPEX] | B18: 0.015 | C18: %
A19: WACC [%] | B19: 0.18 | C19: %
A20: NPV dönem [yıl] | B20: 25 | C20: yıl
A21: Kredi faiz oranı [%] | B21: 0.28 | C21: %
A22: Öz kaynak oranı [%] | B22: 0.4 | C22: %
A24: CAPEX / YATIRIM toplam (ayna) | B24: =IFERROR(gyf_capexToplam,0)
A25: OPEX / ISLETME yıllık (ayna) | B25: =IFERROR(gyf_opexYillik,0)
A26: Yıllık gelir (ayna) | B26: =IFERROR(gyf_yillikGelir,0)
A27: Giriş doluluk | B27: =IFERROR(IF(OR(COUNTA(B6:B22)=0,gyf_girisBeklenen=0),0,ROUND(COUNTA(B6:B22)/gyf_girisBeklenen*100,0)),0)
A29: Giriş tablosu (otomasyon / boş-mod)
A30: Alan Anahtarı | B30: Değer | C30: Birim | D30: Zorunlu | E30: Kaynak | F30: Kontrol
A31: sirket_adi | B31: Örnek Enerji Yatırım A.Ş. | C31: metin | D31: Evet | E31: GIRDI | F31: =IF($A31="","",IF($B31="","EKSİK","TAM"))
A32: donem | B32: 2026-Q3 | C32: metin | D32: Evet | E32: GIRDI | F32: =IF($A32="","",IF($B32="","EKSİK","TAM"))
A33: hesapYili | B33: 2026 | C33: yıl | D33: Evet | E33: GIRDI | F33: =IF($A33="","",IF($B33="","EKSİK","TAM"))
A34: proje_tipi | B34: CATI | C34: kod | D34: Evet | E34: GIRDI | F34: =IF($A34="","",IF($B34="","EKSİK","TAM"))
A35: kurulu_guc | B35: 100 | C35: kWp | D35: Evet | E35: GIRDI | F35: =IF($A35="","",IF($B35="","EKSİK","TAM"))
A36: spesifik_uretim | B36: 1400 | C36: kWh/kWp | D36: Evet | E36: GIRDI | F36: =IF($A36="","",IF($B36="","EKSİK","TAM"))
A37: degradasyon | B37: 0.005 | C37: oran | D37: Evet | E37: GIRDI | F37: =IF($A37="","",IF($B37="","EKSİK","TAM"))
A38: oz_tuketim | B38: 0.7 | C38: oran | D38: Evet | E38: GIRDI | F38: =IF($A38="","",IF($B38="","EKSİK","TAM"))
A39: yillik_tuketim | B39: 200000 | C39: kWh | D39: Evet | E39: GIRDI | F39: =IF($A39="","",IF($B39="","EKSİK","TAM"))
A40: perakende_tarife | B40: 3.5 | C40: TL/kWh | D40: Evet | E40: GIRDI | F40: =IF($A40="","",IF($B40="","EKSİK","TAM"))
A41: satis_tarife | B41: 1.2 | C41: TL/kWh | D41: Evet | E41: GIRDI | F41: =IF($A41="","",IF($B41="","EKSİK","TAM"))
A42: capex_birim | B42: 12000 | C42: TL/kWp | D42: Evet | E42: GIRDI | F42: =IF($A42="","",IF($B42="","EKSİK","TAM"))
A43: opex_oran | B43: 0.015 | C43: oran | D43: Evet | E43: GIRDI | F43: =IF($A43="","",IF($B43="","EKSİK","TAM"))
...

Sheet VARSAYIMLAR
A1: VARSAYIMLAR — GES Yatırım Fizibilite Simülatörü
A3: Model varsayımları — her satırda kaynak ve güven
A5: varsayim_id | B5: aciklama | C5: deger | D5: birim | E5: kaynak | F5: guven | G5: duyarlilik | H5: kontrol
A6: V-01 | B6: Özgül üretim kaynağı | C6: PVGIS/ölçüm | D6: metin | E6: PVGIS / saha ölçümü | F6: sert | G6: yüksek | H6: =IF($A6="","",IF(OR($E6="",$F6=""),"EKSİK","TAM"))
A7: V-02 | B7: Degradasyon | C7: 0.5%/yıl | D7: oran | E7: Panel üretici veri sayfası | F7: sert | G7: orta | H7: =IF($A7="","",IF(OR($E7="",$F7=""),"EKSİK","TAM"))
A8: V-03 | B8: Öz tüketim oranı | C8: tesis profili | D8: oran | E8: Sayaç / fatura analizi | F8: yumuşak | G8: yüksek | H8: =IF($A8="","",IF(OR($E8="",$F8=""),"EKSİK","TAM"))
A9: V-04 | B9: Perakende tarife | C9: EPDK dağıtım | D9: TL/kWh | E9: EPDK tarife tablosu | F9: sert | G9: yüksek | H9: =IF($A9="","",IF(OR($E9="",$F9=""),"EKSİK","TAM"))
A10: V-05 | B10: Şebeke satış tarife | C10: YEKDEM/mahalle | D10: TL/kWh | E10: YEKDEM / iç politika | F10: yumuşak | G10: yüksek | H10: =IF($A10="","",IF(OR($E10="",$F10=""),"EKSİK","TAM"))
A11: V-06 | B11: CAPEX birim | C11: teklif ortalaması | D11: TL/kWp | E11: EPC teklifleri | F11: yumuşak | G11: yüksek | H11: =IF($A11="","",IF(OR($E11="",$F11=""),"EKSİK","TAM"))
A12: V-07 | B12: OPEX oranı | C12: % CAPEX | D12: oran | E12: İşletme bütçesi | F12: yumuşak | G12: orta | H12: =IF($A12="","",IF(OR($E12="",$F12=""),"EKSİK","TAM"))
A13: V-08 | B13: WACC / iskonto | C13: nominal | D13: oran | E13: Finans komitesi | F13: yumuşak | G13: yüksek | H13: =IF($A13="","",IF(OR($E13="",$F13=""),"EKSİK","TAM"))
A14: V-09 | B14: Para dünyası | C14: nominal | D14: metin | E14: MOTOR para_dunyasi | F14: sert | G14: orta | H14: =IF($A14="","",IF(OR($E14="",$F14=""),"EKSİK","TAM"))
A15: V-10 | B15: Kötümser üretim şoku | C15: −25% | D15: oran | E15: Stres testi | F15: yumuşak | G15: yüksek | H15: =IF($A15="","",IF(OR($E15="",$F15=""),"EKSİK","TAM"))
J17: CAPEX / YATIRIM tutarı (ayna) | K17: =IFERROR(gyf_capexToplam,0)
J18: OPEX / ISLETME yıllık (ayna) | K18: =IFERROR(gyf_opexYillik,0)

Sheet KURALLAR
A1: KURALLAR — GES Yatırım Fizibilite Simülatörü
A3: Tarife / teşvik kural tablosu (yıl yan yana)
A4: Oranlar MOTOR'da sabit yazılmaz; INDEX/MATCH ile buradan çekilir.
A6: kural_id | B6: madde | C6: kural_adi | D6: kosul_metni | E6: parametre_adi | F6: deger_2025 | G6: deger_2026 | H6: deger_2027 | I6: yururluk | J6: kaynak | K6: aktif_deger
A7: GYF-001 | B7: EPDK tarife | C7: perakende_tarife | D7: öz tüketim × tarife | E7: perakende_tl_kwh | F7: 3.2 | G7: 3.5 | H7: 3.8 | I7: 01.01.2025 | J7: EPDK dağıtım bedelli | K7: =IF($A7="","",IFERROR(CHOOSE(MAX(1,MIN(3,IF(OR(hesapYili="",hesapYili=0),1,hesapYili-gyf_yilTaban))),$F7,$G7,$H7),0))
A8: GYF-002 | B8: YEKDEM / satış | C8: satis_tarife | D8: şebeke satış × tarife | E8: satis_tl_kwh | F8: 1.1 | G8: 1.2 | H8: 1.3 | I8: 01.01.2025 | J8: YEKDEM referans | K8: =IF($A8="","",IFERROR(CHOOSE(MAX(1,MIN(3,IF(OR(hesapYili="",hesapYili=0),1,hesapYili-gyf_yilTaban))),$F8,$G8,$H8),0))
A9: GYF-003 | B9: İç politika | C9: hedef_geri_odeme | D9: geri ödeme ≤ eşik | E9: geri_odeme_yil | F9: 8 | G9: 8 | H9: 7 | I9: 01.01.2025 | J9: Hedef geri ödeme yılı | K9: =IF($A9="","",IFERROR(CHOOSE(MAX(1,MIN(3,IF(OR(hesapYili="",hesapYili=0),1,hesapYili-gyf_yilTaban))),$F9,$G9,$H9),0))
A10: GYF-004 | B10: İç politika | C10: min_oz_tuketim | D10: öz tüketim ≥ eşik | E10: min_oz_tuketim | F10: 0.4 | G10: 0.4 | H10: 0.45 | I10: 01.01.2025 | J10: Asgari öz tüketim | K10: =IF($A10="","",IFERROR(CHOOSE(MAX(1,MIN(3,IF(OR(hesapYili="",hesapYili=0),1,hesapYili-gyf_yilTaban))),$F10,$G10,$H10),0))
A11: GYF-005 | B11: Uygulama | C11: yuvarlama | D11: her hesap | E11: yuvarlama_ondalik | F11: 2 | G11: 2 | H11: 2 | I11: 01.01.2025 | J11: Yuvarlama ondalık | K11: =IF($A11="","",IFERROR(CHOOSE(MAX(1,MIN(3,IF(OR(hesapYili="",hesapYili=0),1,hesapYili-gyf_yilTaban))),$F11,$G11,$H11),0))
A14: Kural-yıl matrisi özeti
A15: Perakende (aktif yıl) | C15: =IFERROR(INDEX(CHOOSE(MAX(1,MIN(3,IF(OR(hesapYili="",hesapYili=0),1,hesapYili-gyf_yilTaban))),tblKurallar[deger_2025],tblKurallar[deger_2026],tblKurallar[deger_2027]),MATCH("GYF-001",tblKurallar[kural_id],0)),0)
A16: Satış tarife (aktif yıl) | C16: =IFERROR(INDEX(CHOOSE(MAX(1,MIN(3,IF(OR(hesapYili="",hesapYili=0),1,hesapYili-gyf_yilTaban))),tblKurallar[deger_2025],tblKurallar[deger_2026],tblKurallar[deger_2027]),MATCH("GYF-002",tblKurallar[kural_id],0)),0)
A17: Matris metni | C17: =IFERROR(_xlfn.TEXTJOIN(" | ",TRUE,"GYF-001=",TEXT(C15,"0.00"),"GYF-002=",TEXT(C16,"0.00"),"yıl=",IF(OR(hesapYili="",hesapYili=0),"-",hesapYili)),"-")

Sheet MOTOR
A1: MOTOR — GES Yatırım Fizibilite Simülatörü
A3: Hesap zinciri — her adımda kural_id · para_dunyasi=nominal
A4: Tarifeler tblKurallar'dan; girdiler GIRDI'den.
A6: adim | B6: ad | C6: formul | D6: birim | E6: ne_ise_yarar | F6: kural_id | G6: deger
A7: 1 | B7: Hesap yılı oku | C7: =IFERROR(hesapYili,0) | D7: yıl | E7: Aktif kural yılı | F7: GYF-005 | G7: =IFERROR(hesapYili,0)
A8: 2 | B8: Perakende tarife kural | C8: =IFERROR(INDEX(CHOOSE(MAX(1,MIN(3,IF(OR(hesapYili="",hesapYili=0),1,hesapYili-gyf_yilTaban))),tblKurallar[deger_2025],tblKurallar[deger_2026],tblKurallar[deger_2027]),MATCH("GYF-001",tblKurallar[kural_id],0)),0) | D8: TL/kWh | E8: EPDK perakende | F8: GYF-001 | G8: =IFERROR(INDEX(CHOOSE(MAX(1,MIN(3,IF(OR(hesapYili="",hesapYili=0),1,hesapYili-gyf_yilTaban))),tblKurallar[deger_2025],tblKurallar[deger_2026],tblKurallar[deger_2027]),MATCH("GYF-001",tblKurallar[kural_id],0)),0)
A9: 3 | B9: Satış tarife kural | C9: =IFERROR(INDEX(CHOOSE(MAX(1,MIN(3,IF(OR(hesapYili="",hesapYili=0),1,hesapYili-gyf_yilTaban))),tblKurallar[deger_2025],tblKurallar[deger_2026],tblKurallar[deger_2027]),MATCH("GYF-002",tblKurallar[kural_id],0)),0) | D9: TL/kWh | E9: YEKDEM/satış | F9: GYF-002 | G9: =IFERROR(INDEX(CHOOSE(MAX(1,MIN(3,IF(OR(hesapYili="",hesapYili=0),1,hesapYili-gyf_yilTaban))),tblKurallar[deger_2025],tblKurallar[deger_2026],tblKurallar[deger_2027]),MATCH("GYF-002",tblKurallar[kural_id],0)),0)
A10: 4 | B10: Hedef geri ödeme | C10: =IFERROR(INDEX(CHOOSE(MAX(1,MIN(3,IF(OR(hesapYili="",hesapYili=0),1,hesapYili-gyf_yilTaban))),tblKurallar[deger_2025],tblKurallar[deger_2026],tblKurallar[deger_2027]),MATCH("GYF-003",tblKurallar[kural_id],0)),0) | D10: yıl | E10: Geri ödeme eşiği | F10: GYF-003 | G10: =IFERROR(INDEX(CHOOSE(MAX(1,MIN(3,IF(OR(hesapYili="",hesapYili=0),1,hesapYili-gyf_yilTaban))),tblKurallar[deger_2025],tblKurallar[deger_2026],tblKurallar[deger_2027]),MATCH("GYF-003",tblKurallar[kural_id],0)),0)
A11: 5 | B11: Min öz tüketim | C11: =IFERROR(INDEX(CHOOSE(MAX(1,MIN(3,IF(OR(hesapYili="",hesapYili=0),1,hesapYili-gyf_yilTaban))),tblKurallar[deger_2025],tblKurallar[deger_2026],tblKurallar[deger_2027]),MATCH("GYF-004",tblKurallar[kural_id],0)),0) | D11: oran | E11: Asgari öz tüketim | F11: GYF-004 | G11: =IFERROR(INDEX(CHOOSE(MAX(1,MIN(3,IF(OR(hesapYili="",hesapYili=0),1,hesapYili-gyf_yilTaban))),tblKurallar[deger_2025],tblKurallar[deger_2026],tblKurallar[deger_2027]),MATCH("GYF-004",tblKurallar[kural_id],0)),0)
A12: 6 | B12: Yuvarlama ondalık | C12: =IFERROR(INDEX(CHOOSE(MAX(1,MIN(3,IF(OR(hesapYili="",hesapYili=0),1,hesapYili-gyf_yilTaban))),tblKurallar[deger_2025],tblKurallar[deger_2026],tblKurallar[deger_2027]),MATCH("GYF-005",tblKurallar[kural_id],0)),0) | D12: adet | E12: Yuvarlama basamağı | F12: GYF-005 | G12: =IFERROR(INDEX(CHOOSE(MAX(1,MIN(3,IF(OR(hesapYili="",hesapYili=0),1,hesapYili-gyf_yilTaban))),tblKurallar[deger_2025],tblKurallar[deger_2026],tblKurallar[deger_2027]),MATCH("GYF-005",tblKurallar[kural_id],0)),0)
A13: 7 | B13: Kurulu güç kWp | C13: =IFERROR(GIRDI!B10,0) | D13: kWp | E13: DC güç | F13: GYF-005 | G13: =IFERROR(GIRDI!B10,0)
A14: 8 | B14: Özgül üretim | C14: =IFERROR(GIRDI!B11,0) | D14: kWh/kWp | E14: Yıllık özgül | F14: GYF-005 | G14: =IFERROR(GIRDI!B11,0)
A15: 9 | B15: Degradasyon | C15: =IFERROR(GIRDI!B12,0) | D15: oran | E15: Yıllık kayıp | F15: GYF-005 | G15: =IFERROR(GIRDI!B12,0)
A16: 10 | B16: Öz tüketim oranı | C16: =IFERROR(GIRDI!B13,0) | D16: oran | E16: Öz tüketim payı | F16: GYF-004 | G16: =IFERROR(GIRDI!B13,0)
A17: 11 | B17: Yıllık tüketim | C17: =IFERROR(GIRDI!B14,0) | D17: kWh | E17: Tesis tüketimi | F17: GYF-004 | G17: =IFERROR(GIRDI!B14,0)
A18: 12 | B18: Perakende giriş | C18: =IFERROR(GIRDI!B15,0) | D18: TL/kWh | E18: Giriş perakende | F18: GYF-001 | G18: =IFERROR(GIRDI!B15,0)
A19: 13 | B19: Satış giriş | C19: =IFERROR(GIRDI!B16,0) | D19: TL/kWh | E19: Giriş satış | F19: GYF-002 | G19: =IFERROR(GIRDI!B16,0)
A20: 14 | B20: CAPEX birim | C20: =IFERROR(GIRDI!B17,0) | D20: TL/kWp | E20: Birim yatırım | F20: GYF-005 | G20: =IFERROR(GIRDI!B17,0)
A21: 15 | B21: OPEX oranı | C21: =IFERROR(GIRDI!B18,0) | D21: oran | E21: İşletme oranı | F21: GYF-005 | G21: =IFERROR(GIRDI!B18,0)
A22: 16 | B22: WACC | C22: =IFERROR(GIRDI!B19,0) | D22: oran | E22: İskonto nominal | F22: GYF-005 | G22: =IFERROR(GIRDI!B19,0)
A23: 17 | B23: NPV dönem | C23: =IFERROR(GIRDI!B20,0) | D23: adet | E23: Akış yılı | F23: GYF-005 | G23: =IFERROR(GIRDI!B20,0)
A24: 18 | B24: Kredi faiz | C24: =IFERROR(GIRDI!B21,0) | D24: oran | E24: Kredi senaryosu | F24: GYF-005 | G24: =IFERROR(GIRDI!B21,0)
A25: 19 | B25: Öz kaynak oranı | C25: =IFERROR(GIRDI!B22,0) | D25: oran | E25: Öz kaynak payı | F25: GYF-005 | G25: =IFERROR(GIRDI!B22,0)
A26: 20 | B26: Yıllık üretim Y1 | C26: =IFERROR(ROUND(G13*G14,MAX(0,MIN(gyf_yuvarMax,IFERROR(N(G12),0)))),0) | D26: kWh | E26: kWp×özgül | F26: GYF-005 | G26: =IFERROR(ROUND(G13*G14,MAX(0,MIN(gyf_yuvarMax,IFERROR(N(G12),0)))),0)
A27: 21 | B27: Öz tüketim kWh | C27: =IFERROR(ROUND(G26*G16,MAX(0,MIN(gyf_yuvarMax,IFERROR(N(G12),0)))),0) | D27: kWh | E27: Üretim×öz oran | F27: GYF-004 | G27: =IFERROR(ROUND(G26*G16,MAX(0,MIN(gyf_yuvarMax,IFERROR(N(G12),0)))),0)
A28: 22 | B28: Şebeke satış kWh | C28: =IFERROR(G26-G27,0) | D28: kWh | E28: Kalan üretim | F28: GYF-002 | G28: =IFERROR(G26-G27,0)
A29: 23 | B29: Tüketim eşleşme kWh | C29: =IFERROR(ROUND(MIN(G27,G17),MAX(0,MIN(gyf_yuvarMax,IFERROR(N(G12),0)))),0) | D29: kWh | E29: min(öz,tüketim) | F29: GYF-004 | G29: =IFERROR(ROUND(MIN(G27,G17),MAX(0,MIN(gyf_yuvarMax,IFERROR(N(G12),0)))),0)
A30: 24 | B30: Öz tasarruf geliri | C30: =IFERROR(ROUND(G29*G18,MAX(0,MIN(gyf_yuvarMax,IFERROR(N(G12),0)))),0) | D30: TL | E30: eşleşme×perakende | F30: GYF-001 | G30: =IFERROR(ROUND(G29*G18,MAX(0,MIN(gyf_yuvarMax,IFERROR(N(G12),0)))),0)
A31: 25 | B31: Şebeke satış geliri | C31: =IFERROR(ROUND(G28*G19,MAX(0,MIN(gyf_yuvarMax,IFERROR(N(G12),0)))),0) | D31: TL | E31: satış×tarife | F31: GYF-002 | G31: =IFERROR(ROUND(G28*G19,MAX(0,MIN(gyf_yuvarMax,IFERROR(N(G12),0)))),0)
A32: 26 | B32: Yıllık gelir baz | C32: =IFERROR(G30+G31,0) | D32: TL | E32: Toplam gelir Y1 | F32: GYF-001 | G32: =IFERROR(G30+G31,0)
A33: 27 | B33: CAPEX / YATIRIM | C33: =IFERROR(ROUND(G13*G20,MAX(0,MIN(gyf_yuvarMax,IFERROR(N(G12),0)))),0) | D33: TL | E33: kWp×birim CAPEX | F33: GYF-005 | G33: =IFERROR(ROUND(G13*G20,MAX(0,MIN(gyf_yuvarMax,IFERROR(N(G12),0)))),0)
A34: 28 | B34: OPEX / ISLETME yıllık | C34: =IFERROR(ROUND(G33*G21,MAX(0,MIN(gyf_yuvarMax,IFERROR(N(G12),0)))),0) | D34: TL | E34: CAPEX×oran | F34: GYF-005 | G34: =IFERROR(ROUND(G33*G21,MAX(0,MIN(gyf_yuvarMax,IFERROR(N(G12),0)))),0)
A35: 29 | B35: Net nakit Y1 | C35: =IFERROR(G32-G34,0) | D35: TL | E35: Gelir−OPEX | F35: GYF-005 | G35: =IFERROR(G32-G34,0)
A36: 30 | B36: Geri ödeme yılı | C36: =IFERROR(IF(OR(G35<=0,G33<=0),gyf_geriOdemeSonsuz,ROUND(G33/G35,1)),0) | D36: yıl | E36: CAPEX/net | F36: GYF-003 | G36: =IFERROR(IF(OR(G35<=0,G33<=0),gyf_geriOdemeSonsuz,ROUND(G33/G35,1)),0)
A37: 31 | B37: NPV (baz) | C37: =IFERROR(IF(OR(G23<=0,G22=""),0,IF(G22=0,ROUND(G35*G23-G33,MAX(0,MIN(gyf_yuvarMax,IFERROR(N(G12),0)))),ROUND(G35*(1-POWER(1+G22,-G23))/G22-G33,MAX(0,MIN(gyf_yuvarMax,IFERROR(N(G12),0)))))),0) | D37: TL | E37: Anüite NPV − CAPEX | F37: GYF-005 | G37: =IFERROR(IF(OR(G23<=0,G22=""),0,IF(G22=0,ROUND(G35*G23-G33,MAX(0,MIN(gyf_yuvarMax,IFERROR(N(G12),0)))),ROUND(G35*(1-POWER(1+G22,-G23))/G22-G33,MAX(0,MIN(gyf_yuvarMax,IFERROR(N(G12),0)))))),0)
A38: 32 | B38: IRR yaklaşımı | C38: =IFERROR(IF(OR(G33<=0,G35<=0,G23<=0),0,ROUND(G35/G33-gyf_bazCarpan/G23,4)),0) | D38: oran | E38: Kabaca IRR | F38: GYF-005 | G38: =IFERROR(IF(OR(G33<=0,G35<=0,G23<=0),0,ROUND(G35/G33-gyf_bazCarpan/G23,4)),0)
A39: 33 | B39: Karar kodu | C39: =IFERROR(IF(COUNTA(tblGirdi[Alan Anahtarı])=0,"VERI_YOK",IF(OR(G33<=0,G13<=0,G32<=0),"YAPMA",IF(OR(G37<0,G36>G10*gyf_dikkatCarpan),"YAPMA",IF(OR(G36>G10,G37<gyf_npvDikkat),"DIKKAT","YAPILIR")))),"") | D39: kod | E39: Karar kodu | F39: GYF-003 | G39: =IFERROR(IF(COUNTA(tblGirdi[Alan Anahtarı])=0,"VERI_YOK",IF(OR(G33<=0,G13<=0,G32<=0),"YAPMA",IF(OR(G37<0,G36>G10*gyf_dikkatCarpan),"YAPMA",IF(OR(G36>G10,G37<gyf_npvDikkat),"DIKKAT","YAPILIR")))),"")
A40: 34 | B40: Karar metni | C40: =IFERROR(IF(G39="VERI_YOK","VERİ YOK",IF(G39="YAPILIR","YATIRIM YAPILIR",IF(G39="DIKKAT","DİKKAT","YATIRIM YAPMA"))),"") | D40: metin | E40: Kullanıcıya karar | F40: GYF-003 | G40: =IFERROR(IF(G39="VERI_YOK","VERİ YOK",IF(G39="YAPILIR","YATIRIM YAPILIR",IF(G39="DIKKAT","DİKKAT","YATIRIM YAPMA"))),"")
A41: 35 | B41: Gerekçe | C41: =IFERROR(IF(G39="VERI_YOK","Giriş tablosu boş — hesap yapılamaz.",IF(G39="YAPILIR","NPV pozitif AND geri ödeme hedef altında; GES yatırımı uygun.",IF(G39="DIKKAT","Geri ödeme veya NPV dikkat bandında; tarife/üretimi gözden geçirin.","NPV negatif veya geri ödeme aşırı; kötümser/bazda YATIRIM YAPMA."))),"") | D41: metin | E41: Gerekçe cümlesi | F41: GYF-003 | G41: =IFERROR(IF(G39="VERI_YOK","Giriş tablosu boş — hesap yapılamaz.",IF(G39="YAPILIR","NPV pozitif AND geri ödeme hedef altında; GES yatırımı uygun.",IF(G39="DIKKAT","Geri ödeme veya NPV dikkat bandında; tarife/üretimi gözden geçirin.","NPV negatif veya geri ödeme aşırı; kötümser/bazda YATIRIM YAPMA."))),"")
A42: 36 | B42: Güven skoru | C42: =IFERROR(ROUND(IF(OR(COUNTA(GIRDI!B6:B22)=0,gyf_girisBeklenen=0),0,COUNTA(GIRDI!B6:B22)/gyf_girisBeklenen*100),0),0) | D42: puan | E42: Giriş bütünlüğü | F42: GYF-005 | G42: =IFERROR(ROUND(IF(OR(COUNTA(GIRDI!B6:B22)=0,gyf_girisBeklenen=0),0,COUNTA(GIRDI!B6:B22)/gyf_girisBeklenen*100),0),0)
...

Sheet FINANSMAN
A1: FINANSMAN — GES Yatırım Fizibilite Simülatörü
A3: Finansman senaryoları — OZ_KAYNAK ve KREDI
A5: Senaryo | B5: Pay | C5: Tutar [₺] | D5: Faiz / maliyet | E5: NPV etkisi
A6: OZ_KAYNAK | B6: =GIRDI!B22 | C6: =IFERROR(gyf_capexToplam*B6,0) | D6: =IFERROR(GIRDI!B22*gyf_sifirCarpan,0) | E6: =IFERROR(MOTOR!G37,0)
A7: KREDI | B7: =gyf_bazCarpan-GIRDI!B22 | C7: =IFERROR(gyf_capexToplam*B7,0) | D7: =GIRDI!B21 | E7: =IFERROR(MOTOR!G37-C7*D7*GIRDI!B20,0)
A9: CAPEX / YATIRIM toplam | B9: =IFERROR(gyf_capexToplam,0)
A10: OPEX / ISLETME yıllık | B10: =IFERROR(gyf_opexYillik,0)
A11: Finansman karşılaştırma | B11: =IFERROR(_xlfn.TEXTJOIN(" | ",TRUE,"OZ_KAYNAK NPV ",TEXT(E6,"₺ #,##0")," · KREDI NPV ",TEXT(E7,"₺ #,##0")),"-")
A12: CAPEX OPEX özet | B12: =IFERROR(_xlfn.TEXTJOIN(" | ",TRUE,"CAPEX ",TEXT(B9,"₺ #,##0")," · OPEX ",TEXT(B10,"₺ #,##0")),"-")
A13: FinansDemo
A14: OZ_KAYNAK | B14: 480000
A15: KREDI | B15: 720000

Sheet SENARYO
A1: SENARYO — GES Yatırım Fizibilite Simülatörü
A3: Senaryo ve duyarlılık (tornado)
A5: Senaryo | B5: Çarpan | C5: Yıllık gelir | D5: NPV | E5: Karar | G5: NpvDemo
A6: İyimser | B6: =IFERROR(gyf_senaryoIyi+N(GIRDI!B10)*gyf_sifirCarpan,0) | C6: =IFERROR(MOTOR!G46,0) | D6: =IFERROR(MOTOR!G48,0) | E6: =IF(COUNTA(tblGirdi[Alan Anahtarı])=0,"VERİ YOK",IF(D6<0,"YATIRIM YAPMA","YATIRIM YAPILIR")) | G6: 1800000
A7: Baz | B7: =IFERROR(gyf_bazCarpan+N(GIRDI!B10)*gyf_sifirCarpan,1) | C7: =IFERROR(gyf_yillikGelir,0) | D7: =IFERROR(gyf_npv,0) | E7: =IF(COUNTA(tblGirdi[Alan Anahtarı])=0,"VERİ YOK",IFERROR(gyf_kararMetni,"-")) | G7: 850000
A8: Kötümser | B8: =IFERROR(gyf_senaryoKotu+N(GIRDI!B10)*gyf_sifirCarpan,0) | C8: =IFERROR(MOTOR!G47,0) | D8: =IFERROR(MOTOR!G49,0) | E8: =IF(COUNTA(tblGirdi[Alan Anahtarı])=0,"VERİ YOK",IFERROR(MOTOR!G50,"YATIRIM YAPMA")) | G8: -180000
A10: Senaryo NPV bant (iyimser−kötümser) | B10: =IFERROR(D6-D8,0)
A11: Senaryo yorumu | B11: =IFERROR(_xlfn.TEXTJOIN("; ",TRUE,"İyimser NPV ",TEXT(D6,"₺ #,##0")," · Baz ",TEXT(D7,"₺ #,##0")," · Kötümser ",TEXT(D8,"₺ #,##0")),"-")
A13: Duyarlılık (tornado)
A14: Değişken | B14: Etki [₺] | C14: Sıra | E14: EtkiDemo
A15: Tornado tarife etkisi | B15: =IFERROR(MOTOR!G51,0) | C15: =IFERROR(IF(B15>=MAX(B15:B19),gyf_siraBir,IF(B15=LARGE(B15:B19,2),gyf_siraIki,IF(B15=LARGE(B15:B19,3),gyf_siraUc,4))),4) | E15: 220000
A16: Tornado üretim etkisi | B16: =IFERROR(MOTOR!G52,0) | C16: =IFERROR(IF(B16>=MAX(B15:B19),gyf_siraBir,IF(B16=LARGE(B15:B19,2),gyf_siraIki,IF(B16=LARGE(B15:B19,3),gyf_siraUc,4))),4) | E16: 180000
A17: Tornado CAPEX etkisi | B17: =IFERROR(MOTOR!G53,0) | C17: =IFERROR(IF(B17>=MAX(B15:B19),gyf_siraBir,IF(B17=LARGE(B15:B19,2),gyf_siraIki,IF(B17=LARGE(B15:B19,3),gyf_siraUc,4))),4) | E17: 150000
A18: Tornado OPEX etkisi | B18: =IFERROR(MOTOR!G54,0) | C18: =IFERROR(IF(B18>=MAX(B15:B19),gyf_siraBir,IF(B18=LARGE(B15:B19,2),gyf_siraIki,IF(B18=LARGE(B15:B19,3),gyf_siraUc,4))),4) | E18: 90000
A19: Tornado WACC etkisi | B19: =IFERROR(MOTOR!G55,0) | C19: =IFERROR(IF(B19>=MAX(B15:B19),gyf_siraBir,IF(B19=LARGE(B15:B19,2),gyf_siraIki,IF(B19=LARGE(B15:B19,3),gyf_siraUc,4))),4) | E19: 70000
A21: Duyarlılık sıra özeti | B21: =IFERROR(CONCATENATE("1)",INDEX(A15:A19,MATCH(gyf_siraBir,C15:C19,0))," 2)",INDEX(A15:A19,MATCH(gyf_siraIki,C15:C19,0))),"-")
A22: Duyarlılık yorumu | B22: =_xlfn.TEXTJOIN("; ",TRUE,"En yüksek etki ",TEXT(MAX(B15:B19),"₺ #,##0")," — öncelik bu değişkende")
A24: Tahmin alt | B24: =IFERROR(gyf_npv*gyf_tahminAlt,0) | C24: =IFERROR(gyf_npv,0) | D24: =IFERROR(gyf_npv*gyf_tahminUst,0)
A26: Tahmin (PERCENTILE)
A27: Seri nokta | D27: TrendDemo
A28: 1 | B28: =D6 | D28: 700000
A29: 2 | B29: =D7 | D29: 850000
A30: 3 | B30: =D8 | D30: 1100000
A31: 4 | B31: =D9 | D31: 850000
A32: Tahmin P90 | B32: =IFERROR(PERCENTILE(B28:B31,gyf_yuzdelikOran),0)
A33: Tahmin yorumu | B33: =_xlfn.TEXTJOIN("; ",TRUE,"P90 ",TEXT(B32,"₺ #,##0")," · Alt ",TEXT(B24,"₺ #,##0")," · Üst ",TEXT(D24,"₺ #,##0"))

Sheet KARAR
A1: KARAR — GES Yatırım Fizibilite Simülatörü
A3: Yatırım kararı
A5: Karar | B5: =gyf_kararMetni
A6: Gerekçe | B6: =gyf_kararGerekce
A8: NPV (baz) | B8: =IFERROR(gyf_npv,0)
A9: IRR | B9: =IFERROR(gyf_irr,0)
A10: İyimser NPV | B10: =IFERROR(MOTOR!G48,0)
A11: Kötümser karar | B11: =IFERROR(MOTOR!G50,"YATIRIM YAPMA")
A12: Kötümser NPV | B12: =IFERROR(MOTOR!G49,0)
A14: Finansman | B14: =IFERROR(gyf_finansmanKarsilastirma,"-")
A16: Aksiyon 1 | B16: =_xlfn.TEXTJOIN(" ",TRUE,"Tarife duyarlılığını kontrol edin; etki ",TEXT(IFERROR(MOTOR!G51,0),"₺ #,##0"))
A17: Aksiyon 2 | B17: =_xlfn.TEXTJOIN(" ",TRUE,"Öz tüketim oranını gözden geçirin; eşleşme ",TEXT(IFERROR(gyf_tuketimEslesme,0),"#,##0")," kWh")
A18: Aksiyon 3 | B18: =_xlfn.TEXTJOIN(" ",TRUE,"OZ_KAYNAK vs KREDI karşılaştırmasını FINANSMAN sayfasında inceleyin")
A20: KararDemo
A21: İyimser | B21: 1800000
A22: Baz | B22: 850000
A23: Kötümser | B23: -180000

Sheet VAKALAR
A1: VAKALAR — GES Yatırım Fizibilite Simülatörü
A3: Altın vakalar — beklenen vs hesaplanan
A5: vaka_id | B5: aciklama | C5: girdi_ozeti | D5: beklenen_sonuc | E5: hesaplanan | F5: fark | G5: durum | H5: kaynak
A6: V1 | B6: Demo çatı baz CAPEX | C6: 100kWp×12000 | D6: 1200000 | E6: =IFERROR(gyf_capexToplam,0) | F6: =E6-D6 | G6: =IF(ABS(F6)<=gyf_tolerans,"TUTARLI","KIRIK") | H6: Demo
A7: V2 | B7: Demo yıllık üretim | C7: 100×1400 | D7: 140000 | E7: =IFERROR(MOTOR!G26,0) | F7: =E7-D7 | G7: =IF(ABS(F7)<=gyf_tolerans,"TUTARLI","KIRIK") | H7: Demo
A8: V3 | B8: Öz tüketim kWh | C8: 140000×0.7 | D8: 98000 | E8: =IFERROR(MOTOR!G27,0) | F8: =E8-D8 | G8: =IF(ABS(F8)<=gyf_tolerans,"TUTARLI","KIRIK") | H8: Demo
A9: V4 | B9: Kötümser karar yolu | C9: NPV<0 → YAPMA | D9: 1 | E9: =IF(ISNUMBER(SEARCH("YAPMA",IFERROR(MOTOR!G50,""))),1,0) | F9: =E9-D9 | G9: =IF(E9=1,"TUTARLI","KIRIK") | H9: F05
A12: Vaka durum özeti | B12: =IFERROR(_xlfn.TEXTJOIN(" | ",TRUE,G6,G7,G8,G9),"-")
A13: Vaka fark toplamı | B13: =IFERROR(SUM(F6:F9),0)
A15: VakaDemo
A16: V1 | B16: 1200000
A17: V2 | B17: 140000
A18: V3 | B18: 98000
A19: V4 | B19: 1

Sheet KANIT_RAPORU
A1: KANIT RAPORU — GES Yatırım Fizibilite Simülatörü
A3: Bankaya / yatırımcıya fizibilite kanıtı
A5: Şirket | B5: =GIRDI!B6
A6: Dönem | B6: =GIRDI!B7
A7: Proje tipi | B7: =GIRDI!B9
A8: Kurulu güç [kWp] | B8: =GIRDI!B10
A10: CAPEX / YATIRIM | B10: =IFERROR(gyf_capexToplam,0)
A11: OPEX / ISLETME | B11: =IFERROR(gyf_opexYillik,0)
A12: Yıllık gelir | B12: =IFERROR(gyf_yillikGelir,0)
A13: Tüketim eşleşme | B13: =IFERROR(gyf_tuketimEslesme,0)
A15: NPV baz | B15: =IFERROR(gyf_npv,0)
A16: IRR | B16: =IFERROR(gyf_irr,0)
A17: NPV aralık | B17: =_xlfn.TEXTJOIN(" … ",TRUE,TEXT(IFERROR(MOTOR!G48,0),"₺ #,##0"),TEXT(IFERROR(MOTOR!G49,0),"₺ #,##0"))
A19: Finansman | B19: =IFERROR(gyf_finansmanKarsilastirma,"-")
A20: Karar | B20: =gyf_kararMetni
A21: Kanıt özeti | B21: =IFERROR(gyf_kanitRaporu,"-")
A23: İmza — Yatırımcı | B23: ________________________
A24: İmza — Banka | B24: ________________________
A26: Sürüm 1.0.0 | GYF-PRO | Tarih | B26: =raporTarihi

Sheet KONTROLLER
A1: KONTROLLER — GES Yatırım Fizibilite Simülatörü
A3: Dosya sağlık kontrolleri
A5: Giriş dolu mu | B5: =IF(COUNTA(tblGirdi[Alan Anahtarı])=0,"BOŞ","DOLU")
A6: CAPEX pozitif mi | B6: =IF(IFERROR(gyf_capexToplam,0)>0,"TEMİZ","NEGATİF")
A7: OPEX ayrık mı | B7: =IF(AND(IFERROR(gyf_capexToplam,0)>0,IFERROR(gyf_opexYillik,0)>=0),"TEMİZ","EKSİK")
A8: NPV hesaplı mı | B8: =IF(ISNUMBER(gyf_npv),"TEMİZ","HATALI")
A9: Kötümser YAPMA yolu | B9: =IF(ISNUMBER(SEARCH("YAPMA",IFERROR(MOTOR!G50,""))),"TEMİZ","EKSİK")
A10: Varsayım kaynak/güven | B10: =IF(COUNTIF(tblVarsayimlar[kontrol],"EKSİK")=0,"TEMİZ","EKSİK")
A11: Vaka tutarlılığı | B11: =IF(COUNTIF(VAKALAR!G6:G9,"KIRIK")=0,"TUTARLI","KIRIK")
A12: Sağlık skoru | B12: =IFERROR(ROUND((COUNTIF(B5:B11,"TEMİZ")+COUNTIF(B5:B11,"DOLU")+COUNTIF(B5:B11,"TUTARLI"))/7*100,0),0)

Sheet ORNEK_VERI
A1: ORNEK VERI — GES Yatırım Fizibilite Simülatörü
A3: Örnek senaryolar (CSV ile uyumlu)
A5: Senaryo | B5: Proje_tipi | C5: Kurulu_guc_kWp | D5: Spesifik_uretim | E5: Oz_tuketim | F5: Perakende_tarife | G5: Satis_tarife | H5: Capex_birim | I5: Opex_oran | J5: WACC | K5: Yil | L5: Durum
A6: Demo cati | B6: CATI | C6: 100 | D6: 1400 | E6: 0.7 | F6: 3.5 | G6: 1.2 | H6: 12000 | I6: 0.015 | J6: 0.18 | K6: 2026 | L6: =IF($A6="","",IF($C6="","EKSİK","TAM"))
A7: Yuksek uretim | B7: CATI | C7: 100 | D7: 1600 | E7: 0.75 | F7: 3.8 | G7: 1.4 | H7: 11000 | I7: 0.012 | J7: 0.16 | K7: 2026 | L7: =IF($A7="","",IF($C7="","EKSİK","TAM"))
A8: Kotumser saha | B8: SAHA | C8: 250 | D8: 1200 | E8: 0.4 | F8: 3.2 | G8: 1 | H8: 14000 | I8: 0.02 | J8: 0.2 | K8: 2026 | L8: =IF($A8="","",IF($C8="","EKSİK","TAM"))
A9: 2025 gecis | B9: CATI | C9: 80 | D9: 1350 | E9: 0.65 | F9: 3 | G9: 1.1 | H9: 12500 | I9: 0.016 | J9: 0.18 | K9: 2025 | L9: =IF($A9="","",IF($C9="","EKSİK","TAM"))
L10: =IF($A10="","",IF($C10="","EKSİK","TAM"))
L11: =IF($A11="","",IF($C11="","EKSİK","TAM"))
L12: =IF($A12="","",IF($C12="","EKSİK","TAM"))
L13: =IF($A13="","",IF($C13="","EKSİK","TAM"))
L14: =IF($A14="","",IF($C14="","EKSİK","TAM"))
L15: =IF($A15="","",IF($C15="","EKSİK","TAM"))
L16: =IF($A16="","",IF($C16="","EKSİK","TAM"))
L17: =IF($A17="","",IF($C17="","EKSİK","TAM"))
L18: =IF($A18="","",IF($C18="","EKSİK","TAM"))
L19: =IF($A19="","",IF($C19="","EKSİK","TAM"))
L20: =IF($A20="","",IF($C20="","EKSİK","TAM"))
L21: =IF($A21="","",IF($C21="","EKSİK","TAM"))
A22: OrnekCapexDemo | L22: =IF($A22="","",IF($C22="","EKSİK","TAM"))
A23: Demo cati | B23: 1200000 | L23: =IF($A23="","",IF($C23="","EKSİK","TAM"))
A24: Yuksek uretim | B24: 1100000 | L24: =IF($A24="","",IF($C24="","EKSİK","TAM"))
A25: Kotumser saha | B25: 3500000 | L25: =IF($A25="","",IF($C25="","EKSİK","TAM"))
A26: 2025 gecis | B26: 1000000 | L26: =IF($A26="","",IF($C26="","EKSİK","TAM"))
L27: =IF($A27="","",IF($C27="","EKSİK","TAM"))
L28: =IF($A28="","",IF($C28="","EKSİK","TAM"))
L29: =IF($A29="","",IF($C29="","EKSİK","TAM"))
L30: =IF($A30="","",IF($C30="","EKSİK","TAM"))
L31: =IF($A31="","",IF($C31="","EKSİK","TAM"))
L32: =IF($A32="","",IF($C32="","EKSİK","TAM"))
L33: =IF($A33="","",IF($C33="","EKSİK","TAM"))
L34: =IF($A34="","",IF($C34="","EKSİK","TAM"))
L35: =IF($A35="","",IF($C35="","EKSİK","TAM"))
L36: =IF($A36="","",IF($C36="","EKSİK","TAM"))
L37: =IF($A37="","",IF($C37="","EKSİK","TAM"))
L38: =IF($A38="","",IF($C38="","EKSİK","TAM"))
... L1004: =IF($A1004="","",IF($C1004="","EKSİK","TAM"))

Sheet LISTELER
A1: LISTELER — GES Yatırım Fizibilite Simülatörü
A3: Doğrulama listeleri
A5: Yıl | C5: ProjeTipi | E5: EvetHayır
A6: 2025 | C6: CATI | E6: Evet
A7: 2026 | C7: SAHA | E7: Hayır
A8: 2027

Sheet AYARLAR
A1: AYARLAR — GES Yatırım Fizibilite Simülatörü
A3: Parametreler (tek kaynak) — tarife/teşvik
A5: anahtar | B5: deger | C5: birim | D5: aciklama | E5: kaynak | F5: yururluk_tarihi | G5: dogrulama_tarihi | H5: kontrol
A6: hesapYili | B6: 2026 | C6: yıl | D6: Aktif hesap yılı | E6: Kullanıcı / GIRDI | F6: 01.01.2025 | G6: 11.08.2026 | H6: =IF(A6="","",IF(B6="","EKSİK","TAM"))
A7: raporTarihi | B7: 46245 | C7: tarih | D7: Rapor tarihi | E7: Üretim | F7: 01.01.2025 | G7: 11.08.2026 | H7: =IF(A7="","",IF(B7="","EKSİK","TAM"))
A8: gyf_tolerans | B8: 1 | C8: adet | D8: Vaka tutarlılık toleransı | E8: Uygulama notu | F8: 01.01.2025 | G8: 11.08.2026 | H8: =IF(A8="","",IF(B8="","EKSİK","TAM"))
A9: gyf_azamiEsik | B9: 100000000000 | C9: TL | D9: Azami giriş eşiği | E9: İç politika | F9: 01.01.2025 | G9: 11.08.2026 | H9: =IF(A9="","",IF(B9="","EKSİK","TAM"))
A10: gyf_senaryoIyi | B10: 1.12 | C10: çarpan | D10: İyimser üretim çarpanı | E10: Model varsayımı | F10: 01.01.2025 | G10: 11.08.2026 | H10: =IF(A10="","",IF(B10="","EKSİK","TAM"))
A11: gyf_senaryoKotu | B11: 0.75 | C11: çarpan | D11: Kötümser üretim çarpanı | E11: Model varsayımı | F11: 01.01.2025 | G11: 11.08.2026 | H11: =IF(A11="","",IF(B11="","EKSİK","TAM"))
A12: gyf_tarifeKotu | B12: 0.85 | C12: çarpan | D12: Kötümser tarife çarpanı | E12: Model varsayımı | F12: 01.01.2025 | G12: 11.08.2026 | H12: =IF(A12="","",IF(B12="","EKSİK","TAM"))
A13: gyf_capexIyi | B13: 0.95 | C13: çarpan | D13: İyimser CAPEX çarpanı | E13: Model varsayımı | F13: 01.01.2025 | G13: 11.08.2026 | H13: =IF(A13="","",IF(B13="","EKSİK","TAM"))
A14: gyf_capexKotu | B14: 1.15 | C14: çarpan | D14: Kötümser CAPEX çarpanı | E14: Model varsayımı | F14: 01.01.2025 | G14: 11.08.2026 | H14: =IF(A14="","",IF(B14="","EKSİK","TAM"))
A15: gyf_opexKotu | B15: 1.4 | C15: çarpan | D15: Kötümser OPEX çarpanı | E15: Model varsayımı | F15: 01.01.2025 | G15: 11.08.2026 | H15: =IF(A15="","",IF(B15="","EKSİK","TAM"))
A16: gyf_tahminAlt | B16: 0.85 | C16: çarpan | D16: Tahmin alt bant | E16: Model varsayımı | F16: 01.01.2025 | G16: 11.08.2026 | H16: =IF(A16="","",IF(B16="","EKSİK","TAM"))
A17: gyf_tahminUst | B17: 1.15 | C17: çarpan | D17: Tahmin üst bant | E17: Model varsayımı | F17: 01.01.2025 | G17: 11.08.2026 | H17: =IF(A17="","",IF(B17="","EKSİK","TAM"))
... A23: gyf_yuzdelikOran | B23: 0.9 | C23: oran | D23: Yüzdelik P90 | E23: İstatistik | F23: 01.01.2025 | G23: 11.08.2026 | H23: =IF(A23="","",IF(B23="","EKSİK","TAM"))
A24: gyf_parmakIzi | B24: 0f39f85d5b68650a | C24: metin | D24: Dosya parmak izi | E24: Üretim | F24: 01.01.2025 | G24: 11.08.2026 | H24: =IF(A24="","",IF(B24="","EKSİK","TAM"))
A25: dosya_surumu | B25: 1.0.0 | C25: metin | D25: Ürün sürümü | E25: ExcelArşiv | F25: 01.01.2025 | G25: 11.08.2026 | H25: =IF(A25="","",IF(B25="","EKSİK","TAM"))
A26: gyf_girisBeklenen | B26: 17 | C26: adet | D26: Zorunlu giriş sayısı | E26: Ürün mimarisi | F26: 01.01.2025 | G26: 11.08.2026 | H26: =IF(A26="","",IF(B26="","EKSİK","TAM"))
A27: gyf_riskDusuk | B27: 20 | C27: puan | D27: YAPILIR risk skoru | E27: İç politika | F27: 01.01.2025 | G27: 11.08.2026 | H27: =IF(A27="","",IF(B27="","EKSİK","TAM"))
A28: gyf_riskOrta | B28: 55 | C28: puan | D28: DİKKAT risk skoru | E28: İç politika | F28: 01.01.2025 | G28: 11.08.2026 | H28: =IF(A28="","",IF(B28="","EKSİK","TAM"))
A29: gyf_riskYuksek | B29: 85 | C29: puan | D29: YAPMA risk skoru | E29: İç politika | F29: 01.01.2025 | G29: 11.08.2026 | H29: =IF(A29="","",IF(B29="","EKSİK","TAM"))
A30: gyf_yilTaban | B30: 2024 | C30: yıl | D30: CHOOSE yıl tabanı | E30: Ürün mimarisi | F30: 01.01.2025 | G30: 11.08.2026 | H30: =IF(A30="","",IF(B30="","EKSİK","TAM"))
A31: gyf_yuvarMax | B31: 10 | C31: adet | D31: ROUND basamak tavanı | E31: Ürün mimarisi | F31: 01.01.2025 | G31: 11.08.2026 | H31: =IF(A31="","",IF(B31="","EKSİK","TAM"))
A32: gyf_bazCarpan | B32: 1 | C32: çarpan | D32: Baz senaryo çarpanı | E32: Model varsayımı | F32: 01.01.2025 | G32: 11.08.2026 | H32: =IF(A32="","",IF(B32="","EKSİK","TAM"))
A33: gyf_sifirCarpan | B33: 0 | C33: çarpan | D33: Nötr çarpan | E33: Model varsayımı | F33: 01.01.2025 | G33: 11.08.2026 | H33: =IF(A33="","",IF(B33="","EKSİK","TAM"))
A34: gyf_siraBir | B34: 1 | C34: adet | D34: Tornado sıra 1 | E34: Ürün mimarisi | F34: 01.01.2025 | G34: 11.08.2026 | H34: =IF(A34="","",IF(B34="","EKSİK","TAM"))
A35: gyf_siraIki | B35: 2 | C35: adet | D35: Tornado sıra 2 | E35: Ürün mimarisi | F35: 01.01.2025 | G35: 11.08.2026 | H35: =IF(A35="","",IF(B35="","EKSİK","TAM"))
A36: gyf_siraUc | B36: 3 | C36: adet | D36: Tornado sıra 3 | E36: Ürün mimarisi | F36: 01.01.2025 | G36: 11.08.2026 | H36: =IF(A36="","",IF(B36="","EKSİK","TAM"))
A37: gyf_dikkatCarpan | B37: 1.25 | C37: çarpan | D37: Geri ödeme dikkat çarpanı | E37: İç politika | F37: 01.01.2025 | G37: 11.08.2026 | H37: =IF(A37="","",IF(B37="","EKSİK","TAM"))
... A42: vaka_oz | B42: 98000 | C42: kWh | D42: Vaka öz tüketim | E42: Altın vaka | F42: 01.01.2025 | G42: 11.08.2026 | H42: =IF(A42="","",IF(B42="","EKSİK","TAM"))
J44: Sürüm 1.0.0 | Şifre koruması: 1234 (formül alanları)

Sheet KILAVUZ
A1: KILAVUZ — GES Yatırım Fizibilite Simülatörü
A3: Karar kuralları
A5: • VERİ YOK — giriş tablosu boşsa hesap yapılmaz.
A6: • YATIRIM YAPILIR — NPV pozitif ve geri ödeme hedef altında.
A7: • DİKKAT — geri ödeme veya NPV dikkat bandında; tarife/üretim gözden geçirilmeli.
A8: • YATIRIM YAPMA — NPV negatif veya geri ödeme aşırı (kötümser yol dahil).
A10: Belirsizlik beyanları
A11: Bu nokta mevzuatta tartışmalıdır; dosya yorum A ve yorum B sonucunu yan yana gösterir: yekdem_tarife_yenileme
A13: YEKDEM/şebeke satış tarifesi dönemsel yenilenir; bu dosya kullanıcı girişli tarife kullanır (dış API yok — Ç15). Tarife değişince GIRDI ve KURALLAR güncellenir.
A15: Dış veri formatı | B15: Özgül üretim: PVGIS veya saha ölçümü (kWh/kWp). Tarife: EPDK tebliğ / fatura. CAPEX: EPC teklif. OPEX: işletme bütçesi. API bağlantısı yoktur.
A17: Kullanım sırası
A18: GIRDI → VARSAYIMLAR → KURALLAR → MOTOR → FINANSMAN → SENARYO → PANO → KARAR → VAKALAR → KANIT_RAPORU → AYARLAR.
A20: Sürüm 1.0.0 | Lisans: Tek kullanıcı | ExcelArşiv | GYF-PRO
