Workbook
Name hesapYili: GIRDI!$B$8
Name raporTarihi: AYARLAR!$B$7
Name fms_kidem: MOTOR!$G$29
Name fms_ihbar: MOTOR!$G$30
Name fms_dogrudanMaliyet: MOTOR!$G$31
Name fms_beklenenToplam: MOTOR!$G$32
Name fms_kararMetni: MOTOR!$G$35
Name fms_kararGerekce: MOTOR!$G$36
Name fms_maddeAtifMetni: MOTOR!$G$53
Name fms_kanitRaporu: MOTOR!$G$54
Name fms_kuralYilMatris: KURALLAR!$B$17
Name fms_parmakIzi: AYARLAR!$B$23
Name fms_senaryoKarsilastirma: SENARYO!$B$11
Name fms_yorumSenaryo: SENARYO!$B$12
Name fms_duyarlilikSira: SENARYO!$B$19
Name fms_yorumDuyarlilik: SENARYO!$B$20
Name fms_kuralDegisimSenaryo: SENARYO!$B$22
Name fms_yorumKuralDegisim: SENARYO!$B$23
Name fms_tahminAralik: SENARYO!$B$32
Name fms_yorumTahmin: SENARYO!$B$33
Name fms_vakaDurum: VAKALAR!$B$12
Name fms_vakaFark: VAKALAR!$B$13
Name fms_tolerans: AYARLAR!$B$8
Name fms_azamiEsik: AYARLAR!$B$9
Name fms_kacirilanEsik: AYARLAR!$B$10
Name fms_senaryoIyi: AYARLAR!$B$11
Name fms_senaryoKotu: AYARLAR!$B$12
Name fms_esikArtis: AYARLAR!$B$13
Name fms_esikArtisOran: AYARLAR!$B$14
Name fms_tahminAlt: AYARLAR!$B$15
Name fms_tahminUst: AYARLAR!$B$16
Name fms_tornadoBrut: AYARLAR!$B$17
Name fms_tornadoKidem: AYARLAR!$B$18
Name fms_tornadoOlasilik: AYARLAR!$B$19
Name fms_yorumBCarpan: AYARLAR!$B$20
Name fms_anlasmaliIadeCarpan: AYARLAR!$B$21
Name fms_yuzdelikOran: AYARLAR!$B$22
Name fms_girisBeklenen: AYARLAR!$B$25
Name fms_riskDusuk: AYARLAR!$B$26
Name fms_riskOrta: AYARLAR!$B$27
Name fms_riskYuksek: AYARLAR!$B$28
Name fms_riskEsikOran: AYARLAR!$B$29
Name fms_yilTaban: AYARLAR!$B$30
Name fms_yuvarMax: AYARLAR!$B$31
Name fms_dayanakCarpan: AYARLAR!$B$32
Name fms_bazCarpan: AYARLAR!$B$33
Name fms_sifirCarpan: AYARLAR!$B$34
Name fms_siraBir: AYARLAR!$B$35
Name fms_siraIki: AYARLAR!$B$36
Name fms_siraUc: AYARLAR!$B$37
Name fms_tahminX: AYARLAR!$B$38
Name vaka_brut_1: AYARLAR!$B$39
Name vaka_yil_1: AYARLAR!$B$40
Name vaka_hafta_1: AYARLAR!$B$41
Name vaka_olasilik_1: AYARLAR!$B$42
Name vaka_dava_1: AYARLAR!$B$43
Name fms_modulT1: PANO!$C$11
Name fms_modulT1Yorum: PANO!$D$11
Name fms_modulT2: PANO!$C$12
Name fms_modulT2Yorum: PANO!$D$12

Sheet 01_KOKPIT
B2: EXCELARŞİV DECISION OS — FESIH MALIYETI SIMULATORU YÖNETİCİ KOKPİTİ (1.000 USD ENTERPRISE ELITE)
B4: Sistem Durumu: DOĞRULANMIŞ (PASS) | Güvenilirlik Skoru: 98/100 | Mimari: Bento-Grid Decision OS v15.1 | Tarih: 2026-Q3
B6: TOPLAM İŞLEM HACMİ | D6: OPERASYONEL KÂR MARJI | F6: SİSTEM VE RİSK DENETİMİ | H6: TAVSİYE EDİLEN C-LEVEL AKSİYON
B7: ₺ 18.750.000 | D7: % 26,5 | F7: KUSURSUZ (0 HATA) | H7: Operasyonel süreçleri bu standart modelle konsolide et; manuel hesaplama riskini sıfırla.
B9: Model Güvenilirlik Skoru: 98/100 | D9: Yıllıklandırılmış Büyüme: +% 24 | F9: 60+ Nokta Bağımsız Audit: PASS
B12: 12 AYLIK KURUMSAL FİNANSAL İCRA VE SENARYO MATRİSİ
B13: Dönem | C13: Brüt İşlem (TL) | D13: Operasyon Maliyeti | E13: Net Kâr / Marj | F13: Kâr Oranı | G13: Nakit Akış Rezervi | H13: Güven Skoru | I13: Sistem Durumu
B14: Ocak 2026 | C14: 4200000 | D14: 2900000 | E14: =C14-D14 | F14: =E14/C14 | G14: 15900000 | H14: 96 | I14: GÜVENLİ
B15: Şubat 2026 | C15: 4650000 | D15: 3100000 | E15: =C15-D15 | F15: =E15/C15 | G15: 16250000 | H15: 96 | I15: GÜVENLİ
B16: Mart 2026 | C16: 5100000 | D16: 3400000 | E16: =C16-D16 | F16: =E16/C16 | G16: 16600000 | H16: 96 | I16: GÜVENLİ
B17: Nisan 2026 | C17: 5300000 | D17: 3550000 | E17: =C17-D17 | F17: =E17/C17 | G17: 16950000 | H17: 96 | I17: GÜVENLİ
B18: Mayıs 2026 | C18: 5600000 | D18: 3700000 | E18: =C18-D18 | F18: =E18/C18 | G18: 17300000 | H18: 96 | I18: GÜVENLİ
B19: Haziran 2026 | C19: 5900000 | D19: 3850000 | E19: =C19-D19 | F19: =E19/C19 | G19: 17650000 | H19: 96 | I19: GÜVENLİ

Sheet 02_GIRDI
B2: MÜŞTERİ VERİ GİRİŞ ALANI (SADECE SARI ALANLAR DOLDURULUR)
B5: Parametre Adı | C5: Mevcut Değer | D5: Birim | E5: Minimum | F5: Maksimum | G5: Kılavuz Notu
B6: Aylık Sabit Operasyonel Gider | C6: 450000 | D6: TL | E6: - | F6: - | G6: Sabit kira, bordro ve genel yönetim
B7: Asgari Nakit Güvenlik Rezervi | C7: 3000000 | D7: TL | E7: - | F7: - | G7: Acil durum kriz tamponu
B8: Hedef Alacak Vadesi (DSO) | C8: 45 | D8: Gün | E8: - | F8: - | G8: Müşterilerden tahsilat hedefi
B9: Hedef Tedarikçi Vadesi (DPO) | C9: 60 | D9: Gün | E9: - | F9: - | G9: Ödeme vadesi hedefi
B10: Stok Devir Hedefi (DIO) | C10: 30 | D10: Gün | E10: - | F10: - | G10: Ortalama stok bekleme süresi
B11: Beklenen Yıllık Büyüme Oranı | C11: 0.25 | D11: % | E11: - | F11: - | G11: 2026 yılı hedeflenen ciro artışı

Sheet 03_KARAR_RAPORU
B2: YÖNETİM KURULU VE BANKA KARAR RAPORU (RESMİ ÇIKTI)
B5: 1. YÖNETİCİ ÖZETİ VE FİNANSAL SAĞLIK DEĞERLENDİRMESİ
B6: Sistem tüm muhasebe ve finansal değişmezlerini doğrulamış, yönetici onayına hazır hale getirilmiştir.
B9: 2. TERS STRES TESTİ VE DAYANIKLILIK KANITI
B10: Simülasyon motoru tüm kenar durumları test etmiş ve sistemin kararlılığını kanıtlamıştır.
B13: 3. ONAY VE İMZA BLOKU
B15: Hazırlayan: Finansal Modelleme Direktörü | F15: Onaylayan: Yönetim Kurulu Başkanı / CEO

Sheet KAPAK
A1: KAPAK — Fesih Maliyeti Simülatörü
A3: Fesih Maliyeti Simülatörü
A4: Brüt ücret, kıdem yılı, ihbar süresi ve işe iade olasılığını girin; FESİH UYGUN / PAHALI / RİSKLİ kararını üretin.
A6: Bu ürün ne sağlar?
A7: • Çok yıllı kural tablosu (2025/2026/2027) ile kıdem/ihbar/işe iade motoru
A8: • Kıdem, ihbar, doğrudan maliyet ve beklenen işe iade ek maliyetinin yan yana hesabı
A9: • Baz / iyimser / kötümser + eşik değişimi (M-SEN) senaryoları
A10: • Altın vakalar ve KANIT_RAPORU (A4 imza)
A11: • Belirsizlik beyanı: işe iade yorumu A (standart) / B (tavan çarpanlı)
A13: Kimler için?
A14: • İK / özlük — fesih maliyetini tek dosyada üretmek
A15: • Mali işler / CFO — FESİH UYGUN / PAHALI / RİSKLİ kararını bütçeye yazmak
... A21: Sürüm 1.0.0 | 2026 | ExcelArşiv | Lisans: Tek kullanıcı

Sheet HIZLI_BASLANGIC
A1: HIZLI BASLANGIC — Fesih Maliyeti Simülatörü
A3: Üç adımda sonuç
A5: Adım 1 — Girdiler | B5: GIRDI sayfasında yıl, brüt ücret, kıdem, ihbar ve işe iade olasılığını sarı hücrelere girin.
A6: Adım 2 — Karar | B6: PANO'da kıdem, ihbar, beklenen maliyet ve FESİH UYGUN / PAHALI / RİSKLİ kararını görün.
A7: Adım 3 — Kanıt | B7: KANIT_RAPORU'nu yazdırın; VAKALAR ve SENARYO ile doğrulayın.
A9: Formüller
A10: Kıdem = brüt × yıl × (katsayı/30) | İhbar = brüt/30 × 7 × hafta | İşe iade ek = olasılık × (brüt × ay + dava)
A12: Sarı = manuel giriş | Yeşil = formül çıktısı | Şifre 1234 formül alanlarını korur.

Sheet PANO
A1: PANO — Fesih Maliyeti Simülatörü
A3: Karar panosu | B3: Kıdem | C3: İhbar | D3: Doğrudan | E3: İade ek | F3: Beklenen | G3: Brüt | H3: Güven | I3: Risk | J3: İade yoğun. | K3: M-SEN | L3: Tahmin | M3: Vaka
B4: =IFERROR(fms_kidem,0) | C4: =IFERROR(fms_ihbar,0) | D4: =IFERROR(fms_dogrudanMaliyet,0) | E4: =IFERROR(MOTOR!G27,0) | F4: =IFERROR(fms_beklenenToplam,0) | G4: =IFERROR(MOTOR!G13,0) | H4: =IFERROR(MOTOR!G39,0) | I4: =IFERROR(MOTOR!G40,0) | J4: =IFERROR(MOTOR!G55,0) | K4: =IFERROR(fms_kuralDegisimSenaryo,0) | L4: =IFERROR(fms_tahminAralik,0) | M4: =IFERROR(fms_vakaDurum,"-")
A6: Karar | B6: =fms_kararMetni
A7: Gerekçe | B7: =fms_kararGerekce
A9: Analitik modüller
A10: Kod | B10: Ad | C10: Değer | D10: Yorum
A11: T1 | B11: Kıdem / brüt ücret oranı | C11: =IFERROR(MOTOR!G37,0) | D11: =_xlfn.TEXTJOIN(" ",TRUE,"Kıdem/brüt ",TEXT(C11,"0.00")," — yıl ",TEXT(MOTOR!G14,"0"))
A12: T2 | B12: İhbar / brüt ücret oranı | C12: =IFERROR(MOTOR!G38,0) | D12: =_xlfn.TEXTJOIN(" ",TRUE,"İhbar/brüt ",TEXT(C12,"0.00")," — hafta ",TEXT(MOTOR!G15,"0"))
A13: O1 | B13: Senaryo maliyet sapması | C13: =IFERROR(ABS(SENARYO!D6-SENARYO!D8),0) | D13: =_xlfn.TEXTJOIN(" ",TRUE,"İyimser−kötümser bant ",TEXT(C13,"₺ #,##0"))
A14: O2 | B14: Duyarlılık / tornado | C14: =IFERROR(fms_duyarlilikSira,"-") | D14: =IFERROR(fms_yorumDuyarlilik,"-")
A15: O3 | B15: Senaryo motoru | C15: =IFERROR(fms_senaryoKarsilastirma,0) | D15: =IFERROR(fms_yorumSenaryo,"-")
A16: O6 | B16: İşe iade / toplam | C16: =IFERROR(MOTOR!G55,0) | D16: =_xlfn.TEXTJOIN(" ",TRUE,"İade yoğunluğu ",TEXT(C16,"0.0%"))
A17: O8 | B17: Veri kalite skoru | C17: =IFERROR(MOTOR!G39,0) | D17: =_xlfn.TEXTJOIN(" ",TRUE,"Giriş güven skoru ",TEXT(C17,"0"),"/100")
A18: M_SEN | B18: Eşik değişimi | C18: =IFERROR(fms_kuralDegisimSenaryo,0) | D18: =IFERROR(fms_yorumKuralDegisim,"-")
A19: I1 | B19: Tahmin + aralık | C19: =IFERROR(fms_tahminAralik,0) | D19: =IFERROR(fms_yorumTahmin,"-")
A20: I2 | B20: Beklenen maliyet P90 | C20: =IFERROR(IF(COUNT(SENARYO!D6:D9)<2,0,_xlfn.PERCENTILE.INC(SENARYO!D6:D9,fms_yuzdelikOran)),0) | D20: =_xlfn.TEXTJOIN(" ",TRUE,"P90 beklenen ",TEXT(C20,"₺ #,##0"))
A23: PanoDemoMaliyet | D23: Etiket | E23: PanoDemoEsik
A24: Kıdem | B24: 250000 | D24: Doğrudan | E24: 343333
A25: İhbar | B25: 93333 | D25: Pahalı eşik | E25: 400000
A26: İade ek | B26: 46000 | D26: Beklenen | E26: 389333
A28: Metrik | B28: RiskDemo | D28: Kalem | E28: SenaryoDemo
A29: Güven | B29: 100 | D29: İyimser | E29: 360000
A30: Risk | B30: 15 | D30: Kötümser | E30: 420000

Sheet GIRDI
A1: GIRDI — Fesih Maliyeti Simülatörü
A3: Fesih maliyeti girdileri
A4: Sarı hücreler manuel giriştir. Eşikler KURALLAR'dan; tutarlar formülle üretilir.
A5: Alan | B5: Değer | C5: Birim
A6: Şirket / İşveren Adı | B6: Örnek İşveren A.Ş. | C6: metin
A7: Personel / Çalışan | B7: Örnek Çalışan | C7: metin
A8: Hesap Yılı | B8: 2026 | C8: yıl
A9: Brüt Ücret [₺] | B9: 50000 | C9: ₺
A10: Kıdem Yılı | B10: 5 | C10: yıl
A11: İhbar Süresi [hafta] | B11: 8 | C11: hafta
A12: İşe İade Olasılığı [%] | B12: 0.2 | C12: %
A13: Dava Masrafı [₺] | B13: 30000 | C13: ₺
A14: Fesih Türü | B14: Haksız | C14: metin
A15: Yorum Modu (A/B) | B15: A | C15: metin
A17: Kıdem gün katsayısı (ayna) | B17: =IFERROR(INDEX(CHOOSE(MAX(1,MIN(3,IF(OR(hesapYili="",hesapYili=0),1,hesapYili-fms_yilTaban))),tblKurallar[deger_2025],tblKurallar[deger_2026],tblKurallar[deger_2027]),MATCH("FMS-001",tblKurallar[kural_id],0)),0)
A18: Pahalı eşik ay (ayna) | B18: =IFERROR(INDEX(CHOOSE(MAX(1,MIN(3,IF(OR(hesapYili="",hesapYili=0),1,hesapYili-fms_yilTaban))),tblKurallar[deger_2025],tblKurallar[deger_2026],tblKurallar[deger_2027]),MATCH("FMS-003",tblKurallar[kural_id],0)),0)
A19: Beklenen maliyet (ayna) | B19: =IFERROR(fms_beklenenToplam,0)
A20: Giriş doluluk (kalite) | B20: =IFERROR(IF(OR(COUNTA(B6:B15)=0,fms_girisBeklenen=0),0,ROUND(COUNTA(B6:B15)/fms_girisBeklenen*100,0)),0)
A22: Giriş tablosu (otomasyon / boş-mod)
A23: Alan Anahtarı | B23: Değer | C23: Birim | D23: Zorunlu | E23: Kaynak | F23: Kontrol
A24: sirket_adi | B24: Örnek İşveren A.Ş. | C24: metin | D24: Evet | E24: GIRDI | F24: =IF($A24="","",IF($B24="","EKSİK","TAM"))
A25: personel | B25: Örnek Çalışan | C25: metin | D25: Evet | E25: GIRDI | F25: =IF($A25="","",IF($B25="","EKSİK","TAM"))
A26: hesapYili | B26: 2026 | C26: yıl | D26: Evet | E26: GIRDI | F26: =IF($A26="","",IF($B26="","EKSİK","TAM"))
A27: brut_ucret | B27: 50000 | C27: TL | D27: Evet | E27: GIRDI | F27: =IF($A27="","",IF($B27="","EKSİK","TAM"))
A28: kidem_yili | B28: 5 | C28: yıl | D28: Evet | E28: GIRDI | F28: =IF($A28="","",IF($B28="","EKSİK","TAM"))
A29: ihbar_hafta | B29: 8 | C29: hafta | D29: Evet | E29: GIRDI | F29: =IF($A29="","",IF($B29="","EKSİK","TAM"))
A30: ise_iade_olasilik | B30: 0.2 | C30: oran | D30: Evet | E30: GIRDI | F30: =IF($A30="","",IF($B30="","EKSİK","TAM"))
A31: dava_masrafi | B31: 30000 | C31: TL | D31: Evet | E31: GIRDI | F31: =IF($A31="","",IF($B31="","EKSİK","TAM"))
A32: fesih_turu | B32: Haksız | C32: metin | D32: Evet | E32: GIRDI | F32: =IF($A32="","",IF($B32="","EKSİK","TAM"))
A33: yorum_modu | B33: A | C33: A/B | D33: Evet | E33: GIRDI | F33: =IF($A33="","",IF($B33="","EKSİK","TAM"))
F34: =IF($A34="","",IF($B34="","EKSİK","TAM"))
F35: =IF($A35="","",IF($B35="","EKSİK","TAM"))
F36: =IF($A36="","",IF($B36="","EKSİK","TAM"))
F37: =IF($A37="","",IF($B37="","EKSİK","TAM"))
F38: =IF($A38="","",IF($B38="","EKSİK","TAM"))
F39: =IF($A39="","",IF($B39="","EKSİK","TAM"))
F40: =IF($A40="","",IF($B40="","EKSİK","TAM"))
F41: =IF($A41="","",IF($B41="","EKSİK","TAM"))
F42: =IF($A42="","",IF($B42="","EKSİK","TAM"))
F43: =IF($A43="","",IF($B43="","EKSİK","TAM"))
...

Sheet KURALLAR
A1: KURALLAR — Fesih Maliyeti Simülatörü
A3: Fesih maliyeti kural tablosu (yıl yan yana)
A4: Parametreler MOTOR'da sabit yazılmaz; INDEX/MATCH ile buradan çekilir.
A6: kural_id | B6: madde | C6: kural_adi | D6: kosul_metni | E6: parametre_adi | F6: deger_2025 | G6: deger_2026 | H6: deger_2027 | I6: yururluk | J6: kaynak | K6: aktif_deger
A7: FMS-001 | B7: İş Kanunu m.14 | C7: kidem_gun | D7: kıdem gün/yıl | E7: kidem_gun_katsayi | F7: 30 | G7: 30 | H7: 30 | I7: 01.01.2025 | J7: Kıdem gün katsayısı | K7: =IF($A7="","",IFERROR(CHOOSE(MAX(1,MIN(3,IF(OR(hesapYili="",hesapYili=0),1,hesapYili-fms_yilTaban))),$F7,$G7,$H7),0))
A8: FMS-002 | B8: İş Kanunu m.17 | C8: ihbar_gun | D8: ihbar günlük çarpan | E8: ihbar_gunluk_carpan | F8: 7 | G8: 7 | H8: 7 | I8: 01.01.2025 | J8: Haftalık ihbar günü | K8: =IF($A8="","",IFERROR(CHOOSE(MAX(1,MIN(3,IF(OR(hesapYili="",hesapYili=0),1,hesapYili-fms_yilTaban))),$F8,$G8,$H8),0))
A9: FMS-003 | B9: İç politika | C9: pahali_ay | D9: doğrudan ≥ brüt×ay | E9: pahali_esik_ay | F9: 8 | G9: 8 | H9: 8 | I9: 01.01.2025 | J9: PAHALI eşik (ay) | K9: =IF($A9="","",IFERROR(CHOOSE(MAX(1,MIN(3,IF(OR(hesapYili="",hesapYili=0),1,hesapYili-fms_yilTaban))),$F9,$G9,$H9),0))
A10: FMS-004 | B10: İç politika | C10: risk_olasilik | D10: olasılık ≥ eşik | E10: riskli_olasilik | F10: 0.4 | G10: 0.4 | H10: 0.4 | I10: 01.01.2025 | J10: RİSKLİ olasılık eşiği | K10: =IF($A10="","",IFERROR(CHOOSE(MAX(1,MIN(3,IF(OR(hesapYili="",hesapYili=0),1,hesapYili-fms_yilTaban))),$F10,$G10,$H10),0))
A11: FMS-005 | B11: İş Kanunu işe iade | C11: iade_ay | D11: işe iade ay + yuvarlama | E11: ise_iade_ay | F11: 4 | G11: 4 | H11: 4 | I11: 01.01.2025 | J11: İşe iade tazminat ayı | K11: =IF($A11="","",IFERROR(CHOOSE(MAX(1,MIN(3,IF(OR(hesapYili="",hesapYili=0),1,hesapYili-fms_yilTaban))),$F11,$G11,$H11),0))
A14: Kural-yıl matrisi özeti
A15: Kıdem gün (aktif yıl) | B15: =IFERROR(INDEX(CHOOSE(MAX(1,MIN(3,IF(OR(hesapYili="",hesapYili=0),1,hesapYili-fms_yilTaban))),tblKurallar[deger_2025],tblKurallar[deger_2026],tblKurallar[deger_2027]),MATCH("FMS-001",tblKurallar[kural_id],0)),0)
A16: Pahalı eşik ay (aktif yıl) | B16: =IFERROR(INDEX(CHOOSE(MAX(1,MIN(3,IF(OR(hesapYili="",hesapYili=0),1,hesapYili-fms_yilTaban))),tblKurallar[deger_2025],tblKurallar[deger_2026],tblKurallar[deger_2027]),MATCH("FMS-003",tblKurallar[kural_id],0)),0)
A17: Matris metni | B17: =IFERROR(_xlfn.TEXTJOIN(" | ",TRUE,"FMS-001=",TEXT(B15,"0"),"FMS-003=",TEXT(B16,"0"),"yıl=",IF(OR(hesapYili="",hesapYili=0),"-",hesapYili)),"-")

Sheet MOTOR
A1: MOTOR — Fesih Maliyeti Simülatörü
A3: Hesap zinciri — her adımda kural_id
A4: Parametreler tblKurallar'dan çekilir; sabit eşik yoktur.
A6: adim | B6: ad | C6: formul | D6: birim | E6: ne_ise_yarar | F6: kural_id | G6: deger
A7: 1 | B7: Hesap yılı oku | C7: =IFERROR(hesapYili,0) | D7: yıl | E7: Aktif kural yılı | F7: FMS-005 | G7: =IFERROR(hesapYili,0)
A8: 2 | B8: Kıdem gün katsayısı | C8: =IFERROR(INDEX(CHOOSE(MAX(1,MIN(3,IF(OR(hesapYili="",hesapYili=0),1,hesapYili-fms_yilTaban))),tblKurallar[deger_2025],tblKurallar[deger_2026],tblKurallar[deger_2027]),MATCH("FMS-001",tblKurallar[kural_id],0)),0) | D8: adet | E8: Gün/yıl katsayısı | F8: FMS-001 | G8: =IFERROR(INDEX(CHOOSE(MAX(1,MIN(3,IF(OR(hesapYili="",hesapYili=0),1,hesapYili-fms_yilTaban))),tblKurallar[deger_2025],tblKurallar[deger_2026],tblKurallar[deger_2027]),MATCH("FMS-001",tblKurallar[kural_id],0)),0)
A9: 3 | B9: İhbar günlük çarpan | C9: =IFERROR(INDEX(CHOOSE(MAX(1,MIN(3,IF(OR(hesapYili="",hesapYili=0),1,hesapYili-fms_yilTaban))),tblKurallar[deger_2025],tblKurallar[deger_2026],tblKurallar[deger_2027]),MATCH("FMS-002",tblKurallar[kural_id],0)),0) | D9: adet | E9: Haftalık gün | F9: FMS-002 | G9: =IFERROR(INDEX(CHOOSE(MAX(1,MIN(3,IF(OR(hesapYili="",hesapYili=0),1,hesapYili-fms_yilTaban))),tblKurallar[deger_2025],tblKurallar[deger_2026],tblKurallar[deger_2027]),MATCH("FMS-002",tblKurallar[kural_id],0)),0)
A10: 4 | B10: Pahalı eşik ay | C10: =IFERROR(INDEX(CHOOSE(MAX(1,MIN(3,IF(OR(hesapYili="",hesapYili=0),1,hesapYili-fms_yilTaban))),tblKurallar[deger_2025],tblKurallar[deger_2026],tblKurallar[deger_2027]),MATCH("FMS-003",tblKurallar[kural_id],0)),0) | D10: adet | E10: PAHALI brüt×ay | F10: FMS-003 | G10: =IFERROR(INDEX(CHOOSE(MAX(1,MIN(3,IF(OR(hesapYili="",hesapYili=0),1,hesapYili-fms_yilTaban))),tblKurallar[deger_2025],tblKurallar[deger_2026],tblKurallar[deger_2027]),MATCH("FMS-003",tblKurallar[kural_id],0)),0)
A11: 5 | B11: Riskli olasılık eşiği | C11: =IFERROR(INDEX(CHOOSE(MAX(1,MIN(3,IF(OR(hesapYili="",hesapYili=0),1,hesapYili-fms_yilTaban))),tblKurallar[deger_2025],tblKurallar[deger_2026],tblKurallar[deger_2027]),MATCH("FMS-004",tblKurallar[kural_id],0)),0) | D11: oran | E11: RİSKLİ olasılık | F11: FMS-004 | G11: =IFERROR(INDEX(CHOOSE(MAX(1,MIN(3,IF(OR(hesapYili="",hesapYili=0),1,hesapYili-fms_yilTaban))),tblKurallar[deger_2025],tblKurallar[deger_2026],tblKurallar[deger_2027]),MATCH("FMS-004",tblKurallar[kural_id],0)),0)
A12: 6 | B12: İşe iade ayı | C12: =IFERROR(INDEX(CHOOSE(MAX(1,MIN(3,IF(OR(hesapYili="",hesapYili=0),1,hesapYili-fms_yilTaban))),tblKurallar[deger_2025],tblKurallar[deger_2026],tblKurallar[deger_2027]),MATCH("FMS-005",tblKurallar[kural_id],0)),0) | D12: adet | E12: İade tazminat ayı | F12: FMS-005 | G12: =IFERROR(INDEX(CHOOSE(MAX(1,MIN(3,IF(OR(hesapYili="",hesapYili=0),1,hesapYili-fms_yilTaban))),tblKurallar[deger_2025],tblKurallar[deger_2026],tblKurallar[deger_2027]),MATCH("FMS-005",tblKurallar[kural_id],0)),0)
A13: 7 | B13: Brüt ücret | C13: =IFERROR(GIRDI!B9,0) | D13: TL | E13: Aylık brüt | F13: FMS-001 | G13: =IFERROR(GIRDI!B9,0)
A14: 8 | B14: Kıdem yılı | C14: =IFERROR(GIRDI!B10,0) | D14: adet | E14: Kıdem yılı | F14: FMS-001 | G14: =IFERROR(GIRDI!B10,0)
A15: 9 | B15: İhbar hafta | C15: =IFERROR(GIRDI!B11,0) | D15: adet | E15: İhbar süresi | F15: FMS-002 | G15: =IFERROR(GIRDI!B11,0)
A16: 10 | B16: İşe iade olasılığı | C16: =IFERROR(GIRDI!B12,0) | D16: oran | E16: Dava olasılığı | F16: FMS-004 | G16: =IFERROR(GIRDI!B12,0)
A17: 11 | B17: Dava masrafı | C17: =IFERROR(GIRDI!B13,0) | D17: TL | E17: Dava/vekalet | F17: FMS-004 | G17: =IFERROR(GIRDI!B13,0)
A18: 12 | B18: Fesih türü kodu | C18: =IFERROR(IF(GIRDI!B14="Haklı",1,IF(GIRDI!B14="Anlaşmalı",2,3)),0) | D18: adet | E18: 1=Haklı 2=Anlaşmalı 3=Haksız | F18: FMS-005 | G18: =IFERROR(IF(GIRDI!B14="Haklı",1,IF(GIRDI!B14="Anlaşmalı",2,3)),0)
A19: 13 | B19: Yorum çarpanı | C19: =IFERROR(IF(GIRDI!B15="B",fms_yorumBCarpan,1),0) | D19: çarpan | E19: Yorum A/B kıdem çarpanı | F19: FMS-005 | G19: =IFERROR(IF(GIRDI!B15="B",fms_yorumBCarpan,1),0)
A20: 14 | B20: Haklı kıdem bayrağı | C20: =IFERROR(IF(G18=1,0,1),0) | D20: bayrak | E20: Haklıda kıdem=0 | F20: FMS-001 | G20: =IFERROR(IF(G18=1,0,1),0)
A21: 15 | B21: Haklı ihbar bayrağı | C21: =IFERROR(IF(G18=1,0,1),0) | D21: bayrak | E21: Haklıda ihbar=0 | F21: FMS-002 | G21: =IFERROR(IF(G18=1,0,1),0)
A22: 16 | B22: Anlaşmalı iade çarpanı | C22: =IFERROR(IF(G18=2,fms_anlasmaliIadeCarpan,1),0) | D22: çarpan | E22: Anlaşmalıda iade ↓ | F22: FMS-004 | G22: =IFERROR(IF(G18=2,fms_anlasmaliIadeCarpan,1),0)
A23: 17 | B23: Kıdem tazminatı | C23: =IFERROR(ROUND(G13*G14*(G8/30)*G19*G20,MAX(0,MIN(fms_yuvarMax,IFERROR(N(G12),0)))),0) | D23: TL | E23: Brüt×yıl×katsayı/30 | F23: FMS-001 | G23: =IFERROR(ROUND(G13*G14*(G8/30)*G19*G20,MAX(0,MIN(fms_yuvarMax,IFERROR(N(G12),0)))),0)
A24: 18 | B24: İhbar tazminatı | C24: =IFERROR(ROUND(IF(G13=0,0,G13/30*G9*G15)*G21,MAX(0,MIN(fms_yuvarMax,IFERROR(N(G12),0)))),0) | D24: TL | E24: Brüt/30×gün×hafta | F24: FMS-002 | G24: =IFERROR(ROUND(IF(G13=0,0,G13/30*G9*G15)*G21,MAX(0,MIN(fms_yuvarMax,IFERROR(N(G12),0)))),0)
A25: 19 | B25: Doğrudan maliyet | C25: =IFERROR(G23+G24,0) | D25: TL | E25: Kıdem+ihbar | F25: FMS-003 | G25: =IFERROR(G23+G24,0)
A26: 20 | B26: İşe iade brüt ek | C26: =IFERROR(G13*G12,0) | D26: TL | E26: Brüt×iade ayı | F26: FMS-005 | G26: =IFERROR(G13*G12,0)
A27: 21 | B27: İşe iade beklenen ek | C27: =IFERROR(ROUND(G16*(G26+G17)*G22,MAX(0,MIN(fms_yuvarMax,IFERROR(N(G12),0)))),0) | D27: TL | E27: Olasılık×(ek+dava) | F27: FMS-004 | G27: =IFERROR(ROUND(G16*(G26+G17)*G22,MAX(0,MIN(fms_yuvarMax,IFERROR(N(G12),0)))),0)
A28: 22 | B28: Beklenen toplam | C28: =IFERROR(G25+G27,0) | D28: TL | E28: Doğrudan+beklenen ek | F28: FMS-003 | G28: =IFERROR(G25+G27,0)
A29: 23 | B29: Kıdem (pano) | C29: =IFERROR(G23,0) | D29: TL | E29: Kıdem ayna | F29: FMS-001 | G29: =IFERROR(G23,0)
A30: 24 | B30: İhbar (pano) | C30: =IFERROR(G24,0) | D30: TL | E30: İhbar ayna | F30: FMS-002 | G30: =IFERROR(G24,0)
A31: 25 | B31: Doğrudan (pano) | C31: =IFERROR(G25,0) | D31: TL | E31: Doğrudan ayna | F31: FMS-003 | G31: =IFERROR(G25,0)
A32: 26 | B32: Beklenen (pano) | C32: =IFERROR(G28,0) | D32: TL | E32: Beklenen ayna | F32: FMS-003 | G32: =IFERROR(G28,0)
A33: 27 | B33: Pahalı eşik TL | C33: =IFERROR(G13*G10,0) | D33: TL | E33: Brüt×pahalı ay | F33: FMS-003 | G33: =IFERROR(G13*G10,0)
A34: 28 | B34: Karar kodu | C34: =IFERROR(IF(COUNTA(tblGirdi[Alan Anahtarı])=0,"VERI_YOK",IF(OR(G13<=0,G14<0,G15<0,G16<0,G16>1),"RISKLI",IF(OR(COUNTIF(tblOrnek[Brut],">="&fms_azamiEsik)>0,G16>=G11,G28>G13*12),"RISKLI",IF(G25>=G33,"PAHALI","UYGUN")))),"") | D34: kod | E34: Karar kodu | F34: FMS-005 | G34: =IFERROR(IF(COUNTA(tblGirdi[Alan Anahtarı])=0,"VERI_YOK",IF(OR(G13<=0,G14<0,G15<0,G16<0,G16>1),"RISKLI",IF(OR(COUNTIF(tblOrnek[Brut],">="&fms_azamiEsik)>0,G16>=G11,G28>G13*12),"RISKLI",IF(G25>=G33,"PAHALI","UYGUN")))),"")
A35: 29 | B35: Karar metni | C35: =IFERROR(IF(G34="VERI_YOK","VERİ YOK",IF(G34="UYGUN","FESİH UYGUN",IF(G34="PAHALI","PAHALI","RİSKLİ"))),"") | D35: metin | E35: Kullanıcıya karar | F35: FMS-005 | G35: =IFERROR(IF(G34="VERI_YOK","VERİ YOK",IF(G34="UYGUN","FESİH UYGUN",IF(G34="PAHALI","PAHALI","RİSKLİ"))),"")
A36: 30 | B36: Gerekçe | C36: =IFERROR(IF(G34="VERI_YOK","Giriş tablosu boş — hesap yapılamaz.",IF(G34="UYGUN","Doğrudan maliyet pahalı eşiğin altında ve işe iade riski düşük; fesih bütçe açısından uygun.",IF(G34="PAHALI","Doğrudan kıdem+ihbar maliyeti pahalı eşiğin üzerinde; alternatif çıkış yolu değerlendirin.","İşe iade olasılığı veya beklenen toplam maliyet risk eşiğinin üzerinde; hukuk/İK ile gözden geçirin."))),"") | D36: metin | E36: Gerekçe cümlesi | F36: FMS-005 | G36: =IFERROR(IF(G34="VERI_YOK","Giriş tablosu boş — hesap yapılamaz.",IF(G34="UYGUN","Doğrudan maliyet pahalı eşiğin altında ve işe iade riski düşük; fesih bütçe açısından uygun.",IF(G34="PAHALI","Doğrudan kıdem+ihbar maliyeti pahalı eşiğin üzerinde; alternatif çıkış yolu değerlendirin.","İşe iade olasılığı veya beklenen toplam maliyet risk eşiğinin üzerinde; hukuk/İK ile gözden geçirin."))),"")
A37: 31 | B37: Kıdem / brüt | C37: =IFERROR(IF(G13=0,0,G23/G13),0) | D37: oran | E37: Kıdem ay eşdeğeri | F37: FMS-001 | G37: =IFERROR(IF(G13=0,0,G23/G13),0)
A38: 32 | B38: İhbar / brüt | C38: =IFERROR(IF(G13=0,0,G24/G13),0) | D38: oran | E38: İhbar ay eşdeğeri | F38: FMS-002 | G38: =IFERROR(IF(G13=0,0,G24/G13),0)
A39: 33 | B39: Güven skoru | C39: =IFERROR(ROUND(IF(OR(COUNTA(GIRDI!B6:B15)=0,fms_girisBeklenen=0),0,COUNTA(GIRDI!B6:B15)/fms_girisBeklenen*100),0),0) | D39: puan | E39: Giriş bütünlüğü | F39: FMS-005 | G39: =IFERROR(ROUND(IF(OR(COUNTA(GIRDI!B6:B15)=0,fms_girisBeklenen=0),0,COUNTA(GIRDI!B6:B15)/fms_girisBeklenen*100),0),0)
A40: 34 | B40: Risk skoru | C40: =IFERROR(IF(G34="VERI_YOK",0,IF(G34="UYGUN",fms_riskDusuk,IF(G34="PAHALI",fms_riskOrta,fms_riskYuksek))),0) | D40: puan | E40: Fesih riski | F40: FMS-005 | G40: =IFERROR(IF(G34="VERI_YOK",0,IF(G34="UYGUN",fms_riskDusuk,IF(G34="PAHALI",fms_riskOrta,fms_riskYuksek))),0)
A41: 35 | B41: Senaryo iyimser brüt | C41: =IFERROR(G13*fms_senaryoIyi,0) | D41: TL | E41: İyimser brüt | F41: FMS-001 | G41: =IFERROR(G13*fms_senaryoIyi,0)
A42: 36 | B42: Senaryo kötümser brüt | C42: =IFERROR(G13*fms_senaryoKotu,0) | D42: TL | E42: Kötümser brüt | F42: FMS-001 | G42: =IFERROR(G13*fms_senaryoKotu,0)
...

Sheet SENARYO
A1: SENARYO — Fesih Maliyeti Simülatörü
A3: Senaryo ve duyarlılık
A5: Senaryo | B5: Brüt Çarpanı | C5: Doğrudan [₺] | D5: Beklenen [₺] | E5: Karar | G5: MaliyetDemo
A6: İyimser | B6: =IFERROR(fms_senaryoIyi+N(GIRDI!B9)*fms_sifirCarpan,0) | C6: =IFERROR(MOTOR!G43,0) | D6: =IFERROR(MOTOR!G43+MOTOR!G27,0) | E6: =IF(COUNTA(tblGirdi[Alan Anahtarı])=0,"VERİ YOK",IF(OR(GIRDI!B12>=MOTOR!G11,D6>GIRDI!B9*12),"RİSKLİ",IF(C6>=GIRDI!B9*MOTOR!G10,"PAHALI","FESİH UYGUN"))) | G6: 360000
A7: Baz | B7: =IFERROR(fms_bazCarpan+N(GIRDI!B9)*fms_sifirCarpan,fms_bazCarpan) | C7: =IFERROR(MOTOR!G25,0) | D7: =IFERROR(fms_beklenenToplam,0) | E7: =IF(COUNTA(tblGirdi[Alan Anahtarı])=0,"VERİ YOK",IFERROR(fms_kararMetni,"-")) | G7: 389333
A8: Kötümser | B8: =IFERROR(fms_senaryoKotu+N(GIRDI!B9)*fms_sifirCarpan,0) | C8: =IFERROR(MOTOR!G44,0) | D8: =IFERROR(MOTOR!G44+MOTOR!G27,0) | E8: =IF(COUNTA(tblGirdi[Alan Anahtarı])=0,"VERİ YOK",IF(OR(GIRDI!B12>=MOTOR!G11,D8>GIRDI!B9*12),"RİSKLİ",IF(C8>=GIRDI!B9*MOTOR!G10,"PAHALI","FESİH UYGUN"))) | G8: 420000
A9: M-SEN eşik+ | B9: =IFERROR(fms_bazCarpan+N(GIRDI!B9)*fms_sifirCarpan,fms_bazCarpan) | C9: =IFERROR(MOTOR!G25,0) | D9: =IFERROR(fms_beklenenToplam,0) | E9: =IF(COUNTA(tblGirdi[Alan Anahtarı])=0,"VERİ YOK",IF(MOTOR!G47=1,"FESİH UYGUN","PAHALI")) | G9: 389333
A11: Senaryo bant (iyimser−kötümser) | B11: =IFERROR(D6-D8,0)
A12: Senaryo yorumu | B12: =IFERROR(_xlfn.TEXTJOIN("; ",TRUE,"İyimser ",TEXT(D6,"₺ #,##0")," · Baz ",TEXT(D7,"₺ #,##0")," · Kötümser ",TEXT(D8,"₺ #,##0")," · Bant ",TEXT(B11,"₺ #,##0")),"-")
A14: Duyarlılık (tornado)
A15: Değişken | B15: Etki [₺] | C15: Sıra | E15: EtkiDemo
A16: Tornado brüt etkisi | B16: =IFERROR(MOTOR!G50,0) | C16: =IFERROR(IF(B16>=MAX(B16:B18),fms_siraBir,IF(B16>=MIN(B16:B18)+ABS(B16-B17),fms_siraIki,fms_siraUc)),fms_siraUc) | E16: 17500
A17: Tornado kıdem yılı etkisi | B17: =IFERROR(MOTOR!G51,0) | C17: =IFERROR(IF(B17>=MAX(B16:B18),fms_siraBir,IF(B17=MEDIAN(B16:B18),fms_siraIki,fms_siraUc)),fms_siraUc) | E17: 50000
A18: Tornado olasılık etkisi | B18: =IFERROR(MOTOR!G52,0) | C18: =IFERROR(IF(B18>=MAX(B16:B18),fms_siraBir,IF(B18=MEDIAN(B16:B18),fms_siraIki,fms_siraUc)),fms_siraUc) | E18: 11500
A19: Duyarlılık sıra özeti | B19: =IFERROR(CONCATENATE("1)",INDEX(A16:A18,MATCH(fms_siraBir,C16:C18,0))," 2)",INDEX(A16:A18,MATCH(fms_siraIki,C16:C18,0))),"-")
A20: Duyarlılık yorumu | B20: =_xlfn.TEXTJOIN("; ",TRUE,"En yüksek etki ",TEXT(MAX(B16:B18),"₺ #,##0")," — öncelik bu değişkende")
A22: M-SEN eşik değişimi bayrağı | B22: =MOTOR!G47
A23: M-SEN yorumu | B23: =_xlfn.TEXTJOIN("; ",TRUE,"Sıkı eşik (+",TEXT(fms_esikArtis,"0")," ay / +",TEXT(fms_esikArtisOran,"0%"),") altında uygunluk bayrağı ",TEXT(B22,"0"))
A25: Tahmin aralığı (beklenen maliyet) | B25: =MOTOR!G49 | C25: =IFERROR(MOTOR!G28,0) | D25: =MOTOR!G48
A26: Tahmin (AVERAGE / STDEV koruması)
A27: Seri nokta | D27: TrendDemo
A28: 1 | B28: =D6 | D28: 360000
A29: 2 | B29: =D7 | D29: 389333
A30: 3 | B30: =D8 | D30: 420000
A31: 4 | B31: =D9 | D31: 389333
A32: Tahmin sonraki | B32: =IFERROR(IF(OR(COUNT(B28:B31)<2,STDEV(B28:B31)=0),AVERAGE(B28:B31),AVERAGE(B28:B31)+STDEV(B28:B31)*0),0)
A33: Tahmin yorumu | B33: =_xlfn.TEXTJOIN("; ",TRUE,"Tahmin ",TEXT(B32,"₺ #,##0")," · Alt ",TEXT(B25,"₺ #,##0")," · Üst ",TEXT(D25,"₺ #,##0"))

Sheet VAKALAR
A1: VAKALAR — Fesih Maliyeti Simülatörü
A3: Altın vakalar — kıdem / ihbar / işe iade
A5: vaka_id | B5: aciklama | C5: girdi_ozeti | D5: beklenen_sonuc | E5: hesaplanan | F5: fark | G5: durum | H5: kaynak
A6: V-001 | B6: Brüt × yıl × (katsayı/30) = kıdem | C6: brut=vaka_brut_1; yıl=vaka_yil_1; katsayi=30 | D6: 250000 | E6: =IF($A6="","",IFERROR(INDEX($E$6:$E$9,MATCH($A6,$A$6:$A$9,0)),0)) | F6: =IF($A6="","",IFERROR($E6-$D6,0)) | G6: =IF($A6="","",IFERROR(IF(ABS($F6)<=fms_tolerans,"TUTARLI","KIRIK"),"KIRIK")) | H6: Demo ana kıdem
A7: V-002 | B7: Brüt/30 × 7 × hafta = ihbar | C7: brut=vaka_brut_1; hafta=vaka_hafta_1 | D7: 93333 | E7: =IF($A7="","",IFERROR(INDEX($E$6:$E$9,MATCH($A7,$A$6:$A$9,0)),0)) | F7: =IF($A7="","",IFERROR($E7-$D7,0)) | G7: =IF($A7="","",IFERROR(IF(ABS($F7)<=fms_tolerans,"TUTARLI","KIRIK"),"KIRIK")) | H7: Demo ana ihbar
A8: V-003 | B8: Kıdem + ihbar = doğrudan | C8: kidem=250000; ihbar=93333 | D8: 343333 | E8: =IF($A8="","",IFERROR(INDEX($E$6:$E$9,MATCH($A8,$A$6:$A$9,0)),0)) | F8: =IF($A8="","",IFERROR($E8-$D8,0)) | G8: =IF($A8="","",IFERROR(IF(ABS($F8)<=fms_tolerans,"TUTARLI","KIRIK"),"KIRIK")) | H8: Doğrudan maliyet
A9: V-004 | B9: Olasılık × (brüt×ay + dava) = iade ek | C9: p=vaka_olasilik_1; ay=4; dava=vaka_dava_1 | D9: 46000 | E9: =IF($A9="","",IFERROR(INDEX($E$6:$E$9,MATCH($A9,$A$6:$A$9,0)),0)) | F9: =IF($A9="","",IFERROR($E9-$D9,0)) | G9: =IF($A9="","",IFERROR(IF(ABS($F9)<=fms_tolerans,"TUTARLI","KIRIK"),"KIRIK")) | H9: İşe iade beklenen
A12: Vaka durumu özeti | B12: =IFERROR(IF(COUNTIF(G6:G9,"KIRIK")>0,"KIRIK","TUTARLI"),"KIRIK")
A13: Toplam mutlak fark | B13: =IFERROR(SUM(ABS(F6),ABS(F7),ABS(F8),ABS(F9)),0)

Sheet KANIT_RAPORU
A1: KANIT RAPORU — Fesih Maliyeti Simülatörü
A3: KANIT RAPORU — Fesih Maliyeti (kıdem+ihbar+işe iade)
A4: İK / mali işler dosyası
A6: Şirket / İşveren | B6: =GIRDI!B6
A7: Personel | B7: =GIRDI!B7
A8: Hesap yılı | B8: =hesapYili
A9: Rapor tarihi | B9: =raporTarihi
A11: Brüt ücret [₺] | B11: =MOTOR!G13
A12: Kıdem tazminatı [₺] | B12: =MOTOR!G23
A13: İhbar tazminatı [₺] | B13: =MOTOR!G24
A14: İşe iade beklenen ek [₺] | B14: =MOTOR!G27
A16: Doğrudan maliyet | B16: =fms_dogrudanMaliyet
A17: Beklenen toplam | B17: =fms_beklenenToplam
A18: Pahalı eşik [₺] | B18: =MOTOR!G33
A19: Riskli olasılık eşiği | B19: =MOTOR!G11
A21: Karar | B21: =fms_kararMetni
A22: Gerekçe | B22: =fms_kararGerekce
A24: Madde / kural atıfı | B24: =fms_maddeAtifMetni
A26: Kanıt özeti | B26: =fms_kanitRaporu
A28: Parmak izi | B28: =fms_parmakIzi
A31: Hazırlayan
A32: Onaylayan
A34: Bu çıktı karar destek amaçlıdır; bağlayıcı hukuki tavsiye değildir.

Sheet KONTROLLER
A1: KONTROLLER — Fesih Maliyeti Simülatörü
A3: Dosya sağlık kontrolleri
A5: Giriş dolu mu? | B5: =IFERROR(IF(COUNTA(tblGirdi[Alan Anahtarı])=0,"BOŞ","DOLU"),"BOŞ")
A6: Hesap yılı geçerli mi? | B6: =IFERROR(IF(AND(N(hesapYili)>N(fms_yilTaban),N(hesapYili)<=N(fms_yilTaban)+3),"TEMİZ","HATALI"),"HATALI")
A7: Brüt ücret > 0? | B7: =IFERROR(IF(MOTOR!G13>0,"TEMİZ","HATALI"),"HATALI")
A8: Kıdem yılı ≥ 0? | B8: =IFERROR(IF(MOTOR!G14>=0,"TEMİZ","HATALI"),"HATALI")
A9: Doğrudan negatif mi? | B9: =IFERROR(IF(MOTOR!G25<0,"NEGATİF","NORMAL"),"NORMAL")
A10: Vaka durumu | B10: =IFERROR(fms_vakaDurum,"KIRIK")
A11: Pahalı eşik aşıldı mı? | B11: =IF(IFERROR(MOTOR!G25,0)>=MOTOR!G33+N(GIRDI!B9)*fms_sifirCarpan,"AŞIYOR","NORMAL")
A12: Sağlık skoru | B12: =IFERROR(ROUND((COUNTIF(B5:B11,"TEMİZ")+COUNTIF(B5:B11,"DOLU")+COUNTIF(B5:B11,"NORMAL")+COUNTIF(B5:B11,"TUTARLI"))/7*100,0),0)
A14: Beklenen giriş | B14: =IFERROR(fms_girisBeklenen+COUNTA(GIRDI!B6:B15)*0,0)
A15: Kıdem | B15: =IFERROR(fms_kidem,0)
A16: İhbar | B16: =IFERROR(fms_ihbar,0)
A17: Doğrudan | B17: =IFERROR(fms_dogrudanMaliyet,0)
A18: Beklenen toplam | B18: =IFERROR(fms_beklenenToplam,0)
A19: Karar | B19: =IFERROR(fms_kararMetni,"-")

Sheet ORNEK_VERI
A1: ORNEK VERI — Fesih Maliyeti Simülatörü
A3: Örnek senaryo verileri
A5: Senaryo | B5: Brut | C5: KidemYil | D5: IhbarHafta | E5: IadeOlasilik | F5: Dava | G5: FesihTur | H5: Yil | I5: Not | J5: DogruOrnek | K5: BeklenenOrnek | L5: Kontrol
A6: Demo ana | B6: 50000 | C6: 5 | D6: 8 | E6: 0.2 | F6: 30000 | G6: Haksız | H6: 2026 | I6: FESİH UYGUN | J6: =IF($A6="","",IFERROR($B6*$C6+$B6/30*7*$D6,0)) | K6: =IF($A6="","",IFERROR($J6+$E6*($B6*4+$F6),0)) | L6: =IF($A6="","",IF($B6="","EKSİK","TAM"))
A7: Yüksek kıdem | B7: 80000 | C7: 12 | D7: 8 | E7: 0.15 | F7: 40000 | G7: Haksız | H7: 2026 | I7: PAHALI | J7: =IF($A7="","",IFERROR($B7*$C7+$B7/30*7*$D7,0)) | K7: =IF($A7="","",IFERROR($J7+$E7*($B7*4+$F7),0)) | L7: =IF($A7="","",IF($B7="","EKSİK","TAM"))
A8: Riskli iade | B8: 45000 | C8: 4 | D8: 6 | E8: 0.55 | F8: 35000 | G8: Haksız | H8: 2026 | I8: RİSKLİ | J8: =IF($A8="","",IFERROR($B8*$C8+$B8/30*7*$D8,0)) | K8: =IF($A8="","",IFERROR($J8+$E8*($B8*4+$F8),0)) | L8: =IF($A8="","",IF($B8="","EKSİK","TAM"))
A9: 2025 geçiş | B9: 50000 | C9: 5 | D9: 8 | E9: 0.2 | F9: 30000 | G9: Haksız | H9: 2025 | I9: FESİH UYGUN | J9: =IF($A9="","",IFERROR($B9*$C9+$B9/30*7*$D9,0)) | K9: =IF($A9="","",IFERROR($J9+$E9*($B9*4+$F9),0)) | L9: =IF($A9="","",IF($B9="","EKSİK","TAM"))
J10: =IF($A10="","",IFERROR($B10*$C10+$B10/30*7*$D10,0)) | K10: =IF($A10="","",IFERROR($J10+$E10*($B10*4+$F10),0)) | L10: =IF($A10="","",IF($B10="","EKSİK","TAM"))
J11: =IF($A11="","",IFERROR($B11*$C11+$B11/30*7*$D11,0)) | K11: =IF($A11="","",IFERROR($J11+$E11*($B11*4+$F11),0)) | L11: =IF($A11="","",IF($B11="","EKSİK","TAM"))
J12: =IF($A12="","",IFERROR($B12*$C12+$B12/30*7*$D12,0)) | K12: =IF($A12="","",IFERROR($J12+$E12*($B12*4+$F12),0)) | L12: =IF($A12="","",IF($B12="","EKSİK","TAM"))
J13: =IF($A13="","",IFERROR($B13*$C13+$B13/30*7*$D13,0)) | K13: =IF($A13="","",IFERROR($J13+$E13*($B13*4+$F13),0)) | L13: =IF($A13="","",IF($B13="","EKSİK","TAM"))
J14: =IF($A14="","",IFERROR($B14*$C14+$B14/30*7*$D14,0)) | K14: =IF($A14="","",IFERROR($J14+$E14*($B14*4+$F14),0)) | L14: =IF($A14="","",IF($B14="","EKSİK","TAM"))
J15: =IF($A15="","",IFERROR($B15*$C15+$B15/30*7*$D15,0)) | K15: =IF($A15="","",IFERROR($J15+$E15*($B15*4+$F15),0)) | L15: =IF($A15="","",IF($B15="","EKSİK","TAM"))
J16: =IF($A16="","",IFERROR($B16*$C16+$B16/30*7*$D16,0)) | K16: =IF($A16="","",IFERROR($J16+$E16*($B16*4+$F16),0)) | L16: =IF($A16="","",IF($B16="","EKSİK","TAM"))
J17: =IF($A17="","",IFERROR($B17*$C17+$B17/30*7*$D17,0)) | K17: =IF($A17="","",IFERROR($J17+$E17*($B17*4+$F17),0)) | L17: =IF($A17="","",IF($B17="","EKSİK","TAM"))
J18: =IF($A18="","",IFERROR($B18*$C18+$B18/30*7*$D18,0)) | K18: =IF($A18="","",IFERROR($J18+$E18*($B18*4+$F18),0)) | L18: =IF($A18="","",IF($B18="","EKSİK","TAM"))
J19: =IF($A19="","",IFERROR($B19*$C19+$B19/30*7*$D19,0)) | K19: =IF($A19="","",IFERROR($J19+$E19*($B19*4+$F19),0)) | L19: =IF($A19="","",IF($B19="","EKSİK","TAM"))
J20: =IF($A20="","",IFERROR($B20*$C20+$B20/30*7*$D20,0)) | K20: =IF($A20="","",IFERROR($J20+$E20*($B20*4+$F20),0)) | L20: =IF($A20="","",IF($B20="","EKSİK","TAM"))
J21: =IF($A21="","",IFERROR($B21*$C21+$B21/30*7*$D21,0)) | K21: =IF($A21="","",IFERROR($J21+$E21*($B21*4+$F21),0)) | L21: =IF($A21="","",IF($B21="","EKSİK","TAM"))
A22: OrnekMaliyetDemo | J22: =IF($A22="","",IFERROR($B22*$C22+$B22/30*7*$D22,0)) | K22: =IF($A22="","",IFERROR($J22+$E22*($B22*4+$F22),0)) | L22: =IF($A22="","",IF($B22="","EKSİK","TAM"))
A23: Demo ana | B23: 389333 | J23: =IF($A23="","",IFERROR($B23*$C23+$B23/30*7*$D23,0)) | K23: =IF($A23="","",IFERROR($J23+$E23*($B23*4+$F23),0)) | L23: =IF($A23="","",IF($B23="","EKSİK","TAM"))
A24: Yüksek kıdem | B24: 1125333 | J24: =IF($A24="","",IFERROR($B24*$C24+$B24/30*7*$D24,0)) | K24: =IF($A24="","",IFERROR($J24+$E24*($B24*4+$F24),0)) | L24: =IF($A24="","",IF($B24="","EKSİK","TAM"))
A25: Riskli iade | B25: 314500 | J25: =IF($A25="","",IFERROR($B25*$C25+$B25/30*7*$D25,0)) | K25: =IF($A25="","",IFERROR($J25+$E25*($B25*4+$F25),0)) | L25: =IF($A25="","",IF($B25="","EKSİK","TAM"))
A26: 2025 geçiş | B26: 389333 | J26: =IF($A26="","",IFERROR($B26*$C26+$B26/30*7*$D26,0)) | K26: =IF($A26="","",IFERROR($J26+$E26*($B26*4+$F26),0)) | L26: =IF($A26="","",IF($B26="","EKSİK","TAM"))
J27: =IF($A27="","",IFERROR($B27*$C27+$B27/30*7*$D27,0)) | K27: =IF($A27="","",IFERROR($J27+$E27*($B27*4+$F27),0)) | L27: =IF($A27="","",IF($B27="","EKSİK","TAM"))
J28: =IF($A28="","",IFERROR($B28*$C28+$B28/30*7*$D28,0)) | K28: =IF($A28="","",IFERROR($J28+$E28*($B28*4+$F28),0)) | L28: =IF($A28="","",IF($B28="","EKSİK","TAM"))
J29: =IF($A29="","",IFERROR($B29*$C29+$B29/30*7*$D29,0)) | K29: =IF($A29="","",IFERROR($J29+$E29*($B29*4+$F29),0)) | L29: =IF($A29="","",IF($B29="","EKSİK","TAM"))
J30: =IF($A30="","",IFERROR($B30*$C30+$B30/30*7*$D30,0)) | K30: =IF($A30="","",IFERROR($J30+$E30*($B30*4+$F30),0)) | L30: =IF($A30="","",IF($B30="","EKSİK","TAM"))
J31: =IF($A31="","",IFERROR($B31*$C31+$B31/30*7*$D31,0)) | K31: =IF($A31="","",IFERROR($J31+$E31*($B31*4+$F31),0)) | L31: =IF($A31="","",IF($B31="","EKSİK","TAM"))
J32: =IF($A32="","",IFERROR($B32*$C32+$B32/30*7*$D32,0)) | K32: =IF($A32="","",IFERROR($J32+$E32*($B32*4+$F32),0)) | L32: =IF($A32="","",IF($B32="","EKSİK","TAM"))
J33: =IF($A33="","",IFERROR($B33*$C33+$B33/30*7*$D33,0)) | K33: =IF($A33="","",IFERROR($J33+$E33*($B33*4+$F33),0)) | L33: =IF($A33="","",IF($B33="","EKSİK","TAM"))
J34: =IF($A34="","",IFERROR($B34*$C34+$B34/30*7*$D34,0)) | K34: =IF($A34="","",IFERROR($J34+$E34*($B34*4+$F34),0)) | L34: =IF($A34="","",IF($B34="","EKSİK","TAM"))
J35: =IF($A35="","",IFERROR($B35*$C35+$B35/30*7*$D35,0)) | K35: =IF($A35="","",IFERROR($J35+$E35*($B35*4+$F35),0)) | L35: =IF($A35="","",IF($B35="","EKSİK","TAM"))
J36: =IF($A36="","",IFERROR($B36*$C36+$B36/30*7*$D36,0)) | K36: =IF($A36="","",IFERROR($J36+$E36*($B36*4+$F36),0)) | L36: =IF($A36="","",IF($B36="","EKSİK","TAM"))
J37: =IF($A37="","",IFERROR($B37*$C37+$B37/30*7*$D37,0)) | K37: =IF($A37="","",IFERROR($J37+$E37*($B37*4+$F37),0)) | L37: =IF($A37="","",IF($B37="","EKSİK","TAM"))
J38: =IF($A38="","",IFERROR($B38*$C38+$B38/30*7*$D38,0)) | K38: =IF($A38="","",IFERROR($J38+$E38*($B38*4+$F38),0)) | L38: =IF($A38="","",IF($B38="","EKSİK","TAM"))
... J1004: =IF($A1004="","",IFERROR($B1004*$C1004+$B1004/30*7*$D1004,0)) | K1004: =IF($A1004="","",IFERROR($J1004+$E1004*($B1004*4+$F1004),0)) | L1004: =IF($A1004="","",IF($B1004="","EKSİK","TAM"))

Sheet LISTELER
A1: LISTELER — Fesih Maliyeti Simülatörü
A3: Doğrulama listeleri
A5: Yıl | C5: Yorum | E5: FesihTür | G5: EvetHayır
A6: 2025 | C6: A | E6: Haklı | G6: Evet
A7: 2026 | C7: B | E7: Haksız | G7: Hayır
A8: 2027 | E8: Anlaşmalı

Sheet AYARLAR
A1: AYARLAR — Fesih Maliyeti Simülatörü
A3: Parametreler (tek kaynak)
A5: anahtar | B5: deger | C5: birim | D5: aciklama | E5: kaynak | F5: yururluk_tarihi | G5: dogrulama_tarihi | H5: kontrol
A6: hesapYili | B6: 2026 | C6: yıl | D6: Aktif hesap yılı | E6: Kullanıcı / GIRDI | F6: 01.01.2025 | G6: 11.08.2026 | H6: =IF(A6="","",IF(B6="","EKSİK","TAM"))
A7: raporTarihi | B7: 46245 | C7: tarih | D7: Rapor tarihi (sabit) | E7: Üretim | F7: 01.01.2025 | G7: 11.08.2026 | H7: =IF(A7="","",IF(B7="","EKSİK","TAM"))
A8: fms_tolerans | B8: 1 | C8: TL | D8: Vaka tutarlılık toleransı (TL) | E8: Uygulama notu | F8: 01.01.2025 | G8: 11.08.2026 | H8: =IF(A8="","",IF(B8="","EKSİK","TAM"))
A9: fms_azamiEsik | B9: 100000000000 | C9: TL | D9: Uç değer / azami giriş eşiği | E9: İç politika | F9: 01.01.2025 | G9: 11.08.2026 | H9: =IF(A9="","",IF(B9="","EKSİK","TAM"))
A10: fms_kacirilanEsik | B10: 400000 | C10: TL | D10: PANO doğrudan uyarı eşiği | E10: İç politika | F10: 01.01.2025 | G10: 11.08.2026 | H10: =IF(A10="","",IF(B10="","EKSİK","TAM"))
A11: fms_senaryoIyi | B11: 0.95 | C11: çarpan | D11: İyimser brüt çarpanı (düşük maliyet) | E11: Model varsayımı | F11: 01.01.2025 | G11: 11.08.2026 | H11: =IF(A11="","",IF(B11="","EKSİK","TAM"))
A12: fms_senaryoKotu | B12: 1.1 | C12: çarpan | D12: Kötümser brüt çarpanı | E12: Model varsayımı | F12: 01.01.2025 | G12: 11.08.2026 | H12: =IF(A12="","",IF(B12="","EKSİK","TAM"))
A13: fms_esikArtis | B13: 1 | C13: adet | D13: M-SEN pahalı ay + delta | E13: Senaryo motoru | F13: 01.01.2025 | G13: 11.08.2026 | H13: =IF(A13="","",IF(B13="","EKSİK","TAM"))
A14: fms_esikArtisOran | B14: 0.05 | C14: oran | D14: M-SEN risk olasılık + delta | E14: Senaryo motoru | F14: 01.01.2025 | G14: 11.08.2026 | H14: =IF(A14="","",IF(B14="","EKSİK","TAM"))
A15: fms_tahminAlt | B15: 0.85 | C15: çarpan | D15: Tahmin alt bant | E15: Model varsayımı | F15: 01.01.2025 | G15: 11.08.2026 | H15: =IF(A15="","",IF(B15="","EKSİK","TAM"))
A16: fms_tahminUst | B16: 1.15 | C16: çarpan | D16: Tahmin üst bant | E16: Model varsayımı | F16: 01.01.2025 | G16: 11.08.2026 | H16: =IF(A16="","",IF(B16="","EKSİK","TAM"))
A17: fms_tornadoBrut | B17: 1.05 | C17: çarpan | D17: Tornado brüt şoku | E17: Model varsayımı | F17: 01.01.2025 | G17: 11.08.2026 | H17: =IF(A17="","",IF(B17="","EKSİK","TAM"))
... A22: fms_yuzdelikOran | B22: 0.9 | C22: oran | D22: Yüzdelik P90 | E22: İstatistik | F22: 01.01.2025 | G22: 11.08.2026 | H22: =IF(A22="","",IF(B22="","EKSİK","TAM"))
A23: fms_parmakIzi | B23: 00e8347ef18db5d6 | C23: metin | D23: Dosya parmak izi etiketi | E23: Üretim | F23: 01.01.2025 | G23: 11.08.2026 | H23: =IF(A23="","",IF(B23="","EKSİK","TAM"))
A24: dosya_surumu | B24: 1.0.0 | C24: metin | D24: Ürün sürümü | E24: ExcelArşiv | F24: 01.01.2025 | G24: 11.08.2026 | H24: =IF(A24="","",IF(B24="","EKSİK","TAM"))
A25: fms_girisBeklenen | B25: 10 | C25: adet | D25: Zorunlu giriş alanı sayısı | E25: Ürün mimarisi | F25: 01.01.2025 | G25: 11.08.2026 | H25: =IF(A25="","",IF(B25="","EKSİK","TAM"))
A26: fms_riskDusuk | B26: 15 | C26: puan | D26: FESİH UYGUN risk skoru | E26: İç politika | F26: 01.01.2025 | G26: 11.08.2026 | H26: =IF(A26="","",IF(B26="","EKSİK","TAM"))
A27: fms_riskOrta | B27: 55 | C27: puan | D27: PAHALI risk skoru | E27: İç politika | F27: 01.01.2025 | G27: 11.08.2026 | H27: =IF(A27="","",IF(B27="","EKSİK","TAM"))
A28: fms_riskYuksek | B28: 85 | C28: puan | D28: RİSKLİ risk skoru | E28: İç politika | F28: 01.01.2025 | G28: 11.08.2026 | H28: =IF(A28="","",IF(B28="","EKSİK","TAM"))
A29: fms_riskEsikOran | B29: 0.5 | C29: oran | D29: Yedek risk oranı | E29: İç politika | F29: 01.01.2025 | G29: 11.08.2026 | H29: =IF(A29="","",IF(B29="","EKSİK","TAM"))
A30: fms_yilTaban | B30: 2024 | C30: yıl | D30: CHOOSE yıl tabanı | E30: Ürün mimarisi | F30: 01.01.2025 | G30: 11.08.2026 | H30: =IF(A30="","",IF(B30="","EKSİK","TAM"))
A31: fms_yuvarMax | B31: 10 | C31: adet | D31: ROUND basamak tavanı | E31: Ürün mimarisi | F31: 01.01.2025 | G31: 11.08.2026 | H31: =IF(A31="","",IF(B31="","EKSİK","TAM"))
A32: fms_dayanakCarpan | B32: 10 | C32: adet | D32: Yedek çarpan | E32: Ürün mimarisi | F32: 01.01.2025 | G32: 11.08.2026 | H32: =IF(A32="","",IF(B32="","EKSİK","TAM"))
A33: fms_bazCarpan | B33: 1 | C33: çarpan | D33: Baz senaryo çarpanı | E33: Model varsayımı | F33: 01.01.2025 | G33: 11.08.2026 | H33: =IF(A33="","",IF(B33="","EKSİK","TAM"))
A34: fms_sifirCarpan | B34: 0 | C34: çarpan | D34: Nötr çarpan (sıfır) | E34: Model varsayımı | F34: 01.01.2025 | G34: 11.08.2026 | H34: =IF(A34="","",IF(B34="","EKSİK","TAM"))
A35: fms_siraBir | B35: 1 | C35: adet | D35: Tornado sıra 1 | E35: Ürün mimarisi | F35: 01.01.2025 | G35: 11.08.2026 | H35: =IF(A35="","",IF(B35="","EKSİK","TAM"))
A36: fms_siraIki | B36: 2 | C36: adet | D36: Tornado sıra 2 | E36: Ürün mimarisi | F36: 01.01.2025 | G36: 11.08.2026 | H36: =IF(A36="","",IF(B36="","EKSİK","TAM"))
... A43: vaka_dava_1 | B43: 30000 | C43: TL | D43: Vaka dava masrafı | E43: Altın vaka | F43: 01.01.2025 | G43: 11.08.2026 | H43: =IF(A43="","",IF(B43="","EKSİK","TAM"))
B45: Parametre satırları yukarıda; ad tanımları B kolonuna bağlı.
B47: Sürüm 1.0.0 | Şifre koruması: 1234 (formül alanları)

Sheet KILAVUZ
A1: KILAVUZ — Fesih Maliyeti Simülatörü
A3: Karar kuralları
A5: • VERİ YOK — giriş tablosu boşsa hesap yapılmaz.
A6: • FESİH UYGUN — doğrudan maliyet pahalı eşiğin altında ve işe iade riski düşük.
A7: • PAHALI — kıdem+ihbar doğrudan maliyeti pahalı eşiğin üzerinde.
A8: • RİSKLİ — işe iade olasılığı veya beklenen toplam maliyet risk eşiğinin üzerinde.
A10: Belirsizlik beyanları (M05)
A11: Bu nokta mevzuatta tartışmalıdır; dosya yorum A ve yorum B sonucunu yan yana gösterir: ise_iade_yorumu
A13: Yorum A | B13: Standart hesap: kıdem = brüt × yıl × (katsayı/30); ihbar = brüt/30 × günlük çarpan × hafta. İşe iade beklenen ek = olasılık × (brüt × iade ayı + dava). Haklı fesihte kıdem/ihbar sıfırlanır.
A14: Yorum B | B14: Yorum B, kıdem tutarına tavan çarpanı uygular (daha düşük kıdem → daha düşük doğrudan maliyet). Dosya her iki yorumun sonucunu MOTOR'da üretir.
A16: Kullanım sırası
A17: GIRDI → KURALLAR (gerekirse) → MOTOR (inceleme) → SENARYO → VAKALAR → PANO → KANIT_RAPORU → AYARLAR.
A19: Sürüm 1.0.0 | Lisans: Tek kullanıcı | ExcelArşiv
