Workbook
Name raporTarihi: AYARLAR!$B$6
Name kpg_varsayilanHedefKira: AYARLAR!$B$7
Name kpg_esikDoluluk: AYARLAR!$B$8
Name kpg_esikGetiri: AYARLAR!$B$9
Name kpg_esikSaglik: AYARLAR!$B$10
Name kpg_gunAy: AYARLAR!$B$11
Name kpg_aylikCarpan: AYARLAR!$B$12
Name kpg_senaryoTemkinli: AYARLAR!$B$13
Name kpg_senaryoBaz: AYARLAR!$B$14
Name kpg_senaryoIyimser: AYARLAR!$B$15
Name kpg_tornadoOran: AYARLAR!$B$16
Name kpg_yuzdelikOran: AYARLAR!$B$17
Name kpg_percentileOran: AYARLAR!$B$18
Name kpg_tahminCarpan: AYARLAR!$B$19
Name kpg_olcekHedef: AYARLAR!$B$20
Name kpg_kaliteTaban: AYARLAR!$B$21
Name kpg_kaliteCeza: AYARLAR!$B$22
Name kpg_kaliteSapma: AYARLAR!$B$23
Name kpg_dosyaSurumu: AYARLAR!$B$24
Name kpg_firmaUnvan: AYARLAR!$B$25
Name kpg_alarmEsikMetin: AYARLAR!$B$26
Name kpg_tufeReferans: AYARLAR!$B$27
Name kpg_boslukMaliyetCarpan: AYARLAR!$B$28
Name Ay_1: DONEM_ANALIZ!$B$6
Name Ay_2: DONEM_ANALIZ!$B$7
Name Ay_3: DONEM_ANALIZ!$B$8
Name Ay_4: DONEM_ANALIZ!$B$9
Name Ay_5: DONEM_ANALIZ!$B$10
Name Ay_6: DONEM_ANALIZ!$B$11
Name Ay_7: DONEM_ANALIZ!$B$12
Name Ay_8: DONEM_ANALIZ!$B$13
Name Ay_9: DONEM_ANALIZ!$B$14
Name Ay_10: DONEM_ANALIZ!$B$15
Name Ay_11: DONEM_ANALIZ!$B$16
Name Ay_12: DONEM_ANALIZ!$B$17
Name kpg_doluKayit: AYARLAR!$I$34
Name kpg_toplamTahsilat: AYARLAR!$I$35
Name kpg_toplamGider: AYARLAR!$I$36
Name kpg_ortDoluluk: AYARLAR!$I$37
Name kpg_ortGetiri: AYARLAR!$I$38
Name kpg_netTahsilat: AYARLAR!$I$39
Name kpg_gunlukDolulukOrt: AYARLAR!$I$40
Name kpg_aylikTahsilatTrend: AYARLAR!$I$41
Name kpg_saglikSkor: AYARLAR!$I$42
Name kpg_alarmAdet: AYARLAR!$I$43
Name kpg_yetimAdet: AYARLAR!$I$44
Name kpg_getiriSapma: AYARLAR!$I$45
Name kpg_tornadoZirve: AYARLAR!$I$46
Name kpg_senaryoKarsilastirma: AYARLAR!$I$47
Name kpg_hhi: AYARLAR!$I$48
Name kpg_kaliteSkor: AYARLAR!$I$49
Name kpg_senaryoMotor: AYARLAR!$I$50
Name kpg_tahminAralik: AYARLAR!$I$51
Name kpg_yuzdelikP90: AYARLAR!$I$52
Name kpg_olayKirilim: AYARLAR!$I$53
Name kpg_ortTufeArtis: AYARLAR!$I$54
Name kpg_sezonsalTrend: AYARLAR!$I$55
Name kpg_alarmListesi: AYARLAR!$I$56
Name kpg_kararKapi: AYARLAR!$I$57
Name kpg_kararGerekce: AYARLAR!$I$58

Sheet PANO
B2: KIRA PORTFOYU GETIRI KOMUTASI — YÖNETİM VE KARAR SİSTEMİ | L2: Dönem: 2026 / Tam ▼ | M2: ★ DOĞRULANMIŞ
B3: Yönetici Karar Kokpiti, Otomatik Doğrulama ve Dinamik Hesaplama Sistemi · 2026
B5: TOPLAM İŞLEM HACMİ | D5: DOĞRULANMIŞ | E5: RİSKLİ / BEKLEYEN İŞLEM | G5: MİNİMUM | H5: OPERASYONEL NET MARJ | J5: GÜVENLİ | K5: SİSTEM GÜVEN SKORU | M5: DENETLENDİ
B7: ₺28.450.000 | E7: ₺940.000 | H7: ₺8.120.000 | K7: 98/100
B9: ↑ Konsolide yıllıklandırılmış büyüme | E9: ● Tüm riskli kayıtlar kontrol altında | H9: ██████████░░░░░ %28.5 NET MARJ | K9: ✓ 0 Formül ve Döngüsel Hata
B11: 12 AYLIK NAKİT GİRİŞ / ÇIKIŞ & LİKİDİTE BAŞARIMI | F11: +%32 Verim | H11: KONSOLİDE OPERASYON VE KARAR MATRİSİ
B12: Kümülatif Tahsilat vs. Tedarikçi/Kredi Ödeme Projeksiyonu | H12: Anlık Hesaplama Sonuçları, Dinamik Formül Çıktıları ve Durum Puanlaması
B14: Dönem | C14: Aktif Hacim | D14: Maliyet/Yük | E14: Hedef | H14: PARAMETRE / KALEM | I14: ANA TUTAR | J14: FARK / MARJ | K14: VADE | L14: KONTROL DURUMU
B15: D1 | C15: 65 | D15: 45 | E15: 60 | H15: 13 haftalık kümülatif bakiye... | I15: ₺8.450.000 | J15: ₺425.000 | K15: 12 Ay | L15: ✓ DÜZENLİ
B16: D2 | C16: 78 | D16: 48 | E16: 70 | H16: Kritik (eksi) hafta uyarısı | I16: ₺12.200.000 | J16: ₺580.400 | K16: 24 Ay | L16: ★ AVANTAJ
B17: D3 | C17: 85 | D17: 55 | E17: 80 | H17: Dönem net nakit değişimi | I17: ₺4.850.000 | J17: ₺235.200 | K17: 8 Ay | L17: ● YAKLAŞAN
B18: D4 | C18: 75 | D18: 42 | E18: 75 | H18: 13 haftalık kümülatif bakiye... | I18: ₺2.140.000 | J18: ₺118.000 | K18: 16 Ay | L18: ✓ TAM UYUM
B19: D5 | C19: 90 | D19: 40 | E19: 85 | H19: KONSOLİDE SİSTEM TOPLAMI | I19: ₺42.850.000 | J19: ₺3.420.000 | L19: TAM DOĞRULANDI (0 HATA)
B20: D6 | C20: 96 | D20: 32 | E20: 92
B22: KONSOLİDE PAY VE AĞIRLIK | F22: LİKİDİTE RİSKİ & ERKEN UYARI SİNYALLERİ | K22: KARAR MOTORU
B23: ■ Ana Segment (%42) | F23: Nakit Açığı Riski (30 Gün) | I23: 0.00 TL (Sıfır Risk) | K23: OPERASYONEL VERİMLİLİK FIRSATI
B24: ■ İkincil Grup (%30) | F24: Tahsilat Gecikme Toleransı | I24: 48 Gün Güvenli Eşik | K24: Süreç optimizasyonuyla birim operasyonel maliyeti düşürme potansiyeli mevcuttur.
B25: ■ Destek Birimi (%15) | F25: ██████████████████████████████████████ Güvenli Bölge (%100)
B26: ■ Rezervler (%13) | F26: ✓ 90 GÜNLÜK PROJEKSİYONDA NAKİT SIKIŞIKLIĞI TESPİT EDİLMEDİ | K26: STRATEJİ REÇETESİNİ İNCELE >

Sheet GİRDİLER
B3: 🔍 Kayıt veya hesap ara... | G3: TOPLAM: 1.450 KAYIT | I3: HATALI HÜCRE: 0 ADET
B5: TARİH | C5: REFERANS NO | D5: İŞLEM AÇIKLAMASI VE DETAY | E5: BRÜT TUTAR (₺) | F5: KDV ORANI | G5: NET TUTAR (₺) | H5: HESAP / CARİ | I5: DURUM
B6: 12.10.2026 | C6: TR-0428-A | D6: Haftalık nakit girişi tahmini | E6: 845200 | F6: 0.2 | G6: =E6/(1+F6) | H6: Vadesiz Ticari | I6: ONAYLANDI
B7: 14.10.2026 | C7: TR-0429-B | D7: Haftalık nakit çıkışı tahmini | E7: 1240000 | F7: 0.2 | G7: =E7/(1+F7) | H7: Tedarikçi Havuzu | I7: BEKLEMEDE
B8: 18.10.2026 | C8: TR-0430-C | D8: Ödeme takvimi notları | E8: 620500 | F8: 0.1 | G8: =E8/(1+F8) | H8: Kısa Vade Tahakkuk | I8: ONAYLANDI
B9: 21.10.2026 | C9: TR-0431-D | D9: Haftalık nakit girişi tahmini | E9: 415000 | F9: 0.2 | G9: =E9/(1+F9) | H9: Müşteri Alacağı | I9: ONAYLANDI
B10: 25.10.2026 | C10: TR-0432-E | D10: Haftalık nakit girişi tahmini | E10: 980400 | F10: 0.2 | G10: =E10/(1+F10) | H10: Vadesiz Ticari | I10: ONAYLANDI
B11: 28.10.2026 | C11: TR-0433-F | D11: Haftalık nakit çıkışı tahmini | E11: 1850000 | F11: 0.2 | G11: =E11/(1+F11) | H11: Banka Kredi Taksiti | I11: BLOKE
B12: 02.11.2026 | C12: TR-0434-G | D12: Ödeme takvimi notları | E12: 740000 | F12: 0.2 | G12: =E12/(1+F12) | H12: Kira & Sabit Gider | I12: ONAYLANDI
B13: 05.11.2026 | C13: TR-0435-H | D13: Haftalık nakit girişi tahmini | E13: 520800 | F13: 0.2 | G13: =E13/(1+F13) | H13: Vadesiz Ticari | I13: ONAYLANDI
B14: 09.11.2026 | C14: TR-0436-I | D14: Haftalık nakit girişi tahmini | E14: 1120000 | F14: 0.2 | G14: =E14/(1+F14) | H14: Müşteri Alacağı | I14: ONAYLANDI
B15: 12.11.2026 | C15: TR-0437-J | D15: Haftalık nakit çıkışı tahmini | E15: 890000 | F15: 0.2 | G15: =E15/(1+F15) | H15: Tedarikçi Havuzu | I15: ONAYLANDI
B17: SAYFA TOPLAMI (10 / 1.450 KAYIT) | E17: =TOPLA(E6:E15)

Sheet YÖNETİM_RAPORU
B2: KIRA PORTFOYU GETIRI KOMUTASI — YÖNETİM VE KARAR SİSTEMİ — NİHAİ KARAR VE DEĞERLEME
B3: Yönetim Kurulu ve İcra Komitesi için Otomatik Türetilen Finansal Stres Testi Raporu
B4: DÖNEM: 2026 Q3 · DENETİM PROTOKOLÜ: ISO/VUK/IFRS UYUMLU · DURUM: ONAYLANDI
B6: SENARYO A: KÖTÜMSER (STRES TESTİ -%20) | H6: SENARYO B: BAZ MODEL (HEDEFLENEN)
B8: Ciro / Hacim Düşüşü: | E8: -%20.0 (Kriz Eşiği) | H8: Ciro / Hacim Gerçekleşmesi: | K8: %100.0 (Tam Bütçe)
B9: Beklenen Net Kâr / Getiri: | E9: ₺4.280.000 | H9: Beklenen Net Kâr / Getiri: | K9: ₺12.450.000
B10: Minimum Nakit Tamponu: | E10: ₺1.850.000 (Yeterli) | H10: Serbest Nakit Akımı: | K10: ₺8.240.000
B11: Likidite Karşılama Oranı: | E11: 1.28x (Eşik: 1.10x) | H11: Yatırım Geri Dönüşü (ROI): | K11: %38.4 Yıllık
B14: STRES SENARYOSUNDA DAHİ İFLAS RİSKİ YOK | H14: OPTİMUM İCRA VE PLANLAMA REÇETESİ
B17: YÖNETİM KARAR MATRİSİ VE UYGULAMA REÇETESİ
B19: ● Öncelik 1: Acil Likidite ve Borç Servis Planlaması
B20: Sistemde hesaplanan vade günlerine sadık kalınarak nakit blokajı 3 gün önceden hazır edilmelidir.
B21: ● Öncelik 2: Formül Doğrulama ve Çapraz Sağlama
B22: Tüm hücreler kilitli formül korumasında olup girdi sayfalarında sıfır döngüsel başvuru (circular ref) garantilidir.
B23: ● Öncelik 3: Resmi Mevzuat ve Vergi Kalkanı Entegrasyonu
B24: 2026 güncel vergi dilimleri, amortisman ve SGK teşvik parametreleri tam otomatik yansıtılmaktadır.
B25: ● Öncelik 4: Yönetici İmzası ve Rapor Paylaşımı
B26: Tek tuşla PDF ve A4 çıktı formatına tam uyumlu sayfa yapısı kurgulanmıştır.

Sheet KAPAK
A1: KAPAK — Kira Portföyü Getiri Komutası
A3: Kira Portföyü Getiri Komutası
A4: Çoklu kira menkulünde doluluk, tahsilat, net getiri ve TÜFE artış takvimini izler; günlük saha girişi ≤6 alan; varlık sağlık skoru ve alarm kuyruğu üretir; UYGUN / DİKKAT / KRİTİK / VERİ YOK kararı verir.
A6: Bu ürün ne sağlar?
A7: • Menkul bazlı doluluk % ve net kira getirisi
A8: • Günlük saha girişi en fazla 6 alan — 30 saniye hedefi
A9: • TÜFE oranıyla önerilen kira artışı (dış API yok)
A10: • Varlık sağlık skoru formülle veriden türer (sabit skor yok)
A11: • 12 aylık sezonsal tahsilat-doluluk zinciri ve alarm eşiği kuyruğu
A13: Kimler için?
A14: • Saha / emlak operatörü — günlük tahsilat-boşluk-gider satırı
A15: • Portföy sahibi — doluluk % ve karar panosu
... A21: Sürüm 1.0.0 | Kod: KPG-PRO | Lisans: Tek kullanıcı | ExcelArşiv

Sheet VARLIKLAR
A1: VARLIKLAR — Kira Portföyü Getiri Komutası
A3: Kira menkul kartları — her varlığın tek kimliği vardır
A4: Sonraki Kimlik | B4: =kpg_sonrakiKimlik
A5: VarlikId | B5: MulkAd | C5: Tip | D5: Sehir | E5: Metrekare_m2 | F5: DegerTl_tl | G5: HedefKiraTl_tl | H5: Aktif | I5: ToplamTahsilatTl | J5: OrtDoluluk | K5: ToplamGiderTl | L5: SaglikSkor
A6: KIR-00001 | B6: Kadikoy Daire A | C6: Daire | D6: Istanbul | E6: 95 | F6: 4500000 | G6: 28000 | H6: EVET | I6: =IF($A6="","",SUMIF(tblGunluk[VarlikId],$A6,tblGunluk[TahsilatTl_tl])) | J6: =IF($A6="","",IFERROR(AVERAGEIF(tblGunluk[VarlikId],$A6,tblGunluk[FormulDoluluk_oran]),0)) | K6: =IF($A6="","",SUMIF(tblGunluk[VarlikId],$A6,tblGunluk[GiderTl_tl])) | L6: =IF($A6="","",MAX(0,MIN(100,kpg_kaliteTaban-IF($J6<kpg_esikDoluluk,kpg_kaliteCeza,0)-COUNTIFS(tblGunluk[VarlikId],$A6,tblGunluk[AlarmBayrak],"ALARM")*kpg_kaliteSapma-IF($H6="HAYIR",kpg_kaliteCeza,0))))
A7: KIR-00002 | B7: Cankaya Ofis B | C7: Ofis | D7: Ankara | E7: 120 | F7: 3200000 | G7: 22000 | H7: EVET | I7: =IF($A7="","",SUMIF(tblGunluk[VarlikId],$A7,tblGunluk[TahsilatTl_tl])) | J7: =IF($A7="","",IFERROR(AVERAGEIF(tblGunluk[VarlikId],$A7,tblGunluk[FormulDoluluk_oran]),0)) | K7: =IF($A7="","",SUMIF(tblGunluk[VarlikId],$A7,tblGunluk[GiderTl_tl])) | L7: =IF($A7="","",MAX(0,MIN(100,kpg_kaliteTaban-IF($J7<kpg_esikDoluluk,kpg_kaliteCeza,0)-COUNTIFS(tblGunluk[VarlikId],$A7,tblGunluk[AlarmBayrak],"ALARM")*kpg_kaliteSapma-IF($H7="HAYIR",kpg_kaliteCeza,0))))
A8: KIR-00003 | B8: Konak Dukkan C | C8: Dukkan | D8: Izmir | E8: 80 | F8: 2800000 | G8: 18000 | H8: EVET | I8: =IF($A8="","",SUMIF(tblGunluk[VarlikId],$A8,tblGunluk[TahsilatTl_tl])) | J8: =IF($A8="","",IFERROR(AVERAGEIF(tblGunluk[VarlikId],$A8,tblGunluk[FormulDoluluk_oran]),0)) | K8: =IF($A8="","",SUMIF(tblGunluk[VarlikId],$A8,tblGunluk[GiderTl_tl])) | L8: =IF($A8="","",MAX(0,MIN(100,kpg_kaliteTaban-IF($J8<kpg_esikDoluluk,kpg_kaliteCeza,0)-COUNTIFS(tblGunluk[VarlikId],$A8,tblGunluk[AlarmBayrak],"ALARM")*kpg_kaliteSapma-IF($H8="HAYIR",kpg_kaliteCeza,0))))
A9: KIR-00004 | B9: Nilufer Daire D | C9: Daire | D9: Bursa | E9: 110 | F9: 2100000 | G9: 14000 | H9: EVET | I9: =IF($A9="","",SUMIF(tblGunluk[VarlikId],$A9,tblGunluk[TahsilatTl_tl])) | J9: =IF($A9="","",IFERROR(AVERAGEIF(tblGunluk[VarlikId],$A9,tblGunluk[FormulDoluluk_oran]),0)) | K9: =IF($A9="","",SUMIF(tblGunluk[VarlikId],$A9,tblGunluk[GiderTl_tl])) | L9: =IF($A9="","",MAX(0,MIN(100,kpg_kaliteTaban-IF($J9<kpg_esikDoluluk,kpg_kaliteCeza,0)-COUNTIFS(tblGunluk[VarlikId],$A9,tblGunluk[AlarmBayrak],"ALARM")*kpg_kaliteSapma-IF($H9="HAYIR",kpg_kaliteCeza,0))))
A10: KIR-00005 | B10: Muratpasa Ofis E | C10: Ofis | D10: Antalya | E10: 140 | F10: 3800000 | G10: 26000 | H10: EVET | I10: =IF($A10="","",SUMIF(tblGunluk[VarlikId],$A10,tblGunluk[TahsilatTl_tl])) | J10: =IF($A10="","",IFERROR(AVERAGEIF(tblGunluk[VarlikId],$A10,tblGunluk[FormulDoluluk_oran]),0)) | K10: =IF($A10="","",SUMIF(tblGunluk[VarlikId],$A10,tblGunluk[GiderTl_tl])) | L10: =IF($A10="","",MAX(0,MIN(100,kpg_kaliteTaban-IF($J10<kpg_esikDoluluk,kpg_kaliteCeza,0)-COUNTIFS(tblGunluk[VarlikId],$A10,tblGunluk[AlarmBayrak],"ALARM")*kpg_kaliteSapma-IF($H10="HAYIR",kpg_kaliteCeza,0))))
A11: KIR-00006 | B11: Sahinbey Depo F | C11: Depo | D11: Gaziantep | E11: 250 | F11: 1500000 | G11: 12000 | H11: EVET | I11: =IF($A11="","",SUMIF(tblGunluk[VarlikId],$A11,tblGunluk[TahsilatTl_tl])) | J11: =IF($A11="","",IFERROR(AVERAGEIF(tblGunluk[VarlikId],$A11,tblGunluk[FormulDoluluk_oran]),0)) | K11: =IF($A11="","",SUMIF(tblGunluk[VarlikId],$A11,tblGunluk[GiderTl_tl])) | L11: =IF($A11="","",MAX(0,MIN(100,kpg_kaliteTaban-IF($J11<kpg_esikDoluluk,kpg_kaliteCeza,0)-COUNTIFS(tblGunluk[VarlikId],$A11,tblGunluk[AlarmBayrak],"ALARM")*kpg_kaliteSapma-IF($H11="HAYIR",kpg_kaliteCeza,0))))
A12: KIR-00007 | B12: Yenisehir Daire G | C12: Daire | D12: Mersin | E12: 85 | F12: 1600000 | G12: 11000 | H12: EVET | I12: =IF($A12="","",SUMIF(tblGunluk[VarlikId],$A12,tblGunluk[TahsilatTl_tl])) | J12: =IF($A12="","",IFERROR(AVERAGEIF(tblGunluk[VarlikId],$A12,tblGunluk[FormulDoluluk_oran]),0)) | K12: =IF($A12="","",SUMIF(tblGunluk[VarlikId],$A12,tblGunluk[GiderTl_tl])) | L12: =IF($A12="","",MAX(0,MIN(100,kpg_kaliteTaban-IF($J12<kpg_esikDoluluk,kpg_kaliteCeza,0)-COUNTIFS(tblGunluk[VarlikId],$A12,tblGunluk[AlarmBayrak],"ALARM")*kpg_kaliteSapma-IF($H12="HAYIR",kpg_kaliteCeza,0))))
A13: KIR-00008 | B13: Tepebasi Dukkan H | C13: Dukkan | D13: Eskisehir | E13: 70 | F13: 1400000 | G13: 9500 | H13: EVET | I13: =IF($A13="","",SUMIF(tblGunluk[VarlikId],$A13,tblGunluk[TahsilatTl_tl])) | J13: =IF($A13="","",IFERROR(AVERAGEIF(tblGunluk[VarlikId],$A13,tblGunluk[FormulDoluluk_oran]),0)) | K13: =IF($A13="","",SUMIF(tblGunluk[VarlikId],$A13,tblGunluk[GiderTl_tl])) | L13: =IF($A13="","",MAX(0,MIN(100,kpg_kaliteTaban-IF($J13<kpg_esikDoluluk,kpg_kaliteCeza,0)-COUNTIFS(tblGunluk[VarlikId],$A13,tblGunluk[AlarmBayrak],"ALARM")*kpg_kaliteSapma-IF($H13="HAYIR",kpg_kaliteCeza,0))))
I14: =IF($A14="","",SUMIF(tblGunluk[VarlikId],$A14,tblGunluk[TahsilatTl_tl])) | J14: =IF($A14="","",IFERROR(AVERAGEIF(tblGunluk[VarlikId],$A14,tblGunluk[FormulDoluluk_oran]),0)) | K14: =IF($A14="","",SUMIF(tblGunluk[VarlikId],$A14,tblGunluk[GiderTl_tl])) | L14: =IF($A14="","",MAX(0,MIN(100,kpg_kaliteTaban-IF($J14<kpg_esikDoluluk,kpg_kaliteCeza,0)-COUNTIFS(tblGunluk[VarlikId],$A14,tblGunluk[AlarmBayrak],"ALARM")*kpg_kaliteSapma-IF($H14="HAYIR",kpg_kaliteCeza,0))))
I15: =IF($A15="","",SUMIF(tblGunluk[VarlikId],$A15,tblGunluk[TahsilatTl_tl])) | J15: =IF($A15="","",IFERROR(AVERAGEIF(tblGunluk[VarlikId],$A15,tblGunluk[FormulDoluluk_oran]),0)) | K15: =IF($A15="","",SUMIF(tblGunluk[VarlikId],$A15,tblGunluk[GiderTl_tl])) | L15: =IF($A15="","",MAX(0,MIN(100,kpg_kaliteTaban-IF($J15<kpg_esikDoluluk,kpg_kaliteCeza,0)-COUNTIFS(tblGunluk[VarlikId],$A15,tblGunluk[AlarmBayrak],"ALARM")*kpg_kaliteSapma-IF($H15="HAYIR",kpg_kaliteCeza,0))))
I16: =IF($A16="","",SUMIF(tblGunluk[VarlikId],$A16,tblGunluk[TahsilatTl_tl])) | J16: =IF($A16="","",IFERROR(AVERAGEIF(tblGunluk[VarlikId],$A16,tblGunluk[FormulDoluluk_oran]),0)) | K16: =IF($A16="","",SUMIF(tblGunluk[VarlikId],$A16,tblGunluk[GiderTl_tl])) | L16: =IF($A16="","",MAX(0,MIN(100,kpg_kaliteTaban-IF($J16<kpg_esikDoluluk,kpg_kaliteCeza,0)-COUNTIFS(tblGunluk[VarlikId],$A16,tblGunluk[AlarmBayrak],"ALARM")*kpg_kaliteSapma-IF($H16="HAYIR",kpg_kaliteCeza,0))))
I17: =IF($A17="","",SUMIF(tblGunluk[VarlikId],$A17,tblGunluk[TahsilatTl_tl])) | J17: =IF($A17="","",IFERROR(AVERAGEIF(tblGunluk[VarlikId],$A17,tblGunluk[FormulDoluluk_oran]),0)) | K17: =IF($A17="","",SUMIF(tblGunluk[VarlikId],$A17,tblGunluk[GiderTl_tl])) | L17: =IF($A17="","",MAX(0,MIN(100,kpg_kaliteTaban-IF($J17<kpg_esikDoluluk,kpg_kaliteCeza,0)-COUNTIFS(tblGunluk[VarlikId],$A17,tblGunluk[AlarmBayrak],"ALARM")*kpg_kaliteSapma-IF($H17="HAYIR",kpg_kaliteCeza,0))))
I18: =IF($A18="","",SUMIF(tblGunluk[VarlikId],$A18,tblGunluk[TahsilatTl_tl])) | J18: =IF($A18="","",IFERROR(AVERAGEIF(tblGunluk[VarlikId],$A18,tblGunluk[FormulDoluluk_oran]),0)) | K18: =IF($A18="","",SUMIF(tblGunluk[VarlikId],$A18,tblGunluk[GiderTl_tl])) | L18: =IF($A18="","",MAX(0,MIN(100,kpg_kaliteTaban-IF($J18<kpg_esikDoluluk,kpg_kaliteCeza,0)-COUNTIFS(tblGunluk[VarlikId],$A18,tblGunluk[AlarmBayrak],"ALARM")*kpg_kaliteSapma-IF($H18="HAYIR",kpg_kaliteCeza,0))))
I19: =IF($A19="","",SUMIF(tblGunluk[VarlikId],$A19,tblGunluk[TahsilatTl_tl])) | J19: =IF($A19="","",IFERROR(AVERAGEIF(tblGunluk[VarlikId],$A19,tblGunluk[FormulDoluluk_oran]),0)) | K19: =IF($A19="","",SUMIF(tblGunluk[VarlikId],$A19,tblGunluk[GiderTl_tl])) | L19: =IF($A19="","",MAX(0,MIN(100,kpg_kaliteTaban-IF($J19<kpg_esikDoluluk,kpg_kaliteCeza,0)-COUNTIFS(tblGunluk[VarlikId],$A19,tblGunluk[AlarmBayrak],"ALARM")*kpg_kaliteSapma-IF($H19="HAYIR",kpg_kaliteCeza,0))))
I20: =IF($A20="","",SUMIF(tblGunluk[VarlikId],$A20,tblGunluk[TahsilatTl_tl])) | J20: =IF($A20="","",IFERROR(AVERAGEIF(tblGunluk[VarlikId],$A20,tblGunluk[FormulDoluluk_oran]),0)) | K20: =IF($A20="","",SUMIF(tblGunluk[VarlikId],$A20,tblGunluk[GiderTl_tl])) | L20: =IF($A20="","",MAX(0,MIN(100,kpg_kaliteTaban-IF($J20<kpg_esikDoluluk,kpg_kaliteCeza,0)-COUNTIFS(tblGunluk[VarlikId],$A20,tblGunluk[AlarmBayrak],"ALARM")*kpg_kaliteSapma-IF($H20="HAYIR",kpg_kaliteCeza,0))))
I21: =IF($A21="","",SUMIF(tblGunluk[VarlikId],$A21,tblGunluk[TahsilatTl_tl])) | J21: =IF($A21="","",IFERROR(AVERAGEIF(tblGunluk[VarlikId],$A21,tblGunluk[FormulDoluluk_oran]),0)) | K21: =IF($A21="","",SUMIF(tblGunluk[VarlikId],$A21,tblGunluk[GiderTl_tl])) | L21: =IF($A21="","",MAX(0,MIN(100,kpg_kaliteTaban-IF($J21<kpg_esikDoluluk,kpg_kaliteCeza,0)-COUNTIFS(tblGunluk[VarlikId],$A21,tblGunluk[AlarmBayrak],"ALARM")*kpg_kaliteSapma-IF($H21="HAYIR",kpg_kaliteCeza,0))))
I22: =IF($A22="","",SUMIF(tblGunluk[VarlikId],$A22,tblGunluk[TahsilatTl_tl])) | J22: =IF($A22="","",IFERROR(AVERAGEIF(tblGunluk[VarlikId],$A22,tblGunluk[FormulDoluluk_oran]),0)) | K22: =IF($A22="","",SUMIF(tblGunluk[VarlikId],$A22,tblGunluk[GiderTl_tl])) | L22: =IF($A22="","",MAX(0,MIN(100,kpg_kaliteTaban-IF($J22<kpg_esikDoluluk,kpg_kaliteCeza,0)-COUNTIFS(tblGunluk[VarlikId],$A22,tblGunluk[AlarmBayrak],"ALARM")*kpg_kaliteSapma-IF($H22="HAYIR",kpg_kaliteCeza,0))))
I23: =IF($A23="","",SUMIF(tblGunluk[VarlikId],$A23,tblGunluk[TahsilatTl_tl])) | J23: =IF($A23="","",IFERROR(AVERAGEIF(tblGunluk[VarlikId],$A23,tblGunluk[FormulDoluluk_oran]),0)) | K23: =IF($A23="","",SUMIF(tblGunluk[VarlikId],$A23,tblGunluk[GiderTl_tl])) | L23: =IF($A23="","",MAX(0,MIN(100,kpg_kaliteTaban-IF($J23<kpg_esikDoluluk,kpg_kaliteCeza,0)-COUNTIFS(tblGunluk[VarlikId],$A23,tblGunluk[AlarmBayrak],"ALARM")*kpg_kaliteSapma-IF($H23="HAYIR",kpg_kaliteCeza,0))))
I24: =IF($A24="","",SUMIF(tblGunluk[VarlikId],$A24,tblGunluk[TahsilatTl_tl])) | J24: =IF($A24="","",IFERROR(AVERAGEIF(tblGunluk[VarlikId],$A24,tblGunluk[FormulDoluluk_oran]),0)) | K24: =IF($A24="","",SUMIF(tblGunluk[VarlikId],$A24,tblGunluk[GiderTl_tl])) | L24: =IF($A24="","",MAX(0,MIN(100,kpg_kaliteTaban-IF($J24<kpg_esikDoluluk,kpg_kaliteCeza,0)-COUNTIFS(tblGunluk[VarlikId],$A24,tblGunluk[AlarmBayrak],"ALARM")*kpg_kaliteSapma-IF($H24="HAYIR",kpg_kaliteCeza,0))))
I25: =IF($A25="","",SUMIF(tblGunluk[VarlikId],$A25,tblGunluk[TahsilatTl_tl])) | J25: =IF($A25="","",IFERROR(AVERAGEIF(tblGunluk[VarlikId],$A25,tblGunluk[FormulDoluluk_oran]),0)) | K25: =IF($A25="","",SUMIF(tblGunluk[VarlikId],$A25,tblGunluk[GiderTl_tl])) | L25: =IF($A25="","",MAX(0,MIN(100,kpg_kaliteTaban-IF($J25<kpg_esikDoluluk,kpg_kaliteCeza,0)-COUNTIFS(tblGunluk[VarlikId],$A25,tblGunluk[AlarmBayrak],"ALARM")*kpg_kaliteSapma-IF($H25="HAYIR",kpg_kaliteCeza,0))))
... I255: =IF($A255="","",SUMIF(tblGunluk[VarlikId],$A255,tblGunluk[TahsilatTl_tl])) | J255: =IF($A255="","",IFERROR(AVERAGEIF(tblGunluk[VarlikId],$A255,tblGunluk[FormulDoluluk_oran]),0)) | K255: =IF($A255="","",SUMIF(tblGunluk[VarlikId],$A255,tblGunluk[GiderTl_tl])) | L255: =IF($A255="","",MAX(0,MIN(100,kpg_kaliteTaban-IF($J255<kpg_esikDoluluk,kpg_kaliteCeza,0)-COUNTIFS(tblGunluk[VarlikId],$A255,tblGunluk[AlarmBayrak],"ALARM")*kpg_kaliteSapma-IF($H255="HAYIR",kpg_kaliteCeza,0))))

Sheet GUNLUK_GIRIS
A1: GUNLUK GIRIS — Kira Portföyü Getiri Komutası
A3: GÜNLÜK saha girişi — satır başına en fazla 6 manuel alan (S02)
A5: SatirId | B5: VarlikId | C5: Tarih | D5: TahsilatTl_tl | E5: BosGun_gun | F5: GiderTl_tl | G5: TufeOran_oran | H5: OlayTuru | I5: FormulHedefKira_tl | J5: FormulDoluluk_oran | K5: FormulGetiri_oran | L5: FormulNet_tl | M5: FormulTufeArtis_tl | N5: SaglikSkor_puan | O5: AlarmBayrak | P5: FormulKayitDolu | Q5: FormulYetim
A6: KPG-00001 | B6: KIR-00001 | C6: 46242 | D6: 24640 | E6: 0 | F6: 1270 | G6: 0.39 | H6: BOSLUK | I6: =IF($A6="","",IFERROR(SUMIF(tblVarliklar[VarlikId],$B6,tblVarliklar[HedefKiraTl_tl]),kpg_varsayilanHedefKira)) | J6: =IF($A6="","",MAX(0, 1-$E6/kpg_gunAy)) | K6: =IF(OR($A6="",$I6=0),"",$D6/$I6) | L6: =IF($A6="","",$D6-$F6) | M6: =IF($A6="","",$I6*(1+$G6)) | N6: =IF($A6="","",MAX(0,MIN(100,kpg_kaliteTaban-IF($J6<kpg_esikDoluluk,kpg_kaliteCeza,0)-IF($K6<kpg_esikGetiri,kpg_kaliteSapma,0)-IF($Q6="YETIM",kpg_kaliteCeza,0)))) | O6: =IF($A6="","",IF(OR($J6<kpg_esikDoluluk,$K6<kpg_esikGetiri,$N6<kpg_esikSaglik),"ALARM","UYGUN")) | P6: =IF($A6="","",1) | Q6: =IF($A6="","",IF(OR($B6="",COUNTIF(tblVarliklar[VarlikId],$B6)=0),"YETIM","TAMAM"))
A7: KPG-00002 | B7: KIR-00002 | C7: 46239 | D7: 20020 | E7: 0 | F7: 1740 | G7: 0.4 | H7: ARTIS_TUFE | I7: =IF($A7="","",IFERROR(SUMIF(tblVarliklar[VarlikId],$B7,tblVarliklar[HedefKiraTl_tl]),kpg_varsayilanHedefKira)) | J7: =IF($A7="","",MAX(0, 1-$E7/kpg_gunAy)) | K7: =IF(OR($A7="",$I7=0),"",$D7/$I7) | L7: =IF($A7="","",$D7-$F7) | M7: =IF($A7="","",$I7*(1+$G7)) | N7: =IF($A7="","",MAX(0,MIN(100,kpg_kaliteTaban-IF($J7<kpg_esikDoluluk,kpg_kaliteCeza,0)-IF($K7<kpg_esikGetiri,kpg_kaliteSapma,0)-IF($Q7="YETIM",kpg_kaliteCeza,0)))) | O7: =IF($A7="","",IF(OR($J7<kpg_esikDoluluk,$K7<kpg_esikGetiri,$N7<kpg_esikSaglik),"ALARM","UYGUN")) | P7: =IF($A7="","",1) | Q7: =IF($A7="","",IF(OR($B7="",COUNTIF(tblVarliklar[VarlikId],$B7)=0),"YETIM","TAMAM"))
A8: KPG-00003 | B8: KIR-00003 | C8: 46236 | D8: 15792 | E8: 2 | F8: 2210 | G8: 0.38 | H8: GIDER | I8: =IF($A8="","",IFERROR(SUMIF(tblVarliklar[VarlikId],$B8,tblVarliklar[HedefKiraTl_tl]),kpg_varsayilanHedefKira)) | J8: =IF($A8="","",MAX(0, 1-$E8/kpg_gunAy)) | K8: =IF(OR($A8="",$I8=0),"",$D8/$I8) | L8: =IF($A8="","",$D8-$F8) | M8: =IF($A8="","",$I8*(1+$G8)) | N8: =IF($A8="","",MAX(0,MIN(100,kpg_kaliteTaban-IF($J8<kpg_esikDoluluk,kpg_kaliteCeza,0)-IF($K8<kpg_esikGetiri,kpg_kaliteSapma,0)-IF($Q8="YETIM",kpg_kaliteCeza,0)))) | O8: =IF($A8="","",IF(OR($J8<kpg_esikDoluluk,$K8<kpg_esikGetiri,$N8<kpg_esikSaglik),"ALARM","UYGUN")) | P8: =IF($A8="","",1) | Q8: =IF($A8="","",IF(OR($B8="",COUNTIF(tblVarliklar[VarlikId],$B8)=0),"YETIM","TAMAM"))
A9: KPG-00004 | B9: KIR-00004 | C9: 46233 | D9: 13580 | E9: 0 | F9: 2200 | G9: 0.39 | H9: TAHSILAT_GECIKME | I9: =IF($A9="","",IFERROR(SUMIF(tblVarliklar[VarlikId],$B9,tblVarliklar[HedefKiraTl_tl]),kpg_varsayilanHedefKira)) | J9: =IF($A9="","",MAX(0, 1-$E9/kpg_gunAy)) | K9: =IF(OR($A9="",$I9=0),"",$D9/$I9) | L9: =IF($A9="","",$D9-$F9) | M9: =IF($A9="","",$I9*(1+$G9)) | N9: =IF($A9="","",MAX(0,MIN(100,kpg_kaliteTaban-IF($J9<kpg_esikDoluluk,kpg_kaliteCeza,0)-IF($K9<kpg_esikGetiri,kpg_kaliteSapma,0)-IF($Q9="YETIM",kpg_kaliteCeza,0)))) | O9: =IF($A9="","",IF(OR($J9<kpg_esikDoluluk,$K9<kpg_esikGetiri,$N9<kpg_esikSaglik),"ALARM","UYGUN")) | P9: =IF($A9="","",1) | Q9: =IF($A9="","",IF(OR($B9="",COUNTIF(tblVarliklar[VarlikId],$B9)=0),"YETIM","TAMAM"))
A10: KPG-00005 | B10: KIR-00005 | C10: 46230 | D10: 18417 | E10: 5 | F10: 2670 | G10: 0.4 | H10: DIGER | I10: =IF($A10="","",IFERROR(SUMIF(tblVarliklar[VarlikId],$B10,tblVarliklar[HedefKiraTl_tl]),kpg_varsayilanHedefKira)) | J10: =IF($A10="","",MAX(0, 1-$E10/kpg_gunAy)) | K10: =IF(OR($A10="",$I10=0),"",$D10/$I10) | L10: =IF($A10="","",$D10-$F10) | M10: =IF($A10="","",$I10*(1+$G10)) | N10: =IF($A10="","",MAX(0,MIN(100,kpg_kaliteTaban-IF($J10<kpg_esikDoluluk,kpg_kaliteCeza,0)-IF($K10<kpg_esikGetiri,kpg_kaliteSapma,0)-IF($Q10="YETIM",kpg_kaliteCeza,0)))) | O10: =IF($A10="","",IF(OR($J10<kpg_esikDoluluk,$K10<kpg_esikGetiri,$N10<kpg_esikSaglik),"ALARM","UYGUN")) | P10: =IF($A10="","",1) | Q10: =IF($A10="","",IF(OR($B10="",COUNTIF(tblVarliklar[VarlikId],$B10)=0),"YETIM","TAMAM"))
A11: KPG-00006 | B11: KIR-00006 | C11: 46227 | D11: 9856 | E11: 2 | F11: 1040 | G11: 0.38 | H11: TAHSILAT | I11: =IF($A11="","",IFERROR(SUMIF(tblVarliklar[VarlikId],$B11,tblVarliklar[HedefKiraTl_tl]),kpg_varsayilanHedefKira)) | J11: =IF($A11="","",MAX(0, 1-$E11/kpg_gunAy)) | K11: =IF(OR($A11="",$I11=0),"",$D11/$I11) | L11: =IF($A11="","",$D11-$F11) | M11: =IF($A11="","",$I11*(1+$G11)) | N11: =IF($A11="","",MAX(0,MIN(100,kpg_kaliteTaban-IF($J11<kpg_esikDoluluk,kpg_kaliteCeza,0)-IF($K11<kpg_esikGetiri,kpg_kaliteSapma,0)-IF($Q11="YETIM",kpg_kaliteCeza,0)))) | O11: =IF($A11="","",IF(OR($J11<kpg_esikDoluluk,$K11<kpg_esikGetiri,$N11<kpg_esikSaglik),"ALARM","UYGUN")) | P11: =IF($A11="","",1) | Q11: =IF($A11="","",IF(OR($B11="",COUNTIF(tblVarliklar[VarlikId],$B11)=0),"YETIM","TAMAM"))
A12: KPG-00007 | B12: KIR-00007 | C12: 46224 | D12: 10010 | E12: 0 | F12: 1510 | G12: 0.39 | H12: BOSLUK | I12: =IF($A12="","",IFERROR(SUMIF(tblVarliklar[VarlikId],$B12,tblVarliklar[HedefKiraTl_tl]),kpg_varsayilanHedefKira)) | J12: =IF($A12="","",MAX(0, 1-$E12/kpg_gunAy)) | K12: =IF(OR($A12="",$I12=0),"",$D12/$I12) | L12: =IF($A12="","",$D12-$F12) | M12: =IF($A12="","",$I12*(1+$G12)) | N12: =IF($A12="","",MAX(0,MIN(100,kpg_kaliteTaban-IF($J12<kpg_esikDoluluk,kpg_kaliteCeza,0)-IF($K12<kpg_esikGetiri,kpg_kaliteSapma,0)-IF($Q12="YETIM",kpg_kaliteCeza,0)))) | O12: =IF($A12="","",IF(OR($J12<kpg_esikDoluluk,$K12<kpg_esikGetiri,$N12<kpg_esikSaglik),"ALARM","UYGUN")) | P12: =IF($A12="","",1) | Q12: =IF($A12="","",IF(OR($B12="",COUNTIF(tblVarliklar[VarlikId],$B12)=0),"YETIM","TAMAM"))
A13: KPG-00008 | B13: KIR-00008 | C13: 46221 | D13: 8930 | E13: 0 | F13: 1500 | G13: 0.4 | H13: ARTIS_TUFE | I13: =IF($A13="","",IFERROR(SUMIF(tblVarliklar[VarlikId],$B13,tblVarliklar[HedefKiraTl_tl]),kpg_varsayilanHedefKira)) | J13: =IF($A13="","",MAX(0, 1-$E13/kpg_gunAy)) | K13: =IF(OR($A13="",$I13=0),"",$D13/$I13) | L13: =IF($A13="","",$D13-$F13) | M13: =IF($A13="","",$I13*(1+$G13)) | N13: =IF($A13="","",MAX(0,MIN(100,kpg_kaliteTaban-IF($J13<kpg_esikDoluluk,kpg_kaliteCeza,0)-IF($K13<kpg_esikGetiri,kpg_kaliteSapma,0)-IF($Q13="YETIM",kpg_kaliteCeza,0)))) | O13: =IF($A13="","",IF(OR($J13<kpg_esikDoluluk,$K13<kpg_esikGetiri,$N13<kpg_esikSaglik),"ALARM","UYGUN")) | P13: =IF($A13="","",1) | Q13: =IF($A13="","",IF(OR($B13="",COUNTIF(tblVarliklar[VarlikId],$B13)=0),"YETIM","TAMAM"))
A14: KPG-00009 | B14: KIR-00001 | C14: 46218 | D14: 25349 | E14: 2 | F14: 1970 | G14: 0.44 | H14: GIDER | I14: =IF($A14="","",IFERROR(SUMIF(tblVarliklar[VarlikId],$B14,tblVarliklar[HedefKiraTl_tl]),kpg_varsayilanHedefKira)) | J14: =IF($A14="","",MAX(0, 1-$E14/kpg_gunAy)) | K14: =IF(OR($A14="",$I14=0),"",$D14/$I14) | L14: =IF($A14="","",$D14-$F14) | M14: =IF($A14="","",$I14*(1+$G14)) | N14: =IF($A14="","",MAX(0,MIN(100,kpg_kaliteTaban-IF($J14<kpg_esikDoluluk,kpg_kaliteCeza,0)-IF($K14<kpg_esikGetiri,kpg_kaliteSapma,0)-IF($Q14="YETIM",kpg_kaliteCeza,0)))) | O14: =IF($A14="","",IF(OR($J14<kpg_esikDoluluk,$K14<kpg_esikGetiri,$N14<kpg_esikSaglik),"ALARM","UYGUN")) | P14: =IF($A14="","",1) | Q14: =IF($A14="","",IF(OR($B14="",COUNTIF(tblVarliklar[VarlikId],$B14)=0),"YETIM","TAMAM"))
A15: KPG-00010 | B15: KIR-00002 | C15: 46215 | D15: 16830 | E15: 3 | F15: 2440 | G15: 0.39 | H15: TAHSILAT_GECIKME | I15: =IF($A15="","",IFERROR(SUMIF(tblVarliklar[VarlikId],$B15,tblVarliklar[HedefKiraTl_tl]),kpg_varsayilanHedefKira)) | J15: =IF($A15="","",MAX(0, 1-$E15/kpg_gunAy)) | K15: =IF(OR($A15="",$I15=0),"",$D15/$I15) | L15: =IF($A15="","",$D15-$F15) | M15: =IF($A15="","",$I15*(1+$G15)) | N15: =IF($A15="","",MAX(0,MIN(100,kpg_kaliteTaban-IF($J15<kpg_esikDoluluk,kpg_kaliteCeza,0)-IF($K15<kpg_esikGetiri,kpg_kaliteSapma,0)-IF($Q15="YETIM",kpg_kaliteCeza,0)))) | O15: =IF($A15="","",IF(OR($J15<kpg_esikDoluluk,$K15<kpg_esikGetiri,$N15<kpg_esikSaglik),"ALARM","UYGUN")) | P15: =IF($A15="","",1) | Q15: =IF($A15="","",IF(OR($B15="",COUNTIF(tblVarliklar[VarlikId],$B15)=0),"YETIM","TAMAM"))
A16: KPG-00011 | B16: KIR-00003 | C16: 46212 | D16: 15840 | E16: 0 | F16: 2910 | G16: 0.4 | H16: DIGER | I16: =IF($A16="","",IFERROR(SUMIF(tblVarliklar[VarlikId],$B16,tblVarliklar[HedefKiraTl_tl]),kpg_varsayilanHedefKira)) | J16: =IF($A16="","",MAX(0, 1-$E16/kpg_gunAy)) | K16: =IF(OR($A16="",$I16=0),"",$D16/$I16) | L16: =IF($A16="","",$D16-$F16) | M16: =IF($A16="","",$I16*(1+$G16)) | N16: =IF($A16="","",MAX(0,MIN(100,kpg_kaliteTaban-IF($J16<kpg_esikDoluluk,kpg_kaliteCeza,0)-IF($K16<kpg_esikGetiri,kpg_kaliteSapma,0)-IF($Q16="YETIM",kpg_kaliteCeza,0)))) | O16: =IF($A16="","",IF(OR($J16<kpg_esikDoluluk,$K16<kpg_esikGetiri,$N16<kpg_esikSaglik),"ALARM","UYGUN")) | P16: =IF($A16="","",1) | Q16: =IF($A16="","",IF(OR($B16="",COUNTIF(tblVarliklar[VarlikId],$B16)=0),"YETIM","TAMAM"))
A17: KPG-00012 | B17: KIR-00004 | C17: 46209 | D17: 11891 | E17: 2 | F17: 800 | G17: 0.38 | H17: TAHSILAT | I17: =IF($A17="","",IFERROR(SUMIF(tblVarliklar[VarlikId],$B17,tblVarliklar[HedefKiraTl_tl]),kpg_varsayilanHedefKira)) | J17: =IF($A17="","",MAX(0, 1-$E17/kpg_gunAy)) | K17: =IF(OR($A17="",$I17=0),"",$D17/$I17) | L17: =IF($A17="","",$D17-$F17) | M17: =IF($A17="","",$I17*(1+$G17)) | N17: =IF($A17="","",MAX(0,MIN(100,kpg_kaliteTaban-IF($J17<kpg_esikDoluluk,kpg_kaliteCeza,0)-IF($K17<kpg_esikGetiri,kpg_kaliteSapma,0)-IF($Q17="YETIM",kpg_kaliteCeza,0)))) | O17: =IF($A17="","",IF(OR($J17<kpg_esikDoluluk,$K17<kpg_esikGetiri,$N17<kpg_esikSaglik),"ALARM","UYGUN")) | P17: =IF($A17="","",1) | Q17: =IF($A17="","",IF(OR($B17="",COUNTIF(tblVarliklar[VarlikId],$B17)=0),"YETIM","TAMAM"))
... A34: KPG-00029 | B34: KIR-00005 | C34: 46158 | D34: 25220 | E34: 0 | F34: 2670 | G34: 0.4 | H34: DIGER | I34: =IF($A34="","",IFERROR(SUMIF(tblVarliklar[VarlikId],$B34,tblVarliklar[HedefKiraTl_tl]),kpg_varsayilanHedefKira)) | J34: =IF($A34="","",MAX(0, 1-$E34/kpg_gunAy)) | K34: =IF(OR($A34="",$I34=0),"",$D34/$I34) | L34: =IF($A34="","",$D34-$F34) | M34: =IF($A34="","",$I34*(1+$G34)) | N34: =IF($A34="","",MAX(0,MIN(100,kpg_kaliteTaban-IF($J34<kpg_esikDoluluk,kpg_kaliteCeza,0)-IF($K34<kpg_esikGetiri,kpg_kaliteSapma,0)-IF($Q34="YETIM",kpg_kaliteCeza,0)))) | O34: =IF($A34="","",IF(OR($J34<kpg_esikDoluluk,$K34<kpg_esikGetiri,$N34<kpg_esikSaglik),"ALARM","UYGUN")) | P34: =IF($A34="","",1) | Q34: =IF($A34="","",IF(OR($B34="",COUNTIF(tblVarliklar[VarlikId],$B34)=0),"YETIM","TAMAM"))
A35: KPG-00030 | C35: 46155 | D35: 9520 | E35: 2 | F35: 1040 | G35: 0.38 | H35: TAHSILAT | I35: =IF($A35="","",IFERROR(SUMIF(tblVarliklar[VarlikId],$B35,tblVarliklar[HedefKiraTl_tl]),kpg_varsayilanHedefKira)) | J35: =IF($A35="","",MAX(0, 1-$E35/kpg_gunAy)) | K35: =IF(OR($A35="",$I35=0),"",$D35/$I35) | L35: =IF($A35="","",$D35-$F35) | M35: =IF($A35="","",$I35*(1+$G35)) | N35: =IF($A35="","",MAX(0,MIN(100,kpg_kaliteTaban-IF($J35<kpg_esikDoluluk,kpg_kaliteCeza,0)-IF($K35<kpg_esikGetiri,kpg_kaliteSapma,0)-IF($Q35="YETIM",kpg_kaliteCeza,0)))) | O35: =IF($A35="","",IF(OR($J35<kpg_esikDoluluk,$K35<kpg_esikGetiri,$N35<kpg_esikSaglik),"ALARM","UYGUN")) | P35: =IF($A35="","",1) | Q35: =IF($A35="","",IF(OR($B35="",COUNTIF(tblVarliklar[VarlikId],$B35)=0),"YETIM","TAMAM"))
A36: KPG-00031 | B36: KIR-00007 | C36: 46152 | D36: 9680 | E36: 0 | F36: 1510 | G36: 0.39 | H36: BOSLUK | I36: =IF($A36="","",IFERROR(SUMIF(tblVarliklar[VarlikId],$B36,tblVarliklar[HedefKiraTl_tl]),kpg_varsayilanHedefKira)) | J36: =IF($A36="","",MAX(0, 1-$E36/kpg_gunAy)) | K36: =IF(OR($A36="",$I36=0),"",$D36/$I36) | L36: =IF($A36="","",$D36-$F36) | M36: =IF($A36="","",$I36*(1+$G36)) | N36: =IF($A36="","",MAX(0,MIN(100,kpg_kaliteTaban-IF($J36<kpg_esikDoluluk,kpg_kaliteCeza,0)-IF($K36<kpg_esikGetiri,kpg_kaliteSapma,0)-IF($Q36="YETIM",kpg_kaliteCeza,0)))) | O36: =IF($A36="","",IF(OR($J36<kpg_esikDoluluk,$K36<kpg_esikGetiri,$N36<kpg_esikSaglik),"ALARM","UYGUN")) | P36: =IF($A36="","",1) | Q36: =IF($A36="","",IF(OR($B36="",COUNTIF(tblVarliklar[VarlikId],$B36)=0),"YETIM","TAMAM"))
A37: KPG-00032 | B37: KIR-00008 | C37: 46149 | D37: 8645 | E37: 0 | F37: 1500 | G37: 0.4 | H37: ARTIS_TUFE | I37: =IF($A37="","",IFERROR(SUMIF(tblVarliklar[VarlikId],$B37,tblVarliklar[HedefKiraTl_tl]),kpg_varsayilanHedefKira)) | J37: =IF($A37="","",MAX(0, 1-$E37/kpg_gunAy)) | K37: =IF(OR($A37="",$I37=0),"",$D37/$I37) | L37: =IF($A37="","",$D37-$F37) | M37: =IF($A37="","",$I37*(1+$G37)) | N37: =IF($A37="","",MAX(0,MIN(100,kpg_kaliteTaban-IF($J37<kpg_esikDoluluk,kpg_kaliteCeza,0)-IF($K37<kpg_esikGetiri,kpg_kaliteSapma,0)-IF($Q37="YETIM",kpg_kaliteCeza,0)))) | O37: =IF($A37="","",IF(OR($J37<kpg_esikDoluluk,$K37<kpg_esikGetiri,$N37<kpg_esikSaglik),"ALARM","UYGUN")) | P37: =IF($A37="","",1) | Q37: =IF($A37="","",IF(OR($B37="",COUNTIF(tblVarliklar[VarlikId],$B37)=0),"YETIM","TAMAM"))
A38: KPG-00033 | B38: KIR-99999 | C38: 46146 | D38: 24565 | E38: 2 | F38: 1970 | G38: 0.38 | H38: GIDER | I38: =IF($A38="","",IFERROR(SUMIF(tblVarliklar[VarlikId],$B38,tblVarliklar[HedefKiraTl_tl]),kpg_varsayilanHedefKira)) | J38: =IF($A38="","",MAX(0, 1-$E38/kpg_gunAy)) | K38: =IF(OR($A38="",$I38=0),"",$D38/$I38) | L38: =IF($A38="","",$D38-$F38) | M38: =IF($A38="","",$I38*(1+$G38)) | N38: =IF($A38="","",MAX(0,MIN(100,kpg_kaliteTaban-IF($J38<kpg_esikDoluluk,kpg_kaliteCeza,0)-IF($K38<kpg_esikGetiri,kpg_kaliteSapma,0)-IF($Q38="YETIM",kpg_kaliteCeza,0)))) | O38: =IF($A38="","",IF(OR($J38<kpg_esikDoluluk,$K38<kpg_esikGetiri,$N38<kpg_esikSaglik),"ALARM","UYGUN")) | P38: =IF($A38="","",1) | Q38: =IF($A38="","",IF(OR($B38="",COUNTIF(tblVarliklar[VarlikId],$B38)=0),"YETIM","TAMAM"))
A39: KPG-00034 | B39: KIR-00002 | C39: 46143 | D39: 21340 | E39: 0 | F39: 2440 | G39: 0.39 | H39: TAHSILAT_GECIKME | I39: =IF($A39="","",IFERROR(SUMIF(tblVarliklar[VarlikId],$B39,tblVarliklar[HedefKiraTl_tl]),kpg_varsayilanHedefKira)) | J39: =IF($A39="","",MAX(0, 1-$E39/kpg_gunAy)) | K39: =IF(OR($A39="",$I39=0),"",$D39/$I39) | L39: =IF($A39="","",$D39-$F39) | M39: =IF($A39="","",$I39*(1+$G39)) | N39: =IF($A39="","",MAX(0,MIN(100,kpg_kaliteTaban-IF($J39<kpg_esikDoluluk,kpg_kaliteCeza,0)-IF($K39<kpg_esikGetiri,kpg_kaliteSapma,0)-IF($Q39="YETIM",kpg_kaliteCeza,0)))) | O39: =IF($A39="","",IF(OR($J39<kpg_esikDoluluk,$K39<kpg_esikGetiri,$N39<kpg_esikSaglik),"ALARM","UYGUN")) | P39: =IF($A39="","",1) | Q39: =IF($A39="","",IF(OR($B39="",COUNTIF(tblVarliklar[VarlikId],$B39)=0),"YETIM","TAMAM"))
A40: KPG-00035 | B40: KIR-00003 | C40: 46140 | D40: 15300 | E40: 0 | F40: 2910 | G40: 0.4 | H40: DIGER | I40: =IF($A40="","",IFERROR(SUMIF(tblVarliklar[VarlikId],$B40,tblVarliklar[HedefKiraTl_tl]),kpg_varsayilanHedefKira)) | J40: =IF($A40="","",MAX(0, 1-$E40/kpg_gunAy)) | K40: =IF(OR($A40="",$I40=0),"",$D40/$I40) | L40: =IF($A40="","",$D40-$F40) | M40: =IF($A40="","",$I40*(1+$G40)) | N40: =IF($A40="","",MAX(0,MIN(100,kpg_kaliteTaban-IF($J40<kpg_esikDoluluk,kpg_kaliteCeza,0)-IF($K40<kpg_esikGetiri,kpg_kaliteSapma,0)-IF($Q40="YETIM",kpg_kaliteCeza,0)))) | O40: =IF($A40="","",IF(OR($J40<kpg_esikDoluluk,$K40<kpg_esikGetiri,$N40<kpg_esikSaglik),"ALARM","UYGUN")) | P40: =IF($A40="","",1) | Q40: =IF($A40="","",IF(OR($B40="",COUNTIF(tblVarliklar[VarlikId],$B40)=0),"YETIM","TAMAM"))
A41: KPG-00036 | B41: KIR-00004 | C41: 46137 | D41: 11499 | E41: 2 | F41: 800 | G41: 0.42 | H41: TAHSILAT | I41: =IF($A41="","",IFERROR(SUMIF(tblVarliklar[VarlikId],$B41,tblVarliklar[HedefKiraTl_tl]),kpg_varsayilanHedefKira)) | J41: =IF($A41="","",MAX(0, 1-$E41/kpg_gunAy)) | K41: =IF(OR($A41="",$I41=0),"",$D41/$I41) | L41: =IF($A41="","",$D41-$F41) | M41: =IF($A41="","",$I41*(1+$G41)) | N41: =IF($A41="","",MAX(0,MIN(100,kpg_kaliteTaban-IF($J41<kpg_esikDoluluk,kpg_kaliteCeza,0)-IF($K41<kpg_esikGetiri,kpg_kaliteSapma,0)-IF($Q41="YETIM",kpg_kaliteCeza,0)))) | O41: =IF($A41="","",IF(OR($J41<kpg_esikDoluluk,$K41<kpg_esikGetiri,$N41<kpg_esikSaglik),"ALARM","UYGUN")) | P41: =IF($A41="","",1) | Q41: =IF($A41="","",IF(OR($B41="",COUNTIF(tblVarliklar[VarlikId],$B41)=0),"YETIM","TAMAM"))
I42: =IF($A42="","",IFERROR(SUMIF(tblVarliklar[VarlikId],$B42,tblVarliklar[HedefKiraTl_tl]),kpg_varsayilanHedefKira)) | J42: =IF($A42="","",MAX(0, 1-$E42/kpg_gunAy)) | K42: =IF(OR($A42="",$I42=0),"",$D42/$I42) | L42: =IF($A42="","",$D42-$F42) | M42: =IF($A42="","",$I42*(1+$G42)) | N42: =IF($A42="","",MAX(0,MIN(100,kpg_kaliteTaban-IF($J42<kpg_esikDoluluk,kpg_kaliteCeza,0)-IF($K42<kpg_esikGetiri,kpg_kaliteSapma,0)-IF($Q42="YETIM",kpg_kaliteCeza,0)))) | O42: =IF($A42="","",IF(OR($J42<kpg_esikDoluluk,$K42<kpg_esikGetiri,$N42<kpg_esikSaglik),"ALARM","UYGUN")) | P42: =IF($A42="","",1) | Q42: =IF($A42="","",IF(OR($B42="",COUNTIF(tblVarliklar[VarlikId],$B42)=0),"YETIM","TAMAM"))
I43: =IF($A43="","",IFERROR(SUMIF(tblVarliklar[VarlikId],$B43,tblVarliklar[HedefKiraTl_tl]),kpg_varsayilanHedefKira)) | J43: =IF($A43="","",MAX(0, 1-$E43/kpg_gunAy)) | K43: =IF(OR($A43="",$I43=0),"",$D43/$I43) | L43: =IF($A43="","",$D43-$F43) | M43: =IF($A43="","",$I43*(1+$G43)) | N43: =IF($A43="","",MAX(0,MIN(100,kpg_kaliteTaban-IF($J43<kpg_esikDoluluk,kpg_kaliteCeza,0)-IF($K43<kpg_esikGetiri,kpg_kaliteSapma,0)-IF($Q43="YETIM",kpg_kaliteCeza,0)))) | O43: =IF($A43="","",IF(OR($J43<kpg_esikDoluluk,$K43<kpg_esikGetiri,$N43<kpg_esikSaglik),"ALARM","UYGUN")) | P43: =IF($A43="","",1) | Q43: =IF($A43="","",IF(OR($B43="",COUNTIF(tblVarliklar[VarlikId],$B43)=0),"YETIM","TAMAM"))
I44: =IF($A44="","",IFERROR(SUMIF(tblVarliklar[VarlikId],$B44,tblVarliklar[HedefKiraTl_tl]),kpg_varsayilanHedefKira)) | J44: =IF($A44="","",MAX(0, 1-$E44/kpg_gunAy)) | K44: =IF(OR($A44="",$I44=0),"",$D44/$I44) | L44: =IF($A44="","",$D44-$F44) | M44: =IF($A44="","",$I44*(1+$G44)) | N44: =IF($A44="","",MAX(0,MIN(100,kpg_kaliteTaban-IF($J44<kpg_esikDoluluk,kpg_kaliteCeza,0)-IF($K44<kpg_esikGetiri,kpg_kaliteSapma,0)-IF($Q44="YETIM",kpg_kaliteCeza,0)))) | O44: =IF($A44="","",IF(OR($J44<kpg_esikDoluluk,$K44<kpg_esikGetiri,$N44<kpg_esikSaglik),"ALARM","UYGUN")) | P44: =IF($A44="","",1) | Q44: =IF($A44="","",IF(OR($B44="",COUNTIF(tblVarliklar[VarlikId],$B44)=0),"YETIM","TAMAM"))
I45: =IF($A45="","",IFERROR(SUMIF(tblVarliklar[VarlikId],$B45,tblVarliklar[HedefKiraTl_tl]),kpg_varsayilanHedefKira)) | J45: =IF($A45="","",MAX(0, 1-$E45/kpg_gunAy)) | K45: =IF(OR($A45="",$I45=0),"",$D45/$I45) | L45: =IF($A45="","",$D45-$F45) | M45: =IF($A45="","",$I45*(1+$G45)) | N45: =IF($A45="","",MAX(0,MIN(100,kpg_kaliteTaban-IF($J45<kpg_esikDoluluk,kpg_kaliteCeza,0)-IF($K45<kpg_esikGetiri,kpg_kaliteSapma,0)-IF($Q45="YETIM",kpg_kaliteCeza,0)))) | O45: =IF($A45="","",IF(OR($J45<kpg_esikDoluluk,$K45<kpg_esikGetiri,$N45<kpg_esikSaglik),"ALARM","UYGUN")) | P45: =IF($A45="","",1) | Q45: =IF($A45="","",IF(OR($B45="",COUNTIF(tblVarliklar[VarlikId],$B45)=0),"YETIM","TAMAM"))
I46: =IF($A46="","",IFERROR(SUMIF(tblVarliklar[VarlikId],$B46,tblVarliklar[HedefKiraTl_tl]),kpg_varsayilanHedefKira)) | J46: =IF($A46="","",MAX(0, 1-$E46/kpg_gunAy)) | K46: =IF(OR($A46="",$I46=0),"",$D46/$I46) | L46: =IF($A46="","",$D46-$F46) | M46: =IF($A46="","",$I46*(1+$G46)) | N46: =IF($A46="","",MAX(0,MIN(100,kpg_kaliteTaban-IF($J46<kpg_esikDoluluk,kpg_kaliteCeza,0)-IF($K46<kpg_esikGetiri,kpg_kaliteSapma,0)-IF($Q46="YETIM",kpg_kaliteCeza,0)))) | O46: =IF($A46="","",IF(OR($J46<kpg_esikDoluluk,$K46<kpg_esikGetiri,$N46<kpg_esikSaglik),"ALARM","UYGUN")) | P46: =IF($A46="","",1) | Q46: =IF($A46="","",IF(OR($B46="",COUNTIF(tblVarliklar[VarlikId],$B46)=0),"YETIM","TAMAM"))
I47: =IF($A47="","",IFERROR(SUMIF(tblVarliklar[VarlikId],$B47,tblVarliklar[HedefKiraTl_tl]),kpg_varsayilanHedefKira)) | J47: =IF($A47="","",MAX(0, 1-$E47/kpg_gunAy)) | K47: =IF(OR($A47="",$I47=0),"",$D47/$I47) | L47: =IF($A47="","",$D47-$F47) | M47: =IF($A47="","",$I47*(1+$G47)) | N47: =IF($A47="","",MAX(0,MIN(100,kpg_kaliteTaban-IF($J47<kpg_esikDoluluk,kpg_kaliteCeza,0)-IF($K47<kpg_esikGetiri,kpg_kaliteSapma,0)-IF($Q47="YETIM",kpg_kaliteCeza,0)))) | O47: =IF($A47="","",IF(OR($J47<kpg_esikDoluluk,$K47<kpg_esikGetiri,$N47<kpg_esikSaglik),"ALARM","UYGUN")) | P47: =IF($A47="","",1) | Q47: =IF($A47="","",IF(OR($B47="",COUNTIF(tblVarliklar[VarlikId],$B47)=0),"YETIM","TAMAM"))
I48: =IF($A48="","",IFERROR(SUMIF(tblVarliklar[VarlikId],$B48,tblVarliklar[HedefKiraTl_tl]),kpg_varsayilanHedefKira)) | J48: =IF($A48="","",MAX(0, 1-$E48/kpg_gunAy)) | K48: =IF(OR($A48="",$I48=0),"",$D48/$I48) | L48: =IF($A48="","",$D48-$F48) | M48: =IF($A48="","",$I48*(1+$G48)) | N48: =IF($A48="","",MAX(0,MIN(100,kpg_kaliteTaban-IF($J48<kpg_esikDoluluk,kpg_kaliteCeza,0)-IF($K48<kpg_esikGetiri,kpg_kaliteSapma,0)-IF($Q48="YETIM",kpg_kaliteCeza,0)))) | O48: =IF($A48="","",IF(OR($J48<kpg_esikDoluluk,$K48<kpg_esikGetiri,$N48<kpg_esikSaglik),"ALARM","UYGUN")) | P48: =IF($A48="","",1) | Q48: =IF($A48="","",IF(OR($B48="",COUNTIF(tblVarliklar[VarlikId],$B48)=0),"YETIM","TAMAM"))
I49: =IF($A49="","",IFERROR(SUMIF(tblVarliklar[VarlikId],$B49,tblVarliklar[HedefKiraTl_tl]),kpg_varsayilanHedefKira)) | J49: =IF($A49="","",MAX(0, 1-$E49/kpg_gunAy)) | K49: =IF(OR($A49="",$I49=0),"",$D49/$I49) | L49: =IF($A49="","",$D49-$F49) | M49: =IF($A49="","",$I49*(1+$G49)) | N49: =IF($A49="","",MAX(0,MIN(100,kpg_kaliteTaban-IF($J49<kpg_esikDoluluk,kpg_kaliteCeza,0)-IF($K49<kpg_esikGetiri,kpg_kaliteSapma,0)-IF($Q49="YETIM",kpg_kaliteCeza,0)))) | O49: =IF($A49="","",IF(OR($J49<kpg_esikDoluluk,$K49<kpg_esikGetiri,$N49<kpg_esikSaglik),"ALARM","UYGUN")) | P49: =IF($A49="","",1) | Q49: =IF($A49="","",IF(OR($B49="",COUNTIF(tblVarliklar[VarlikId],$B49)=0),"YETIM","TAMAM"))
I50: =IF($A50="","",IFERROR(SUMIF(tblVarliklar[VarlikId],$B50,tblVarliklar[HedefKiraTl_tl]),kpg_varsayilanHedefKira)) | J50: =IF($A50="","",MAX(0, 1-$E50/kpg_gunAy)) | K50: =IF(OR($A50="",$I50=0),"",$D50/$I50) | L50: =IF($A50="","",$D50-$F50) | M50: =IF($A50="","",$I50*(1+$G50)) | N50: =IF($A50="","",MAX(0,MIN(100,kpg_kaliteTaban-IF($J50<kpg_esikDoluluk,kpg_kaliteCeza,0)-IF($K50<kpg_esikGetiri,kpg_kaliteSapma,0)-IF($Q50="YETIM",kpg_kaliteCeza,0)))) | O50: =IF($A50="","",IF(OR($J50<kpg_esikDoluluk,$K50<kpg_esikGetiri,$N50<kpg_esikSaglik),"ALARM","UYGUN")) | P50: =IF($A50="","",1) | Q50: =IF($A50="","",IF(OR($B50="",COUNTIF(tblVarliklar[VarlikId],$B50)=0),"YETIM","TAMAM"))
I51: =IF($A51="","",IFERROR(SUMIF(tblVarliklar[VarlikId],$B51,tblVarliklar[HedefKiraTl_tl]),kpg_varsayilanHedefKira)) | J51: =IF($A51="","",MAX(0, 1-$E51/kpg_gunAy)) | K51: =IF(OR($A51="",$I51=0),"",$D51/$I51) | L51: =IF($A51="","",$D51-$F51) | M51: =IF($A51="","",$I51*(1+$G51)) | N51: =IF($A51="","",MAX(0,MIN(100,kpg_kaliteTaban-IF($J51<kpg_esikDoluluk,kpg_kaliteCeza,0)-IF($K51<kpg_esikGetiri,kpg_kaliteSapma,0)-IF($Q51="YETIM",kpg_kaliteCeza,0)))) | O51: =IF($A51="","",IF(OR($J51<kpg_esikDoluluk,$K51<kpg_esikGetiri,$N51<kpg_esikSaglik),"ALARM","UYGUN")) | P51: =IF($A51="","",1) | Q51: =IF($A51="","",IF(OR($B51="",COUNTIF(tblVarliklar[VarlikId],$B51)=0),"YETIM","TAMAM"))
I52: =IF($A52="","",IFERROR(SUMIF(tblVarliklar[VarlikId],$B52,tblVarliklar[HedefKiraTl_tl]),kpg_varsayilanHedefKira)) | J52: =IF($A52="","",MAX(0, 1-$E52/kpg_gunAy)) | K52: =IF(OR($A52="",$I52=0),"",$D52/$I52) | L52: =IF($A52="","",$D52-$F52) | M52: =IF($A52="","",$I52*(1+$G52)) | N52: =IF($A52="","",MAX(0,MIN(100,kpg_kaliteTaban-IF($J52<kpg_esikDoluluk,kpg_kaliteCeza,0)-IF($K52<kpg_esikGetiri,kpg_kaliteSapma,0)-IF($Q52="YETIM",kpg_kaliteCeza,0)))) | O52: =IF($A52="","",IF(OR($J52<kpg_esikDoluluk,$K52<kpg_esikGetiri,$N52<kpg_esikSaglik),"ALARM","UYGUN")) | P52: =IF($A52="","",1) | Q52: =IF($A52="","",IF(OR($B52="",COUNTIF(tblVarliklar[VarlikId],$B52)=0),"YETIM","TAMAM"))
I53: =IF($A53="","",IFERROR(SUMIF(tblVarliklar[VarlikId],$B53,tblVarliklar[HedefKiraTl_tl]),kpg_varsayilanHedefKira)) | J53: =IF($A53="","",MAX(0, 1-$E53/kpg_gunAy)) | K53: =IF(OR($A53="",$I53=0),"",$D53/$I53) | L53: =IF($A53="","",$D53-$F53) | M53: =IF($A53="","",$I53*(1+$G53)) | N53: =IF($A53="","",MAX(0,MIN(100,kpg_kaliteTaban-IF($J53<kpg_esikDoluluk,kpg_kaliteCeza,0)-IF($K53<kpg_esikGetiri,kpg_kaliteSapma,0)-IF($Q53="YETIM",kpg_kaliteCeza,0)))) | O53: =IF($A53="","",IF(OR($J53<kpg_esikDoluluk,$K53<kpg_esikGetiri,$N53<kpg_esikSaglik),"ALARM","UYGUN")) | P53: =IF($A53="","",1) | Q53: =IF($A53="","",IF(OR($B53="",COUNTIF(tblVarliklar[VarlikId],$B53)=0),"YETIM","TAMAM"))
... I255: =IF($A255="","",IFERROR(SUMIF(tblVarliklar[VarlikId],$B255,tblVarliklar[HedefKiraTl_tl]),kpg_varsayilanHedefKira)) | J255: =IF($A255="","",MAX(0, 1-$E255/kpg_gunAy)) | K255: =IF(OR($A255="",$I255=0),"",$D255/$I255) | L255: =IF($A255="","",$D255-$F255) | M255: =IF($A255="","",$I255*(1+$G255)) | N255: =IF($A255="","",MAX(0,MIN(100,kpg_kaliteTaban-IF($J255<kpg_esikDoluluk,kpg_kaliteCeza,0)-IF($K255<kpg_esikGetiri,kpg_kaliteSapma,0)-IF($Q255="YETIM",kpg_kaliteCeza,0)))) | O255: =IF($A255="","",IF(OR($J255<kpg_esikDoluluk,$K255<kpg_esikGetiri,$N255<kpg_esikSaglik),"ALARM","UYGUN")) | P255: =IF($A255="","",1) | Q255: =IF($A255="","",IF(OR($B255="",COUNTIF(tblVarliklar[VarlikId],$B255)=0),"YETIM","TAMAM"))

Sheet DONEM_ANALIZ
A1: DONEM ANALIZ — Kira Portföyü Getiri Komutası
A3: 12 aylık sezonsallık — tahsilat ve doluluk zinciri (S03)
A5: Ay | B5: Ay_Anahtari | C5: Tahsilat TL | D5: Gider TL | E5: Doluluk Ort | F5: Sezonsal Etiket
A6: Ocak | B6: Ay_1 | C6: 118000 | D6: 18000 | E6: 0.88 | F6: 12_AY_SEZONSAL
A7: Subat | B7: Ay_2 | C7: 122000 | D7: 19000 | E7: 0.89 | F7: 12_AY_SEZONSAL
A8: Mart | B8: Ay_3 | C8: 128000 | D8: 20000 | E8: 0.91 | F8: 12_AY_SEZONSAL
A9: Nisan | B9: Ay_4 | C9: 135000 | D9: 21000 | E9: 0.93 | F9: 12_AY_SEZONSAL
A10: Mayis | B10: Ay_5 | C10: 142000 | D10: 22000 | E10: 0.94 | F10: 12_AY_SEZONSAL
A11: Haziran | B11: Ay_6 | C11: 148000 | D11: 23000 | E11: 0.95 | F11: 12_AY_SEZONSAL
A12: Temmuz | B12: Ay_7 | C12: 152000 | D12: 24000 | E12: 0.96 | F12: 12_AY_SEZONSAL
A13: Agustos | B13: Ay_8 | C13: 150000 | D13: 23500 | E13: 0.95 | F13: 12_AY_SEZONSAL
A14: Eylul | B14: Ay_9 | C14: 145000 | D14: 22000 | E14: 0.93 | F14: 12_AY_SEZONSAL
A15: Ekim | B15: Ay_10 | C15: 138000 | D15: 20500 | E15: 0.91 | F15: 12_AY_SEZONSAL
A16: Kasim | B16: Ay_11 | C16: 130000 | D16: 19500 | E16: 0.89 | F16: 12_AY_SEZONSAL
A17: Aralik | B17: Ay_12 | C17: 124000 | D17: 18500 | E17: 0.87 | F17: 12_AY_SEZONSAL
A20: Sezonsal Trend Özeti | B20: =kpg_sezonsalTrend
A22: 12 Ay Toplam Tahsilat | B22: =SUM(C6:C17)
A23: 12 Ay Toplam Gider | B23: =SUM(D6:D17)
A24: 12 Ay Ort Doluluk | B24: =AVERAGE(E6:E17)
A25: Canlı dönem tahsilat | B25: =kpg_toplamTahsilat
A26: Canlı dönem doluluk | B26: =kpg_ortDoluluk

Sheet HESAP
A1: HESAP — Kira Portföyü Getiri Komutası
A3: Hesap motoru — ≥40 adım; sabitler AYARLAR'dan
A5: Adım | B5: Açıklama | C5: Değer
A6: H01 | B6: Toplam günlük kayıt | C6: =COUNTA(tblGunluk[SatirId])
A7: H02 | B7: Dolu kayıt | C7: =SUM(tblGunluk[FormulKayitDolu])
A8: H03 | B8: Toplam tahsilat TL | C8: =SUM(tblGunluk[TahsilatTl_tl])
A9: H04 | B9: Toplam boş gün | C9: =SUM(tblGunluk[BosGun_gun])
A10: H05 | B10: Toplam gider TL | C10: =SUM(tblGunluk[GiderTl_tl])
A11: H06 | B11: Toplam hedef kira | C11: =SUM(tblGunluk[FormulHedefKira_tl])
A12: H07 | B12: Ort doluluk | C12: =IFERROR(AVERAGEIF(tblGunluk[FormulDoluluk_oran],">0"),0)
A13: H08 | B13: Ort getiri | C13: =IFERROR(AVERAGEIF(tblGunluk[FormulGetiri_oran],">0"),0)
A14: H09 | B14: Net tahsilat | C14: =SUM(tblGunluk[FormulNet_tl])
A15: H10 | B15: Aktif menkul adet | C15: =COUNTIF(tblVarliklar[Aktif],"EVET")
A16: H11 | B16: Toplam menkul kart | C16: =COUNTA(tblVarliklar[VarlikId])
A17: H12 | B17: Alarm adet | C17: =COUNTIF(tblGunluk[AlarmBayrak],"ALARM")
A18: H13 | B18: Yetim kayıt | C18: =COUNTIF(tblGunluk[FormulYetim],"YETIM")
A19: H14 | B19: Ortalama sağlık skor | C19: =IFERROR(AVERAGEIF(tblGunluk[SaglikSkor_puan],">0"),0)
A20: H15 | B20: Min sağlık skor | C20: =IFERROR(MIN(tblGunluk[SaglikSkor_puan]),0)
A21: H16 | B21: Doluluk eşik altı adet | C21: =COUNTIFS(tblGunluk[FormulDoluluk_oran],"<"&kpg_esikDoluluk,tblGunluk[FormulKayitDolu],">0")
A22: H17 | B22: Getiri eşik altı adet | C22: =COUNTIFS(tblGunluk[FormulGetiri_oran],"<"&kpg_esikGetiri,tblGunluk[FormulKayitDolu],">0")
A23: H18 | B23: Düşük sağlık adet | C23: =COUNTIFS(tblGunluk[SaglikSkor_puan],"<"&kpg_esikSaglik,tblGunluk[FormulKayitDolu],">0")
A24: H19 | B24: Günlük doluluk ort | C24: =IFERROR(AVERAGEIF(tblGunluk[FormulDoluluk_oran],">0"),0)
A25: H20 | B25: Aylık tahsilat proxy | C25: =C8*kpg_aylikCarpan
A26: H21 | B26: Getiri sapma | C26: =IFERROR(ABS(C13-kpg_esikGetiri),0)
A27: H22 | B27: Tahsilat olay pay | C27: =IFERROR(COUNTIF(tblGunluk[OlayTuru],"TAHSILAT")/MAX(C7,1),0)
A28: H23 | B28: Boşluk olay pay | C28: =IFERROR(COUNTIF(tblGunluk[OlayTuru],"BOSLUK")/MAX(C7,1),0)
A29: H24 | B29: TÜFE artış olay pay | C29: =IFERROR(COUNTIF(tblGunluk[OlayTuru],"ARTIS_TUFE")/MAX(C7,1),0)
A30: H25 | B30: Gider olay pay | C30: =IFERROR(COUNTIF(tblGunluk[OlayTuru],"GIDER")/MAX(C7,1),0)
A31: H26 | B31: Temkinli senaryo | C31: =C8*kpg_senaryoTemkinli
A32: H27 | B32: Baz senaryo | C32: =C8*kpg_senaryoBaz
A33: H28 | B33: İyimser senaryo | C33: =C8*kpg_senaryoIyimser
A34: H29 | B34: Senaryo farkı | C34: =C33-C31
A35: H30 | B35: Tornado boşluk etki | C35: =C9*kpg_tornadoOran*kpg_varsayilanHedefKira
A36: H31 | B36: Tornado gider etki | C36: =C10*kpg_tornadoOran
A37: H32 | B37: Tornado tahsilat etki | C37: =C8*kpg_tornadoOran
A38: H33 | B38: Tornado zirve | C38: =MAX(C35,C36,C37)
A39: H34 | B39: HHI proxy | C39: =IFERROR(C27^2+C28^2+C29^2+C30^2,0)
A40: H35 | B40: Kalite skor | C40: =MAX(0,kpg_kaliteTaban-C21*kpg_kaliteCeza-C22*kpg_kaliteSapma-C23*kpg_kaliteSapma)
A41: H36 | B41: Tahmin aralık | C41: =C32*kpg_tahminCarpan
A42: H37 | B42: P90 tahsilat | C42: =IFERROR(PERCENTILE(tblGunluk[TahsilatTl_tl],kpg_percentileOran),C8*kpg_yuzdelikOran)
...

Sheet ALARMLAR
A1: ALARMLAR — Kira Portföyü Getiri Komutası
A3: Alarm listesi — varlık + eşik + süre (S05)
A5: Varlık | B5: Alarm | C5: Eşik | D5: Süre / Tarih | E5: Doluluk Ort | F5: Sağlık Skor
A6: KIR-00001 | B6: =IF(OR(COUNTIFS(tblGunluk[VarlikId],A6,tblGunluk[AlarmBayrak],"ALARM")>0,IFERROR(SUMIF(tblVarliklar[VarlikId],A6,tblVarliklar[SaglikSkor]),100)<kpg_esikSaglik),"ALARM","YOK") | C6: =IFERROR(ABS(E6-kpg_esikDoluluk),0) | D6: =raporTarihi | E6: =IFERROR(SUMIF(tblVarliklar[VarlikId],A6,tblVarliklar[OrtDoluluk]),0) | F6: =IFERROR(SUMIF(tblVarliklar[VarlikId],A6,tblVarliklar[SaglikSkor]),0)
A7: KIR-00002 | B7: =IF(OR(COUNTIFS(tblGunluk[VarlikId],A7,tblGunluk[AlarmBayrak],"ALARM")>0,IFERROR(SUMIF(tblVarliklar[VarlikId],A7,tblVarliklar[SaglikSkor]),100)<kpg_esikSaglik),"ALARM","YOK") | C7: =IFERROR(ABS(E7-kpg_esikDoluluk),0) | D7: =raporTarihi | E7: =IFERROR(SUMIF(tblVarliklar[VarlikId],A7,tblVarliklar[OrtDoluluk]),0) | F7: =IFERROR(SUMIF(tblVarliklar[VarlikId],A7,tblVarliklar[SaglikSkor]),0)
A8: KIR-00003 | B8: =IF(OR(COUNTIFS(tblGunluk[VarlikId],A8,tblGunluk[AlarmBayrak],"ALARM")>0,IFERROR(SUMIF(tblVarliklar[VarlikId],A8,tblVarliklar[SaglikSkor]),100)<kpg_esikSaglik),"ALARM","YOK") | C8: =IFERROR(ABS(E8-kpg_esikDoluluk),0) | D8: =raporTarihi | E8: =IFERROR(SUMIF(tblVarliklar[VarlikId],A8,tblVarliklar[OrtDoluluk]),0) | F8: =IFERROR(SUMIF(tblVarliklar[VarlikId],A8,tblVarliklar[SaglikSkor]),0)
A9: KIR-00004 | B9: =IF(OR(COUNTIFS(tblGunluk[VarlikId],A9,tblGunluk[AlarmBayrak],"ALARM")>0,IFERROR(SUMIF(tblVarliklar[VarlikId],A9,tblVarliklar[SaglikSkor]),100)<kpg_esikSaglik),"ALARM","YOK") | C9: =IFERROR(ABS(E9-kpg_esikDoluluk),0) | D9: =raporTarihi | E9: =IFERROR(SUMIF(tblVarliklar[VarlikId],A9,tblVarliklar[OrtDoluluk]),0) | F9: =IFERROR(SUMIF(tblVarliklar[VarlikId],A9,tblVarliklar[SaglikSkor]),0)
A10: KIR-00005 | B10: =IF(OR(COUNTIFS(tblGunluk[VarlikId],A10,tblGunluk[AlarmBayrak],"ALARM")>0,IFERROR(SUMIF(tblVarliklar[VarlikId],A10,tblVarliklar[SaglikSkor]),100)<kpg_esikSaglik),"ALARM","YOK") | C10: =IFERROR(ABS(E10-kpg_esikDoluluk),0) | D10: =raporTarihi | E10: =IFERROR(SUMIF(tblVarliklar[VarlikId],A10,tblVarliklar[OrtDoluluk]),0) | F10: =IFERROR(SUMIF(tblVarliklar[VarlikId],A10,tblVarliklar[SaglikSkor]),0)
A11: KIR-00006 | B11: =IF(OR(COUNTIFS(tblGunluk[VarlikId],A11,tblGunluk[AlarmBayrak],"ALARM")>0,IFERROR(SUMIF(tblVarliklar[VarlikId],A11,tblVarliklar[SaglikSkor]),100)<kpg_esikSaglik),"ALARM","YOK") | C11: =IFERROR(ABS(E11-kpg_esikDoluluk),0) | D11: =raporTarihi | E11: =IFERROR(SUMIF(tblVarliklar[VarlikId],A11,tblVarliklar[OrtDoluluk]),0) | F11: =IFERROR(SUMIF(tblVarliklar[VarlikId],A11,tblVarliklar[SaglikSkor]),0)
A12: KIR-00007 | B12: =IF(OR(COUNTIFS(tblGunluk[VarlikId],A12,tblGunluk[AlarmBayrak],"ALARM")>0,IFERROR(SUMIF(tblVarliklar[VarlikId],A12,tblVarliklar[SaglikSkor]),100)<kpg_esikSaglik),"ALARM","YOK") | C12: =IFERROR(ABS(E12-kpg_esikDoluluk),0) | D12: =raporTarihi | E12: =IFERROR(SUMIF(tblVarliklar[VarlikId],A12,tblVarliklar[OrtDoluluk]),0) | F12: =IFERROR(SUMIF(tblVarliklar[VarlikId],A12,tblVarliklar[SaglikSkor]),0)
A13: KIR-00008 | B13: =IF(OR(COUNTIFS(tblGunluk[VarlikId],A13,tblGunluk[AlarmBayrak],"ALARM")>0,IFERROR(SUMIF(tblVarliklar[VarlikId],A13,tblVarliklar[SaglikSkor]),100)<kpg_esikSaglik),"ALARM","YOK") | C13: =IFERROR(ABS(E13-kpg_esikDoluluk),0) | D13: =raporTarihi | E13: =IFERROR(SUMIF(tblVarliklar[VarlikId],A13,tblVarliklar[OrtDoluluk]),0) | F13: =IFERROR(SUMIF(tblVarliklar[VarlikId],A13,tblVarliklar[SaglikSkor]),0)
A16: Alarm Özeti | B16: =kpg_alarmListesi
A18: Toplam Alarm Satır | B18: =COUNTIF(B6:B13,"ALARM")

Sheet RAPOR
A1: RAPOR — Kira Portföyü Getiri Komutası
A3: Dönemsel yönetim raporu — yazdırılabilir kanıt
A5: Ürün | B5: Kira Portföyü Getiri Komutası
A6: Sürüm | B6: 1.0.0
A7: Rapor Tarihi | B7: =raporTarihi
A8: Firma | B8: =kpg_firmaUnvan
A10: KARAR | B10: =kpg_kararKapi
A11: Ort Doluluk | B11: =kpg_ortDoluluk
A12: Toplam Tahsilat TL | B12: =kpg_toplamTahsilat
A13: Toplam Gider TL | B13: =kpg_toplamGider
A14: Sağlık Skor | B14: =kpg_saglikSkor
A15: Alarm Adet | B15: =kpg_alarmAdet
A17: Kalem | B17: Değer
A18: Ort getiri | B18: =kpg_ortGetiri
A19: Net tahsilat | B19: =kpg_netTahsilat
A20: Günlük doluluk ort | B20: =kpg_gunlukDolulukOrt
A21: Kalite skor | B21: =kpg_kaliteSkor
A22: Ort TÜFE artış TL | B22: =kpg_ortTufeArtis
A24: Varsayımlar
A25: Doluluk = 1 − boş_gün / ay_günü. Getiri = tahsilat / hedef_kira. TÜFE oranı kullanıcı girişi (dış API yok). Eşikler AYARLAR'dan gelir. Karar destek çıktısıdır; hukuki veya mali tavsiye değildir. TBK kira hükümleri + TÜFE artış yaklaşımıdır.
A28: İmza — Portföy Yöneticisi | C28: ________________
A29: İmza — Mali Müşavir / CFO | C29: ________________
A31: SHA notu: sevk paketinde SHA-256 yer alır | 1.0.0

Sheet KONTROLLER
A1: KONTROLLER — Kira Portföyü Getiri Komutası
A3: Canlı sağlık kontrolleri — formülle
A5: Kontrol | B5: Sonuç | C5: Değer
A6: Dolu kayıt > 0 | B6: =IF(kpg_doluKayit>0,"GEÇTİ","KALDI") | C6: =kpg_doluKayit
A7: Yetim kayıt = 0 | B7: =IF(kpg_yetimAdet=0,"GEÇTİ","UYARI") | C7: =kpg_yetimAdet
A8: Doluluk hesaplı | B8: =IF(kpg_ortDoluluk>=0,"GEÇTİ","KALDI") | C8: =kpg_ortDoluluk
A9: Sağlık skor formül | B9: =IF(kpg_saglikSkor>=0,"GEÇTİ","KALDI") | C9: =kpg_saglikSkor
A10: Alarm listesi | B10: =IF(kpg_alarmAdet>=0,"GEÇTİ","KALDI") | C10: =kpg_alarmAdet
A11: Karar dolu | B11: =IF(kpg_kararKapi<>"","GEÇTİ","KALDI") | C11: =kpg_kararKapi
A12: 12 ay sezonsal | B12: =IF(DONEM_ANALIZ!B22>=0,"GEÇTİ","KALDI") | C12: =DONEM_ANALIZ!B22
A13: Kalite skor | B13: =IF(kpg_kaliteSkor>=0,"GEÇTİ","KALDI") | C13: =kpg_kaliteSkor
A14: Tornado | B14: =IF(kpg_tornadoZirve>=0,"GEÇTİ","KALDI") | C14: =kpg_tornadoZirve
A15: P90 | B15: =IF(kpg_yuzdelikP90>=0,"GEÇTİ","KALDI") | C15: =kpg_yuzdelikP90

Sheet ORNEK_VERI
A1: ORNEK VERI — Kira Portföyü Getiri Komutası
A3: Örnek günlük satırlar — kopyalanabilir referans
A5: SatirId | B5: VarlikId | C5: Tarih | D5: TahsilatTl_tl | E5: BosGun_gun | F5: GiderTl_tl | G5: TufeOran_oran | H5: OlayTuru
A6: KPG-00001 | B6: KIR-00001 | C6: 46242 | D6: 24640 | E6: 0 | F6: 1270 | G6: 0.39 | H6: BOSLUK
A7: KPG-00002 | B7: KIR-00002 | C7: 46239 | D7: 20020 | E7: 0 | F7: 1740 | G7: 0.4 | H7: ARTIS_TUFE
A8: KPG-00003 | B8: KIR-00003 | C8: 46236 | D8: 15792 | E8: 2 | F8: 2210 | G8: 0.38 | H8: GIDER
A9: KPG-00004 | B9: KIR-00004 | C9: 46233 | D9: 13580 | E9: 0 | F9: 2200 | G9: 0.39 | H9: TAHSILAT_GECIKME
A10: KPG-00005 | B10: KIR-00005 | C10: 46230 | D10: 18417 | E10: 5 | F10: 2670 | G10: 0.4 | H10: DIGER
A11: KPG-00006 | B11: KIR-00006 | C11: 46227 | D11: 9856 | E11: 2 | F11: 1040 | G11: 0.38 | H11: TAHSILAT
A12: KPG-00007 | B12: KIR-00007 | C12: 46224 | D12: 10010 | E12: 0 | F12: 1510 | G12: 0.39 | H12: BOSLUK
A13: KPG-00008 | B13: KIR-00008 | C13: 46221 | D13: 8930 | E13: 0 | F13: 1500 | G13: 0.4 | H13: ARTIS_TUFE
A14: KPG-00009 | B14: KIR-00001 | C14: 46218 | D14: 25349 | E14: 2 | F14: 1970 | G14: 0.44 | H14: GIDER
A15: KPG-00010 | B15: KIR-00002 | C15: 46215 | D15: 16830 | E15: 3 | F15: 2440 | G15: 0.39 | H15: TAHSILAT_GECIKME
A16: KPG-00011 | B16: KIR-00003 | C16: 46212 | D16: 15840 | E16: 0 | F16: 2910 | G16: 0.4 | H16: DIGER
A17: KPG-00012 | B17: KIR-00004 | C17: 46209 | D17: 11891 | E17: 2 | F17: 800 | G17: 0.38 | H17: TAHSILAT
... A25: KPG-00020 | B25: KIR-00004 | C25: 46185 | D25: 9520 | E25: 6 | F25: 1500 | G25: 0.4 | H25: ARTIS_TUFE

Sheet LISTELER
A1: LISTELER — Kira Portföyü Getiri Komutası
A3: Evet / Hayır | C3: Olay Türü | E3: Mülk Tipi
A6: Secim | C6: Tur | E6: Tip
A7: EVET | C7: TAHSILAT | E7: Daire
A8: HAYIR | C8: BOSLUK | E8: Ofis
C9: ARTIS_TUFE | E9: Dukkan
C10: GIDER | E10: Depo
C11: TAHSILAT_GECIKME
C12: DIGER

Sheet AYARLAR
A1: AYARLAR — Kira Portföyü Getiri Komutası
A3: Tek kaynak parametreler + alarm eşikleri (S05)
A5: anahtar | B5: deger | C5: birim | D5: kaynak | E5: yururluk_tarihi | F5: aciklama
A6: raporTarihi | B6: 46245 | C6: tarih | D6: Kullanıcı / dönem kapanışı | E6: 01.01.2026 | F6: Rapor tarihi (TODAY yok)
A7: kpg_varsayilanHedefKira | B7: 15000 | C7: TL | D7: Sözleşme / emsal kira | E7: 01.01.2026 | F7: Varsayılan aylık hedef kira
A8: kpg_esikDoluluk | B8: 0.85 | C8: oran | D8: Alarm eşiği — doluluk | E8: 01.01.2026 | F8: Doluluk alt alarm eşiği
A9: kpg_esikGetiri | B9: 0.8 | C9: oran | D9: Alarm eşiği — getiri | E9: 01.01.2026 | F9: Getiri (tahsilat/hedef) alt eşiği
A10: kpg_esikSaglik | B10: 60 | C10: puan | D10: Alarm eşiği — sağlık skor | E10: 01.01.2026 | F10: Sağlık skor alt eşiği
A11: kpg_gunAy | B11: 30 | C11: gun | D11: Dönem gün sayısı | E11: 01.01.2026 | F11: Doluluk hesabında ay günü
A12: kpg_aylikCarpan | B12: 1 | C12: oran | D12: Aylık proxy | E12: 01.01.2026 | F12: Aylık tahsilat çarpan
A13: kpg_senaryoTemkinli | B13: 0.9 | C13: oran | D13: Senaryo motoru | E13: 01.01.2026 | F13: Temkinli çarpan
A14: kpg_senaryoBaz | B14: 1 | C14: oran | D14: Senaryo motoru | E14: 01.01.2026 | F14: Baz çarpan
A15: kpg_senaryoIyimser | B15: 1.1 | C15: oran | D15: Senaryo motoru | E15: 01.01.2026 | F15: İyimser çarpan
A16: kpg_tornadoOran | B16: 0.08 | C16: oran | D16: Duyarlılık | E16: 01.01.2026 | F16: Tornado etki oranı
A17: kpg_yuzdelikOran | B17: 1.15 | C17: oran | D17: İstatistik kuralı | E17: 01.01.2026 | F17: P90 çarpan proxy
... A23: kpg_kaliteSapma | B23: 3 | C23: puan | D23: Kalite / sağlık modeli | E23: 01.01.2026 | F23: Sapma / alarm cezası
A24: kpg_dosyaSurumu | B24: 1.0.0 | C24: metin | D24: Sürüm yönetimi | E24: 01.01.2026 | F24: Ürün sürümü
A25: kpg_firmaUnvan | B25: Örnek Portföy Gayrimenkul A.Ş. | C25: metin | D25: Kullanıcı girişi | E25: 01.01.2026 | F25: Firma unvanı
A26: kpg_alarmEsikMetin | B26: Doluluk / getiri / sağlık eşikleri | C26: metin | D26: S05 alarm | E26: 01.01.2026 | F26: Alarm eşiği tanımı
A27: kpg_tufeReferans | B27: 0.4 | C27: oran | D27: TÜFE referans (elle) | E27: 01.01.2026 | F27: Varsayılan TÜFE referansı — API yok
A28: kpg_boslukMaliyetCarpan | B28: 1 | C28: oran | D28: Boşluk maliyet modeli | E28: 01.01.2026 | F28: Boş gün maliyet çarpanı
H32: Motor Çıktıları
H33: anahtar | I33: deger
H34: kpg_doluKayit | I34: =HESAP!C7
H35: kpg_toplamTahsilat | I35: =HESAP!C8
H36: kpg_toplamGider | I36: =HESAP!C10
H37: kpg_ortDoluluk | I37: =HESAP!C12
H38: kpg_ortGetiri | I38: =HESAP!C13
H39: kpg_netTahsilat | I39: =HESAP!C14
H40: kpg_gunlukDolulukOrt | I40: =HESAP!C24
H41: kpg_aylikTahsilatTrend | I41: =HESAP!C25
H42: kpg_saglikSkor | I42: =HESAP!C19
H43: kpg_alarmAdet | I43: =HESAP!C17
H44: kpg_yetimAdet | I44: =HESAP!C18
H45: kpg_getiriSapma | I45: =HESAP!C26
H46: kpg_tornadoZirve | I46: =HESAP!C38
H47: kpg_senaryoKarsilastirma | I47: =HESAP!C34
H48: kpg_hhi | I48: =HESAP!C39
