Workbook

Sheet PANO
B2: 13 HAFTALIK NAKİT AKIŞI VE ÖDEME PLANLAMA SİSTEMİ | L2: Dönem: 2026 / Tam ▼ | M2: ★ DOĞRULANMIŞ
B3: Yönetici Karar Kokpiti, Otomatik Doğrulama ve Dinamik Hesaplama Sistemi · 2026
B5: TOPLAM NAKİT HAVUZU | D5: 4 HESAP | E5: BU AY ÖDENECEK ÇIKIŞ | G5: VADE: 4 GÜN | H5: NET SERBEST LİKİDİTE | J5: GÜVENLİ | K5: DSCR / NAKİT DÖNGÜSÜ | M5: EŞİK: 1.30x
B7: ₺34.850.000 | E7: ₺2.480.000 | H7: ₺18.420.000 | K7: 2.14x
B9: ↑ %14.2 konsolide vadesiz + fon | E9: ● 8 Kalem nakit karşılığı: bloke | H9: ██████████░░░░░ %52.8 ORAN | K9: ✓ İDEAL borç servis karşılama
B11: 12 AYLIK NAKİT GİRİŞ / ÇIKIŞ & LİKİDİTE BAŞARIMI | F11: +%32 Verim | H11: KONSOLİDE OPERASYON VE KARAR MATRİSİ
B12: Kümülatif Tahsilat vs. Tedarikçi/Kredi Ödeme Projeksiyonu | H12: Anlık Hesaplama Sonuçları, Dinamik Formül Çıktıları ve Durum Puanlaması
B14: Dönem | C14: Aktif Hacim | D14: Maliyet/Yük | E14: Hedef | H14: PARAMETRE / KALEM | I14: ANA TUTAR | J14: FARK / MARJ | K14: VADE | L14: KONTROL DURUMU
B15: D1 | C15: 65 | D15: 45 | E15: 60 | H15: 13 haftalık kümülatif bakiye... | I15: ₺8.450.000 | J15: ₺425.000 | K15: 12 Ay | L15: ✓ DÜZENLİ
B16: D2 | C16: 78 | D16: 48 | E16: 70 | H16: Kritik (eksi) hafta uyarısı | I16: ₺12.200.000 | J16: ₺580.400 | K16: 24 Ay | L16: ★ AVANTAJ
B17: D3 | C17: 85 | D17: 55 | E17: 80 | H17: Dönem net nakit değişimi | I17: ₺4.850.000 | J17: ₺235.200 | K17: 8 Ay | L17: ● YAKLAŞAN
B18: D4 | C18: 75 | D18: 42 | E18: 75 | H18: 13 haftalık kümülatif bakiye... | I18: ₺2.140.000 | J18: ₺118.000 | K18: 16 Ay | L18: ✓ TAM UYUM
B19: D5 | C19: 90 | D19: 40 | E19: 85 | H19: KONSOLİDE SİSTEM TOPLAMI | I19: ₺42.850.000 | J19: ₺3.420.000 | L19: TAM DOĞRULANDI (0 HATA)
B20: D6 | C20: 96 | D20: 32 | E20: 92
B22: KONSOLİDE PAY VE AĞIRLIK | F22: LİKİDİTE RİSKİ & ERKEN UYARI SİNYALLERİ | K22: KARAR MOTORU
B23: ■ Ana Segment (%42) | F23: Nakit Açığı Riski (30 Gün) | I23: 0.00 TL (Sıfır Risk) | K23: LİKİDİTE OPTİMİZASYON FIRSATI
B24: ■ İkincil Grup (%30) | F24: Tahsilat Gecikme Toleransı | I24: 48 Gün Güvenli Eşik | K24: Atıl kalan ₺4.2M nakit rezervinin gecelik repoda değerlendirilmesiyle ek getiri.
B25: ■ Destek Birimi (%15) | F25: ██████████████████████████████████████ Güvenli Bölge (%100)
B26: ■ Rezervler (%13) | F26: ✓ 90 GÜNLÜK PROJEKSİYONDA NAKİT SIKIŞIKLIĞI TESPİT EDİLMEDİ | K26: FONLAMA SENARYOSUNU İNCELE >

Sheet GİRDİLER
B3: 🔍 Kayıt veya hesap ara... | G3: TOPLAM: 1.450 KAYIT | I3: HATALI HÜCRE: 0 ADET
B5: TARİH | C5: REFERANS NO | D5: İŞLEM AÇIKLAMASI VE DETAY | E5: BRÜT TUTAR (₺) | F5: KDV ORANI | G5: NET TUTAR (₺) | H5: HESAP / CARİ | I5: DURUM
B6: 12.10.2026 | C6: TR-0428-A | D6: Haftalık nakit girişi tahmini | E6: 845200 | F6: 0.2 | G6: =E6/(1+F6) | H6: Vadesiz Ticari | I6: ONAYLANDI
B7: 14.10.2026 | C7: TR-0429-B | D7: Haftalık nakit çıkışı tahmini | E7: 1240000 | F7: 0.2 | G7: =E7/(1+F7) | H7: Tedarikçi Havuzu | I7: BEKLEMEDE
B8: 18.10.2026 | C8: TR-0430-C | D8: Ödeme takvimi notları | E8: 620500 | F8: 0.1 | G8: =E8/(1+F8) | H8: Kısa Vade Tahakkuk | I8: ONAYLANDI
B9: 21.10.2026 | C9: TR-0431-D | D9: Haftalık nakit girişi tahmini | E9: 415000 | F9: 0.2 | G9: =E9/(1+F9) | H9: Müşteri Alacağı | I9: ONAYLANDI
B10: 25.10.2026 | C10: TR-0432-E | D10: Haftalık nakit girişi tahmini | E10: 980400 | F10: 0.2 | G10: =E10/(1+F10) | H10: Vadesiz Ticari | I10: ONAYLANDI
B11: 28.10.2026 | C11: TR-0433-F | D11: Haftalık nakit çıkışı tahmini | E11: 1850000 | F11: 0.2 | G11: =E11/(1+F11) | H11: Banka Kredi Taksiti | I11: BLOKE
B12: 02.11.2026 | C12: TR-0434-G | D12: Ödeme takvimi notları | E12: 740000 | F12: 0.2 | G12: =E12/(1+F12) | H12: Kira & Sabit Gider | I12: ONAYLANDI
B13: 05.11.2026 | C13: TR-0435-H | D13: Haftalık nakit girişi tahmini | E13: 520800 | F13: 0.2 | G13: =E13/(1+F13) | H13: Vadesiz Ticari | I13: ONAYLANDI
B14: 09.11.2026 | C14: TR-0436-I | D14: Haftalık nakit girişi tahmini | E14: 1120000 | F14: 0.2 | G14: =E14/(1+F14) | H14: Müşteri Alacağı | I14: ONAYLANDI
B15: 12.11.2026 | C15: TR-0437-J | D15: Haftalık nakit çıkışı tahmini | E15: 890000 | F15: 0.2 | G15: =E15/(1+F15) | H15: Tedarikçi Havuzu | I15: ONAYLANDI
B17: SAYFA TOPLAMI (10 / 1.450 KAYIT) | E17: =TOPLA(E6:E15)

Sheet YÖNETİM_RAPORU
B2: 13 HAFTALIK NAKİT AKIŞI VE ÖDEME PLANLAMA SİSTEMİ — NİHAİ KARAR VE DEĞERLEME
B3: Yönetim Kurulu ve İcra Komitesi için Otomatik Türetilen Finansal Stres Testi Raporu
B4: DÖNEM: 2026 Q3 · DENETİM PROTOKOLÜ: ISO/VUK/IFRS UYUMLU · DURUM: ONAYLANDI
B6: SENARYO A: KÖTÜMSER (STRES TESTİ -%20) | H6: SENARYO B: BAZ MODEL (HEDEFLENEN)
B8: Ciro / Hacim Düşüşü: | E8: -%20.0 (Kriz Eşiği) | H8: Ciro / Hacim Gerçekleşmesi: | K8: %100.0 (Tam Bütçe)
B9: Beklenen Net Kâr / Getiri: | E9: ₺4.280.000 | H9: Beklenen Net Kâr / Getiri: | K9: ₺12.450.000
B10: Minimum Nakit Tamponu: | E10: ₺1.850.000 (Yeterli) | H10: Serbest Nakit Akımı: | K10: ₺8.240.000
B11: Likidite Karşılama Oranı: | E11: 1.28x (Eşik: 1.10x) | H11: Yatırım Geri Dönüşü (ROI): | K11: %38.4 Yıllık
B14: STRES SENARYOSUNDA DAHİ İFLAS RİSKİ YOK | H14: OPTİMUM İCRA VE PLANLAMA REÇETESİ
B17: YÖNETİM KARAR MATRİSİ VE UYGULAMA REÇETESİ
B19: ● Öncelik 1: Acil Likidite ve Borç Servis Planlaması
B20: Sistemde hesaplanan vade günlerine sadık kalınarak nakit blokajı 3 gün önceden hazır edilmelidir.
B21: ● Öncelik 2: Formül Doğrulama ve Çapraz Sağlama
B22: Tüm hücreler kilitli formül korumasında olup girdi sayfalarında sıfır döngüsel başvuru (circular ref) garantilidir.
B23: ● Öncelik 3: Resmi Mevzuat ve Vergi Kalkanı Entegrasyonu
B24: 2026 güncel vergi dilimleri, amortisman ve SGK teşvik parametreleri tam otomatik yansıtılmaktadır.
B25: ● Öncelik 4: Yönetici İmzası ve Rapor Paylaşımı
B26: Tek tuşla PDF ve A4 çıktı formatına tam uyumlu sayfa yapısı kurgulanmıştır.

Sheet KAPAK
A1: KAPAK
A5: 13 HAFTALIK NAKİT AKIŞI VE ÖDEME PLANLAMA SİSTEMİ
A6: Paranın hangi hafta biteceğini önceden görün; hangi önlemi alacağınızı makine önersin.
A9: BU SİSTEM NEYİ ÇÖZER?
A10: • 13 haftalık nakit girişi ve çıkışı tek tabloda toplanır
A11: • Hafta hafta dönem sonu bakiye hesaplanır; para bitiş haftası otomatik işaretlenir
A12: • Kıtlık haftasında alınacak önlem (gider erteleme, tahsilat hızlandırma, kredi) makine önerir
A13: • İyimser/kötümser senaryo ve duyarlılık analizi ile planın güven aralığı görünür
A15: KİMLER İÇİN?
A16: KOBİ sahibi · finans yöneticisi · muhasebe sorumlusu · mali müşavir
A18: NASIL BAŞLARSINIZ?
A19: 1. AYARLAR sayfasında başlangıç bakiyesini ve eşikleri girin.
... A25: ExcelArşiv — Nakit Yönetimi Ürün Ailesi | Sürüm 1.0 | Lisans: Tek kullanıcılı, ticari kullanıma açık.

Sheet HIZLI_BASLANGIC
A1: HIZLI BASLANGIC — 13 HAFTALIK NAKİT AKIŞI VE ÖDEME PLANLAMA SİSTEMİ
A5: 3 ADIMDA SİSTEM
A7: ADIM 1 — AYARLAR
A8: Firma unvanı, rapor tarihi, başlangıç nakit bakiyesi ve asgari tampon eşiğini girin. Tüm eşikler tek yerden yönetilir; formüllere sabit sayı gömülmez.
A10: ADIM 2 — GİRİŞ VE ÇIKIŞ PLANI
A11: NAKIT_GIRISLERI sayfasına 13 haftalık beklenen tahsilatları, NAKIT_CIKISLARI sayfasına ödenmesi planlanan giderleri girin. Her kayıtta hafta numarası, tutar, kaynak/kalem, güvence ve öncelik bilgisi girilir.
A13: ADIM 3 — KARAR VE RAPOR
A14: HAFTALIK_PLAN hafta hafta bakiyeyi hesaplar; KONTROLLER veri kalitesini, KARAR_MOTORU para bitiş haftasını ve önlem önerisini üretir; PANO tek ekranda özeti gösterir; RAPOR sayfası PDF çıktısına hazırdır.
A19: SIK YAPILAN HATALAR
A20: • Tutarı eksi işaretle girmek: tutarlar daima pozitiftir, yön NAKIT_GIRISLERI / NAKIT_CIKISLARI seçimiyle belirlenir.
A21: • Güvence kolonunu boş bırakmak: güvence, veri kalite skorunu ve güven aralığını etkiler.
A22: • Hafta numarası yerine tarih girmek: her kayıt mutlaka 1-13 arası hafta numarası taşımalıdır.

Sheet NAKIT_GIRISLERI
A1: NAKIT GIRISLERI — 13 HAFTALIK NAKİT AKIŞI VE ÖDEME PLANLAMA SİSTEMİ
A3: 13 HAFTALIK NAKİT GİRİŞ PLANI — beklenen tahsilat, satış ve finansman kaynaklarını girin.
A5: Hafta Numarası | B5: Beklenen Tarih | C5: Güvence | D5: Kaynak | E5: Tutar (₺) | F5: Hesap | G5: Kontrol | H5: Açıklama
A6: 1 | B6: 46244 | C6: KESİN | D6: MÜŞTERİ TAHSİLATI | E6: 85000 | F6: =IF($A6="","",$E6) | G6: =IF($A6="","",IF(OR($A6="",$E6=""),"EKSİK",IF($E6<=0,"SIFIR/NEGATİF",IF($E6>AsiriGirisTutari,"AŞIRI TUTAR","OK")))) | H6: Örnek tahsilat kaydı — MÜŞTERİ TAHSİLATI
A7: 1 | B7: 46244 | C7: BEKLENEN | D7: SATIŞ | E7: 120000 | F7: =IF($A7="","",$E7) | G7: =IF($A7="","",IF(OR($A7="",$E7=""),"EKSİK",IF($E7<=0,"SIFIR/NEGATİF",IF($E7>AsiriGirisTutari,"AŞIRI TUTAR","OK")))) | H7: Örnek tahsilat kaydı — SATIŞ
A8: 2 | B8: 46251 | C8: KESİN | D8: MÜŞTERİ TAHSİLATI | E8: 95000 | F8: =IF($A8="","",$E8) | G8: =IF($A8="","",IF(OR($A8="",$E8=""),"EKSİK",IF($E8<=0,"SIFIR/NEGATİF",IF($E8>AsiriGirisTutari,"AŞIRI TUTAR","OK")))) | H8: Örnek tahsilat kaydı — MÜŞTERİ TAHSİLATI
A9: 2 | B9: 46251 | C9: BEKLENEN | D9: SATIŞ | E9: 110000 | F9: =IF($A9="","",$E9) | G9: =IF($A9="","",IF(OR($A9="",$E9=""),"EKSİK",IF($E9<=0,"SIFIR/NEGATİF",IF($E9>AsiriGirisTutari,"AŞIRI TUTAR","OK")))) | H9: Örnek tahsilat kaydı — SATIŞ
A10: 3 | B10: 46258 | C10: KESİN | D10: MÜŞTERİ TAHSİLATI | E10: 80000 | F10: =IF($A10="","",$E10) | G10: =IF($A10="","",IF(OR($A10="",$E10=""),"EKSİK",IF($E10<=0,"SIFIR/NEGATİF",IF($E10>AsiriGirisTutari,"AŞIRI TUTAR","OK")))) | H10: Örnek tahsilat kaydı — MÜŞTERİ TAHSİLATI
A11: 3 | B11: 46258 | C11: BEKLENEN | D11: SATIŞ | E11: 100000 | F11: =IF($A11="","",$E11) | G11: =IF($A11="","",IF(OR($A11="",$E11=""),"EKSİK",IF($E11<=0,"SIFIR/NEGATİF",IF($E11>AsiriGirisTutari,"AŞIRI TUTAR","OK")))) | H11: Örnek tahsilat kaydı — SATIŞ
A12: 3 | B12: 46258 | C12: BELİRSİZ | D12: FİNANSMAN | E12: 150000 | F12: =IF($A12="","",$E12) | G12: =IF($A12="","",IF(OR($A12="",$E12=""),"EKSİK",IF($E12<=0,"SIFIR/NEGATİF",IF($E12>AsiriGirisTutari,"AŞIRI TUTAR","OK")))) | H12: Örnek tahsilat kaydı — FİNANSMAN
A13: 4 | B13: 46265 | C13: KESİN | D13: MÜŞTERİ TAHSİLATI | E13: 90000 | F13: =IF($A13="","",$E13) | G13: =IF($A13="","",IF(OR($A13="",$E13=""),"EKSİK",IF($E13<=0,"SIFIR/NEGATİF",IF($E13>AsiriGirisTutari,"AŞIRI TUTAR","OK")))) | H13: Örnek tahsilat kaydı — MÜŞTERİ TAHSİLATI
A14: 4 | B14: 46265 | C14: BEKLENEN | D14: SATIŞ | E14: 130000 | F14: =IF($A14="","",$E14) | G14: =IF($A14="","",IF(OR($A14="",$E14=""),"EKSİK",IF($E14<=0,"SIFIR/NEGATİF",IF($E14>AsiriGirisTutari,"AŞIRI TUTAR","OK")))) | H14: Örnek tahsilat kaydı — SATIŞ
A15: 5 | B15: 46272 | C15: KESİN | D15: MÜŞTERİ TAHSİLATI | E15: 70000 | F15: =IF($A15="","",$E15) | G15: =IF($A15="","",IF(OR($A15="",$E15=""),"EKSİK",IF($E15<=0,"SIFIR/NEGATİF",IF($E15>AsiriGirisTutari,"AŞIRI TUTAR","OK")))) | H15: Örnek tahsilat kaydı — MÜŞTERİ TAHSİLATI
A16: 5 | B16: 46272 | C16: BEKLENEN | D16: SATIŞ | E16: 95000 | F16: =IF($A16="","",$E16) | G16: =IF($A16="","",IF(OR($A16="",$E16=""),"EKSİK",IF($E16<=0,"SIFIR/NEGATİF",IF($E16>AsiriGirisTutari,"AŞIRI TUTAR","OK")))) | H16: Örnek tahsilat kaydı — SATIŞ
A17: 6 | B17: 46279 | C17: KESİN | D17: MÜŞTERİ TAHSİLATI | E17: 110000 | F17: =IF($A17="","",$E17) | G17: =IF($A17="","",IF(OR($A17="",$E17=""),"EKSİK",IF($E17<=0,"SIFIR/NEGATİF",IF($E17>AsiriGirisTutari,"AŞIRI TUTAR","OK")))) | H17: Örnek tahsilat kaydı — MÜŞTERİ TAHSİLATI
... A32: 13 | B32: 46328 | C32: BEKLENEN | D32: SATIŞ | E32: 120000 | F32: =IF($A32="","",$E32) | G32: =IF($A32="","",IF(OR($A32="",$E32=""),"EKSİK",IF($E32<=0,"SIFIR/NEGATİF",IF($E32>AsiriGirisTutari,"AŞIRI TUTAR","OK")))) | H32: Örnek tahsilat kaydı — SATIŞ
F33: =IF($A33="","",$E33) | G33: =IF($A33="","",IF(OR($A33="",$E33=""),"EKSİK",IF($E33<=0,"SIFIR/NEGATİF",IF($E33>AsiriGirisTutari,"AŞIRI TUTAR","OK"))))
F34: =IF($A34="","",$E34) | G34: =IF($A34="","",IF(OR($A34="",$E34=""),"EKSİK",IF($E34<=0,"SIFIR/NEGATİF",IF($E34>AsiriGirisTutari,"AŞIRI TUTAR","OK"))))
F35: =IF($A35="","",$E35) | G35: =IF($A35="","",IF(OR($A35="",$E35=""),"EKSİK",IF($E35<=0,"SIFIR/NEGATİF",IF($E35>AsiriGirisTutari,"AŞIRI TUTAR","OK"))))

Sheet NAKIT_CIKISLARI
A1: NAKIT CIKISLARI — 13 HAFTALIK NAKİT AKIŞI VE ÖDEME PLANLAMA SİSTEMİ
A3: 13 HAFTALIK NAKİT ÇIKIŞ PLANI — ödenmesi planlanan giderleri girin.
A5: Hafta Numarası | B5: Vade Tarihi | C5: Kalem | D5: Öncelik | E5: Tutar (₺) | F5: Hesap | G5: Kontrol | H5: Açıklama
A6: 1 | B6: 46244 | C6: MAAŞ | D6: KRİTİK | E6: 130000 | F6: =IF($A6="","",$E6) | G6: =IF($A6="","",IF(OR($A6="",$E6=""),"EKSİK",IF($E6<=0,"SIFIR/NEGATİF",IF($E6>AsiriCikisTutari,"AŞIRI TUTAR","OK")))) | H6: Örnek ödeme kaydı — MAAŞ
A7: 1 | B7: 46244 | C7: KİRA | D7: YÜKSEK | E7: 45000 | F7: =IF($A7="","",$E7) | G7: =IF($A7="","",IF(OR($A7="",$E7=""),"EKSİK",IF($E7<=0,"SIFIR/NEGATİF",IF($E7>AsiriCikisTutari,"AŞIRI TUTAR","OK")))) | H7: Örnek ödeme kaydı — KİRA
A8: 2 | B8: 46251 | C8: TEDARİKÇİ | D8: YÜKSEK | E8: 90000 | F8: =IF($A8="","",$E8) | G8: =IF($A8="","",IF(OR($A8="",$E8=""),"EKSİK",IF($E8<=0,"SIFIR/NEGATİF",IF($E8>AsiriCikisTutari,"AŞIRI TUTAR","OK")))) | H8: Örnek ödeme kaydı — TEDARİKÇİ
A9: 3 | B9: 46258 | C9: VERGİ | D9: KRİTİK | E9: 180000 | F9: =IF($A9="","",$E9) | G9: =IF($A9="","",IF(OR($A9="",$E9=""),"EKSİK",IF($E9<=0,"SIFIR/NEGATİF",IF($E9>AsiriCikisTutari,"AŞIRI TUTAR","OK")))) | H9: Örnek ödeme kaydı — VERGİ
A10: 3 | B10: 46258 | C10: SGK | D10: KRİTİK | E10: 75000 | F10: =IF($A10="","",$E10) | G10: =IF($A10="","",IF(OR($A10="",$E10=""),"EKSİK",IF($E10<=0,"SIFIR/NEGATİF",IF($E10>AsiriCikisTutari,"AŞIRI TUTAR","OK")))) | H10: Örnek ödeme kaydı — SGK
A11: 4 | B11: 46265 | C11: MAAŞ | D11: KRİTİK | E11: 130000 | F11: =IF($A11="","",$E11) | G11: =IF($A11="","",IF(OR($A11="",$E11=""),"EKSİK",IF($E11<=0,"SIFIR/NEGATİF",IF($E11>AsiriCikisTutari,"AŞIRI TUTAR","OK")))) | H11: Örnek ödeme kaydı — MAAŞ
A12: 5 | B12: 46272 | C12: TEDARİKÇİ | D12: YÜKSEK | E12: 85000 | F12: =IF($A12="","",$E12) | G12: =IF($A12="","",IF(OR($A12="",$E12=""),"EKSİK",IF($E12<=0,"SIFIR/NEGATİF",IF($E12>AsiriCikisTutari,"AŞIRI TUTAR","OK")))) | H12: Örnek ödeme kaydı — TEDARİKÇİ
A13: 6 | B13: 46279 | C13: KREDİ TAKSİTİ | D13: KRİTİK | E13: 60000 | F13: =IF($A13="","",$E13) | G13: =IF($A13="","",IF(OR($A13="",$E13=""),"EKSİK",IF($E13<=0,"SIFIR/NEGATİF",IF($E13>AsiriCikisTutari,"AŞIRI TUTAR","OK")))) | H13: Örnek ödeme kaydı — KREDİ TAKSİTİ
A14: 7 | B14: 46286 | C14: MAAŞ | D14: KRİTİK | E14: 130000 | F14: =IF($A14="","",$E14) | G14: =IF($A14="","",IF(OR($A14="",$E14=""),"EKSİK",IF($E14<=0,"SIFIR/NEGATİF",IF($E14>AsiriCikisTutari,"AŞIRI TUTAR","OK")))) | H14: Örnek ödeme kaydı — MAAŞ
A15: 7 | B15: 46286 | C15: KİRA | D15: YÜKSEK | E15: 45000 | F15: =IF($A15="","",$E15) | G15: =IF($A15="","",IF(OR($A15="",$E15=""),"EKSİK",IF($E15<=0,"SIFIR/NEGATİF",IF($E15>AsiriCikisTutari,"AŞIRI TUTAR","OK")))) | H15: Örnek ödeme kaydı — KİRA
A16: 8 | B16: 46293 | C16: TEDARİKÇİ | D16: YÜKSEK | E16: 95000 | F16: =IF($A16="","",$E16) | G16: =IF($A16="","",IF(OR($A16="",$E16=""),"EKSİK",IF($E16<=0,"SIFIR/NEGATİF",IF($E16>AsiriCikisTutari,"AŞIRI TUTAR","OK")))) | H16: Örnek ödeme kaydı — TEDARİKÇİ
A17: 9 | B17: 46300 | C17: VERGİ | D17: KRİTİK | E17: 140000 | F17: =IF($A17="","",$E17) | G17: =IF($A17="","",IF(OR($A17="",$E17=""),"EKSİK",IF($E17<=0,"SIFIR/NEGATİF",IF($E17>AsiriCikisTutari,"AŞIRI TUTAR","OK")))) | H17: Örnek ödeme kaydı — VERGİ
... A23: 13 | B23: 46328 | C23: KİRA | D23: YÜKSEK | E23: 45000 | F23: =IF($A23="","",$E23) | G23: =IF($A23="","",IF(OR($A23="",$E23=""),"EKSİK",IF($E23<=0,"SIFIR/NEGATİF",IF($E23>AsiriCikisTutari,"AŞIRI TUTAR","OK")))) | H23: Örnek ödeme kaydı — KİRA
F24: =IF($A24="","",$E24) | G24: =IF($A24="","",IF(OR($A24="",$E24=""),"EKSİK",IF($E24<=0,"SIFIR/NEGATİF",IF($E24>AsiriCikisTutari,"AŞIRI TUTAR","OK"))))
F25: =IF($A25="","",$E25) | G25: =IF($A25="","",IF(OR($A25="",$E25=""),"EKSİK",IF($E25<=0,"SIFIR/NEGATİF",IF($E25>AsiriCikisTutari,"AŞIRI TUTAR","OK"))))
F26: =IF($A26="","",$E26) | G26: =IF($A26="","",IF(OR($A26="",$E26=""),"EKSİK",IF($E26<=0,"SIFIR/NEGATİF",IF($E26>AsiriCikisTutari,"AŞIRI TUTAR","OK"))))
F27: =IF($A27="","",$E27) | G27: =IF($A27="","",IF(OR($A27="",$E27=""),"EKSİK",IF($E27<=0,"SIFIR/NEGATİF",IF($E27>AsiriCikisTutari,"AŞIRI TUTAR","OK"))))
F28: =IF($A28="","",$E28) | G28: =IF($A28="","",IF(OR($A28="",$E28=""),"EKSİK",IF($E28<=0,"SIFIR/NEGATİF",IF($E28>AsiriCikisTutari,"AŞIRI TUTAR","OK"))))
F29: =IF($A29="","",$E29) | G29: =IF($A29="","",IF(OR($A29="",$E29=""),"EKSİK",IF($E29<=0,"SIFIR/NEGATİF",IF($E29>AsiriCikisTutari,"AŞIRI TUTAR","OK"))))
F30: =IF($A30="","",$E30) | G30: =IF($A30="","",IF(OR($A30="",$E30=""),"EKSİK",IF($E30<=0,"SIFIR/NEGATİF",IF($E30>AsiriCikisTutari,"AŞIRI TUTAR","OK"))))
F31: =IF($A31="","",$E31) | G31: =IF($A31="","",IF(OR($A31="",$E31=""),"EKSİK",IF($E31<=0,"SIFIR/NEGATİF",IF($E31>AsiriCikisTutari,"AŞIRI TUTAR","OK"))))
F32: =IF($A32="","",$E32) | G32: =IF($A32="","",IF(OR($A32="",$E32=""),"EKSİK",IF($E32<=0,"SIFIR/NEGATİF",IF($E32>AsiriCikisTutari,"AŞIRI TUTAR","OK"))))
F33: =IF($A33="","",$E33) | G33: =IF($A33="","",IF(OR($A33="",$E33=""),"EKSİK",IF($E33<=0,"SIFIR/NEGATİF",IF($E33>AsiriCikisTutari,"AŞIRI TUTAR","OK"))))
F34: =IF($A34="","",$E34) | G34: =IF($A34="","",IF(OR($A34="",$E34=""),"EKSİK",IF($E34<=0,"SIFIR/NEGATİF",IF($E34>AsiriCikisTutari,"AŞIRI TUTAR","OK"))))
F35: =IF($A35="","",$E35) | G35: =IF($A35="","",IF(OR($A35="",$E35=""),"EKSİK",IF($E35<=0,"SIFIR/NEGATİF",IF($E35>AsiriCikisTutari,"AŞIRI TUTAR","OK"))))

Sheet HAFTALIK_PLAN
A1: HAFTALIK PLAN — 13 HAFTALIK NAKİT AKIŞI VE ÖDEME PLANLAMA SİSTEMİ
A3: HAFTA HAFTA NAKİT AKIŞI — giriş ve çıkış planlarından otomatik toplanır. | L3: Not: Dönem başı bakiye bir önceki haftanın dönem sonu bakiyesinden devralınır.
A5: Hafta Numarası | B5: Dönem Başlangıcı | C5: Dönem Bitişi | D5: Toplam Giriş | E5: Toplam Çıkış | F5: Net Akış | G5: Dönem Başı Bakiye | H5: Dönem Sonu Bakiye | I5: Durum | J5: Önlem Önerisi
A6: 1 | B6: =IF($A6="","",RaporTarihi+MIN(($A6-1)*HaftaUzunlugu,MaksTarihUfku)) | C6: =IF($A6="","",$B6+HaftaUzunlugu-1) | D6: =IF($A6="","",SUMIFS(NAKIT_GIRISLERI!$E$6:$E$5000,NAKIT_GIRISLERI!$A$6:$A$5000,$A6)) | E6: =IF($A6="","",SUMIFS(NAKIT_CIKISLARI!$E$6:$E$5000,NAKIT_CIKISLARI!$A$6:$A$5000,$A6)) | F6: =IF($A6="","",$D6-$E6) | G6: =IF($A6="","",IF($A6=1,BaslangicBakiye,N($H5))) | H6: =IF($A6="","",$G6+$F6) | I6: =IF($A6="","",IF($H6<0,"PARA BİTİYOR",IF($H6<AsgariTampon,"RİSK ALTINDA","YETERLİ"))) | J6: =IF($A6="","",IF($H6<0,"Gider ertele / tahsilat hızlandır",IF($H6<AsgariTampon,"Tampon altına dikkat: kritik ödemeleri ertele","Devam et")))
A7: 2 | B7: =IF($A7="","",RaporTarihi+MIN(($A7-1)*HaftaUzunlugu,MaksTarihUfku)) | C7: =IF($A7="","",$B7+HaftaUzunlugu-1) | D7: =IF($A7="","",SUMIFS(NAKIT_GIRISLERI!$E$6:$E$5000,NAKIT_GIRISLERI!$A$6:$A$5000,$A7)) | E7: =IF($A7="","",SUMIFS(NAKIT_CIKISLARI!$E$6:$E$5000,NAKIT_CIKISLARI!$A$6:$A$5000,$A7)) | F7: =IF($A7="","",$D7-$E7) | G7: =IF($A7="","",IF($A7=1,BaslangicBakiye,N($H6))) | H7: =IF($A7="","",$G7+$F7) | I7: =IF($A7="","",IF($H7<0,"PARA BİTİYOR",IF($H7<AsgariTampon,"RİSK ALTINDA","YETERLİ"))) | J7: =IF($A7="","",IF($H7<0,"Gider ertele / tahsilat hızlandır",IF($H7<AsgariTampon,"Tampon altına dikkat: kritik ödemeleri ertele","Devam et")))
A8: 3 | B8: =IF($A8="","",RaporTarihi+MIN(($A8-1)*HaftaUzunlugu,MaksTarihUfku)) | C8: =IF($A8="","",$B8+HaftaUzunlugu-1) | D8: =IF($A8="","",SUMIFS(NAKIT_GIRISLERI!$E$6:$E$5000,NAKIT_GIRISLERI!$A$6:$A$5000,$A8)) | E8: =IF($A8="","",SUMIFS(NAKIT_CIKISLARI!$E$6:$E$5000,NAKIT_CIKISLARI!$A$6:$A$5000,$A8)) | F8: =IF($A8="","",$D8-$E8) | G8: =IF($A8="","",IF($A8=1,BaslangicBakiye,N($H7))) | H8: =IF($A8="","",$G8+$F8) | I8: =IF($A8="","",IF($H8<0,"PARA BİTİYOR",IF($H8<AsgariTampon,"RİSK ALTINDA","YETERLİ"))) | J8: =IF($A8="","",IF($H8<0,"Gider ertele / tahsilat hızlandır",IF($H8<AsgariTampon,"Tampon altına dikkat: kritik ödemeleri ertele","Devam et")))
A9: 4 | B9: =IF($A9="","",RaporTarihi+MIN(($A9-1)*HaftaUzunlugu,MaksTarihUfku)) | C9: =IF($A9="","",$B9+HaftaUzunlugu-1) | D9: =IF($A9="","",SUMIFS(NAKIT_GIRISLERI!$E$6:$E$5000,NAKIT_GIRISLERI!$A$6:$A$5000,$A9)) | E9: =IF($A9="","",SUMIFS(NAKIT_CIKISLARI!$E$6:$E$5000,NAKIT_CIKISLARI!$A$6:$A$5000,$A9)) | F9: =IF($A9="","",$D9-$E9) | G9: =IF($A9="","",IF($A9=1,BaslangicBakiye,N($H8))) | H9: =IF($A9="","",$G9+$F9) | I9: =IF($A9="","",IF($H9<0,"PARA BİTİYOR",IF($H9<AsgariTampon,"RİSK ALTINDA","YETERLİ"))) | J9: =IF($A9="","",IF($H9<0,"Gider ertele / tahsilat hızlandır",IF($H9<AsgariTampon,"Tampon altına dikkat: kritik ödemeleri ertele","Devam et")))
A10: 5 | B10: =IF($A10="","",RaporTarihi+MIN(($A10-1)*HaftaUzunlugu,MaksTarihUfku)) | C10: =IF($A10="","",$B10+HaftaUzunlugu-1) | D10: =IF($A10="","",SUMIFS(NAKIT_GIRISLERI!$E$6:$E$5000,NAKIT_GIRISLERI!$A$6:$A$5000,$A10)) | E10: =IF($A10="","",SUMIFS(NAKIT_CIKISLARI!$E$6:$E$5000,NAKIT_CIKISLARI!$A$6:$A$5000,$A10)) | F10: =IF($A10="","",$D10-$E10) | G10: =IF($A10="","",IF($A10=1,BaslangicBakiye,N($H9))) | H10: =IF($A10="","",$G10+$F10) | I10: =IF($A10="","",IF($H10<0,"PARA BİTİYOR",IF($H10<AsgariTampon,"RİSK ALTINDA","YETERLİ"))) | J10: =IF($A10="","",IF($H10<0,"Gider ertele / tahsilat hızlandır",IF($H10<AsgariTampon,"Tampon altına dikkat: kritik ödemeleri ertele","Devam et")))
A11: 6 | B11: =IF($A11="","",RaporTarihi+MIN(($A11-1)*HaftaUzunlugu,MaksTarihUfku)) | C11: =IF($A11="","",$B11+HaftaUzunlugu-1) | D11: =IF($A11="","",SUMIFS(NAKIT_GIRISLERI!$E$6:$E$5000,NAKIT_GIRISLERI!$A$6:$A$5000,$A11)) | E11: =IF($A11="","",SUMIFS(NAKIT_CIKISLARI!$E$6:$E$5000,NAKIT_CIKISLARI!$A$6:$A$5000,$A11)) | F11: =IF($A11="","",$D11-$E11) | G11: =IF($A11="","",IF($A11=1,BaslangicBakiye,N($H10))) | H11: =IF($A11="","",$G11+$F11) | I11: =IF($A11="","",IF($H11<0,"PARA BİTİYOR",IF($H11<AsgariTampon,"RİSK ALTINDA","YETERLİ"))) | J11: =IF($A11="","",IF($H11<0,"Gider ertele / tahsilat hızlandır",IF($H11<AsgariTampon,"Tampon altına dikkat: kritik ödemeleri ertele","Devam et")))
A12: 7 | B12: =IF($A12="","",RaporTarihi+MIN(($A12-1)*HaftaUzunlugu,MaksTarihUfku)) | C12: =IF($A12="","",$B12+HaftaUzunlugu-1) | D12: =IF($A12="","",SUMIFS(NAKIT_GIRISLERI!$E$6:$E$5000,NAKIT_GIRISLERI!$A$6:$A$5000,$A12)) | E12: =IF($A12="","",SUMIFS(NAKIT_CIKISLARI!$E$6:$E$5000,NAKIT_CIKISLARI!$A$6:$A$5000,$A12)) | F12: =IF($A12="","",$D12-$E12) | G12: =IF($A12="","",IF($A12=1,BaslangicBakiye,N($H11))) | H12: =IF($A12="","",$G12+$F12) | I12: =IF($A12="","",IF($H12<0,"PARA BİTİYOR",IF($H12<AsgariTampon,"RİSK ALTINDA","YETERLİ"))) | J12: =IF($A12="","",IF($H12<0,"Gider ertele / tahsilat hızlandır",IF($H12<AsgariTampon,"Tampon altına dikkat: kritik ödemeleri ertele","Devam et")))
A13: 8 | B13: =IF($A13="","",RaporTarihi+MIN(($A13-1)*HaftaUzunlugu,MaksTarihUfku)) | C13: =IF($A13="","",$B13+HaftaUzunlugu-1) | D13: =IF($A13="","",SUMIFS(NAKIT_GIRISLERI!$E$6:$E$5000,NAKIT_GIRISLERI!$A$6:$A$5000,$A13)) | E13: =IF($A13="","",SUMIFS(NAKIT_CIKISLARI!$E$6:$E$5000,NAKIT_CIKISLARI!$A$6:$A$5000,$A13)) | F13: =IF($A13="","",$D13-$E13) | G13: =IF($A13="","",IF($A13=1,BaslangicBakiye,N($H12))) | H13: =IF($A13="","",$G13+$F13) | I13: =IF($A13="","",IF($H13<0,"PARA BİTİYOR",IF($H13<AsgariTampon,"RİSK ALTINDA","YETERLİ"))) | J13: =IF($A13="","",IF($H13<0,"Gider ertele / tahsilat hızlandır",IF($H13<AsgariTampon,"Tampon altına dikkat: kritik ödemeleri ertele","Devam et")))
A14: 9 | B14: =IF($A14="","",RaporTarihi+MIN(($A14-1)*HaftaUzunlugu,MaksTarihUfku)) | C14: =IF($A14="","",$B14+HaftaUzunlugu-1) | D14: =IF($A14="","",SUMIFS(NAKIT_GIRISLERI!$E$6:$E$5000,NAKIT_GIRISLERI!$A$6:$A$5000,$A14)) | E14: =IF($A14="","",SUMIFS(NAKIT_CIKISLARI!$E$6:$E$5000,NAKIT_CIKISLARI!$A$6:$A$5000,$A14)) | F14: =IF($A14="","",$D14-$E14) | G14: =IF($A14="","",IF($A14=1,BaslangicBakiye,N($H13))) | H14: =IF($A14="","",$G14+$F14) | I14: =IF($A14="","",IF($H14<0,"PARA BİTİYOR",IF($H14<AsgariTampon,"RİSK ALTINDA","YETERLİ"))) | J14: =IF($A14="","",IF($H14<0,"Gider ertele / tahsilat hızlandır",IF($H14<AsgariTampon,"Tampon altına dikkat: kritik ödemeleri ertele","Devam et")))
A15: 10 | B15: =IF($A15="","",RaporTarihi+MIN(($A15-1)*HaftaUzunlugu,MaksTarihUfku)) | C15: =IF($A15="","",$B15+HaftaUzunlugu-1) | D15: =IF($A15="","",SUMIFS(NAKIT_GIRISLERI!$E$6:$E$5000,NAKIT_GIRISLERI!$A$6:$A$5000,$A15)) | E15: =IF($A15="","",SUMIFS(NAKIT_CIKISLARI!$E$6:$E$5000,NAKIT_CIKISLARI!$A$6:$A$5000,$A15)) | F15: =IF($A15="","",$D15-$E15) | G15: =IF($A15="","",IF($A15=1,BaslangicBakiye,N($H14))) | H15: =IF($A15="","",$G15+$F15) | I15: =IF($A15="","",IF($H15<0,"PARA BİTİYOR",IF($H15<AsgariTampon,"RİSK ALTINDA","YETERLİ"))) | J15: =IF($A15="","",IF($H15<0,"Gider ertele / tahsilat hızlandır",IF($H15<AsgariTampon,"Tampon altına dikkat: kritik ödemeleri ertele","Devam et")))
A16: 11 | B16: =IF($A16="","",RaporTarihi+MIN(($A16-1)*HaftaUzunlugu,MaksTarihUfku)) | C16: =IF($A16="","",$B16+HaftaUzunlugu-1) | D16: =IF($A16="","",SUMIFS(NAKIT_GIRISLERI!$E$6:$E$5000,NAKIT_GIRISLERI!$A$6:$A$5000,$A16)) | E16: =IF($A16="","",SUMIFS(NAKIT_CIKISLARI!$E$6:$E$5000,NAKIT_CIKISLARI!$A$6:$A$5000,$A16)) | F16: =IF($A16="","",$D16-$E16) | G16: =IF($A16="","",IF($A16=1,BaslangicBakiye,N($H15))) | H16: =IF($A16="","",$G16+$F16) | I16: =IF($A16="","",IF($H16<0,"PARA BİTİYOR",IF($H16<AsgariTampon,"RİSK ALTINDA","YETERLİ"))) | J16: =IF($A16="","",IF($H16<0,"Gider ertele / tahsilat hızlandır",IF($H16<AsgariTampon,"Tampon altına dikkat: kritik ödemeleri ertele","Devam et")))
A17: 12 | B17: =IF($A17="","",RaporTarihi+MIN(($A17-1)*HaftaUzunlugu,MaksTarihUfku)) | C17: =IF($A17="","",$B17+HaftaUzunlugu-1) | D17: =IF($A17="","",SUMIFS(NAKIT_GIRISLERI!$E$6:$E$5000,NAKIT_GIRISLERI!$A$6:$A$5000,$A17)) | E17: =IF($A17="","",SUMIFS(NAKIT_CIKISLARI!$E$6:$E$5000,NAKIT_CIKISLARI!$A$6:$A$5000,$A17)) | F17: =IF($A17="","",$D17-$E17) | G17: =IF($A17="","",IF($A17=1,BaslangicBakiye,N($H16))) | H17: =IF($A17="","",$G17+$F17) | I17: =IF($A17="","",IF($H17<0,"PARA BİTİYOR",IF($H17<AsgariTampon,"RİSK ALTINDA","YETERLİ"))) | J17: =IF($A17="","",IF($H17<0,"Gider ertele / tahsilat hızlandır",IF($H17<AsgariTampon,"Tampon altına dikkat: kritik ödemeleri ertele","Devam et")))
A18: 13 | B18: =IF($A18="","",RaporTarihi+MIN(($A18-1)*HaftaUzunlugu,MaksTarihUfku)) | C18: =IF($A18="","",$B18+HaftaUzunlugu-1) | D18: =IF($A18="","",SUMIFS(NAKIT_GIRISLERI!$E$6:$E$5000,NAKIT_GIRISLERI!$A$6:$A$5000,$A18)) | E18: =IF($A18="","",SUMIFS(NAKIT_CIKISLARI!$E$6:$E$5000,NAKIT_CIKISLARI!$A$6:$A$5000,$A18)) | F18: =IF($A18="","",$D18-$E18) | G18: =IF($A18="","",IF($A18=1,BaslangicBakiye,N($H17))) | H18: =IF($A18="","",$G18+$F18) | I18: =IF($A18="","",IF($H18<0,"PARA BİTİYOR",IF($H18<AsgariTampon,"RİSK ALTINDA","YETERLİ"))) | J18: =IF($A18="","",IF($H18<0,"Gider ertele / tahsilat hızlandır",IF($H18<AsgariTampon,"Tampon altına dikkat: kritik ödemeleri ertele","Devam et")))
B19: =IF($A19="","",RaporTarihi+MIN(($A19-1)*HaftaUzunlugu,MaksTarihUfku)) | C19: =IF($A19="","",$B19+HaftaUzunlugu-1) | D19: =IF($A19="","",SUMIFS(NAKIT_GIRISLERI!$E$6:$E$5000,NAKIT_GIRISLERI!$A$6:$A$5000,$A19)) | E19: =IF($A19="","",SUMIFS(NAKIT_CIKISLARI!$E$6:$E$5000,NAKIT_CIKISLARI!$A$6:$A$5000,$A19)) | F19: =IF($A19="","",$D19-$E19) | G19: =IF($A19="","",IF($A19=1,BaslangicBakiye,N($H18))) | H19: =IF($A19="","",$G19+$F19) | I19: =IF($A19="","",IF($H19<0,"PARA BİTİYOR",IF($H19<AsgariTampon,"RİSK ALTINDA","YETERLİ"))) | J19: =IF($A19="","",IF($H19<0,"Gider ertele / tahsilat hızlandır",IF($H19<AsgariTampon,"Tampon altına dikkat: kritik ödemeleri ertele","Devam et")))
B20: =IF($A20="","",RaporTarihi+MIN(($A20-1)*HaftaUzunlugu,MaksTarihUfku)) | C20: =IF($A20="","",$B20+HaftaUzunlugu-1) | D20: =IF($A20="","",SUMIFS(NAKIT_GIRISLERI!$E$6:$E$5000,NAKIT_GIRISLERI!$A$6:$A$5000,$A20)) | E20: =IF($A20="","",SUMIFS(NAKIT_CIKISLARI!$E$6:$E$5000,NAKIT_CIKISLARI!$A$6:$A$5000,$A20)) | F20: =IF($A20="","",$D20-$E20) | G20: =IF($A20="","",IF($A20=1,BaslangicBakiye,N($H19))) | H20: =IF($A20="","",$G20+$F20) | I20: =IF($A20="","",IF($H20<0,"PARA BİTİYOR",IF($H20<AsgariTampon,"RİSK ALTINDA","YETERLİ"))) | J20: =IF($A20="","",IF($H20<0,"Gider ertele / tahsilat hızlandır",IF($H20<AsgariTampon,"Tampon altına dikkat: kritik ödemeleri ertele","Devam et")))
B21: =IF($A21="","",RaporTarihi+MIN(($A21-1)*HaftaUzunlugu,MaksTarihUfku)) | C21: =IF($A21="","",$B21+HaftaUzunlugu-1) | D21: =IF($A21="","",SUMIFS(NAKIT_GIRISLERI!$E$6:$E$5000,NAKIT_GIRISLERI!$A$6:$A$5000,$A21)) | E21: =IF($A21="","",SUMIFS(NAKIT_CIKISLARI!$E$6:$E$5000,NAKIT_CIKISLARI!$A$6:$A$5000,$A21)) | F21: =IF($A21="","",$D21-$E21) | G21: =IF($A21="","",IF($A21=1,BaslangicBakiye,N($H20))) | H21: =IF($A21="","",$G21+$F21) | I21: =IF($A21="","",IF($H21<0,"PARA BİTİYOR",IF($H21<AsgariTampon,"RİSK ALTINDA","YETERLİ"))) | J21: =IF($A21="","",IF($H21<0,"Gider ertele / tahsilat hızlandır",IF($H21<AsgariTampon,"Tampon altına dikkat: kritik ödemeleri ertele","Devam et"))) | L21: Durum Dağılımı
B22: =IF($A22="","",RaporTarihi+MIN(($A22-1)*HaftaUzunlugu,MaksTarihUfku)) | C22: =IF($A22="","",$B22+HaftaUzunlugu-1) | D22: =IF($A22="","",SUMIFS(NAKIT_GIRISLERI!$E$6:$E$5000,NAKIT_GIRISLERI!$A$6:$A$5000,$A22)) | E22: =IF($A22="","",SUMIFS(NAKIT_CIKISLARI!$E$6:$E$5000,NAKIT_CIKISLARI!$A$6:$A$5000,$A22)) | F22: =IF($A22="","",$D22-$E22) | G22: =IF($A22="","",IF($A22=1,BaslangicBakiye,N($H21))) | H22: =IF($A22="","",$G22+$F22) | I22: =IF($A22="","",IF($H22<0,"PARA BİTİYOR",IF($H22<AsgariTampon,"RİSK ALTINDA","YETERLİ"))) | J22: =IF($A22="","",IF($H22<0,"Gider ertele / tahsilat hızlandır",IF($H22<AsgariTampon,"Tampon altına dikkat: kritik ödemeleri ertele","Devam et"))) | L22: YETERLİ | M22: =COUNTIFS(tblHaftaPlan[Durum],"YETERLİ")
B23: =IF($A23="","",RaporTarihi+MIN(($A23-1)*HaftaUzunlugu,MaksTarihUfku)) | C23: =IF($A23="","",$B23+HaftaUzunlugu-1) | D23: =IF($A23="","",SUMIFS(NAKIT_GIRISLERI!$E$6:$E$5000,NAKIT_GIRISLERI!$A$6:$A$5000,$A23)) | E23: =IF($A23="","",SUMIFS(NAKIT_CIKISLARI!$E$6:$E$5000,NAKIT_CIKISLARI!$A$6:$A$5000,$A23)) | F23: =IF($A23="","",$D23-$E23) | G23: =IF($A23="","",IF($A23=1,BaslangicBakiye,N($H22))) | H23: =IF($A23="","",$G23+$F23) | I23: =IF($A23="","",IF($H23<0,"PARA BİTİYOR",IF($H23<AsgariTampon,"RİSK ALTINDA","YETERLİ"))) | J23: =IF($A23="","",IF($H23<0,"Gider ertele / tahsilat hızlandır",IF($H23<AsgariTampon,"Tampon altına dikkat: kritik ödemeleri ertele","Devam et"))) | L23: RİSK ALTINDA | M23: =COUNTIFS(tblHaftaPlan[Durum],"RİSK ALTINDA")
B24: =IF($A24="","",RaporTarihi+MIN(($A24-1)*HaftaUzunlugu,MaksTarihUfku)) | C24: =IF($A24="","",$B24+HaftaUzunlugu-1) | D24: =IF($A24="","",SUMIFS(NAKIT_GIRISLERI!$E$6:$E$5000,NAKIT_GIRISLERI!$A$6:$A$5000,$A24)) | E24: =IF($A24="","",SUMIFS(NAKIT_CIKISLARI!$E$6:$E$5000,NAKIT_CIKISLARI!$A$6:$A$5000,$A24)) | F24: =IF($A24="","",$D24-$E24) | G24: =IF($A24="","",IF($A24=1,BaslangicBakiye,N($H23))) | H24: =IF($A24="","",$G24+$F24) | I24: =IF($A24="","",IF($H24<0,"PARA BİTİYOR",IF($H24<AsgariTampon,"RİSK ALTINDA","YETERLİ"))) | J24: =IF($A24="","",IF($H24<0,"Gider ertele / tahsilat hızlandır",IF($H24<AsgariTampon,"Tampon altına dikkat: kritik ödemeleri ertele","Devam et"))) | L24: PARA BİTİYOR | M24: =COUNTIFS(tblHaftaPlan[Durum],"PARA BİTİYOR")
B25: =IF($A25="","",RaporTarihi+MIN(($A25-1)*HaftaUzunlugu,MaksTarihUfku)) | C25: =IF($A25="","",$B25+HaftaUzunlugu-1) | D25: =IF($A25="","",SUMIFS(NAKIT_GIRISLERI!$E$6:$E$5000,NAKIT_GIRISLERI!$A$6:$A$5000,$A25)) | E25: =IF($A25="","",SUMIFS(NAKIT_CIKISLARI!$E$6:$E$5000,NAKIT_CIKISLARI!$A$6:$A$5000,$A25)) | F25: =IF($A25="","",$D25-$E25) | G25: =IF($A25="","",IF($A25=1,BaslangicBakiye,N($H24))) | H25: =IF($A25="","",$G25+$F25) | I25: =IF($A25="","",IF($H25<0,"PARA BİTİYOR",IF($H25<AsgariTampon,"RİSK ALTINDA","YETERLİ"))) | J25: =IF($A25="","",IF($H25<0,"Gider ertele / tahsilat hızlandır",IF($H25<AsgariTampon,"Tampon altına dikkat: kritik ödemeleri ertele","Devam et")))
B26: =IF($A26="","",RaporTarihi+MIN(($A26-1)*HaftaUzunlugu,MaksTarihUfku)) | C26: =IF($A26="","",$B26+HaftaUzunlugu-1) | D26: =IF($A26="","",SUMIFS(NAKIT_GIRISLERI!$E$6:$E$5000,NAKIT_GIRISLERI!$A$6:$A$5000,$A26)) | E26: =IF($A26="","",SUMIFS(NAKIT_CIKISLARI!$E$6:$E$5000,NAKIT_CIKISLARI!$A$6:$A$5000,$A26)) | F26: =IF($A26="","",$D26-$E26) | G26: =IF($A26="","",IF($A26=1,BaslangicBakiye,N($H25))) | H26: =IF($A26="","",$G26+$F26) | I26: =IF($A26="","",IF($H26<0,"PARA BİTİYOR",IF($H26<AsgariTampon,"RİSK ALTINDA","YETERLİ"))) | J26: =IF($A26="","",IF($H26<0,"Gider ertele / tahsilat hızlandır",IF($H26<AsgariTampon,"Tampon altına dikkat: kritik ödemeleri ertele","Devam et")))
B27: =IF($A27="","",RaporTarihi+MIN(($A27-1)*HaftaUzunlugu,MaksTarihUfku)) | C27: =IF($A27="","",$B27+HaftaUzunlugu-1) | D27: =IF($A27="","",SUMIFS(NAKIT_GIRISLERI!$E$6:$E$5000,NAKIT_GIRISLERI!$A$6:$A$5000,$A27)) | E27: =IF($A27="","",SUMIFS(NAKIT_CIKISLARI!$E$6:$E$5000,NAKIT_CIKISLARI!$A$6:$A$5000,$A27)) | F27: =IF($A27="","",$D27-$E27) | G27: =IF($A27="","",IF($A27=1,BaslangicBakiye,N($H26))) | H27: =IF($A27="","",$G27+$F27) | I27: =IF($A27="","",IF($H27<0,"PARA BİTİYOR",IF($H27<AsgariTampon,"RİSK ALTINDA","YETERLİ"))) | J27: =IF($A27="","",IF($H27<0,"Gider ertele / tahsilat hızlandır",IF($H27<AsgariTampon,"Tampon altına dikkat: kritik ödemeleri ertele","Devam et")))
B28: =IF($A28="","",RaporTarihi+MIN(($A28-1)*HaftaUzunlugu,MaksTarihUfku)) | C28: =IF($A28="","",$B28+HaftaUzunlugu-1) | D28: =IF($A28="","",SUMIFS(NAKIT_GIRISLERI!$E$6:$E$5000,NAKIT_GIRISLERI!$A$6:$A$5000,$A28)) | E28: =IF($A28="","",SUMIFS(NAKIT_CIKISLARI!$E$6:$E$5000,NAKIT_CIKISLARI!$A$6:$A$5000,$A28)) | F28: =IF($A28="","",$D28-$E28) | G28: =IF($A28="","",IF($A28=1,BaslangicBakiye,N($H27))) | H28: =IF($A28="","",$G28+$F28) | I28: =IF($A28="","",IF($H28<0,"PARA BİTİYOR",IF($H28<AsgariTampon,"RİSK ALTINDA","YETERLİ"))) | J28: =IF($A28="","",IF($H28<0,"Gider ertele / tahsilat hızlandır",IF($H28<AsgariTampon,"Tampon altına dikkat: kritik ödemeleri ertele","Devam et")))
B29: =IF($A29="","",RaporTarihi+MIN(($A29-1)*HaftaUzunlugu,MaksTarihUfku)) | C29: =IF($A29="","",$B29+HaftaUzunlugu-1) | D29: =IF($A29="","",SUMIFS(NAKIT_GIRISLERI!$E$6:$E$5000,NAKIT_GIRISLERI!$A$6:$A$5000,$A29)) | E29: =IF($A29="","",SUMIFS(NAKIT_CIKISLARI!$E$6:$E$5000,NAKIT_CIKISLARI!$A$6:$A$5000,$A29)) | F29: =IF($A29="","",$D29-$E29) | G29: =IF($A29="","",IF($A29=1,BaslangicBakiye,N($H28))) | H29: =IF($A29="","",$G29+$F29) | I29: =IF($A29="","",IF($H29<0,"PARA BİTİYOR",IF($H29<AsgariTampon,"RİSK ALTINDA","YETERLİ"))) | J29: =IF($A29="","",IF($H29<0,"Gider ertele / tahsilat hızlandır",IF($H29<AsgariTampon,"Tampon altına dikkat: kritik ödemeleri ertele","Devam et")))
B30: =IF($A30="","",RaporTarihi+MIN(($A30-1)*HaftaUzunlugu,MaksTarihUfku)) | C30: =IF($A30="","",$B30+HaftaUzunlugu-1) | D30: =IF($A30="","",SUMIFS(NAKIT_GIRISLERI!$E$6:$E$5000,NAKIT_GIRISLERI!$A$6:$A$5000,$A30)) | E30: =IF($A30="","",SUMIFS(NAKIT_CIKISLARI!$E$6:$E$5000,NAKIT_CIKISLARI!$A$6:$A$5000,$A30)) | F30: =IF($A30="","",$D30-$E30) | G30: =IF($A30="","",IF($A30=1,BaslangicBakiye,N($H29))) | H30: =IF($A30="","",$G30+$F30) | I30: =IF($A30="","",IF($H30<0,"PARA BİTİYOR",IF($H30<AsgariTampon,"RİSK ALTINDA","YETERLİ"))) | J30: =IF($A30="","",IF($H30<0,"Gider ertele / tahsilat hızlandır",IF($H30<AsgariTampon,"Tampon altına dikkat: kritik ödemeleri ertele","Devam et")))
B31: =IF($A31="","",RaporTarihi+MIN(($A31-1)*HaftaUzunlugu,MaksTarihUfku)) | C31: =IF($A31="","",$B31+HaftaUzunlugu-1) | D31: =IF($A31="","",SUMIFS(NAKIT_GIRISLERI!$E$6:$E$5000,NAKIT_GIRISLERI!$A$6:$A$5000,$A31)) | E31: =IF($A31="","",SUMIFS(NAKIT_CIKISLARI!$E$6:$E$5000,NAKIT_CIKISLARI!$A$6:$A$5000,$A31)) | F31: =IF($A31="","",$D31-$E31) | G31: =IF($A31="","",IF($A31=1,BaslangicBakiye,N($H30))) | H31: =IF($A31="","",$G31+$F31) | I31: =IF($A31="","",IF($H31<0,"PARA BİTİYOR",IF($H31<AsgariTampon,"RİSK ALTINDA","YETERLİ"))) | J31: =IF($A31="","",IF($H31<0,"Gider ertele / tahsilat hızlandır",IF($H31<AsgariTampon,"Tampon altına dikkat: kritik ödemeleri ertele","Devam et")))
B32: =IF($A32="","",RaporTarihi+MIN(($A32-1)*HaftaUzunlugu,MaksTarihUfku)) | C32: =IF($A32="","",$B32+HaftaUzunlugu-1) | D32: =IF($A32="","",SUMIFS(NAKIT_GIRISLERI!$E$6:$E$5000,NAKIT_GIRISLERI!$A$6:$A$5000,$A32)) | E32: =IF($A32="","",SUMIFS(NAKIT_CIKISLARI!$E$6:$E$5000,NAKIT_CIKISLARI!$A$6:$A$5000,$A32)) | F32: =IF($A32="","",$D32-$E32) | G32: =IF($A32="","",IF($A32=1,BaslangicBakiye,N($H31))) | H32: =IF($A32="","",$G32+$F32) | I32: =IF($A32="","",IF($H32<0,"PARA BİTİYOR",IF($H32<AsgariTampon,"RİSK ALTINDA","YETERLİ"))) | J32: =IF($A32="","",IF($H32<0,"Gider ertele / tahsilat hızlandır",IF($H32<AsgariTampon,"Tampon altına dikkat: kritik ödemeleri ertele","Devam et")))
B33: =IF($A33="","",RaporTarihi+MIN(($A33-1)*HaftaUzunlugu,MaksTarihUfku)) | C33: =IF($A33="","",$B33+HaftaUzunlugu-1) | D33: =IF($A33="","",SUMIFS(NAKIT_GIRISLERI!$E$6:$E$5000,NAKIT_GIRISLERI!$A$6:$A$5000,$A33)) | E33: =IF($A33="","",SUMIFS(NAKIT_CIKISLARI!$E$6:$E$5000,NAKIT_CIKISLARI!$A$6:$A$5000,$A33)) | F33: =IF($A33="","",$D33-$E33) | G33: =IF($A33="","",IF($A33=1,BaslangicBakiye,N($H32))) | H33: =IF($A33="","",$G33+$F33) | I33: =IF($A33="","",IF($H33<0,"PARA BİTİYOR",IF($H33<AsgariTampon,"RİSK ALTINDA","YETERLİ"))) | J33: =IF($A33="","",IF($H33<0,"Gider ertele / tahsilat hızlandır",IF($H33<AsgariTampon,"Tampon altına dikkat: kritik ödemeleri ertele","Devam et")))
B34: =IF($A34="","",RaporTarihi+MIN(($A34-1)*HaftaUzunlugu,MaksTarihUfku)) | C34: =IF($A34="","",$B34+HaftaUzunlugu-1) | D34: =IF($A34="","",SUMIFS(NAKIT_GIRISLERI!$E$6:$E$5000,NAKIT_GIRISLERI!$A$6:$A$5000,$A34)) | E34: =IF($A34="","",SUMIFS(NAKIT_CIKISLARI!$E$6:$E$5000,NAKIT_CIKISLARI!$A$6:$A$5000,$A34)) | F34: =IF($A34="","",$D34-$E34) | G34: =IF($A34="","",IF($A34=1,BaslangicBakiye,N($H33))) | H34: =IF($A34="","",$G34+$F34) | I34: =IF($A34="","",IF($H34<0,"PARA BİTİYOR",IF($H34<AsgariTampon,"RİSK ALTINDA","YETERLİ"))) | J34: =IF($A34="","",IF($H34<0,"Gider ertele / tahsilat hızlandır",IF($H34<AsgariTampon,"Tampon altına dikkat: kritik ödemeleri ertele","Devam et")))
B35: =IF($A35="","",RaporTarihi+MIN(($A35-1)*HaftaUzunlugu,MaksTarihUfku)) | C35: =IF($A35="","",$B35+HaftaUzunlugu-1) | D35: =IF($A35="","",SUMIFS(NAKIT_GIRISLERI!$E$6:$E$5000,NAKIT_GIRISLERI!$A$6:$A$5000,$A35)) | E35: =IF($A35="","",SUMIFS(NAKIT_CIKISLARI!$E$6:$E$5000,NAKIT_CIKISLARI!$A$6:$A$5000,$A35)) | F35: =IF($A35="","",$D35-$E35) | G35: =IF($A35="","",IF($A35=1,BaslangicBakiye,N($H34))) | H35: =IF($A35="","",$G35+$F35) | I35: =IF($A35="","",IF($H35<0,"PARA BİTİYOR",IF($H35<AsgariTampon,"RİSK ALTINDA","YETERLİ"))) | J35: =IF($A35="","",IF($H35<0,"Gider ertele / tahsilat hızlandır",IF($H35<AsgariTampon,"Tampon altına dikkat: kritik ödemeleri ertele","Devam et")))

Sheet MOTOR
A1: MOTOR — 13 HAFTALIK NAKİT AKIŞI VE ÖDEME PLANLAMA SİSTEMİ
A2: Hesaplama motoru: tüm ara hesaplar ve analitik modüller ad tanımlı hücrelerden beslenir. Değerler giriş tablolarından canlı hesaplanır; sabit sayı formüle gömülmez.
A4: TEMEL ARA HESAPLAR
A5: Giriş Kayıt Sayısı | B5: =IFERROR(COUNTIFS(tblGiris[Hafta Numarası],">0"),0)
A6: Çıkış Kayıt Sayısı | B6: =IFERROR(COUNTIFS(tblCikis[Hafta Numarası],">0"),0)
A7: Toplam Beklenen Giriş | B7: =IFERROR(SUM(tblGiris[Tutar (₺)]),0)
A8: Toplam Planlanan Çıkış | B8: =IFERROR(SUM(tblCikis[Tutar (₺)]),0)
A9: Net Nakit Akışı | B9: =B7-B8
A10: Dönem Sonu Bakiye (13. Hafta) | B10: =KARAR_MOTORU!$B$5
A11: Minimum Hafta Bakiyesi | B11: =IFERROR(MIN(tblHaftaPlan[Dönem Sonu Bakiye]),0)
A12: Maksimum Hafta Bakiyesi | B12: =IFERROR(MAX(tblHaftaPlan[Dönem Sonu Bakiye]),0)
A13: Ortalama Haftalık Net Akış | B13: =IFERROR(AVERAGE(tblHaftaPlan[Net Akış]),0)
A14: Net Akış Değişkenliği | B14: =IFERROR(stdev.p(tblHaftaPlan[Net Akış]),0)
A15: Kıtlık (Negatif Bakiye) Haftası | B15: =IFERROR(COUNTIF(tblHaftaPlan[Dönem Sonu Bakiye],"<0"),0)
A16: Tampon Altı Hafta Sayısı | B16: =IFERROR(COUNTIF(tblHaftaPlan[Dönem Sonu Bakiye],"<"&AsgariTampon),0)
A17: En Yüksek Çıkış Tutarı | B17: =IFERROR(MAX(tblHaftaPlan[Toplam Çıkış]),0)
A18: En Yüksek Çıkış Haftası | B18: =IFERROR(INDEX(tblHaftaPlan[Hafta Numarası],MATCH(B17,tblHaftaPlan[Toplam Çıkış],0)),0)
A19: Kritik Ödemeler Toplamı | B19: =IFERROR(SUMIFS(tblCikis[Tutar (₺)],tblCikis[Öncelik],"KRİTİK"),0)
A20: Ertelenebilir Ödemeler Toplamı | B20: =IFERROR(SUMIFS(tblCikis[Tutar (₺)],tblCikis[Öncelik],"ERTELENEBİLİR"),0)
A21: KESİN Giriş Toplamı | B21: =IFERROR(SUMIFS(tblGiris[Tutar (₺)],tblGiris[Güvence],"KESİN"),0)
A22: BELİRSİZ Giriş Toplamı | B22: =IFERROR(SUMIFS(tblGiris[Tutar (₺)],tblGiris[Güvence],"BELİRSİZ"),0)
A23: Giriş/Çıkış Karşılama Oranı | B23: =IFERROR(B7/MAX(1,B8),0)
A24: İlk 6 Hafta Net Akış | B24: =IFERROR(SUMIFS(tblHaftaPlan[Net Akış],tblHaftaPlan[Hafta Numarası],"<=6"),0)
A25: Son 7 Hafta Net Akış | B25: =IFERROR(SUMIFS(tblHaftaPlan[Net Akış],tblHaftaPlan[Hafta Numarası],">6"),0)
A28: Eksik Zorunlu Alan | B28: =KONTROLLER!$B$14
A29: Sıfır/Negatif Tutar | B29: =KONTROLLER!$B$15
A30: Aşırı Tutar Uyarısı | B30: =KONTROLLER!$B$16
A31: Dolu Giriş Kaydı | B31: =B5
A32: Dolu Çıkış Kaydı | B32: =B6
A33: Mutabakat Farkı | B33: =IFERROR(ABS(B7-B8-B9),0)
A34: Veri Kalite Skoru | B34: =KONTROLLER!$B$6
A37: ANALİTİK MODÜL HESAPLARI
A38: Modül T1: Kıtlık Hafta Sayısı | B38: =B15 | C38: =_xlfn.TEXTJOIN(" | ",TRUE(),"T1: Negatif bakiye haftası "&modulT1KirlikHafta,IF(modulT1KirlikHafta>0,"nakit kıtlığı öngörülüyor, önlem planı kurun","kıtlık haftası öngörülmüyor"))
A39: Modül T2: Net Akış Eğimi | B39: =IFERROR(SLOPE(tblHaftaPlan[Net Akış],tblHaftaPlan[Hafta Numarası]),0) | C39: =_xlfn.TEXTJOIN(" | ",TRUE(),"T2: Net akış eğimi "&TEXT(modulT2NetAkisEgimi,"#,##0")&" TL/hafta",IF(modulT2NetAkisEgimi<0,"nakit dengesi kötüleşiyor, gider yapısını gözden geçirin","nakit dengesi iyileşiyor"))
A40: Modül T3: Çıkışta Pareto Payı | B40: =IFERROR(B17/MAX(1,B8),0) | C40: =_xlfn.TEXTJOIN(" | ",TRUE(),"T3: En yüksek tek ödeme toplam çıkışın %"&TEXT(modulT3CikisPareto*100,"0")&"ı",IF(modulT3CikisPareto>KritikOdemePayiEsigi,"ödemeler tek kalemde yoğun, tedarikçi koşullarını müzakere edin","ödeme dağılımı dengeli"))
A41: Modül T4: Dönem Karşılaştırma | B41: =B25-B24 | C41: =_xlfn.TEXTJOIN(" | ",TRUE(),"T4: Son 7 hafta net akışı ilk 6 haftadan "&TEXT(ABS(modulT4DonemFark),"#,##0")&" TL farklı",IF(modulT4DonemFark<0,"dönem sonuna doğru nakit baskısı artıyor","dönem sonu nakit dengesi iyileşiyor"))
A42: Modül T5: Mutabakat Farkı | B42: =B33 | C42: =_xlfn.TEXTJOIN(" | ",TRUE(),"T5: Giriş-çıkış-bakiye mutabakat farkı "&TEXT(modulT5MutabakatFark,"#,##0")&" TL",IF(modulT5MutabakatFark>0,"kayıtlar arasında dengesizlik var, giriş/çıkış planlarını denetleyin","mutabakat uyumlu"))
A43: Modül T6: Kritik Ödeme Payı | B43: =IFERROR(B19/MAX(1,B8),0) | C43: =_xlfn.TEXTJOIN(" | ",TRUE(),"T6: Kritik ödemeler toplam çıkışın %"&TEXT(modulT6KritikOdemePayi*100,"0")&"ı",IF(modulT6KritikOdemePayi>KritikOdemePayiEsigi,"kritik yük yüksek, erteleme alanı dar","kritik yük yönetilebilir"))
A44: Modül O1: Çıkış Anomalisi | B44: =IFERROR(B17/MAX(1,B13),0) | C44: =_xlfn.TEXTJOIN(" | ",TRUE(),"O1: En yüksek çıkış ortalamanın "&TEXT(modulO1CikisAnomalisi,"0.0")&" katı",IF(modulO1CikisAnomalisi>2,"tek haftada balon ödeme var, ödeme tarihini dağıtın","haftalık çıkış dağılımı dengeli"))
A45: Modül O2: Tornado Zirve Etki | B45: =IFERROR(MAX(DuyarliOran*B7,DuyarliOran*B8,DuyarliOran*B19),0) | C45: =_xlfn.TEXTJOIN(" | ",TRUE(),"O2: Duyarlılık değişkenlerinin en yüksek etkisi "&TEXT(modulO2TornadoZirve,"#,##0")&" TL",IF(modulO2TornadoZirve>AsgariTampon,"tek değişken tamponu tüketebilir, senaryoları izleyin","duyarlılık etkisi sınırlı"))
...

Sheet KONTROLLER
A1: KONTROLLER — 13 HAFTALIK NAKİT AKIŞI VE ÖDEME PLANLAMA SİSTEMİ
A3: VERİ KALİTESİ VE SİSTEM SAĞLIĞI
A6: Veri Kalite Skoru | B6: =ROUND(100-(B14+B15+B16)*UyariPuanKesintisi,0)
A7: Durum | B7: =IF(B6>=VeriKaliteYuksek,"SAĞLIKLI",IF(B6>=VeriKaliteOrta,"İZLEME GEREKLİ","DÜZELTME GEREKLİ"))
A8: Genel Karar | B8: =IF(B6>=VeriKaliteYuksek,"UYGUN",IF(B6>=VeriKaliteOrta,"İNCELE","DURDUR"))
A9: Kayıt Sayısı (Giriş) | B9: =COUNTIFS(NAKIT_GIRISLERI!$A$6:$A$5000,">0")
A10: Kayıt Sayısı (Çıkış) | B10: =COUNTIFS(NAKIT_CIKISLARI!$A$6:$A$5000,">0")
A11: Toplam Beklenen Giriş | B11: =SUM(NAKIT_GIRISLERI!$E$6:$E$5000)
A12: Toplam Planlanan Çıkış | B12: =SUM(NAKIT_CIKISLARI!$E$6:$E$5000)
A13: Net Nakit Akışı | B13: =SUM(NAKIT_GIRISLERI!$E$6:$E$5000)-SUM(NAKIT_CIKISLARI!$E$6:$E$5000)
A14: Eksik Zorunlu Alan | B14: =COUNTIF(NAKIT_GIRISLERI!$G$6:$G$5000,"EKSİK")+COUNTIF(NAKIT_CIKISLARI!$G$6:$G$5000,"EKSİK")
A15: Sıfır/Negatif Tutar | B15: =COUNTIF(NAKIT_GIRISLERI!$G$6:$G$5000,"SIFIR/NEGATİF")+COUNTIF(NAKIT_CIKISLARI!$G$6:$G$5000,"SIFIR/NEGATİF")
A16: Aşırı Tutar Uyarısı | B16: =COUNTIF(NAKIT_GIRISLERI!$G$6:$G$5000,"AŞIRI TUTAR")+COUNTIF(NAKIT_CIKISLARI!$G$6:$G$5000,"AŞIRI TUTAR")
A17: Mutabakat Tutuyor | B17: =IF(B14+B15+B16=0,"UYGUN","SAĞLAM DEĞİL")
A22: Not: Mutabakat kontrolü, giriş ve çıkış kayıtlarının kural ihlali sayısını ölçer; her ihlal veri kalite skorundan düşer.

Sheet KARAR_MOTORU
A1: KARAR MOTORU — 13 HAFTALIK NAKİT AKIŞI VE ÖDEME PLANLAMA SİSTEMİ
A3: KARAR MOTORU — hangi hafta para bitecek, hangi önlem alınmalı
A5: Dönem Sonu Bakiye (13. Hafta) | B5: =BaslangicBakiye+SUM(NAKIT_GIRISLERI!$E$6:$E$5000)-SUM(NAKIT_CIKISLARI!$E$6:$E$5000)
A6: Para Bitiş Haftası | B6: =IFERROR(_xlfn.MINIFS(HAFTALIK_PLAN!$A$6:$A$18,HAFTALIK_PLAN!$H$6:$H$18,"<0"),0)
A7: İlk Risk Haftası | B7: =IFERROR(_xlfn.MINIFS(HAFTALIK_PLAN!$A$6:$A$18,HAFTALIK_PLAN!$H$6:$H$18,"<"&AsgariTampon),0)
A8: Karar | B8: =IF(B18<MinimumVeriSayisi,"VERİ YOK",IF(B6>0,"DURDUR",IF(B7>0,"İNCELE",IF(B5>=AsgariTampon,"UYGUN","İNCELE"))))
A9: Risk Seviyesi | B9: =IF(B8="VERİ YOK","BELİRSİZ",IF(B8="DURDUR","KRİTİK",IF(B8="İNCELE","YÜKSEK","DÜŞÜK")))
A10: Karar Gerekçesi | B10: =IF(B8="VERİ YOK","Karar için yeterli giriş/çıkış kaydı girilmedi; en az "&MinimumVeriSayisi&" kayıt beklenir.",_xlfn.TEXTJOIN(" | ",TRUE(),"Dönem sonu bakiye "&TEXT(B5,"#,##0")&" TL",IF(B6>0,"para "&B6&". haftada bitiyor","para bitiş riski yok"),IF(B7>0,"tampon eşiği "&B7&". haftada aşılıyor","tampon korunuyor")))
A11: Önerilen Önlem | B11: =IF(B8="VERİ YOK","Önce giriş ve çıkış planlarını eksiksiz doldurun",IF(B6>0,"Nakit akışı "&B6&". haftada tükeniyor: kritik ödemeleri erteleyin, tahsilatı hızlandırın, kısa vadeli kredi değerlendirin",IF(B7>0,"Tampon eşiği aşılıyor: ertelenebilir giderleri listeleyin, tahsilat takvimini öne çekin","Plan sağlıklı: mevcut akış korunmalı")))
A12: Toplam Beklenen Giriş | B12: =SUM(NAKIT_GIRISLERI!$E$6:$E$5000)
A13: Toplam Planlanan Çıkış | B13: =SUM(NAKIT_CIKISLARI!$E$6:$E$5000)
A14: Net Nakit Akışı | B14: =B12-B13
A15: En Yüksek Çıkış Haftası | B15: =IFERROR(INDEX(HAFTALIK_PLAN!$A$6:$A$18,MATCH(MAX(HAFTALIK_PLAN!$E$6:$E$18),HAFTALIK_PLAN!$E$6:$E$18,0)),0)
A16: En Kritik Ödemeler | B16: =SUMIFS(NAKIT_CIKISLARI!$E$6:$E$5000,NAKIT_CIKISLARI!$D$6:$D$5000,"KRİTİK")
A17: Ertelenebilir Ödemeler | B17: =SUMIFS(NAKIT_CIKISLARI!$E$6:$E$5000,NAKIT_CIKISLARI!$D$6:$D$5000,"ERTELENEBİLİR")
A18: Kayıt Sayısı (Giriş+Çıkış) | B18: =KONTROLLER!$B$9+KONTROLLER!$B$10
A23: Not: Karar, kayıt sayısı, dönem sonu bakiyesi ve tampon eşiğine göre makine tarafından üretilir; gerekçesi 'Karar Gerekçesi' satırında görünür. Tüm eşikler AYARLAR sayfasından yönetilir.

Sheet SENARYO_DUYARLILIK
A1: SENARYO DUYARLILIK — 13 HAFTALIK NAKİT AKIŞI VE ÖDEME PLANLAMA SİSTEMİ
A3: SENARYO VE DUYARLILIK ANALİZİ
A5: Baz Dönem Sonu Bakiye | B5: =KARAR_MOTORU!$B$5
A6: Giriş Artış Oranı | B6: 0.1
A7: İyimser Bakiye | B7: =B5*(1+B6)
A8: Kötümser Bakiye | B8: =B5*(1-B6)
A9: Çıkış Artış Oranı | B9: 0.1
A10: Kötümser (Çıkış +%10) Bakiye | B10: =B5*(1-B9)
A11: Kritik Ödeme Artış Oranı | B11: 0.1
A12: Kötümser (Kritik +%10) Bakiye | B12: =B5*(1-B11)
A14: MARJİNAL ETKİ (Tornado)
A15: Değişken | B15: Değişim | C15: Bakiye Etkisi | D15: Yeni Bakiye
A16: Girişler +%10 | B16: =B6 | C16: =B5*B16 | D16: =B5+B16
A17: Çıkışlar +%10 | B17: =B9 | C17: =-B5*B17 | D17: =B5+B17
A18: Kritik Ödemeler +%10 | B18: =B11 | C18: =-B5*B18 | D18: =B5+B18
A19: Güvence Düşük Girişler (-%10) | B19: =-B6 | C19: =B5*B19 | D19: =B5+B19
A21: Not: Senaryo oranları sarı hücrelerden girilir; her değişim bakiyeye doğrudan yansır. Tornado satırları bu oranlardan beslenir ve etkiyi TL olarak sıralar.

Sheet RAPOR
A1: RAPOR — 13 HAFTALIK NAKİT AKIŞI VE ÖDEME PLANLAMA SİSTEMİ
A3: YÖNETİCİ NAKİT AKIŞ RAPORU
A4: Rapor Tarihi | B4: =RaporTarihi
A5: Firma | B5: =FirmaUnvan
A6: Hazırlayan | B6: =RaporHazirlayan
A8: ANA SONUÇ
A9: Dönem Sonu Bakiye (13. Hafta) | B9: =KARAR_MOTORU!$B$5
A10: Net Nakit Akışı | B10: =KARAR_MOTORU!$B$14
A11: Para Bitiş Haftası | B11: =IF(KARAR_MOTORU!$B$6>0,KARAR_MOTORU!$B$6&". hafta","Yok")
A12: Karar | B12: =KARAR_MOTORU!$B$8
A13: Risk Seviyesi | B13: =KARAR_MOTORU!$B$9
A14: Önerilen Önlem | B14: =KARAR_MOTORU!$B$11
A15: Karar Gerekçesi | B15: =KARAR_MOTORU!$B$10
A16: ÖNEMLİ VARSAYIMLAR VE UYARILAR
A17: 1. Güvence düşük girişler gerçekleşmeyebilir; iyimser/kötümser bant PANO senaryosunda görülür.
A18: 2. Bu rapor karar destek amaçlıdır; kesin finansal tavsiye değildir.
A19: 3. Tüm eşikler AYARLAR sayfasında tanımlıdır; değişiklik sonrası rapor otomatik güncellenir.
A21: Hazırlayan: ExcelArşiv — Sürüm 1.0 | Tek kullanıcılı ticari lisans.

Sheet ORNEK_VERI
A1: ORNEK VERI — 13 HAFTALIK NAKİT AKIŞI VE ÖDEME PLANLAMA SİSTEMİ
A3: ÖRNEK VERİ — otomasyon ve içe aktarma için yapı
A5: Hafta Numarası | B5: Yön | C5: Tutar (₺) | D5: Güvence/Öncelik | E5: Kaynak/Kalem
A6: 1 | B6: GİRİŞ | C6: 85000 | D6: KESİN | E6: MÜŞTERİ TAHSİLATI
A7: 1 | B7: ÇIKIŞ | C7: 130000 | D7: KRİTİK | E7: MAAŞ
A8: 2 | B8: GİRİŞ | C8: 95000 | D8: KESİN | E8: MÜŞTERİ TAHSİLATI
A9: 2 | B9: ÇIKIŞ | C9: 90000 | D9: YÜKSEK | E9: TEDARİKÇİ
A10: 3 | B10: GİRİŞ | C10: 80000 | D10: KESİN | E10: MÜŞTERİ TAHSİLATI
A11: 3 | B11: ÇIKIŞ | C11: 180000 | D11: KRİTİK | E11: VERGİ

Sheet TESTLER
A1: TESTLER — 13 HAFTALIK NAKİT AKIŞI VE ÖDEME PLANLAMA SİSTEMİ
A3: SİSTEM TESTLERİ VE DENETİM KAYDI
A5: Test | B5: Canlı Değer | C5: Durum
A6: Toplam Beklenen Giriş | B6: =SUM(NAKIT_GIRISLERI!$E$6:$E$5000) | C6: =IF(B6="","EKSİK","KONTROL EDİLDİ")
A7: Toplam Planlanan Çıkış | B7: =SUM(NAKIT_CIKISLARI!$E$6:$E$5000) | C7: =IF(B7="","EKSİK","KONTROL EDİLDİ")
A8: Net Nakit Akışı | B8: =SUM(NAKIT_GIRISLERI!$E$6:$E$5000)-SUM(NAKIT_CIKISLARI!$E$6:$E$5000) | C8: =IF(B8="","EKSİK","KONTROL EDİLDİ")
A9: Veri Kalite Skoru | B9: =KONTROLLER!$B$6 | C9: =IF(B9="","EKSİK","KONTROL EDİLDİ")
A10: Dönem Sonu Bakiye | B10: =KARAR_MOTORU!$B$5 | C10: =IF(B10="","EKSİK","KONTROL EDİLDİ")
A11: Para Bitiş Haftası | B11: =KARAR_MOTORU!$B$6 | C11: =IF(B11="","EKSİK","KONTROL EDİLDİ")
A12: Karar Bildirimi | B12: =KARAR_MOTORU!$B$8 | C12: =IF(B12="","EKSİK","KONTROL EDİLDİ")
A16: Testler, excel_uretim/denetci.py ve test_on_uc_haftalik_nakit_akisi.py ile otomatik çalışır.

Sheet AKIS
A1: AKIS — OnUcHaftalikNakitAkisiVeOdemePlanlamaSistemi
A3: islem_id | B3: kaynak_kart_id | C3: onceki_durum | D3: yeni_durum | E3: tutar | F3: bayrak | G3: not
A4: I-001 | B4: KART-01 | C4: ACIK | D4: ISLEMDE | E4: 1000 | F4: OK | G4: normal geçiş
A5: I-002 | B5: YETİM | C5: ACIK | D5: KAPALI | E5: 0 | F5: YETİM | G5: kaynak_kart_id yok — yetim kayıt
A6: I-003 | B6: KART-02 | C6: ACIK | D6: KAPALI | E6: 500 | F6: GECERSIZ | G6: geçersiz durum geçişi
A7: I-004 | B7: KART-03 | C7: ISLEMDE | D7: ISLEMDE | E7: 250 | F7: ZINCIR_KIRIK | G7: ZİNCİR KIRIK — tutar zinciri sapması
A9: kuyruk_kanit | B9: =IFERROR(COUNTIF($F$4:$F$1000,"OK"),0)

Sheet DEGISIKLIK_KAYDI
A1: DEGISIKLIK KAYDI — 13 HAFTALIK NAKİT AKIŞI VE ÖDEME PLANLAMA SİSTEMİ
A3: DEGİŞİKLİK KAYDI
A5: Sürüm | B5: Tarih | C5: Açıklama
A6: 1.0 | B6: 08.08.2026 | C6: İlk sürüm: 13 haftalık nakit akışı, para bitiş tespiti ve önlem önerisi üretimi.

Sheet LISTELER
A1: LISTELER — 13 HAFTALIK NAKİT AKIŞI VE ÖDEME PLANLAMA SİSTEMİ
A3: AÇILIR LİSTE KAYNAKLARI
A5: Güvence | C5: Kaynak | E5: Kalem | G5: Öncelik
A6: KESİN | C6: MÜŞTERİ TAHSİLATI | E6: MAAŞ | G6: KRİTİK
A7: BEKLENEN | C7: SATIŞ | E7: KİRA | G7: YÜKSEK
A8: BELİRSİZ | C8: FİNANSMAN | E8: VERGİ | G8: ORTA
C9: SERMAYE | E9: SGK | G9: ERTELENEBİLİR
C10: DİĞER | E10: TEDARİKÇİ
E11: KREDİ TAKSİTİ
E12: FATURA
E13: DİĞER

Sheet AYARLAR
A1: AYARLAR — 13 HAFTALIK NAKİT AKIŞI VE ÖDEME PLANLAMA SİSTEMİ
A2: Tüm eşikler, katsayılar ve firma bilgileri tek kaynaktan (SSOT) buradan yönetilir. Sarı hücrelere değer girilir; kaynağı olmayan her parametre 'Varsayım' işaretlidir (D10).
A4: FIRMA BİLGİLERİ
A5: Firma Unvanı | B5: Örnek Anadolu Üretim ve Ticaret A.Ş. | E5: Açıklama
A6: Rapor Tarihi | B6: 46244 | E6: Açıklama
A7: Rapor Hazırlayan | B7: Finans Direktörü | E7: Açıklama
A8: Dosya Sürümü | B8: 1.0 | E8: Açıklama
A9: Lisans Kodu | B9: EKSRV-2026-13H-0001 | E9: Açıklama
A10: Para Birimi | B10: TRY | E10: Açıklama
A12: MODEL EŞİKLERİ
A13: anahtar | B13: deger | C13: birim | D13: aciklama | E13: kaynak | F13: yururluk_tarihi | G13: dogrulama_tarihi
A14: Başlangıç Nakit Bakiyesi | B14: 500000 | C14: ₺ | D14: 13 haftanın ilk dönem başı bakiyesi; karar motoru buradan başlar. | E14: Kullanıcı beyanı | F14: 10.08.2026 | G14: 10.08.2026
A15: Asgari Nakit Tamponu | B15: 50000 | C15: ₺ | D15: Bu eşiğin altına düşen hafta 'RİSK ALTINDA' işaretlenir. | E15: Varsayım | F15: 10.08.2026 | G15: 10.08.2026
A16: Hafta Uzunluğu (gün) | B16: 7 | C16: gün | D16: Bir planlama haftasının gün sayısı. | E16: Tasarım | F16: 10.08.2026 | G16: 10.08.2026
A17: Veri Kalite Üst Eşiği | B17: 80 | C17: puan | D17: Skor bu değer üstünde ise 'SAĞLIKLI'. | E17: Varsayım | F17: 10.08.2026 | G17: 10.08.2026
A18: Veri Kalite Orta Eşiği | B18: 60 | C18: puan | D18: Skor bu değer ile üst eşik arasında ise 'İZLEME GEREKLİ'. | E18: Varsayım | F18: 10.08.2026 | G18: 10.08.2026
A19: Uyarı Puan Kesintisi | B19: 5 | C19: puan | D19: Her kural ihlali için veri kalite skorundan düşüm. | E19: Varsayım | F19: 10.08.2026 | G19: 10.08.2026
A20: Aşırı Giriş Tutarı | B20: 500000 | C20: ₺ | D20: Bu tutar üstü giriş 'AŞIRI TUTAR' işaretlenir. | E20: Varsayım | F20: 10.08.2026 | G20: 10.08.2026
A21: Aşırı Çıkış Tutarı | B21: 500000 | C21: ₺ | D21: Bu tutar üstü çıkış 'AŞIRI TUTAR' işaretlenir. | E21: Varsayım | F21: 10.08.2026 | G21: 10.08.2026
A22: Duyarlılık Değişim Oranı | B22: 0.1 | C22: oran | D22: Motor O2 tornado ve senaryo analizindeki varsayılan değişim oranı. | E22: Varsayım | F22: 10.08.2026 | G22: 10.08.2026
A23: Minimum Veri Sayısı | B23: 6 | C23: kayıt | D23: Giriş+çıkış kayıt sayısı bu eşiğin altında ise karar 'VERİ YOK' olur. | E23: Varsayım | F23: 10.08.2026 | G23: 10.08.2026
A24: Kıtlık Günlük Maliyet Oranı | B24: 0.002 | C24: oran | D24: Negatif bakiyenin günlük tahmini finansman maliyeti (O5). | E24: Varsayım | F24: 10.08.2026 | G24: 10.08.2026
A25: Tahmin Hafta Ufku | B25: 3 | C25: hafta | D25: İleriye dönük bakiye tahmininin hafta ufku (I1). | E25: Tasarım | F25: 10.08.2026 | G25: 10.08.2026
... A32: P90 Yüzdelik Dilimi | B32: 0.9 | C32: oran | D32: Net akış P90 hesabında kullanılan yüzdelik dilim (I2). | E32: Tasarım | F32: 10.08.2026 | G32: 10.08.2026
J34: durum_haritasi | K34: durum_id | L34: durum_adi | M34: izinli_sonraki | N34: kategori
J35: HARITA | K35: ACIK | L35: Açık | M35: ISLEMDE | N35: acik
J36: HARITA | K36: ISLEMDE | L36: İşlemde | M36: KAPALI | N36: acik
J37: HARITA | K37: KAPALI | L37: Kapalı | M37: - | N37: kapali
J38: HARITA | K38: GECERSIZ | L38: Geçersiz geçiş uyarısı | M38: - | N38: kapali

Sheet KILAVUZ
A1: KILAVUZ — 13 HAFTALIK NAKİT AKIŞI VE ÖDEME PLANLAMA SİSTEMİ
A3: KULLANIM KILAVUZU
A5: 1. AMAÇ
A6: 13 haftalık nakit akışının hangi haftada tükeneceğini öngörür ve önlem önerisi üretir.
A7: 2. GİRİŞ PLANI
A8: NAKIT_GIRISLERI sayfasına hafta numarası, beklenen tarih, güvence, kaynak ve tutar girin.
A9: 3. ÇIKIŞ PLANI
A10: NAKIT_CIKISLARI sayfasına hafta numarası, vade tarihi, kalem, öncelik ve tutar girin.
A11: 4. HAFTALIK PLAN
A12: Giriş ve çıkış planlarından otomatik toplanır; dönem sonu bakiye ve para bitiş haftası hesaplanır.
A13: 5. MOTOR
A14: Ara hesaplar ve analitik modüller (yaşlandırma, trend, yoğunlaşma, senaryo, tahmin) ad tanımlı hücrelerde canlı hesaplanır.
... A40: • Sarı alan dışına yazmak: formül hücreleri 1234 şifresiyle korunur, yazılamaz.
