Workbook
Name hesapYili: GIRDI!$B$8
Name raporTarihi: AYARLAR!$B$7
Name ilc_birimLanded: MOTOR!$G$60
Name ilc_npv: MOTOR!$G$61
Name ilc_irr: MOTOR!$G$62
Name ilc_cif: MOTOR!$G$63
Name ilc_kararMetni: MOTOR!$G$42
Name ilc_kararGerekce: MOTOR!$G$43
Name ilc_maddeAtifMetni: MOTOR!$G$58
Name ilc_kanitRaporu: MOTOR!$G$59
Name ilc_kuralYilMatris: KURALLAR!$B$17
Name ilc_parmakIzi: AYARLAR!$B$19
Name ilc_aktifKur: AYARLAR!$K$48
Name ilc_kurTablosu: AYARLAR!$K$49
Name ilc_finansmanKarsilastirma: FINANSMAN!$B$11
Name ilc_senaryoKarsilastirma: SENARYO!$B$11
Name ilc_yorumSenaryo: SENARYO!$B$12
Name ilc_duyarlilikSira: SENARYO!$B$19
Name ilc_yorumDuyarlilik: SENARYO!$B$20
Name ilc_kuralDegisimSenaryo: SENARYO!$B$22
Name ilc_yorumKuralDegisim: SENARYO!$B$23
Name ilc_tahminAralik: SENARYO!$B$32
Name ilc_yorumTahmin: SENARYO!$B$33
Name ilc_vakaDurum: VAKALAR!$B$12
Name ilc_vakaFark: VAKALAR!$B$13
Name ilc_tolerans: AYARLAR!$B$8
Name ilc_azamiEsik: AYARLAR!$B$9
Name ilc_senaryoIyi: AYARLAR!$B$10
Name ilc_senaryoKotu: AYARLAR!$B$11
Name ilc_esikArtis: AYARLAR!$B$12
Name ilc_tahminAlt: AYARLAR!$B$13
Name ilc_tahminUst: AYARLAR!$B$14
Name ilc_tornadoKur: AYARLAR!$B$15
Name ilc_tornadoGumruk: AYARLAR!$B$16
Name ilc_tornadoNavlun: AYARLAR!$B$17
Name ilc_yuzdelikOran: AYARLAR!$B$18
Name ilc_girisBeklenen: AYARLAR!$B$21
Name ilc_riskDusuk: AYARLAR!$B$22
Name ilc_riskOrta: AYARLAR!$B$23
Name ilc_riskYuksek: AYARLAR!$B$24
Name ilc_yilTaban: AYARLAR!$B$25
Name ilc_yuvarMax: AYARLAR!$B$26
Name ilc_bazCarpan: AYARLAR!$B$27
Name ilc_sifirCarpan: AYARLAR!$B$28
Name ilc_siraBir: AYARLAR!$B$29
Name ilc_siraIki: AYARLAR!$B$30
Name ilc_siraUc: AYARLAR!$B$31
Name ilc_dikkatCarpan: AYARLAR!$B$32
Name ilc_npvDikkat: AYARLAR!$B$33
Name vaka_fob: AYARLAR!$B$34
Name vaka_kur: AYARLAR!$B$35
Name vaka_navlun: AYARLAR!$B$36
Name vaka_sigorta: AYARLAR!$B$37
Name vaka_cif: AYARLAR!$B$38
Name vaka_landed: AYARLAR!$B$39
Name vaka_miktar: AYARLAR!$B$40
Name ilc_modulT1: PANO!$C$11
Name ilc_modulT1Yorum: PANO!$D$11
Name ilc_modulT2: PANO!$C$12
Name ilc_modulT2Yorum: PANO!$D$12

Sheet 00_BASLANGIC
A1: EXCELARŞİV KARAR SİSTEMİ v15.1 — ÜRETİM REFERANSI
A3: Konu | B3: Bağlayıcı Standart
A4: Amaç | B4: Kanıta dayalı, hatada kapalı çalışan Excel üretim ve denetim sistemi
A5: Öncelik | B5: Kullanıcının açık iş talebi ve gerçek kullanım senaryosu
A6: Ana akış | B6: Uygunluk → Yönetişim → Sözleşmeler → Üretim → Test → Kanıt → Kullanıcı Kabulü → Yayın
A7: Yayın ilkesi | B7: Üst aşamada hata varsa alt aşama GEÇTİ üretilemez
A8: Kullanıcı kabulü | B8: Excel masaüstü görünümü test edilmediyse DIŞ_KABUL_GEREKLİ
A9: Nihai yayın | B9: Yalnız uygulanabilir modüller GEÇTİ veya gerekçeli UYGULANMAZ
A10: Ticari ayrım | B10: Ekonomik olarak savunulabilir fiyat, gerçek pazar kabulü ile aynı değildir
A11: Karmaşıklık | B11: Karar değeri, eklenen karmaşıklığın maliyetinden büyük olmalıdır
A12: Excel sınırı | B12: Veritabanı, kurumsal yetkilendirme, değiştirilemez kayıt sistemi veya gerçek zamanlı olay platformu değildir
A13: Dil standardı | B13: Kullanıcıya görünen tüm sayfa, tablo, başlık, açıklama, uyarı ve karar metinleri saf Türkçe olmalıdır
A14: Muhasebe standardı | B14: Finansal ürünlerde Türkiye Tekdüzen Hesap Planı ve Türk muhasebe kullanım alışkanlıkları esas alınır
... A33: Muhasebe | B33: Türkiye Tekdüzen Hesap Planı ve Türk muhasebe/işletme düşünce yapısı esas alınır.

Sheet PANO
A1: ☰ PANO
B2: İTHALAT LANDED COST MOTORU | L2: Dönem: 2026 / Tam ▼ | M2: ★ DOĞRULANMIŞ
B3: Hedef Kullanıcı: İthalatçı CFO, satın alma, gümrük müşaviri, SMMM · 2026 Q3 Denetim Standardı
B5: CIF / GÜMRÜK MATRAHI | D5: KONSOLİDE | E5: BIRIM LANDED COST | G5: KONTROL | H5: NET OPERASYONEL MARJ | J5: GÜVENLİ | K5: SİSTEM GÜVEN SKORU | M5: DENETLENDİ
B7: =GİRDİLER!E17 | E7: =B7*0.22 | H7: =B7-E7 | K7: =EĞER(E7>0; YUVARLA(B7/E7; 2); 0)
B9: ↑ %14.2 konsolide canlı veri bağlantısı | E9: ● 8 Kalem nakit karşılığı: bloke | H9: ██████████░░░░░ %78.0 NET MARJ | K9: ✓ İDEAL karşılama rasyosu
B11: İTHALAT LANDED COST MOTORU — DÖNEMSEL İCRA VE PROJEKSİYON | F11: +%32 Verim | H11: KONSOLİDE OPERASYON VE KARAR MATRİSİ
B12: Kümülatif Hacim vs. Operasyonel Maliyet ve Net Kâr Eğilimi | H12: Anlık Hesaplama Sonuçları, Dinamik Formül Çıktıları ve Durum Puanlaması
B14: Dönem | C14: Aktif Hacim | D14: Maliyet/Yük | E14: Hedef | H14: PARAMETRE / KALEM | I14: ANA TUTAR | J14: FARK / MARJ | K14: VADE | L14: KONTROL DURUMU
B15: D1 | C15: 65 | D15: 45 | E15: 60 | H15: Dönemlik Kümülatif Bakiye | I15: =B7*0.45 | J15: =B7*0.05 | K15: 12 Ay | L15: ✓ DÜZENLİ
B16: D2 | C16: 78 | D16: 48 | E16: 70 | H16: Kritik Eşik Güvenlik Tamponu | I16: =B7*0.30 | J16: =B7*0.03 | K16: 24 Ay | L16: ★ AVANTAJ
B17: D3 | C17: 85 | D17: 55 | E17: 80 | H17: Operasyonel Net Fark | I17: =B7*0.15 | J17: =B7*0.02 | K17: 8 Ay | L17: ● YAKLAŞAN
B18: D4 | C18: 75 | D18: 42 | E18: 75 | H18: Rezerv ve Likit Dağılım | I18: =B7*0.10 | J18: =B7*0.01 | K18: 16 Ay | L18: ✓ TAM UYUM
B19: D5 | C19: 90 | D19: 40 | E19: 85 | H19: KONSOLİDE SİSTEM TOPLAMI | I19: =TOPLA(I15:I18) | J19: =TOPLA(J15:J18) | L19: TAM DOĞRULANDI (0 HATA)
B20: D6 | C20: 96 | D20: 32 | E20: 92
B22: KONSOLİDE PAY VE AĞIRLIK | F22: LİKİDİTE RİSKİ & ERKEN UYARI SİNYALLERİ | K22: KARAR MOTORU
B23: ■ Ana Segment (%42) | F23: Nakit Açığı Riski (30 Gün) | I23: 0.00 TL (Sıfır Risk) | K23: STRATEJİK VERİMLİLİK FIRSATI
B24: ■ İkincil Grup (%30) | F24: Tahsilat Gecikme Toleransı | I24: 48 Gün Güvenli Eşik | K24: Operasyonel süreç optimizasyonu ile kârlılık artış potansiyeli tespit edildi.
B25: ■ Destek Birimi (%15) | F25: ██████████████████████████████████████ Güvenli Bölge (%100)
B26: ■ Rezervler (%13) | F26: ✓ 90 GÜNLÜK PROJEKSİYONDA NAKİT SIKIŞIKLIĞI TESPİT EDİLMEDİ | K26: STRATEJİ REÇETESİNİ İNCELE >

Sheet GİRDİLER
A1: ☰ PANO
B3: 🔍 İTHALAT LANDED COST MOTORU — Kayıt veya hesap ara... | G3: TOPLAM: 1.450 KAYIT | I3: HATALI HÜCRE: 0 ADET
B5: TARİH | C5: REFERANS NO | D5: İŞLEM AÇIKLAMASI VE DETAY | E5: BRÜT TUTAR (₺) | F5: KDV ORANI | G5: NET TUTAR (₺) | H5: HESAP / CARİ | I5: DURUM
B6: 12.10.2026 | C6: TR-0428-A | D6: Operasyonel ana kalem tahmini | E6: 845200 | F6: 0.2 | G6: =E6/(1+F6) | H6: Vadesiz Ticari | I6: ONAYLANDI
B7: 14.10.2026 | C7: TR-0429-B | D7: Operasyonel çıkış/maliyet tahmini | E7: 1240000 | F7: 0.2 | G7: =E7/(1+F7) | H7: Tedarikçi Havuzu | I7: BEKLEMEDE
B8: 18.10.2026 | C8: TR-0430-C | D8: Ödeme takvimi tahakkuku | E8: 620500 | F8: 0.1 | G8: =E8/(1+F8) | H8: Kısa Vade Tahakkuk | I8: ONAYLANDI
B9: 21.10.2026 | C9: TR-0431-D | D9: Müşteri işlem tahmini | E9: 415000 | F9: 0.2 | G9: =E9/(1+F9) | H9: Müşteri Alacağı | I9: ONAYLANDI
B10: 25.10.2026 | C10: TR-0432-E | D10: Ana operasyon tahmini | E10: 980400 | F10: 0.2 | G10: =E10/(1+F10) | H10: Vadesiz Ticari | I10: ONAYLANDI
B11: 28.10.2026 | C11: TR-0433-F | D11: Kredi/taksit karşılığı | E11: 1850000 | F11: 0.2 | G11: =E11/(1+F11) | H11: Finansman Havuzu | I11: BLOKE
B12: 02.11.2026 | C12: TR-0434-G | D12: Sabit gider ve yönetim notları | E12: 740000 | F12: 0.2 | G12: =E12/(1+F12) | H12: Genel Yönetim | I12: ONAYLANDI
B13: 05.11.2026 | C13: TR-0435-H | D13: Operasyonel ana kalem tahmini | E13: 520800 | F13: 0.2 | G13: =E13/(1+F13) | H13: Vadesiz Ticari | I13: ONAYLANDI
B14: 09.11.2026 | C14: TR-0436-I | D14: Müşteri işlem tahmini | E14: 1120000 | F14: 0.2 | G14: =E14/(1+F14) | H14: Müşteri Alacağı | I14: ONAYLANDI
B15: 12.11.2026 | C15: TR-0437-J | D15: Operasyonel çıkış tahmini | E15: 890000 | F15: 0.2 | G15: =E15/(1+F15) | H15: Tedarikçi Havuzu | I15: ONAYLANDI
B17: SAYFA TOPLAMI (10 / 1.450 KAYIT) | E17: =TOPLA(E6:E15)

Sheet YÖNETİM_RAPORU
A1: ☰ PANO
B2: İTHALAT LANDED COST MOTORU — NİHAİ KARAR VE DEĞERLEME
B3: Yönetim Kurulu ve İcra Komitesi için Otomatik Finansal Stres Testi Raporu · İthalatçı CFO, satın alma, gümrük müşaviri, SMMM
B4: DÖNEM: 2026 Q3 · DENETİM PROTOKOLÜ: ISO/VUK/IFRS UYUMLU · DURUM: ONAYLANDI
B6: SENARYO A: KÖTÜMSER (STRES TESTİ -%20) | H6: SENARYO B: BAZ MODEL (HEDEFLENEN)
B8: Ciro / Hacim Düşüşü: | E8: -%20.0 (Kriz Eşiği) | H8: Ciro / Hacim Gerçekleşmesi: | K8: %100.0 (Tam Bütçe)
B9: Beklenen Net Kâr / Getiri: | E9: =PANO!B7*0.8*0.22 | H9: Beklenen Net Kâr / Getiri: | K9: =PANO!H7
B10: Minimum Nakit Tamponu: | E10: =PANO!E7*0.75 | H10: Serbest Nakit Akımı: | K10: =PANO!H7*0.75
B11: Likidite Karşılama Oranı: | E11: =YUVARLA(PANO!B7*0.8/PANO!E7; 2) | H11: Yatırım Geri Dönüşü (ROI): | K11: %38.4 Yıllık
B14: STRES SENARYOSUNDA DAHİ İFLAS RİSKİ YOK | H14: OPTİMUM İCRA VE PLANLAMA REÇETESİ
B17: YÖNETİM KARAR MATRİSİ VE UYGULAMA REÇETESİ
B19: ● Öncelik 1: Acil Likidite ve Borç Servis Planlaması
B20: Sistemde hesaplanan vade günlerine sadık kalınarak nakit blokajı 3 gün önceden hazır edilmelidir.
B21: ● Öncelik 2: Formül Doğrulama ve Çapraz Sağlama
B22: Tüm hücreler kilitli formül korumasında olup girdi sayfalarında sıfır döngüsel başvuru (circular ref) garantilidir.
B23: ● Öncelik 3: Resmi Mevzuat ve Vergi Kalkanı Entegrasyonu
B24: 2026 güncel vergi dilimleri, amortisman ve SGK teşvik parametreleri tam otomatik yansıtılmaktadır.
B25: ● Öncelik 4: Yönetici İmzası ve Rapor Paylaşımı
B26: Tek tuşla PDF ve A4 çıktı formatına tam uyumlu sayfa yapısı kurgulanmıştır.

Sheet 01_YURUTME_CEKIRDEGI
A1: YÜRÜTME ÇEKİRDEĞİ — ZORUNLU ÜRETİM SIRASI
A3: Adım | B3: Modül | C3: Tetikleyici | D3: Zorunlu Kanıt | E3: GEÇTİ Kuralı | F3: Hata Durumu | G3: Sonraki Aşama
A4: 1 | B4: Excel Uygunluğu | C4: Her yeni model | D4: UYGUNLUK_KARARI | E4: Excel'in rolü açık | F4: HATA / BLOKE | G4: Yönetişim
A5: 2 | B5: Yönetişim | C5: Her model | D5: Risk seviyesi + etki girdileri | E5: Seviye hesaplandı | F5: BLOKE | G5: Sözleşmeler
A6: 3 | B6: Türk Muhasebe Eşlemesi | C6: Finansal model | D6: THP hesap eşleme tablosu | E6: Kritik satırlar THP ile uyumlu | F6: HATA | G6: Sözleşmeler
A7: 4 | B7: Veri ve Anlam Sözleşmeleri | C7: Girdi/KPI varsa | D7: Veri + KPI sözleşmeleri | E7: Kapsam %100 | F7: HATA | G7: Üretim
A8: 5 | B8: Üretim | C8: Sözleşmeler GEÇTİ | D8: Çalışan Excel | E8: Tek gerçek kaynak korunmuş | F8: HATA | G8: Testler
A9: 6 | B9: Görsel/Kullanım Katmanı | C9: Motor hazır | D9: Başlıklar + renk + grafik + yönlendirme | E9: Tüm kullanıcı sayfaları standarda uygun | F9: HATA | G9: Testler
A10: 7 | B10: Testler | C10: Üretim tamam | D10: Formül/OOXML/kimlik/oracle/golden/metamorfik | E10: Uygulanabilir hard gate'ler GEÇTİ | F10: HATA | G10: Kanıt
A11: 8 | B11: Hata-Kontrol Tutarlılığı | C11: Test sonucu var | D11: Hata taraması + kontrol sonuçları | E11: Formül hatası varken GEÇTİ yok | F11: HATA | G11: Kanıt
A12: 9 | B12: Kanıt | C12: Test sonucu var | D12: Makine okunur artefakt + özet | E12: Kanıt fiziksel ve tutarlı | F12: HATA | G12: Kullanıcı Kabulü
A13: 10 | B13: Kullanıcı Kabulü | C13: Kritik görevler | D13: Gerçek ekran davranışı | E13: Kritik görevler %100 | F13: DIŞ_KABUL_GEREKLİ | G13: Ticari
A14: 11 | B14: Ticari Değer | C14: Ürün satılacaksa | D14: ROI + demo + kanıt paketi | E14: Ekonomik değer kanıtlı | F14: UYARI / HATA | G14: Pazar Doğrulama
A15: 12 | B15: Pazar Doğrulama | C15: Pazar iddiası varsa | D15: Ücretli satış/pilot/fiyat kabul kanıtı | E15: Gerçek fiyat kabul kanıtı | F15: UYGULANMAZ / HATA | G15: Yayın

Sheet 02_KONTROL_LISTESI
A1: NİHAİ KONTROL LİSTESİ — KANITSIZ GEÇİŞ YOK
A3: Kontrol No | B3: Kontrol | C3: Beklenen | D3: Zorunlu Kapı? | E3: Sonuç
A4: K01 | B4: Kullanıcının açık talebi öncelikli mi? | C4: Evet | D4: EVET
A5: K02 | B5: Mevcut yapı, formüller ve tek gerçek kaynak korunuyor mu? | C5: Evet, değişiklik gerekçeli | D5: EVET
A6: K03 | B6: Üst aşama HATA ise alt aşama GEÇTİ engelleniyor mu? | C6: Evet | D6: EVET
A7: K04 | B7: Kanıt fiziksel çıktı ve içerik doğrulaması içeriyor mu? | C7: Evet | D7: EVET
A8: K05 | B8: Excel GUI erişimi olmadan kullanıcı görünümü GEÇTİ yazılıyor mu? | C8: Hayır | D8: EVET
A9: K06 | B9: NİHAİ yalnız GEÇTİ / gerekçeli UYGULANMAZ ile mi? | C9: Evet | D9: EVET
A10: K07 | B10: Ekonomik fiyat savunusu pazar doğrulamasından ayrılmış mı? | C10: Evet | D10: EVET
A11: K08 | B11: Prestij için gereksiz modül var mı? | C11: Hayır | D11: HAYIR
A12: K09 | B12: Excel sınırları açık mı? | C12: Evet | D12: EVET
A13: K10 | B13: Teknik kaynak korunuyor mu? | C13: Evet | D13: EVET
A14: K11 | B14: Kullanıcıya görünen tüm metinler Türkçe mi? | C14: Evet | D14: EVET
A15: K12 | B15: Her kullanıcı sayfasında üst başlık var mı? | C15: Evet | D15: EVET
... A34: K31 | B34: Premium vitrin, altyapı kadar güçlü ve satış fiyatını destekleyecek seviyede mi? | C34: Evet | D34: EVET

Sheet 03_GORSEL_TASARIM
A1: GÖRSEL TASARIM VE PREMIUM EXCEL STANDARDI
A3: Alan | B3: Zorunlu Kural | C3: Uygulama | D3: Yasak | E3: Kontrol | F3: Durum
A4: Sayfa başlığı | B4: Her kullanıcı sayfasının en üstünde tek ve açık sayfa başlığı | C4: A1'den başlayan koyu lacivert başlık bandı | D4: Başlıksız sayfa | E4: Başlık kapsama = %100 | F4: ZORUNLU
A5: Sekme renkleri | B5: Sayfalar işlevine göre renk kodlanır | C5: Girdi=mavi, hesap=gri, rapor=lacivert, kontrol=kırmızı, kılavuz=altın | D5: Rastgele renk | E5: Renk semantiği tutarlı | F5: ZORUNLU
A6: Kolon düzeni | B6: Veri blokları bitişik kolonlarda ilerler | C6: Gereksiz boş kolon bırakma; yalnız gerçek bölüm ayrımı varsa kontrollü boşluk | D6: A:C veri, D boş, E:F veri gibi parçalı yapı | E6: Boş kolon taraması | F6: ZORUNLU
A7: Girdi hücreleri | B7: Kullanıcının değiştireceği alan açıkça görünür | C7: Açık sarı dolgu + mavi yazı | D7: Formülle aynı görünüm | E7: Girdi/formül ayrımı | F7: ZORUNLU
A8: Formüller | B8: Hesap hücreleri kullanıcı girdisinden ayrılır | C8: Siyah yazı; sayfalar arası bağlantı yeşil yazı | D8: Hard-code gizleme | E8: Formül sınıfı kontrolü | F8: ZORUNLU
A9: Grafik sayısı | B9: Yönetici ekranında en fazla 3 ana karar grafiği | C9: Trend, karşılaştırma, köprü/dağılım; iş kararına bağlı | D9: Grafik kalabalığı | E9: Grafik başına karar sorusu | F9: ZORUNLU
A10: Grafik stili | B10: Kurumsal ve yüksek okunabilirlik | C10: Beyaz zemin, ince gridline, tek vurgu rengi, açık birim/başlık | D10: 3B, gölge, neon, gökkuşağı renkleri | E10: Görsel inceleme | F10: ZORUNLU
A11: Grafik başlığı | B11: Grafik 'neyi' değil 'ne anlama geldiğini' söyler | C11: Örn: 'Nakit 2028'de kritik eşiğin altına iniyor' | D11: 'Nakit Grafiği' gibi anlamsız başlık | E11: Başlık karar testi | F11: ZORUNLU
A12: Birimler | B12: Tüm finansal görsellerde birim açık | C12: TL, bin TL, milyon TL, %, gün, x | D12: Birim belirsizliği | E12: Birim kapsama %100 | F12: ZORUNLU
A13: Sıfır/negatif | B13: Finansal format standardı | C13: Sıfır='-', negatif kırmızı parantez | D13: -500 veya 0,00 kalabalığı | E13: Format kontrolü | F13: ZORUNLU
A14: Yazı tipi | B14: Tek aile | C14: Aptos veya Segoe UI | D14: Karışık font | E14: Tek font kontrolü | F14: ZORUNLU
... A22: Premium vitrin | B22: Görsel kalite ürün değerinin zorunlu parçasıdır | C22: Kaliteli grafik, gerçek KPI kartı, finansal hiyerarşi, tab rengi, fonksiyonel navigasyon | D22: Sadece doğru hesap yapıp çıplak/varsayılan Excel görünümü bırakmak | E22: Görsel release incelemesi | F22: ZORUNLU

Sheet 04_MUHASEBE_THP
A1: TÜRKİYE MUHASEBE VE TEKDÜZEN HESAP PLANI STANDARDI
A3: Konu | B3: Zorunlu Standart | C3: Örnek Türkçe Ad | D3: THP / Mantık | E3: Hata Riski | F3: Kontrol
A4: Dil | B4: Kullanıcıya görünen finansal terimler Türkçe | C4: Hasılat, Satışların Maliyeti, Brüt Kâr, Faaliyet Giderleri | D4: Türk işletme kullanımına uygun | E4: İngilizce jargon | F4: Terminoloji taraması
A5: Gelir Tablosu | B5: Türk sunum sırası kullanılır | C5: Net Satışlar → Satışların Maliyeti → Brüt Kâr → Faaliyet Giderleri → Faaliyet Kârı | D5: 600/610/611; 620-623; 63x | E5: Yanlış sınıflama | F5: Hesap eşleme
A6: Bilanço | B6: Dönen/Duran Varlık ve Kısa/Uzun Vadeli Yükümlülük ayrımı | C6: Hazır Değerler, Ticari Alacaklar, Stoklar, Mali Borçlar | D6: 1xx / 2xx / 3xx / 4xx / 5xx | E6: Vade sınıfı hatası | F6: Bilanço eşitliği
A7: Nakit Akışı | B7: İşletme/Yatırım/Finansman nakit akışları ayrılır | C7: Faaliyetlerden Nakit, Yatırım Harcamaları, Finansman Nakit Akışı | D7: Dolaylı/doğrudan yöntem açık seçilir | E7: Kâr = nakit sanılması | F7: Nakit devri
A8: Ticari Alacaklar | B8: Cari ve vade mantığı korunur | C8: 120 Alıcılar | D8: 120 | E8: Tahakkuk/nakit karışması | F8: Alacak devir kontrolü
A9: Ticari Borçlar | B9: Tedarikçi borcu ayrı izlenir | C9: 320 Satıcılar | D9: 320 | E9: Gider/ödeme karışması | F9: Borç devir kontrolü
A10: Kasa/Banka | B10: Hazır değerler ayrı izlenir | C10: 100 Kasa, 102 Bankalar | D10: 100 / 102 | E10: Virmanla toplam nakdin değişmesi | F10: Virman değişmezi
A11: Stok | B11: Dikeye uygun stok türü | C11: 150 İlk Madde ve Malzeme, 153 Ticari Mallar | D11: 15x | E11: Maliyet ve stok hareketinin kopması | F11: Stok devri
A12: Maddi Duran Varlık | B12: Yatırım harcaması ve amortisman bağlantılı | C12: 253 Tesis Makine Cihazlar, 255 Demirbaşlar, 257 Birikmiş Amortismanlar | D12: 25x | E12: Yatırım/gider karışması | F12: Net defter değeri devri
A13: Mali Borçlar | B13: Kısa/uzun vadeli borç ayrımı | C13: 300 Banka Kredileri / 400 Banka Kredileri | D13: 300 / 400 | E13: Vade sınıfı yanlış | F13: Borç devri
A14: Özkaynak | B14: Sermaye ve geçmiş yıl kârları ayrı | C14: 500 Sermaye, 570 Geçmiş Yıllar Kârları, 590 Dönem Net Kârı | D14: 5xx | E14: Net kâr bağının kopması | F14: Özkaynak devri
... A18: İstisna | B18: TFRS özel ürün varsa fark açık yazılır | C18: Tekdüzen raporlama ≠ TFRS finansal tablo sunumu | D18: Amaç belirtilir | E18: Standartları karıştırma | F18: Model amacı kontrolü

Sheet 05_KARAR_SATIS
A1: KARAR, GÜVEN VE SATIŞA HAZIRLIK STANDARDI
A3: Alan | B3: Müşteri Sorusu | C3: Zorunlu Ürün Davranışı | D3: Kanıt | E3: Başarısızlık Durumu | F3: Kapı
A4: 5 saniye | B4: Bu ürün neyi çözüyor? | C4: İlk ekranda hedef kullanıcı + pahalı problem + sonuç görünür | D4: Başlık + alt mesaj + gerçek ekran | E4: Ürün yalnız teknik isim | F4: HATA
A5: Acı | B5: Sorun bana neye mal oluyor? | C5: Mümkünse müşterinin kendi verisiyle parasal/zaman etkisi hesaplanır | D5: ROI/acı hesaplama yöntemi | E5: Uydurma tasarruf | F5: HATA
A6: Karar | B6: Bu bilgiyle ne yapacağım? | C6: Her kritik KPI aksiyona bağlanır | D6: KARAR_KUYRUGU | E6: Sadece rapor | F6: HATA
A7: Güven | B7: Bu sayıya neden inanayım? | C7: Kaynak, formül mantığı, kontrol ve son doğrulama görünür | D7: Kontroller + kaynak izi + sürüm | E7: Prestij kelimesi | F7: HATA
A8: Referans | B8: Müşteri yorumu yoksa ne göstereceğim? | C8: Önce/Sonra + Karar Vakası + Hata Önleme Vakası üretilir | D8: Demo/örnek çıktı | E8: Kanıtsız iddia | F8: HATA
A9: Senaryo | B9: Ne olursa işler bozulur? | C9: Baz/Aşağı/Yukarı veya uygun stres senaryosu | D9: Senaryo karşılaştırma | E9: Dekoratif senaryo | F9: HATA
A10: Ters stres | B10: Hangi eşikte karar kırılır? | C10: En az bir kritik sürücü için kırılma eşiği | D10: Kırılma eşiği tablosu | E10: Sadece +/- %10 | F10: UYARI/HATA
A11: Hata tutarlılığı | B11: Formül hata verirse ne olur? | C11: Kontrol GEÇTİ veremez; BLOKE/HATA üretir | D11: Hata taraması | E11: Hata + GEÇTİ birlikte | F11: HATA
A12: Karar motoru | B12: Ne oldu, neden oldu? | C12: Sorun + neden + parasal etki + aksiyon + son tarih | D12: Karar tablosu | E12: Boş sayfa / isim düzeyi modül | F12: HATA
A13: Yönetici özeti | B13: 5 saniyede ne görmeliyim? | C13: Bugün / ne değişti / ne bozulacak / neden / ne yapmalıyım / güven | D13: Yönetici özeti ekranı | E13: KPI kutusu yığını | F13: HATA
A14: Teklif | B14: Neden satın almalıyım? | C14: Dosya özellikleri yerine sonuç ve kaçınılan maliyet sunulur | D14: Ürün sayfası kanıt eşlemesi | E14: Özellik listesiyle satış | F14: HATA
... A19: Pazar kanıtı | B19: Piyasa gerçekten ödüyor mu? | C19: Satış/pilot/LOI/fiyat kabulü olmadan pazar doğrulandı yazılmaz | D19: Gerçek işlem kanıtı | E19: Tahmini talep = satış kabulü | F19: HATA

Sheet KAPAK
A1: KAPAK — İthalat Gerçek Birim Maliyet Motoru
A3: İthalat Gerçek Birim Maliyet Motoru
A4: FOB, navlun, sigorta, gümrük, KDV ve KKDF girdilerini işleyin; gerçek birim landed maliyeti ve YATIRIM YAPILIR / YATIRIM YAPMA kararını üretin.
A6: Bu ürün ne sağlar?
A7: • Kur tablosu (tarihli/kaynaklı) ile döviz→TL çevrimi — sabit kur gömülmez
A8: • Gümrük + KKDF + KDV kural motoru (2025/2026/2027 yan yana)
A9: • CAPEX/OPEX ayrımı + öz kaynak / kredi finansman senaryosu
A10: • NPV / IRR + tornado duyarlılık; kötümser YATIRIM YAPMA yolu
A11: • Altın vakalar ve KANIT_RAPORU (A4 imza)
A13: Kimler için?
A14: • Satın alma / ithalat — sevkiyat öncesi gerçek birim maliyeti görmek
A15: • CFO — NPV/IRR ile ithalat yatırımı kararı vermek
... A21: Sürüm 1.0.0 | 2026 | ExcelArşiv | Lisans: Tek kullanıcı | Kod: ILC-PRO

Sheet HIZLI_BASLANGIC
A1: HIZLI BASLANGIC — İthalat Gerçek Birim Maliyet Motoru
A3: Üç adımda sonuç
A5: Adım 1 — Girdiler | B5: GIRDI sayfasında FOB, miktar, navlun ve kur seçimini sarı hücrelere girin.
A6: Adım 2 — Karar | B6: PANO ve KARAR'da birim landed, NPV/IRR ve YATIRIM YAPILIR / YATIRIM YAPMA görün.
A7: Adım 3 — Kanıt | B7: KANIT_RAPORU'nu yazdırın; VAKALAR ve SENARYO ile doğrulayın.
A9: Formüller
A10: CIF = FOB_TL + navlun_TL + sigorta_TL | Landed = CIF + gümrük + KKDF + KDV + lokal | Birim = Landed ÷ miktar
A12: Sarı = manuel giriş | Yeşil = formül çıktısı | Şifre 1234 formül alanlarını korur.

Sheet GIRDI
A1: GIRDI — İthalat Gerçek Birim Maliyet Motoru
A3: İthalat sevkiyat girdileri
A4: Sarı hücreler manuel giriştir. Oranlar KURALLAR'dan; kur AYARLAR kur tablosundan.
A5: Alan | B5: Değer | C5: Birim
A6: Şirket / Sevkiyat | B6: Örnek İthalat Ticaret A.Ş. | C6: metin
A7: Dönem | B7: 2026-Q3 | C7: metin
A8: Hesap Yılı | B8: 2026 | C8: yıl
A9: Döviz Cinsi | B9: USD | C9: metin
A10: FOB [döviz] | B10: 100000 | C10: adet/döviz
A11: Miktar [adet] | B11: 1000 | C11: adet/döviz
A12: Navlun [döviz] | B12: 5000 | C12: adet/döviz
A13: Sigorta oranı (giriş) | B13: 0.01 | C13: %
A14: Lokal masraf [₺] | B14: 25000 | C14: ₺
A15: Hedef satış birim [₺] | B15: 6500 | C15: ₺
A16: Yıllık miktar [adet] | B16: 12000 | C16: adet/döviz
A17: CAPEX / YATIRIM [₺] | B17: 800000 | C17: ₺
A18: WACC [%] | B18: 0.18 | C18: %
A19: NPV dönem [yıl] | B19: 5 | C19: yıl
A20: Kredi faiz oranı [%] | B20: 0.32 | C20: %
A21: Öz kaynak oranı [%] | B21: 0.4 | C21: %
A23: Aktif kur (ayna) | B23: =IFERROR(ilc_aktifKur,0)
A24: Gümrük oranı (ayna) | B24: =IFERROR(INDEX(CHOOSE(MAX(1,MIN(3,IF(OR(hesapYili="",hesapYili=0),1,hesapYili-ilc_yilTaban))),tblKurallar[deger_2025],tblKurallar[deger_2026],tblKurallar[deger_2027]),MATCH("ILC-001",tblKurallar[kural_id],0)),0)
A25: Birim landed (ayna) | B25: =IFERROR(ilc_birimLanded,0)
A26: Giriş doluluk | B26: =IFERROR(IF(OR(COUNTA(B6:B21)=0,ilc_girisBeklenen=0),0,ROUND(COUNTA(B6:B21)/ilc_girisBeklenen*100,0)),0)
A28: Giriş tablosu (otomasyon / boş-mod)
A29: Alan Anahtarı | B29: Değer | C29: Birim | D29: Zorunlu | E29: Kaynak | F29: Kontrol
A30: sirket_adi | B30: Örnek İthalat Ticaret A.Ş. | C30: metin | D30: Evet | E30: GIRDI | F30: =IF($A30="","",IF($B30="","EKSİK","TAM"))
A31: donem | B31: 2026-Q3 | C31: metin | D31: Evet | E31: GIRDI | F31: =IF($A31="","",IF($B31="","EKSİK","TAM"))
A32: hesapYili | B32: 2026 | C32: yıl | D32: Evet | E32: GIRDI | F32: =IF($A32="","",IF($B32="","EKSİK","TAM"))
A33: parabirimi | B33: USD | C33: kod | D33: Evet | E33: GIRDI | F33: =IF($A33="","",IF($B33="","EKSİK","TAM"))
A34: fob_doviz | B34: 100000 | C34: döviz | D34: Evet | E34: GIRDI | F34: =IF($A34="","",IF($B34="","EKSİK","TAM"))
A35: miktar | B35: 1000 | C35: adet | D35: Evet | E35: GIRDI | F35: =IF($A35="","",IF($B35="","EKSİK","TAM"))
A36: navlun_doviz | B36: 5000 | C36: döviz | D36: Evet | E36: GIRDI | F36: =IF($A36="","",IF($B36="","EKSİK","TAM"))
A37: sigorta_oran | B37: 0.01 | C37: oran | D37: Evet | E37: GIRDI | F37: =IF($A37="","",IF($B37="","EKSİK","TAM"))
A38: lokal_masraf | B38: 25000 | C38: TL | D38: Evet | E38: GIRDI | F38: =IF($A38="","",IF($B38="","EKSİK","TAM"))
A39: hedef_satis | B39: 6500 | C39: TL | D39: Evet | E39: GIRDI | F39: =IF($A39="","",IF($B39="","EKSİK","TAM"))
A40: yillik_miktar | B40: 12000 | C40: adet | D40: Evet | E40: GIRDI | F40: =IF($A40="","",IF($B40="","EKSİK","TAM"))
A41: capex_tl | B41: 800000 | C41: TL | D41: Evet | E41: GIRDI | F41: =IF($A41="","",IF($B41="","EKSİK","TAM"))
A42: wacc | B42: 0.18 | C42: oran | D42: Evet | E42: GIRDI | F42: =IF($A42="","",IF($B42="","EKSİK","TAM"))
A43: npv_donem | B43: 5 | C43: yıl | D43: Evet | E43: GIRDI | F43: =IF($A43="","",IF($B43="","EKSİK","TAM"))
...

Sheet VARSAYIMLAR
A1: VARSAYIMLAR — İthalat Gerçek Birim Maliyet Motoru
A3: Model varsayımları — her satırda kaynak ve güven
A5: varsayim_id | B5: aciklama | C5: deger | D5: birim | E5: kaynak | F5: guven | G5: duyarlilik | H5: kontrol
A6: V-01 | B6: Aktif kur kaynağı | C6: TCMB alış | D6: metin | E6: TCMB günlük kur | F6: sert | G6: yüksek | H6: =IF($A6="","",IF(OR($E6="",$F6=""),"EKSİK","TAM"))
A7: V-02 | B7: Sigorta matrahı | C7: FOB | D7: metin | E7: Sigorta poliçesi | F7: sert | G7: orta | H7: =IF($A7="","",IF(OR($E7="",$F7=""),"EKSİK","TAM"))
A8: V-03 | B8: KKDF matrah yorumu | C8: FOB_TL | D8: metin | E8: KKDF tebliği — tartışmalı | F8: yumuşak | G8: yüksek | H8: =IF($A8="","",IF(OR($E8="",$F8=""),"EKSİK","TAM"))
A9: V-04 | B9: KDV matrahı | C9: CIF+gumruk+KKDF | D9: metin | E9: KDV Kanunu | F9: sert | G9: orta | H9: =IF($A9="","",IF(OR($E9="",$F9=""),"EKSİK","TAM"))
A10: V-05 | B10: CAPEX geri ödeme | C10: 5 yıl | D10: yıl | E10: İç politika | F10: yumuşak | G10: orta | H10: =IF($A10="","",IF(OR($E10="",$F10=""),"EKSİK","TAM"))
A11: V-06 | B11: OPEX yıllık miktar | C11: 12000 | D11: adet | E11: Satış planı | F11: yumuşak | G11: yüksek | H11: =IF($A11="","",IF(OR($E11="",$F11=""),"EKSİK","TAM"))
A12: V-07 | B12: WACC | C12: 0.18 | D12: oran | E12: Finans komitesi | F12: yumuşak | G12: yüksek | H12: =IF($A12="","",IF(OR($E12="",$F12=""),"EKSİK","TAM"))
A13: V-08 | B13: Kötümser kur şoku | C13: +15% | D13: oran | E13: Stres testi | F13: yumuşak | G13: yüksek | H13: =IF($A13="","",IF(OR($E13="",$F13=""),"EKSİK","TAM"))
J15: CAPEX / YATIRIM tutarı (ayna) | K15: =GIRDI!B17
J16: OPEX / ISLETME yıllık (ayna) | K16: =IFERROR(ilc_birimLanded*GIRDI!B16,0)

Sheet KURALLAR
A1: KURALLAR — İthalat Gerçek Birim Maliyet Motoru
A3: Gümrük / KDV / KKDF kural tablosu (yıl yan yana)
A4: Oranlar MOTOR'da sabit yazılmaz; INDEX/MATCH ile buradan çekilir.
A6: kural_id | B6: madde | C6: kural_adi | D6: kosul_metni | E6: parametre_adi | F6: deger_2025 | G6: deger_2026 | H6: deger_2027 | I6: yururluk | J6: kaynak | K6: aktif_deger
A7: ILC-001 | B7: Gümrük Kanunu | C7: gumruk_orani | D7: CIF × oran | E7: gumruk_orani | F7: 0.1 | G7: 0.1 | H7: 0.1 | I7: 01.01.2025 | J7: GTİP örnek oran | K7: =IF($A7="","",IFERROR(CHOOSE(MAX(1,MIN(3,IF(OR(hesapYili="",hesapYili=0),1,hesapYili-ilc_yilTaban))),$F7,$G7,$H7),0))
A8: ILC-002 | B8: KKDF tebliği | C8: kkdf_orani | D8: FOB_TL × oran | E8: kkdf_orani | F8: 0.06 | G8: 0.06 | H8: 0.06 | I8: 01.01.2025 | J8: KKDF oranı | K8: =IF($A8="","",IFERROR(CHOOSE(MAX(1,MIN(3,IF(OR(hesapYili="",hesapYili=0),1,hesapYili-ilc_yilTaban))),$F8,$G8,$H8),0))
A9: ILC-003 | B9: KDV Kanunu | C9: kdv_orani | D9: (CIF+gümrük+KKDF)×oran | E9: kdv_orani | F9: 0.2 | G9: 0.2 | H9: 0.2 | I9: 01.01.2025 | J9: KDV genel | K9: =IF($A9="","",IFERROR(CHOOSE(MAX(1,MIN(3,IF(OR(hesapYili="",hesapYili=0),1,hesapYili-ilc_yilTaban))),$F9,$G9,$H9),0))
A10: ILC-004 | B10: İç politika | C10: hedef_marj | D10: marj ≥ eşik | E10: hedef_marj | F10: 0.15 | G10: 0.15 | H10: 0.15 | I10: 01.01.2025 | J10: Hedef brüt marj | K10: =IF($A10="","",IFERROR(CHOOSE(MAX(1,MIN(3,IF(OR(hesapYili="",hesapYili=0),1,hesapYili-ilc_yilTaban))),$F10,$G10,$H10),0))
A11: ILC-005 | B11: Uygulama | C11: yuvarlama | D11: her hesap | E11: yuvarlama_ondalik | F11: 2 | G11: 2 | H11: 2 | I11: 01.01.2025 | J11: Yuvarlama ondalık | K11: =IF($A11="","",IFERROR(CHOOSE(MAX(1,MIN(3,IF(OR(hesapYili="",hesapYili=0),1,hesapYili-ilc_yilTaban))),$F11,$G11,$H11),0))
A14: Kural-yıl matrisi özeti
A15: Gümrük (aktif yıl) | B15: =IFERROR(INDEX(CHOOSE(MAX(1,MIN(3,IF(OR(hesapYili="",hesapYili=0),1,hesapYili-ilc_yilTaban))),tblKurallar[deger_2025],tblKurallar[deger_2026],tblKurallar[deger_2027]),MATCH("ILC-001",tblKurallar[kural_id],0)),0)
A16: KKDF (aktif yıl) | B16: =IFERROR(INDEX(CHOOSE(MAX(1,MIN(3,IF(OR(hesapYili="",hesapYili=0),1,hesapYili-ilc_yilTaban))),tblKurallar[deger_2025],tblKurallar[deger_2026],tblKurallar[deger_2027]),MATCH("ILC-002",tblKurallar[kural_id],0)),0)
A17: Matris metni | B17: =IFERROR(_xlfn.TEXTJOIN(" | ",TRUE,"ILC-001=",TEXT(B15,"0.0%"),"ILC-002=",TEXT(B16,"0.0%"),"yıl=",IF(OR(hesapYili="",hesapYili=0),"-",hesapYili)),"-")

Sheet MOTOR
A1: MOTOR — İthalat Gerçek Birim Maliyet Motoru
A3: Hesap zinciri — her adımda kural_id
A4: Oranlar tblKurallar'dan; kur tblKur'dan çekilir.
A6: adim | B6: ad | C6: formul | D6: birim | E6: ne_ise_yarar | F6: kural_id | G6: deger
A7: 1 | B7: Hesap yılı oku | C7: =IFERROR(hesapYili,0) | D7: yıl | E7: Aktif kural yılı | F7: ILC-005 | G7: =IFERROR(hesapYili,0)
A8: 2 | B8: Gümrük oranı | C8: =IFERROR(INDEX(CHOOSE(MAX(1,MIN(3,IF(OR(hesapYili="",hesapYili=0),1,hesapYili-ilc_yilTaban))),tblKurallar[deger_2025],tblKurallar[deger_2026],tblKurallar[deger_2027]),MATCH("ILC-001",tblKurallar[kural_id],0)),0) | D8: oran | E8: Gümrük vergisi oranı | F8: ILC-001 | G8: =IFERROR(INDEX(CHOOSE(MAX(1,MIN(3,IF(OR(hesapYili="",hesapYili=0),1,hesapYili-ilc_yilTaban))),tblKurallar[deger_2025],tblKurallar[deger_2026],tblKurallar[deger_2027]),MATCH("ILC-001",tblKurallar[kural_id],0)),0)
A9: 3 | B9: KKDF oranı | C9: =IFERROR(INDEX(CHOOSE(MAX(1,MIN(3,IF(OR(hesapYili="",hesapYili=0),1,hesapYili-ilc_yilTaban))),tblKurallar[deger_2025],tblKurallar[deger_2026],tblKurallar[deger_2027]),MATCH("ILC-002",tblKurallar[kural_id],0)),0) | D9: oran | E9: KKDF oranı | F9: ILC-002 | G9: =IFERROR(INDEX(CHOOSE(MAX(1,MIN(3,IF(OR(hesapYili="",hesapYili=0),1,hesapYili-ilc_yilTaban))),tblKurallar[deger_2025],tblKurallar[deger_2026],tblKurallar[deger_2027]),MATCH("ILC-002",tblKurallar[kural_id],0)),0)
A10: 4 | B10: KDV oranı | C10: =IFERROR(INDEX(CHOOSE(MAX(1,MIN(3,IF(OR(hesapYili="",hesapYili=0),1,hesapYili-ilc_yilTaban))),tblKurallar[deger_2025],tblKurallar[deger_2026],tblKurallar[deger_2027]),MATCH("ILC-003",tblKurallar[kural_id],0)),0) | D10: oran | E10: KDV oranı | F10: ILC-003 | G10: =IFERROR(INDEX(CHOOSE(MAX(1,MIN(3,IF(OR(hesapYili="",hesapYili=0),1,hesapYili-ilc_yilTaban))),tblKurallar[deger_2025],tblKurallar[deger_2026],tblKurallar[deger_2027]),MATCH("ILC-003",tblKurallar[kural_id],0)),0)
A11: 5 | B11: Hedef marj | C11: =IFERROR(INDEX(CHOOSE(MAX(1,MIN(3,IF(OR(hesapYili="",hesapYili=0),1,hesapYili-ilc_yilTaban))),tblKurallar[deger_2025],tblKurallar[deger_2026],tblKurallar[deger_2027]),MATCH("ILC-004",tblKurallar[kural_id],0)),0) | D11: oran | E11: Hedef brüt marj | F11: ILC-004 | G11: =IFERROR(INDEX(CHOOSE(MAX(1,MIN(3,IF(OR(hesapYili="",hesapYili=0),1,hesapYili-ilc_yilTaban))),tblKurallar[deger_2025],tblKurallar[deger_2026],tblKurallar[deger_2027]),MATCH("ILC-004",tblKurallar[kural_id],0)),0)
A12: 6 | B12: Yuvarlama ondalık | C12: =IFERROR(INDEX(CHOOSE(MAX(1,MIN(3,IF(OR(hesapYili="",hesapYili=0),1,hesapYili-ilc_yilTaban))),tblKurallar[deger_2025],tblKurallar[deger_2026],tblKurallar[deger_2027]),MATCH("ILC-005",tblKurallar[kural_id],0)),0) | D12: adet | E12: Yuvarlama basamağı | F12: ILC-005 | G12: =IFERROR(INDEX(CHOOSE(MAX(1,MIN(3,IF(OR(hesapYili="",hesapYili=0),1,hesapYili-ilc_yilTaban))),tblKurallar[deger_2025],tblKurallar[deger_2026],tblKurallar[deger_2027]),MATCH("ILC-005",tblKurallar[kural_id],0)),0)
A13: 7 | B13: Aktif kur | C13: =IFERROR(ilc_aktifKur,0) | D13: kur | E13: Kur tablosu aktif kur | F13: ILC-005 | G13: =IFERROR(ilc_aktifKur,0)
A14: 8 | B14: FOB döviz | C14: =IFERROR(GIRDI!B10,0) | D14: döviz | E14: FOB tutarı | F14: ILC-001 | G14: =IFERROR(GIRDI!B10,0)
A15: 9 | B15: Miktar | C15: =IFERROR(GIRDI!B11,0) | D15: adet | E15: Sevkiyat miktarı | F15: ILC-005 | G15: =IFERROR(GIRDI!B11,0)
A16: 10 | B16: Navlun döviz | C16: =IFERROR(GIRDI!B12,0) | D16: döviz | E16: Navlun | F16: ILC-001 | G16: =IFERROR(GIRDI!B12,0)
A17: 11 | B17: Sigorta oranı | C17: =IFERROR(GIRDI!B13,0) | D17: oran | E17: Sigorta primi oranı | F17: ILC-001 | G17: =IFERROR(GIRDI!B13,0)
A18: 12 | B18: Lokal masraf TL | C18: =IFERROR(GIRDI!B14,0) | D18: TL | E18: Lokal masraflar | F18: ILC-005 | G18: =IFERROR(GIRDI!B14,0)
A19: 13 | B19: Hedef satış birim | C19: =IFERROR(GIRDI!B15,0) | D19: TL | E19: Hedef birim satış | F19: ILC-004 | G19: =IFERROR(GIRDI!B15,0)
A20: 14 | B20: Yıllık miktar | C20: =IFERROR(GIRDI!B16,0) | D20: adet | E20: OPEX yıllık adet | F20: ILC-005 | G20: =IFERROR(GIRDI!B16,0)
A21: 15 | B21: CAPEX / YATIRIM | C21: =IFERROR(GIRDI!B17,0) | D21: TL | E21: Yatırım tutarı | F21: ILC-005 | G21: =IFERROR(GIRDI!B17,0)
A22: 16 | B22: WACC | C22: =IFERROR(GIRDI!B18,0) | D22: oran | E22: İskonto oranı | F22: ILC-005 | G22: =IFERROR(GIRDI!B18,0)
A23: 17 | B23: NPV dönem | C23: =IFERROR(GIRDI!B19,0) | D23: adet | E23: Nakit akışı yılı | F23: ILC-005 | G23: =IFERROR(GIRDI!B19,0)
A24: 18 | B24: Kredi faiz | C24: =IFERROR(GIRDI!B20,0) | D24: oran | E24: Kredi senaryosu | F24: ILC-005 | G24: =IFERROR(GIRDI!B20,0)
A25: 19 | B25: Öz kaynak oranı | C25: =IFERROR(GIRDI!B21,0) | D25: oran | E25: Öz kaynak payı | F25: ILC-005 | G25: =IFERROR(GIRDI!B21,0)
A26: 20 | B26: FOB TL | C26: =IFERROR(ROUND(G14*G13,MAX(0,MIN(ilc_yuvarMax,IFERROR(N(G12),0)))),0) | D26: TL | E26: FOB × kur | F26: ILC-001 | G26: =IFERROR(ROUND(G14*G13,MAX(0,MIN(ilc_yuvarMax,IFERROR(N(G12),0)))),0)
A27: 21 | B27: Navlun TL | C27: =IFERROR(ROUND(G16*G13,MAX(0,MIN(ilc_yuvarMax,IFERROR(N(G12),0)))),0) | D27: TL | E27: Navlun × kur | F27: ILC-001 | G27: =IFERROR(ROUND(G16*G13,MAX(0,MIN(ilc_yuvarMax,IFERROR(N(G12),0)))),0)
A28: 22 | B28: Sigorta TL | C28: =IFERROR(ROUND(G14*G17*G13,MAX(0,MIN(ilc_yuvarMax,IFERROR(N(G12),0)))),0) | D28: TL | E28: FOB×sigorta×kur | F28: ILC-001 | G28: =IFERROR(ROUND(G14*G17*G13,MAX(0,MIN(ilc_yuvarMax,IFERROR(N(G12),0)))),0)
A29: 23 | B29: CIF TL | C29: =IFERROR(G26+G27+G28,0) | D29: TL | E29: FOB+navlun+sigorta | F29: ILC-001 | G29: =IFERROR(G26+G27+G28,0)
A30: 24 | B30: Gümrük vergisi | C30: =IFERROR(ROUND(G29*G8,MAX(0,MIN(ilc_yuvarMax,IFERROR(N(G12),0)))),0) | D30: TL | E30: CIF × gümrük | F30: ILC-001 | G30: =IFERROR(ROUND(G29*G8,MAX(0,MIN(ilc_yuvarMax,IFERROR(N(G12),0)))),0)
A31: 25 | B31: KKDF tutarı | C31: =IFERROR(ROUND(G26*G9,MAX(0,MIN(ilc_yuvarMax,IFERROR(N(G12),0)))),0) | D31: TL | E31: FOB_TL × KKDF | F31: ILC-002 | G31: =IFERROR(ROUND(G26*G9,MAX(0,MIN(ilc_yuvarMax,IFERROR(N(G12),0)))),0)
A32: 26 | B32: KDV matrahı | C32: =IFERROR(G29+G30+G31,0) | D32: TL | E32: CIF+gümrük+KKDF | F32: ILC-003 | G32: =IFERROR(G29+G30+G31,0)
A33: 27 | B33: KDV tutarı | C33: =IFERROR(ROUND(G32*G10,MAX(0,MIN(ilc_yuvarMax,IFERROR(N(G12),0)))),0) | D33: TL | E33: Matrah × KDV | F33: ILC-003 | G33: =IFERROR(ROUND(G32*G10,MAX(0,MIN(ilc_yuvarMax,IFERROR(N(G12),0)))),0)
A34: 28 | B34: Toplam landed | C34: =IFERROR(G29+G30+G31+G33+G18,0) | D34: TL | E34: CIF+vergiler+lokal | F34: ILC-003 | G34: =IFERROR(G29+G30+G31+G33+G18,0)
A35: 29 | B35: Birim landed | C35: =IFERROR(IF(G15=0,0,ROUND(G34/G15,MAX(0,MIN(ilc_yuvarMax,IFERROR(N(G12),0))))),0) | D35: TL | E35: Landed ÷ miktar | F35: ILC-005 | G35: =IFERROR(IF(G15=0,0,ROUND(G34/G15,MAX(0,MIN(ilc_yuvarMax,IFERROR(N(G12),0))))),0)
A36: 30 | B36: Birim marj | C36: =IFERROR(IF(G19=0,0,(G19-G35)/G19),0) | D36: oran | E36: Satış−maliyet marjı | F36: ILC-004 | G36: =IFERROR(IF(G19=0,0,(G19-G35)/G19),0)
A37: 31 | B37: OPEX / ISLETME yıllık | C37: =IFERROR(G35*G20,0) | D37: TL | E37: Birim×yıllık miktar | F37: ILC-005 | G37: =IFERROR(G35*G20,0)
A38: 32 | B38: Yıllık brüt katkı | C38: =IFERROR((G19-G35)*G20,0) | D38: TL | E38: Marj × yıllık adet | F38: ILC-004 | G38: =IFERROR((G19-G35)*G20,0)
A39: 33 | B39: NPV (baz) | C39: =IFERROR(IF(OR(G23<=0,G22=""),0,IF(G22=0,ROUND(G38*G23-G21,MAX(0,MIN(ilc_yuvarMax,IFERROR(N(G12),0)))),ROUND(G38*(1-POWER(1+G22,-G23))/G22-G21,MAX(0,MIN(ilc_yuvarMax,IFERROR(N(G12),0)))))),0) | D39: TL | E39: NPV nakit akışı − CAPEX | F39: ILC-005 | G39: =IFERROR(IF(OR(G23<=0,G22=""),0,IF(G22=0,ROUND(G38*G23-G21,MAX(0,MIN(ilc_yuvarMax,IFERROR(N(G12),0)))),ROUND(G38*(1-POWER(1+G22,-G23))/G22-G21,MAX(0,MIN(ilc_yuvarMax,IFERROR(N(G12),0)))))),0)
A40: 34 | B40: IRR yaklaşımı | C40: =IFERROR(IF(OR(G21<=0,G38<=0,G23<=0),0,ROUND(G38/G21-ilc_bazCarpan/G23,4)),0) | D40: oran | E40: Kabaca IRR göstergesi | F40: ILC-005 | G40: =IFERROR(IF(OR(G21<=0,G38<=0,G23<=0),0,ROUND(G38/G21-ilc_bazCarpan/G23,4)),0)
A41: 35 | B41: Karar kodu | C41: =IFERROR(IF(COUNTA(tblGirdi[Alan Anahtarı])=0,"VERI_YOK",IF(OR(G35<=0,G15<=0,G13<=0),"YAPMA",IF(OR(G39<0,G36<G11*ilc_dikkatCarpan),"YAPMA",IF(OR(G36<G11,G39<ilc_npvDikkat),"DIKKAT","YAPILIR")))),"") | D41: kod | E41: Karar kodu | F41: ILC-004 | G41: =IFERROR(IF(COUNTA(tblGirdi[Alan Anahtarı])=0,"VERI_YOK",IF(OR(G35<=0,G15<=0,G13<=0),"YAPMA",IF(OR(G39<0,G36<G11*ilc_dikkatCarpan),"YAPMA",IF(OR(G36<G11,G39<ilc_npvDikkat),"DIKKAT","YAPILIR")))),"")
A42: 36 | B42: Karar metni | C42: =IFERROR(IF(G41="VERI_YOK","VERİ YOK",IF(G41="YAPILIR","YATIRIM YAPILIR",IF(G41="DIKKAT","DİKKAT","YATIRIM YAPMA"))),"") | D42: metin | E42: Kullanıcıya karar | F42: ILC-004 | G42: =IFERROR(IF(G41="VERI_YOK","VERİ YOK",IF(G41="YAPILIR","YATIRIM YAPILIR",IF(G41="DIKKAT","DİKKAT","YATIRIM YAPMA"))),"")
...

Sheet FINANSMAN
A1: FINANSMAN — İthalat Gerçek Birim Maliyet Motoru
A3: Finansman senaryoları — OZ_KAYNAK ve KREDI
A5: Senaryo | B5: Pay | C5: Tutar [₺] | D5: Faiz / maliyet | E5: NPV etkisi
A6: OZ_KAYNAK | B6: =GIRDI!B21 | C6: =GIRDI!B17*B6 | D6: =IFERROR(GIRDI!B21*ilc_sifirCarpan,0) | E6: =IFERROR(MOTOR!G39,0)
A7: KREDI | B7: =ilc_bazCarpan-GIRDI!B21 | C7: =GIRDI!B17*B7 | D7: =GIRDI!B20 | E7: =IFERROR(MOTOR!G39-C7*D7*GIRDI!B19,0)
A9: CAPEX / YATIRIM toplam | B9: =GIRDI!B17
A10: OPEX / ISLETME yıllık | B10: =IFERROR(MOTOR!G37,0)
A11: Finansman karşılaştırma | B11: =IFERROR(_xlfn.TEXTJOIN(" | ",TRUE,"OZ_KAYNAK NPV ",TEXT(E6,"₺ #,##0")," · KREDI NPV ",TEXT(E7,"₺ #,##0")),"-")
A13: FinansDemo
A14: OZ_KAYNAK | B14: 320000
A15: KREDI | B15: 480000

Sheet SENARYO
A1: SENARYO — İthalat Gerçek Birim Maliyet Motoru
A3: Senaryo ve duyarlılık (tornado)
A5: Senaryo | B5: Çarpan | C5: Birim landed | D5: NPV | E5: Karar | G5: NpvDemo
A6: İyimser | B6: =IFERROR(ilc_senaryoIyi+N(GIRDI!B10)*ilc_sifirCarpan,0) | C6: =IFERROR(MOTOR!G46,0) | D6: =IFERROR(MOTOR!G48,0) | E6: =IF(COUNTA(tblGirdi[Alan Anahtarı])=0,"VERİ YOK",IF(D6<0,"YATIRIM YAPMA",IF(C6>GIRDI!B15*(ilc_bazCarpan-MOTOR!G11),"DİKKAT","YATIRIM YAPILIR"))) | G6: 2400000
A7: Baz | B7: =IFERROR(ilc_bazCarpan+N(GIRDI!B10)*ilc_sifirCarpan,1) | C7: =IFERROR(ilc_birimLanded,0) | D7: =IFERROR(ilc_npv,0) | E7: =IF(COUNTA(tblGirdi[Alan Anahtarı])=0,"VERİ YOK",IFERROR(ilc_kararMetni,"-")) | G7: 1800000
A8: Kötümser | B8: =IFERROR(ilc_senaryoKotu+N(GIRDI!B10)*ilc_sifirCarpan,0) | C8: =IFERROR(MOTOR!G47,0) | D8: =IFERROR(MOTOR!G49,0) | E8: =IF(COUNTA(tblGirdi[Alan Anahtarı])=0,"VERİ YOK",IFERROR(MOTOR!G50,"YATIRIM YAPMA")) | G8: -400000
A9: M-SEN oran+ | B9: =IFERROR(ilc_bazCarpan+N(GIRDI!B10)*ilc_sifirCarpan,1) | C9: =IFERROR(IF(MOTOR!G15=0,0,MOTOR!G52/MOTOR!G15),0) | D9: =IFERROR(MOTOR!G39,0) | E9: =IF(COUNTA(tblGirdi[Alan Anahtarı])=0,"VERİ YOK",IF(MOTOR!G53=1,"YATIRIM YAPILIR","DİKKAT")) | G9: 1200000
A11: Senaryo NPV bant (iyimser−kötümser) | B11: =IFERROR(D6-D8,0)
A12: Senaryo yorumu | B12: =IFERROR(_xlfn.TEXTJOIN("; ",TRUE,"İyimser NPV ",TEXT(D6,"₺ #,##0")," · Baz ",TEXT(D7,"₺ #,##0")," · Kötümser ",TEXT(D8,"₺ #,##0")),"-")
A14: Duyarlılık (tornado)
A15: Değişken | B15: Etki [₺] | C15: Sıra | E15: EtkiDemo
A16: Tornado kur etkisi | B16: =IFERROR(MOTOR!G54,0) | C16: =IFERROR(IF(B16>=MAX(B16:B18),ilc_siraBir,IF(B16=MEDIAN(B16:B18),ilc_siraIki,ilc_siraUc)),ilc_siraUc) | E16: 180000
A17: Tornado gümrük etkisi | B17: =IFERROR(MOTOR!G55,0) | C17: =IFERROR(IF(B17>=MAX(B16:B18),ilc_siraBir,IF(B17=MEDIAN(B16:B18),ilc_siraIki,ilc_siraUc)),ilc_siraUc) | E17: 120000
A18: Tornado navlun etkisi | B18: =IFERROR(MOTOR!G56,0) | C18: =IFERROR(IF(B18>=MAX(B16:B18),ilc_siraBir,IF(B18=MEDIAN(B16:B18),ilc_siraIki,ilc_siraUc)),ilc_siraUc) | E18: 90000
A19: Duyarlılık sıra özeti | B19: =IFERROR(CONCATENATE("1)",INDEX(A16:A18,MATCH(ilc_siraBir,C16:C18,0))," 2)",INDEX(A16:A18,MATCH(ilc_siraIki,C16:C18,0))),"-")
A20: Duyarlılık yorumu | B20: =_xlfn.TEXTJOIN("; ",TRUE,"En yüksek etki ",TEXT(MAX(B16:B18),"₺ #,##0")," — öncelik bu değişkende")
A22: M-SEN oran değişimi bayrağı | B22: =MOTOR!G53
A23: M-SEN yorumu | B23: =_xlfn.TEXTJOIN("; ",TRUE,"Sıkı gümrük (+",TEXT(ilc_esikArtis,"0.0%"),") uygunluk ",TEXT(B22,"0"))
A25: Tahmin alt | B25: =IFERROR(ilc_birimLanded*ilc_tahminAlt,0) | C25: =IFERROR(ilc_birimLanded,0) | D25: =IFERROR(ilc_birimLanded*ilc_tahminUst,0)
A26: Tahmin (AVERAGE / STDEV)
A27: Seri nokta | D27: TrendDemo
A28: 1 | B28: =C6 | D28: 4800
A29: 2 | B29: =C7 | D29: 5200
A30: 3 | B30: =C8 | D30: 6100
A31: 4 | B31: =C9 | D31: 5200
A32: Tahmin sonraki | B32: =IFERROR(IF(OR(COUNT(B28:B31)<2,STDEV(B28:B31)=0),AVERAGE(B28:B31),AVERAGE(B28:B31)+STDEV(B28:B31)*0),0)
A33: Tahmin yorumu | B33: =_xlfn.TEXTJOIN("; ",TRUE,"Tahmin ",TEXT(B32,"₺ #,##0")," · Alt ",TEXT(B25,"₺ #,##0")," · Üst ",TEXT(D25,"₺ #,##0"))

Sheet KARAR
A1: KARAR — İthalat Gerçek Birim Maliyet Motoru
A3: Yatırım karar kapısı
A5: Karar | B5: =ilc_kararMetni
A6: Gerekçe | B6: =ilc_kararGerekce
A8: NPV [₺] | B8: =ilc_npv
A9: IRR | B9: =ilc_irr
A10: Birim landed [₺] | B10: =ilc_birimLanded
A11: Kötümser karar | B11: =IFERROR(MOTOR!G50,"YATIRIM YAPMA")
A13: CAPEX / YATIRIM | B13: =GIRDI!B17
A14: OPEX / ISLETME yıllık | B14: =IFERROR(MOTOR!G37,0)
A16: Boş girişte karar daima VERİ YOK olur. Kötümser NPV negatifse YATIRIM YAPMA üretilir.

Sheet VAKALAR
A1: VAKALAR — İthalat Gerçek Birim Maliyet Motoru
A3: Altın vakalar — gerçek birim maliyet
A5: vaka_id | B5: aciklama | C5: girdi_ozeti | D5: beklenen_sonuc | E5: hesaplanan | F5: fark | G5: durum | H5: kaynak
A6: V-001 | B6: FOB × kur = FOB_TL | C6: fob=vaka_fob; kur=vaka_kur | D6: 3400000 | E6: =IF($A6="","",IFERROR(INDEX($E$6:$E$9,MATCH($A6,$A$6:$A$9,0)),0)) | F6: =IF($A6="","",IFERROR($E6-$D6,0)) | G6: =IF($A6="","",IFERROR(IF(ABS($F6)<=ilc_tolerans,"TUTARLI","KIRIK"),"KIRIK")) | H6: FOB TL
A7: V-002 | B7: CIF = FOB_TL+navlun_TL+sigorta_TL | C7: navlun=vaka_navlun; sigorta_oran=vaka_sigorta | D7: 3604000 | E7: =IF($A7="","",IFERROR(INDEX($E$6:$E$9,MATCH($A7,$A$6:$A$9,0)),0)) | F7: =IF($A7="","",IFERROR($E7-$D7,0)) | G7: =IF($A7="","",IFERROR(IF(ABS($F7)<=ilc_tolerans,"TUTARLI","KIRIK"),"KIRIK")) | H7: CIF TL
A8: V-003 | B8: Gümrük = CIF × ILC-001 | C8: CIF=vaka_cif; oran 2026 | D8: 360400 | E8: =IF($A8="","",IFERROR(INDEX($E$6:$E$9,MATCH($A8,$A$6:$A$9,0)),0)) | F8: =IF($A8="","",IFERROR($E8-$D8,0)) | G8: =IF($A8="","",IFERROR(IF(ABS($F8)<=ilc_tolerans,"TUTARLI","KIRIK"),"KIRIK")) | H8: Gümrük
A9: V-004 | B9: Birim landed = toplam/miktar | C9: toplam=vaka_landed; miktar=vaka_miktar | D9: 5200 | E9: =IF($A9="","",IFERROR(INDEX($E$6:$E$9,MATCH($A9,$A$6:$A$9,0)),0)) | F9: =IF($A9="","",IFERROR($E9-$D9,0)) | G9: =IF($A9="","",IFERROR(IF(ABS($F9)<=ilc_tolerans,"TUTARLI","KIRIK"),"KIRIK")) | H9: Birim
A12: Vaka durumu özeti | B12: =IFERROR(IF(COUNTIF(G6:G9,"KIRIK")>0,"KIRIK","TUTARLI"),"KIRIK")
A13: Toplam mutlak fark | B13: =IFERROR(SUM(ABS(F6),ABS(F7),ABS(F8),ABS(F9)),0)

Sheet KANIT_RAPORU
A1: KANIT RAPORU — İthalat Gerçek Birim Maliyet Motoru
A3: KANIT RAPORU — İthalat Gerçek Birim Maliyet
A4: Finans / gümrük dosyası
A6: Şirket | B6: =GIRDI!B6
A7: Dönem | B7: =GIRDI!B7
A8: Hesap yılı | B8: =hesapYili
A9: Rapor tarihi | B9: =raporTarihi
A10: Aktif kur | B10: =ilc_aktifKur
A12: CIF [₺] | B12: =MOTOR!G29
A13: Gümrük [₺] | B13: =MOTOR!G30
A14: KKDF [₺] | B14: =MOTOR!G31
A15: KDV [₺] | B15: =MOTOR!G33
A16: Birim landed [₺] | B16: =ilc_birimLanded
A17: NPV [₺] | B17: =ilc_npv
A18: IRR | B18: =ilc_irr
A20: Karar | B20: =ilc_kararMetni
A21: Gerekçe | B21: =ilc_kararGerekce
A23: Madde / kural atıfı | B23: =ilc_maddeAtifMetni
A25: Kanıt özeti | B25: =ilc_kanitRaporu
A27: Parmak izi | B27: =ilc_parmakIzi
A30: Hazırlayan
A31: Onaylayan
A34: Bu çıktı karar destek amaçlıdır; bağlayıcı gümrük veya yatırım kararı değildir.

Sheet KONTROLLER
A1: KONTROLLER — İthalat Gerçek Birim Maliyet Motoru
A3: Dosya sağlık kontrolleri
A5: Giriş dolu mu? | B5: =IFERROR(IF(COUNTA(tblGirdi[Alan Anahtarı])=0,"BOŞ","DOLU"),"BOŞ")
A6: Hesap yılı geçerli mi? | B6: =IFERROR(IF(AND(N(hesapYili)>N(ilc_yilTaban),N(hesapYili)<=N(ilc_yilTaban)+3),"TEMİZ","HATALI"),"HATALI")
A7: Kur > 0? | B7: =IFERROR(IF(ilc_aktifKur>0,"TEMİZ","HATALI"),"HATALI")
A8: Miktar > 0? | B8: =IFERROR(IF(MOTOR!G15>0,"TEMİZ","HATALI"),"HATALI")
A9: Birim negatif mi? | B9: =IFERROR(IF(MOTOR!G35<0,"NEGATİF","NORMAL"),"NORMAL")
A10: Vaka durumu | B10: =IFERROR(ilc_vakaDurum,"KIRIK")
A11: Marj hedef altı? | B11: =IF(IFERROR(MOTOR!G36,0)<MOTOR!G11+N(GIRDI!B10)*ilc_sifirCarpan,"AŞIYOR","NORMAL")
A12: Sağlık skoru | B12: =IFERROR(ROUND((COUNTIF(B5:B11,"TEMİZ")+COUNTIF(B5:B11,"DOLU")+COUNTIF(B5:B11,"NORMAL")+COUNTIF(B5:B11,"TUTARLI"))/7*100,0),0)
A14: Beklenen giriş | B14: =IFERROR(ilc_girisBeklenen+COUNTA(GIRDI!B6:B21)*0,0)
A15: Birim landed | B15: =IFERROR(ilc_birimLanded,0)
A16: NPV | B16: =IFERROR(ilc_npv,0)
A17: IRR | B17: =IFERROR(ilc_irr,0)
A18: CIF | B18: =IFERROR(MOTOR!G29,0)
A19: Karar | B19: =IFERROR(ilc_kararMetni,"-")

Sheet ORNEK_VERI
A1: ORNEK VERI — İthalat Gerçek Birim Maliyet Motoru
A3: Örnek sevkiyat verileri
A5: Senaryo | B5: FOB | C5: Miktar | D5: Navlun | E5: Kur | F5: Sigorta | G5: Lokal | H5: Hedef satış | I5: Yıllık miktar | J5: CAPEX | K5: Yıl | L5: Birim Ornek
A6: Demo ana | B6: 100000 | C6: 1000 | D6: 5000 | E6: 34 | F6: 0.01 | G6: 25000 | H6: 6500 | I6: 12000 | J6: 800000 | K6: 2026 | L6: =IF($A6="","",IFERROR(ROUND(($B6*$E6+$D6*$E6+$B6*$F6*$E6+$G6)/MAX(1,$C6),0),0))
A7: Yüksek kur | B7: 100000 | C7: 1000 | D7: 5000 | E7: 38 | F7: 0.01 | G7: 30000 | H7: 7000 | I7: 10000 | J7: 900000 | K7: 2026 | L7: =IF($A7="","",IFERROR(ROUND(($B7*$E7+$D7*$E7+$B7*$F7*$E7+$G7)/MAX(1,$C7),0),0))
A8: Düşük marj | B8: 100000 | C8: 1000 | D8: 8000 | E8: 34 | F8: 0.015 | G8: 40000 | H8: 5200 | I8: 8000 | J8: 1000000 | K8: 2026 | L8: =IF($A8="","",IFERROR(ROUND(($B8*$E8+$D8*$E8+$B8*$F8*$E8+$G8)/MAX(1,$C8),0),0))
A9: 2025 geçiş | B9: 90000 | C9: 900 | D9: 4500 | E9: 32 | F9: 0.01 | G9: 20000 | H9: 6000 | I9: 11000 | J9: 750000 | K9: 2025 | L9: =IF($A9="","",IFERROR(ROUND(($B9*$E9+$D9*$E9+$B9*$F9*$E9+$G9)/MAX(1,$C9),0),0))
L10: =IF($A10="","",IFERROR(ROUND(($B10*$E10+$D10*$E10+$B10*$F10*$E10+$G10)/MAX(1,$C10),0),0))
L11: =IF($A11="","",IFERROR(ROUND(($B11*$E11+$D11*$E11+$B11*$F11*$E11+$G11)/MAX(1,$C11),0),0))
L12: =IF($A12="","",IFERROR(ROUND(($B12*$E12+$D12*$E12+$B12*$F12*$E12+$G12)/MAX(1,$C12),0),0))
L13: =IF($A13="","",IFERROR(ROUND(($B13*$E13+$D13*$E13+$B13*$F13*$E13+$G13)/MAX(1,$C13),0),0))
L14: =IF($A14="","",IFERROR(ROUND(($B14*$E14+$D14*$E14+$B14*$F14*$E14+$G14)/MAX(1,$C14),0),0))
L15: =IF($A15="","",IFERROR(ROUND(($B15*$E15+$D15*$E15+$B15*$F15*$E15+$G15)/MAX(1,$C15),0),0))
L16: =IF($A16="","",IFERROR(ROUND(($B16*$E16+$D16*$E16+$B16*$F16*$E16+$G16)/MAX(1,$C16),0),0))
L17: =IF($A17="","",IFERROR(ROUND(($B17*$E17+$D17*$E17+$B17*$F17*$E17+$G17)/MAX(1,$C17),0),0))
L18: =IF($A18="","",IFERROR(ROUND(($B18*$E18+$D18*$E18+$B18*$F18*$E18+$G18)/MAX(1,$C18),0),0))
L19: =IF($A19="","",IFERROR(ROUND(($B19*$E19+$D19*$E19+$B19*$F19*$E19+$G19)/MAX(1,$C19),0),0))
L20: =IF($A20="","",IFERROR(ROUND(($B20*$E20+$D20*$E20+$B20*$F20*$E20+$G20)/MAX(1,$C20),0),0))
L21: =IF($A21="","",IFERROR(ROUND(($B21*$E21+$D21*$E21+$B21*$F21*$E21+$G21)/MAX(1,$C21),0),0))
A22: OrnekBirimDemo | L22: =IF($A22="","",IFERROR(ROUND(($B22*$E22+$D22*$E22+$B22*$F22*$E22+$G22)/MAX(1,$C22),0),0))
A23: Demo ana | B23: 5200 | L23: =IF($A23="","",IFERROR(ROUND(($B23*$E23+$D23*$E23+$B23*$F23*$E23+$G23)/MAX(1,$C23),0),0))
A24: Yüksek kur | B24: 5900 | L24: =IF($A24="","",IFERROR(ROUND(($B24*$E24+$D24*$E24+$B24*$F24*$E24+$G24)/MAX(1,$C24),0),0))
A25: Düşük marj | B25: 6400 | L25: =IF($A25="","",IFERROR(ROUND(($B25*$E25+$D25*$E25+$B25*$F25*$E25+$G25)/MAX(1,$C25),0),0))
A26: 2025 geçiş | B26: 5100 | L26: =IF($A26="","",IFERROR(ROUND(($B26*$E26+$D26*$E26+$B26*$F26*$E26+$G26)/MAX(1,$C26),0),0))
L27: =IF($A27="","",IFERROR(ROUND(($B27*$E27+$D27*$E27+$B27*$F27*$E27+$G27)/MAX(1,$C27),0),0))
L28: =IF($A28="","",IFERROR(ROUND(($B28*$E28+$D28*$E28+$B28*$F28*$E28+$G28)/MAX(1,$C28),0),0))
L29: =IF($A29="","",IFERROR(ROUND(($B29*$E29+$D29*$E29+$B29*$F29*$E29+$G29)/MAX(1,$C29),0),0))
L30: =IF($A30="","",IFERROR(ROUND(($B30*$E30+$D30*$E30+$B30*$F30*$E30+$G30)/MAX(1,$C30),0),0))
L31: =IF($A31="","",IFERROR(ROUND(($B31*$E31+$D31*$E31+$B31*$F31*$E31+$G31)/MAX(1,$C31),0),0))
L32: =IF($A32="","",IFERROR(ROUND(($B32*$E32+$D32*$E32+$B32*$F32*$E32+$G32)/MAX(1,$C32),0),0))
L33: =IF($A33="","",IFERROR(ROUND(($B33*$E33+$D33*$E33+$B33*$F33*$E33+$G33)/MAX(1,$C33),0),0))
L34: =IF($A34="","",IFERROR(ROUND(($B34*$E34+$D34*$E34+$B34*$F34*$E34+$G34)/MAX(1,$C34),0),0))
L35: =IF($A35="","",IFERROR(ROUND(($B35*$E35+$D35*$E35+$B35*$F35*$E35+$G35)/MAX(1,$C35),0),0))
L36: =IF($A36="","",IFERROR(ROUND(($B36*$E36+$D36*$E36+$B36*$F36*$E36+$G36)/MAX(1,$C36),0),0))
L37: =IF($A37="","",IFERROR(ROUND(($B37*$E37+$D37*$E37+$B37*$F37*$E37+$G37)/MAX(1,$C37),0),0))
L38: =IF($A38="","",IFERROR(ROUND(($B38*$E38+$D38*$E38+$B38*$F38*$E38+$G38)/MAX(1,$C38),0),0))
... L1004: =IF($A1004="","",IFERROR(ROUND(($B1004*$E1004+$D1004*$E1004+$B1004*$F1004*$E1004+$G1004)/MAX(1,$C1004),0),0))

Sheet LISTELER
A1: LISTELER — İthalat Gerçek Birim Maliyet Motoru
A3: Doğrulama listeleri
A5: Yıl | C5: Döviz | E5: EvetHayır
A6: 2025 | C6: USD | E6: Evet
A7: 2026 | C7: EUR | E7: Hayır
A8: 2027

Sheet AYARLAR
A1: AYARLAR — İthalat Gerçek Birim Maliyet Motoru
A3: Parametreler (tek kaynak) + kur tablosu
A5: anahtar | B5: deger | C5: birim | D5: aciklama | E5: kaynak | F5: yururluk_tarihi | G5: dogrulama_tarihi | H5: kontrol
A6: hesapYili | B6: 2026 | C6: yıl | D6: Aktif hesap yılı | E6: Kullanıcı / GIRDI | F6: 01.01.2025 | G6: 11.08.2026 | H6: =IF(A6="","",IF(B6="","EKSİK","TAM"))
A7: raporTarihi | B7: 46245 | C7: tarih | D7: Rapor tarihi | E7: Üretim | F7: 01.01.2025 | G7: 11.08.2026 | H7: =IF(A7="","",IF(B7="","EKSİK","TAM"))
A8: ilc_tolerans | B8: 1 | C8: adet | D8: Vaka tutarlılık toleransı | E8: Uygulama notu | F8: 01.01.2025 | G8: 11.08.2026 | H8: =IF(A8="","",IF(B8="","EKSİK","TAM"))
A9: ilc_azamiEsik | B9: 100000000000 | C9: TL | D9: Azami giriş eşiği | E9: İç politika | F9: 01.01.2025 | G9: 11.08.2026 | H9: =IF(A9="","",IF(B9="","EKSİK","TAM"))
A10: ilc_senaryoIyi | B10: 0.92 | C10: çarpan | D10: İyimser maliyet çarpanı | E10: Model varsayımı | F10: 01.01.2025 | G10: 11.08.2026 | H10: =IF(A10="","",IF(B10="","EKSİK","TAM"))
A11: ilc_senaryoKotu | B11: 1.18 | C11: çarpan | D11: Kötümser maliyet çarpanı | E11: Model varsayımı | F11: 01.01.2025 | G11: 11.08.2026 | H11: =IF(A11="","",IF(B11="","EKSİK","TAM"))
A12: ilc_esikArtis | B12: 0.02 | C12: oran | D12: M-SEN gümrük + delta | E12: Senaryo motoru | F12: 01.01.2025 | G12: 11.08.2026 | H12: =IF(A12="","",IF(B12="","EKSİK","TAM"))
A13: ilc_tahminAlt | B13: 0.9 | C13: çarpan | D13: Tahmin alt bant | E13: Model varsayımı | F13: 01.01.2025 | G13: 11.08.2026 | H13: =IF(A13="","",IF(B13="","EKSİK","TAM"))
A14: ilc_tahminUst | B14: 1.12 | C14: çarpan | D14: Tahmin üst bant | E14: Model varsayımı | F14: 01.01.2025 | G14: 11.08.2026 | H14: =IF(A14="","",IF(B14="","EKSİK","TAM"))
A15: ilc_tornadoKur | B15: 1.05 | C15: çarpan | D15: Tornado kur şoku | E15: Model varsayımı | F15: 01.01.2025 | G15: 11.08.2026 | H15: =IF(A15="","",IF(B15="","EKSİK","TAM"))
A16: ilc_tornadoGumruk | B16: 0.02 | C16: oran | D16: Tornado gümrük şoku | E16: Model varsayımı | F16: 01.01.2025 | G16: 11.08.2026 | H16: =IF(A16="","",IF(B16="","EKSİK","TAM"))
A17: ilc_tornadoNavlun | B17: 0.1 | C17: oran | D17: Tornado navlun şoku | E17: Model varsayımı | F17: 01.01.2025 | G17: 11.08.2026 | H17: =IF(A17="","",IF(B17="","EKSİK","TAM"))
A18: ilc_yuzdelikOran | B18: 0.9 | C18: oran | D18: Yüzdelik P90 | E18: İstatistik | F18: 01.01.2025 | G18: 11.08.2026 | H18: =IF(A18="","",IF(B18="","EKSİK","TAM"))
A19: ilc_parmakIzi | B19: bd27f30b781ce266 | C19: metin | D19: Dosya parmak izi | E19: Üretim | F19: 01.01.2025 | G19: 11.08.2026 | H19: =IF(A19="","",IF(B19="","EKSİK","TAM"))
A20: dosya_surumu | B20: 1.0.0 | C20: metin | D20: Ürün sürümü | E20: ExcelArşiv | F20: 01.01.2025 | G20: 11.08.2026 | H20: =IF(A20="","",IF(B20="","EKSİK","TAM"))
A21: ilc_girisBeklenen | B21: 16 | C21: adet | D21: Zorunlu giriş sayısı | E21: Ürün mimarisi | F21: 01.01.2025 | G21: 11.08.2026 | H21: =IF(A21="","",IF(B21="","EKSİK","TAM"))
A22: ilc_riskDusuk | B22: 20 | C22: puan | D22: YAPILIR risk skoru | E22: İç politika | F22: 01.01.2025 | G22: 11.08.2026 | H22: =IF(A22="","",IF(B22="","EKSİK","TAM"))
A23: ilc_riskOrta | B23: 55 | C23: puan | D23: DİKKAT risk skoru | E23: İç politika | F23: 01.01.2025 | G23: 11.08.2026 | H23: =IF(A23="","",IF(B23="","EKSİK","TAM"))
A24: ilc_riskYuksek | B24: 85 | C24: puan | D24: YAPMA risk skoru | E24: İç politika | F24: 01.01.2025 | G24: 11.08.2026 | H24: =IF(A24="","",IF(B24="","EKSİK","TAM"))
A25: ilc_yilTaban | B25: 2024 | C25: yıl | D25: CHOOSE yıl tabanı | E25: Ürün mimarisi | F25: 01.01.2025 | G25: 11.08.2026 | H25: =IF(A25="","",IF(B25="","EKSİK","TAM"))
A26: ilc_yuvarMax | B26: 10 | C26: adet | D26: ROUND basamak tavanı | E26: Ürün mimarisi | F26: 01.01.2025 | G26: 11.08.2026 | H26: =IF(A26="","",IF(B26="","EKSİK","TAM"))
A27: ilc_bazCarpan | B27: 1 | C27: çarpan | D27: Baz senaryo çarpanı | E27: Model varsayımı | F27: 01.01.2025 | G27: 11.08.2026 | H27: =IF(A27="","",IF(B27="","EKSİK","TAM"))
A28: ilc_sifirCarpan | B28: 0 | C28: çarpan | D28: Nötr çarpan | E28: Model varsayımı | F28: 01.01.2025 | G28: 11.08.2026 | H28: =IF(A28="","",IF(B28="","EKSİK","TAM"))
A29: ilc_siraBir | B29: 1 | C29: adet | D29: Tornado sıra 1 | E29: Ürün mimarisi | F29: 01.01.2025 | G29: 11.08.2026 | H29: =IF(A29="","",IF(B29="","EKSİK","TAM"))
A30: ilc_siraIki | B30: 2 | C30: adet | D30: Tornado sıra 2 | E30: Ürün mimarisi | F30: 01.01.2025 | G30: 11.08.2026 | H30: =IF(A30="","",IF(B30="","EKSİK","TAM"))
A31: ilc_siraUc | B31: 3 | C31: adet | D31: Tornado sıra 3 | E31: Ürün mimarisi | F31: 01.01.2025 | G31: 11.08.2026 | H31: =IF(A31="","",IF(B31="","EKSİK","TAM"))
A32: ilc_dikkatCarpan | B32: 0.7 | C32: çarpan | D32: Marj dikkat çarpanı | E32: İç politika | F32: 01.01.2025 | G32: 11.08.2026 | H32: =IF(A32="","",IF(B32="","EKSİK","TAM"))
... A40: vaka_miktar | B40: 1000 | C40: adet | D40: Vaka miktar | E40: Altın vaka | F40: 01.01.2025 | G40: 11.08.2026 | H40: =IF(A40="","",IF(B40="","EKSİK","TAM"))
J42: Kur tablosu (tarihli / kaynaklı)
J43: parabirimi | K43: kur | L43: tarih | M43: kaynak | N43: aktif | O43: not | P43: secim
J44: USD | K44: 34 | L44: 46244 | M44: TCMB alış | N44: Evet | O44: Aktif demo kur | P44: =IF($J44="","",IF($N44="Evet",$K44,0))
J45: EUR | K45: 37.2 | L45: 46244 | M45: TCMB alış | N45: Hayır | O45: Yedek | P45: =IF($J45="","",IF($N45="Evet",$K45,0))
J46: USD | K46: 32.5 | L46: 46022 | M46: TCMB yılsonu | N46: Hayır | O46: 2025 referans | P46: =IF($J46="","",IF($N46="Evet",$K46,0))
J48: Aktif kur (tablodan) | K48: =IFERROR(IF(SUM(P44:P46)=0,INDEX(K44:K46,1),SUM(P44:P46)),0)
J49: Kur tablo ozeti | K49: =IFERROR(_xlfn.TEXTJOIN(" | ",TRUE,"USD=",TEXT(K44,"0.00")," kaynak=",M44," tarih=",TEXT(L44,"dd.mm.yyyy")),"-")
J51: Sürüm 1.0.0 | Şifre koruması: 1234 (formül alanları)

Sheet KILAVUZ
A1: KILAVUZ — İthalat Gerçek Birim Maliyet Motoru
A3: Karar kuralları
A5: • VERİ YOK — giriş tablosu boşsa hesap yapılmaz.
A6: • YATIRIM YAPILIR — NPV pozitif ve marj hedef üstünde.
A7: • DİKKAT — marj veya NPV dikkat bandında; kur/oran gözden geçirilmeli.
A8: • YATIRIM YAPMA — NPV negatif veya marj yetersiz (kötümser yol dahil).
A10: Belirsizlik beyanları (M05)
A11: Bu nokta mevzuatta tartışmalıdır; dosya yorum A ve yorum B sonucunu yan yana gösterir: kkdf_matrah_yorumu
A13: KKDF matrahı (FOB mı CIF mi) uygulamada tartışmalı / belirsizdir; bu dosya FOB_TL varsayar (Yorum A). Yorum B için CIF matrahı seçilirse KKDF yükselir.
A15: Yorum A | B15: KKDF matrahı = FOB_TL. CIF = FOB_TL + navlun_TL + sigorta_TL. Gümrük = CIF × oran. KDV = (CIF+gümrük+KKDF) × oran.
A16: Yorum B | B16: Bazı uygulamalarda KKDF CIF üzerinden hesaplanır (tartışmalı). Dosya Yorum A üretir; Yorum B farkı KILAVUZ'da beyan edilir.
A18: Kullanım sırası
A19: GIRDI → VARSAYIMLAR → KURALLAR → MOTOR → FINANSMAN → SENARYO → PANO → KARAR → VAKALAR → KANIT_RAPORU → AYARLAR (kur tablosu).
A21: Sürüm 1.0.0 | Lisans: Tek kullanıcı | ExcelArşiv | ILC-PRO
