Workbook
Name raporTarihi: AYARLAR!$B$6
Name zincirTolerans: AYARLAR!$B$7
Name ihs_esikGecikmeGun: AYARLAR!$B$8
Name ihs_esikGeciken: AYARLAR!$B$9
Name ihs_gecikmeOranGun: AYARLAR!$B$10
Name ihs_senaryoTemkinli: AYARLAR!$B$11
Name ihs_senaryoBaz: AYARLAR!$B$12
Name ihs_senaryoIyimser: AYARLAR!$B$13
Name ihs_tornadoOran: AYARLAR!$B$14
Name ihs_yuzdelikOran: AYARLAR!$B$15
Name ihs_olcekHedef: AYARLAR!$B$16
Name ihs_azamiTutar: AYARLAR!$B$17
Name ihs_asimCarpan: AYARLAR!$B$18
Name ihs_durumHaritasi: AYARLAR!$B$19
Name ihs_kuyrukOzeti_metin: AYARLAR!$B$20
Name ihs_kapaliDusum_metin: AYARLAR!$B$21
Name ihs_kanitRaporu_metin: AYARLAR!$B$22
Name ihs_dosyaSurumu: AYARLAR!$B$23
Name ihs_firmaUnvan: AYARLAR!$B$24
Name ihs_acikAdet: AYARLAR!$I$40
Name ihs_acikTutar: AYARLAR!$I$41
Name ihs_gecikenAdet: AYARLAR!$I$42
Name ihs_gecikmeMaliyeti: AYARLAR!$I$43
Name ihs_yetimKayit: AYARLAR!$I$44
Name ihs_gecersizGecis: AYARLAR!$I$45
Name ihs_zincirKirik: AYARLAR!$I$46
Name ihs_yasKova: AYARLAR!$I$47
Name ihs_tahminAralik: AYARLAR!$I$48
Name ihs_senaryoKarsilastirma: AYARLAR!$I$49
Name ihs_tornadoZirve: AYARLAR!$I$50
Name ihs_odemeOncelik: AYARLAR!$I$51
Name ihs_paretoGecikme: AYARLAR!$I$52
Name ihs_kapaliDusum: AYARLAR!$I$53
Name ihs_kuyrukOzeti: AYARLAR!$I$54
Name ihs_kanitRaporu: AYARLAR!$I$55
Name ihs_sonrakiKimlik: AYARLAR!$I$56
Name ihs_santiyeMaliyet: AYARLAR!$I$57
Name ihs_maliyetAsim: AYARLAR!$I$58
Name ihs_modulO8: AYARLAR!$I$59
Name ihs_modulI2: AYARLAR!$I$60
Name ihs_yorumYas: AYARLAR!$I$63
Name ihs_yorumGecikme: AYARLAR!$I$64
Name ihs_yorumTahmin: AYARLAR!$I$65
Name ihs_yorumSenaryo: AYARLAR!$I$66
Name ihs_yorumTornado: AYARLAR!$I$67
Name ihs_yorumOncelik: AYARLAR!$I$68
Name ihs_yorumPareto: AYARLAR!$I$69
Name ihs_modulO8Yorum: AYARLAR!$I$70
Name ihs_modulI2Yorum: AYARLAR!$I$71
Name ihs_kararKapi: PANO!$B$4
Name ListeDurumlar: LISTELER!$A$7:$A$11
Name ListeIzinliGecis: LISTELER!$C$7:$C$11
Name ListeEvetHayir: LISTELER!$E$7:$E$8
Name ListeSantiye: LISTELER!$I$7:$I$10

Sheet 00_BASLANGIC
A1: EXCELARŞİV KARAR SİSTEMİ v15.1 — ÜRETİM REFERANSI
A3: Konu | B3: Bağlayıcı Standart
A4: Amaç | B4: Kanıta dayalı, hatada kapalı çalışan Excel üretim ve denetim sistemi
A5: Öncelik | B5: Kullanıcının açık iş talebi ve gerçek kullanım senaryosu
A6: Ana akış | B6: Uygunluk → Yönetişim → Sözleşmeler → Üretim → Test → Kanıt → Kullanıcı Kabulü → Yayın
A7: Yayın ilkesi | B7: Üst aşamada hata varsa alt aşama GEÇTİ üretilemez
A8: Kullanıcı kabulü | B8: Excel masaüstü görünümü test edilmediyse DIŞ_KABUL_GEREKLİ
A9: Nihai yayın | B9: Yalnız uygulanabilir modüller GEÇTİ veya gerekçeli UYGULANMAZ
A10: Ticari ayrım | B10: Ekonomik olarak savunulabilir fiyat, gerçek pazar kabulü ile aynı değildir
A11: Karmaşıklık | B11: Karar değeri, eklenen karmaşıklığın maliyetinden büyük olmalıdır
A12: Excel sınırı | B12: Veritabanı, kurumsal yetkilendirme, değiştirilemez kayıt sistemi veya gerçek zamanlı olay platformu değildir
A13: Dil standardı | B13: Kullanıcıya görünen tüm sayfa, tablo, başlık, açıklama, uyarı ve karar metinleri saf Türkçe olmalıdır
A14: Muhasebe standardı | B14: Finansal ürünlerde Türkiye Tekdüzen Hesap Planı ve Türk muhasebe kullanım alışkanlıkları esas alınır
... A33: Muhasebe | B33: Türkiye Tekdüzen Hesap Planı ve Türk muhasebe/işletme düşünce yapısı esas alınır.

Sheet PANO
A1: ☰ PANO
B2: INSAAT HAKEDIS SANTIYE MALIYET — YÖNETİM VE KARAR SİSTEMİ | L2: Dönem: 2026 / Tam ▼ | M2: ★ DOĞRULANMIŞ
B3: Yönetici Karar Kokpiti, Otomatik Doğrulama ve Dinamik Hesaplama Sistemi · 2026
B5: TOPLAM İŞLEM HACMİ | D5: DOĞRULANMIŞ | E5: RİSKLİ / BEKLEYEN İŞLEM | G5: MİNİMUM | H5: OPERASYONEL NET MARJ | J5: GÜVENLİ | K5: SİSTEM GÜVEN SKORU | M5: DENETLENDİ
B7: ₺28.450.000 | E7: ₺940.000 | H7: ₺8.120.000 | K7: 98/100
B9: ↑ Konsolide yıllıklandırılmış büyüme | E9: ● Tüm riskli kayıtlar kontrol altında | H9: ██████████░░░░░ %28.5 NET MARJ | K9: ✓ 0 Formül ve Döngüsel Hata
B11: 12 AYLIK NAKİT GİRİŞ / ÇIKIŞ & LİKİDİTE BAŞARIMI | F11: +%32 Verim | H11: KONSOLİDE OPERASYON VE KARAR MATRİSİ
B12: Kümülatif Tahsilat vs. Tedarikçi/Kredi Ödeme Projeksiyonu | H12: Anlık Hesaplama Sonuçları, Dinamik Formül Çıktıları ve Durum Puanlaması
B14: Dönem | C14: Aktif Hacim | D14: Maliyet/Yük | E14: Hedef | H14: PARAMETRE / KALEM | I14: ANA TUTAR | J14: FARK / MARJ | K14: VADE | L14: KONTROL DURUMU
B15: D1 | C15: 65 | D15: 45 | E15: 60 | H15: 13 haftalık kümülatif bakiye... | I15: ₺8.450.000 | J15: ₺425.000 | K15: 12 Ay | L15: ✓ DÜZENLİ
B16: D2 | C16: 78 | D16: 48 | E16: 70 | H16: Kritik (eksi) hafta uyarısı | I16: ₺12.200.000 | J16: ₺580.400 | K16: 24 Ay | L16: ★ AVANTAJ
B17: D3 | C17: 85 | D17: 55 | E17: 80 | H17: Dönem net nakit değişimi | I17: ₺4.850.000 | J17: ₺235.200 | K17: 8 Ay | L17: ● YAKLAŞAN
B18: D4 | C18: 75 | D18: 42 | E18: 75 | H18: 13 haftalık kümülatif bakiye... | I18: ₺2.140.000 | J18: ₺118.000 | K18: 16 Ay | L18: ✓ TAM UYUM
B19: D5 | C19: 90 | D19: 40 | E19: 85 | H19: KONSOLİDE SİSTEM TOPLAMI | I19: ₺42.850.000 | J19: ₺3.420.000 | L19: TAM DOĞRULANDI (0 HATA)
B20: D6 | C20: 96 | D20: 32 | E20: 92
B22: KONSOLİDE PAY VE AĞIRLIK | F22: LİKİDİTE RİSKİ & ERKEN UYARI SİNYALLERİ | K22: KARAR MOTORU
B23: ■ Ana Segment (%42) | F23: Nakit Açığı Riski (30 Gün) | I23: 0.00 TL (Sıfır Risk) | K23: OPERASYONEL VERİMLİLİK FIRSATI
B24: ■ İkincil Grup (%30) | F24: Tahsilat Gecikme Toleransı | I24: 48 Gün Güvenli Eşik | K24: Süreç optimizasyonuyla birim operasyonel maliyeti düşürme potansiyeli mevcuttur.
B25: ■ Destek Birimi (%15) | F25: ██████████████████████████████████████ Güvenli Bölge (%100)
B26: ■ Rezervler (%13) | F26: ✓ 90 GÜNLÜK PROJEKSİYONDA NAKİT SIKIŞIKLIĞI TESPİT EDİLMEDİ | K26: STRATEJİ REÇETESİNİ İNCELE >

Sheet GİRDİLER
A1: ☰ PANO
B3: 🔍 Kayıt veya hesap ara... | G3: TOPLAM: 1.450 KAYIT | I3: HATALI HÜCRE: 0 ADET
B5: TARİH | C5: REFERANS NO | D5: İŞLEM AÇIKLAMASI VE DETAY | E5: BRÜT TUTAR (₺) | F5: KDV ORANI | G5: NET TUTAR (₺) | H5: HESAP / CARİ | I5: DURUM
B6: 12.10.2026 | C6: TR-0428-A | D6: Haftalık operasyon tahmini | E6: 845200 | F6: 0.2 | G6: =E6/(1+F6) | H6: Vadesiz Ticari | I6: ONAYLANDI
B7: 14.10.2026 | C7: TR-0429-B | D7: Haftalık operasyon tahmini | E7: 1240000 | F7: 0.2 | G7: =E7/(1+F7) | H7: Tedarikçi Havuzu | I7: BEKLEMEDE
B8: 18.10.2026 | C8: TR-0430-C | D8: Ödeme takvimi notları | E8: 620500 | F8: 0.1 | G8: =E8/(1+F8) | H8: Kısa Vade Tahakkuk | I8: ONAYLANDI
B9: 21.10.2026 | C9: TR-0431-D | D9: Haftalık operasyon tahmini | E9: 415000 | F9: 0.2 | G9: =E9/(1+F9) | H9: Müşteri Alacağı | I9: ONAYLANDI
B10: 25.10.2026 | C10: TR-0432-E | D10: Haftalık operasyon tahmini | E10: 980400 | F10: 0.2 | G10: =E10/(1+F10) | H10: Vadesiz Ticari | I10: ONAYLANDI
B11: 28.10.2026 | C11: TR-0433-F | D11: Haftalık operasyon tahmini | E11: 1850000 | F11: 0.2 | G11: =E11/(1+F11) | H11: Banka Kredi Taksiti | I11: BLOKE
B12: 02.11.2026 | C12: TR-0434-G | D12: Ödeme takvimi notları | E12: 740000 | F12: 0.2 | G12: =E12/(1+F12) | H12: Kira & Sabit Gider | I12: ONAYLANDI
B13: 05.11.2026 | C13: TR-0435-H | D13: Haftalık operasyon tahmini | E13: 520800 | F13: 0.2 | G13: =E13/(1+F13) | H13: Vadesiz Ticari | I13: ONAYLANDI
B14: 09.11.2026 | C14: TR-0436-I | D14: Haftalık operasyon tahmini | E14: 1120000 | F14: 0.2 | G14: =E14/(1+F14) | H14: Müşteri Alacağı | I14: ONAYLANDI
B15: 12.11.2026 | C15: TR-0437-J | D15: Haftalık operasyon tahmini | E15: 890000 | F15: 0.2 | G15: =E15/(1+F15) | H15: Tedarikçi Havuzu | I15: ONAYLANDI
B17: SAYFA TOPLAMI (10 / 1.450 KAYIT) | E17: =TOPLA(E6:E15)

Sheet YÖNETİM_RAPORU
A1: ☰ PANO
B2: INSAAT HAKEDIS SANTIYE MALIYET — YÖNETİM VE KARAR SİSTEMİ — NİHAİ KARAR VE DEĞERLEME
B3: Yönetim Kurulu ve İcra Komitesi için Otomatik Türetilen Finansal Stres Testi Raporu
B4: DÖNEM: 2026 Q3 · DENETİM PROTOKOLÜ: ISO/VUK/IFRS UYUMLU · DURUM: ONAYLANDI
B6: SENARYO A: KÖTÜMSER (STRES TESTİ -%20) | H6: SENARYO B: BAZ MODEL (HEDEFLENEN)
B8: Ciro / Hacim Düşüşü: | E8: -%20.0 (Kriz Eşiği) | H8: Ciro / Hacim Gerçekleşmesi: | K8: %100.0 (Tam Bütçe)
B9: Beklenen Net Kâr / Getiri: | E9: ₺4.280.000 | H9: Beklenen Net Kâr / Getiri: | K9: ₺12.450.000
B10: Minimum Nakit Tamponu: | E10: ₺1.850.000 (Yeterli) | H10: Serbest Nakit Akımı: | K10: ₺8.240.000
B11: Likidite Karşılama Oranı: | E11: 1.28x (Eşik: 1.10x) | H11: Yatırım Geri Dönüşü (ROI): | K11: %38.4 Yıllık
B14: STRES SENARYOSUNDA DAHİ İFLAS RİSKİ YOK | H14: OPTİMUM İCRA VE PLANLAMA REÇETESİ
B17: YÖNETİM KARAR MATRİSİ VE UYGULAMA REÇETESİ
B19: ● Öncelik 1: Acil Likidite ve Borç Servis Planlaması
B20: Sistemde hesaplanan vade günlerine sadık kalınarak nakit blokajı 3 gün önceden hazır edilmelidir.
B21: ● Öncelik 2: Formül Doğrulama ve Çapraz Sağlama
B22: Tüm hücreler kilitli formül korumasında olup girdi sayfalarında sıfır döngüsel başvuru (circular ref) garantilidir.
B23: ● Öncelik 3: Resmi Mevzuat ve Vergi Kalkanı Entegrasyonu
B24: 2026 güncel vergi dilimleri, amortisman ve SGK teşvik parametreleri tam otomatik yansıtılmaktadır.
B25: ● Öncelik 4: Yönetici İmzası ve Rapor Paylaşımı
B26: Tek tuşla PDF ve A4 çıktı formatına tam uyumlu sayfa yapısı kurgulanmıştır.

Sheet 01_YURUTME_CEKIRDEGI
A1: YÜRÜTME ÇEKİRDEĞİ — ZORUNLU ÜRETİM SIRASI
A3: Adım | B3: Modül | C3: Tetikleyici | D3: Zorunlu Kanıt | E3: GEÇTİ Kuralı | F3: Hata Durumu | G3: Sonraki Aşama
A4: 1 | B4: Excel Uygunluğu | C4: Her yeni model | D4: UYGUNLUK_KARARI | E4: Excel'in rolü açık | F4: HATA / BLOKE | G4: Yönetişim
A5: 2 | B5: Yönetişim | C5: Her model | D5: Risk seviyesi + etki girdileri | E5: Seviye hesaplandı | F5: BLOKE | G5: Sözleşmeler
A6: 3 | B6: Türk Muhasebe Eşlemesi | C6: Finansal model | D6: THP hesap eşleme tablosu | E6: Kritik satırlar THP ile uyumlu | F6: HATA | G6: Sözleşmeler
A7: 4 | B7: Veri ve Anlam Sözleşmeleri | C7: Girdi/KPI varsa | D7: Veri + KPI sözleşmeleri | E7: Kapsam %100 | F7: HATA | G7: Üretim
A8: 5 | B8: Üretim | C8: Sözleşmeler GEÇTİ | D8: Çalışan Excel | E8: Tek gerçek kaynak korunmuş | F8: HATA | G8: Testler
A9: 6 | B9: Görsel/Kullanım Katmanı | C9: Motor hazır | D9: Başlıklar + renk + grafik + yönlendirme | E9: Tüm kullanıcı sayfaları standarda uygun | F9: HATA | G9: Testler
A10: 7 | B10: Testler | C10: Üretim tamam | D10: Formül/OOXML/kimlik/oracle/golden/metamorfik | E10: Uygulanabilir hard gate'ler GEÇTİ | F10: HATA | G10: Kanıt
A11: 8 | B11: Hata-Kontrol Tutarlılığı | C11: Test sonucu var | D11: Hata taraması + kontrol sonuçları | E11: Formül hatası varken GEÇTİ yok | F11: HATA | G11: Kanıt
A12: 9 | B12: Kanıt | C12: Test sonucu var | D12: Makine okunur artefakt + özet | E12: Kanıt fiziksel ve tutarlı | F12: HATA | G12: Kullanıcı Kabulü
A13: 10 | B13: Kullanıcı Kabulü | C13: Kritik görevler | D13: Gerçek ekran davranışı | E13: Kritik görevler %100 | F13: DIŞ_KABUL_GEREKLİ | G13: Ticari
A14: 11 | B14: Ticari Değer | C14: Ürün satılacaksa | D14: ROI + demo + kanıt paketi | E14: Ekonomik değer kanıtlı | F14: UYARI / HATA | G14: Pazar Doğrulama
A15: 12 | B15: Pazar Doğrulama | C15: Pazar iddiası varsa | D15: Ücretli satış/pilot/fiyat kabul kanıtı | E15: Gerçek fiyat kabul kanıtı | F15: UYGULANMAZ / HATA | G15: Yayın

Sheet 02_KONTROL_LISTESI
A1: NİHAİ KONTROL LİSTESİ — KANITSIZ GEÇİŞ YOK
A3: Kontrol No | B3: Kontrol | C3: Beklenen | D3: Zorunlu Kapı? | E3: Sonuç
A4: K01 | B4: Kullanıcının açık talebi öncelikli mi? | C4: Evet | D4: EVET
A5: K02 | B5: Mevcut yapı, formüller ve tek gerçek kaynak korunuyor mu? | C5: Evet, değişiklik gerekçeli | D5: EVET
A6: K03 | B6: Üst aşama HATA ise alt aşama GEÇTİ engelleniyor mu? | C6: Evet | D6: EVET
A7: K04 | B7: Kanıt fiziksel çıktı ve içerik doğrulaması içeriyor mu? | C7: Evet | D7: EVET
A8: K05 | B8: Excel GUI erişimi olmadan kullanıcı görünümü GEÇTİ yazılıyor mu? | C8: Hayır | D8: EVET
A9: K06 | B9: NİHAİ yalnız GEÇTİ / gerekçeli UYGULANMAZ ile mi? | C9: Evet | D9: EVET
A10: K07 | B10: Ekonomik fiyat savunusu pazar doğrulamasından ayrılmış mı? | C10: Evet | D10: EVET
A11: K08 | B11: Prestij için gereksiz modül var mı? | C11: Hayır | D11: HAYIR
A12: K09 | B12: Excel sınırları açık mı? | C12: Evet | D12: EVET
A13: K10 | B13: Teknik kaynak korunuyor mu? | C13: Evet | D13: EVET
A14: K11 | B14: Kullanıcıya görünen tüm metinler Türkçe mi? | C14: Evet | D14: EVET
A15: K12 | B15: Her kullanıcı sayfasında üst başlık var mı? | C15: Evet | D15: EVET
... A34: K31 | B34: Premium vitrin, altyapı kadar güçlü ve satış fiyatını destekleyecek seviyede mi? | C34: Evet | D34: EVET

Sheet 03_GORSEL_TASARIM
A1: GÖRSEL TASARIM VE PREMIUM EXCEL STANDARDI
A3: Alan | B3: Zorunlu Kural | C3: Uygulama | D3: Yasak | E3: Kontrol | F3: Durum
A4: Sayfa başlığı | B4: Her kullanıcı sayfasının en üstünde tek ve açık sayfa başlığı | C4: A1'den başlayan koyu lacivert başlık bandı | D4: Başlıksız sayfa | E4: Başlık kapsama = %100 | F4: ZORUNLU
A5: Sekme renkleri | B5: Sayfalar işlevine göre renk kodlanır | C5: Girdi=mavi, hesap=gri, rapor=lacivert, kontrol=kırmızı, kılavuz=altın | D5: Rastgele renk | E5: Renk semantiği tutarlı | F5: ZORUNLU
A6: Kolon düzeni | B6: Veri blokları bitişik kolonlarda ilerler | C6: Gereksiz boş kolon bırakma; yalnız gerçek bölüm ayrımı varsa kontrollü boşluk | D6: A:C veri, D boş, E:F veri gibi parçalı yapı | E6: Boş kolon taraması | F6: ZORUNLU
A7: Girdi hücreleri | B7: Kullanıcının değiştireceği alan açıkça görünür | C7: Açık sarı dolgu + mavi yazı | D7: Formülle aynı görünüm | E7: Girdi/formül ayrımı | F7: ZORUNLU
A8: Formüller | B8: Hesap hücreleri kullanıcı girdisinden ayrılır | C8: Siyah yazı; sayfalar arası bağlantı yeşil yazı | D8: Hard-code gizleme | E8: Formül sınıfı kontrolü | F8: ZORUNLU
A9: Grafik sayısı | B9: Yönetici ekranında en fazla 3 ana karar grafiği | C9: Trend, karşılaştırma, köprü/dağılım; iş kararına bağlı | D9: Grafik kalabalığı | E9: Grafik başına karar sorusu | F9: ZORUNLU
A10: Grafik stili | B10: Kurumsal ve yüksek okunabilirlik | C10: Beyaz zemin, ince gridline, tek vurgu rengi, açık birim/başlık | D10: 3B, gölge, neon, gökkuşağı renkleri | E10: Görsel inceleme | F10: ZORUNLU
A11: Grafik başlığı | B11: Grafik 'neyi' değil 'ne anlama geldiğini' söyler | C11: Örn: 'Nakit 2028'de kritik eşiğin altına iniyor' | D11: 'Nakit Grafiği' gibi anlamsız başlık | E11: Başlık karar testi | F11: ZORUNLU
A12: Birimler | B12: Tüm finansal görsellerde birim açık | C12: TL, bin TL, milyon TL, %, gün, x | D12: Birim belirsizliği | E12: Birim kapsama %100 | F12: ZORUNLU
A13: Sıfır/negatif | B13: Finansal format standardı | C13: Sıfır='-', negatif kırmızı parantez | D13: -500 veya 0,00 kalabalığı | E13: Format kontrolü | F13: ZORUNLU
A14: Yazı tipi | B14: Tek aile | C14: Aptos veya Segoe UI | D14: Karışık font | E14: Tek font kontrolü | F14: ZORUNLU
... A22: Premium vitrin | B22: Görsel kalite ürün değerinin zorunlu parçasıdır | C22: Kaliteli grafik, gerçek KPI kartı, finansal hiyerarşi, tab rengi, fonksiyonel navigasyon | D22: Sadece doğru hesap yapıp çıplak/varsayılan Excel görünümü bırakmak | E22: Görsel release incelemesi | F22: ZORUNLU

Sheet 04_MUHASEBE_THP
A1: TÜRKİYE MUHASEBE VE TEKDÜZEN HESAP PLANI STANDARDI
A3: Konu | B3: Zorunlu Standart | C3: Örnek Türkçe Ad | D3: THP / Mantık | E3: Hata Riski | F3: Kontrol
A4: Dil | B4: Kullanıcıya görünen finansal terimler Türkçe | C4: Hasılat, Satışların Maliyeti, Brüt Kâr, Faaliyet Giderleri | D4: Türk işletme kullanımına uygun | E4: İngilizce jargon | F4: Terminoloji taraması
A5: Gelir Tablosu | B5: Türk sunum sırası kullanılır | C5: Net Satışlar → Satışların Maliyeti → Brüt Kâr → Faaliyet Giderleri → Faaliyet Kârı | D5: 600/610/611; 620-623; 63x | E5: Yanlış sınıflama | F5: Hesap eşleme
A6: Bilanço | B6: Dönen/Duran Varlık ve Kısa/Uzun Vadeli Yükümlülük ayrımı | C6: Hazır Değerler, Ticari Alacaklar, Stoklar, Mali Borçlar | D6: 1xx / 2xx / 3xx / 4xx / 5xx | E6: Vade sınıfı hatası | F6: Bilanço eşitliği
A7: Nakit Akışı | B7: İşletme/Yatırım/Finansman nakit akışları ayrılır | C7: Faaliyetlerden Nakit, Yatırım Harcamaları, Finansman Nakit Akışı | D7: Dolaylı/doğrudan yöntem açık seçilir | E7: Kâr = nakit sanılması | F7: Nakit devri
A8: Ticari Alacaklar | B8: Cari ve vade mantığı korunur | C8: 120 Alıcılar | D8: 120 | E8: Tahakkuk/nakit karışması | F8: Alacak devir kontrolü
A9: Ticari Borçlar | B9: Tedarikçi borcu ayrı izlenir | C9: 320 Satıcılar | D9: 320 | E9: Gider/ödeme karışması | F9: Borç devir kontrolü
A10: Kasa/Banka | B10: Hazır değerler ayrı izlenir | C10: 100 Kasa, 102 Bankalar | D10: 100 / 102 | E10: Virmanla toplam nakdin değişmesi | F10: Virman değişmezi
A11: Stok | B11: Dikeye uygun stok türü | C11: 150 İlk Madde ve Malzeme, 153 Ticari Mallar | D11: 15x | E11: Maliyet ve stok hareketinin kopması | F11: Stok devri
A12: Maddi Duran Varlık | B12: Yatırım harcaması ve amortisman bağlantılı | C12: 253 Tesis Makine Cihazlar, 255 Demirbaşlar, 257 Birikmiş Amortismanlar | D12: 25x | E12: Yatırım/gider karışması | F12: Net defter değeri devri
A13: Mali Borçlar | B13: Kısa/uzun vadeli borç ayrımı | C13: 300 Banka Kredileri / 400 Banka Kredileri | D13: 300 / 400 | E13: Vade sınıfı yanlış | F13: Borç devri
A14: Özkaynak | B14: Sermaye ve geçmiş yıl kârları ayrı | C14: 500 Sermaye, 570 Geçmiş Yıllar Kârları, 590 Dönem Net Kârı | D14: 5xx | E14: Net kâr bağının kopması | F14: Özkaynak devri
... A18: İstisna | B18: TFRS özel ürün varsa fark açık yazılır | C18: Tekdüzen raporlama ≠ TFRS finansal tablo sunumu | D18: Amaç belirtilir | E18: Standartları karıştırma | F18: Model amacı kontrolü

Sheet 05_KARAR_SATIS
A1: KARAR, GÜVEN VE SATIŞA HAZIRLIK STANDARDI
A3: Alan | B3: Müşteri Sorusu | C3: Zorunlu Ürün Davranışı | D3: Kanıt | E3: Başarısızlık Durumu | F3: Kapı
A4: 5 saniye | B4: Bu ürün neyi çözüyor? | C4: İlk ekranda hedef kullanıcı + pahalı problem + sonuç görünür | D4: Başlık + alt mesaj + gerçek ekran | E4: Ürün yalnız teknik isim | F4: HATA
A5: Acı | B5: Sorun bana neye mal oluyor? | C5: Mümkünse müşterinin kendi verisiyle parasal/zaman etkisi hesaplanır | D5: ROI/acı hesaplama yöntemi | E5: Uydurma tasarruf | F5: HATA
A6: Karar | B6: Bu bilgiyle ne yapacağım? | C6: Her kritik KPI aksiyona bağlanır | D6: KARAR_KUYRUGU | E6: Sadece rapor | F6: HATA
A7: Güven | B7: Bu sayıya neden inanayım? | C7: Kaynak, formül mantığı, kontrol ve son doğrulama görünür | D7: Kontroller + kaynak izi + sürüm | E7: Prestij kelimesi | F7: HATA
A8: Referans | B8: Müşteri yorumu yoksa ne göstereceğim? | C8: Önce/Sonra + Karar Vakası + Hata Önleme Vakası üretilir | D8: Demo/örnek çıktı | E8: Kanıtsız iddia | F8: HATA
A9: Senaryo | B9: Ne olursa işler bozulur? | C9: Baz/Aşağı/Yukarı veya uygun stres senaryosu | D9: Senaryo karşılaştırma | E9: Dekoratif senaryo | F9: HATA
A10: Ters stres | B10: Hangi eşikte karar kırılır? | C10: En az bir kritik sürücü için kırılma eşiği | D10: Kırılma eşiği tablosu | E10: Sadece +/- %10 | F10: UYARI/HATA
A11: Hata tutarlılığı | B11: Formül hata verirse ne olur? | C11: Kontrol GEÇTİ veremez; BLOKE/HATA üretir | D11: Hata taraması | E11: Hata + GEÇTİ birlikte | F11: HATA
A12: Karar motoru | B12: Ne oldu, neden oldu? | C12: Sorun + neden + parasal etki + aksiyon + son tarih | D12: Karar tablosu | E12: Boş sayfa / isim düzeyi modül | F12: HATA
A13: Yönetici özeti | B13: 5 saniyede ne görmeliyim? | C13: Bugün / ne değişti / ne bozulacak / neden / ne yapmalıyım / güven | D13: Yönetici özeti ekranı | E13: KPI kutusu yığını | F13: HATA
A14: Teklif | B14: Neden satın almalıyım? | C14: Dosya özellikleri yerine sonuç ve kaçınılan maliyet sunulur | D14: Ürün sayfası kanıt eşlemesi | E14: Özellik listesiyle satış | F14: HATA
... A19: Pazar kanıtı | B19: Piyasa gerçekten ödüyor mu? | C19: Satış/pilot/LOI/fiyat kabulü olmadan pazar doğrulandı yazılmaz | D19: Gerçek işlem kanıtı | E19: Tahmini talep = satış kabulü | F19: HATA

Sheet KAPAK
A1: KAPAK — İnşaat Hakediş ve Şantiye Maliyet Takip
A3: İnşaat Hakediş ve Şantiye Maliyet Takip
A4: Hakediş kuyruğu ile şantiye maliyet kartını tek dosyada birleştirir; durum makinesi, yaşlandırma ve bütçe sapması ile karar üretir.
A6: Bu ürün ne sağlar?
A7: • Makrosuz durum makinesi: Taslak → Bekliyor → Onay → Ödeme / İptal
A8: • Hakediş kuyruk + yaşlandırma kovaları (0-7 / 8-30 / 31-60 / 60+)
A9: • Şantiye maliyet kartı: bütçe, işçilik, malzeme, makine, genel gider, hakediş
A10: • Geçersiz geçiş, yetim kayıt ve zincir kırık uyarıları
A11: • Karar kapısı: VERİ YOK / UYGUN / DİKKAT / KRİTİK
A13: Kimler için?
A14: • Şantiye muhasebesi — kuyruk ve maliyet kartını günceller
A15: • Proje müdürü — sapma ve gecikme kararını görür
... A21: Sürüm 1.0.0 | Lisans: Tek kullanıcı | ExcelArşiv

Sheet KARTLAR
A1: KARTLAR — İnşaat Hakediş ve Şantiye Maliyet Takip
A3: Taşeron / proje kartları — her kaydın tek kimliği vardır
A4: Sonraki Kimlik | B4: =ihs_sonrakiKimlik
A5: KartId | B5: Unvan | C5: Brans | D5: Sehir | E5: SozlesmeNo | F5: LimitTl | G5: RiskNotu | H5: Aktif | I5: SantiyeId | J5: ToplamHacim | K5: OrtGecikme
A6: KAR-00001 | B6: Atlas Kalıp Ltd. | C6: Kalıp | D6: İstanbul | E6: SZL-2026-001 | F6: 2500000 | G6: Normal | H6: EVET | I6: SAN-00001 | J6: =IF($A6="","",SUMIF(tblAkis[KaynakKartId],$A6,tblAkis[Tutar])) | K6: =IF($A6="","",IFERROR(AVERAGEIF(tblAkis[KaynakKartId],$A6,tblAkis[YasGun]),0))
A7: KAR-00002 | B7: Demir Yapı A.Ş. | C7: Demir | D7: Ankara | E7: SZL-2026-002 | F7: 2650000 | G7: Normal | H7: EVET | I7: SAN-00001 | J7: =IF($A7="","",SUMIF(tblAkis[KaynakKartId],$A7,tblAkis[Tutar])) | K7: =IF($A7="","",IFERROR(AVERAGEIF(tblAkis[KaynakKartId],$A7,tblAkis[YasGun]),0))
A8: KAR-00003 | B8: Nova Beton | C8: Beton | D8: İzmir | E8: SZL-2026-003 | F8: 2800000 | G8: Normal | H8: EVET | I8: SAN-00002 | J8: =IF($A8="","",SUMIF(tblAkis[KaynakKartId],$A8,tblAkis[Tutar])) | K8: =IF($A8="","",IFERROR(AVERAGEIF(tblAkis[KaynakKartId],$A8,tblAkis[YasGun]),0))
A9: KAR-00004 | B9: Proje Elektrik | C9: Elektrik | D9: Bursa | E9: SZL-2026-004 | F9: 2950000 | G9: Normal | H9: EVET | I9: SAN-00002 | J9: =IF($A9="","",SUMIF(tblAkis[KaynakKartId],$A9,tblAkis[Tutar])) | K9: =IF($A9="","",IFERROR(AVERAGEIF(tblAkis[KaynakKartId],$A9,tblAkis[YasGun]),0))
A10: KAR-00005 | B10: Su Tesisat Pro | C10: Tesisat | D10: Antalya | E10: SZL-2026-005 | F10: 3100000 | G10: Normal | H10: EVET | I10: SAN-00003 | J10: =IF($A10="","",SUMIF(tblAkis[KaynakKartId],$A10,tblAkis[Tutar])) | K10: =IF($A10="","",IFERROR(AVERAGEIF(tblAkis[KaynakKartId],$A10,tblAkis[YasGun]),0))
A11: KAR-00006 | B11: Cephe Sistemleri | C11: Cephe | D11: Kocaeli | E11: SZL-2026-006 | F11: 3250000 | G11: Normal | H11: EVET | I11: SAN-00003 | J11: =IF($A11="","",SUMIF(tblAkis[KaynakKartId],$A11,tblAkis[Tutar])) | K11: =IF($A11="","",IFERROR(AVERAGEIF(tblAkis[KaynakKartId],$A11,tblAkis[YasGun]),0))
A12: KAR-00007 | B12: Zemin Stabil | C12: Zemin | D12: Adana | E12: SZL-2026-007 | F12: 3400000 | G12: Normal | H12: EVET | I12: SAN-00004 | J12: =IF($A12="","",SUMIF(tblAkis[KaynakKartId],$A12,tblAkis[Tutar])) | K12: =IF($A12="","",IFERROR(AVERAGEIF(tblAkis[KaynakKartId],$A12,tblAkis[YasGun]),0))
A13: KAR-00008 | B13: İskele Güven | C13: İskele | D13: Gaziantep | E13: SZL-2026-008 | F13: 3550000 | G13: Normal | H13: EVET | I13: SAN-00004 | J13: =IF($A13="","",SUMIF(tblAkis[KaynakKartId],$A13,tblAkis[Tutar])) | K13: =IF($A13="","",IFERROR(AVERAGEIF(tblAkis[KaynakKartId],$A13,tblAkis[YasGun]),0))
J14: =IF($A14="","",SUMIF(tblAkis[KaynakKartId],$A14,tblAkis[Tutar])) | K14: =IF($A14="","",IFERROR(AVERAGEIF(tblAkis[KaynakKartId],$A14,tblAkis[YasGun]),0))
J15: =IF($A15="","",SUMIF(tblAkis[KaynakKartId],$A15,tblAkis[Tutar])) | K15: =IF($A15="","",IFERROR(AVERAGEIF(tblAkis[KaynakKartId],$A15,tblAkis[YasGun]),0))
J16: =IF($A16="","",SUMIF(tblAkis[KaynakKartId],$A16,tblAkis[Tutar])) | K16: =IF($A16="","",IFERROR(AVERAGEIF(tblAkis[KaynakKartId],$A16,tblAkis[YasGun]),0))
J17: =IF($A17="","",SUMIF(tblAkis[KaynakKartId],$A17,tblAkis[Tutar])) | K17: =IF($A17="","",IFERROR(AVERAGEIF(tblAkis[KaynakKartId],$A17,tblAkis[YasGun]),0))
J18: =IF($A18="","",SUMIF(tblAkis[KaynakKartId],$A18,tblAkis[Tutar])) | K18: =IF($A18="","",IFERROR(AVERAGEIF(tblAkis[KaynakKartId],$A18,tblAkis[YasGun]),0))
J19: =IF($A19="","",SUMIF(tblAkis[KaynakKartId],$A19,tblAkis[Tutar])) | K19: =IF($A19="","",IFERROR(AVERAGEIF(tblAkis[KaynakKartId],$A19,tblAkis[YasGun]),0))
J20: =IF($A20="","",SUMIF(tblAkis[KaynakKartId],$A20,tblAkis[Tutar])) | K20: =IF($A20="","",IFERROR(AVERAGEIF(tblAkis[KaynakKartId],$A20,tblAkis[YasGun]),0))
J21: =IF($A21="","",SUMIF(tblAkis[KaynakKartId],$A21,tblAkis[Tutar])) | K21: =IF($A21="","",IFERROR(AVERAGEIF(tblAkis[KaynakKartId],$A21,tblAkis[YasGun]),0))
J22: =IF($A22="","",SUMIF(tblAkis[KaynakKartId],$A22,tblAkis[Tutar])) | K22: =IF($A22="","",IFERROR(AVERAGEIF(tblAkis[KaynakKartId],$A22,tblAkis[YasGun]),0))
J23: =IF($A23="","",SUMIF(tblAkis[KaynakKartId],$A23,tblAkis[Tutar])) | K23: =IF($A23="","",IFERROR(AVERAGEIF(tblAkis[KaynakKartId],$A23,tblAkis[YasGun]),0))
J24: =IF($A24="","",SUMIF(tblAkis[KaynakKartId],$A24,tblAkis[Tutar])) | K24: =IF($A24="","",IFERROR(AVERAGEIF(tblAkis[KaynakKartId],$A24,tblAkis[YasGun]),0))
J25: =IF($A25="","",SUMIF(tblAkis[KaynakKartId],$A25,tblAkis[Tutar])) | K25: =IF($A25="","",IFERROR(AVERAGEIF(tblAkis[KaynakKartId],$A25,tblAkis[YasGun]),0))
... J255: =IF($A255="","",SUMIF(tblAkis[KaynakKartId],$A255,tblAkis[Tutar])) | K255: =IF($A255="","",IFERROR(AVERAGEIF(tblAkis[KaynakKartId],$A255,tblAkis[YasGun]),0))

Sheet AKIS
A1: AKIS — İnşaat Hakediş ve Şantiye Maliyet Takip
A3: İşlem satırları — durum makinesi + yetim + geçersiz geçiş + zincir bayrakları
A5: IslemId | B5: KaynakKartId | C5: SantiyeId | D5: Tarih | E5: OncekiDurum | F5: Durum | G5: Teklif | H5: Siparis | I5: Hakedis | J5: Fatura | K5: Odeme | L5: Tutar | M5: Donem | N5: Aciklama | O5: YasGun | P5: YasKova | Q5: YetimBayrak | R5: GecisUyarisi | S5: ZincirBayrak | T5: KayitDolu
A6: HAK-00001 | B6: KAR-00001 | C6: SAN-00001 | D6: 46245 | F6: DRAFT | G6: 112500 | H6: 112500 | I6: 112500 | J6: 112500 | K6: 0 | L6: 112500 | M6: 2026-08 | N6: Hakediş kalemi 1 | O6: =IF($A6="","",IF($D6="","",raporTarihi-$D6)) | P6: =IF($A6="","",IF($O6="","",IF($O6<=7,"0-7",IF($O6<=30,"8-30",IF($O6<=60,"31-60","60+"))))) | Q6: =IF($A6="","",IF($B6="","YETİM",IF(COUNTIF(tblKartlar[KartId],$B6)=0,"YETİM",""))) | R6: =IF(OR($A6="",$E6=""),"",IF(OR($E6&"|"&$F6="",COUNTIF(ListeIzinliGecis,$E6&"|"&$F6)>0),"","GEÇERSİZ GEÇİŞ")) | S6: =IF($A6="","",IF(OR($G6="",$I6=""),"",IF(ABS($I6-$G6)>zincirTolerans,"ZİNCİR KIRIK","OK"))) | T6: =IF($A6="","",1)
A7: HAK-00002 | B7: KAR-00002 | C7: SAN-00001 | D7: 46242 | E7: DRAFT | F7: BEKLIYOR | G7: 125000 | H7: 125000 | I7: 125000 | J7: 125000 | K7: 0 | L7: 125000 | M7: 2026-08 | N7: Hakediş kalemi 2 | O7: =IF($A7="","",IF($D7="","",raporTarihi-$D7)) | P7: =IF($A7="","",IF($O7="","",IF($O7<=7,"0-7",IF($O7<=30,"8-30",IF($O7<=60,"31-60","60+"))))) | Q7: =IF($A7="","",IF($B7="","YETİM",IF(COUNTIF(tblKartlar[KartId],$B7)=0,"YETİM",""))) | R7: =IF(OR($A7="",$E7=""),"",IF(OR($E7&"|"&$F7="",COUNTIF(ListeIzinliGecis,$E7&"|"&$F7)>0),"","GEÇERSİZ GEÇİŞ")) | S7: =IF($A7="","",IF(OR($G7="",$I7=""),"",IF(ABS($I7-$G7)>zincirTolerans,"ZİNCİR KIRIK","OK"))) | T7: =IF($A7="","",1)
A8: HAK-00003 | B8: KAR-00003 | C8: SAN-00002 | D8: 46239 | E8: BEKLIYOR | F8: ONAY | G8: 137500 | H8: 137500 | I8: 137500 | J8: 137500 | K8: 0 | L8: 137500 | M8: 2026-08 | N8: Hakediş kalemi 3 | O8: =IF($A8="","",IF($D8="","",raporTarihi-$D8)) | P8: =IF($A8="","",IF($O8="","",IF($O8<=7,"0-7",IF($O8<=30,"8-30",IF($O8<=60,"31-60","60+"))))) | Q8: =IF($A8="","",IF($B8="","YETİM",IF(COUNTIF(tblKartlar[KartId],$B8)=0,"YETİM",""))) | R8: =IF(OR($A8="",$E8=""),"",IF(OR($E8&"|"&$F8="",COUNTIF(ListeIzinliGecis,$E8&"|"&$F8)>0),"","GEÇERSİZ GEÇİŞ")) | S8: =IF($A8="","",IF(OR($G8="",$I8=""),"",IF(ABS($I8-$G8)>zincirTolerans,"ZİNCİR KIRIK","OK"))) | T8: =IF($A8="","",1)
A9: HAK-00004 | B9: KAR-00004 | C9: SAN-00002 | D9: 46236 | E9: ONAY | F9: ODEME | G9: 150000 | H9: 150000 | I9: 150000 | J9: 150000 | K9: 150000 | L9: 150000 | M9: 2026-08 | N9: Hakediş kalemi 4 | O9: =IF($A9="","",IF($D9="","",raporTarihi-$D9)) | P9: =IF($A9="","",IF($O9="","",IF($O9<=7,"0-7",IF($O9<=30,"8-30",IF($O9<=60,"31-60","60+"))))) | Q9: =IF($A9="","",IF($B9="","YETİM",IF(COUNTIF(tblKartlar[KartId],$B9)=0,"YETİM",""))) | R9: =IF(OR($A9="",$E9=""),"",IF(OR($E9&"|"&$F9="",COUNTIF(ListeIzinliGecis,$E9&"|"&$F9)>0),"","GEÇERSİZ GEÇİŞ")) | S9: =IF($A9="","",IF(OR($G9="",$I9=""),"",IF(ABS($I9-$G9)>zincirTolerans,"ZİNCİR KIRIK","OK"))) | T9: =IF($A9="","",1)
A10: HAK-00005 | B10: KAR-00005 | C10: SAN-00003 | D10: 46233 | E10: BEKLIYOR | F10: IPTAL | G10: 162500 | H10: 162500 | I10: 162500 | J10: 162500 | K10: 0 | L10: 162500 | M10: 2026-08 | N10: Hakediş kalemi 5 | O10: =IF($A10="","",IF($D10="","",raporTarihi-$D10)) | P10: =IF($A10="","",IF($O10="","",IF($O10<=7,"0-7",IF($O10<=30,"8-30",IF($O10<=60,"31-60","60+"))))) | Q10: =IF($A10="","",IF($B10="","YETİM",IF(COUNTIF(tblKartlar[KartId],$B10)=0,"YETİM",""))) | R10: =IF(OR($A10="",$E10=""),"",IF(OR($E10&"|"&$F10="",COUNTIF(ListeIzinliGecis,$E10&"|"&$F10)>0),"","GEÇERSİZ GEÇİŞ")) | S10: =IF($A10="","",IF(OR($G10="",$I10=""),"",IF(ABS($I10-$G10)>zincirTolerans,"ZİNCİR KIRIK","OK"))) | T10: =IF($A10="","",1)
A11: HAK-00006 | B11: KAR-00006 | C11: SAN-00003 | D11: 46230 | E11: DRAFT | F11: BEKLIYOR | G11: 175000 | H11: 175000 | I11: 175000 | J11: 175000 | K11: 0 | L11: 175000 | M11: 2026-08 | N11: Hakediş kalemi 6 | O11: =IF($A11="","",IF($D11="","",raporTarihi-$D11)) | P11: =IF($A11="","",IF($O11="","",IF($O11<=7,"0-7",IF($O11<=30,"8-30",IF($O11<=60,"31-60","60+"))))) | Q11: =IF($A11="","",IF($B11="","YETİM",IF(COUNTIF(tblKartlar[KartId],$B11)=0,"YETİM",""))) | R11: =IF(OR($A11="",$E11=""),"",IF(OR($E11&"|"&$F11="",COUNTIF(ListeIzinliGecis,$E11&"|"&$F11)>0),"","GEÇERSİZ GEÇİŞ")) | S11: =IF($A11="","",IF(OR($G11="",$I11=""),"",IF(ABS($I11-$G11)>zincirTolerans,"ZİNCİR KIRIK","OK"))) | T11: =IF($A11="","",1)
A12: HAK-00007 | B12: KAR-00007 | C12: SAN-00004 | D12: 46227 | E12: BEKLIYOR | F12: ONAY | G12: 187500 | H12: 187500 | I12: 187500 | J12: 187500 | K12: 0 | L12: 187500 | M12: 2026-08 | N12: Hakediş kalemi 7 | O12: =IF($A12="","",IF($D12="","",raporTarihi-$D12)) | P12: =IF($A12="","",IF($O12="","",IF($O12<=7,"0-7",IF($O12<=30,"8-30",IF($O12<=60,"31-60","60+"))))) | Q12: =IF($A12="","",IF($B12="","YETİM",IF(COUNTIF(tblKartlar[KartId],$B12)=0,"YETİM",""))) | R12: =IF(OR($A12="",$E12=""),"",IF(OR($E12&"|"&$F12="",COUNTIF(ListeIzinliGecis,$E12&"|"&$F12)>0),"","GEÇERSİZ GEÇİŞ")) | S12: =IF($A12="","",IF(OR($G12="",$I12=""),"",IF(ABS($I12-$G12)>zincirTolerans,"ZİNCİR KIRIK","OK"))) | T12: =IF($A12="","",1)
A13: HAK-00008 | B13: KAR-00008 | C13: SAN-00004 | D13: 46224 | E13: ONAY | F13: BEKLIYOR | G13: 200000 | H13: 200000 | I13: 200000 | J13: 200000 | K13: 0 | L13: 200000 | M13: 2026-08 | N13: Hakediş kalemi 8 | O13: =IF($A13="","",IF($D13="","",raporTarihi-$D13)) | P13: =IF($A13="","",IF($O13="","",IF($O13<=7,"0-7",IF($O13<=30,"8-30",IF($O13<=60,"31-60","60+"))))) | Q13: =IF($A13="","",IF($B13="","YETİM",IF(COUNTIF(tblKartlar[KartId],$B13)=0,"YETİM",""))) | R13: =IF(OR($A13="",$E13=""),"",IF(OR($E13&"|"&$F13="",COUNTIF(ListeIzinliGecis,$E13&"|"&$F13)>0),"","GEÇERSİZ GEÇİŞ")) | S13: =IF($A13="","",IF(OR($G13="",$I13=""),"",IF(ABS($I13-$G13)>zincirTolerans,"ZİNCİR KIRIK","OK"))) | T13: =IF($A13="","",1)
A14: HAK-00009 | B14: KAR-00001 | C14: SAN-00001 | D14: 46221 | F14: DRAFT | G14: 212500 | H14: 212500 | I14: 212500 | J14: 212500 | K14: 0 | L14: 212500 | M14: 2026-08 | N14: Hakediş kalemi 9 | O14: =IF($A14="","",IF($D14="","",raporTarihi-$D14)) | P14: =IF($A14="","",IF($O14="","",IF($O14<=7,"0-7",IF($O14<=30,"8-30",IF($O14<=60,"31-60","60+"))))) | Q14: =IF($A14="","",IF($B14="","YETİM",IF(COUNTIF(tblKartlar[KartId],$B14)=0,"YETİM",""))) | R14: =IF(OR($A14="",$E14=""),"",IF(OR($E14&"|"&$F14="",COUNTIF(ListeIzinliGecis,$E14&"|"&$F14)>0),"","GEÇERSİZ GEÇİŞ")) | S14: =IF($A14="","",IF(OR($G14="",$I14=""),"",IF(ABS($I14-$G14)>zincirTolerans,"ZİNCİR KIRIK","OK"))) | T14: =IF($A14="","",1)
A15: HAK-00010 | B15: KAR-00002 | C15: SAN-00001 | D15: 46218 | E15: DRAFT | F15: BEKLIYOR | G15: 225000 | H15: 225000 | I15: 225000 | J15: 225000 | K15: 0 | L15: 225000 | M15: 2026-08 | N15: Hakediş kalemi 10 | O15: =IF($A15="","",IF($D15="","",raporTarihi-$D15)) | P15: =IF($A15="","",IF($O15="","",IF($O15<=7,"0-7",IF($O15<=30,"8-30",IF($O15<=60,"31-60","60+"))))) | Q15: =IF($A15="","",IF($B15="","YETİM",IF(COUNTIF(tblKartlar[KartId],$B15)=0,"YETİM",""))) | R15: =IF(OR($A15="",$E15=""),"",IF(OR($E15&"|"&$F15="",COUNTIF(ListeIzinliGecis,$E15&"|"&$F15)>0),"","GEÇERSİZ GEÇİŞ")) | S15: =IF($A15="","",IF(OR($G15="",$I15=""),"",IF(ABS($I15-$G15)>zincirTolerans,"ZİNCİR KIRIK","OK"))) | T15: =IF($A15="","",1)
A16: HAK-00011 | B16: KAR-00003 | C16: SAN-00002 | D16: 46215 | E16: BEKLIYOR | F16: ONAY | G16: 237500 | H16: 237500 | I16: 237500 | J16: 237500 | K16: 0 | L16: 237500 | M16: 2026-08 | N16: Hakediş kalemi 11 | O16: =IF($A16="","",IF($D16="","",raporTarihi-$D16)) | P16: =IF($A16="","",IF($O16="","",IF($O16<=7,"0-7",IF($O16<=30,"8-30",IF($O16<=60,"31-60","60+"))))) | Q16: =IF($A16="","",IF($B16="","YETİM",IF(COUNTIF(tblKartlar[KartId],$B16)=0,"YETİM",""))) | R16: =IF(OR($A16="",$E16=""),"",IF(OR($E16&"|"&$F16="",COUNTIF(ListeIzinliGecis,$E16&"|"&$F16)>0),"","GEÇERSİZ GEÇİŞ")) | S16: =IF($A16="","",IF(OR($G16="",$I16=""),"",IF(ABS($I16-$G16)>zincirTolerans,"ZİNCİR KIRIK","OK"))) | T16: =IF($A16="","",1)
A17: HAK-00012 | B17: KAR-00004 | C17: SAN-00002 | D17: 46212 | E17: ONAY | F17: ODEME | G17: 250000 | H17: 250000 | I17: 295000 | J17: 295000 | K17: 295000 | L17: 295000 | M17: 2026-08 | N17: Hakediş kalemi 12 | O17: =IF($A17="","",IF($D17="","",raporTarihi-$D17)) | P17: =IF($A17="","",IF($O17="","",IF($O17<=7,"0-7",IF($O17<=30,"8-30",IF($O17<=60,"31-60","60+"))))) | Q17: =IF($A17="","",IF($B17="","YETİM",IF(COUNTIF(tblKartlar[KartId],$B17)=0,"YETİM",""))) | R17: =IF(OR($A17="",$E17=""),"",IF(OR($E17&"|"&$F17="",COUNTIF(ListeIzinliGecis,$E17&"|"&$F17)>0),"","GEÇERSİZ GEÇİŞ")) | S17: =IF($A17="","",IF(OR($G17="",$I17=""),"",IF(ABS($I17-$G17)>zincirTolerans,"ZİNCİR KIRIK","OK"))) | T17: =IF($A17="","",1)
A18: HAK-00013 | B18: KAR-00005 | C18: SAN-00003 | D18: 46209 | E18: BEKLIYOR | F18: IPTAL | G18: 262500 | H18: 262500 | I18: 262500 | J18: 262500 | K18: 0 | L18: 262500 | M18: 2026-08 | N18: Hakediş kalemi 13 | O18: =IF($A18="","",IF($D18="","",raporTarihi-$D18)) | P18: =IF($A18="","",IF($O18="","",IF($O18<=7,"0-7",IF($O18<=30,"8-30",IF($O18<=60,"31-60","60+"))))) | Q18: =IF($A18="","",IF($B18="","YETİM",IF(COUNTIF(tblKartlar[KartId],$B18)=0,"YETİM",""))) | R18: =IF(OR($A18="",$E18=""),"",IF(OR($E18&"|"&$F18="",COUNTIF(ListeIzinliGecis,$E18&"|"&$F18)>0),"","GEÇERSİZ GEÇİŞ")) | S18: =IF($A18="","",IF(OR($G18="",$I18=""),"",IF(ABS($I18-$G18)>zincirTolerans,"ZİNCİR KIRIK","OK"))) | T18: =IF($A18="","",1)
A19: HAK-00014 | B19: KAR-00006 | C19: SAN-00003 | D19: 46206 | E19: DRAFT | F19: BEKLIYOR | G19: 275000 | H19: 275000 | I19: 275000 | J19: 275000 | K19: 0 | L19: 275000 | M19: 2026-08 | N19: Hakediş kalemi 14 | O19: =IF($A19="","",IF($D19="","",raporTarihi-$D19)) | P19: =IF($A19="","",IF($O19="","",IF($O19<=7,"0-7",IF($O19<=30,"8-30",IF($O19<=60,"31-60","60+"))))) | Q19: =IF($A19="","",IF($B19="","YETİM",IF(COUNTIF(tblKartlar[KartId],$B19)=0,"YETİM",""))) | R19: =IF(OR($A19="",$E19=""),"",IF(OR($E19&"|"&$F19="",COUNTIF(ListeIzinliGecis,$E19&"|"&$F19)>0),"","GEÇERSİZ GEÇİŞ")) | S19: =IF($A19="","",IF(OR($G19="",$I19=""),"",IF(ABS($I19-$G19)>zincirTolerans,"ZİNCİR KIRIK","OK"))) | T19: =IF($A19="","",1)
A20: HAK-00015 | B20: KAR-00007 | C20: SAN-00004 | D20: 46203 | E20: BEKLIYOR | F20: ONAY | G20: 287500 | H20: 287500 | I20: 287500 | J20: 279500 | K20: 0 | L20: 287500 | M20: 2026-08 | N20: Hakediş kalemi 15 | O20: =IF($A20="","",IF($D20="","",raporTarihi-$D20)) | P20: =IF($A20="","",IF($O20="","",IF($O20<=7,"0-7",IF($O20<=30,"8-30",IF($O20<=60,"31-60","60+"))))) | Q20: =IF($A20="","",IF($B20="","YETİM",IF(COUNTIF(tblKartlar[KartId],$B20)=0,"YETİM",""))) | R20: =IF(OR($A20="",$E20=""),"",IF(OR($E20&"|"&$F20="",COUNTIF(ListeIzinliGecis,$E20&"|"&$F20)>0),"","GEÇERSİZ GEÇİŞ")) | S20: =IF($A20="","",IF(OR($G20="",$I20=""),"",IF(ABS($I20-$G20)>zincirTolerans,"ZİNCİR KIRIK","OK"))) | T20: =IF($A20="","",1)
A21: HAK-00016 | B21: KAR-00008 | C21: SAN-00004 | D21: 46200 | E21: ONAY | F21: BEKLIYOR | G21: 300000 | H21: 300000 | I21: 300000 | J21: 300000 | K21: 0 | L21: 300000 | M21: 2026-08 | N21: Hakediş kalemi 16 | O21: =IF($A21="","",IF($D21="","",raporTarihi-$D21)) | P21: =IF($A21="","",IF($O21="","",IF($O21<=7,"0-7",IF($O21<=30,"8-30",IF($O21<=60,"31-60","60+"))))) | Q21: =IF($A21="","",IF($B21="","YETİM",IF(COUNTIF(tblKartlar[KartId],$B21)=0,"YETİM",""))) | R21: =IF(OR($A21="",$E21=""),"",IF(OR($E21&"|"&$F21="",COUNTIF(ListeIzinliGecis,$E21&"|"&$F21)>0),"","GEÇERSİZ GEÇİŞ")) | S21: =IF($A21="","",IF(OR($G21="",$I21=""),"",IF(ABS($I21-$G21)>zincirTolerans,"ZİNCİR KIRIK","OK"))) | T21: =IF($A21="","",1)
A22: HAK-00017 | B22: KAR-00001 | C22: SAN-00001 | D22: 46197 | F22: DRAFT | G22: 312500 | H22: 312500 | I22: 312500 | J22: 312500 | K22: 0 | L22: 312500 | M22: 2026-08 | N22: Hakediş kalemi 17 | O22: =IF($A22="","",IF($D22="","",raporTarihi-$D22)) | P22: =IF($A22="","",IF($O22="","",IF($O22<=7,"0-7",IF($O22<=30,"8-30",IF($O22<=60,"31-60","60+"))))) | Q22: =IF($A22="","",IF($B22="","YETİM",IF(COUNTIF(tblKartlar[KartId],$B22)=0,"YETİM",""))) | R22: =IF(OR($A22="",$E22=""),"",IF(OR($E22&"|"&$F22="",COUNTIF(ListeIzinliGecis,$E22&"|"&$F22)>0),"","GEÇERSİZ GEÇİŞ")) | S22: =IF($A22="","",IF(OR($G22="",$I22=""),"",IF(ABS($I22-$G22)>zincirTolerans,"ZİNCİR KIRIK","OK"))) | T22: =IF($A22="","",1)
A23: HAK-00018 | B23: KAR-00002 | C23: SAN-00001 | D23: 46194 | E23: DRAFT | F23: ONAY | G23: 325000 | H23: 325000 | I23: 325000 | J23: 325000 | K23: 0 | L23: 325000 | M23: 2026-08 | N23: Hakediş kalemi 18 | O23: =IF($A23="","",IF($D23="","",raporTarihi-$D23)) | P23: =IF($A23="","",IF($O23="","",IF($O23<=7,"0-7",IF($O23<=30,"8-30",IF($O23<=60,"31-60","60+"))))) | Q23: =IF($A23="","",IF($B23="","YETİM",IF(COUNTIF(tblKartlar[KartId],$B23)=0,"YETİM",""))) | R23: =IF(OR($A23="",$E23=""),"",IF(OR($E23&"|"&$F23="",COUNTIF(ListeIzinliGecis,$E23&"|"&$F23)>0),"","GEÇERSİZ GEÇİŞ")) | S23: =IF($A23="","",IF(OR($G23="",$I23=""),"",IF(ABS($I23-$G23)>zincirTolerans,"ZİNCİR KIRIK","OK"))) | T23: =IF($A23="","",1)
A24: HAK-00019 | B24: KAR-00003 | C24: SAN-00002 | D24: 46191 | E24: BEKLIYOR | F24: ONAY | G24: 337500 | H24: 337500 | I24: 382500 | J24: 382500 | K24: 0 | L24: 382500 | M24: 2026-08 | N24: Hakediş kalemi 19 | O24: =IF($A24="","",IF($D24="","",raporTarihi-$D24)) | P24: =IF($A24="","",IF($O24="","",IF($O24<=7,"0-7",IF($O24<=30,"8-30",IF($O24<=60,"31-60","60+"))))) | Q24: =IF($A24="","",IF($B24="","YETİM",IF(COUNTIF(tblKartlar[KartId],$B24)=0,"YETİM",""))) | R24: =IF(OR($A24="",$E24=""),"",IF(OR($E24&"|"&$F24="",COUNTIF(ListeIzinliGecis,$E24&"|"&$F24)>0),"","GEÇERSİZ GEÇİŞ")) | S24: =IF($A24="","",IF(OR($G24="",$I24=""),"",IF(ABS($I24-$G24)>zincirTolerans,"ZİNCİR KIRIK","OK"))) | T24: =IF($A24="","",1)
A25: HAK-00020 | B25: KAR-00004 | C25: SAN-00002 | D25: 46188 | E25: ONAY | F25: BEKLIYOR | G25: 350000 | H25: 350000 | I25: 350000 | J25: 350000 | K25: 0 | L25: 350000 | M25: 2026-08 | N25: Hakediş kalemi 20 | O25: =IF($A25="","",IF($D25="","",raporTarihi-$D25)) | P25: =IF($A25="","",IF($O25="","",IF($O25<=7,"0-7",IF($O25<=30,"8-30",IF($O25<=60,"31-60","60+"))))) | Q25: =IF($A25="","",IF($B25="","YETİM",IF(COUNTIF(tblKartlar[KartId],$B25)=0,"YETİM",""))) | R25: =IF(OR($A25="",$E25=""),"",IF(OR($E25&"|"&$F25="",COUNTIF(ListeIzinliGecis,$E25&"|"&$F25)>0),"","GEÇERSİZ GEÇİŞ")) | S25: =IF($A25="","",IF(OR($G25="",$I25=""),"",IF(ABS($I25-$G25)>zincirTolerans,"ZİNCİR KIRIK","OK"))) | T25: =IF($A25="","",1)
A26: HAK-00021 | B26: KAR-00005 | C26: SAN-00003 | D26: 46185 | E26: BEKLIYOR | F26: IPTAL | G26: 362500 | H26: 362500 | I26: 362500 | J26: 362500 | K26: 0 | L26: 362500 | M26: 2026-08 | N26: Hakediş kalemi 21 | O26: =IF($A26="","",IF($D26="","",raporTarihi-$D26)) | P26: =IF($A26="","",IF($O26="","",IF($O26<=7,"0-7",IF($O26<=30,"8-30",IF($O26<=60,"31-60","60+"))))) | Q26: =IF($A26="","",IF($B26="","YETİM",IF(COUNTIF(tblKartlar[KartId],$B26)=0,"YETİM",""))) | R26: =IF(OR($A26="",$E26=""),"",IF(OR($E26&"|"&$F26="",COUNTIF(ListeIzinliGecis,$E26&"|"&$F26)>0),"","GEÇERSİZ GEÇİŞ")) | S26: =IF($A26="","",IF(OR($G26="",$I26=""),"",IF(ABS($I26-$G26)>zincirTolerans,"ZİNCİR KIRIK","OK"))) | T26: =IF($A26="","",1)
A27: HAK-00022 | C27: SAN-00001 | D27: 46182 | E27: DRAFT | F27: BEKLIYOR | G27: 375000 | H27: 375000 | I27: 375000 | J27: 375000 | K27: 0 | L27: 375000 | M27: 2026-08 | N27: Hakediş kalemi 22 | O27: =IF($A27="","",IF($D27="","",raporTarihi-$D27)) | P27: =IF($A27="","",IF($O27="","",IF($O27<=7,"0-7",IF($O27<=30,"8-30",IF($O27<=60,"31-60","60+"))))) | Q27: =IF($A27="","",IF($B27="","YETİM",IF(COUNTIF(tblKartlar[KartId],$B27)=0,"YETİM",""))) | R27: =IF(OR($A27="",$E27=""),"",IF(OR($E27&"|"&$F27="",COUNTIF(ListeIzinliGecis,$E27&"|"&$F27)>0),"","GEÇERSİZ GEÇİŞ")) | S27: =IF($A27="","",IF(OR($G27="",$I27=""),"",IF(ABS($I27-$G27)>zincirTolerans,"ZİNCİR KIRIK","OK"))) | T27: =IF($A27="","",1)
A28: HAK-00023 | B28: KAR-00007 | C28: SAN-00004 | D28: 46179 | E28: BEKLIYOR | F28: ONAY | G28: 387500 | H28: 387500 | I28: 387500 | J28: 387500 | K28: 0 | L28: 387500 | M28: 2026-08 | N28: Hakediş kalemi 23 | O28: =IF($A28="","",IF($D28="","",raporTarihi-$D28)) | P28: =IF($A28="","",IF($O28="","",IF($O28<=7,"0-7",IF($O28<=30,"8-30",IF($O28<=60,"31-60","60+"))))) | Q28: =IF($A28="","",IF($B28="","YETİM",IF(COUNTIF(tblKartlar[KartId],$B28)=0,"YETİM",""))) | R28: =IF(OR($A28="",$E28=""),"",IF(OR($E28&"|"&$F28="",COUNTIF(ListeIzinliGecis,$E28&"|"&$F28)>0),"","GEÇERSİZ GEÇİŞ")) | S28: =IF($A28="","",IF(OR($G28="",$I28=""),"",IF(ABS($I28-$G28)>zincirTolerans,"ZİNCİR KIRIK","OK"))) | T28: =IF($A28="","",1)
A29: HAK-00024 | B29: KAR-00008 | C29: SAN-00004 | D29: 46176 | E29: ONAY | F29: BEKLIYOR | G29: 400000 | H29: 400000 | I29: 400000 | J29: 400000 | K29: 0 | L29: 400000 | M29: 2026-08 | N29: Hakediş kalemi 24 | O29: =IF($A29="","",IF($D29="","",raporTarihi-$D29)) | P29: =IF($A29="","",IF($O29="","",IF($O29<=7,"0-7",IF($O29<=30,"8-30",IF($O29<=60,"31-60","60+"))))) | Q29: =IF($A29="","",IF($B29="","YETİM",IF(COUNTIF(tblKartlar[KartId],$B29)=0,"YETİM",""))) | R29: =IF(OR($A29="",$E29=""),"",IF(OR($E29&"|"&$F29="",COUNTIF(ListeIzinliGecis,$E29&"|"&$F29)>0),"","GEÇERSİZ GEÇİŞ")) | S29: =IF($A29="","",IF(OR($G29="",$I29=""),"",IF(ABS($I29-$G29)>zincirTolerans,"ZİNCİR KIRIK","OK"))) | T29: =IF($A29="","",1)
A30: HAK-00025 | B30: KAR-99999 | C30: SAN-00001 | D30: 46248 | F30: DRAFT | G30: 412500 | H30: 412500 | I30: 412500 | J30: 412500 | K30: 0 | L30: 412500 | M30: 2026-08 | N30: Hakediş kalemi 25 | O30: =IF($A30="","",IF($D30="","",raporTarihi-$D30)) | P30: =IF($A30="","",IF($O30="","",IF($O30<=7,"0-7",IF($O30<=30,"8-30",IF($O30<=60,"31-60","60+"))))) | Q30: =IF($A30="","",IF($B30="","YETİM",IF(COUNTIF(tblKartlar[KartId],$B30)=0,"YETİM",""))) | R30: =IF(OR($A30="",$E30=""),"",IF(OR($E30&"|"&$F30="",COUNTIF(ListeIzinliGecis,$E30&"|"&$F30)>0),"","GEÇERSİZ GEÇİŞ")) | S30: =IF($A30="","",IF(OR($G30="",$I30=""),"",IF(ABS($I30-$G30)>zincirTolerans,"ZİNCİR KIRIK","OK"))) | T30: =IF($A30="","",1)
A31: HAK-00026 | B31: KAR-00002 | C31: SAN-00001 | D31: 46245 | E31: DRAFT | F31: BEKLIYOR | G31: 425000 | H31: 425000 | I31: 425000 | J31: 425000 | K31: 0 | L31: 425000 | M31: 2026-08 | N31: Hakediş kalemi 26 | O31: =IF($A31="","",IF($D31="","",raporTarihi-$D31)) | P31: =IF($A31="","",IF($O31="","",IF($O31<=7,"0-7",IF($O31<=30,"8-30",IF($O31<=60,"31-60","60+"))))) | Q31: =IF($A31="","",IF($B31="","YETİM",IF(COUNTIF(tblKartlar[KartId],$B31)=0,"YETİM",""))) | R31: =IF(OR($A31="",$E31=""),"",IF(OR($E31&"|"&$F31="",COUNTIF(ListeIzinliGecis,$E31&"|"&$F31)>0),"","GEÇERSİZ GEÇİŞ")) | S31: =IF($A31="","",IF(OR($G31="",$I31=""),"",IF(ABS($I31-$G31)>zincirTolerans,"ZİNCİR KIRIK","OK"))) | T31: =IF($A31="","",1)
A32: HAK-00027 | B32: KAR-00003 | C32: SAN-00002 | D32: 46242 | E32: BEKLIYOR | F32: ONAY | G32: 437500 | H32: 437500 | I32: 437500 | J32: 437500 | K32: 0 | L32: 437500 | M32: 2026-08 | N32: Hakediş kalemi 27 | O32: =IF($A32="","",IF($D32="","",raporTarihi-$D32)) | P32: =IF($A32="","",IF($O32="","",IF($O32<=7,"0-7",IF($O32<=30,"8-30",IF($O32<=60,"31-60","60+"))))) | Q32: =IF($A32="","",IF($B32="","YETİM",IF(COUNTIF(tblKartlar[KartId],$B32)=0,"YETİM",""))) | R32: =IF(OR($A32="",$E32=""),"",IF(OR($E32&"|"&$F32="",COUNTIF(ListeIzinliGecis,$E32&"|"&$F32)>0),"","GEÇERSİZ GEÇİŞ")) | S32: =IF($A32="","",IF(OR($G32="",$I32=""),"",IF(ABS($I32-$G32)>zincirTolerans,"ZİNCİR KIRIK","OK"))) | T32: =IF($A32="","",1)
A33: HAK-00028 | B33: KAR-00004 | C33: SAN-00002 | D33: 46239 | E33: ONAY | F33: ODEME | G33: 450000 | H33: 450000 | I33: 450000 | J33: 450000 | K33: 450000 | L33: 450000 | M33: 2026-08 | N33: Hakediş kalemi 28 | O33: =IF($A33="","",IF($D33="","",raporTarihi-$D33)) | P33: =IF($A33="","",IF($O33="","",IF($O33<=7,"0-7",IF($O33<=30,"8-30",IF($O33<=60,"31-60","60+"))))) | Q33: =IF($A33="","",IF($B33="","YETİM",IF(COUNTIF(tblKartlar[KartId],$B33)=0,"YETİM",""))) | R33: =IF(OR($A33="",$E33=""),"",IF(OR($E33&"|"&$F33="",COUNTIF(ListeIzinliGecis,$E33&"|"&$F33)>0),"","GEÇERSİZ GEÇİŞ")) | S33: =IF($A33="","",IF(OR($G33="",$I33=""),"",IF(ABS($I33-$G33)>zincirTolerans,"ZİNCİR KIRIK","OK"))) | T33: =IF($A33="","",1)
O34: =IF($A34="","",IF($D34="","",raporTarihi-$D34)) | P34: =IF($A34="","",IF($O34="","",IF($O34<=7,"0-7",IF($O34<=30,"8-30",IF($O34<=60,"31-60","60+"))))) | Q34: =IF($A34="","",IF($B34="","YETİM",IF(COUNTIF(tblKartlar[KartId],$B34)=0,"YETİM",""))) | R34: =IF(OR($A34="",$E34=""),"",IF(OR($E34&"|"&$F34="",COUNTIF(ListeIzinliGecis,$E34&"|"&$F34)>0),"","GEÇERSİZ GEÇİŞ")) | S34: =IF($A34="","",IF(OR($G34="",$I34=""),"",IF(ABS($I34-$G34)>zincirTolerans,"ZİNCİR KIRIK","OK"))) | T34: =IF($A34="","",1)
O35: =IF($A35="","",IF($D35="","",raporTarihi-$D35)) | P35: =IF($A35="","",IF($O35="","",IF($O35<=7,"0-7",IF($O35<=30,"8-30",IF($O35<=60,"31-60","60+"))))) | Q35: =IF($A35="","",IF($B35="","YETİM",IF(COUNTIF(tblKartlar[KartId],$B35)=0,"YETİM",""))) | R35: =IF(OR($A35="",$E35=""),"",IF(OR($E35&"|"&$F35="",COUNTIF(ListeIzinliGecis,$E35&"|"&$F35)>0),"","GEÇERSİZ GEÇİŞ")) | S35: =IF($A35="","",IF(OR($G35="",$I35=""),"",IF(ABS($I35-$G35)>zincirTolerans,"ZİNCİR KIRIK","OK"))) | T35: =IF($A35="","",1)
O36: =IF($A36="","",IF($D36="","",raporTarihi-$D36)) | P36: =IF($A36="","",IF($O36="","",IF($O36<=7,"0-7",IF($O36<=30,"8-30",IF($O36<=60,"31-60","60+"))))) | Q36: =IF($A36="","",IF($B36="","YETİM",IF(COUNTIF(tblKartlar[KartId],$B36)=0,"YETİM",""))) | R36: =IF(OR($A36="",$E36=""),"",IF(OR($E36&"|"&$F36="",COUNTIF(ListeIzinliGecis,$E36&"|"&$F36)>0),"","GEÇERSİZ GEÇİŞ")) | S36: =IF($A36="","",IF(OR($G36="",$I36=""),"",IF(ABS($I36-$G36)>zincirTolerans,"ZİNCİR KIRIK","OK"))) | T36: =IF($A36="","",1)
O37: =IF($A37="","",IF($D37="","",raporTarihi-$D37)) | P37: =IF($A37="","",IF($O37="","",IF($O37<=7,"0-7",IF($O37<=30,"8-30",IF($O37<=60,"31-60","60+"))))) | Q37: =IF($A37="","",IF($B37="","YETİM",IF(COUNTIF(tblKartlar[KartId],$B37)=0,"YETİM",""))) | R37: =IF(OR($A37="",$E37=""),"",IF(OR($E37&"|"&$F37="",COUNTIF(ListeIzinliGecis,$E37&"|"&$F37)>0),"","GEÇERSİZ GEÇİŞ")) | S37: =IF($A37="","",IF(OR($G37="",$I37=""),"",IF(ABS($I37-$G37)>zincirTolerans,"ZİNCİR KIRIK","OK"))) | T37: =IF($A37="","",1)
O38: =IF($A38="","",IF($D38="","",raporTarihi-$D38)) | P38: =IF($A38="","",IF($O38="","",IF($O38<=7,"0-7",IF($O38<=30,"8-30",IF($O38<=60,"31-60","60+"))))) | Q38: =IF($A38="","",IF($B38="","YETİM",IF(COUNTIF(tblKartlar[KartId],$B38)=0,"YETİM",""))) | R38: =IF(OR($A38="",$E38=""),"",IF(OR($E38&"|"&$F38="",COUNTIF(ListeIzinliGecis,$E38&"|"&$F38)>0),"","GEÇERSİZ GEÇİŞ")) | S38: =IF($A38="","",IF(OR($G38="",$I38=""),"",IF(ABS($I38-$G38)>zincirTolerans,"ZİNCİR KIRIK","OK"))) | T38: =IF($A38="","",1)
O39: =IF($A39="","",IF($D39="","",raporTarihi-$D39)) | P39: =IF($A39="","",IF($O39="","",IF($O39<=7,"0-7",IF($O39<=30,"8-30",IF($O39<=60,"31-60","60+"))))) | Q39: =IF($A39="","",IF($B39="","YETİM",IF(COUNTIF(tblKartlar[KartId],$B39)=0,"YETİM",""))) | R39: =IF(OR($A39="",$E39=""),"",IF(OR($E39&"|"&$F39="",COUNTIF(ListeIzinliGecis,$E39&"|"&$F39)>0),"","GEÇERSİZ GEÇİŞ")) | S39: =IF($A39="","",IF(OR($G39="",$I39=""),"",IF(ABS($I39-$G39)>zincirTolerans,"ZİNCİR KIRIK","OK"))) | T39: =IF($A39="","",1)
O40: =IF($A40="","",IF($D40="","",raporTarihi-$D40)) | P40: =IF($A40="","",IF($O40="","",IF($O40<=7,"0-7",IF($O40<=30,"8-30",IF($O40<=60,"31-60","60+"))))) | Q40: =IF($A40="","",IF($B40="","YETİM",IF(COUNTIF(tblKartlar[KartId],$B40)=0,"YETİM",""))) | R40: =IF(OR($A40="",$E40=""),"",IF(OR($E40&"|"&$F40="",COUNTIF(ListeIzinliGecis,$E40&"|"&$F40)>0),"","GEÇERSİZ GEÇİŞ")) | S40: =IF($A40="","",IF(OR($G40="",$I40=""),"",IF(ABS($I40-$G40)>zincirTolerans,"ZİNCİR KIRIK","OK"))) | T40: =IF($A40="","",1)
O41: =IF($A41="","",IF($D41="","",raporTarihi-$D41)) | P41: =IF($A41="","",IF($O41="","",IF($O41<=7,"0-7",IF($O41<=30,"8-30",IF($O41<=60,"31-60","60+"))))) | Q41: =IF($A41="","",IF($B41="","YETİM",IF(COUNTIF(tblKartlar[KartId],$B41)=0,"YETİM",""))) | R41: =IF(OR($A41="",$E41=""),"",IF(OR($E41&"|"&$F41="",COUNTIF(ListeIzinliGecis,$E41&"|"&$F41)>0),"","GEÇERSİZ GEÇİŞ")) | S41: =IF($A41="","",IF(OR($G41="",$I41=""),"",IF(ABS($I41-$G41)>zincirTolerans,"ZİNCİR KIRIK","OK"))) | T41: =IF($A41="","",1)
O42: =IF($A42="","",IF($D42="","",raporTarihi-$D42)) | P42: =IF($A42="","",IF($O42="","",IF($O42<=7,"0-7",IF($O42<=30,"8-30",IF($O42<=60,"31-60","60+"))))) | Q42: =IF($A42="","",IF($B42="","YETİM",IF(COUNTIF(tblKartlar[KartId],$B42)=0,"YETİM",""))) | R42: =IF(OR($A42="",$E42=""),"",IF(OR($E42&"|"&$F42="",COUNTIF(ListeIzinliGecis,$E42&"|"&$F42)>0),"","GEÇERSİZ GEÇİŞ")) | S42: =IF($A42="","",IF(OR($G42="",$I42=""),"",IF(ABS($I42-$G42)>zincirTolerans,"ZİNCİR KIRIK","OK"))) | T42: =IF($A42="","",1)
...

Sheet KUYRUKLAR
A1: KUYRUKLAR — İnşaat Hakediş ve Şantiye Maliyet Takip
A3: Durum bazlı canlı kuyruk — kapalı kayıtlar düşer
A5: Kuyruk | B5: Adet | C5: Tutar
A6: Bekliyor | B6: =COUNTIFS(tblAkis[durum],"BEKLIYOR",tblAkis[tutar],">0") | C6: =SUMIFS(tblAkis[tutar],tblAkis[durum],"BEKLIYOR")
A7: Onaylandı | B7: =COUNTIFS(tblAkis[durum],"ONAY",tblAkis[tutar],">0") | C7: =SUMIFS(tblAkis[tutar],tblAkis[durum],"ONAY")
A8: Taslak | B8: =COUNTIFS(tblAkis[durum],"DRAFT",tblAkis[tutar],">0") | C8: =SUMIFS(tblAkis[tutar],tblAkis[durum],"DRAFT")
A9: Geciken (açık, yaş>eşik) | B9: =COUNTIFS(tblAkis[YasGun],">"&ihs_esikGecikmeGun,tblAkis[Durum],"<>ODEME",tblAkis[Durum],"<>IPTAL",tblAkis[Tutar],">0") | C9: =SUMIFS(tblAkis[Tutar],tblAkis[YasGun],">"&ihs_esikGecikmeGun,tblAkis[Durum],"<>ODEME",tblAkis[Durum],"<>IPTAL")
A11: Kapalı (Ödeme+İptal) — kuyruktan düşer
A12: Ödendi | B12: =COUNTIFS(tblAkis[durum],"ODEME",tblAkis[tutar],">0") | C12: =SUMIFS(tblAkis[tutar],tblAkis[durum],"ODEME")
A13: İptal | B13: =COUNTIFS(tblAkis[durum],"IPTAL",tblAkis[tutar],">0") | C13: =SUMIFS(tblAkis[tutar],tblAkis[durum],"IPTAL")
A15: Kuyruk Özeti | B15: =ihs_kuyrukOzeti
A17: Yaş Kova Dağılımı
A18: 0-7 | B18: =COUNTIF(tblAkis[YasKova],"0-7") | C18: =SUMIF(tblAkis[YasKova],"0-7",tblAkis[Tutar])
A19: 8-30 | B19: =COUNTIF(tblAkis[YasKova],"8-30") | C19: =SUMIF(tblAkis[YasKova],"8-30",tblAkis[Tutar])
A20: 31-60 | B20: =COUNTIF(tblAkis[YasKova],"31-60") | C20: =SUMIF(tblAkis[YasKova],"31-60",tblAkis[Tutar])
A21: 60+ | B21: =COUNTIF(tblAkis[YasKova],"60+") | C21: =SUMIF(tblAkis[YasKova],"60+",tblAkis[Tutar])

Sheet SANTIYE_MALIYET
A1: SANTIYE MALIYET — İnşaat Hakediş ve Şantiye Maliyet Takip
A3: Şantiye maliyet kartı — bütçe, işçilik, malzeme, makine, genel gider + bağlı hakediş
A4: Toplam Bütçe | B4: =SUM(tblSantiye[ButceTl]) | C4: Toplam Maliyet | D4: =SUM($J$6:$J$255) | E4: Sapma | F4: =SUM($K$6:$K$255) | G4: Aşım Adet | H4: =COUNTIF($M$6:$M$255,"AŞIM") | O4: Şantiye | P4: Bütçe | Q4: Maliyet
A5: SantiyeId | B5: SantiyeAdi | C5: Sehir | D5: ButceTl | E5: IscilikTl | F5: MalzemeTl | G5: MakineTl | H5: GenelGiderTl | I5: HakedisToplam | J5: ToplamMaliyet | K5: SapmaTl | L5: SapmaOran | M5: AsimBayrak | O5: Kadıköy Konut | P5: 2000000 | Q5: 3040000
A6: SAN-00001 | B6: Kadıköy Konut | C6: İstanbul | D6: 2000000 | E6: 450000 | F6: 520000 | G6: 180000 | H6: 90000 | I6: =IF(A6="","",SUMIF(tblAkis[SantiyeId],A6,tblAkis[Tutar])) | J6: =IF(A6="","",E6+F6+G6+H6+I6) | K6: =IF(A6="","",J6-D6) | L6: =IF(A6="","",IFERROR(K6/MAX(D6,1),0)) | M6: =IF(A6="","",IF(J6>D6*ihs_asimCarpan,"AŞIM","UYGUN")) | O6: Çankaya İş Merkezi | P6: 12000000 | Q6: 3870000
A7: SAN-00002 | B7: Çankaya İş Merkezi | C7: Ankara | D7: 12000000 | E7: 800000 | F7: 900000 | G7: 250000 | H7: 120000 | I7: =IF(A7="","",SUMIF(tblAkis[SantiyeId],A7,tblAkis[Tutar])) | J7: =IF(A7="","",E7+F7+G7+H7+I7) | K7: =IF(A7="","",J7-D7) | L7: =IF(A7="","",IFERROR(K7/MAX(D7,1),0)) | M7: =IF(A7="","",IF(J7>D7*ihs_asimCarpan,"AŞIM","UYGUN")) | O7: Bornova AVM | P7: 9000000 | Q7: 3400000
A8: SAN-00003 | B8: Bornova AVM | C8: İzmir | D8: 9000000 | E8: 600000 | F8: 700000 | G8: 200000 | H8: 100000 | I8: =IF(A8="","",SUMIF(tblAkis[SantiyeId],A8,tblAkis[Tutar])) | J8: =IF(A8="","",E8+F8+G8+H8+I8) | K8: =IF(A8="","",J8-D8) | L8: =IF(A8="","",IFERROR(K8/MAX(D8,1),0)) | M8: =IF(A8="","",IF(J8>D8*ihs_asimCarpan,"AŞIM","UYGUN")) | O8: Nilüfer Villa | P8: 5000000 | Q8: 2730000
A9: SAN-00004 | B9: Nilüfer Villa | C9: Bursa | D9: 5000000 | E9: 300000 | F9: 400000 | G9: 150000 | H9: 80000 | I9: =IF(A9="","",SUMIF(tblAkis[SantiyeId],A9,tblAkis[Tutar])) | J9: =IF(A9="","",E9+F9+G9+H9+I9) | K9: =IF(A9="","",J9-D9) | L9: =IF(A9="","",IFERROR(K9/MAX(D9,1),0)) | M9: =IF(A9="","",IF(J9>D9*ihs_asimCarpan,"AŞIM","UYGUN"))
I10: =IF(A10="","",SUMIF(tblAkis[SantiyeId],A10,tblAkis[Tutar])) | J10: =IF(A10="","",E10+F10+G10+H10+I10) | K10: =IF(A10="","",J10-D10) | L10: =IF(A10="","",IFERROR(K10/MAX(D10,1),0)) | M10: =IF(A10="","",IF(J10>D10*ihs_asimCarpan,"AŞIM","UYGUN"))
I11: =IF(A11="","",SUMIF(tblAkis[SantiyeId],A11,tblAkis[Tutar])) | J11: =IF(A11="","",E11+F11+G11+H11+I11) | K11: =IF(A11="","",J11-D11) | L11: =IF(A11="","",IFERROR(K11/MAX(D11,1),0)) | M11: =IF(A11="","",IF(J11>D11*ihs_asimCarpan,"AŞIM","UYGUN"))
I12: =IF(A12="","",SUMIF(tblAkis[SantiyeId],A12,tblAkis[Tutar])) | J12: =IF(A12="","",E12+F12+G12+H12+I12) | K12: =IF(A12="","",J12-D12) | L12: =IF(A12="","",IFERROR(K12/MAX(D12,1),0)) | M12: =IF(A12="","",IF(J12>D12*ihs_asimCarpan,"AŞIM","UYGUN"))
I13: =IF(A13="","",SUMIF(tblAkis[SantiyeId],A13,tblAkis[Tutar])) | J13: =IF(A13="","",E13+F13+G13+H13+I13) | K13: =IF(A13="","",J13-D13) | L13: =IF(A13="","",IFERROR(K13/MAX(D13,1),0)) | M13: =IF(A13="","",IF(J13>D13*ihs_asimCarpan,"AŞIM","UYGUN"))
I14: =IF(A14="","",SUMIF(tblAkis[SantiyeId],A14,tblAkis[Tutar])) | J14: =IF(A14="","",E14+F14+G14+H14+I14) | K14: =IF(A14="","",J14-D14) | L14: =IF(A14="","",IFERROR(K14/MAX(D14,1),0)) | M14: =IF(A14="","",IF(J14>D14*ihs_asimCarpan,"AŞIM","UYGUN"))
I15: =IF(A15="","",SUMIF(tblAkis[SantiyeId],A15,tblAkis[Tutar])) | J15: =IF(A15="","",E15+F15+G15+H15+I15) | K15: =IF(A15="","",J15-D15) | L15: =IF(A15="","",IFERROR(K15/MAX(D15,1),0)) | M15: =IF(A15="","",IF(J15>D15*ihs_asimCarpan,"AŞIM","UYGUN"))
I16: =IF(A16="","",SUMIF(tblAkis[SantiyeId],A16,tblAkis[Tutar])) | J16: =IF(A16="","",E16+F16+G16+H16+I16) | K16: =IF(A16="","",J16-D16) | L16: =IF(A16="","",IFERROR(K16/MAX(D16,1),0)) | M16: =IF(A16="","",IF(J16>D16*ihs_asimCarpan,"AŞIM","UYGUN"))
I17: =IF(A17="","",SUMIF(tblAkis[SantiyeId],A17,tblAkis[Tutar])) | J17: =IF(A17="","",E17+F17+G17+H17+I17) | K17: =IF(A17="","",J17-D17) | L17: =IF(A17="","",IFERROR(K17/MAX(D17,1),0)) | M17: =IF(A17="","",IF(J17>D17*ihs_asimCarpan,"AŞIM","UYGUN"))
I18: =IF(A18="","",SUMIF(tblAkis[SantiyeId],A18,tblAkis[Tutar])) | J18: =IF(A18="","",E18+F18+G18+H18+I18) | K18: =IF(A18="","",J18-D18) | L18: =IF(A18="","",IFERROR(K18/MAX(D18,1),0)) | M18: =IF(A18="","",IF(J18>D18*ihs_asimCarpan,"AŞIM","UYGUN"))
I19: =IF(A19="","",SUMIF(tblAkis[SantiyeId],A19,tblAkis[Tutar])) | J19: =IF(A19="","",E19+F19+G19+H19+I19) | K19: =IF(A19="","",J19-D19) | L19: =IF(A19="","",IFERROR(K19/MAX(D19,1),0)) | M19: =IF(A19="","",IF(J19>D19*ihs_asimCarpan,"AŞIM","UYGUN"))
I20: =IF(A20="","",SUMIF(tblAkis[SantiyeId],A20,tblAkis[Tutar])) | J20: =IF(A20="","",E20+F20+G20+H20+I20) | K20: =IF(A20="","",J20-D20) | L20: =IF(A20="","",IFERROR(K20/MAX(D20,1),0)) | M20: =IF(A20="","",IF(J20>D20*ihs_asimCarpan,"AŞIM","UYGUN"))
I21: =IF(A21="","",SUMIF(tblAkis[SantiyeId],A21,tblAkis[Tutar])) | J21: =IF(A21="","",E21+F21+G21+H21+I21) | K21: =IF(A21="","",J21-D21) | L21: =IF(A21="","",IFERROR(K21/MAX(D21,1),0)) | M21: =IF(A21="","",IF(J21>D21*ihs_asimCarpan,"AŞIM","UYGUN"))
... I255: =IF(A255="","",SUMIF(tblAkis[SantiyeId],A255,tblAkis[Tutar])) | J255: =IF(A255="","",E255+F255+G255+H255+I255) | K255: =IF(A255="","",J255-D255) | L255: =IF(A255="","",IFERROR(K255/MAX(D255,1),0)) | M255: =IF(A255="","",IF(J255>D255*ihs_asimCarpan,"AŞIM","UYGUN"))

Sheet HESAP
A1: HESAP — İnşaat Hakediş ve Şantiye Maliyet Takip
A3: Hesap motoru — ≥40 adım; sabitler AYARLAR'dan
A5: Adım | B5: Açıklama | C5: Değer
A6: H01 | B6: Toplam işlem | C6: =COUNTA(tblAkis[IslemId])
A7: H02 | B7: Dolu kayıt | C7: =SUM(tblAkis[KayitDolu])
A8: H03 | B8: Toplam tutar | C8: =SUM(tblAkis[Tutar])
A9: H04 | B9: Teklif toplam | C9: =SUM(tblAkis[Teklif])
A10: H05 | B10: Sipariş toplam | C10: =SUM(tblAkis[Siparis])
A11: H06 | B11: Hakediş toplam | C11: =SUM(tblAkis[Hakedis])
A12: H07 | B12: Fatura toplam | C12: =SUM(tblAkis[Fatura])
A13: H08 | B13: Ödeme toplam | C13: =SUM(tblAkis[Odeme])
A14: H09 | B14: Taslak adet | C14: =COUNTIF(tblAkis[Durum],"DRAFT")
A15: H10 | B15: Bekliyor adet | C15: =COUNTIF(tblAkis[Durum],"BEKLIYOR")
A16: H11 | B16: Onay adet | C16: =COUNTIF(tblAkis[Durum],"ONAY")
A17: H12 | B17: Ödeme adet | C17: =COUNTIF(tblAkis[Durum],"ODEME")
A18: H13 | B18: İptal adet | C18: =COUNTIF(tblAkis[Durum],"IPTAL")
A19: H14 | B19: Açık adet | C19: =C14+C15+C16
A20: H15 | B20: Kapalı adet | C20: =C17+C18
A21: H16 | B21: Açık tutar | C21: =SUMIF(tblAkis[Durum],"DRAFT",tblAkis[Tutar])+SUMIF(tblAkis[Durum],"BEKLIYOR",tblAkis[Tutar])+SUMIF(tblAkis[Durum],"ONAY",tblAkis[Tutar])
A22: H17 | B22: Yetim adet | C22: =COUNTIF(tblAkis[YetimBayrak],"YETİM")
A23: H18 | B23: Geçersiz geçiş | C23: =COUNTIF(tblAkis[GecisUyarisi],"GEÇERSİZ GEÇİŞ")
A24: H19 | B24: Zincir kırık | C24: =COUNTIF(tblAkis[ZincirBayrak],"ZİNCİR KIRIK")
A25: H20 | B25: Zincir tamam | C25: =COUNTIF(tblAkis[ZincirBayrak],"OK")
A26: H21 | B26: Yaş 0-7 | C26: =COUNTIF(tblAkis[YasKova],"0-7")
A27: H22 | B27: Yaş 8-30 | C27: =COUNTIF(tblAkis[YasKova],"8-30")
A28: H23 | B28: Yaş 31-60 | C28: =COUNTIF(tblAkis[YasKova],"31-60")
A29: H24 | B29: Yaş 60+ | C29: =COUNTIF(tblAkis[YasKova],"60+")
A30: H25 | B30: Ort yaş gün | C30: =IFERROR(AVERAGE(tblAkis[YasGun]),0)
A31: H26 | B31: Geciken adet | C31: =COUNTIFS(tblAkis[YasGun],">"&ihs_esikGecikmeGun,tblAkis[Durum],"<>ODEME",tblAkis[Durum],"<>IPTAL",tblAkis[Tutar],">0")
A32: H27 | B32: Geciken tutar | C32: =SUMIFS(tblAkis[Tutar],tblAkis[YasGun],">"&ihs_esikGecikmeGun,tblAkis[Durum],"<>ODEME",tblAkis[Durum],"<>IPTAL")
A33: H28 | B33: Gecikme maliyeti | C33: =C32*ihs_gecikmeOranGun
A34: H29 | B34: Temkinli senaryo | C34: =C21*ihs_senaryoTemkinli
A35: H30 | B35: Baz senaryo | C35: =C21*ihs_senaryoBaz
A36: H31 | B36: İyimser senaryo | C36: =C21*ihs_senaryoIyimser
A37: H32 | B37: Senaryo farkı | C37: =C36-C34
A38: H33 | B38: Tornado (oran×tutar) | C38: =C21*ihs_tornadoOran
A39: H34 | B39: Ödeme öncelik havuzu | C39: =SUMIFS(tblAkis[Tutar],tblAkis[Durum],"ONAY",tblAkis[YasGun],">"&ihs_esikGecikmeGun)
A40: H35 | B40: Pareto gecikme payı | C40: =IFERROR(C32/MAX(C21,1),0)
A41: H36 | B41: Tahmin yüzdelik | C41: =IFERROR(_xlfn.PERCENTILE.INC(tblAkis[Tutar],ihs_yuzdelikOran),0)
A42: H37 | B42: Tahmin eğilim | C42: =IFERROR(FORECAST(COUNTA(tblAkis[IslemId])+1,tblAkis[Tutar],tblAkis[KayitDolu]),C41)
...

Sheet RAPOR
A1: RAPOR — İnşaat Hakediş ve Şantiye Maliyet Takip
A3: Dönemsel Hakediş ve Şantiye Kanıt Raporu
A4: Rapor Tarihi | B4: =raporTarihi
A5: Sürüm | B5: 1.0.0 | D5: Lisans | E5: Tek kullanıcı
A7: KARAR | B7: =PANO!B4
A9: Açık Kuyruk | B9: =ihs_acikAdet
